Workbook

Sheet Producto 1 Plano 26
B2: ANEXO 1 - CANTIDADES DE ENERGÍA SOLICITADA EN kWh
B3: PRODUCTO 1
B4: PERIODO 01 DE ENERO DEL 2026 A DICIEMBRE 31 DE 2026
C5: DIA | D5: 1 | E5: 2 | F5: 3 | G5: 4 | H5: 5 | I5: 6 | J5: 7 | K5: 8 | L5: 9 | M5: 10 | N5: 11 | O5: 12 | P5: 13 | Q5: 14 | R5: 15 | S5: 16 | T5: 17 | U5: 18 | V5: 19 | W5: 20 | X5: 21 | Y5: 22 | Z5: 23 | AA5: 24 | AB5: Total | AC5: No. DÍAS | AD5: Total
B6: 46023 | C6: Hábil | D6: 5647.26 | E6: 5647.26 | F6: 5647.26 | G6: 5647.26 | H6: 5647.26 | I6: 5647.26 | J6: 5647.26 | K6: 5647.26 | L6: 5647.26 | M6: 5647.26 | N6: 5647.26 | O6: 5647.26 | P6: 5647.26 | Q6: 5647.26 | R6: 5647.26 | S6: 5647.26 | T6: 5647.26 | U6: 5647.26 | V6: 5647.26 | W6: 5647.26 | X6: 5647.26 | Y6: 5647.26 | Z6: 5647.26 | AA6: 5647.26 | AB6: =(SUM(D6:AA6)) -> 135534.24 | AC6: 20 | AD6: =(AB6*AC6)+(AB7*AC7)+(AB8*AC8)+(AB9*AC9) -> 4201561.4 | AE6: =+AD6 -> 4201561.4
C7: Sábado | D7: 5647.26 | E7: 5647.26 | F7: 5647.26 | G7: 5647.26 | H7: 5647.26 | I7: 5647.26 | J7: 5647.26 | K7: 5647.26 | L7: 5647.26 | M7: 5647.26 | N7: 5647.26 | O7: 5647.26 | P7: 5647.26 | Q7: 5647.26 | R7: 5647.26 | S7: 5647.26 | T7: 5647.26 | U7: 5647.26 | V7: 5647.26 | W7: 5647.26 | X7: 5647.26 | Y7: 5647.26 | Z7: 5647.26 | AA7: 5647.26 | AB7: =(SUM(D7:AA7)) -> 135534.24 | AC7: 5 | AE7: =+AD10 -> 3794958.7
C8: Domingo | D8: 5647.26 | E8: 5647.26 | F8: 5647.26 | G8: 5647.26 | H8: 5647.26 | I8: 5647.26 | J8: 5647.26 | K8: 5647.26 | L8: 5647.26 | M8: 5647.26 | N8: 5647.26 | O8: 5647.26 | P8: 5647.26 | Q8: 5647.26 | R8: 5647.26 | S8: 5647.26 | T8: 5647.26 | U8: 5647.26 | V8: 5647.26 | W8: 5647.26 | X8: 5647.26 | Y8: 5647.26 | Z8: 5647.26 | AA8: 5647.26 | AB8: =(SUM(D8:AA8)) -> 135534.24 | AC8: 4 | AE8: =+AD14 -> 4201561.4
C9: Festivo | D9: 5647.26 | E9: 5647.26 | F9: 5647.26 | G9: 5647.26 | H9: 5647.26 | I9: 5647.26 | J9: 5647.26 | K9: 5647.26 | L9: 5647.26 | M9: 5647.26 | N9: 5647.26 | O9: 5647.26 | P9: 5647.26 | Q9: 5647.26 | R9: 5647.26 | S9: 5647.26 | T9: 5647.26 | U9: 5647.26 | V9: 5647.26 | W9: 5647.26 | X9: 5647.26 | Y9: 5647.26 | Z9: 5647.26 | AA9: 5647.26 | AB9: =(SUM(D9:AA9)) -> 135534.24 | AC9: 2 | AE9: =+AD18 -> 4066027.2
B10: 46054 | C10: Hábil | D10: 5647.26 | E10: 5647.26 | F10: 5647.26 | G10: 5647.26 | H10: 5647.26 | I10: 5647.26 | J10: 5647.26 | K10: 5647.26 | L10: 5647.26 | M10: 5647.26 | N10: 5647.26 | O10: 5647.26 | P10: 5647.26 | Q10: 5647.26 | R10: 5647.26 | S10: 5647.26 | T10: 5647.26 | U10: 5647.26 | V10: 5647.26 | W10: 5647.26 | X10: 5647.26 | Y10: 5647.26 | Z10: 5647.26 | AA10: 5647.26 | AB10: =(SUM(D10:AA10)) -> 135534.24 | AC10: 20 | AD10: =(AB10*AC10)+(AB11*AC11)+(AB12*AC12)+(AB13*AC13) -> 3794958.7 | AE10: =+AD22 -> 4201561.4
C11: Sábado | D11: 5647.26 | E11: 5647.26 | F11: 5647.26 | G11: 5647.26 | H11: 5647.26 | I11: 5647.26 | J11: 5647.26 | K11: 5647.26 | L11: 5647.26 | M11: 5647.26 | N11: 5647.26 | O11: 5647.26 | P11: 5647.26 | Q11: 5647.26 | R11: 5647.26 | S11: 5647.26 | T11: 5647.26 | U11: 5647.26 | V11: 5647.26 | W11: 5647.26 | X11: 5647.26 | Y11: 5647.26 | Z11: 5647.26 | AA11: 5647.26 | AB11: =(SUM(D11:AA11)) -> 135534.24 | AC11: 4 | AE11: =+AD26 -> 4066027.2
C12: Domingo | D12: 5647.26 | E12: 5647.26 | F12: 5647.26 | G12: 5647.26 | H12: 5647.26 | I12: 5647.26 | J12: 5647.26 | K12: 5647.26 | L12: 5647.26 | M12: 5647.26 | N12: 5647.26 | O12: 5647.26 | P12: 5647.26 | Q12: 5647.26 | R12: 5647.26 | S12: 5647.26 | T12: 5647.26 | U12: 5647.26 | V12: 5647.26 | W12: 5647.26 | X12: 5647.26 | Y12: 5647.26 | Z12: 5647.26 | AA12: 5647.26 | AB12: =(SUM(D12:AA12)) -> 135534.24 | AC12: 4 | AE12: =+AD30 -> 4201561.4
C13: Festivo | D13: 5647.26 | E13: 5647.26 | F13: 5647.26 | G13: 5647.26 | H13: 5647.26 | I13: 5647.26 | J13: 5647.26 | K13: 5647.26 | L13: 5647.26 | M13: 5647.26 | N13: 5647.26 | O13: 5647.26 | P13: 5647.26 | Q13: 5647.26 | R13: 5647.26 | S13: 5647.26 | T13: 5647.26 | U13: 5647.26 | V13: 5647.26 | W13: 5647.26 | X13: 5647.26 | Y13: 5647.26 | Z13: 5647.26 | AA13: 5647.26 | AB13: =(SUM(D13:AA13)) -> 135534.24 | AC13: 0 | AE13: =+AD34 -> 4201561.4
B14: 46082 | C14: Hábil | D14: 5647.26 | E14: 5647.26 | F14: 5647.26 | G14: 5647.26 | H14: 5647.26 | I14: 5647.26 | J14: 5647.26 | K14: 5647.26 | L14: 5647.26 | M14: 5647.26 | N14: 5647.26 | O14: 5647.26 | P14: 5647.26 | Q14: 5647.26 | R14: 5647.26 | S14: 5647.26 | T14: 5647.26 | U14: 5647.26 | V14: 5647.26 | W14: 5647.26 | X14: 5647.26 | Y14: 5647.26 | Z14: 5647.26 | AA14: 5647.26 | AB14: =(SUM(D14:AA14)) -> 135534.24 | AC14: 21 | AD14: =(AB14*AC14)+(AB15*AC15)+(AB16*AC16)+(AB17*AC17) -> 4201561.4 | AE14: =+AD38 -> 4066027.2
C15: Sábado | D15: 5647.26 | E15: 5647.26 | F15: 5647.26 | G15: 5647.26 | H15: 5647.26 | I15: 5647.26 | J15: 5647.26 | K15: 5647.26 | L15: 5647.26 | M15: 5647.26 | N15: 5647.26 | O15: 5647.26 | P15: 5647.26 | Q15: 5647.26 | R15: 5647.26 | S15: 5647.26 | T15: 5647.26 | U15: 5647.26 | V15: 5647.26 | W15: 5647.26 | X15: 5647.26 | Y15: 5647.26 | Z15: 5647.26 | AA15: 5647.26 | AB15: =(SUM(D15:AA15)) -> 135534.24 | AC15: 4 | AE15: =+AD42 -> 4201561.4
C16: Domingo | D16: 5647.26 | E16: 5647.26 | F16: 5647.26 | G16: 5647.26 | H16: 5647.26 | I16: 5647.26 | J16: 5647.26 | K16: 5647.26 | L16: 5647.26 | M16: 5647.26 | N16: 5647.26 | O16: 5647.26 | P16: 5647.26 | Q16: 5647.26 | R16: 5647.26 | S16: 5647.26 | T16: 5647.26 | U16: 5647.26 | V16: 5647.26 | W16: 5647.26 | X16: 5647.26 | Y16: 5647.26 | Z16: 5647.26 | AA16: 5647.26 | AB16: =(SUM(D16:AA16)) -> 135534.24 | AC16: 5 | AE16: =+AD46 -> 4066027.2
C17: Festivo | D17: 5647.26 | E17: 5647.26 | F17: 5647.26 | G17: 5647.26 | H17: 5647.26 | I17: 5647.26 | J17: 5647.26 | K17: 5647.26 | L17: 5647.26 | M17: 5647.26 | N17: 5647.26 | O17: 5647.26 | P17: 5647.26 | Q17: 5647.26 | R17: 5647.26 | S17: 5647.26 | T17: 5647.26 | U17: 5647.26 | V17: 5647.26 | W17: 5647.26 | X17: 5647.26 | Y17: 5647.26 | Z17: 5647.26 | AA17: 5647.26 | AB17: =(SUM(D17:AA17)) -> 135534.24 | AC17: 1 | AE17: =+AD50 -> 4201561.4
B18: 46113 | C18: Hábil | D18: 5647.26 | E18: 5647.26 | F18: 5647.26 | G18: 5647.26 | H18: 5647.26 | I18: 5647.26 | J18: 5647.26 | K18: 5647.26 | L18: 5647.26 | M18: 5647.26 | N18: 5647.26 | O18: 5647.26 | P18: 5647.26 | Q18: 5647.26 | R18: 5647.26 | S18: 5647.26 | T18: 5647.26 | U18: 5647.26 | V18: 5647.26 | W18: 5647.26 | X18: 5647.26 | Y18: 5647.26 | Z18: 5647.26 | AA18: 5647.26 | AB18: =(SUM(D18:AA18)) -> 135534.24 | AC18: 20 | AD18: =(AB18*AC18)+(AB19*AC19)+(AB20*AC20)+(AB21*AC21) -> 4066027.2 | AE18: =+#REF! -> #REF!
C19: Sábado | D19: 5647.26 | E19: 5647.26 | F19: 5647.26 | G19: 5647.26 | H19: 5647.26 | I19: 5647.26 | J19: 5647.26 | K19: 5647.26 | L19: 5647.26 | M19: 5647.26 | N19: 5647.26 | O19: 5647.26 | P19: 5647.26 | Q19: 5647.26 | R19: 5647.26 | S19: 5647.26 | T19: 5647.26 | U19: 5647.26 | V19: 5647.26 | W19: 5647.26 | X19: 5647.26 | Y19: 5647.26 | Z19: 5647.26 | AA19: 5647.26 | AB19: =(SUM(D19:AA19)) -> 135534.24 | AC19: 4 | AE19: =+#REF! -> #REF!
C20: Domingo | D20: 5647.26 | E20: 5647.26 | F20: 5647.26 | G20: 5647.26 | H20: 5647.26 | I20: 5647.26 | J20: 5647.26 | K20: 5647.26 | L20: 5647.26 | M20: 5647.26 | N20: 5647.26 | O20: 5647.26 | P20: 5647.26 | Q20: 5647.26 | R20: 5647.26 | S20: 5647.26 | T20: 5647.26 | U20: 5647.26 | V20: 5647.26 | W20: 5647.26 | X20: 5647.26 | Y20: 5647.26 | Z20: 5647.26 | AA20: 5647.26 | AB20: =(SUM(D20:AA20)) -> 135534.24 | AC20: 4 | AE20: =+#REF! -> #REF!
C21: Festivo | D21: 5647.26 | E21: 5647.26 | F21: 5647.26 | G21: 5647.26 | H21: 5647.26 | I21: 5647.26 | J21: 5647.26 | K21: 5647.26 | L21: 5647.26 | M21: 5647.26 | N21: 5647.26 | O21: 5647.26 | P21: 5647.26 | Q21: 5647.26 | R21: 5647.26 | S21: 5647.26 | T21: 5647.26 | U21: 5647.26 | V21: 5647.26 | W21: 5647.26 | X21: 5647.26 | Y21: 5647.26 | Z21: 5647.26 | AA21: 5647.26 | AB21: =(SUM(D21:AA21)) -> 135534.24 | AC21: 2 | AE21: =+#REF! -> #REF!
B22: 46143 | C22: Hábil | D22: 5647.26 | E22: 5647.26 | F22: 5647.26 | G22: 5647.26 | H22: 5647.26 | I22: 5647.26 | J22: 5647.26 | K22: 5647.26 | L22: 5647.26 | M22: 5647.26 | N22: 5647.26 | O22: 5647.26 | P22: 5647.26 | Q22: 5647.26 | R22: 5647.26 | S22: 5647.26 | T22: 5647.26 | U22: 5647.26 | V22: 5647.26 | W22: 5647.26 | X22: 5647.26 | Y22: 5647.26 | Z22: 5647.26 | AA22: 5647.26 | AB22: =(SUM(D22:AA22)) -> 135534.24 | AC22: 19 | AD22: =(AB22*AC22)+(AB23*AC23)+(AB24*AC24)+(AB25*AC25) -> 4201561.4 | AE22: =+#REF! -> #REF!
C23: Sábado | D23: 5647.26 | E23: 5647.26 | F23: 5647.26 | G23: 5647.26 | H23: 5647.26 | I23: 5647.26 | J23: 5647.26 | K23: 5647.26 | L23: 5647.26 | M23: 5647.26 | N23: 5647.26 | O23: 5647.26 | P23: 5647.26 | Q23: 5647.26 | R23: 5647.26 | S23: 5647.26 | T23: 5647.26 | U23: 5647.26 | V23: 5647.26 | W23: 5647.26 | X23: 5647.26 | Y23: 5647.26 | Z23: 5647.26 | AA23: 5647.26 | AB23: =(SUM(D23:AA23)) -> 135534.24 | AC23: 5 | AE23: =+#REF! -> #REF!
C24: Domingo | D24: 5647.26 | E24: 5647.26 | F24: 5647.26 | G24: 5647.26 | H24: 5647.26 | I24: 5647.26 | J24: 5647.26 | K24: 5647.26 | L24: 5647.26 | M24: 5647.26 | N24: 5647.26 | O24: 5647.26 | P24: 5647.26 | Q24: 5647.26 | R24: 5647.26 | S24: 5647.26 | T24: 5647.26 | U24: 5647.26 | V24: 5647.26 | W24: 5647.26 | X24: 5647.26 | Y24: 5647.26 | Z24: 5647.26 | AA24: 5647.26 | AB24: =(SUM(D24:AA24)) -> 135534.24 | AC24: 5 | AE24: =+#REF! -> #REF!
C25: Festivo | D25: 5647.26 | E25: 5647.26 | F25: 5647.26 | G25: 5647.26 | H25: 5647.26 | I25: 5647.26 | J25: 5647.26 | K25: 5647.26 | L25: 5647.26 | M25: 5647.26 | N25: 5647.26 | O25: 5647.26 | P25: 5647.26 | Q25: 5647.26 | R25: 5647.26 | S25: 5647.26 | T25: 5647.26 | U25: 5647.26 | V25: 5647.26 | W25: 5647.26 | X25: 5647.26 | Y25: 5647.26 | Z25: 5647.26 | AA25: 5647.26 | AB25: =(SUM(D25:AA25)) -> 135534.24 | AC25: 2 | AE25: =+#REF! -> #REF!
B26: 46174 | C26: Hábil | D26: 5647.26 | E26: 5647.26 | F26: 5647.26 | G26: 5647.26 | H26: 5647.26 | I26: 5647.26 | J26: 5647.26 | K26: 5647.26 | L26: 5647.26 | M26: 5647.26 | N26: 5647.26 | O26: 5647.26 | P26: 5647.26 | Q26: 5647.26 | R26: 5647.26 | S26: 5647.26 | T26: 5647.26 | U26: 5647.26 | V26: 5647.26 | W26: 5647.26 | X26: 5647.26 | Y26: 5647.26 | Z26: 5647.26 | AA26: 5647.26 | AB26: =(SUM(D26:AA26)) -> 135534.24 | AC26: 19 | AD26: =(AB26*AC26)+(AB27*AC27)+(AB28*AC28)+(AB29*AC29) -> 4066027.2 | AE26: =+#REF! -> #REF!
C27: Sábado | D27: 5647.26 | E27: 5647.26 | F27: 5647.26 | G27: 5647.26 | H27: 5647.26 | I27: 5647.26 | J27: 5647.26 | K27: 5647.26 | L27: 5647.26 | M27: 5647.26 | N27: 5647.26 | O27: 5647.26 | P27: 5647.26 | Q27: 5647.26 | R27: 5647.26 | S27: 5647.26 | T27: 5647.26 | U27: 5647.26 | V27: 5647.26 | W27: 5647.26 | X27: 5647.26 | Y27: 5647.26 | Z27: 5647.26 | AA27: 5647.26 | AB27: =(SUM(D27:AA27)) -> 135534.24 | AC27: 4 | AE27: =+#REF! -> #REF!
C28: Domingo | D28: 5647.26 | E28: 5647.26 | F28: 5647.26 | G28: 5647.26 | H28: 5647.26 | I28: 5647.26 | J28: 5647.26 | K28: 5647.26 | L28: 5647.26 | M28: 5647.26 | N28: 5647.26 | O28: 5647.26 | P28: 5647.26 | Q28: 5647.26 | R28: 5647.26 | S28: 5647.26 | T28: 5647.26 | U28: 5647.26 | V28: 5647.26 | W28: 5647.26 | X28: 5647.26 | Y28: 5647.26 | Z28: 5647.26 | AA28: 5647.26 | AB28: =(SUM(D28:AA28)) -> 135534.24 | AC28: 4 | AE28: =+#REF! -> #REF!
C29: Festivo | D29: 5647.26 | E29: 5647.26 | F29: 5647.26 | G29: 5647.26 | H29: 5647.26 | I29: 5647.26 | J29: 5647.26 | K29: 5647.26 | L29: 5647.26 | M29: 5647.26 | N29: 5647.26 | O29: 5647.26 | P29: 5647.26 | Q29: 5647.26 | R29: 5647.26 | S29: 5647.26 | T29: 5647.26 | U29: 5647.26 | V29: 5647.26 | W29: 5647.26 | X29: 5647.26 | Y29: 5647.26 | Z29: 5647.26 | AA29: 5647.26 | AB29: =(SUM(D29:AA29)) -> 135534.24 | AC29: 3 | AE29: =+#REF! -> #REF!
B30: 46204 | C30: Hábil | D30: 5647.26 | E30: 5647.26 | F30: 5647.26 | G30: 5647.26 | H30: 5647.26 | I30: 5647.26 | J30: 5647.26 | K30: 5647.26 | L30: 5647.26 | M30: 5647.26 | N30: 5647.26 | O30: 5647.26 | P30: 5647.26 | Q30: 5647.26 | R30: 5647.26 | S30: 5647.26 | T30: 5647.26 | U30: 5647.26 | V30: 5647.26 | W30: 5647.26 | X30: 5647.26 | Y30: 5647.26 | Z30: 5647.26 | AA30: 5647.26 | AB30: =(SUM(D30:AA30)) -> 135534.24 | AC30: 22 | AD30: =(AB30*AC30)+(AB31*AC31)+(AB32*AC32)+(AB33*AC33) -> 4201561.4 | AE30: =+#REF! -> #REF!
C31: Sábado | D31: 5647.26 | E31: 5647.26 | F31: 5647.26 | G31: 5647.26 | H31: 5647.26 | I31: 5647.26 | J31: 5647.26 | K31: 5647.26 | L31: 5647.26 | M31: 5647.26 | N31: 5647.26 | O31: 5647.26 | P31: 5647.26 | Q31: 5647.26 | R31: 5647.26 | S31: 5647.26 | T31: 5647.26 | U31: 5647.26 | V31: 5647.26 | W31: 5647.26 | X31: 5647.26 | Y31: 5647.26 | Z31: 5647.26 | AA31: 5647.26 | AB31: =(SUM(D31:AA31)) -> 135534.24 | AC31: 4 | AE31: =+#REF! -> #REF!
C32: domingo | D32: 5647.26 | E32: 5647.26 | F32: 5647.26 | G32: 5647.26 | H32: 5647.26 | I32: 5647.26 | J32: 5647.26 | K32: 5647.26 | L32: 5647.26 | M32: 5647.26 | N32: 5647.26 | O32: 5647.26 | P32: 5647.26 | Q32: 5647.26 | R32: 5647.26 | S32: 5647.26 | T32: 5647.26 | U32: 5647.26 | V32: 5647.26 | W32: 5647.26 | X32: 5647.26 | Y32: 5647.26 | Z32: 5647.26 | AA32: 5647.26 | AB32: =(SUM(D32:AA32)) -> 135534.24 | AC32: 4 | AE32: =+#REF! -> #REF!
C33: Festivo | D33: 5647.26 | E33: 5647.26 | F33: 5647.26 | G33: 5647.26 | H33: 5647.26 | I33: 5647.26 | J33: 5647.26 | K33: 5647.26 | L33: 5647.26 | M33: 5647.26 | N33: 5647.26 | O33: 5647.26 | P33: 5647.26 | Q33: 5647.26 | R33: 5647.26 | S33: 5647.26 | T33: 5647.26 | U33: 5647.26 | V33: 5647.26 | W33: 5647.26 | X33: 5647.26 | Y33: 5647.26 | Z33: 5647.26 | AA33: 5647.26 | AB33: =(SUM(D33:AA33)) -> 135534.24 | AC33: 1 | AE33: =+#REF! -> #REF!
B34: 46235 | C34: Hábil | D34: 5647.26 | E34: 5647.26 | F34: 5647.26 | G34: 5647.26 | H34: 5647.26 | I34: 5647.26 | J34: 5647.26 | K34: 5647.26 | L34: 5647.26 | M34: 5647.26 | N34: 5647.26 | O34: 5647.26 | P34: 5647.26 | Q34: 5647.26 | R34: 5647.26 | S34: 5647.26 | T34: 5647.26 | U34: 5647.26 | V34: 5647.26 | W34: 5647.26 | X34: 5647.26 | Y34: 5647.26 | Z34: 5647.26 | AA34: 5647.26 | AB34: =(SUM(D34:AA34)) -> 135534.24 | AC34: 19 | AD34: =(AB34*AC34)+(AB35*AC35)+(AB36*AC36)+(AB37*AC37) -> 4201561.4 | AE34: =+#REF! -> #REF!
C35: Sábado | D35: 5647.26 | E35: 5647.26 | F35: 5647.26 | G35: 5647.26 | H35: 5647.26 | I35: 5647.26 | J35: 5647.26 | K35: 5647.26 | L35: 5647.26 | M35: 5647.26 | N35: 5647.26 | O35: 5647.26 | P35: 5647.26 | Q35: 5647.26 | R35: 5647.26 | S35: 5647.26 | T35: 5647.26 | U35: 5647.26 | V35: 5647.26 | W35: 5647.26 | X35: 5647.26 | Y35: 5647.26 | Z35: 5647.26 | AA35: 5647.26 | AB35: =(SUM(D35:AA35)) -> 135534.24 | AC35: 5 | AE35: =+#REF! -> #REF!
C36: Domingo | D36: 5647.26 | E36: 5647.26 | F36: 5647.26 | G36: 5647.26 | H36: 5647.26 | I36: 5647.26 | J36: 5647.26 | K36: 5647.26 | L36: 5647.26 | M36: 5647.26 | N36: 5647.26 | O36: 5647.26 | P36: 5647.26 | Q36: 5647.26 | R36: 5647.26 | S36: 5647.26 | T36: 5647.26 | U36: 5647.26 | V36: 5647.26 | W36: 5647.26 | X36: 5647.26 | Y36: 5647.26 | Z36: 5647.26 | AA36: 5647.26 | AB36: =(SUM(D36:AA36)) -> 135534.24 | AC36: 5 | AE36: =+#REF! -> #REF!
C37: Festivo | D37: 5647.26 | E37: 5647.26 | F37: 5647.26 | G37: 5647.26 | H37: 5647.26 | I37: 5647.26 | J37: 5647.26 | K37: 5647.26 | L37: 5647.26 | M37: 5647.26 | N37: 5647.26 | O37: 5647.26 | P37: 5647.26 | Q37: 5647.26 | R37: 5647.26 | S37: 5647.26 | T37: 5647.26 | U37: 5647.26 | V37: 5647.26 | W37: 5647.26 | X37: 5647.26 | Y37: 5647.26 | Z37: 5647.26 | AA37: 5647.26 | AB37: =(SUM(D37:AA37)) -> 135534.24 | AC37: 2 | AE37: =+#REF! -> #REF!
B38: 46266 | C38: Hábil | D38: 5647.26 | E38: 5647.26 | F38: 5647.26 | G38: 5647.26 | H38: 5647.26 | I38: 5647.26 | J38: 5647.26 | K38: 5647.26 | L38: 5647.26 | M38: 5647.26 | N38: 5647.26 | O38: 5647.26 | P38: 5647.26 | Q38: 5647.26 | R38: 5647.26 | S38: 5647.26 | T38: 5647.26 | U38: 5647.26 | V38: 5647.26 | W38: 5647.26 | X38: 5647.26 | Y38: 5647.26 | Z38: 5647.26 | AA38: 5647.26 | AB38: =(SUM(D38:AA38)) -> 135534.24 | AC38: 22 | AD38: =(AB38*AC38)+(AB39*AC39)+(AB40*AC40)+(AB41*AC41) -> 4066027.2 | AE38: =+#REF! -> #REF!
C39: Sábado | D39: 5647.26 | E39: 5647.26 | F39: 5647.26 | G39: 5647.26 | H39: 5647.26 | I39: 5647.26 | J39: 5647.26 | K39: 5647.26 | L39: 5647.26 | M39: 5647.26 | N39: 5647.26 | O39: 5647.26 | P39: 5647.26 | Q39: 5647.26 | R39: 5647.26 | S39: 5647.26 | T39: 5647.26 | U39: 5647.26 | V39: 5647.26 | W39: 5647.26 | X39: 5647.26 | Y39: 5647.26 | Z39: 5647.26 | AA39: 5647.26 | AB39: =(SUM(D39:AA39)) -> 135534.24 | AC39: 4 | AE39: =+#REF! -> #REF!
C40: Domingo | D40: 5647.26 | E40: 5647.26 | F40: 5647.26 | G40: 5647.26 | H40: 5647.26 | I40: 5647.26 | J40: 5647.26 | K40: 5647.26 | L40: 5647.26 | M40: 5647.26 | N40: 5647.26 | O40: 5647.26 | P40: 5647.26 | Q40: 5647.26 | R40: 5647.26 | S40: 5647.26 | T40: 5647.26 | U40: 5647.26 | V40: 5647.26 | W40: 5647.26 | X40: 5647.26 | Y40: 5647.26 | Z40: 5647.26 | AA40: 5647.26 | AB40: =(SUM(D40:AA40)) -> 135534.24 | AC40: 4 | AE40: =+#REF! -> #REF!
C41: Festivo | D41: 5647.26 | E41: 5647.26 | F41: 5647.26 | G41: 5647.26 | H41: 5647.26 | I41: 5647.26 | J41: 5647.26 | K41: 5647.26 | L41: 5647.26 | M41: 5647.26 | N41: 5647.26 | O41: 5647.26 | P41: 5647.26 | Q41: 5647.26 | R41: 5647.26 | S41: 5647.26 | T41: 5647.26 | U41: 5647.26 | V41: 5647.26 | W41: 5647.26 | X41: 5647.26 | Y41: 5647.26 | Z41: 5647.26 | AA41: 5647.26 | AB41: =(SUM(D41:AA41)) -> 135534.24 | AC41: 0 | AE41: =+#REF! -> #REF!
...

Sheet Anexo 2 Producto 1
B4: ANEXO 2 - OFERTA PRODUCTO 1
B5: NOMBRE DEL OFERENTE
B6: PRECIOS Y CANTIDADES DE ENERGIA OFERTADA
B7: EN PESOS DE ENERO 2025
B8: PRODUCTO 1
B9: AÑO | C9: MES | D9: PERIODO 2026
D10: E. Solicitada [kWh] | E10: % E. Ofertado | F10: E. Ofertada [kWh] | G10: $/kWh
B11: 2026 | C11: Enero | D11: =+'Producto 1 Plano 26'!AE6 -> 4201561.4 | F11: =+E11*D11 -> 0
B12: 2026 | C12: Febrero | D12: =+'Producto 1 Plano 26'!AE7 -> 3794958.7 | F12: =+E12*D12 -> 0
B13: 2026 | C13: Marzo | D13: =+'Producto 1 Plano 26'!AE8 -> 4201561.4 | F13: =+E13*D13 -> 0
B14: 2026 | C14: Abril | D14: =+'Producto 1 Plano 26'!AE9 -> 4066027.2 | F14: =+E14*D14 -> 0
B15: 2026 | C15: Mayo | D15: =+'Producto 1 Plano 26'!AE10 -> 4201561.4 | F15: =+E15*D15 -> 0
B16: 2026 | C16: Junio | D16: =+'Producto 1 Plano 26'!AE11 -> 4066027.2 | F16: =+E16*D16 -> 0
B17: 2026 | C17: Julio | D17: =+'Producto 1 Plano 26'!AE12 -> 4201561.4 | F17: =+E17*D17 -> 0
B18: 2026 | C18: Agosto | D18: =+'Producto 1 Plano 26'!AE13 -> 4201561.4 | F18: =+E18*D18 -> 0
B19: 2026 | C19: Septiembre | D19: =+'Producto 1 Plano 26'!AE14 -> 4066027.2 | F19: =+E19*D19 -> 0
B20: 2026 | C20: Octubre | D20: =+'Producto 1 Plano 26'!AE15 -> 4201561.4 | F20: =+E20*D20 -> 0
B21: 2026 | C21: Noviembre | D21: =+'Producto 1 Plano 26'!AE16 -> 4066027.2 | F21: =+E21*D21 -> 0
B22: 2026 | C22: Diciembre | D22: =+'Producto 1 Plano 26'!AE17 -> 4201561.4 | F22: =+E22*D22 -> 0 | H22: =SUM(D11:D22) -> 49469998 | I22: =+H22/1000 -> 49469.998
B23: Total Producto 1 | D23: =+SUM(D11:D22) -> 49469998 | I23: =+D23/1000 -> 49469.998
B25: E. Solicitada = Energía solicitada por RUITOQUE para el producto.
B26: % E. Ofertado = Porcentaje de energía ofertado por el agente respecto a la E. Solicitada.
B27: E. Ofertada = Energía ofertada por el agente, producto de la E. Solicitada y el % E. Ofertado.
B28: $/kWh = Tarifa de la oferta para todas las horas del mes.

Sheet Producto 2 Plano 27
B2: ANEXO 1 - CANTIDADES DE ENERGÍA SOLICITADA EN kWh
B3: PRODUCTO 2
B4: PERIODO 01 DE ENERO DEL 2027 A DICIEMBRE 31 DE 2027
C5: DIA | D5: 1 | E5: 2 | F5: 3 | G5: 4 | H5: 5 | I5: 6 | J5: 7 | K5: 8 | L5: 9 | M5: 10 | N5: 11 | O5: 12 | P5: 13 | Q5: 14 | R5: 15 | S5: 16 | T5: 17 | U5: 18 | V5: 19 | W5: 20 | X5: 21 | Y5: 22 | Z5: 23 | AA5: 24 | AB5: Total | AC5: No. DÍAS | AD5: Total
B6: 46388 | C6: Hábil | D6: 994.29 | E6: 994.29 | F6: 994.29 | G6: 994.29 | H6: 994.29 | I6: 994.29 | J6: 994.29 | K6: 994.29 | L6: 994.29 | M6: 994.29 | N6: 994.29 | O6: 994.29 | P6: 994.29 | Q6: 994.29 | R6: 994.29 | S6: 994.29 | T6: 994.29 | U6: 994.29 | V6: 994.29 | W6: 994.29 | X6: 994.29 | Y6: 994.29 | Z6: 994.29 | AA6: 994.29 | AB6: =(SUM(D6:AA6)) -> 23862.96 | AC6: 19 | AD6: =(AB6*AC6)+(AB7*AC7)+(AB8*AC8)+(AB9*AC9) -> 739751.76 | AE6: =+AD6 -> 739751.76
C7: Sábado | D7: 994.29 | E7: 994.29 | F7: 994.29 | G7: 994.29 | H7: 994.29 | I7: 994.29 | J7: 994.29 | K7: 994.29 | L7: 994.29 | M7: 994.29 | N7: 994.29 | O7: 994.29 | P7: 994.29 | Q7: 994.29 | R7: 994.29 | S7: 994.29 | T7: 994.29 | U7: 994.29 | V7: 994.29 | W7: 994.29 | X7: 994.29 | Y7: 994.29 | Z7: 994.29 | AA7: 994.29 | AB7: =(SUM(D7:AA7)) -> 23862.96 | AC7: 5 | AE7: =+AD10 -> 668162.88
C8: Domingo | D8: 994.29 | E8: 994.29 | F8: 994.29 | G8: 994.29 | H8: 994.29 | I8: 994.29 | J8: 994.29 | K8: 994.29 | L8: 994.29 | M8: 994.29 | N8: 994.29 | O8: 994.29 | P8: 994.29 | Q8: 994.29 | R8: 994.29 | S8: 994.29 | T8: 994.29 | U8: 994.29 | V8: 994.29 | W8: 994.29 | X8: 994.29 | Y8: 994.29 | Z8: 994.29 | AA8: 994.29 | AB8: =(SUM(D8:AA8)) -> 23862.96 | AC8: 5 | AE8: =+AD14 -> 739751.76
C9: Festivo | D9: 994.29 | E9: 994.29 | F9: 994.29 | G9: 994.29 | H9: 994.29 | I9: 994.29 | J9: 994.29 | K9: 994.29 | L9: 994.29 | M9: 994.29 | N9: 994.29 | O9: 994.29 | P9: 994.29 | Q9: 994.29 | R9: 994.29 | S9: 994.29 | T9: 994.29 | U9: 994.29 | V9: 994.29 | W9: 994.29 | X9: 994.29 | Y9: 994.29 | Z9: 994.29 | AA9: 994.29 | AB9: =(SUM(D9:AA9)) -> 23862.96 | AC9: 2 | AE9: =+AD18 -> 715888.8
B10: 46419 | C10: Hábil | D10: 994.29 | E10: 994.29 | F10: 994.29 | G10: 994.29 | H10: 994.29 | I10: 994.29 | J10: 994.29 | K10: 994.29 | L10: 994.29 | M10: 994.29 | N10: 994.29 | O10: 994.29 | P10: 994.29 | Q10: 994.29 | R10: 994.29 | S10: 994.29 | T10: 994.29 | U10: 994.29 | V10: 994.29 | W10: 994.29 | X10: 994.29 | Y10: 994.29 | Z10: 994.29 | AA10: 994.29 | AB10: =(SUM(D10:AA10)) -> 23862.96 | AC10: 20 | AD10: =(AB10*AC10)+(AB11*AC11)+(AB12*AC12)+(AB13*AC13) -> 668162.88 | AE10: =+AD22 -> 739751.76
C11: Sábado | D11: 994.29 | E11: 994.29 | F11: 994.29 | G11: 994.29 | H11: 994.29 | I11: 994.29 | J11: 994.29 | K11: 994.29 | L11: 994.29 | M11: 994.29 | N11: 994.29 | O11: 994.29 | P11: 994.29 | Q11: 994.29 | R11: 994.29 | S11: 994.29 | T11: 994.29 | U11: 994.29 | V11: 994.29 | W11: 994.29 | X11: 994.29 | Y11: 994.29 | Z11: 994.29 | AA11: 994.29 | AB11: =(SUM(D11:AA11)) -> 23862.96 | AC11: 4 | AE11: =+AD26 -> 715888.8
C12: Domingo | D12: 994.29 | E12: 994.29 | F12: 994.29 | G12: 994.29 | H12: 994.29 | I12: 994.29 | J12: 994.29 | K12: 994.29 | L12: 994.29 | M12: 994.29 | N12: 994.29 | O12: 994.29 | P12: 994.29 | Q12: 994.29 | R12: 994.29 | S12: 994.29 | T12: 994.29 | U12: 994.29 | V12: 994.29 | W12: 994.29 | X12: 994.29 | Y12: 994.29 | Z12: 994.29 | AA12: 994.29 | AB12: =(SUM(D12:AA12)) -> 23862.96 | AC12: 4 | AE12: =+AD30 -> 739751.76
C13: Festivo | D13: 994.29 | E13: 994.29 | F13: 994.29 | G13: 994.29 | H13: 994.29 | I13: 994.29 | J13: 994.29 | K13: 994.29 | L13: 994.29 | M13: 994.29 | N13: 994.29 | O13: 994.29 | P13: 994.29 | Q13: 994.29 | R13: 994.29 | S13: 994.29 | T13: 994.29 | U13: 994.29 | V13: 994.29 | W13: 994.29 | X13: 994.29 | Y13: 994.29 | Z13: 994.29 | AA13: 994.29 | AB13: =(SUM(D13:AA13)) -> 23862.96 | AC13: 0 | AE13: =+AD34 -> 739751.76
B14: 46447 | C14: Hábil | D14: 994.29 | E14: 994.29 | F14: 994.29 | G14: 994.29 | H14: 994.29 | I14: 994.29 | J14: 994.29 | K14: 994.29 | L14: 994.29 | M14: 994.29 | N14: 994.29 | O14: 994.29 | P14: 994.29 | Q14: 994.29 | R14: 994.29 | S14: 994.29 | T14: 994.29 | U14: 994.29 | V14: 994.29 | W14: 994.29 | X14: 994.29 | Y14: 994.29 | Z14: 994.29 | AA14: 994.29 | AB14: =(SUM(D14:AA14)) -> 23862.96 | AC14: 20 | AD14: =(AB14*AC14)+(AB15*AC15)+(AB16*AC16)+(AB17*AC17) -> 739751.76 | AE14: =+AD38 -> 715888.8
C15: Sábado | D15: 994.29 | E15: 994.29 | F15: 994.29 | G15: 994.29 | H15: 994.29 | I15: 994.29 | J15: 994.29 | K15: 994.29 | L15: 994.29 | M15: 994.29 | N15: 994.29 | O15: 994.29 | P15: 994.29 | Q15: 994.29 | R15: 994.29 | S15: 994.29 | T15: 994.29 | U15: 994.29 | V15: 994.29 | W15: 994.29 | X15: 994.29 | Y15: 994.29 | Z15: 994.29 | AA15: 994.29 | AB15: =(SUM(D15:AA15)) -> 23862.96 | AC15: 4 | AE15: =+AD42 -> 739751.76
C16: Domingo | D16: 994.29 | E16: 994.29 | F16: 994.29 | G16: 994.29 | H16: 994.29 | I16: 994.29 | J16: 994.29 | K16: 994.29 | L16: 994.29 | M16: 994.29 | N16: 994.29 | O16: 994.29 | P16: 994.29 | Q16: 994.29 | R16: 994.29 | S16: 994.29 | T16: 994.29 | U16: 994.29 | V16: 994.29 | W16: 994.29 | X16: 994.29 | Y16: 994.29 | Z16: 994.29 | AA16: 994.29 | AB16: =(SUM(D16:AA16)) -> 23862.96 | AC16: 4 | AE16: =+AD46 -> 715888.8
C17: Festivo | D17: 994.29 | E17: 994.29 | F17: 994.29 | G17: 994.29 | H17: 994.29 | I17: 994.29 | J17: 994.29 | K17: 994.29 | L17: 994.29 | M17: 994.29 | N17: 994.29 | O17: 994.29 | P17: 994.29 | Q17: 994.29 | R17: 994.29 | S17: 994.29 | T17: 994.29 | U17: 994.29 | V17: 994.29 | W17: 994.29 | X17: 994.29 | Y17: 994.29 | Z17: 994.29 | AA17: 994.29 | AB17: =(SUM(D17:AA17)) -> 23862.96 | AC17: 3 | AE17: =+AD50 -> 739751.76
B18: 46478 | C18: Hábil | D18: 994.29 | E18: 994.29 | F18: 994.29 | G18: 994.29 | H18: 994.29 | I18: 994.29 | J18: 994.29 | K18: 994.29 | L18: 994.29 | M18: 994.29 | N18: 994.29 | O18: 994.29 | P18: 994.29 | Q18: 994.29 | R18: 994.29 | S18: 994.29 | T18: 994.29 | U18: 994.29 | V18: 994.29 | W18: 994.29 | X18: 994.29 | Y18: 994.29 | Z18: 994.29 | AA18: 994.29 | AB18: =(SUM(D18:AA18)) -> 23862.96 | AC18: 22 | AD18: =(AB18*AC18)+(AB19*AC19)+(AB20*AC20)+(AB21*AC21) -> 715888.8
C19: Sábado | D19: 994.29 | E19: 994.29 | F19: 994.29 | G19: 994.29 | H19: 994.29 | I19: 994.29 | J19: 994.29 | K19: 994.29 | L19: 994.29 | M19: 994.29 | N19: 994.29 | O19: 994.29 | P19: 994.29 | Q19: 994.29 | R19: 994.29 | S19: 994.29 | T19: 994.29 | U19: 994.29 | V19: 994.29 | W19: 994.29 | X19: 994.29 | Y19: 994.29 | Z19: 994.29 | AA19: 994.29 | AB19: =(SUM(D19:AA19)) -> 23862.96 | AC19: 4
C20: Domingo | D20: 994.29 | E20: 994.29 | F20: 994.29 | G20: 994.29 | H20: 994.29 | I20: 994.29 | J20: 994.29 | K20: 994.29 | L20: 994.29 | M20: 994.29 | N20: 994.29 | O20: 994.29 | P20: 994.29 | Q20: 994.29 | R20: 994.29 | S20: 994.29 | T20: 994.29 | U20: 994.29 | V20: 994.29 | W20: 994.29 | X20: 994.29 | Y20: 994.29 | Z20: 994.29 | AA20: 994.29 | AB20: =(SUM(D20:AA20)) -> 23862.96 | AC20: 4
C21: Festivo | D21: 994.29 | E21: 994.29 | F21: 994.29 | G21: 994.29 | H21: 994.29 | I21: 994.29 | J21: 994.29 | K21: 994.29 | L21: 994.29 | M21: 994.29 | N21: 994.29 | O21: 994.29 | P21: 994.29 | Q21: 994.29 | R21: 994.29 | S21: 994.29 | T21: 994.29 | U21: 994.29 | V21: 994.29 | W21: 994.29 | X21: 994.29 | Y21: 994.29 | Z21: 994.29 | AA21: 994.29 | AB21: =(SUM(D21:AA21)) -> 23862.96 | AC21: 0
B22: 46508 | C22: Hábil | D22: 994.29 | E22: 994.29 | F22: 994.29 | G22: 994.29 | H22: 994.29 | I22: 994.29 | J22: 994.29 | K22: 994.29 | L22: 994.29 | M22: 994.29 | N22: 994.29 | O22: 994.29 | P22: 994.29 | Q22: 994.29 | R22: 994.29 | S22: 994.29 | T22: 994.29 | U22: 994.29 | V22: 994.29 | W22: 994.29 | X22: 994.29 | Y22: 994.29 | Z22: 994.29 | AA22: 994.29 | AB22: =(SUM(D22:AA22)) -> 23862.96 | AC22: 19 | AD22: =(AB22*AC22)+(AB23*AC23)+(AB24*AC24)+(AB25*AC25) -> 739751.76
C23: Sábado | D23: 994.29 | E23: 994.29 | F23: 994.29 | G23: 994.29 | H23: 994.29 | I23: 994.29 | J23: 994.29 | K23: 994.29 | L23: 994.29 | M23: 994.29 | N23: 994.29 | O23: 994.29 | P23: 994.29 | Q23: 994.29 | R23: 994.29 | S23: 994.29 | T23: 994.29 | U23: 994.29 | V23: 994.29 | W23: 994.29 | X23: 994.29 | Y23: 994.29 | Z23: 994.29 | AA23: 994.29 | AB23: =(SUM(D23:AA23)) -> 23862.96 | AC23: 4
C24: Domingo | D24: 994.29 | E24: 994.29 | F24: 994.29 | G24: 994.29 | H24: 994.29 | I24: 994.29 | J24: 994.29 | K24: 994.29 | L24: 994.29 | M24: 994.29 | N24: 994.29 | O24: 994.29 | P24: 994.29 | Q24: 994.29 | R24: 994.29 | S24: 994.29 | T24: 994.29 | U24: 994.29 | V24: 994.29 | W24: 994.29 | X24: 994.29 | Y24: 994.29 | Z24: 994.29 | AA24: 994.29 | AB24: =(SUM(D24:AA24)) -> 23862.96 | AC24: 5
C25: Festivo | D25: 994.29 | E25: 994.29 | F25: 994.29 | G25: 994.29 | H25: 994.29 | I25: 994.29 | J25: 994.29 | K25: 994.29 | L25: 994.29 | M25: 994.29 | N25: 994.29 | O25: 994.29 | P25: 994.29 | Q25: 994.29 | R25: 994.29 | S25: 994.29 | T25: 994.29 | U25: 994.29 | V25: 994.29 | W25: 994.29 | X25: 994.29 | Y25: 994.29 | Z25: 994.29 | AA25: 994.29 | AB25: =(SUM(D25:AA25)) -> 23862.96 | AC25: 3
B26: 46539 | C26: Hábil | D26: 994.29 | E26: 994.29 | F26: 994.29 | G26: 994.29 | H26: 994.29 | I26: 994.29 | J26: 994.29 | K26: 994.29 | L26: 994.29 | M26: 994.29 | N26: 994.29 | O26: 994.29 | P26: 994.29 | Q26: 994.29 | R26: 994.29 | S26: 994.29 | T26: 994.29 | U26: 994.29 | V26: 994.29 | W26: 994.29 | X26: 994.29 | Y26: 994.29 | Z26: 994.29 | AA26: 994.29 | AB26: =(SUM(D26:AA26)) -> 23862.96 | AC26: 21 | AD26: =(AB26*AC26)+(AB27*AC27)+(AB28*AC28)+(AB29*AC29) -> 715888.8
C27: Sábado | D27: 994.29 | E27: 994.29 | F27: 994.29 | G27: 994.29 | H27: 994.29 | I27: 994.29 | J27: 994.29 | K27: 994.29 | L27: 994.29 | M27: 994.29 | N27: 994.29 | O27: 994.29 | P27: 994.29 | Q27: 994.29 | R27: 994.29 | S27: 994.29 | T27: 994.29 | U27: 994.29 | V27: 994.29 | W27: 994.29 | X27: 994.29 | Y27: 994.29 | Z27: 994.29 | AA27: 994.29 | AB27: =(SUM(D27:AA27)) -> 23862.96 | AC27: 4
C28: Domingo | D28: 994.29 | E28: 994.29 | F28: 994.29 | G28: 994.29 | H28: 994.29 | I28: 994.29 | J28: 994.29 | K28: 994.29 | L28: 994.29 | M28: 994.29 | N28: 994.29 | O28: 994.29 | P28: 994.29 | Q28: 994.29 | R28: 994.29 | S28: 994.29 | T28: 994.29 | U28: 994.29 | V28: 994.29 | W28: 994.29 | X28: 994.29 | Y28: 994.29 | Z28: 994.29 | AA28: 994.29 | AB28: =(SUM(D28:AA28)) -> 23862.96 | AC28: 4
C29: Festivo | D29: 994.29 | E29: 994.29 | F29: 994.29 | G29: 994.29 | H29: 994.29 | I29: 994.29 | J29: 994.29 | K29: 994.29 | L29: 994.29 | M29: 994.29 | N29: 994.29 | O29: 994.29 | P29: 994.29 | Q29: 994.29 | R29: 994.29 | S29: 994.29 | T29: 994.29 | U29: 994.29 | V29: 994.29 | W29: 994.29 | X29: 994.29 | Y29: 994.29 | Z29: 994.29 | AA29: 994.29 | AB29: =(SUM(D29:AA29)) -> 23862.96 | AC29: 1
B30: 46569 | C30: Hábil | D30: 994.29 | E30: 994.29 | F30: 994.29 | G30: 994.29 | H30: 994.29 | I30: 994.29 | J30: 994.29 | K30: 994.29 | L30: 994.29 | M30: 994.29 | N30: 994.29 | O30: 994.29 | P30: 994.29 | Q30: 994.29 | R30: 994.29 | S30: 994.29 | T30: 994.29 | U30: 994.29 | V30: 994.29 | W30: 994.29 | X30: 994.29 | Y30: 994.29 | Z30: 994.29 | AA30: 994.29 | AB30: =(SUM(D30:AA30)) -> 23862.96 | AC30: 20 | AD30: =(AB30*AC30)+(AB31*AC31)+(AB32*AC32)+(AB33*AC33) -> 739751.76
C31: Sábado | D31: 994.29 | E31: 994.29 | F31: 994.29 | G31: 994.29 | H31: 994.29 | I31: 994.29 | J31: 994.29 | K31: 994.29 | L31: 994.29 | M31: 994.29 | N31: 994.29 | O31: 994.29 | P31: 994.29 | Q31: 994.29 | R31: 994.29 | S31: 994.29 | T31: 994.29 | U31: 994.29 | V31: 994.29 | W31: 994.29 | X31: 994.29 | Y31: 994.29 | Z31: 994.29 | AA31: 994.29 | AB31: =(SUM(D31:AA31)) -> 23862.96 | AC31: 5
C32: domingo | D32: 994.29 | E32: 994.29 | F32: 994.29 | G32: 994.29 | H32: 994.29 | I32: 994.29 | J32: 994.29 | K32: 994.29 | L32: 994.29 | M32: 994.29 | N32: 994.29 | O32: 994.29 | P32: 994.29 | Q32: 994.29 | R32: 994.29 | S32: 994.29 | T32: 994.29 | U32: 994.29 | V32: 994.29 | W32: 994.29 | X32: 994.29 | Y32: 994.29 | Z32: 994.29 | AA32: 994.29 | AB32: =(SUM(D32:AA32)) -> 23862.96 | AC32: 4
C33: Festivo | D33: 994.29 | E33: 994.29 | F33: 994.29 | G33: 994.29 | H33: 994.29 | I33: 994.29 | J33: 994.29 | K33: 994.29 | L33: 994.29 | M33: 994.29 | N33: 994.29 | O33: 994.29 | P33: 994.29 | Q33: 994.29 | R33: 994.29 | S33: 994.29 | T33: 994.29 | U33: 994.29 | V33: 994.29 | W33: 994.29 | X33: 994.29 | Y33: 994.29 | Z33: 994.29 | AA33: 994.29 | AB33: =(SUM(D33:AA33)) -> 23862.96 | AC33: 2
B34: 46600 | C34: Hábil | D34: 994.29 | E34: 994.29 | F34: 994.29 | G34: 994.29 | H34: 994.29 | I34: 994.29 | J34: 994.29 | K34: 994.29 | L34: 994.29 | M34: 994.29 | N34: 994.29 | O34: 994.29 | P34: 994.29 | Q34: 994.29 | R34: 994.29 | S34: 994.29 | T34: 994.29 | U34: 994.29 | V34: 994.29 | W34: 994.29 | X34: 994.29 | Y34: 994.29 | Z34: 994.29 | AA34: 994.29 | AB34: =(SUM(D34:AA34)) -> 23862.96 | AC34: 21 | AD34: =(AB34*AC34)+(AB35*AC35)+(AB36*AC36)+(AB37*AC37) -> 739751.76
C35: Sábado | D35: 994.29 | E35: 994.29 | F35: 994.29 | G35: 994.29 | H35: 994.29 | I35: 994.29 | J35: 994.29 | K35: 994.29 | L35: 994.29 | M35: 994.29 | N35: 994.29 | O35: 994.29 | P35: 994.29 | Q35: 994.29 | R35: 994.29 | S35: 994.29 | T35: 994.29 | U35: 994.29 | V35: 994.29 | W35: 994.29 | X35: 994.29 | Y35: 994.29 | Z35: 994.29 | AA35: 994.29 | AB35: =(SUM(D35:AA35)) -> 23862.96 | AC35: 3
C36: Domingo | D36: 994.29 | E36: 994.29 | F36: 994.29 | G36: 994.29 | H36: 994.29 | I36: 994.29 | J36: 994.29 | K36: 994.29 | L36: 994.29 | M36: 994.29 | N36: 994.29 | O36: 994.29 | P36: 994.29 | Q36: 994.29 | R36: 994.29 | S36: 994.29 | T36: 994.29 | U36: 994.29 | V36: 994.29 | W36: 994.29 | X36: 994.29 | Y36: 994.29 | Z36: 994.29 | AA36: 994.29 | AB36: =(SUM(D36:AA36)) -> 23862.96 | AC36: 5
C37: Festivo | D37: 994.29 | E37: 994.29 | F37: 994.29 | G37: 994.29 | H37: 994.29 | I37: 994.29 | J37: 994.29 | K37: 994.29 | L37: 994.29 | M37: 994.29 | N37: 994.29 | O37: 994.29 | P37: 994.29 | Q37: 994.29 | R37: 994.29 | S37: 994.29 | T37: 994.29 | U37: 994.29 | V37: 994.29 | W37: 994.29 | X37: 994.29 | Y37: 994.29 | Z37: 994.29 | AA37: 994.29 | AB37: =(SUM(D37:AA37)) -> 23862.96 | AC37: 2
B38: 46631 | C38: Hábil | D38: 994.29 | E38: 994.29 | F38: 994.29 | G38: 994.29 | H38: 994.29 | I38: 994.29 | J38: 994.29 | K38: 994.29 | L38: 994.29 | M38: 994.29 | N38: 994.29 | O38: 994.29 | P38: 994.29 | Q38: 994.29 | R38: 994.29 | S38: 994.29 | T38: 994.29 | U38: 994.29 | V38: 994.29 | W38: 994.29 | X38: 994.29 | Y38: 994.29 | Z38: 994.29 | AA38: 994.29 | AB38: =(SUM(D38:AA38)) -> 23862.96 | AC38: 22 | AD38: =(AB38*AC38)+(AB39*AC39)+(AB40*AC40)+(AB41*AC41) -> 715888.8
C39: Sábado | D39: 994.29 | E39: 994.29 | F39: 994.29 | G39: 994.29 | H39: 994.29 | I39: 994.29 | J39: 994.29 | K39: 994.29 | L39: 994.29 | M39: 994.29 | N39: 994.29 | O39: 994.29 | P39: 994.29 | Q39: 994.29 | R39: 994.29 | S39: 994.29 | T39: 994.29 | U39: 994.29 | V39: 994.29 | W39: 994.29 | X39: 994.29 | Y39: 994.29 | Z39: 994.29 | AA39: 994.29 | AB39: =(SUM(D39:AA39)) -> 23862.96 | AC39: 4
C40: Domingo | D40: 994.29 | E40: 994.29 | F40: 994.29 | G40: 994.29 | H40: 994.29 | I40: 994.29 | J40: 994.29 | K40: 994.29 | L40: 994.29 | M40: 994.29 | N40: 994.29 | O40: 994.29 | P40: 994.29 | Q40: 994.29 | R40: 994.29 | S40: 994.29 | T40: 994.29 | U40: 994.29 | V40: 994.29 | W40: 994.29 | X40: 994.29 | Y40: 994.29 | Z40: 994.29 | AA40: 994.29 | AB40: =(SUM(D40:AA40)) -> 23862.96 | AC40: 4
C41: Festivo | D41: 994.29 | E41: 994.29 | F41: 994.29 | G41: 994.29 | H41: 994.29 | I41: 994.29 | J41: 994.29 | K41: 994.29 | L41: 994.29 | M41: 994.29 | N41: 994.29 | O41: 994.29 | P41: 994.29 | Q41: 994.29 | R41: 994.29 | S41: 994.29 | T41: 994.29 | U41: 994.29 | V41: 994.29 | W41: 994.29 | X41: 994.29 | Y41: 994.29 | Z41: 994.29 | AA41: 994.29 | AB41: =(SUM(D41:AA41)) -> 23862.96 | AC41: 0
...

Sheet Anexo 2 Producto 2
B4: ANEXO 2 - OFERTA PRODUCTO 2
B5: NOMBRE DEL OFERENTE
B6: PRECIOS Y CANTIDADES DE ENERGIA OFERTADA
B7: EN PESOS DE ENERO 2025
B8: PRODUCTO 2
B9: AÑO | C9: MES | D9: PERIODO 2027
D10: E. Solicitada [kWh] | E10: % E. Ofertado | F10: E. Ofertada [kWh] | G10: $/kWh
B11: 2027 | C11: Enero | D11: =+'Producto 2 Plano 27'!AE6 -> 739751.76 | F11: =+E11*D11 -> 0
B12: 2027 | C12: Febrero | D12: =+'Producto 2 Plano 27'!AE7 -> 668162.88 | F12: =+E12*D12 -> 0
B13: 2027 | C13: Marzo | D13: =+'Producto 2 Plano 27'!AE8 -> 739751.76 | F13: =+E13*D13 -> 0
B14: 2027 | C14: Abril | D14: =+'Producto 2 Plano 27'!AE9 -> 715888.8 | F14: =+E14*D14 -> 0
B15: 2027 | C15: Mayo | D15: =+'Producto 2 Plano 27'!AE10 -> 739751.76 | F15: =+E15*D15 -> 0
B16: 2027 | C16: Junio | D16: =+'Producto 2 Plano 27'!AE11 -> 715888.8 | F16: =+E16*D16 -> 0
B17: 2027 | C17: Julio | D17: =+'Producto 2 Plano 27'!AE12 -> 739751.76 | F17: =+E17*D17 -> 0
B18: 2027 | C18: Agosto | D18: =+'Producto 2 Plano 27'!AE13 -> 739751.76 | F18: =+E18*D18 -> 0
B19: 2027 | C19: Septiembre | D19: =+'Producto 2 Plano 27'!AE14 -> 715888.8 | F19: =+E19*D19 -> 0
B20: 2027 | C20: Octubre | D20: =+'Producto 2 Plano 27'!AE15 -> 739751.76 | F20: =+E20*D20 -> 0
B21: 2027 | C21: Noviembre | D21: =+'Producto 2 Plano 27'!AE16 -> 715888.8 | F21: =+E21*D21 -> 0
B22: 2027 | C22: Diciembre | D22: =+'Producto 2 Plano 27'!AE17 -> 739751.76 | F22: =+E22*D22 -> 0 | H22: =SUM(D11:D22) -> 8709980.4 | I22: =+H22/1000 -> 8709.9804
B23: Total Producto 2 | D23: =+SUM(D11:D22) -> 8709980.4 | I23: =+D23/1000 -> 8709.9804
B25: E. Solicitada = Energía solicitada por RUITOQUE para el producto.
B26: % E. Ofertado = Porcentaje de energía ofertado por el agente respecto a la E. Solicitada.
B27: E. Ofertada = Energía ofertada por el agente, producto de la E. Solicitada y el % E. Ofertado.
B28: $/kWh = Tarifa de la oferta para todas las horas del mes.

Sheet Producto 3 Plano 28
B2: ANEXO 1 - CANTIDADES DE ENERGÍA SOLICITADA EN kWh
B3: PRODUCTO 3
B4: PERIODO 01 DE ENERO DEL 2028 A DICIEMBRE 31 DE 2028
C5: DIA | D5: 1 | E5: 2 | F5: 3 | G5: 4 | H5: 5 | I5: 6 | J5: 7 | K5: 8 | L5: 9 | M5: 10 | N5: 11 | O5: 12 | P5: 13 | Q5: 14 | R5: 15 | S5: 16 | T5: 17 | U5: 18 | V5: 19 | W5: 20 | X5: 21 | Y5: 22 | Z5: 23 | AA5: 24 | AB5: Total | AC5: No. DÍAS | AD5: Total
B6: 46753 | C6: Hábil | D6: 5227.17 | E6: 5227.17 | F6: 5227.17 | G6: 5227.17 | H6: 5227.17 | I6: 5227.17 | J6: 5227.17 | K6: 5227.17 | L6: 5227.17 | M6: 5227.17 | N6: 5227.17 | O6: 5227.17 | P6: 5227.17 | Q6: 5227.17 | R6: 5227.17 | S6: 5227.17 | T6: 5227.17 | U6: 5227.17 | V6: 5227.17 | W6: 5227.17 | X6: 5227.17 | Y6: 5227.17 | Z6: 5227.17 | AA6: 5227.17 | AB6: =(SUM(D6:AA6)) -> 125452.08 | AC6: 20 | AD6: =(AB6*AC6)+(AB7*AC7)+(AB8*AC8)+(AB9*AC9) -> 3889014.5 | AE6: =+AD6 -> 3889014.5
C7: Sábado | D7: 5227.17 | E7: 5227.17 | F7: 5227.17 | G7: 5227.17 | H7: 5227.17 | I7: 5227.17 | J7: 5227.17 | K7: 5227.17 | L7: 5227.17 | M7: 5227.17 | N7: 5227.17 | O7: 5227.17 | P7: 5227.17 | Q7: 5227.17 | R7: 5227.17 | S7: 5227.17 | T7: 5227.17 | U7: 5227.17 | V7: 5227.17 | W7: 5227.17 | X7: 5227.17 | Y7: 5227.17 | Z7: 5227.17 | AA7: 5227.17 | AB7: =(SUM(D7:AA7)) -> 125452.08 | AC7: 4 | AE7: =+AD10 -> 3638110.3
C8: Domingo | D8: 5227.17 | E8: 5227.17 | F8: 5227.17 | G8: 5227.17 | H8: 5227.17 | I8: 5227.17 | J8: 5227.17 | K8: 5227.17 | L8: 5227.17 | M8: 5227.17 | N8: 5227.17 | O8: 5227.17 | P8: 5227.17 | Q8: 5227.17 | R8: 5227.17 | S8: 5227.17 | T8: 5227.17 | U8: 5227.17 | V8: 5227.17 | W8: 5227.17 | X8: 5227.17 | Y8: 5227.17 | Z8: 5227.17 | AA8: 5227.17 | AB8: =(SUM(D8:AA8)) -> 125452.08 | AC8: 5 | AE8: =+AD14 -> 3889014.5
C9: Festivo | D9: 5227.17 | E9: 5227.17 | F9: 5227.17 | G9: 5227.17 | H9: 5227.17 | I9: 5227.17 | J9: 5227.17 | K9: 5227.17 | L9: 5227.17 | M9: 5227.17 | N9: 5227.17 | O9: 5227.17 | P9: 5227.17 | Q9: 5227.17 | R9: 5227.17 | S9: 5227.17 | T9: 5227.17 | U9: 5227.17 | V9: 5227.17 | W9: 5227.17 | X9: 5227.17 | Y9: 5227.17 | Z9: 5227.17 | AA9: 5227.17 | AB9: =(SUM(D9:AA9)) -> 125452.08 | AC9: 2 | AE9: =+AD18 -> 3763562.4
B10: 46784 | C10: Hábil | D10: 5227.17 | E10: 5227.17 | F10: 5227.17 | G10: 5227.17 | H10: 5227.17 | I10: 5227.17 | J10: 5227.17 | K10: 5227.17 | L10: 5227.17 | M10: 5227.17 | N10: 5227.17 | O10: 5227.17 | P10: 5227.17 | Q10: 5227.17 | R10: 5227.17 | S10: 5227.17 | T10: 5227.17 | U10: 5227.17 | V10: 5227.17 | W10: 5227.17 | X10: 5227.17 | Y10: 5227.17 | Z10: 5227.17 | AA10: 5227.17 | AB10: =(SUM(D10:AA10)) -> 125452.08 | AC10: 21 | AD10: =(AB10*AC10)+(AB11*AC11)+(AB12*AC12)+(AB13*AC13) -> 3638110.3 | AE10: =+AD22 -> 3889014.5
C11: Sábado | D11: 5227.17 | E11: 5227.17 | F11: 5227.17 | G11: 5227.17 | H11: 5227.17 | I11: 5227.17 | J11: 5227.17 | K11: 5227.17 | L11: 5227.17 | M11: 5227.17 | N11: 5227.17 | O11: 5227.17 | P11: 5227.17 | Q11: 5227.17 | R11: 5227.17 | S11: 5227.17 | T11: 5227.17 | U11: 5227.17 | V11: 5227.17 | W11: 5227.17 | X11: 5227.17 | Y11: 5227.17 | Z11: 5227.17 | AA11: 5227.17 | AB11: =(SUM(D11:AA11)) -> 125452.08 | AC11: 4 | AE11: =+AD26 -> 3763562.4
C12: Domingo | D12: 5227.17 | E12: 5227.17 | F12: 5227.17 | G12: 5227.17 | H12: 5227.17 | I12: 5227.17 | J12: 5227.17 | K12: 5227.17 | L12: 5227.17 | M12: 5227.17 | N12: 5227.17 | O12: 5227.17 | P12: 5227.17 | Q12: 5227.17 | R12: 5227.17 | S12: 5227.17 | T12: 5227.17 | U12: 5227.17 | V12: 5227.17 | W12: 5227.17 | X12: 5227.17 | Y12: 5227.17 | Z12: 5227.17 | AA12: 5227.17 | AB12: =(SUM(D12:AA12)) -> 125452.08 | AC12: 4 | AE12: =+AD30 -> 3889014.5
C13: Festivo | D13: 5227.17 | E13: 5227.17 | F13: 5227.17 | G13: 5227.17 | H13: 5227.17 | I13: 5227.17 | J13: 5227.17 | K13: 5227.17 | L13: 5227.17 | M13: 5227.17 | N13: 5227.17 | O13: 5227.17 | P13: 5227.17 | Q13: 5227.17 | R13: 5227.17 | S13: 5227.17 | T13: 5227.17 | U13: 5227.17 | V13: 5227.17 | W13: 5227.17 | X13: 5227.17 | Y13: 5227.17 | Z13: 5227.17 | AA13: 5227.17 | AB13: =(SUM(D13:AA13)) -> 125452.08 | AC13: 0 | AE13: =+AD34 -> 3889014.5
B14: 46813 | C14: Hábil | D14: 5227.17 | E14: 5227.17 | F14: 5227.17 | G14: 5227.17 | H14: 5227.17 | I14: 5227.17 | J14: 5227.17 | K14: 5227.17 | L14: 5227.17 | M14: 5227.17 | N14: 5227.17 | O14: 5227.17 | P14: 5227.17 | Q14: 5227.17 | R14: 5227.17 | S14: 5227.17 | T14: 5227.17 | U14: 5227.17 | V14: 5227.17 | W14: 5227.17 | X14: 5227.17 | Y14: 5227.17 | Z14: 5227.17 | AA14: 5227.17 | AB14: =(SUM(D14:AA14)) -> 125452.08 | AC14: 22 | AD14: =(AB14*AC14)+(AB15*AC15)+(AB16*AC16)+(AB17*AC17) -> 3889014.5 | AE14: =+AD38 -> 3763562.4
C15: Sábado | D15: 5227.17 | E15: 5227.17 | F15: 5227.17 | G15: 5227.17 | H15: 5227.17 | I15: 5227.17 | J15: 5227.17 | K15: 5227.17 | L15: 5227.17 | M15: 5227.17 | N15: 5227.17 | O15: 5227.17 | P15: 5227.17 | Q15: 5227.17 | R15: 5227.17 | S15: 5227.17 | T15: 5227.17 | U15: 5227.17 | V15: 5227.17 | W15: 5227.17 | X15: 5227.17 | Y15: 5227.17 | Z15: 5227.17 | AA15: 5227.17 | AB15: =(SUM(D15:AA15)) -> 125452.08 | AC15: 4 | AE15: =+AD42 -> 3889014.5
C16: Domingo | D16: 5227.17 | E16: 5227.17 | F16: 5227.17 | G16: 5227.17 | H16: 5227.17 | I16: 5227.17 | J16: 5227.17 | K16: 5227.17 | L16: 5227.17 | M16: 5227.17 | N16: 5227.17 | O16: 5227.17 | P16: 5227.17 | Q16: 5227.17 | R16: 5227.17 | S16: 5227.17 | T16: 5227.17 | U16: 5227.17 | V16: 5227.17 | W16: 5227.17 | X16: 5227.17 | Y16: 5227.17 | Z16: 5227.17 | AA16: 5227.17 | AB16: =(SUM(D16:AA16)) -> 125452.08 | AC16: 4 | AE16: =+AD46 -> 3763562.4
C17: Festivo | D17: 5227.17 | E17: 5227.17 | F17: 5227.17 | G17: 5227.17 | H17: 5227.17 | I17: 5227.17 | J17: 5227.17 | K17: 5227.17 | L17: 5227.17 | M17: 5227.17 | N17: 5227.17 | O17: 5227.17 | P17: 5227.17 | Q17: 5227.17 | R17: 5227.17 | S17: 5227.17 | T17: 5227.17 | U17: 5227.17 | V17: 5227.17 | W17: 5227.17 | X17: 5227.17 | Y17: 5227.17 | Z17: 5227.17 | AA17: 5227.17 | AB17: =(SUM(D17:AA17)) -> 125452.08 | AC17: 1 | AE17: =+AD50 -> 3889014.5
B18: 46844 | C18: Hábil | D18: 5227.17 | E18: 5227.17 | F18: 5227.17 | G18: 5227.17 | H18: 5227.17 | I18: 5227.17 | J18: 5227.17 | K18: 5227.17 | L18: 5227.17 | M18: 5227.17 | N18: 5227.17 | O18: 5227.17 | P18: 5227.17 | Q18: 5227.17 | R18: 5227.17 | S18: 5227.17 | T18: 5227.17 | U18: 5227.17 | V18: 5227.17 | W18: 5227.17 | X18: 5227.17 | Y18: 5227.17 | Z18: 5227.17 | AA18: 5227.17 | AB18: =(SUM(D18:AA18)) -> 125452.08 | AC18: 18 | AD18: =(AB18*AC18)+(AB19*AC19)+(AB20*AC20)+(AB21*AC21) -> 3763562.4
C19: Sábado | D19: 5227.17 | E19: 5227.17 | F19: 5227.17 | G19: 5227.17 | H19: 5227.17 | I19: 5227.17 | J19: 5227.17 | K19: 5227.17 | L19: 5227.17 | M19: 5227.17 | N19: 5227.17 | O19: 5227.17 | P19: 5227.17 | Q19: 5227.17 | R19: 5227.17 | S19: 5227.17 | T19: 5227.17 | U19: 5227.17 | V19: 5227.17 | W19: 5227.17 | X19: 5227.17 | Y19: 5227.17 | Z19: 5227.17 | AA19: 5227.17 | AB19: =(SUM(D19:AA19)) -> 125452.08 | AC19: 5
C20: Domingo | D20: 5227.17 | E20: 5227.17 | F20: 5227.17 | G20: 5227.17 | H20: 5227.17 | I20: 5227.17 | J20: 5227.17 | K20: 5227.17 | L20: 5227.17 | M20: 5227.17 | N20: 5227.17 | O20: 5227.17 | P20: 5227.17 | Q20: 5227.17 | R20: 5227.17 | S20: 5227.17 | T20: 5227.17 | U20: 5227.17 | V20: 5227.17 | W20: 5227.17 | X20: 5227.17 | Y20: 5227.17 | Z20: 5227.17 | AA20: 5227.17 | AB20: =(SUM(D20:AA20)) -> 125452.08 | AC20: 5
C21: Festivo | D21: 5227.17 | E21: 5227.17 | F21: 5227.17 | G21: 5227.17 | H21: 5227.17 | I21: 5227.17 | J21: 5227.17 | K21: 5227.17 | L21: 5227.17 | M21: 5227.17 | N21: 5227.17 | O21: 5227.17 | P21: 5227.17 | Q21: 5227.17 | R21: 5227.17 | S21: 5227.17 | T21: 5227.17 | U21: 5227.17 | V21: 5227.17 | W21: 5227.17 | X21: 5227.17 | Y21: 5227.17 | Z21: 5227.17 | AA21: 5227.17 | AB21: =(SUM(D21:AA21)) -> 125452.08 | AC21: 2
B22: 46874 | C22: Hábil | D22: 5227.17 | E22: 5227.17 | F22: 5227.17 | G22: 5227.17 | H22: 5227.17 | I22: 5227.17 | J22: 5227.17 | K22: 5227.17 | L22: 5227.17 | M22: 5227.17 | N22: 5227.17 | O22: 5227.17 | P22: 5227.17 | Q22: 5227.17 | R22: 5227.17 | S22: 5227.17 | T22: 5227.17 | U22: 5227.17 | V22: 5227.17 | W22: 5227.17 | X22: 5227.17 | Y22: 5227.17 | Z22: 5227.17 | AA22: 5227.17 | AB22: =(SUM(D22:AA22)) -> 125452.08 | AC22: 21 | AD22: =(AB22*AC22)+(AB23*AC23)+(AB24*AC24)+(AB25*AC25) -> 3889014.5
C23: Sábado | D23: 5227.17 | E23: 5227.17 | F23: 5227.17 | G23: 5227.17 | H23: 5227.17 | I23: 5227.17 | J23: 5227.17 | K23: 5227.17 | L23: 5227.17 | M23: 5227.17 | N23: 5227.17 | O23: 5227.17 | P23: 5227.17 | Q23: 5227.17 | R23: 5227.17 | S23: 5227.17 | T23: 5227.17 | U23: 5227.17 | V23: 5227.17 | W23: 5227.17 | X23: 5227.17 | Y23: 5227.17 | Z23: 5227.17 | AA23: 5227.17 | AB23: =(SUM(D23:AA23)) -> 125452.08 | AC23: 4
C24: Domingo | D24: 5227.17 | E24: 5227.17 | F24: 5227.17 | G24: 5227.17 | H24: 5227.17 | I24: 5227.17 | J24: 5227.17 | K24: 5227.17 | L24: 5227.17 | M24: 5227.17 | N24: 5227.17 | O24: 5227.17 | P24: 5227.17 | Q24: 5227.17 | R24: 5227.17 | S24: 5227.17 | T24: 5227.17 | U24: 5227.17 | V24: 5227.17 | W24: 5227.17 | X24: 5227.17 | Y24: 5227.17 | Z24: 5227.17 | AA24: 5227.17 | AB24: =(SUM(D24:AA24)) -> 125452.08 | AC24: 4
C25: Festivo | D25: 5227.17 | E25: 5227.17 | F25: 5227.17 | G25: 5227.17 | H25: 5227.17 | I25: 5227.17 | J25: 5227.17 | K25: 5227.17 | L25: 5227.17 | M25: 5227.17 | N25: 5227.17 | O25: 5227.17 | P25: 5227.17 | Q25: 5227.17 | R25: 5227.17 | S25: 5227.17 | T25: 5227.17 | U25: 5227.17 | V25: 5227.17 | W25: 5227.17 | X25: 5227.17 | Y25: 5227.17 | Z25: 5227.17 | AA25: 5227.17 | AB25: =(SUM(D25:AA25)) -> 125452.08 | AC25: 2
B26: 46905 | C26: Hábil | D26: 5227.17 | E26: 5227.17 | F26: 5227.17 | G26: 5227.17 | H26: 5227.17 | I26: 5227.17 | J26: 5227.17 | K26: 5227.17 | L26: 5227.17 | M26: 5227.17 | N26: 5227.17 | O26: 5227.17 | P26: 5227.17 | Q26: 5227.17 | R26: 5227.17 | S26: 5227.17 | T26: 5227.17 | U26: 5227.17 | V26: 5227.17 | W26: 5227.17 | X26: 5227.17 | Y26: 5227.17 | Z26: 5227.17 | AA26: 5227.17 | AB26: =(SUM(D26:AA26)) -> 125452.08 | AC26: 20 | AD26: =(AB26*AC26)+(AB27*AC27)+(AB28*AC28)+(AB29*AC29) -> 3763562.4
C27: Sábado | D27: 5227.17 | E27: 5227.17 | F27: 5227.17 | G27: 5227.17 | H27: 5227.17 | I27: 5227.17 | J27: 5227.17 | K27: 5227.17 | L27: 5227.17 | M27: 5227.17 | N27: 5227.17 | O27: 5227.17 | P27: 5227.17 | Q27: 5227.17 | R27: 5227.17 | S27: 5227.17 | T27: 5227.17 | U27: 5227.17 | V27: 5227.17 | W27: 5227.17 | X27: 5227.17 | Y27: 5227.17 | Z27: 5227.17 | AA27: 5227.17 | AB27: =(SUM(D27:AA27)) -> 125452.08 | AC27: 4
C28: Domingo | D28: 5227.17 | E28: 5227.17 | F28: 5227.17 | G28: 5227.17 | H28: 5227.17 | I28: 5227.17 | J28: 5227.17 | K28: 5227.17 | L28: 5227.17 | M28: 5227.17 | N28: 5227.17 | O28: 5227.17 | P28: 5227.17 | Q28: 5227.17 | R28: 5227.17 | S28: 5227.17 | T28: 5227.17 | U28: 5227.17 | V28: 5227.17 | W28: 5227.17 | X28: 5227.17 | Y28: 5227.17 | Z28: 5227.17 | AA28: 5227.17 | AB28: =(SUM(D28:AA28)) -> 125452.08 | AC28: 4
C29: Festivo | D29: 5227.17 | E29: 5227.17 | F29: 5227.17 | G29: 5227.17 | H29: 5227.17 | I29: 5227.17 | J29: 5227.17 | K29: 5227.17 | L29: 5227.17 | M29: 5227.17 | N29: 5227.17 | O29: 5227.17 | P29: 5227.17 | Q29: 5227.17 | R29: 5227.17 | S29: 5227.17 | T29: 5227.17 | U29: 5227.17 | V29: 5227.17 | W29: 5227.17 | X29: 5227.17 | Y29: 5227.17 | Z29: 5227.17 | AA29: 5227.17 | AB29: =(SUM(D29:AA29)) -> 125452.08 | AC29: 2
B30: 46935 | C30: Hábil | D30: 5227.17 | E30: 5227.17 | F30: 5227.17 | G30: 5227.17 | H30: 5227.17 | I30: 5227.17 | J30: 5227.17 | K30: 5227.17 | L30: 5227.17 | M30: 5227.17 | N30: 5227.17 | O30: 5227.17 | P30: 5227.17 | Q30: 5227.17 | R30: 5227.17 | S30: 5227.17 | T30: 5227.17 | U30: 5227.17 | V30: 5227.17 | W30: 5227.17 | X30: 5227.17 | Y30: 5227.17 | Z30: 5227.17 | AA30: 5227.17 | AB30: =(SUM(D30:AA30)) -> 125452.08 | AC30: 19 | AD30: =(AB30*AC30)+(AB31*AC31)+(AB32*AC32)+(AB33*AC33) -> 3889014.5
C31: Sábado | D31: 5227.17 | E31: 5227.17 | F31: 5227.17 | G31: 5227.17 | H31: 5227.17 | I31: 5227.17 | J31: 5227.17 | K31: 5227.17 | L31: 5227.17 | M31: 5227.17 | N31: 5227.17 | O31: 5227.17 | P31: 5227.17 | Q31: 5227.17 | R31: 5227.17 | S31: 5227.17 | T31: 5227.17 | U31: 5227.17 | V31: 5227.17 | W31: 5227.17 | X31: 5227.17 | Y31: 5227.17 | Z31: 5227.17 | AA31: 5227.17 | AB31: =(SUM(D31:AA31)) -> 125452.08 | AC31: 5
C32: domingo | D32: 5227.17 | E32: 5227.17 | F32: 5227.17 | G32: 5227.17 | H32: 5227.17 | I32: 5227.17 | J32: 5227.17 | K32: 5227.17 | L32: 5227.17 | M32: 5227.17 | N32: 5227.17 | O32: 5227.17 | P32: 5227.17 | Q32: 5227.17 | R32: 5227.17 | S32: 5227.17 | T32: 5227.17 | U32: 5227.17 | V32: 5227.17 | W32: 5227.17 | X32: 5227.17 | Y32: 5227.17 | Z32: 5227.17 | AA32: 5227.17 | AB32: =(SUM(D32:AA32)) -> 125452.08 | AC32: 5
C33: Festivo | D33: 5227.17 | E33: 5227.17 | F33: 5227.17 | G33: 5227.17 | H33: 5227.17 | I33: 5227.17 | J33: 5227.17 | K33: 5227.17 | L33: 5227.17 | M33: 5227.17 | N33: 5227.17 | O33: 5227.17 | P33: 5227.17 | Q33: 5227.17 | R33: 5227.17 | S33: 5227.17 | T33: 5227.17 | U33: 5227.17 | V33: 5227.17 | W33: 5227.17 | X33: 5227.17 | Y33: 5227.17 | Z33: 5227.17 | AA33: 5227.17 | AB33: =(SUM(D33:AA33)) -> 125452.08 | AC33: 2
B34: 46966 | C34: Hábil | D34: 5227.17 | E34: 5227.17 | F34: 5227.17 | G34: 5227.17 | H34: 5227.17 | I34: 5227.17 | J34: 5227.17 | K34: 5227.17 | L34: 5227.17 | M34: 5227.17 | N34: 5227.17 | O34: 5227.17 | P34: 5227.17 | Q34: 5227.17 | R34: 5227.17 | S34: 5227.17 | T34: 5227.17 | U34: 5227.17 | V34: 5227.17 | W34: 5227.17 | X34: 5227.17 | Y34: 5227.17 | Z34: 5227.17 | AA34: 5227.17 | AB34: =(SUM(D34:AA34)) -> 125452.08 | AC34: 21 | AD34: =(AB34*AC34)+(AB35*AC35)+(AB36*AC36)+(AB37*AC37) -> 3889014.5
C35: Sábado | D35: 5227.17 | E35: 5227.17 | F35: 5227.17 | G35: 5227.17 | H35: 5227.17 | I35: 5227.17 | J35: 5227.17 | K35: 5227.17 | L35: 5227.17 | M35: 5227.17 | N35: 5227.17 | O35: 5227.17 | P35: 5227.17 | Q35: 5227.17 | R35: 5227.17 | S35: 5227.17 | T35: 5227.17 | U35: 5227.17 | V35: 5227.17 | W35: 5227.17 | X35: 5227.17 | Y35: 5227.17 | Z35: 5227.17 | AA35: 5227.17 | AB35: =(SUM(D35:AA35)) -> 125452.08 | AC35: 4
C36: Domingo | D36: 5227.17 | E36: 5227.17 | F36: 5227.17 | G36: 5227.17 | H36: 5227.17 | I36: 5227.17 | J36: 5227.17 | K36: 5227.17 | L36: 5227.17 | M36: 5227.17 | N36: 5227.17 | O36: 5227.17 | P36: 5227.17 | Q36: 5227.17 | R36: 5227.17 | S36: 5227.17 | T36: 5227.17 | U36: 5227.17 | V36: 5227.17 | W36: 5227.17 | X36: 5227.17 | Y36: 5227.17 | Z36: 5227.17 | AA36: 5227.17 | AB36: =(SUM(D36:AA36)) -> 125452.08 | AC36: 4
C37: Festivo | D37: 5227.17 | E37: 5227.17 | F37: 5227.17 | G37: 5227.17 | H37: 5227.17 | I37: 5227.17 | J37: 5227.17 | K37: 5227.17 | L37: 5227.17 | M37: 5227.17 | N37: 5227.17 | O37: 5227.17 | P37: 5227.17 | Q37: 5227.17 | R37: 5227.17 | S37: 5227.17 | T37: 5227.17 | U37: 5227.17 | V37: 5227.17 | W37: 5227.17 | X37: 5227.17 | Y37: 5227.17 | Z37: 5227.17 | AA37: 5227.17 | AB37: =(SUM(D37:AA37)) -> 125452.08 | AC37: 2
B38: 46997 | C38: Hábil | D38: 5227.17 | E38: 5227.17 | F38: 5227.17 | G38: 5227.17 | H38: 5227.17 | I38: 5227.17 | J38: 5227.17 | K38: 5227.17 | L38: 5227.17 | M38: 5227.17 | N38: 5227.17 | O38: 5227.17 | P38: 5227.17 | Q38: 5227.17 | R38: 5227.17 | S38: 5227.17 | T38: 5227.17 | U38: 5227.17 | V38: 5227.17 | W38: 5227.17 | X38: 5227.17 | Y38: 5227.17 | Z38: 5227.17 | AA38: 5227.17 | AB38: =(SUM(D38:AA38)) -> 125452.08 | AC38: 21 | AD38: =(AB38*AC38)+(AB39*AC39)+(AB40*AC40)+(AB41*AC41) -> 3763562.4
C39: Sábado | D39: 5227.17 | E39: 5227.17 | F39: 5227.17 | G39: 5227.17 | H39: 5227.17 | I39: 5227.17 | J39: 5227.17 | K39: 5227.17 | L39: 5227.17 | M39: 5227.17 | N39: 5227.17 | O39: 5227.17 | P39: 5227.17 | Q39: 5227.17 | R39: 5227.17 | S39: 5227.17 | T39: 5227.17 | U39: 5227.17 | V39: 5227.17 | W39: 5227.17 | X39: 5227.17 | Y39: 5227.17 | Z39: 5227.17 | AA39: 5227.17 | AB39: =(SUM(D39:AA39)) -> 125452.08 | AC39: 5
C40: Domingo | D40: 5227.17 | E40: 5227.17 | F40: 5227.17 | G40: 5227.17 | H40: 5227.17 | I40: 5227.17 | J40: 5227.17 | K40: 5227.17 | L40: 5227.17 | M40: 5227.17 | N40: 5227.17 | O40: 5227.17 | P40: 5227.17 | Q40: 5227.17 | R40: 5227.17 | S40: 5227.17 | T40: 5227.17 | U40: 5227.17 | V40: 5227.17 | W40: 5227.17 | X40: 5227.17 | Y40: 5227.17 | Z40: 5227.17 | AA40: 5227.17 | AB40: =(SUM(D40:AA40)) -> 125452.08 | AC40: 4
C41: Festivo | D41: 5227.17 | E41: 5227.17 | F41: 5227.17 | G41: 5227.17 | H41: 5227.17 | I41: 5227.17 | J41: 5227.17 | K41: 5227.17 | L41: 5227.17 | M41: 5227.17 | N41: 5227.17 | O41: 5227.17 | P41: 5227.17 | Q41: 5227.17 | R41: 5227.17 | S41: 5227.17 | T41: 5227.17 | U41: 5227.17 | V41: 5227.17 | W41: 5227.17 | X41: 5227.17 | Y41: 5227.17 | Z41: 5227.17 | AA41: 5227.17 | AB41: =(SUM(D41:AA41)) -> 125452.08 | AC41: 0
...

Sheet Anexo 2 Producto 3
B4: ANEXO 2 - OFERTA PRODUCTO 3
B5: NOMBRE DEL OFERENTE
B6: PRECIOS Y CANTIDADES DE ENERGIA OFERTADA
B7: EN PESOS DE ENERO 2025
B8: PRODUCTO 3
B9: AÑO | C9: MES | D9: PERIODO 2028
D10: E. Solicitada [kWh] | E10: % E. Ofertado | F10: E. Ofertada [kWh] | G10: $/kWh
B11: 2028 | C11: Enero | D11: =+'Producto 3 Plano 28'!AE6 -> 3889014.5 | F11: =+E11*D11 -> 0
B12: 2028 | C12: Febrero | D12: =+'Producto 3 Plano 28'!AE7 -> 3638110.3 | F12: =+E12*D12 -> 0
B13: 2028 | C13: Marzo | D13: =+'Producto 3 Plano 28'!AE8 -> 3889014.5 | F13: =+E13*D13 -> 0
B14: 2028 | C14: Abril | D14: =+'Producto 3 Plano 28'!AE9 -> 3763562.4 | F14: =+E14*D14 -> 0
B15: 2028 | C15: Mayo | D15: =+'Producto 3 Plano 28'!AE10 -> 3889014.5 | F15: =+E15*D15 -> 0
B16: 2028 | C16: Junio | D16: =+'Producto 3 Plano 28'!AE11 -> 3763562.4 | F16: =+E16*D16 -> 0
B17: 2028 | C17: Julio | D17: =+'Producto 3 Plano 28'!AE12 -> 3889014.5 | F17: =+E17*D17 -> 0
B18: 2028 | C18: Agosto | D18: =+'Producto 3 Plano 28'!AE13 -> 3889014.5 | F18: =+E18*D18 -> 0
B19: 2028 | C19: Septiembre | D19: =+'Producto 3 Plano 28'!AE14 -> 3763562.4 | F19: =+E19*D19 -> 0
B20: 2028 | C20: Octubre | D20: =+'Producto 3 Plano 28'!AE15 -> 3889014.5 | F20: =+E20*D20 -> 0
B21: 2028 | C21: Noviembre | D21: =+'Producto 3 Plano 28'!AE16 -> 3763562.4 | F21: =+E21*D21 -> 0
B22: 2028 | C22: Diciembre | D22: =+'Producto 3 Plano 28'!AE17 -> 3889014.5 | F22: =+E22*D22 -> 0 | H22: =SUM(D11:D22) -> 45915461 | I22: =+H22/1000 -> 45915.461
B23: Total Producto 3 | D23: =+SUM(D11:D22) -> 45915461 | I23: =+D23/1000 -> 45915.461
B25: E. Solicitada = Energía solicitada por RUITOQUE para el producto.
B26: % E. Ofertado = Porcentaje de energía ofertado por el agente respecto a la E. Solicitada.
B27: E. Ofertada = Energía ofertada por el agente, producto de la E. Solicitada y el % E. Ofertado.
B28: $/kWh = Tarifa de la oferta para todas las horas del mes.

Sheet Producto 4 Plano 29
B2: ANEXO 1 - CANTIDADES DE ENERGÍA SOLICITADA EN kWh
B3: PRODUCTO 4
B4: PERIODO 01 DE ENERO DEL 2029 A DICIEMBRE 31 DE 2029
C5: DIA | D5: 1 | E5: 2 | F5: 3 | G5: 4 | H5: 5 | I5: 6 | J5: 7 | K5: 8 | L5: 9 | M5: 10 | N5: 11 | O5: 12 | P5: 13 | Q5: 14 | R5: 15 | S5: 16 | T5: 17 | U5: 18 | V5: 19 | W5: 20 | X5: 21 | Y5: 22 | Z5: 23 | AA5: 24 | AB5: Total | AC5: No. DÍAS | AD5: Total
B6: 47119 | C6: Hábil | D6: 8940.64 | E6: 8940.64 | F6: 8940.64 | G6: 8940.64 | H6: 8940.64 | I6: 8940.64 | J6: 8940.64 | K6: 8940.64 | L6: 8940.64 | M6: 8940.64 | N6: 8940.64 | O6: 8940.64 | P6: 8940.64 | Q6: 8940.64 | R6: 8940.64 | S6: 8940.64 | T6: 8940.64 | U6: 8940.64 | V6: 8940.64 | W6: 8940.64 | X6: 8940.64 | Y6: 8940.64 | Z6: 8940.64 | AA6: 8940.64 | AB6: =(SUM(D6:AA6)) -> 214575.36 | AC6: 21 | AD6: =(AB6*AC6)+(AB7*AC7)+(AB8*AC8)+(AB9*AC9) -> 6651836.2 | AE6: =+AD6 -> 6651836.2
C7: Sábado | D7: 8940.64 | E7: 8940.64 | F7: 8940.64 | G7: 8940.64 | H7: 8940.64 | I7: 8940.64 | J7: 8940.64 | K7: 8940.64 | L7: 8940.64 | M7: 8940.64 | N7: 8940.64 | O7: 8940.64 | P7: 8940.64 | Q7: 8940.64 | R7: 8940.64 | S7: 8940.64 | T7: 8940.64 | U7: 8940.64 | V7: 8940.64 | W7: 8940.64 | X7: 8940.64 | Y7: 8940.64 | Z7: 8940.64 | AA7: 8940.64 | AB7: =(SUM(D7:AA7)) -> 214575.36 | AC7: 4 | AE7: =+AD10 -> 6008110.1
C8: Domingo | D8: 8940.64 | E8: 8940.64 | F8: 8940.64 | G8: 8940.64 | H8: 8940.64 | I8: 8940.64 | J8: 8940.64 | K8: 8940.64 | L8: 8940.64 | M8: 8940.64 | N8: 8940.64 | O8: 8940.64 | P8: 8940.64 | Q8: 8940.64 | R8: 8940.64 | S8: 8940.64 | T8: 8940.64 | U8: 8940.64 | V8: 8940.64 | W8: 8940.64 | X8: 8940.64 | Y8: 8940.64 | Z8: 8940.64 | AA8: 8940.64 | AB8: =(SUM(D8:AA8)) -> 214575.36 | AC8: 4 | AE8: =+AD14 -> 6651836.2
C9: Festivo | D9: 8940.64 | E9: 8940.64 | F9: 8940.64 | G9: 8940.64 | H9: 8940.64 | I9: 8940.64 | J9: 8940.64 | K9: 8940.64 | L9: 8940.64 | M9: 8940.64 | N9: 8940.64 | O9: 8940.64 | P9: 8940.64 | Q9: 8940.64 | R9: 8940.64 | S9: 8940.64 | T9: 8940.64 | U9: 8940.64 | V9: 8940.64 | W9: 8940.64 | X9: 8940.64 | Y9: 8940.64 | Z9: 8940.64 | AA9: 8940.64 | AB9: =(SUM(D9:AA9)) -> 214575.36 | AC9: 2 | AE9: =+AD18 -> 6437260.8
B10: 47150 | C10: Hábil | D10: 8940.64 | E10: 8940.64 | F10: 8940.64 | G10: 8940.64 | H10: 8940.64 | I10: 8940.64 | J10: 8940.64 | K10: 8940.64 | L10: 8940.64 | M10: 8940.64 | N10: 8940.64 | O10: 8940.64 | P10: 8940.64 | Q10: 8940.64 | R10: 8940.64 | S10: 8940.64 | T10: 8940.64 | U10: 8940.64 | V10: 8940.64 | W10: 8940.64 | X10: 8940.64 | Y10: 8940.64 | Z10: 8940.64 | AA10: 8940.64 | AB10: =(SUM(D10:AA10)) -> 214575.36 | AC10: 20 | AD10: =(AB10*AC10)+(AB11*AC11)+(AB12*AC12)+(AB13*AC13) -> 6008110.1 | AE10: =+AD22 -> 6651836.2
C11: Sábado | D11: 8940.64 | E11: 8940.64 | F11: 8940.64 | G11: 8940.64 | H11: 8940.64 | I11: 8940.64 | J11: 8940.64 | K11: 8940.64 | L11: 8940.64 | M11: 8940.64 | N11: 8940.64 | O11: 8940.64 | P11: 8940.64 | Q11: 8940.64 | R11: 8940.64 | S11: 8940.64 | T11: 8940.64 | U11: 8940.64 | V11: 8940.64 | W11: 8940.64 | X11: 8940.64 | Y11: 8940.64 | Z11: 8940.64 | AA11: 8940.64 | AB11: =(SUM(D11:AA11)) -> 214575.36 | AC11: 4 | AE11: =+AD26 -> 6437260.8
C12: Domingo | D12: 8940.64 | E12: 8940.64 | F12: 8940.64 | G12: 8940.64 | H12: 8940.64 | I12: 8940.64 | J12: 8940.64 | K12: 8940.64 | L12: 8940.64 | M12: 8940.64 | N12: 8940.64 | O12: 8940.64 | P12: 8940.64 | Q12: 8940.64 | R12: 8940.64 | S12: 8940.64 | T12: 8940.64 | U12: 8940.64 | V12: 8940.64 | W12: 8940.64 | X12: 8940.64 | Y12: 8940.64 | Z12: 8940.64 | AA12: 8940.64 | AB12: =(SUM(D12:AA12)) -> 214575.36 | AC12: 4 | AE12: =+AD30 -> 6651836.2
C13: Festivo | D13: 8940.64 | E13: 8940.64 | F13: 8940.64 | G13: 8940.64 | H13: 8940.64 | I13: 8940.64 | J13: 8940.64 | K13: 8940.64 | L13: 8940.64 | M13: 8940.64 | N13: 8940.64 | O13: 8940.64 | P13: 8940.64 | Q13: 8940.64 | R13: 8940.64 | S13: 8940.64 | T13: 8940.64 | U13: 8940.64 | V13: 8940.64 | W13: 8940.64 | X13: 8940.64 | Y13: 8940.64 | Z13: 8940.64 | AA13: 8940.64 | AB13: =(SUM(D13:AA13)) -> 214575.36 | AC13: 0 | AE13: =+AD34 -> 6651836.2
B14: 47178 | C14: Hábil | D14: 8940.64 | E14: 8940.64 | F14: 8940.64 | G14: 8940.64 | H14: 8940.64 | I14: 8940.64 | J14: 8940.64 | K14: 8940.64 | L14: 8940.64 | M14: 8940.64 | N14: 8940.64 | O14: 8940.64 | P14: 8940.64 | Q14: 8940.64 | R14: 8940.64 | S14: 8940.64 | T14: 8940.64 | U14: 8940.64 | V14: 8940.64 | W14: 8940.64 | X14: 8940.64 | Y14: 8940.64 | Z14: 8940.64 | AA14: 8940.64 | AB14: =(SUM(D14:AA14)) -> 214575.36 | AC14: 19 | AD14: =(AB14*AC14)+(AB15*AC15)+(AB16*AC16)+(AB17*AC17) -> 6651836.2 | AE14: =+AD38 -> 6437260.8
