Workbook

Sheet Cantidades - Producto 1
A1: Cantidad Ofrecida | B1: Tipo de día | C1: N° días mes | D1: MES-AÑO | E1: H1 | F1: H2 | G1: H3 | H1: H4 | I1: H5 | J1: H6 | K1: H7 | L1: H8 | M1: H9 | N1: H10 | O1: H11 | P1: H12 | Q1: H13 | R1: H14 | S1: H15 | T1: H16 | U1: H17 | V1: H18 | W1: H19 | X1: H20 | Y1: H21 | Z1: H22 | AA1: H23 | AB1: H24 | AC1: TOTAL | AD1: TOTAL MES
A2: CANTIDADES 2025
B3: ORD. | C3: 20 | D3: 45748 | E3: 3694.45 | F3: 3694.45 | G3: 3694.45 | H3: 3694.45 | I3: 3694.45 | J3: 3694.45 | K3: 3694.45 | L3: 3694.45 | M3: 3694.45 | N3: 3694.45 | O3: 3694.45 | P3: 3694.45 | Q3: 3694.45 | R3: 3694.45 | S3: 3694.45 | T3: 3694.45 | U3: 3694.45 | V3: 3694.45 | W3: 3694.45 | X3: 3694.45 | Y3: 3694.45 | Z3: 3694.45 | AA3: 3694.45 | AB3: 3694.45 | AC3: =SUM(E3:AB3)*C3 -> 1773336
B4: SAB. | C4: 4 | E4: 3694.45 | F4: 3694.45 | G4: 3694.45 | H4: 3694.45 | I4: 3694.45 | J4: 3694.45 | K4: 3694.45 | L4: 3694.45 | M4: 3694.45 | N4: 3694.45 | O4: 3694.45 | P4: 3694.45 | Q4: 3694.45 | R4: 3694.45 | S4: 3694.45 | T4: 3694.45 | U4: 3694.45 | V4: 3694.45 | W4: 3694.45 | X4: 3694.45 | Y4: 3694.45 | Z4: 3694.45 | AA4: 3694.45 | AB4: 3694.45 | AC4: =SUM(E4:AB4)*C4 -> 354667.2
B5: DOM- FES | C5: 6 | E5: 3694.45 | F5: 3694.45 | G5: 3694.45 | H5: 3694.45 | I5: 3694.45 | J5: 3694.45 | K5: 3694.45 | L5: 3694.45 | M5: 3694.45 | N5: 3694.45 | O5: 3694.45 | P5: 3694.45 | Q5: 3694.45 | R5: 3694.45 | S5: 3694.45 | T5: 3694.45 | U5: 3694.45 | V5: 3694.45 | W5: 3694.45 | X5: 3694.45 | Y5: 3694.45 | Z5: 3694.45 | AA5: 3694.45 | AB5: 3694.45 | AC5: =SUM(E5:AB5)*C5 -> 532000.8 | AD5: =+AC3+AC4+AC5 -> 2660004
B7: ORD. | C7: 21 | D7: 45778 | E7: 3941.44 | F7: 3941.44 | G7: 3941.44 | H7: 3941.44 | I7: 3941.44 | J7: 3941.44 | K7: 3941.44 | L7: 3941.44 | M7: 3941.44 | N7: 3941.44 | O7: 3941.44 | P7: 3941.44 | Q7: 3941.44 | R7: 3941.44 | S7: 3941.44 | T7: 3941.44 | U7: 3941.44 | V7: 3941.44 | W7: 3941.44 | X7: 3941.44 | Y7: 3941.44 | Z7: 3941.44 | AA7: 3941.44 | AB7: 3941.44 | AC7: 1891891.2
B8: SAB. | C8: 5 | E8: 3941.44 | F8: 3941.44 | G8: 3941.44 | H8: 3941.44 | I8: 3941.44 | J8: 3941.44 | K8: 3941.44 | L8: 3941.44 | M8: 3941.44 | N8: 3941.44 | O8: 3941.44 | P8: 3941.44 | Q8: 3941.44 | R8: 3941.44 | S8: 3941.44 | T8: 3941.44 | U8: 3941.44 | V8: 3941.44 | W8: 3941.44 | X8: 3941.44 | Y8: 3941.44 | Z8: 3941.44 | AA8: 3941.44 | AB8: 3941.44 | AC8: 472972.8
B9: DOM- FES | C9: 5 | E9: 3941.44 | F9: 3941.44 | G9: 3941.44 | H9: 3941.44 | I9: 3941.44 | J9: 3941.44 | K9: 3941.44 | L9: 3941.44 | M9: 3941.44 | N9: 3941.44 | O9: 3941.44 | P9: 3941.44 | Q9: 3941.44 | R9: 3941.44 | S9: 3941.44 | T9: 3941.44 | U9: 3941.44 | V9: 3941.44 | W9: 3941.44 | X9: 3941.44 | Y9: 3941.44 | Z9: 3941.44 | AA9: 3941.44 | AB9: 3941.44 | AC9: 472972.8 | AD9: 2837836.8
B11: ORD. | C11: 18 | E11: 3694.45 | F11: 3694.45 | G11: 3694.45 | H11: 3694.45 | I11: 3694.45 | J11: 3694.45 | K11: 3694.45 | L11: 3694.45 | M11: 3694.45 | N11: 3694.45 | O11: 3694.45 | P11: 3694.45 | Q11: 3694.45 | R11: 3694.45 | S11: 3694.45 | T11: 3694.45 | U11: 3694.45 | V11: 3694.45 | W11: 3694.45 | X11: 3694.45 | Y11: 3694.45 | Z11: 3694.45 | AA11: 3694.45 | AB11: 3694.45 | AC11: 1596002.4
B12: SAB. | C12: 4 | D12: 45809 | E12: 3694.45 | F12: 3694.45 | G12: 3694.45 | H12: 3694.45 | I12: 3694.45 | J12: 3694.45 | K12: 3694.45 | L12: 3694.45 | M12: 3694.45 | N12: 3694.45 | O12: 3694.45 | P12: 3694.45 | Q12: 3694.45 | R12: 3694.45 | S12: 3694.45 | T12: 3694.45 | U12: 3694.45 | V12: 3694.45 | W12: 3694.45 | X12: 3694.45 | Y12: 3694.45 | Z12: 3694.45 | AA12: 3694.45 | AB12: 3694.45 | AC12: 354667.2
B13: DOM- FES | C13: 8 | E13: 3694.45 | F13: 3694.45 | G13: 3694.45 | H13: 3694.45 | I13: 3694.45 | J13: 3694.45 | K13: 3694.45 | L13: 3694.45 | M13: 3694.45 | N13: 3694.45 | O13: 3694.45 | P13: 3694.45 | Q13: 3694.45 | R13: 3694.45 | S13: 3694.45 | T13: 3694.45 | U13: 3694.45 | V13: 3694.45 | W13: 3694.45 | X13: 3694.45 | Y13: 3694.45 | Z13: 3694.45 | AA13: 3694.45 | AB13: 3694.45 | AC13: 709334.4 | AD13: 2660004
B15: ORD. | C15: 23 | E15: 3456.99 | F15: 3456.99 | G15: 3456.99 | H15: 3456.99 | I15: 3456.99 | J15: 3456.99 | K15: 3456.99 | L15: 3456.99 | M15: 3456.99 | N15: 3456.99 | O15: 3456.99 | P15: 3456.99 | Q15: 3456.99 | R15: 3456.99 | S15: 3456.99 | T15: 3456.99 | U15: 3456.99 | V15: 3456.99 | W15: 3456.99 | X15: 3456.99 | Y15: 3456.99 | Z15: 3456.99 | AA15: 3456.99 | AB15: 3456.99 | AC15: 1908258.5
B16: SAB. | C16: 4 | D16: 45839 | E16: 3456.99 | F16: 3456.99 | G16: 3456.99 | H16: 3456.99 | I16: 3456.99 | J16: 3456.99 | K16: 3456.99 | L16: 3456.99 | M16: 3456.99 | N16: 3456.99 | O16: 3456.99 | P16: 3456.99 | Q16: 3456.99 | R16: 3456.99 | S16: 3456.99 | T16: 3456.99 | U16: 3456.99 | V16: 3456.99 | W16: 3456.99 | X16: 3456.99 | Y16: 3456.99 | Z16: 3456.99 | AA16: 3456.99 | AB16: 3456.99 | AC16: 331871.04
B17: DOM- FES | C17: 4 | E17: 3456.99 | F17: 3456.99 | G17: 3456.99 | H17: 3456.99 | I17: 3456.99 | J17: 3456.99 | K17: 3456.99 | L17: 3456.99 | M17: 3456.99 | N17: 3456.99 | O17: 3456.99 | P17: 3456.99 | Q17: 3456.99 | R17: 3456.99 | S17: 3456.99 | T17: 3456.99 | U17: 3456.99 | V17: 3456.99 | W17: 3456.99 | X17: 3456.99 | Y17: 3456.99 | Z17: 3456.99 | AA17: 3456.99 | AB17: 3456.99 | AC17: 331871.04 | AD17: 2572000.6
B19: ORD. | C19: 20 | E19: 3456.99 | F19: 3456.99 | G19: 3456.99 | H19: 3456.99 | I19: 3456.99 | J19: 3456.99 | K19: 3456.99 | L19: 3456.99 | M19: 3456.99 | N19: 3456.99 | O19: 3456.99 | P19: 3456.99 | Q19: 3456.99 | R19: 3456.99 | S19: 3456.99 | T19: 3456.99 | U19: 3456.99 | V19: 3456.99 | W19: 3456.99 | X19: 3456.99 | Y19: 3456.99 | Z19: 3456.99 | AA19: 3456.99 | AB19: 3456.99 | AC19: 1659355.2
B20: SAB. | C20: 5 | D20: 45870 | E20: 3456.99 | F20: 3456.99 | G20: 3456.99 | H20: 3456.99 | I20: 3456.99 | J20: 3456.99 | K20: 3456.99 | L20: 3456.99 | M20: 3456.99 | N20: 3456.99 | O20: 3456.99 | P20: 3456.99 | Q20: 3456.99 | R20: 3456.99 | S20: 3456.99 | T20: 3456.99 | U20: 3456.99 | V20: 3456.99 | W20: 3456.99 | X20: 3456.99 | Y20: 3456.99 | Z20: 3456.99 | AA20: 3456.99 | AB20: 3456.99 | AC20: 414838.8
B21: DOM- FES | C21: 6 | E21: 3456.99 | F21: 3456.99 | G21: 3456.99 | H21: 3456.99 | I21: 3456.99 | J21: 3456.99 | K21: 3456.99 | L21: 3456.99 | M21: 3456.99 | N21: 3456.99 | O21: 3456.99 | P21: 3456.99 | Q21: 3456.99 | R21: 3456.99 | S21: 3456.99 | T21: 3456.99 | U21: 3456.99 | V21: 3456.99 | W21: 3456.99 | X21: 3456.99 | Y21: 3456.99 | Z21: 3456.99 | AA21: 3456.99 | AB21: 3456.99 | AC21: 497806.56 | AD21: 2572000.6
B23: ORD. | C23: 22 | E23: 3138.89 | F23: 3138.89 | G23: 3138.89 | H23: 3138.89 | I23: 3138.89 | J23: 3138.89 | K23: 3138.89 | L23: 3138.89 | M23: 3138.89 | N23: 3138.89 | O23: 3138.89 | P23: 3138.89 | Q23: 3138.89 | R23: 3138.89 | S23: 3138.89 | T23: 3138.89 | U23: 3138.89 | V23: 3138.89 | W23: 3138.89 | X23: 3138.89 | Y23: 3138.89 | Z23: 3138.89 | AA23: 3138.89 | AB23: 3138.89 | AC23: 1657333.9
B24: SAB. | C24: 4 | D24: 45901 | E24: 3138.89 | F24: 3138.89 | G24: 3138.89 | H24: 3138.89 | I24: 3138.89 | J24: 3138.89 | K24: 3138.89 | L24: 3138.89 | M24: 3138.89 | N24: 3138.89 | O24: 3138.89 | P24: 3138.89 | Q24: 3138.89 | R24: 3138.89 | S24: 3138.89 | T24: 3138.89 | U24: 3138.89 | V24: 3138.89 | W24: 3138.89 | X24: 3138.89 | Y24: 3138.89 | Z24: 3138.89 | AA24: 3138.89 | AB24: 3138.89 | AC24: 301333.44
B25: DOM- FES | C25: 4 | E25: 3138.89 | F25: 3138.89 | G25: 3138.89 | H25: 3138.89 | I25: 3138.89 | J25: 3138.89 | K25: 3138.89 | L25: 3138.89 | M25: 3138.89 | N25: 3138.89 | O25: 3138.89 | P25: 3138.89 | Q25: 3138.89 | R25: 3138.89 | S25: 3138.89 | T25: 3138.89 | U25: 3138.89 | V25: 3138.89 | W25: 3138.89 | X25: 3138.89 | Y25: 3138.89 | Z25: 3138.89 | AA25: 3138.89 | AB25: 3138.89 | AC25: 301333.44 | AD25: 2260000.8
B27: ORD. | C27: 22 | E27: 3456.99 | F27: 3456.99 | G27: 3456.99 | H27: 3456.99 | I27: 3456.99 | J27: 3456.99 | K27: 3456.99 | L27: 3456.99 | M27: 3456.99 | N27: 3456.99 | O27: 3456.99 | P27: 3456.99 | Q27: 3456.99 | R27: 3456.99 | S27: 3456.99 | T27: 3456.99 | U27: 3456.99 | V27: 3456.99 | W27: 3456.99 | X27: 3456.99 | Y27: 3456.99 | Z27: 3456.99 | AA27: 3456.99 | AB27: 3456.99 | AC27: 1825290.7
B28: SAB. | C28: 4 | D28: 45931 | E28: 3456.99 | F28: 3456.99 | G28: 3456.99 | H28: 3456.99 | I28: 3456.99 | J28: 3456.99 | K28: 3456.99 | L28: 3456.99 | M28: 3456.99 | N28: 3456.99 | O28: 3456.99 | P28: 3456.99 | Q28: 3456.99 | R28: 3456.99 | S28: 3456.99 | T28: 3456.99 | U28: 3456.99 | V28: 3456.99 | W28: 3456.99 | X28: 3456.99 | Y28: 3456.99 | Z28: 3456.99 | AA28: 3456.99 | AB28: 3456.99 | AC28: 331871.04
B29: DOM- FES | C29: 5 | E29: 3456.99 | F29: 3456.99 | G29: 3456.99 | H29: 3456.99 | I29: 3456.99 | J29: 3456.99 | K29: 3456.99 | L29: 3456.99 | M29: 3456.99 | N29: 3456.99 | O29: 3456.99 | P29: 3456.99 | Q29: 3456.99 | R29: 3456.99 | S29: 3456.99 | T29: 3456.99 | U29: 3456.99 | V29: 3456.99 | W29: 3456.99 | X29: 3456.99 | Y29: 3456.99 | Z29: 3456.99 | AA29: 3456.99 | AB29: 3456.99 | AC29: 414838.8 | AD29: 2572000.6
B31: ORD. | C31: 18 | D31: 45962 | E31: 3138.9 | F31: 3138.9 | G31: 3138.9 | H31: 3138.9 | I31: 3138.9 | J31: 3138.9 | K31: 3138.9 | L31: 3138.9 | M31: 3138.9 | N31: 3138.9 | O31: 3138.9 | P31: 3138.9 | Q31: 3138.9 | R31: 3138.9 | S31: 3138.9 | T31: 3138.9 | U31: 3138.9 | V31: 3138.9 | W31: 3138.9 | X31: 3138.9 | Y31: 3138.9 | Z31: 3138.9 | AA31: 3138.9 | AB31: 3138.9 | AC31: 1356004.8
B32: SAB. | C32: 5 | E32: 3138.9 | F32: 3138.9 | G32: 3138.9 | H32: 3138.9 | I32: 3138.9 | J32: 3138.9 | K32: 3138.9 | L32: 3138.9 | M32: 3138.9 | N32: 3138.9 | O32: 3138.9 | P32: 3138.9 | Q32: 3138.9 | R32: 3138.9 | S32: 3138.9 | T32: 3138.9 | U32: 3138.9 | V32: 3138.9 | W32: 3138.9 | X32: 3138.9 | Y32: 3138.9 | Z32: 3138.9 | AA32: 3138.9 | AB32: 3138.9 | AC32: 376668
B33: DOM- FES | C33: 7 | E33: 3138.9 | F33: 3138.9 | G33: 3138.9 | H33: 3138.9 | I33: 3138.9 | J33: 3138.9 | K33: 3138.9 | L33: 3138.9 | M33: 3138.9 | N33: 3138.9 | O33: 3138.9 | P33: 3138.9 | Q33: 3138.9 | R33: 3138.9 | S33: 3138.9 | T33: 3138.9 | U33: 3138.9 | V33: 3138.9 | W33: 3138.9 | X33: 3138.9 | Y33: 3138.9 | Z33: 3138.9 | AA33: 3138.9 | AB33: 3138.9 | AC33: 527335.2 | AD33: 2260008
B35: ORD. | C35: 21 | D35: 45992 | E35: 2434.14 | F35: 2434.14 | G35: 2434.14 | H35: 2434.14 | I35: 2434.14 | J35: 2434.14 | K35: 2434.14 | L35: 2434.14 | M35: 2434.14 | N35: 2434.14 | O35: 2434.14 | P35: 2434.14 | Q35: 2434.14 | R35: 2434.14 | S35: 2434.14 | T35: 2434.14 | U35: 2434.14 | V35: 2434.14 | W35: 2434.14 | X35: 2434.14 | Y35: 2434.14 | Z35: 2434.14 | AA35: 2434.14 | AB35: 2434.14 | AC35: 1226806.6
B36: SAB. | C36: 4 | E36: 2434.14 | F36: 2434.14 | G36: 2434.14 | H36: 2434.14 | I36: 2434.14 | J36: 2434.14 | K36: 2434.14 | L36: 2434.14 | M36: 2434.14 | N36: 2434.14 | O36: 2434.14 | P36: 2434.14 | Q36: 2434.14 | R36: 2434.14 | S36: 2434.14 | T36: 2434.14 | U36: 2434.14 | V36: 2434.14 | W36: 2434.14 | X36: 2434.14 | Y36: 2434.14 | Z36: 2434.14 | AA36: 2434.14 | AB36: 2434.14 | AC36: 233677.44
B37: DOM- FES | C37: 6 | E37: 2434.14 | F37: 2434.14 | G37: 2434.14 | H37: 2434.14 | I37: 2434.14 | J37: 2434.14 | K37: 2434.14 | L37: 2434.14 | M37: 2434.14 | N37: 2434.14 | O37: 2434.14 | P37: 2434.14 | Q37: 2434.14 | R37: 2434.14 | S37: 2434.14 | T37: 2434.14 | U37: 2434.14 | V37: 2434.14 | W37: 2434.14 | X37: 2434.14 | Y37: 2434.14 | Z37: 2434.14 | AA37: 2434.14 | AB37: 2434.14 | AC37: 350516.16 | AD37: 1811000.2
A38: CANTIDADES 2026
B39: ORD. | C39: 20 | D39: 46023 | E39: 8310.6331 | F39: 8064.307 | G39: 7881.4379 | H39: 7729.7715 | I39: 7656.0365 | J39: 7726.0675 | K39: 7826.7925 | L39: 8446.1302 | M39: 9138.0896 | N39: 9707.8633 | O39: 10133.241 | P39: 10490.968 | Q39: 10465.411 | R39: 10539.369 | S39: 10819.821 | T39: 10882.19 | U39: 10684.51 | V39: 10522.57 | W39: 10990.297 | X39: 10969.28 | Y39: 10607.361 | Z39: 10059.541 | AA39: 9368.777 | AB39: 8757.3279 | AC39: 227777.79
B40: SAB. | C40: 5 | E40: 8311.5329 | F40: 8046.1135 | G40: 7857.7577 | H40: 7783.5403 | I40: 7724.5041 | J40: 7786.8732 | K40: 7810.1441 | L40: 8363.4846 | M40: 9032.9461 | N40: 9640.3525 | O40: 10147.972 | P40: 10507.183 | Q40: 10469.349 | R40: 10512.726 | S40: 10790.614 | T40: 10826.677 | U40: 10647.229 | V40: 10542.392 | W40: 11006.475 | X40: 10985.884 | Y40: 10609.639 | Z40: 10119.243 | AA40: 9430.407 | AB40: 8813.2974 | AC40: 227766.34
B41: DOM- FES | C41: 6 | E41: 8330.2888 | F41: 8030.4006 | G41: 7813.1635 | H41: 7719.7445 | I41: 7712.8982 | J41: 7796.0603 | K41: 7866.0948 | L41: 8408.6341 | M41: 9059.126 | N41: 9622.7809 | O41: 10085.892 | P41: 10530.886 | Q41: 10546.523 | R41: 10608.043 | S41: 10842.133 | T41: 10856.181 | U41: 10614.955 | V41: 10455.777 | W41: 10927.81 | X41: 10889.779 | Y41: 10518.161 | Z41: 10012.469 | AA41: 9407.3265 | AB41: 8812.5791 | AC41: 227467.71 | AD41: 7059193.8
B43: ORD. | C43: 20 | D43: 46054 | E43: 6168.67 | F43: 6077.67 | G43: 6034.9 | H43: 6036.27 | I43: 6109.52 | J43: 6222.82 | K43: 6549.05 | L43: 6812.5 | M43: 6978.57 | N43: 7085.04 | O43: 7173.31 | P43: 7254.76 | Q43: 7302.53 | R43: 7235.19 | S43: 7180.59 | T43: 7130.09 | U43: 7073.21 | V43: 7061.38 | W43: 7235.19 | X43: 7299.8 | Y43: 7151.93 | Z43: 6913.05 | AA43: 6632.32 | AB43: 6357.04 | AC43: 163075.4
B44: SAB. | C44: 4 | E44: 6063.11 | F44: 5975.3 | G44: 5928.43 | H44: 5916.6 | I44: 5957.1 | J44: 5998.96 | K44: 6164.58 | L44: 6362.5 | M44: 6559.52 | N44: 6705.57 | O44: 6817.96 | P44: 6906.68 | Q44: 6944.45 | R44: 6887.57 | S44: 6801.12 | T44: 6731.51 | U44: 6680.55 | V44: 6686.01 | W44: 6836.16 | X44: 6874.83 | Y44: 6764.27 | Z44: 6587.73 | AA44: 6378.88 | AB44: 6183.69 | AC44: 155713.08
B45: DOM- FES | C45: 4 | E45: 5773.73 | F45: 5700.48 | G45: 5661.8 | H45: 5642.69 | I45: 5644.51 | J45: 5634.5 | K45: 5696.84 | L45: 5807.86 | M45: 5963.92 | N45: 6094.96 | O45: 6187.78 | P45: 6265.13 | Q45: 6319.28 | R45: 6301.08 | S45: 6238.29 | T45: 6176.86 | U45: 6148.2 | V45: 6167.43 | W45: 6300.62 | X45: 6367.51 | Y45: 6296.53 | Z45: 6161.39 | AA45: 5993.04 | AB45: 5841.07 | AC45: 144385.5 | AD45: 4461902.3
B47: ORD. | C47: 21 | D47: 46082 | E47: 9993.05 | F47: 9921.16 | G47: 9887.49 | H47: 9888.86 | I47: 9945.73 | J47: 10035.82 | K47: 10292.9 | L47: 10499.47 | M47: 10631.42 | N47: 10715.14 | O47: 10784.75 | P47: 10848.91 | Q47: 10885.76 | R47: 10832.98 | S47: 10790.21 | T47: 10750.17 | U47: 10705.13 | V47: 10696.48 | W47: 10832.98 | X47: 10883.49 | Y47: 10767.46 | Z47: 10579.09 | AA47: 10358.42 | AB47: 10140.47 | AC47: 251667.34
B48: SAB. | C48: 4 | E48: 10813.87 | F48: 10673.28 | G48: 10597.75 | H48: 10579.09 | I48: 10644.16 | J48: 10710.59 | K48: 10975.85 | L48: 11293.44 | M48: 11609.67 | N48: 11844.45 | O48: 12023.72 | P48: 12166.13 | Q48: 12226.65 | R48: 12135.65 | S48: 11997.33 | T48: 11885.4 | U48: 11803.5 | V48: 11812.14 | W48: 12053.75 | X48: 12115.63 | Y48: 11938.18 | Z48: 11654.71 | AA48: 11319.83 | AB48: 11006.79 | AC48: 275881.56
B49: DOM- FES | C49: 6 | E49: 9691.39 | F49: 9632.69 | G49: 9601.75 | H49: 9586.74 | I49: 9588.1 | J49: 9579.91 | K49: 9629.51 | L49: 9718.69 | M49: 9843.81 | N49: 9948.46 | O49: 10022.63 | P49: 10084.51 | Q49: 10127.73 | R49: 10113.17 | S49: 10062.67 | T49: 10013.98 | U49: 9990.78 | V49: 10006.7 | W49: 10112.72 | X49: 10166.41 | Y49: 10109.53 | Z49: 10001.24 | AA49: 9866.56 | AB49: 9745.08 | AC49: 237244.76 | AD49: 7812008.9
B51: ORD. | C51: 20 | D51: 46113 | E51: 7411.34 | F51: 7182.8226 | G51: 7020.8933 | H51: 6924.818 | I51: 6897.7253 | J51: 6980.7795 | K51: 7067.9964 | L51: 7592.7207 | M51: 8193.7573 | N51: 8704.1316 | O51: 9090.8411 | P51: 9399.1802 | Q51: 9358.4149 | R51: 9387.0832 | S51: 9601.5142 | T51: 9632.3513 | U51: 9449.5725 | V51: 9312.49 | W51: 9720.1662 | X51: 9672.8478 | Y51: 9336.5179 | Z51: 8884.3382 | AA51: 8303.3065 | AB51: 7790.1487 | AC51: 202915.76
...

Sheet Anexo 3 Oferta P1
D2: ANEXO No. 3
D3: CUADRO DE PRESENTACIÓN DE PRECIO OFERTADO
B5: Invitación N° | D5: Convoctatoria Pública No. CP-EGVC2025-001
B6: Oferente | D6: [Nombre del oferente]
B7: Modalidad | D7: Pague lo Contratado - PLC (1)
B8: Precio en | D8: $/kWh - Precios constantes de Diciembre-2024
B10: CUADRO DE PRECIOS Y CANTIDAD DE ENERGÍA OFERTADOS
B11: AÑO | C11: Cantidad de energia Solicitada kWh/mes | D11: Precio ofertado $/kWh | E11: % Energia Ofertada | F11: Cantidad de energia ofertada kWh/mes
B12: 45748 | C12: ='Cantidades - Producto 1'!AD5 -> 2660004 | E12: 0 | F12: 0 | G12: =+C12+'Anexo 3 Oferta P3'!C12 -> 5660007.8
B13: 45778 | C13: ='Cantidades - Producto 1'!AD9 -> 2837836.8 | E13: 0
B14: 45809 | C14: ='Cantidades - Producto 1'!AD13 -> 2660004 | E14: 0
B15: 45839 | C15: ='Cantidades - Producto 1'!AD17 -> 2572000.6 | E15: 0
B16: 45870 | C16: ='Cantidades - Producto 1'!AD21 -> 2572000.6 | E16: 0
B17: 45901 | C17: ='Cantidades - Producto 1'!AD25 -> 2260000.8 | E17: 0
B18: 45931 | C18: ='Cantidades - Producto 1'!AD29 -> 2572000.6 | E18: 0
B19: 45962 | C19: ='Cantidades - Producto 1'!AD33 -> 2260008 | E19: 0
B20: 45992 | C20: ='Cantidades - Producto 1'!AD37 -> 1811000.2 | E20: 0
B21: 2025 (4) | C21: =SUM(C12:C20) -> 22204855
B22: 46023 | C22: ='Cantidades - Producto 1'!AD41 -> 7059193.8 | E22: 0
B23: 46054 | C23: ='Cantidades - Producto 1'!AD45 -> 4461902.3 | E23: 0
B24: 46082 | C24: ='Cantidades - Producto 1'!AD49 -> 7812008.9 | E24: 0
B25: 46113 | C25: ='Cantidades - Producto 1'!AD53 -> 6086826.3 | E25: 0
B26: 46143 | C26: ='Cantidades - Producto 1'!AD57 -> 6327237.5 | E26: 0
B27: 46174 | C27: ='Cantidades - Producto 1'!AD61 -> 7248631.6 | E27: 0
B28: 46204 | C28: ='Cantidades - Producto 1'!AD65 -> 7314930.9 | E28: 0
B29: 46235 | C29: ='Cantidades - Producto 1'!AD69 -> 6441105.7 | E29: 0
B30: 46266 | C30: ='Cantidades - Producto 1'!AD73 -> 6270407 | E30: 0
B31: 46296 | C31: ='Cantidades - Producto 1'!AD77 -> 6516255.6 | E31: 0
B32: 46327 | C32: ='Cantidades - Producto 1'!AD81 -> 5919030.7 | E32: 0
B33: 46357 | C33: ='Cantidades - Producto 1'!AD85 -> 5077185.8 | E33: 0
B34: 2026 | C34: =SUM(C22:C33) -> 76534716
B35: 46388 | C35: ='Cantidades - Producto 1'!AD89 -> 4423628.3 | E35: 0
B36: 46419 | C36: ='Cantidades - Producto 1'!AD93 -> 4823468.9 | E36: 0
B37: 46447 | C37: ='Cantidades - Producto 1'!AD97 -> 8912198.5 | E37: 0
B38: 46478 | C38: ='Cantidades - Producto 1'!AD101 -> 7454656.5 | E38: 0
B39: 46508 | C39: ='Cantidades - Producto 1'!AD105 -> 7747001.5 | E39: 0
B40: 46539 | C40: ='Cantidades - Producto 1'!AD109 -> 6598464.9 | E40: 0
B41: 46569 | C41: ='Cantidades - Producto 1'!AD113 -> 8667879.6 | E41: 0
B42: 46600 | C42: ='Cantidades - Producto 1'!AD117 -> 6892331.9 | E42: 0
B43: 46631 | C43: ='Cantidades - Producto 1'!AD121 -> 6706239 | E43: 0
...

Sheet Cantidades - Producto 2
A1: Cantidad Ofrecida | B1: Tipo de día | C1: N° días mes | D1: MES-AÑO | E1: H1 | F1: H2 | G1: H3 | H1: H4 | I1: H5 | J1: H6 | K1: H7 | L1: H8 | M1: H9 | N1: H10 | O1: H11 | P1: H12 | Q1: H13 | R1: H14 | S1: H15 | T1: H16 | U1: H17 | V1: H18 | W1: H19 | X1: H20 | Y1: H21 | Z1: H22 | AA1: H23 | AB1: H24 | AC1: TOTAL | AD1: TOTAL MES
A2: CANTIDADES 2025
B3: ORD. | C3: 20 | D3: 45748 | E3: 3600 | F3: 3600 | G3: 3600 | H3: 3600 | I3: 3600 | J3: 3600 | K3: 3600 | L3: 3600 | M3: 3600 | N3: 3600 | O3: 3600 | P3: 3600 | Q3: 3600 | R3: 3600 | S3: 3600 | T3: 3600 | U3: 3600 | V3: 3600 | W3: 3600 | X3: 3600 | Y3: 3600 | Z3: 3600 | AA3: 3600 | AB3: 3600 | AC3: 1728000
B4: SAB. | C4: 4 | E4: 3600 | F4: 3600 | G4: 3600 | H4: 3600 | I4: 3600 | J4: 3600 | K4: 3600 | L4: 3600 | M4: 3600 | N4: 3600 | O4: 3600 | P4: 3600 | Q4: 3600 | R4: 3600 | S4: 3600 | T4: 3600 | U4: 3600 | V4: 3600 | W4: 3600 | X4: 3600 | Y4: 3600 | Z4: 3600 | AA4: 3600 | AB4: 3600 | AC4: 345600
B5: DOM- FES | C5: 6 | E5: 3600 | F5: 3600 | G5: 3600 | H5: 3600 | I5: 3600 | J5: 3600 | K5: 3600 | L5: 3600 | M5: 3600 | N5: 3600 | O5: 3600 | P5: 3600 | Q5: 3600 | R5: 3600 | S5: 3600 | T5: 3600 | U5: 3600 | V5: 3600 | W5: 3600 | X5: 3600 | Y5: 3600 | Z5: 3600 | AA5: 3600 | AB5: 3600 | AC5: 518400 | AD5: 2592000
B7: ORD. | C7: 21 | D7: 45778 | E7: 1800 | F7: 1800 | G7: 1800 | H7: 1800 | I7: 1800 | J7: 1800 | K7: 1800 | L7: 1800 | M7: 1800 | N7: 1800 | O7: 1800 | P7: 1800 | Q7: 1800 | R7: 1800 | S7: 1800 | T7: 1800 | U7: 1800 | V7: 1800 | W7: 1800 | X7: 1800 | Y7: 1800 | Z7: 1800 | AA7: 1800 | AB7: 1800 | AC7: 907200
B8: SAB. | C8: 5 | E8: 1800 | F8: 1800 | G8: 1800 | H8: 1800 | I8: 1800 | J8: 1800 | K8: 1800 | L8: 1800 | M8: 1800 | N8: 1800 | O8: 1800 | P8: 1800 | Q8: 1800 | R8: 1800 | S8: 1800 | T8: 1800 | U8: 1800 | V8: 1800 | W8: 1800 | X8: 1800 | Y8: 1800 | Z8: 1800 | AA8: 1800 | AB8: 1800 | AC8: 216000
B9: DOM- FES | C9: 5 | E9: 1800 | F9: 1800 | G9: 1800 | H9: 1800 | I9: 1800 | J9: 1800 | K9: 1800 | L9: 1800 | M9: 1800 | N9: 1800 | O9: 1800 | P9: 1800 | Q9: 1800 | R9: 1800 | S9: 1800 | T9: 1800 | U9: 1800 | V9: 1800 | W9: 1800 | X9: 1800 | Y9: 1800 | Z9: 1800 | AA9: 1800 | AB9: 1800 | AC9: 216000 | AD9: 1339200
B11: ORD. | C11: 18 | E11: 1500 | F11: 1500 | G11: 1500 | H11: 1500 | I11: 1500 | J11: 1500 | K11: 1500 | L11: 1500 | M11: 1500 | N11: 1500 | O11: 1500 | P11: 1500 | Q11: 1500 | R11: 1500 | S11: 1500 | T11: 1500 | U11: 1500 | V11: 1500 | W11: 1500 | X11: 1500 | Y11: 1500 | Z11: 1500 | AA11: 1500 | AB11: 1500 | AC11: 648000
B12: SAB. | C12: 4 | D12: 45809 | E12: 1500 | F12: 1500 | G12: 1500 | H12: 1500 | I12: 1500 | J12: 1500 | K12: 1500 | L12: 1500 | M12: 1500 | N12: 1500 | O12: 1500 | P12: 1500 | Q12: 1500 | R12: 1500 | S12: 1500 | T12: 1500 | U12: 1500 | V12: 1500 | W12: 1500 | X12: 1500 | Y12: 1500 | Z12: 1500 | AA12: 1500 | AB12: 1500 | AC12: 144000
B13: DOM- FES | C13: 8 | E13: 1500 | F13: 1500 | G13: 1500 | H13: 1500 | I13: 1500 | J13: 1500 | K13: 1500 | L13: 1500 | M13: 1500 | N13: 1500 | O13: 1500 | P13: 1500 | Q13: 1500 | R13: 1500 | S13: 1500 | T13: 1500 | U13: 1500 | V13: 1500 | W13: 1500 | X13: 1500 | Y13: 1500 | Z13: 1500 | AA13: 1500 | AB13: 1500 | AC13: 288000 | AD13: 1080000
B15: ORD. | C15: 23 | E15: 1500 | F15: 1500 | G15: 1500 | H15: 1500 | I15: 1500 | J15: 1500 | K15: 1500 | L15: 1500 | M15: 1500 | N15: 1500 | O15: 1500 | P15: 1500 | Q15: 1500 | R15: 1500 | S15: 1500 | T15: 1500 | U15: 1500 | V15: 1500 | W15: 1500 | X15: 1500 | Y15: 1500 | Z15: 1500 | AA15: 1500 | AB15: 1500 | AC15: 828000
B16: SAB. | C16: 4 | D16: 45839 | E16: 1500 | F16: 1500 | G16: 1500 | H16: 1500 | I16: 1500 | J16: 1500 | K16: 1500 | L16: 1500 | M16: 1500 | N16: 1500 | O16: 1500 | P16: 1500 | Q16: 1500 | R16: 1500 | S16: 1500 | T16: 1500 | U16: 1500 | V16: 1500 | W16: 1500 | X16: 1500 | Y16: 1500 | Z16: 1500 | AA16: 1500 | AB16: 1500 | AC16: 144000
B17: DOM- FES | C17: 4 | E17: 1500 | F17: 1500 | G17: 1500 | H17: 1500 | I17: 1500 | J17: 1500 | K17: 1500 | L17: 1500 | M17: 1500 | N17: 1500 | O17: 1500 | P17: 1500 | Q17: 1500 | R17: 1500 | S17: 1500 | T17: 1500 | U17: 1500 | V17: 1500 | W17: 1500 | X17: 1500 | Y17: 1500 | Z17: 1500 | AA17: 1500 | AB17: 1500 | AC17: 144000 | AD17: 1116000
B19: ORD. | C19: 20 | E19: 1500 | F19: 1500 | G19: 1500 | H19: 1500 | I19: 1500 | J19: 1500 | K19: 1500 | L19: 1500 | M19: 1500 | N19: 1500 | O19: 1500 | P19: 1500 | Q19: 1500 | R19: 1500 | S19: 1500 | T19: 1500 | U19: 1500 | V19: 1500 | W19: 1500 | X19: 1500 | Y19: 1500 | Z19: 1500 | AA19: 1500 | AB19: 1500 | AC19: 720000
B20: SAB. | C20: 5 | D20: 45870 | E20: 1500 | F20: 1500 | G20: 1500 | H20: 1500 | I20: 1500 | J20: 1500 | K20: 1500 | L20: 1500 | M20: 1500 | N20: 1500 | O20: 1500 | P20: 1500 | Q20: 1500 | R20: 1500 | S20: 1500 | T20: 1500 | U20: 1500 | V20: 1500 | W20: 1500 | X20: 1500 | Y20: 1500 | Z20: 1500 | AA20: 1500 | AB20: 1500 | AC20: 180000
B21: DOM- FES | C21: 6 | E21: 1500 | F21: 1500 | G21: 1500 | H21: 1500 | I21: 1500 | J21: 1500 | K21: 1500 | L21: 1500 | M21: 1500 | N21: 1500 | O21: 1500 | P21: 1500 | Q21: 1500 | R21: 1500 | S21: 1500 | T21: 1500 | U21: 1500 | V21: 1500 | W21: 1500 | X21: 1500 | Y21: 1500 | Z21: 1500 | AA21: 1500 | AB21: 1500 | AC21: 216000 | AD21: 1116000
B23: ORD. | C23: 22 | E23: 1500 | F23: 1500 | G23: 1500 | H23: 1500 | I23: 1500 | J23: 1500 | K23: 1500 | L23: 1500 | M23: 1500 | N23: 1500 | O23: 1500 | P23: 1500 | Q23: 1500 | R23: 1500 | S23: 1500 | T23: 1500 | U23: 1500 | V23: 1500 | W23: 1500 | X23: 1500 | Y23: 1500 | Z23: 1500 | AA23: 1500 | AB23: 1500 | AC23: 792000
B24: SAB. | C24: 4 | D24: 45901 | E24: 1500 | F24: 1500 | G24: 1500 | H24: 1500 | I24: 1500 | J24: 1500 | K24: 1500 | L24: 1500 | M24: 1500 | N24: 1500 | O24: 1500 | P24: 1500 | Q24: 1500 | R24: 1500 | S24: 1500 | T24: 1500 | U24: 1500 | V24: 1500 | W24: 1500 | X24: 1500 | Y24: 1500 | Z24: 1500 | AA24: 1500 | AB24: 1500 | AC24: 144000
B25: DOM- FES | C25: 4 | E25: 1500 | F25: 1500 | G25: 1500 | H25: 1500 | I25: 1500 | J25: 1500 | K25: 1500 | L25: 1500 | M25: 1500 | N25: 1500 | O25: 1500 | P25: 1500 | Q25: 1500 | R25: 1500 | S25: 1500 | T25: 1500 | U25: 1500 | V25: 1500 | W25: 1500 | X25: 1500 | Y25: 1500 | Z25: 1500 | AA25: 1500 | AB25: 1500 | AC25: 144000 | AD25: 1080000
B27: ORD. | C27: 22 | E27: 1500 | F27: 1500 | G27: 1500 | H27: 1500 | I27: 1500 | J27: 1500 | K27: 1500 | L27: 1500 | M27: 1500 | N27: 1500 | O27: 1500 | P27: 1500 | Q27: 1500 | R27: 1500 | S27: 1500 | T27: 1500 | U27: 1500 | V27: 1500 | W27: 1500 | X27: 1500 | Y27: 1500 | Z27: 1500 | AA27: 1500 | AB27: 1500 | AC27: 792000
B28: SAB. | C28: 4 | D28: 45931 | E28: 1500 | F28: 1500 | G28: 1500 | H28: 1500 | I28: 1500 | J28: 1500 | K28: 1500 | L28: 1500 | M28: 1500 | N28: 1500 | O28: 1500 | P28: 1500 | Q28: 1500 | R28: 1500 | S28: 1500 | T28: 1500 | U28: 1500 | V28: 1500 | W28: 1500 | X28: 1500 | Y28: 1500 | Z28: 1500 | AA28: 1500 | AB28: 1500 | AC28: 144000
B29: DOM- FES | C29: 5 | E29: 1500 | F29: 1500 | G29: 1500 | H29: 1500 | I29: 1500 | J29: 1500 | K29: 1500 | L29: 1500 | M29: 1500 | N29: 1500 | O29: 1500 | P29: 1500 | Q29: 1500 | R29: 1500 | S29: 1500 | T29: 1500 | U29: 1500 | V29: 1500 | W29: 1500 | X29: 1500 | Y29: 1500 | Z29: 1500 | AA29: 1500 | AB29: 1500 | AC29: 180000 | AD29: 1116000
B31: ORD. | C31: 18 | D31: 45962 | E31: 1500 | F31: 1500 | G31: 1500 | H31: 1500 | I31: 1500 | J31: 1500 | K31: 1500 | L31: 1500 | M31: 1500 | N31: 1500 | O31: 1500 | P31: 1500 | Q31: 1500 | R31: 1500 | S31: 1500 | T31: 1500 | U31: 1500 | V31: 1500 | W31: 1500 | X31: 1500 | Y31: 1500 | Z31: 1500 | AA31: 1500 | AB31: 1500 | AC31: 648000
B32: SAB. | C32: 5 | E32: 1500 | F32: 1500 | G32: 1500 | H32: 1500 | I32: 1500 | J32: 1500 | K32: 1500 | L32: 1500 | M32: 1500 | N32: 1500 | O32: 1500 | P32: 1500 | Q32: 1500 | R32: 1500 | S32: 1500 | T32: 1500 | U32: 1500 | V32: 1500 | W32: 1500 | X32: 1500 | Y32: 1500 | Z32: 1500 | AA32: 1500 | AB32: 1500 | AC32: 180000
B33: DOM- FES | C33: 7 | E33: 1500 | F33: 1500 | G33: 1500 | H33: 1500 | I33: 1500 | J33: 1500 | K33: 1500 | L33: 1500 | M33: 1500 | N33: 1500 | O33: 1500 | P33: 1500 | Q33: 1500 | R33: 1500 | S33: 1500 | T33: 1500 | U33: 1500 | V33: 1500 | W33: 1500 | X33: 1500 | Y33: 1500 | Z33: 1500 | AA33: 1500 | AB33: 1500 | AC33: 252000 | AD33: 1080000
B35: ORD. | C35: 21 | D35: 45992 | E35: 5500 | F35: 5500 | G35: 5500 | H35: 5500 | I35: 5500 | J35: 5500 | K35: 5500 | L35: 5500 | M35: 5500 | N35: 5500 | O35: 5500 | P35: 5500 | Q35: 5500 | R35: 5500 | S35: 5500 | T35: 5500 | U35: 5500 | V35: 5500 | W35: 5500 | X35: 5500 | Y35: 5500 | Z35: 5500 | AA35: 5500 | AB35: 5500 | AC35: 2772000
B36: SAB. | C36: 4 | E36: 5500 | F36: 5500 | G36: 5500 | H36: 5500 | I36: 5500 | J36: 5500 | K36: 5500 | L36: 5500 | M36: 5500 | N36: 5500 | O36: 5500 | P36: 5500 | Q36: 5500 | R36: 5500 | S36: 5500 | T36: 5500 | U36: 5500 | V36: 5500 | W36: 5500 | X36: 5500 | Y36: 5500 | Z36: 5500 | AA36: 5500 | AB36: 5500 | AC36: 528000
B37: DOM- FES | C37: 6 | E37: 5500 | F37: 5500 | G37: 5500 | H37: 5500 | I37: 5500 | J37: 5500 | K37: 5500 | L37: 5500 | M37: 5500 | N37: 5500 | O37: 5500 | P37: 5500 | Q37: 5500 | R37: 5500 | S37: 5500 | T37: 5500 | U37: 5500 | V37: 5500 | W37: 5500 | X37: 5500 | Y37: 5500 | Z37: 5500 | AA37: 5500 | AB37: 5500 | AC37: 792000 | AD37: 4092000
A39: CANTIDADES 2026
B40: ORD. | C40: 20 | D40: 46023 | E40: 2077.6583 | F40: 2077.6583 | G40: 2077.6583 | H40: 2077.6583 | I40: 2077.6583 | J40: 2077.6583 | K40: 2077.6583 | L40: 2077.6583 | M40: 2077.6583 | N40: 2077.6583 | O40: 2077.6583 | P40: 2077.6583 | Q40: 2077.6583 | R40: 2077.6583 | S40: 2077.6583 | T40: 2077.6583 | U40: 2077.6583 | V40: 2077.6583 | W40: 2077.6583 | X40: 2077.6583 | Y40: 2077.6583 | Z40: 2077.6583 | AA40: 2077.6583 | AB40: 2077.6583 | AC40: 49863.799
B41: SAB. | C41: 5 | E41: 2077.6583 | F41: 2077.6583 | G41: 2077.6583 | H41: 2077.6583 | I41: 2077.6583 | J41: 2077.6583 | K41: 2077.6583 | L41: 2077.6583 | M41: 2077.6583 | N41: 2077.6583 | O41: 2077.6583 | P41: 2077.6583 | Q41: 2077.6583 | R41: 2077.6583 | S41: 2077.6583 | T41: 2077.6583 | U41: 2077.6583 | V41: 2077.6583 | W41: 2077.6583 | X41: 2077.6583 | Y41: 2077.6583 | Z41: 2077.6583 | AA41: 2077.6583 | AB41: 2077.6583 | AC41: 49863.799
B42: DOM- FES | C42: 6 | E42: 2077.6583 | F42: 2077.6583 | G42: 2077.6583 | H42: 2077.6583 | I42: 2077.6583 | J42: 2077.6583 | K42: 2077.6583 | L42: 2077.6583 | M42: 2077.6583 | N42: 2077.6583 | O42: 2077.6583 | P42: 2077.6583 | Q42: 2077.6583 | R42: 2077.6583 | S42: 2077.6583 | T42: 2077.6583 | U42: 2077.6583 | V42: 2077.6583 | W42: 2077.6583 | X42: 2077.6583 | Y42: 2077.6583 | Z42: 2077.6583 | AA42: 2077.6583 | AB42: 2077.6583 | AC42: 49863.799 | AD42: 1545777.8
B44: ORD. | C44: 20 | D44: 46054 | E44: 4295.8431 | F44: 4295.8431 | G44: 4295.8431 | H44: 4295.8431 | I44: 4295.8431 | J44: 4295.8431 | K44: 4295.8431 | L44: 4295.8431 | M44: 4295.8431 | N44: 4295.8431 | O44: 4295.8431 | P44: 4295.8431 | Q44: 4295.8431 | R44: 4295.8431 | S44: 4295.8431 | T44: 4295.8431 | U44: 4295.8431 | V44: 4295.8431 | W44: 4295.8431 | X44: 4295.8431 | Y44: 4295.8431 | Z44: 4295.8431 | AA44: 4295.8431 | AB44: 4295.8431 | AC44: 103100.24
B45: SAB. | C45: 4 | E45: 4295.8431 | F45: 4295.8431 | G45: 4295.8431 | H45: 4295.8431 | I45: 4295.8431 | J45: 4295.8431 | K45: 4295.8431 | L45: 4295.8431 | M45: 4295.8431 | N45: 4295.8431 | O45: 4295.8431 | P45: 4295.8431 | Q45: 4295.8431 | R45: 4295.8431 | S45: 4295.8431 | T45: 4295.8431 | U45: 4295.8431 | V45: 4295.8431 | W45: 4295.8431 | X45: 4295.8431 | Y45: 4295.8431 | Z45: 4295.8431 | AA45: 4295.8431 | AB45: 4295.8431 | AC45: 103100.24
B46: DOM- FES | C46: 4 | E46: 4295.8431 | F46: 4295.8431 | G46: 4295.8431 | H46: 4295.8431 | I46: 4295.8431 | J46: 4295.8431 | K46: 4295.8431 | L46: 4295.8431 | M46: 4295.8431 | N46: 4295.8431 | O46: 4295.8431 | P46: 4295.8431 | Q46: 4295.8431 | R46: 4295.8431 | S46: 4295.8431 | T46: 4295.8431 | U46: 4295.8431 | V46: 4295.8431 | W46: 4295.8431 | X46: 4295.8431 | Y46: 4295.8431 | Z46: 4295.8431 | AA46: 4295.8431 | AB46: 4295.8431 | AC46: 103100.24 | AD46: 2886806.6
B48: ORD. | C48: 21 | D48: 46082 | E48: 1400 | F48: 1400 | G48: 1400 | H48: 1400 | I48: 1400 | J48: 1400 | K48: 1400 | L48: 1400 | M48: 1400 | N48: 1400 | O48: 1400 | P48: 1400 | Q48: 1400 | R48: 1400 | S48: 1400 | T48: 1400 | U48: 1400 | V48: 1400 | W48: 1400 | X48: 1400 | Y48: 1400 | Z48: 1400 | AA48: 1400 | AB48: 1400 | AC48: 33600
B49: SAB. | C49: 4 | E49: 1400 | F49: 1400 | G49: 1400 | H49: 1400 | I49: 1400 | J49: 1400 | K49: 1400 | L49: 1400 | M49: 1400 | N49: 1400 | O49: 1400 | P49: 1400 | Q49: 1400 | R49: 1400 | S49: 1400 | T49: 1400 | U49: 1400 | V49: 1400 | W49: 1400 | X49: 1400 | Y49: 1400 | Z49: 1400 | AA49: 1400 | AB49: 1400 | AC49: 33600
B50: DOM- FES | C50: 6 | E50: 1400 | F50: 1400 | G50: 1400 | H50: 1400 | I50: 1400 | J50: 1400 | K50: 1400 | L50: 1400 | M50: 1400 | N50: 1400 | O50: 1400 | P50: 1400 | Q50: 1400 | R50: 1400 | S50: 1400 | T50: 1400 | U50: 1400 | V50: 1400 | W50: 1400 | X50: 1400 | Y50: 1400 | Z50: 1400 | AA50: 1400 | AB50: 1400 | AC50: 33600 | AD50: 1041600
B52: ORD. | C52: 20 | D52: 46113 | E52: 3176.2886 | F52: 3176.2886 | G52: 3176.2886 | H52: 3176.2886 | I52: 3176.2886 | J52: 3176.2886 | K52: 3176.2886 | L52: 3176.2886 | M52: 3176.2886 | N52: 3176.2886 | O52: 3176.2886 | P52: 3176.2886 | Q52: 3176.2886 | R52: 3176.2886 | S52: 3176.2886 | T52: 3176.2886 | U52: 3176.2886 | V52: 3176.2886 | W52: 3176.2886 | X52: 3176.2886 | Y52: 3176.2886 | Z52: 3176.2886 | AA52: 3176.2886 | AB52: 3176.2886 | AC52: 76230.925
...

Sheet Anexo 3 Oferta P2
D2: ANEXO No. 3
D3: CUADRO DE PRESENTACIÓN DE PRECIO OFERTADO
B5: Invitación N° | D5: Convoctatoria Pública No. CP-EGVC2025-001
B6: Oferente | D6: [Nombre del oferente]
B7: Modalidad | D7: Pague lo Contratado - PLC (1)
B8: Precio en | D8: $/kWh - Precios constantes de Diciembre-2024
B10: CUADRO DE PRECIOS Y CANTIDAD DE ENERGÍA OFERTADOS
B11: AÑO | C11: Cantidad de energia Solicitada kWh/mes | D11: Precio ofertado $/kWh | E11: % Energia Ofertada | F11: Cantidad de energia ofertada kWh/mes
B12: 45748 | C12: =+'Cantidades - Producto 2'!AD5 -> 2592000 | E12: 0
B13: 45778 | C13: =+'Cantidades - Producto 2'!AD9 -> 1339200 | E13: 0
B14: 45809 | C14: =+'Cantidades - Producto 2'!AD13 -> 1080000 | E14: 0
B15: 45839 | C15: =+'Cantidades - Producto 2'!AD17 -> 1116000 | E15: 0
B16: 45870 | C16: =+'Cantidades - Producto 2'!AD21 -> 1116000 | E16: 0
B17: 45901 | C17: =+'Cantidades - Producto 2'!AD25 -> 1080000 | E17: 0
B18: 45931 | C18: =+'Cantidades - Producto 2'!AD29 -> 1116000 | E18: 0
B19: 45962 | C19: =+'Cantidades - Producto 2'!AD33 -> 1080000 | E19: 0
B20: 45992 | C20: =+'Cantidades - Producto 2'!AD37 -> 4092000 | E20: 0
B21: 2025 | C21: =SUM(C12:C20) -> 14611200
B22: 46023 | C22: 1545777.8 | E22: 0
B23: 46054 | C23: 2886806.6 | E23: 0
B24: 46082 | C24: 1041600 | E24: 0
B25: 46113 | C25: 2286927.8 | E25: 0
B26: 46143 | C26: 2368061.8 | E26: 0
B27: 46174 | C27: 1368000 | E27: 0
B28: 46204 | C28: 1621587.4 | E28: 0
B29: 46235 | C29: 2433501.9 | E29: 0
B30: 46266 | C30: 2625087.9 | E30: 0
B31: 46296 | C31: 2792681 | E31: 0
B32: 46327 | C32: 2247215.1 | E32: 0
B33: 46357 | C33: 4034473.8 | E33: 0
B34: 2026 | C34: =SUM(C22:C33) -> 27251721
B35: 46388 | C35: 5050364.3 | E35: 0
B36: 46419 | C36: 3779657 | E36: 0
B37: 46447 | C37: 798072.29 | E37: 0
B38: 46478 | C38: 1863664.1 | E38: 0
B39: 46508 | C39: 1936750.4 | E39: 0
B40: 46539 | C40: 2827913.5 | E40: 0
B41: 46569 | C41: 1157609.2 | E41: 0
B42: 46600 | C42: 2953856.5 | E42: 0
B43: 46631 | C43: 2874102.4 | E43: 0
...

Sheet Cantidades - Producto 3
A1: Cantidad Ofrecida | B1: Tipo de día | C1: N° días mes | D1: MES-AÑO | E1: H1 | F1: H2 | G1: H3 | H1: H4 | I1: H5 | J1: H6 | K1: H7 | L1: H8 | M1: H9 | N1: H10 | O1: H11 | P1: H12 | Q1: H13 | R1: H14 | S1: H15 | T1: H16 | U1: H17 | V1: H18 | W1: H19 | X1: H20 | Y1: H21 | Z1: H22 | AA1: H23 | AB1: H24 | AC1: TOTAL | AD1: TOTAL MES
A2: CANTIDADES 2025 | AE2: 2025
B3: ORD. | C3: 20 | D3: 45748 | E3: 3752.35 | F3: 3752.35 | G3: 3752.35 | H3: 3752.35 | I3: 3752.35 | J3: 3752.35 | K3: 3752.35 | L3: 4878.055 | M3: 4878.055 | N3: 4878.055 | O3: 4878.055 | P3: 4878.055 | Q3: 4878.055 | R3: 4878.055 | S3: 4878.055 | T3: 4878.055 | U3: 4878.055 | V3: 3564.7325 | W3: 3564.7325 | X3: 3564.7325 | Y3: 3564.7325 | Z3: 3564.7325 | AA3: 3564.7325 | AB3: 3564.7325 | AC3: =SUM(E3:AB3)*C3 -> 2000002.5
B4: SAB. | C4: 4 | E4: 3752.35 | F4: 3752.35 | G4: 3752.35 | H4: 3752.35 | I4: 3752.35 | J4: 3752.35 | K4: 3752.35 | L4: 4878.055 | M4: 4878.055 | N4: 4878.055 | O4: 4878.055 | P4: 4878.055 | Q4: 4878.055 | R4: 4878.055 | S4: 4878.055 | T4: 4878.055 | U4: 4878.055 | V4: 3564.7325 | W4: 3564.7325 | X4: 3564.7325 | Y4: 3564.7325 | Z4: 3564.7325 | AA4: 3564.7325 | AB4: 3564.7325 | AC4: =SUM(E4:AB4)*C4 -> 400000.51
B5: DOM- FES | C5: 6 | E5: 3752.35 | F5: 3752.35 | G5: 3752.35 | H5: 3752.35 | I5: 3752.35 | J5: 3752.35 | K5: 3752.35 | L5: 4878.055 | M5: 4878.055 | N5: 4878.055 | O5: 4878.055 | P5: 4878.055 | Q5: 4878.055 | R5: 4878.055 | S5: 4878.055 | T5: 4878.055 | U5: 4878.055 | V5: 3564.7325 | W5: 3564.7325 | X5: 3564.7325 | Y5: 3564.7325 | Z5: 3564.7325 | AA5: 3564.7325 | AB5: 3564.7325 | AC5: =SUM(E5:AB5)*C5 -> 600000.76 | AD5: =+AC3+AC4+AC5 -> 3000003.8
B7: ORD. | C7: 21 | D7: 45778 | E7: 4841.73 | F7: 4841.73 | G7: 4841.73 | H7: 4841.73 | I7: 4841.73 | J7: 4841.73 | K7: 4841.73 | L7: 6294.249 | M7: 6294.249 | N7: 6294.249 | O7: 6294.249 | P7: 6294.249 | Q7: 6294.249 | R7: 6294.249 | S7: 6294.249 | T7: 6294.249 | U7: 6294.249 | V7: 4599.6435 | W7: 4599.6435 | X7: 4599.6435 | Y7: 4599.6435 | Z7: 4599.6435 | AA7: 4599.6435 | AB7: 4599.6435 | AC7: 2580642.1
B8: SAB. | C8: 5 | E8: 4841.73 | F8: 4841.73 | G8: 4841.73 | H8: 4841.73 | I8: 4841.73 | J8: 4841.73 | K8: 4841.73 | L8: 6294.249 | M8: 6294.249 | N8: 6294.249 | O8: 6294.249 | P8: 6294.249 | Q8: 6294.249 | R8: 6294.249 | S8: 6294.249 | T8: 6294.249 | U8: 6294.249 | V8: 4599.6435 | W8: 4599.6435 | X8: 4599.6435 | Y8: 4599.6435 | Z8: 4599.6435 | AA8: 4599.6435 | AB8: 4599.6435 | AC8: 645160.52
B9: DOM- FES | C9: 5 | E9: 4841.73 | F9: 4841.73 | G9: 4841.73 | H9: 4841.73 | I9: 4841.73 | J9: 4841.73 | K9: 4841.73 | L9: 6294.249 | M9: 6294.249 | N9: 6294.249 | O9: 6294.249 | P9: 6294.249 | Q9: 6294.249 | R9: 6294.249 | S9: 6294.249 | T9: 6294.249 | U9: 6294.249 | V9: 4599.6435 | W9: 4599.6435 | X9: 4599.6435 | Y9: 4599.6435 | Z9: 4599.6435 | AA9: 4599.6435 | AB9: 4599.6435 | AC9: 774192.63 | AD9: 3999995.2
B11: ORD. | C11: 18 | E11: 6253.91 | F11: 6253.91 | G11: 6253.91 | H11: 6253.91 | I11: 6253.91 | J11: 6253.91 | K11: 6253.91 | L11: 8130.083 | M11: 8130.083 | N11: 8130.083 | O11: 8130.083 | P11: 8130.083 | Q11: 8130.083 | R11: 8130.083 | S11: 8130.083 | T11: 8130.083 | U11: 8130.083 | V11: 5941.2145 | W11: 5941.2145 | X11: 5941.2145 | Y11: 5941.2145 | Z11: 5941.2145 | AA11: 5941.2145 | AB11: 5941.2145 | AC11: 3000000.6
B12: SAB. | C12: 4 | D12: 45809 | E12: 6253.91 | F12: 6253.91 | G12: 6253.91 | H12: 6253.91 | I12: 6253.91 | J12: 6253.91 | K12: 6253.91 | L12: 8130.083 | M12: 8130.083 | N12: 8130.083 | O12: 8130.083 | P12: 8130.083 | Q12: 8130.083 | R12: 8130.083 | S12: 8130.083 | T12: 8130.083 | U12: 8130.083 | V12: 5941.2145 | W12: 5941.2145 | X12: 5941.2145 | Y12: 5941.2145 | Z12: 5941.2145 | AA12: 5941.2145 | AB12: 5941.2145 | AC12: 666666.81
B13: DOM- FES | C13: 8 | E13: 6253.91 | F13: 6253.91 | G13: 6253.91 | H13: 6253.91 | I13: 6253.91 | J13: 6253.91 | K13: 6253.91 | L13: 8130.083 | M13: 8130.083 | N13: 8130.083 | O13: 8130.083 | P13: 8130.083 | Q13: 8130.083 | R13: 8130.083 | S13: 8130.083 | T13: 8130.083 | U13: 8130.083 | V13: 5941.2145 | W13: 5941.2145 | X13: 5941.2145 | Y13: 5941.2145 | Z13: 5941.2145 | AA13: 5941.2145 | AB13: 5941.2145 | AC13: 1333333.6 | AD13: 5000001
B15: ORD. | C15: 23 | E15: 6052.17 | F15: 6052.17 | G15: 6052.17 | H15: 6052.17 | I15: 6052.17 | J15: 6052.17 | K15: 6052.17 | L15: 7867.821 | M15: 7867.821 | N15: 7867.821 | O15: 7867.821 | P15: 7867.821 | Q15: 7867.821 | R15: 7867.821 | S15: 7867.821 | T15: 7867.821 | U15: 7867.821 | V15: 5749.5615 | W15: 5749.5615 | X15: 5749.5615 | Y15: 5749.5615 | Z15: 5749.5615 | AA15: 5749.5615 | AB15: 5749.5615 | AC15: 3709677.6
B16: SAB. | C16: 4 | D16: 45839 | E16: 6052.17 | F16: 6052.17 | G16: 6052.17 | H16: 6052.17 | I16: 6052.17 | J16: 6052.17 | K16: 6052.17 | L16: 7867.821 | M16: 7867.821 | N16: 7867.821 | O16: 7867.821 | P16: 7867.821 | Q16: 7867.821 | R16: 7867.821 | S16: 7867.821 | T16: 7867.821 | U16: 7867.821 | V16: 5749.5615 | W16: 5749.5615 | X16: 5749.5615 | Y16: 5749.5615 | Z16: 5749.5615 | AA16: 5749.5615 | AB16: 5749.5615 | AC16: 645161.32
B17: DOM- FES | C17: 4 | E17: 6052.17 | F17: 6052.17 | G17: 6052.17 | H17: 6052.17 | I17: 6052.17 | J17: 6052.17 | K17: 6052.17 | L17: 7867.821 | M17: 7867.821 | N17: 7867.821 | O17: 7867.821 | P17: 7867.821 | Q17: 7867.821 | R17: 7867.821 | S17: 7867.821 | T17: 7867.821 | U17: 7867.821 | V17: 5749.5615 | W17: 5749.5615 | X17: 5749.5615 | Y17: 5749.5615 | Z17: 5749.5615 | AA17: 5749.5615 | AB17: 5749.5615 | AC17: 645161.32 | AD17: 5000000.2
B19: ORD. | C19: 20 | E19: 6052.17 | F19: 6052.17 | G19: 6052.17 | H19: 6052.17 | I19: 6052.17 | J19: 6052.17 | K19: 6052.17 | L19: 7867.821 | M19: 7867.821 | N19: 7867.821 | O19: 7867.821 | P19: 7867.821 | Q19: 7867.821 | R19: 7867.821 | S19: 7867.821 | T19: 7867.821 | U19: 7867.821 | V19: 5749.5615 | W19: 5749.5615 | X19: 5749.5615 | Y19: 5749.5615 | Z19: 5749.5615 | AA19: 5749.5615 | AB19: 5749.5615 | AC19: 3225806.6
B20: SAB. | C20: 5 | D20: 45870 | E20: 6052.17 | F20: 6052.17 | G20: 6052.17 | H20: 6052.17 | I20: 6052.17 | J20: 6052.17 | K20: 6052.17 | L20: 7867.821 | M20: 7867.821 | N20: 7867.821 | O20: 7867.821 | P20: 7867.821 | Q20: 7867.821 | R20: 7867.821 | S20: 7867.821 | T20: 7867.821 | U20: 7867.821 | V20: 5749.5615 | W20: 5749.5615 | X20: 5749.5615 | Y20: 5749.5615 | Z20: 5749.5615 | AA20: 5749.5615 | AB20: 5749.5615 | AC20: 806451.65
B21: DOM- FES | C21: 6 | E21: 6052.17 | F21: 6052.17 | G21: 6052.17 | H21: 6052.17 | I21: 6052.17 | J21: 6052.17 | K21: 6052.17 | L21: 7867.821 | M21: 7867.821 | N21: 7867.821 | O21: 7867.821 | P21: 7867.821 | Q21: 7867.821 | R21: 7867.821 | S21: 7867.821 | T21: 7867.821 | U21: 7867.821 | V21: 5749.5615 | W21: 5749.5615 | X21: 5749.5615 | Y21: 5749.5615 | Z21: 5749.5615 | AA21: 5749.5615 | AB21: 5749.5615 | AC21: 967741.98 | AD21: 5000000.2
B23: ORD. | C23: 22 | E23: 6253.91 | F23: 6253.91 | G23: 6253.91 | H23: 6253.91 | I23: 6253.91 | J23: 6253.91 | K23: 6253.91 | L23: 8130.083 | M23: 8130.083 | N23: 8130.083 | O23: 8130.083 | P23: 8130.083 | Q23: 8130.083 | R23: 8130.083 | S23: 8130.083 | T23: 8130.083 | U23: 8130.083 | V23: 5941.2145 | W23: 5941.2145 | X23: 5941.2145 | Y23: 5941.2145 | Z23: 5941.2145 | AA23: 5941.2145 | AB23: 5941.2145 | AC23: 3666667.4
B24: SAB. | C24: 4 | D24: 45901 | E24: 6253.91 | F24: 6253.91 | G24: 6253.91 | H24: 6253.91 | I24: 6253.91 | J24: 6253.91 | K24: 6253.91 | L24: 8130.083 | M24: 8130.083 | N24: 8130.083 | O24: 8130.083 | P24: 8130.083 | Q24: 8130.083 | R24: 8130.083 | S24: 8130.083 | T24: 8130.083 | U24: 8130.083 | V24: 5941.2145 | W24: 5941.2145 | X24: 5941.2145 | Y24: 5941.2145 | Z24: 5941.2145 | AA24: 5941.2145 | AB24: 5941.2145 | AC24: 666666.81
B25: DOM- FES | C25: 4 | E25: 6253.91 | F25: 6253.91 | G25: 6253.91 | H25: 6253.91 | I25: 6253.91 | J25: 6253.91 | K25: 6253.91 | L25: 8130.083 | M25: 8130.083 | N25: 8130.083 | O25: 8130.083 | P25: 8130.083 | Q25: 8130.083 | R25: 8130.083 | S25: 8130.083 | T25: 8130.083 | U25: 8130.083 | V25: 5941.2145 | W25: 5941.2145 | X25: 5941.2145 | Y25: 5941.2145 | Z25: 5941.2145 | AA25: 5941.2145 | AB25: 5941.2145 | AC25: 666666.81 | AD25: 5000001
B27: ORD. | C27: 22 | E27: 6052.17 | F27: 6052.17 | G27: 6052.17 | H27: 6052.17 | I27: 6052.17 | J27: 6052.17 | K27: 6052.17 | L27: 7867.821 | M27: 7867.821 | N27: 7867.821 | O27: 7867.821 | P27: 7867.821 | Q27: 7867.821 | R27: 7867.821 | S27: 7867.821 | T27: 7867.821 | U27: 7867.821 | V27: 5749.5615 | W27: 5749.5615 | X27: 5749.5615 | Y27: 5749.5615 | Z27: 5749.5615 | AA27: 5749.5615 | AB27: 5749.5615 | AC27: 3548387.3
B28: SAB. | C28: 4 | D28: 45931 | E28: 6052.17 | F28: 6052.17 | G28: 6052.17 | H28: 6052.17 | I28: 6052.17 | J28: 6052.17 | K28: 6052.17 | L28: 7867.821 | M28: 7867.821 | N28: 7867.821 | O28: 7867.821 | P28: 7867.821 | Q28: 7867.821 | R28: 7867.821 | S28: 7867.821 | T28: 7867.821 | U28: 7867.821 | V28: 5749.5615 | W28: 5749.5615 | X28: 5749.5615 | Y28: 5749.5615 | Z28: 5749.5615 | AA28: 5749.5615 | AB28: 5749.5615 | AC28: 645161.32
B29: DOM- FES | C29: 5 | E29: 6052.17 | F29: 6052.17 | G29: 6052.17 | H29: 6052.17 | I29: 6052.17 | J29: 6052.17 | K29: 6052.17 | L29: 7867.821 | M29: 7867.821 | N29: 7867.821 | O29: 7867.821 | P29: 7867.821 | Q29: 7867.821 | R29: 7867.821 | S29: 7867.821 | T29: 7867.821 | U29: 7867.821 | V29: 5749.5615 | W29: 5749.5615 | X29: 5749.5615 | Y29: 5749.5615 | Z29: 5749.5615 | AA29: 5749.5615 | AB29: 5749.5615 | AC29: 806451.65 | AD29: 5000000.2
B31: ORD. | C31: 18 | D31: 45962 | E31: 6253.91 | F31: 6253.91 | G31: 6253.91 | H31: 6253.91 | I31: 6253.91 | J31: 6253.91 | K31: 6253.91 | L31: 8130.083 | M31: 8130.083 | N31: 8130.083 | O31: 8130.083 | P31: 8130.083 | Q31: 8130.083 | R31: 8130.083 | S31: 8130.083 | T31: 8130.083 | U31: 8130.083 | V31: 5941.2145 | W31: 5941.2145 | X31: 5941.2145 | Y31: 5941.2145 | Z31: 5941.2145 | AA31: 5941.2145 | AB31: 5941.2145 | AC31: 3000000.6
B32: SAB. | C32: 5 | E32: 6253.91 | F32: 6253.91 | G32: 6253.91 | H32: 6253.91 | I32: 6253.91 | J32: 6253.91 | K32: 6253.91 | L32: 8130.083 | M32: 8130.083 | N32: 8130.083 | O32: 8130.083 | P32: 8130.083 | Q32: 8130.083 | R32: 8130.083 | S32: 8130.083 | T32: 8130.083 | U32: 8130.083 | V32: 5941.2145 | W32: 5941.2145 | X32: 5941.2145 | Y32: 5941.2145 | Z32: 5941.2145 | AA32: 5941.2145 | AB32: 5941.2145 | AC32: 833333.51
B33: DOM- FES | C33: 7 | E33: 6253.91 | F33: 6253.91 | G33: 6253.91 | H33: 6253.91 | I33: 6253.91 | J33: 6253.91 | K33: 6253.91 | L33: 8130.083 | M33: 8130.083 | N33: 8130.083 | O33: 8130.083 | P33: 8130.083 | Q33: 8130.083 | R33: 8130.083 | S33: 8130.083 | T33: 8130.083 | U33: 8130.083 | V33: 5941.2145 | W33: 5941.2145 | X33: 5941.2145 | Y33: 5941.2145 | Z33: 5941.2145 | AA33: 5941.2145 | AB33: 5941.2145 | AC33: 1166666.9 | AD33: 5000001
B35: ORD. | C35: 21 | D35: 45992 | E35: 3631.3018 | F35: 3631.3018 | G35: 3631.3018 | H35: 3631.3018 | I35: 3631.3018 | J35: 3631.3018 | K35: 3631.3018 | L35: 4720.6924 | M35: 4720.6924 | N35: 4720.6924 | O35: 4720.6924 | P35: 4720.6924 | Q35: 4720.6924 | R35: 4720.6924 | S35: 4720.6924 | T35: 4720.6924 | U35: 4720.6924 | V35: 3449.7367 | W35: 3449.7367 | X35: 3449.7367 | Y35: 3449.7367 | Z35: 3449.7367 | AA35: 3449.7367 | AB35: 3449.7367 | AC35: 2032258.1
B36: SAB. | C36: 4 | E36: 3631.3018 | F36: 3631.3018 | G36: 3631.3018 | H36: 3631.3018 | I36: 3631.3018 | J36: 3631.3018 | K36: 3631.3018 | L36: 4720.6924 | M36: 4720.6924 | N36: 4720.6924 | O36: 4720.6924 | P36: 4720.6924 | Q36: 4720.6924 | R36: 4720.6924 | S36: 4720.6924 | T36: 4720.6924 | U36: 4720.6924 | V36: 3449.7367 | W36: 3449.7367 | X36: 3449.7367 | Y36: 3449.7367 | Z36: 3449.7367 | AA36: 3449.7367 | AB36: 3449.7367 | AC36: 387096.77
B37: DOM- FES | C37: 6 | E37: 3631.3018 | F37: 3631.3018 | G37: 3631.3018 | H37: 3631.3018 | I37: 3631.3018 | J37: 3631.3018 | K37: 3631.3018 | L37: 4720.6924 | M37: 4720.6924 | N37: 4720.6924 | O37: 4720.6924 | P37: 4720.6924 | Q37: 4720.6924 | R37: 4720.6924 | S37: 4720.6924 | T37: 4720.6924 | U37: 4720.6924 | V37: 3449.7367 | W37: 3449.7367 | X37: 3449.7367 | Y37: 3449.7367 | Z37: 3449.7367 | AA37: 3449.7367 | AB37: 3449.7367 | AC37: 580645.16 | AD37: 3000000
A38: CANTIDADES 2026

Sheet Anexo 3 Oferta P3
D2: ANEXO No. 3
D3: CUADRO DE PRESENTACIÓN DE PRECIO OFERTADO
B5: Invitación N° | D5: Convoctatoria Pública No. CP-EGVC2025-001
B6: Oferente | D6: [Nombre del oferente]
B7: Modalidad | D7: Pague lo Contratado - PLC (1)
B8: Precio en | D8: $/kWh - Precios constantes de Diciembre-2024
B10: CUADRO DE PRECIOS Y CANTIDAD DE ENERGÍA OFERTADOS
B11: AÑO | C11: Cantidad de energia Solicitada kWh/mes | D11: Precio ofertado $/kWh | E11: % Energia Ofertada | F11: Cantidad de energia ofertada kWh/mes
B12: 45748 | C12: ='Cantidades - Producto 3'!AD5 -> 3000003.8 | E12: 0
B13: 45778 | C13: ='Cantidades - Producto 3'!AD9 -> 3999995.2 | E13: 0
B14: 45809 | C14: ='Cantidades - Producto 3'!AD13 -> 5000001 | E14: 0
B15: 45839 | C15: ='Cantidades - Producto 3'!AD17 -> 5000000.2 | E15: 0
B16: 45870 | C16: ='Cantidades - Producto 3'!AD21 -> 5000000.2 | E16: 0
B17: 45901 | C17: ='Cantidades - Producto 3'!AD25 -> 5000001 | E17: 0
B18: 45931 | C18: ='Cantidades - Producto 3'!AD29 -> 5000000.2 | E18: 0
B19: 45962 | C19: ='Cantidades - Producto 3'!AD33 -> 5000001 | E19: 0
B20: 45992 | C20: ='Cantidades - Producto 3'!AD37 -> 3000000 | E20: 0
B21: 2025 (4) | C21: =SUM(C12:C20) -> 40000003
B22: Promedio total | C22: =C21 -> 40000003
B24: (1) PLC: Pague lo Contratado
B25: (2) Precios en Pesos colombianos, para cada periodo (mes), expresados con dos cifras decimales [$/kWh] - - Precios constantes de diciembre-2024
B26: (3) La energía ofertada y adjudicada se despachará de acuerdo con la curva de demanda definida en el Anexo No. 4.
B27: (4) Los oferentes que quieran participar en la totalidad de este producto deberán como mínimo, ofertar para el año 2025 un treinta porciento (30%) de la energía solicitada.
B28: (5) Si no se reciben la oferta minima para el año 2025
B29: (6) si se recibe una oferta con la totalidad o el 100% de la energia solicitada si los precios por cada año estan por debajo del precio de reserva, se adjudicara el total del producto.
B32: Firma Oferente
