Workbook

Sheet Anexo 1
B3: ANEXO No 1 - PRODUCTO No. 1 - CURVA
B4: PAGUE LO CONTRATADO AÑO 2026
B5: PRECIO OFERTADO EN $ / kWh DE ENERO DE 2025
B8: MES | C8: ENERGIA SOLICITADA kWh/MES | D8: % OFERTADO ANUAL | E8: ENERGIA OFERTADA kWh/MES | F8: PRECIO OFERTADO ANUAL $/kWh
B10: 46023 | C10: =+'Anexo 8'!AC6 -> 23221203 | E10: =+'Cantidades Ofertadas Prod 1'!AC6 -> 0
B11: 46054 | C11: =+'Anexo 8'!AC9 -> 23785588 | E11: =+'Cantidades Ofertadas Prod 1'!AC9 -> 0
B12: 46082 | C12: =+'Anexo 8'!AC12 -> 31383419 | E12: =+'Cantidades Ofertadas Prod 1'!AC12 -> 0
B13: 46113 | C13: =+'Anexo 8'!AC15 -> 25056664 | E13: =+'Cantidades Ofertadas Prod 1'!AC15 -> 0
B14: 46143 | C14: =+'Anexo 8'!AC18 -> 27370737 | E14: =+'Cantidades Ofertadas Prod 1'!AC18 -> 0
B15: 46174 | C15: =+'Anexo 8'!AC21 -> 29093091 | E15: =+'Cantidades Ofertadas Prod 1'!AC21 -> 0
B16: 46204 | C16: =+'Anexo 8'!AC24 -> 29539875 | E16: =+'Cantidades Ofertadas Prod 1'!AC24 -> 0
B17: 46235 | C17: =+'Anexo 8'!AC27 -> 30580393 | E17: =+'Cantidades Ofertadas Prod 1'!AC27 -> 0
B18: 46266 | C18: =+'Anexo 8'!AC30 -> 32899598 | E18: =+'Cantidades Ofertadas Prod 1'!AC30 -> 0
B19: 46296 | C19: =+'Anexo 8'!AC33 -> 32296425 | E19: =+'Cantidades Ofertadas Prod 1'!AC33 -> 0
B20: 46327 | C20: =+'Anexo 8'!AC36 -> 29221777 | E20: =+'Cantidades Ofertadas Prod 1'!AC36 -> 0
B21: 46357 | C21: =+'Anexo 8'!AC39 -> 33826029 | E21: =+'Cantidades Ofertadas Prod 1'!AC39 -> 0
B22: TOTAL | C22: =+SUM(C10:C21) -> 348274799 | E22: =SUM(E10:E21) -> 0 | F22: =+F10 -> 0
B23: *Solo se debe ingresar valores en las celdas en color Naranja
B24: * Se debe ofertar un unico % para todos los meses del año.
B25: * Los % ofertados se aplicaran a las curvas de carga de la hoja "Anexo 8".
B26: * La energia ofertada se calcula de manera automatica en la hoja "Cantidades Ofertadas Prod 1"
A27: _____________________________________ | H27: =+C27-G27 -> 0
A28: Firma del Representante Legal | H28: =+C28-G28 -> 0
A29: o Apoderado General (Responsable del negocio) | H29: =+C29-G29 -> 0
B30: * Se debe ofertar un unico precio por producto.
B31: * Para este producto solo se reciben ofertas siguiendo la curva.
B34: ____________________________________________
B35: Firma del Representante Legal
B36: o Apoderado General (Responsable del negocio)

Sheet Anexo 8
A1: CURVAS REQUERIDAS PRODUCTO 1 AÑO 2026 MODALIDAD PAGUE LO CONTRATADO - kWh
A4: Periodo | B4: Tipo de día | C4: H01 | D4: H02 | E4: H03 | F4: H04 | G4: H05 | H4: H06 | I4: H07 | J4: H08 | K4: H09 | L4: H10 | M4: H11 | N4: H12 | O4: H13 | P4: H14 | Q4: H15 | R4: H16 | S4: H17 | T4: H18 | U4: H19 | V4: H20 | W4: H21 | X4: H22 | Y4: H23 | Z4: H24 | AA4: TOTAL DÍA | AB4: Días/ | AC4: TOTAL MES
AB5: mes
A6: 46023 | B6: O | C6: 26852 | D6: 25740 | E6: 24756 | F6: 24169 | G6: 24068 | H6: 23304 | I6: 22282 | J6: 41766 | K6: 43930 | L6: 45027 | M6: 46200 | N6: 48504 | O6: 50324 | P6: 50988 | Q6: 50590 | R6: 50629 | S6: 49808 | T6: 25237 | U6: 23329 | V6: 18754 | W6: 18392 | X6: 19629 | Y6: 21011 | Z6: 20881 | AA6: =SUM(C6:Z6) -> 796170 | AB6: 20 | AC6: =+AA6*AB6+AA7*AB7+AA8*AB8 -> 23221203
B7: S | C7: 24280 | D7: 22980 | E7: 22039 | F7: 21315 | G7: 21141 | H7: 21493 | I7: 21252 | J7: 39914 | K7: 42076 | L7: 43340 | M7: 43556 | N7: 45217 | O7: 46195 | P7: 46343 | Q7: 46583 | R7: 47215 | S7: 47964 | T7: 25550 | U7: 23637 | V7: 18623 | W7: 16802 | X7: 15507 | Y7: 15845 | Z7: 16310 | AA7: =SUM(C7:Z7) -> 735177 | AB7: 5
B8: F | C8: 20522 | D8: 19583 | E8: 19952 | F8: 19425 | G8: 19136 | H8: 19327 | I8: 17713 | J8: 34273 | K8: 35693 | L8: 36782 | M8: 37433 | N8: 38459 | O8: 39993 | P8: 40586 | Q8: 40909 | R8: 41033 | S8: 41401 | T8: 17157 | U8: 12272 | V8: 8145 | W8: 8206 | X8: 9450 | Y8: 12700 | Z8: 13503 | AA8: =SUM(C8:Z8) -> 603653 | AB8: 6
A9: 46054 | B9: O | C9: 29466 | D9: 27901 | E9: 27147 | F9: 26615 | G9: 26465 | H9: 25042 | I9: 23982 | J9: 44776 | K9: 47891 | L9: 48955 | M9: 49736 | N9: 51692 | O9: 52947 | P9: 53301 | Q9: 53362 | R9: 52857 | S9: 52878 | T9: 26901 | U9: 24274 | V9: 19386 | W9: 19373 | X9: 19693 | Y9: 22070 | Z9: 23127 | AA9: =SUM(C9:Z9) -> 849837 | AB9: 20 | AC9: =+AA9*AB9+AA10*AB10+AA11*AB11 -> 23785588
B10: S | C10: 28967 | D10: 27462 | E10: 26582 | F10: 25843 | G10: 25422 | H10: 24775 | I10: 24794 | J10: 43202 | K10: 46680 | L10: 47748 | M10: 48338 | N10: 50561 | O10: 51781 | P10: 52025 | Q10: 52155 | R10: 52097 | S10: 53043 | T10: 30316 | U10: 27719 | V10: 22938 | W10: 21756 | X10: 21600 | Y10: 23389 | Z10: 23070 | AA10: =SUM(C10:Z10) -> 852263 | AB10: 4
B11: F | C11: 29889 | D11: 28702 | E11: 28142 | F11: 27566 | G11: 27130 | H11: 26766 | I11: 24587 | J11: 42199 | K11: 45220 | L11: 47788 | M11: 48539 | N11: 47050 | O11: 50726 | P11: 50639 | Q11: 50609 | R11: 49876 | S11: 50762 | T11: 28494 | U11: 25444 | V11: 21543 | W11: 21986 | X11: 22621 | Y11: 24874 | Z11: 23797 | AA11: =SUM(C11:Z11) -> 844949 | AB11: 4
A12: 46082 | B12: O | C12: 34365 | D12: 32953 | E12: 32400 | F12: 31895 | G12: 32121 | H12: 32020 | I12: 31798 | J12: 52301 | K12: 55806 | L12: 57432 | M12: 58389 | N12: 60337 | O12: 60296 | P12: 60983 | Q12: 61680 | R12: 61547 | S12: 60768 | T12: 35697 | U12: 35346 | V12: 34015 | W12: 33393 | X12: 32405 | Y12: 30843 | Z12: 29259 | AA12: =SUM(C12:Z12) -> 1048049 | AB12: 21 | AC12: =+AA12*AB12+AA13*AB13+AA14*AB14 -> 31383419
B13: S | C13: 34147 | D13: 32270 | E13: 31622 | F13: 31326 | G13: 30655 | H13: 30917 | I13: 30006 | J13: 49618 | K13: 52807 | L13: 54724 | M13: 55714 | N13: 56811 | O13: 56744 | P13: 56231 | Q13: 56190 | R13: 56304 | S13: 55563 | T13: 32772 | U13: 30996 | V13: 29003 | W13: 28195 | X13: 27685 | Y13: 27334 | Z13: 26837 | AA13: =SUM(C13:Z13) -> 974471 | AB13: 4
B14: F | C14: 33083 | D14: 31848 | E14: 31342 | F14: 30822 | G14: 29213 | H14: 29333 | I14: 28038 | J14: 45720 | K14: 47999 | L14: 48961 | M14: 49528 | N14: 51284 | O14: 52871 | P14: 52675 | Q14: 52111 | R14: 52532 | S14: 52828 | T14: 29922 | U14: 28575 | V14: 26860 | W14: 26878 | X14: 27021 | Y14: 26648 | Z14: 26659 | AA14: =SUM(C14:Z14) -> 912751 | AB14: 6
A15: 46113 | B15: O | C15: 28838 | D15: 28133 | E15: 27230 | F15: 27223 | G15: 26481 | H15: 26287 | I15: 26357 | J15: 45536 | K15: 48334 | L15: 50060 | M15: 50805 | N15: 52705 | O15: 52530 | P15: 53522 | Q15: 54466 | R15: 54543 | S15: 53319 | T15: 27662 | U15: 25516 | V15: 24077 | W15: 23977 | X15: 24103 | Y15: 23882 | Z15: 23267 | AA15: =SUM(C15:Z15) -> 878853 | AB15: 20 | AC15: =+AA15*AB15+AA16*AB16+AA17*AB17 -> 25056664
B16: S | C16: 26277 | D16: 25541 | E16: 24111 | F16: 23601 | G16: 23056 | H16: 22892 | I16: 22357 | J16: 41475 | K16: 44551 | L16: 46183 | M16: 46543 | N16: 48401 | O16: 48519 | P16: 48767 | Q16: 48856 | R16: 49081 | S16: 49390 | T16: 25742 | U16: 23036 | V16: 20328 | W16: 19066 | X16: 19872 | Y16: 20791 | Z16: 20022 | AA16: =SUM(C16:Z16) -> 788458 | AB16: 4
B17: F | C17: 26202 | D17: 26093 | E17: 24786 | F17: 24300 | G17: 23294 | H17: 22322 | I17: 21693 | J17: 39069 | K17: 40890 | L17: 42473 | M17: 42842 | N17: 43893 | O17: 44380 | P17: 44300 | Q17: 43555 | R17: 44189 | S17: 44304 | T17: 21281 | U17: 18104 | V17: 14524 | W17: 14727 | X17: 16308 | Y17: 19030 | Z17: 18403 | AA17: =SUM(C17:Z17) -> 720962 | AB17: 6
A18: 46143 | B18: O | C18: 29692 | D18: 28611 | E18: 27731 | F18: 27436 | G18: 27290 | H18: 26644 | I18: 26686 | J18: 45682 | K18: 47993 | L18: 49259 | M18: 50674 | N18: 52554 | O18: 52933 | P18: 53708 | Q18: 54094 | R18: 54035 | S18: 53061 | T18: 27970 | U18: 26821 | V18: 25309 | W18: 24646 | X18: 24900 | Y18: 24538 | Z18: 24253 | AA18: =SUM(C18:Z18) -> 886520 | AB18: 19 | AC18: =+AA18*AB18+AA19*AB19+AA20*AB20 -> 27370737
B19: S | C19: 31519 | D19: 30391 | E19: 29593 | F19: 29247 | G19: 28557 | H19: 27818 | I19: 28236 | J19: 46793 | K19: 50275 | L19: 52992 | M19: 52947 | N19: 54359 | O19: 54192 | P19: 53801 | Q19: 53357 | R19: 52785 | S19: 53267 | T19: 29414 | U19: 29162 | V19: 26201 | W19: 24823 | X19: 24314 | Y19: 24012 | Z19: 23829 | AA19: =SUM(C19:Z19) -> 911884 | AB19: 5
B20: F | C20: 29065 | D20: 28446 | E20: 27568 | F20: 27595 | G20: 26928 | H20: 25722 | I20: 24500 | J20: 42424 | K20: 44188 | L20: 46448 | M20: 47063 | N20: 49254 | O20: 49936 | P20: 50733 | Q20: 49898 | R20: 57619 | S20: 49899 | T20: 27159 | U20: 25750 | V20: 23938 | W20: 23806 | X20: 24631 | Y20: 25649 | Z20: 24272 | AA20: =SUM(C20:Z20) -> 852491 | AB20: 7
A21: 46174 | B21: O | C21: 31162 | D21: 29911 | E21: 29419 | F21: 29034 | G21: 28755 | H21: 28666 | I21: 27882 | J21: 46480 | K21: 48455 | L21: 49612 | M21: 50980 | N21: 52999 | O21: 53510 | P21: 54147 | Q21: 54820 | R21: 54785 | S21: 53846 | T21: 29466 | U21: 30469 | V21: 28234 | W21: 27424 | X21: 26711 | Y21: 25451 | Z21: 24943 | AA21: =SUM(C21:Z21) -> 917161 | AB21: 19 | AC21: =+AA21*AB21+AA22*AB22+AA23*AB23 -> 29093091
B22: S | C22: 36658 | D22: 34684 | E22: 33734 | F22: 33047 | G22: 31865 | H22: 31144 | I22: 29826 | J22: 47535 | K22: 51181 | L22: 52801 | M22: 54174 | N22: 55511 | O22: 56433 | P22: 57160 | Q22: 57762 | R22: 58693 | S22: 59548 | T22: 37129 | U22: 38081 | V22: 35050 | W22: 32668 | X22: 31883 | Y22: 31756 | Z22: 30189 | AA22: =SUM(C22:Z22) -> 1018512 | AB22: 4
B23: F | C23: 37650 | D23: 36651 | E23: 36109 | F23: 35594 | G23: 35316 | H23: 35794 | I23: 33433 | J23: 52161 | K23: 55315 | L23: 56475 | M23: 57689 | N23: 59508 | O23: 58974 | P23: 59693 | Q23: 60550 | R23: 61439 | S23: 61330 | T23: 37838 | U23: 38961 | V23: 35985 | W23: 35219 | X23: 35148 | Y23: 34529 | Z23: 33351 | AA23: =SUM(C23:Z23) -> 1084712 | AB23: 7
A24: 46204 | B24: O | C24: 35177 | D24: 33748 | E24: 32877 | F24: 32200 | G24: 31752 | H24: 31180 | I24: 29553 | J24: 48939 | K24: 51389 | L24: 52903 | M24: 54326 | N24: 56436 | O24: 56686 | P24: 57512 | Q24: 58233 | R24: 58361 | S24: 57321 | T24: 32760 | U24: 34648 | V24: 31775 | W24: 30961 | X24: 30322 | Y24: 29741 | Z24: 29075 | AA24: =SUM(C24:Z24) -> 997875 | AB24: 22 | AC24: =+AA24*AB24+AA25*AB25+AA26*AB26 -> 29539875
B25: S | C25: 26003 | D25: 25280 | E25: 24599 | F25: 24420 | G25: 23539 | H25: 22987 | I25: 22640 | J25: 42204 | K25: 45062 | L25: 45720 | M25: 46808 | N25: 48016 | O25: 48249 | P25: 48154 | Q25: 48213 | R25: 48706 | S25: 48871 | T25: 26558 | U25: 26201 | V25: 22599 | W25: 20582 | X25: 20732 | Y25: 21179 | Z25: 21793 | AA25: =SUM(C25:Z25) -> 799115 | AB25: 4
B26: F | C26: 31904 | D26: 30795 | E26: 29657 | F26: 29330 | G26: 28670 | H26: 27986 | I26: 25716 | J26: 43092 | K26: 45107 | L26: 47178 | M26: 47488 | N26: 49268 | O26: 50441 | P26: 50869 | Q26: 50500 | R26: 50770 | S26: 50890 | T26: 28954 | U26: 29055 | V26: 26024 | W26: 25553 | X26: 25931 | Y26: 26646 | Z26: 26209 | AA26: =SUM(C26:Z26) -> 878033 | AB26: 5
A27: 46235 | B27: O | C27: 34855 | D27: 33658 | E27: 33068 | F27: 32431 | G27: 32154 | H27: 31881 | I27: 30672 | J27: 49816 | K27: 52238 | L27: 53650 | M27: 54801 | N27: 57115 | O27: 58224 | P27: 59648 | Q27: 60044 | R27: 60107 | S27: 58811 | T27: 34378 | U27: 35626 | V27: 33633 | W27: 32496 | X27: 31372 | Y27: 30498 | Z27: 30253 | AA27: =SUM(C27:Z27) -> 1021429 | AB27: 19 | AC27: =+AA27*AB27+AA28*AB28+AA29*AB29 -> 30580393
B28: S | C28: 33638 | D28: 33021 | E28: 32009 | F28: 31066 | G28: 30147 | H28: 29622 | I28: 27046 | J28: 46538 | K28: 49383 | L28: 51319 | M28: 52362 | N28: 53816 | O28: 54230 | P28: 54788 | Q28: 54607 | R28: 54885 | S28: 54593 | T28: 31892 | U28: 32470 | V28: 28338 | W28: 26582 | X28: 26345 | Y28: 26382 | Z28: 26598 | AA28: =SUM(C28:Z28) -> 941677 | AB28: 5
B29: F | C29: 34569 | D29: 33247 | E29: 32153 | F29: 31421 | G29: 30786 | H29: 30216 | I29: 27749 | J29: 46078 | K29: 48095 | L29: 49196 | M29: 49986 | N29: 51460 | O29: 53087 | P29: 53290 | Q29: 52113 | R29: 51488 | S29: 51851 | T29: 29406 | U29: 30225 | V29: 28172 | W29: 27444 | X29: 27418 | Y29: 27501 | Z29: 26600 | AA29: =SUM(C29:Z29) -> 923551 | AB29: 7
A30: 46266 | B30: O | C30: 39991 | D30: 38061 | E30: 36900 | F30: 36185 | G30: 35380 | H30: 35182 | I30: 34193 | J30: 53922 | K30: 56283 | L30: 57974 | M30: 59679 | N30: 61994 | O30: 63333 | P30: 64339 | Q30: 65388 | R30: 66023 | S30: 65173 | T30: 39277 | U30: 39825 | V30: 38194 | W30: 37435 | X30: 36488 | Y30: 35214 | Z30: 34714 | AA30: =SUM(C30:Z30) -> 1131147 | AB30: 22 | AC30: =+AA30*AB30+AA31*AB31+AA32*AB32 -> 32899598
B31: S | C31: 40973 | D31: 38577 | E31: 37315 | F31: 36567 | G31: 35427 | H31: 33832 | I31: 32875 | J31: 52114 | K31: 55859 | L31: 57677 | M31: 58712 | N31: 60885 | O31: 61069 | P31: 61594 | Q31: 61718 | R31: 61952 | S31: 62662 | T31: 39199 | U31: 37671 | V31: 35249 | W31: 33603 | X31: 33489 | Y31: 33302 | Z31: 32329 | AA31: =SUM(C31:Z31) -> 1094650 | AB31: 4
B32: F | C32: 35368 | D32: 34071 | E32: 33090 | F32: 32473 | G32: 31180 | H32: 29854 | I32: 26679 | J32: 43831 | K32: 45950 | L32: 47279 | M32: 47745 | N32: 49013 | O32: 50385 | P32: 50997 | Q32: 50360 | R32: 51668 | S32: 51948 | T32: 28904 | U32: 29535 | V32: 27406 | W32: 27050 | X32: 27307 | Y32: 28558 | Z32: 28290 | AA32: =SUM(C32:Z32) -> 908941 | AB32: 4
A33: 46296 | B33: O | C33: 36542 | D33: 35266 | E33: 34437 | F33: 33641 | G33: 33211 | H33: 33051 | I33: 31469 | J33: 49878 | K33: 52164 | L33: 53162 | M33: 54330 | N33: 56897 | O33: 58268 | P33: 59422 | Q33: 60108 | R33: 60574 | S33: 60058 | T33: 35300 | U33: 34647 | V33: 33223 | W33: 31820 | X33: 31378 | Y33: 30807 | Z33: 30952 | AA33: =SUM(C33:Z33) -> 1030605 | AB33: 21 | AC33: =+AA33*AB33+AA34*AB34+AA35*AB35 -> 32296425
B34: S | C34: 42567 | D34: 40963 | E34: 39771 | F34: 38803 | G34: 38188 | H34: 37679 | I34: 37935 | J34: 57316 | K34: 60748 | L34: 63288 | M34: 65117 | N34: 67141 | O34: 68250 | P34: 68849 | Q34: 69240 | R34: 68950 | S34: 68745 | T34: 46177 | U34: 47424 | V34: 45708 | W34: 43347 | X34: 41712 | Y34: 40896 | Z34: 38164 | AA34: =SUM(C34:Z34) -> 1236978 | AB34: 5
B35: F | C35: 33424 | D35: 32398 | E35: 30980 | F35: 30266 | G35: 29298 | H35: 28410 | I35: 25961 | J35: 42787 | K35: 44506 | L35: 46503 | M35: 47438 | N35: 49242 | O35: 50967 | P35: 51011 | Q35: 51110 | R35: 52255 | S35: 52601 | T35: 30573 | U35: 28963 | V35: 26658 | W35: 26462 | X35: 27078 | Y35: 27766 | Z35: 27109 | AA35: =SUM(C35:Z35) -> 893766 | AB35: 5
A36: 46327 | B36: O | C36: 35648 | D36: 34332 | E36: 33461 | F36: 33105 | G36: 32635 | H36: 32758 | I36: 32145 | J36: 51333 | K36: 53865 | L36: 55514 | M36: 57481 | N36: 60166 | O36: 60669 | P36: 61143 | Q36: 62699 | R36: 61231 | S36: 60637 | T36: 36012 | U36: 37182 | V36: 35475 | W36: 34521 | X36: 33273 | Y36: 31619 | Z36: 30917 | AA36: =SUM(C36:Z36) -> 1057821 | AB36: 19 | AC36: =+AA36*AB36+AA37*AB37+AA38*AB38 -> 29221777
B37: S | C37: 33763 | D37: 32548 | E37: 31753 | F37: 30842 | G37: 30506 | H37: 29303 | I37: 27169 | J37: 45580 | K37: 48494 | L37: 50688 | M37: 51274 | N37: 52997 | O37: 53934 | P37: 52921 | Q37: 53590 | R37: 53760 | S37: 54441 | T37: 31426 | U37: 31047 | V37: 29682 | W37: 28413 | X37: 27982 | Y37: 27225 | Z37: 25948 | AA37: =SUM(C37:Z37) -> 935286 | AB37: 4
B38: F | C38: 28134 | D38: 27462 | E38: 26528 | F38: 25720 | G38: 25419 | H38: 24726 | I38: 21778 | J38: 38840 | K38: 40416 | L38: 41929 | M38: 42165 | N38: 43538 | O38: 44810 | P38: 45373 | Q38: 44593 | R38: 44178 | S38: 45379 | T38: 22535 | U38: 22810 | V38: 22325 | W38: 22517 | X38: 22946 | Y38: 22922 | Z38: 21819 | AA38: =SUM(C38:Z38) -> 768862 | AB38: 7
A39: 46357 | B39: O | C39: 40043 | D39: 38056 | E39: 36969 | F39: 35926 | G39: 35581 | H39: 35516 | I39: 34305 | J39: 54365 | K39: 57378 | L39: 59413 | M39: 61217 | N39: 64156 | O39: 65263 | P39: 65539 | Q39: 66225 | R39: 65610 | S39: 64363 | T39: 39679 | U39: 39987 | V39: 38229 | W39: 36779 | X39: 35910 | Y39: 34978 | Z39: 34926 | AA39: =SUM(C39:Z39) -> 1140413 | AB39: 21 | AC39: =+AA39*AB39+AA40*AB40+AA41*AB41 -> 33826029
B40: S | C40: 34391 | D40: 33884 | E40: 33269 | F40: 32040 | G40: 31482 | H40: 30907 | I40: 29186 | J40: 48193 | K40: 51106 | L40: 52040 | M40: 53424 | N40: 54189 | O40: 54557 | P40: 53480 | Q40: 53706 | R40: 53306 | S40: 53484 | T40: 30859 | U40: 29829 | V40: 25920 | W40: 24012 | X40: 23077 | Y40: 22378 | Z40: 23636 | AA40: =SUM(C40:Z40) -> 932355 | AB40: 4
B41: F | C41: 38085 | D41: 36860 | E41: 35732 | F41: 34928 | G41: 34397 | H41: 33466 | I41: 30990 | J41: 48419 | K41: 50527 | L41: 52313 | M41: 53780 | N41: 55180 | O41: 56534 | P41: 57370 | Q41: 57429 | R41: 57569 | S41: 58363 | T41: 35685 | U41: 35804 | V41: 33999 | W41: 32747 | X41: 31764 | Y41: 31710 | Z41: 31005 | AA41: =SUM(C41:Z41) -> 1024656 | AB41: 6
A42: TOTAL AÑO | C42: =+SUM(C6:C41) -> 1173709 | D42: =+SUM(D6:D41) -> 1130127 | E42: =+SUM(E6:E41) -> 1098831 | F42: =+SUM(F6:F41) -> 1077417 | G42: =+SUM(G6:G41) -> 1056645 | H42: =+SUM(H6:H41) -> 1038822 | I42: =+SUM(I6:I41) -> 993483 | J42: =+SUM(J6:J41) -> 1664169 | ... AC42: =+SUM(AC6:AC41) -> 348274799

Sheet Cantidades Ofertadas Prod 1
A1: CANTIDADES OFERTADAS PRODUCTO 1 AÑO 2026 MODALIDAD PAGUE LO CONTRATADO - kWh
A4: Periodo | B4: Tipo de día | C4: H01 | D4: H02 | E4: H03 | F4: H04 | G4: H05 | H4: H06 | I4: H07 | J4: H08 | K4: H09 | L4: H10 | M4: H11 | N4: H12 | O4: H13 | P4: H14 | Q4: H15 | R4: H16 | S4: H17 | T4: H18 | U4: H19 | V4: H20 | W4: H21 | X4: H22 | Y4: H23 | Z4: H24 | AA4: TOTAL DÍA | AB4: Días/ | AC4: TOTAL MES
AB5: mes
A6: 46023 | B6: O | C6: =ROUND('Anexo 8'!C6*'Anexo 1'!$D$10,0) -> 0 | D6: =ROUND('Anexo 8'!D6*'Anexo 1'!$D$10,0) -> 0 | E6: =ROUND('Anexo 8'!E6*'Anexo 1'!$D$10,0) -> 0 | F6: =ROUND('Anexo 8'!F6*'Anexo 1'!$D$10,0) -> 0 | G6: =ROUND('Anexo 8'!G6*'Anexo 1'!$D$10,0) -> 0 | H6: =ROUND('Anexo 8'!H6*'Anexo 1'!$D$10,0) -> 0 | I6: =ROUND('Anexo 8'!I6*'Anexo 1'!$D$10,0) -> 0 | J6: =ROUND('Anexo 8'!J6*'Anexo 1'!$D$10,0) -> 0 | ... Z6: =ROUND('Anexo 8'!Z6*'Anexo 1'!$D$10,0) -> 0 | AA6: =SUM(C6:Z6) -> 0 | AB6: 20 | AC6: =+AA6*AB6+AA7*AB7+AA8*AB8 -> 0
B7: S | C7: =ROUND('Anexo 8'!C7*'Anexo 1'!$D$10,0) -> 0 | D7: =ROUND('Anexo 8'!D7*'Anexo 1'!$D$10,0) -> 0 | E7: =ROUND('Anexo 8'!E7*'Anexo 1'!$D$10,0) -> 0 | F7: =ROUND('Anexo 8'!F7*'Anexo 1'!$D$10,0) -> 0 | G7: =ROUND('Anexo 8'!G7*'Anexo 1'!$D$10,0) -> 0 | H7: =ROUND('Anexo 8'!H7*'Anexo 1'!$D$10,0) -> 0 | I7: =ROUND('Anexo 8'!I7*'Anexo 1'!$D$10,0) -> 0 | J7: =ROUND('Anexo 8'!J7*'Anexo 1'!$D$10,0) -> 0 | ... Z7: =ROUND('Anexo 8'!Z7*'Anexo 1'!$D$10,0) -> 0 | AA7: =SUM(C7:Z7) -> 0 | AB7: 5
B8: F | C8: =ROUND('Anexo 8'!C8*'Anexo 1'!$D$10,0) -> 0 | D8: =ROUND('Anexo 8'!D8*'Anexo 1'!$D$10,0) -> 0 | E8: =ROUND('Anexo 8'!E8*'Anexo 1'!$D$10,0) -> 0 | F8: =ROUND('Anexo 8'!F8*'Anexo 1'!$D$10,0) -> 0 | G8: =ROUND('Anexo 8'!G8*'Anexo 1'!$D$10,0) -> 0 | H8: =ROUND('Anexo 8'!H8*'Anexo 1'!$D$10,0) -> 0 | I8: =ROUND('Anexo 8'!I8*'Anexo 1'!$D$10,0) -> 0 | J8: =ROUND('Anexo 8'!J8*'Anexo 1'!$D$10,0) -> 0 | ... Z8: =ROUND('Anexo 8'!Z8*'Anexo 1'!$D$10,0) -> 0 | AA8: =SUM(C8:Z8) -> 0 | AB8: 6
A9: 46054 | B9: O | C9: =ROUND('Anexo 8'!C9*'Anexo 1'!$D$10,0) -> 0 | D9: =ROUND('Anexo 8'!D9*'Anexo 1'!$D$10,0) -> 0 | E9: =ROUND('Anexo 8'!E9*'Anexo 1'!$D$10,0) -> 0 | F9: =ROUND('Anexo 8'!F9*'Anexo 1'!$D$10,0) -> 0 | G9: =ROUND('Anexo 8'!G9*'Anexo 1'!$D$10,0) -> 0 | H9: =ROUND('Anexo 8'!H9*'Anexo 1'!$D$10,0) -> 0 | I9: =ROUND('Anexo 8'!I9*'Anexo 1'!$D$10,0) -> 0 | J9: =ROUND('Anexo 8'!J9*'Anexo 1'!$D$10,0) -> 0 | ... Z9: =ROUND('Anexo 8'!Z9*'Anexo 1'!$D$10,0) -> 0 | AA9: =SUM(C9:Z9) -> 0 | AB9: 20 | AC9: =+AA9*AB9+AA10*AB10+AA11*AB11 -> 0
B10: S | C10: =ROUND('Anexo 8'!C10*'Anexo 1'!$D$10,0) -> 0 | D10: =ROUND('Anexo 8'!D10*'Anexo 1'!$D$10,0) -> 0 | E10: =ROUND('Anexo 8'!E10*'Anexo 1'!$D$10,0) -> 0 | F10: =ROUND('Anexo 8'!F10*'Anexo 1'!$D$10,0) -> 0 | G10: =ROUND('Anexo 8'!G10*'Anexo 1'!$D$10,0) -> 0 | H10: =ROUND('Anexo 8'!H10*'Anexo 1'!$D$10,0) -> 0 | I10: =ROUND('Anexo 8'!I10*'Anexo 1'!$D$10,0) -> 0 | J10: =ROUND('Anexo 8'!J10*'Anexo 1'!$D$10,0) -> 0 | ... Z10: =ROUND('Anexo 8'!Z10*'Anexo 1'!$D$10,0) -> 0 | AA10: =SUM(C10:Z10) -> 0 | AB10: 4
B11: F | C11: =ROUND('Anexo 8'!C11*'Anexo 1'!$D$10,0) -> 0 | D11: =ROUND('Anexo 8'!D11*'Anexo 1'!$D$10,0) -> 0 | E11: =ROUND('Anexo 8'!E11*'Anexo 1'!$D$10,0) -> 0 | F11: =ROUND('Anexo 8'!F11*'Anexo 1'!$D$10,0) -> 0 | G11: =ROUND('Anexo 8'!G11*'Anexo 1'!$D$10,0) -> 0 | H11: =ROUND('Anexo 8'!H11*'Anexo 1'!$D$10,0) -> 0 | I11: =ROUND('Anexo 8'!I11*'Anexo 1'!$D$10,0) -> 0 | J11: =ROUND('Anexo 8'!J11*'Anexo 1'!$D$10,0) -> 0 | ... Z11: =ROUND('Anexo 8'!Z11*'Anexo 1'!$D$10,0) -> 0 | AA11: =SUM(C11:Z11) -> 0 | AB11: 4
A12: 46082 | B12: O | C12: =ROUND('Anexo 8'!C12*'Anexo 1'!$D$10,0) -> 0 | D12: =ROUND('Anexo 8'!D12*'Anexo 1'!$D$10,0) -> 0 | E12: =ROUND('Anexo 8'!E12*'Anexo 1'!$D$10,0) -> 0 | F12: =ROUND('Anexo 8'!F12*'Anexo 1'!$D$10,0) -> 0 | G12: =ROUND('Anexo 8'!G12*'Anexo 1'!$D$10,0) -> 0 | H12: =ROUND('Anexo 8'!H12*'Anexo 1'!$D$10,0) -> 0 | I12: =ROUND('Anexo 8'!I12*'Anexo 1'!$D$10,0) -> 0 | J12: =ROUND('Anexo 8'!J12*'Anexo 1'!$D$10,0) -> 0 | ... Z12: =ROUND('Anexo 8'!Z12*'Anexo 1'!$D$10,0) -> 0 | AA12: =SUM(C12:Z12) -> 0 | AB12: 21 | AC12: =+AA12*AB12+AA13*AB13+AA14*AB14 -> 0
B13: S | C13: =ROUND('Anexo 8'!C13*'Anexo 1'!$D$10,0) -> 0 | D13: =ROUND('Anexo 8'!D13*'Anexo 1'!$D$10,0) -> 0 | E13: =ROUND('Anexo 8'!E13*'Anexo 1'!$D$10,0) -> 0 | F13: =ROUND('Anexo 8'!F13*'Anexo 1'!$D$10,0) -> 0 | G13: =ROUND('Anexo 8'!G13*'Anexo 1'!$D$10,0) -> 0 | H13: =ROUND('Anexo 8'!H13*'Anexo 1'!$D$10,0) -> 0 | I13: =ROUND('Anexo 8'!I13*'Anexo 1'!$D$10,0) -> 0 | J13: =ROUND('Anexo 8'!J13*'Anexo 1'!$D$10,0) -> 0 | ... Z13: =ROUND('Anexo 8'!Z13*'Anexo 1'!$D$10,0) -> 0 | AA13: =SUM(C13:Z13) -> 0 | AB13: 4
B14: F | C14: =ROUND('Anexo 8'!C14*'Anexo 1'!$D$10,0) -> 0 | D14: =ROUND('Anexo 8'!D14*'Anexo 1'!$D$10,0) -> 0 | E14: =ROUND('Anexo 8'!E14*'Anexo 1'!$D$10,0) -> 0 | F14: =ROUND('Anexo 8'!F14*'Anexo 1'!$D$10,0) -> 0 | G14: =ROUND('Anexo 8'!G14*'Anexo 1'!$D$10,0) -> 0 | H14: =ROUND('Anexo 8'!H14*'Anexo 1'!$D$10,0) -> 0 | I14: =ROUND('Anexo 8'!I14*'Anexo 1'!$D$10,0) -> 0 | J14: =ROUND('Anexo 8'!J14*'Anexo 1'!$D$10,0) -> 0 | ... Z14: =ROUND('Anexo 8'!Z14*'Anexo 1'!$D$10,0) -> 0 | AA14: =SUM(C14:Z14) -> 0 | AB14: 6
A15: 46113 | B15: O | C15: =ROUND('Anexo 8'!C15*'Anexo 1'!$D$10,0) -> 0 | D15: =ROUND('Anexo 8'!D15*'Anexo 1'!$D$10,0) -> 0 | E15: =ROUND('Anexo 8'!E15*'Anexo 1'!$D$10,0) -> 0 | F15: =ROUND('Anexo 8'!F15*'Anexo 1'!$D$10,0) -> 0 | G15: =ROUND('Anexo 8'!G15*'Anexo 1'!$D$10,0) -> 0 | H15: =ROUND('Anexo 8'!H15*'Anexo 1'!$D$10,0) -> 0 | I15: =ROUND('Anexo 8'!I15*'Anexo 1'!$D$10,0) -> 0 | J15: =ROUND('Anexo 8'!J15*'Anexo 1'!$D$10,0) -> 0 | ... Z15: =ROUND('Anexo 8'!Z15*'Anexo 1'!$D$10,0) -> 0 | AA15: =SUM(C15:Z15) -> 0 | AB15: 20 | AC15: =+AA15*AB15+AA16*AB16+AA17*AB17 -> 0
B16: S | C16: =ROUND('Anexo 8'!C16*'Anexo 1'!$D$10,0) -> 0 | D16: =ROUND('Anexo 8'!D16*'Anexo 1'!$D$10,0) -> 0 | E16: =ROUND('Anexo 8'!E16*'Anexo 1'!$D$10,0) -> 0 | F16: =ROUND('Anexo 8'!F16*'Anexo 1'!$D$10,0) -> 0 | G16: =ROUND('Anexo 8'!G16*'Anexo 1'!$D$10,0) -> 0 | H16: =ROUND('Anexo 8'!H16*'Anexo 1'!$D$10,0) -> 0 | I16: =ROUND('Anexo 8'!I16*'Anexo 1'!$D$10,0) -> 0 | J16: =ROUND('Anexo 8'!J16*'Anexo 1'!$D$10,0) -> 0 | ... Z16: =ROUND('Anexo 8'!Z16*'Anexo 1'!$D$10,0) -> 0 | AA16: =SUM(C16:Z16) -> 0 | AB16: 4
B17: F | C17: =ROUND('Anexo 8'!C17*'Anexo 1'!$D$10,0) -> 0 | D17: =ROUND('Anexo 8'!D17*'Anexo 1'!$D$10,0) -> 0 | E17: =ROUND('Anexo 8'!E17*'Anexo 1'!$D$10,0) -> 0 | F17: =ROUND('Anexo 8'!F17*'Anexo 1'!$D$10,0) -> 0 | G17: =ROUND('Anexo 8'!G17*'Anexo 1'!$D$10,0) -> 0 | H17: =ROUND('Anexo 8'!H17*'Anexo 1'!$D$10,0) -> 0 | I17: =ROUND('Anexo 8'!I17*'Anexo 1'!$D$10,0) -> 0 | J17: =ROUND('Anexo 8'!J17*'Anexo 1'!$D$10,0) -> 0 | ... Z17: =ROUND('Anexo 8'!Z17*'Anexo 1'!$D$10,0) -> 0 | AA17: =SUM(C17:Z17) -> 0 | AB17: 6
A18: 46143 | B18: O | C18: =ROUND('Anexo 8'!C18*'Anexo 1'!$D$10,0) -> 0 | D18: =ROUND('Anexo 8'!D18*'Anexo 1'!$D$10,0) -> 0 | E18: =ROUND('Anexo 8'!E18*'Anexo 1'!$D$10,0) -> 0 | F18: =ROUND('Anexo 8'!F18*'Anexo 1'!$D$10,0) -> 0 | G18: =ROUND('Anexo 8'!G18*'Anexo 1'!$D$10,0) -> 0 | H18: =ROUND('Anexo 8'!H18*'Anexo 1'!$D$10,0) -> 0 | I18: =ROUND('Anexo 8'!I18*'Anexo 1'!$D$10,0) -> 0 | J18: =ROUND('Anexo 8'!J18*'Anexo 1'!$D$10,0) -> 0 | ... Z18: =ROUND('Anexo 8'!Z18*'Anexo 1'!$D$10,0) -> 0 | AA18: =SUM(C18:Z18) -> 0 | AB18: 19 | AC18: =+AA18*AB18+AA19*AB19+AA20*AB20 -> 0
B19: S | C19: =ROUND('Anexo 8'!C19*'Anexo 1'!$D$10,0) -> 0 | D19: =ROUND('Anexo 8'!D19*'Anexo 1'!$D$10,0) -> 0 | E19: =ROUND('Anexo 8'!E19*'Anexo 1'!$D$10,0) -> 0 | F19: =ROUND('Anexo 8'!F19*'Anexo 1'!$D$10,0) -> 0 | G19: =ROUND('Anexo 8'!G19*'Anexo 1'!$D$10,0) -> 0 | H19: =ROUND('Anexo 8'!H19*'Anexo 1'!$D$10,0) -> 0 | I19: =ROUND('Anexo 8'!I19*'Anexo 1'!$D$10,0) -> 0 | J19: =ROUND('Anexo 8'!J19*'Anexo 1'!$D$10,0) -> 0 | ... Z19: =ROUND('Anexo 8'!Z19*'Anexo 1'!$D$10,0) -> 0 | AA19: =SUM(C19:Z19) -> 0 | AB19: 5
B20: F | C20: =ROUND('Anexo 8'!C20*'Anexo 1'!$D$10,0) -> 0 | D20: =ROUND('Anexo 8'!D20*'Anexo 1'!$D$10,0) -> 0 | E20: =ROUND('Anexo 8'!E20*'Anexo 1'!$D$10,0) -> 0 | F20: =ROUND('Anexo 8'!F20*'Anexo 1'!$D$10,0) -> 0 | G20: =ROUND('Anexo 8'!G20*'Anexo 1'!$D$10,0) -> 0 | H20: =ROUND('Anexo 8'!H20*'Anexo 1'!$D$10,0) -> 0 | I20: =ROUND('Anexo 8'!I20*'Anexo 1'!$D$10,0) -> 0 | J20: =ROUND('Anexo 8'!J20*'Anexo 1'!$D$10,0) -> 0 | ... Z20: =ROUND('Anexo 8'!Z20*'Anexo 1'!$D$10,0) -> 0 | AA20: =SUM(C20:Z20) -> 0 | AB20: 7
A21: 46174 | B21: O | C21: =ROUND('Anexo 8'!C21*'Anexo 1'!$D$10,0) -> 0 | D21: =ROUND('Anexo 8'!D21*'Anexo 1'!$D$10,0) -> 0 | E21: =ROUND('Anexo 8'!E21*'Anexo 1'!$D$10,0) -> 0 | F21: =ROUND('Anexo 8'!F21*'Anexo 1'!$D$10,0) -> 0 | G21: =ROUND('Anexo 8'!G21*'Anexo 1'!$D$10,0) -> 0 | H21: =ROUND('Anexo 8'!H21*'Anexo 1'!$D$10,0) -> 0 | I21: =ROUND('Anexo 8'!I21*'Anexo 1'!$D$10,0) -> 0 | J21: =ROUND('Anexo 8'!J21*'Anexo 1'!$D$10,0) -> 0 | ... Z21: =ROUND('Anexo 8'!Z21*'Anexo 1'!$D$10,0) -> 0 | AA21: =SUM(C21:Z21) -> 0 | AB21: 19 | AC21: =+AA21*AB21+AA22*AB22+AA23*AB23 -> 0
B22: S | C22: =ROUND('Anexo 8'!C22*'Anexo 1'!$D$10,0) -> 0 | D22: =ROUND('Anexo 8'!D22*'Anexo 1'!$D$10,0) -> 0 | E22: =ROUND('Anexo 8'!E22*'Anexo 1'!$D$10,0) -> 0 | F22: =ROUND('Anexo 8'!F22*'Anexo 1'!$D$10,0) -> 0 | G22: =ROUND('Anexo 8'!G22*'Anexo 1'!$D$10,0) -> 0 | H22: =ROUND('Anexo 8'!H22*'Anexo 1'!$D$10,0) -> 0 | I22: =ROUND('Anexo 8'!I22*'Anexo 1'!$D$10,0) -> 0 | J22: =ROUND('Anexo 8'!J22*'Anexo 1'!$D$10,0) -> 0 | ... Z22: =ROUND('Anexo 8'!Z22*'Anexo 1'!$D$10,0) -> 0 | AA22: =SUM(C22:Z22) -> 0 | AB22: 4
B23: F | C23: =ROUND('Anexo 8'!C23*'Anexo 1'!$D$10,0) -> 0 | D23: =ROUND('Anexo 8'!D23*'Anexo 1'!$D$10,0) -> 0 | E23: =ROUND('Anexo 8'!E23*'Anexo 1'!$D$10,0) -> 0 | F23: =ROUND('Anexo 8'!F23*'Anexo 1'!$D$10,0) -> 0 | G23: =ROUND('Anexo 8'!G23*'Anexo 1'!$D$10,0) -> 0 | H23: =ROUND('Anexo 8'!H23*'Anexo 1'!$D$10,0) -> 0 | I23: =ROUND('Anexo 8'!I23*'Anexo 1'!$D$10,0) -> 0 | J23: =ROUND('Anexo 8'!J23*'Anexo 1'!$D$10,0) -> 0 | ... Z23: =ROUND('Anexo 8'!Z23*'Anexo 1'!$D$10,0) -> 0 | AA23: =SUM(C23:Z23) -> 0 | AB23: 7
A24: 46204 | B24: O | C24: =ROUND('Anexo 8'!C24*'Anexo 1'!$D$10,0) -> 0 | D24: =ROUND('Anexo 8'!D24*'Anexo 1'!$D$10,0) -> 0 | E24: =ROUND('Anexo 8'!E24*'Anexo 1'!$D$10,0) -> 0 | F24: =ROUND('Anexo 8'!F24*'Anexo 1'!$D$10,0) -> 0 | G24: =ROUND('Anexo 8'!G24*'Anexo 1'!$D$10,0) -> 0 | H24: =ROUND('Anexo 8'!H24*'Anexo 1'!$D$10,0) -> 0 | I24: =ROUND('Anexo 8'!I24*'Anexo 1'!$D$10,0) -> 0 | J24: =ROUND('Anexo 8'!J24*'Anexo 1'!$D$10,0) -> 0 | ... Z24: =ROUND('Anexo 8'!Z24*'Anexo 1'!$D$10,0) -> 0 | AA24: =SUM(C24:Z24) -> 0 | AB24: 22 | AC24: =+AA24*AB24+AA25*AB25+AA26*AB26 -> 0
B25: S | C25: =ROUND('Anexo 8'!C25*'Anexo 1'!$D$10,0) -> 0 | D25: =ROUND('Anexo 8'!D25*'Anexo 1'!$D$10,0) -> 0 | E25: =ROUND('Anexo 8'!E25*'Anexo 1'!$D$10,0) -> 0 | F25: =ROUND('Anexo 8'!F25*'Anexo 1'!$D$10,0) -> 0 | G25: =ROUND('Anexo 8'!G25*'Anexo 1'!$D$10,0) -> 0 | H25: =ROUND('Anexo 8'!H25*'Anexo 1'!$D$10,0) -> 0 | I25: =ROUND('Anexo 8'!I25*'Anexo 1'!$D$10,0) -> 0 | J25: =ROUND('Anexo 8'!J25*'Anexo 1'!$D$10,0) -> 0 | ... Z25: =ROUND('Anexo 8'!Z25*'Anexo 1'!$D$10,0) -> 0 | AA25: =SUM(C25:Z25) -> 0 | AB25: 4
B26: F | C26: =ROUND('Anexo 8'!C26*'Anexo 1'!$D$10,0) -> 0 | D26: =ROUND('Anexo 8'!D26*'Anexo 1'!$D$10,0) -> 0 | E26: =ROUND('Anexo 8'!E26*'Anexo 1'!$D$10,0) -> 0 | F26: =ROUND('Anexo 8'!F26*'Anexo 1'!$D$10,0) -> 0 | G26: =ROUND('Anexo 8'!G26*'Anexo 1'!$D$10,0) -> 0 | H26: =ROUND('Anexo 8'!H26*'Anexo 1'!$D$10,0) -> 0 | I26: =ROUND('Anexo 8'!I26*'Anexo 1'!$D$10,0) -> 0 | J26: =ROUND('Anexo 8'!J26*'Anexo 1'!$D$10,0) -> 0 | ... Z26: =ROUND('Anexo 8'!Z26*'Anexo 1'!$D$10,0) -> 0 | AA26: =SUM(C26:Z26) -> 0 | AB26: 5
A27: 46235 | B27: O | C27: =ROUND('Anexo 8'!C27*'Anexo 1'!$D$10,0) -> 0 | D27: =ROUND('Anexo 8'!D27*'Anexo 1'!$D$10,0) -> 0 | E27: =ROUND('Anexo 8'!E27*'Anexo 1'!$D$10,0) -> 0 | F27: =ROUND('Anexo 8'!F27*'Anexo 1'!$D$10,0) -> 0 | G27: =ROUND('Anexo 8'!G27*'Anexo 1'!$D$10,0) -> 0 | H27: =ROUND('Anexo 8'!H27*'Anexo 1'!$D$10,0) -> 0 | I27: =ROUND('Anexo 8'!I27*'Anexo 1'!$D$10,0) -> 0 | J27: =ROUND('Anexo 8'!J27*'Anexo 1'!$D$10,0) -> 0 | ... Z27: =ROUND('Anexo 8'!Z27*'Anexo 1'!$D$10,0) -> 0 | AA27: =SUM(C27:Z27) -> 0 | AB27: 19 | AC27: =+AA27*AB27+AA28*AB28+AA29*AB29 -> 0
B28: S | C28: =ROUND('Anexo 8'!C28*'Anexo 1'!$D$10,0) -> 0 | D28: =ROUND('Anexo 8'!D28*'Anexo 1'!$D$10,0) -> 0 | E28: =ROUND('Anexo 8'!E28*'Anexo 1'!$D$10,0) -> 0 | F28: =ROUND('Anexo 8'!F28*'Anexo 1'!$D$10,0) -> 0 | G28: =ROUND('Anexo 8'!G28*'Anexo 1'!$D$10,0) -> 0 | H28: =ROUND('Anexo 8'!H28*'Anexo 1'!$D$10,0) -> 0 | I28: =ROUND('Anexo 8'!I28*'Anexo 1'!$D$10,0) -> 0 | J28: =ROUND('Anexo 8'!J28*'Anexo 1'!$D$10,0) -> 0 | ... Z28: =ROUND('Anexo 8'!Z28*'Anexo 1'!$D$10,0) -> 0 | AA28: =SUM(C28:Z28) -> 0 | AB28: 5
B29: F | C29: =ROUND('Anexo 8'!C29*'Anexo 1'!$D$10,0) -> 0 | D29: =ROUND('Anexo 8'!D29*'Anexo 1'!$D$10,0) -> 0 | E29: =ROUND('Anexo 8'!E29*'Anexo 1'!$D$10,0) -> 0 | F29: =ROUND('Anexo 8'!F29*'Anexo 1'!$D$10,0) -> 0 | G29: =ROUND('Anexo 8'!G29*'Anexo 1'!$D$10,0) -> 0 | H29: =ROUND('Anexo 8'!H29*'Anexo 1'!$D$10,0) -> 0 | I29: =ROUND('Anexo 8'!I29*'Anexo 1'!$D$10,0) -> 0 | J29: =ROUND('Anexo 8'!J29*'Anexo 1'!$D$10,0) -> 0 | ... Z29: =ROUND('Anexo 8'!Z29*'Anexo 1'!$D$10,0) -> 0 | AA29: =SUM(C29:Z29) -> 0 | AB29: 7
A30: 46266 | B30: O | C30: =ROUND('Anexo 8'!C30*'Anexo 1'!$D$10,0) -> 0 | D30: =ROUND('Anexo 8'!D30*'Anexo 1'!$D$10,0) -> 0 | E30: =ROUND('Anexo 8'!E30*'Anexo 1'!$D$10,0) -> 0 | F30: =ROUND('Anexo 8'!F30*'Anexo 1'!$D$10,0) -> 0 | G30: =ROUND('Anexo 8'!G30*'Anexo 1'!$D$10,0) -> 0 | H30: =ROUND('Anexo 8'!H30*'Anexo 1'!$D$10,0) -> 0 | I30: =ROUND('Anexo 8'!I30*'Anexo 1'!$D$10,0) -> 0 | J30: =ROUND('Anexo 8'!J30*'Anexo 1'!$D$10,0) -> 0 | ... Z30: =ROUND('Anexo 8'!Z30*'Anexo 1'!$D$10,0) -> 0 | AA30: =SUM(C30:Z30) -> 0 | AB30: 22 | AC30: =+AA30*AB30+AA31*AB31+AA32*AB32 -> 0
B31: S | C31: =ROUND('Anexo 8'!C31*'Anexo 1'!$D$10,0) -> 0 | D31: =ROUND('Anexo 8'!D31*'Anexo 1'!$D$10,0) -> 0 | E31: =ROUND('Anexo 8'!E31*'Anexo 1'!$D$10,0) -> 0 | F31: =ROUND('Anexo 8'!F31*'Anexo 1'!$D$10,0) -> 0 | G31: =ROUND('Anexo 8'!G31*'Anexo 1'!$D$10,0) -> 0 | H31: =ROUND('Anexo 8'!H31*'Anexo 1'!$D$10,0) -> 0 | I31: =ROUND('Anexo 8'!I31*'Anexo 1'!$D$10,0) -> 0 | J31: =ROUND('Anexo 8'!J31*'Anexo 1'!$D$10,0) -> 0 | ... Z31: =ROUND('Anexo 8'!Z31*'Anexo 1'!$D$10,0) -> 0 | AA31: =SUM(C31:Z31) -> 0 | AB31: 4
B32: F | C32: =ROUND('Anexo 8'!C32*'Anexo 1'!$D$10,0) -> 0 | D32: =ROUND('Anexo 8'!D32*'Anexo 1'!$D$10,0) -> 0 | E32: =ROUND('Anexo 8'!E32*'Anexo 1'!$D$10,0) -> 0 | F32: =ROUND('Anexo 8'!F32*'Anexo 1'!$D$10,0) -> 0 | G32: =ROUND('Anexo 8'!G32*'Anexo 1'!$D$10,0) -> 0 | H32: =ROUND('Anexo 8'!H32*'Anexo 1'!$D$10,0) -> 0 | I32: =ROUND('Anexo 8'!I32*'Anexo 1'!$D$10,0) -> 0 | J32: =ROUND('Anexo 8'!J32*'Anexo 1'!$D$10,0) -> 0 | ... Z32: =ROUND('Anexo 8'!Z32*'Anexo 1'!$D$10,0) -> 0 | AA32: =SUM(C32:Z32) -> 0 | AB32: 4
A33: 46296 | B33: O | C33: =ROUND('Anexo 8'!C33*'Anexo 1'!$D$10,0) -> 0 | D33: =ROUND('Anexo 8'!D33*'Anexo 1'!$D$10,0) -> 0 | E33: =ROUND('Anexo 8'!E33*'Anexo 1'!$D$10,0) -> 0 | F33: =ROUND('Anexo 8'!F33*'Anexo 1'!$D$10,0) -> 0 | G33: =ROUND('Anexo 8'!G33*'Anexo 1'!$D$10,0) -> 0 | H33: =ROUND('Anexo 8'!H33*'Anexo 1'!$D$10,0) -> 0 | I33: =ROUND('Anexo 8'!I33*'Anexo 1'!$D$10,0) -> 0 | J33: =ROUND('Anexo 8'!J33*'Anexo 1'!$D$10,0) -> 0 | ... Z33: =ROUND('Anexo 8'!Z33*'Anexo 1'!$D$10,0) -> 0 | AA33: =SUM(C33:Z33) -> 0 | AB33: 21 | AC33: =+AA33*AB33+AA34*AB34+AA35*AB35 -> 0
B34: S | C34: =ROUND('Anexo 8'!C34*'Anexo 1'!$D$10,0) -> 0 | D34: =ROUND('Anexo 8'!D34*'Anexo 1'!$D$10,0) -> 0 | E34: =ROUND('Anexo 8'!E34*'Anexo 1'!$D$10,0) -> 0 | F34: =ROUND('Anexo 8'!F34*'Anexo 1'!$D$10,0) -> 0 | G34: =ROUND('Anexo 8'!G34*'Anexo 1'!$D$10,0) -> 0 | H34: =ROUND('Anexo 8'!H34*'Anexo 1'!$D$10,0) -> 0 | I34: =ROUND('Anexo 8'!I34*'Anexo 1'!$D$10,0) -> 0 | J34: =ROUND('Anexo 8'!J34*'Anexo 1'!$D$10,0) -> 0 | ... Z34: =ROUND('Anexo 8'!Z34*'Anexo 1'!$D$10,0) -> 0 | AA34: =SUM(C34:Z34) -> 0 | AB34: 5
B35: F | C35: =ROUND('Anexo 8'!C35*'Anexo 1'!$D$10,0) -> 0 | D35: =ROUND('Anexo 8'!D35*'Anexo 1'!$D$10,0) -> 0 | E35: =ROUND('Anexo 8'!E35*'Anexo 1'!$D$10,0) -> 0 | F35: =ROUND('Anexo 8'!F35*'Anexo 1'!$D$10,0) -> 0 | G35: =ROUND('Anexo 8'!G35*'Anexo 1'!$D$10,0) -> 0 | H35: =ROUND('Anexo 8'!H35*'Anexo 1'!$D$10,0) -> 0 | I35: =ROUND('Anexo 8'!I35*'Anexo 1'!$D$10,0) -> 0 | J35: =ROUND('Anexo 8'!J35*'Anexo 1'!$D$10,0) -> 0 | ... Z35: =ROUND('Anexo 8'!Z35*'Anexo 1'!$D$10,0) -> 0 | AA35: =SUM(C35:Z35) -> 0 | AB35: 5
A36: 46327 | B36: O | C36: =ROUND('Anexo 8'!C36*'Anexo 1'!$D$10,0) -> 0 | D36: =ROUND('Anexo 8'!D36*'Anexo 1'!$D$10,0) -> 0 | E36: =ROUND('Anexo 8'!E36*'Anexo 1'!$D$10,0) -> 0 | F36: =ROUND('Anexo 8'!F36*'Anexo 1'!$D$10,0) -> 0 | G36: =ROUND('Anexo 8'!G36*'Anexo 1'!$D$10,0) -> 0 | H36: =ROUND('Anexo 8'!H36*'Anexo 1'!$D$10,0) -> 0 | I36: =ROUND('Anexo 8'!I36*'Anexo 1'!$D$10,0) -> 0 | J36: =ROUND('Anexo 8'!J36*'Anexo 1'!$D$10,0) -> 0 | ... Z36: =ROUND('Anexo 8'!Z36*'Anexo 1'!$D$10,0) -> 0 | AA36: =SUM(C36:Z36) -> 0 | AB36: 19 | AC36: =+AA36*AB36+AA37*AB37+AA38*AB38 -> 0
B37: S | C37: =ROUND('Anexo 8'!C37*'Anexo 1'!$D$10,0) -> 0 | D37: =ROUND('Anexo 8'!D37*'Anexo 1'!$D$10,0) -> 0 | E37: =ROUND('Anexo 8'!E37*'Anexo 1'!$D$10,0) -> 0 | F37: =ROUND('Anexo 8'!F37*'Anexo 1'!$D$10,0) -> 0 | G37: =ROUND('Anexo 8'!G37*'Anexo 1'!$D$10,0) -> 0 | H37: =ROUND('Anexo 8'!H37*'Anexo 1'!$D$10,0) -> 0 | I37: =ROUND('Anexo 8'!I37*'Anexo 1'!$D$10,0) -> 0 | J37: =ROUND('Anexo 8'!J37*'Anexo 1'!$D$10,0) -> 0 | ... Z37: =ROUND('Anexo 8'!Z37*'Anexo 1'!$D$10,0) -> 0 | AA37: =SUM(C37:Z37) -> 0 | AB37: 4
B38: F | C38: =ROUND('Anexo 8'!C38*'Anexo 1'!$D$10,0) -> 0 | D38: =ROUND('Anexo 8'!D38*'Anexo 1'!$D$10,0) -> 0 | E38: =ROUND('Anexo 8'!E38*'Anexo 1'!$D$10,0) -> 0 | F38: =ROUND('Anexo 8'!F38*'Anexo 1'!$D$10,0) -> 0 | G38: =ROUND('Anexo 8'!G38*'Anexo 1'!$D$10,0) -> 0 | H38: =ROUND('Anexo 8'!H38*'Anexo 1'!$D$10,0) -> 0 | I38: =ROUND('Anexo 8'!I38*'Anexo 1'!$D$10,0) -> 0 | J38: =ROUND('Anexo 8'!J38*'Anexo 1'!$D$10,0) -> 0 | ... Z38: =ROUND('Anexo 8'!Z38*'Anexo 1'!$D$10,0) -> 0 | AA38: =SUM(C38:Z38) -> 0 | AB38: 7
A39: 46357 | B39: O | C39: =ROUND('Anexo 8'!C39*'Anexo 1'!$D$10,0) -> 0 | D39: =ROUND('Anexo 8'!D39*'Anexo 1'!$D$10,0) -> 0 | E39: =ROUND('Anexo 8'!E39*'Anexo 1'!$D$10,0) -> 0 | F39: =ROUND('Anexo 8'!F39*'Anexo 1'!$D$10,0) -> 0 | G39: =ROUND('Anexo 8'!G39*'Anexo 1'!$D$10,0) -> 0 | H39: =ROUND('Anexo 8'!H39*'Anexo 1'!$D$10,0) -> 0 | I39: =ROUND('Anexo 8'!I39*'Anexo 1'!$D$10,0) -> 0 | J39: =ROUND('Anexo 8'!J39*'Anexo 1'!$D$10,0) -> 0 | ... Z39: =ROUND('Anexo 8'!Z39*'Anexo 1'!$D$10,0) -> 0 | AA39: =SUM(C39:Z39) -> 0 | AB39: 21 | AC39: =+AA39*AB39+AA40*AB40+AA41*AB41 -> 0
B40: S | C40: =ROUND('Anexo 8'!C40*'Anexo 1'!$D$10,0) -> 0 | D40: =ROUND('Anexo 8'!D40*'Anexo 1'!$D$10,0) -> 0 | E40: =ROUND('Anexo 8'!E40*'Anexo 1'!$D$10,0) -> 0 | F40: =ROUND('Anexo 8'!F40*'Anexo 1'!$D$10,0) -> 0 | G40: =ROUND('Anexo 8'!G40*'Anexo 1'!$D$10,0) -> 0 | H40: =ROUND('Anexo 8'!H40*'Anexo 1'!$D$10,0) -> 0 | I40: =ROUND('Anexo 8'!I40*'Anexo 1'!$D$10,0) -> 0 | J40: =ROUND('Anexo 8'!J40*'Anexo 1'!$D$10,0) -> 0 | ... Z40: =ROUND('Anexo 8'!Z40*'Anexo 1'!$D$10,0) -> 0 | AA40: =SUM(C40:Z40) -> 0 | AB40: 4
B41: F | C41: =ROUND('Anexo 8'!C41*'Anexo 1'!$D$10,0) -> 0 | D41: =ROUND('Anexo 8'!D41*'Anexo 1'!$D$10,0) -> 0 | E41: =ROUND('Anexo 8'!E41*'Anexo 1'!$D$10,0) -> 0 | F41: =ROUND('Anexo 8'!F41*'Anexo 1'!$D$10,0) -> 0 | G41: =ROUND('Anexo 8'!G41*'Anexo 1'!$D$10,0) -> 0 | H41: =ROUND('Anexo 8'!H41*'Anexo 1'!$D$10,0) -> 0 | I41: =ROUND('Anexo 8'!I41*'Anexo 1'!$D$10,0) -> 0 | J41: =ROUND('Anexo 8'!J41*'Anexo 1'!$D$10,0) -> 0 | ... Z41: =ROUND('Anexo 8'!Z41*'Anexo 1'!$D$10,0) -> 0 | AA41: =SUM(C41:Z41) -> 0 | AB41: 6
A42: TOTAL AÑO | C42: =+SUM(C6:C41) -> 0 | D42: =+SUM(D6:D41) -> 0 | E42: =+SUM(E6:E41) -> 0 | F42: =+SUM(F6:F41) -> 0 | G42: =+SUM(G6:G41) -> 0 | H42: =+SUM(H6:H41) -> 0 | I42: =+SUM(I6:I41) -> 0 | J42: =+SUM(J6:J41) -> 0 | ... AC42: =+SUM(AC6:AC41) -> 0

Sheet Anexo 2
B3: ANEXO No 2 - PRODUCTO No. 2 - CURVA
B4: PAGUE LO CONTRATADO AÑO 2027
B5: PRECIO OFERTADO EN $ / kWh DE ENERO DE 2025
B8: MES | C8: ENERGIA SOLICITADA kWh/MES | D8: % OFERTADO ANUAL | E8: ENERGIA OFERTADA kWh/MES | F8: PRECIO OFERTADO ANUAL $/kWh
B10: 46388 | C10: =+'Anexo 9'!AC6 -> 65954714 | E10: =+'Cantidades Ofertadas Prod 2'!AC6 -> 0
B11: 46419 | C11: =+'Anexo 9'!AC9 -> 62974516 | E11: =+'Cantidades Ofertadas Prod 2'!AC9 -> 0
B12: 46447 | C12: =+'Anexo 9'!AC12 -> 67623091 | E12: =+'Cantidades Ofertadas Prod 2'!AC12 -> 0
B13: 46478 | C13: =+'Anexo 9'!AC15 -> 60519442 | E13: =+'Cantidades Ofertadas Prod 2'!AC15 -> 0
B14: 46508 | C14: =+'Anexo 9'!AC18 -> 63348286 | E14: =+'Cantidades Ofertadas Prod 2'!AC18 -> 0
B15: 46539 | C15: =+'Anexo 9'!AC21 -> 63361286 | E15: =+'Cantidades Ofertadas Prod 2'!AC21 -> 0
B16: 46569 | C16: =+'Anexo 9'!AC24 -> 66315125 | E16: =+'Cantidades Ofertadas Prod 2'!AC24 -> 0
B17: 46600 | C17: =+'Anexo 9'!AC27 -> 68019167 | E17: =+'Cantidades Ofertadas Prod 2'!AC27 -> 0
B18: 46631 | C18: =+'Anexo 9'!AC30 -> 69317302 | E18: =+'Cantidades Ofertadas Prod 2'!AC30 -> 0
B19: 46661 | C19: =+'Anexo 9'!AC33 -> 68101844 | E19: =+'Cantidades Ofertadas Prod 2'!AC33 -> 0
B20: 46692 | C20: =+'Anexo 9'!AC36 -> 63784834 | E20: =+'Cantidades Ofertadas Prod 2'!AC36 -> 0
B21: 46722 | C21: =+'Anexo 9'!AC39 -> 70600381 | E21: =+'Cantidades Ofertadas Prod 2'!AC39 -> 0
B22: TOTAL | C22: =+SUM(C10:C21) -> 789919988 | E22: =SUM(E10:E21) -> 0 | F22: =+F10 -> 0
B23: *Solo se debe ingresar valores en las celdas en color Naranja
B24: * Se debe ofertar un unico % para todos los meses del año.
B25: * Los % ofertados se aplicaran a las curvas de carga de la hoja "Anexo 9".
B26: * La energia ofertada se calcula de manera automatica en la hoja "Cantidades Ofertadas Prod2"
B27: * Se debe ofertar un unico precio por producto.
B28: * Para ofertas planas se debe diligenciar el anexo 2A, con un tope horario de 20.000 kWh
B32: ____________________________________________
B33: Firma del Representante Legal
B34: o Apoderado General (Responsable del negocio)

Sheet Anexo 2A
B3: ANEXO No 2A - PRODUCTO No. 2 - OFERTA PLANA
B4: PAGUE LO CONTRATADO AÑO 2027
B5: PRECIO OFERTADO EN $ / kWh DE ENERO DE 2025
B8: MES | C8: ENERGIA MAXIMA A OFERTAR kWh/MES | D8: kWh OFERTADO | E8: ENERGIA OFERTADA kWh/MES | F8: PRECIO OFERTADO ANUAL $/kWh
A9: 20000
A10: 31 | B10: 46388 | C10: =+$A$9*A10*24 -> 14880000 | E10: =+$D$10*A10*24 -> 0
A11: 28 | B11: 46419 | C11: =+$A$9*A11*24 -> 13440000 | E11: =+$D$10*A11*24 -> 0
A12: 31 | B12: 46447 | C12: =+$A$9*A12*24 -> 14880000 | E12: =+$D$10*A12*24 -> 0
A13: 30 | B13: 46478 | C13: =+$A$9*A13*24 -> 14400000 | E13: =+$D$10*A13*24 -> 0
A14: 31 | B14: 46508 | C14: =+$A$9*A14*24 -> 14880000 | E14: =+$D$10*A14*24 -> 0
A15: 30 | B15: 46539 | C15: =+$A$9*A15*24 -> 14400000 | E15: =+$D$10*A15*24 -> 0
A16: 31 | B16: 46569 | C16: =+$A$9*A16*24 -> 14880000 | E16: =+$D$10*A16*24 -> 0
A17: 31 | B17: 46600 | C17: =+$A$9*A17*24 -> 14880000 | E17: =+$D$10*A17*24 -> 0
A18: 30 | B18: 46631 | C18: =+$A$9*A18*24 -> 14400000 | E18: =+$D$10*A18*24 -> 0
A19: 31 | B19: 46661 | C19: =+$A$9*A19*24 -> 14880000 | E19: =+$D$10*A19*24 -> 0
A20: 30 | B20: 46692 | C20: =+$A$9*A20*24 -> 14400000 | E20: =+$D$10*A20*24 -> 0
A21: 31 | B21: 46722 | C21: =+$A$9*A21*24 -> 14880000 | E21: =+$D$10*A21*24 -> 0
B22: TOTAL | C22: =+SUM(C10:C21) -> 175200000 | E22: =SUM(E10:E21) -> 0 | F22: =+F10 -> 0
B23: *Solo se debe ingresar valores en las celdas en color Naranja
B24: * Se debe oferta un valor de kWh el cual se aplica para todas las horas del año, con un tope horario de 20.000 kWh
B25: * Se debe ofertar un unico precio por producto.
B26: * A las ofertas planas al momento de la evaluación se le adicionarán 5 $/kWh al precio ofertado; con el fin de hacerlas comparables con las Ofertas que siguen la curva
B29: ____________________________________________
B30: Firma del Representante Legal
B31: o Apoderado General (Responsable del negocio)

Sheet Anexo 9
A1: CURVAS REQUERIDAS PRODUCTO 2 AÑO 2027 MODALIDAD PAGUE LO CONTRATADO - kWh
A4: Periodo | B4: Tipo de día | C4: H01 | D4: H02 | E4: H03 | F4: H04 | G4: H05 | H4: H06 | I4: H07 | J4: H08 | K4: H09 | L4: H10 | M4: H11 | N4: H12 | O4: H13 | P4: H14 | Q4: H15 | R4: H16 | S4: H17 | T4: H18 | U4: H19 | V4: H20 | W4: H21 | X4: H22 | Y4: H23 | Z4: H24 | AA4: TOTAL DÍA | AB4: Días/ | AC4: TOTAL MES
AB5: mes
A6: 46388 | B6: O | C6: 72823 | D6: 68815 | E6: 66032 | F6: 64506 | G6: 64966 | H6: 66584 | I6: 67774 | J6: 95414 | K6: 102983 | L6: 108084 | M6: 113343 | N6: 119706 | O6: 121218 | P6: 122077 | Q6: 122736 | R6: 122995 | S6: 121243 | T6: 88230 | U6: 91818 | V6: 92972 | W6: 89586 | X6: 85072 | Y6: 77357 | Z6: 69044 | AA6: =SUM(C6:Z6) -> 2215378 | AB6: 19 | AC6: =+AA6*AB6+AA7*AB7+AA8*AB8 -> 65954714
B7: S | C7: 70933 | D7: 66358 | E7: 63390 | F7: 61367 | G7: 61200 | H7: 63019 | I7: 64375 | J7: 91127 | K7: 99285 | L7: 105015 | M7: 108449 | N7: 113542 | O7: 115028 | P7: 114556 | Q7: 114123 | R7: 114518 | S7: 114914 | T7: 85842 | U7: 90325 | V7: 91482 | W7: 86708 | X7: 80670 | Y7: 73752 | Z7: 66916 | AA7: =SUM(C7:Z7) -> 2116894 | AB7: 5
B8: F | C8: 68842 | D8: 64442 | E8: 62687 | F8: 60523 | G8: 59434 | H8: 59954 | I8: 57640 | J8: 79879 | K8: 85823 | L8: 90872 | M8: 94419 | N8: 98520 | O8: 102032 | P8: 102524 | Q8: 101814 | R8: 101330 | S8: 101445 | T8: 72315 | U8: 76202 | V8: 78495 | W8: 76330 | X8: 72544 | Y8: 67719 | Z8: 61081 | AA8: =SUM(C8:Z8) -> 1896866 | AB8: 7
A9: 46419 | B9: O | C9: 74983 | D9: 70603 | E9: 68254 | F9: 66915 | G9: 67575 | H9: 69713 | I9: 71496 | J9: 99489 | K9: 107509 | L9: 112024 | M9: 116514 | N9: 122115 | O9: 122260 | P9: 123175 | Q9: 124785 | R9: 124465 | S9: 123742 | T9: 89369 | U9: 91617 | V9: 93982 | W9: 90980 | X9: 85510 | Y9: 78299 | Z9: 70354 | AA9: =SUM(C9:Z9) -> 2265728 | AB9: 20 | AC9: =+AA9*AB9+AA10*AB10+AA11*AB11 -> 62974516
B10: S | C10: 76091 | D10: 71515 | E10: 68671 | F10: 66767 | G10: 66399 | H10: 67114 | I10: 69494 | J10: 95829 | K10: 105602 | L10: 110820 | M10: 114665 | N10: 120331 | O10: 121847 | P10: 121285 | Q10: 120710 | R10: 120243 | S10: 120807 | T10: 91232 | U10: 93781 | V10: 96259 | W10: 92002 | X10: 87103 | Y10: 81630 | Z10: 73798 | AA10: =SUM(C10:Z10) -> 2253995 | AB10: 4
B11: F | C11: 79015 | D11: 74432 | E11: 71829 | F11: 69692 | G11: 68714 | H11: 68725 | I11: 66521 | J11: 90350 | K11: 98469 | L11: 105223 | M11: 108585 | N11: 109523 | O11: 115337 | P11: 114744 | Q11: 113514 | R11: 111928 | S11: 112600 | T11: 84068 | U11: 86609 | V11: 90393 | W11: 88671 | X11: 84251 | Y11: 77932 | Z11: 69869 | AA11: =SUM(C11:Z11) -> 2160994 | AB11: 4
A12: 46447 | B12: O | C12: 73388 | D12: 69672 | E12: 67896 | F12: 66723 | G12: 67730 | H12: 70639 | I12: 72492 | J12: 100110 | K12: 107844 | L12: 112406 | M12: 116308 | N12: 121163 | O12: 120136 | P12: 121199 | Q12: 123132 | R12: 123145 | S12: 121719 | T12: 88444 | U12: 91705 | V12: 93679 | W12: 90760 | X12: 85488 | Y12: 77399 | Z12: 69361 | AA12: =SUM(C12:Z12) -> 2252538 | AB12: 20 | AC12: =+AA12*AB12+AA13*AB13+AA14*AB14 -> 67623091
B13: S | C13: 74270 | D13: 69675 | E13: 67662 | F13: 66604 | G13: 65816 | H13: 67413 | I13: 67400 | J13: 94914 | K13: 103148 | L13: 108627 | M13: 112323 | N13: 115742 | O13: 115614 | P13: 114252 | Q13: 113649 | R13: 113373 | S13: 111924 | T13: 82499 | U13: 84796 | V13: 85748 | W13: 82523 | X13: 78709 | Y13: 73533 | Z13: 68128 | AA13: =SUM(C13:Z13) -> 2138342 | AB13: 4
B14: F | C14: 74111 | D14: 70075 | E14: 67974 | F14: 66331 | G14: 63932 | H14: 64570 | I14: 62852 | J14: 86543 | K14: 92773 | L14: 96719 | M14: 99344 | N14: 103697 | O14: 106956 | P14: 106345 | Q14: 104656 | R14: 104726 | S14: 104802 | T14: 75558 | U14: 78740 | V14: 80936 | W14: 79115 | X14: 76088 | Y14: 70412 | Z14: 65454 | AA14: =SUM(C14:Z14) -> 2002709 | AB14: 7
A15: 46478 | B15: O | C15: 67471 | D15: 64616 | E15: 62307 | F15: 61742 | G15: 61532 | H15: 63860 | I15: 65833 | J15: 92281 | K15: 99311 | L15: 104237 | M15: 108114 | N15: 113138 | O15: 111964 | P15: 113434 | Q15: 115656 | R15: 115863 | S15: 113801 | T15: 80005 | U15: 82021 | V15: 83020 | W15: 80754 | X15: 76616 | Y15: 69849 | Z15: 62878 | AA15: =SUM(C15:Z15) -> 2070303 | AB15: 22 | AC15: =+AA15*AB15+AA16*AB16+AA17*AB17 -> 60519442
B16: S | C16: 65110 | D16: 61937 | E16: 58719 | F16: 57229 | G16: 56713 | H16: 57485 | I16: 58047 | J16: 85323 | K16: 93559 | L16: 98942 | M16: 101821 | N16: 106870 | O16: 107190 | P16: 106852 | Q16: 106375 | R16: 106248 | S16: 106482 | T16: 76213 | U16: 78180 | V16: 78432 | W16: 74604 | X16: 71169 | Y16: 67266 | Z16: 61175 | AA16: =SUM(C16:Z16) -> 1941941 | AB16: 4
B17: F | C17: 66628 | D17: 63951 | E17: 60696 | F17: 58977 | G17: 57305 | H17: 56045 | I17: 55535 | J17: 79313 | K17: 85034 | L17: 90037 | M17: 92665 | N17: 96176 | O17: 98069 | P17: 97612 | Q17: 95586 | R17: 95838 | S17: 95679 | T17: 66361 | U17: 68741 | V17: 69758 | W17: 67893 | X17: 65198 | Y17: 62105 | Z17: 56051 | AA17: =SUM(C17:Z17) -> 1801253 | AB17: 4
A18: 46508 | B18: O | C18: 68129 | D18: 64771 | E18: 62556 | F18: 61654 | G18: 62135 | H18: 63510 | I18: 65826 | J18: 92175 | K18: 98649 | L18: 103058 | M18: 107667 | N18: 112709 | O18: 112325 | P18: 113270 | Q18: 114567 | R18: 114592 | S18: 112839 | T18: 79894 | U18: 83286 | V18: 84144 | W18: 80967 | X18: 77032 | Y18: 70075 | Z18: 63692 | AA18: =SUM(C18:Z18) -> 2069522 | AB18: 19 | AC18: =+AA18*AB18+AA19*AB19+AA20*AB20 -> 63348286
B19: S | C19: 71689 | D19: 68081 | E19: 65758 | F19: 64542 | G19: 63827 | H19: 63472 | I19: 65803 | J19: 92357 | K19: 101128 | L19: 107939 | M19: 110251 | N19: 114157 | O19: 113960 | P19: 112630 | Q19: 111223 | R19: 109993 | S19: 110212 | T19: 79907 | U19: 85281 | V19: 83931 | W19: 79890 | X19: 75671 | Y19: 70301 | Z19: 65095 | AA19: =SUM(C19:Z19) -> 2087098 | AB19: 4
B20: F | C20: 69323 | D20: 66134 | E20: 63550 | F20: 62581 | G20: 61451 | H20: 59585 | I20: 58760 | J20: 83501 | K20: 89309 | L20: 95321 | M20: 98282 | N20: 103284 | O20: 105138 | P20: 105916 | Q20: 103686 | R20: 114556 | S20: 102844 | T20: 73967 | U20: 78001 | V20: 79119 | W20: 77155 | X20: 74548 | Y20: 70433 | Z20: 63428 | AA20: =SUM(C20:Z20) -> 1959872 | AB20: 8
A21: 46539 | B21: O | C21: 68489 | D21: 64738 | E21: 63200 | F21: 62152 | G21: 62497 | H21: 64203 | I21: 66764 | J21: 92842 | K21: 99210 | L21: 103634 | M21: 108384 | N21: 113604 | O21: 113373 | P21: 113973 | Q21: 115812 | R21: 115695 | S21: 114100 | T21: 81869 | U21: 86127 | V21: 87528 | W21: 84214 | X21: 78903 | Y21: 70323 | Z21: 63340 | AA21: =SUM(C21:Z21) -> 2094974 | AB21: 21 | AC21: =+AA21*AB21+AA22*AB22+AA23*AB23 -> 63361286
B22: S | C22: 74083 | D22: 69284 | E22: 66716 | F22: 65211 | G22: 64113 | H22: 63637 | I22: 65317 | J22: 91146 | K22: 100554 | L22: 106021 | M22: 110088 | N22: 114029 | O22: 115209 | P22: 115346 | Q22: 115201 | R22: 115923 | S22: 116301 | T22: 87854 | U22: 93016 | V22: 92359 | W22: 87064 | X22: 82623 | Y22: 76501 | Z22: 69172 | AA22: =SUM(C22:Z22) -> 2156768 | AB22: 4
B23: F | C23: 75682 | D23: 71800 | E23: 69711 | F23: 68186 | G23: 67377 | H23: 67428 | I23: 66268 | J23: 92064 | K23: 99632 | L23: 104297 | M23: 108161 | N23: 112586 | O23: 113504 | P23: 113664 | Q23: 112965 | R23: 113224 | S23: 113059 | T23: 83546 | U23: 88751 | V23: 89590 | W23: 86998 | X23: 83092 | Y23: 76620 | Z23: 69747 | AA23: =SUM(C23:Z23) -> 2147952 | AB23: 5
A24: 46569 | B24: O | C24: 74054 | D24: 70071 | E24: 67771 | F24: 66313 | G24: 66544 | H24: 67702 | I24: 68963 | J24: 96599 | K24: 103981 | L24: 109210 | M24: 114110 | N24: 119509 | O24: 118799 | P24: 119701 | Q24: 121297 | R24: 121388 | S24: 119319 | T24: 86318 | U24: 90846 | V24: 92013 | W24: 88955 | X24: 84023 | Y24: 76363 | Z24: 69205 | AA24: =SUM(C24:Z24) -> 2213054 | AB24: 20 | AC24: =+AA24*AB24+AA25*AB25+AA26*AB26 -> 66315125
B25: S | C25: 65701 | D25: 62035 | E25: 59894 | F25: 58720 | G25: 57728 | H25: 57760 | I25: 59933 | J25: 88802 | K25: 97380 | L25: 101744 | M25: 105756 | N25: 109649 | O25: 109847 | P25: 108742 | Q25: 107840 | R25: 107846 | S25: 107489 | T25: 78665 | U25: 81849 | V25: 81880 | W25: 77098 | X25: 73864 | Y25: 68907 | Z25: 64220 | AA25: =SUM(C25:Z25) -> 1993349 | AB25: 5
B26: F | C26: 73800 | D26: 69823 | E26: 66801 | F26: 65276 | G26: 64171 | H26: 63482 | I26: 61812 | J26: 85861 | K26: 92502 | L26: 98406 | M26: 100996 | N26: 105345 | O26: 107865 | P26: 107563 | Q26: 105867 | R26: 105386 | S26: 104974 | T26: 76686 | U26: 80326 | V26: 82369 | W26: 80383 | X26: 77032 | Y26: 72010 | Z26: 65814 | AA26: =SUM(C26:Z26) -> 2014550 | AB26: 6
A27: 46600 | B27: O | C27: 73500 | D27: 70006 | E27: 68095 | F27: 66740 | G27: 67074 | H27: 69147 | I27: 70962 | J27: 97517 | K27: 104448 | L27: 109141 | M27: 113863 | N27: 119426 | O27: 119805 | P27: 121684 | Q27: 123253 | R27: 123261 | S27: 120957 | T27: 88143 | U27: 92804 | V27: 94171 | W27: 90589 | X27: 84755 | Y27: 76919 | Z27: 70373 | AA27: =SUM(C27:Z27) -> 2236633 | AB27: 21 | AC27: =+AA27*AB27+AA28*AB28+AA29*AB29 -> 68019167
B28: S | C28: 75706 | D28: 72599 | E28: 69892 | F28: 67519 | G28: 66230 | H28: 67215 | I28: 66654 | J28: 94930 | K28: 103779 | L28: 109366 | M28: 114050 | N28: 118192 | O28: 118754 | P28: 118794 | Q28: 118038 | R28: 117852 | S28: 116707 | T28: 87219 | U28: 91941 | V28: 90450 | W28: 86089 | X28: 82247 | Y28: 77068 | Z28: 71184 | AA28: =SUM(C28:Z28) -> 2202475 | AB28: 3
B29: F | C29: 76966 | D29: 72766 | E29: 69634 | F29: 67715 | G29: 66531 | H29: 65981 | I29: 63935 | J29: 89262 | K29: 95762 | L29: 100483 | M29: 103438 | N29: 107566 | O29: 110707 | P29: 110439 | Q29: 107845 | R29: 105802 | S29: 106107 | T29: 77152 | U29: 82431 | V29: 84494 | W29: 81661 | X29: 78008 | Y29: 72657 | Z29: 65865 | AA29: =SUM(C29:Z29) -> 2063207 | AB29: 7
A30: 46631 | B30: O | C30: 79183 | D30: 74700 | E30: 71916 | F30: 70646 | G30: 70404 | H30: 72632 | I30: 74750 | J30: 101987 | K30: 108836 | L30: 114331 | M30: 119551 | N30: 125338 | O30: 125965 | P30: 127340 | Q30: 129753 | R30: 130703 | S30: 128692 | T30: 94694 | U30: 99959 | V30: 99454 | W30: 95935 | X30: 90291 | Y30: 81670 | Z30: 74827 | AA30: =SUM(C30:Z30) -> 2363557 | AB30: 22 | AC30: =+AA30*AB30+AA31*AB31+AA32*AB32 -> 69317302
B31: S | C31: 81331 | D31: 75919 | E31: 73024 | F31: 71607 | G31: 70295 | H31: 68942 | I31: 70690 | J31: 99123 | K31: 108847 | L31: 114737 | M31: 119160 | N31: 124158 | O31: 124423 | P31: 124133 | Q31: 123436 | R31: 122778 | S31: 122936 | T31: 93337 | U31: 96711 | V31: 95270 | W31: 90425 | X31: 86898 | Y31: 81268 | Z31: 74621 | AA31: =SUM(C31:Z31) -> 2314069 | AB31: 4
B32: F | C32: 76557 | D32: 72474 | E32: 69651 | F32: 67631 | G32: 65687 | H32: 63842 | I32: 61665 | J32: 85431 | K32: 91949 | L32: 96992 | M32: 99740 | N32: 103459 | O32: 106176 | P32: 106252 | Q32: 104372 | R32: 104844 | S32: 104858 | T32: 75772 | U32: 82064 | V32: 81836 | W32: 79801 | X32: 76411 | Y32: 71992 | Z32: 66237 | AA32: =SUM(C32:Z32) -> 2015693 | AB32: 4
A33: 46661 | B33: O | C33: 74054 | D33: 70472 | E33: 68391 | F33: 66884 | G33: 67074 | H33: 68574 | I33: 70517 | J33: 96373 | K33: 102929 | L33: 107288 | M33: 111917 | N33: 117777 | O33: 118417 | P33: 119791 | Q33: 121673 | R33: 122404 | S33: 120945 | T33: 89287 | U33: 93845 | V33: 91750 | W33: 87355 | X33: 82244 | Y33: 75021 | Z33: 69294 | AA33: =SUM(C33:Z33) -> 2214276 | AB33: 20 | AC33: =+AA33*AB33+AA34*AB34+AA35*AB35 -> 68101844
B34: S | C34: 80833 | D34: 76812 | E34: 74228 | F34: 72176 | G34: 71594 | H34: 71708 | I34: 74865 | J34: 102246 | K34: 110846 | L34: 116994 | M34: 121764 | N34: 126318 | O34: 127627 | P34: 127910 | Q34: 127462 | R34: 126519 | S34: 125729 | T34: 98458 | U34: 105718 | V34: 103640 | W34: 98477 | X34: 92616 | Y34: 86898 | Z34: 78608 | AA34: =SUM(C34:Z34) -> 2400046 | AB34: 5
B35: F | C35: 72753 | D35: 69105 | E35: 65770 | F35: 63876 | G35: 62452 | H35: 60844 | I35: 59741 | J35: 83140 | K35: 88870 | L35: 94518 | M35: 97842 | N35: 101958 | O35: 105214 | P35: 104811 | Q35: 103902 | R35: 104554 | S35: 104472 | T35: 77219 | U35: 81503 | V35: 80170 | W35: 77913 | X35: 74538 | Y35: 70067 | Z35: 64117 | AA35: =SUM(C35:Z35) -> 1969349 | AB35: 6
A36: 46692 | B36: O | C36: 72435 | D36: 68825 | E36: 66681 | F36: 65754 | G36: 65994 | H36: 68262 | I36: 71031 | J36: 97672 | K36: 104258 | L36: 109052 | M36: 114357 | N36: 120290 | O36: 119922 | P36: 120419 | Q36: 123221 | R36: 121498 | S36: 120269 | T36: 89510 | U36: 96463 | V36: 94085 | W36: 90244 | X36: 84221 | Y36: 75713 | Z36: 68921 | AA36: =SUM(C36:Z36) -> 2229097 | AB36: 20 | AC36: =+AA36*AB36+AA37*AB37+AA38*AB38 -> 63784834
B37: S | C37: 71362 | D37: 67593 | E37: 65451 | F37: 63412 | G37: 63167 | H37: 61960 | I37: 62572 | J37: 88628 | K37: 96663 | L37: 102616 | M37: 105756 | N37: 110256 | O37: 110826 | P37: 108720 | Q37: 109196 | R37: 109413 | S37: 109453 | T37: 81828 | U37: 87249 | V37: 85955 | W37: 81810 | X37: 77424 | Y37: 71129 | Z37: 64600 | AA37: =SUM(C37:Z37) -> 2057039 | AB37: 4
B38: F | C38: 65990 | D38: 62752 | E38: 60178 | F38: 58123 | G38: 57534 | H38: 56039 | I38: 54577 | J38: 78455 | K38: 84222 | L38: 89494 | M38: 92296 | N38: 96247 | O38: 98969 | P38: 98932 | Q38: 97060 | R38: 95676 | S38: 96642 | T38: 68662 | U38: 75211 | V38: 75505 | W38: 73633 | X38: 70197 | Y38: 64656 | Z38: 58073 | AA38: =SUM(C38:Z38) -> 1829123 | AB38: 6
A39: 46722 | B39: O | C39: 79050 | D39: 74419 | E39: 71828 | F39: 69996 | G39: 70076 | H39: 71600 | I39: 72642 | J39: 100922 | K39: 108578 | L39: 114134 | M39: 118952 | N39: 125214 | O39: 125966 | P39: 126327 | Q39: 127876 | R39: 127215 | S39: 125106 | T39: 93000 | U39: 98711 | V39: 97645 | W39: 93579 | X39: 88805 | Y39: 81833 | Z39: 76050 | AA39: =SUM(C39:Z39) -> 2339524 | AB39: 22 | AC39: =+AA39*AB39+AA40*AB40+AA41*AB41 -> 70600381
B40: S | C40: 74311 | D40: 70945 | E40: 69029 | F40: 66795 | G40: 66128 | H40: 66333 | I40: 66036 | J40: 93054 | K40: 100916 | L40: 105356 | M40: 109654 | N40: 112696 | O40: 113160 | P40: 111198 | Q40: 110918 | R40: 109775 | S40: 109454 | T40: 81392 | U40: 86276 | V40: 82495 | W40: 77962 | X40: 73393 | Y40: 67562 | Z40: 64213 | AA40: =SUM(C40:Z40) -> 2089051 | AB40: 3
B41: F | C41: 79974 | D41: 75863 | E41: 73021 | F41: 70803 | G41: 69716 | H41: 68384 | I41: 66326 | J41: 90050 | K41: 96196 | L41: 101588 | M41: 105601 | N41: 109466 | O41: 112174 | P41: 112787 | Q41: 111952 | R41: 111513 | S41: 111958 | T41: 83756 | U41: 90167 | V41: 89237 | W41: 85697 | X41: 81086 | Y41: 76197 | Z41: 70438 | AA41: =SUM(C41:Z41) -> 2143950 | AB41: 6
A42: TOTAL AÑO | C42: =+SUM(C6:C41) -> 2638620 | D42: =+SUM(D6:D41) -> 2498078 | E42: =+SUM(E6:E41) -> 2408863 | F42: =+SUM(F6:F41) -> 2351688 | G42: =+SUM(G6:G41) -> 2331115 | H42: =+SUM(H6:H41) -> 2347363 | I42: =+SUM(I6:I41) -> 2365868 | J42: =+SUM(J6:J41) -> 3304709 | ... AC42: =+SUM(AC6:AC41) -> 789919988

Sheet Cantidades Ofertadas Prod 2
A1: CANTIDADES OFERTADAS PRODUCTO 2 AÑO 2027 MODALIDAD PAGUE LO CONTRATADO - kWh
A4: Periodo | B4: Tipo de día | C4: H01 | D4: H02 | E4: H03 | F4: H04 | G4: H05 | H4: H06 | I4: H07 | J4: H08 | K4: H09 | L4: H10 | M4: H11 | N4: H12 | O4: H13 | P4: H14 | Q4: H15 | R4: H16 | S4: H17 | T4: H18 | U4: H19 | V4: H20 | W4: H21 | X4: H22 | Y4: H23 | Z4: H24 | AA4: TOTAL DÍA | AB4: Días/ | AC4: TOTAL MES
AB5: mes
A6: 46388 | B6: O | C6: =ROUND('Anexo 9'!C6*'Anexo 2'!$D$10,0) -> 0 | D6: =ROUND('Anexo 9'!D6*'Anexo 2'!$D$10,0) -> 0 | E6: =ROUND('Anexo 9'!E6*'Anexo 2'!$D$10,0) -> 0 | F6: =ROUND('Anexo 9'!F6*'Anexo 2'!$D$10,0) -> 0 | G6: =ROUND('Anexo 9'!G6*'Anexo 2'!$D$10,0) -> 0 | H6: =ROUND('Anexo 9'!H6*'Anexo 2'!$D$10,0) -> 0 | I6: =ROUND('Anexo 9'!I6*'Anexo 2'!$D$10,0) -> 0 | J6: =ROUND('Anexo 9'!J6*'Anexo 2'!$D$10,0) -> 0 | ... Z6: =ROUND('Anexo 9'!Z6*'Anexo 2'!$D$10,0) -> 0 | AA6: =SUM(C6:Z6) -> 0 | AB6: 19 | AC6: =+AA6*AB6+AA7*AB7+AA8*AB8 -> 0
B7: S | C7: =ROUND('Anexo 9'!C7*'Anexo 2'!$D$10,0) -> 0 | D7: =ROUND('Anexo 9'!D7*'Anexo 2'!$D$10,0) -> 0 | E7: =ROUND('Anexo 9'!E7*'Anexo 2'!$D$10,0) -> 0 | F7: =ROUND('Anexo 9'!F7*'Anexo 2'!$D$10,0) -> 0 | G7: =ROUND('Anexo 9'!G7*'Anexo 2'!$D$10,0) -> 0 | H7: =ROUND('Anexo 9'!H7*'Anexo 2'!$D$10,0) -> 0 | I7: =ROUND('Anexo 9'!I7*'Anexo 2'!$D$10,0) -> 0 | J7: =ROUND('Anexo 9'!J7*'Anexo 2'!$D$10,0) -> 0 | ... Z7: =ROUND('Anexo 9'!Z7*'Anexo 2'!$D$10,0) -> 0 | AA7: =SUM(C7:Z7) -> 0 | AB7: 5
B8: F | C8: =ROUND('Anexo 9'!C8*'Anexo 2'!$D$10,0) -> 0 | D8: =ROUND('Anexo 9'!D8*'Anexo 2'!$D$10,0) -> 0 | E8: =ROUND('Anexo 9'!E8*'Anexo 2'!$D$10,0) -> 0 | F8: =ROUND('Anexo 9'!F8*'Anexo 2'!$D$10,0) -> 0 | G8: =ROUND('Anexo 9'!G8*'Anexo 2'!$D$10,0) -> 0 | H8: =ROUND('Anexo 9'!H8*'Anexo 2'!$D$10,0) -> 0 | I8: =ROUND('Anexo 9'!I8*'Anexo 2'!$D$10,0) -> 0 | J8: =ROUND('Anexo 9'!J8*'Anexo 2'!$D$10,0) -> 0 | ... Z8: =ROUND('Anexo 9'!Z8*'Anexo 2'!$D$10,0) -> 0 | AA8: =SUM(C8:Z8) -> 0 | AB8: 7
A9: 46419 | B9: O | C9: =ROUND('Anexo 9'!C9*'Anexo 2'!$D$10,0) -> 0 | D9: =ROUND('Anexo 9'!D9*'Anexo 2'!$D$10,0) -> 0 | E9: =ROUND('Anexo 9'!E9*'Anexo 2'!$D$10,0) -> 0 | F9: =ROUND('Anexo 9'!F9*'Anexo 2'!$D$10,0) -> 0 | G9: =ROUND('Anexo 9'!G9*'Anexo 2'!$D$10,0) -> 0 | H9: =ROUND('Anexo 9'!H9*'Anexo 2'!$D$10,0) -> 0 | I9: =ROUND('Anexo 9'!I9*'Anexo 2'!$D$10,0) -> 0 | J9: =ROUND('Anexo 9'!J9*'Anexo 2'!$D$10,0) -> 0 | ... Z9: =ROUND('Anexo 9'!Z9*'Anexo 2'!$D$10,0) -> 0 | AA9: =SUM(C9:Z9) -> 0 | AB9: 20 | AC9: =+AA9*AB9+AA10*AB10+AA11*AB11 -> 0
B10: S | C10: =ROUND('Anexo 9'!C10*'Anexo 2'!$D$10,0) -> 0 | D10: =ROUND('Anexo 9'!D10*'Anexo 2'!$D$10,0) -> 0 | E10: =ROUND('Anexo 9'!E10*'Anexo 2'!$D$10,0) -> 0 | F10: =ROUND('Anexo 9'!F10*'Anexo 2'!$D$10,0) -> 0 | G10: =ROUND('Anexo 9'!G10*'Anexo 2'!$D$10,0) -> 0 | H10: =ROUND('Anexo 9'!H10*'Anexo 2'!$D$10,0) -> 0 | I10: =ROUND('Anexo 9'!I10*'Anexo 2'!$D$10,0) -> 0 | J10: =ROUND('Anexo 9'!J10*'Anexo 2'!$D$10,0) -> 0 | ... Z10: =ROUND('Anexo 9'!Z10*'Anexo 2'!$D$10,0) -> 0 | AA10: =SUM(C10:Z10) -> 0 | AB10: 4
B11: F | C11: =ROUND('Anexo 9'!C11*'Anexo 2'!$D$10,0) -> 0 | D11: =ROUND('Anexo 9'!D11*'Anexo 2'!$D$10,0) -> 0 | E11: =ROUND('Anexo 9'!E11*'Anexo 2'!$D$10,0) -> 0 | F11: =ROUND('Anexo 9'!F11*'Anexo 2'!$D$10,0) -> 0 | G11: =ROUND('Anexo 9'!G11*'Anexo 2'!$D$10,0) -> 0 | H11: =ROUND('Anexo 9'!H11*'Anexo 2'!$D$10,0) -> 0 | I11: =ROUND('Anexo 9'!I11*'Anexo 2'!$D$10,0) -> 0 | J11: =ROUND('Anexo 9'!J11*'Anexo 2'!$D$10,0) -> 0 | ... Z11: =ROUND('Anexo 9'!Z11*'Anexo 2'!$D$10,0) -> 0 | AA11: =SUM(C11:Z11) -> 0 | AB11: 4
A12: 46447 | B12: O | C12: =ROUND('Anexo 9'!C12*'Anexo 2'!$D$10,0) -> 0 | D12: =ROUND('Anexo 9'!D12*'Anexo 2'!$D$10,0) -> 0 | E12: =ROUND('Anexo 9'!E12*'Anexo 2'!$D$10,0) -> 0 | F12: =ROUND('Anexo 9'!F12*'Anexo 2'!$D$10,0) -> 0 | G12: =ROUND('Anexo 9'!G12*'Anexo 2'!$D$10,0) -> 0 | H12: =ROUND('Anexo 9'!H12*'Anexo 2'!$D$10,0) -> 0 | I12: =ROUND('Anexo 9'!I12*'Anexo 2'!$D$10,0) -> 0 | J12: =ROUND('Anexo 9'!J12*'Anexo 2'!$D$10,0) -> 0 | ... Z12: =ROUND('Anexo 9'!Z12*'Anexo 2'!$D$10,0) -> 0 | AA12: =SUM(C12:Z12) -> 0 | AB12: 20 | AC12: =+AA12*AB12+AA13*AB13+AA14*AB14 -> 0
B13: S | C13: =ROUND('Anexo 9'!C13*'Anexo 2'!$D$10,0) -> 0 | D13: =ROUND('Anexo 9'!D13*'Anexo 2'!$D$10,0) -> 0 | E13: =ROUND('Anexo 9'!E13*'Anexo 2'!$D$10,0) -> 0 | F13: =ROUND('Anexo 9'!F13*'Anexo 2'!$D$10,0) -> 0 | G13: =ROUND('Anexo 9'!G13*'Anexo 2'!$D$10,0) -> 0 | H13: =ROUND('Anexo 9'!H13*'Anexo 2'!$D$10,0) -> 0 | I13: =ROUND('Anexo 9'!I13*'Anexo 2'!$D$10,0) -> 0 | J13: =ROUND('Anexo 9'!J13*'Anexo 2'!$D$10,0) -> 0 | ... Z13: =ROUND('Anexo 9'!Z13*'Anexo 2'!$D$10,0) -> 0 | AA13: =SUM(C13:Z13) -> 0 | AB13: 4
