Workbook
Name _Toc148954622: 'Banco de Preguntas'!#REF!
Name _Toc148954623: 'Banco de Preguntas'!#REF!
Name _Toc148954624: 'Banco de Preguntas'!#REF!
Name _Toc148954625: 'Banco de Preguntas'!#REF!
Name aaa: [1]Hoja9!$A$1,[1]Hoja9!$A$3,[1]Hoja9!$A$5,[1]Hoja9!$B$6,[1]Hoja9!$C$7
Name aaa: [1]Hoja9!$A$1,[1]Hoja9!$A$3,[1]Hoja9!$A$5,[1]Hoja9!$B$6,[1]Hoja9!$C$7
Name aaa: [1]Hoja9!$A$1,[1]Hoja9!$A$3,[1]Hoja9!$A$5,[1]Hoja9!$B$6,[1]Hoja9!$C$7
Name aaa: [1]Hoja9!$A$1,[1]Hoja9!$A$3,[1]Hoja9!$A$5,[1]Hoja9!$B$6,[1]Hoja9!$C$7
Name aaa: [1]Hoja9!$A$1,[1]Hoja9!$A$3,[1]Hoja9!$A$5,[1]Hoja9!$B$6,[1]Hoja9!$C$7
Name aaa: [1]Hoja9!$A$1,[1]Hoja9!$A$3,[1]Hoja9!$A$5,[1]Hoja9!$B$6,[1]Hoja9!$C$7
Name aaa: [1]Hoja9!$A$1,[1]Hoja9!$A$3,[1]Hoja9!$A$5,[1]Hoja9!$B$6,[1]Hoja9!$C$7
Name aaa: [1]Hoja9!$A$1,[1]Hoja9!$A$3,[1]Hoja9!$A$5,[1]Hoja9!$B$6,[1]Hoja9!$C$7
Name aaa: #REF!,#REF!,#REF!,#REF!,#REF!
Name AAAA: #REF!
Name Criterio_Extraer_Dem_Reg: #REF!
Name Criterio_Extraer_Dem_Reg: #REF!
Name Criterio_Extraer_Dem_Reg: #REF!
Name Criterio_Extraer_Dem_Reg: #REF!
Name Criterio_Extraer_Dem_Reg: #REF!
Name Criterio_Extraer_Dem_Reg: #REF!
Name Criterio_Extraer_Dem_Reg: #REF!
Name Criterio_Extraer_Dem_Reg: #REF!
Name Criterio_Extraer_Dem_Reg: #REF!
Name Criterio_Extraer_Dem_Reg: #REF!
Name Criterio_Extraer_Dem_Reg: #REF!
Name Criterio_Extraer_Dem_Reg: #REF!
Name Criterio_Extraer_Dem_Reg: #REF!
Name Cuadro: #REF!
Name Cuadro: #REF!
Name Cuadro: #REF!
Name Cuadro: #REF!
Name Cuadro: #REF!
Name Cuadro: #REF!
Name Cuadro: #REF!
Name Cuadro: #REF!
Name Cuadro: #REF!
Name Cuadro: #REF!
Name Cuadro: #REF!
Name Cuadro: #REF!
Name Cuadro: #REF!
Name eeee: #REF!
Name eeee: #REF!
Name eeee: [2]Comparación!#REF!
Name eeee: [2]Comparación!#REF!
Name eeee: [2]Comparación!#REF!
Name eeee: [2]Comparación!#REF!
Name eeee: #REF!
Name eeee: #REF!
Name eeee: [2]Comparación!#REF!
Name eeee: [2]Comparación!#REF!
Name eeee: [2]Comparación!#REF!
Name eeee: [2]Comparación!#REF!
Name eeee: #REF!
Name Meses: [3]Evaluación_Mensual!$S$2:$S$25
Name Meses: [3]Evaluación_Mensual!$S$2:$S$25
Name Meses: [3]Evaluación_Mensual!$S$2:$S$25
Name Meses: [3]Evaluación_Mensual!$S$2:$S$25
Name Meses: [3]Evaluación_Mensual!$S$2:$S$25
Name Meses: [3]Evaluación_Mensual!$S$2:$S$25
Name Meses: [3]Evaluación_Mensual!$S$2:$S$25

Sheet Listas desplegables
A2: Tipo de agente: | B2: Tipo de oferta:
A3: Comercializador | B3: CURVA
A4: Generador | B4: CURVA SOLAR
B5: CURVA FNCER
B6: PLANA SOLAR
B7: MIXTA
B8: PLANA

Sheet Banco de Preguntas
A2: Consolidado banco de preguntas y respuestas agentes convocatorias ESSA
A3: N° Convocatoria
A4: Nombre remitente correo:
A5: Correo electrónico
A6: Teléfono de contacto:
A9: AGENTE | B9: N° pregunta | C9: PREGUNTA | D9: RESPUESTA

Sheet Factor garantia
A2: 12. TABLA Factores de Indexación IPP serie oferta interna
A4: Mes | B4: Factor | D4: Mes | E4: Factor | G4: Mes | H4: Factor | J4: Mes | K4: Factor
A5: 45778 | B5: =+'[6]Factor (2)'!B5 -> 1.01 | D5: 47484 | E5: =+'[6]Factor (2)'!E5 -> 1.14 | G5: 49310 | H5: =+'[6]Factor (2)'!H5 -> 1.32 | J5: 51136 | K5: =+'[6]Factor (2)'!K5 -> 1.53
A6: 45809 | B6: =+'[6]Factor (2)'!B6 -> 1.01 | D6: 47515 | E6: =+'[6]Factor (2)'!E6 -> 1.15 | G6: 49341 | H6: =+'[6]Factor (2)'!H6 -> 1.33 | J6: 51167 | K6: =+'[6]Factor (2)'!K6 -> 1.54
A7: 45839 | B7: =+'[6]Factor (2)'!B7 -> 1.02 | D7: 47543 | E7: =+'[6]Factor (2)'!E7 -> 1.15 | G7: 49369 | H7: =+'[6]Factor (2)'!H7 -> 1.33 | J7: 51196 | K7: =+'[6]Factor (2)'!K7 -> 1.54
A8: 45870 | B8: =+'[6]Factor (2)'!B8 -> 1.02 | D8: 47574 | E8: =+'[6]Factor (2)'!E8 -> 1.15 | G8: 49400 | H8: =+'[6]Factor (2)'!H8 -> 1.33 | J8: 51227 | K8: =+'[6]Factor (2)'!K8 -> 1.54
A9: 45901 | B9: =+'[6]Factor (2)'!B9 -> 1.02 | D9: 47604 | E9: =+'[6]Factor (2)'!E9 -> 1.15 | G9: 49430 | H9: =+'[6]Factor (2)'!H9 -> 1.33 | J9: 51257 | K9: =+'[6]Factor (2)'!K9 -> 1.55
A10: 45931 | B10: =+'[6]Factor (2)'!B10 -> 1.02 | D10: 47635 | E10: =+'[6]Factor (2)'!E10 -> 1.16 | G10: 49461 | H10: =+'[6]Factor (2)'!H10 -> 1.34 | J10: 51288 | K10: =+'[6]Factor (2)'!K10 -> 1.55
A11: 45962 | B11: =+'[6]Factor (2)'!B11 -> 1.03 | D11: 47665 | E11: =+'[6]Factor (2)'!E11 -> 1.16 | G11: 49491 | H11: =+'[6]Factor (2)'!H11 -> 1.34 | J11: 51318 | K11: =+'[6]Factor (2)'!K11 -> 1.55
A12: 45992 | B12: =+'[6]Factor (2)'!B12 -> 1.03 | D12: 47696 | E12: =+'[6]Factor (2)'!E12 -> 1.16 | G12: 49522 | H12: =+'[6]Factor (2)'!H12 -> 1.34 | J12: 51349 | K12: =+'[6]Factor (2)'!K12 -> 1.55
A13: 46023 | B13: =+'[6]Factor (2)'!B13 -> 1.03 | D13: 47727 | E13: =+'[6]Factor (2)'!E13 -> 1.16 | G13: 49553 | H13: =+'[6]Factor (2)'!H13 -> 1.34 | J13: 51380 | K13: =+'[6]Factor (2)'!K13 -> 1.56
A14: 46054 | B14: =+'[6]Factor (2)'!B14 -> 1.03 | D14: 47757 | E14: =+'[6]Factor (2)'!E14 -> 1.16 | G14: 49583 | H14: =+'[6]Factor (2)'!H14 -> 1.35 | J14: 51410 | K14: =+'[6]Factor (2)'!K14 -> 1.56
A15: 46082 | B15: =+'[6]Factor (2)'!B15 -> 1.03 | D15: 47788 | E15: =+'[6]Factor (2)'!E15 -> 1.17 | G15: 49614 | H15: =+'[6]Factor (2)'!H15 -> 1.36 | J15: 51441 | K15: =+'[6]Factor (2)'!K15 -> 1.57
A16: 46113 | B16: =+'[6]Factor (2)'!B16 -> 1.03 | D16: 47818 | E16: =+'[6]Factor (2)'!E16 -> 1.17 | G16: 49644 | H16: =+'[6]Factor (2)'!H16 -> 1.36 | J16: 51471 | K16: =+'[6]Factor (2)'!K16 -> 1.57
A17: 46143 | B17: =+'[6]Factor (2)'!B17 -> 1.04 | D17: 47849 | E17: =+'[6]Factor (2)'!E17 -> 1.18 | G17: 49675 | H17: =+'[6]Factor (2)'!H17 -> 1.36
A18: 46174 | B18: =+'[6]Factor (2)'!B18 -> 1.04 | D18: 47880 | E18: =+'[6]Factor (2)'!E18 -> 1.18 | G18: 49706 | H18: =+'[6]Factor (2)'!H18 -> 1.37
A19: 46204 | B19: =+'[6]Factor (2)'!B19 -> 1.04 | D19: 47908 | E19: =+'[6]Factor (2)'!E19 -> 1.18 | G19: 49735 | H19: =+'[6]Factor (2)'!H19 -> 1.37
A20: 46235 | B20: =+'[6]Factor (2)'!B20 -> 1.04 | D20: 47939 | E20: =+'[6]Factor (2)'!E20 -> 1.18 | G20: 49766 | H20: =+'[6]Factor (2)'!H20 -> 1.37
A21: 46266 | B21: =+'[6]Factor (2)'!B21 -> 1.04 | D21: 47969 | E21: =+'[6]Factor (2)'!E21 -> 1.19 | G21: 49796 | H21: =+'[6]Factor (2)'!H21 -> 1.37
A22: 46296 | B22: =+'[6]Factor (2)'!B22 -> 1.05 | D22: 48000 | E22: =+'[6]Factor (2)'!E22 -> 1.19 | G22: 49827 | H22: =+'[6]Factor (2)'!H22 -> 1.38
A23: 46327 | B23: =+'[6]Factor (2)'!B23 -> 1.05 | D23: 48030 | E23: =+'[6]Factor (2)'!E23 -> 1.19 | G23: 49857 | H23: =+'[6]Factor (2)'!H23 -> 1.38
A24: 46357 | B24: =+'[6]Factor (2)'!B24 -> 1.05 | D24: 48061 | E24: =+'[6]Factor (2)'!E24 -> 1.19 | G24: 49888 | H24: =+'[6]Factor (2)'!H24 -> 1.38
A25: 46388 | B25: =+'[6]Factor (2)'!B25 -> 1.06 | D25: 48092 | E25: =+'[6]Factor (2)'!E25 -> 1.19 | G25: 49919 | H25: =+'[6]Factor (2)'!H25 -> 1.38
A26: 46419 | B26: =+'[6]Factor (2)'!B26 -> 1.06 | D26: 48122 | E26: =+'[6]Factor (2)'!E26 -> 1.2 | G26: 49949 | H26: =+'[6]Factor (2)'!H26 -> 1.39
A27: 46447 | B27: =+'[6]Factor (2)'!B27 -> 1.06 | D27: 48153 | E27: =+'[6]Factor (2)'!E27 -> 1.21 | G27: 49980 | H27: =+'[6]Factor (2)'!H27 -> 1.4
A28: 46478 | B28: =+'[6]Factor (2)'!B28 -> 1.06 | D28: 48183 | E28: =+'[6]Factor (2)'!E28 -> 1.21 | G28: 50010 | H28: =+'[6]Factor (2)'!H28 -> 1.4
... A60: 47453 | B60: =+'[6]Factor (2)'!B60 -> 1.14 | D60: 49157 | E60: =+'[6]Factor (2)'!E60 -> 1.3 | G60: 50983 | H60: =+'[6]Factor (2)'!H60 -> 1.51
D61: 49188 | E61: =+'[6]Factor (2)'!E61 -> 1.3 | G61: 51014 | H61: =+'[6]Factor (2)'!H61 -> 1.51
D62: 49218 | E62: =+'[6]Factor (2)'!E62 -> 1.31 | G62: 51044 | H62: =+'[6]Factor (2)'!H62 -> 1.52
D63: 49249 | E63: =+'[6]Factor (2)'!E63 -> 1.32 | G63: 51075 | H63: =+'[6]Factor (2)'!H63 -> 1.53
D64: 49279 | E64: =+'[6]Factor (2)'!E64 -> 1.32 | G64: 51105 | H64: =+'[6]Factor (2)'!H64 -> 1.53

Sheet Cantidades suministrar P1_2025
B2: ANEXO 10.1 CANTIDADES DE ENERGÍA A SUMINISTRAR PRODUCTO 1
B3: AÑO 2025
B6: Oferta Básica, para la Solicitud Pública de Ofertas No. CP-ESSC2025-001, del 1 de mayo de 2025 a 31 de diciembre de 2025.
B8: OFERENTE: | E8: Diligenciar
B9: Tipo de agente: | E9: Elegir de la lista desplegable
B10: Oferta No.: | E10: Diligenciar
B11: Tipo de oferta: | C11: CURVA | E11: Fijo
B12: % de su oferta con FNCER: | E12: Diligenciar
B14: Mes-año | C14: Energia Solicitada (kWh) | D14: % a ofertar | E14: Energia Oferta kWh | F14: Precio $ / kWh
A16: 31 | B16: 45658 | C16: =+'Cantidades P1_(2025)'!AE11 -> 0 | E16: =+C16*D16 -> 0
A17: 28 | B17: 45689 | C17: =+'Cantidades P1_(2025)'!AE12 -> 0 | E17: =+C17*D17 -> 0
A18: 31 | B18: 45717 | C18: =+'Cantidades P1_(2025)'!AE13 -> 0 | E18: =+C18*D18 -> 0
A19: 30 | B19: 45748 | C19: =+'Cantidades P1_(2025)'!AE14 -> 0 | E19: =+C19*D19 -> 0
A20: 31 | B20: 45778 | C20: =+'Cantidades P1_(2025)'!AE15 -> 25274336 | E20: =+C20*D20 -> 0
A21: 30 | B21: 45809 | C21: =+'Cantidades P1_(2025)'!AE16 -> 23289238 | E21: =+C21*D21 -> 0
A22: 31 | B22: 45839 | C22: =+'Cantidades P1_(2025)'!AE17 -> 30787655 | E22: =+C22*D22 -> 0
A23: 31 | B23: 45870 | C23: =+'Cantidades P1_(2025)'!AE18 -> 33589040 | E23: =+C23*D23 -> 0
A24: 30 | B24: 45901 | C24: =+'Cantidades P1_(2025)'!AE19 -> 35398839 | E24: =+C24*D24 -> 0
A25: 31 | B25: 45931 | C25: =+'Cantidades P1_(2025)'!AE20 -> 30572928 | E25: =+C25*D25 -> 0
A26: 30 | B26: 45962 | C26: =+'Cantidades P1_(2025)'!AE21 -> 34475949 | E26: =+C26*D26 -> 0
A27: 31 | B27: 45992 | C27: =+'Cantidades P1_(2025)'!AE22 -> 24036400 | E27: =+C27*D27 -> 0
A28: =SUM(A16:A27) -> 365 | B28: TOTAL | C28: =SUM(C16:C27) -> 2.3742439e+08 | D28: =+E28/C28 -> 0 | E28: =SUM(E16:E27) -> 0
B31: Notas:
B32: (1) La Energía Ofertada se distribuye en forma horaria de acuerdo con la curva de carga presentada en la tabla 9.1. TABLAS CANTIDADES DE ENERGÍA SOLICITADA PRODUCTO 1 AÑO 2025 del pliego de condiciones.
B34: (2) Tipo de Contrato: pague lo contratado.
B35: (3) Precio ofertado en $kWh, en pesos de diciembre 2024 (IPP Provisional)
B36: (4) El precio debe ser el mismo para todos los meses del año, con dos cifras decimales
B37: (5) El % igual o diferente para cada uno de los meses del año, con dos cifras decimales.
B38: (6) El precio incluye todos los cargos, impuestos y contribuciones que según la reglamentación vigente en la fecha de apertura de propuestas son responsabilidad de EL OFERENTE.
B39: (7) No serán tenidas en cuenta ofertas con condiciones y/o modificaciones adicionales a los Pliegos definitivos.
B40: (8) La oferta se acoge a todas las condiciones del pliego CP-ESSC2025-001.
B41: (9) Tipo de oferta curva
B42: EL OFERENTE deberá tener en cuenta lo siguiente al completar cada una de las Tablas de las cantidades a suministrar: Debe definir el porcentaje ofertado, hasta máximo el 100% de lo solicitado, teniendo en cuenta el tipo de contrato; EL CONTRATANTE aceptará la oferta de acuerdo a la metodología de evaluación hasta el máximo ofertado.
B48: FIRMA OFERENTE E.S.P.

Sheet Cantidades suministrar P2_2026
B2: ANEXO 10.2 CANTIDADES DE ENERGÍA A SUMINISTRAR PRODUCTO 2
B3: AÑO 2026
B6: Oferta Básica, para la Solicitud Pública de Ofertas No. CP-ESSC2025-001, del 1 de enero de 2026 a 31 de diciembre de 2026.
B8: OFERENTE: | E8: Diligenciar
B9: Tipo de agente: | E9: Elegir de la lista desplegable
B10: Oferta No.: | E10: Diligenciar
B11: Tipo de oferta: | C11: CURVA | E11: Fijo
B12: % de su oferta con FNCER: | E12: Diligenciar
B14: Mes-año | C14: Energia Solicitada (kWh) | D14: % a ofertar | E14: Energia Oferta kWh | F14: Precio $ / kWh
A16: 31 | B16: 46023 | C16: =+'Cantidades P2_(2026)'!AE11 -> 52892640 | E16: =+C16*D16 -> 0
A17: 28 | B17: 46054 | C17: =+'Cantidades P2_(2026)'!AE12 -> 43666628 | E17: =+C17*D17 -> 0
A18: 31 | B18: 46082 | C18: =+'Cantidades P2_(2026)'!AE13 -> 56214180 | E18: =+C18*D18 -> 0
A19: 30 | B19: 46113 | C19: =+'Cantidades P2_(2026)'!AE14 -> 49009504 | E19: =+C19*D19 -> 0
A20: 31 | B20: 46143 | C20: =+'Cantidades P2_(2026)'!AE15 -> 46722351 | E20: =+C20*D20 -> 0
A21: 30 | B21: 46174 | C21: =+'Cantidades P2_(2026)'!AE16 -> 45425929 | E21: =+C21*D21 -> 0
A22: 31 | B22: 46204 | C22: =+'Cantidades P2_(2026)'!AE17 -> 33835623 | E22: =+C22*D22 -> 0
A23: 31 | B23: 46235 | C23: =+'Cantidades P2_(2026)'!AE18 -> 32309527 | E23: =+C23*D23 -> 0
A24: 30 | B24: 46266 | C24: =+'Cantidades P2_(2026)'!AE19 -> 36615880 | E24: =+C24*D24 -> 0
A25: 31 | B25: 46296 | C25: =+'Cantidades P2_(2026)'!AE20 -> 32001011 | E25: =+C25*D25 -> 0
A26: 30 | B26: 46327 | C26: =+'Cantidades P2_(2026)'!AE21 -> 36404289 | E26: =+C26*D26 -> 0
A27: 31 | B27: 46357 | C27: =+'Cantidades P2_(2026)'!AE22 -> 26272122 | E27: =+C27*D27 -> 0
A28: =SUM(A16:A27) -> 365 | B28: TOTAL | C28: =SUM(C16:C27) -> 4.9136969e+08 | D28: =+E28/C28 -> 0 | E28: =SUM(E16:E27) -> 0
B31: Notas:
B32: (1) La Energía Ofertada se distribuye en forma horaria de acuerdo con la curva de carga presentada en la tabla 9.2. TABLAS CANTIDADES DE ENERGÍA SOLICITADA PRODUCTO 2 AÑO 2026 del pliego de condiciones.
B34: (2) Tipo de Contrato: pague lo contratado.
B35: (3) Precio ofertado en $kWh, en pesos de diciembre 2024 (IPP Provisional)
B36: (4) El precio debe ser el mismo para todos los meses del año, con dos cifras decimales
B37: (5) El % igual o diferente para cada uno de los meses del año, con dos cifras decimales.
B38: (6) El precio incluye todos los cargos, impuestos y contribuciones que según la reglamentación vigente en la fecha de apertura de propuestas son responsabilidad de EL OFERENTE.
B39: (7) No serán tenidas en cuenta ofertas con condiciones y/o modificaciones adicionales a los Pliegos definitivos.
B40: (8) La oferta se acoge a todas las condiciones del pliego CP-ESSC2025-001.
B41: (9) Tipo de oferta curva
B42: EL OFERENTE deberá tener en cuenta lo siguiente al completar cada una de las Tablas de las cantidades a suministrar: Debe definir el porcentaje ofertado, hasta máximo el 100% de lo solicitado, teniendo en cuenta el tipo de contrato; EL CONTRATANTE aceptará la oferta de acuerdo a la metodología de evaluación hasta el máximo ofertado.
B48: FIRMA OFERENTE E.S.P.

Sheet Cantidades suministrar P3_2027
B2: ANEXO 10.3 CANTIDADES DE ENERGÍA A SUMINISTRAR PRODUCTO 3
B3: AÑO 2027
B6: Oferta Básica, para la Solicitud Pública de Ofertas No. CP-ESSC2025-001, del 1 de enero de 2027 a 31 de diciembre de 2027.
B8: OFERENTE: | E8: Diligenciar
B9: Tipo de agente: | E9: Elegir de la lista desplegable
B10: Oferta No.: | E10: Diligenciar
B11: Tipo de oferta: | C11: CURVA | E11: Fijo
B12: % de su oferta con FNCER: | E12: Diligenciar
B14: Mes-año | C14: Energia Solicitada (kWh) | D14: % a ofertar | E14: Energia Oferta kWh | F14: Precio $ / kWh
A16: 31 | B16: 46388 | C16: =+'Cantidades P3_(2027)'!AE11 -> 49754275 | E16: =+C16*D16 -> 0
A17: 28 | B17: 46419 | C17: =+'Cantidades P3_(2027)'!AE12 -> 42439375 | E17: =+C17*D17 -> 0
A18: 31 | B18: 46447 | C18: =+'Cantidades P3_(2027)'!AE13 -> 53971518 | E18: =+C18*D18 -> 0
A19: 30 | B19: 46478 | C19: =+'Cantidades P3_(2027)'!AE14 -> 48426502 | E19: =+C19*D19 -> 0
A20: 31 | B20: 46508 | C20: =+'Cantidades P3_(2027)'!AE15 -> 46689956 | E20: =+C20*D20 -> 0
A21: 30 | B21: 46539 | C21: =+'Cantidades P3_(2027)'!AE16 -> 43845308 | E21: =+C21*D21 -> 0
A22: 31 | B22: 46569 | C22: =+'Cantidades P3_(2027)'!AE17 -> 41380294 | E22: =+C22*D22 -> 0
A23: 31 | B23: 46600 | C23: =+'Cantidades P3_(2027)'!AE18 -> 42178097 | E23: =+C23*D23 -> 0
A24: 30 | B24: 46631 | C24: =+'Cantidades P3_(2027)'!AE19 -> 47596709 | E24: =+C24*D24 -> 0
A25: 31 | B25: 46661 | C25: =+'Cantidades P3_(2027)'!AE20 -> 42681224 | E25: =+C25*D25 -> 0
A26: 30 | B26: 46692 | C26: =+'Cantidades P3_(2027)'!AE21 -> 45932158 | E26: =+C26*D26 -> 0
A27: 31 | B27: 46722 | C27: =+'Cantidades P3_(2027)'!AE22 -> 36952154 | E27: =+C27*D27 -> 0
A28: =SUM(A16:A27) -> 365 | B28: TOTAL | C28: =SUM(C16:C27) -> 5.4184757e+08 | D28: =+E28/C28 -> 0 | E28: =SUM(E16:E27) -> 0
B31: Notas:
B32: (1) La Energía Ofertada se distribuye en forma horaria de acuerdo con la curva de carga presentada en la tabla 9.3. TABLAS CANTIDADES DE ENERGÍA SOLICITADA PRODUCTO 3 AÑO 2027 del pliego de condiciones.
B34: (2) Tipo de Contrato: pague lo contratado.
B35: (3) Precio ofertado en $kWh, en pesos de diciembre 2024 (IPP Provisional)
B36: (4) El precio debe ser el mismo para todos los meses del año, con dos cifras decimales
B37: (5) El % igual o diferente para cada uno de los meses del año, con dos cifras decimales.
B38: (6) El precio incluye todos los cargos, impuestos y contribuciones que según la reglamentación vigente en la fecha de apertura de propuestas son responsabilidad de EL OFERENTE.
B39: (7) No serán tenidas en cuenta ofertas con condiciones y/o modificaciones adicionales a los Pliegos definitivos.
B40: (8) La oferta se acoge a todas las condiciones del pliego CP-ESSC2025-001.
B41: (9) Tipo de oferta curva
B42: EL OFERENTE deberá tener en cuenta lo siguiente al completar cada una de las Tablas de las cantidades a suministrar: Debe definir el porcentaje ofertado, hasta máximo el 100% de lo solicitado, teniendo en cuenta el tipo de contrato; EL CONTRATANTE aceptará la oferta de acuerdo a la metodología de evaluación hasta el máximo ofertado.
B48: FIRMA OFERENTE E.S.P.

Sheet Cantidades suministrar P4_2028
B2: ANEXO 10.4 CANTIDADES DE ENERGÍA A SUMINISTRAR PRODUCTO 4
B3: AÑO 2028
B6: Oferta Básica, para la Solicitud Pública de Ofertas No. CP-ESSC2025-001, del 1 de enero de 2028 a 31 de diciembre de 2028.
B8: OFERENTE: | E8: Diligenciar
B9: Tipo de agente: | E9: Elegir de la lista desplegable
B10: Oferta No.: | E10: Diligenciar
B11: Tipo de oferta: | C11: CURVA | E11: Fijo
B12: % de su oferta con FNCER: | E12: Diligenciar
B14: Mes-año | C14: Energia Solicitada (kWh) | D14: % a ofertar | E14: Energia Oferta kWh | F14: Precio $ / kWh
A16: 31 | B16: 46753 | C16: =+'Cantidades P4_(2028)'!AE11 -> 35501892 | E16: =+C16*$D$16 -> 0
A17: 28 | B17: 46784 | C17: =+'Cantidades P4_(2028)'!AE12 -> 25095936 | E17: =+C17*$D$16 -> 0
A18: 31 | B18: 46813 | C18: =+'Cantidades P4_(2028)'!AE13 -> 38148265 | E18: =+C18*$D$16 -> 0
A19: 30 | B19: 46844 | C19: =+'Cantidades P4_(2028)'!AE14 -> 32531127 | E19: =+C19*$D$16 -> 0
A20: 31 | B20: 46874 | C20: =+'Cantidades P4_(2028)'!AE15 -> 30044688 | E20: =+C20*$D$16 -> 0
A21: 30 | B21: 46905 | C21: =+'Cantidades P4_(2028)'!AE16 -> 29378670 | E21: =+C21*$D$16 -> 0
A22: 31 | B22: 46935 | C22: =+'Cantidades P4_(2028)'!AE17 -> 32227545 | E22: =+C22*$D$16 -> 0
A23: 31 | B23: 46966 | C23: =+'Cantidades P4_(2028)'!AE18 -> 32668048 | E23: =+C23*$D$16 -> 0
A24: 30 | B24: 46997 | C24: =+'Cantidades P4_(2028)'!AE19 -> 40099007 | E24: =+C24*$D$16 -> 0
A25: 31 | B25: 47027 | C25: =+'Cantidades P4_(2028)'!AE20 -> 34829175 | E25: =+C25*$D$16 -> 0
A26: 30 | B26: 47058 | C26: =+'Cantidades P4_(2028)'!AE21 -> 36675826 | E26: =+C26*$D$16 -> 0
A27: 31 | B27: 47088 | C27: =+'Cantidades P4_(2028)'!AE22 -> 25979329 | E27: =+C27*$D$16 -> 0
A28: =SUM(A16:A27) -> 365 | B28: TOTAL | C28: =SUM(C16:C27) -> 3.9317951e+08 | D28: =+E28/C28 -> 0 | E28: =SUM(E16:E27) -> 0
B31: Notas:
B32: (1) La Energía Ofertada se distribuye en forma horaria de acuerdo con la curva de carga presentada en la tabla 9.4. TABLAS CANTIDADES DE ENERGÍA SOLICITADA PRODUCTO 4 AÑO 2028 del pliego de condiciones.
B34: (2) Tipo de Contrato: pague lo contratado.
B35: (3) Precio ofertado en $kWh, en pesos de diciembre 2024 (IPP Provisional)
B36: (4) El precio debe ser el mismo para todos los meses del año, con dos cifras decimales
B37: (5) El % debe ser el mismo para todos los meses del año, con dos cifras decimales.
B38: (6) El precio incluye todos los cargos, impuestos y contribuciones que según la reglamentación vigente en la fecha de apertura de propuestas son responsabilidad de EL OFERENTE.
B39: (7) No serán tenidas en cuenta ofertas con condiciones y/o modificaciones adicionales a los Pliegos definitivos.
B40: (8) La oferta se acoge a todas las condiciones del pliego CP-ESSC2025-001.
B41: (9) Tipo de oferta curva
B42: EL OFERENTE deberá tener en cuenta lo siguiente al completar cada una de las Tablas de las cantidades a suministrar: Debe definir el porcentaje ofertado, hasta máximo el 100% de lo solicitado, teniendo en cuenta el tipo de contrato; EL CONTRATANTE aceptará la oferta de acuerdo a la metodología de evaluación hasta el máximo ofertado.
B48: FIRMA OFERENTE E.S.P.

Sheet Cant suministrar P5_29-40
B2: ANEXO 10.5 CANTIDADES DE ENERGÍA A SUMINISTRAR PRODUCTO 5
B3: AÑO 2029 al 2040
B6: Oferta Básica, para la Solicitud Pública de Ofertas No. CP-ESSC2025-001, del 1 de enero de 2029 a 31 de diciembre de 2040.
B7: OFERENTE: | K7: Diligenciar
B8: Tipo de agente: | K8: Elegir de la lista desplegable
B9: Oferta No: | K9: Diligenciar
B10: Tipo de oferta: | C10: CURVA | K10: Elegir de la lista desplegable
B11: % de su oferta con FNCER: | K11: Diligenciar
B13: Mes-año | C13: Energia Solicitada (kWh) | D13: % a ofertar | E13: Energia Oferta kWh | F13: Precio $ / kWh | H13: Mes-año | I13: Energia Solicitada (kWh) | J13: % a ofertar | K13: Energia Oferta kWh | L13: Precio $ / kWh
A15: 31 | B15: 47119 | C15: =+'Cantidades P5_(2029-2040)'!AC11 -> 30705470 | E15: =+C15*$D$15 -> 0 | H15: 49310 | I15: =+'Cantidades P5_(2029-2040)'!$AC$305 -> 11229385 | J15: =+$D$15 -> 0 | K15: =+I15*$J$15 -> 0
A16: 29 | B16: 47150 | C16: =+'Cantidades P5_(2029-2040)'!AC15 -> 22776052 | E16: =+C16*$D$15 -> 0 | H16: 49341 | I16: =+'Cantidades P5_(2029-2040)'!$AC$309 -> 10815000 | K16: =+I16*$J$15 -> 0
A17: 31 | B17: 47178 | C17: =+'Cantidades P5_(2029-2040)'!AC19 -> 33773824 | E17: =+C17*$D$15 -> 0 | H17: 49369 | I17: =+'Cantidades P5_(2029-2040)'!$AC$313 -> 12700423 | K17: =+I17*$J$15 -> 0
A18: 30 | B18: 47209 | C18: =+'Cantidades P5_(2029-2040)'!AC23 -> 28887141 | E18: =+C18*$D$15 -> 0 | H18: 49400 | I18: =+'Cantidades P5_(2029-2040)'!$AC$317 -> 13241252 | K18: =+I18*$J$15 -> 0
A19: 31 | B19: 47239 | C19: =+'Cantidades P5_(2029-2040)'!AC27 -> 26452679 | E19: =+C19*$D$15 -> 0 | H19: 49430 | I19: =+'Cantidades P5_(2029-2040)'!$AC$321 -> 14292836 | K19: =+I19*$J$15 -> 0
A20: 30 | B20: 47270 | C20: =+'Cantidades P5_(2029-2040)'!AC31 -> 25284267 | E20: =+C20*$D$15 -> 0 | H20: 49461 | I20: =+'Cantidades P5_(2029-2040)'!$AC$325 -> 12044014 | K20: =+I20*$J$15 -> 0
A21: 31 | B21: 47300 | C21: =+'Cantidades P5_(2029-2040)'!AC35 -> 28109899 | E21: =+C21*$D$15 -> 0 | H21: 49491 | I21: =+'Cantidades P5_(2029-2040)'!$AC$329 -> 12728364 | K21: =+I21*$J$15 -> 0
A22: 31 | B22: 47331 | C22: =+'Cantidades P5_(2029-2040)'!AC39 -> 28773743 | E22: =+C22*$D$15 -> 0 | H22: 49522 | I22: =+'Cantidades P5_(2029-2040)'!$AC$333 -> 13407853 | K22: =+I22*$J$15 -> 0
A23: 30 | B23: 47362 | C23: =+'Cantidades P5_(2029-2040)'!AC43 -> 35752687 | E23: =+C23*$D$15 -> 0 | H23: 49553 | I23: =+'Cantidades P5_(2029-2040)'!$AC$337 -> 15314049 | K23: =+I23*$J$15 -> 0
A24: 31 | B24: 47392 | C24: =+'Cantidades P5_(2029-2040)'!AC47 -> 30660260 | E24: =+C24*$D$15 -> 0 | H24: 49583 | I24: =+'Cantidades P5_(2029-2040)'!$AC$341 -> 14721460 | K24: =+I24*$J$15 -> 0
A25: 30 | B25: 47423 | C25: =+'Cantidades P5_(2029-2040)'!AC51 -> 32757071 | E25: =+C25*$D$15 -> 0 | H25: 49614 | I25: =+'Cantidades P5_(2029-2040)'!$AC$345 -> 16328816 | K25: =+I25*$J$15 -> 0
A26: 31 | B26: 47453 | C26: =+'Cantidades P5_(2029-2040)'!AC55 -> 22726250 | E26: =+C26*$D$15 -> 0 | H26: 49644 | I26: =+'Cantidades P5_(2029-2040)'!$AC$349 -> 12746690 | K26: =+I26*$J$15 -> 0
A27: 31 | B27: 47484 | C27: =+'Cantidades P5_(2029-2040)'!$AC$60 -> 33159730 | D27: =+$D$15 -> 0 | E27: =+C27*$D$27 -> 0 | H27: 49675 | I27: =+'Cantidades P5_(2029-2040)'!$AC$354 -> 17170103 | J27: =+$D$15 -> 0 | K27: =+I27*$J$27 -> 0
A28: 28 | B28: 47515 | C28: =+'Cantidades P5_(2029-2040)'!$AC$64 -> 27220925 | E28: =+C28*$D$27 -> 0 | H28: 49706 | I28: =+'Cantidades P5_(2029-2040)'!$AC$358 -> 14650068 | K28: =+I28*$J$27 -> 0
A29: 31 | B29: 47543 | C29: =+'Cantidades P5_(2029-2040)'!$AC$68 -> 36755144 | E29: =+C29*$D$27 -> 0 | H29: 49735 | I29: =+'Cantidades P5_(2029-2040)'!$AC$362 -> 19751565 | K29: =+I29*$J$27 -> 0
A30: 30 | B30: 47574 | C30: =+'Cantidades P5_(2029-2040)'!$AC$72 -> 32751765 | E30: =+C30*$D$27 -> 0 | H30: 49766 | I30: =+'Cantidades P5_(2029-2040)'!$AC$366 -> 18817025 | K30: =+I30*$J$27 -> 0
A31: 31 | B31: 47604 | C31: =+'Cantidades P5_(2029-2040)'!$AC$76 -> 30656534 | E31: =+C31*$D$27 -> 0 | H31: 49796 | I31: =+'Cantidades P5_(2029-2040)'!$AC$370 -> 18121459 | K31: =+I31*$J$27 -> 0
A32: 30 | B32: 47635 | C32: =+'Cantidades P5_(2029-2040)'!$AC$80 -> 27811957 | E32: =+C32*$D$27 -> 0 | H32: 49827 | I32: =+'Cantidades P5_(2029-2040)'!$AC$374 -> 16050325 | K32: =+I32*$J$27 -> 0
A33: 31 | B33: 47665 | C33: =+'Cantidades P5_(2029-2040)'!$AC$84 -> 31347807 | E33: =+C33*$D$27 -> 0 | H33: 49857 | I33: =+'Cantidades P5_(2029-2040)'!$AC$378 -> 17703453 | K33: =+I33*$J$27 -> 0
A34: 31 | B34: 47696 | C34: =+'Cantidades P5_(2029-2040)'!$AC$88 -> 32279755 | E34: =+C34*$D$27 -> 0 | H34: 49888 | I34: =+'Cantidades P5_(2029-2040)'!$AC$382 -> 17824828 | K34: =+I34*$J$27 -> 0
A35: 30 | B35: 47727 | C35: =+'Cantidades P5_(2029-2040)'!$AC$92 -> 38265613 | E35: =+C35*$D$27 -> 0 | H35: 49919 | I35: =+'Cantidades P5_(2029-2040)'!$AC$386 -> 20935156 | K35: =+I35*$J$27 -> 0
A36: 31 | B36: 47757 | C36: =+'Cantidades P5_(2029-2040)'!$AC$96 -> 33470313 | E36: =+C36*$D$27 -> 0 | H36: 49949 | I36: =+'Cantidades P5_(2029-2040)'!$AC$390 -> 18555864 | K36: =+I36*$J$27 -> 0
A37: 30 | B37: 47788 | C37: =+'Cantidades P5_(2029-2040)'!$AC$100 -> 35913927 | E37: =+C37*$D$27 -> 0 | H37: 49980 | I37: =+'Cantidades P5_(2029-2040)'!$AC$394 -> 20551660 | K37: =+I37*$J$27 -> 0
A38: 31 | B38: 47818 | C38: =+'Cantidades P5_(2029-2040)'!$AC$104 -> 27154877 | E38: =+C38*$D$27 -> 0 | H38: 50010 | I38: =+'Cantidades P5_(2029-2040)'!$AC$398 -> 15367244 | K38: =+I38*$J$27 -> 0
A39: 31 | B39: 47849 | C39: =+'Cantidades P5_(2029-2040)'!$AC$109 -> 21934067 | D39: =+$D$15 -> 0 | E39: =+C39*$D$39 -> 0 | H39: 50041 | I39: =+'Cantidades P5_(2029-2040)'!$AC$403 -> 25718051 | J39: =+$D$15 -> 0 | K39: =+I39*$J$39 -> 0
A40: 28 | B40: 47880 | C40: =+'Cantidades P5_(2029-2040)'!$AC$113 -> 18739989 | E40: =+C40*$D$39 -> 0 | H40: 50072 | I40: =+'Cantidades P5_(2029-2040)'!$AC$407 -> 25467006 | K40: =+I40*$J$39 -> 0
A41: 31 | B41: 47908 | C41: =+'Cantidades P5_(2029-2040)'!$AC$117 -> 24821666 | E41: =+C41*$D$39 -> 0 | H41: 50100 | I41: =+'Cantidades P5_(2029-2040)'!$AC$411 -> 28355166 | K41: =+I41*$J$39 -> 0
A42: 30 | B42: 47939 | C42: =+'Cantidades P5_(2029-2040)'!$AC$121 -> 23045246 | E42: =+C42*$D$39 -> 0 | H42: 50131 | I42: =+'Cantidades P5_(2029-2040)'!$AC$415 -> 28259633 | K42: =+I42*$J$39 -> 0
A43: 31 | B43: 47969 | C43: =+'Cantidades P5_(2029-2040)'!$AC$125 -> 22176513 | E43: =+C43*$D$39 -> 0 | H43: 50161 | I43: =+'Cantidades P5_(2029-2040)'!$AC$419 -> 28180001 | K43: =+I43*$J$39 -> 0
A44: 30 | B44: 48000 | C44: =+'Cantidades P5_(2029-2040)'!$AC$129 -> 18532812 | E44: =+C44*$D$39 -> 0 | H44: 50192 | I44: =+'Cantidades P5_(2029-2040)'!$AC$423 -> 24641284 | K44: =+I44*$J$39 -> 0
A45: 31 | B45: 48030 | C45: =+'Cantidades P5_(2029-2040)'!$AC$133 -> 21039691 | E45: =+C45*$D$39 -> 0 | H45: 50222 | I45: =+'Cantidades P5_(2029-2040)'!$AC$427 -> 26776827 | K45: =+I45*$J$39 -> 0
...

Sheet Cant suministrar P6_26-40
B2: ANEXO 10.6 CANTIDADES DE ENERGÍA A SUMINISTRAR PRODUCTO 6
B3: AÑO 2026 al 2040
B6: Oferta Básica, para la Solicitud Pública de Ofertas No. CP-ESSC2025-001, del 1 de julio de 2026 a 31 de diciembre de 2040.
B7: OFERENTE: | K7: Diligenciar
B8: Tipo de agente: | K8: Elegir de la lista desplegable
B9: Oferta No: | K9: Diligenciar
B10: Tipo de oferta: | C10: CURVA SOLAR | K10: Elegir de la lista desplegable
B11: % de su oferta con FNCER: | K11: Diligenciar
B13: Mes-año | C13: Energia Solicitada (kWh) | D13: % a ofertar | E13: Energia Oferta kWh | F13: Precio $ / kWh | H13: Mes-año | I13: Energia Solicitada (kWh) | J13: % a ofertar | K13: Energia Oferta kWh | L13: Precio $ / kWh | N13: Mes-año | O13: Energia Solicitada (kWh) | P13: % a ofertar | Q13: Energia Oferta kWh | R13: Precio $ / kWh
A15: 31 | B15: 46023 | C15: =+'Cantidades P6_(2026-2040)'!$AC$60 -> 0 | D15: 0.2 | E15: =+C15*$D$15 -> 0 | H15: 48580 | I15: =+'Cantidades P6_(2026-2040)'!$AC$403 -> 20213563 | J15: =+$D$15 -> 0.2 | K15: =+I15*$J$15 -> 4042712.6 | N15: 49310 | O15: =+'Cantidades P6_(2026-2040)'!$AC$501 -> 20020518 | P15: =+#REF! -> #REF! | Q15: =+O15*$D$63 -> 4004103.5
A16: 29 | B16: 46054 | C16: =+'Cantidades P6_(2026-2040)'!$AC$64 -> 0 | E16: =+C16*$D$15 -> 0 | H16: 48611 | I16: =+'Cantidades P6_(2026-2040)'!$AC$407 -> 18827988 | K16: =+I16*$J$15 -> 3765597.7 | N16: 49341 | O16: =+'Cantidades P6_(2026-2040)'!$AC$505 -> 18648175 | Q16: =+O16*$D$63 -> 3729634.9
A17: 31 | B17: 46082 | C17: =+'Cantidades P6_(2026-2040)'!$AC$68 -> 0 | E17: =+C17*$D$15 -> 0 | H17: 48639 | I17: =+'Cantidades P6_(2026-2040)'!$AC$411 -> 19588075 | K17: =+I17*$J$15 -> 3917614.9 | N17: 49369 | O17: =+'Cantidades P6_(2026-2040)'!$AC$509 -> 19401002 | Q17: =+O17*$D$63 -> 3880200.4
A18: 30 | B18: 46113 | C18: =+'Cantidades P6_(2026-2040)'!$AC$72 -> 0 | E18: =+C18*$D$15 -> 0 | H18: 48670 | I18: =+'Cantidades P6_(2026-2040)'!$AC$415 -> 17497836 | K18: =+I18*$J$15 -> 3499567.1 | N18: 49400 | O18: =+'Cantidades P6_(2026-2040)'!$AC$513 -> 17330726 | Q18: =+O18*$D$63 -> 3466145.1
A19: 31 | B19: 46143 | C19: =+'Cantidades P6_(2026-2040)'!$AC$76 -> 0 | E19: =+C19*$D$15 -> 0 | H19: 48700 | I19: =+'Cantidades P6_(2026-2040)'!$AC$419 -> 16626903 | K19: =+I19*$J$15 -> 3325380.6 | N19: 49430 | O19: =+'Cantidades P6_(2026-2040)'!$AC$517 -> 16468111 | Q19: =+O19*$D$63 -> 3293622.2
A20: 30 | B20: 46174 | C20: =+'Cantidades P6_(2026-2040)'!$AC$80 -> 0 | E20: =+C20*$D$15 -> 0 | H20: 48731 | I20: =+'Cantidades P6_(2026-2040)'!$AC$423 -> 16951524 | K20: =+I20*$J$15 -> 3390304.8 | N20: 49461 | O20: =+'Cantidades P6_(2026-2040)'!$AC$521 -> 16789631 | Q20: =+O20*$D$63 -> 3357926.2
A21: 31 | B21: 46204 | C21: =+'Cantidades P6_(2026-2040)'!$AC$84 -> 18703616 | E21: =+C21*$D$15 -> 3740723.3 | H21: 48761 | I21: =+'Cantidades P6_(2026-2040)'!$AC$427 -> 18281676 | K21: =+I21*$J$15 -> 3656335.2 | N21: 49491 | O21: =+'Cantidades P6_(2026-2040)'!$AC$525 -> 18107080 | Q21: =+O21*$D$63 -> 3621416
A22: 31 | B22: 46235 | C22: =+'Cantidades P6_(2026-2040)'!$AC$88 -> 17707279 | E22: =+C22*$D$15 -> 3541455.7 | H22: 48792 | I22: =+'Cantidades P6_(2026-2040)'!$AC$431 -> 17307814 | K22: =+I22*$J$15 -> 3461562.9 | N22: 49522 | O22: =+'Cantidades P6_(2026-2040)'!$AC$529 -> 17142519 | Q22: =+O22*$D$63 -> 3428503.8
A23: 30 | B23: 46266 | C23: =+'Cantidades P6_(2026-2040)'!$AC$92 -> 15269085 | E23: =+C23*$D$15 -> 3053817 | H23: 48823 | I23: =+'Cantidades P6_(2026-2040)'!$AC$435 -> 14924625 | K23: =+I23*$J$15 -> 2984925 | N23: 49553 | O23: =+'Cantidades P6_(2026-2040)'!$AC$533 -> 14782089 | Q23: =+O23*$D$63 -> 2956417.9
A24: 31 | B24: 46296 | C24: =+'Cantidades P6_(2026-2040)'!$AC$96 -> 15730803 | E24: =+C24*$D$15 -> 3146160.5 | H24: 48853 | I24: =+'Cantidades P6_(2026-2040)'!$AC$439 -> 15375927 | K24: =+I24*$J$15 -> 3075185.3 | N24: 49583 | O24: =+'Cantidades P6_(2026-2040)'!$AC$537 -> 15229081 | Q24: =+O24*$D$63 -> 3045816.2
A25: 30 | B25: 46327 | C25: =+'Cantidades P6_(2026-2040)'!$AC$100 -> 13697625 | E25: =+C25*$D$15 -> 2739525 | H25: 48884 | I25: =+'Cantidades P6_(2026-2040)'!$AC$443 -> 13388616 | K25: =+I25*$J$15 -> 2677723.2 | N25: 49614 | O25: =+'Cantidades P6_(2026-2040)'!$AC$541 -> 13260751 | Q25: =+O25*$D$63 -> 2652150.1
A26: 31 | B26: 46357 | C26: =+'Cantidades P6_(2026-2040)'!$AC$104 -> 18063692 | E26: =+C26*$D$15 -> 3612738.4 | H26: 48914 | I26: =+'Cantidades P6_(2026-2040)'!$AC$447 -> 17656188 | K26: =+I26*$J$15 -> 3531237.5 | N26: 49644 | O26: =+'Cantidades P6_(2026-2040)'!$AC$545 -> 17487565 | Q26: =+O26*$D$63 -> 3497513
A27: 31 | B27: 46388 | C27: =+'Cantidades P6_(2026-2040)'!$AC$109 -> 20639874 | D27: =+$D$15 -> 0.2 | E27: =+C27*$D$27 -> 4127974.8 | H27: 48945 | I27: =+'Cantidades P6_(2026-2040)'!$AC$452 -> 20117040 | J27: =+$D$15 -> 0.2 | K27: =+I27*$J$27 -> 4023408 | N27: 49675 | O27: =+'Cantidades P6_(2026-2040)'!$AC$550 -> 19940082 | P27: =+#REF! -> #REF! | Q27: =+O27*$D$63 -> 3988016.3
A28: 28 | B28: 46419 | C28: =+'Cantidades P6_(2026-2040)'!$AC$113 -> 19225077 | E28: =+C28*$D$27 -> 3845015.3 | H28: 48976 | I28: =+'Cantidades P6_(2026-2040)'!$AC$456 -> 18738082 | K28: =+I28*$J$27 -> 3747616.3 | N28: 49706 | O28: =+'Cantidades P6_(2026-2040)'!$AC$554 -> 19236583 | Q28: =+O28*$D$63 -> 3847316.5
A29: 31 | B29: 46447 | C29: =+'Cantidades P6_(2026-2040)'!$AC$117 -> 20001194 | E29: =+C29*$D$27 -> 4000238.9 | H29: 49004 | I29: =+'Cantidades P6_(2026-2040)'!$AC$460 -> 19494539 | K29: =+I29*$J$27 -> 3898907.8 | N29: 49735 | O29: =+'Cantidades P6_(2026-2040)'!$AC$558 -> 19323056 | Q29: =+O29*$D$63 -> 3864611.1
A30: 30 | B30: 46478 | C30: =+'Cantidades P6_(2026-2040)'!$AC$121 -> 17866871 | E30: =+C30*$D$27 -> 3573374.2 | H30: 49035 | I30: =+'Cantidades P6_(2026-2040)'!$AC$464 -> 17414281 | K30: =+I30*$J$27 -> 3482856.2 | N30: 49766 | O30: =+'Cantidades P6_(2026-2040)'!$AC$562 -> 17261097 | Q30: =+O30*$D$63 -> 3452219.4
A31: 31 | B31: 46508 | C31: =+'Cantidades P6_(2026-2040)'!$AC$125 -> 16977570 | E31: =+C31*$D$27 -> 3395514 | H31: 49065 | I31: =+'Cantidades P6_(2026-2040)'!$AC$468 -> 16547507 | K31: =+I31*$J$27 -> 3309501.4 | N31: 49796 | O31: =+'Cantidades P6_(2026-2040)'!$AC$566 -> 16401947 | Q31: =+O31*$D$63 -> 3280389.4
A32: 30 | B32: 46539 | C32: =+'Cantidades P6_(2026-2040)'!$AC$129 -> 17309037 | E32: =+C32*$D$27 -> 3461807.3 | H32: 49096 | I32: =+'Cantidades P6_(2026-2040)'!$AC$472 -> 16870577 | K32: =+I32*$J$27 -> 3374115.4 | N32: 49827 | O32: =+'Cantidades P6_(2026-2040)'!$AC$570 -> 16722176 | Q32: =+O32*$D$63 -> 3344435.1
A33: 31 | B33: 46569 | C33: =+'Cantidades P6_(2026-2040)'!$AC$133 -> 18667243 | E33: =+C33*$D$27 -> 3733448.5 | H33: 49126 | I33: =+'Cantidades P6_(2026-2040)'!$AC$476 -> 18194378 | K33: =+I33*$J$27 -> 3638875.6 | N33: 49857 | O33: =+'Cantidades P6_(2026-2040)'!$AC$574 -> 18034332 | Q33: =+O33*$D$63 -> 3606866.3
A34: 31 | B34: 46600 | C34: =+'Cantidades P6_(2026-2040)'!$AC$137 -> 17672842 | E34: =+C34*$D$27 -> 3534568.4 | H34: 49157 | I34: =+'Cantidades P6_(2026-2040)'!$AC$480 -> 17225166 | K34: =+I34*$J$27 -> 3445033.2 | N34: 49888 | O34: =+'Cantidades P6_(2026-2040)'!$AC$578 -> 17073645 | Q34: =+O34*$D$63 -> 3414729.1
A35: 30 | B35: 46631 | C35: =+'Cantidades P6_(2026-2040)'!$AC$141 -> 15239390 | E35: =+C35*$D$27 -> 3047878 | H35: 49188 | I35: =+'Cantidades P6_(2026-2040)'!$AC$484 -> 14853357 | K35: =+I35*$J$27 -> 2970671.5 | N35: 49919 | O35: =+'Cantidades P6_(2026-2040)'!$AC$582 -> 14722701 | Q35: =+O35*$D$63 -> 2944540.1
A36: 31 | B36: 46661 | C36: =+'Cantidades P6_(2026-2040)'!$AC$145 -> 15700210 | E36: =+C36*$D$27 -> 3140042 | H36: 49218 | I36: =+'Cantidades P6_(2026-2040)'!$AC$488 -> 15302504 | K36: =+I36*$J$27 -> 3060500.8 | N36: 49949 | O36: =+'Cantidades P6_(2026-2040)'!$AC$586 -> 15167896 | Q36: =+O36*$D$63 -> 3033579.2
A37: 30 | B37: 46692 | C37: =+'Cantidades P6_(2026-2040)'!$AC$149 -> 13670986 | E37: =+C37*$D$27 -> 2734197.3 | H37: 49249 | I37: =+'Cantidades P6_(2026-2040)'!$AC$492 -> 13324683 | K37: =+I37*$J$27 -> 2664936.5 | N37: 49980 | O37: =+'Cantidades P6_(2026-2040)'!$AC$590 -> 13207473 | Q37: =+O37*$D$63 -> 2641494.5
A38: 31 | B38: 46722 | C38: =+'Cantidades P6_(2026-2040)'!$AC$153 -> 18028563 | E38: =+C38*$D$27 -> 3605712.6 | H38: 49279 | I38: =+'Cantidades P6_(2026-2040)'!$AC$496 -> 17571876 | K38: =+I38*$J$27 -> 3514375.2 | N38: 50010 | O38: =+'Cantidades P6_(2026-2040)'!$AC$594 -> 17417306 | Q38: =+O38*$D$63 -> 3483461.2
A39: 31 | B39: 46753 | C39: =+'Cantidades P6_(2026-2040)'!$AC$158 -> 20591613 | D39: =+$D$15 -> 0.2 | E39: =+C39*$D$39 -> 4118322.6 | H39: 49310 | I39: =+'Cantidades P6_(2026-2040)'!$AC$501 -> 20020518 | J39: =+$D$15 -> 0.2 | K39: =+I39*$J$39 -> 4004103.5 | N39: 50041 | O39: =+'Cantidades P6_(2026-2040)'!$AC$599 -> 19867689 | P39: =+#REF! -> #REF! | Q39: =+O39*$D$63 -> 3973537.8
A40: 28 | B40: 46784 | C40: =+'Cantidades P6_(2026-2040)'!$AC$162 -> 19865127 | E40: =+C40*$D$39 -> 3973025.5 | H40: 49341 | I40: =+'Cantidades P6_(2026-2040)'!$AC$505 -> 18648175 | K40: =+I40*$J$39 -> 3729634.9 | N40: 50072 | O40: =+'Cantidades P6_(2026-2040)'!$AC$603 -> 18505822 | Q40: =+O40*$D$63 -> 3701164.4
A41: 31 | B41: 46813 | C41: =+'Cantidades P6_(2026-2040)'!$AC$166 -> 19954426 | E41: =+C41*$D$39 -> 3990885.2 | H41: 49369 | I41: =+'Cantidades P6_(2026-2040)'!$AC$509 -> 19401002 | K41: =+I41*$J$39 -> 3880200.4 | N41: 50100 | O41: =+'Cantidades P6_(2026-2040)'!$AC$607 -> 19252904 | Q41: =+O41*$D$63 -> 3850580.8
A42: 30 | B42: 46844 | C42: =+'Cantidades P6_(2026-2040)'!$AC$170 -> 17825093 | E42: =+C42*$D$39 -> 3565018.7 | H42: 49400 | I42: =+'Cantidades P6_(2026-2040)'!$AC$513 -> 17330726 | K42: =+I42*$J$39 -> 3466145.1 | N42: 50131 | O42: =+'Cantidades P6_(2026-2040)'!$AC$611 -> 17198430 | Q42: =+O42*$D$63 -> 3439686.1
A43: 31 | B43: 46874 | C43: =+'Cantidades P6_(2026-2040)'!$AC$174 -> 16937872 | E43: =+C43*$D$39 -> 3387574.4 | H43: 49430 | I43: =+'Cantidades P6_(2026-2040)'!$AC$517 -> 16468111 | K43: =+I43*$J$39 -> 3293622.2 | N43: 50161 | O43: =+'Cantidades P6_(2026-2040)'!$AC$615 -> 16342400 | Q43: =+O43*$D$63 -> 3268479.9
A44: 30 | B44: 46905 | C44: =+'Cantidades P6_(2026-2040)'!$AC$178 -> 17268564 | E44: =+C44*$D$39 -> 3453712.7 | H44: 49461 | I44: =+'Cantidades P6_(2026-2040)'!$AC$521 -> 16789631 | K44: =+I44*$J$39 -> 3357926.2 | N44: 50192 | O44: =+'Cantidades P6_(2026-2040)'!$AC$619 -> 16661466 | Q44: =+O44*$D$63 -> 3332293.2
A45: 31 | B45: 46935 | C45: =+'Cantidades P6_(2026-2040)'!$AC$182 -> 18623594 | E45: =+C45*$D$39 -> 3724718.7 | H45: 49491 | I45: =+'Cantidades P6_(2026-2040)'!$AC$525 -> 18107080 | K45: =+I45*$J$39 -> 3621416 | N45: 50222 | O45: =+'Cantidades P6_(2026-2040)'!$AC$623 -> 17968857 | Q45: =+O45*$D$63 -> 3593771.4
...

Sheet Hoja9
B2: Mes | C2: AÑO 2026 Energia Solicitada (kWh) | D2: AÑO 2027 Energia Solicitada (kWh) | E2: AÑO 2028 Energia Solicitada (kWh) | F2: AÑO 2029 Energia Solicitada (kWh) | G2: AÑO 2030 Energia Solicitada (kWh) | H2: AÑO 2031 Energia Solicitada (kWh) | I2: AÑO 2032 Energia Solicitada (kWh) | J2: AÑO 2033 Energia Solicitada (kWh) | K2: AÑO 2034 Energia Solicitada (kWh) | L2: AÑO 2035 Energia Solicitada (kWh) | M2: TOTAL PRODUCTO 2 Energia Solicitada (kWh)
B3: CURVA | C3: La misma curva de la tabla 9.1.2 del producto 1 | D3: La misma curva de la tabla 9.1.3 del producto 1 | E3: La misma curva de la tabla 9.1.4 del producto 1 | F3: La misma curva de la tabla 9.1.5 del producto 1 | G3: La misma curva de la tabla 9.1.6 del producto 1 | H3: La misma curva de la tabla 9.1.7 del producto 1 | I3: La misma curva de la tabla 9.1.8 del producto 1 | J3: La misma curva de la tabla 9.1.9 del producto 1 | K3: La misma curva de la tabla 9.1.10 del producto 1 | L3: La misma curva de la tabla 9.1.11 del producto 1
B4: ene | C4: =+#REF! -> #REF! | D4: =+#REF! -> #REF! | E4: =+#REF! -> #REF! | F4: =+#REF! -> #REF! | G4: =+#REF! -> #REF! | H4: =+#REF! -> #REF! | I4: =+#REF! -> #REF! | J4: =+#REF! -> #REF! | ... L4: =+#REF! -> #REF! | M4: =SUM(C4:L4) -> #REF!
B5: feb | C5: =+#REF! -> #REF! | D5: =+#REF! -> #REF! | E5: =+#REF! -> #REF! | F5: =+#REF! -> #REF! | G5: =+#REF! -> #REF! | H5: =+#REF! -> #REF! | I5: =+#REF! -> #REF! | J5: =+#REF! -> #REF! | ... L5: =+#REF! -> #REF! | M5: =SUM(C5:L5) -> #REF!
B6: mar | C6: =+#REF! -> #REF! | D6: =+#REF! -> #REF! | E6: =+#REF! -> #REF! | F6: =+#REF! -> #REF! | G6: =+#REF! -> #REF! | H6: =+#REF! -> #REF! | I6: =+#REF! -> #REF! | J6: =+#REF! -> #REF! | ... L6: =+#REF! -> #REF! | M6: =SUM(C6:L6) -> #REF!
B7: abr | C7: =+#REF! -> #REF! | D7: =+#REF! -> #REF! | E7: =+#REF! -> #REF! | F7: =+#REF! -> #REF! | G7: =+#REF! -> #REF! | H7: =+#REF! -> #REF! | I7: =+#REF! -> #REF! | J7: =+#REF! -> #REF! | ... L7: =+#REF! -> #REF! | M7: =SUM(C7:L7) -> #REF!
B8: may | C8: =+#REF! -> #REF! | D8: =+#REF! -> #REF! | E8: =+#REF! -> #REF! | F8: =+#REF! -> #REF! | G8: =+#REF! -> #REF! | H8: =+#REF! -> #REF! | I8: =+#REF! -> #REF! | J8: =+#REF! -> #REF! | ... L8: =+#REF! -> #REF! | M8: =SUM(C8:L8) -> #REF!
B9: jun | C9: =+#REF! -> #REF! | D9: =+#REF! -> #REF! | E9: =+#REF! -> #REF! | F9: =+#REF! -> #REF! | G9: =+#REF! -> #REF! | H9: =+#REF! -> #REF! | I9: =+#REF! -> #REF! | J9: =+#REF! -> #REF! | ... L9: =+#REF! -> #REF! | M9: =SUM(C9:L9) -> #REF!
B10: jul | C10: =+#REF! -> #REF! | D10: =+#REF! -> #REF! | E10: =+#REF! -> #REF! | F10: =+#REF! -> #REF! | G10: =+#REF! -> #REF! | H10: =+#REF! -> #REF! | I10: =+#REF! -> #REF! | J10: =+#REF! -> #REF! | ... L10: =+#REF! -> #REF! | M10: =SUM(C10:L10) -> #REF!
B11: ago | C11: =+#REF! -> #REF! | D11: =+#REF! -> #REF! | E11: =+#REF! -> #REF! | F11: =+#REF! -> #REF! | G11: =+#REF! -> #REF! | H11: =+#REF! -> #REF! | I11: =+#REF! -> #REF! | J11: =+#REF! -> #REF! | ... L11: =+#REF! -> #REF! | M11: =SUM(C11:L11) -> #REF!
B12: sep | C12: =+#REF! -> #REF! | D12: =+#REF! -> #REF! | E12: =+#REF! -> #REF! | F12: =+#REF! -> #REF! | G12: =+#REF! -> #REF! | H12: =+#REF! -> #REF! | I12: =+#REF! -> #REF! | J12: =+#REF! -> #REF! | ... L12: =+#REF! -> #REF! | M12: =SUM(C12:L12) -> #REF!
B13: oct | C13: =+#REF! -> #REF! | D13: =+#REF! -> #REF! | E13: =+#REF! -> #REF! | F13: =+#REF! -> #REF! | G13: =+#REF! -> #REF! | H13: =+#REF! -> #REF! | I13: =+#REF! -> #REF! | J13: =+#REF! -> #REF! | ... L13: =+#REF! -> #REF! | M13: =SUM(C13:L13) -> #REF!
B14: nov | C14: =+#REF! -> #REF! | D14: =+#REF! -> #REF! | E14: =+#REF! -> #REF! | F14: =+#REF! -> #REF! | G14: =+#REF! -> #REF! | H14: =+#REF! -> #REF! | I14: =+#REF! -> #REF! | J14: =+#REF! -> #REF! | ... L14: =+#REF! -> #REF! | M14: =SUM(C14:L14) -> #REF!
B15: dic | C15: =+#REF! -> #REF! | D15: =+#REF! -> #REF! | E15: =+#REF! -> #REF! | F15: =+#REF! -> #REF! | G15: =+#REF! -> #REF! | H15: =+#REF! -> #REF! | I15: =+#REF! -> #REF! | J15: =+#REF! -> #REF! | ... L15: =+#REF! -> #REF! | M15: =SUM(C15:L15) -> #REF!
B16: TOTAL | C16: =SUM(C4:C15) -> #REF! | D16: =SUM(D4:D15) -> #REF! | E16: =SUM(E4:E15) -> #REF! | F16: =SUM(F4:F15) -> #REF! | G16: =SUM(G4:G15) -> #REF! | H16: =SUM(H4:H15) -> #REF! | I16: =SUM(I4:I15) -> #REF! | J16: =SUM(J4:J15) -> #REF! | ... M16: =SUM(M4:M15) -> #REF!
M17: =+M16-#REF! -> #REF!

Sheet Hoja9 (2)
B2: Mes | C2: AÑO 2027 Energia Solicitada (kWh) | D2: AÑO 2028 Energia Solicitada (kWh) | E2: AÑO 2029 Energia Solicitada (kWh) | F2: AÑO 2030 Energia Solicitada (kWh) | G2: AÑO 2031 Energia Solicitada (kWh) | H2: AÑO 2032 Energia Solicitada (kWh) | I2: AÑO 2033 Energia Solicitada (kWh) | J2: AÑO 2034 Energia Solicitada (kWh) | K2: AÑO 2035 Energia Solicitada (kWh) | L2: AÑO 2036 Energia Solicitada (kWh) | M2: TOTAL PRODUCTO 3 Energia Solicitada (kWh)
B3: CURVA | C3: La misma curva de la tabla 9.1.3 del producto 1 | D3: La misma curva de la tabla 9.1.4 del producto 1 | E3: La misma curva de la tabla 9.1.5 del producto 1 | F3: La misma curva de la tabla 9.1.6 del producto 1 | G3: La misma curva de la tabla 9.1.7 del producto 1 | H3: La misma curva de la tabla 9.1.8 del producto 1 | I3: La misma curva de la tabla 9.1.9 del producto 1 | J3: La misma curva de la tabla 9.1.10 del producto 1 | K3: La misma curva de la tabla 9.1.11 del producto 1 | L3: La misma curva de la tabla 9.1.12 del producto 1
B4: ene | C4: =+#REF! -> #REF! | D4: =+#REF! -> #REF! | E4: =+#REF! -> #REF! | F4: =+#REF! -> #REF! | G4: =+#REF! -> #REF! | H4: =+#REF! -> #REF! | I4: =+#REF! -> #REF! | J4: =+#REF! -> #REF! | ... L4: =+#REF! -> #REF! | M4: =SUM(C4:L4) -> #REF!
B5: feb | C5: =+#REF! -> #REF! | D5: =+#REF! -> #REF! | E5: =+#REF! -> #REF! | F5: =+#REF! -> #REF! | G5: =+#REF! -> #REF! | H5: =+#REF! -> #REF! | I5: =+#REF! -> #REF! | J5: =+#REF! -> #REF! | ... L5: =+#REF! -> #REF! | M5: =SUM(C5:L5) -> #REF!
B6: mar | C6: =+#REF! -> #REF! | D6: =+#REF! -> #REF! | E6: =+#REF! -> #REF! | F6: =+#REF! -> #REF! | G6: =+#REF! -> #REF! | H6: =+#REF! -> #REF! | I6: =+#REF! -> #REF! | J6: =+#REF! -> #REF! | ... L6: =+#REF! -> #REF! | M6: =SUM(C6:L6) -> #REF!
B7: abr | C7: =+#REF! -> #REF! | D7: =+#REF! -> #REF! | E7: =+#REF! -> #REF! | F7: =+#REF! -> #REF! | G7: =+#REF! -> #REF! | H7: =+#REF! -> #REF! | I7: =+#REF! -> #REF! | J7: =+#REF! -> #REF! | ... L7: =+#REF! -> #REF! | M7: =SUM(C7:L7) -> #REF!
B8: may | C8: =+#REF! -> #REF! | D8: =+#REF! -> #REF! | E8: =+#REF! -> #REF! | F8: =+#REF! -> #REF! | G8: =+#REF! -> #REF! | H8: =+#REF! -> #REF! | I8: =+#REF! -> #REF! | J8: =+#REF! -> #REF! | ... L8: =+#REF! -> #REF! | M8: =SUM(C8:L8) -> #REF!
B9: jun | C9: =+#REF! -> #REF! | D9: =+#REF! -> #REF! | E9: =+#REF! -> #REF! | F9: =+#REF! -> #REF! | G9: =+#REF! -> #REF! | H9: =+#REF! -> #REF! | I9: =+#REF! -> #REF! | J9: =+#REF! -> #REF! | ... L9: =+#REF! -> #REF! | M9: =SUM(C9:L9) -> #REF!
B10: jul | C10: =+#REF! -> #REF! | D10: =+#REF! -> #REF! | E10: =+#REF! -> #REF! | F10: =+#REF! -> #REF! | G10: =+#REF! -> #REF! | H10: =+#REF! -> #REF! | I10: =+#REF! -> #REF! | J10: =+#REF! -> #REF! | ... L10: =+#REF! -> #REF! | M10: =SUM(C10:L10) -> #REF!
B11: ago | C11: =+#REF! -> #REF! | D11: =+#REF! -> #REF! | E11: =+#REF! -> #REF! | F11: =+#REF! -> #REF! | G11: =+#REF! -> #REF! | H11: =+#REF! -> #REF! | I11: =+#REF! -> #REF! | J11: =+#REF! -> #REF! | ... L11: =+#REF! -> #REF! | M11: =SUM(C11:L11) -> #REF!
B12: sep | C12: =+#REF! -> #REF! | D12: =+#REF! -> #REF! | E12: =+#REF! -> #REF! | F12: =+#REF! -> #REF! | G12: =+#REF! -> #REF! | H12: =+#REF! -> #REF! | I12: =+#REF! -> #REF! | J12: =+#REF! -> #REF! | ... L12: =+#REF! -> #REF! | M12: =SUM(C12:L12) -> #REF!
B13: oct | C13: =+#REF! -> #REF! | D13: =+#REF! -> #REF! | E13: =+#REF! -> #REF! | F13: =+#REF! -> #REF! | G13: =+#REF! -> #REF! | H13: =+#REF! -> #REF! | I13: =+#REF! -> #REF! | J13: =+#REF! -> #REF! | ... L13: =+#REF! -> #REF! | M13: =SUM(C13:L13) -> #REF!
B14: nov | C14: =+#REF! -> #REF! | D14: =+#REF! -> #REF! | E14: =+#REF! -> #REF! | F14: =+#REF! -> #REF! | G14: =+#REF! -> #REF! | H14: =+#REF! -> #REF! | I14: =+#REF! -> #REF! | J14: =+#REF! -> #REF! | ... L14: =+#REF! -> #REF! | M14: =SUM(C14:L14) -> #REF!
B15: dic | C15: =+#REF! -> #REF! | D15: =+#REF! -> #REF! | E15: =+#REF! -> #REF! | F15: =+#REF! -> #REF! | G15: =+#REF! -> #REF! | H15: =+#REF! -> #REF! | I15: =+#REF! -> #REF! | J15: =+#REF! -> #REF! | ... L15: =+#REF! -> #REF! | M15: =SUM(C15:L15) -> #REF!
B16: TOTAL | C16: =SUM(C4:C15) -> #REF! | D16: =SUM(D4:D15) -> #REF! | E16: =SUM(E4:E15) -> #REF! | F16: =SUM(F4:F15) -> #REF! | G16: =SUM(G4:G15) -> #REF! | H16: =SUM(H4:H15) -> #REF! | I16: =SUM(I4:I15) -> #REF! | J16: =SUM(J4:J15) -> #REF! | ... M16: =SUM(M4:M15) -> #REF!
M17: =+M16-#REF! -> #REF!

Sheet Cantidades P1_(2025)
B4: 9.1 TABLAS CANTIDADES DE ENERGÍA SOLICITADA PRODUCTO 1 AÑO 2025 (kWh)
B5: ELETRIFICADORA DE SANTANDER S.A E.S.P.
B6: SOLICITUD PÚBLICA DE OFERTAS CP-ESSC2025-001
B7: PAGUELO CONTRATADO
B10: Mes | C10: Tipo Día | D10: Días | E10: H1 | F10: H2 | G10: H3 | H10: H4 | I10: H5 | J10: H6 | K10: H7 | L10: H8 | M10: H9 | N10: H10 | O10: H11 | P10: H12 | Q10: H13 | R10: H14 | S10: H15 | T10: H16 | U10: H17 | V10: H18 | W10: H19 | X10: H20 | Y10: H21 | Z10: H22 | AA10: H23 | AB10: H24 | AC10: TOTAL MES kWh | AE10: =+AC10 -> TOTAL MES kWh
B11: 45658 | C11: Ordinario | D11: 21 | E11: =ROUND('[7]2025'!E15,2) -> 0 | F11: =ROUND('[7]2025'!F15,2) -> 0 | G11: =ROUND('[7]2025'!G15,2) -> 0 | H11: =ROUND('[7]2025'!H15,2) -> 0 | I11: =ROUND('[7]2025'!I15,2) -> 0 | J11: =ROUND('[7]2025'!J15,2) -> 0 | K11: =ROUND('[7]2025'!K15,2) -> 0 | L11: =ROUND('[7]2025'!L15,2) -> 0 | ... AB11: =ROUND('[7]2025'!AB15,2) -> 0 | AC11: =SUM(E11:AB11)*D11+SUM(E12:AB12)*D12+SUM(E13:AB13)*D13+SUM(E14:AB14)*D14 -> 0 | AE11: =+AC11 -> 0
C12: Sábado | D12: 4 | E12: =ROUND('[7]2025'!E16,2) -> 0 | F12: =ROUND('[7]2025'!F16,2) -> 0 | G12: =ROUND('[7]2025'!G16,2) -> 0 | H12: =ROUND('[7]2025'!H16,2) -> 0 | I12: =ROUND('[7]2025'!I16,2) -> 0 | J12: =ROUND('[7]2025'!J16,2) -> 0 | K12: =ROUND('[7]2025'!K16,2) -> 0 | L12: =ROUND('[7]2025'!L16,2) -> 0 | ... AB12: =ROUND('[7]2025'!AB16,2) -> 0 | AE12: =+AC15 -> 0
C13: Domingo | D13: 4 | E13: =ROUND('[7]2025'!E17,2) -> 0 | F13: =ROUND('[7]2025'!F17,2) -> 0 | G13: =ROUND('[7]2025'!G17,2) -> 0 | H13: =ROUND('[7]2025'!H17,2) -> 0 | I13: =ROUND('[7]2025'!I17,2) -> 0 | J13: =ROUND('[7]2025'!J17,2) -> 0 | K13: =ROUND('[7]2025'!K17,2) -> 0 | L13: =ROUND('[7]2025'!L17,2) -> 0 | ... AB13: =ROUND('[7]2025'!AB17,2) -> 0 | AE13: =+AC19 -> 0
C14: Festivo | D14: 2 | E14: =ROUND('[7]2025'!E18,2) -> 0 | F14: =ROUND('[7]2025'!F18,2) -> 0 | G14: =ROUND('[7]2025'!G18,2) -> 0 | H14: =ROUND('[7]2025'!H18,2) -> 0 | I14: =ROUND('[7]2025'!I18,2) -> 0 | J14: =ROUND('[7]2025'!J18,2) -> 0 | K14: =ROUND('[7]2025'!K18,2) -> 0 | L14: =ROUND('[7]2025'!L18,2) -> 0 | ... AB14: =ROUND('[7]2025'!AB18,2) -> 0 | AE14: =+AC23 -> 0
B15: 45689 | C15: Ordinario | D15: 20 | E15: =ROUND('[7]2025'!E19,2) -> 0 | F15: =ROUND('[7]2025'!F19,2) -> 0 | G15: =ROUND('[7]2025'!G19,2) -> 0 | H15: =ROUND('[7]2025'!H19,2) -> 0 | I15: =ROUND('[7]2025'!I19,2) -> 0 | J15: =ROUND('[7]2025'!J19,2) -> 0 | K15: =ROUND('[7]2025'!K19,2) -> 0 | L15: =ROUND('[7]2025'!L19,2) -> 0 | ... AB15: =ROUND('[7]2025'!AB19,2) -> 0 | AC15: =SUM(E15:AB15)*D15+SUM(E16:AB16)*D16+SUM(E17:AB17)*D17+SUM(E18:AB18)*D18 -> 0 | AE15: =+AC27 -> 25274336
B16: Feb | C16: Sábado | D16: 4 | E16: =ROUND('[7]2025'!E20,2) -> 0 | F16: =ROUND('[7]2025'!F20,2) -> 0 | G16: =ROUND('[7]2025'!G20,2) -> 0 | H16: =ROUND('[7]2025'!H20,2) -> 0 | I16: =ROUND('[7]2025'!I20,2) -> 0 | J16: =ROUND('[7]2025'!J20,2) -> 0 | K16: =ROUND('[7]2025'!K20,2) -> 0 | L16: =ROUND('[7]2025'!L20,2) -> 0 | ... AB16: =ROUND('[7]2025'!AB20,2) -> 0 | AE16: =+AC31 -> 23289238
B17: Feb | C17: Domingo | D17: 4 | E17: =ROUND('[7]2025'!E21,2) -> 0 | F17: =ROUND('[7]2025'!F21,2) -> 0 | G17: =ROUND('[7]2025'!G21,2) -> 0 | H17: =ROUND('[7]2025'!H21,2) -> 0 | I17: =ROUND('[7]2025'!I21,2) -> 0 | J17: =ROUND('[7]2025'!J21,2) -> 0 | K17: =ROUND('[7]2025'!K21,2) -> 0 | L17: =ROUND('[7]2025'!L21,2) -> 0 | ... AB17: =ROUND('[7]2025'!AB21,2) -> 0 | AE17: =+AC35 -> 30787655
B18: Feb | C18: Festivo | D18: 0 | E18: =ROUND('[7]2025'!E22,2) -> 0 | F18: =ROUND('[7]2025'!F22,2) -> 0 | G18: =ROUND('[7]2025'!G22,2) -> 0 | H18: =ROUND('[7]2025'!H22,2) -> 0 | I18: =ROUND('[7]2025'!I22,2) -> 0 | J18: =ROUND('[7]2025'!J22,2) -> 0 | K18: =ROUND('[7]2025'!K22,2) -> 0 | L18: =ROUND('[7]2025'!L22,2) -> 0 | ... AB18: =ROUND('[7]2025'!AB22,2) -> 0 | AE18: =+AC39 -> 33589040
B19: 45717 | C19: Ordinario | D19: 20 | E19: =ROUND('[7]2025'!E23,2) -> 0 | F19: =ROUND('[7]2025'!F23,2) -> 0 | G19: =ROUND('[7]2025'!G23,2) -> 0 | H19: =ROUND('[7]2025'!H23,2) -> 0 | I19: =ROUND('[7]2025'!I23,2) -> 0 | J19: =ROUND('[7]2025'!J23,2) -> 0 | K19: =ROUND('[7]2025'!K23,2) -> 0 | L19: =ROUND('[7]2025'!L23,2) -> 0 | ... AB19: =ROUND('[7]2025'!AB23,2) -> 0 | AC19: =SUM(E19:AB19)*D19+SUM(E20:AB20)*D20+SUM(E21:AB21)*D21+SUM(E22:AB22)*D22 -> 0 | AE19: =+AC43 -> 35398839
C20: Sábado | D20: 5 | E20: =ROUND('[7]2025'!E24,2) -> 0 | F20: =ROUND('[7]2025'!F24,2) -> 0 | G20: =ROUND('[7]2025'!G24,2) -> 0 | H20: =ROUND('[7]2025'!H24,2) -> 0 | I20: =ROUND('[7]2025'!I24,2) -> 0 | J20: =ROUND('[7]2025'!J24,2) -> 0 | K20: =ROUND('[7]2025'!K24,2) -> 0 | L20: =ROUND('[7]2025'!L24,2) -> 0 | ... AB20: =ROUND('[7]2025'!AB24,2) -> 0 | AE20: =+AC47 -> 30572928
C21: Domingo | D21: 5 | E21: =ROUND('[7]2025'!E25,2) -> 0 | F21: =ROUND('[7]2025'!F25,2) -> 0 | G21: =ROUND('[7]2025'!G25,2) -> 0 | H21: =ROUND('[7]2025'!H25,2) -> 0 | I21: =ROUND('[7]2025'!I25,2) -> 0 | J21: =ROUND('[7]2025'!J25,2) -> 0 | K21: =ROUND('[7]2025'!K25,2) -> 0 | L21: =ROUND('[7]2025'!L25,2) -> 0 | ... AB21: =ROUND('[7]2025'!AB25,2) -> 0 | AE21: =+AC51 -> 34475949
C22: Festivo | D22: 1 | E22: =ROUND('[7]2025'!E26,2) -> 0 | F22: =ROUND('[7]2025'!F26,2) -> 0 | G22: =ROUND('[7]2025'!G26,2) -> 0 | H22: =ROUND('[7]2025'!H26,2) -> 0 | I22: =ROUND('[7]2025'!I26,2) -> 0 | J22: =ROUND('[7]2025'!J26,2) -> 0 | K22: =ROUND('[7]2025'!K26,2) -> 0 | L22: =ROUND('[7]2025'!L26,2) -> 0 | ... AB22: =ROUND('[7]2025'!AB26,2) -> 0 | AE22: =+AC55 -> 24036400
B23: 45748 | C23: Ordinario | D23: 20 | E23: =ROUND('[7]2025'!E27,2) -> 0 | F23: =ROUND('[7]2025'!F27,2) -> 0 | G23: =ROUND('[7]2025'!G27,2) -> 0 | H23: =ROUND('[7]2025'!H27,2) -> 0 | I23: =ROUND('[7]2025'!I27,2) -> 0 | J23: =ROUND('[7]2025'!J27,2) -> 0 | K23: =ROUND('[7]2025'!K27,2) -> 0 | L23: =ROUND('[7]2025'!L27,2) -> 0 | ... AB23: =ROUND('[7]2025'!AB27,2) -> 0 | AC23: =SUM(E23:AB23)*D23+SUM(E24:AB24)*D24+SUM(E25:AB25)*D25+SUM(E26:AB26)*D26 -> 0 | AE23: =SUM(AE11:AE22) -> 2.3742439e+08
B24: Feb | C24: Sábado | D24: 4 | E24: =ROUND('[7]2025'!E28,2) -> 0 | F24: =ROUND('[7]2025'!F28,2) -> 0 | G24: =ROUND('[7]2025'!G28,2) -> 0 | H24: =ROUND('[7]2025'!H28,2) -> 0 | I24: =ROUND('[7]2025'!I28,2) -> 0 | J24: =ROUND('[7]2025'!J28,2) -> 0 | K24: =ROUND('[7]2025'!K28,2) -> 0 | L24: =ROUND('[7]2025'!L28,2) -> 0 | ... AB24: =ROUND('[7]2025'!AB28,2) -> 0
B25: Feb | C25: Domingo | D25: 4 | E25: =ROUND('[7]2025'!E29,2) -> 0 | F25: =ROUND('[7]2025'!F29,2) -> 0 | G25: =ROUND('[7]2025'!G29,2) -> 0 | H25: =ROUND('[7]2025'!H29,2) -> 0 | I25: =ROUND('[7]2025'!I29,2) -> 0 | J25: =ROUND('[7]2025'!J29,2) -> 0 | K25: =ROUND('[7]2025'!K29,2) -> 0 | L25: =ROUND('[7]2025'!L29,2) -> 0 | ... AB25: =ROUND('[7]2025'!AB29,2) -> 0
B26: Feb | C26: Festivo | D26: 2 | E26: =ROUND('[7]2025'!E30,2) -> 0 | F26: =ROUND('[7]2025'!F30,2) -> 0 | G26: =ROUND('[7]2025'!G30,2) -> 0 | H26: =ROUND('[7]2025'!H30,2) -> 0 | I26: =ROUND('[7]2025'!I30,2) -> 0 | J26: =ROUND('[7]2025'!J30,2) -> 0 | K26: =ROUND('[7]2025'!K30,2) -> 0 | L26: =ROUND('[7]2025'!L30,2) -> 0 | ... AB26: =ROUND('[7]2025'!AB30,2) -> 0
B27: 45778 | C27: Ordinario | D27: =+'[7]2025'!D31 -> 21 | E27: =ROUND('[7]2025'!E31,2) -> 25637.02 | F27: =ROUND('[7]2025'!F31,2) -> 24468.25 | G27: =ROUND('[7]2025'!G31,2) -> 23378.3 | H27: =ROUND('[7]2025'!H31,2) -> 22564.64 | I27: =ROUND('[7]2025'!I31,2) -> 23375.01 | J27: =ROUND('[7]2025'!J31,2) -> 19242.88 | K27: =ROUND('[7]2025'!K31,2) -> 23846.74 | L27: =ROUND('[7]2025'!L31,2) -> 33385.23 | ... AB27: =ROUND('[7]2025'!AB31,2) -> 43280.13 | AC27: =SUM(E27:AB27)*D27+SUM(E28:AB28)*D28+SUM(E29:AB29)*D29+SUM(E30:AB30)*D30 -> 25274336
C28: Sábado | D28: =+'[7]2025'!D32 -> 5 | E28: =ROUND('[7]2025'!E32,2) -> 24620.69 | F28: =ROUND('[7]2025'!F32,2) -> 23754.07 | G28: =ROUND('[7]2025'!G32,2) -> 22791.14 | H28: =ROUND('[7]2025'!H32,2) -> 22597.52 | I28: =ROUND('[7]2025'!I32,2) -> 21882.62 | J28: =ROUND('[7]2025'!J32,2) -> 13746.07 | K28: =ROUND('[7]2025'!K32,2) -> 19851.19 | L28: =ROUND('[7]2025'!L32,2) -> 30032.43 | ... AB28: =ROUND('[7]2025'!AB32,2) -> 40891.55
C29: Domingo | D29: =+'[7]2025'!D33 -> 4 | E29: =ROUND('[7]2025'!E33,2) -> 23416.58 | F29: =ROUND('[7]2025'!F33,2) -> 22587.42 | G29: =ROUND('[7]2025'!G33,2) -> 22214.84 | H29: =ROUND('[7]2025'!H33,2) -> 21992.1 | I29: =ROUND('[7]2025'!I33,2) -> 21392.7 | J29: =ROUND('[7]2025'!J33,2) -> 14142.35 | K29: =ROUND('[7]2025'!K33,2) -> 18200.84 | L29: =ROUND('[7]2025'!L33,2) -> 26499.51 | ... AB29: =ROUND('[7]2025'!AB33,2) -> 46260.63
C30: Festivo | D30: =+'[7]2025'!D34 -> 1 | E30: =ROUND('[7]2025'!E34,2) -> 23416.58 | F30: =ROUND('[7]2025'!F34,2) -> 22587.42 | G30: =ROUND('[7]2025'!G34,2) -> 22214.84 | H30: =ROUND('[7]2025'!H34,2) -> 21992.1 | I30: =ROUND('[7]2025'!I34,2) -> 21392.7 | J30: =ROUND('[7]2025'!J34,2) -> 14142.35 | K30: =ROUND('[7]2025'!K34,2) -> 18200.84 | L30: =ROUND('[7]2025'!L34,2) -> 26499.51 | ... AB30: =ROUND('[7]2025'!AB34,2) -> 46260.63
B31: 45809 | C31: Ordinario | D31: =+'[7]2025'!D35 -> 18 | E31: =ROUND('[7]2025'!E35,2) -> 22785.98 | F31: =ROUND('[7]2025'!F35,2) -> 21817.41 | G31: =ROUND('[7]2025'!G35,2) -> 21031.19 | H31: =ROUND('[7]2025'!H35,2) -> 20930.61 | I31: =ROUND('[7]2025'!I35,2) -> 21887.12 | J31: =ROUND('[7]2025'!J35,2) -> 18454.08 | K31: =ROUND('[7]2025'!K35,2) -> 24336.15 | L31: =ROUND('[7]2025'!L35,2) -> 35092.55 | ... AB31: =ROUND('[7]2025'!AB35,2) -> 41475.03 | AC31: =SUM(E31:AB31)*D31+SUM(E32:AB32)*D32+SUM(E33:AB33)*D33+SUM(E34:AB34)*D34 -> 23289238
B32: Feb | C32: Sábado | D32: =+'[7]2025'!D36 -> 4 | E32: =ROUND('[7]2025'!E36,2) -> 20730 | F32: =ROUND('[7]2025'!F36,2) -> 20753.55 | G32: =ROUND('[7]2025'!G36,2) -> 19748.35 | H32: =ROUND('[7]2025'!H36,2) -> 18693.4 | I32: =ROUND('[7]2025'!I36,2) -> 19105.73 | J32: =ROUND('[7]2025'!J36,2) -> 14186.19 | K32: =ROUND('[7]2025'!K36,2) -> 21055.3 | L32: =ROUND('[7]2025'!L36,2) -> 31418.38 | ... AB32: =ROUND('[7]2025'!AB36,2) -> 28865.68
B33: Feb | C33: Domingo | D33: =+'[7]2025'!D37 -> 5 | E33: =ROUND('[7]2025'!E37,2) -> 16146.24 | F33: =ROUND('[7]2025'!F37,2) -> 17076.95 | G33: =ROUND('[7]2025'!G37,2) -> 16856.41 | H33: =ROUND('[7]2025'!H37,2) -> 17301.2 | I33: =ROUND('[7]2025'!I37,2) -> 17072.87 | J33: =ROUND('[7]2025'!J37,2) -> 12647.9 | K33: =ROUND('[7]2025'!K37,2) -> 15999.39 | L33: =ROUND('[7]2025'!L37,2) -> 25882.4 | ... AB33: =ROUND('[7]2025'!AB37,2) -> 41784.91
B34: Feb | C34: Festivo | D34: =+'[7]2025'!D38 -> 3 | E34: =ROUND('[7]2025'!E38,2) -> 16146.24 | F34: =ROUND('[7]2025'!F38,2) -> 17076.95 | G34: =ROUND('[7]2025'!G38,2) -> 16856.41 | H34: =ROUND('[7]2025'!H38,2) -> 17301.2 | I34: =ROUND('[7]2025'!I38,2) -> 17072.87 | J34: =ROUND('[7]2025'!J38,2) -> 12647.9 | K34: =ROUND('[7]2025'!K38,2) -> 15999.39 | L34: =ROUND('[7]2025'!L38,2) -> 25882.4 | ... AB34: =ROUND('[7]2025'!AB38,2) -> 41784.91
B35: 45839 | C35: Ordinario | D35: =+'[7]2025'!D39 -> 23 | E35: =ROUND('[7]2025'!E39,2) -> 29900.11 | F35: =ROUND('[7]2025'!F39,2) -> 27958.87 | G35: =ROUND('[7]2025'!G39,2) -> 26303.72 | H35: =ROUND('[7]2025'!H39,2) -> 25621.13 | I35: =ROUND('[7]2025'!I39,2) -> 25538.33 | J35: =ROUND('[7]2025'!J39,2) -> 21222.87 | K35: =ROUND('[7]2025'!K39,2) -> 26846.43 | L35: =ROUND('[7]2025'!L39,2) -> 37690.8 | ... AB35: =ROUND('[7]2025'!AB39,2) -> 50102.09 | AC35: =SUM(E35:AB35)*D35+SUM(E36:AB36)*D36+SUM(E37:AB37)*D37+SUM(E38:AB38)*D38 -> 30787655
C36: Sábado | D36: =+'[7]2025'!D40 -> 4 | E36: =ROUND('[7]2025'!E40,2) -> 29473.18 | F36: =ROUND('[7]2025'!F40,2) -> 28152.66 | G36: =ROUND('[7]2025'!G40,2) -> 26608.92 | H36: =ROUND('[7]2025'!H40,2) -> 25747.42 | I36: =ROUND('[7]2025'!I40,2) -> 25135.63 | J36: =ROUND('[7]2025'!J40,2) -> 20702.84 | K36: =ROUND('[7]2025'!K40,2) -> 25993.03 | L36: =ROUND('[7]2025'!L40,2) -> 37972.34 | ... AB36: =ROUND('[7]2025'!AB40,2) -> 53501.8
C37: Domingo | D37: =+'[7]2025'!D41 -> 3 | E37: =ROUND('[7]2025'!E41,2) -> 35255.3 | F37: =ROUND('[7]2025'!F41,2) -> 32508.59 | G37: =ROUND('[7]2025'!G41,2) -> 31342.97 | H37: =ROUND('[7]2025'!H41,2) -> 30886.62 | I37: =ROUND('[7]2025'!I41,2) -> 29533.06 | J37: =ROUND('[7]2025'!J41,2) -> 22958.94 | K37: =ROUND('[7]2025'!K41,2) -> 25224.73 | L37: =ROUND('[7]2025'!L41,2) -> 33538.25 | ... AB37: =ROUND('[7]2025'!AB41,2) -> 53180.52
C38: Festivo | D38: =+'[7]2025'!D42 -> 1 | E38: =ROUND('[7]2025'!E42,2) -> 35255.3 | F38: =ROUND('[7]2025'!F42,2) -> 32508.59 | G38: =ROUND('[7]2025'!G42,2) -> 31342.97 | H38: =ROUND('[7]2025'!H42,2) -> 30886.62 | I38: =ROUND('[7]2025'!I42,2) -> 29533.06 | J38: =ROUND('[7]2025'!J42,2) -> 22958.94 | K38: =ROUND('[7]2025'!K42,2) -> 25224.73 | L38: =ROUND('[7]2025'!L42,2) -> 33538.25 | ... AB38: =ROUND('[7]2025'!AB42,2) -> 53180.52
B39: 45870 | C39: Ordinario | D39: =+'[7]2025'!D43 -> 19 | E39: =ROUND('[7]2025'!E43,2) -> 34664.58 | F39: =ROUND('[7]2025'!F43,2) -> 32843.38 | G39: =ROUND('[7]2025'!G43,2) -> 31690.03 | H39: =ROUND('[7]2025'!H43,2) -> 30587.63 | I39: =ROUND('[7]2025'!I43,2) -> 31139.86 | J39: =ROUND('[7]2025'!J43,2) -> 27446.8 | K39: =ROUND('[7]2025'!K43,2) -> 31401.44 | L39: =ROUND('[7]2025'!L43,2) -> 41516.62 | ... AB39: =ROUND('[7]2025'!AB43,2) -> 53675.24 | AC39: =SUM(E39:AB39)*D39+SUM(E40:AB40)*D40+SUM(E41:AB41)*D41+SUM(E42:AB42)*D42 -> 33589040
B40: Feb | C40: Sábado | D40: =+'[7]2025'!D44 -> 5 | E40: =ROUND('[7]2025'!E44,2) -> 36288.84 | F40: =ROUND('[7]2025'!F44,2) -> 35108.56 | G40: =ROUND('[7]2025'!G44,2) -> 34392.01 | H40: =ROUND('[7]2025'!H44,2) -> 32486.25 | I40: =ROUND('[7]2025'!I44,2) -> 31777.5 | J40: =ROUND('[7]2025'!J44,2) -> 26624.35 | K40: =ROUND('[7]2025'!K44,2) -> 30523.43 | L40: =ROUND('[7]2025'!L44,2) -> 41604.94 | ... AB40: =ROUND('[7]2025'!AB44,2) -> 57883.03
