Workbook

Sheet Cantidades 2027
C2: CANTIDADES DE ENERGÍA SOLICITADAS (kWh)
C3: EMPRESAS PÚBLICAS DE MEDELLÍN E.S.P.
C4: 2027
C6: Mes | D6: Tipo Día | E6: Días | F6: H1 | G6: H2 | H6: H3 | I6: H4 | J6: H5 | K6: H6 | L6: H7 | M6: H8 | N6: H9 | O6: H10 | P6: H11 | Q6: H12 | R6: H13 | S6: H14 | T6: H15 | U6: H16 | V6: H17 | W6: H18 | X6: H19 | Y6: H20 | Z6: H21 | AA6: H22 | AB6: H23 | AC6: H24 | AD6: TOTAL MES
C7: Ene | D7: Ordinario | E7: 19 | F7: =+[1]Resumen!F7*1000 -> 43813.642 | G7: =+[1]Resumen!G7*1000 -> 39665.254 | H7: =+[1]Resumen!H7*1000 -> 36828.059 | I7: =+[1]Resumen!I7*1000 -> 36269.994 | J7: =+[1]Resumen!J7*1000 -> 38345.209 | K7: =+[1]Resumen!K7*1000 -> 47715.167 | L7: =+[1]Resumen!L7*1000 -> 58442.347 | M7: =+[1]Resumen!M7*1000 -> 55336.176 | ... AC7: =+[1]Resumen!AC7*1000 -> 35254.686 | AD7: =SUM(F7:AC7)*E7+SUM(F8:AC8)*E8+SUM(F9:AC9)*E9+SUM(F10:AC10)*E10 -> 40268590
D8: Sábado | E8: 5 | F8: =+[1]Resumen!F8*1000 -> 46194.401 | G8: =+[1]Resumen!G8*1000 -> 41036.063 | H8: =+[1]Resumen!H8*1000 -> 37664.072 | I8: =+[1]Resumen!I8*1000 -> 35817.653 | J8: =+[1]Resumen!J8*1000 -> 37198.734 | K8: =+[1]Resumen!K8*1000 -> 42053.352 | L8: =+[1]Resumen!L8*1000 -> 47939.68 | M8: =+[1]Resumen!M8*1000 -> 44469.307 | ... AC8: =+[1]Resumen!AC8*1000 -> 34092.389
D9: Domingo | E9: 5 | F9: =+[1]Resumen!F9*1000 -> 45192.353 | G9: =+[1]Resumen!G9*1000 -> 39849.56 | H9: =+[1]Resumen!H9*1000 -> 35957.4 | I9: =+[1]Resumen!I9*1000 -> 33879.222 | J9: =+[1]Resumen!J9*1000 -> 34169.308 | K9: =+[1]Resumen!K9*1000 -> 36410.747 | L9: =+[1]Resumen!L9*1000 -> 38292.833 | M9: =+[1]Resumen!M9*1000 -> 33298.071 | ... AC9: =+[1]Resumen!AC9*1000 -> 28114.828
D10: Festivo | E10: 2 | F10: =+[1]Resumen!F10*1000 -> 45973.328 | G10: =+[1]Resumen!G10*1000 -> 42913.387 | H10: =+[1]Resumen!H10*1000 -> 41013.358 | I10: =+[1]Resumen!I10*1000 -> 37804.168 | J10: =+[1]Resumen!J10*1000 -> 37810.128 | K10: =+[1]Resumen!K10*1000 -> 38750.848 | L10: =+[1]Resumen!L10*1000 -> 39671.246 | M10: =+[1]Resumen!M10*1000 -> 31541.757 | ... AC10: =+[1]Resumen!AC10*1000 -> 25016.408
C11: Feb | D11: Ordinario | E11: 20 | F11: =+[1]Resumen!F11*1000 -> 48162.847 | G11: =+[1]Resumen!G11*1000 -> 43331.341 | H11: =+[1]Resumen!H11*1000 -> 41032.857 | I11: =+[1]Resumen!I11*1000 -> 40886.006 | J11: =+[1]Resumen!J11*1000 -> 46062.138 | K11: =+[1]Resumen!K11*1000 -> 64182.607 | L11: =+[1]Resumen!L11*1000 -> 73866.923 | M11: =+[1]Resumen!M11*1000 -> 65816.15 | ... AC11: =+[1]Resumen!AC11*1000 -> 38562.637 | AD11: =SUM(F11:AC11)*E11+SUM(F12:AC12)*E12+SUM(F13:AC13)*E13+SUM(F14:AC14)*E14 -> 42743658
D12: Sábado | E12: 4 | F12: =+[1]Resumen!F12*1000 -> 52728.415 | G12: =+[1]Resumen!G12*1000 -> 47353.752 | H12: =+[1]Resumen!H12*1000 -> 43588.394 | I12: =+[1]Resumen!I12*1000 -> 42699.076 | J12: =+[1]Resumen!J12*1000 -> 45335.844 | K12: =+[1]Resumen!K12*1000 -> 50515.339 | L12: =+[1]Resumen!L12*1000 -> 60057.54 | M12: =+[1]Resumen!M12*1000 -> 58343.067 | ... AC12: =+[1]Resumen!AC12*1000 -> 38293.086
D13: Domingo | E13: 4 | F13: =+[1]Resumen!F13*1000 -> 49175.459 | G13: =+[1]Resumen!G13*1000 -> 43335.393 | H13: =+[1]Resumen!H13*1000 -> 39717.105 | I13: =+[1]Resumen!I13*1000 -> 37973.377 | J13: =+[1]Resumen!J13*1000 -> 38578.843 | K13: =+[1]Resumen!K13*1000 -> 40573.264 | L13: =+[1]Resumen!L13*1000 -> 44876.928 | M13: =+[1]Resumen!M13*1000 -> 41089.417 | ... AC13: =+[1]Resumen!AC13*1000 -> 31295.462
D14: Festivo | E14: 0 | F14: =+[1]Resumen!F14*1000 -> 0 | G14: =+[1]Resumen!G14*1000 -> 0 | H14: =+[1]Resumen!H14*1000 -> 0 | I14: =+[1]Resumen!I14*1000 -> 0 | J14: =+[1]Resumen!J14*1000 -> 0 | K14: =+[1]Resumen!K14*1000 -> 0 | L14: =+[1]Resumen!L14*1000 -> 0 | M14: =+[1]Resumen!M14*1000 -> 0 | ... AC14: =+[1]Resumen!AC14*1000 -> 0
C15: Mar | D15: Ordinario | E15: 20 | F15: =+[1]Resumen!F15*1000 -> 45602.346 | G15: =+[1]Resumen!G15*1000 -> 41466.933 | H15: =+[1]Resumen!H15*1000 -> 39227.914 | I15: =+[1]Resumen!I15*1000 -> 39154.496 | J15: =+[1]Resumen!J15*1000 -> 43612.289 | K15: =+[1]Resumen!K15*1000 -> 59705.133 | L15: =+[1]Resumen!L15*1000 -> 68233.622 | M15: =+[1]Resumen!M15*1000 -> 60892.728 | ... AC15: =+[1]Resumen!AC15*1000 -> 35670.822 | AD15: =SUM(F15:AC15)*E15+SUM(F16:AC16)*E16+SUM(F17:AC17)*E17+SUM(F18:AC18)*E18 -> 43700782
D16: Sábado | E16: 4 | F16: =+[1]Resumen!F16*1000 -> 45253.642 | G16: =+[1]Resumen!G16*1000 -> 40768.025 | H16: =+[1]Resumen!H16*1000 -> 37631.079 | I16: =+[1]Resumen!I16*1000 -> 36806.182 | J16: =+[1]Resumen!J16*1000 -> 39701.956 | K16: =+[1]Resumen!K16*1000 -> 45895.301 | L16: =+[1]Resumen!L16*1000 -> 53515.62 | M16: =+[1]Resumen!M16*1000 -> 54207.199 | ... AC16: =+[1]Resumen!AC16*1000 -> 36579.392
D17: Domingo | E17: 4 | F17: =+[1]Resumen!F17*1000 -> 45724.075 | G17: =+[1]Resumen!G17*1000 -> 40525.568 | H17: =+[1]Resumen!H17*1000 -> 36643.448 | I17: =+[1]Resumen!I17*1000 -> 34812.527 | J17: =+[1]Resumen!J17*1000 -> 34871.136 | K17: =+[1]Resumen!K17*1000 -> 36515.981 | L17: =+[1]Resumen!L17*1000 -> 39098.911 | M17: =+[1]Resumen!M17*1000 -> 36423.933 | ... AC17: =+[1]Resumen!AC17*1000 -> 29297.069
D18: Festivo | E18: 3 | F18: =+[1]Resumen!F18*1000 -> 55146.743 | G18: =+[1]Resumen!G18*1000 -> 50360.435 | H18: =+[1]Resumen!H18*1000 -> 46653.286 | I18: =+[1]Resumen!I18*1000 -> 44435.099 | J18: =+[1]Resumen!J18*1000 -> 45416.321 | K18: =+[1]Resumen!K18*1000 -> 46842.985 | L18: =+[1]Resumen!L18*1000 -> 48659.543 | M18: =+[1]Resumen!M18*1000 -> 46812.925 | ... AC18: =+[1]Resumen!AC18*1000 -> 41758.169
C19: Abr | D19: Ordinario | E19: 22 | F19: =+[1]Resumen!F19*1000 -> 43311.265 | G19: =+[1]Resumen!G19*1000 -> 38703.287 | H19: =+[1]Resumen!H19*1000 -> 36360.718 | I19: =+[1]Resumen!I19*1000 -> 36297.043 | J19: =+[1]Resumen!J19*1000 -> 40587.588 | K19: =+[1]Resumen!K19*1000 -> 55183.916 | L19: =+[1]Resumen!L19*1000 -> 64184.649 | M19: =+[1]Resumen!M19*1000 -> 57676.655 | ... AC19: =+[1]Resumen!AC19*1000 -> 35318.174 | AD19: =SUM(F19:AC19)*E19+SUM(F20:AC20)*E20+SUM(F21:AC21)*E21+SUM(F22:AC22)*E22 -> 41482288
D20: Sábado | E20: 4 | F20: =+[1]Resumen!F20*1000 -> 43895.661 | G20: =+[1]Resumen!G20*1000 -> 38220.973 | H20: =+[1]Resumen!H20*1000 -> 34897.797 | I20: =+[1]Resumen!I20*1000 -> 34246.014 | J20: =+[1]Resumen!J20*1000 -> 36382.557 | K20: =+[1]Resumen!K20*1000 -> 41827.771 | L20: =+[1]Resumen!L20*1000 -> 49866.974 | M20: =+[1]Resumen!M20*1000 -> 49003.197 | ... AC20: =+[1]Resumen!AC20*1000 -> 35372.054
D21: Domingo | E21: 4 | F21: =+[1]Resumen!F21*1000 -> 46190.9 | G21: =+[1]Resumen!G21*1000 -> 40514.873 | H21: =+[1]Resumen!H21*1000 -> 36603.729 | I21: =+[1]Resumen!I21*1000 -> 34919.992 | J21: =+[1]Resumen!J21*1000 -> 35186.363 | K21: =+[1]Resumen!K21*1000 -> 36157.015 | L21: =+[1]Resumen!L21*1000 -> 40405.25 | M21: =+[1]Resumen!M21*1000 -> 38010.445 | ... AC21: =+[1]Resumen!AC21*1000 -> 26801.961
D22: Festivo | E22: 0 | F22: =+[1]Resumen!F22*1000 -> 109560.77 | G22: =+[1]Resumen!G22*1000 -> 101670.19 | H22: =+[1]Resumen!H22*1000 -> 96208.357 | I22: =+[1]Resumen!I22*1000 -> 93669.423 | J22: =+[1]Resumen!J22*1000 -> 94584.784 | K22: =+[1]Resumen!K22*1000 -> 96366.153 | L22: =+[1]Resumen!L22*1000 -> 99747.089 | M22: =+[1]Resumen!M22*1000 -> 96639.561 | ... AC22: =+[1]Resumen!AC22*1000 -> 97455.209
C23: May | D23: Ordinario | E23: 19 | F23: =+[1]Resumen!F23*1000 -> 35141.335 | G23: =+[1]Resumen!G23*1000 -> 30280.099 | H23: =+[1]Resumen!H23*1000 -> 27902.655 | I23: =+[1]Resumen!I23*1000 -> 27853.924 | J23: =+[1]Resumen!J23*1000 -> 32039.68 | K23: =+[1]Resumen!K23*1000 -> 48139.892 | L23: =+[1]Resumen!L23*1000 -> 57437.856 | M23: =+[1]Resumen!M23*1000 -> 51729.977 | ... AC23: =+[1]Resumen!AC23*1000 -> 26797.938 | AD23: =SUM(F23:AC23)*E23+SUM(F24:AC24)*E24+SUM(F25:AC25)*E25+SUM(F26:AC26)*E26 -> 34680251
D24: Sábado | E24: 4 | F24: =+[1]Resumen!F24*1000 -> 35875.082 | G24: =+[1]Resumen!G24*1000 -> 30677.377 | H24: =+[1]Resumen!H24*1000 -> 27558.144 | I24: =+[1]Resumen!I24*1000 -> 25987.253 | J24: =+[1]Resumen!J24*1000 -> 26518.698 | K24: =+[1]Resumen!K24*1000 -> 29782.98 | L24: =+[1]Resumen!L24*1000 -> 37368.495 | M24: =+[1]Resumen!M24*1000 -> 37782.296 | ... AC24: =+[1]Resumen!AC24*1000 -> 27114.649
D25: Domingo | E25: 5 | F25: =+[1]Resumen!F25*1000 -> 36190.601 | G25: =+[1]Resumen!G25*1000 -> 31603.937 | H25: =+[1]Resumen!H25*1000 -> 26553.695 | I25: =+[1]Resumen!I25*1000 -> 23001.04 | J25: =+[1]Resumen!J25*1000 -> 20853.918 | K25: =+[1]Resumen!K25*1000 -> 19530.243 | L25: =+[1]Resumen!L25*1000 -> 20795.636 | M25: =+[1]Resumen!M25*1000 -> 18495.821 | ... AC25: =+[1]Resumen!AC25*1000 -> 16825.607
D26: Festivo | E26: 3 | F26: =+[1]Resumen!F26*1000 -> 32618.043 | G26: =+[1]Resumen!G26*1000 -> 27665.577 | H26: =+[1]Resumen!H26*1000 -> 24793.389 | I26: =+[1]Resumen!I26*1000 -> 23586.465 | J26: =+[1]Resumen!J26*1000 -> 27113.976 | K26: =+[1]Resumen!K26*1000 -> 33972.873 | L26: =+[1]Resumen!L26*1000 -> 37259.68 | M26: =+[1]Resumen!M26*1000 -> 34230.956 | ... AC26: =+[1]Resumen!AC26*1000 -> 15376.361
C27: Jun | D27: Ordinario | E27: 21 | F27: =+[1]Resumen!F27*1000 -> 28325.183 | G27: =+[1]Resumen!G27*1000 -> 23892.43 | H27: =+[1]Resumen!H27*1000 -> 21602.528 | I27: =+[1]Resumen!I27*1000 -> 21537.1 | J27: =+[1]Resumen!J27*1000 -> 24055.076 | K27: =+[1]Resumen!K27*1000 -> 33867.597 | L27: =+[1]Resumen!L27*1000 -> 42845.468 | M27: =+[1]Resumen!M27*1000 -> 39415.84 | ... AC27: =+[1]Resumen!AC27*1000 -> 17888.46 | AD27: =SUM(F27:AC27)*E27+SUM(F28:AC28)*E28+SUM(F29:AC29)*E29+SUM(F30:AC30)*E30 -> 27234709
D28: Sábado | E28: 4 | F28: =+[1]Resumen!F28*1000 -> 27883.807 | G28: =+[1]Resumen!G28*1000 -> 23016.111 | H28: =+[1]Resumen!H28*1000 -> 19614.064 | I28: =+[1]Resumen!I28*1000 -> 18496.812 | J28: =+[1]Resumen!J28*1000 -> 19877.309 | K28: =+[1]Resumen!K28*1000 -> 23552.241 | L28: =+[1]Resumen!L28*1000 -> 30830.89 | M28: =+[1]Resumen!M28*1000 -> 30604.155 | ... AC28: =+[1]Resumen!AC28*1000 -> 18128.648
D29: Domingo | E29: 4 | F29: =+[1]Resumen!F29*1000 -> 30211.074 | G29: =+[1]Resumen!G29*1000 -> 25896.936 | H29: =+[1]Resumen!H29*1000 -> 22247.284 | I29: =+[1]Resumen!I29*1000 -> 20860.461 | J29: =+[1]Resumen!J29*1000 -> 20802.884 | K29: =+[1]Resumen!K29*1000 -> 21550.54 | L29: =+[1]Resumen!L29*1000 -> 22613.172 | M29: =+[1]Resumen!M29*1000 -> 18294.529 | ... AC29: =+[1]Resumen!AC29*1000 -> 15511.083
D30: Festivo | E30: 1 | F30: =+[1]Resumen!F30*1000 -> 27732.945 | G30: =+[1]Resumen!G30*1000 -> 23085.912 | H30: =+[1]Resumen!H30*1000 -> 20089.687 | I30: =+[1]Resumen!I30*1000 -> 18779.847 | J30: =+[1]Resumen!J30*1000 -> 18824.436 | K30: =+[1]Resumen!K30*1000 -> 20393.882 | L30: =+[1]Resumen!L30*1000 -> 22184.648 | M30: =+[1]Resumen!M30*1000 -> 17420.144 | ... AC30: =+[1]Resumen!AC30*1000 -> 15902.629
C31: Jul | D31: Ordinario | E31: 20 | F31: =+[1]Resumen!F31*1000 -> 37663.95 | G31: =+[1]Resumen!G31*1000 -> 32840.857 | H31: =+[1]Resumen!H31*1000 -> 30017.352 | I31: =+[1]Resumen!I31*1000 -> 29726.083 | J31: =+[1]Resumen!J31*1000 -> 32122.988 | K31: =+[1]Resumen!K31*1000 -> 42911.076 | L31: =+[1]Resumen!L31*1000 -> 51975.531 | M31: =+[1]Resumen!M31*1000 -> 48760.519 | ... AC31: =+[1]Resumen!AC31*1000 -> 26046.288 | AD31: =SUM(F31:AC31)*E31+SUM(F32:AC32)*E32+SUM(F33:AC33)*E33+SUM(F34:AC34)*E34 -> 34154193
D32: Sábado | E32: 5 | F32: =+[1]Resumen!F32*1000 -> 35916.113 | G32: =+[1]Resumen!G32*1000 -> 31147.71 | H32: =+[1]Resumen!H32*1000 -> 28207.946 | I32: =+[1]Resumen!I32*1000 -> 26690.28 | J32: =+[1]Resumen!J32*1000 -> 28346.407 | K32: =+[1]Resumen!K32*1000 -> 32387.089 | L32: =+[1]Resumen!L32*1000 -> 39455.748 | M32: =+[1]Resumen!M32*1000 -> 39243.341 | ... AC32: =+[1]Resumen!AC32*1000 -> 20336.097
D33: Domingo | E33: 4 | F33: =+[1]Resumen!F33*1000 -> 30132.492 | G33: =+[1]Resumen!G33*1000 -> 25550.275 | H33: =+[1]Resumen!H33*1000 -> 21996.706 | I33: =+[1]Resumen!I33*1000 -> 20094.413 | J33: =+[1]Resumen!J33*1000 -> 20912.187 | K33: =+[1]Resumen!K33*1000 -> 21745.407 | L33: =+[1]Resumen!L33*1000 -> 25242.463 | M33: =+[1]Resumen!M33*1000 -> 22212.207 | ... AC33: =+[1]Resumen!AC33*1000 -> 12812.426
D34: Festivo | E34: 2 | F34: =+[1]Resumen!F34*1000 -> 42831.439 | G34: =+[1]Resumen!G34*1000 -> 36728.58 | H34: =+[1]Resumen!H34*1000 -> 32397.791 | I34: =+[1]Resumen!I34*1000 -> 29753.126 | J34: =+[1]Resumen!J34*1000 -> 27876.462 | K34: =+[1]Resumen!K34*1000 -> 25866.55 | L34: =+[1]Resumen!L34*1000 -> 28362.453 | M34: =+[1]Resumen!M34*1000 -> 25236.247 | ... AC34: =+[1]Resumen!AC34*1000 -> 24120.472
C35: Ago | D35: Ordinario | E35: 21 | F35: =+[1]Resumen!F35*1000 -> 35088.724 | G35: =+[1]Resumen!G35*1000 -> 30172.253 | H35: =+[1]Resumen!H35*1000 -> 27238.442 | I35: =+[1]Resumen!I35*1000 -> 26927.832 | J35: =+[1]Resumen!J35*1000 -> 30454.288 | K35: =+[1]Resumen!K35*1000 -> 43620.265 | L35: =+[1]Resumen!L35*1000 -> 53613.085 | M35: =+[1]Resumen!M35*1000 -> 49126.894 | ... AC35: =+[1]Resumen!AC35*1000 -> 24852.056 | AD35: =SUM(F35:AC35)*E35+SUM(F36:AC36)*E36+SUM(F37:AC37)*E37+SUM(F38:AC38)*E38 -> 33336329
D36: Sábado | E36: 3 | F36: =+[1]Resumen!F36*1000 -> 35089.231 | G36: =+[1]Resumen!G36*1000 -> 30069.087 | H36: =+[1]Resumen!H36*1000 -> 27106.336 | I36: =+[1]Resumen!I36*1000 -> 25327.471 | J36: =+[1]Resumen!J36*1000 -> 27339.716 | K36: =+[1]Resumen!K36*1000 -> 30700.518 | L36: =+[1]Resumen!L36*1000 -> 38204.549 | M36: =+[1]Resumen!M36*1000 -> 38629.059 | ... AC36: =+[1]Resumen!AC36*1000 -> 18339.122
D37: Domingo | E37: 5 | F37: =+[1]Resumen!F37*1000 -> 30382.339 | G37: =+[1]Resumen!G37*1000 -> 26150.149 | H37: =+[1]Resumen!H37*1000 -> 22557.868 | I37: =+[1]Resumen!I37*1000 -> 21173.485 | J37: =+[1]Resumen!J37*1000 -> 21601.121 | K37: =+[1]Resumen!K37*1000 -> 23962.09 | L37: =+[1]Resumen!L37*1000 -> 25643.088 | M37: =+[1]Resumen!M37*1000 -> 22962.331 | ... AC37: =+[1]Resumen!AC37*1000 -> 13322.732
D38: Festivo | E38: 2 | F38: =+[1]Resumen!F38*1000 -> 27244.322 | G38: =+[1]Resumen!G38*1000 -> 22522.035 | H38: =+[1]Resumen!H38*1000 -> 18433.676 | I38: =+[1]Resumen!I38*1000 -> 18016.71 | J38: =+[1]Resumen!J38*1000 -> 17837.45 | K38: =+[1]Resumen!K38*1000 -> 21322.147 | L38: =+[1]Resumen!L38*1000 -> 24853.46 | M38: =+[1]Resumen!M38*1000 -> 20603.632 | ... AC38: =+[1]Resumen!AC38*1000 -> 13341.339
C39: Sep | D39: Ordinario | E39: 22 | F39: =+[1]Resumen!F39*1000 -> 45528.864 | G39: =+[1]Resumen!G39*1000 -> 41140.809 | H39: =+[1]Resumen!H39*1000 -> 38589.913 | I39: =+[1]Resumen!I39*1000 -> 38177.224 | J39: =+[1]Resumen!J39*1000 -> 41541.562 | K39: =+[1]Resumen!K39*1000 -> 55118.825 | L39: =+[1]Resumen!L39*1000 -> 64013.205 | M39: =+[1]Resumen!M39*1000 -> 57927.04 | ... AC39: =+[1]Resumen!AC39*1000 -> 33668.348 | AD39: =SUM(F39:AC39)*E39+SUM(F40:AC40)*E40+SUM(F41:AC41)*E41+SUM(F42:AC42)*E42 -> 40506338
D40: Sábado | E40: 4 | F40: =+[1]Resumen!F40*1000 -> 41601.758 | G40: =+[1]Resumen!G40*1000 -> 37419.336 | H40: =+[1]Resumen!H40*1000 -> 34569.532 | I40: =+[1]Resumen!I40*1000 -> 33397.393 | J40: =+[1]Resumen!J40*1000 -> 35662.845 | K40: =+[1]Resumen!K40*1000 -> 41505.623 | L40: =+[1]Resumen!L40*1000 -> 47772.394 | M40: =+[1]Resumen!M40*1000 -> 47055.738 | ... AC40: =+[1]Resumen!AC40*1000 -> 31817.277
D41: Domingo | E41: 4 | F41: =+[1]Resumen!F41*1000 -> 44723.543 | G41: =+[1]Resumen!G41*1000 -> 38784.716 | H41: =+[1]Resumen!H41*1000 -> 35176.828 | I41: =+[1]Resumen!I41*1000 -> 32810.97 | J41: =+[1]Resumen!J41*1000 -> 32841.809 | K41: =+[1]Resumen!K41*1000 -> 33743.131 | L41: =+[1]Resumen!L41*1000 -> 35968.813 | M41: =+[1]Resumen!M41*1000 -> 32295.471 | ... AC41: =+[1]Resumen!AC41*1000 -> 24134.662
D42: Festivo | E42: 0 | F42: =+[1]Resumen!F42*1000 -> 0 | G42: =+[1]Resumen!G42*1000 -> 0 | H42: =+[1]Resumen!H42*1000 -> 0 | I42: =+[1]Resumen!I42*1000 -> 0 | J42: =+[1]Resumen!J42*1000 -> 0 | K42: =+[1]Resumen!K42*1000 -> 0 | L42: =+[1]Resumen!L42*1000 -> 0 | M42: =+[1]Resumen!M42*1000 -> 0 | ... AC42: =+[1]Resumen!AC42*1000 -> 0
...

Sheet Cantidades 2028
C2: CANTIDADES DE ENERGÍA SOLICITADAS (kWh)
C3: EMPRESAS PÚBLICAS DE MEDELLÍN E.S.P.
C4: 2028
C6: Mes | D6: Tipo Día | E6: Días | F6: H1 | G6: H2 | H6: H3 | I6: H4 | J6: H5 | K6: H6 | L6: H7 | M6: H8 | N6: H9 | O6: H10 | P6: H11 | Q6: H12 | R6: H13 | S6: H14 | T6: H15 | U6: H16 | V6: H17 | W6: H18 | X6: H19 | Y6: H20 | Z6: H21 | AA6: H22 | AB6: H23 | AC6: H24 | AD6: TOTAL MES
C7: Ene | D7: Ordinario | E7: 20 | F7: =+[2]Resumen!F7*1000 -> 74040.341 | G7: =+[2]Resumen!G7*1000 -> 62593.148 | H7: =+[2]Resumen!H7*1000 -> 55846.897 | I7: =+[2]Resumen!I7*1000 -> 55002.529 | J7: =+[2]Resumen!J7*1000 -> 67163.652 | K7: =+[2]Resumen!K7*1000 -> 93269.859 | L7: =+[2]Resumen!L7*1000 -> 122335.52 | M7: =+[2]Resumen!M7*1000 -> 128313.99 | ... AC7: =+[2]Resumen!AC7*1000 -> 74090.195 | AD7: =SUM(F7:AC7)*E7+SUM(F8:AC8)*E8+SUM(F9:AC9)*E9+SUM(F10:AC10)*E10 -> 93960932
D8: Sábado | E8: 4 | F8: =+[2]Resumen!F8*1000 -> 82065.019 | G8: =+[2]Resumen!G8*1000 -> 68304.639 | H8: =+[2]Resumen!H8*1000 -> 60288.156 | I8: =+[2]Resumen!I8*1000 -> 57095.06 | J8: =+[2]Resumen!J8*1000 -> 62884.607 | K8: =+[2]Resumen!K8*1000 -> 76217.862 | L8: =+[2]Resumen!L8*1000 -> 96001.036 | M8: =+[2]Resumen!M8*1000 -> 103611.16 | ... AC8: =+[2]Resumen!AC8*1000 -> 76753.161
D9: Domingo | E9: 5 | F9: =+[2]Resumen!F9*1000 -> 80798.476 | G9: =+[2]Resumen!G9*1000 -> 66381.665 | H9: =+[2]Resumen!H9*1000 -> 57035.044 | I9: =+[2]Resumen!I9*1000 -> 52381.321 | J9: =+[2]Resumen!J9*1000 -> 53407.841 | K9: =+[2]Resumen!K9*1000 -> 59164.634 | L9: =+[2]Resumen!L9*1000 -> 67157.418 | M9: =+[2]Resumen!M9*1000 -> 67579.973 | ... AC9: =+[2]Resumen!AC9*1000 -> 63188.164
D10: Festivo | E10: 2 | F10: =+[2]Resumen!F10*1000 -> 85507.994 | G10: =+[2]Resumen!G10*1000 -> 75103.491 | H10: =+[2]Resumen!H10*1000 -> 67074.881 | I10: =+[2]Resumen!I10*1000 -> 59592.939 | J10: =+[2]Resumen!J10*1000 -> 59302.126 | K10: =+[2]Resumen!K10*1000 -> 61732.99 | L10: =+[2]Resumen!L10*1000 -> 65045.52 | M10: =+[2]Resumen!M10*1000 -> 58823.086 | ... AC10: =+[2]Resumen!AC10*1000 -> 56203.167
C11: Feb | D11: Ordinario | E11: 21 | F11: =+[2]Resumen!F11*1000 -> 72519.999 | G11: =+[2]Resumen!G11*1000 -> 60708.686 | H11: =+[2]Resumen!H11*1000 -> 55035.116 | I11: =+[2]Resumen!I11*1000 -> 54989.185 | J11: =+[2]Resumen!J11*1000 -> 71754.034 | K11: =+[2]Resumen!K11*1000 -> 109886.86 | L11: =+[2]Resumen!L11*1000 -> 139370.93 | M11: =+[2]Resumen!M11*1000 -> 139259.1 | ... AC11: =+[2]Resumen!AC11*1000 -> 71468.334 | AD11: =SUM(F11:AC11)*E11+SUM(F12:AC12)*E12+SUM(F13:AC13)*E13+SUM(F14:AC14)*E14 -> 92294495
D12: Sábado | E12: 4 | F12: =+[2]Resumen!F12*1000 -> 85607.248 | G12: =+[2]Resumen!G12*1000 -> 71824.31 | H12: =+[2]Resumen!H12*1000 -> 63185.711 | I12: =+[2]Resumen!I12*1000 -> 61129.996 | J12: =+[2]Resumen!J12*1000 -> 67709.48 | K12: =+[2]Resumen!K12*1000 -> 79558.743 | L12: =+[2]Resumen!L12*1000 -> 103514.21 | M12: =+[2]Resumen!M12*1000 -> 114315.98 | ... AC12: =+[2]Resumen!AC12*1000 -> 74602.389
D13: Domingo | E13: 4 | F13: =+[2]Resumen!F13*1000 -> 80738.1 | G13: =+[2]Resumen!G13*1000 -> 66168.4 | H13: =+[2]Resumen!H13*1000 -> 56805.832 | I13: =+[2]Resumen!I13*1000 -> 51738.138 | J13: =+[2]Resumen!J13*1000 -> 52662.27 | K13: =+[2]Resumen!K13*1000 -> 57221.353 | L13: =+[2]Resumen!L13*1000 -> 66821.106 | M13: =+[2]Resumen!M13*1000 -> 68062.964 | ... AC13: =+[2]Resumen!AC13*1000 -> 57067.267
D14: Festivo | E14: 0 | F14: =+[2]Resumen!F14*1000 -> 0 | G14: =+[2]Resumen!G14*1000 -> 0 | H14: =+[2]Resumen!H14*1000 -> 0 | I14: =+[2]Resumen!I14*1000 -> 0 | J14: =+[2]Resumen!J14*1000 -> 0 | K14: =+[2]Resumen!K14*1000 -> 0 | L14: =+[2]Resumen!L14*1000 -> 0 | M14: =+[2]Resumen!M14*1000 -> 0 | ... AC14: =+[2]Resumen!AC14*1000 -> 0
C15: Mar | D15: Ordinario | E15: 22 | F15: =+[2]Resumen!F15*1000 -> 75406.387 | G15: =+[2]Resumen!G15*1000 -> 64055.875 | H15: =+[2]Resumen!H15*1000 -> 58179.107 | I15: =+[2]Resumen!I15*1000 -> 58331.825 | J15: =+[2]Resumen!J15*1000 -> 74776.408 | K15: =+[2]Resumen!K15*1000 -> 111526.37 | L15: =+[2]Resumen!L15*1000 -> 139708.71 | M15: =+[2]Resumen!M15*1000 -> 142130.47 | ... AC15: =+[2]Resumen!AC15*1000 -> 73919.501 | AD15: =SUM(F15:AC15)*E15+SUM(F16:AC16)*E16+SUM(F17:AC17)*E17+SUM(F18:AC18)*E18 -> 1.0131428e+08
D16: Sábado | E16: 4 | F16: =+[2]Resumen!F16*1000 -> 81261.18 | G16: =+[2]Resumen!G16*1000 -> 68415.04 | H16: =+[2]Resumen!H16*1000 -> 60575.002 | I16: =+[2]Resumen!I16*1000 -> 58973.034 | J16: =+[2]Resumen!J16*1000 -> 67441.704 | K16: =+[2]Resumen!K16*1000 -> 83945.391 | L16: =+[2]Resumen!L16*1000 -> 107805.94 | M16: =+[2]Resumen!M16*1000 -> 121987.23 | ... AC16: =+[2]Resumen!AC16*1000 -> 80734.26
D17: Domingo | E17: 4 | F17: =+[2]Resumen!F17*1000 -> 82287.898 | G17: =+[2]Resumen!G17*1000 -> 67993.377 | H17: =+[2]Resumen!H17*1000 -> 58435.553 | I17: =+[2]Resumen!I17*1000 -> 53874.298 | J17: =+[2]Resumen!J17*1000 -> 54975.362 | K17: =+[2]Resumen!K17*1000 -> 60677.109 | L17: =+[2]Resumen!L17*1000 -> 69856.51 | M17: =+[2]Resumen!M17*1000 -> 75930.113 | ... AC17: =+[2]Resumen!AC17*1000 -> 64858.93
D18: Festivo | E18: 1 | F18: =+[2]Resumen!F18*1000 -> 91445.314 | G18: =+[2]Resumen!G18*1000 -> 77279.899 | H18: =+[2]Resumen!H18*1000 -> 68316.413 | I18: =+[2]Resumen!I18*1000 -> 64371.972 | J18: =+[2]Resumen!J18*1000 -> 67276.447 | K18: =+[2]Resumen!K18*1000 -> 72963.732 | L18: =+[2]Resumen!L18*1000 -> 81256.532 | M18: =+[2]Resumen!M18*1000 -> 87565.548 | ... AC18: =+[2]Resumen!AC18*1000 -> 76160.902
C19: Abr | D19: Ordinario | E19: 18 | F19: =+[2]Resumen!F19*1000 -> 76681.835 | G19: =+[2]Resumen!G19*1000 -> 64783.213 | H19: =+[2]Resumen!H19*1000 -> 58864.199 | I19: =+[2]Resumen!I19*1000 -> 59070.845 | J19: =+[2]Resumen!J19*1000 -> 74597.974 | K19: =+[2]Resumen!K19*1000 -> 107229.16 | L19: =+[2]Resumen!L19*1000 -> 135644.17 | M19: =+[2]Resumen!M19*1000 -> 140840.51 | ... AC19: =+[2]Resumen!AC19*1000 -> 77143.928 | AD19: =SUM(F19:AC19)*E19+SUM(F20:AC20)*E20+SUM(F21:AC21)*E21+SUM(F22:AC22)*E22 -> 95730393
D20: Sábado | E20: 5 | F20: =+[2]Resumen!F20*1000 -> 80677.985 | G20: =+[2]Resumen!G20*1000 -> 66646.932 | H20: =+[2]Resumen!H20*1000 -> 58728.858 | I20: =+[2]Resumen!I20*1000 -> 56953.268 | J20: =+[2]Resumen!J20*1000 -> 63831.165 | K20: =+[2]Resumen!K20*1000 -> 76791.388 | L20: =+[2]Resumen!L20*1000 -> 97748.845 | M20: =+[2]Resumen!M20*1000 -> 110066.1 | ... AC20: =+[2]Resumen!AC20*1000 -> 80638.728
D21: Domingo | E21: 5 | F21: =+[2]Resumen!F21*1000 -> 85097.416 | G21: =+[2]Resumen!G21*1000 -> 70310.686 | H21: =+[2]Resumen!H21*1000 -> 60793.014 | I21: =+[2]Resumen!I21*1000 -> 56560.895 | J21: =+[2]Resumen!J21*1000 -> 57837.714 | K21: =+[2]Resumen!K21*1000 -> 61234.1 | L21: =+[2]Resumen!L21*1000 -> 72062.32 | M21: =+[2]Resumen!M21*1000 -> 78513.799 | ... AC21: =+[2]Resumen!AC21*1000 -> 63757.422
D22: Festivo | E22: 2 | F22: =+[2]Resumen!F22*1000 -> 93447.52 | G22: =+[2]Resumen!G22*1000 -> 77940.194 | H22: =+[2]Resumen!H22*1000 -> 68100.553 | I22: =+[2]Resumen!I22*1000 -> 63576.356 | J22: =+[2]Resumen!J22*1000 -> 65461.496 | K22: =+[2]Resumen!K22*1000 -> 69306.727 | L22: =+[2]Resumen!L22*1000 -> 77683.804 | M22: =+[2]Resumen!M22*1000 -> 80974.445 | ... AC22: =+[2]Resumen!AC22*1000 -> 79103.065
C23: May | D23: Ordinario | E23: 21 | F23: =+[2]Resumen!F23*1000 -> 75560.718 | G23: =+[2]Resumen!G23*1000 -> 63544.945 | H23: =+[2]Resumen!H23*1000 -> 57552.303 | I23: =+[2]Resumen!I23*1000 -> 58028.941 | J23: =+[2]Resumen!J23*1000 -> 74392.441 | K23: =+[2]Resumen!K23*1000 -> 108919.43 | L23: =+[2]Resumen!L23*1000 -> 138975.54 | M23: =+[2]Resumen!M23*1000 -> 143820.19 | ... AC23: =+[2]Resumen!AC23*1000 -> 76031.066 | AD23: =SUM(F23:AC23)*E23+SUM(F24:AC24)*E24+SUM(F25:AC25)*E25+SUM(F26:AC26)*E26 -> 99950640
D24: Sábado | E24: 4 | F24: =+[2]Resumen!F24*1000 -> 83446.715 | G24: =+[2]Resumen!G24*1000 -> 69415.603 | H24: =+[2]Resumen!H24*1000 -> 61958.117 | I24: =+[2]Resumen!I24*1000 -> 59579.956 | J24: =+[2]Resumen!J24*1000 -> 66301.993 | K24: =+[2]Resumen!K24*1000 -> 77858.045 | L24: =+[2]Resumen!L24*1000 -> 100610.79 | M24: =+[2]Resumen!M24*1000 -> 114600.25 | ... AC24: =+[2]Resumen!AC24*1000 -> 78772.606
D25: Domingo | E25: 4 | F25: =+[2]Resumen!F25*1000 -> 80525.834 | G25: =+[2]Resumen!G25*1000 -> 66624.66 | H25: =+[2]Resumen!H25*1000 -> 56820.333 | I25: =+[2]Resumen!I25*1000 -> 51958.096 | J25: =+[2]Resumen!J25*1000 -> 51232.162 | K25: =+[2]Resumen!K25*1000 -> 53057.032 | L25: =+[2]Resumen!L25*1000 -> 62306.448 | M25: =+[2]Resumen!M25*1000 -> 68159.459 | ... AC25: =+[2]Resumen!AC25*1000 -> 59434.45
D26: Festivo | E26: 2 | F26: =+[2]Resumen!F26*1000 -> 74259.8 | G26: =+[2]Resumen!G26*1000 -> 60772.581 | H26: =+[2]Resumen!H26*1000 -> 53048.968 | I26: =+[2]Resumen!I26*1000 -> 50573.404 | J26: =+[2]Resumen!J26*1000 -> 57573.065 | K26: =+[2]Resumen!K26*1000 -> 68620.062 | L26: =+[2]Resumen!L26*1000 -> 80716.351 | M26: =+[2]Resumen!M26*1000 -> 87879.366 | ... AC26: =+[2]Resumen!AC26*1000 -> 60559.788
C27: Jun | D27: Ordinario | E27: 20 | F27: =+[2]Resumen!F27*1000 -> 68905.993 | G27: =+[2]Resumen!G27*1000 -> 56855.211 | H27: =+[2]Resumen!H27*1000 -> 50683.021 | I27: =+[2]Resumen!I27*1000 -> 50619.252 | J27: =+[2]Resumen!J27*1000 -> 63597.879 | K27: =+[2]Resumen!K27*1000 -> 89115.842 | L27: =+[2]Resumen!L27*1000 -> 118187.93 | M27: =+[2]Resumen!M27*1000 -> 128123.06 | ... AC27: =+[2]Resumen!AC27*1000 -> 67079.87 | AD27: =SUM(F27:AC27)*E27+SUM(F28:AC28)*E28+SUM(F29:AC29)*E29+SUM(F30:AC30)*E30 -> 88752437
D28: Sábado | E28: 4 | F28: =+[2]Resumen!F28*1000 -> 75005.72 | G28: =+[2]Resumen!G28*1000 -> 61299.177 | H28: =+[2]Resumen!H28*1000 -> 52786.284 | I28: =+[2]Resumen!I28*1000 -> 50561.139 | J28: =+[2]Resumen!J28*1000 -> 57056.528 | K28: =+[2]Resumen!K28*1000 -> 68806.422 | L28: =+[2]Resumen!L28*1000 -> 91862.732 | M28: =+[2]Resumen!M28*1000 -> 105932.9 | ... AC28: =+[2]Resumen!AC28*1000 -> 72074.451
D29: Domingo | E29: 4 | F29: =+[2]Resumen!F29*1000 -> 78440.495 | G29: =+[2]Resumen!G29*1000 -> 64806.658 | H29: =+[2]Resumen!H29*1000 -> 55305.682 | I29: =+[2]Resumen!I29*1000 -> 51321.908 | J29: =+[2]Resumen!J29*1000 -> 52224.818 | K29: =+[2]Resumen!K29*1000 -> 54902.669 | L29: =+[2]Resumen!L29*1000 -> 63367.352 | M29: =+[2]Resumen!M29*1000 -> 67690.129 | ... AC29: =+[2]Resumen!AC29*1000 -> 61313.226
D30: Festivo | E30: 2 | F30: =+[2]Resumen!F30*1000 -> 70180.791 | G30: =+[2]Resumen!G30*1000 -> 57070.232 | H30: =+[2]Resumen!H30*1000 -> 48875.37 | I30: =+[2]Resumen!I30*1000 -> 45614.641 | J30: =+[2]Resumen!J30*1000 -> 47852.658 | K30: =+[2]Resumen!K30*1000 -> 52801.233 | L30: =+[2]Resumen!L30*1000 -> 61306.798 | M30: =+[2]Resumen!M30*1000 -> 65070.835 | ... AC30: =+[2]Resumen!AC30*1000 -> 58632.593
C31: Jul | D31: Ordinario | E31: 19 | F31: =+[2]Resumen!F31*1000 -> 66015.9 | G31: =+[2]Resumen!G31*1000 -> 53255.884 | H31: =+[2]Resumen!H31*1000 -> 46226.021 | I31: =+[2]Resumen!I31*1000 -> 45729.247 | J31: =+[2]Resumen!J31*1000 -> 59336.679 | K31: =+[2]Resumen!K31*1000 -> 88734.717 | L31: =+[2]Resumen!L31*1000 -> 117865.76 | M31: =+[2]Resumen!M31*1000 -> 125592.55 | ... AC31: =+[2]Resumen!AC31*1000 -> 65447.958 | AD31: =SUM(F31:AC31)*E31+SUM(F32:AC32)*E32+SUM(F33:AC33)*E33+SUM(F34:AC34)*E34 -> 88100350
D32: Sábado | E32: 5 | F32: =+[2]Resumen!F32*1000 -> 70414.108 | G32: =+[2]Resumen!G32*1000 -> 56527.729 | H32: =+[2]Resumen!H32*1000 -> 48235.738 | I32: =+[2]Resumen!I32*1000 -> 45154.937 | J32: =+[2]Resumen!J32*1000 -> 51772.858 | K32: =+[2]Resumen!K32*1000 -> 64447.76 | L32: =+[2]Resumen!L32*1000 -> 87187.569 | M32: =+[2]Resumen!M32*1000 -> 101466.84 | ... AC32: =+[2]Resumen!AC32*1000 -> 61170.435
D33: Domingo | E33: 5 | F33: =+[2]Resumen!F33*1000 -> 61566.834 | G33: =+[2]Resumen!G33*1000 -> 47091.045 | H33: =+[2]Resumen!H33*1000 -> 37709.082 | I33: =+[2]Resumen!I33*1000 -> 32991.064 | J33: =+[2]Resumen!J33*1000 -> 34758.415 | K33: =+[2]Resumen!K33*1000 -> 38515.248 | L33: =+[2]Resumen!L33*1000 -> 49464.402 | M33: =+[2]Resumen!M33*1000 -> 54602.269 | ... AC33: =+[2]Resumen!AC33*1000 -> 43499.275
D34: Festivo | E34: 2 | F34: =+[2]Resumen!F34*1000 -> 78909.695 | G34: =+[2]Resumen!G34*1000 -> 62812 | H34: =+[2]Resumen!H34*1000 -> 52704.829 | I34: =+[2]Resumen!I34*1000 -> 47458.724 | J34: =+[2]Resumen!J34*1000 -> 46712.832 | K34: =+[2]Resumen!K34*1000 -> 46806.989 | L34: =+[2]Resumen!L34*1000 -> 56848.795 | M34: =+[2]Resumen!M34*1000 -> 61959.06 | ... AC34: =+[2]Resumen!AC34*1000 -> 62306.98
C35: Ago | D35: Ordinario | E35: 21 | F35: =+[2]Resumen!F35*1000 -> 63613.093 | G35: =+[2]Resumen!G35*1000 -> 50783.352 | H35: =+[2]Resumen!H35*1000 -> 43824.725 | I35: =+[2]Resumen!I35*1000 -> 43349.858 | J35: =+[2]Resumen!J35*1000 -> 58610.812 | K35: =+[2]Resumen!K35*1000 -> 91390.6 | L35: =+[2]Resumen!L35*1000 -> 121758.6 | M35: =+[2]Resumen!M35*1000 -> 126878.17 | ... AC35: =+[2]Resumen!AC35*1000 -> 63956.753 | AD35: =SUM(F35:AC35)*E35+SUM(F36:AC36)*E36+SUM(F37:AC37)*E37+SUM(F38:AC38)*E38 -> 89084306
D36: Sábado | E36: 4 | F36: =+[2]Resumen!F36*1000 -> 68546.216 | G36: =+[2]Resumen!G36*1000 -> 55084.384 | H36: =+[2]Resumen!H36*1000 -> 46972.718 | I36: =+[2]Resumen!I36*1000 -> 44206.464 | J36: =+[2]Resumen!J36*1000 -> 51446.695 | K36: =+[2]Resumen!K36*1000 -> 63622.87 | L36: =+[2]Resumen!L36*1000 -> 86890.447 | M36: =+[2]Resumen!M36*1000 -> 101465 | ... AC36: =+[2]Resumen!AC36*1000 -> 58894.959
D37: Domingo | E37: 4 | F37: =+[2]Resumen!F37*1000 -> 64046.095 | G37: =+[2]Resumen!G37*1000 -> 50204.402 | H37: =+[2]Resumen!H37*1000 -> 40452.659 | I37: =+[2]Resumen!I37*1000 -> 36174.458 | J37: =+[2]Resumen!J37*1000 -> 38112.563 | K37: =+[2]Resumen!K37*1000 -> 43693.854 | L37: =+[2]Resumen!L37*1000 -> 51635.009 | M37: =+[2]Resumen!M37*1000 -> 57040.525 | ... AC37: =+[2]Resumen!AC37*1000 -> 47913.601
D38: Festivo | E38: 2 | F38: =+[2]Resumen!F38*1000 -> 58669.334 | G38: =+[2]Resumen!G38*1000 -> 44672.168 | H38: =+[2]Resumen!H38*1000 -> 35101.333 | I38: =+[2]Resumen!I38*1000 -> 33104.12 | J38: =+[2]Resumen!J38*1000 -> 35605.145 | K38: =+[2]Resumen!K38*1000 -> 44037.993 | L38: =+[2]Resumen!L38*1000 -> 56311.535 | M38: =+[2]Resumen!M38*1000 -> 60543.464 | ... AC38: =+[2]Resumen!AC38*1000 -> 47547.563
C39: Sep | D39: Ordinario | E39: 21 | F39: =+[2]Resumen!F39*1000 -> 60745.942 | G39: =+[2]Resumen!G39*1000 -> 48729.488 | H39: =+[2]Resumen!H39*1000 -> 42472.707 | I39: =+[2]Resumen!I39*1000 -> 42087.31 | J39: =+[2]Resumen!J39*1000 -> 57271.497 | K39: =+[2]Resumen!K39*1000 -> 90815.557 | L39: =+[2]Resumen!L39*1000 -> 119966.36 | M39: =+[2]Resumen!M39*1000 -> 123254.76 | ... AC39: =+[2]Resumen!AC39*1000 -> 59379.19 | AD39: =SUM(F39:AC39)*E39+SUM(F40:AC40)*E40+SUM(F41:AC41)*E41+SUM(F42:AC42)*E42 -> 85827980
D40: Sábado | E40: 5 | F40: =+[2]Resumen!F40*1000 -> 64727.941 | G40: =+[2]Resumen!G40*1000 -> 51652.961 | H40: =+[2]Resumen!H40*1000 -> 43292.834 | I40: =+[2]Resumen!I40*1000 -> 41113.343 | J40: =+[2]Resumen!J40*1000 -> 48890.481 | K40: =+[2]Resumen!K40*1000 -> 63709.81 | L40: =+[2]Resumen!L40*1000 -> 85284.172 | M40: =+[2]Resumen!M40*1000 -> 99020.826 | ... AC40: =+[2]Resumen!AC40*1000 -> 61042.378
D41: Domingo | E41: 4 | F41: =+[2]Resumen!F41*1000 -> 65865.108 | G41: =+[2]Resumen!G41*1000 -> 50124.127 | H41: =+[2]Resumen!H41*1000 -> 40788.226 | I41: =+[2]Resumen!I41*1000 -> 35832.007 | J41: =+[2]Resumen!J41*1000 -> 36503.803 | K41: =+[2]Resumen!K41*1000 -> 40128.316 | L41: =+[2]Resumen!L41*1000 -> 48715.467 | M41: =+[2]Resumen!M41*1000 -> 52992.467 | ... AC41: =+[2]Resumen!AC41*1000 -> 43464.282
D42: Festivo | E42: 0 | F42: =+[2]Resumen!F42*1000 -> 0 | G42: =+[2]Resumen!G42*1000 -> 0 | H42: =+[2]Resumen!H42*1000 -> 0 | I42: =+[2]Resumen!I42*1000 -> 0 | J42: =+[2]Resumen!J42*1000 -> 0 | K42: =+[2]Resumen!K42*1000 -> 0 | L42: =+[2]Resumen!L42*1000 -> 0 | M42: =+[2]Resumen!M42*1000 -> 0 | ... AC42: =+[2]Resumen!AC42*1000 -> 0
...

Sheet Cantidades 2029
C2: CANTIDADES DE ENERGÍA SOLICITADAS (kWh)
C3: EMPRESAS PÚBLICAS DE MEDELLÍN E.S.P.
C4: 2029
C6: Mes | D6: Tipo Día | E6: Días | F6: H1 | G6: H2 | H6: H3 | I6: H4 | J6: H5 | K6: H6 | L6: H7 | M6: H8 | N6: H9 | O6: H10 | P6: H11 | Q6: H12 | R6: H13 | S6: H14 | T6: H15 | U6: H16 | V6: H17 | W6: H18 | X6: H19 | Y6: H20 | Z6: H21 | AA6: H22 | AB6: H23 | AC6: H24 | AD6: TOTAL MES
C7: Ene | D7: Ordinario | E7: 21 | F7: =+[3]Resumen!F7*1000 -> 108131.06 | G7: =+[3]Resumen!G7*1000 -> 95731.359 | H7: =+[3]Resumen!H7*1000 -> 88578.898 | I7: =+[3]Resumen!I7*1000 -> 87783.827 | J7: =+[3]Resumen!J7*1000 -> 100104.41 | K7: =+[3]Resumen!K7*1000 -> 128191.54 | L7: =+[3]Resumen!L7*1000 -> 159399.76 | M7: =+[3]Resumen!M7*1000 -> 164500.14 | ... AC7: =+[3]Resumen!AC7*1000 -> 122963.06 | AD7: =SUM(F7:AC7)*E7+SUM(F8:AC8)*E8+SUM(F9:AC9)*E9+SUM(F10:AC10)*E10 -> 1.2550018e+08
D8: Sábado | E8: 4 | F8: =+[3]Resumen!F8*1000 -> 115732.7 | G8: =+[3]Resumen!G8*1000 -> 100987.03 | H8: =+[3]Resumen!H8*1000 -> 92478.203 | I8: =+[3]Resumen!I8*1000 -> 89182.159 | J8: =+[3]Resumen!J8*1000 -> 95712.657 | K8: =+[3]Resumen!K8*1000 -> 110017.33 | L8: =+[3]Resumen!L8*1000 -> 131646.31 | M8: =+[3]Resumen!M8*1000 -> 138816.72 | ... AC8: =+[3]Resumen!AC8*1000 -> 124591.21
D9: Domingo | E9: 4 | F9: =+[3]Resumen!F9*1000 -> 114272.71 | G9: =+[3]Resumen!G9*1000 -> 98772.267 | H9: =+[3]Resumen!H9*1000 -> 88777.787 | I9: =+[3]Resumen!I9*1000 -> 83842.897 | J9: =+[3]Resumen!J9*1000 -> 85016.545 | K9: =+[3]Resumen!K9*1000 -> 91133.23 | L9: =+[3]Resumen!L9*1000 -> 100051.13 | M9: =+[3]Resumen!M9*1000 -> 99211.659 | ... AC9: =+[3]Resumen!AC9*1000 -> 110236.41
D10: Festivo | E10: 2 | F10: =+[3]Resumen!F10*1000 -> 119461.79 | G10: =+[3]Resumen!G10*1000 -> 108274.6 | H10: =+[3]Resumen!H10*1000 -> 99526.775 | I10: =+[3]Resumen!I10*1000 -> 91606.573 | J10: =+[3]Resumen!J10*1000 -> 91346.188 | K10: =+[3]Resumen!K10*1000 -> 93886.047 | L10: =+[3]Resumen!L10*1000 -> 97632.011 | M10: =+[3]Resumen!M10*1000 -> 89610.021 | ... AC10: =+[3]Resumen!AC10*1000 -> 102967.5
C11: Feb | D11: Ordinario | E11: 20 | F11: =+[3]Resumen!F11*1000 -> 116500.89 | G11: =+[3]Resumen!G11*1000 -> 103360.4 | H11: =+[3]Resumen!H11*1000 -> 96981.422 | I11: =+[3]Resumen!I11*1000 -> 96964.908 | J11: =+[3]Resumen!J11*1000 -> 114441.69 | K11: =+[3]Resumen!K11*1000 -> 156282.98 | L11: =+[3]Resumen!L11*1000 -> 188800.4 | M11: =+[3]Resumen!M11*1000 -> 187922.58 | ... AC11: =+[3]Resumen!AC11*1000 -> 130968.31 | AD11: =SUM(F11:AC11)*E11+SUM(F12:AC12)*E12+SUM(F13:AC13)*E13+SUM(F14:AC14)*E14 -> 1.2577248e+08
D12: Sábado | E12: 4 | F12: =+[3]Resumen!F12*1000 -> 129230.17 | G12: =+[3]Resumen!G12*1000 -> 114230.35 | H12: =+[3]Resumen!H12*1000 -> 104918.12 | I12: =+[3]Resumen!I12*1000 -> 103046.9 | J12: =+[3]Resumen!J12*1000 -> 111678.36 | K12: =+[3]Resumen!K12*1000 -> 127747.78 | L12: =+[3]Resumen!L12*1000 -> 155217.31 | M12: =+[3]Resumen!M12*1000 -> 165402.75 | ... AC12: =+[3]Resumen!AC12*1000 -> 134015.27
D13: Domingo | E13: 4 | F13: =+[3]Resumen!F13*1000 -> 124667.64 | G13: =+[3]Resumen!G13*1000 -> 108657.96 | H13: =+[3]Resumen!H13*1000 -> 98484.443 | I13: =+[3]Resumen!I13*1000 -> 93350.32 | J13: =+[3]Resumen!J13*1000 -> 95435.909 | K13: =+[3]Resumen!K13*1000 -> 101800.81 | L13: =+[3]Resumen!L13*1000 -> 114358.74 | M13: =+[3]Resumen!M13*1000 -> 116015.83 | ... AC13: =+[3]Resumen!AC13*1000 -> 115837.98
D14: Festivo | E14: 0 | F14: =+[3]Resumen!F14*1000 -> 0 | G14: =+[3]Resumen!G14*1000 -> 0 | H14: =+[3]Resumen!H14*1000 -> 0 | I14: =+[3]Resumen!I14*1000 -> 0 | J14: =+[3]Resumen!J14*1000 -> 0 | K14: =+[3]Resumen!K14*1000 -> 0 | L14: =+[3]Resumen!L14*1000 -> 0 | M14: =+[3]Resumen!M14*1000 -> 0 | ... AC14: =+[3]Resumen!AC14*1000 -> 0
C15: Mar | D15: Ordinario | E15: 19 | F15: =+[3]Resumen!F15*1000 -> 112667.85 | G15: =+[3]Resumen!G15*1000 -> 100434.21 | H15: =+[3]Resumen!H15*1000 -> 94133.057 | I15: =+[3]Resumen!I15*1000 -> 94374.35 | J15: =+[3]Resumen!J15*1000 -> 111589.42 | K15: =+[3]Resumen!K15*1000 -> 151880.66 | L15: =+[3]Resumen!L15*1000 -> 182660.72 | M15: =+[3]Resumen!M15*1000 -> 184104.09 | ... AC15: =+[3]Resumen!AC15*1000 -> 126508.77 | AD15: =SUM(F15:AC15)*E15+SUM(F16:AC16)*E16+SUM(F17:AC17)*E17+SUM(F18:AC18)*E18 -> 1.3431931e+08
D16: Sábado | E16: 5 | F16: =+[3]Resumen!F16*1000 -> 118704.13 | G16: =+[3]Resumen!G16*1000 -> 104793.22 | H16: =+[3]Resumen!H16*1000 -> 96394.229 | I16: =+[3]Resumen!I16*1000 -> 94776.901 | J16: =+[3]Resumen!J16*1000 -> 104263.73 | K16: =+[3]Resumen!K16*1000 -> 122217.3 | L16: =+[3]Resumen!L16*1000 -> 148530.69 | M16: =+[3]Resumen!M16*1000 -> 162720.57 | ... AC16: =+[3]Resumen!AC16*1000 -> 132452.94
D17: Domingo | E17: 4 | F17: =+[3]Resumen!F17*1000 -> 119435.62 | G17: =+[3]Resumen!G17*1000 -> 103927.65 | H17: =+[3]Resumen!H17*1000 -> 93760.123 | I17: =+[3]Resumen!I17*1000 -> 88819.201 | J17: =+[3]Resumen!J17*1000 -> 90202.92 | K17: =+[3]Resumen!K17*1000 -> 96596.825 | L17: =+[3]Resumen!L17*1000 -> 106780.71 | M17: =+[3]Resumen!M17*1000 -> 112115.31 | ... AC17: =+[3]Resumen!AC17*1000 -> 115238.65
D18: Festivo | E18: 3 | F18: =+[3]Resumen!F18*1000 -> 128481.04 | G18: =+[3]Resumen!G18*1000 -> 113112.42 | H18: =+[3]Resumen!H18*1000 -> 103533.97 | I18: =+[3]Resumen!I18*1000 -> 99471.836 | J18: =+[3]Resumen!J18*1000 -> 102598.24 | K18: =+[3]Resumen!K18*1000 -> 109219.42 | L18: =+[3]Resumen!L18*1000 -> 118385.52 | M18: =+[3]Resumen!M18*1000 -> 123284.19 | ... AC18: =+[3]Resumen!AC18*1000 -> 127083.17
C19: Abr | D19: Ordinario | E19: 21 | F19: =+[3]Resumen!F19*1000 -> 110863.9 | G19: =+[3]Resumen!G19*1000 -> 98176.141 | H19: =+[3]Resumen!H19*1000 -> 91853.927 | I19: =+[3]Resumen!I19*1000 -> 92084.431 | J19: =+[3]Resumen!J19*1000 -> 107805.64 | K19: =+[3]Resumen!K19*1000 -> 142598.85 | L19: =+[3]Resumen!L19*1000 -> 172998.15 | M19: =+[3]Resumen!M19*1000 -> 177656.78 | ... AC19: =+[3]Resumen!AC19*1000 -> 126220.36 | AD19: =SUM(F19:AC19)*E19+SUM(F20:AC20)*E20+SUM(F21:AC21)*E21+SUM(F22:AC22)*E22 -> 1.2816719e+08
D20: Sábado | E20: 4 | F20: =+[3]Resumen!F20*1000 -> 114424.24 | G20: =+[3]Resumen!G20*1000 -> 99520.384 | H20: =+[3]Resumen!H20*1000 -> 91109.948 | I20: =+[3]Resumen!I20*1000 -> 89347.403 | J20: =+[3]Resumen!J20*1000 -> 97188.556 | K20: =+[3]Resumen!K20*1000 -> 111294.22 | L20: =+[3]Resumen!L20*1000 -> 134098.74 | M20: =+[3]Resumen!M20*1000 -> 146041.71 | ... AC20: =+[3]Resumen!AC20*1000 -> 128767.63
D21: Domingo | E21: 5 | F21: =+[3]Resumen!F21*1000 -> 119032.23 | G21: =+[3]Resumen!G21*1000 -> 103270.83 | H21: =+[3]Resumen!H21*1000 -> 93305.067 | I21: =+[3]Resumen!I21*1000 -> 88900 | J21: =+[3]Resumen!J21*1000 -> 90653.569 | K21: =+[3]Resumen!K21*1000 -> 94810.061 | L21: =+[3]Resumen!L21*1000 -> 106766.45 | M21: =+[3]Resumen!M21*1000 -> 112529.57 | ... AC21: =+[3]Resumen!AC21*1000 -> 111542.9
D22: Festivo | E22: 0 | F22: =+[3]Resumen!F22*1000 -> 211200.85 | G22: =+[3]Resumen!G22*1000 -> 192832.67 | H22: =+[3]Resumen!H22*1000 -> 181468.8 | I22: =+[3]Resumen!I22*1000 -> 176314.59 | J22: =+[3]Resumen!J22*1000 -> 178887.75 | K22: =+[3]Resumen!K22*1000 -> 184152.94 | L22: =+[3]Resumen!L22*1000 -> 194805.2 | M22: =+[3]Resumen!M22*1000 -> 196114.96 | ... AC22: =+[3]Resumen!AC22*1000 -> 214317.13
C23: May | D23: Ordinario | E23: 21 | F23: =+[3]Resumen!F23*1000 -> 111665.93 | G23: =+[3]Resumen!G23*1000 -> 98680.12 | H23: =+[3]Resumen!H23*1000 -> 92135.565 | I23: =+[3]Resumen!I23*1000 -> 92563.332 | J23: =+[3]Resumen!J23*1000 -> 108669.42 | K23: =+[3]Resumen!K23*1000 -> 143961.44 | L23: =+[3]Resumen!L23*1000 -> 176443.44 | M23: =+[3]Resumen!M23*1000 -> 181896.78 | ... AC23: =+[3]Resumen!AC23*1000 -> 126935.17 | AD23: =SUM(F23:AC23)*E23+SUM(F24:AC24)*E24+SUM(F25:AC25)*E25+SUM(F26:AC26)*E26 -> 1.3282954e+08
D24: Sábado | E24: 4 | F24: =+[3]Resumen!F24*1000 -> 118922.53 | G24: =+[3]Resumen!G24*1000 -> 103924.51 | H24: =+[3]Resumen!H24*1000 -> 96032.564 | I24: =+[3]Resumen!I24*1000 -> 93648.151 | J24: =+[3]Resumen!J24*1000 -> 101474 | K24: =+[3]Resumen!K24*1000 -> 114229.84 | L24: =+[3]Resumen!L24*1000 -> 140026.38 | M24: =+[3]Resumen!M24*1000 -> 155040.9 | ... AC24: =+[3]Resumen!AC24*1000 -> 129489.87
D25: Domingo | E25: 4 | F25: =+[3]Resumen!F25*1000 -> 116486.08 | G25: =+[3]Resumen!G25*1000 -> 101425.95 | H25: =+[3]Resumen!H25*1000 -> 91176.137 | I25: =+[3]Resumen!I25*1000 -> 86298.366 | J25: =+[3]Resumen!J25*1000 -> 86408.717 | K25: =+[3]Resumen!K25*1000 -> 89155.891 | L25: =+[3]Resumen!L25*1000 -> 100561.4 | M25: =+[3]Resumen!M25*1000 -> 106304.23 | ... AC25: =+[3]Resumen!AC25*1000 -> 110010.07
D26: Festivo | E26: 2 | F26: =+[3]Resumen!F26*1000 -> 109070.58 | G26: =+[3]Resumen!G26*1000 -> 94748.433 | H26: =+[3]Resumen!H26*1000 -> 86312.753 | I26: =+[3]Resumen!I26*1000 -> 83659.793 | J26: =+[3]Resumen!J26*1000 -> 90902.443 | K26: =+[3]Resumen!K26*1000 -> 102165.65 | L26: =+[3]Resumen!L26*1000 -> 115415.88 | M26: =+[3]Resumen!M26*1000 -> 121985.45 | ... AC26: =+[3]Resumen!AC26*1000 -> 109535.57
C27: Jun | D27: Ordinario | E27: 19 | F27: =+[3]Resumen!F27*1000 -> 107622.53 | G27: =+[3]Resumen!G27*1000 -> 94557.666 | H27: =+[3]Resumen!H27*1000 -> 87936.529 | I27: =+[3]Resumen!I27*1000 -> 87928.207 | J27: =+[3]Resumen!J27*1000 -> 101432.68 | K27: =+[3]Resumen!K27*1000 -> 129441.33 | L27: =+[3]Resumen!L27*1000 -> 161253.95 | M27: =+[3]Resumen!M27*1000 -> 171147.17 | ... AC27: =+[3]Resumen!AC27*1000 -> 121045.39 | AD27: =SUM(F27:AC27)*E27+SUM(F28:AC28)*E28+SUM(F29:AC29)*E29+SUM(F30:AC30)*E30 -> 1.2235907e+08
D28: Sábado | E28: 5 | F28: =+[3]Resumen!F28*1000 -> 113336.53 | G28: =+[3]Resumen!G28*1000 -> 98621.33 | H28: =+[3]Resumen!H28*1000 -> 89492.85 | I28: =+[3]Resumen!I28*1000 -> 87109.313 | J28: =+[3]Resumen!J28*1000 -> 94631.908 | K28: =+[3]Resumen!K28*1000 -> 107634.69 | L28: =+[3]Resumen!L28*1000 -> 132844.37 | M28: =+[3]Resumen!M28*1000 -> 147029.18 | ... AC28: =+[3]Resumen!AC28*1000 -> 124206.38
D29: Domingo | E29: 4 | F29: =+[3]Resumen!F29*1000 -> 115837.27 | G29: =+[3]Resumen!G29*1000 -> 101063.85 | H29: =+[3]Resumen!H29*1000 -> 90946.461 | I29: =+[3]Resumen!I29*1000 -> 86646.613 | J29: =+[3]Resumen!J29*1000 -> 87789.987 | K29: =+[3]Resumen!K29*1000 -> 91037.935 | L29: =+[3]Resumen!L29*1000 -> 100858.72 | M29: =+[3]Resumen!M29*1000 -> 104457.99 | ... AC29: =+[3]Resumen!AC29*1000 -> 112704.13
D30: Festivo | E30: 2 | F30: =+[3]Resumen!F30*1000 -> 107299.6 | G30: =+[3]Resumen!G30*1000 -> 93091.009 | H30: =+[3]Resumen!H30*1000 -> 84314.063 | I30: =+[3]Resumen!I30*1000 -> 80834.809 | J30: =+[3]Resumen!J30*1000 -> 83425.979 | K30: =+[3]Resumen!K30*1000 -> 88736.207 | L30: =+[3]Resumen!L30*1000 -> 98293.948 | M30: =+[3]Resumen!M30*1000 -> 101271.49 | ... AC30: =+[3]Resumen!AC30*1000 -> 109996.32
C31: Jul | D31: Ordinario | E31: 20 | F31: =+[3]Resumen!F31*1000 -> 118731.77 | G31: =+[3]Resumen!G31*1000 -> 104986.92 | H31: =+[3]Resumen!H31*1000 -> 97466.925 | I31: =+[3]Resumen!I31*1000 -> 96990.608 | J31: =+[3]Resumen!J31*1000 -> 110870.6 | K31: =+[3]Resumen!K31*1000 -> 142968.44 | L31: =+[3]Resumen!L31*1000 -> 174589.55 | M31: =+[3]Resumen!M31*1000 -> 181608.77 | ... AC31: =+[3]Resumen!AC31*1000 -> 133563.22 | AD31: =SUM(F31:AC31)*E31+SUM(F32:AC32)*E32+SUM(F33:AC33)*E33+SUM(F34:AC34)*E34 -> 1.3366753e+08
D32: Sábado | E32: 4 | F32: =+[3]Resumen!F32*1000 -> 122873.75 | G32: =+[3]Resumen!G32*1000 -> 107923.2 | H32: =+[3]Resumen!H32*1000 -> 99034.927 | I32: =+[3]Resumen!I32*1000 -> 95812.418 | J32: =+[3]Resumen!J32*1000 -> 103148.77 | K32: =+[3]Resumen!K32*1000 -> 117077.71 | L32: =+[3]Resumen!L32*1000 -> 141894.25 | M32: =+[3]Resumen!M32*1000 -> 156220.24 | ... AC32: =+[3]Resumen!AC32*1000 -> 128435.52
D33: Domingo | E33: 5 | F33: =+[3]Resumen!F33*1000 -> 114461.54 | G33: =+[3]Resumen!G33*1000 -> 98926.722 | H33: =+[3]Resumen!H33*1000 -> 88785.462 | I33: =+[3]Resumen!I33*1000 -> 83629.108 | J33: =+[3]Resumen!J33*1000 -> 85515.758 | K33: =+[3]Resumen!K33*1000 -> 89537.839 | L33: =+[3]Resumen!L33*1000 -> 101297.66 | M33: =+[3]Resumen!M33*1000 -> 105370.66 | ... AC33: =+[3]Resumen!AC33*1000 -> 110002.67
D34: Festivo | E34: 2 | F34: =+[3]Resumen!F34*1000 -> 131393.29 | G34: =+[3]Resumen!G34*1000 -> 114445.95 | H34: =+[3]Resumen!H34*1000 -> 103569.27 | I34: =+[3]Resumen!I34*1000 -> 98094.36 | J34: =+[3]Resumen!J34*1000 -> 97833.923 | K34: =+[3]Resumen!K34*1000 -> 98684.602 | L34: =+[3]Resumen!L34*1000 -> 109586.99 | M34: =+[3]Resumen!M34*1000 -> 113951.98 | ... AC34: =+[3]Resumen!AC34*1000 -> 127784.64
C35: Ago | D35: Ordinario | E35: 21 | F35: =+[3]Resumen!F35*1000 -> 116073.25 | G35: =+[3]Resumen!G35*1000 -> 102321.02 | H35: =+[3]Resumen!H35*1000 -> 94908.984 | I35: =+[3]Resumen!I35*1000 -> 94518.625 | J35: =+[3]Resumen!J35*1000 -> 109966.36 | K35: =+[3]Resumen!K35*1000 -> 145208.94 | L35: =+[3]Resumen!L35*1000 -> 178018.56 | M35: =+[3]Resumen!M35*1000 -> 182493.43 | ... AC35: =+[3]Resumen!AC35*1000 -> 131482.17 | AD35: =SUM(F35:AC35)*E35+SUM(F36:AC36)*E36+SUM(F37:AC37)*E37+SUM(F38:AC38)*E38 -> 1.3390988e+08
D36: Sábado | E36: 4 | F36: =+[3]Resumen!F36*1000 -> 120528.5 | G36: =+[3]Resumen!G36*1000 -> 106056.51 | H36: =+[3]Resumen!H36*1000 -> 97368.92 | I36: =+[3]Resumen!I36*1000 -> 94490.762 | J36: =+[3]Resumen!J36*1000 -> 102461.41 | K36: =+[3]Resumen!K36*1000 -> 115720.54 | L36: =+[3]Resumen!L36*1000 -> 140701.9 | M36: =+[3]Resumen!M36*1000 -> 155389.01 | ... AC36: =+[3]Resumen!AC36*1000 -> 124909.99
D37: Domingo | E37: 4 | F37: =+[3]Resumen!F37*1000 -> 115734.9 | G37: =+[3]Resumen!G37*1000 -> 100854.39 | H37: =+[3]Resumen!H37*1000 -> 90415.409 | I37: =+[3]Resumen!I37*1000 -> 85888.477 | J37: =+[3]Resumen!J37*1000 -> 87941.173 | K37: =+[3]Resumen!K37*1000 -> 93807.039 | L37: =+[3]Resumen!L37*1000 -> 102711.05 | M37: =+[3]Resumen!M37*1000 -> 107141.29 | ... AC37: =+[3]Resumen!AC37*1000 -> 113127.46
D38: Festivo | E38: 2 | F38: =+[3]Resumen!F38*1000 -> 110442.53 | G38: =+[3]Resumen!G38*1000 -> 95176.016 | H38: =+[3]Resumen!H38*1000 -> 85028.301 | I38: =+[3]Resumen!I38*1000 -> 82702.55 | J38: =+[3]Resumen!J38*1000 -> 85625.107 | K38: =+[3]Resumen!K38*1000 -> 94525.767 | L38: =+[3]Resumen!L38*1000 -> 107659.29 | M38: =+[3]Resumen!M38*1000 -> 111151.4 | ... AC38: =+[3]Resumen!AC38*1000 -> 113321.92
C39: Sep | D39: Ordinario | E39: 20 | F39: =+[3]Resumen!F39*1000 -> 115541.21 | G39: =+[3]Resumen!G39*1000 -> 102548.99 | H39: =+[3]Resumen!H39*1000 -> 95858.008 | I39: =+[3]Resumen!I39*1000 -> 95546.925 | J39: =+[3]Resumen!J39*1000 -> 111102.69 | K39: =+[3]Resumen!K39*1000 -> 147299.68 | L39: =+[3]Resumen!L39*1000 -> 179235.03 | M39: =+[3]Resumen!M39*1000 -> 182032.03 | ... AC39: =+[3]Resumen!AC39*1000 -> 129354.41 | AD39: =SUM(F39:AC39)*E39+SUM(F40:AC40)*E40+SUM(F41:AC41)*E41+SUM(F42:AC42)*E42 -> 1.3038233e+08
D40: Sábado | E40: 5 | F40: =+[3]Resumen!F40*1000 -> 119334.18 | G40: =+[3]Resumen!G40*1000 -> 105166.67 | H40: =+[3]Resumen!H40*1000 -> 96201.327 | I40: =+[3]Resumen!I40*1000 -> 93929.705 | J40: =+[3]Resumen!J40*1000 -> 102589.25 | K40: =+[3]Resumen!K40*1000 -> 118588.46 | L40: =+[3]Resumen!L40*1000 -> 142425.26 | M40: =+[3]Resumen!M40*1000 -> 156423.26 | ... AC40: =+[3]Resumen!AC40*1000 -> 130122.64
D41: Domingo | E41: 5 | F41: =+[3]Resumen!F41*1000 -> 120294.19 | G41: =+[3]Resumen!G41*1000 -> 103377.33 | H41: =+[3]Resumen!H41*1000 -> 93311.374 | I41: =+[3]Resumen!I41*1000 -> 87996.313 | J41: =+[3]Resumen!J41*1000 -> 88811.175 | K41: =+[3]Resumen!K41*1000 -> 92870.104 | L41: =+[3]Resumen!L41*1000 -> 102449.36 | M41: =+[3]Resumen!M41*1000 -> 105877.15 | ... AC41: =+[3]Resumen!AC41*1000 -> 111553.77
D42: Festivo | E42: 0 | F42: =+[3]Resumen!F42*1000 -> 0 | G42: =+[3]Resumen!G42*1000 -> 0 | H42: =+[3]Resumen!H42*1000 -> 0 | I42: =+[3]Resumen!I42*1000 -> 0 | J42: =+[3]Resumen!J42*1000 -> 0 | K42: =+[3]Resumen!K42*1000 -> 0 | L42: =+[3]Resumen!L42*1000 -> 0 | M42: =+[3]Resumen!M42*1000 -> 0 | ... AC42: =+[3]Resumen!AC42*1000 -> 0
...

Sheet Cantidades 2030
C2: CANTIDADES DE ENERGÍA SOLICITADAS (kWh)
C3: EMPRESAS PÚBLICAS DE MEDELLÍN E.S.P.
C4: 2030
C6: Mes | D6: Tipo Día | E6: Días | F6: H1 | G6: H2 | H6: H3 | I6: H4 | J6: H5 | K6: H6 | L6: H7 | M6: H8 | N6: H9 | O6: H10 | P6: H11 | Q6: H12 | R6: H13 | S6: H14 | T6: H15 | U6: H16 | V6: H17 | W6: H18 | X6: H19 | Y6: H20 | Z6: H21 | AA6: H22 | AB6: H23 | AC6: H24 | AD6: TOTAL MES
C7: Ene | D7: Ordinario | E7: 21 | F7: =+[4]Resumen!F7*1000 -> 112739.97 | G7: =+[4]Resumen!G7*1000 -> 103779.61 | H7: =+[4]Resumen!H7*1000 -> 98635.076 | I7: =+[4]Resumen!I7*1000 -> 98062.913 | J7: =+[4]Resumen!J7*1000 -> 111097.92 | K7: =+[4]Resumen!K7*1000 -> 132061.66 | L7: =+[4]Resumen!L7*1000 -> 155226.58 | M7: =+[4]Resumen!M7*1000 -> 157822.1 | ... AC7: =+[4]Resumen!AC7*1000 -> 125133.55 | AD7: =SUM(F7:AC7)*E7+SUM(F8:AC8)*E8+SUM(F9:AC9)*E9+SUM(F10:AC10)*E10 -> 1.2077596e+08
D8: Sábado | E8: 4 | F8: =+[4]Resumen!F8*1000 -> 122702.85 | G8: =+[4]Resumen!G8*1000 -> 111689.43 | H8: =+[4]Resumen!H8*1000 -> 105357.94 | I8: =+[4]Resumen!I8*1000 -> 102948.76 | J8: =+[4]Resumen!J8*1000 -> 107880.7 | K8: =+[4]Resumen!K8*1000 -> 118561.25 | L8: =+[4]Resumen!L8*1000 -> 134832.09 | M8: =+[4]Resumen!M8*1000 -> 139120.94 | ... AC8: =+[4]Resumen!AC8*1000 -> 131074.47
D9: Domingo | E9: 4 | F9: =+[4]Resumen!F9*1000 -> 121646.71 | G9: =+[4]Resumen!G9*1000 -> 110077.01 | H9: =+[4]Resumen!H9*1000 -> 102621.37 | I9: =+[4]Resumen!I9*1000 -> 98956.838 | J9: =+[4]Resumen!J9*1000 -> 99825.632 | K9: =+[4]Resumen!K9*1000 -> 104371.2 | L9: =+[4]Resumen!L9*1000 -> 111144.33 | M9: =+[4]Resumen!M9*1000 -> 109378.69 | ... AC9: =+[4]Resumen!AC9*1000 -> 120529.76
D10: Festivo | E10: 2 | F10: =+[4]Resumen!F10*1000 -> 124728.04 | G10: =+[4]Resumen!G10*1000 -> 116329.18 | H10: =+[4]Resumen!H10*1000 -> 109688.27 | I10: =+[4]Resumen!I10*1000 -> 103932.03 | J10: =+[4]Resumen!J10*1000 -> 103704.35 | K10: =+[4]Resumen!K10*1000 -> 105637.38 | L10: =+[4]Resumen!L10*1000 -> 108453.04 | M10: =+[4]Resumen!M10*1000 -> 101420.98 | ... AC10: =+[4]Resumen!AC10*1000 -> 114697.82
C11: Feb | D11: Ordinario | E11: 20 | F11: =+[4]Resumen!F11*1000 -> 119021.24 | G11: =+[4]Resumen!G11*1000 -> 109563.13 | H11: =+[4]Resumen!H11*1000 -> 104946.34 | I11: =+[4]Resumen!I11*1000 -> 104931.59 | J11: =+[4]Resumen!J11*1000 -> 122027.89 | K11: =+[4]Resumen!K11*1000 -> 153109.31 | L11: =+[4]Resumen!L11*1000 -> 177430.48 | M11: =+[4]Resumen!M11*1000 -> 175644.15 | ... AC11: =+[4]Resumen!AC11*1000 -> 131208.39 | AD11: =SUM(F11:AC11)*E11+SUM(F12:AC12)*E12+SUM(F13:AC13)*E13+SUM(F14:AC14)*E14 -> 1.1860737e+08
D12: Sábado | E12: 4 | F12: =+[4]Resumen!F12*1000 -> 132750.01 | G12: =+[4]Resumen!G12*1000 -> 121524.27 | H12: =+[4]Resumen!H12*1000 -> 114602.62 | I12: =+[4]Resumen!I12*1000 -> 113162.3 | J12: =+[4]Resumen!J12*1000 -> 119584.97 | K12: =+[4]Resumen!K12*1000 -> 131641.82 | L12: =+[4]Resumen!L12*1000 -> 152192.4 | M12: =+[4]Resumen!M12*1000 -> 158719.55 | ... AC12: =+[4]Resumen!AC12*1000 -> 138575.79
D13: Domingo | E13: 4 | F13: =+[4]Resumen!F13*1000 -> 129645.6 | G13: =+[4]Resumen!G13*1000 -> 117694.04 | H13: =+[4]Resumen!H13*1000 -> 110104.65 | I13: =+[4]Resumen!I13*1000 -> 106278.92 | J13: =+[4]Resumen!J13*1000 -> 107816.81 | K13: =+[4]Resumen!K13*1000 -> 112594.86 | L13: =+[4]Resumen!L13*1000 -> 121981.81 | M13: =+[4]Resumen!M13*1000 -> 121959.91 | ... AC13: =+[4]Resumen!AC13*1000 -> 125391.06
D14: Festivo | E14: 0 | F14: =+[4]Resumen!F14*1000 -> 0 | G14: =+[4]Resumen!G14*1000 -> 0 | H14: =+[4]Resumen!H14*1000 -> 0 | I14: =+[4]Resumen!I14*1000 -> 0 | J14: =+[4]Resumen!J14*1000 -> 0 | K14: =+[4]Resumen!K14*1000 -> 0 | L14: =+[4]Resumen!L14*1000 -> 0 | M14: =+[4]Resumen!M14*1000 -> 0 | ... AC14: =+[4]Resumen!AC14*1000 -> 0
C15: Mar | D15: Ordinario | E15: 20 | F15: =+[4]Resumen!F15*1000 -> 115908.45 | G15: =+[4]Resumen!G15*1000 -> 107038.5 | H15: =+[4]Resumen!H15*1000 -> 102486.69 | I15: =+[4]Resumen!I15*1000 -> 102677.39 | J15: =+[4]Resumen!J15*1000 -> 119557.71 | K15: =+[4]Resumen!K15*1000 -> 149462.02 | L15: =+[4]Resumen!L15*1000 -> 172560.04 | M15: =+[4]Resumen!M15*1000 -> 172504.01 | ... AC15: =+[4]Resumen!AC15*1000 -> 127691.53 | AD15: =SUM(F15:AC15)*E15+SUM(F16:AC16)*E16+SUM(F17:AC17)*E17+SUM(F18:AC18)*E18 -> 1.2740401e+08
D16: Sábado | E16: 5 | F16: =+[4]Resumen!F16*1000 -> 124981.39 | G16: =+[4]Resumen!G16*1000 -> 114495.72 | H16: =+[4]Resumen!H16*1000 -> 108247.7 | I16: =+[4]Resumen!I16*1000 -> 106984.86 | J16: =+[4]Resumen!J16*1000 -> 113963.77 | K16: =+[4]Resumen!K16*1000 -> 127244.52 | L16: =+[4]Resumen!L16*1000 -> 147011.5 | M16: =+[4]Resumen!M16*1000 -> 156146.54 | ... AC16: =+[4]Resumen!AC16*1000 -> 136601.77
D17: Domingo | E17: 5 | F17: =+[4]Resumen!F17*1000 -> 125297.77 | G17: =+[4]Resumen!G17*1000 -> 113651.65 | H17: =+[4]Resumen!H17*1000 -> 106174.42 | I17: =+[4]Resumen!I17*1000 -> 102464.33 | J17: =+[4]Resumen!J17*1000 -> 103544.01 | K17: =+[4]Resumen!K17*1000 -> 108328.83 | L17: =+[4]Resumen!L17*1000 -> 116105.36 | M17: =+[4]Resumen!M17*1000 -> 118713.18 | ... AC17: =+[4]Resumen!AC17*1000 -> 123924.98
D18: Festivo | E18: 1 | F18: =+[4]Resumen!F18*1000 -> 130772.99 | G18: =+[4]Resumen!G18*1000 -> 119339.25 | H18: =+[4]Resumen!H18*1000 -> 112272.23 | I18: =+[4]Resumen!I18*1000 -> 109241.5 | J18: =+[4]Resumen!J18*1000 -> 111622.65 | K18: =+[4]Resumen!K18*1000 -> 116655.23 | L18: =+[4]Resumen!L18*1000 -> 123693.26 | M18: =+[4]Resumen!M18*1000 -> 126032.99 | ... AC18: =+[4]Resumen!AC18*1000 -> 131935.9
C19: Abr | D19: Ordinario | E19: 20 | F19: =+[4]Resumen!F19*1000 -> 115860.71 | G19: =+[4]Resumen!G19*1000 -> 106683.95 | H19: =+[4]Resumen!H19*1000 -> 102101.65 | I19: =+[4]Resumen!I19*1000 -> 102279.73 | J19: =+[4]Resumen!J19*1000 -> 118213.31 | K19: =+[4]Resumen!K19*1000 -> 144487.19 | L19: =+[4]Resumen!L19*1000 -> 167465.74 | M19: =+[4]Resumen!M19*1000 -> 169827.13 | ... AC19: =+[4]Resumen!AC19*1000 -> 128690.81 | AD19: =SUM(F19:AC19)*E19+SUM(F20:AC20)*E20+SUM(F21:AC21)*E21+SUM(F22:AC22)*E22 -> 1.2243437e+08
D20: Sábado | E20: 4 | F20: =+[4]Resumen!F20*1000 -> 123189.79 | G20: =+[4]Resumen!G20*1000 -> 112006.74 | H20: =+[4]Resumen!H20*1000 -> 105711.83 | I20: =+[4]Resumen!I20*1000 -> 104355.04 | J20: =+[4]Resumen!J20*1000 -> 110344.37 | K20: =+[4]Resumen!K20*1000 -> 121021.03 | L20: =+[4]Resumen!L20*1000 -> 138534.05 | M20: =+[4]Resumen!M20*1000 -> 146553.48 | ... AC20: =+[4]Resumen!AC20*1000 -> 135543.1
D21: Domingo | E21: 4 | F21: =+[4]Resumen!F21*1000 -> 126364.65 | G21: =+[4]Resumen!G21*1000 -> 114560.94 | H21: =+[4]Resumen!H21*1000 -> 107067.78 | I21: =+[4]Resumen!I21*1000 -> 103711.24 | J21: =+[4]Resumen!J21*1000 -> 105024.27 | K21: =+[4]Resumen!K21*1000 -> 108289.65 | L21: =+[4]Resumen!L21*1000 -> 117307.1 | M21: =+[4]Resumen!M21*1000 -> 120449.4 | ... AC21: =+[4]Resumen!AC21*1000 -> 122676.91
D22: Festivo | E22: 2 | F22: =+[4]Resumen!F22*1000 -> 131684.58 | G22: =+[4]Resumen!G22*1000 -> 119394.69 | H22: =+[4]Resumen!H22*1000 -> 111817.86 | I22: =+[4]Resumen!I22*1000 -> 108395.2 | J22: =+[4]Resumen!J22*1000 -> 110174.18 | K22: =+[4]Resumen!K22*1000 -> 113750.24 | L22: =+[4]Resumen!L22*1000 -> 120799.2 | M22: =+[4]Resumen!M22*1000 -> 121917.16 | ... AC22: =+[4]Resumen!AC22*1000 -> 133894.59
C23: May | D23: Ordinario | E23: 22 | F23: =+[4]Resumen!F23*1000 -> 106730.16 | G23: =+[4]Resumen!G23*1000 -> 97451.464 | H23: =+[4]Resumen!H23*1000 -> 92774.675 | I23: =+[4]Resumen!I23*1000 -> 93061.759 | J23: =+[4]Resumen!J23*1000 -> 108876.23 | K23: =+[4]Resumen!K23*1000 -> 135080.88 | L23: =+[4]Resumen!L23*1000 -> 159265.98 | M23: =+[4]Resumen!M23*1000 -> 162081.2 | ... AC23: =+[4]Resumen!AC23*1000 -> 119248.42 | AD23: =SUM(F23:AC23)*E23+SUM(F24:AC24)*E24+SUM(F25:AC25)*E25+SUM(F26:AC26)*E26 -> 1.204358e+08
D24: Sábado | E24: 4 | F24: =+[4]Resumen!F24*1000 -> 116592.94 | G24: =+[4]Resumen!G24*1000 -> 105500.05 | H24: =+[4]Resumen!H24*1000 -> 99593.74 | I24: =+[4]Resumen!I24*1000 -> 97850.339 | J24: =+[4]Resumen!J24*1000 -> 103900.31 | K24: =+[4]Resumen!K24*1000 -> 113842.26 | L24: =+[4]Resumen!L24*1000 -> 133302.31 | M24: =+[4]Resumen!M24*1000 -> 142948.5 | ... AC24: =+[4]Resumen!AC24*1000 -> 125979.09
D25: Domingo | E25: 4 | F25: =+[4]Resumen!F25*1000 -> 114802.04 | G25: =+[4]Resumen!G25*1000 -> 103562.77 | H25: =+[4]Resumen!H25*1000 -> 95982.175 | I25: =+[4]Resumen!I25*1000 -> 92400.366 | J25: =+[4]Resumen!J25*1000 -> 92743.858 | K25: =+[4]Resumen!K25*1000 -> 95043.468 | L25: =+[4]Resumen!L25*1000 -> 103943.93 | M25: =+[4]Resumen!M25*1000 -> 107155.89 | ... AC25: =+[4]Resumen!AC25*1000 -> 111935.15
D26: Festivo | E26: 1 | F26: =+[4]Resumen!F26*1000 -> 109066.8 | G26: =+[4]Resumen!G26*1000 -> 98386.721 | H26: =+[4]Resumen!H26*1000 -> 92120.451 | I26: =+[4]Resumen!I26*1000 -> 90106.252 | J26: =+[4]Resumen!J26*1000 -> 95235.078 | K26: =+[4]Resumen!K26*1000 -> 103139.31 | L26: =+[4]Resumen!L26*1000 -> 113064.85 | M26: =+[4]Resumen!M26*1000 -> 116671.82 | ... AC26: =+[4]Resumen!AC26*1000 -> 111621.34
C27: Jun | D27: Ordinario | E27: 18 | F27: =+[4]Resumen!F27*1000 -> 105927.1 | G27: =+[4]Resumen!G27*1000 -> 96457.068 | H27: =+[4]Resumen!H27*1000 -> 91610.392 | I27: =+[4]Resumen!I27*1000 -> 91576.319 | J27: =+[4]Resumen!J27*1000 -> 105504.6 | K27: =+[4]Resumen!K27*1000 -> 126431.46 | L27: =+[4]Resumen!L27*1000 -> 150402.35 | M27: =+[4]Resumen!M27*1000 -> 156781.56 | ... AC27: =+[4]Resumen!AC27*1000 -> 117573.15 | AD27: =SUM(F27:AC27)*E27+SUM(F28:AC28)*E28+SUM(F29:AC29)*E29+SUM(F30:AC30)*E30 -> 1.1260123e+08
D28: Sábado | E28: 5 | F28: =+[4]Resumen!F28*1000 -> 114652.53 | G28: =+[4]Resumen!G28*1000 -> 103564.89 | H28: =+[4]Resumen!H28*1000 -> 96763.068 | I28: =+[4]Resumen!I28*1000 -> 94972.508 | J28: =+[4]Resumen!J28*1000 -> 100778.94 | K28: =+[4]Resumen!K28*1000 -> 110660.77 | L28: =+[4]Resumen!L28*1000 -> 129845.82 | M28: =+[4]Resumen!M28*1000 -> 139167.64 | ... AC28: =+[4]Resumen!AC28*1000 -> 124462.81
D29: Domingo | E29: 5 | F29: =+[4]Resumen!F29*1000 -> 116074.8 | G29: =+[4]Resumen!G29*1000 -> 104940.03 | H29: =+[4]Resumen!H29*1000 -> 97352.063 | I29: =+[4]Resumen!I29*1000 -> 94056.274 | J29: =+[4]Resumen!J29*1000 -> 94953.791 | K29: =+[4]Resumen!K29*1000 -> 97514.039 | L29: =+[4]Resumen!L29*1000 -> 105079.11 | M29: =+[4]Resumen!M29*1000 -> 106692.72 | ... AC29: =+[4]Resumen!AC29*1000 -> 115620.64
D30: Festivo | E30: 2 | F30: =+[4]Resumen!F30*1000 -> 109780.55 | G30: =+[4]Resumen!G30*1000 -> 99134.464 | H30: =+[4]Resumen!H30*1000 -> 92508.449 | I30: =+[4]Resumen!I30*1000 -> 89879.302 | J30: =+[4]Resumen!J30*1000 -> 91929.322 | K30: =+[4]Resumen!K30*1000 -> 95864.224 | L30: =+[4]Resumen!L30*1000 -> 103356.99 | M30: =+[4]Resumen!M30*1000 -> 104580.55 | ... AC30: =+[4]Resumen!AC30*1000 -> 113945.95
C31: Jul | D31: Ordinario | E31: 22 | F31: =+[4]Resumen!F31*1000 -> 114934.67 | G31: =+[4]Resumen!G31*1000 -> 105150.76 | H31: =+[4]Resumen!H31*1000 -> 99816.111 | I31: =+[4]Resumen!I31*1000 -> 99499.827 | J31: =+[4]Resumen!J31*1000 -> 113913.89 | K31: =+[4]Resumen!K31*1000 -> 138013.38 | L31: =+[4]Resumen!L31*1000 -> 161578.2 | M31: =+[4]Resumen!M31*1000 -> 165424.98 | ... AC31: =+[4]Resumen!AC31*1000 -> 127326.32 | AD31: =SUM(F31:AC31)*E31+SUM(F32:AC32)*E32+SUM(F33:AC33)*E33+SUM(F34:AC34)*E34 -> 1.2413667e+08
D32: Sábado | E32: 3 | F32: =+[4]Resumen!F32*1000 -> 122877.59 | G32: =+[4]Resumen!G32*1000 -> 111825.51 | H32: =+[4]Resumen!H32*1000 -> 105218.18 | I32: =+[4]Resumen!I32*1000 -> 102877.13 | J32: =+[4]Resumen!J32*1000 -> 108428.48 | K32: =+[4]Resumen!K32*1000 -> 118811.72 | L32: =+[4]Resumen!L32*1000 -> 137429.27 | M32: =+[4]Resumen!M32*1000 -> 146786.39 | ... AC32: =+[4]Resumen!AC32*1000 -> 129195.54
D33: Domingo | E33: 4 | F33: =+[4]Resumen!F33*1000 -> 117244.07 | G33: =+[4]Resumen!G33*1000 -> 105691.31 | H33: =+[4]Resumen!H33*1000 -> 98133.102 | I33: =+[4]Resumen!I33*1000 -> 94317.126 | J33: =+[4]Resumen!J33*1000 -> 95686.991 | K33: =+[4]Resumen!K33*1000 -> 98709.136 | L33: =+[4]Resumen!L33*1000 -> 107480.26 | M33: =+[4]Resumen!M33*1000 -> 109253.89 | ... AC33: =+[4]Resumen!AC33*1000 -> 115847.66
D34: Festivo | E34: 2 | F34: =+[4]Resumen!F34*1000 -> 128060.78 | G34: =+[4]Resumen!G34*1000 -> 115678.98 | H34: =+[4]Resumen!H34*1000 -> 107755.24 | I34: =+[4]Resumen!I34*1000 -> 103787.96 | J34: =+[4]Resumen!J34*1000 -> 103981.51 | K34: =+[4]Resumen!K34*1000 -> 105085.75 | L34: =+[4]Resumen!L34*1000 -> 113421.98 | M34: =+[4]Resumen!M34*1000 -> 115548.21 | ... AC34: =+[4]Resumen!AC34*1000 -> 127866.3
