Workbook

Sheet Producto 1
A1: ANEXO No. 1A CANTIDADES DE ENERGIA REQUERIDA
A2: CONVOCATORIA PÚBLICA EMSA-CP-EMSC2026-001
A5: AÑO | B5: ENERGIA SOLICITADA | C5: PAGUE LO CONTRATADO
C6: Oferta (%) De la Curva Demanda
B7: Necesidad TOTAL AÑO kWh | C7: % | D7: Oferta $/kWh
A8: 46388 | B8: =VLOOKUP(A8,'Cant producto 1_2027-2028'!$A$6:$AC$77,29,FALSE) -> 7440000
A9: 46419 | B9: =VLOOKUP(A9,'Cant producto 1_2027-2028'!$A$6:$AC$77,29,FALSE) -> 6720000
A10: 46447 | B10: =VLOOKUP(A10,'Cant producto 1_2027-2028'!$A$6:$AC$77,29,FALSE) -> 7440000
A11: 46478 | B11: =VLOOKUP(A11,'Cant producto 1_2027-2028'!$A$6:$AC$77,29,FALSE) -> 7200000
A12: 46508 | B12: =VLOOKUP(A12,'Cant producto 1_2027-2028'!$A$6:$AC$77,29,FALSE) -> 7440000
A13: 46539 | B13: =VLOOKUP(A13,'Cant producto 1_2027-2028'!$A$6:$AC$77,29,FALSE) -> 7200000
A14: 46569 | B14: =VLOOKUP(A14,'Cant producto 1_2027-2028'!$A$6:$AC$77,29,FALSE) -> 7440000
A15: 46600 | B15: =VLOOKUP(A15,'Cant producto 1_2027-2028'!$A$6:$AC$77,29,FALSE) -> 7440000
A16: 46631 | B16: =VLOOKUP(A16,'Cant producto 1_2027-2028'!$A$6:$AC$77,29,FALSE) -> 7200000
A17: 46661 | B17: =VLOOKUP(A17,'Cant producto 1_2027-2028'!$A$6:$AC$77,29,FALSE) -> 7440000
A18: 46692 | B18: =VLOOKUP(A18,'Cant producto 1_2027-2028'!$A$6:$AC$77,29,FALSE) -> 7200000
A19: 46722 | B19: =VLOOKUP(A19,'Cant producto 1_2027-2028'!$A$6:$AC$77,29,FALSE) -> 7440000
... A31: 47088 | B31: =VLOOKUP(A31,'Cant producto 1_2027-2028'!$A$6:$AC$77,29,FALSE) -> 11160000
A32: TOTAL | B32: =SUM(B8:B31) -> 219360000
A34: NOMBRE Y FIRMA DEL REPRESENTANTE LEGAL
A35: AGENTE PROPONENTE
A37: NOTAS:
A39: Se acepta adjudicaciones parciales: NO___ SI_____

Sheet Cant producto 1_2027-2028
A1: ANEXO No. 1
A2: ENERGIA ELECTRICA PLANA ENERO-2027 A DICIEMBRE-2028
A3: CONVOCATORIA PÚBLICA EMSA No. CP-EMSC2026-001
B4: HORA | C4: 1 | D4: 2 | E4: 3 | F4: 4 | G4: 5 | H4: 6 | I4: 7 | J4: 8 | K4: 9 | L4: 10 | M4: 11 | N4: 12 | O4: 13 | P4: 14 | Q4: 15 | R4: 16 | S4: 17 | T4: 18 | U4: 19 | V4: 20 | W4: 21 | X4: 22 | Y4: 23 | Z4: 24 | AA4: # DIAS | AB4: TOTAL | AC4: MES
A5: MES/AÑO | B5: TIPO DE DIA | C5: kWh | D5: kWh | E5: kWh | F5: kWh | G5: kWh | H5: kWh | I5: kWh | J5: kWh | K5: kWh | L5: kWh | M5: kWh | N5: kWh | O5: kWh | P5: kWh | Q5: kWh | R5: kWh | S5: kWh | T5: kWh | U5: kWh | V5: kWh | W5: kWh | X5: kWh | Y5: kWh | Z5: kWh
A6: 46388 | B6: NORMAL | C6: 10000 | D6: =+C6 -> 10000 | E6: =+D6 -> 10000 | F6: =+E6 -> 10000 | G6: =+F6 -> 10000 | H6: =+G6 -> 10000 | I6: =+H6 -> 10000 | J6: =+I6 -> 10000 | K6: =+J6 -> 10000 | ... Z6: =+Y6 -> 10000 | AA6: 19 | AB6: =+SUM(C6:Z6)*AA6 -> 4560000 | AC6: =+AB6+AB7+AB8 -> 7440000
B7: SABADO | C7: 10000 | D7: =+C7 -> 10000 | E7: =+D7 -> 10000 | F7: =+E7 -> 10000 | G7: =+F7 -> 10000 | H7: =+G7 -> 10000 | I7: =+H7 -> 10000 | J7: =+I7 -> 10000 | K7: =+J7 -> 10000 | ... Z7: =+Y7 -> 10000 | AA7: 5 | AB7: =+SUM(C7:Z7)*AA7 -> 1200000
B8: DOM/FES | C8: 10000 | D8: =+C8 -> 10000 | E8: =+D8 -> 10000 | F8: =+E8 -> 10000 | G8: =+F8 -> 10000 | H8: =+G8 -> 10000 | I8: =+H8 -> 10000 | J8: =+I8 -> 10000 | K8: =+J8 -> 10000 | ... Z8: =+Y8 -> 10000 | AA8: 7 | AB8: =+SUM(C8:Z8)*AA8 -> 1680000
A9: 46419 | B9: NORMAL | C9: 10000 | D9: =+C9 -> 10000 | E9: =+D9 -> 10000 | F9: =+E9 -> 10000 | G9: =+F9 -> 10000 | H9: =+G9 -> 10000 | I9: =+H9 -> 10000 | J9: =+I9 -> 10000 | K9: =+J9 -> 10000 | ... Z9: =+Y9 -> 10000 | AA9: 20 | AB9: =+SUM(C9:Z9)*AA9 -> 4800000 | AC9: =+AB9+AB10+AB11 -> 6720000
B10: SABADO | C10: 10000 | D10: =+C10 -> 10000 | E10: =+D10 -> 10000 | F10: =+E10 -> 10000 | G10: =+F10 -> 10000 | H10: =+G10 -> 10000 | I10: =+H10 -> 10000 | J10: =+I10 -> 10000 | K10: =+J10 -> 10000 | ... Z10: =+Y10 -> 10000 | AA10: 4 | AB10: =+SUM(C10:Z10)*AA10 -> 960000
B11: DOM/FES | C11: 10000 | D11: =+C11 -> 10000 | E11: =+D11 -> 10000 | F11: =+E11 -> 10000 | G11: =+F11 -> 10000 | H11: =+G11 -> 10000 | I11: =+H11 -> 10000 | J11: =+I11 -> 10000 | K11: =+J11 -> 10000 | ... Z11: =+Y11 -> 10000 | AA11: 4 | AB11: =+SUM(C11:Z11)*AA11 -> 960000
A12: 46447 | B12: NORMAL | C12: 10000 | D12: =+C12 -> 10000 | E12: =+D12 -> 10000 | F12: =+E12 -> 10000 | G12: =+F12 -> 10000 | H12: =+G12 -> 10000 | I12: =+H12 -> 10000 | J12: =+I12 -> 10000 | K12: =+J12 -> 10000 | ... Z12: =+Y12 -> 10000 | AA12: 20 | AB12: =+SUM(C12:Z12)*AA12 -> 4800000 | AC12: =+AB12+AB13+AB14 -> 7440000
B13: SABADO | C13: 10000 | D13: =+C13 -> 10000 | E13: =+D13 -> 10000 | F13: =+E13 -> 10000 | G13: =+F13 -> 10000 | H13: =+G13 -> 10000 | I13: =+H13 -> 10000 | J13: =+I13 -> 10000 | K13: =+J13 -> 10000 | ... Z13: =+Y13 -> 10000 | AA13: 4 | AB13: =+SUM(C13:Z13)*AA13 -> 960000
B14: DOM/FES | C14: 10000 | D14: =+C14 -> 10000 | E14: =+D14 -> 10000 | F14: =+E14 -> 10000 | G14: =+F14 -> 10000 | H14: =+G14 -> 10000 | I14: =+H14 -> 10000 | J14: =+I14 -> 10000 | K14: =+J14 -> 10000 | ... Z14: =+Y14 -> 10000 | AA14: 7 | AB14: =+SUM(C14:Z14)*AA14 -> 1680000
A15: 46478 | B15: NORMAL | C15: 10000 | D15: =+C15 -> 10000 | E15: =+D15 -> 10000 | F15: =+E15 -> 10000 | G15: =+F15 -> 10000 | H15: =+G15 -> 10000 | I15: =+H15 -> 10000 | J15: =+I15 -> 10000 | K15: =+J15 -> 10000 | ... Z15: =+Y15 -> 10000 | AA15: 22 | AB15: =+SUM(C15:Z15)*AA15 -> 5280000 | AC15: =+AB15+AB16+AB17 -> 7200000
B16: SABADO | C16: 10000 | D16: =+C16 -> 10000 | E16: =+D16 -> 10000 | F16: =+E16 -> 10000 | G16: =+F16 -> 10000 | H16: =+G16 -> 10000 | I16: =+H16 -> 10000 | J16: =+I16 -> 10000 | K16: =+J16 -> 10000 | ... Z16: =+Y16 -> 10000 | AA16: 4 | AB16: =+SUM(C16:Z16)*AA16 -> 960000
B17: DOM/FES | C17: 10000 | D17: =+C17 -> 10000 | E17: =+D17 -> 10000 | F17: =+E17 -> 10000 | G17: =+F17 -> 10000 | H17: =+G17 -> 10000 | I17: =+H17 -> 10000 | J17: =+I17 -> 10000 | K17: =+J17 -> 10000 | ... Z17: =+Y17 -> 10000 | AA17: 4 | AB17: =+SUM(C17:Z17)*AA17 -> 960000
A18: 46508 | B18: NORMAL | C18: 10000 | D18: =+C18 -> 10000 | E18: =+D18 -> 10000 | F18: =+E18 -> 10000 | G18: =+F18 -> 10000 | H18: =+G18 -> 10000 | I18: =+H18 -> 10000 | J18: =+I18 -> 10000 | K18: =+J18 -> 10000 | ... Z18: =+Y18 -> 10000 | AA18: 19 | AB18: =+SUM(C18:Z18)*AA18 -> 4560000 | AC18: =+AB18+AB19+AB20 -> 7440000
B19: SABADO | C19: 10000 | D19: =+C19 -> 10000 | E19: =+D19 -> 10000 | F19: =+E19 -> 10000 | G19: =+F19 -> 10000 | H19: =+G19 -> 10000 | I19: =+H19 -> 10000 | J19: =+I19 -> 10000 | K19: =+J19 -> 10000 | ... Z19: =+Y19 -> 10000 | AA19: 4 | AB19: =+SUM(C19:Z19)*AA19 -> 960000
B20: DOM/FES | C20: 10000 | D20: =+C20 -> 10000 | E20: =+D20 -> 10000 | F20: =+E20 -> 10000 | G20: =+F20 -> 10000 | H20: =+G20 -> 10000 | I20: =+H20 -> 10000 | J20: =+I20 -> 10000 | K20: =+J20 -> 10000 | ... Z20: =+Y20 -> 10000 | AA20: 8 | AB20: =+SUM(C20:Z20)*AA20 -> 1920000
A21: 46539 | B21: NORMAL | C21: 10000 | D21: =+C21 -> 10000 | E21: =+D21 -> 10000 | F21: =+E21 -> 10000 | G21: =+F21 -> 10000 | H21: =+G21 -> 10000 | I21: =+H21 -> 10000 | J21: =+I21 -> 10000 | K21: =+J21 -> 10000 | ... Z21: =+Y21 -> 10000 | AA21: 21 | AB21: =+SUM(C21:Z21)*AA21 -> 5040000 | AC21: =+AB21+AB22+AB23 -> 7200000
B22: SABADO | C22: 10000 | D22: =+C22 -> 10000 | E22: =+D22 -> 10000 | F22: =+E22 -> 10000 | G22: =+F22 -> 10000 | H22: =+G22 -> 10000 | I22: =+H22 -> 10000 | J22: =+I22 -> 10000 | K22: =+J22 -> 10000 | ... Z22: =+Y22 -> 10000 | AA22: 4 | AB22: =+SUM(C22:Z22)*AA22 -> 960000
B23: DOM/FES | C23: 10000 | D23: =+C23 -> 10000 | E23: =+D23 -> 10000 | F23: =+E23 -> 10000 | G23: =+F23 -> 10000 | H23: =+G23 -> 10000 | I23: =+H23 -> 10000 | J23: =+I23 -> 10000 | K23: =+J23 -> 10000 | ... Z23: =+Y23 -> 10000 | AA23: 5 | AB23: =+SUM(C23:Z23)*AA23 -> 1200000
A24: 46569 | B24: NORMAL | C24: 10000 | D24: =+C24 -> 10000 | E24: =+D24 -> 10000 | F24: =+E24 -> 10000 | G24: =+F24 -> 10000 | H24: =+G24 -> 10000 | I24: =+H24 -> 10000 | J24: =+I24 -> 10000 | K24: =+J24 -> 10000 | ... Z24: =+Y24 -> 10000 | AA24: 20 | AB24: =+SUM(C24:Z24)*AA24 -> 4800000 | AC24: =+AB24+AB25+AB26 -> 7440000
B25: SABADO | C25: 10000 | D25: =+C25 -> 10000 | E25: =+D25 -> 10000 | F25: =+E25 -> 10000 | G25: =+F25 -> 10000 | H25: =+G25 -> 10000 | I25: =+H25 -> 10000 | J25: =+I25 -> 10000 | K25: =+J25 -> 10000 | ... Z25: =+Y25 -> 10000 | AA25: 5 | AB25: =+SUM(C25:Z25)*AA25 -> 1200000
B26: DOM/FES | C26: 10000 | D26: =+C26 -> 10000 | E26: =+D26 -> 10000 | F26: =+E26 -> 10000 | G26: =+F26 -> 10000 | H26: =+G26 -> 10000 | I26: =+H26 -> 10000 | J26: =+I26 -> 10000 | K26: =+J26 -> 10000 | ... Z26: =+Y26 -> 10000 | AA26: 6 | AB26: =+SUM(C26:Z26)*AA26 -> 1440000
A27: 46600 | B27: NORMAL | C27: 10000 | D27: =+C27 -> 10000 | E27: =+D27 -> 10000 | F27: =+E27 -> 10000 | G27: =+F27 -> 10000 | H27: =+G27 -> 10000 | I27: =+H27 -> 10000 | J27: =+I27 -> 10000 | K27: =+J27 -> 10000 | ... Z27: =+Y27 -> 10000 | AA27: 21 | AB27: =+SUM(C27:Z27)*AA27 -> 5040000 | AC27: =+AB27+AB28+AB29 -> 7440000
B28: SABADO | C28: 10000 | D28: =+C28 -> 10000 | E28: =+D28 -> 10000 | F28: =+E28 -> 10000 | G28: =+F28 -> 10000 | H28: =+G28 -> 10000 | I28: =+H28 -> 10000 | J28: =+I28 -> 10000 | K28: =+J28 -> 10000 | ... Z28: =+Y28 -> 10000 | AA28: 3 | AB28: =+SUM(C28:Z28)*AA28 -> 720000
B29: DOM/FES | C29: 10000 | D29: =+C29 -> 10000 | E29: =+D29 -> 10000 | F29: =+E29 -> 10000 | G29: =+F29 -> 10000 | H29: =+G29 -> 10000 | I29: =+H29 -> 10000 | J29: =+I29 -> 10000 | K29: =+J29 -> 10000 | ... Z29: =+Y29 -> 10000 | AA29: 7 | AB29: =+SUM(C29:Z29)*AA29 -> 1680000
A30: 46631 | B30: NORMAL | C30: 10000 | D30: =+C30 -> 10000 | E30: =+D30 -> 10000 | F30: =+E30 -> 10000 | G30: =+F30 -> 10000 | H30: =+G30 -> 10000 | I30: =+H30 -> 10000 | J30: =+I30 -> 10000 | K30: =+J30 -> 10000 | ... Z30: =+Y30 -> 10000 | AA30: 22 | AB30: =+SUM(C30:Z30)*AA30 -> 5280000 | AC30: =+AB30+AB31+AB32 -> 7200000
B31: SABADO | C31: 10000 | D31: =+C31 -> 10000 | E31: =+D31 -> 10000 | F31: =+E31 -> 10000 | G31: =+F31 -> 10000 | H31: =+G31 -> 10000 | I31: =+H31 -> 10000 | J31: =+I31 -> 10000 | K31: =+J31 -> 10000 | ... Z31: =+Y31 -> 10000 | AA31: 4 | AB31: =+SUM(C31:Z31)*AA31 -> 960000
B32: DOM/FES | C32: 10000 | D32: =+C32 -> 10000 | E32: =+D32 -> 10000 | F32: =+E32 -> 10000 | G32: =+F32 -> 10000 | H32: =+G32 -> 10000 | I32: =+H32 -> 10000 | J32: =+I32 -> 10000 | K32: =+J32 -> 10000 | ... Z32: =+Y32 -> 10000 | AA32: 4 | AB32: =+SUM(C32:Z32)*AA32 -> 960000
A33: 46661 | B33: NORMAL | C33: 10000 | D33: =+C33 -> 10000 | E33: =+D33 -> 10000 | F33: =+E33 -> 10000 | G33: =+F33 -> 10000 | H33: =+G33 -> 10000 | I33: =+H33 -> 10000 | J33: =+I33 -> 10000 | K33: =+J33 -> 10000 | ... Z33: =+Y33 -> 10000 | AA33: 20 | AB33: =+SUM(C33:Z33)*AA33 -> 4800000 | AC33: =+AB33+AB34+AB35 -> 7440000
B34: SABADO | C34: 10000 | D34: =+C34 -> 10000 | E34: =+D34 -> 10000 | F34: =+E34 -> 10000 | G34: =+F34 -> 10000 | H34: =+G34 -> 10000 | I34: =+H34 -> 10000 | J34: =+I34 -> 10000 | K34: =+J34 -> 10000 | ... Z34: =+Y34 -> 10000 | AA34: 5 | AB34: =+SUM(C34:Z34)*AA34 -> 1200000
B35: DOM/FES | C35: 10000 | D35: =+C35 -> 10000 | E35: =+D35 -> 10000 | F35: =+E35 -> 10000 | G35: =+F35 -> 10000 | H35: =+G35 -> 10000 | I35: =+H35 -> 10000 | J35: =+I35 -> 10000 | K35: =+J35 -> 10000 | ... Z35: =+Y35 -> 10000 | AA35: 6 | AB35: =+SUM(C35:Z35)*AA35 -> 1440000
A36: 46692 | B36: NORMAL | C36: 10000 | D36: =+C36 -> 10000 | E36: =+D36 -> 10000 | F36: =+E36 -> 10000 | G36: =+F36 -> 10000 | H36: =+G36 -> 10000 | I36: =+H36 -> 10000 | J36: =+I36 -> 10000 | K36: =+J36 -> 10000 | ... Z36: =+Y36 -> 10000 | AA36: 20 | AB36: =+SUM(C36:Z36)*AA36 -> 4800000 | AC36: =+AB36+AB37+AB38 -> 7200000
B37: SABADO | C37: 10000 | D37: =+C37 -> 10000 | E37: =+D37 -> 10000 | F37: =+E37 -> 10000 | G37: =+F37 -> 10000 | H37: =+G37 -> 10000 | I37: =+H37 -> 10000 | J37: =+I37 -> 10000 | K37: =+J37 -> 10000 | ... Z37: =+Y37 -> 10000 | AA37: 4 | AB37: =+SUM(C37:Z37)*AA37 -> 960000
B38: DOM/FES | C38: 10000 | D38: =+C38 -> 10000 | E38: =+D38 -> 10000 | F38: =+E38 -> 10000 | G38: =+F38 -> 10000 | H38: =+G38 -> 10000 | I38: =+H38 -> 10000 | J38: =+I38 -> 10000 | K38: =+J38 -> 10000 | ... Z38: =+Y38 -> 10000 | AA38: 6 | AB38: =+SUM(C38:Z38)*AA38 -> 1440000
A39: 46722 | B39: NORMAL | C39: 10000 | D39: =+C39 -> 10000 | E39: =+D39 -> 10000 | F39: =+E39 -> 10000 | G39: =+F39 -> 10000 | H39: =+G39 -> 10000 | I39: =+H39 -> 10000 | J39: =+I39 -> 10000 | K39: =+J39 -> 10000 | ... Z39: =+Y39 -> 10000 | AA39: 22 | AB39: =+SUM(C39:Z39)*AA39 -> 5280000 | AC39: =+AB39+AB40+AB41 -> 7440000
B40: SABADO | C40: 10000 | D40: =+C40 -> 10000 | E40: =+D40 -> 10000 | F40: =+E40 -> 10000 | G40: =+F40 -> 10000 | H40: =+G40 -> 10000 | I40: =+H40 -> 10000 | J40: =+I40 -> 10000 | K40: =+J40 -> 10000 | ... Z40: =+Y40 -> 10000 | AA40: 3 | AB40: =+SUM(C40:Z40)*AA40 -> 720000
...

Sheet Producto 2
A1: ANEXO No. 1A CANTIDADES DE ENERGIA REQUERIDA
A2: CONVOCATORIA PÚBLICA EMSA-CP-EMSC2026-001
A3: OFERTA DE SUMINISTRO DE ENERGÍA ELECTRICA PLANA DE ENERO-2029 A DICIEMBRE-2030
A5: AÑO | B5: ENERGIA SOLICITADA | C5: PAGUE LO CONTRATADO
C6: Oferta (%) De la Curva Demanda
B7: Necesidad TOTAL AÑO kWh | C7: % | D7: Oferta $/kWh
A8: 47119 | B8: =+VLOOKUP(A8,'Cant producto 2_2029-2030'!$A:$AD,29,FALSE) -> 23808000
A9: 47150 | B9: =+VLOOKUP(A9,'Cant producto 2_2029-2030'!$A:$AD,29,FALSE) -> 21504000
A10: 47178 | B10: =+VLOOKUP(A10,'Cant producto 2_2029-2030'!$A:$AD,29,FALSE) -> 23808000
A11: 47209 | B11: =+VLOOKUP(A11,'Cant producto 2_2029-2030'!$A:$AD,29,FALSE) -> 23040000
A12: 47239 | B12: =+VLOOKUP(A12,'Cant producto 2_2029-2030'!$A:$AD,29,FALSE) -> 23808000
A13: 47270 | B13: =+VLOOKUP(A13,'Cant producto 2_2029-2030'!$A:$AD,29,FALSE) -> 23040000
A14: 47300 | B14: =+VLOOKUP(A14,'Cant producto 2_2029-2030'!$A:$AD,29,FALSE) -> 23808000
A15: 47331 | B15: =+VLOOKUP(A15,'Cant producto 2_2029-2030'!$A:$AD,29,FALSE) -> 23808000
A16: 47362 | B16: =+VLOOKUP(A16,'Cant producto 2_2029-2030'!$A:$AD,29,FALSE) -> 23040000
A17: 47392 | B17: =+VLOOKUP(A17,'Cant producto 2_2029-2030'!$A:$AD,29,FALSE) -> 23808000
A18: 47423 | B18: =+VLOOKUP(A18,'Cant producto 2_2029-2030'!$A:$AD,29,FALSE) -> 23040000
A19: 47453 | B19: =+VLOOKUP(A19,'Cant producto 2_2029-2030'!$A:$AD,29,FALSE) -> 23808000
... A31: 47818 | B31: =+VLOOKUP(A31,'Cant producto 2_2029-2030'!$A:$AD,29,FALSE) -> 23808000
A32: TOTAL | B32: =SUM(B8:B31) -> 560640000
A34: NOMBRE Y FIRMA DEL REPRESENTANTE LEGAL
A35: AGENTE PROPONENTE
A37: NOTAS:
A39: Se acepta adjudicaciones parciales: NO___ SI_____

Sheet Cant producto 2_2029-2030
A1: ANEXO No. 1
A2: ENERGIA ELECTRICA PLANA ENERO-2029 A DICIEMBRE-2030
A3: CONVOCATORIA PÚBLICA EMSA No. CP-EMSC2026-001
B4: HORA | C4: 1 | D4: 2 | E4: 3 | F4: 4 | G4: 5 | H4: 6 | I4: 7 | J4: 8 | K4: 9 | L4: 10 | M4: 11 | N4: 12 | O4: 13 | P4: 14 | Q4: 15 | R4: 16 | S4: 17 | T4: 18 | U4: 19 | V4: 20 | W4: 21 | X4: 22 | Y4: 23 | Z4: 24 | AA4: # DIAS | AB4: TOTAL | AC4: MES
A5: MES/AÑO | B5: TIPO DE DIA | C5: kWh | D5: kWh | E5: kWh | F5: kWh | G5: kWh | H5: kWh | I5: kWh | J5: kWh | K5: kWh | L5: kWh | M5: kWh | N5: kWh | O5: kWh | P5: kWh | Q5: kWh | R5: kWh | S5: kWh | T5: kWh | U5: kWh | V5: kWh | W5: kWh | X5: kWh | Y5: kWh | Z5: kWh
A6: 47119 | B6: NORMAL | C6: 32000 | D6: =+C6 -> 32000 | E6: =+D6 -> 32000 | F6: =+E6 -> 32000 | G6: =+F6 -> 32000 | H6: =+G6 -> 32000 | I6: =+H6 -> 32000 | J6: =+I6 -> 32000 | K6: =+J6 -> 32000 | ... Z6: =+Y6 -> 32000 | AA6: 21 | AB6: =+SUM(C6:Z6)*AA6 -> 16128000 | AC6: =+AB6+AB7+AB8 -> 23808000
B7: SABADO | C7: 32000 | D7: =+C7 -> 32000 | E7: =+D7 -> 32000 | F7: =+E7 -> 32000 | G7: =+F7 -> 32000 | H7: =+G7 -> 32000 | I7: =+H7 -> 32000 | J7: =+I7 -> 32000 | K7: =+J7 -> 32000 | ... Z7: =+Y7 -> 32000 | AA7: 4 | AB7: =+SUM(C7:Z7)*AA7 -> 3072000
B8: DOM/FES | C8: 32000 | D8: =+C8 -> 32000 | E8: =+D8 -> 32000 | F8: =+E8 -> 32000 | G8: =+F8 -> 32000 | H8: =+G8 -> 32000 | I8: =+H8 -> 32000 | J8: =+I8 -> 32000 | K8: =+J8 -> 32000 | ... Z8: =+Y8 -> 32000 | AA8: 6 | AB8: =+SUM(C8:Z8)*AA8 -> 4608000
A9: 47150 | B9: NORMAL | C9: 32000 | D9: =+C9 -> 32000 | E9: =+D9 -> 32000 | F9: =+E9 -> 32000 | G9: =+F9 -> 32000 | H9: =+G9 -> 32000 | I9: =+H9 -> 32000 | J9: =+I9 -> 32000 | K9: =+J9 -> 32000 | ... Z9: =+Y9 -> 32000 | AA9: 20 | AB9: =+SUM(C9:Z9)*AA9 -> 15360000 | AC9: =+AB9+AB10+AB11 -> 21504000
B10: SABADO | C10: 32000 | D10: =+C10 -> 32000 | E10: =+D10 -> 32000 | F10: =+E10 -> 32000 | G10: =+F10 -> 32000 | H10: =+G10 -> 32000 | I10: =+H10 -> 32000 | J10: =+I10 -> 32000 | K10: =+J10 -> 32000 | ... Z10: =+Y10 -> 32000 | AA10: 4 | AB10: =+SUM(C10:Z10)*AA10 -> 3072000
B11: DOM/FES | C11: 32000 | D11: =+C11 -> 32000 | E11: =+D11 -> 32000 | F11: =+E11 -> 32000 | G11: =+F11 -> 32000 | H11: =+G11 -> 32000 | I11: =+H11 -> 32000 | J11: =+I11 -> 32000 | K11: =+J11 -> 32000 | ... Z11: =+Y11 -> 32000 | AA11: 4 | AB11: =+SUM(C11:Z11)*AA11 -> 3072000
A12: 47178 | B12: NORMAL | C12: 32000 | D12: =+C12 -> 32000 | E12: =+D12 -> 32000 | F12: =+E12 -> 32000 | G12: =+F12 -> 32000 | H12: =+G12 -> 32000 | I12: =+H12 -> 32000 | J12: =+I12 -> 32000 | K12: =+J12 -> 32000 | ... Z12: =+Y12 -> 32000 | AA12: 19 | AB12: =+SUM(C12:Z12)*AA12 -> 14592000 | AC12: =+AB12+AB13+AB14 -> 23808000
B13: SABADO | C13: 32000 | D13: =+C13 -> 32000 | E13: =+D13 -> 32000 | F13: =+E13 -> 32000 | G13: =+F13 -> 32000 | H13: =+G13 -> 32000 | I13: =+H13 -> 32000 | J13: =+I13 -> 32000 | K13: =+J13 -> 32000 | ... Z13: =+Y13 -> 32000 | AA13: 5 | AB13: =+SUM(C13:Z13)*AA13 -> 3840000
B14: DOM/FES | C14: 32000 | D14: =+C14 -> 32000 | E14: =+D14 -> 32000 | F14: =+E14 -> 32000 | G14: =+F14 -> 32000 | H14: =+G14 -> 32000 | I14: =+H14 -> 32000 | J14: =+I14 -> 32000 | K14: =+J14 -> 32000 | ... Z14: =+Y14 -> 32000 | AA14: 7 | AB14: =+SUM(C14:Z14)*AA14 -> 5376000
A15: 47209 | B15: NORMAL | C15: 32000 | D15: =+C15 -> 32000 | E15: =+D15 -> 32000 | F15: =+E15 -> 32000 | G15: =+F15 -> 32000 | H15: =+G15 -> 32000 | I15: =+H15 -> 32000 | J15: =+I15 -> 32000 | K15: =+J15 -> 32000 | ... Z15: =+Y15 -> 32000 | AA15: 21 | AB15: =+SUM(C15:Z15)*AA15 -> 16128000 | AC15: =+AB15+AB16+AB17 -> 23040000
B16: SABADO | C16: 32000 | D16: =+C16 -> 32000 | E16: =+D16 -> 32000 | F16: =+E16 -> 32000 | G16: =+F16 -> 32000 | H16: =+G16 -> 32000 | I16: =+H16 -> 32000 | J16: =+I16 -> 32000 | K16: =+J16 -> 32000 | ... Z16: =+Y16 -> 32000 | AA16: 4 | AB16: =+SUM(C16:Z16)*AA16 -> 3072000
B17: DOM/FES | C17: 32000 | D17: =+C17 -> 32000 | E17: =+D17 -> 32000 | F17: =+E17 -> 32000 | G17: =+F17 -> 32000 | H17: =+G17 -> 32000 | I17: =+H17 -> 32000 | J17: =+I17 -> 32000 | K17: =+J17 -> 32000 | ... Z17: =+Y17 -> 32000 | AA17: 5 | AB17: =+SUM(C17:Z17)*AA17 -> 3840000
A18: 47239 | B18: NORMAL | C18: 32000 | D18: =+C18 -> 32000 | E18: =+D18 -> 32000 | F18: =+E18 -> 32000 | G18: =+F18 -> 32000 | H18: =+G18 -> 32000 | I18: =+H18 -> 32000 | J18: =+I18 -> 32000 | K18: =+J18 -> 32000 | ... Z18: =+Y18 -> 32000 | AA18: 21 | AB18: =+SUM(C18:Z18)*AA18 -> 16128000 | AC18: =+AB18+AB19+AB20 -> 23808000
B19: SABADO | C19: 32000 | D19: =+C19 -> 32000 | E19: =+D19 -> 32000 | F19: =+E19 -> 32000 | G19: =+F19 -> 32000 | H19: =+G19 -> 32000 | I19: =+H19 -> 32000 | J19: =+I19 -> 32000 | K19: =+J19 -> 32000 | ... Z19: =+Y19 -> 32000 | AA19: 4 | AB19: =+SUM(C19:Z19)*AA19 -> 3072000
B20: DOM/FES | C20: 32000 | D20: =+C20 -> 32000 | E20: =+D20 -> 32000 | F20: =+E20 -> 32000 | G20: =+F20 -> 32000 | H20: =+G20 -> 32000 | I20: =+H20 -> 32000 | J20: =+I20 -> 32000 | K20: =+J20 -> 32000 | ... Z20: =+Y20 -> 32000 | AA20: 6 | AB20: =+SUM(C20:Z20)*AA20 -> 4608000
A21: 47270 | B21: NORMAL | C21: 32000 | D21: =+C21 -> 32000 | E21: =+D21 -> 32000 | F21: =+E21 -> 32000 | G21: =+F21 -> 32000 | H21: =+G21 -> 32000 | I21: =+H21 -> 32000 | J21: =+I21 -> 32000 | K21: =+J21 -> 32000 | ... Z21: =+Y21 -> 32000 | AA21: 19 | AB21: =+SUM(C21:Z21)*AA21 -> 14592000 | AC21: =+AB21+AB22+AB23 -> 23040000
B22: SABADO | C22: 32000 | D22: =+C22 -> 32000 | E22: =+D22 -> 32000 | F22: =+E22 -> 32000 | G22: =+F22 -> 32000 | H22: =+G22 -> 32000 | I22: =+H22 -> 32000 | J22: =+I22 -> 32000 | K22: =+J22 -> 32000 | ... Z22: =+Y22 -> 32000 | AA22: 5 | AB22: =+SUM(C22:Z22)*AA22 -> 3840000
B23: DOM/FES | C23: 32000 | D23: =+C23 -> 32000 | E23: =+D23 -> 32000 | F23: =+E23 -> 32000 | G23: =+F23 -> 32000 | H23: =+G23 -> 32000 | I23: =+H23 -> 32000 | J23: =+I23 -> 32000 | K23: =+J23 -> 32000 | ... Z23: =+Y23 -> 32000 | AA23: 6 | AB23: =+SUM(C23:Z23)*AA23 -> 4608000
A24: 47300 | B24: NORMAL | C24: 32000 | D24: =+C24 -> 32000 | E24: =+D24 -> 32000 | F24: =+E24 -> 32000 | G24: =+F24 -> 32000 | H24: =+G24 -> 32000 | I24: =+H24 -> 32000 | J24: =+I24 -> 32000 | K24: =+J24 -> 32000 | ... Z24: =+Y24 -> 32000 | AA24: 20 | AB24: =+SUM(C24:Z24)*AA24 -> 15360000 | AC24: =+AB24+AB25+AB26 -> 23808000
B25: SABADO | C25: 32000 | D25: =+C25 -> 32000 | E25: =+D25 -> 32000 | F25: =+E25 -> 32000 | G25: =+F25 -> 32000 | H25: =+G25 -> 32000 | I25: =+H25 -> 32000 | J25: =+I25 -> 32000 | K25: =+J25 -> 32000 | ... Z25: =+Y25 -> 32000 | AA25: 4 | AB25: =+SUM(C25:Z25)*AA25 -> 3072000
B26: DOM/FES | C26: 32000 | D26: =+C26 -> 32000 | E26: =+D26 -> 32000 | F26: =+E26 -> 32000 | G26: =+F26 -> 32000 | H26: =+G26 -> 32000 | I26: =+H26 -> 32000 | J26: =+I26 -> 32000 | K26: =+J26 -> 32000 | ... Z26: =+Y26 -> 32000 | AA26: 7 | AB26: =+SUM(C26:Z26)*AA26 -> 5376000
A27: 47331 | B27: NORMAL | C27: 32000 | D27: =+C27 -> 32000 | E27: =+D27 -> 32000 | F27: =+E27 -> 32000 | G27: =+F27 -> 32000 | H27: =+G27 -> 32000 | I27: =+H27 -> 32000 | J27: =+I27 -> 32000 | K27: =+J27 -> 32000 | ... Z27: =+Y27 -> 32000 | AA27: 21 | AB27: =+SUM(C27:Z27)*AA27 -> 16128000 | AC27: =+AB27+AB28+AB29 -> 23808000
B28: SABADO | C28: 32000 | D28: =+C28 -> 32000 | E28: =+D28 -> 32000 | F28: =+E28 -> 32000 | G28: =+F28 -> 32000 | H28: =+G28 -> 32000 | I28: =+H28 -> 32000 | J28: =+I28 -> 32000 | K28: =+J28 -> 32000 | ... Z28: =+Y28 -> 32000 | AA28: 4 | AB28: =+SUM(C28:Z28)*AA28 -> 3072000
B29: DOM/FES | C29: 32000 | D29: =+C29 -> 32000 | E29: =+D29 -> 32000 | F29: =+E29 -> 32000 | G29: =+F29 -> 32000 | H29: =+G29 -> 32000 | I29: =+H29 -> 32000 | J29: =+I29 -> 32000 | K29: =+J29 -> 32000 | ... Z29: =+Y29 -> 32000 | AA29: 6 | AB29: =+SUM(C29:Z29)*AA29 -> 4608000
A30: 47362 | B30: NORMAL | C30: 32000 | D30: =+C30 -> 32000 | E30: =+D30 -> 32000 | F30: =+E30 -> 32000 | G30: =+F30 -> 32000 | H30: =+G30 -> 32000 | I30: =+H30 -> 32000 | J30: =+I30 -> 32000 | K30: =+J30 -> 32000 | ... Z30: =+Y30 -> 32000 | AA30: 20 | AB30: =+SUM(C30:Z30)*AA30 -> 15360000 | AC30: =+AB30+AB31+AB32 -> 23040000
B31: SABADO | C31: 32000 | D31: =+C31 -> 32000 | E31: =+D31 -> 32000 | F31: =+E31 -> 32000 | G31: =+F31 -> 32000 | H31: =+G31 -> 32000 | I31: =+H31 -> 32000 | J31: =+I31 -> 32000 | K31: =+J31 -> 32000 | ... Z31: =+Y31 -> 32000 | AA31: 5 | AB31: =+SUM(C31:Z31)*AA31 -> 3840000
B32: DOM/FES | C32: 32000 | D32: =+C32 -> 32000 | E32: =+D32 -> 32000 | F32: =+E32 -> 32000 | G32: =+F32 -> 32000 | H32: =+G32 -> 32000 | I32: =+H32 -> 32000 | J32: =+I32 -> 32000 | K32: =+J32 -> 32000 | ... Z32: =+Y32 -> 32000 | AA32: 5 | AB32: =+SUM(C32:Z32)*AA32 -> 3840000
A33: 47392 | B33: NORMAL | C33: 32000 | D33: =+C33 -> 32000 | E33: =+D33 -> 32000 | F33: =+E33 -> 32000 | G33: =+F33 -> 32000 | H33: =+G33 -> 32000 | I33: =+H33 -> 32000 | J33: =+I33 -> 32000 | K33: =+J33 -> 32000 | ... Z33: =+Y33 -> 32000 | AA33: 22 | AB33: =+SUM(C33:Z33)*AA33 -> 16896000 | AC33: =+AB33+AB34+AB35 -> 23808000
B34: SABADO | C34: 32000 | D34: =+C34 -> 32000 | E34: =+D34 -> 32000 | F34: =+E34 -> 32000 | G34: =+F34 -> 32000 | H34: =+G34 -> 32000 | I34: =+H34 -> 32000 | J34: =+I34 -> 32000 | K34: =+J34 -> 32000 | ... Z34: =+Y34 -> 32000 | AA34: 4 | AB34: =+SUM(C34:Z34)*AA34 -> 3072000
B35: DOM/FES | C35: 32000 | D35: =+C35 -> 32000 | E35: =+D35 -> 32000 | F35: =+E35 -> 32000 | G35: =+F35 -> 32000 | H35: =+G35 -> 32000 | I35: =+H35 -> 32000 | J35: =+I35 -> 32000 | K35: =+J35 -> 32000 | ... Z35: =+Y35 -> 32000 | AA35: 5 | AB35: =+SUM(C35:Z35)*AA35 -> 3840000
A36: 47423 | B36: NORMAL | C36: 32000 | D36: =+C36 -> 32000 | E36: =+D36 -> 32000 | F36: =+E36 -> 32000 | G36: =+F36 -> 32000 | H36: =+G36 -> 32000 | I36: =+H36 -> 32000 | J36: =+I36 -> 32000 | K36: =+J36 -> 32000 | ... Z36: =+Y36 -> 32000 | AA36: 20 | AB36: =+SUM(C36:Z36)*AA36 -> 15360000 | AC36: =+AB36+AB37+AB38 -> 23040000
B37: SABADO | C37: 32000 | D37: =+C37 -> 32000 | E37: =+D37 -> 32000 | F37: =+E37 -> 32000 | G37: =+F37 -> 32000 | H37: =+G37 -> 32000 | I37: =+H37 -> 32000 | J37: =+I37 -> 32000 | K37: =+J37 -> 32000 | ... Z37: =+Y37 -> 32000 | AA37: 4 | AB37: =+SUM(C37:Z37)*AA37 -> 3072000
B38: DOM/FES | C38: 32000 | D38: =+C38 -> 32000 | E38: =+D38 -> 32000 | F38: =+E38 -> 32000 | G38: =+F38 -> 32000 | H38: =+G38 -> 32000 | I38: =+H38 -> 32000 | J38: =+I38 -> 32000 | K38: =+J38 -> 32000 | ... Z38: =+Y38 -> 32000 | AA38: 6 | AB38: =+SUM(C38:Z38)*AA38 -> 4608000
A39: 47453 | B39: NORMAL | C39: 32000 | D39: =+C39 -> 32000 | E39: =+D39 -> 32000 | F39: =+E39 -> 32000 | G39: =+F39 -> 32000 | H39: =+G39 -> 32000 | I39: =+H39 -> 32000 | J39: =+I39 -> 32000 | K39: =+J39 -> 32000 | ... Z39: =+Y39 -> 32000 | AA39: 20 | AB39: =+SUM(C39:Z39)*AA39 -> 15360000 | AC39: =+AB39+AB40+AB41 -> 23808000
B40: SABADO | C40: 32000 | D40: =+C40 -> 32000 | E40: =+D40 -> 32000 | F40: =+E40 -> 32000 | G40: =+F40 -> 32000 | H40: =+G40 -> 32000 | I40: =+H40 -> 32000 | J40: =+I40 -> 32000 | K40: =+J40 -> 32000 | ... Z40: =+Y40 -> 32000 | AA40: 4 | AB40: =+SUM(C40:Z40)*AA40 -> 3072000
...

Sheet Producto 3
A1: ANEXO No. 1A CANTIDADES DE ENERGIA REQUERIDA
A2: CONVOCATORIA PÚBLICA EMSA-CP-EMSC2026-001
A3: OFERTA DE SUMINISTRO DE ENERGÍA ELECTRICA PLANA DE ENERO-2031 A DICIEMBRE-2031
A5: AÑO | B5: ENERGIA SOLICITADA | C5: PAGUE LO CONTRATADO
C6: Oferta (%) De la Curva Demanda
B7: Necesidad TOTAL AÑO kWh | C7: % | D7: Oferta $/kWh
A8: 47849 | B8: =+VLOOKUP(A8,'Cant producto 3_2031'!$A:$AD,29,FALSE) -> 29760000
A9: 47880 | B9: =+VLOOKUP(A9,'Cant producto 3_2031'!$A:$AD,29,FALSE) -> 26880000
A10: 47908 | B10: =+VLOOKUP(A10,'Cant producto 3_2031'!$A:$AD,29,FALSE) -> 29760000
A11: 47939 | B11: =+VLOOKUP(A11,'Cant producto 3_2031'!$A:$AD,29,FALSE) -> 28800000
A12: 47969 | B12: =+VLOOKUP(A12,'Cant producto 3_2031'!$A:$AD,29,FALSE) -> 29760000
A13: 48000 | B13: =+VLOOKUP(A13,'Cant producto 3_2031'!$A:$AD,29,FALSE) -> 28800000
A14: 48030 | B14: =+VLOOKUP(A14,'Cant producto 3_2031'!$A:$AD,29,FALSE) -> 29760000
A15: 48061 | B15: =+VLOOKUP(A15,'Cant producto 3_2031'!$A:$AD,29,FALSE) -> 29760000
A16: 48092 | B16: =+VLOOKUP(A16,'Cant producto 3_2031'!$A:$AD,29,FALSE) -> 28800000
A17: 48122 | B17: =+VLOOKUP(A17,'Cant producto 3_2031'!$A:$AD,29,FALSE) -> 29760000
A18: 48153 | B18: =+VLOOKUP(A18,'Cant producto 3_2031'!$A:$AD,29,FALSE) -> 28800000
A19: 48183 | B19: =+VLOOKUP(A19,'Cant producto 3_2031'!$A:$AD,29,FALSE) -> 29760000
A20: TOTAL | B20: =SUM(B8:B19) -> 350400000
A22: NOMBRE Y FIRMA DEL REPRESENTANTE LEGAL
A23: AGENTE PROPONENTE
A25: NOTAS:
A27: Se acepta adjudicaciones parciales: NO___ SI_____

Sheet Cant producto 3_2031
A1: ANEXO No. 1
A2: ENERGIA ELECTRICA PLANA ENERO-2031 A DICIEMBRE-2031
A3: CONVOCATORIA PÚBLICA EMSA No. CP-EMSC2026-001
B4: HORA | C4: 1 | D4: 2 | E4: 3 | F4: 4 | G4: 5 | H4: 6 | I4: 7 | J4: 8 | K4: 9 | L4: 10 | M4: 11 | N4: 12 | O4: 13 | P4: 14 | Q4: 15 | R4: 16 | S4: 17 | T4: 18 | U4: 19 | V4: 20 | W4: 21 | X4: 22 | Y4: 23 | Z4: 24 | AA4: # DIAS | AB4: TOTAL | AC4: MES
A5: MES/AÑO | B5: TIPO DE DIA | C5: kWh | D5: kWh | E5: kWh | F5: kWh | G5: kWh | H5: kWh | I5: kWh | J5: kWh | K5: kWh | L5: kWh | M5: kWh | N5: kWh | O5: kWh | P5: kWh | Q5: kWh | R5: kWh | S5: kWh | T5: kWh | U5: kWh | V5: kWh | W5: kWh | X5: kWh | Y5: kWh | Z5: kWh
A6: 47849 | B6: NORMAL | C6: 40000 | D6: =+C6 -> 40000 | E6: =+D6 -> 40000 | F6: =+E6 -> 40000 | G6: =+F6 -> 40000 | H6: =+G6 -> 40000 | I6: =+H6 -> 40000 | J6: =+I6 -> 40000 | K6: =+J6 -> 40000 | ... Z6: =+Y6 -> 40000 | AA6: 21 | AB6: =+SUM(C6:Z6)*AA6 -> 20160000 | AC6: =+AB6+AB7+AB8 -> 29760000
B7: SABADO | C7: 40000 | D7: =+C7 -> 40000 | E7: =+D7 -> 40000 | F7: =+E7 -> 40000 | G7: =+F7 -> 40000 | H7: =+G7 -> 40000 | I7: =+H7 -> 40000 | J7: =+I7 -> 40000 | K7: =+J7 -> 40000 | ... Z7: =+Y7 -> 40000 | AA7: 4 | AB7: =+SUM(C7:Z7)*AA7 -> 3840000
B8: DOM/FES | C8: 40000 | D8: =+C8 -> 40000 | E8: =+D8 -> 40000 | F8: =+E8 -> 40000 | G8: =+F8 -> 40000 | H8: =+G8 -> 40000 | I8: =+H8 -> 40000 | J8: =+I8 -> 40000 | K8: =+J8 -> 40000 | ... Z8: =+Y8 -> 40000 | AA8: 6 | AB8: =+SUM(C8:Z8)*AA8 -> 5760000
A9: 47880 | B9: NORMAL | C9: 40000 | D9: =+C9 -> 40000 | E9: =+D9 -> 40000 | F9: =+E9 -> 40000 | G9: =+F9 -> 40000 | H9: =+G9 -> 40000 | I9: =+H9 -> 40000 | J9: =+I9 -> 40000 | K9: =+J9 -> 40000 | ... Z9: =+Y9 -> 40000 | AA9: 20 | AB9: =+SUM(C9:Z9)*AA9 -> 19200000 | AC9: =+AB9+AB10+AB11 -> 26880000
B10: SABADO | C10: 40000 | D10: =+C10 -> 40000 | E10: =+D10 -> 40000 | F10: =+E10 -> 40000 | G10: =+F10 -> 40000 | H10: =+G10 -> 40000 | I10: =+H10 -> 40000 | J10: =+I10 -> 40000 | K10: =+J10 -> 40000 | ... Z10: =+Y10 -> 40000 | AA10: 4 | AB10: =+SUM(C10:Z10)*AA10 -> 3840000
B11: DOM/FES | C11: 40000 | D11: =+C11 -> 40000 | E11: =+D11 -> 40000 | F11: =+E11 -> 40000 | G11: =+F11 -> 40000 | H11: =+G11 -> 40000 | I11: =+H11 -> 40000 | J11: =+I11 -> 40000 | K11: =+J11 -> 40000 | ... Z11: =+Y11 -> 40000 | AA11: 4 | AB11: =+SUM(C11:Z11)*AA11 -> 3840000
A12: 47908 | B12: NORMAL | C12: 40000 | D12: =+C12 -> 40000 | E12: =+D12 -> 40000 | F12: =+E12 -> 40000 | G12: =+F12 -> 40000 | H12: =+G12 -> 40000 | I12: =+H12 -> 40000 | J12: =+I12 -> 40000 | K12: =+J12 -> 40000 | ... Z12: =+Y12 -> 40000 | AA12: 20 | AB12: =+SUM(C12:Z12)*AA12 -> 19200000 | AC12: =+AB12+AB13+AB14 -> 29760000
B13: SABADO | C13: 40000 | D13: =+C13 -> 40000 | E13: =+D13 -> 40000 | F13: =+E13 -> 40000 | G13: =+F13 -> 40000 | H13: =+G13 -> 40000 | I13: =+H13 -> 40000 | J13: =+I13 -> 40000 | K13: =+J13 -> 40000 | ... Z13: =+Y13 -> 40000 | AA13: 5 | AB13: =+SUM(C13:Z13)*AA13 -> 4800000
B14: DOM/FES | C14: 40000 | D14: =+C14 -> 40000 | E14: =+D14 -> 40000 | F14: =+E14 -> 40000 | G14: =+F14 -> 40000 | H14: =+G14 -> 40000 | I14: =+H14 -> 40000 | J14: =+I14 -> 40000 | K14: =+J14 -> 40000 | ... Z14: =+Y14 -> 40000 | AA14: 6 | AB14: =+SUM(C14:Z14)*AA14 -> 5760000
A15: 47939 | B15: NORMAL | C15: 40000 | D15: =+C15 -> 40000 | E15: =+D15 -> 40000 | F15: =+E15 -> 40000 | G15: =+F15 -> 40000 | H15: =+G15 -> 40000 | I15: =+H15 -> 40000 | J15: =+I15 -> 40000 | K15: =+J15 -> 40000 | ... Z15: =+Y15 -> 40000 | AA15: 20 | AB15: =+SUM(C15:Z15)*AA15 -> 19200000 | AC15: =+AB15+AB16+AB17 -> 28800000
B16: SABADO | C16: 40000 | D16: =+C16 -> 40000 | E16: =+D16 -> 40000 | F16: =+E16 -> 40000 | G16: =+F16 -> 40000 | H16: =+G16 -> 40000 | I16: =+H16 -> 40000 | J16: =+I16 -> 40000 | K16: =+J16 -> 40000 | ... Z16: =+Y16 -> 40000 | AA16: 4 | AB16: =+SUM(C16:Z16)*AA16 -> 3840000
B17: DOM/FES | C17: 40000 | D17: =+C17 -> 40000 | E17: =+D17 -> 40000 | F17: =+E17 -> 40000 | G17: =+F17 -> 40000 | H17: =+G17 -> 40000 | I17: =+H17 -> 40000 | J17: =+I17 -> 40000 | K17: =+J17 -> 40000 | ... Z17: =+Y17 -> 40000 | AA17: 6 | AB17: =+SUM(C17:Z17)*AA17 -> 5760000
A18: 47969 | B18: NORMAL | C18: 40000 | D18: =+C18 -> 40000 | E18: =+D18 -> 40000 | F18: =+E18 -> 40000 | G18: =+F18 -> 40000 | H18: =+G18 -> 40000 | I18: =+H18 -> 40000 | J18: =+I18 -> 40000 | K18: =+J18 -> 40000 | ... Z18: =+Y18 -> 40000 | AA18: 20 | AB18: =+SUM(C18:Z18)*AA18 -> 19200000 | AC18: =+AB18+AB19+AB20 -> 29760000
B19: SABADO | C19: 40000 | D19: =+C19 -> 40000 | E19: =+D19 -> 40000 | F19: =+E19 -> 40000 | G19: =+F19 -> 40000 | H19: =+G19 -> 40000 | I19: =+H19 -> 40000 | J19: =+I19 -> 40000 | K19: =+J19 -> 40000 | ... Z19: =+Y19 -> 40000 | AA19: 5 | AB19: =+SUM(C19:Z19)*AA19 -> 4800000
B20: DOM/FES | C20: 40000 | D20: =+C20 -> 40000 | E20: =+D20 -> 40000 | F20: =+E20 -> 40000 | G20: =+F20 -> 40000 | H20: =+G20 -> 40000 | I20: =+H20 -> 40000 | J20: =+I20 -> 40000 | K20: =+J20 -> 40000 | ... Z20: =+Y20 -> 40000 | AA20: 6 | AB20: =+SUM(C20:Z20)*AA20 -> 5760000
A21: 48000 | B21: NORMAL | C21: 40000 | D21: =+C21 -> 40000 | E21: =+D21 -> 40000 | F21: =+E21 -> 40000 | G21: =+F21 -> 40000 | H21: =+G21 -> 40000 | I21: =+H21 -> 40000 | J21: =+I21 -> 40000 | K21: =+J21 -> 40000 | ... Z21: =+Y21 -> 40000 | AA21: 18 | AB21: =+SUM(C21:Z21)*AA21 -> 17280000 | AC21: =+AB21+AB22+AB23 -> 28800000
B22: SABADO | C22: 40000 | D22: =+C22 -> 40000 | E22: =+D22 -> 40000 | F22: =+E22 -> 40000 | G22: =+F22 -> 40000 | H22: =+G22 -> 40000 | I22: =+H22 -> 40000 | J22: =+I22 -> 40000 | K22: =+J22 -> 40000 | ... Z22: =+Y22 -> 40000 | AA22: 4 | AB22: =+SUM(C22:Z22)*AA22 -> 3840000
B23: DOM/FES | C23: 40000 | D23: =+C23 -> 40000 | E23: =+D23 -> 40000 | F23: =+E23 -> 40000 | G23: =+F23 -> 40000 | H23: =+G23 -> 40000 | I23: =+H23 -> 40000 | J23: =+I23 -> 40000 | K23: =+J23 -> 40000 | ... Z23: =+Y23 -> 40000 | AA23: 8 | AB23: =+SUM(C23:Z23)*AA23 -> 7680000
A24: 48030 | B24: NORMAL | C24: 40000 | D24: =+C24 -> 40000 | E24: =+D24 -> 40000 | F24: =+E24 -> 40000 | G24: =+F24 -> 40000 | H24: =+G24 -> 40000 | I24: =+H24 -> 40000 | J24: =+I24 -> 40000 | K24: =+J24 -> 40000 | ... Z24: =+Y24 -> 40000 | AA24: 23 | AB24: =+SUM(C24:Z24)*AA24 -> 22080000 | AC24: =+AB24+AB25+AB26 -> 29760000
B25: SABADO | C25: 40000 | D25: =+C25 -> 40000 | E25: =+D25 -> 40000 | F25: =+E25 -> 40000 | G25: =+F25 -> 40000 | H25: =+G25 -> 40000 | I25: =+H25 -> 40000 | J25: =+I25 -> 40000 | K25: =+J25 -> 40000 | ... Z25: =+Y25 -> 40000 | AA25: 4 | AB25: =+SUM(C25:Z25)*AA25 -> 3840000
B26: DOM/FES | C26: 40000 | D26: =+C26 -> 40000 | E26: =+D26 -> 40000 | F26: =+E26 -> 40000 | G26: =+F26 -> 40000 | H26: =+G26 -> 40000 | I26: =+H26 -> 40000 | J26: =+I26 -> 40000 | K26: =+J26 -> 40000 | ... Z26: =+Y26 -> 40000 | AA26: 4 | AB26: =+SUM(C26:Z26)*AA26 -> 3840000
A27: 48061 | B27: NORMAL | C27: 40000 | D27: =+C27 -> 40000 | E27: =+D27 -> 40000 | F27: =+E27 -> 40000 | G27: =+F27 -> 40000 | H27: =+G27 -> 40000 | I27: =+H27 -> 40000 | J27: =+I27 -> 40000 | K27: =+J27 -> 40000 | ... Z27: =+Y27 -> 40000 | AA27: 19 | AB27: =+SUM(C27:Z27)*AA27 -> 18240000 | AC27: =+AB27+AB28+AB29 -> 29760000
B28: SABADO | C28: 40000 | D28: =+C28 -> 40000 | E28: =+D28 -> 40000 | F28: =+E28 -> 40000 | G28: =+F28 -> 40000 | H28: =+G28 -> 40000 | I28: =+H28 -> 40000 | J28: =+I28 -> 40000 | K28: =+J28 -> 40000 | ... Z28: =+Y28 -> 40000 | AA28: 5 | AB28: =+SUM(C28:Z28)*AA28 -> 4800000
B29: DOM/FES | C29: 40000 | D29: =+C29 -> 40000 | E29: =+D29 -> 40000 | F29: =+E29 -> 40000 | G29: =+F29 -> 40000 | H29: =+G29 -> 40000 | I29: =+H29 -> 40000 | J29: =+I29 -> 40000 | K29: =+J29 -> 40000 | ... Z29: =+Y29 -> 40000 | AA29: 7 | AB29: =+SUM(C29:Z29)*AA29 -> 6720000
A30: 48092 | B30: NORMAL | C30: 40000 | D30: =+C30 -> 40000 | E30: =+D30 -> 40000 | F30: =+E30 -> 40000 | G30: =+F30 -> 40000 | H30: =+G30 -> 40000 | I30: =+H30 -> 40000 | J30: =+I30 -> 40000 | K30: =+J30 -> 40000 | ... Z30: =+Y30 -> 40000 | AA30: 22 | AB30: =+SUM(C30:Z30)*AA30 -> 21120000 | AC30: =+AB30+AB31+AB32 -> 28800000
B31: SABADO | C31: 40000 | D31: =+C31 -> 40000 | E31: =+D31 -> 40000 | F31: =+E31 -> 40000 | G31: =+F31 -> 40000 | H31: =+G31 -> 40000 | I31: =+H31 -> 40000 | J31: =+I31 -> 40000 | K31: =+J31 -> 40000 | ... Z31: =+Y31 -> 40000 | AA31: 4 | AB31: =+SUM(C31:Z31)*AA31 -> 3840000
B32: DOM/FES | C32: 40000 | D32: =+C32 -> 40000 | E32: =+D32 -> 40000 | F32: =+E32 -> 40000 | G32: =+F32 -> 40000 | H32: =+G32 -> 40000 | I32: =+H32 -> 40000 | J32: =+I32 -> 40000 | K32: =+J32 -> 40000 | ... Z32: =+Y32 -> 40000 | AA32: 4 | AB32: =+SUM(C32:Z32)*AA32 -> 3840000
A33: 48122 | B33: NORMAL | C33: 40000 | D33: =+C33 -> 40000 | E33: =+D33 -> 40000 | F33: =+E33 -> 40000 | G33: =+F33 -> 40000 | H33: =+G33 -> 40000 | I33: =+H33 -> 40000 | J33: =+I33 -> 40000 | K33: =+J33 -> 40000 | ... Z33: =+Y33 -> 40000 | AA33: 22 | AB33: =+SUM(C33:Z33)*AA33 -> 21120000 | AC33: =+AB33+AB34+AB35 -> 29760000
B34: SABADO | C34: 40000 | D34: =+C34 -> 40000 | E34: =+D34 -> 40000 | F34: =+E34 -> 40000 | G34: =+F34 -> 40000 | H34: =+G34 -> 40000 | I34: =+H34 -> 40000 | J34: =+I34 -> 40000 | K34: =+J34 -> 40000 | ... Z34: =+Y34 -> 40000 | AA34: 4 | AB34: =+SUM(C34:Z34)*AA34 -> 3840000
B35: DOM/FES | C35: 40000 | D35: =+C35 -> 40000 | E35: =+D35 -> 40000 | F35: =+E35 -> 40000 | G35: =+F35 -> 40000 | H35: =+G35 -> 40000 | I35: =+H35 -> 40000 | J35: =+I35 -> 40000 | K35: =+J35 -> 40000 | ... Z35: =+Y35 -> 40000 | AA35: 5 | AB35: =+SUM(C35:Z35)*AA35 -> 4800000
A36: 48153 | B36: NORMAL | C36: 40000 | D36: =+C36 -> 40000 | E36: =+D36 -> 40000 | F36: =+E36 -> 40000 | G36: =+F36 -> 40000 | H36: =+G36 -> 40000 | I36: =+H36 -> 40000 | J36: =+I36 -> 40000 | K36: =+J36 -> 40000 | ... Z36: =+Y36 -> 40000 | AA36: 18 | AB36: =+SUM(C36:Z36)*AA36 -> 17280000 | AC36: =+AB36+AB37+AB38 -> 28800000
B37: SABADO | C37: 40000 | D37: =+C37 -> 40000 | E37: =+D37 -> 40000 | F37: =+E37 -> 40000 | G37: =+F37 -> 40000 | H37: =+G37 -> 40000 | I37: =+H37 -> 40000 | J37: =+I37 -> 40000 | K37: =+J37 -> 40000 | ... Z37: =+Y37 -> 40000 | AA37: 5 | AB37: =+SUM(C37:Z37)*AA37 -> 4800000
B38: DOM/FES | C38: 40000 | D38: =+C38 -> 40000 | E38: =+D38 -> 40000 | F38: =+E38 -> 40000 | G38: =+F38 -> 40000 | H38: =+G38 -> 40000 | I38: =+H38 -> 40000 | J38: =+I38 -> 40000 | K38: =+J38 -> 40000 | ... Z38: =+Y38 -> 40000 | AA38: 7 | AB38: =+SUM(C38:Z38)*AA38 -> 6720000
A39: 48183 | B39: NORMAL | C39: 40000 | D39: =+C39 -> 40000 | E39: =+D39 -> 40000 | F39: =+E39 -> 40000 | G39: =+F39 -> 40000 | H39: =+G39 -> 40000 | I39: =+H39 -> 40000 | J39: =+I39 -> 40000 | K39: =+J39 -> 40000 | ... Z39: =+Y39 -> 40000 | AA39: 21 | AB39: =+SUM(C39:Z39)*AA39 -> 20160000 | AC39: =+AB39+AB40+AB41 -> 29760000
B40: SABADO | C40: 40000 | D40: =+C40 -> 40000 | E40: =+D40 -> 40000 | F40: =+E40 -> 40000 | G40: =+F40 -> 40000 | H40: =+G40 -> 40000 | I40: =+H40 -> 40000 | J40: =+I40 -> 40000 | K40: =+J40 -> 40000 | ... Z40: =+Y40 -> 40000 | AA40: 4 | AB40: =+SUM(C40:Z40)*AA40 -> 3840000
...

Sheet Producto 4
A1: ANEXO No. 1A CANTIDADES DE ENERGIA REQUERIDA
A2: CONVOCATORIA PÚBLICA EMSA-CP-EMSC2026-001
A3: OFERTA DE SUMINISTRO DE ENERGÍA ELECTRICA PLANA DE ENERO-2032 A DICIEMBRE-2032
A5: AÑO | B5: ENERGIA SOLICITADA | C5: PAGUE LO CONTRATADO
C6: Oferta (%) De la Curva Demanda
B7: Necesidad TOTAL AÑO kWh | C7: % | D7: Oferta $/kWh
A8: 48214 | B8: =+VLOOKUP(A8,'Cant producto 4_2032'!$A:$AD,29,FALSE) -> 39432000
A9: 48245 | B9: =+VLOOKUP(A9,'Cant producto 4_2032'!$A:$AD,29,FALSE) -> 36888000
A10: 48274 | B10: =+VLOOKUP(A10,'Cant producto 4_2032'!$A:$AD,29,FALSE) -> 39432000
A11: 48305 | B11: =+VLOOKUP(A11,'Cant producto 4_2032'!$A:$AD,29,FALSE) -> 30960000
A12: 48335 | B12: =+VLOOKUP(A12,'Cant producto 4_2032'!$A:$AD,29,FALSE) -> 31992000
A13: 48366 | B13: =+VLOOKUP(A13,'Cant producto 4_2032'!$A:$AD,29,FALSE) -> 27360000
A14: 48396 | B14: =+VLOOKUP(A14,'Cant producto 4_2032'!$A:$AD,29,FALSE) -> 28272000
A15: 48427 | B15: =+VLOOKUP(A15,'Cant producto 4_2032'!$A:$AD,29,FALSE) -> 31992000
A16: 48458 | B16: =+VLOOKUP(A16,'Cant producto 4_2032'!$A:$AD,29,FALSE) -> 30960000
A17: 48488 | B17: =+VLOOKUP(A17,'Cant producto 4_2032'!$A:$AD,29,FALSE) -> 31992000
A18: 48519 | B18: =+VLOOKUP(A18,'Cant producto 4_2032'!$A:$AD,29,FALSE) -> 30960000
A19: 48549 | B19: =+VLOOKUP(A19,'Cant producto 4_2032'!$A:$AD,29,FALSE) -> 39432000
A20: TOTAL | B20: =+SUM(B8:B19) -> 399672000
A23: NOTAS:
A25: Se acepta adjudicaciones parciales: NO___ SI_____
A312: NOMBRE Y FIRMA DEL REPRESENTANTE LEGAL
A313: AGENTE PROPONENTE
A315: NOTAS:
A316: Se acepta adjudicaciones parciales: NO___ SI_____ % Minimo a aceptar: _____
A317: En este formulario, el oferente debera manifestar formalmente si acepta o no adjudicaciones parciales y en caso afirmativo el porcentaje minimo que acepta.
A319: En el caso de no marcar en este formulario la casilla de adjudicaciones parciales, se entendera que NO acepta adjudicaciones parciales.

Sheet Cant producto 4_2032
A1: ANEXO No. 1
A2: ENERGIA ELECTRICA PLANA ENERO-2032 A DICIEMBRE-2032
A3: CONVOCATORIA PÚBLICA EMSA No. CP-EMSC2026-001
B4: HORA | C4: 1 | D4: 2 | E4: 3 | F4: 4 | G4: 5 | H4: 6 | I4: 7 | J4: 8 | K4: 9 | L4: 10 | M4: 11 | N4: 12 | O4: 13 | P4: 14 | Q4: 15 | R4: 16 | S4: 17 | T4: 18 | U4: 19 | V4: 20 | W4: 21 | X4: 22 | Y4: 23 | Z4: 24 | AA4: # DIAS | AB4: TOTAL | AC4: MES
A5: MES/AÑO | B5: TIPO DE DIA | C5: kWh | D5: kWh | E5: kWh | F5: kWh | G5: kWh | H5: kWh | I5: kWh | J5: kWh | K5: kWh | L5: kWh | M5: kWh | N5: kWh | O5: kWh | P5: kWh | Q5: kWh | R5: kWh | S5: kWh | T5: kWh | U5: kWh | V5: kWh | W5: kWh | X5: kWh | Y5: kWh | Z5: kWh
A6: 48214 | B6: NORMAL | C6: 53000 | D6: =+C6 -> 53000 | E6: =+D6 -> 53000 | F6: =+E6 -> 53000 | G6: =+F6 -> 53000 | H6: =+G6 -> 53000 | I6: =+H6 -> 53000 | J6: =+I6 -> 53000 | K6: =+J6 -> 53000 | ... Z6: =+Y6 -> 53000 | AA6: 20 | AB6: =+SUM(C6:Z6)*AA6 -> 25440000 | AC6: =+AB6+AB7+AB8 -> 39432000
B7: SABADO | C7: 53000 | D7: =+C7 -> 53000 | E7: =+D7 -> 53000 | F7: =+E7 -> 53000 | G7: =+F7 -> 53000 | H7: =+G7 -> 53000 | I7: =+H7 -> 53000 | J7: =+I7 -> 53000 | K7: =+J7 -> 53000 | ... Z7: =+Y7 -> 53000 | AA7: 5 | AB7: =+SUM(C7:Z7)*AA7 -> 6360000
B8: DOM/FES | C8: 53000 | D8: =+C8 -> 53000 | E8: =+D8 -> 53000 | F8: =+E8 -> 53000 | G8: =+F8 -> 53000 | H8: =+G8 -> 53000 | I8: =+H8 -> 53000 | J8: =+I8 -> 53000 | K8: =+J8 -> 53000 | ... Z8: =+Y8 -> 53000 | AA8: 6 | AB8: =+SUM(C8:Z8)*AA8 -> 7632000
A9: 48245 | B9: NORMAL | C9: 53000 | D9: =+C9 -> 53000 | E9: =+D9 -> 53000 | F9: =+E9 -> 53000 | G9: =+F9 -> 53000 | H9: =+G9 -> 53000 | I9: =+H9 -> 53000 | J9: =+I9 -> 53000 | K9: =+J9 -> 53000 | ... Z9: =+Y9 -> 53000 | AA9: 20 | AB9: =+SUM(C9:Z9)*AA9 -> 25440000 | AC9: =+AB9+AB10+AB11 -> 36888000
B10: SABADO | C10: 53000 | D10: =+C10 -> 53000 | E10: =+D10 -> 53000 | F10: =+E10 -> 53000 | G10: =+F10 -> 53000 | H10: =+G10 -> 53000 | I10: =+H10 -> 53000 | J10: =+I10 -> 53000 | K10: =+J10 -> 53000 | ... Z10: =+Y10 -> 53000 | AA10: 4 | AB10: =+SUM(C10:Z10)*AA10 -> 5088000
B11: DOM/FES | C11: 53000 | D11: =+C11 -> 53000 | E11: =+D11 -> 53000 | F11: =+E11 -> 53000 | G11: =+F11 -> 53000 | H11: =+G11 -> 53000 | I11: =+H11 -> 53000 | J11: =+I11 -> 53000 | K11: =+J11 -> 53000 | ... Z11: =+Y11 -> 53000 | AA11: 5 | AB11: =+SUM(C11:Z11)*AA11 -> 6360000
A12: 48274 | B12: NORMAL | C12: 53000 | D12: =+C12 -> 53000 | E12: =+D12 -> 53000 | F12: =+E12 -> 53000 | G12: =+F12 -> 53000 | H12: =+G12 -> 53000 | I12: =+H12 -> 53000 | J12: =+I12 -> 53000 | K12: =+J12 -> 53000 | ... Z12: =+Y12 -> 53000 | AA12: 20 | AB12: =+SUM(C12:Z12)*AA12 -> 25440000 | AC12: =+AB12+AB13+AB14 -> 39432000
B13: SABADO | C13: 53000 | D13: =+C13 -> 53000 | E13: =+D13 -> 53000 | F13: =+E13 -> 53000 | G13: =+F13 -> 53000 | H13: =+G13 -> 53000 | I13: =+H13 -> 53000 | J13: =+I13 -> 53000 | K13: =+J13 -> 53000 | ... Z13: =+Y13 -> 53000 | AA13: 4 | AB13: =+SUM(C13:Z13)*AA13 -> 5088000
B14: DOM/FES | C14: 53000 | D14: =+C14 -> 53000 | E14: =+D14 -> 53000 | F14: =+E14 -> 53000 | G14: =+F14 -> 53000 | H14: =+G14 -> 53000 | I14: =+H14 -> 53000 | J14: =+I14 -> 53000 | K14: =+J14 -> 53000 | ... Z14: =+Y14 -> 53000 | AA14: 7 | AB14: =+SUM(C14:Z14)*AA14 -> 8904000
A15: 48305 | B15: NORMAL | C15: 43000 | D15: =+C15 -> 43000 | E15: =+D15 -> 43000 | F15: =+E15 -> 43000 | G15: =+F15 -> 43000 | H15: =+G15 -> 43000 | I15: =+H15 -> 43000 | J15: =+I15 -> 43000 | K15: =+J15 -> 43000 | ... Z15: =+Y15 -> 43000 | AA15: 22 | AB15: =+SUM(C15:Z15)*AA15 -> 22704000 | AC15: =+AB15+AB16+AB17 -> 30960000
B16: SABADO | C16: 43000 | D16: =+C16 -> 43000 | E16: =+D16 -> 43000 | F16: =+E16 -> 43000 | G16: =+F16 -> 43000 | H16: =+G16 -> 43000 | I16: =+H16 -> 43000 | J16: =+I16 -> 43000 | K16: =+J16 -> 43000 | ... Z16: =+Y16 -> 43000 | AA16: 4 | AB16: =+SUM(C16:Z16)*AA16 -> 4128000
B17: DOM/FES | C17: 43000 | D17: =+C17 -> 43000 | E17: =+D17 -> 43000 | F17: =+E17 -> 43000 | G17: =+F17 -> 43000 | H17: =+G17 -> 43000 | I17: =+H17 -> 43000 | J17: =+I17 -> 43000 | K17: =+J17 -> 43000 | ... Z17: =+Y17 -> 43000 | AA17: 4 | AB17: =+SUM(C17:Z17)*AA17 -> 4128000
A18: 48335 | B18: NORMAL | C18: 43000 | D18: =+C18 -> 43000 | E18: =+D18 -> 43000 | F18: =+E18 -> 43000 | G18: =+F18 -> 43000 | H18: =+G18 -> 43000 | I18: =+H18 -> 43000 | J18: =+I18 -> 43000 | K18: =+J18 -> 43000 | ... Z18: =+Y18 -> 43000 | AA18: 19 | AB18: =+SUM(C18:Z18)*AA18 -> 19608000 | AC18: =+AB18+AB19+AB20 -> 31992000
B19: SABADO | C19: 43000 | D19: =+C19 -> 43000 | E19: =+D19 -> 43000 | F19: =+E19 -> 43000 | G19: =+F19 -> 43000 | H19: =+G19 -> 43000 | I19: =+H19 -> 43000 | J19: =+I19 -> 43000 | K19: =+J19 -> 43000 | ... Z19: =+Y19 -> 43000 | AA19: 4 | AB19: =+SUM(C19:Z19)*AA19 -> 4128000
B20: DOM/FES | C20: 43000 | D20: =+C20 -> 43000 | E20: =+D20 -> 43000 | F20: =+E20 -> 43000 | G20: =+F20 -> 43000 | H20: =+G20 -> 43000 | I20: =+H20 -> 43000 | J20: =+I20 -> 43000 | K20: =+J20 -> 43000 | ... Z20: =+Y20 -> 43000 | AA20: 8 | AB20: =+SUM(C20:Z20)*AA20 -> 8256000
A21: 48366 | B21: NORMAL | C21: 38000 | D21: =+C21 -> 38000 | E21: =+D21 -> 38000 | F21: =+E21 -> 38000 | G21: =+F21 -> 38000 | H21: =+G21 -> 38000 | I21: =+H21 -> 38000 | J21: =+I21 -> 38000 | K21: =+J21 -> 38000 | ... Z21: =+Y21 -> 38000 | AA21: 21 | AB21: =+SUM(C21:Z21)*AA21 -> 19152000 | AC21: =+AB21+AB22+AB23 -> 27360000
B22: SABADO | C22: 38000 | D22: =+C22 -> 38000 | E22: =+D22 -> 38000 | F22: =+E22 -> 38000 | G22: =+F22 -> 38000 | H22: =+G22 -> 38000 | I22: =+H22 -> 38000 | J22: =+I22 -> 38000 | K22: =+J22 -> 38000 | ... Z22: =+Y22 -> 38000 | AA22: 4 | AB22: =+SUM(C22:Z22)*AA22 -> 3648000
B23: DOM/FES | C23: 38000 | D23: =+C23 -> 38000 | E23: =+D23 -> 38000 | F23: =+E23 -> 38000 | G23: =+F23 -> 38000 | H23: =+G23 -> 38000 | I23: =+H23 -> 38000 | J23: =+I23 -> 38000 | K23: =+J23 -> 38000 | ... Z23: =+Y23 -> 38000 | AA23: 5 | AB23: =+SUM(C23:Z23)*AA23 -> 4560000
A24: 48396 | B24: NORMAL | C24: 38000 | D24: =+C24 -> 38000 | E24: =+D24 -> 38000 | F24: =+E24 -> 38000 | G24: =+F24 -> 38000 | H24: =+G24 -> 38000 | I24: =+H24 -> 38000 | J24: =+I24 -> 38000 | K24: =+J24 -> 38000 | ... Z24: =+Y24 -> 38000 | AA24: 20 | AB24: =+SUM(C24:Z24)*AA24 -> 18240000 | AC24: =+AB24+AB25+AB26 -> 28272000
B25: SABADO | C25: 38000 | D25: =+C25 -> 38000 | E25: =+D25 -> 38000 | F25: =+E25 -> 38000 | G25: =+F25 -> 38000 | H25: =+G25 -> 38000 | I25: =+H25 -> 38000 | J25: =+I25 -> 38000 | K25: =+J25 -> 38000 | ... Z25: =+Y25 -> 38000 | AA25: 5 | AB25: =+SUM(C25:Z25)*AA25 -> 4560000
B26: DOM/FES | C26: 38000 | D26: =+C26 -> 38000 | E26: =+D26 -> 38000 | F26: =+E26 -> 38000 | G26: =+F26 -> 38000 | H26: =+G26 -> 38000 | I26: =+H26 -> 38000 | J26: =+I26 -> 38000 | K26: =+J26 -> 38000 | ... Z26: =+Y26 -> 38000 | AA26: 6 | AB26: =+SUM(C26:Z26)*AA26 -> 5472000
A27: 48427 | B27: NORMAL | C27: 43000 | D27: =+C27 -> 43000 | E27: =+D27 -> 43000 | F27: =+E27 -> 43000 | G27: =+F27 -> 43000 | H27: =+G27 -> 43000 | I27: =+H27 -> 43000 | J27: =+I27 -> 43000 | K27: =+J27 -> 43000 | ... Z27: =+Y27 -> 43000 | AA27: 21 | AB27: =+SUM(C27:Z27)*AA27 -> 21672000 | AC27: =+AB27+AB28+AB29 -> 31992000
B28: SABADO | C28: 43000 | D28: =+C28 -> 43000 | E28: =+D28 -> 43000 | F28: =+E28 -> 43000 | G28: =+F28 -> 43000 | H28: =+G28 -> 43000 | I28: =+H28 -> 43000 | J28: =+I28 -> 43000 | K28: =+J28 -> 43000 | ... Z28: =+Y28 -> 43000 | AA28: 3 | AB28: =+SUM(C28:Z28)*AA28 -> 3096000
B29: DOM/FES | C29: 43000 | D29: =+C29 -> 43000 | E29: =+D29 -> 43000 | F29: =+E29 -> 43000 | G29: =+F29 -> 43000 | H29: =+G29 -> 43000 | I29: =+H29 -> 43000 | J29: =+I29 -> 43000 | K29: =+J29 -> 43000 | ... Z29: =+Y29 -> 43000 | AA29: 7 | AB29: =+SUM(C29:Z29)*AA29 -> 7224000
A30: 48458 | B30: NORMAL | C30: 43000 | D30: =+C30 -> 43000 | E30: =+D30 -> 43000 | F30: =+E30 -> 43000 | G30: =+F30 -> 43000 | H30: =+G30 -> 43000 | I30: =+H30 -> 43000 | J30: =+I30 -> 43000 | K30: =+J30 -> 43000 | ... Z30: =+Y30 -> 43000 | AA30: 22 | AB30: =+SUM(C30:Z30)*AA30 -> 22704000 | AC30: =+AB30+AB31+AB32 -> 30960000
B31: SABADO | C31: 43000 | D31: =+C31 -> 43000 | E31: =+D31 -> 43000 | F31: =+E31 -> 43000 | G31: =+F31 -> 43000 | H31: =+G31 -> 43000 | I31: =+H31 -> 43000 | J31: =+I31 -> 43000 | K31: =+J31 -> 43000 | ... Z31: =+Y31 -> 43000 | AA31: 4 | AB31: =+SUM(C31:Z31)*AA31 -> 4128000
B32: DOM/FES | C32: 43000 | D32: =+C32 -> 43000 | E32: =+D32 -> 43000 | F32: =+E32 -> 43000 | G32: =+F32 -> 43000 | H32: =+G32 -> 43000 | I32: =+H32 -> 43000 | J32: =+I32 -> 43000 | K32: =+J32 -> 43000 | ... Z32: =+Y32 -> 43000 | AA32: 4 | AB32: =+SUM(C32:Z32)*AA32 -> 4128000
A33: 48488 | B33: NORMAL | C33: 43000 | D33: =+C33 -> 43000 | E33: =+D33 -> 43000 | F33: =+E33 -> 43000 | G33: =+F33 -> 43000 | H33: =+G33 -> 43000 | I33: =+H33 -> 43000 | J33: =+I33 -> 43000 | K33: =+J33 -> 43000 | ... Z33: =+Y33 -> 43000 | AA33: 20 | AB33: =+SUM(C33:Z33)*AA33 -> 20640000 | AC33: =+AB33+AB34+AB35 -> 31992000
B34: SABADO | C34: 43000 | D34: =+C34 -> 43000 | E34: =+D34 -> 43000 | F34: =+E34 -> 43000 | G34: =+F34 -> 43000 | H34: =+G34 -> 43000 | I34: =+H34 -> 43000 | J34: =+I34 -> 43000 | K34: =+J34 -> 43000 | ... Z34: =+Y34 -> 43000 | AA34: 5 | AB34: =+SUM(C34:Z34)*AA34 -> 5160000
B35: DOM/FES | C35: 43000 | D35: =+C35 -> 43000 | E35: =+D35 -> 43000 | F35: =+E35 -> 43000 | G35: =+F35 -> 43000 | H35: =+G35 -> 43000 | I35: =+H35 -> 43000 | J35: =+I35 -> 43000 | K35: =+J35 -> 43000 | ... Z35: =+Y35 -> 43000 | AA35: 6 | AB35: =+SUM(C35:Z35)*AA35 -> 6192000
A36: 48519 | B36: NORMAL | C36: 43000 | D36: =+C36 -> 43000 | E36: =+D36 -> 43000 | F36: =+E36 -> 43000 | G36: =+F36 -> 43000 | H36: =+G36 -> 43000 | I36: =+H36 -> 43000 | J36: =+I36 -> 43000 | K36: =+J36 -> 43000 | ... Z36: =+Y36 -> 43000 | AA36: 20 | AB36: =+SUM(C36:Z36)*AA36 -> 20640000 | AC36: =+AB36+AB37+AB38 -> 30960000
B37: SABADO | C37: 43000 | D37: =+C37 -> 43000 | E37: =+D37 -> 43000 | F37: =+E37 -> 43000 | G37: =+F37 -> 43000 | H37: =+G37 -> 43000 | I37: =+H37 -> 43000 | J37: =+I37 -> 43000 | K37: =+J37 -> 43000 | ... Z37: =+Y37 -> 43000 | AA37: 4 | AB37: =+SUM(C37:Z37)*AA37 -> 4128000
B38: DOM/FES | C38: 43000 | D38: =+C38 -> 43000 | E38: =+D38 -> 43000 | F38: =+E38 -> 43000 | G38: =+F38 -> 43000 | H38: =+G38 -> 43000 | I38: =+H38 -> 43000 | J38: =+I38 -> 43000 | K38: =+J38 -> 43000 | ... Z38: =+Y38 -> 43000 | AA38: 6 | AB38: =+SUM(C38:Z38)*AA38 -> 6192000
A39: 48549 | B39: NORMAL | C39: 53000 | D39: =+C39 -> 53000 | E39: =+D39 -> 53000 | F39: =+E39 -> 53000 | G39: =+F39 -> 53000 | H39: =+G39 -> 53000 | I39: =+H39 -> 53000 | J39: =+I39 -> 53000 | K39: =+J39 -> 53000 | ... Z39: =+Y39 -> 53000 | AA39: 22 | AB39: =+SUM(C39:Z39)*AA39 -> 27984000 | AC39: =+AB39+AB40+AB41 -> 39432000
B40: SABADO | C40: 53000 | D40: =+C40 -> 53000 | E40: =+D40 -> 53000 | F40: =+E40 -> 53000 | G40: =+F40 -> 53000 | H40: =+G40 -> 53000 | I40: =+H40 -> 53000 | J40: =+I40 -> 53000 | K40: =+J40 -> 53000 | ... Z40: =+Y40 -> 53000 | AA40: 3 | AB40: =+SUM(C40:Z40)*AA40 -> 3816000
...

Sheet Producto 5
A1: ANEXO No. 1A CANTIDADES DE ENERGIA REQUERIDA
A2: CONVOCATORIA PÚBLICA EMSA-CP-EMSC2026-001
A3: OFERTA DE SUMINISTRO DE ENERGÍA ELECTRICA PLANA DE ENERO-2033 A DICIEMBRE-2036
A5: AÑO | B5: ENERGIA SOLICITADA | C5: PAGUE LO CONTRATADO
C6: Oferta (%) De la Curva Demanda
B7: Necesidad TOTAL AÑO kWh | C7: % | D7: Oferta $/kWh
A8: 48580 | B8: =+VLOOKUP(A8,'Cant producto_5_2033-36'!$A:$AD,29,FALSE) -> 46128000
A9: 48611 | B9: =+VLOOKUP(A9,'Cant producto_5_2033-36'!$A:$AD,29,FALSE) -> 41664000
A10: 48639 | B10: =+VLOOKUP(A10,'Cant producto_5_2033-36'!$A:$AD,29,FALSE) -> 46128000
A11: 48670 | B11: =+VLOOKUP(A11,'Cant producto_5_2033-36'!$A:$AD,29,FALSE) -> 44640000
A12: 48700 | B12: =+VLOOKUP(A12,'Cant producto_5_2033-36'!$A:$AD,29,FALSE) -> 46128000
A13: 48731 | B13: =+VLOOKUP(A13,'Cant producto_5_2033-36'!$A:$AD,29,FALSE) -> 44640000
A14: 48761 | B14: =+VLOOKUP(A14,'Cant producto_5_2033-36'!$A:$AD,29,FALSE) -> 46128000
A15: 48792 | B15: =+VLOOKUP(A15,'Cant producto_5_2033-36'!$A:$AD,29,FALSE) -> 46128000
A16: 48823 | B16: =+VLOOKUP(A16,'Cant producto_5_2033-36'!$A:$AD,29,FALSE) -> 44640000
A17: 48853 | B17: =+VLOOKUP(A17,'Cant producto_5_2033-36'!$A:$AD,29,FALSE) -> 46128000
A18: 48884 | B18: =+VLOOKUP(A18,'Cant producto_5_2033-36'!$A:$AD,29,FALSE) -> 44640000
A19: 48914 | B19: =+VLOOKUP(A19,'Cant producto_5_2033-36'!$A:$AD,29,FALSE) -> 46128000
... A55: 50010 | B55: =+VLOOKUP(A55,'Cant producto_5_2033-36'!$A:$AD,29,FALSE) -> 72912000
A56: TOTAL | B56: =+SUM(B8:B55) -> 2858112000
A59: NOTAS:
A61: Se acepta adjudicaciones parciales: NO___ SI_____
A348: NOMBRE Y FIRMA DEL REPRESENTANTE LEGAL
A349: AGENTE PROPONENTE
A351: NOTAS:
A352: Se acepta adjudicaciones parciales: NO___ SI_____ % Minimo a aceptar: _____
A353: En este formulario, el oferente debera manifestar formalmente si acepta o no adjudicaciones parciales y en caso afirmativo el porcentaje minimo que acepta.
A355: En el caso de no marcar en este formulario la casilla de adjudicaciones parciales, se entendera que NO acepta adjudicaciones parciales.

Sheet Cant producto_5_2033-36
A1: ANEXO No. 1
A2: ENERGIA ELECTRICA PLANA ENERO-2033 A DICIEMBRE-2036
A3: CONVOCATORIA PÚBLICA EMSA No. CP-EMSC2026-001
B4: HORA | C4: 1 | D4: 2 | E4: 3 | F4: 4 | G4: 5 | H4: 6 | I4: 7 | J4: 8 | K4: 9 | L4: 10 | M4: 11 | N4: 12 | O4: 13 | P4: 14 | Q4: 15 | R4: 16 | S4: 17 | T4: 18 | U4: 19 | V4: 20 | W4: 21 | X4: 22 | Y4: 23 | Z4: 24 | AA4: # DIAS | AB4: TOTAL | AC4: MES
A5: MES/AÑO | B5: TIPO DE DIA | C5: kWh | D5: kWh | E5: kWh | F5: kWh | G5: kWh | H5: kWh | I5: kWh | J5: kWh | K5: kWh | L5: kWh | M5: kWh | N5: kWh | O5: kWh | P5: kWh | Q5: kWh | R5: kWh | S5: kWh | T5: kWh | U5: kWh | V5: kWh | W5: kWh | X5: kWh | Y5: kWh | Z5: kWh
A6: 48580 | B6: NORMAL | C6: 62000 | D6: =+C6 -> 62000 | E6: =+D6 -> 62000 | F6: =+E6 -> 62000 | G6: =+F6 -> 62000 | H6: =+G6 -> 62000 | I6: =+H6 -> 62000 | J6: =+I6 -> 62000 | K6: =+J6 -> 62000 | ... Z6: =+Y6 -> 62000 | AA6: 20 | AB6: =+SUM(C6:Z6)*AA6 -> 29760000 | AC6: =+AB6+AB7+AB8 -> 46128000
B7: SABADO | C7: 62000 | D7: =+C7 -> 62000 | E7: =+D7 -> 62000 | F7: =+E7 -> 62000 | G7: =+F7 -> 62000 | H7: =+G7 -> 62000 | I7: =+H7 -> 62000 | J7: =+I7 -> 62000 | K7: =+J7 -> 62000 | ... Z7: =+Y7 -> 62000 | AA7: 5 | AB7: =+SUM(C7:Z7)*AA7 -> 7440000
B8: DOM/FES | C8: 62000 | D8: =+C8 -> 62000 | E8: =+D8 -> 62000 | F8: =+E8 -> 62000 | G8: =+F8 -> 62000 | H8: =+G8 -> 62000 | I8: =+H8 -> 62000 | J8: =+I8 -> 62000 | K8: =+J8 -> 62000 | ... Z8: =+Y8 -> 62000 | AA8: 6 | AB8: =+SUM(C8:Z8)*AA8 -> 8928000
A9: 48611 | B9: NORMAL | C9: 62000 | D9: =+C9 -> 62000 | E9: =+D9 -> 62000 | F9: =+E9 -> 62000 | G9: =+F9 -> 62000 | H9: =+G9 -> 62000 | I9: =+H9 -> 62000 | J9: =+I9 -> 62000 | K9: =+J9 -> 62000 | ... Z9: =+Y9 -> 62000 | AA9: 20 | AB9: =+SUM(C9:Z9)*AA9 -> 29760000 | AC9: =+AB9+AB10+AB11 -> 41664000
B10: SABADO | C10: 62000 | D10: =+C10 -> 62000 | E10: =+D10 -> 62000 | F10: =+E10 -> 62000 | G10: =+F10 -> 62000 | H10: =+G10 -> 62000 | I10: =+H10 -> 62000 | J10: =+I10 -> 62000 | K10: =+J10 -> 62000 | ... Z10: =+Y10 -> 62000 | AA10: 4 | AB10: =+SUM(C10:Z10)*AA10 -> 5952000
B11: DOM/FES | C11: 62000 | D11: =+C11 -> 62000 | E11: =+D11 -> 62000 | F11: =+E11 -> 62000 | G11: =+F11 -> 62000 | H11: =+G11 -> 62000 | I11: =+H11 -> 62000 | J11: =+I11 -> 62000 | K11: =+J11 -> 62000 | ... Z11: =+Y11 -> 62000 | AA11: 4 | AB11: =+SUM(C11:Z11)*AA11 -> 5952000
A12: 48639 | B12: NORMAL | C12: 62000 | D12: =+C12 -> 62000 | E12: =+D12 -> 62000 | F12: =+E12 -> 62000 | G12: =+F12 -> 62000 | H12: =+G12 -> 62000 | I12: =+H12 -> 62000 | J12: =+I12 -> 62000 | K12: =+J12 -> 62000 | ... Z12: =+Y12 -> 62000 | AA12: 22 | AB12: =+SUM(C12:Z12)*AA12 -> 32736000 | AC12: =+AB12+AB13+AB14 -> 46128000
B13: SABADO | C13: 62000 | D13: =+C13 -> 62000 | E13: =+D13 -> 62000 | F13: =+E13 -> 62000 | G13: =+F13 -> 62000 | H13: =+G13 -> 62000 | I13: =+H13 -> 62000 | J13: =+I13 -> 62000 | K13: =+J13 -> 62000 | ... Z13: =+Y13 -> 62000 | AA13: 4 | AB13: =+SUM(C13:Z13)*AA13 -> 5952000
B14: DOM/FES | C14: 62000 | D14: =+C14 -> 62000 | E14: =+D14 -> 62000 | F14: =+E14 -> 62000 | G14: =+F14 -> 62000 | H14: =+G14 -> 62000 | I14: =+H14 -> 62000 | J14: =+I14 -> 62000 | K14: =+J14 -> 62000 | ... Z14: =+Y14 -> 62000 | AA14: 5 | AB14: =+SUM(C14:Z14)*AA14 -> 7440000
A15: 48670 | B15: NORMAL | C15: 62000 | D15: =+C15 -> 62000 | E15: =+D15 -> 62000 | F15: =+E15 -> 62000 | G15: =+F15 -> 62000 | H15: =+G15 -> 62000 | I15: =+H15 -> 62000 | J15: =+I15 -> 62000 | K15: =+J15 -> 62000 | ... Z15: =+Y15 -> 62000 | AA15: 19 | AB15: =+SUM(C15:Z15)*AA15 -> 28272000 | AC15: =+AB15+AB16+AB17 -> 44640000
B16: SABADO | C16: 62000 | D16: =+C16 -> 62000 | E16: =+D16 -> 62000 | F16: =+E16 -> 62000 | G16: =+F16 -> 62000 | H16: =+G16 -> 62000 | I16: =+H16 -> 62000 | J16: =+I16 -> 62000 | K16: =+J16 -> 62000 | ... Z16: =+Y16 -> 62000 | AA16: 5 | AB16: =+SUM(C16:Z16)*AA16 -> 7440000
B17: DOM/FES | C17: 62000 | D17: =+C17 -> 62000 | E17: =+D17 -> 62000 | F17: =+E17 -> 62000 | G17: =+F17 -> 62000 | H17: =+G17 -> 62000 | I17: =+H17 -> 62000 | J17: =+I17 -> 62000 | K17: =+J17 -> 62000 | ... Z17: =+Y17 -> 62000 | AA17: 6 | AB17: =+SUM(C17:Z17)*AA17 -> 8928000
A18: 48700 | B18: NORMAL | C18: 62000 | D18: =+C18 -> 62000 | E18: =+D18 -> 62000 | F18: =+E18 -> 62000 | G18: =+F18 -> 62000 | H18: =+G18 -> 62000 | I18: =+H18 -> 62000 | J18: =+I18 -> 62000 | K18: =+J18 -> 62000 | ... Z18: =+Y18 -> 62000 | AA18: 21 | AB18: =+SUM(C18:Z18)*AA18 -> 31248000 | AC18: =+AB18+AB19+AB20 -> 46128000
B19: SABADO | C19: 62000 | D19: =+C19 -> 62000 | E19: =+D19 -> 62000 | F19: =+E19 -> 62000 | G19: =+F19 -> 62000 | H19: =+G19 -> 62000 | I19: =+H19 -> 62000 | J19: =+I19 -> 62000 | K19: =+J19 -> 62000 | ... Z19: =+Y19 -> 62000 | AA19: 4 | AB19: =+SUM(C19:Z19)*AA19 -> 5952000
B20: DOM/FES | C20: 62000 | D20: =+C20 -> 62000 | E20: =+D20 -> 62000 | F20: =+E20 -> 62000 | G20: =+F20 -> 62000 | H20: =+G20 -> 62000 | I20: =+H20 -> 62000 | J20: =+I20 -> 62000 | K20: =+J20 -> 62000 | ... Z20: =+Y20 -> 62000 | AA20: 6 | AB20: =+SUM(C20:Z20)*AA20 -> 8928000
A21: 48731 | B21: NORMAL | C21: 62000 | D21: =+C21 -> 62000 | E21: =+D21 -> 62000 | F21: =+E21 -> 62000 | G21: =+F21 -> 62000 | H21: =+G21 -> 62000 | I21: =+H21 -> 62000 | J21: =+I21 -> 62000 | K21: =+J21 -> 62000 | ... Z21: =+Y21 -> 62000 | AA21: 21 | AB21: =+SUM(C21:Z21)*AA21 -> 31248000 | AC21: =+AB21+AB22+AB23 -> 44640000
B22: SABADO | C22: 62000 | D22: =+C22 -> 62000 | E22: =+D22 -> 62000 | F22: =+E22 -> 62000 | G22: =+F22 -> 62000 | H22: =+G22 -> 62000 | I22: =+H22 -> 62000 | J22: =+I22 -> 62000 | K22: =+J22 -> 62000 | ... Z22: =+Y22 -> 62000 | AA22: 4 | AB22: =+SUM(C22:Z22)*AA22 -> 5952000
B23: DOM/FES | C23: 62000 | D23: =+C23 -> 62000 | E23: =+D23 -> 62000 | F23: =+E23 -> 62000 | G23: =+F23 -> 62000 | H23: =+G23 -> 62000 | I23: =+H23 -> 62000 | J23: =+I23 -> 62000 | K23: =+J23 -> 62000 | ... Z23: =+Y23 -> 62000 | AA23: 5 | AB23: =+SUM(C23:Z23)*AA23 -> 7440000
A24: 48761 | B24: NORMAL | C24: 62000 | D24: =+C24 -> 62000 | E24: =+D24 -> 62000 | F24: =+E24 -> 62000 | G24: =+F24 -> 62000 | H24: =+G24 -> 62000 | I24: =+H24 -> 62000 | J24: =+I24 -> 62000 | K24: =+J24 -> 62000 | ... Z24: =+Y24 -> 62000 | AA24: 19 | AB24: =+SUM(C24:Z24)*AA24 -> 28272000 | AC24: =+AB24+AB25+AB26 -> 46128000
B25: SABADO | C25: 62000 | D25: =+C25 -> 62000 | E25: =+D25 -> 62000 | F25: =+E25 -> 62000 | G25: =+F25 -> 62000 | H25: =+G25 -> 62000 | I25: =+H25 -> 62000 | J25: =+I25 -> 62000 | K25: =+J25 -> 62000 | ... Z25: =+Y25 -> 62000 | AA25: 5 | AB25: =+SUM(C25:Z25)*AA25 -> 7440000
B26: DOM/FES | C26: 62000 | D26: =+C26 -> 62000 | E26: =+D26 -> 62000 | F26: =+E26 -> 62000 | G26: =+F26 -> 62000 | H26: =+G26 -> 62000 | I26: =+H26 -> 62000 | J26: =+I26 -> 62000 | K26: =+J26 -> 62000 | ... Z26: =+Y26 -> 62000 | AA26: 7 | AB26: =+SUM(C26:Z26)*AA26 -> 10416000
A27: 48792 | B27: NORMAL | C27: 62000 | D27: =+C27 -> 62000 | E27: =+D27 -> 62000 | F27: =+E27 -> 62000 | G27: =+F27 -> 62000 | H27: =+G27 -> 62000 | I27: =+H27 -> 62000 | J27: =+I27 -> 62000 | K27: =+J27 -> 62000 | ... Z27: =+Y27 -> 62000 | AA27: 22 | AB27: =+SUM(C27:Z27)*AA27 -> 32736000 | AC27: =+AB27+AB28+AB29 -> 46128000
B28: SABADO | C28: 62000 | D28: =+C28 -> 62000 | E28: =+D28 -> 62000 | F28: =+E28 -> 62000 | G28: =+F28 -> 62000 | H28: =+G28 -> 62000 | I28: =+H28 -> 62000 | J28: =+I28 -> 62000 | K28: =+J28 -> 62000 | ... Z28: =+Y28 -> 62000 | AA28: 4 | AB28: =+SUM(C28:Z28)*AA28 -> 5952000
B29: DOM/FES | C29: 62000 | D29: =+C29 -> 62000 | E29: =+D29 -> 62000 | F29: =+E29 -> 62000 | G29: =+F29 -> 62000 | H29: =+G29 -> 62000 | I29: =+H29 -> 62000 | J29: =+I29 -> 62000 | K29: =+J29 -> 62000 | ... Z29: =+Y29 -> 62000 | AA29: 5 | AB29: =+SUM(C29:Z29)*AA29 -> 7440000
