Workbook

Sheet Oferta Producto 1
B1: ANEXO. CANTIDADES DE ENERGÍA Y PRECIO
B2: PRODUCTO: | C2: 1
B4: CONVOCATORIA PUBLICA: | C4: CP-CHCC2025-001
B5: OFERENTE:
B6: AÑO: | C6: 2027
B7: CANTIDAD EN: | C7: KWh
B8: EN PESOS DE | C8: 45689
B9: INDICADOR: | C9: IPP- PROVISIONAL
B10: TIPO DE CONTRATO: | C10: PC
B11: TIPO DE CARGA: | C11: CURVA
B13: Fecha | C13: Energia Solicitada kWh | D13: Porcentaje Ofertado % | E13: Energia Ofertada kWh | F13: Precio $/KWh
B14: 46388 | C14: =+'Cantidad Producto 1'!AE7 -> 16083668 | E14: =+C14*D14 -> 0
B15: 46419 | C15: =+'Cantidad Producto 1'!AE8 -> 16772713 | E15: =+C15*D15 -> 0
B16: 46447 | C16: =+'Cantidad Producto 1'!AE9 -> 15930449 | E16: =+C16*D16 -> 0
B17: 46478 | C17: =+'Cantidad Producto 1'!AE10 -> 15981097 | E17: =+C17*D17 -> 0
B18: 46508 | C18: =+'Cantidad Producto 1'!AE11 -> 14566451 | E18: =+C18*D18 -> 0
B19: 46539 | C19: =+'Cantidad Producto 1'!AE12 -> 14674689 | E19: =+C19*D19 -> 0
B20: 46569 | C20: =+'Cantidad Producto 1'!AE13 -> 13313300 | E20: =+C20*D20 -> 0
B21: 46600 | C21: =+'Cantidad Producto 1'!AE14 -> 12973895 | E21: =+C21*D21 -> 0
B22: 46631 | C22: =+'Cantidad Producto 1'!AE15 -> 14018103 | E22: =+C22*D22 -> 0
B23: 46661 | C23: =+'Cantidad Producto 1'!AE16 -> 13266334 | E23: =+C23*D23 -> 0
B24: 46692 | C24: =+'Cantidad Producto 1'!AE17 -> 13751175 | E24: =+C24*D24 -> 0
B25: 46722 | C25: =+'Cantidad Producto 1'!AE18 -> 12975104 | E25: =+C25*D25 -> 0
B26: Total año | C26: =SUM(C14:C25) -> 1.7430698e+08 | D26: % | E26: =SUM(E14:E25) -> 0
B29: Notas:
B30: 1. La Energía Ofertada se distribuye en forma horaria de acuerdo con la curva de carga presentada en la hoja Cantidades Producto.
B31: 2. Se aceptan ofertas siguiendo la curva
B32: 3.Tipo de Contrato: pague lo contratado.
B33: 4. Precio ofertado en $kWh, en pesos de febrero 2025.
B34: 5.Con % igual para todos los meses del año, el precio debe ser el mismo para todos los meses del año

Sheet Oferta Producto 2
B1: ANEXO. CANTIDADES DE ENERGÍA Y PRECIO
B2: PRODUCTO: | C2: 2
B4: CONVOCATORIA PUBLICA: | C4: =+'Oferta Producto 1'!C4 -> CP-CHCC2025-001
B5: OFERENTE:
B6: AÑO: | C6: 2028
B7: CANTIDAD EN: | C7: KWh
B8: EN PESOS DE | C8: =+'Oferta Producto 1'!C8 -> 45689
B9: INDICADOR: | C9: IPP- PROVISIONAL
B10: TIPO DE CONTRATO: | C10: PC
B11: TIPO DE CARGA: | C11: CURVA
B13: Fecha | C13: Energia Solicitada kWh | D13: Porcentaje Ofertado % | E13: Energia Ofertada kWh | F13: Precio $/KWh
B14: 46753 | C14: =+'Cantidad Producto 2'!AE7 -> 5640298 | E14: =+C14*D14 -> 0
B15: 46784 | C15: =+'Cantidad Producto 2'!AE8 -> 5481906.5 | E15: =+C15*D15 -> 0
B16: 46813 | C16: =+'Cantidad Producto 2'!AE9 -> 5737244.8 | E16: =+C16*D16 -> 0
B17: 46844 | C17: =+'Cantidad Producto 2'!AE10 -> 5761066.8 | E17: =+C17*D17 -> 0
B18: 46874 | C18: =+'Cantidad Producto 2'!AE11 -> 5621176.9 | E18: =+C18*D18 -> 0
B19: 46905 | C19: =+'Cantidad Producto 2'!AE12 -> 5640392.8 | E19: =+C19*D19 -> 0
B20: 46935 | C20: =+'Cantidad Producto 2'!AE13 -> 5897064.8 | E20: =+C20*D20 -> 0
B21: 46966 | C21: =+'Cantidad Producto 2'!AE14 -> 5698999.5 | E21: =+C21*D21 -> 0
B22: 46997 | C22: =+'Cantidad Producto 2'!AE15 -> 5553537.9 | E22: =+C22*D22 -> 0
B23: 47027 | C23: =+'Cantidad Producto 2'!AE16 -> 5705697 | E23: =+C23*D23 -> 0
B24: 47058 | C24: =+'Cantidad Producto 2'!AE17 -> 5600704.9 | E24: =+C24*D24 -> 0
B25: 47088 | C25: =+'Cantidad Producto 2'!AE18 -> 5690344.3 | E25: =+C25*D25 -> 0
B26: Total producto | C26: =SUM(C14:C25) -> 68028434 | D26: % | E26: =SUM(E14:E25) -> 0
B29: Notas:
B30: 1. La Energía Ofertada se distribuye en forma horaria de acuerdo con la curva de carga presentada en la hoja Cantidades Producto.
B31: 2. Se aceptan ofertas siguiendo la curva
B32: 3.Tipo de Contrato: pague lo contratado.
B33: 4. Precio ofertado en $kWh, en pesos de febrero 2025.
B34: 5.Con % igual para todos los meses del año, el precio debe ser el mismo para todos los meses del año

Sheet Oferta Producto 3
B1: ANEXO. CANTIDADES DE ENERGÍA Y PRECIO
B2: PRODUCTO: | C2: 3
B4: CONVOCATORIA PUBLICA: | C4: =+'Oferta Producto 1'!C4 -> CP-CHCC2025-001
B5: OFERENTE:
B6: AÑO: | C6: 2029
B7: CANTIDAD EN: | C7: KWh
B8: EN PESOS DE | C8: =+'Oferta Producto 1'!C8 -> 45689
B9: INDICADOR: | C9: IPP- PROVISIONAL
B10: TIPO DE CONTRATO: | C10: PC
B11: TIPO DE CARGA: | C11: CURVA
B13: Fecha | C13: Energia Solicitada kWh | D13: Porcentaje Ofertado % | E13: Energia Ofertada kWh | F13: Precio $/KWh
B14: 47119 | C14: =+'Cantidad Producto 3'!AE7 -> 7611173.4
B15: 47150 | C15: =+'Cantidad Producto 3'!AE8 -> 7372921
B16: 47178 | C16: =+'Cantidad Producto 3'!AE9 -> 7629884.1
B17: 47209 | C17: =+'Cantidad Producto 3'!AE10 -> 7671929.7
B18: 47239 | C18: =+'Cantidad Producto 3'!AE11 -> 7564719.2
B19: 47270 | C19: =+'Cantidad Producto 3'!AE12 -> 7481094.2
B20: 47300 | C20: =+'Cantidad Producto 3'!AE13 -> 7609421.9
B21: 47331 | C21: =+'Cantidad Producto 3'!AE14 -> 7737643
B22: 47362 | C22: =+'Cantidad Producto 3'!AE15 -> 7520959.6
B23: 47392 | C23: =+'Cantidad Producto 3'!AE16 -> 7771992.7
B24: 47423 | C24: =+'Cantidad Producto 3'!AE17 -> 7622142.1
B25: 47453 | C25: =+'Cantidad Producto 3'!AE18 -> 7728670
B26: Total producto | C26: =SUM(C14:C25) -> 91322551 | D26: %
B29: Notas:
B30: 1. La Energía Ofertada se distribuye en forma horaria de acuerdo con la curva de carga presentada en la hoja Cantidades Producto.
B31: 2. Se aceptan ofertas siguiendo la curva
B32: 3.Tipo de Contrato: pague lo contratado.
B33: 4. Precio ofertado en $kWh, en pesos de febrero 2025.
B34: 5.Con % igual para todos los meses del año, el precio debe ser el mismo para todos los meses del año

Sheet Oferta Producto 4
B1: ANEXO. CANTIDADES DE ENERGÍA Y PRECIO
B2: PRODUCTO: | C2: 4
B4: CONVOCATORIA PUBLICA: | C4: =+'Oferta Producto 1'!C4 -> CP-CHCC2025-001
B5: OFERENTE:
B6: AÑO: | C6: 2030
B7: CANTIDAD EN: | C7: KWh
B8: EN PESOS DE | C8: =+'Oferta Producto 1'!C8 -> 45689
B9: INDICADOR: | C9: IPP- PROVISIONAL
B10: TIPO DE CONTRATO: | C10: PC
B11: TIPO DE CARGA: | C11: CURVA
B13: Fecha | C13: Energia Solicitada kWh | D13: Porcentaje Ofertado % | E13: Energia Ofertada kWh | F13: Precio $/KWh
B14: 47484 | C14: =+'Cantidad Producto 4'!AE7 -> 9409166.4
B15: 47515 | C15: =+'Cantidad Producto 4'!AE8 -> 9079556.8
B16: 47543 | C16: =+'Cantidad Producto 4'!AE9 -> 9418074
B17: 47574 | C17: =+'Cantidad Producto 4'!AE10 -> 9434893.2
B18: 47604 | C18: =+'Cantidad Producto 4'!AE11 -> 9337617.4
B19: 47635 | C19: =+'Cantidad Producto 4'!AE12 -> 9246410.5
B20: 47665 | C20: =+'Cantidad Producto 4'!AE13 -> 9352791.7
B21: 47696 | C21: =+'Cantidad Producto 4'!AE14 -> 9545266
B22: 47727 | C22: =+'Cantidad Producto 4'!AE15 -> 9276815.5
B23: 47757 | C23: =+'Cantidad Producto 4'!AE16 -> 9574587.7
B24: 47788 | C24: =+'Cantidad Producto 4'!AE17 -> 9400577.5
B25: 47818 | C25: =+'Cantidad Producto 4'!AE18 -> 9542555.6
B26: Total producto | C26: =SUM(C14:C25) -> 1.1261831e+08 | D26: %
B29: Notas:
B30: 1. La Energía Ofertada se distribuye en forma horaria de acuerdo con la curva de carga presentada en la hoja Cantidades Producto.
B31: 2. Se aceptan ofertas siguiendo la curva
B32: 3.Tipo de Contrato: pague lo contratado.
B33: 4. Precio ofertado en $kWh, en pesos de febrero 2025.
B34: 5.Con % igual para todos los meses del año, el precio debe ser el mismo para todos los meses del año

Sheet Oferta Producto 5
B1: ANEXO. CANTIDADES DE ENERGÍA Y PRECIO
B2: PRODUCTO: | C2: 5
B4: CONVOCATORIA PUBLICA: | C4: =+'Oferta Producto 1'!C4 -> CP-CHCC2025-001
B5: OFERENTE:
B6: AÑO: | C6: 2031
B7: CANTIDAD EN: | C7: KWh
B8: EN PESOS DE | C8: =+'Oferta Producto 1'!C8 -> 45689
B9: INDICADOR: | C9: IPP- PROVISIONAL
B10: TIPO DE CONTRATO: | C10: PC
B11: TIPO DE CARGA: | C11: CURVA
B13: Fecha | C13: Energia Solicitada kWh | D13: Porcentaje Ofertado % | E13: Energia Ofertada kWh | F13: Precio $/KWh
B14: 47849 | C14: =+'Cantidad Producto 5'!AE7 -> 21420608
B15: 47880 | C15: =+'Cantidad Producto 5'!AE8 -> 21812343
B16: 47908 | C16: =+'Cantidad Producto 5'!AE9 -> 21131939
B17: 47939 | C17: =+'Cantidad Producto 5'!AE10 -> 21385626
B18: 47969 | C18: =+'Cantidad Producto 5'!AE11 -> 21461838
B19: 48000 | C19: =+'Cantidad Producto 5'!AE12 -> 21296894
B20: 48030 | C20: =+'Cantidad Producto 5'!AE13 -> 21324668
B21: 48061 | C21: =+'Cantidad Producto 5'!AE14 -> 21433379
B22: 48092 | C22: =+'Cantidad Producto 5'!AE15 -> 22122625
B23: 48122 | C23: =+'Cantidad Producto 5'!AE16 -> 21708117
B24: 48153 | C24: =+'Cantidad Producto 5'!AE17 -> 22105418
B25: 48183 | C25: =+'Cantidad Producto 5'!AE18 -> 21482702
B26: Total producto | C26: =SUM(C14:C25) -> 2.5868616e+08 | D26: %
B29: Notas:
B30: 1. La Energía Ofertada se distribuye en forma horaria de acuerdo con la curva de carga presentada en la hoja Cantidades Producto.
B31: 2. Se aceptan ofertas siguiendo la curva
B32: 3.Tipo de Contrato: pague lo contratado.
B33: 4. Precio ofertado en $kWh, en pesos de febrero 2025.
B34: 5.Con % igual para todos los meses del año, el precio debe ser el mismo para todos los meses del año

Sheet Oferta Producto 6
B1: ANEXO. CANTIDADES DE ENERGÍA Y PRECIO
B2: PRODUCTO: | C2: 6
B4: CONVOCATORIA PUBLICA: | C4: =+'Oferta Producto 1'!C4 -> CP-CHCC2025-001
B5: OFERENTE:
B6: AÑO: | C6: 2032
B7: CANTIDAD EN: | C7: KWh
B8: EN PESOS DE | C8: =+'Oferta Producto 1'!C8 -> 45689
B9: INDICADOR: | C9: IPP- PROVISIONAL
B10: TIPO DE CONTRATO: | C10: PC
B11: TIPO DE CARGA: | C11: CURVA
B13: Fecha | C13: Energia Solicitada kWh | D13: Porcentaje Ofertado % | E13: Energia Ofertada kWh | F13: Precio $/KWh
B14: 48214 | C14: =+'Cantidad Producto 6'!AE7 -> 21728549
B15: 48245 | C15: =+'Cantidad Producto 6'!AE8 -> 21917429
B16: 48274 | C16: =+'Cantidad Producto 6'!AE9 -> 21438237
B17: 48305 | C17: =+'Cantidad Producto 6'!AE10 -> 21698464
B18: 48335 | C18: =+'Cantidad Producto 6'!AE11 -> 21766749
B19: 48366 | C19: =+'Cantidad Producto 6'!AE12 -> 21609648
B20: 48396 | C20: =+'Cantidad Producto 6'!AE13 -> 22030649
B21: 48427 | C21: =+'Cantidad Producto 6'!AE14 -> 21883418
B22: 48458 | C22: =+'Cantidad Producto 6'!AE15 -> 22427742
B23: 48488 | C23: =+'Cantidad Producto 6'!AE16 -> 22015326
B24: 48519 | C24: =+'Cantidad Producto 6'!AE17 -> 22410234
B25: 48549 | C25: =+'Cantidad Producto 6'!AE18 -> 21934849
B26: Total producto | C26: =SUM(C14:C25) -> 2.628613e+08 | D26: %
B29: Notas:
B30: 1. La Energía Ofertada se distribuye en forma horaria de acuerdo con la curva de carga presentada en la hoja Cantidades Producto.
B31: 2. Se aceptan ofertas siguiendo la curva
B32: 3.Tipo de Contrato: pague lo contratado.
B33: 4. Precio ofertado en $kWh, en pesos de febrero 2025.
B34: 5.Con % igual para todos los meses del año, el precio debe ser el mismo para todos los meses del año

Sheet Cantidad Producto 1
B2: CANTIDADES DE ENERGÍA SOLICITADAS (kWh)
B3: CENTRAL HIDROELECTRICA DE CALDAS S.A. E.S.P. -BENEFICIO E INTERÉS COLECTIVO
B4: 2027
B6: Mes | C6: Tipo Día | D6: Días | E6: H1 | F6: H2 | G6: H3 | H6: H4 | I6: H5 | J6: H6 | K6: H7 | L6: H8 | M6: H9 | N6: H10 | O6: H11 | P6: H12 | Q6: H13 | R6: H14 | S6: H15 | T6: H16 | U6: H17 | V6: H18 | W6: H19 | X6: H20 | Y6: H21 | Z6: H22 | AA6: H23 | AB6: H24 | AC6: TOTAL MES
B7: Ene | C7: Ordinario | D7: 19 | E7: 27916.71 | F7: 26213.35 | G7: 25314.08 | H7: 25096.16 | I7: 12385.41 | J7: 14922.43 | K7: 16495.02 | L7: 25594.45 | M7: 25938.38 | N7: 26405.21 | O7: 27580.72 | P7: 28794.09 | Q7: 28559.87 | R7: 28425.01 | S7: 28782.73 | T7: 28811.15 | U7: 28753.12 | V7: 24602.82 | W7: 1321.31 | X7: 1380.56 | Y7: 1324.47 | Z7: 24067.93 | AA7: 20279.82 | AB7: 38081.71 | AC7: =+SUM(E7:AB7)*D7+SUM(E8:AB8)*D8+SUM(E9:AB9)*D9+SUM(E10:AB10)*D10 -> 16083668 | AE7: =+AC7 -> 16083668
B8: Ene | C8: Sábado | D8: 5 | E8: 13373.88 | F8: 12303.68 | G8: 12021.35 | H8: 11967.23 | I8: 12040.98 | J8: 12798.69 | K8: 14032.8 | L8: 24028.43 | M8: 25574.49 | N8: 26577.82 | O8: 27147.86 | P8: 27730.71 | Q8: 28454.42 | R8: 27947.68 | S8: 27954.01 | T8: 26391.52 | U8: 26984.74 | V8: 22966.18 | W8: 25228.12 | X8: 25993.9 | Y8: 24775.16 | Z8: 22962.24 | AA8: 20459.66 | AB8: 18437.34 | AE8: =+AC11 -> 16772713
B9: Ene | C9: Domingo | D9: 5 | E9: 13917.79 | F9: 12754.14 | G9: 11992.67 | H9: 11601.79 | I9: 11221.58 | J9: 11194.6 | K9: 11297.69 | L9: 19903.12 | M9: 21539.02 | N9: 22656.63 | O9: 23557.49 | P9: 24657.23 | Q9: 25290.3 | R9: 25532.36 | S9: 24904.71 | T9: 24844.57 | U9: 24990.87 | V9: 21352.81 | W9: 24146.98 | X9: 25371.01 | Y9: 24497.32 | Z9: 22202 | AA9: 18957.16 | AB9: 16485.36 | AE9: =+AC15 -> 15930449
B10: Ene | C10: Festivo | D10: 2 | E10: 13975.84 | F10: 13542.97 | G10: 12889.59 | H10: 12197.47 | I10: 11687.75 | J10: 11209.16 | K10: 10300.71 | L10: 17927.67 | M10: 19010.08 | N10: 20572.4 | O10: 21501.02 | P10: 22548.01 | Q10: 23928.94 | R10: 24738.14 | S10: 23873.26 | T10: 23964.61 | U10: 24297.16 | V10: 21176.59 | W10: 23526.28 | X10: 24197.88 | Y10: 23398.4 | Z10: 21440.04 | AA10: 18901.88 | AB10: 16531.21 | AE10: =+AC19 -> 15981097
B11: Feb | C11: Ordinario | D11: 20 | E11: 33265.88 | F11: 31548.6 | G11: 31007.89 | H11: 30763.75 | I11: 16266.69 | J11: 19913.99 | K11: 19944.01 | L11: 28368.95 | M11: 28494.13 | N11: 29029.52 | O11: 30176.3 | P11: 31330.55 | Q11: 30977.19 | R11: 31073.39 | S11: 31674.12 | T11: 31873.59 | U11: 31333.28 | V11: 25877.62 | W11: 1443.12 | X11: 1548.13 | Y11: 1501.98 | Z11: 27394.14 | AA11: 23928.33 | AB11: 42507.2 | AC11: =+SUM(E11:AB11)*D11+SUM(E12:AB12)*D12+SUM(E13:AB13)*D13+SUM(E14:AB14)*D14 -> 16772713 | AE11: =+AC23 -> 14566451
B12: Feb | C12: Sábado | D12: 4 | E12: 16814.21 | F12: 15704.55 | G12: 14956.66 | H12: 14829.48 | I12: 15161.36 | J12: 15937.12 | K12: 15669.55 | L12: 26437.78 | M12: 28097.82 | N12: 28836.42 | O12: 30156.69 | P12: 31123.69 | Q12: 31548.57 | R12: 30651.43 | S12: 30150.08 | T12: 29896.15 | U12: 29547.65 | V12: 24790.57 | W12: 27990.41 | X12: 30026.1 | Y12: 28794.6 | Z12: 26739.56 | AA12: 24154.73 | AB12: 21753.82 | AE12: =+AC27 -> 14674689
B13: Feb | C13: Domingo | D13: 4 | E13: 17702.67 | F13: 16325.48 | G13: 15569.38 | H13: 15102.69 | I13: 14583.29 | J13: 14560.76 | K13: 13472.01 | L13: 22325.42 | M13: 24210.91 | N13: 25907.05 | O13: 26822.64 | P13: 27647.51 | Q13: 28616.82 | R13: 28332.72 | S13: 27844.92 | T13: 27455.7 | U13: 26637.18 | V13: 23187.74 | W13: 26205.46 | X13: 28437.5 | Y13: 27931.43 | Z13: 25849.67 | AA13: 22835.64 | AB13: 19632.93 | AE13: =+AC31 -> 13313300
B14: Feb | C14: Festivo | D14: 0 | E14: 0 | F14: 0 | G14: 0 | H14: 0 | I14: 0 | J14: 0 | K14: 0 | L14: 0 | M14: 0 | N14: 0 | O14: 0 | P14: 0 | Q14: 0 | R14: 0 | S14: 0 | T14: 0 | U14: 0 | V14: 0 | W14: 0 | X14: 0 | Y14: 0 | Z14: 0 | AA14: 0 | AB14: 0 | AE14: =+AC35 -> 12973895
B15: Mar | C15: Ordinario | D15: 20 | E15: 29242.93 | F15: 27763.79 | G15: 27206.58 | H15: 26759.14 | I15: 14022.35 | J15: 16399.43 | K15: 15808.01 | L15: 24355.9 | M15: 24669.82 | N15: 25213 | O15: 26010.98 | P15: 26856 | Q15: 26758.18 | R15: 26966.34 | S15: 27616.19 | T15: 27654.17 | U15: 27233.46 | V15: 22649.06 | W15: 1250.04 | X15: 1351.52 | Y15: 1316.75 | Z15: 24241.96 | AA15: 21355.58 | AB15: 38670.61 | AC15: =+SUM(E15:AB15)*D15+SUM(E16:AB16)*D16+SUM(E17:AB17)*D17+SUM(E18:AB18)*D18 -> 15930449 | AE15: =+AC39 -> 14018103
B16: Mar | C16: Sábado | D16: 4 | E16: 15082.83 | F16: 13978.44 | G16: 13505.5 | H16: 13287.71 | I16: 13271.87 | J16: 13825.08 | K16: 12608.12 | L16: 22433.44 | M16: 23872.57 | N16: 24807.19 | O16: 25302.89 | P16: 25843.98 | Q16: 25961.4 | R16: 25868.04 | S16: 25676.61 | T16: 25484.81 | U16: 25013.8 | V16: 21184.8 | W16: 24177.92 | X16: 25378.15 | Y16: 24369.69 | Z16: 23152.88 | AA16: 21227.29 | AB16: 19508.1 | AE16: =+AC43 -> 13266334
B17: Mar | C17: Domingo | D17: 4 | E17: 15349.09 | F17: 14239.51 | G17: 13671.36 | H17: 13205.86 | I17: 12950.02 | J17: 12852.08 | K17: 11005.9 | L17: 19430.83 | M17: 21174.78 | N17: 22635.72 | O17: 22936.59 | P17: 23230.57 | Q17: 23667.76 | R17: 24229.86 | S17: 23920.39 | T17: 23945.96 | U17: 23485.64 | V17: 19534.23 | W17: 22249.67 | X17: 24754.16 | Y17: 24488.87 | Z17: 23066.27 | AA17: 20570.84 | AB17: 18244.3 | AE17: =+AC47 -> 13751175
B18: Mar | C18: Festivo | D18: 3 | E18: 14457.73 | F18: 13370.75 | G18: 12821 | H18: 12603.42 | I18: 12372.18 | J18: 12688.32 | K18: 11218.27 | L18: 20252.99 | M18: 21955.72 | N18: 22046.43 | O18: 21832.84 | P18: 22626.81 | Q18: 23516.61 | R18: 23600.25 | S18: 22843.3 | T18: 22686.66 | U18: 22434.18 | V18: 18706.32 | W18: 21865.66 | X18: 22908.25 | Y18: 22304.11 | Z18: 22198.14 | AA18: 20898.5 | AB18: 19244.86 | AE18: =+AC51 -> 12975104
B19: Abr | C19: Ordinario | D19: 22 | E19: 29715.26 | F19: 27972.53 | G19: 27331.7 | H19: 27203.56 | I19: 14204.54 | J19: 17774.02 | K19: 17861.39 | L19: 25611.54 | M19: 24753.54 | N19: 24982.42 | O19: 25840.46 | P19: 25546.59 | Q19: 25931.9 | R19: 26412.54 | S19: 27292.37 | T19: 27658.87 | U19: 27799.6 | V19: 23826.93 | W19: 1355.39 | X19: 1396.52 | Y19: 1349.84 | Z19: 24860.97 | AA19: 21399.04 | AB19: 38918.55 | AC19: =+SUM(E19:AB19)*D19+SUM(E20:AB20)*D20+SUM(E21:AB21)*D21+SUM(E22:AB22)*D22 -> 15981097 | AE19: =SUM(AE7:AE18) -> 1.7430698e+08
B20: Abr | C20: Sábado | D20: 4 | E20: 15265.86 | F20: 14461.24 | G20: 13541.6 | H20: 13492.49 | I20: 13890.1 | J20: 14710.61 | K20: 13704.26 | L20: 24897.94 | M20: 26766.18 | N20: 27340.96 | O20: 27642.78 | P20: 27782.02 | Q20: 28507.4 | R20: 27290.43 | S20: 27008.52 | T20: 27103.78 | U20: 27087.87 | V20: 20986.21 | W20: 26487.89 | X20: 27608.51 | Y20: 26460.15 | Z20: 24922.48 | AA20: 22381.83 | AB20: 21828.94
B21: Abr | C21: Domingo | D21: 4 | E21: 15969.34 | F21: 15023.08 | G21: 14374.66 | H21: 13888.49 | I21: 13421.84 | J21: 13319.29 | K21: 11938.02 | L21: 20502.45 | M21: 22041.03 | N21: 22962.91 | O21: 23787.54 | P21: 24640.76 | Q21: 26072.4 | R21: 26576.22 | S21: 25669.36 | T21: 25382.78 | U21: 24820.26 | V21: 21602.54 | W21: 24935.49 | X21: 25872.14 | Y21: 25477.88 | Z21: 23471.11 | AA21: 20772.15 | AB21: 18082.08
B22: Abr | C22: Festivo | D22: 0 | E22: 0 | F22: 0 | G22: 0 | H22: 0 | I22: 0 | J22: 0 | K22: 0 | L22: 0 | M22: 0 | N22: 0 | O22: 0 | P22: 0 | Q22: 0 | R22: 0 | S22: 0 | T22: 0 | U22: 0 | V22: 0 | W22: 0 | X22: 0 | Y22: 0 | Z22: 0 | AA22: 0 | AB22: 0
B23: May | C23: Ordinario | D23: 19 | E23: 28459.24 | F23: 27200.85 | G23: 26572.82 | H23: 26459.57 | I23: 13702.93 | J23: 16838.3 | K23: 15731.6 | L23: 22599.65 | M23: 20240.35 | N23: 19586.67 | O23: 20153.8 | P23: 21068.56 | Q23: 20642.77 | R23: 20972.67 | S23: 22005.62 | T23: 23089.35 | U23: 24973.74 | V23: 22035.57 | W23: 1321.66 | X23: 1356.32 | Y23: 1301.71 | Z23: 24121.03 | AA23: 21102.82 | AB23: 38156.85 | AC23: =+SUM(E23:AB23)*D23+SUM(E24:AB24)*D24+SUM(E25:AB25)*D25+SUM(E26:AB26)*D26 -> 14566451
B24: May | C24: Sábado | D24: 4 | E24: 14822.72 | F24: 13966.94 | G24: 13517.02 | H24: 13233.35 | I24: 13563.38 | J24: 14023.6 | K24: 12749.42 | L24: 21668.99 | M24: 20982.89 | N24: 20998.6 | O24: 21037.44 | P24: 21627.07 | Q24: 21602.94 | R24: 21099.93 | S24: 21308.98 | T24: 22017.4 | U24: 24047.04 | V24: 21306.77 | W24: 25799.91 | X24: 26613.72 | Y24: 25496.65 | Z24: 23976.13 | AA24: 21715.9 | AB24: 19110.8
B25: May | C25: Domingo | D25: 5 | E25: 15102.48 | F25: 14136.57 | G25: 13554.93 | H25: 13038 | I25: 12915.12 | J25: 12500.83 | K25: 10148.46 | L25: 17591.74 | M25: 17244.85 | N25: 17814.35 | O25: 18327.46 | P25: 19189.49 | Q25: 19290.98 | R25: 18963.84 | S25: 18682.48 | T25: 19512.8 | U25: 21716.04 | V25: 19287.76 | W25: 23960.74 | X25: 25179.8 | Y25: 24785.03 | Z25: 23233.83 | AA25: 20871.15 | AB25: 18105.14
B26: May | C26: Festivo | D26: 3 | E26: 14268.25 | F26: 13381.75 | G26: 13058.88 | H26: 12700.09 | I26: 12840.31 | J26: 12835.33 | K26: 10635.99 | L26: 18190.97 | M26: 17775.59 | N26: 18161.15 | O26: 19225.62 | P26: 20760.8 | Q26: 21572.57 | R26: 21316.13 | S26: 21092.58 | T26: 21687.48 | U26: 23458.16 | V26: 21112.96 | W26: 26015.86 | X26: 27210.13 | Y26: 26038.7 | Z26: 24170.88 | AA26: 21351.02 | AB26: 18250.94
B27: Jun | C27: Ordinario | D27: 21 | E27: 29252.04 | F27: 27630.51 | G27: 27106.63 | H27: 27007.5 | I27: 13767.24 | J27: 15901.29 | K27: 15114.58 | L27: 23050.58 | M27: 21388.15 | N27: 21103.46 | O27: 21649.11 | P27: 22949.64 | Q27: 22495.94 | R27: 22469.84 | S27: 23472.88 | T27: 24167.4 | U27: 26017.75 | V27: 22677.22 | W27: 1359.32 | X27: 1401.12 | Y27: 1338.49 | Z27: 24820.06 | AA27: 21635.7 | AB27: 39143.49 | AC27: =+SUM(E27:AB27)*D27+SUM(E28:AB28)*D28+SUM(E29:AB29)*D29+SUM(E30:AB30)*D30 -> 14674689
B28: Jun | C28: Sábado | D28: 4 | E28: 15397.19 | F28: 14345.16 | G28: 14033.25 | H28: 13688.7 | I28: 14088.44 | J28: 14582.39 | K28: 13383.44 | L28: 22591.34 | M28: 21817.23 | N28: 21810.7 | O28: 21821.85 | P28: 22700.69 | Q28: 22682.78 | R28: 22319.56 | S28: 22740.02 | T28: 23451.07 | U28: 25285.34 | V28: 22220.98 | W28: 26767.22 | X28: 27987.2 | Y28: 26796.14 | Z28: 24937.4 | AA28: 22587.08 | AB28: 19980.43
B29: Jun | C29: Domingo | D29: 4 | E29: 15647.31 | F29: 14970.55 | G29: 14159.52 | H29: 13858.62 | I29: 13696.78 | J29: 13282.09 | K29: 10509.98 | L29: 18318.02 | M29: 17960 | N29: 18064.96 | O29: 18305.61 | P29: 19309.53 | Q29: 20008.53 | R29: 19826.07 | S29: 20087.51 | T29: 20772.02 | U29: 22469.32 | V29: 19967.28 | W29: 24348.82 | X29: 25462.77 | Y29: 24737.23 | Z29: 23212.26 | AA29: 21045.91 | AB29: 18561.15
B30: Jun | C30: Festivo | D30: 1 | E30: 15301.19 | F30: 14438.48 | G30: 13810.72 | H30: 13437.35 | I30: 13656.67 | J30: 13449.77 | K30: 10855.47 | L30: 17929.94 | M30: 17696.02 | N30: 17218.79 | O30: 18486.3 | P30: 20025.26 | Q30: 20544.55 | R30: 19526.15 | S30: 20006.3 | T30: 20577.05 | U30: 21958.85 | V30: 21235.53 | W30: 26664.98 | X30: 27470.85 | Y30: 26157.25 | Z30: 23785.46 | AA30: 20747.21 | AB30: 18000.08
B31: Jul | C31: Ordinario | D31: 20 | E31: 26685.46 | F31: 24845.04 | G31: 24191.67 | H31: 23834.16 | I31: 11625.64 | J31: 14399.14 | K31: 12822.7 | L31: 19508.13 | M31: 17469.13 | N31: 17162.19 | O31: 17820.86 | P31: 19405.9 | Q31: 18621.94 | R31: 18761.03 | S31: 20115.04 | T31: 20871.09 | U31: 22450.28 | V31: 21762.51 | W31: 1311.43 | X31: 1382.79 | Y31: 1322.76 | Z31: 24343.08 | AA31: 21168.46 | AB31: 39738.22 | AC31: =+SUM(E31:AB31)*D31+SUM(E32:AB32)*D32+SUM(E33:AB33)*D33+SUM(E34:AB34)*D34 -> 13313300
B32: Jul | C32: Sábado | D32: 5 | E32: 11349.26 | F32: 10735.2 | G32: 10165.38 | H32: 10235.58 | I32: 10449.26 | J32: 11000.87 | K32: 9879.5 | L32: 18146.66 | M32: 17611.42 | N32: 17824.19 | O32: 17807.63 | P32: 18760.59 | Q32: 18471.16 | R32: 18265.51 | S32: 18377.25 | T32: 19064.69 | U32: 21138.74 | V32: 20878.08 | W32: 25217.46 | X32: 26810.36 | Y32: 25615.17 | Z32: 24043.71 | AA32: 21481.48 | AB32: 18737.34
B33: Jul | C33: Domingo | D33: 4 | E33: 12675.55 | F33: 11936.94 | G33: 10980.33 | H33: 10704.59 | I33: 10554.04 | J33: 10187.96 | K33: 7486.1 | L33: 14420.02 | M33: 13893.99 | N33: 14491.76 | O33: 15111.96 | P33: 16646.7 | Q33: 17080.92 | R33: 17088.93 | S33: 17181.96 | T33: 17872.59 | U33: 19828.2 | V33: 19916.2 | W33: 24329.36 | X33: 25850.14 | Y33: 24623.33 | Z33: 22938.06 | AA33: 21097.38 | AB33: 18546
B34: Jul | C34: Festivo | D34: 2 | E34: 12175.01 | F34: 11316.7 | G34: 10669.49 | H34: 10799.56 | I34: 10366.64 | J34: 10480.63 | K34: 8141.21 | L34: 15235.86 | M34: 14811.42 | N34: 14512.15 | O34: 15636.97 | P34: 16677.66 | Q34: 17010.58 | R34: 16985.4 | S34: 17447.56 | T34: 18239.45 | U34: 19557.48 | V34: 19367.38 | W34: 23803.66 | X34: 25390.05 | Y34: 24506.06 | Z34: 22534.67 | AA34: 20545.96 | AB34: 18199.71
B35: Ago | C35: Ordinario | D35: 21 | E35: 25642.43 | F35: 24333.8 | G35: 23574.43 | H35: 23462.16 | I35: 11698.08 | J35: 14985.23 | K35: 13446.56 | L35: 19657.71 | M35: 17525.21 | N35: 16908.86 | O35: 17493.77 | P35: 18504.55 | Q35: 17702.98 | R35: 18218.82 | S35: 19470.99 | T35: 20263.93 | U35: 22116.31 | V35: 20558.97 | W35: 1274.78 | X35: 1333.05 | Y35: 1280.13 | Z35: 23608.82 | AA35: 20006.6 | AB35: 38453.76 | AC35: =+SUM(E35:AB35)*D35+SUM(E36:AB36)*D36+SUM(E37:AB37)*D37+SUM(E38:AB38)*D38 -> 12973895
B36: Ago | C36: Sábado | D36: 3 | E36: 12939.74 | F36: 12013.28 | G36: 11584.56 | H36: 11419.52 | I36: 11738.71 | J36: 12299.3 | K36: 10448.4 | L36: 18731.57 | M36: 17885.02 | N36: 18066.81 | O36: 18186.9 | P36: 19183.34 | Q36: 18347.99 | R36: 18088.89 | S36: 18106.92 | T36: 18746.72 | U36: 21092.14 | V36: 19980.86 | W36: 25100.56 | X36: 25853.78 | Y36: 24522.64 | Z36: 22933.26 | AA36: 19853.27 | AB36: 17981.24
B37: Ago | C37: Domingo | D37: 5 | E37: 12022.48 | F37: 11432.61 | G37: 10953.69 | H37: 10595.06 | I37: 10322.83 | J37: 10354.86 | K37: 6821.94 | L37: 13474.9 | M37: 13112.3 | N37: 13186.49 | O37: 13875.94 | P37: 14985.52 | Q37: 15139.06 | R37: 15763.99 | S37: 15878.58 | T37: 16492.62 | U37: 18694.65 | V37: 17967.68 | W37: 22797.87 | X37: 24018.42 | Y37: 23526.3 | Z37: 22035.17 | AA37: 18521.87 | AB37: 16602.21
B38: Ago | C38: Festivo | D38: 2 | E38: 11417.77 | F38: 10963.15 | G38: 10328.01 | H38: 10292.12 | I38: 10393.56 | J38: 10551.12 | K38: 7956.4 | L38: 15206.96 | M38: 14390.32 | N38: 15206.77 | O38: 16239.46 | P38: 18119.83 | Q38: 17799.96 | R38: 17778.34 | S38: 17850.61 | T38: 18357.88 | U38: 19923.15 | V38: 19840.91 | W38: 24291.32 | X38: 25984.37 | Y38: 24885.02 | Z38: 22747.89 | AA38: 19389.86 | AB38: 16951.63
B39: Sep | C39: Ordinario | D39: 22 | E39: 28581.48 | F39: 27213.73 | G39: 26704.59 | H39: 26379.72 | I39: 13246.73 | J39: 16378.41 | K39: 15049.85 | L39: 21634.66 | M39: 19300.85 | N39: 18927.75 | O39: 19237.7 | P39: 20329.96 | Q39: 19948.1 | R39: 20486.93 | S39: 21859.06 | T39: 22991.2 | U39: 24749.47 | V39: 23033.62 | W39: 1415.25 | X39: 1433 | Y39: 1374.47 | Z39: 25059.37 | AA39: 21631.23 | AB39: 40743.63 | AC39: =+SUM(E39:AB39)*D39+SUM(E40:AB40)*D40+SUM(E41:AB41)*D41+SUM(E42:AB42)*D42 -> 14018103
B40: Sep | C40: Sábado | D40: 4 | E40: 14654.14 | F40: 13383.57 | G40: 12959.54 | H40: 12684.13 | I40: 13105.69 | J40: 13716.21 | K40: 12300.84 | L40: 20263.77 | M40: 19859.53 | N40: 19829.64 | O40: 19736.55 | P40: 20229.26 | Q40: 20027.94 | R40: 19767.05 | S40: 20042.1 | T40: 20975.5 | U40: 23471.94 | V40: 21931.89 | W40: 26853.37 | X40: 26717.13 | Y40: 25876.52 | Z40: 23530.76 | AA40: 21178.92 | AB40: 19157.25
B41: Sep | C41: Domingo | D41: 4 | E41: 14167.5 | F41: 13357.36 | G41: 12850.85 | H41: 12403.75 | I41: 12118.74 | J41: 11589.86 | K41: 8904.2 | L41: 15757.13 | M41: 15605.26 | N41: 15603.16 | O41: 15890.28 | P41: 16519.03 | Q41: 16967.14 | R41: 17025.16 | S41: 17732.56 | T41: 18852.02 | U41: 20898.2 | V41: 20453.57 | W41: 25813.19 | X41: 26074.41 | Y41: 25508.69 | Z41: 22906.07 | AA41: 20099.32 | AB41: 17765.92
B42: Sep | C42: Festivo | D42: 0 | E42: 0 | F42: 0 | G42: 0 | H42: 0 | I42: 0 | J42: 0 | K42: 0 | L42: 0 | M42: 0 | N42: 0 | O42: 0 | P42: 0 | Q42: 0 | R42: 0 | S42: 0 | T42: 0 | U42: 0 | V42: 0 | W42: 0 | X42: 0 | Y42: 0 | Z42: 0 | AA42: 0 | AB42: 0
...

Sheet Cantidad Producto 2
B2: CANTIDADES DE ENERGÍA SOLICITADAS (kWh)
B3: CENTRAL HIDROELECTRICA DE CALDAS S.A. E.S.P. -BENEFICIO E INTERÉS COLECTIVO
B4: 2028
B6: Mes | C6: Tipo Día | D6: Días | E6: H1 | F6: H2 | G6: H3 | H6: H4 | I6: H5 | J6: H6 | K6: H7 | L6: H8 | M6: H9 | N6: H10 | O6: H11 | P6: H12 | Q6: H13 | R6: H14 | S6: H15 | T6: H16 | U6: H17 | V6: H18 | W6: H19 | X6: H20 | Y6: H21 | Z6: H22 | AA6: H23 | AB6: H24 | AC6: TOTAL MES
B7: Ene | C7: Ordinario | D7: 20 | E7: 4795.18 | F7: 4422.26 | G7: 4182.23 | H7: 4208.02 | I7: 4732.92 | J7: 6399.93 | K7: 7172.62 | L7: 11449.46 | M7: 9497.35 | N7: 8741.52 | O7: 9007.82 | P7: 9582.79 | Q7: 9113.16 | R7: 9288.2 | S7: 9942.2 | T7: 10745.36 | U7: 13346.71 | V7: 8237.12 | W7: 9417.92 | X7: 9518.55 | Y7: 8961.73 | Z7: 7735.16 | AA7: 5927.34 | AB7: 4813.55 | AC7: =+SUM(E7:AB7)*D7+SUM(E8:AB8)*D8+SUM(E9:AB9)*D9+SUM(E10:AB10)*D10 -> 5640298 | AE7: =+AC7 -> 5640298
B8: Ene | C8: Sábado | D8: 4 | E8: 5341.02 | F8: 4673.09 | G8: 4596.31 | H8: 4607.49 | I8: 4669.12 | J8: 5259.9 | K8: 5853.06 | L8: 10786.6 | M8: 9390.93 | N8: 9153.28 | O8: 9064.7 | P8: 9304.8 | Q8: 9790.96 | R8: 9710.95 | S8: 10304.26 | T8: 9684.3 | U8: 12792.01 | V8: 7535.84 | W8: 8893.94 | X8: 8613.52 | Y8: 8121.44 | Z8: 7412.84 | AA8: 6280.62 | AB8: 5418 | AE8: =+AC11 -> 5481906.5
B9: Ene | C9: Domingo | D9: 5 | E9: 5415.14 | F9: 4822.02 | G9: 4229.3 | H9: 3974.61 | I9: 3763.91 | J9: 3912.26 | K9: 3706.78 | L9: 8036.66 | M9: 6751.02 | N9: 6433.25 | O9: 6527.87 | P9: 7351.59 | Q9: 7417.07 | R9: 7863.24 | S9: 7963.08 | T9: 8875.04 | U9: 11628.66 | V9: 6565.36 | W9: 8600.29 | X9: 8506.7 | Y9: 7933.08 | Z9: 6518.19 | AA9: 5178.44 | AB9: 3970.85 | AE9: =+AC15 -> 5737244.8
B10: Ene | C10: Festivo | D10: 2 | E10: 5017.75 | F10: 4911.88 | G10: 4535.56 | H10: 4306.02 | I10: 4019.58 | J10: 3738.56 | K10: 2852.81 | L10: 6719.24 | M10: 5094.08 | N10: 5085.52 | O10: 5096.11 | P10: 5703.4 | Q10: 6528.94 | R10: 7585.87 | S10: 7311.71 | T10: 8435.45 | U10: 11351.04 | V10: 7044.55 | W10: 7942.62 | X10: 7637.06 | Y10: 7092.93 | Z10: 6010.56 | AA10: 5176.24 | AB10: 4181.54 | AE10: =+AC19 -> 5761066.8
B11: Feb | C11: Ordinario | D11: 21 | E11: 6287.98 | F11: 5906.83 | G11: 5773.14 | H11: 5719.78 | I11: 6183.41 | J11: 7836.22 | K11: 6903.5 | L11: 10726.16 | M11: 8715.9 | N11: 8114.23 | O11: 8120.13 | P11: 8653.77 | Q11: 8509.5 | R11: 8712.17 | S11: 9489.22 | T11: 10427.68 | U11: 12502.94 | V11: 6582.31 | W11: 8581.79 | X11: 9203.22 | Y11: 8961.7 | Z11: 8176.5 | AA11: 7164.28 | AB11: 6200.37 | AC11: =+SUM(E11:AB11)*D11+SUM(E12:AB12)*D12+SUM(E13:AB13)*D13+SUM(E14:AB14)*D14 -> 5481906.5 | AE11: =+AC23 -> 5621176.9
B12: Feb | C12: Sábado | D12: 4 | E12: 6546.1 | F12: 6071.22 | G12: 5751.07 | H12: 5684.92 | I12: 5845.48 | J12: 6247.98 | K12: 5176.7 | L12: 9997.43 | M12: 8632.38 | N12: 8133.06 | O12: 8162.73 | P12: 8598.86 | Q12: 8778.42 | R12: 8577 | S12: 8847.88 | T12: 9606.57 | U12: 11742.16 | V12: 6240.9 | W12: 8326.82 | X12: 8936.37 | Y12: 8584.49 | Z12: 7948.11 | AA12: 7167.26 | AB12: 6379.1 | AE12: =+AC27 -> 5640392.8
B13: Feb | C13: Domingo | D13: 4 | E13: 6872.18 | F13: 6286.87 | G13: 5968.54 | H13: 5768.71 | I13: 5584.37 | J13: 5608.47 | K13: 4118.5 | L13: 8220.15 | M13: 6995.16 | N13: 6829.66 | O13: 6731.94 | P13: 7169.58 | Q13: 7571.94 | R13: 7631.67 | S13: 7932.18 | T13: 8603.46 | U13: 10573.17 | V13: 5753.66 | W13: 7762.15 | X13: 8422.91 | Y13: 8292.75 | Z13: 7669.54 | AA13: 6777.04 | AB13: 5722.18 | AE13: =+AC31 -> 5897064.8
B14: Feb | C14: Festivo | D14: 0 | E14: 0 | F14: 0 | G14: 0 | H14: 0 | I14: 0 | J14: 0 | K14: 0 | L14: 0 | M14: 0 | N14: 0 | O14: 0 | P14: 0 | Q14: 0 | R14: 0 | S14: 0 | T14: 0 | U14: 0 | V14: 0 | W14: 0 | X14: 0 | Y14: 0 | Z14: 0 | AA14: 0 | AB14: 0 | AE14: =+AC35 -> 5698999.5
B15: Mar | C15: Ordinario | D15: 22 | E15: 7399.95 | F15: 6953.96 | G15: 6782.7 | H15: 6599.1 | I15: 6739.66 | J15: 7514.3 | K15: 5478.54 | L15: 9617.58 | M15: 7851.04 | N15: 7309.16 | O15: 7196.55 | P15: 7691.3 | Q15: 7856.23 | R15: 8233.17 | S15: 9086.34 | T15: 9911.01 | U15: 11969.58 | V15: 6224.48 | W15: 8240.5 | X15: 9317.78 | Y15: 9377.28 | Z15: 8812.79 | AA15: 7977.79 | AB15: 7488.56 | AC15: =+SUM(E15:AB15)*D15+SUM(E16:AB16)*D16+SUM(E17:AB17)*D17+SUM(E18:AB18)*D18 -> 5737244.8 | AE15: =+AC39 -> 5553537.9
B16: Mar | C16: Sábado | D16: 4 | E16: 7450.24 | F16: 6814.19 | G16: 6524.31 | H16: 6398.73 | I16: 6288.24 | J16: 6498.67 | K16: 4055.3 | L16: 8666.28 | M16: 7290.88 | N16: 6941.48 | O16: 6684.78 | P16: 6935.6 | Q16: 7074.81 | R16: 7441.66 | S16: 7964.43 | T16: 8757.84 | U16: 10814.52 | V16: 5551.24 | W16: 8003.98 | X16: 8350.76 | Y16: 8122.38 | Z16: 7983.01 | AA16: 7650.76 | AB16: 7166.58 | AE16: =+AC43 -> 5705697
B17: Mar | C17: Domingo | D17: 4 | E17: 7573.88 | F17: 6961.96 | G17: 6641.42 | H17: 6394.56 | I17: 6252.75 | J17: 6265.79 | K17: 3773.24 | L17: 7753.8 | M17: 6395.06 | N17: 6223.66 | O17: 5753.64 | P17: 5812.08 | Q17: 5981.03 | R17: 6657.88 | S17: 7114.09 | T17: 8090.63 | U17: 10184.45 | V17: 5027.89 | W17: 7173.45 | X17: 8389.68 | Y17: 8570.21 | Z17: 8267.44 | AA17: 7622.16 | AB17: 6755.64 | AE17: =+AC47 -> 5600704.9
B18: Mar | C18: Festivo | D18: 1 | E18: 7112.83 | F18: 6491.99 | G18: 6142.52 | H18: 6049.75 | I18: 5854.12 | J18: 6118.94 | K18: 3866.19 | L18: 8267.37 | M18: 7021.74 | N18: 5841.44 | O18: 4818.48 | P18: 5159.64 | Q18: 5687.1 | R18: 6120.08 | S18: 6314.65 | T18: 7137.09 | U18: 9421.71 | V18: 4667.16 | W18: 7247.85 | X18: 6974.78 | Y18: 7086.88 | Z18: 8214.56 | AA18: 7948.97 | AB18: 7565.02 | AE18: =+AC51 -> 5690344.3
B19: Abr | C19: Ordinario | D19: 18 | E19: 7163.23 | F19: 6660.7 | G19: 6465.7 | H19: 6401.78 | I19: 6871.59 | J19: 8531.04 | K19: 6904.66 | L19: 10488.37 | M19: 7862.3 | N19: 7080.85 | O19: 7013.69 | P19: 6650.58 | Q19: 7141.65 | R19: 7700.05 | S19: 8750.12 | T19: 9802.49 | U19: 12324.13 | V19: 6826.35 | W19: 9362.64 | X19: 9546.49 | Y19: 9407.38 | Z19: 8762.84 | AA19: 7632.75 | AB19: 6835.74 | AC19: =+SUM(E19:AB19)*D19+SUM(E20:AB20)*D20+SUM(E21:AB21)*D21+SUM(E22:AB22)*D22 -> 5761066.8
B20: Abr | C20: Sábado | D20: 5 | E20: 7595.77 | F20: 7166.67 | G20: 6569.58 | H20: 6578.65 | I20: 6784.82 | J20: 7189.17 | K20: 5210.48 | L20: 10542.07 | M20: 9392.48 | N20: 8666.91 | O20: 8228.41 | P20: 8165.86 | Q20: 8557.85 | R20: 8298.64 | S20: 8787.66 | T20: 9784.48 | U20: 12278.94 | V20: 6158.3 | W20: 9625.1 | X20: 10119.22 | Y20: 9776.95 | Z20: 9323.73 | AA20: 8466.08 | AB20: 8002.46
B21: Abr | C21: Domingo | D21: 5 | E21: 7984.04 | F21: 7518.01 | G21: 7179.97 | H21: 6939.12 | I21: 6657.5 | J21: 6650.56 | K21: 4409.28 | L21: 8436.73 | M21: 6859.38 | N21: 6270.26 | O21: 6202.22 | P21: 6776.73 | Q21: 7757.52 | R21: 8351.06 | S21: 8397.29 | T21: 9184.92 | U21: 11166.41 | V21: 6186.42 | W21: 8877.5 | X21: 9037.37 | Y21: 9102.44 | Z21: 8471.54 | AA21: 7676.97 | AB21: 6625.73
B22: Abr | C22: Festivo | D22: 2 | E22: 8403.69 | F22: 7927.65 | G22: 7538.19 | H22: 7083.76 | I22: 6791.25 | J22: 6629.09 | K22: 4295.3 | L22: 8332.85 | M22: 6955.93 | N22: 6756.46 | O22: 7206.53 | P22: 7459.39 | Q22: 7931.7 | R22: 8608.23 | S22: 8813.16 | T22: 9610.11 | U22: 11710.02 | V22: 6738.65 | W22: 9639.84 | X22: 10153.5 | Y22: 10405.39 | Z22: 9055.13 | AA22: 7169.16 | AB22: 5661.24
B23: May | C23: Ordinario | D23: 21 | E23: 6631.98 | F23: 6309.35 | G23: 6127.96 | H23: 6058.05 | I23: 6352.79 | J23: 7591.55 | K23: 5977.84 | L23: 9901.09 | M23: 7719.29 | N23: 6946.51 | O23: 7009.08 | P23: 7463.71 | Q23: 7349 | R23: 7721.46 | S23: 8492.9 | T23: 9493.79 | U23: 11690.09 | V23: 6054.2 | W23: 8671.32 | X23: 8794 | Y23: 8528.38 | Z23: 8106.91 | AA23: 7347.66 | AB23: 6537.29 | AC23: =+SUM(E23:AB23)*D23+SUM(E24:AB24)*D24+SUM(E25:AB25)*D25+SUM(E26:AB26)*D26 -> 5621176.9
B24: May | C24: Sábado | D24: 4 | E24: 7132.57 | F24: 6646.84 | G24: 6429.93 | H24: 6243.66 | I24: 6388.59 | J24: 6534.56 | K24: 4882.32 | L24: 9654.93 | M24: 8255.07 | N24: 7847.67 | O24: 7558.91 | P24: 7880.65 | Q24: 7893.66 | R24: 7784.98 | S24: 8254.64 | T24: 9081.75 | U24: 11395.61 | V24: 6005.98 | W24: 8803.92 | X24: 8903.96 | Y24: 8572.62 | Z24: 8185.68 | AA24: 7574.66 | AB24: 6529.26
B25: May | C25: Domingo | D25: 4 | E25: 7186.8 | F25: 6676.95 | G25: 6400.76 | H25: 6121.73 | I25: 6094.72 | J25: 5948.13 | K25: 3843.66 | L25: 7949.91 | M25: 6610.89 | N25: 6446.5 | O25: 6484.47 | P25: 7014.6 | Q25: 7082.66 | R25: 6984.04 | S25: 7036.75 | T25: 7968.7 | U25: 10405.73 | V25: 5349.14 | W25: 8154.4 | X25: 8469.24 | Y25: 8399.4 | Z25: 8036.6 | AA25: 7489.68 | AB25: 6377.22
B26: May | C26: Festivo | D26: 2 | E26: 6944.36 | F26: 6463.17 | G26: 6310.72 | H26: 6102.82 | I26: 6182.62 | J26: 6265.65 | K26: 4309.17 | L26: 8480.43 | M26: 7196.83 | N26: 6836.54 | O26: 7152.34 | P26: 8002.03 | Q26: 8472.79 | R26: 8471.24 | S26: 8614.08 | T26: 9385.36 | U26: 11487.15 | V26: 6557.78 | W26: 9444.52 | X26: 9544.64 | Y26: 8998.14 | Z26: 8592.92 | AA26: 7954.46 | AB26: 6668.38
B27: Jun | C27: Ordinario | D27: 20 | E27: 6502.73 | F27: 6071.39 | G27: 5951.62 | H27: 5893.62 | I27: 6209.8 | J27: 7057.56 | K27: 5664.42 | L27: 10044.14 | M27: 8314.01 | N27: 7762.94 | O27: 7768.81 | P27: 8444.32 | Q27: 8307.96 | R27: 8404.68 | S27: 9171.03 | T27: 9886.56 | U27: 12084.39 | V27: 6481.22 | W27: 9276.85 | X27: 9338.94 | Y27: 8976.51 | Z27: 8500.37 | AA27: 7587.98 | AB27: 6585.89 | AC27: =+SUM(E27:AB27)*D27+SUM(E28:AB28)*D28+SUM(E29:AB29)*D29+SUM(E30:AB30)*D30 -> 5640392.8
B28: Jun | C28: Sábado | D28: 4 | E28: 7329.24 | F28: 6724.56 | G28: 6618.1 | H28: 6411.22 | I28: 6588.25 | J28: 6826.03 | K28: 5209.67 | L28: 10184.53 | M28: 8682.09 | N28: 8283.32 | O28: 7982.17 | P28: 8466.62 | Q28: 8465.71 | R28: 8404.5 | S28: 8993.72 | T28: 9810.15 | U28: 12032.26 | V28: 6634.9 | W28: 9408.05 | X28: 9888.71 | Y28: 9562.78 | Z28: 9009.56 | AA28: 8270.69 | AB28: 7238.72
B29: Jun | C29: Domingo | D29: 4 | E29: 7373.77 | F29: 7076.45 | G29: 6639.1 | H29: 6529.67 | I29: 6473.66 | J29: 6342.87 | K29: 3893.52 | L29: 8253.53 | M29: 6892.04 | N29: 6391.99 | O29: 6279.79 | P29: 6863.8 | Q29: 7258.08 | R29: 7283.11 | S29: 7841.68 | T29: 8663.23 | U29: 10724.55 | V29: 5948.52 | W29: 8596.48 | X29: 8686.92 | Y29: 8423.01 | Z29: 8083.65 | AA29: 7579.78 | AB29: 6640.41
B30: Jun | C30: Festivo | D30: 2 | E30: 7246.3 | F30: 6813.46 | G30: 6446.04 | H30: 6265.76 | I30: 6427.36 | J30: 6392.67 | K30: 4161.14 | L30: 7954.41 | M30: 6829.18 | N30: 5780.53 | O30: 6242.32 | P30: 7052.9 | Q30: 7305.36 | R30: 6734.94 | S30: 7464.58 | T30: 8282.16 | U30: 10079.32 | V30: 6383.27 | W30: 9800.96 | X30: 9538.33 | Y30: 9016.15 | Z30: 8172.86 | AA30: 7193.01 | AB30: 6205.66
B31: Jul | C31: Ordinario | D31: 19 | E31: 6959.7 | F31: 6489.5 | G31: 6318.74 | H31: 6202.4 | I31: 6579.17 | J31: 7763.92 | K31: 5919.02 | L31: 10151.43 | M31: 8194.68 | N31: 7664.69 | O31: 7775.84 | P31: 8715.99 | Q31: 8321.71 | R31: 8514.37 | S31: 9487.35 | T31: 10215.75 | U31: 12196.44 | V31: 6620.02 | W31: 9522.35 | X31: 9847.35 | Y31: 9476.95 | Z31: 8830 | AA31: 7971.39 | AB31: 6687.26 | AC31: =+SUM(E31:AB31)*D31+SUM(E32:AB32)*D32+SUM(E33:AB33)*D33+SUM(E34:AB34)*D34 -> 5897064.8
B32: Jul | C32: Sábado | D32: 5 | E32: 6318.7 | F32: 6041.92 | G32: 5703.49 | H32: 5773.86 | I32: 5877.26 | J32: 6132.77 | K32: 4691.22 | L32: 9593.75 | M32: 8276.57 | N32: 8023.38 | O32: 7718.96 | P32: 8318.84 | Q32: 8087.42 | R32: 8176.96 | S32: 8511.7 | T32: 9341.88 | U32: 11713.91 | V32: 6404.37 | W32: 9130.62 | X32: 9710.38 | Y32: 9305.82 | Z32: 8867.2 | AA32: 8014.57 | AB32: 6836.34
B33: Jul | C33: Domingo | D33: 5 | E33: 7047.34 | F33: 6696.62 | G33: 6166.21 | H33: 6041.95 | I33: 5994.43 | J33: 5802.68 | K33: 3545.77 | L33: 7938.7 | M33: 6479.58 | N33: 6362.26 | O33: 6504.15 | P33: 7498.64 | Q33: 7703.38 | R33: 7821.21 | S33: 8195.44 | T33: 9000.58 | U33: 11284.97 | V33: 6386.65 | W33: 9070.92 | X33: 9380.67 | Y33: 8702.11 | Z33: 8229.88 | AA33: 8111.58 | AB33: 7113.36
B34: Jul | C34: Festivo | D34: 2 | E34: 6906.44 | F34: 6474.27 | G34: 6068.53 | H34: 6198.96 | I34: 5891.82 | J34: 5976.11 | K34: 3904 | L34: 8223.4 | M34: 7027.77 | N34: 6199.2 | O34: 6665.78 | P34: 7207.66 | Q34: 7276.11 | R34: 7436.5 | S34: 8080.48 | T34: 8989.89 | U34: 10864.18 | V34: 5700.86 | W34: 8399.23 | X34: 8859.06 | Y34: 8569.36 | Z34: 7895.22 | AA34: 7682.72 | AB34: 6860.24
B35: Ago | C35: Ordinario | D35: 21 | E35: 6562.45 | F35: 6259.91 | G35: 6009.94 | H35: 5951.65 | I35: 6436.86 | J35: 8013.11 | K35: 6249.6 | L35: 10167.57 | M35: 8170.46 | N35: 7447.4 | O35: 7539.65 | P35: 8093.81 | Q35: 7652 | R35: 8089.49 | S35: 8943.25 | T35: 9703.64 | U35: 11907.57 | V35: 5849.77 | W35: 9094.68 | X35: 9338.46 | Y35: 8997.56 | Z35: 8344.01 | AA35: 7142.56 | AB35: 6299.11 | AC35: =+SUM(E35:AB35)*D35+SUM(E36:AB36)*D36+SUM(E37:AB37)*D37+SUM(E38:AB38)*D38 -> 5698999.5
B36: Ago | C36: Sábado | D36: 4 | E36: 7336.51 | F36: 6796.46 | G36: 6566.87 | H36: 6486.99 | I36: 6648.96 | J36: 6822.85 | K36: 4840.7 | L36: 9841 | M36: 8400.88 | N36: 8212.58 | O36: 7963.33 | P36: 8597.5 | Q36: 7990.53 | R36: 8044.21 | S36: 8277.88 | T36: 9071.84 | U36: 11640.6 | V36: 5936.9 | W36: 9273.39 | X36: 9228.28 | Y36: 8673.92 | Z36: 8225.72 | AA36: 6954.53 | AB36: 6431.26
B37: Ago | C37: Domingo | D37: 4 | E37: 6437.27 | F37: 6164.75 | G37: 5952.25 | H37: 5815.96 | I37: 5655.54 | J37: 5693.7 | K37: 2741.96 | L37: 6960.01 | M37: 5684.48 | N37: 5316.21 | O37: 5578.05 | P37: 6319.36 | Q37: 6317 | R37: 6796.57 | S37: 7144.11 | T37: 7948.77 | U37: 10395.25 | V37: 5025.76 | W37: 8154.86 | X37: 8485.42 | Y37: 8447.61 | Z37: 8106.68 | AA37: 6664.2 | AB37: 6053.79
B38: Ago | C38: Festivo | D38: 2 | E38: 6358.4 | F38: 6129.9 | G38: 5743.48 | H38: 5783.08 | I38: 5854.85 | J38: 5969.75 | K38: 3878.25 | L38: 8486.95 | M38: 7054.32 | N38: 7124.32 | O38: 7394.52 | P38: 8519.06 | Q38: 8056.3 | R38: 8244.41 | S38: 8631.3 | T38: 9309.63 | U38: 11173 | V38: 6187.61 | W38: 9049.35 | X38: 9696.08 | Y38: 9275.2 | Z38: 8614.81 | AA38: 7410.5 | AB38: 6530.84
B39: Sep | C39: Ordinario | D39: 21 | E39: 6691.04 | F39: 6379.31 | G39: 6266.46 | H39: 6159.33 | I39: 6574.88 | J39: 7906.88 | K39: 6186.48 | L39: 10253.66 | M39: 8064.34 | N39: 7481.02 | O39: 7249.42 | P39: 7831.34 | Q39: 7706.36 | R39: 8116.3 | S39: 9056.25 | T39: 10070.3 | U39: 12178.65 | V39: 6188 | W39: 9201.74 | X39: 9135.5 | Y39: 8885.42 | Z39: 8123.94 | AA39: 7172.94 | AB39: 6291.76 | AC39: =+SUM(E39:AB39)*D39+SUM(E40:AB40)*D40+SUM(E41:AB41)*D41+SUM(E42:AB42)*D42 -> 5553537.9
B40: Sep | C40: Sábado | D40: 5 | E40: 7428.34 | F40: 6771.21 | G40: 6589.24 | H40: 6452.5 | I40: 6668.97 | J40: 6981.8 | K40: 5217.1 | L40: 9687.01 | M40: 8435.97 | N40: 7988.79 | O40: 7596.34 | P40: 7924.68 | Q40: 7771.4 | R40: 7767.62 | S40: 8217.11 | T40: 9196.81 | U40: 11842.76 | V40: 5776.96 | W40: 8617.04 | X40: 8457.74 | Y40: 8387.16 | Z40: 7469.92 | AA40: 6925.15 | AB40: 6325.07
B41: Sep | C41: Domingo | D41: 4 | E41: 7072.28 | F41: 6712.5 | G41: 6480.5 | H41: 6285.55 | I41: 6205.34 | J41: 5869.27 | K41: 3638.52 | L41: 7746.54 | M41: 6528.61 | N41: 5993.08 | O41: 5861.01 | P41: 6145.72 | Q41: 6304.95 | R41: 6496.1 | S41: 7236.73 | T41: 8340.8 | U41: 10660.1 | V41: 5595.5 | W41: 8574.46 | X41: 8340.27 | Y41: 8336.21 | Z41: 7387.87 | AA41: 6783.76 | AB41: 6018.5
B42: Sep | C42: Festivo | D42: 0 | E42: 0 | F42: 0 | G42: 0 | H42: 0 | I42: 0 | J42: 0 | K42: 0 | L42: 0 | M42: 0 | N42: 0 | O42: 0 | P42: 0 | Q42: 0 | R42: 0 | S42: 0 | T42: 0 | U42: 0 | V42: 0 | W42: 0 | X42: 0 | Y42: 0 | Z42: 0 | AA42: 0 | AB42: 0
...

Sheet Cantidad Producto 3
B2: CANTIDADES DE ENERGÍA SOLICITADAS (kWh)
B3: CENTRAL HIDROELECTRICA DE CALDAS S.A. E.S.P. -BENEFICIO E INTERÉS COLECTIVO
B4: 2029
B6: Mes | C6: Tipo Día | D6: Días | E6: H1 | F6: H2 | G6: H3 | H6: H4 | I6: H5 | J6: H6 | K6: H7 | L6: H8 | M6: H9 | N6: H10 | O6: H11 | P6: H12 | Q6: H13 | R6: H14 | S6: H15 | T6: H16 | U6: H17 | V6: H18 | W6: H19 | X6: H20 | Y6: H21 | Z6: H22 | AA6: H23 | AB6: H24 | AC6: TOTAL MES
B7: Ene | C7: Ordinario | D7: 21 | E7: 5598.18 | F7: 5172.9 | G7: 4914.58 | H7: 4925.18 | I7: 5494.77 | J7: 7328.16 | K7: 7977.3 | L7: 13061.36 | M7: 11080.12 | N7: 10339.58 | O7: 10649.46 | P7: 11321.78 | Q7: 10894.94 | R7: 11075.02 | S7: 11798.31 | T7: 12629.96 | U7: 15212.58 | V7: 14223.66 | W7: 15928.36 | X7: 16378.35 | Y7: 15527.75 | Z7: 13755.37 | AA7: 11116.12 | AB7: 9296.52 | AC7: =+SUM(E7:AB7)*D7+SUM(E8:AB8)*D8+SUM(E9:AB9)*D9+SUM(E10:AB10)*D10 -> 7611173.4 | AE7: =+AC7 -> 7611173.4
B8: Ene | C8: Sábado | D8: 4 | E8: 6143.69 | F8: 5414.84 | G8: 5315.46 | H8: 5319.85 | I8: 5374.47 | J8: 5974.42 | K8: 6414.48 | L8: 12196.36 | M8: 10917.3 | N8: 10704.94 | O8: 10603.85 | P8: 10879.2 | Q8: 11423.46 | R8: 11320.13 | S8: 11920.72 | T8: 11278.88 | U8: 14400.62 | V8: 13194.93 | W8: 15145.73 | X8: 15237.18 | Y8: 14415.86 | Z8: 13270.16 | AA8: 11527.91 | AB8: 10028.74 | AE8: =+AC11 -> 7372921
B9: Ene | C9: Domingo | D9: 4 | E9: 6303.3 | F9: 5623.89 | G9: 5007.09 | H9: 4729.12 | I9: 4469.17 | J9: 4555.01 | K9: 4135.8 | L9: 9102.15 | M9: 7943.58 | N9: 7698.23 | O9: 7815.93 | P9: 8669.36 | Q9: 8854.32 | R9: 9326.71 | S9: 9401.34 | T9: 10307.34 | U9: 13043.83 | V9: 11881.72 | W9: 14436.88 | X9: 14815.6 | Y9: 14082.1 | Z9: 12183.99 | AA9: 10103.86 | AB9: 8212.74 | AE9: =+AC15 -> 7629884.1
B10: Ene | C10: Festivo | D10: 2 | E10: 5980.4 | F10: 5845.75 | G10: 5430.27 | H10: 5120.44 | I10: 4769.11 | J10: 4416.57 | K10: 3231.53 | L10: 7623.39 | M10: 6071.41 | N10: 6165.45 | O10: 6221.25 | P10: 6896.23 | Q10: 7849.24 | R10: 8935.92 | S10: 8653.87 | T10: 9763.26 | U10: 12668.89 | V10: 12118.14 | W10: 13791.68 | X10: 13879.25 | Y10: 13105.05 | Z10: 11542.36 | AA10: 10017.8 | AB10: 8383.7 | AE10: =+AC19 -> 7671929.7
B11: Feb | C11: Ordinario | D11: 20 | E11: 7454.75 | F11: 7020.65 | G11: 6883.6 | H11: 6827.34 | I11: 7399.57 | J11: 9427.24 | K11: 8335.59 | L11: 13013.86 | M11: 10915.1 | N11: 10293.31 | O11: 10366.93 | P11: 10976.31 | Q11: 10802.38 | R11: 11051.78 | S11: 11935.81 | T11: 12922.82 | U11: 14985.47 | V11: 12891.16 | W11: 15421.42 | X11: 16580.32 | Y11: 16020.2 | Z11: 14553.24 | AA11: 12600.37 | AB11: 10933.02 | AC11: =+SUM(E11:AB11)*D11+SUM(E12:AB12)*D12+SUM(E13:AB13)*D13+SUM(E14:AB14)*D14 -> 7372921 | AE11: =+AC23 -> 7564719.2
B12: Feb | C12: Sábado | D12: 4 | E12: 7745.22 | F12: 7187.52 | G12: 6805.49 | H12: 6737.7 | I12: 6919.12 | J12: 7359.19 | K12: 6116.46 | L12: 12032.02 | M12: 10775.4 | N12: 10275.65 | O12: 10398.92 | P12: 10888.91 | Q12: 11130.86 | R12: 10858.07 | S12: 11102.53 | T12: 11857.53 | U12: 14003.9 | V12: 12311.32 | W12: 14927.3 | X12: 16042.79 | Y12: 15342.49 | Z12: 14232.08 | AA12: 12805.39 | AB12: 11360.88 | AE12: =+AC27 -> 7481094.2
B13: Feb | C13: Domingo | D13: 4 | E13: 8173.8 | F13: 7475.84 | G13: 7098.35 | H13: 6856.84 | I13: 6587.7 | J13: 6563.26 | K13: 4832.84 | L13: 9727.77 | M13: 8651.59 | N13: 8618.54 | O13: 8566.54 | P13: 9045.23 | Q13: 9572.71 | R13: 9634.59 | S13: 9907.65 | T13: 10555.64 | U13: 12469.2 | V13: 11434.52 | W13: 13983.57 | X13: 15222.7 | Y13: 14908.51 | Z13: 13753.52 | AA13: 12069.37 | AB13: 10242.04 | AE13: =+AC31 -> 7609421.9
B14: Feb | C14: Festivo | D14: 0 | E14: 0 | F14: 0 | G14: 0 | H14: 0 | I14: 0 | J14: 0 | K14: 0 | L14: 0 | M14: 0 | N14: 0 | O14: 0 | P14: 0 | Q14: 0 | R14: 0 | S14: 0 | T14: 0 | U14: 0 | V14: 0 | W14: 0 | X14: 0 | Y14: 0 | Z14: 0 | AA14: 0 | AB14: 0 | AE14: =+AC35 -> 7737643
B15: Mar | C15: Ordinario | D15: 19 | E15: 7658.98 | F15: 7206.31 | G15: 7034.55 | H15: 6899.39 | I15: 7246.99 | J15: 8675.8 | K15: 7126.42 | L15: 11910.05 | M15: 9981.8 | N15: 9416.41 | O15: 9378.81 | P15: 9897.7 | Q15: 9867.56 | R15: 10199.17 | S15: 11116.55 | T15: 11997.47 | U15: 14108.69 | V15: 12429.98 | W15: 14867.31 | X15: 16092.36 | Y15: 15653.25 | Z15: 14381.84 | AA15: 12623.47 | AB15: 11315.55 | AC15: =+SUM(E15:AB15)*D15+SUM(E16:AB16)*D16+SUM(E17:AB17)*D17+SUM(E18:AB18)*D18 -> 7629884.1 | AE15: =+AC39 -> 7520959.6
B16: Mar | C16: Sábado | D16: 5 | E16: 7884.37 | F16: 7218.77 | G16: 6933.42 | H16: 6800.72 | I16: 6797.95 | J16: 7138.63 | K16: 5217.97 | L16: 10776.07 | M16: 9508.7 | N16: 9173.52 | O16: 8957.58 | P16: 9297.36 | Q16: 9395.63 | R16: 9546.72 | S16: 9964.13 | T16: 10708.94 | U16: 12781.09 | V16: 11554.9 | W16: 14361.77 | X16: 15090.32 | Y16: 14473.14 | Z16: 13717.3 | AA16: 12531.94 | AB16: 11349.99 | AE16: =+AC43 -> 7771992.7
B17: Mar | C17: Domingo | D17: 4 | E17: 8041.38 | F17: 7372.7 | G17: 7029.48 | H17: 6751.95 | I17: 6605.45 | J17: 6558.06 | K17: 4256.32 | L17: 9000.74 | M17: 7911.12 | N17: 7885.41 | O17: 7555.85 | P17: 7749.65 | Q17: 8039.71 | R17: 8579.1 | S17: 8927.75 | T17: 9799.86 | U17: 11863.56 | V17: 10553.34 | W17: 13201.36 | X17: 14702.17 | Y17: 14525.2 | Z17: 13648.06 | AA17: 12122.24 | AB17: 10591.14 | AE17: =+AC47 -> 7622142.1
B18: Mar | C18: Festivo | D18: 3 | E18: 7514.54 | F18: 6860.05 | G18: 6530.17 | H18: 6397.48 | I18: 6266.44 | J18: 6461.42 | K18: 4382.26 | L18: 9486.16 | M18: 8370.17 | N18: 7539.36 | O18: 6912.58 | P18: 7400.99 | Q18: 7955.2 | R18: 8211.51 | S18: 8297.28 | T18: 9060.97 | U18: 11246.54 | V18: 10064.8 | W18: 12969.4 | X18: 13629.49 | Y18: 13247.29 | Z18: 13123.63 | AA18: 12312.32 | AB18: 11177.03 | AE18: =+AC51 -> 7728670
B19: Abr | C19: Ordinario | D19: 21 | E19: 7475.1 | F19: 6972.72 | G19: 6785.14 | H19: 6747.88 | I19: 7354.09 | J19: 9460.66 | K19: 8294.98 | L19: 12634.4 | M19: 10009.16 | N19: 9251.56 | O19: 9238.82 | P19: 9084.19 | Q19: 9337.58 | R19: 9832.4 | S19: 10881.32 | T19: 11956.26 | U19: 14404.21 | V19: 12995.72 | W19: 15958.5 | X19: 16456.26 | Y19: 15888.31 | Z19: 14601.83 | AA19: 12525.2 | AB19: 10868.63 | AC19: =+SUM(E19:AB19)*D19+SUM(E20:AB20)*D20+SUM(E21:AB21)*D21+SUM(E22:AB22)*D22 -> 7671929.7
B20: Abr | C20: Sábado | D20: 4 | E20: 7988.65 | F20: 7507.96 | G20: 6965.41 | H20: 6933.42 | I20: 7169.98 | J20: 7659.43 | K20: 5840.87 | L20: 12220.83 | M20: 11189.74 | N20: 10634.82 | O20: 10298.74 | P20: 10394.5 | Q20: 10859.05 | R20: 10346.22 | S20: 10715.12 | T20: 11629.76 | U20: 13972.87 | V20: 11309.64 | W20: 15577.36 | X20: 16246.01 | Y20: 15554.56 | Z20: 14627.92 | AA20: 13101.38 | AB20: 12610.14
B21: Abr | C21: Domingo | D21: 5 | E21: 8401.14 | F21: 7836.4 | G21: 7450.55 | H21: 7164.02 | I21: 6892.94 | J21: 6841.18 | K21: 4810.78 | L21: 9650.14 | M21: 8425.31 | N21: 8070.34 | O21: 8037.89 | P21: 8548.18 | Q21: 9413.55 | R21: 9923.14 | S21: 9926.9 | T21: 10618.03 | U21: 12626.12 | V21: 11653.85 | W21: 14647.23 | X21: 15216.08 | Y21: 14968.7 | Z21: 13764.78 | AA21: 12140.22 | AB21: 10412.3
B22: Abr | C22: Festivo | D22: 0 | E22: 0 | F22: 0 | G22: 0 | H22: 0 | I22: 0 | J22: 0 | K22: 0 | L22: 0 | M22: 0 | N22: 0 | O22: 0 | P22: 0 | Q22: 0 | R22: 0 | S22: 0 | T22: 0 | U22: 0 | V22: 0 | W22: 0 | X22: 0 | Y22: 0 | Z22: 0 | AA22: 0 | AB22: 0
B23: May | C23: Ordinario | D23: 21 | E23: 6945.8 | F23: 6592.29 | G23: 6413.42 | H23: 6382.33 | I23: 6883.13 | J23: 8695.98 | K23: 7538.77 | L23: 12058.1 | M23: 9800.14 | N23: 9045.09 | O23: 9151.45 | P23: 9684.38 | Q23: 9450.75 | R23: 9731.04 | S23: 10552.78 | T23: 11541.46 | U23: 13725.56 | V23: 12208.29 | W23: 15187.34 | X23: 15597.51 | Y23: 14955.08 | Z23: 13829.43 | AA23: 12057.98 | AB23: 10423.24 | AC23: =+SUM(E23:AB23)*D23+SUM(E24:AB24)*D24+SUM(E25:AB25)*D25+SUM(E26:AB26)*D26 -> 7564719.2
B24: May | C24: Sábado | D24: 4 | E24: 7529.08 | F24: 7035.64 | G24: 6773.56 | H24: 6610.03 | I24: 6802.26 | J24: 7070.46 | K24: 5819.32 | L24: 11526.45 | M24: 10228.38 | N24: 9856.75 | O24: 9662.22 | P24: 10005.92 | Q24: 10005.68 | R24: 9806.6 | S24: 10154.46 | T24: 10927.09 | U24: 13184.12 | V24: 11780.11 | W24: 14812.94 | X24: 15288.32 | Y24: 14634.97 | Z24: 13741.5 | AA24: 12415.35 | AB24: 10773.5
B25: May | C25: Domingo | D25: 4 | E25: 7691.68 | F25: 7133.74 | G25: 6796.9 | H25: 6498.69 | I25: 6429.67 | J25: 6196.29 | K25: 4324.48 | L25: 9192.61 | M25: 8086.19 | N25: 8030.63 | O25: 8107.37 | P25: 8606.36 | Q25: 8675.87 | R25: 8578.04 | S25: 8645.68 | T25: 9490.46 | U25: 11827.67 | V25: 10597.19 | W25: 13734.1 | X25: 14447.04 | Y25: 14212.71 | Z25: 13301.02 | AA25: 11913.33 | AB25: 10189.38
B26: May | C26: Festivo | D26: 2 | E26: 7210.72 | F26: 6697.42 | G26: 6510.76 | H26: 6303.36 | I26: 6385.49 | J26: 6386.27 | K26: 4600.92 | L26: 9531.85 | M26: 8388.6 | N26: 8229.58 | O26: 8621.13 | P26: 9509.3 | Q26: 9985.55 | R26: 9928.34 | S26: 10027.2 | T26: 10735.39 | U26: 12829.8 | V26: 11647.77 | W26: 14921.99 | X26: 15625.88 | Y26: 14941.58 | Z26: 13842.76 | AA26: 12183.46 | AB26: 10271.81
B27: Jun | C27: Ordinario | D27: 19 | E27: 6920.17 | F27: 6469.07 | G27: 6322.79 | H27: 6294.99 | I27: 6738.24 | J27: 7972.55 | K27: 6988.5 | L27: 12119.8 | M27: 10256.06 | N27: 9708.2 | O27: 9800.81 | P27: 10553.04 | Q27: 10304.46 | R27: 10381.76 | S27: 11189.17 | T27: 11954.66 | U27: 14126.51 | V27: 12528.32 | W27: 15574.28 | X27: 16067.48 | Y27: 15335.57 | Z27: 14191.22 | AA27: 12325.99 | AB27: 10569.11 | AC27: =+SUM(E27:AB27)*D27+SUM(E28:AB28)*D28+SUM(E29:AB29)*D29+SUM(E30:AB30)*D30 -> 7481094.2
B28: Jun | C28: Sábado | D28: 5 | E28: 7678.7 | F28: 7071.54 | G28: 6890.66 | H28: 6690.98 | I28: 6923.43 | J28: 7207.86 | K28: 5989.39 | L28: 11854.01 | M28: 10503.61 | N28: 10116.86 | O28: 9901.15 | P28: 10409.64 | Q28: 10411.65 | R28: 10297.2 | S28: 10770.09 | T28: 11546.04 | U28: 13693.6 | V28: 12256.52 | W28: 15323.84 | X28: 16038.05 | Y28: 15339.41 | Z28: 14251.82 | AA28: 12876.28 | AB28: 11229.01
B29: Jun | C29: Domingo | D29: 4 | E29: 7821.53 | F29: 7432.99 | G29: 6963.84 | H29: 6791.39 | I29: 6698.37 | J29: 6460.6 | K29: 4335.87 | L29: 9402.16 | M29: 8287.96 | N29: 7964.24 | O29: 7879.71 | P29: 8459.6 | Q29: 8874.94 | R29: 8862.96 | S29: 9242.98 | T29: 10005.04 | U29: 12054.37 | V29: 10933.8 | W29: 13908.86 | X29: 14566.06 | Y29: 14142.94 | Z29: 13247.86 | AA29: 11975.92 | AB29: 10408.86
B30: Jun | C30: Festivo | D30: 2 | E30: 7627 | F30: 7128.76 | G30: 6766.96 | H30: 6549.83 | I30: 6678.24 | J30: 6557.38 | K30: 4535.38 | L30: 9178.58 | M30: 8136.64 | N30: 7475.25 | O30: 7982 | P30: 8872.18 | Q30: 9180.91 | R30: 8688.12 | S30: 9195.75 | T30: 9890.3 | U30: 11765.24 | V30: 11678.13 | W30: 15255.04 | X30: 15739.64 | Y30: 14974.94 | Z30: 13589.52 | AA30: 11811.05 | AB30: 10085.1
B31: Jul | C31: Ordinario | D31: 20 | E31: 7089.97 | F31: 6608.18 | G31: 6435.15 | H31: 6341.67 | I31: 6833.27 | J31: 8438.54 | K31: 7003.62 | L31: 11892.62 | M31: 9816.68 | N31: 9259.36 | O31: 9421.11 | P31: 10340.88 | Q31: 9902.24 | R31: 10073.84 | S31: 11083.27 | T31: 11883.56 | U31: 13886.44 | V31: 12373.05 | W31: 15392.86 | X31: 16233.25 | Y31: 15529.24 | Z31: 14289.9 | AA31: 12424.63 | AB31: 10440.68 | AC31: =+SUM(E31:AB31)*D31+SUM(E32:AB32)*D32+SUM(E33:AB33)*D33+SUM(E34:AB34)*D34 -> 7609421.9
B32: Jul | C32: Sábado | D32: 4 | E32: 6673.99 | F32: 6317.77 | G32: 5987.41 | H32: 6028.06 | I32: 6151.8 | J32: 6470.85 | K32: 5302.3 | L32: 11110.29 | M32: 9901.04 | N32: 9644.52 | O32: 9416.7 | P32: 9970.24 | Q32: 9816.21 | R32: 9790.47 | S32: 10081.22 | T32: 10841.97 | U32: 13118.2 | V32: 11852.12 | W32: 14801.87 | X32: 15734.08 | Y32: 15033.4 | Z32: 14108.91 | AA32: 12605.86 | AB32: 10888.28
B33: Jul | C33: Domingo | D33: 5 | E33: 7440.76 | F33: 7013.78 | G33: 6459.36 | H33: 6300.6 | I33: 6217.28 | J33: 6008.68 | K33: 3927.36 | L33: 8972.48 | M33: 7766.16 | N33: 7730.06 | O33: 7868.47 | P33: 8757.23 | Q33: 9019.01 | R33: 9114.68 | S33: 9396.64 | T33: 10160.47 | U33: 12353.63 | V33: 11280.41 | W33: 14274.03 | X33: 15168.97 | Y33: 14456.44 | Z33: 13468.52 | AA33: 12376.7 | AB33: 10777.07
B34: Jul | C34: Festivo | D34: 2 | E34: 7152.78 | F34: 6656.3 | G34: 6280.79 | H34: 6356.4 | I34: 6106.63 | J34: 6174.47 | K34: 4303.3 | L34: 9438.11 | M34: 8291.85 | N34: 7733.78 | O34: 8164.88 | P34: 8767.19 | Q34: 8975.27 | R34: 9051.58 | S34: 9546.75 | T34: 10368.54 | U34: 12200.7 | V34: 10971.61 | W34: 13979.77 | X34: 14911.24 | Y34: 14392.84 | Z34: 13239.03 | AA34: 12061.8 | AB34: 10578.16
B35: Ago | C35: Ordinario | D35: 21 | E35: 7102.7 | F35: 6734.98 | G35: 6524.19 | H35: 6491.03 | I35: 7105.72 | J35: 9067.62 | K35: 7691.65 | L35: 12299.2 | M35: 10190.72 | N35: 9480 | O35: 9629.4 | P35: 10247.84 | Q35: 9787.86 | R35: 10170.57 | S35: 11125.52 | T35: 11942.46 | U35: 14108.2 | V35: 12168.12 | W35: 15517.3 | X35: 16234.38 | Y35: 15592.33 | Z35: 14376.27 | AA35: 12183.23 | AB35: 10513.82 | AC35: =+SUM(E35:AB35)*D35+SUM(E36:AB36)*D36+SUM(E37:AB37)*D37+SUM(E38:AB38)*D38 -> 7737643
B36: Ago | C36: Sábado | D36: 4 | E36: 7869.04 | F36: 7305.91 | G36: 7043.08 | H36: 6940.84 | I36: 7134.4 | J36: 7484.92 | K36: 5923.7 | L36: 11767.1 | M36: 10416.12 | N36: 10171.01 | O36: 10051.07 | P36: 10657.87 | Q36: 10180.75 | R36: 10104.72 | S36: 10328.88 | T36: 11050.89 | U36: 13493.46 | V36: 11805.25 | W36: 15266.94 | X36: 15742.3 | Y36: 14938.59 | Z36: 13965.42 | AA36: 12102.3 | AB36: 10821.25
B37: Ago | C37: Domingo | D37: 4 | E37: 7319.92 | F37: 6953.84 | G37: 6660.71 | H37: 6443.21 | I37: 6287.39 | J37: 6319.88 | K37: 3763.56 | L37: 8657.1 | M37: 7587.6 | N37: 7277.37 | O37: 7483.28 | P37: 8151.63 | Q37: 8256.11 | R37: 8707.6 | S37: 8987.45 | T37: 9696.07 | U37: 12039.86 | V37: 10566.05 | W37: 13853.08 | X37: 14607.25 | Y37: 14304.43 | Z37: 13391.98 | AA37: 11268.89 | AB37: 9973.16
B38: Ago | C38: Festivo | D38: 2 | E38: 6970.63 | F38: 6685.73 | G38: 6302.57 | H38: 6276.14 | I38: 6340.39 | J38: 6447.78 | K38: 4435.84 | L38: 9674.18 | M38: 8335.58 | N38: 8467.93 | O38: 8885.86 | P38: 10013.65 | Q38: 9845.52 | R38: 9908.97 | S38: 10161.75 | T38: 10808.44 | U38: 12787.63 | V38: 11710.02 | W38: 14780.3 | X38: 15802.72 | Y38: 15135.06 | Z38: 13826.88 | AA38: 11786.13 | AB38: 10191.67
B39: Sep | C39: Ordinario | D39: 20 | E39: 7269.64 | F39: 6928.73 | G39: 6803.59 | H39: 6719.44 | I39: 7278.3 | J39: 9004.46 | K39: 7658.5 | L39: 12456.8 | M39: 10191.66 | N39: 9568.19 | O39: 9494.6 | P39: 10090.39 | Q39: 9898.3 | R39: 10307.71 | S39: 11319.86 | T39: 12334.37 | U39: 14452.7 | V39: 12414.49 | W39: 15815.55 | X39: 16017.49 | Y39: 15369.1 | Z39: 14016.28 | AA39: 12104.68 | AB39: 10471.5 | AC39: =+SUM(E39:AB39)*D39+SUM(E40:AB40)*D40+SUM(E41:AB41)*D41+SUM(E42:AB42)*D42 -> 7520959.6
B40: Sep | C40: Sábado | D40: 5 | E40: 8051.72 | F40: 7351.78 | G40: 7122.24 | H40: 6970.1 | I40: 7200.51 | J40: 7527.19 | K40: 6145.65 | L40: 11697.14 | M40: 10509.83 | N40: 10075.35 | O40: 9772.66 | P40: 10030.68 | Q40: 9932.08 | R40: 9895.19 | S40: 10299.87 | T40: 11207.02 | U40: 13732.69 | V40: 11799.78 | W40: 15003.52 | X40: 14924.1 | Y40: 14463.19 | Z40: 13151.34 | AA40: 11839.79 | AB40: 10605.25
B41: Sep | C41: Domingo | D41: 5 | E41: 7766.04 | F41: 7329.15 | G41: 7056.87 | H41: 6810.35 | I41: 6647.78 | J41: 6344.74 | K41: 4263.91 | L41: 9195.05 | M41: 8144.82 | N41: 7719.8 | O41: 7630.41 | P41: 7967.08 | Q41: 8230.12 | R41: 8368.94 | S41: 9020.34 | T41: 10036.93 | U41: 12291.68 | V41: 10981.04 | W41: 14429.95 | X41: 14569.46 | Y41: 14256.8 | Z41: 12802.64 | AA41: 11235.28 | AB41: 9838.76
B42: Sep | C42: Festivo | D42: 0 | E42: 0 | F42: 0 | G42: 0 | H42: 0 | I42: 0 | J42: 0 | K42: 0 | L42: 0 | M42: 0 | N42: 0 | O42: 0 | P42: 0 | Q42: 0 | R42: 0 | S42: 0 | T42: 0 | U42: 0 | V42: 0 | W42: 0 | X42: 0 | Y42: 0 | Z42: 0 | AA42: 0 | AB42: 0
...

Sheet Cantidad Producto 4
B2: CANTIDADES DE ENERGÍA SOLICITADAS (kWh)
B3: CENTRAL HIDROELECTRICA DE CALDAS S.A. E.S.P. -BENEFICIO E INTERÉS COLECTIVO
B4: 2030
B6: Mes | C6: Tipo Día | D6: Días | E6: H1 | F6: H2 | G6: H3 | H6: H4 | I6: H5 | J6: H6 | K6: H7 | L6: H8 | M6: H9 | N6: H10 | O6: H11 | P6: H12 | Q6: H13 | R6: H14 | S6: H15 | T6: H16 | U6: H17 | V6: H18 | W6: H19 | X6: H20 | Y6: H21 | Z6: H22 | AA6: H23 | AB6: H24 | AC6: TOTAL MES
B7: Ene | C7: Ordinario | D7: 21 | E7: 17761.06 | F7: 16460.45 | G7: 15732.11 | H7: 15659.66 | I7: 7261.06 | J7: 9135.43 | K7: 9977.93 | L7: 14741.24 | M7: 13491.62 | N7: 13225.72 | O7: 13768.42 | P7: 14644.39 | Q7: 14292.51 | R7: 14326.02 | S7: 14883.01 | T7: 15459.08 | U7: 17324.79 | V7: 16622.96 | W7: 923.24 | X7: 957.52 | Y7: 910.96 | Z7: 16346.52 | AA7: 13542.2 | AB7: 26836 | AC7: =+SUM(E7:AB7)*D7+SUM(E8:AB8)*D8+SUM(E9:AB9)*D9+SUM(E10:AB10)*D10 -> 9409166.4 | AE7: =+AC7 -> 9409166.4
B8: Ene | C8: Sábado | D8: 4 | E8: 8116.14 | F8: 7278.79 | G8: 7046.78 | H8: 6984.78 | I8: 7085.95 | J8: 7732.01 | K8: 8275.81 | L8: 13734.85 | M8: 13265.89 | N8: 13431.84 | O8: 13584.02 | P8: 14070.7 | Q8: 14541.95 | R8: 14286.2 | S8: 14594.88 | T8: 13991.1 | U8: 16289.11 | V8: 15537.23 | W8: 17616.25 | X8: 18032.25 | Y8: 17103.98 | Z8: 15786.34 | AA8: 13865.5 | AB8: 12102.84 | AE8: =+AC11 -> 9079556.8
B9: Ene | C9: Domingo | D9: 4 | E9: 8337.37 | F9: 7522.38 | G9: 6896.15 | H9: 6586.86 | I9: 6342.54 | J9: 6435.2 | K9: 6119.49 | L9: 10680.36 | M9: 10327.54 | N9: 10545.89 | O9: 10888.31 | P9: 11776.13 | Q9: 12097.96 | R9: 12384.58 | S9: 12276.95 | T9: 12860.51 | U9: 14832.69 | V9: 14202.74 | W9: 16698.33 | X9: 17443.29 | Y9: 16721.84 | Z9: 14838.19 | AA9: 12541.64 | AB9: 10451.62 | AE9: =+AC15 -> 9418074
B10: Ene | C10: Festivo | D10: 2 | E10: 8300.81 | F10: 7947.76 | G10: 7432.92 | H10: 7037.17 | I10: 6678.85 | J10: 6398.84 | K10: 5335.26 | L10: 9280.35 | M10: 8455.02 | N10: 8917.97 | O10: 9262.14 | P10: 10119.92 | Q10: 11070.45 | R10: 11866.52 | S10: 11505.31 | T10: 12240.06 | U10: 14369.46 | V10: 14216.94 | W10: 16233.32 | X10: 16657.02 | Y10: 15840.2 | Z10: 14206.55 | AA10: 12379.25 | AB10: 10522.64 | AE10: =+AC19 -> 9434893.2
