Workbook

Sheet PRODUCTO 01
C1: CP-GNCC2025-002
C2: CP-GNCC2025-002-PROD01
C3: CANTIDAD EN: | D3: KWh
C4: MODALIDAD: | D4: PAGUE LO CONTRATADO
C5: OFERENTE:
C9: MES DE SUMINISTRO | D9: ENERGÍA SOLICITADA (KWh) | E9: % ENERGÍA OFRECIDA | F9: ENERGÍA OFRECIDA (KWh) | G9: PRECIO OFERTADO ($/KWh)
C10: 46023 | D10: =+_xlfn.XLOOKUP(C10,'Cantidades horarias PROD 01'!E:E,'Cantidades horarias PROD 01'!F:F) -> 39045741 | E10: 1 | F10: =ROUND(D10*$E10,2) -> 39045741
C11: 46054 | D11: =+_xlfn.XLOOKUP(C11,'Cantidades horarias PROD 01'!E:E,'Cantidades horarias PROD 01'!F:F) -> 36042923 | E11: 1 | F11: =ROUND(D11*$E11,2) -> 36042923
C12: 46082 | D12: =+_xlfn.XLOOKUP(C12,'Cantidades horarias PROD 01'!E:E,'Cantidades horarias PROD 01'!F:F) -> 39294897 | E12: 1 | F12: =ROUND(D12*$E12,2) -> 39294897
C13: 46113 | D13: =+_xlfn.XLOOKUP(C13,'Cantidades horarias PROD 01'!E:E,'Cantidades horarias PROD 01'!F:F) -> 37825628 | E13: 1 | F13: =ROUND(D13*$E13,2) -> 37825628
C14: 46143 | D14: =+_xlfn.XLOOKUP(C14,'Cantidades horarias PROD 01'!E:E,'Cantidades horarias PROD 01'!F:F) -> 39202114 | E14: 1 | F14: =ROUND(D14*$E14,2) -> 39202114
C15: 46174 | D15: =+_xlfn.XLOOKUP(C15,'Cantidades horarias PROD 01'!E:E,'Cantidades horarias PROD 01'!F:F) -> 37941686 | E15: 1 | F15: =ROUND(D15*$E15,2) -> 37941686
C16: 46204 | D16: =+_xlfn.XLOOKUP(C16,'Cantidades horarias PROD 01'!E:E,'Cantidades horarias PROD 01'!F:F) -> 40137511 | E16: 1 | F16: =ROUND(D16*$E16,2) -> 40137511
C17: 46235 | D17: =+_xlfn.XLOOKUP(C17,'Cantidades horarias PROD 01'!E:E,'Cantidades horarias PROD 01'!F:F) -> 38908847 | E17: 1 | F17: =ROUND(D17*$E17,2) -> 38908847
C18: 46266 | D18: =+_xlfn.XLOOKUP(C18,'Cantidades horarias PROD 01'!E:E,'Cantidades horarias PROD 01'!F:F) -> 38535133 | E18: 1 | F18: =ROUND(D18*$E18,2) -> 38535133
C19: 46296 | D19: =+_xlfn.XLOOKUP(C19,'Cantidades horarias PROD 01'!E:E,'Cantidades horarias PROD 01'!F:F) -> 39571327 | E19: 1 | F19: =ROUND(D19*$E19,2) -> 39571327
C20: 46327 | D20: =+_xlfn.XLOOKUP(C20,'Cantidades horarias PROD 01'!E:E,'Cantidades horarias PROD 01'!F:F) -> 38022246 | E20: 1 | F20: =ROUND(D20*$E20,2) -> 38022246
C21: 46357 | D21: =+_xlfn.XLOOKUP(C21,'Cantidades horarias PROD 01'!E:E,'Cantidades horarias PROD 01'!F:F) -> 38156821 | E21: 1 | F21: =ROUND(D21*$E21,2) -> 38156821
C22: TOTAL | D22: =SUM(D10:D21) -> 4.6268487e+08 | E22: =IFERROR(F22/D22,0) -> 1 | F22: =SUM(F10:F21) -> 4.6268487e+08 | G22: =G10 -> 0
D24: Relacion ≥ | E24: 0.8
D25: Relacion: | E25: =MIN(E10:E21)/MAX(E10:E21) -> 1
C26: Nota
C27: 1. $/kWh expresados en pesos de julio de 2025.
C28: 2. La energia ofertada se despachara conforme a las cantidades horarias de este anexo
C32: XXXXXXXXXXXXXXXXXXXXXXXX
C33: REPRESENTANTE LEGAL
C34: XXXXXXXXXXXXXXXXXXXXXX S.A E.S.P

Sheet Cantidades horarias PROD 01
E1: CUADRO DE CANTIDADES HORARIAS OFRECIDAS
E2: CANTIDADES DE ENERGIA (KWh) - PRODUCTO 1
E3: PAGUE LO CONTRATADO
E5: OFERENTE:
F8: Cantidad Ofrecida | G8: Tipo de día | H8: N° días mes | I8: H1 | J8: H2 | K8: H3 | L8: H4 | M8: H5 | N8: H6 | O8: H7 | P8: H8 | Q8: H9 | R8: H10 | S8: H11 | T8: H12 | U8: H13 | V8: H14 | W8: H15 | X8: H16 | Y8: H17 | Z8: H18 | AA8: H19 | AB8: H20 | AC8: H21 | AD8: H22 | AE8: H23 | AF8: H24 | AG8: TOTAL
E9: 46023 | F9: =+AG13 -> 39045741 | G9: OR | H9: 20 | I9: 46531.807 | J9: 45464.635 | K9: 44892.082 | L9: 44894.445 | M9: 44638.293 | N9: 46081.403 | O9: 49363.983 | P9: 56329.077 | Q9: 61907.059 | R9: 63611.528 | S9: 64667.698 | T9: 64235.098 | U9: 62105.257 | V9: 61214.617 | W9: 63059.359 | X9: 64186.176 | Y9: 63490.423 | Z9: 63548.963 | AA9: 60555.118 | AB9: 58586.029 | AC9: 55680.976 | AD9: 52286.072 | AE9: 49739.852 | AF9: 48446.831 | AG9: =ROUND(SUM(I9:AF9)*H9,2) -> 26710336
G10: SA | H10: 5 | I10: 45437.722 | J10: 44363.604 | K10: 43958.12 | L10: 43768.702 | M10: 43450.757 | N10: 44531.574 | O10: 47965.669 | P10: 56599.476 | Q10: 57593.086 | R10: 55870.048 | S10: 60910.344 | T10: 60882.835 | U10: 57733.248 | V10: 57559.075 | W10: 59494.37 | X10: 58760.909 | Y10: 58674.257 | Z10: 59557.763 | AA10: 56696.882 | AB10: 55913.586 | AC10: 53391.134 | AD10: 50052.733 | AE10: 47317.133 | AF10: 45879.755 | AG10: =ROUND(SUM(I10:AF10)*H10,2) -> 6331813.9
G11: DO | H11: 4 | I11: 41998.111 | J11: 41561.923 | K11: 41371.287 | L11: 41164.563 | M11: 41488.393 | N11: 41079.541 | O11: 43066.107 | P11: 40039.386 | Q11: 34127.207 | R11: 30990.951 | S11: 35524.432 | T11: 39293.398 | U11: 41886.636 | V11: 43425.272 | W11: 41722.063 | X11: 41823.475 | Y11: 41910.776 | Z11: 42002.278 | AA11: 41628.764 | AB11: 41745.982 | AC11: 41268.055 | AD11: 40833.699 | AE11: 40687.202 | AF11: 40272.84 | AG11: =ROUND(SUM(I11:AF11)*H11,2) -> 3883649.4
G12: FE | H12: 2 | I12: 45535.495 | J12: 44988.562 | K12: 44762.523 | L12: 44775.143 | M12: 45064.269 | N12: 43522.709 | O12: 44777.933 | P12: 45761.319 | Q12: 41659.23 | R12: 39509.735 | S12: 44276.367 | T12: 48716.46 | U12: 50615.966 | V12: 49758.923 | W12: 46112.203 | X12: 43322.167 | Y12: 43257.199 | Z12: 43951.743 | AA12: 43897.392 | AB12: 44005.468 | AC12: 42814.91 | AD12: 40020.75 | AE12: 39677.973 | AF12: 39186.609 | AG12: =ROUND(SUM(I12:AF12)*H12,2) -> 2119942.1
G13: TOTAL | H13: =+SUM(H9:H12) -> 31 | I13: =+SUMPRODUCT(I9:I12,$H9:$H12) -> 1416888.2 | J13: =+SUMPRODUCT(J9:J12,$H9:$H12) -> 1387335.5 | K13: =+SUMPRODUCT(K9:K12,$H9:$H12) -> 1372642.4 | L13: =+SUMPRODUCT(L9:L12,$H9:$H12) -> 1370940.9 | M13: =+SUMPRODUCT(M9:M12,$H9:$H12) -> 1366101.8 | N13: =+SUMPRODUCT(N9:N12,$H9:$H12) -> 1395649.5 | O13: =+SUMPRODUCT(O9:O12,$H9:$H12) -> 1488928.3 | P13: =+SUMPRODUCT(P9:P12,$H9:$H12) -> 1661259.1 | ... AF13: =+SUMPRODUCT(AF9:AF12,$H9:$H12) -> 1437800 | AG13: =SUM(I13:AF13) -> 39045741
E14: 46054 | F14: =+AG18 -> 36042923 | G14: OR | H14: 20 | I14: 47285.378 | J14: 46205.821 | K14: 45610.856 | L14: 45617.717 | M14: 45183.114 | N14: 46617.123 | O14: 49798.301 | P14: 56495.408 | Q14: 62462.846 | R14: 62046.563 | S14: 65453.149 | T14: 65450.122 | U14: 63155.503 | V14: 62633.198 | W14: 63701.525 | X14: 64825.532 | Y14: 64152.577 | Z14: 64083.299 | AA14: 61156.394 | AB14: 59231.351 | AC14: 56338.255 | AD14: 52989.373 | AE14: 50326.455 | AF14: 49084.491 | AG14: =+SUM(I14:AF14)*H14 -> 26998087
E15: 46054 | G15: SA | H15: 4 | I15: 46448.031 | J15: 45385.644 | K15: 44978.292 | L15: 44756.384 | M15: 44348.887 | N15: 45419.541 | O15: 48776.132 | P15: 57796.136 | Q15: 57520.428 | R15: 54464.035 | S15: 57761.488 | T15: 59124.563 | U15: 57662.181 | V15: 61889.652 | W15: 61402.474 | X15: 60067.947 | Y15: 59749.338 | Z15: 60602.272 | AA15: 58175.593 | AB15: 56917.733 | AC15: 54461.406 | AD15: 51094.74 | AE15: 48330.093 | AF15: 46897.292 | AG15: =+SUM(I15:AF15)*H15 -> 5136121.1
E16: 46054 | G16: DO | H16: 4 | I16: 42428.397 | J16: 41965.62 | K16: 41744.496 | L16: 41563.245 | M16: 41908.14 | N16: 41646.644 | O16: 43285.058 | P16: 39993.347 | Q16: 34646.419 | R16: 30227.298 | S16: 33060.495 | T16: 38146.466 | U16: 42317.789 | V16: 46387.573 | W16: 42650.271 | X16: 42171.893 | Y16: 42219.848 | Z16: 42358.008 | AA16: 41929.965 | AB16: 42206.588 | AC16: 41648.821 | AD16: 41152.535 | AE16: 40987.302 | AF16: 40532.392 | AG16: =+SUM(I16:AF16)*H16 -> 3908714.4
E17: 46054 | G17: FE | H17: 0 | I17: 0 | J17: 0 | K17: 0 | L17: 0 | M17: 0 | N17: 0 | O17: 0 | P17: 0 | Q17: 0 | R17: 0 | S17: 0 | T17: 0 | U17: 0 | V17: 0 | W17: 0 | X17: 0 | Y17: 0 | Z17: 0 | AA17: 0 | AB17: 0 | AC17: 0 | AD17: 0 | AE17: 0 | AF17: 0 | AG17: =+SUM(I17:AF17)*H17 -> 0
E18: 46054 | G18: TOTAL | H18: =+SUM(H14:H17) -> 28 | I18: =+SUMPRODUCT(I14:I17,$H14:$H17) -> 1301213.3 | J18: =+SUMPRODUCT(J14:J17,$H14:$H17) -> 1273521.5 | K18: =+SUMPRODUCT(K14:K17,$H14:$H17) -> 1259108.3 | L18: =+SUMPRODUCT(L14:L17,$H14:$H17) -> 1257632.9 | M18: =+SUMPRODUCT(M14:M17,$H14:$H17) -> 1248690.4 | N18: =+SUMPRODUCT(N14:N17,$H14:$H17) -> 1280607.2 | O18: =+SUMPRODUCT(O14:O17,$H14:$H17) -> 1364210.8 | P18: =+SUMPRODUCT(P14:P17,$H14:$H17) -> 1521066.1 | ... AF18: =+SUMPRODUCT(AF14:AF17,$H14:$H17) -> 1331408.6 | AG18: =SUM(I18:AF18) -> 36042923
E19: 46082 | F19: =+AG23 -> 39294897 | G19: OR | H19: 21 | I19: 47448.963 | J19: 46381.126 | K19: 45790.527 | L19: 45786.691 | M19: 45375.465 | N19: 46685.021 | O19: 49677.663 | P19: 54609.619 | Q19: 58688.471 | R19: 61558.936 | S19: 62389.448 | T19: 62003.335 | U19: 60067.544 | V19: 61387.675 | W19: 63256.699 | X19: 64424.956 | Y19: 63752.966 | Z19: 63742.09 | AA19: 60904.761 | AB19: 59100.323 | AC19: 56245.039 | AD19: 52985.046 | AE19: 50390.877 | AF19: 49152.465 | AG19: =+SUM(I19:AF19)*H19 -> 27967920
E20: 46082 | G20: SA | H20: 4 | I20: 46418.223 | J20: 45365.056 | K20: 44992.234 | L20: 44815.293 | M20: 44434.044 | N20: 45443.274 | O20: 47887.926 | P20: 54761.103 | Q20: 60542.341 | R20: 61433.365 | S20: 63897.726 | T20: 63909.495 | U20: 61192.759 | V20: 60738.776 | W20: 59542.377 | X20: 59841.711 | Y20: 59499.179 | Z20: 60379.537 | AA20: 58023.595 | AB20: 56849.319 | AC20: 54438.821 | AD20: 51163.59 | AE20: 48498.365 | AF20: 47094.123 | AG20: =+SUM(I20:AF20)*H20 -> 5204648.9
E21: 46082 | G21: DO | H21: 5 | I21: 43990.728 | J21: 43535.399 | K21: 43288.412 | L21: 43088.634 | M21: 43239.142 | N21: 42204.153 | O21: 42157.455 | P21: 43868.905 | Q21: 40082.898 | R21: 36567.898 | S21: 39159.991 | T21: 42335.137 | U21: 45361.587 | V21: 43328.215 | W21: 41504.207 | X21: 42318.22 | Y21: 42188.899 | Z21: 42611.098 | AA21: 42282.711 | AB21: 42620.062 | AC21: 41983.221 | AD21: 41561.433 | AE21: 41380.759 | AF21: 40990.617 | AG21: =+SUM(I21:AF21)*H21 -> 5058248.9
E22: 46082 | G22: FE | H22: 1 | I22: 45702.535 | J22: 45167.195 | K22: 44909.556 | L22: 44694.201 | M22: 44629.094 | N22: 42633.949 | O22: 42433.092 | P22: 46967.586 | Q22: 47622.082 | R22: 45092.963 | S22: 47918.017 | T22: 51709.935 | U22: 49093.616 | V22: 46463.78 | W22: 42247.539 | X22: 42176.439 | Y22: 41773.424 | Z22: 42539.199 | AA22: 42401.904 | AB22: 42878.31 | AC22: 41916.957 | AD22: 41372.364 | AE22: 41078.242 | AF22: 40657.044 | AG22: =+SUM(I22:AF22)*H22 -> 1064079
E23: 46082 | G23: TOTAL | H23: =+SUM(H19:H22) -> 31 | I23: =+SUMPRODUCT(I19:I22,$H19:$H22) -> 1447757.3 | J23: =+SUMPRODUCT(J19:J22,$H19:$H22) -> 1418308.1 | K23: =+SUMPRODUCT(K19:K22,$H19:$H22) -> 1402921.6 | L23: =+SUMPRODUCT(L19:L22,$H19:$H22) -> 1400919 | M23: =+SUMPRODUCT(M19:M22,$H19:$H22) -> 1391445.8 | N23: =+SUMPRODUCT(N19:N22,$H19:$H22) -> 1415813.2 | O23: =+SUMPRODUCT(O19:O22,$H19:$H22) -> 1488003 | P23: =+SUMPRODUCT(P19:P22,$H19:$H22) -> 1632158.5 | ... AF23: =+SUMPRODUCT(AF19:AF22,$H19:$H22) -> 1466188.4 | AG23: =SUM(I23:AF23) -> 39294897
E24: 46113 | F24: =+AG28 -> 37825628 | G24: OR | H24: 20 | I24: 48589.29 | J24: 47504.826 | K24: 46896.955 | L24: 46881.77 | M24: 46460.389 | N24: 47814.913 | O24: 50946.604 | P24: 56036.337 | Q24: 60502.753 | R24: 57655.591 | S24: 59729.777 | T24: 59590.434 | U24: 60416.598 | V24: 63169.58 | W24: 65051.573 | X24: 66186.195 | Y24: 65493.163 | Z24: 65398.699 | AA24: 62450.269 | AB24: 60585.265 | AC24: 57652.009 | AD24: 54301.761 | AE24: 51633.698 | AF24: 50367.184 | AG24: =+SUM(I24:AF24)*H24 -> 27026313
E25: 46113 | G25: SA | H25: 4 | I25: 47490.138 | J25: 46416.194 | K25: 46022.107 | L25: 45821.528 | M25: 45424.94 | N25: 46440.259 | O25: 49125.483 | P25: 56191.442 | Q25: 54130.09 | R25: 49931.013 | S25: 50903.099 | T25: 49558.574 | U25: 48033.241 | V25: 48120.144 | W25: 56452.589 | X25: 61153.675 | Y25: 60804.788 | Z25: 61647.63 | AA25: 59258.595 | AB25: 58040.207 | AC25: 55552.582 | AD25: 52174.457 | AE25: 49408.539 | AF25: 47982.112 | AG25: =+SUM(I25:AF25)*H25 -> 4984333.7
E26: 46113 | G26: DO | H26: 4 | I26: 44299.376 | J26: 43853.842 | K26: 43589.512 | L26: 43382.348 | M26: 43678.469 | N26: 43248.316 | O26: 41542.633 | P26: 35674.919 | Q26: 30920.87 | R26: 25320.686 | S26: 25803.986 | T26: 28227.096 | U26: 32402.778 | V26: 34175.222 | W26: 43222.267 | X26: 43991.874 | Y26: 44028.003 | Z26: 44212.121 | AA26: 43758.651 | AB26: 43959.159 | AC26: 43441.561 | AD26: 43032.5 | AE26: 42881.838 | AF26: 42482.418 | AG26: =+SUM(I26:AF26)*H26 -> 3804521.8
E27: 46113 | G27: FE | H27: 2 | I27: 46098.862 | J27: 45547.092 | K27: 45284.453 | L27: 45060.048 | M27: 45004.301 | N27: 42984.396 | O27: 43063.418 | P27: 41392.971 | Q27: 38444.454 | R27: 33837.53 | S27: 34553.722 | T27: 37645.809 | U27: 41127.369 | V27: 43013.19 | W27: 42035.036 | X27: 42579.696 | Y27: 42174.96 | Z27: 42934.756 | AA27: 42797.731 | AB27: 43264.597 | AC27: 42279.934 | AD27: 41715.161 | AE27: 41413.558 | AF27: 40977.04 | AG27: =+SUM(I27:AF27)*H27 -> 2010460.2
E28: 46113 | G28: TOTAL | H28: =+SUM(H24:H27) -> 30 | I28: =+SUMPRODUCT(I24:I27,$H24:$H27) -> 1431141.6 | J28: =+SUMPRODUCT(J24:J27,$H24:$H27) -> 1402270.9 | K28: =+SUMPRODUCT(K24:K27,$H24:$H27) -> 1386954.5 | L28: =+SUMPRODUCT(L24:L27,$H24:$H27) -> 1384571 | M28: =+SUMPRODUCT(M24:M27,$H24:$H27) -> 1375630 | N28: =+SUMPRODUCT(N24:N27,$H24:$H27) -> 1401021.4 | O28: =+SUMPRODUCT(O24:O27,$H24:$H27) -> 1467731.4 | P28: =+SUMPRODUCT(P24:P27,$H24:$H27) -> 1570978.1 | ... AF28: =+SUMPRODUCT(AF24:AF27,$H24:$H27) -> 1451155.9 | AG28: =SUM(I28:AF28) -> 37825628
E29: 46143 | F29: =+AG33 -> 39202114 | G29: OR | H29: 19 | I29: 49318.953 | J29: 48237.89 | K29: 47630.447 | L29: 47612.319 | M29: 47182.857 | N29: 48464.222 | O29: 51466.902 | P29: 56484.071 | Q29: 59356.372 | R29: 57007.966 | S29: 61419.182 | T29: 63208.113 | U29: 62115.235 | V29: 63459.31 | W29: 65344.014 | X29: 66494.69 | Y29: 65802.362 | Z29: 65747.974 | AA29: 62862.149 | AB29: 61069.962 | AC29: 58177.099 | AD29: 54897.242 | AE29: 52290.967 | AF29: 51039.143 | AG29: =+SUM(I29:AF29)*H29 -> 25967099
E30: 46143 | G30: SA | H30: 5 | I30: 47959.355 | J30: 46900.995 | K30: 46531.51 | L30: 46357.071 | M30: 45957.563 | N30: 46924.133 | O30: 49552.766 | P30: 55671.091 | Q30: 50084.236 | R30: 49133.308 | S30: 52529.623 | T30: 53243.647 | U30: 52040.851 | V30: 54783.144 | W30: 57518.408 | X30: 61438.36 | Y30: 61079.75 | Z30: 61942.759 | AA30: 59584.628 | AB30: 58443.667 | AC30: 56007.331 | AD30: 52701.852 | AE30: 50008.153 | AF30: 48608.336 | AG30: =+SUM(I30:AF30)*H30 -> 6325012.7
E31: 46143 | G31: DO | H31: 5 | I31: 44773.394 | J31: 44351.988 | K31: 44082.139 | L31: 43893.737 | M31: 44179.894 | N31: 43800.484 | O31: 41676.618 | P31: 35367.538 | Q31: 26728.517 | R31: 24362.831 | S31: 27259.231 | T31: 31759.35 | U31: 36285.799 | V31: 40731.191 | W31: 43590.548 | X31: 44342.089 | Y31: 44380.167 | Z31: 44598.866 | AA31: 44121.657 | AB31: 44376.25 | AC31: 43914.116 | AD31: 43570.261 | AE31: 43443.464 | AF31: 43079.658 | AG31: =+SUM(I31:AF31)*H31 -> 4843348.9
E32: 46143 | G32: FE | H32: 2 | I32: 47377.551 | J32: 46830.977 | K32: 46553.067 | L32: 46071.898 | M32: 46389.362 | N32: 44287.005 | O32: 44518.461 | P32: 41096.41 | Q32: 34263.771 | R32: 32886.375 | S32: 36015.556 | T32: 41186.153 | U32: 45019.72 | V32: 47083.138 | W32: 43078.916 | X32: 43582.463 | Y32: 43135.587 | Z32: 44019.375 | AA32: 43887.268 | AB32: 44495.942 | AC32: 43531.131 | AD32: 42987.14 | AE32: 42709.551 | AF32: 42319.435 | AG32: =+SUM(I32:AF32)*H32 -> 2066652.5
E33: 46143 | G33: TOTAL | H33: =+SUM(H29:H32) -> 31 | I33: =+SUMPRODUCT(I29:I32,$H29:$H32) -> 1495479 | J33: =+SUMPRODUCT(J29:J32,$H29:$H32) -> 1466446.8 | K33: =+SUMPRODUCT(K29:K32,$H29:$H32) -> 1451152.9 | L33: =+SUMPRODUCT(L29:L32,$H29:$H32) -> 1448031.9 | M33: =+SUMPRODUCT(M29:M32,$H29:$H32) -> 1439940.3 | N33: =+SUMPRODUCT(N29:N32,$H29:$H32) -> 1463017.3 | O33: =+SUMPRODUCT(O29:O32,$H29:$H32) -> 1523055 | P33: =+SUMPRODUCT(P29:P32,$H29:$H32) -> 1610583.3 | ... AF33: =+SUMPRODUCT(AF29:AF32,$H29:$H32) -> 1512822.6 | AG33: =SUM(I33:AF33) -> 39202114
E34: 46174 | F34: =+AG38 -> 37941686 | G34: OR | H34: 19 | I34: 50264.024 | J34: 49179.972 | K34: 48570.454 | L34: 48557.68 | M34: 48113.627 | N34: 49414.019 | O34: 52445.651 | P34: 57818.587 | Q34: 58883.935 | R34: 53334.923 | S34: 55126.274 | T34: 58430.826 | U34: 58023.833 | V34: 64523.564 | W34: 66406.673 | X34: 67540.342 | Y34: 66846.394 | Z34: 66770.999 | AA34: 63868.005 | AB34: 62055.453 | AC34: 59157.82 | AD34: 55863.435 | AE34: 53248.607 | AF34: 51997.054 | AG34: =+SUM(I34:AF34)*H34 -> 25962401
E35: 46174 | G35: SA | H35: 4 | I35: 49121.847 | J35: 48059.619 | K35: 47683.878 | L35: 47496.228 | M35: 47082.007 | N35: 48055.538 | O35: 51911.309 | P35: 55136.237 | Q35: 50858.849 | R35: 45636.135 | S35: 46326.036 | T35: 48427.576 | U35: 45886.366 | V35: 52071.621 | W35: 59212.138 | X35: 62655.673 | Y35: 62303.85 | Z35: 63154.298 | AA35: 60779.59 | AB35: 59625.212 | AC35: 57173.96 | AD35: 53840.994 | AE35: 51115.9 | AF35: 49709.984 | AG35: =+SUM(I35:AF35)*H35 -> 5053299.4
E36: 46174 | G36: DO | H36: 4 | I36: 45824.627 | J36: 45390.564 | K36: 45115.738 | L36: 44920.7 | M36: 45216.789 | N36: 45211.388 | O36: 40461.227 | P36: 34667.634 | Q36: 27710.37 | R36: 21090.588 | S36: 21295.353 | T36: 27157.188 | U36: 30307.134 | V36: 38171.818 | W36: 44603.339 | X36: 45369.835 | Y36: 45407.621 | Z36: 45625.332 | AA36: 45144.352 | AB36: 45399.88 | AC36: 44926.47 | AD36: 44574.346 | AE36: 44446.26 | AF36: 44071.806 | AG36: =+SUM(I36:AF36)*H36 -> 3848441.4
E37: 46174 | G37: FE | H37: 3 | I37: 48369.694 | J37: 47806.086 | K37: 46444.731 | L37: 45729.658 | M37: 46046.232 | N37: 45681.44 | O37: 43302.381 | P37: 40382.966 | Q37: 35230.144 | R37: 29605.442 | S37: 30043.009 | T37: 36573.171 | U37: 39028.754 | V37: 47007.347 | W37: 45051.663 | X37: 44607.658 | Y37: 44160.959 | Z37: 45034.001 | AA37: 44901.759 | AB37: 45495.892 | AC37: 44506.344 | AD37: 43939.339 | AE37: 43653.042 | AF37: 43246.25 | AG37: =+SUM(I37:AF37)*H37 -> 3077543.9
E38: 46174 | G38: TOTAL | H38: =+SUM(H34:H37) -> 30 | I38: =+SUMPRODUCT(I34:I37,$H34:$H37) -> 1479911.4 | J38: =+SUMPRODUCT(J34:J37,$H34:$H37) -> 1451638.5 | K38: =+SUMPRODUCT(K34:K37,$H34:$H37) -> 1433371.3 | L38: =+SUMPRODUCT(L34:L37,$H34:$H37) -> 1429452.6 | M38: =+SUMPRODUCT(M34:M37,$H34:$H37) -> 1421492.8 | N38: =+SUMPRODUCT(N34:N37,$H34:$H37) -> 1448978.4 | O38: =+SUMPRODUCT(O34:O37,$H34:$H37) -> 1495864.7 | P38: =+SUMPRODUCT(P34:P37,$H34:$H37) -> 1578917.5 | ... AF38: =+SUMPRODUCT(AF34:AF37,$H34:$H37) -> 1492809.9 | AG38: =SUM(I38:AF38) -> 37941686
E39: 46204 | F39: =+AG43 -> 40137511 | G39: OR | H39: 22 | I39: 50077.112 | J39: 48995.241 | K39: 48386.941 | L39: 48367.78 | M39: 47939.078 | N39: 49223.184 | O39: 52234.555 | P39: 57260.449 | Q39: 61472.712 | R39: 55222.389 | S39: 59118.588 | T39: 59610.943 | U39: 58207.189 | V39: 64255.292 | W39: 66140.834 | X39: 67290.556 | Y39: 66597.099 | Z39: 66538.619 | AA39: 63646.254 | AB39: 61850.555 | AC39: 58952.603 | AD39: 55667.047 | AE39: 53055.749 | AF39: 51801.916 | AG39: =+SUM(I39:AF39)*H39 -> 30182079
E40: 46204 | G40: SA | H40: 4 | I40: 48792.956 | J40: 47733.575 | K40: 47363.114 | L40: 47187.983 | M40: 46788.616 | N40: 47755.561 | O40: 50831.601 | P40: 57163.555 | Q40: 53305.986 | R40: 47386.121 | S40: 50176.18 | T40: 49453.203 | U40: 45934.112 | V40: 52364.443 | W40: 56969.121 | X40: 62283.162 | Y40: 61923.86 | Z40: 62785.458 | AA40: 60426.321 | AB40: 59283.074 | AC40: 56843.046 | AD40: 53533.106 | AE40: 50835.293 | AF40: 49434.402 | AG40: =+SUM(I40:AF40)*H40 -> 5066215.4
E41: 46204 | G41: DO | H41: 4 | I41: 45258.396 | J41: 44843.208 | K41: 44572.59 | L41: 44388.547 | M41: 44675.534 | N41: 44337.673 | O41: 41582.776 | P41: 36445.862 | Q41: 29833.097 | R41: 22487.124 | S41: 24770.308 | T41: 27848.746 | U41: 30079.649 | V41: 38225.52 | W41: 44021.263 | X41: 44772.38 | Y41: 44812.599 | Z41: 45041.019 | AA41: 44555.9 | AB41: 44829.701 | AC41: 44388.107 | AD41: 44065.598 | AE41: 43949.356 | AF41: 43594.141 | AG41: =+SUM(I41:AF41)*H41 -> 3853516.4
E42: 46204 | G42: FE | H42: 1 | I42: 48057.956 | J42: 47508.785 | K42: 47140.691 | L42: 46259.568 | M42: 46576.722 | N42: 45259.385 | O42: 44426.279 | P42: 42184.794 | Q42: 37379.76 | R42: 31017.878 | S42: 33533.943 | T42: 37284.408 | U42: 38823.39 | V42: 47082.219 | W42: 45756.483 | X42: 44354.535 | Y42: 43913.627 | Z42: 44782.52 | AA42: 44649.029 | AB42: 45242.322 | AC42: 44272.064 | AD42: 43717.337 | AE42: 43435.515 | AF42: 43041.124 | AG42: =+SUM(I42:AF42)*H42 -> 1035700.3
E43: 46204 | G43: TOTAL | H43: =+SUM(H39:H42) -> 31 | I43: =+SUMPRODUCT(I39:I42,$H39:$H42) -> 1525959.8 | J43: =+SUMPRODUCT(J39:J42,$H39:$H42) -> 1495711.2 | K43: =+SUMPRODUCT(K39:K42,$H39:$H42) -> 1479396.2 | L43: =+SUMPRODUCT(L39:L42,$H39:$H42) -> 1476656.8 | M43: =+SUMPRODUCT(M39:M42,$H39:$H42) -> 1467093 | N43: =+SUMPRODUCT(N39:N42,$H39:$H42) -> 1496542.4 | O43: =+SUMPRODUCT(O39:O42,$H39:$H42) -> 1563244 | P43: =+SUMPRODUCT(P39:P42,$H39:$H42) -> 1676352.3 | ... AF43: =+SUMPRODUCT(AF39:AF42,$H39:$H42) -> 1554797.4 | AG43: =SUM(I43:AF43) -> 40137511
...

Sheet PRODUCTO 02
C1: CP-GNCC2025-002
C2: CP-GNCC2025-002-PROD02
C3: CANTIDAD EN: | D3: KWh
C4: MODALIDAD: | D4: PAGUE LO CONTRATADO
C5: OFERENTE:
C9: MES DE SUMINISTRO | D9: ENERGÍA SOLICITADA (KWh) | E9: % ENERGÍA OFRECIDA | F9: ENERGÍA OFRECIDA (KWh) | G9: PRECIO OFERTADO ($/KWh)
C10: 46388 | D10: =+_xlfn.XLOOKUP(C10,'Cantidades horarias PROD 02'!E:E,'Cantidades horarias PROD 02'!F:F) -> 11440518 | E10: 1 | F10: =ROUND(D10*$E10,2) -> 11440518
C11: 46419 | D11: =+_xlfn.XLOOKUP(C11,'Cantidades horarias PROD 02'!E:E,'Cantidades horarias PROD 02'!F:F) -> 10200418 | E11: 1 | F11: =ROUND(D11*$E11,2) -> 10200418
C12: 46447 | D12: =+_xlfn.XLOOKUP(C12,'Cantidades horarias PROD 02'!E:E,'Cantidades horarias PROD 02'!F:F) -> 11568663 | E12: 1 | F12: =ROUND(D12*$E12,2) -> 11568663
C13: 46478 | D13: =+_xlfn.XLOOKUP(C13,'Cantidades horarias PROD 02'!E:E,'Cantidades horarias PROD 02'!F:F) -> 11416737 | E13: 1 | F13: =ROUND(D13*$E13,2) -> 11416737
C14: 46508 | D14: =+_xlfn.XLOOKUP(C14,'Cantidades horarias PROD 02'!E:E,'Cantidades horarias PROD 02'!F:F) -> 12949904 | E14: 1 | F14: =ROUND(D14*$E14,2) -> 12949904
C15: 46539 | D15: =+_xlfn.XLOOKUP(C15,'Cantidades horarias PROD 02'!E:E,'Cantidades horarias PROD 02'!F:F) -> 11118312 | E15: 1 | F15: =ROUND(D15*$E15,2) -> 11118312
C16: 46569 | D16: =+_xlfn.XLOOKUP(C16,'Cantidades horarias PROD 02'!E:E,'Cantidades horarias PROD 02'!F:F) -> 11391158 | E16: 1 | F16: =ROUND(D16*$E16,2) -> 11391158
C17: 46600 | D17: =+_xlfn.XLOOKUP(C17,'Cantidades horarias PROD 02'!E:E,'Cantidades horarias PROD 02'!F:F) -> 11268128 | E17: 1 | F17: =ROUND(D17*$E17,2) -> 11268128
C18: 46631 | D18: =+_xlfn.XLOOKUP(C18,'Cantidades horarias PROD 02'!E:E,'Cantidades horarias PROD 02'!F:F) -> 11165385 | E18: 1 | F18: =ROUND(D18*$E18,2) -> 11165385
C19: 46661 | D19: =+_xlfn.XLOOKUP(C19,'Cantidades horarias PROD 02'!E:E,'Cantidades horarias PROD 02'!F:F) -> 11392405 | E19: 1 | F19: =ROUND(D19*$E19,2) -> 11392405
C20: 46692 | D20: =+_xlfn.XLOOKUP(C20,'Cantidades horarias PROD 02'!E:E,'Cantidades horarias PROD 02'!F:F) -> 11092068 | E20: 1 | F20: =ROUND(D20*$E20,2) -> 11092068
C21: 46722 | D21: =+_xlfn.XLOOKUP(C21,'Cantidades horarias PROD 02'!E:E,'Cantidades horarias PROD 02'!F:F) -> 11426856 | E21: 1 | F21: =ROUND(D21*$E21,2) -> 11426856
C22: TOTAL | D22: =SUM(D10:D21) -> 1.3643055e+08 | E22: =IFERROR(F22/D22,0) -> 1 | F22: =SUM(F10:F21) -> 1.3643055e+08 | G22: =G10 -> 0
D24: Relacion ≥ | E24: 0.8
D25: Relacion: | E25: =MIN(E10:E21)/MAX(E10:E21) -> 1
C26: Nota
C27: 1. $/kWh expresados en pesos de julio de 2025.
C28: 2. La energia ofertada se despachara conforme a las cantidades horarias de este anexo
C32: XXXXXXXXXXXXXXXXXXXXXXXX
C33: REPRESENTANTE LEGAL
C34: XXXXXXXXXXXXXXXXXXXXXX S.A E.S.P

Sheet Cantidades horarias PROD 02
E1: CUADRO DE CANTIDADES HORARIAS OFRECIDAS
E2: CANTIDADES DE ENERGIA (KWh) - PRODUCTO 2
E4: PAGUE LO CONTRATADO
E5: OFERENTE:
E8: MES | F8: Cantidad Ofrecida | G8: Tipo de día | H8: N° días mes | I8: H1 | J8: H2 | K8: H3 | L8: H4 | M8: H5 | N8: H6 | O8: H7 | P8: H8 | Q8: H9 | R8: H10 | S8: H11 | T8: H12 | U8: H13 | V8: H14 | W8: H15 | X8: H16 | Y8: H17 | Z8: H18 | AA8: H19 | AB8: H20 | AC8: H21 | AD8: H22 | AE8: H23 | AF8: H24 | AG8: TOTAL
E9: 46388 | F9: =+AG13 -> 11440518 | G9: OR | H9: 19 | I9: 14619.285 | J9: 14324.808 | K9: 14148.61 | L9: 14098.365 | M9: 14101.837 | N9: 14389.626 | O9: 15199.684 | P9: 16068.333 | Q9: 16626.62 | R9: 16341.103 | S9: 16876.252 | T9: 17113.527 | U9: 16945.573 | V9: 17439.311 | W9: 18320.417 | X9: 19179.924 | Y9: 19625.981 | Z9: 19809.92 | AA9: 19140.614 | AB9: 18553.633 | AC9: 17718.057 | AD9: 16607.472 | AE9: 15661.91 | AF9: 15169.486 | AG9: =ROUND(SUM(I9:AF9)*H9,2) -> 7563526.7
G10: SA | H10: 5 | I10: 14632.925 | J10: 14318.894 | K10: 14123.78 | L10: 14039.773 | M10: 14010.899 | N10: 14152.925 | O10: 14645.999 | P10: 15116.821 | Q10: 13733.816 | R10: 12131.126 | S10: 13525.767 | T10: 13534.426 | U10: 13112.45 | V10: 13967.519 | W10: 16119.03 | X10: 16891.267 | Y10: 17490.386 | Z10: 18163.905 | AA10: 17899.323 | AB10: 17521.796 | AC10: 16856.11 | AD10: 15829.622 | AE10: 14951.039 | AF10: 14464.097 | AG10: =ROUND(SUM(I10:AF10)*H10,2) -> 1806168.5
G11: DO | H11: 5 | I11: 13882.926 | J11: 13636.02 | K11: 13473.96 | L11: 13365.201 | M11: 13357.171 | N11: 13213.7 | O11: 12903.949 | P11: 9402.7606 | Q11: 5641.948 | R11: 3743.7538 | S11: 4855.3642 | T11: 6587.8234 | U11: 8500.452 | V11: 10583.808 | W11: 13342.986 | X11: 14153.514 | Y11: 14914.817 | Z11: 15658.426 | AA11: 15731.04 | AB11: 15564.127 | AC11: 15093.303 | AD11: 14577.941 | AE11: 14149.143 | AF11: 13822.533 | AG11: =ROUND(SUM(I11:AF11)*H11,2) -> 1450783.3
G12: FE | H12: 2 | I12: 14123.325 | J12: 13886.326 | K12: 13737.982 | L12: 13638.78 | M12: 13630.762 | N12: 13389.667 | O12: 13086.598 | P12: 10335.678 | Q12: 8511.9383 | R12: 7444.2837 | S12: 8283.27 | T12: 9254.0064 | U12: 9875.2517 | V12: 12019.638 | W12: 13603.664 | X12: 14437.68 | Y12: 15135.979 | Z12: 15897.717 | AA12: 15938.103 | AB12: 15787.618 | AC12: 15254.677 | AD12: 14677.225 | AE12: 14206.51 | AF12: 13863.052 | AG12: =ROUND(SUM(I12:AF12)*H12,2) -> 620039.46
G13: TOTAL | H13: =+SUM(H9:H12) -> 31 | I13: =+SUMPRODUCT(I9:I12,$H9:$H12) -> 448592.32 | J13: =+SUMPRODUCT(J9:J12,$H9:$H12) -> 439718.58 | K13: =+SUMPRODUCT(K9:K12,$H9:$H12) -> 434288.26 | L13: =+SUMPRODUCT(L9:L12,$H9:$H12) -> 432171.37 | M13: =+SUMPRODUCT(M9:M12,$H9:$H12) -> 432036.78 | N13: =+SUMPRODUCT(N9:N12,$H9:$H12) -> 437015.36 | O13: =+SUMPRODUCT(O9:O12,$H9:$H12) -> 452716.94 | P13: =+SUMPRODUCT(P9:P12,$H9:$H12) -> 448567.58 | ... AF13: =+SUMPRODUCT(AF9:AF12,$H9:$H12) -> 457379.48 | AG13: =SUM(I13:AF13) -> 11440518
E14: 46419 | F14: =+AG18 -> 10200418 | G14: OR | H14: 20 | I14: 14355.851 | J14: 14043.258 | K14: 13842.248 | L14: 13780.028 | M14: 13708.103 | N14: 13927.919 | O14: 14348.049 | P14: 14762.611 | Q14: 15055.728 | R14: 14962.98 | S14: 15213.16 | T14: 15557.766 | U14: 15648.227 | V14: 16062.041 | W14: 16721.35 | X14: 17585.339 | Y14: 18230.674 | Z14: 18905.846 | AA14: 18541.904 | AB14: 18083.716 | AC14: 17273.459 | AD14: 16299.446 | AE14: 15489.734 | AF14: 15036.97 | AG14: =+SUM(I14:AF14)*H14 -> 7548728.1
E15: =+E14 -> 46419 | G15: SA | H15: 4 | I15: 14479.459 | J15: 14186.219 | K15: 14035.517 | L15: 13953.539 | M15: 13948.815 | N15: 14186.99 | O15: 14902.435 | P15: 15699.455 | Q15: 14140.354 | R15: 12130.14 | S15: 12968.003 | T15: 13257.814 | U15: 13324.758 | V15: 15024.669 | W15: 16861.145 | X15: 18453.308 | Y15: 18950.762 | Z15: 19265.153 | AA15: 18671.962 | AB15: 18182.037 | AC15: 17412.218 | AD15: 16304.435 | AE15: 15351.361 | AF15: 14835.356 | AG15: =+SUM(I15:AF15)*H15 -> 1482103.6
E16: =+E15 -> 46419 | G16: DO | H16: 4 | I16: 13979.567 | J16: 13728.886 | K16: 13560.619 | L16: 13449.12 | M16: 13444.8 | N16: 13294.343 | O16: 12972.425 | P16: 9696.8997 | Q16: 6014.6104 | R16: 3726.1693 | S16: 4263.2147 | T16: 6268.4199 | U16: 8655.8665 | V16: 11592.116 | W16: 13414.32 | X16: 14230.416 | Y16: 14991.202 | Z16: 15738.088 | AA16: 15805.311 | AB16: 15643.698 | AC16: 15167.176 | AD16: 14649.868 | AE16: 14219.816 | AF16: 13889.512 | AG16: =+SUM(I16:AF16)*H16 -> 1169585.9
E17: =+E16 -> 46419 | G17: FE | H17: 0 | I17: 0 | J17: 0 | K17: 0 | L17: 0 | M17: 0 | N17: 0 | O17: 0 | P17: 0 | Q17: 0 | R17: 0 | S17: 0 | T17: 0 | U17: 0 | V17: 0 | W17: 0 | X17: 0 | Y17: 0 | Z17: 0 | AA17: 0 | AB17: 0 | AC17: 0 | AD17: 0 | AE17: 0 | AF17: 0 | AG17: =+SUM(I17:AF17)*H17 -> 0
E18: =+E17 -> 46419 | G18: TOTAL | H18: =+SUM(H14:H17) -> 28 | I18: =+SUMPRODUCT(I14:I17,$H14:$H17) -> 400953.13 | J18: =+SUMPRODUCT(J14:J17,$H14:$H17) -> 392525.57 | K18: =+SUMPRODUCT(K14:K17,$H14:$H17) -> 387229.51 | L18: =+SUMPRODUCT(L14:L17,$H14:$H17) -> 385211.2 | M18: =+SUMPRODUCT(M14:M17,$H14:$H17) -> 383736.52 | N18: =+SUMPRODUCT(N14:N17,$H14:$H17) -> 388483.7 | O18: =+SUMPRODUCT(O14:O17,$H14:$H17) -> 398460.42 | P18: =+SUMPRODUCT(P14:P17,$H14:$H17) -> 396837.63 | ... AF18: =+SUMPRODUCT(AF14:AF17,$H14:$H17) -> 415638.88 | AG18: =SUM(I18:AF18) -> 10200418
E19: 46447 | F19: =+AG23 -> 11568663 | G19: OR | H19: 20 | I19: 14529.859 | J19: 14236.508 | K19: 14058.461 | L19: 14008.626 | M19: 14003.945 | N19: 14276.595 | O19: 15054.051 | P19: 15909.531 | Q19: 16456.001 | R19: 16402.235 | S19: 16685.887 | T19: 16916.932 | U19: 16751.405 | V19: 17250.999 | W19: 18132.45 | X19: 18990.126 | Y19: 19435.223 | Z19: 19625.374 | AA19: 18970.798 | AB19: 18402.083 | AC19: 17574.677 | AD19: 16481.912 | AE19: 15553.659 | AF19: 15066 | AG19: =+SUM(I19:AF19)*H19 -> 7895466.7
E20: =+E19 -> 46447 | G20: SA | H20: 4 | I20: 14572.675 | J20: 14263.351 | K20: 14072.348 | L20: 13992.08 | M20: 13956.549 | N20: 14088.07 | O20: 14565.233 | P20: 15030.791 | Q20: 15338.984 | R20: 15143.739 | S20: 15467.779 | T20: 15465.952 | U20: 15387.84 | V20: 15585.235 | W20: 16035.812 | X20: 16803.999 | Y20: 17402.424 | Z20: 18074.842 | AA20: 17811.875 | AB20: 17453.748 | AC20: 16795.216 | AD20: 15778.573 | AE20: 14909.005 | AF20: 14427.894 | AG20: =+SUM(I20:AF20)*H20 -> 1489696
E21: =+E20 -> 46447 | G21: DO | H21: 4 | I21: 13980.28 | J21: 13729.896 | K21: 13560.119 | L21: 13452.84 | M21: 13422.926 | N21: 13195.175 | O21: 12807.407 | P21: 12189.946 | Q21: 9126.0922 | R21: 6535.7476 | S21: 6938.0642 | T21: 8534.3118 | U21: 10819.699 | V21: 12650.061 | W21: 13215.104 | X21: 14031.496 | Y21: 14766.076 | Z21: 15554.281 | AA21: 15635.408 | AB21: 15498.802 | AC21: 15004.961 | AD21: 14491.828 | AE21: 14055.898 | AF21: 13733.025 | AG21: =+SUM(I21:AF21)*H21 -> 1227717.8
E22: =+E21 -> 46447 | G22: FE | H22: 3 | I22: 14018.302 | J22: 13783.685 | K22: 13630.857 | L22: 13535.223 | M22: 13516.033 | N22: 13239.045 | O22: 12891.283 | P22: 12595.52 | Q22: 10444.655 | R22: 9022.905 | S22: 9411.2869 | T22: 10352.612 | U22: 12423.224 | V22: 12966.866 | W22: 13361.277 | X22: 14193.012 | Y22: 14877.002 | Z22: 15675.3 | AA22: 15714.949 | AB22: 15604.934 | AC22: 15074.798 | AD22: 14508.218 | AE22: 14042.964 | AF22: 13710.045 | AG22: =+SUM(I22:AF22)*H22 -> 955781.99
E23: =+E22 -> 46447 | G23: TOTAL | H23: =+SUM(H19:H22) -> 31 | I23: =+SUMPRODUCT(I19:I22,$H19:$H22) -> 446863.9 | J23: =+SUMPRODUCT(J19:J22,$H19:$H22) -> 438054.21 | K23: =+SUMPRODUCT(K19:K22,$H19:$H22) -> 432591.67 | L23: =+SUMPRODUCT(L19:L22,$H19:$H22) -> 430557.87 | M23: =+SUMPRODUCT(M19:M22,$H19:$H22) -> 430144.9 | N23: =+SUMPRODUCT(N19:N22,$H19:$H22) -> 434382.01 | O23: =+SUMPRODUCT(O19:O22,$H19:$H22) -> 449245.43 | P23: =+SUMPRODUCT(P19:P22,$H19:$H22) -> 464860.12 | ... AF23: =+SUMPRODUCT(AF19:AF22,$H19:$H22) -> 455093.81 | AG23: =SUM(I23:AF23) -> 11568663
E24: 46478 | F24: =+AG28 -> 11416737 | G24: OR | H24: 22 | I24: 14822.221 | J24: 14508.073 | K24: 14304.518 | L24: 14237.874 | M24: 14167.086 | N24: 14375.249 | O24: 14787.651 | P24: 15209.715 | Q24: 15508.037 | R24: 15424.869 | S24: 15674.916 | T24: 16021.267 | U24: 16110.481 | V24: 16527.392 | W24: 17190.195 | X24: 18056.295 | Y24: 18698.281 | Z24: 19371.986 | AA24: 19004.484 | AB24: 18555.348 | AC24: 17739.611 | AD24: 16766.669 | AE24: 15957.587 | AF24: 15502.235 | AG24: =+SUM(I24:AF24)*H24 -> 8547484.9
E25: =+E24 -> 46478 | G25: SA | H25: 4 | I25: 14800.775 | J25: 14506.538 | K25: 14356.957 | L25: 14278.625 | M25: 14276.065 | N25: 14506.094 | O25: 15214.638 | P25: 16012.431 | Q25: 16491.908 | R25: 16390.757 | S25: 16657.082 | T25: 16736.459 | U25: 16502.12 | V25: 16412.756 | W25: 17943.422 | X25: 18781.279 | Y25: 19273.174 | Z25: 19586.973 | AA25: 18997.326 | AB25: 18513.493 | AC25: 17739.337 | AD25: 16629.464 | AE25: 15676.332 | AF25: 15161.444 | AG25: =+SUM(I25:AF25)*H25 -> 1581781.8
E26: =+E25 -> 46478 | G26: DO | H26: 4 | I26: 14289.937 | J26: 14040.969 | K26: 13868.68 | L26: 13760.333 | M26: 13751.507 | N26: 13611.361 | O26: 13291.632 | P26: 12433.309 | Q26: 10354.154 | R26: 8264.1852 | S26: 8695.8288 | T26: 9751.4791 | U26: 11845.701 | V26: 13017.032 | W26: 13728.89 | X26: 14538.852 | Y26: 15297.394 | Z26: 16051.118 | AA26: 16114.127 | AB26: 15957.702 | AC26: 15481.134 | AD26: 14969.843 | AE26: 14538.26 | AF26: 14214.044 | AG26: =+SUM(I26:AF26)*H26 -> 1287469.9
E27: =+E26 -> 46478 | G27: FE | H27: 0 | I27: 0 | J27: 0 | K27: 0 | L27: 0 | M27: 0 | N27: 0 | O27: 0 | P27: 0 | Q27: 0 | R27: 0 | S27: 0 | T27: 0 | U27: 0 | V27: 0 | W27: 0 | X27: 0 | Y27: 0 | Z27: 0 | AA27: 0 | AB27: 0 | AC27: 0 | AD27: 0 | AE27: 0 | AF27: 0 | AG27: =+SUM(I27:AF27)*H27 -> 0
E28: =+E27 -> 46478 | G28: TOTAL | H28: =+SUM(H24:H27) -> 30 | I28: =+SUMPRODUCT(I24:I27,$H24:$H27) -> 442451.72 | J28: =+SUMPRODUCT(J24:J27,$H24:$H27) -> 433367.64 | K28: =+SUMPRODUCT(K24:K27,$H24:$H27) -> 427601.95 | L28: =+SUMPRODUCT(L24:L27,$H24:$H27) -> 425389.06 | M28: =+SUMPRODUCT(M24:M27,$H24:$H27) -> 423786.18 | N28: =+SUMPRODUCT(N24:N27,$H24:$H27) -> 428725.28 | O28: =+SUMPRODUCT(O24:O27,$H24:$H27) -> 439353.4 | P28: =+SUMPRODUCT(P24:P27,$H24:$H27) -> 448396.7 | ... AF28: =+SUMPRODUCT(AF24:AF27,$H24:$H27) -> 458551.13 | AG28: =SUM(I28:AF28) -> 11416737
E29: 46508 | F29: =+AG33 -> 12949904 | G29: OR | H29: 19 | I29: 16451.819 | J29: 16156.555 | K29: 15976.07 | L29: 15924.164 | M29: 15916.842 | N29: 16185.407 | O29: 16964.32 | P29: 17832.141 | Q29: 18390.7 | R29: 18347.983 | S29: 18634.77 | T29: 18869.068 | U29: 18699.103 | V29: 19202.166 | W29: 20085.887 | X29: 20941.019 | Y29: 21383.17 | Z29: 21567.02 | AA29: 20905.416 | AB29: 20338.479 | AC29: 19505.631 | AD29: 18409.99 | AE29: 17479.981 | AF29: 16990.379 | AG29: =+SUM(I29:AF29)*H29 -> 8382003.5
E30: =+E29 -> 46508 | G30: SA | H30: 4 | I30: 16462.316 | J30: 16152.24 | K30: 15961.719 | L30: 15881.818 | M30: 15843.642 | N30: 15968.982 | O30: 16444.03 | P30: 16916.113 | Q30: 17229.47 | R30: 17148.222 | S30: 17368.653 | T30: 17487.765 | U30: 17319.044 | V30: 17490.566 | W30: 17938.237 | X30: 18701.681 | Y30: 19297.775 | Z30: 19967.682 | AA30: 19704.4 | AB30: 19351.097 | AC30: 18688.824 | AD30: 17667.803 | AE30: 16794.108 | AF30: 16313.636 | AG30: =+SUM(I30:AF30)*H30 -> 1672399.3
E31: =+E30 -> 46508 | G31: DO | H31: 5 | I31: 15744.76 | J31: 15499.285 | K31: 15326.199 | L31: 15220.569 | M31: 15210.303 | N31: 15077.002 | O31: 14758.339 | P31: 13879.73 | Q31: 10999.794 | R31: 9934.5227 | S31: 10498.24 | T31: 12221.287 | U31: 14400.274 | V31: 14767.253 | W31: 15168.4 | X31: 15975.745 | Y31: 16734.568 | Z31: 17493.301 | AA31: 17552.873 | AB31: 17404.281 | AC31: 16935.744 | AD31: 16433.898 | AE31: 16005.772 | AF31: 15686.714 | AG31: =+SUM(I31:AF31)*H31 -> 1794644.3
E32: =+E31 -> 46508 | G32: FE | H32: 3 | I32: 15878.004 | J32: 15641.759 | K32: 15485.997 | L32: 15391.058 | M32: 15367.331 | N32: 15082.038 | O32: 14713.707 | P32: 14420.074 | Q32: 12522.5 | R32: 11552.407 | S32: 12173.119 | T32: 14201.138 | U32: 14565.844 | V32: 14804.203 | W32: 15188.5 | X32: 16013.753 | Y32: 16691.389 | Z32: 17506.783 | AA32: 17547.182 | AB32: 17456.324 | AC32: 16925.688 | AD32: 16359.192 | AE32: 15896.337 | AF32: 15567.916 | AG32: =+SUM(I32:AF32)*H32 -> 1100856.7
E33: =+E32 -> 46508 | G33: TOTAL | H33: =+SUM(H29:H32) -> 31 | I33: =+SUMPRODUCT(I29:I32,$H29:$H32) -> 504791.65 | J33: =+SUMPRODUCT(J29:J32,$H29:$H32) -> 496005.21 | K33: =+SUMPRODUCT(K29:K32,$H29:$H32) -> 490481.19 | L33: =+SUMPRODUCT(L29:L32,$H29:$H32) -> 488362.4 | M33: =+SUMPRODUCT(M29:M32,$H29:$H32) -> 487948.07 | N33: =+SUMPRODUCT(N29:N32,$H29:$H32) -> 492029.79 | O33: =+SUMPRODUCT(O29:O32,$H29:$H32) -> 506031.01 | P33: =+SUMPRODUCT(P29:P32,$H29:$H32) -> 519134.01 | ... AF33: =+SUMPRODUCT(AF29:AF32,$H29:$H32) -> 513209.06 | AG33: =SUM(I33:AF33) -> 12949904
E34: 46539 | F34: =+AG38 -> 11118312 | G34: OR | H34: 21 | I34: 14165.188 | J34: 13869.492 | K34: 13688.705 | L34: 13637.574 | M34: 13628.14 | N34: 13899.46 | O34: 14682.564 | P34: 15554.245 | Q34: 16117.551 | R34: 16077.027 | S34: 16365.665 | T34: 16601.067 | U34: 16429.056 | V34: 16932.798 | W34: 17816.288 | X34: 18668.954 | Y34: 19110.87 | Z34: 19291.679 | AA34: 18627.591 | AB34: 18057.704 | AC34: 17224.162 | AD34: 16126.415 | AE34: 15195.166 | AF34: 14705.609 | AG34: =+SUM(I34:AF34)*H34 -> 8115932.4
E35: =+E34 -> 46539 | G35: SA | H35: 4 | I35: 14191.866 | J35: 13881.231 | K35: 13689.802 | L35: 13607.985 | M35: 13567.679 | N35: 13694.025 | O35: 14173.094 | P35: 14650.546 | Q35: 14968.739 | R35: 14887.77 | S35: 15112.043 | T35: 15232.245 | U35: 15060.54 | V35: 15229.729 | W35: 15676.609 | X35: 16439.17 | Y35: 17036.249 | Z35: 17704.335 | AA35: 17438.651 | AB35: 17083.406 | AC35: 16418.971 | AD35: 15393.965 | AE35: 14515.727 | AF35: 14034.373 | AG35: =+SUM(I35:AF35)*H35 -> 1454755
E36: =+E35 -> 46539 | G36: DO | H36: 4 | I36: 13473.506 | J36: 13226.197 | K36: 13052.391 | L36: 12945.797 | M36: 12936.97 | N36: 12800.757 | O36: 12478.407 | P36: 12089.337 | Q36: 10373.847 | R36: 8244.2447 | S36: 8252.6554 | T36: 10914.319 | U36: 12223.397 | V36: 12490.162 | W36: 12891.578 | X36: 13701.087 | Y36: 14459.871 | Z36: 15218.458 | AA36: 15277.484 | AB36: 15129.028 | AC36: 14658.86 | AD36: 14155.814 | AE36: 13727.501 | AF36: 13406.9 | AG36: =+SUM(I36:AF36)*H36 -> 1232514.3
E37: =+E36 -> 46539 | G37: FE | H37: 1 | I37: 13632.21 | J37: 13393.5 | K37: 13237.011 | L37: 13140.669 | M37: 13118.539 | N37: 12830.625 | O37: 12459.875 | P37: 12168.035 | Q37: 11835.475 | R37: 9798.6731 | S37: 9859.8337 | T37: 12061.519 | U37: 12322.49 | V37: 12561.557 | W37: 12945.385 | X37: 13772.75 | Y37: 14450.411 | Z37: 15264.246 | AA37: 15304.628 | AB37: 15211.664 | AC37: 14677.442 | AD37: 14107.615 | AE37: 13643.497 | AF37: 13312.662 | AG37: =+SUM(I37:AF37)*H37 -> 315110.31
E38: =+E37 -> 46539 | G38: TOTAL | H38: =+SUM(H34:H37) -> 30 | I38: =+SUMPRODUCT(I34:I37,$H34:$H37) -> 421762.65 | J38: =+SUMPRODUCT(J34:J37,$H34:$H37) -> 413082.54 | K38: =+SUMPRODUCT(K34:K37,$H34:$H37) -> 407668.58 | L38: =+SUMPRODUCT(L34:L37,$H34:$H37) -> 405744.86 | M38: =+SUMPRODUCT(M34:M37,$H34:$H37) -> 405328.07 | N38: =+SUMPRODUCT(N34:N37,$H34:$H37) -> 410698.41 | O38: =+SUMPRODUCT(O34:O37,$H34:$H37) -> 427399.73 | P38: =+SUMPRODUCT(P34:P37,$H34:$H37) -> 445766.72 | ... AF38: =+SUMPRODUCT(AF34:AF37,$H34:$H37) -> 431895.55 | AG38: =SUM(I38:AF38) -> 11118312
E39: 46569 | F39: =+AG43 -> 11391158 | G39: OR | H39: 20 | I39: 14132.399 | J39: 13837.016 | K39: 13656.404 | L39: 13604.351 | M39: 13597.139 | N39: 13866.098 | O39: 14646.271 | P39: 15515.357 | Q39: 16075.099 | R39: 16033.233 | S39: 16320.729 | T39: 16555.47 | U39: 16385.121 | V39: 16888.224 | W39: 17772.064 | X39: 18627.055 | Y39: 19069.045 | Z39: 19252.302 | AA39: 18589.754 | AB39: 18022.307 | AC39: 17188.717 | AD39: 16092.252 | AE39: 15161.515 | AF39: 14671.624 | AG39: =+SUM(I39:AF39)*H39 -> 7711190.9
E40: =+E39 -> 46569 | G40: SA | H40: 5 | I40: 14138.511 | J40: 13828.287 | K40: 13637.623 | L40: 13557.62 | M40: 13519.466 | N40: 13644.86 | O40: 14120.339 | P40: 14593.021 | Q40: 14906.978 | R40: 14826.28 | S40: 15047.198 | T40: 15166.465 | U40: 14997.305 | V40: 15168.658 | W40: 15616.219 | X40: 16379.497 | Y40: 16975.495 | Z40: 17645.196 | AA40: 17381.767 | AB40: 17028.131 | AC40: 16365.324 | AD40: 15343.653 | AE40: 14469.365 | AF40: 13988.739 | AG40: =+SUM(I40:AF40)*H40 -> 1811730
E41: =+E40 -> 46569 | G41: DO | H41: 4 | I41: 13385.772 | J41: 13141.203 | K41: 12968 | L41: 12863.005 | M41: 12852.855 | N41: 12720.823 | O41: 12401.627 | P41: 12009.894 | Q41: 11193.739 | R41: 8816.582 | S41: 9527.675 | T41: 10904.811 | U41: 12133.4 | V41: 12399.252 | W41: 12801.552 | X41: 13608.833 | Y41: 14367.97 | Z41: 15128.112 | AA41: 15186.536 | AB41: 15040.726 | AC41: 14575.165 | AD41: 14076.411 | AE41: 13649.811 | AF41: 13331.998 | AG41: =+SUM(I41:AF41)*H41 -> 1236343
E42: =+E41 -> 46569 | G42: FE | H42: 2 | I42: 13581.341 | J42: 13344.721 | K42: 13188.879 | L42: 13093.598 | M42: 13070.666 | N42: 12788.808 | O42: 12423.857 | P42: 12132.145 | Q42: 11895.007 | R42: 10275.753 | S42: 11034.564 | T42: 12023.136 | U42: 12283.267 | V42: 12521.744 | W42: 12905.561 | X42: 13730.369 | Y42: 14408.867 | Z42: 15222.104 | AA42: 15262.305 | AB42: 15169.218 | AC42: 14637.791 | AD42: 14069.741 | AE42: 13606.272 | AF42: 13277.233 | AG42: =+SUM(I42:AF42)*H42 -> 631893.89
E43: =+E42 -> 46569 | G43: TOTAL | H43: =+SUM(H39:H42) -> 31 | I43: =+SUMPRODUCT(I39:I42,$H39:$H42) -> 434046.31 | J43: =+SUMPRODUCT(J39:J42,$H39:$H42) -> 425136 | K43: =+SUMPRODUCT(K39:K42,$H39:$H42) -> 419565.96 | L43: =+SUMPRODUCT(L39:L42,$H39:$H42) -> 417514.34 | M43: =+SUMPRODUCT(M39:M42,$H39:$H42) -> 417092.86 | N43: =+SUMPRODUCT(N39:N42,$H39:$H42) -> 422007.17 | O43: =+SUMPRODUCT(O39:O42,$H39:$H42) -> 437981.33 | P43: =+SUMPRODUCT(P39:P42,$H39:$H42) -> 455576.11 | ... AF43: =+SUMPRODUCT(AF39:AF42,$H39:$H42) -> 443258.64 | AG43: =SUM(I43:AF43) -> 11391158
...

Sheet PRODUCTO 03
C1: CP-GNCC2025-002
C2: CP-GNCC2025-002-PROD03
C3: CANTIDAD EN: | D3: KWh
C4: MODALIDAD: | D4: PAGUE LO CONTRATADO
C5: OFERENTE:
C9: MES DE SUMINISTRO | D9: ENERGÍA SOLICITADA (KWh) | E9: % ENERGÍA OFRECIDA | F9: ENERGÍA OFRECIDA (KWh) | G9: PRECIO OFERTADO ($/KWh)
C10: 46753 | D10: =+_xlfn.XLOOKUP(C10,'Cantidades horarias PROD 03'!E:E,'Cantidades horarias PROD 03'!F:F) -> 17638374 | E10: 1 | F10: =ROUND(D10*$E10,2) -> 17638374
C11: 46784 | D11: =+_xlfn.XLOOKUP(C11,'Cantidades horarias PROD 03'!E:E,'Cantidades horarias PROD 03'!F:F) -> 16702855 | E11: 1 | F11: =ROUND(D11*$E11,2) -> 16702855
C12: 46813 | D12: =+_xlfn.XLOOKUP(C12,'Cantidades horarias PROD 03'!E:E,'Cantidades horarias PROD 03'!F:F) -> 17698009 | E12: 1 | F12: =ROUND(D12*$E12,2) -> 17698009
C13: 46844 | D13: =+_xlfn.XLOOKUP(C13,'Cantidades horarias PROD 03'!E:E,'Cantidades horarias PROD 03'!F:F) -> 16890742 | E13: 1 | F13: =ROUND(D13*$E13,2) -> 16890742
C14: 46874 | D14: =+_xlfn.XLOOKUP(C14,'Cantidades horarias PROD 03'!E:E,'Cantidades horarias PROD 03'!F:F) -> 17388735 | E14: 1 | F14: =ROUND(D14*$E14,2) -> 17388735
C15: 46905 | D15: =+_xlfn.XLOOKUP(C15,'Cantidades horarias PROD 03'!E:E,'Cantidades horarias PROD 03'!F:F) -> 16766444 | E15: 1 | F15: =ROUND(D15*$E15,2) -> 16766444
C16: 46935 | D16: =+_xlfn.XLOOKUP(C16,'Cantidades horarias PROD 03'!E:E,'Cantidades horarias PROD 03'!F:F) -> 17160883 | E16: 1 | F16: =ROUND(D16*$E16,2) -> 17160883
C17: 46966 | D17: =+_xlfn.XLOOKUP(C17,'Cantidades horarias PROD 03'!E:E,'Cantidades horarias PROD 03'!F:F) -> 17403558 | E17: 1 | F17: =ROUND(D17*$E17,2) -> 17403558
C18: 46997 | D18: =+_xlfn.XLOOKUP(C18,'Cantidades horarias PROD 03'!E:E,'Cantidades horarias PROD 03'!F:F) -> 17115135 | E18: 1 | F18: =ROUND(D18*$E18,2) -> 17115135
C19: 47027 | D19: =+_xlfn.XLOOKUP(C19,'Cantidades horarias PROD 03'!E:E,'Cantidades horarias PROD 03'!F:F) -> 17420937 | E19: 1 | F19: =ROUND(D19*$E19,2) -> 17420937
C20: 47058 | D20: =+_xlfn.XLOOKUP(C20,'Cantidades horarias PROD 03'!E:E,'Cantidades horarias PROD 03'!F:F) -> 16804656 | E20: 1 | F20: =ROUND(D20*$E20,2) -> 16804656
C21: 47088 | D21: =+_xlfn.XLOOKUP(C21,'Cantidades horarias PROD 03'!E:E,'Cantidades horarias PROD 03'!F:F) -> 17276321 | E21: 1 | F21: =ROUND(D21*$E21,2) -> 17276321
C22: TOTAL | D22: =SUM(D10:D21) -> 2.0626665e+08 | E22: =IFERROR(F22/D22,0) -> 1 | F22: =SUM(F10:F21) -> 2.0626665e+08 | G22: =G10 -> 0
D24: Relacion ≥ | E24: 0.8
D25: Relacion: | E25: =MIN(E10:E21)/MAX(E10:E21) -> 1
C26: Nota
C27: 1. $/kWh expresados en pesos de julio de 2025.
C28: 2. La energia ofertada se despachara conforme a las cantidades horarias de este anexo
C32: XXXXXXXXXXXXXXXXXXXXXXXX
C33: REPRESENTANTE LEGAL
C34: XXXXXXXXXXXXXXXXXXXXXX S.A E.S.P

Sheet Cantidades horarias PROD 03
E1: CUADRO DE CANTIDADES HORARIAS OFRECIDAS
E2: CANTIDADES DE ENERGIA (KWh) - PRODUCTO 3
E3: PAGUE LO CONTRATADO
E5: OFERENTE:
E8: MES | F8: Cantidad Ofrecida | G8: Tipo de día | H8: N° días mes | I8: H1 | J8: H2 | K8: H3 | L8: H4 | M8: H5 | N8: H6 | O8: H7 | P8: H8 | Q8: H9 | R8: H10 | S8: H11 | T8: H12 | U8: H13 | V8: H14 | W8: H15 | X8: H16 | Y8: H17 | Z8: H18 | AA8: H19 | AB8: H20 | AC8: H21 | AD8: H22 | AE8: H23 | AF8: H24 | AG8: TOTAL
E9: 46753 | F9: =+AG13 -> 17638374 | G9: OR | H9: 20 | I9: 21592.93 | J9: 21082.225 | K9: 20749.201 | L9: 20687.654 | M9: 20691.727 | N9: 21243.448 | O9: 22997.19 | P9: 24741.596 | Q9: 26005.715 | R9: 26300.529 | S9: 27297.483 | T9: 27838.271 | U9: 27252.448 | V9: 28159.689 | W9: 29609.415 | X9: 30662.95 | Y9: 31301.63 | Z9: 31106.414 | AA9: 29794.23 | AB9: 28814.638 | AC9: 27217.294 | AD9: 25278.701 | AE9: 23459.664 | AF9: 22606.076 | AG9: =ROUND(SUM(I9:AF9)*H9,2) -> 12329822
G10: SA | H10: 4 | I10: 21477.65 | J10: 20888.61 | K10: 20578.162 | L10: 20505.39 | M10: 20473.089 | N10: 20710.742 | O10: 21668.984 | P10: 22438.655 | Q10: 23078.787 | R10: 23291.918 | S10: 24081.397 | T10: 24334.313 | U10: 23771.605 | V10: 23828.132 | W10: 24135.94 | X10: 24886.788 | Y10: 25838.775 | Z10: 26880.13 | AA10: 26648.951 | AB10: 26162.243 | AC10: 25050.994 | AD10: 23255.301 | AE10: 21657.971 | AF10: 20747.874 | AG10: =ROUND(SUM(I10:AF10)*H10,2) -> 2225569.6
G11: DO | H11: 5 | I11: 18479.722 | J11: 18032.212 | K11: 17680.169 | L11: 17479.099 | M11: 17362.2 | N11: 17190.756 | O11: 16679.615 | P11: 15886.037 | Q11: 15527.436 | R11: 15370.248 | S11: 15848.024 | T11: 16521.536 | U11: 16915.397 | V11: 17372.588 | W11: 17969.567 | X11: 19040.051 | Y11: 20452.494 | Z11: 21974.529 | AA11: 22169.745 | AB11: 21941.871 | AC11: 20975.663 | AD11: 19940.006 | AE11: 19041.766 | AF11: 18405.248 | AG11: =ROUND(SUM(I11:AF11)*H11,2) -> 2191279.9
G12: FE | H12: 2 | I12: 18909.92 | J12: 18479.676 | K12: 18159.392 | L12: 17970.325 | M12: 17839.434 | N12: 17448.346 | O12: 16910.327 | P12: 16262.754 | Q12: 16016.523 | R12: 15890.483 | S12: 16427.527 | T12: 16954.996 | U12: 17246.252 | V12: 17641.826 | W12: 18256.598 | X12: 19396.801 | Y12: 20712.369 | Z12: 22274.132 | AA12: 22368.794 | AB12: 22178.342 | AC12: 21097.197 | AD12: 19976.148 | AE12: 19034.92 | AF12: 18397.8 | AG12: =ROUND(SUM(I12:AF12)*H12,2) -> 891701.76
G13: TOTAL | H13: =+SUM(H9:H12) -> 31 | I13: =+SUMPRODUCT(I9:I12,$H9:$H12) -> 647987.66 | J13: =+SUMPRODUCT(J9:J12,$H9:$H12) -> 632319.35 | K13: =+SUMPRODUCT(K9:K12,$H9:$H12) -> 622016.29 | L13: =+SUMPRODUCT(L9:L12,$H9:$H12) -> 619110.79 | M13: =+SUMPRODUCT(M9:M12,$H9:$H12) -> 618216.76 | N13: =+SUMPRODUCT(N9:N12,$H9:$H12) -> 628562.4 | O13: =+SUMPRODUCT(O9:O12,$H9:$H12) -> 663838.47 | P13: =+SUMPRODUCT(P9:P12,$H9:$H12) -> 696542.24 | ... AF13: =+SUMPRODUCT(AF9:AF12,$H9:$H12) -> 663934.86 | AG13: =SUM(I13:AF13) -> 17638374
E14: 46784 | F14: =+AG18 -> 16702855 | G14: OR | H14: 21 | I14: 21328.865 | J14: 20822.216 | K14: 20487.938 | L14: 20428.704 | M14: 20422.684 | N14: 20957.238 | O14: 22661.259 | P14: 24375.695 | Q14: 25611.807 | R14: 25889.696 | S14: 26861.316 | T14: 27390.295 | U14: 26811.544 | V14: 27725.041 | W14: 29173.148 | X14: 30225.423 | Y14: 30865.031 | Z14: 30684.91 | AA14: 29401.088 | AB14: 28447.647 | AC14: 26865.444 | AD14: 24955.743 | AE14: 23164.004 | AF14: 22319.238 | AG14: =+SUM(I14:AF14)*H14 -> 12765395
E15: =+E14 -> 46784 | G15: SA | H15: 4 | I15: 21249.455 | J15: 20670.05 | K15: 20365.847 | L15: 20299.221 | M15: 20257.94 | N15: 20485.172 | O15: 21418.373 | P15: 22171.642 | Q15: 22793.677 | R15: 23001.779 | S15: 23769.81 | T15: 24025.186 | U15: 23475.349 | V15: 23551.281 | W15: 23855.537 | X15: 24604.603 | Y15: 25558.267 | Z15: 26599.699 | AA15: 26370.927 | AB15: 25912.738 | AC15: 24817.569 | AD15: 23043.519 | AE15: 21466.21 | AF15: 20565.555 | AG15: =+SUM(I15:AF15)*H15 -> 2201317.6
E16: =+E15 -> 46784 | G16: DO | H16: 4 | I16: 18321.52 | J16: 17882.077 | K16: 17521.958 | L16: 17323.96 | M16: 17205.719 | N16: 17043.734 | O16: 16530.403 | P16: 15723.529 | Q16: 15348.182 | R16: 15183.855 | S16: 15654.168 | T16: 16325.396 | U16: 16719.052 | V16: 17166.879 | W16: 17766.541 | X16: 18834.005 | Y16: 20247.038 | Z16: 21781.703 | AA16: 21965.413 | AB16: 21757.84 | AC16: 20802.382 | AD16: 19782.239 | AE16: 18888.642 | AF16: 18259.293 | AG16: =+SUM(I16:AF16)*H16 -> 1736142.1
E17: =+E16 -> 46784 | G17: FE | H17: 0 | I17: 0 | J17: 0 | K17: 0 | L17: 0 | M17: 0 | N17: 0 | O17: 0 | P17: 0 | Q17: 0 | R17: 0 | S17: 0 | T17: 0 | U17: 0 | V17: 0 | W17: 0 | X17: 0 | Y17: 0 | Z17: 0 | AA17: 0 | AB17: 0 | AC17: 0 | AD17: 0 | AE17: 0 | AF17: 0 | AG17: =+SUM(I17:AF17)*H17 -> 0
E18: =+E17 -> 46784 | G18: TOTAL | H18: =+SUM(H14:H17) -> 29 | I18: =+SUMPRODUCT(I14:I17,$H14:$H17) -> 606190.07 | J18: =+SUMPRODUCT(J14:J17,$H14:$H17) -> 591475.04 | K18: =+SUMPRODUCT(K14:K17,$H14:$H17) -> 581797.92 | L18: =+SUMPRODUCT(L14:L17,$H14:$H17) -> 579495.51 | M18: =+SUMPRODUCT(M14:M17,$H14:$H17) -> 578730.99 | N18: =+SUMPRODUCT(N14:N17,$H14:$H17) -> 590217.63 | O18: =+SUMPRODUCT(O14:O17,$H14:$H17) -> 627681.54 | P18: =+SUMPRODUCT(P14:P17,$H14:$H17) -> 663470.28 | ... AF18: =+SUMPRODUCT(AF14:AF17,$H14:$H17) -> 624003.38 | AG18: =SUM(I18:AF18) -> 16702855
E19: 46813 | F19: =+AG23 -> 17698009 | G19: OR | H19: 22 | I19: 21284.094 | J19: 20775.741 | K19: 20438.865 | L19: 20378.171 | M19: 20365.26 | N19: 20885.429 | O19: 22571.251 | P19: 24288.218 | Q19: 25527.71 | R19: 25812.499 | S19: 26778.339 | T19: 27306.153 | U19: 26725.373 | V19: 27644.819 | W19: 29095.267 | X19: 30144.983 | Y19: 30781.662 | Z19: 30599.393 | AA19: 29317.9 | AB19: 28376.368 | AC19: 26796.049 | AD19: 24894.581 | AE19: 23111.61 | AF19: 22267.951 | AG19: =+SUM(I19:AF19)*H19 -> 13335689
E20: =+E19 -> 46813 | G20: SA | H20: 4 | I20: 21229.627 | J20: 20650.402 | K20: 20348.506 | L20: 20283.534 | M20: 20237.365 | N20: 20453.126 | O20: 21378.206 | P20: 22136.912 | Q20: 22761.944 | R20: 22980.257 | S20: 23745.884 | T20: 24005.795 | U20: 23455.308 | V20: 23539.83 | W20: 23840.06 | X20: 24582.474 | Y20: 25533.013 | Z20: 26572.078 | AA20: 26344.259 | AB20: 25897.972 | AC20: 24801.629 | AD20: 23026.447 | AE20: 21447.905 | AF20: 20549.961 | AG20: =+SUM(I20:AF20)*H20 -> 2199210
E21: =+E20 -> 46813 | G21: DO | H21: 4 | I21: 18560.079 | J21: 18105.32 | K21: 17737.2 | L21: 17539.211 | M21: 17376.719 | N21: 17029.671 | O21: 16355.98 | P21: 15543.794 | Q21: 15208.573 | R21: 15054.772 | S21: 15549.757 | T21: 16177.91 | U21: 16554.838 | V21: 17002.276 | W21: 17580.627 | X21: 18663.33 | Y21: 20020.09 | Z21: 21635.052 | AA21: 21848.007 | AB21: 21683.267 | AC21: 20669.113 | AD21: 19638.102 | AE21: 18725 | AF21: 18096.264 | AG21: =+SUM(I21:AF21)*H21 -> 1729419.8
E22: =+E21 -> 46813 | G22: FE | H22: 1 | I22: 18568.611 | J22: 18143.328 | K22: 17813.708 | L22: 17632.064 | M22: 17477.9 | N22: 17012.027 | O22: 16380.886 | P22: 15709.838 | Q22: 15464.248 | R22: 15337.834 | S22: 15872.22 | T22: 16370.938 | U22: 16654.851 | V22: 17033.388 | W22: 17629.081 | X22: 18764.529 | Y22: 20050.284 | Z22: 21688.225 | AA22: 21781.349 | AB22: 21675.222 | AC22: 20599.92 | AD22: 19501.521 | AE22: 18571.671 | AF22: 17956.513 | AG22: =+SUM(I22:AF22)*H22 -> 433690.16
E23: =+E22 -> 46813 | G23: TOTAL | H23: =+SUM(H19:H22) -> 31 | I23: =+SUMPRODUCT(I19:I22,$H19:$H22) -> 645977.51 | J23: =+SUMPRODUCT(J19:J22,$H19:$H22) -> 630232.52 | K23: =+SUMPRODUCT(K19:K22,$H19:$H22) -> 619811.56 | L23: =+SUMPRODUCT(L19:L22,$H19:$H22) -> 617242.79 | M23: =+SUMPRODUCT(M19:M22,$H19:$H22) -> 615969.97 | N23: =+SUMPRODUCT(N19:N22,$H19:$H22) -> 626422.65 | O23: =+SUMPRODUCT(O19:O22,$H19:$H22) -> 663885.16 | P23: =+SUMPRODUCT(P19:P22,$H19:$H22) -> 700773.46 | ... AF23: =+SUMPRODUCT(AF19:AF22,$H19:$H22) -> 662436.33 | AG23: =SUM(I23:AF23) -> 17698009
E24: 46844 | F24: =+AG28 -> 16890742 | G24: OR | H24: 18 | I24: 21541.06 | J24: 21028.767 | K24: 20687.458 | L24: 20621.991 | M24: 20609.851 | N24: 21136.289 | O24: 22851.674 | P24: 24605.514 | Q24: 25879.9 | R24: 26191.374 | S24: 27175.342 | T24: 27715.366 | U24: 27122.861 | V24: 28045.528 | W24: 29500.205 | X24: 30545.097 | Y24: 31176.14 | Z24: 30976.213 | AA24: 29668.592 | AB24: 28716.631 | AC24: 27115.958 | AD24: 25193.868 | AE24: 23393.21 | AF24: 22541.688 | AG24: =+SUM(I24:AF24)*H24 -> 11052730
E25: =+E24 -> 46844 | G25: SA | H25: 5 | I25: 21448.921 | J25: 20864.674 | K25: 20558.371 | L25: 20490.33 | M25: 20443.895 | N25: 20659.204 | O25: 21597.349 | P25: 22377.608 | Q25: 23023.782 | R25: 23262.852 | S25: 24044.701 | T25: 24310.795 | U25: 23745.222 | V25: 23825.721 | W25: 24121.415 | X25: 24856.703 | Y25: 25803.288 | Z25: 26834.908 | AA25: 26602.205 | AB25: 26147 | AC25: 25032.173 | AD25: 23234.605 | AE25: 21635.469 | AF25: 20732.798 | AG25: =+SUM(I25:AF25)*H25 -> 2778269.9
E26: =+E25 -> 46844 | G26: DO | H26: 5 | I26: 18515.067 | J26: 18068.221 | K26: 17696.376 | L26: 17498.895 | M26: 17377.519 | N26: 17220.468 | O26: 16695.749 | P26: 15889.397 | Q26: 15514.928 | R26: 15361.462 | S26: 15852.235 | T26: 16540.319 | U26: 16928.915 | V26: 17370.95 | W26: 17963.397 | X26: 19028.155 | Y26: 20435.36 | Z26: 21980.274 | AA26: 22155.401 | AB26: 21952.251 | AC26: 20981.119 | AD26: 19960.034 | AE26: 19058.245 | AF26: 18431.339 | AG26: =+SUM(I26:AF26)*H26 -> 2192380.4
E27: =+E26 -> 46844 | G27: FE | H27: 2 | I27: 18568.208 | J27: 18142.925 | K27: 17813.3 | L27: 17631.661 | M27: 17477.497 | N27: 17011.619 | O27: 16380.483 | P27: 15709.429 | Q27: 15463.845 | R27: 15337.426 | S27: 15871.818 | T27: 16370.536 | U27: 16654.448 | V27: 17032.98 | W27: 17628.678 | X27: 18764.126 | Y27: 20049.881 | Z27: 21687.822 | AA27: 21780.946 | AB27: 21674.819 | AC27: 20599.512 | AD27: 19501.118 | AE27: 18571.263 | AF27: 17956.105 | AG27: =+SUM(I27:AF27)*H27 -> 867360.89
E28: =+E27 -> 46844 | G28: TOTAL | H28: =+SUM(H24:H27) -> 30 | I28: =+SUMPRODUCT(I24:I27,$H24:$H27) -> 624695.43 | J28: =+SUMPRODUCT(J24:J27,$H24:$H27) -> 609468.12 | K28: =+SUMPRODUCT(K24:K27,$H24:$H27) -> 599274.59 | L28: =+SUMPRODUCT(L24:L27,$H24:$H27) -> 596405.28 | M28: =+SUMPRODUCT(M24:M27,$H24:$H27) -> 595039.38 | N28: =+SUMPRODUCT(N24:N27,$H24:$H27) -> 603874.81 | O28: =+SUMPRODUCT(O24:O27,$H24:$H27) -> 635556.59 | P28: =+SUMPRODUCT(P24:P27,$H24:$H27) -> 665653.13 | ... AF28: =+SUMPRODUCT(AF24:AF27,$H24:$H27) -> 637483.28 | AG28: =SUM(I28:AF28) -> 16890742
E29: 46874 | F29: =+AG33 -> 17388735 | G29: OR | H29: 21 | I29: 21105.015 | J29: 20592.669 | K29: 20250.706 | L29: 20185.705 | M29: 20167.288 | N29: 20678.953 | O29: 22367.806 | P29: 24110.484 | Q29: 25375.168 | R29: 25682.974 | S29: 26655.352 | T29: 27189.938 | U29: 26599.924 | V29: 27526.589 | W29: 28981.768 | X29: 30026.182 | Y29: 30656.722 | Z29: 30461.326 | AA29: 29165.194 | AB29: 28227.363 | AC29: 26635.7 | AD29: 24728.237 | AE29: 22941.611 | AF29: 22093.905 | AG29: =+SUM(I29:AF29)*H29 -> 12650538
E30: =+E29 -> 46874 | G30: SA | H30: 4 | I30: 20980.39 | J30: 20399.595 | K30: 20098.71 | L30: 20034.49 | M30: 19982.808 | N30: 20185.695 | O30: 21106.377 | P30: 21878.678 | Q30: 22514.458 | R30: 22751.395 | S30: 23520.048 | T30: 23787.162 | U30: 23230.652 | V30: 23323.281 | W30: 23617.456 | X30: 24349.99 | Y30: 25295.675 | Z30: 26329.503 | AA30: 26101.026 | AB30: 25664.791 | AC30: 24560.649 | AD30: 22776.344 | AE30: 21189.205 | AF30: 20292.598 | AG30: =+SUM(I30:AF30)*H30 -> 2175883.9
E31: =+E30 -> 46874 | G31: DO | H31: 4 | I31: 18081.951 | J31: 17637.433 | K31: 17262.41 | L31: 17067.859 | M31: 16946.301 | N31: 16796.04 | O31: 16266.337 | P31: 15446.382 | Q31: 15062.568 | R31: 14904.652 | S31: 15387.549 | T31: 16073.52 | U31: 16461.576 | V31: 16899.984 | W31: 17495.918 | X31: 18559.769 | Y31: 19967.049 | Z31: 21520.592 | AA31: 21688.638 | AB31: 21498.925 | AC31: 20537.495 | AD31: 19530 | AE31: 18633.157 | AF31: 18012.372 | AG31: =+SUM(I31:AF31)*H31 -> 1710953.9
E32: =+E31 -> 46874 | G32: FE | H32: 2 | I32: 18274.707 | J32: 17846.036 | K32: 17510.297 | L32: 17330.115 | M32: 17166.489 | N32: 16683.307 | O32: 16009.314 | P32: 15342.702 | Q32: 15098.031 | R32: 14980.895 | S32: 15536.218 | T32: 16036.957 | U32: 16322.605 | V32: 16692.889 | W32: 17267.509 | X32: 18389.451 | Y32: 19661.972 | Z32: 21335.525 | AA32: 21430.217 | AB32: 21364.005 | AC32: 20287.653 | AD32: 19189.441 | AE32: 18264.585 | AF32: 17658.802 | AG32: =+SUM(I32:AF32)*H32 -> 851359.44
E33: =+E32 -> 46874 | G33: TOTAL | H33: =+SUM(H29:H32) -> 31 | I33: =+SUMPRODUCT(I29:I32,$H29:$H32) -> 636004.09 | J33: =+SUMPRODUCT(J29:J32,$H29:$H32) -> 620286.23 | K33: =+SUMPRODUCT(K29:K32,$H29:$H32) -> 609729.9 | L33: =+SUMPRODUCT(L29:L32,$H29:$H32) -> 606969.42 | M33: =+SUMPRODUCT(M29:M32,$H29:$H32) -> 605562.46 | N33: =+SUMPRODUCT(N29:N32,$H29:$H32) -> 615551.57 | O33: =+SUMPRODUCT(O29:O32,$H29:$H32) -> 651233.42 | P33: =+SUMPRODUCT(P29:P32,$H29:$H32) -> 686305.81 | ... AF33: =+SUMPRODUCT(AF29:AF32,$H29:$H32) -> 652509.49 | AG33: =SUM(I33:AF33) -> 17388735
E34: 46905 | F34: =+AG38 -> 16766444 | G34: OR | H34: 20 | I34: 21081.475 | J34: 20569.303 | K34: 20227.501 | L34: 20162.763 | M34: 20143.774 | N34: 20653.881 | O34: 22339.067 | P34: 24079.043 | Q34: 25341.237 | R34: 25647.466 | S34: 26617.99 | T34: 27151.534 | U34: 26562.286 | V34: 27489.148 | W34: 28944.166 | X34: 29988.767 | Y34: 30619.53 | Z34: 30425.361 | AA34: 29131.45 | AB34: 28195.32 | AC34: 26605.394 | AD34: 24700.158 | AE34: 22915.572 | AF34: 22068.563 | AG34: =+SUM(I34:AF34)*H34 -> 12033215
E35: =+E34 -> 46905 | G35: SA | H35: 4 | I35: 20976.352 | J35: 20395.645 | K35: 20094.872 | L35: 20030.732 | M35: 19978.973 | N35: 20181.681 | O35: 21102.008 | P35: 21874.033 | Q35: 22509.509 | R35: 22746.26 | S35: 23514.6 | T35: 23781.688 | U35: 23225.419 | V35: 23318.26 | W35: 23612.441 | X35: 24344.983 | Y35: 25290.689 | Z35: 26324.604 | AA35: 26096.226 | AB35: 25660.335 | AC35: 24556.484 | AD35: 22772.54 | AE35: 21185.73 | AF35: 20289.244 | AG35: =+SUM(I35:AF35)*H35 -> 2175453.2
E36: =+E35 -> 46905 | G36: DO | H36: 4 | I36: 18028.52 | J36: 17585.13 | K36: 17210.12 | L36: 17016.295 | M36: 16894.918 | N36: 16746.063 | O36: 16215.883 | P36: 15392.36 | Q36: 15006.062 | R36: 14846.216 | S36: 15325.609 | T36: 16009.832 | U36: 16398.108 | V36: 16835.989 | W36: 17433.341 | X36: 18497.156 | Y36: 19904.866 | Z36: 21459.917 | AA36: 21626.738 | AB36: 21440.196 | AC36: 20482.398 | AD36: 19478.492 | AE36: 18583.516 | AF36: 17964.141 | AG36: =+SUM(I36:AF36)*H36 -> 1705527.5
E37: =+E36 -> 46905 | G37: FE | H37: 2 | I37: 18288.508 | J37: 17859.655 | K37: 17523.915 | L37: 17343.532 | M37: 17180.414 | N37: 16699.245 | O37: 16027.412 | P37: 15361.83 | Q37: 15117.344 | R37: 15000.686 | S37: 15556.785 | T37: 16058.696 | U37: 16344.43 | V37: 16714.837 | W37: 17289.341 | X37: 18411.135 | Y37: 19684.227 | Z37: 21356.339 | AA37: 21450.908 | AB37: 21383.188 | AC37: 20306.414 | AD37: 19207.338 | AE37: 18282.108 | AF37: 17675.919 | AG37: =+SUM(I37:AF37)*H37 -> 852248.41
E38: =+E37 -> 46905 | G38: TOTAL | H38: =+SUM(H34:H37) -> 30 | I38: =+SUMPRODUCT(I34:I37,$H34:$H37) -> 614226.01 | J38: =+SUMPRODUCT(J34:J37,$H34:$H37) -> 599028.47 | K38: =+SUMPRODUCT(K34:K37,$H34:$H37) -> 588817.82 | L38: =+SUMPRODUCT(L34:L37,$H34:$H37) -> 586130.44 | M38: =+SUMPRODUCT(M34:M37,$H34:$H37) -> 584731.88 | N38: =+SUMPRODUCT(N34:N37,$H34:$H37) -> 594187.09 | O38: =+SUMPRODUCT(O34:O37,$H34:$H37) -> 628107.72 | P38: =+SUMPRODUCT(P34:P37,$H34:$H37) -> 661370.1 | ... AF38: =+SUMPRODUCT(AF34:AF37,$H34:$H37) -> 629736.65 | AG38: =SUM(I38:AF38) -> 16766444
E39: 46935 | F39: =+AG43 -> 17160883 | G39: OR | H39: 19 | I39: 21124.996 | J39: 20612.399 | K39: 20270.177 | L39: 20204.864 | M39: 20186.676 | N39: 20699.164 | O39: 22390.641 | P39: 24135.957 | Q39: 25403.103 | R39: 25712.687 | S39: 26686.54 | T39: 27222.05 | U39: 26631.223 | V39: 27557.98 | W39: 29013.409 | X39: 30057.532 | Y39: 30687.735 | Z39: 30491.103 | AA39: 29193 | AB39: 28254.101 | AC39: 26660.904 | AD39: 24751.726 | AE39: 22963.58 | AF39: 22115.276 | AG39: =+SUM(I39:AF39)*H39 -> 11457510
