Workbook

Sheet Anexo 1
B3: ANEXO No 1 - PRODUCTO No. 1 - CURVA
B4: PAGUE LO CONTRATADO AÑO 2026
B5: PRECIO OFERTADO EN $ / kWh DE ABRIL DE 2025
B8: MES | C8: ENERGIA SOLICITADA kWh/MES | D8: % OFERTADO ANUAL | E8: ENERGIA OFERTADA kWh/MES | F8: PRECIO OFERTADO ANUAL $/kWh
B10: 46023 | C10: =+'Anexo 11'!AC6 -> 12390605 | E10: =+'Cantidades Ofertadas Prod 1'!AC6 -> 0
B11: 46054 | C11: =+'Anexo 11'!AC9 -> 11417324 | E11: =+'Cantidades Ofertadas Prod 1'!AC9 -> 0
B12: 46082 | C12: =+'Anexo 11'!AC12 -> 12298630 | E12: =+'Cantidades Ofertadas Prod 1'!AC12 -> 0
B13: 46113 | C13: =+'Anexo 11'!AC15 -> 11627746 | E13: =+'Cantidades Ofertadas Prod 1'!AC15 -> 0
B14: 46143 | C14: =+'Anexo 11'!AC18 -> 12073036 | E14: =+'Cantidades Ofertadas Prod 1'!AC18 -> 0
B15: 46174 | C15: =+'Anexo 11'!AC21 -> 11688903 | E15: =+'Cantidades Ofertadas Prod 1'!AC21 -> 0
B16: 46204 | C16: =+'Anexo 11'!AC24 -> 12412726 | E16: =+'Cantidades Ofertadas Prod 1'!AC24 -> 0
B17: 46235 | C17: =+'Anexo 11'!AC27 -> 12586725 | E17: =+'Cantidades Ofertadas Prod 1'!AC27 -> 0
B18: 46266 | C18: =+'Anexo 11'!AC30 -> 12409140 | E18: =+'Cantidades Ofertadas Prod 1'!AC30 -> 0
B19: 46296 | C19: =+'Anexo 11'!AC33 -> 12283132 | E19: =+'Cantidades Ofertadas Prod 1'!AC33 -> 0
B20: 46327 | C20: =+'Anexo 11'!AC36 -> 11629733 | E20: =+'Cantidades Ofertadas Prod 1'!AC36 -> 0
B21: 46357 | C21: =+'Anexo 11'!AC39 -> 12526287 | E21: =+'Cantidades Ofertadas Prod 1'!AC39 -> 0
B22: TOTAL | C22: =+SUM(C10:C21) -> 145343987 | E22: =SUM(E10:E21) -> 0 | F22: =+F10 -> 0
B23: *Solo se debe ingresar valores en las celdas en color Naranja
B24: * Se debe ofertar un unico % para todos los meses del año.
B25: * Los % ofertados se aplicaran a las curvas de carga de la hoja "Anexo 11".
B26: * La energia ofertada se calcula de manera automatica en la hoja "Cantidades Ofertadas Prod 1"
B27: * Se debe ofertar un unico precio por producto.
B28: * Para ofertas planas se debe diligenciar el anexo 1A, con un tope horario de 16.591 kWh
B31: ____________________________________________
B32: Firma del Representante Legal
B33: o Apoderado General (Responsable del negocio)

Sheet Anexo 1A
B3: ANEXO No 1A - PRODUCTO No. 1 - OFERTA PLANA
B4: PAGUE LO CONTRATADO AÑO 2026
B5: PRECIO OFERTADO EN $ / kWh DE ABRIL DE 2025
B8: MES | C8: ENERGIA MAXIMA A OFERTAR kWh/MES | D8: kWh OFERTADO | E8: ENERGIA OFERTADA kWh/MES | F8: PRECIO OFERTADO ANUAL $/kWh
A9: 16591
A10: 31 | B10: 46023 | C10: =+$A$9*A10*24 -> 12343704 | E10: =+$D$10*A10*24 -> 0
A11: 28 | B11: 46054 | C11: =+$A$9*A11*24 -> 11149152 | E11: =+$D$10*A11*24 -> 0
A12: 31 | B12: 46082 | C12: =+$A$9*A12*24 -> 12343704 | E12: =+$D$10*A12*24 -> 0
A13: 30 | B13: 46113 | C13: =+$A$9*A13*24 -> 11945520 | E13: =+$D$10*A13*24 -> 0
A14: 31 | B14: 46143 | C14: =+$A$9*A14*24 -> 12343704 | E14: =+$D$10*A14*24 -> 0
A15: 30 | B15: 46174 | C15: =+$A$9*A15*24 -> 11945520 | E15: =+$D$10*A15*24 -> 0
A16: 31 | B16: 46204 | C16: =+$A$9*A16*24 -> 12343704 | E16: =+$D$10*A16*24 -> 0
A17: 31 | B17: 46235 | C17: =+$A$9*A17*24 -> 12343704 | E17: =+$D$10*A17*24 -> 0
A18: 30 | B18: 46266 | C18: =+$A$9*A18*24 -> 11945520 | E18: =+$D$10*A18*24 -> 0
A19: 31 | B19: 46296 | C19: =+$A$9*A19*24 -> 12343704 | E19: =+$D$10*A19*24 -> 0
A20: 30 | B20: 46327 | C20: =+$A$9*A20*24 -> 11945520 | E20: =+$D$10*A20*24 -> 0
A21: 31 | B21: 46357 | C21: =+$A$9*A21*24 -> 12343704 | E21: =+$D$10*A21*24 -> 0
B22: TOTAL | C22: =+SUM(C10:C21) -> 145337160 | E22: =SUM(E10:E21) -> 0 | F22: =+F10 -> 0
B23: *Solo se debe ingresar valores en las celdas en color Naranja
B24: * Se debe oferta un valor de kWh el cual se aplica para todas las horas del año, con un tope horario de 16.591 kWh
B25: * Se debe ofertar un unico precio por producto.
B26: * A las ofertas planas al momento de la evaluación se le adicionarán 5 $/kWh al precio ofertado; con el fin de hacerlas comparables con las Ofertas que siguen la curva
B31: ____________________________________________
B32: Firma del Representante Legal
B33: o Apoderado General (Responsable del negocio)

Sheet Anexo 11
A1: CURVAS REQUERIDAS PRODUCTO 1 AÑO 2026 MODALIDAD PAGUE LO CONTRATADO - kWh
A4: Periodo | B4: Tipo de día | C4: H01 | D4: H02 | E4: H03 | F4: H04 | G4: H05 | H4: H06 | I4: H07 | J4: H08 | K4: H09 | L4: H10 | M4: H11 | N4: H12 | O4: H13 | P4: H14 | Q4: H15 | R4: H16 | S4: H17 | T4: H18 | U4: H19 | V4: H20 | W4: H21 | X4: H22 | Y4: H23 | Z4: H24 | AA4: TOTAL DÍA | AB4: Días/ | AC4: TOTAL MES
AB5: mes
A6: 46023 | B6: O | C6: 13462 | D6: 12684 | E6: 12216 | F6: 11974 | G6: 12141 | H6: 12865 | I6: 13552 | J6: 14839 | K6: 16287 | L6: 17384 | M6: 18501 | N6: 19554 | O6: 19375 | P6: 19399 | Q6: 19722 | R6: 19784 | S6: 19557 | T6: 19134 | U6: 20540 | V6: 21711 | W6: 20924 | X6: 19543 | Y6: 17324 | Z6: 15082 | AA6: =SUM(C6:Z6) -> 407554 | AB6: 20 | AC6: =+AA6*AB6+AA7*AB7+AA8*AB8 -> 12390605
B7: S | C7: 13787 | D7: 12908 | E7: 12372 | F7: 12034 | G7: 12045 | H7: 12449 | I7: 12921 | J7: 14230 | K7: 15848 | L7: 17070 | M7: 17985 | N7: 18890 | O7: 18988 | P7: 18801 | Q7: 18597 | R7: 18497 | S7: 18358 | T7: 18340 | U7: 20103 | V7: 21359 | W7: 20500 | X7: 19220 | Y7: 17404 | Z7: 15583 | AA7: =SUM(C7:Z7) -> 398289 | AB7: 5
B8: F | C8: 14453 | D8: 13504 | E8: 12874 | F8: 12430 | G8: 12213 | H8: 12298 | I8: 12177 | J8: 12897 | K8: 14128 | L8: 15213 | M8: 16014 | N8: 16847 | O8: 17341 | P8: 17282 | Q8: 16969 | R8: 16788 | S8: 16697 | T8: 16787 | U8: 18710 | V8: 20083 | W8: 19523 | X8: 18326 | Y8: 16481 | Z8: 14645 | AA8: =SUM(C8:Z8) -> 374680 | AB8: 6
A9: 46054 | B9: O | C9: 13541 | D9: 12792 | E9: 12362 | F9: 12150 | G9: 12395 | H9: 13517 | I9: 14412 | J9: 15383 | K9: 16671 | L9: 17636 | M9: 18691 | N9: 19668 | O9: 19275 | P9: 19425 | Q9: 19879 | R9: 19960 | S9: 19738 | T9: 19222 | U9: 20296 | V9: 21832 | W9: 21075 | X9: 19630 | Y9: 17349 | Z9: 15079 | AA9: =SUM(C9:Z9) -> 411978 | AB9: 20 | AC9: =+AA9*AB9+AA10*AB10+AA11*AB11 -> 11417324
B10: S | C10: 14042 | D10: 13212 | E10: 12678 | F10: 12372 | G10: 12408 | H10: 12843 | I10: 13539 | J10: 14847 | K10: 16528 | L10: 17699 | M10: 18630 | N10: 19533 | O10: 19558 | P10: 19308 | Q10: 19093 | R10: 18975 | S10: 18814 | T10: 18755 | U10: 20181 | V10: 21726 | W10: 20876 | X10: 19667 | Y10: 17938 | Z10: 16018 | AA10: =SUM(C10:Z10) -> 409240 | AB10: 4
B11: F | C11: 14585 | D11: 13642 | E11: 13068 | F11: 12637 | G11: 12499 | H11: 12628 | I11: 12732 | J11: 13575 | K11: 14926 | L11: 16031 | M11: 16764 | N11: 17556 | O11: 17999 | P11: 17855 | Q11: 17501 | R11: 17287 | S11: 17179 | T11: 17270 | U11: 18803 | V11: 20510 | W11: 19989 | X11: 18749 | Y11: 16712 | Z11: 14704 | AA11: =SUM(C11:Z11) -> 385201 | AB11: 4
A12: 46082 | B12: O | C12: 13253 | D12: 12536 | E12: 12139 | F12: 11941 | G12: 12204 | H12: 13305 | I12: 14076 | J12: 15150 | K12: 16388 | L12: 17314 | M12: 18302 | N12: 19192 | O12: 18838 | P12: 18916 | Q12: 19306 | R12: 19370 | S12: 19200 | T12: 18838 | U12: 20177 | V12: 21488 | W12: 20707 | X12: 19237 | Y12: 17002 | Z12: 14795 | AA12: =SUM(C12:Z12) -> 403674 | AB12: 21 | AC12: =+AA12*AB12+AA13*AB13+AA14*AB14 -> 12298630
B13: S | C13: 13671 | D13: 12843 | E13: 12403 | F13: 12151 | G13: 12166 | H13: 12628 | I13: 13031 | J13: 14466 | K13: 16025 | L13: 17156 | M13: 18054 | N13: 18802 | O13: 18787 | P13: 18521 | Q13: 18321 | R13: 18171 | S13: 17976 | T13: 17989 | U13: 19616 | V13: 20853 | W13: 20045 | X13: 18889 | Y13: 17169 | Z13: 15431 | AA13: =SUM(C13:Z13) -> 395164 | AB13: 4
B14: F | C14: 14089 | D14: 13178 | E14: 12642 | F14: 12278 | G14: 12128 | H14: 12306 | I14: 12262 | J14: 13173 | K14: 14414 | L14: 15414 | M14: 16112 | N14: 16905 | O14: 17377 | P14: 17245 | Q14: 16883 | R14: 16721 | S14: 16616 | T14: 16746 | U14: 18503 | V14: 19960 | W14: 19398 | X14: 18235 | Y14: 16344 | Z14: 14541 | AA14: =SUM(C14:Z14) -> 373470 | AB14: 6
A15: 46113 | B15: O | C15: 12948 | D15: 12261 | E15: 11848 | F15: 11657 | G15: 11899 | H15: 12787 | I15: 13440 | J15: 14624 | K15: 15861 | L15: 16830 | M15: 17853 | N15: 18779 | O15: 18448 | P15: 18533 | Q15: 18900 | R15: 18937 | S15: 18747 | T15: 18470 | U15: 20082 | V15: 21041 | W15: 20300 | X15: 18816 | Y15: 16570 | Z15: 14421 | AA15: =SUM(C15:Z15) -> 394052 | AB15: 20 | AC15: =+AA15*AB15+AA16*AB16+AA17*AB17 -> 11627746
B16: S | C16: 13224 | D16: 12440 | E16: 11937 | F16: 11639 | G16: 11694 | H16: 12030 | I16: 12452 | J16: 13950 | K16: 15486 | L16: 16651 | M16: 17493 | N16: 18449 | O16: 18507 | P16: 18285 | Q16: 18082 | R16: 17943 | S16: 17892 | T16: 17978 | U16: 19812 | V16: 20826 | W16: 19973 | X16: 18736 | Y16: 16994 | Z16: 15217 | AA16: =SUM(C16:Z16) -> 387690 | AB16: 4
B17: F | C17: 13781 | D17: 12902 | E17: 12333 | F17: 11946 | G17: 11796 | H17: 11776 | I17: 11868 | J17: 12896 | K17: 14099 | L17: 15155 | M17: 15906 | N17: 16672 | O17: 17118 | P17: 16995 | Q17: 16610 | R17: 16429 | S17: 16325 | T17: 16473 | U17: 18431 | V17: 19603 | W17: 18989 | X17: 17793 | Y17: 15961 | Z17: 14134 | AA17: =SUM(C17:Z17) -> 365991 | AB17: 6
A18: 46143 | B18: O | C18: 12967 | D18: 12257 | E18: 11862 | F18: 11664 | G18: 11898 | H18: 12659 | I18: 13455 | J18: 14698 | K18: 15969 | L18: 16967 | M18: 17970 | N18: 18923 | O18: 18635 | P18: 18631 | Q18: 18918 | R18: 18952 | S18: 18758 | T18: 18532 | U18: 20215 | V18: 21170 | W18: 20342 | X18: 18853 | Y18: 16571 | Z18: 14458 | AA18: =SUM(C18:Z18) -> 395324 | AB18: 19 | AC18: =+AA18*AB18+AA19*AB19+AA20*AB20 -> 12073036
B19: S | C19: 13447 | D19: 12669 | E19: 12200 | F19: 11923 | G19: 11971 | H19: 12167 | I19: 12804 | J19: 14310 | K19: 15881 | L19: 17095 | M19: 17926 | N19: 18685 | O19: 18688 | P19: 18391 | Q19: 18088 | R19: 17905 | S19: 17772 | T19: 17936 | U19: 19929 | V19: 20738 | W19: 19916 | X19: 18656 | Y19: 16903 | Z19: 15156 | AA19: =SUM(C19:Z19) -> 391156 | AB19: 5
B20: F | C20: 13682 | D20: 12832 | E20: 12304 | F20: 11953 | G20: 11845 | H20: 11711 | I20: 11952 | J20: 13097 | K20: 14371 | L20: 15502 | M20: 16275 | N20: 17083 | O20: 17437 | P20: 17366 | Q20: 16945 | R20: 17418 | S20: 16649 | T20: 16832 | U20: 18856 | V20: 20033 | W20: 19401 | X20: 18129 | Y20: 16245 | Z20: 14382 | AA20: =SUM(C20:Z20) -> 372300 | AB20: 7
A21: 46174 | B21: O | C21: 12814 | D21: 12089 | E21: 11727 | F21: 11532 | G21: 11747 | H21: 12401 | I21: 13262 | J21: 14574 | K21: 15900 | L21: 16888 | M21: 17921 | N21: 18885 | O21: 18574 | P21: 18553 | Q21: 18908 | R21: 18928 | S21: 18735 | T21: 18445 | U21: 19787 | V21: 21040 | W21: 20255 | X21: 18780 | Y21: 16464 | Z21: 14318 | AA21: =SUM(C21:Z21) -> 392527 | AB21: 19 | AC21: =+AA21*AB21+AA22*AB22+AA23*AB23 -> 11688903
B22: S | C22: 13433 | D22: 12597 | E22: 12118 | F22: 11847 | G22: 11871 | H22: 12063 | I22: 12693 | J22: 14182 | K22: 15862 | L22: 17016 | M22: 17916 | N22: 18697 | O22: 18748 | P22: 18556 | Q22: 18358 | R22: 18324 | S22: 18187 | T22: 18323 | U22: 20034 | V22: 21132 | W22: 20265 | X22: 19028 | Y22: 17195 | Z22: 15331 | AA22: =SUM(C22:Z22) -> 393776 | AB22: 4
B23: F | C23: 13980 | D23: 13089 | E23: 12572 | F23: 12219 | G23: 12136 | H23: 12122 | I23: 12283 | J23: 13477 | K23: 14803 | L23: 15827 | M23: 16670 | N23: 17485 | O23: 17775 | P23: 17652 | Q23: 17311 | R23: 17150 | S23: 17062 | T23: 17202 | U23: 18937 | V23: 20329 | W23: 19730 | X23: 18443 | Y23: 16508 | Z23: 14636 | AA23: =SUM(C23:Z23) -> 379398 | AB23: 7
A24: 46204 | B24: O | C24: 13416 | D24: 12653 | E24: 12213 | F24: 11973 | G24: 12177 | H24: 12828 | I24: 13527 | J24: 14992 | K24: 16415 | L24: 17531 | M24: 18611 | N24: 19569 | O24: 19230 | P24: 19271 | Q24: 19625 | R24: 19664 | S24: 19386 | T24: 18901 | U24: 20011 | V24: 21499 | W24: 20804 | X24: 19402 | Y24: 17089 | Z24: 14960 | AA24: =SUM(C24:Z24) -> 405747 | AB24: 22 | AC24: =+AA24*AB24+AA25*AB25+AA26*AB26 -> 12412726
B25: S | C25: 13446 | D25: 12570 | E25: 12124 | F25: 11825 | G25: 11854 | H25: 12103 | I25: 12705 | J25: 14478 | K25: 16166 | L25: 17322 | M25: 18230 | N25: 18998 | O25: 18963 | P25: 18666 | Q25: 18395 | R25: 18255 | S25: 18093 | T25: 18147 | U25: 19503 | V25: 20936 | W25: 20137 | X25: 18993 | Y25: 17201 | Z25: 15428 | AA25: =SUM(C25:Z25) -> 394538 | AB25: 4
B26: F | C26: 14269 | D26: 13393 | E26: 12815 | F26: 12437 | G26: 12319 | H26: 12323 | I26: 12404 | J26: 13531 | K26: 14884 | L26: 16006 | M26: 16822 | N26: 17580 | O26: 17955 | P26: 17758 | Q26: 17365 | R26: 17157 | S26: 16996 | T26: 17070 | U26: 18507 | V26: 20274 | W26: 19757 | X26: 18568 | Y26: 16636 | Z26: 14802 | AA26: =SUM(C26:Z26) -> 381628 | AB26: 5
A27: 46235 | B27: O | C27: 13574 | D27: 12851 | E27: 12451 | F27: 12215 | G27: 12429 | H27: 13291 | I27: 14058 | J27: 15362 | K27: 16727 | L27: 17771 | M27: 18878 | N27: 19848 | O27: 19506 | P27: 19661 | Q27: 20060 | R27: 20092 | S27: 19802 | T27: 19302 | U27: 20652 | V27: 21903 | W27: 21139 | X27: 19661 | Y27: 17319 | Z27: 15205 | AA27: =SUM(C27:Z27) -> 413757 | AB27: 19 | AC27: =+AA27*AB27+AA28*AB28+AA29*AB29 -> 12586725
B28: S | C28: 14129 | D28: 13344 | E28: 12854 | F28: 12486 | G28: 12459 | H28: 12805 | I28: 13215 | J28: 14888 | K28: 16579 | L28: 17738 | M28: 18754 | N28: 19523 | O28: 19529 | P28: 19319 | Q28: 19117 | R28: 19000 | S28: 18746 | T28: 18710 | U28: 20383 | V28: 21488 | W28: 20674 | X28: 19493 | Y28: 17774 | Z28: 15923 | AA28: =SUM(C28:Z28) -> 408930 | AB28: 5
B29: F | C29: 14393 | D29: 13500 | E29: 12912 | F29: 12537 | G29: 12415 | H29: 12457 | I29: 12455 | J29: 13628 | K29: 14953 | L29: 16046 | M29: 16819 | N29: 17621 | O29: 18034 | P29: 17873 | Q29: 17434 | R29: 17140 | S29: 17029 | T29: 17077 | U29: 18812 | V29: 20319 | W29: 19716 | X29: 18478 | Y29: 16592 | Z29: 14716 | AA29: =SUM(C29:Z29) -> 382956 | AB29: 7
A30: 46266 | B30: O | C30: 13817 | D30: 13056 | E30: 12580 | F30: 12372 | G30: 12573 | H30: 13397 | I30: 14191 | J30: 15537 | K30: 16889 | L30: 18013 | M30: 19129 | N30: 20151 | O30: 19800 | P30: 19944 | Q30: 20410 | R30: 20526 | S30: 20232 | T30: 19817 | U30: 21671 | V30: 22172 | W30: 21339 | X30: 19835 | Y30: 17444 | Z30: 15335 | AA30: =SUM(C30:Z30) -> 420230 | AB30: 22 | AC30: =+AA30*AB30+AA31*AB31+AA32*AB32 -> 12409140
B31: S | C31: 14186 | D31: 13280 | E31: 12790 | F31: 12521 | G31: 12532 | H31: 12648 | I31: 13282 | J31: 15085 | K31: 16803 | L31: 18030 | M31: 19000 | N31: 19777 | O31: 19728 | P31: 19476 | Q31: 19243 | R31: 19073 | S31: 18909 | T31: 19050 | U31: 21084 | V31: 21539 | W31: 20594 | X31: 19386 | Y31: 17621 | Z31: 15819 | AA31: =SUM(C31:Z31) -> 411456 | AB31: 4
B32: F | C32: 14443 | D32: 13576 | E32: 13007 | F32: 12566 | G32: 12367 | H32: 12216 | I32: 12309 | J32: 13461 | K32: 14760 | L32: 15825 | M32: 16567 | N32: 17276 | O32: 17687 | P32: 17561 | Q32: 17191 | R32: 17011 | S32: 16894 | T32: 17029 | U32: 19249 | V32: 20005 | W32: 19451 | X32: 18239 | Y32: 16345 | Z32: 14529 | AA32: =SUM(C32:Z32) -> 379564 | AB32: 4
A33: 46296 | B33: O | C33: 13093 | D33: 12391 | E33: 12001 | F33: 11792 | G33: 12024 | H33: 12687 | I33: 13533 | J33: 14800 | K33: 16072 | L33: 17076 | M33: 18116 | N33: 19080 | O33: 18745 | P33: 18848 | Q33: 19280 | R33: 19372 | S33: 19158 | T33: 19214 | U33: 21339 | V33: 21230 | W33: 20298 | X33: 18776 | Y33: 16542 | Z33: 14555 | AA33: =SUM(C33:Z33) -> 400022 | AB33: 21 | AC33: =+AA33*AB33+AA34*AB34+AA35*AB35 -> 12283132
B34: S | C34: 13784 | D34: 12998 | E34: 12521 | F34: 12204 | G34: 12268 | H34: 12458 | I34: 13162 | J34: 14783 | K34: 16398 | L34: 17520 | M34: 18475 | N34: 19275 | O34: 19307 | P34: 19088 | Q34: 18856 | R34: 18712 | S34: 18544 | T34: 19128 | U34: 21556 | V34: 21518 | W34: 20607 | X34: 19227 | Y34: 17525 | Z34: 15675 | AA34: =SUM(C34:Z34) -> 405589 | AB34: 5
B35: F | C35: 13830 | D35: 12993 | E35: 12415 | F35: 12012 | G35: 11883 | H35: 11716 | I35: 11940 | J35: 13036 | K35: 14279 | L35: 15372 | M35: 16146 | N35: 16907 | O35: 17335 | P35: 17192 | Q35: 16866 | R35: 16700 | S35: 16605 | T35: 17117 | U35: 19563 | V35: 19763 | W35: 19129 | X35: 17880 | Y35: 16025 | Z35: 14241 | AA35: =SUM(C35:Z35) -> 370945 | AB35: 5
A36: 46327 | B36: O | C36: 12851 | D36: 12151 | E36: 11763 | F36: 11581 | G36: 11850 | H36: 12607 | I36: 13507 | J36: 14794 | K36: 16043 | L36: 17009 | M36: 18044 | N36: 19035 | O36: 18646 | P36: 18657 | Q36: 19079 | R36: 19060 | S36: 18904 | T36: 19162 | U36: 21381 | V36: 21262 | W36: 20317 | X36: 18715 | Y36: 16414 | Z36: 14356 | AA36: =SUM(C36:Z36) -> 397188 | AB36: 19 | AC36: =+AA36*AB36+AA37*AB37+AA38*AB38 -> 11629733
B37: S | C37: 13197 | D37: 12452 | E37: 11998 | F37: 11707 | G37: 11758 | H37: 11905 | I37: 12554 | J37: 14047 | K37: 15625 | L37: 16726 | M37: 17606 | N37: 18416 | O37: 18340 | P37: 17999 | Q37: 17898 | R37: 17841 | S37: 17737 | T37: 18372 | U37: 20842 | V37: 20780 | W37: 19828 | X37: 18611 | Y37: 16810 | Z37: 14999 | AA37: =SUM(C37:Z37) -> 388048 | AB37: 4
B38: F | C38: 13250 | D38: 12453 | E38: 11912 | F38: 11517 | G38: 11463 | H38: 11322 | I38: 11591 | J38: 12733 | K38: 13979 | L38: 15049 | M38: 15827 | N38: 16618 | O38: 17010 | P38: 16855 | Q38: 16481 | R38: 16216 | S38: 16140 | T38: 16716 | U38: 19206 | V38: 19437 | W38: 18797 | X38: 17529 | Y38: 15631 | Z38: 13835 | AA38: =SUM(C38:Z38) -> 361567 | AB38: 7
A39: 46357 | B39: O | C39: 13768 | D39: 12935 | E39: 12454 | F39: 12207 | G39: 12377 | H39: 12920 | I39: 13524 | J39: 15115 | K39: 16601 | L39: 17700 | M39: 18702 | N39: 19718 | O39: 19524 | P39: 19509 | Q39: 19797 | R39: 19772 | S39: 19487 | T39: 19357 | U39: 21516 | V39: 21850 | W39: 21002 | X39: 19647 | Y39: 17568 | Z39: 15577 | AA39: =SUM(C39:Z39) -> 412627 | AB39: 21 | AC39: =+AA39*AB39+AA40*AB40+AA41*AB41 -> 12526287
B40: S | C40: 14009 | D40: 13163 | E40: 12679 | F40: 12359 | G40: 12377 | H40: 12685 | I40: 13058 | J40: 14557 | K40: 16087 | L40: 17153 | M40: 18010 | N40: 18724 | O40: 18724 | P40: 18456 | Q40: 18284 | R40: 18093 | S40: 17958 | T40: 18280 | U40: 20709 | V40: 20994 | W40: 20154 | X40: 18953 | Y40: 17239 | Z40: 15584 | AA40: =SUM(C40:Z40) -> 398289 | AB40: 4
B41: F | C41: 14360 | D41: 13485 | E41: 12874 | F41: 12440 | G41: 12270 | H41: 12209 | I41: 12189 | J41: 13176 | K41: 14402 | L41: 15480 | M41: 16287 | N41: 17044 | O41: 17453 | P41: 17431 | Q41: 17155 | R41: 16981 | S41: 16880 | T41: 17200 | U41: 19609 | V41: 20098 | W41: 19411 | X41: 18237 | Y41: 16521 | Z41: 14802 | AA41: =SUM(C41:Z41) -> 377994 | AB41: 6
A42: TOTAL AÑO | C42: =+SUM(C6:C41) -> 492974 | D42: =+SUM(D6:D41) -> 463679 | E42: =+SUM(E6:E41) -> 446018 | F42: =+SUM(F6:F41) -> 435098 | G42: =+SUM(G6:G41) -> 436451 | H42: =+SUM(H6:H41) -> 449132 | I42: =+SUM(I6:I41) -> 466115 | J42: =+SUM(J6:J41) -> 512371 | ... AC42: =+SUM(AC6:AC41) -> 145343987

Sheet Cantidades Ofertadas Prod 1
A1: CANTIDADES OFERTADAS PRODUCTO 1 AÑO 2026 MODALIDAD PAGUE LO CONTRATADO - kWh
A4: Periodo | B4: Tipo de día | C4: H01 | D4: H02 | E4: H03 | F4: H04 | G4: H05 | H4: H06 | I4: H07 | J4: H08 | K4: H09 | L4: H10 | M4: H11 | N4: H12 | O4: H13 | P4: H14 | Q4: H15 | R4: H16 | S4: H17 | T4: H18 | U4: H19 | V4: H20 | W4: H21 | X4: H22 | Y4: H23 | Z4: H24 | AA4: TOTAL DÍA | AB4: Días/ | AC4: TOTAL MES
AB5: mes
A6: 46023 | B6: O | C6: =ROUND('Anexo 11'!C6*'Anexo 1'!$D$10,0) -> 0 | D6: =ROUND('Anexo 11'!D6*'Anexo 1'!$D$10,0) -> 0 | E6: =ROUND('Anexo 11'!E6*'Anexo 1'!$D$10,0) -> 0 | F6: =ROUND('Anexo 11'!F6*'Anexo 1'!$D$10,0) -> 0 | G6: =ROUND('Anexo 11'!G6*'Anexo 1'!$D$10,0) -> 0 | H6: =ROUND('Anexo 11'!H6*'Anexo 1'!$D$10,0) -> 0 | I6: =ROUND('Anexo 11'!I6*'Anexo 1'!$D$10,0) -> 0 | J6: =ROUND('Anexo 11'!J6*'Anexo 1'!$D$10,0) -> 0 | ... Z6: =ROUND('Anexo 11'!Z6*'Anexo 1'!$D$10,0) -> 0 | AA6: =SUM(C6:Z6) -> 0 | AB6: 20 | AC6: =+AA6*AB6+AA7*AB7+AA8*AB8 -> 0
B7: S | C7: =ROUND('Anexo 11'!C7*'Anexo 1'!$D$10,0) -> 0 | D7: =ROUND('Anexo 11'!D7*'Anexo 1'!$D$10,0) -> 0 | E7: =ROUND('Anexo 11'!E7*'Anexo 1'!$D$10,0) -> 0 | F7: =ROUND('Anexo 11'!F7*'Anexo 1'!$D$10,0) -> 0 | G7: =ROUND('Anexo 11'!G7*'Anexo 1'!$D$10,0) -> 0 | H7: =ROUND('Anexo 11'!H7*'Anexo 1'!$D$10,0) -> 0 | I7: =ROUND('Anexo 11'!I7*'Anexo 1'!$D$10,0) -> 0 | J7: =ROUND('Anexo 11'!J7*'Anexo 1'!$D$10,0) -> 0 | ... Z7: =ROUND('Anexo 11'!Z7*'Anexo 1'!$D$10,0) -> 0 | AA7: =SUM(C7:Z7) -> 0 | AB7: 5
B8: F | C8: =ROUND('Anexo 11'!C8*'Anexo 1'!$D$10,0) -> 0 | D8: =ROUND('Anexo 11'!D8*'Anexo 1'!$D$10,0) -> 0 | E8: =ROUND('Anexo 11'!E8*'Anexo 1'!$D$10,0) -> 0 | F8: =ROUND('Anexo 11'!F8*'Anexo 1'!$D$10,0) -> 0 | G8: =ROUND('Anexo 11'!G8*'Anexo 1'!$D$10,0) -> 0 | H8: =ROUND('Anexo 11'!H8*'Anexo 1'!$D$10,0) -> 0 | I8: =ROUND('Anexo 11'!I8*'Anexo 1'!$D$10,0) -> 0 | J8: =ROUND('Anexo 11'!J8*'Anexo 1'!$D$10,0) -> 0 | ... Z8: =ROUND('Anexo 11'!Z8*'Anexo 1'!$D$10,0) -> 0 | AA8: =SUM(C8:Z8) -> 0 | AB8: 6
A9: 46054 | B9: O | C9: =ROUND('Anexo 11'!C9*'Anexo 1'!$D$10,0) -> 0 | D9: =ROUND('Anexo 11'!D9*'Anexo 1'!$D$10,0) -> 0 | E9: =ROUND('Anexo 11'!E9*'Anexo 1'!$D$10,0) -> 0 | F9: =ROUND('Anexo 11'!F9*'Anexo 1'!$D$10,0) -> 0 | G9: =ROUND('Anexo 11'!G9*'Anexo 1'!$D$10,0) -> 0 | H9: =ROUND('Anexo 11'!H9*'Anexo 1'!$D$10,0) -> 0 | I9: =ROUND('Anexo 11'!I9*'Anexo 1'!$D$10,0) -> 0 | J9: =ROUND('Anexo 11'!J9*'Anexo 1'!$D$10,0) -> 0 | ... Z9: =ROUND('Anexo 11'!Z9*'Anexo 1'!$D$10,0) -> 0 | AA9: =SUM(C9:Z9) -> 0 | AB9: 20 | AC9: =+AA9*AB9+AA10*AB10+AA11*AB11 -> 0
B10: S | C10: =ROUND('Anexo 11'!C10*'Anexo 1'!$D$10,0) -> 0 | D10: =ROUND('Anexo 11'!D10*'Anexo 1'!$D$10,0) -> 0 | E10: =ROUND('Anexo 11'!E10*'Anexo 1'!$D$10,0) -> 0 | F10: =ROUND('Anexo 11'!F10*'Anexo 1'!$D$10,0) -> 0 | G10: =ROUND('Anexo 11'!G10*'Anexo 1'!$D$10,0) -> 0 | H10: =ROUND('Anexo 11'!H10*'Anexo 1'!$D$10,0) -> 0 | I10: =ROUND('Anexo 11'!I10*'Anexo 1'!$D$10,0) -> 0 | J10: =ROUND('Anexo 11'!J10*'Anexo 1'!$D$10,0) -> 0 | ... Z10: =ROUND('Anexo 11'!Z10*'Anexo 1'!$D$10,0) -> 0 | AA10: =SUM(C10:Z10) -> 0 | AB10: 4
B11: F | C11: =ROUND('Anexo 11'!C11*'Anexo 1'!$D$10,0) -> 0 | D11: =ROUND('Anexo 11'!D11*'Anexo 1'!$D$10,0) -> 0 | E11: =ROUND('Anexo 11'!E11*'Anexo 1'!$D$10,0) -> 0 | F11: =ROUND('Anexo 11'!F11*'Anexo 1'!$D$10,0) -> 0 | G11: =ROUND('Anexo 11'!G11*'Anexo 1'!$D$10,0) -> 0 | H11: =ROUND('Anexo 11'!H11*'Anexo 1'!$D$10,0) -> 0 | I11: =ROUND('Anexo 11'!I11*'Anexo 1'!$D$10,0) -> 0 | J11: =ROUND('Anexo 11'!J11*'Anexo 1'!$D$10,0) -> 0 | ... Z11: =ROUND('Anexo 11'!Z11*'Anexo 1'!$D$10,0) -> 0 | AA11: =SUM(C11:Z11) -> 0 | AB11: 4
A12: 46082 | B12: O | C12: =ROUND('Anexo 11'!C12*'Anexo 1'!$D$10,0) -> 0 | D12: =ROUND('Anexo 11'!D12*'Anexo 1'!$D$10,0) -> 0 | E12: =ROUND('Anexo 11'!E12*'Anexo 1'!$D$10,0) -> 0 | F12: =ROUND('Anexo 11'!F12*'Anexo 1'!$D$10,0) -> 0 | G12: =ROUND('Anexo 11'!G12*'Anexo 1'!$D$10,0) -> 0 | H12: =ROUND('Anexo 11'!H12*'Anexo 1'!$D$10,0) -> 0 | I12: =ROUND('Anexo 11'!I12*'Anexo 1'!$D$10,0) -> 0 | J12: =ROUND('Anexo 11'!J12*'Anexo 1'!$D$10,0) -> 0 | ... Z12: =ROUND('Anexo 11'!Z12*'Anexo 1'!$D$10,0) -> 0 | AA12: =SUM(C12:Z12) -> 0 | AB12: 21 | AC12: =+AA12*AB12+AA13*AB13+AA14*AB14 -> 0
B13: S | C13: =ROUND('Anexo 11'!C13*'Anexo 1'!$D$10,0) -> 0 | D13: =ROUND('Anexo 11'!D13*'Anexo 1'!$D$10,0) -> 0 | E13: =ROUND('Anexo 11'!E13*'Anexo 1'!$D$10,0) -> 0 | F13: =ROUND('Anexo 11'!F13*'Anexo 1'!$D$10,0) -> 0 | G13: =ROUND('Anexo 11'!G13*'Anexo 1'!$D$10,0) -> 0 | H13: =ROUND('Anexo 11'!H13*'Anexo 1'!$D$10,0) -> 0 | I13: =ROUND('Anexo 11'!I13*'Anexo 1'!$D$10,0) -> 0 | J13: =ROUND('Anexo 11'!J13*'Anexo 1'!$D$10,0) -> 0 | ... Z13: =ROUND('Anexo 11'!Z13*'Anexo 1'!$D$10,0) -> 0 | AA13: =SUM(C13:Z13) -> 0 | AB13: 4
B14: F | C14: =ROUND('Anexo 11'!C14*'Anexo 1'!$D$10,0) -> 0 | D14: =ROUND('Anexo 11'!D14*'Anexo 1'!$D$10,0) -> 0 | E14: =ROUND('Anexo 11'!E14*'Anexo 1'!$D$10,0) -> 0 | F14: =ROUND('Anexo 11'!F14*'Anexo 1'!$D$10,0) -> 0 | G14: =ROUND('Anexo 11'!G14*'Anexo 1'!$D$10,0) -> 0 | H14: =ROUND('Anexo 11'!H14*'Anexo 1'!$D$10,0) -> 0 | I14: =ROUND('Anexo 11'!I14*'Anexo 1'!$D$10,0) -> 0 | J14: =ROUND('Anexo 11'!J14*'Anexo 1'!$D$10,0) -> 0 | ... Z14: =ROUND('Anexo 11'!Z14*'Anexo 1'!$D$10,0) -> 0 | AA14: =SUM(C14:Z14) -> 0 | AB14: 6
A15: 46113 | B15: O | C15: =ROUND('Anexo 11'!C15*'Anexo 1'!$D$10,0) -> 0 | D15: =ROUND('Anexo 11'!D15*'Anexo 1'!$D$10,0) -> 0 | E15: =ROUND('Anexo 11'!E15*'Anexo 1'!$D$10,0) -> 0 | F15: =ROUND('Anexo 11'!F15*'Anexo 1'!$D$10,0) -> 0 | G15: =ROUND('Anexo 11'!G15*'Anexo 1'!$D$10,0) -> 0 | H15: =ROUND('Anexo 11'!H15*'Anexo 1'!$D$10,0) -> 0 | I15: =ROUND('Anexo 11'!I15*'Anexo 1'!$D$10,0) -> 0 | J15: =ROUND('Anexo 11'!J15*'Anexo 1'!$D$10,0) -> 0 | ... Z15: =ROUND('Anexo 11'!Z15*'Anexo 1'!$D$10,0) -> 0 | AA15: =SUM(C15:Z15) -> 0 | AB15: 20 | AC15: =+AA15*AB15+AA16*AB16+AA17*AB17 -> 0
B16: S | C16: =ROUND('Anexo 11'!C16*'Anexo 1'!$D$10,0) -> 0 | D16: =ROUND('Anexo 11'!D16*'Anexo 1'!$D$10,0) -> 0 | E16: =ROUND('Anexo 11'!E16*'Anexo 1'!$D$10,0) -> 0 | F16: =ROUND('Anexo 11'!F16*'Anexo 1'!$D$10,0) -> 0 | G16: =ROUND('Anexo 11'!G16*'Anexo 1'!$D$10,0) -> 0 | H16: =ROUND('Anexo 11'!H16*'Anexo 1'!$D$10,0) -> 0 | I16: =ROUND('Anexo 11'!I16*'Anexo 1'!$D$10,0) -> 0 | J16: =ROUND('Anexo 11'!J16*'Anexo 1'!$D$10,0) -> 0 | ... Z16: =ROUND('Anexo 11'!Z16*'Anexo 1'!$D$10,0) -> 0 | AA16: =SUM(C16:Z16) -> 0 | AB16: 4
B17: F | C17: =ROUND('Anexo 11'!C17*'Anexo 1'!$D$10,0) -> 0 | D17: =ROUND('Anexo 11'!D17*'Anexo 1'!$D$10,0) -> 0 | E17: =ROUND('Anexo 11'!E17*'Anexo 1'!$D$10,0) -> 0 | F17: =ROUND('Anexo 11'!F17*'Anexo 1'!$D$10,0) -> 0 | G17: =ROUND('Anexo 11'!G17*'Anexo 1'!$D$10,0) -> 0 | H17: =ROUND('Anexo 11'!H17*'Anexo 1'!$D$10,0) -> 0 | I17: =ROUND('Anexo 11'!I17*'Anexo 1'!$D$10,0) -> 0 | J17: =ROUND('Anexo 11'!J17*'Anexo 1'!$D$10,0) -> 0 | ... Z17: =ROUND('Anexo 11'!Z17*'Anexo 1'!$D$10,0) -> 0 | AA17: =SUM(C17:Z17) -> 0 | AB17: 6
A18: 46143 | B18: O | C18: =ROUND('Anexo 11'!C18*'Anexo 1'!$D$10,0) -> 0 | D18: =ROUND('Anexo 11'!D18*'Anexo 1'!$D$10,0) -> 0 | E18: =ROUND('Anexo 11'!E18*'Anexo 1'!$D$10,0) -> 0 | F18: =ROUND('Anexo 11'!F18*'Anexo 1'!$D$10,0) -> 0 | G18: =ROUND('Anexo 11'!G18*'Anexo 1'!$D$10,0) -> 0 | H18: =ROUND('Anexo 11'!H18*'Anexo 1'!$D$10,0) -> 0 | I18: =ROUND('Anexo 11'!I18*'Anexo 1'!$D$10,0) -> 0 | J18: =ROUND('Anexo 11'!J18*'Anexo 1'!$D$10,0) -> 0 | ... Z18: =ROUND('Anexo 11'!Z18*'Anexo 1'!$D$10,0) -> 0 | AA18: =SUM(C18:Z18) -> 0 | AB18: 19 | AC18: =+AA18*AB18+AA19*AB19+AA20*AB20 -> 0
B19: S | C19: =ROUND('Anexo 11'!C19*'Anexo 1'!$D$10,0) -> 0 | D19: =ROUND('Anexo 11'!D19*'Anexo 1'!$D$10,0) -> 0 | E19: =ROUND('Anexo 11'!E19*'Anexo 1'!$D$10,0) -> 0 | F19: =ROUND('Anexo 11'!F19*'Anexo 1'!$D$10,0) -> 0 | G19: =ROUND('Anexo 11'!G19*'Anexo 1'!$D$10,0) -> 0 | H19: =ROUND('Anexo 11'!H19*'Anexo 1'!$D$10,0) -> 0 | I19: =ROUND('Anexo 11'!I19*'Anexo 1'!$D$10,0) -> 0 | J19: =ROUND('Anexo 11'!J19*'Anexo 1'!$D$10,0) -> 0 | ... Z19: =ROUND('Anexo 11'!Z19*'Anexo 1'!$D$10,0) -> 0 | AA19: =SUM(C19:Z19) -> 0 | AB19: 5
B20: F | C20: =ROUND('Anexo 11'!C20*'Anexo 1'!$D$10,0) -> 0 | D20: =ROUND('Anexo 11'!D20*'Anexo 1'!$D$10,0) -> 0 | E20: =ROUND('Anexo 11'!E20*'Anexo 1'!$D$10,0) -> 0 | F20: =ROUND('Anexo 11'!F20*'Anexo 1'!$D$10,0) -> 0 | G20: =ROUND('Anexo 11'!G20*'Anexo 1'!$D$10,0) -> 0 | H20: =ROUND('Anexo 11'!H20*'Anexo 1'!$D$10,0) -> 0 | I20: =ROUND('Anexo 11'!I20*'Anexo 1'!$D$10,0) -> 0 | J20: =ROUND('Anexo 11'!J20*'Anexo 1'!$D$10,0) -> 0 | ... Z20: =ROUND('Anexo 11'!Z20*'Anexo 1'!$D$10,0) -> 0 | AA20: =SUM(C20:Z20) -> 0 | AB20: 7
A21: 46174 | B21: O | C21: =ROUND('Anexo 11'!C21*'Anexo 1'!$D$10,0) -> 0 | D21: =ROUND('Anexo 11'!D21*'Anexo 1'!$D$10,0) -> 0 | E21: =ROUND('Anexo 11'!E21*'Anexo 1'!$D$10,0) -> 0 | F21: =ROUND('Anexo 11'!F21*'Anexo 1'!$D$10,0) -> 0 | G21: =ROUND('Anexo 11'!G21*'Anexo 1'!$D$10,0) -> 0 | H21: =ROUND('Anexo 11'!H21*'Anexo 1'!$D$10,0) -> 0 | I21: =ROUND('Anexo 11'!I21*'Anexo 1'!$D$10,0) -> 0 | J21: =ROUND('Anexo 11'!J21*'Anexo 1'!$D$10,0) -> 0 | ... Z21: =ROUND('Anexo 11'!Z21*'Anexo 1'!$D$10,0) -> 0 | AA21: =SUM(C21:Z21) -> 0 | AB21: 19 | AC21: =+AA21*AB21+AA22*AB22+AA23*AB23 -> 0
B22: S | C22: =ROUND('Anexo 11'!C22*'Anexo 1'!$D$10,0) -> 0 | D22: =ROUND('Anexo 11'!D22*'Anexo 1'!$D$10,0) -> 0 | E22: =ROUND('Anexo 11'!E22*'Anexo 1'!$D$10,0) -> 0 | F22: =ROUND('Anexo 11'!F22*'Anexo 1'!$D$10,0) -> 0 | G22: =ROUND('Anexo 11'!G22*'Anexo 1'!$D$10,0) -> 0 | H22: =ROUND('Anexo 11'!H22*'Anexo 1'!$D$10,0) -> 0 | I22: =ROUND('Anexo 11'!I22*'Anexo 1'!$D$10,0) -> 0 | J22: =ROUND('Anexo 11'!J22*'Anexo 1'!$D$10,0) -> 0 | ... Z22: =ROUND('Anexo 11'!Z22*'Anexo 1'!$D$10,0) -> 0 | AA22: =SUM(C22:Z22) -> 0 | AB22: 4
B23: F | C23: =ROUND('Anexo 11'!C23*'Anexo 1'!$D$10,0) -> 0 | D23: =ROUND('Anexo 11'!D23*'Anexo 1'!$D$10,0) -> 0 | E23: =ROUND('Anexo 11'!E23*'Anexo 1'!$D$10,0) -> 0 | F23: =ROUND('Anexo 11'!F23*'Anexo 1'!$D$10,0) -> 0 | G23: =ROUND('Anexo 11'!G23*'Anexo 1'!$D$10,0) -> 0 | H23: =ROUND('Anexo 11'!H23*'Anexo 1'!$D$10,0) -> 0 | I23: =ROUND('Anexo 11'!I23*'Anexo 1'!$D$10,0) -> 0 | J23: =ROUND('Anexo 11'!J23*'Anexo 1'!$D$10,0) -> 0 | ... Z23: =ROUND('Anexo 11'!Z23*'Anexo 1'!$D$10,0) -> 0 | AA23: =SUM(C23:Z23) -> 0 | AB23: 7
A24: 46204 | B24: O | C24: =ROUND('Anexo 11'!C24*'Anexo 1'!$D$10,0) -> 0 | D24: =ROUND('Anexo 11'!D24*'Anexo 1'!$D$10,0) -> 0 | E24: =ROUND('Anexo 11'!E24*'Anexo 1'!$D$10,0) -> 0 | F24: =ROUND('Anexo 11'!F24*'Anexo 1'!$D$10,0) -> 0 | G24: =ROUND('Anexo 11'!G24*'Anexo 1'!$D$10,0) -> 0 | H24: =ROUND('Anexo 11'!H24*'Anexo 1'!$D$10,0) -> 0 | I24: =ROUND('Anexo 11'!I24*'Anexo 1'!$D$10,0) -> 0 | J24: =ROUND('Anexo 11'!J24*'Anexo 1'!$D$10,0) -> 0 | ... Z24: =ROUND('Anexo 11'!Z24*'Anexo 1'!$D$10,0) -> 0 | AA24: =SUM(C24:Z24) -> 0 | AB24: 22 | AC24: =+AA24*AB24+AA25*AB25+AA26*AB26 -> 0
B25: S | C25: =ROUND('Anexo 11'!C25*'Anexo 1'!$D$10,0) -> 0 | D25: =ROUND('Anexo 11'!D25*'Anexo 1'!$D$10,0) -> 0 | E25: =ROUND('Anexo 11'!E25*'Anexo 1'!$D$10,0) -> 0 | F25: =ROUND('Anexo 11'!F25*'Anexo 1'!$D$10,0) -> 0 | G25: =ROUND('Anexo 11'!G25*'Anexo 1'!$D$10,0) -> 0 | H25: =ROUND('Anexo 11'!H25*'Anexo 1'!$D$10,0) -> 0 | I25: =ROUND('Anexo 11'!I25*'Anexo 1'!$D$10,0) -> 0 | J25: =ROUND('Anexo 11'!J25*'Anexo 1'!$D$10,0) -> 0 | ... Z25: =ROUND('Anexo 11'!Z25*'Anexo 1'!$D$10,0) -> 0 | AA25: =SUM(C25:Z25) -> 0 | AB25: 4
B26: F | C26: =ROUND('Anexo 11'!C26*'Anexo 1'!$D$10,0) -> 0 | D26: =ROUND('Anexo 11'!D26*'Anexo 1'!$D$10,0) -> 0 | E26: =ROUND('Anexo 11'!E26*'Anexo 1'!$D$10,0) -> 0 | F26: =ROUND('Anexo 11'!F26*'Anexo 1'!$D$10,0) -> 0 | G26: =ROUND('Anexo 11'!G26*'Anexo 1'!$D$10,0) -> 0 | H26: =ROUND('Anexo 11'!H26*'Anexo 1'!$D$10,0) -> 0 | I26: =ROUND('Anexo 11'!I26*'Anexo 1'!$D$10,0) -> 0 | J26: =ROUND('Anexo 11'!J26*'Anexo 1'!$D$10,0) -> 0 | ... Z26: =ROUND('Anexo 11'!Z26*'Anexo 1'!$D$10,0) -> 0 | AA26: =SUM(C26:Z26) -> 0 | AB26: 5
A27: 46235 | B27: O | C27: =ROUND('Anexo 11'!C27*'Anexo 1'!$D$10,0) -> 0 | D27: =ROUND('Anexo 11'!D27*'Anexo 1'!$D$10,0) -> 0 | E27: =ROUND('Anexo 11'!E27*'Anexo 1'!$D$10,0) -> 0 | F27: =ROUND('Anexo 11'!F27*'Anexo 1'!$D$10,0) -> 0 | G27: =ROUND('Anexo 11'!G27*'Anexo 1'!$D$10,0) -> 0 | H27: =ROUND('Anexo 11'!H27*'Anexo 1'!$D$10,0) -> 0 | I27: =ROUND('Anexo 11'!I27*'Anexo 1'!$D$10,0) -> 0 | J27: =ROUND('Anexo 11'!J27*'Anexo 1'!$D$10,0) -> 0 | ... Z27: =ROUND('Anexo 11'!Z27*'Anexo 1'!$D$10,0) -> 0 | AA27: =SUM(C27:Z27) -> 0 | AB27: 19 | AC27: =+AA27*AB27+AA28*AB28+AA29*AB29 -> 0
B28: S | C28: =ROUND('Anexo 11'!C28*'Anexo 1'!$D$10,0) -> 0 | D28: =ROUND('Anexo 11'!D28*'Anexo 1'!$D$10,0) -> 0 | E28: =ROUND('Anexo 11'!E28*'Anexo 1'!$D$10,0) -> 0 | F28: =ROUND('Anexo 11'!F28*'Anexo 1'!$D$10,0) -> 0 | G28: =ROUND('Anexo 11'!G28*'Anexo 1'!$D$10,0) -> 0 | H28: =ROUND('Anexo 11'!H28*'Anexo 1'!$D$10,0) -> 0 | I28: =ROUND('Anexo 11'!I28*'Anexo 1'!$D$10,0) -> 0 | J28: =ROUND('Anexo 11'!J28*'Anexo 1'!$D$10,0) -> 0 | ... Z28: =ROUND('Anexo 11'!Z28*'Anexo 1'!$D$10,0) -> 0 | AA28: =SUM(C28:Z28) -> 0 | AB28: 5
B29: F | C29: =ROUND('Anexo 11'!C29*'Anexo 1'!$D$10,0) -> 0 | D29: =ROUND('Anexo 11'!D29*'Anexo 1'!$D$10,0) -> 0 | E29: =ROUND('Anexo 11'!E29*'Anexo 1'!$D$10,0) -> 0 | F29: =ROUND('Anexo 11'!F29*'Anexo 1'!$D$10,0) -> 0 | G29: =ROUND('Anexo 11'!G29*'Anexo 1'!$D$10,0) -> 0 | H29: =ROUND('Anexo 11'!H29*'Anexo 1'!$D$10,0) -> 0 | I29: =ROUND('Anexo 11'!I29*'Anexo 1'!$D$10,0) -> 0 | J29: =ROUND('Anexo 11'!J29*'Anexo 1'!$D$10,0) -> 0 | ... Z29: =ROUND('Anexo 11'!Z29*'Anexo 1'!$D$10,0) -> 0 | AA29: =SUM(C29:Z29) -> 0 | AB29: 7
A30: 46266 | B30: O | C30: =ROUND('Anexo 11'!C30*'Anexo 1'!$D$10,0) -> 0 | D30: =ROUND('Anexo 11'!D30*'Anexo 1'!$D$10,0) -> 0 | E30: =ROUND('Anexo 11'!E30*'Anexo 1'!$D$10,0) -> 0 | F30: =ROUND('Anexo 11'!F30*'Anexo 1'!$D$10,0) -> 0 | G30: =ROUND('Anexo 11'!G30*'Anexo 1'!$D$10,0) -> 0 | H30: =ROUND('Anexo 11'!H30*'Anexo 1'!$D$10,0) -> 0 | I30: =ROUND('Anexo 11'!I30*'Anexo 1'!$D$10,0) -> 0 | J30: =ROUND('Anexo 11'!J30*'Anexo 1'!$D$10,0) -> 0 | ... Z30: =ROUND('Anexo 11'!Z30*'Anexo 1'!$D$10,0) -> 0 | AA30: =SUM(C30:Z30) -> 0 | AB30: 22 | AC30: =+AA30*AB30+AA31*AB31+AA32*AB32 -> 0
B31: S | C31: =ROUND('Anexo 11'!C31*'Anexo 1'!$D$10,0) -> 0 | D31: =ROUND('Anexo 11'!D31*'Anexo 1'!$D$10,0) -> 0 | E31: =ROUND('Anexo 11'!E31*'Anexo 1'!$D$10,0) -> 0 | F31: =ROUND('Anexo 11'!F31*'Anexo 1'!$D$10,0) -> 0 | G31: =ROUND('Anexo 11'!G31*'Anexo 1'!$D$10,0) -> 0 | H31: =ROUND('Anexo 11'!H31*'Anexo 1'!$D$10,0) -> 0 | I31: =ROUND('Anexo 11'!I31*'Anexo 1'!$D$10,0) -> 0 | J31: =ROUND('Anexo 11'!J31*'Anexo 1'!$D$10,0) -> 0 | ... Z31: =ROUND('Anexo 11'!Z31*'Anexo 1'!$D$10,0) -> 0 | AA31: =SUM(C31:Z31) -> 0 | AB31: 4
B32: F | C32: =ROUND('Anexo 11'!C32*'Anexo 1'!$D$10,0) -> 0 | D32: =ROUND('Anexo 11'!D32*'Anexo 1'!$D$10,0) -> 0 | E32: =ROUND('Anexo 11'!E32*'Anexo 1'!$D$10,0) -> 0 | F32: =ROUND('Anexo 11'!F32*'Anexo 1'!$D$10,0) -> 0 | G32: =ROUND('Anexo 11'!G32*'Anexo 1'!$D$10,0) -> 0 | H32: =ROUND('Anexo 11'!H32*'Anexo 1'!$D$10,0) -> 0 | I32: =ROUND('Anexo 11'!I32*'Anexo 1'!$D$10,0) -> 0 | J32: =ROUND('Anexo 11'!J32*'Anexo 1'!$D$10,0) -> 0 | ... Z32: =ROUND('Anexo 11'!Z32*'Anexo 1'!$D$10,0) -> 0 | AA32: =SUM(C32:Z32) -> 0 | AB32: 4
A33: 46296 | B33: O | C33: =ROUND('Anexo 11'!C33*'Anexo 1'!$D$10,0) -> 0 | D33: =ROUND('Anexo 11'!D33*'Anexo 1'!$D$10,0) -> 0 | E33: =ROUND('Anexo 11'!E33*'Anexo 1'!$D$10,0) -> 0 | F33: =ROUND('Anexo 11'!F33*'Anexo 1'!$D$10,0) -> 0 | G33: =ROUND('Anexo 11'!G33*'Anexo 1'!$D$10,0) -> 0 | H33: =ROUND('Anexo 11'!H33*'Anexo 1'!$D$10,0) -> 0 | I33: =ROUND('Anexo 11'!I33*'Anexo 1'!$D$10,0) -> 0 | J33: =ROUND('Anexo 11'!J33*'Anexo 1'!$D$10,0) -> 0 | ... Z33: =ROUND('Anexo 11'!Z33*'Anexo 1'!$D$10,0) -> 0 | AA33: =SUM(C33:Z33) -> 0 | AB33: 21 | AC33: =+AA33*AB33+AA34*AB34+AA35*AB35 -> 0
B34: S | C34: =ROUND('Anexo 11'!C34*'Anexo 1'!$D$10,0) -> 0 | D34: =ROUND('Anexo 11'!D34*'Anexo 1'!$D$10,0) -> 0 | E34: =ROUND('Anexo 11'!E34*'Anexo 1'!$D$10,0) -> 0 | F34: =ROUND('Anexo 11'!F34*'Anexo 1'!$D$10,0) -> 0 | G34: =ROUND('Anexo 11'!G34*'Anexo 1'!$D$10,0) -> 0 | H34: =ROUND('Anexo 11'!H34*'Anexo 1'!$D$10,0) -> 0 | I34: =ROUND('Anexo 11'!I34*'Anexo 1'!$D$10,0) -> 0 | J34: =ROUND('Anexo 11'!J34*'Anexo 1'!$D$10,0) -> 0 | ... Z34: =ROUND('Anexo 11'!Z34*'Anexo 1'!$D$10,0) -> 0 | AA34: =SUM(C34:Z34) -> 0 | AB34: 5
B35: F | C35: =ROUND('Anexo 11'!C35*'Anexo 1'!$D$10,0) -> 0 | D35: =ROUND('Anexo 11'!D35*'Anexo 1'!$D$10,0) -> 0 | E35: =ROUND('Anexo 11'!E35*'Anexo 1'!$D$10,0) -> 0 | F35: =ROUND('Anexo 11'!F35*'Anexo 1'!$D$10,0) -> 0 | G35: =ROUND('Anexo 11'!G35*'Anexo 1'!$D$10,0) -> 0 | H35: =ROUND('Anexo 11'!H35*'Anexo 1'!$D$10,0) -> 0 | I35: =ROUND('Anexo 11'!I35*'Anexo 1'!$D$10,0) -> 0 | J35: =ROUND('Anexo 11'!J35*'Anexo 1'!$D$10,0) -> 0 | ... Z35: =ROUND('Anexo 11'!Z35*'Anexo 1'!$D$10,0) -> 0 | AA35: =SUM(C35:Z35) -> 0 | AB35: 5
A36: 46327 | B36: O | C36: =ROUND('Anexo 11'!C36*'Anexo 1'!$D$10,0) -> 0 | D36: =ROUND('Anexo 11'!D36*'Anexo 1'!$D$10,0) -> 0 | E36: =ROUND('Anexo 11'!E36*'Anexo 1'!$D$10,0) -> 0 | F36: =ROUND('Anexo 11'!F36*'Anexo 1'!$D$10,0) -> 0 | G36: =ROUND('Anexo 11'!G36*'Anexo 1'!$D$10,0) -> 0 | H36: =ROUND('Anexo 11'!H36*'Anexo 1'!$D$10,0) -> 0 | I36: =ROUND('Anexo 11'!I36*'Anexo 1'!$D$10,0) -> 0 | J36: =ROUND('Anexo 11'!J36*'Anexo 1'!$D$10,0) -> 0 | ... Z36: =ROUND('Anexo 11'!Z36*'Anexo 1'!$D$10,0) -> 0 | AA36: =SUM(C36:Z36) -> 0 | AB36: 19 | AC36: =+AA36*AB36+AA37*AB37+AA38*AB38 -> 0
B37: S | C37: =ROUND('Anexo 11'!C37*'Anexo 1'!$D$10,0) -> 0 | D37: =ROUND('Anexo 11'!D37*'Anexo 1'!$D$10,0) -> 0 | E37: =ROUND('Anexo 11'!E37*'Anexo 1'!$D$10,0) -> 0 | F37: =ROUND('Anexo 11'!F37*'Anexo 1'!$D$10,0) -> 0 | G37: =ROUND('Anexo 11'!G37*'Anexo 1'!$D$10,0) -> 0 | H37: =ROUND('Anexo 11'!H37*'Anexo 1'!$D$10,0) -> 0 | I37: =ROUND('Anexo 11'!I37*'Anexo 1'!$D$10,0) -> 0 | J37: =ROUND('Anexo 11'!J37*'Anexo 1'!$D$10,0) -> 0 | ... Z37: =ROUND('Anexo 11'!Z37*'Anexo 1'!$D$10,0) -> 0 | AA37: =SUM(C37:Z37) -> 0 | AB37: 4
B38: F | C38: =ROUND('Anexo 11'!C38*'Anexo 1'!$D$10,0) -> 0 | D38: =ROUND('Anexo 11'!D38*'Anexo 1'!$D$10,0) -> 0 | E38: =ROUND('Anexo 11'!E38*'Anexo 1'!$D$10,0) -> 0 | F38: =ROUND('Anexo 11'!F38*'Anexo 1'!$D$10,0) -> 0 | G38: =ROUND('Anexo 11'!G38*'Anexo 1'!$D$10,0) -> 0 | H38: =ROUND('Anexo 11'!H38*'Anexo 1'!$D$10,0) -> 0 | I38: =ROUND('Anexo 11'!I38*'Anexo 1'!$D$10,0) -> 0 | J38: =ROUND('Anexo 11'!J38*'Anexo 1'!$D$10,0) -> 0 | ... Z38: =ROUND('Anexo 11'!Z38*'Anexo 1'!$D$10,0) -> 0 | AA38: =SUM(C38:Z38) -> 0 | AB38: 7
A39: 46357 | B39: O | C39: =ROUND('Anexo 11'!C39*'Anexo 1'!$D$10,0) -> 0 | D39: =ROUND('Anexo 11'!D39*'Anexo 1'!$D$10,0) -> 0 | E39: =ROUND('Anexo 11'!E39*'Anexo 1'!$D$10,0) -> 0 | F39: =ROUND('Anexo 11'!F39*'Anexo 1'!$D$10,0) -> 0 | G39: =ROUND('Anexo 11'!G39*'Anexo 1'!$D$10,0) -> 0 | H39: =ROUND('Anexo 11'!H39*'Anexo 1'!$D$10,0) -> 0 | I39: =ROUND('Anexo 11'!I39*'Anexo 1'!$D$10,0) -> 0 | J39: =ROUND('Anexo 11'!J39*'Anexo 1'!$D$10,0) -> 0 | ... Z39: =ROUND('Anexo 11'!Z39*'Anexo 1'!$D$10,0) -> 0 | AA39: =SUM(C39:Z39) -> 0 | AB39: 21 | AC39: =+AA39*AB39+AA40*AB40+AA41*AB41 -> 0
B40: S | C40: =ROUND('Anexo 11'!C40*'Anexo 1'!$D$10,0) -> 0 | D40: =ROUND('Anexo 11'!D40*'Anexo 1'!$D$10,0) -> 0 | E40: =ROUND('Anexo 11'!E40*'Anexo 1'!$D$10,0) -> 0 | F40: =ROUND('Anexo 11'!F40*'Anexo 1'!$D$10,0) -> 0 | G40: =ROUND('Anexo 11'!G40*'Anexo 1'!$D$10,0) -> 0 | H40: =ROUND('Anexo 11'!H40*'Anexo 1'!$D$10,0) -> 0 | I40: =ROUND('Anexo 11'!I40*'Anexo 1'!$D$10,0) -> 0 | J40: =ROUND('Anexo 11'!J40*'Anexo 1'!$D$10,0) -> 0 | ... Z40: =ROUND('Anexo 11'!Z40*'Anexo 1'!$D$10,0) -> 0 | AA40: =SUM(C40:Z40) -> 0 | AB40: 4
B41: F | C41: =ROUND('Anexo 11'!C41*'Anexo 1'!$D$10,0) -> 0 | D41: =ROUND('Anexo 11'!D41*'Anexo 1'!$D$10,0) -> 0 | E41: =ROUND('Anexo 11'!E41*'Anexo 1'!$D$10,0) -> 0 | F41: =ROUND('Anexo 11'!F41*'Anexo 1'!$D$10,0) -> 0 | G41: =ROUND('Anexo 11'!G41*'Anexo 1'!$D$10,0) -> 0 | H41: =ROUND('Anexo 11'!H41*'Anexo 1'!$D$10,0) -> 0 | I41: =ROUND('Anexo 11'!I41*'Anexo 1'!$D$10,0) -> 0 | J41: =ROUND('Anexo 11'!J41*'Anexo 1'!$D$10,0) -> 0 | ... Z41: =ROUND('Anexo 11'!Z41*'Anexo 1'!$D$10,0) -> 0 | AA41: =SUM(C41:Z41) -> 0 | AB41: 6
A42: TOTAL AÑO | C42: =+SUM(C6:C41) -> 0 | D42: =+SUM(D6:D41) -> 0 | E42: =+SUM(E6:E41) -> 0 | F42: =+SUM(F6:F41) -> 0 | G42: =+SUM(G6:G41) -> 0 | H42: =+SUM(H6:H41) -> 0 | I42: =+SUM(I6:I41) -> 0 | J42: =+SUM(J6:J41) -> 0 | ... AC42: =+SUM(AC6:AC41) -> 0

Sheet Anexo 2
B3: ANEXO No 2 - PRODUCTO No. 2 - CURVA
B4: PAGUE LO CONTRATADO AÑO 2027
B5: PRECIO OFERTADO EN $ / kWh DE ABRIL DE 2025
B8: MES | C8: ENERGIA SOLICITADA kWh/MES | D8: % OFERTADO ANUAL | E8: ENERGIA OFERTADA kWh/MES | F8: PRECIO OFERTADO ANUAL $/kWh
B10: 46388 | C10: =+'Anexo 12'!AC6 -> 10657301 | E10: =+'Cantidades Ofertadas Prod 2'!AC6 -> 0
B11: 46419 | C11: =+'Anexo 12'!AC9 -> 9846236 | E11: =+'Cantidades Ofertadas Prod 2'!AC9 -> 0
B12: 46447 | C12: =+'Anexo 12'!AC12 -> 10580321 | E12: =+'Cantidades Ofertadas Prod 2'!AC12 -> 0
B13: 46478 | C13: =+'Anexo 12'!AC15 -> 10076204 | E13: =+'Cantidades Ofertadas Prod 2'!AC15 -> 0
B14: 46508 | C14: =+'Anexo 12'!AC18 -> 10395490 | E14: =+'Cantidades Ofertadas Prod 2'!AC18 -> 0
B15: 46539 | C15: =+'Anexo 12'!AC21 -> 10103194 | E15: =+'Cantidades Ofertadas Prod 2'!AC21 -> 0
B16: 46569 | C16: =+'Anexo 12'!AC24 -> 10674199 | E16: =+'Cantidades Ofertadas Prod 2'!AC24 -> 0
B17: 46600 | C17: =+'Anexo 12'!AC27 -> 10863111 | E17: =+'Cantidades Ofertadas Prod 2'!AC27 -> 0
B18: 46631 | C18: =+'Anexo 12'!AC30 -> 10701632 | E18: =+'Cantidades Ofertadas Prod 2'!AC30 -> 0
B19: 46661 | C19: =+'Anexo 12'!AC33 -> 10567965 | E19: =+'Cantidades Ofertadas Prod 2'!AC33 -> 0
B20: 46692 | C20: =+'Anexo 12'!AC36 -> 10060220 | E20: =+'Cantidades Ofertadas Prod 2'!AC36 -> 0
B21: 46722 | C21: =+'Anexo 12'!AC39 -> 10807043 | E21: =+'Cantidades Ofertadas Prod 2'!AC39 -> 0
B22: TOTAL | C22: =+SUM(C10:C21) -> 125332916 | E22: =SUM(E10:E21) -> 0 | F22: =+F10 -> 0
B23: *Solo se debe ingresar valores en las celdas en color Naranja
B24: * Se debe ofertar un unico % para todos los meses del año.
B25: * Los % ofertados se aplicaran a las curvas de carga de la hoja "Anexo 12".
B26: * La energia ofertada se calcula de manera automatica en la hoja "Cantidades Ofertadas Prod2"
B27: * Se debe ofertar un unico precio por producto.
B28: * Para ofertas planas se debe diligenciar el anexo 2A, con un tope horario de 14.307 kWh
B31: ____________________________________________
B32: Firma del Representante Legal
B33: o Apoderado General (Responsable del negocio)

Sheet Anexo 2A
B3: ANEXO No 2A - PRODUCTO No. 2 - OFERTA PLANA
B4: PAGUE LO CONTRATADO AÑO 2027
B5: PRECIO OFERTADO EN $ / kWh DE ABRIL DE 2025
B8: MES | C8: ENERGIA MAXIMA A OFERTAR kWh/MES | D8: kWh OFERTADO | E8: ENERGIA OFERTADA kWh/MES | F8: PRECIO OFERTADO ANUAL $/kWh
A9: 14307
A10: 31 | B10: 46388 | C10: =+$A$9*A10*24 -> 10644408 | E10: =+$D$10*A10*24 -> 0
A11: 28 | B11: 46419 | C11: =+$A$9*A11*24 -> 9614304 | E11: =+$D$10*A11*24 -> 0
A12: 31 | B12: 46447 | C12: =+$A$9*A12*24 -> 10644408 | E12: =+$D$10*A12*24 -> 0
A13: 30 | B13: 46478 | C13: =+$A$9*A13*24 -> 10301040 | E13: =+$D$10*A13*24 -> 0
A14: 31 | B14: 46508 | C14: =+$A$9*A14*24 -> 10644408 | E14: =+$D$10*A14*24 -> 0
A15: 30 | B15: 46539 | C15: =+$A$9*A15*24 -> 10301040 | E15: =+$D$10*A15*24 -> 0
A16: 31 | B16: 46569 | C16: =+$A$9*A16*24 -> 10644408 | E16: =+$D$10*A16*24 -> 0
A17: 31 | B17: 46600 | C17: =+$A$9*A17*24 -> 10644408 | E17: =+$D$10*A17*24 -> 0
A18: 30 | B18: 46631 | C18: =+$A$9*A18*24 -> 10301040 | E18: =+$D$10*A18*24 -> 0
A19: 31 | B19: 46661 | C19: =+$A$9*A19*24 -> 10644408 | E19: =+$D$10*A19*24 -> 0
A20: 30 | B20: 46692 | C20: =+$A$9*A20*24 -> 10301040 | E20: =+$D$10*A20*24 -> 0
A21: 31 | B21: 46722 | C21: =+$A$9*A21*24 -> 10644408 | E21: =+$D$10*A21*24 -> 0
B22: TOTAL | C22: =+SUM(C10:C21) -> 125329320 | E22: =SUM(E10:E21) -> 0 | F22: =+F10 -> 0
B23: *Solo se debe ingresar valores en las celdas en color Naranja
B24: * Se debe oferta un valor de kWh el cual se aplica para todas las horas del año, con un tope horario de 14.307 kWh
B25: * Se debe ofertar un unico precio por producto.
B26: * A las ofertas planas al momento de la evaluación se le adicionarán 5 $/kWh al precio ofertado; con el fin de hacerlas comparables con las Ofertas que siguen la curva
B31: ____________________________________________
B32: Firma del Representante Legal
B33: o Apoderado General (Responsable del negocio)

Sheet Anexo 12
A1: CURVAS REQUERIDAS PRODUCTO 2 AÑO 2027 MODALIDAD PAGUE LO CONTRATADO - kWh
A4: Periodo | B4: Tipo de día | C4: H01 | D4: H02 | E4: H03 | F4: H04 | G4: H05 | H4: H06 | I4: H07 | J4: H08 | K4: H09 | L4: H10 | M4: H11 | N4: H12 | O4: H13 | P4: H14 | Q4: H15 | R4: H16 | S4: H17 | T4: H18 | U4: H19 | V4: H20 | W4: H21 | X4: H22 | Y4: H23 | Z4: H24 | AA4: TOTAL DÍA | AB4: Días/ | AC4: TOTAL MES
AB5: mes
A6: 46388 | B6: O | C6: 11610 | D6: 10939 | E6: 10535 | F6: 10326 | G6: 10471 | H6: 11094 | I6: 11687 | J6: 12797 | K6: 14046 | L6: 14992 | M6: 15955 | N6: 16864 | O6: 16709 | P6: 16729 | Q6: 17008 | R6: 17061 | S6: 16866 | T6: 16501 | U6: 17714 | V6: 18724 | W6: 18045 | X6: 16854 | Y6: 14940 | Z6: 13007 | AA6: =SUM(C6:Z6) -> 351474 | AB6: 19 | AC6: =+AA6*AB6+AA7*AB7+AA8*AB8 -> 10657301
B7: S | C7: 11890 | D7: 11132 | E7: 10670 | F7: 10378 | G7: 10387 | H7: 10736 | I7: 11143 | J7: 12272 | K7: 13667 | L7: 14721 | M7: 15510 | N7: 16291 | O7: 16375 | P7: 16214 | Q7: 16038 | R7: 15952 | S7: 15832 | T7: 15817 | U7: 17337 | V7: 18420 | W7: 17679 | X7: 16575 | Y7: 15009 | Z7: 13439 | AA7: =SUM(C7:Z7) -> 343484 | AB7: 5
B8: F | C8: 12464 | D8: 11646 | E8: 11103 | F8: 10719 | G8: 10532 | H8: 10606 | I8: 10502 | J8: 11122 | K8: 12184 | L8: 13120 | M8: 13810 | N8: 14529 | O8: 14955 | P8: 14904 | Q8: 14634 | R8: 14478 | S8: 14399 | T8: 14477 | U8: 16136 | V8: 17320 | W8: 16837 | X8: 15805 | Y8: 14213 | Z8: 12630 | AA8: =SUM(C8:Z8) -> 323125 | AB8: 7
A9: 46419 | B9: O | C9: 11678 | D9: 11032 | E9: 10661 | F9: 10478 | G9: 10689 | H9: 11657 | I9: 12429 | J9: 13266 | K9: 14377 | L9: 15209 | M9: 16119 | N9: 16962 | O9: 16623 | P9: 16752 | Q9: 17143 | R9: 17214 | S9: 17022 | T9: 16577 | U9: 17503 | V9: 18828 | W9: 18175 | X9: 16928 | Y9: 14961 | Z9: 13004 | AA9: =SUM(C9:Z9) -> 355287 | AB9: 20 | AC9: =+AA9*AB9+AA10*AB10+AA11*AB11 -> 9846236
B10: S | C10: 12110 | D10: 11394 | E10: 10934 | F10: 10669 | G10: 10701 | H10: 11076 | I10: 11676 | J10: 12804 | K10: 14254 | L10: 15264 | M10: 16066 | N10: 16845 | O10: 16867 | P10: 16651 | Q10: 16466 | R10: 16364 | S10: 16225 | T10: 16174 | U10: 17404 | V10: 18737 | W10: 18003 | X10: 16960 | Y10: 15470 | Z10: 13814 | AA10: =SUM(C10:Z10) -> 352928 | AB10: 4
B11: F | C11: 12578 | D11: 11765 | E11: 11270 | F11: 10898 | G11: 10779 | H11: 10891 | I11: 10980 | J11: 11707 | K11: 12872 | L11: 13825 | M11: 14457 | N11: 15140 | O11: 15523 | P11: 15398 | Q11: 15093 | R11: 14908 | S11: 14815 | T11: 14893 | U11: 16216 | V11: 17688 | W11: 17239 | X11: 16169 | Y11: 14412 | Z11: 12680 | AA11: =SUM(C11:Z11) -> 332196 | AB11: 4
A12: 46447 | B12: O | C12: 11430 | D12: 10811 | E12: 10469 | F12: 10298 | G12: 10525 | H12: 11474 | I12: 12139 | J12: 13066 | K12: 14133 | L12: 14932 | M12: 15784 | N12: 16552 | O12: 16246 | P12: 16313 | Q12: 16650 | R12: 16705 | S12: 16558 | T12: 16245 | U12: 17401 | V12: 18531 | W12: 17858 | X12: 16590 | Y12: 14662 | Z12: 12759 | AA12: =SUM(C12:Z12) -> 348131 | AB12: 20 | AC12: =+AA12*AB12+AA13*AB13+AA14*AB14 -> 10580321
B13: S | C13: 11790 | D13: 11076 | E13: 10696 | F13: 10479 | G13: 10492 | H13: 10891 | I13: 11238 | J13: 12475 | K13: 13820 | L13: 14795 | M13: 15570 | N13: 16215 | O13: 16202 | P13: 15972 | Q13: 15800 | R13: 15670 | S13: 15502 | T13: 15514 | U13: 16917 | V13: 17983 | W13: 17286 | X13: 16290 | Y13: 14806 | Z13: 13308 | AA13: =SUM(C13:Z13) -> 340787 | AB13: 4
B14: F | C14: 12150 | D14: 11364 | E14: 10902 | F14: 10589 | G14: 10459 | H14: 10613 | I14: 10574 | J14: 11360 | K14: 12431 | L14: 13293 | M14: 13895 | N14: 14579 | O14: 14986 | P14: 14872 | Q14: 14560 | R14: 14420 | S14: 14330 | T14: 14442 | U14: 15957 | V14: 17213 | W14: 16729 | X14: 15726 | Y14: 14095 | Z14: 12540 | AA14: =SUM(C14:Z14) -> 322079 | AB14: 7
A15: 46478 | B15: O | C15: 11166 | D15: 10574 | E15: 10218 | F15: 10053 | G15: 10262 | H15: 11027 | I15: 11591 | J15: 12612 | K15: 13679 | L15: 14514 | M15: 15396 | N15: 16195 | O15: 15910 | P15: 15983 | Q15: 16299 | R15: 16332 | S15: 16167 | T15: 15928 | U15: 17319 | V15: 18146 | W15: 17507 | X15: 16227 | Y15: 14290 | Z15: 12437 | AA15: =SUM(C15:Z15) -> 339832 | AB15: 22 | AC15: =+AA15*AB15+AA16*AB16+AA17*AB17 -> 10076204
B16: S | C16: 11404 | D16: 10729 | E16: 10294 | F16: 10038 | G16: 10085 | H16: 10375 | I16: 10739 | J16: 12030 | K16: 13355 | L16: 14360 | M16: 15086 | N16: 15910 | O16: 15961 | P16: 15769 | Q16: 15594 | R16: 15474 | S16: 15430 | T16: 15504 | U16: 17086 | V16: 17960 | W16: 17225 | X16: 16158 | Y16: 14656 | Z16: 13123 | AA16: =SUM(C16:Z16) -> 334345 | AB16: 4
B17: F | C17: 11884 | D17: 11126 | E17: 10636 | F17: 10302 | G17: 10173 | H17: 10156 | I17: 10235 | J17: 11122 | K17: 12159 | L17: 13070 | M17: 13718 | N17: 14378 | O17: 14762 | P17: 14656 | Q17: 14325 | R17: 14168 | S17: 14079 | T17: 14206 | U17: 15895 | V17: 16906 | W17: 16376 | X17: 15344 | Y17: 13764 | Z17: 12190 | AA17: =SUM(C17:Z17) -> 315630 | AB17: 4
A18: 46508 | B18: O | C18: 11183 | D18: 10571 | E18: 10230 | F18: 10059 | G18: 10261 | H18: 10917 | I18: 11603 | J18: 12675 | K18: 13771 | L18: 14632 | M18: 15497 | N18: 16319 | O18: 16071 | P18: 16067 | Q18: 16315 | R18: 16344 | S18: 16177 | T18: 15982 | U18: 17434 | V18: 18257 | W18: 17543 | X18: 16259 | Y18: 14291 | Z18: 12468 | AA18: =SUM(C18:Z18) -> 340926 | AB18: 19 | AC18: =+AA18*AB18+AA19*AB19+AA20*AB20 -> 10395490
B19: S | C19: 11597 | D19: 10926 | E19: 10521 | F19: 10282 | G19: 10324 | H19: 10493 | I19: 11042 | J19: 12341 | K19: 13695 | L19: 14742 | M19: 15460 | N19: 16114 | O19: 16116 | P19: 15860 | Q19: 15599 | R19: 15441 | S19: 15327 | T19: 15468 | U19: 17187 | V19: 17884 | W19: 17175 | X19: 16089 | Y19: 14577 | Z19: 13070 | AA19: =SUM(C19:Z19) -> 337330 | AB19: 4
B20: F | C20: 11799 | D20: 11066 | E20: 10611 | F20: 10308 | G20: 10215 | H20: 10100 | I20: 10307 | J20: 11295 | K20: 12393 | L20: 13369 | M20: 14036 | N20: 14732 | O20: 15038 | P20: 14977 | Q20: 14614 | R20: 15022 | S20: 14358 | T20: 14516 | U20: 16262 | V20: 17276 | W20: 16731 | X20: 15634 | Y20: 14010 | Z20: 12403 | AA20: =SUM(C20:Z20) -> 321072 | AB20: 8
A21: 46539 | B21: O | C21: 11051 | D21: 10426 | E21: 10113 | F21: 9946 | G21: 10131 | H21: 10694 | I21: 11438 | J21: 12569 | K21: 13712 | L21: 14564 | M21: 15455 | N21: 16287 | O21: 16018 | P21: 16000 | Q21: 16306 | R21: 16323 | S21: 16157 | T21: 15907 | U21: 17064 | V21: 18145 | W21: 17468 | X21: 16196 | Y21: 14199 | Z21: 12348 | AA21: =SUM(C21:Z21) -> 338517 | AB21: 21 | AC21: =+AA21*AB21+AA22*AB22+AA23*AB23 -> 10103194
B22: S | C22: 11585 | D22: 10864 | E22: 10450 | F22: 10217 | G22: 10237 | H22: 10403 | I22: 10947 | J22: 12231 | K22: 13680 | L22: 14674 | M22: 15451 | N22: 16124 | O22: 16168 | P22: 16003 | Q22: 15832 | R22: 15802 | S22: 15684 | T22: 15802 | U22: 17277 | V22: 18224 | W22: 17477 | X22: 16410 | Y22: 14829 | Z22: 13222 | AA22: =SUM(C22:Z22) -> 339593 | AB22: 4
B23: F | C23: 12057 | D23: 11288 | E23: 10842 | F23: 10538 | G23: 10466 | H23: 10454 | I23: 10593 | J23: 11622 | K23: 12766 | L23: 13649 | M23: 14376 | N23: 15079 | O23: 15329 | P23: 15223 | Q23: 14929 | R23: 14790 | S23: 14715 | T23: 14835 | U23: 16331 | V23: 17532 | W23: 17015 | X23: 15905 | Y23: 14237 | Z23: 12622 | AA23: =SUM(C23:Z23) -> 327193 | AB23: 5
A24: 46569 | B24: O | C24: 11570 | D24: 10912 | E24: 10532 | F24: 10325 | G24: 10502 | H24: 11063 | I24: 11666 | J24: 12929 | K24: 14157 | L24: 15119 | M24: 16050 | N24: 16876 | O24: 16584 | P24: 16620 | Q24: 16924 | R24: 16958 | S24: 16718 | T24: 16300 | U24: 17257 | V24: 18541 | W24: 17941 | X24: 16732 | Y24: 14737 | Z24: 12901 | AA24: =SUM(C24:Z24) -> 349914 | AB24: 20 | AC24: =+AA24*AB24+AA25*AB25+AA26*AB26 -> 10674199
B25: S | C25: 11596 | D25: 10840 | E25: 10455 | F25: 10198 | G25: 10223 | H25: 10437 | I25: 10957 | J25: 12486 | K25: 13942 | L25: 14938 | M25: 15721 | N25: 16384 | O25: 16353 | P25: 16097 | Q25: 15864 | R25: 15743 | S25: 15604 | T25: 15650 | U25: 16819 | V25: 18056 | W25: 17366 | X25: 16379 | Y25: 14834 | Z25: 13305 | AA25: =SUM(C25:Z25) -> 340247 | AB25: 5
B26: F | C26: 12306 | D26: 11550 | E26: 11051 | F26: 10725 | G26: 10624 | H26: 10627 | I26: 10697 | J26: 11669 | K26: 12836 | L26: 13803 | M26: 14508 | N26: 15161 | O26: 15484 | P26: 15314 | Q26: 14976 | R26: 14796 | S26: 14657 | T26: 14721 | U26: 15960 | V26: 17484 | W26: 17039 | X26: 16013 | Y26: 14347 | Z26: 12766 | AA26: =SUM(C26:Z26) -> 329114 | AB26: 6
A27: 46600 | B27: O | C27: 11706 | D27: 11082 | E27: 10738 | F27: 10534 | G27: 10719 | H27: 11462 | I27: 12124 | J27: 13248 | K27: 14425 | L27: 15326 | M27: 16280 | N27: 17117 | O27: 16822 | P27: 16955 | Q27: 17300 | R27: 17327 | S27: 17078 | T27: 16646 | U27: 17811 | V27: 18890 | W27: 18230 | X27: 16956 | Y27: 14936 | Z27: 13112 | AA27: =SUM(C27:Z27) -> 356824 | AB27: 21 | AC27: =+AA27*AB27+AA28*AB28+AA29*AB29 -> 10863111
B28: S | C28: 12185 | D28: 11508 | E28: 11085 | F28: 10768 | G28: 10744 | H28: 11043 | I28: 11397 | J28: 12839 | K28: 14298 | L28: 15297 | M28: 16174 | N28: 16837 | O28: 16841 | P28: 16660 | Q28: 16486 | R28: 16386 | S28: 16166 | T28: 16136 | U28: 17578 | V28: 18531 | W28: 17830 | X28: 16811 | Y28: 15328 | Z28: 13732 | AA28: =SUM(C28:Z28) -> 352660 | AB28: 3
B29: F | C29: 12412 | D29: 11643 | E29: 11135 | F29: 10812 | G29: 10707 | H29: 10743 | I29: 10741 | J29: 11753 | K29: 12895 | L29: 13838 | M29: 14505 | N29: 15196 | O29: 15553 | P29: 15413 | Q29: 15035 | R29: 14782 | S29: 14686 | T29: 14727 | U29: 16223 | V29: 17523 | W29: 17003 | X29: 15936 | Y29: 14309 | Z29: 12691 | AA29: =SUM(C29:Z29) -> 330261 | AB29: 7
A30: 46631 | B30: O | C30: 11916 | D30: 11259 | E30: 10849 | F30: 10670 | G30: 10843 | H30: 11554 | I30: 12238 | J30: 13399 | K30: 14565 | L30: 15534 | M30: 16497 | N30: 17379 | O30: 17076 | P30: 17199 | Q30: 17602 | R30: 17702 | S30: 17448 | T30: 17090 | U30: 18689 | V30: 19121 | W30: 18402 | X30: 17105 | Y30: 15044 | Z30: 13225 | AA30: =SUM(C30:Z30) -> 362406 | AB30: 22 | AC30: =+AA30*AB30+AA31*AB31+AA32*AB32 -> 10701632
B31: S | C31: 12234 | D31: 11453 | E31: 11030 | F31: 10798 | G31: 10808 | H31: 10908 | I31: 11455 | J31: 13009 | K31: 14491 | L31: 15549 | M31: 16385 | N31: 17056 | O31: 17014 | P31: 16796 | Q31: 16595 | R31: 16449 | S31: 16307 | T31: 16429 | U31: 18183 | V31: 18575 | W31: 17760 | X31: 16718 | Y31: 15196 | Z31: 13642 | AA31: =SUM(C31:Z31) -> 354840 | AB31: 4
B32: F | C32: 12456 | D32: 11708 | E32: 11217 | F32: 10837 | G32: 10665 | H32: 10535 | I32: 10615 | J32: 11609 | K32: 12729 | L32: 13647 | M32: 14288 | N32: 14899 | O32: 15253 | P32: 15145 | Q32: 14825 | R32: 14670 | S32: 14569 | T32: 14686 | U32: 16600 | V32: 17252 | W32: 16775 | X32: 15729 | Y32: 14096 | Z32: 12530 | AA32: =SUM(C32:Z32) -> 327335 | AB32: 4
A33: 46661 | B33: O | C33: 11291 | D33: 10686 | E33: 10350 | F33: 10170 | G33: 10369 | H33: 10942 | I33: 11671 | J33: 12764 | K33: 13861 | L33: 14726 | M33: 15623 | N33: 16454 | O33: 16166 | P33: 16254 | Q33: 16627 | R33: 16707 | S33: 16522 | T33: 16570 | U33: 18403 | V33: 18309 | W33: 17505 | X33: 16193 | Y33: 14266 | Z33: 12553 | AA33: =SUM(C33:Z33) -> 344982 | AB33: 20 | AC33: =+AA33*AB33+AA34*AB34+AA35*AB35 -> 10567965
B34: S | C34: 11887 | D34: 11209 | E34: 10798 | F34: 10525 | G34: 10580 | H34: 10744 | I34: 11351 | J34: 12749 | K34: 14142 | L34: 15109 | M34: 15932 | N34: 16623 | O34: 16650 | P34: 16462 | Q34: 16262 | R34: 16137 | S34: 15992 | T34: 16496 | U34: 18590 | V34: 18557 | W34: 17771 | X34: 16581 | Y34: 15114 | Z34: 13518 | AA34: =SUM(C34:Z34) -> 349779 | AB34: 5
B35: F | C35: 11927 | D35: 11205 | E35: 10707 | F35: 10359 | G35: 10248 | H35: 10104 | I35: 10297 | J35: 11243 | K35: 12315 | L35: 13256 | M35: 13924 | N35: 14581 | O35: 14949 | P35: 14827 | Q35: 14545 | R35: 14402 | S35: 14320 | T35: 14762 | U35: 16871 | V35: 17044 | W35: 16497 | X35: 15420 | Y35: 13820 | Z35: 12282 | AA35: =SUM(C35:Z35) -> 319905 | AB35: 6
A36: 46692 | B36: O | C36: 11083 | D36: 10479 | E36: 10144 | F36: 9987 | G36: 10219 | H36: 10872 | I36: 11648 | J36: 12758 | K36: 13835 | L36: 14669 | M36: 15561 | N36: 16416 | O36: 16081 | P36: 16090 | Q36: 16454 | R36: 16438 | S36: 16303 | T36: 16525 | U36: 18439 | V36: 18337 | W36: 17521 | X36: 16140 | Y36: 14156 | Z36: 12381 | AA36: =SUM(C36:Z36) -> 342536 | AB36: 20 | AC36: =+AA36*AB36+AA37*AB37+AA38*AB38 -> 10060220
B37: S | C37: 11381 | D37: 10739 | E37: 10347 | F37: 10096 | G37: 10140 | H37: 10267 | I37: 10826 | J37: 12114 | K37: 13475 | L37: 14425 | M37: 15184 | N37: 15882 | O37: 15817 | P37: 15522 | Q37: 15436 | R37: 15386 | S37: 15296 | T37: 15844 | U37: 17974 | V37: 17921 | W37: 17100 | X37: 16050 | Y37: 14497 | Z37: 12935 | AA37: =SUM(C37:Z37) -> 334654 | AB37: 4
B38: F | C38: 11427 | D38: 10739 | E38: 10273 | F38: 9932 | G38: 9886 | H38: 9764 | I38: 9996 | J38: 10981 | K38: 12055 | L38: 12978 | M38: 13649 | N38: 14332 | O38: 14669 | P38: 14536 | Q38: 14213 | R38: 13984 | S38: 13919 | T38: 14416 | U38: 16563 | V38: 16763 | W38: 16211 | X38: 15117 | Y38: 13480 | Z38: 11931 | AA38: =SUM(C38:Z38) -> 311814 | AB38: 6
A39: 46722 | B39: O | C39: 11874 | D39: 11156 | E39: 10740 | F39: 10527 | G39: 10674 | H39: 11142 | I39: 11663 | J39: 13035 | K39: 14317 | L39: 15264 | M39: 16129 | N39: 17005 | O39: 16838 | P39: 16824 | Q39: 17073 | R39: 17051 | S39: 16806 | T39: 16694 | U39: 18556 | V39: 18843 | W39: 18112 | X39: 16943 | Y39: 15150 | Z39: 13434 | AA39: =SUM(C39:Z39) -> 355850 | AB39: 22 | AC39: =+AA39*AB39+AA40*AB40+AA41*AB41 -> 10807043
B40: S | C40: 11988 | D40: 11263 | E40: 10849 | F40: 10576 | G40: 10591 | H40: 10854 | I40: 11173 | J40: 12457 | K40: 13765 | L40: 14678 | M40: 15411 | N40: 16022 | O40: 16022 | P40: 15793 | Q40: 15646 | R40: 15482 | S40: 15366 | T40: 15642 | U40: 17721 | V40: 17965 | W40: 17246 | X40: 16218 | Y40: 14752 | Z40: 13335 | AA40: =SUM(C40:Z40) -> 340815 | AB40: 3
B41: F | C41: 12384 | D41: 11629 | E41: 11103 | F41: 10729 | G41: 10582 | H41: 10529 | I41: 10512 | J41: 11363 | K41: 12420 | L41: 13350 | M41: 14046 | N41: 14699 | O41: 15051 | P41: 15033 | Q41: 14795 | R41: 14644 | S41: 14557 | T41: 14833 | U41: 16911 | V41: 17332 | W41: 16740 | X41: 15728 | Y41: 14248 | Z41: 12765 | AA41: =SUM(C41:Z41) -> 325983 | AB41: 6
A42: TOTAL AÑO | C42: =+SUM(C6:C41) -> 425049 | D42: =+SUM(D6:D41) -> 399789 | E42: =+SUM(E6:E41) -> 384558 | F42: =+SUM(F6:F41) -> 375145 | G42: =+SUM(G6:G41) -> 376313 | H42: =+SUM(H6:H41) -> 387247 | I42: =+SUM(I6:I41) -> 401890 | J42: =+SUM(J6:J41) -> 441771 | ... AC42: =+SUM(AC6:AC41) -> 125332916

Sheet Cantidades Ofertadas Prod 2
A1: CANTIDADES OFERTADAS PRODUCTO 2 AÑO 2027 MODALIDAD PAGUE LO CONTRATADO - kWh
A4: Periodo | B4: Tipo de día | C4: H01 | D4: H02 | E4: H03 | F4: H04 | G4: H05 | H4: H06 | I4: H07 | J4: H08 | K4: H09 | L4: H10 | M4: H11 | N4: H12 | O4: H13 | P4: H14 | Q4: H15 | R4: H16 | S4: H17 | T4: H18 | U4: H19 | V4: H20 | W4: H21 | X4: H22 | Y4: H23 | Z4: H24 | AA4: TOTAL DÍA | AB4: Días/ | AC4: TOTAL MES
AB5: mes
A6: 46388 | B6: O | C6: =ROUND('Anexo 12'!C6*'Anexo 2'!$D$10,0) -> 0 | D6: =ROUND('Anexo 12'!D6*'Anexo 2'!$D$10,0) -> 0 | E6: =ROUND('Anexo 12'!E6*'Anexo 2'!$D$10,0) -> 0 | F6: =ROUND('Anexo 12'!F6*'Anexo 2'!$D$10,0) -> 0 | G6: =ROUND('Anexo 12'!G6*'Anexo 2'!$D$10,0) -> 0 | H6: =ROUND('Anexo 12'!H6*'Anexo 2'!$D$10,0) -> 0 | I6: =ROUND('Anexo 12'!I6*'Anexo 2'!$D$10,0) -> 0 | J6: =ROUND('Anexo 12'!J6*'Anexo 2'!$D$10,0) -> 0 | ... Z6: =ROUND('Anexo 12'!Z6*'Anexo 2'!$D$10,0) -> 0 | AA6: =SUM(C6:Z6) -> 0 | AB6: 19 | AC6: =+AA6*AB6+AA7*AB7+AA8*AB8 -> 0
B7: S | C7: =ROUND('Anexo 12'!C7*'Anexo 2'!$D$10,0) -> 0 | D7: =ROUND('Anexo 12'!D7*'Anexo 2'!$D$10,0) -> 0 | E7: =ROUND('Anexo 12'!E7*'Anexo 2'!$D$10,0) -> 0 | F7: =ROUND('Anexo 12'!F7*'Anexo 2'!$D$10,0) -> 0 | G7: =ROUND('Anexo 12'!G7*'Anexo 2'!$D$10,0) -> 0 | H7: =ROUND('Anexo 12'!H7*'Anexo 2'!$D$10,0) -> 0 | I7: =ROUND('Anexo 12'!I7*'Anexo 2'!$D$10,0) -> 0 | J7: =ROUND('Anexo 12'!J7*'Anexo 2'!$D$10,0) -> 0 | ... Z7: =ROUND('Anexo 12'!Z7*'Anexo 2'!$D$10,0) -> 0 | AA7: =SUM(C7:Z7) -> 0 | AB7: 5
B8: F | C8: =ROUND('Anexo 12'!C8*'Anexo 2'!$D$10,0) -> 0 | D8: =ROUND('Anexo 12'!D8*'Anexo 2'!$D$10,0) -> 0 | E8: =ROUND('Anexo 12'!E8*'Anexo 2'!$D$10,0) -> 0 | F8: =ROUND('Anexo 12'!F8*'Anexo 2'!$D$10,0) -> 0 | G8: =ROUND('Anexo 12'!G8*'Anexo 2'!$D$10,0) -> 0 | H8: =ROUND('Anexo 12'!H8*'Anexo 2'!$D$10,0) -> 0 | I8: =ROUND('Anexo 12'!I8*'Anexo 2'!$D$10,0) -> 0 | J8: =ROUND('Anexo 12'!J8*'Anexo 2'!$D$10,0) -> 0 | ... Z8: =ROUND('Anexo 12'!Z8*'Anexo 2'!$D$10,0) -> 0 | AA8: =SUM(C8:Z8) -> 0 | AB8: 7
A9: 46419 | B9: O | C9: =ROUND('Anexo 12'!C9*'Anexo 2'!$D$10,0) -> 0 | D9: =ROUND('Anexo 12'!D9*'Anexo 2'!$D$10,0) -> 0 | E9: =ROUND('Anexo 12'!E9*'Anexo 2'!$D$10,0) -> 0 | F9: =ROUND('Anexo 12'!F9*'Anexo 2'!$D$10,0) -> 0 | G9: =ROUND('Anexo 12'!G9*'Anexo 2'!$D$10,0) -> 0 | H9: =ROUND('Anexo 12'!H9*'Anexo 2'!$D$10,0) -> 0 | I9: =ROUND('Anexo 12'!I9*'Anexo 2'!$D$10,0) -> 0 | J9: =ROUND('Anexo 12'!J9*'Anexo 2'!$D$10,0) -> 0 | ... Z9: =ROUND('Anexo 12'!Z9*'Anexo 2'!$D$10,0) -> 0 | AA9: =SUM(C9:Z9) -> 0 | AB9: 20 | AC9: =+AA9*AB9+AA10*AB10+AA11*AB11 -> 0
