Workbook

Sheet Cant. Requeridas Producto 1
A1: EMSEROCCIDENTE SA ESP
A2: ANEXO 3A - CANTIDADES DE ENERGÍA SOLICITADA EN kWh
A3: PRODUCTO 1 - PAGUE LO DEMANDADO CON TOPO
A4: Periodo: 1 de abril 2026 al 31 diciembre de 2028
A5: CONVOCATORIA PÚBLICA N° CP-ESOC2026-001
A9: TOPE MAXIMO
A10: Mes | B10: H1 | C10: H2 | D10: H3 | E10: H4 | F10: H5 | G10: H6 | H10: H7 | I10: H8 | J10: H9 | K10: H10 | L10: H11 | M10: H12 | N10: H13 | O10: H14 | P10: H15 | Q10: H16 | R10: H17 | S10: H18 | T10: H19 | U10: H20 | V10: H21 | W10: H22 | X10: H23 | Y10: H24 | Z10: TOTAL DÍA | AA10: DÍAS | AB10: TOTAL MES
A11: 46023 | B11: 0 | C11: 0 | D11: 0 | E11: 0 | F11: 0 | G11: 0 | H11: 0 | I11: 0 | J11: 0 | K11: 0 | L11: 0 | M11: 0 | N11: 0 | O11: 0 | P11: 0 | Q11: 0 | R11: 0 | S11: 0 | T11: 0 | U11: 0 | V11: 0 | W11: 0 | X11: 0 | Y11: 0 | Z11: 0 | AA11: 31
A12: 46054 | B12: 0 | C12: 0 | D12: 0 | E12: 0 | F12: 0 | G12: 0 | H12: 0 | I12: 0 | J12: 0 | K12: 0 | L12: 0 | M12: 0 | N12: 0 | O12: 0 | P12: 0 | Q12: 0 | R12: 0 | S12: 0 | T12: 0 | U12: 0 | V12: 0 | W12: 0 | X12: 0 | Y12: 0 | Z12: 0 | AA12: 28
A13: 46082 | B13: 0 | C13: 0 | D13: 0 | E13: 0 | F13: 0 | G13: 0 | H13: 0 | I13: 0 | J13: 0 | K13: 0 | L13: 0 | M13: 0 | N13: 0 | O13: 0 | P13: 0 | Q13: 0 | R13: 0 | S13: 0 | T13: 0 | U13: 0 | V13: 0 | W13: 0 | X13: 0 | Y13: 0 | Z13: 0 | AA13: 21
A14: 46113 | B14: 628.89333 | C14: 556.16 | D14: 549.62 | E14: 535.67 | F14: 529.48667 | G14: 530.72 | H14: 547.70667 | I14: 602.52667 | J14: 654.28 | K14: 687.83667 | L14: 705.47 | M14: 735.98667 | N14: 751.29 | O14: 757.02333 | P14: 754.65 | Q14: 744.20667 | R14: 744.25667 | S14: 758.62667 | T14: 833.75667 | U14: 858.89667 | V14: 834.07667 | W14: 773.40333 | X14: 694.23667 | Y14: 635.95333 | Z14: =SUM(B14:Y14) -> 16404.733 | AA14: 30 | AB14: =Z14*AA14 -> 492142
A15: 46143 | B15: 628.89333 | C15: 556.16 | D15: 549.62 | E15: 535.67 | F15: 529.48667 | G15: 530.72 | H15: 547.70667 | I15: 602.52667 | J15: 654.28 | K15: 687.83667 | L15: 705.47 | M15: 735.98667 | N15: 751.29 | O15: 757.02333 | P15: 754.65 | Q15: 744.20667 | R15: 744.25667 | S15: 758.62667 | T15: 833.75667 | U15: 858.89667 | V15: 834.07667 | W15: 773.40333 | X15: 694.23667 | Y15: 635.95333 | Z15: =SUM(B15:Y15) -> 16404.733 | AA15: 31 | AB15: =Z15*AA15 -> 508546.73
A16: 46174 | B16: 628.89333 | C16: 556.16 | D16: 549.62 | E16: 535.67 | F16: 529.48667 | G16: 530.72 | H16: 547.70667 | I16: 602.52667 | J16: 654.28 | K16: 687.83667 | L16: 705.47 | M16: 735.98667 | N16: 751.29 | O16: 757.02333 | P16: 754.65 | Q16: 744.20667 | R16: 744.25667 | S16: 758.62667 | T16: 833.75667 | U16: 858.89667 | V16: 834.07667 | W16: 773.40333 | X16: 694.23667 | Y16: 635.95333 | Z16: =SUM(B16:Y16) -> 16404.733 | AA16: 30 | AB16: =Z16*AA16 -> 492142
A17: 46204 | B17: 628.89333 | C17: 556.16 | D17: 549.62 | E17: 535.67 | F17: 529.48667 | G17: 530.72 | H17: 547.70667 | I17: 602.52667 | J17: 654.28 | K17: 687.83667 | L17: 705.47 | M17: 735.98667 | N17: 751.29 | O17: 757.02333 | P17: 754.65 | Q17: 744.20667 | R17: 744.25667 | S17: 758.62667 | T17: 833.75667 | U17: 858.89667 | V17: 834.07667 | W17: 773.40333 | X17: 694.23667 | Y17: 635.95333 | Z17: =SUM(B17:Y17) -> 16404.733 | AA17: 31 | AB17: =Z17*AA17 -> 508546.73
A18: 46235 | B18: 628.89333 | C18: 556.16 | D18: 549.62 | E18: 535.67 | F18: 529.48667 | G18: 530.72 | H18: 547.70667 | I18: 602.52667 | J18: 654.28 | K18: 687.83667 | L18: 705.47 | M18: 735.98667 | N18: 751.29 | O18: 757.02333 | P18: 754.65 | Q18: 744.20667 | R18: 744.25667 | S18: 758.62667 | T18: 833.75667 | U18: 858.89667 | V18: 834.07667 | W18: 773.40333 | X18: 694.23667 | Y18: 635.95333 | Z18: =SUM(B18:Y18) -> 16404.733 | AA18: 31 | AB18: =Z18*AA18 -> 508546.73
A19: 46266 | B19: 628.89333 | C19: 556.16 | D19: 549.62 | E19: 535.67 | F19: 529.48667 | G19: 530.72 | H19: 547.70667 | I19: 602.52667 | J19: 654.28 | K19: 687.83667 | L19: 705.47 | M19: 735.98667 | N19: 751.29 | O19: 757.02333 | P19: 754.65 | Q19: 744.20667 | R19: 744.25667 | S19: 758.62667 | T19: 833.75667 | U19: 858.89667 | V19: 834.07667 | W19: 773.40333 | X19: 694.23667 | Y19: 635.95333 | Z19: =SUM(B19:Y19) -> 16404.733 | AA19: 30 | AB19: =Z19*AA19 -> 492142
A20: 46296 | B20: 628.89333 | C20: 556.16 | D20: 549.62 | E20: 535.67 | F20: 529.48667 | G20: 530.72 | H20: 547.70667 | I20: 602.52667 | J20: 654.28 | K20: 687.83667 | L20: 705.47 | M20: 735.98667 | N20: 751.29 | O20: 757.02333 | P20: 754.65 | Q20: 744.20667 | R20: 744.25667 | S20: 758.62667 | T20: 833.75667 | U20: 858.89667 | V20: 834.07667 | W20: 773.40333 | X20: 694.23667 | Y20: 635.95333 | Z20: =SUM(B20:Y20) -> 16404.733 | AA20: 31 | AB20: =Z20*AA20 -> 508546.73
A21: 46327 | B21: 628.89333 | C21: 556.16 | D21: 549.62 | E21: 535.67 | F21: 529.48667 | G21: 530.72 | H21: 547.70667 | I21: 602.52667 | J21: 654.28 | K21: 687.83667 | L21: 705.47 | M21: 735.98667 | N21: 751.29 | O21: 757.02333 | P21: 754.65 | Q21: 744.20667 | R21: 744.25667 | S21: 758.62667 | T21: 833.75667 | U21: 858.89667 | V21: 834.07667 | W21: 773.40333 | X21: 694.23667 | Y21: 635.95333 | Z21: =SUM(B21:Y21) -> 16404.733 | AA21: 30 | AB21: =Z21*AA21 -> 492142
A22: 46357 | B22: 628.89333 | C22: 556.16 | D22: 549.62 | E22: 535.67 | F22: 529.48667 | G22: 530.72 | H22: 547.70667 | I22: 602.52667 | J22: 654.28 | K22: 687.83667 | L22: 705.47 | M22: 735.98667 | N22: 751.29 | O22: 757.02333 | P22: 754.65 | Q22: 744.20667 | R22: 744.25667 | S22: 758.62667 | T22: 833.75667 | U22: 858.89667 | V22: 834.07667 | W22: 773.40333 | X22: 694.23667 | Y22: 635.95333 | Z22: =SUM(B22:Y22) -> 16404.733 | AA22: 31 | AB22: =Z22*AA22 -> 508546.73
A23: 46388 | B23: =+B14*1.002 -> 630.15112 | C23: =+C14*1.002 -> 557.27232 | D23: =+D14*1.002 -> 550.71924 | E23: =+E14*1.002 -> 536.74134 | F23: =+F14*1.002 -> 530.54564 | G23: =+G14*1.002 -> 531.78144 | H23: =+H14*1.002 -> 548.80208 | I23: =+I14*1.002 -> 603.73172 | ... Z23: =+Z14*1.002 -> 16437.543 | AA23: 31 | AB23: =Z23*AA23 -> 509563.83
A24: 46419 | B24: =+B15*1.002 -> 630.15112 | C24: =+C15*1.002 -> 557.27232 | D24: =+D15*1.002 -> 550.71924 | E24: =+E15*1.002 -> 536.74134 | F24: =+F15*1.002 -> 530.54564 | G24: =+G15*1.002 -> 531.78144 | H24: =+H15*1.002 -> 548.80208 | I24: =+I15*1.002 -> 603.73172 | ... Z24: =+Z15*1.002 -> 16437.543 | AA24: 28 | AB24: =Z24*AA24 -> 460251.2
A25: 46447 | B25: =+B16*1.002 -> 630.15112 | C25: =+C16*1.002 -> 557.27232 | D25: =+D16*1.002 -> 550.71924 | E25: =+E16*1.002 -> 536.74134 | F25: =+F16*1.002 -> 530.54564 | G25: =+G16*1.002 -> 531.78144 | H25: =+H16*1.002 -> 548.80208 | I25: =+I16*1.002 -> 603.73172 | ... Z25: =+Z16*1.002 -> 16437.543 | AA25: 21 | AB25: =Z25*AA25 -> 345188.4
A26: 46478 | B26: =+B17*1.002 -> 630.15112 | C26: =+C17*1.002 -> 557.27232 | D26: =+D17*1.002 -> 550.71924 | E26: =+E17*1.002 -> 536.74134 | F26: =+F17*1.002 -> 530.54564 | G26: =+G17*1.002 -> 531.78144 | H26: =+H17*1.002 -> 548.80208 | I26: =+I17*1.002 -> 603.73172 | ... Z26: =+Z17*1.002 -> 16437.543 | AA26: 30 | AB26: =Z26*AA26 -> 493126.28
A27: 46508 | B27: =+B18*1.002 -> 630.15112 | C27: =+C18*1.002 -> 557.27232 | D27: =+D18*1.002 -> 550.71924 | E27: =+E18*1.002 -> 536.74134 | F27: =+F18*1.002 -> 530.54564 | G27: =+G18*1.002 -> 531.78144 | H27: =+H18*1.002 -> 548.80208 | I27: =+I18*1.002 -> 603.73172 | ... Z27: =+Z18*1.002 -> 16437.543 | AA27: 31 | AB27: =Z27*AA27 -> 509563.83
A28: 46539 | B28: =+B19*1.002 -> 630.15112 | C28: =+C19*1.002 -> 557.27232 | D28: =+D19*1.002 -> 550.71924 | E28: =+E19*1.002 -> 536.74134 | F28: =+F19*1.002 -> 530.54564 | G28: =+G19*1.002 -> 531.78144 | H28: =+H19*1.002 -> 548.80208 | I28: =+I19*1.002 -> 603.73172 | ... Z28: =+Z19*1.002 -> 16437.543 | AA28: 30 | AB28: =Z28*AA28 -> 493126.28
A29: 46569 | B29: =+B20*1.002 -> 630.15112 | C29: =+C20*1.002 -> 557.27232 | D29: =+D20*1.002 -> 550.71924 | E29: =+E20*1.002 -> 536.74134 | F29: =+F20*1.002 -> 530.54564 | G29: =+G20*1.002 -> 531.78144 | H29: =+H20*1.002 -> 548.80208 | I29: =+I20*1.002 -> 603.73172 | ... Z29: =+Z20*1.002 -> 16437.543 | AA29: 31 | AB29: =Z29*AA29 -> 509563.83
A30: 46600 | B30: =+B21*1.002 -> 630.15112 | C30: =+C21*1.002 -> 557.27232 | D30: =+D21*1.002 -> 550.71924 | E30: =+E21*1.002 -> 536.74134 | F30: =+F21*1.002 -> 530.54564 | G30: =+G21*1.002 -> 531.78144 | H30: =+H21*1.002 -> 548.80208 | I30: =+I21*1.002 -> 603.73172 | ... Z30: =+Z21*1.002 -> 16437.543 | AA30: 31 | AB30: =Z30*AA30 -> 509563.83
A31: 46631 | B31: =+B22*1.002 -> 630.15112 | C31: =+C22*1.002 -> 557.27232 | D31: =+D22*1.002 -> 550.71924 | E31: =+E22*1.002 -> 536.74134 | F31: =+F22*1.002 -> 530.54564 | G31: =+G22*1.002 -> 531.78144 | H31: =+H22*1.002 -> 548.80208 | I31: =+I22*1.002 -> 603.73172 | ... Z31: =+Z22*1.002 -> 16437.543 | AA31: 30 | AB31: =Z31*AA31 -> 493126.28
A32: 46661 | B32: =+B31 -> 630.15112 | C32: =+C31 -> 557.27232 | D32: =+D31 -> 550.71924 | E32: =+E31 -> 536.74134 | F32: =+F31 -> 530.54564 | G32: =+G31 -> 531.78144 | H32: =+H31 -> 548.80208 | I32: =+I31 -> 603.73172 | ... Z32: =+Z31 -> 16437.543 | AA32: 31 | AB32: =Z32*AA32 -> 509563.83
A33: 46692 | B33: =+B32 -> 630.15112 | C33: =+C32 -> 557.27232 | D33: =+D32 -> 550.71924 | E33: =+E32 -> 536.74134 | F33: =+F32 -> 530.54564 | G33: =+G32 -> 531.78144 | H33: =+H32 -> 548.80208 | I33: =+I32 -> 603.73172 | ... Z33: =+Z32 -> 16437.543 | AA33: 30 | AB33: =Z33*AA33 -> 493126.28
A34: 46722 | B34: =+B33 -> 630.15112 | C34: =+C33 -> 557.27232 | D34: =+D33 -> 550.71924 | E34: =+E33 -> 536.74134 | F34: =+F33 -> 530.54564 | G34: =+G33 -> 531.78144 | H34: =+H33 -> 548.80208 | I34: =+I33 -> 603.73172 | ... Z34: =+Z33 -> 16437.543 | AA34: 31 | AB34: =Z34*AA34 -> 509563.83
A35: 46753 | B35: =+B23*1.002 -> 631.41142 | C35: =+C23*1.002 -> 558.38686 | D35: =+D23*1.002 -> 551.82068 | E35: =+E23*1.002 -> 537.81482 | F35: =+F23*1.002 -> 531.60673 | G35: =+G23*1.002 -> 532.845 | H35: =+H23*1.002 -> 549.89968 | I35: =+I23*1.002 -> 604.93918 | ... Z35: =+Z23*1.002 -> 16470.418 | AA35: 31 | AB35: =Z35*AA35 -> 510582.95
A36: 46784 | B36: =+B24*1.002 -> 631.41142 | C36: =+C24*1.002 -> 558.38686 | D36: =+D24*1.002 -> 551.82068 | E36: =+E24*1.002 -> 537.81482 | F36: =+F24*1.002 -> 531.60673 | G36: =+G24*1.002 -> 532.845 | H36: =+H24*1.002 -> 549.89968 | I36: =+I24*1.002 -> 604.93918 | ... Z36: =+Z24*1.002 -> 16470.418 | AA36: 28 | AB36: =Z36*AA36 -> 461171.7
A37: 46813 | B37: =+B25*1.002 -> 631.41142 | C37: =+C25*1.002 -> 558.38686 | D37: =+D25*1.002 -> 551.82068 | E37: =+E25*1.002 -> 537.81482 | F37: =+F25*1.002 -> 531.60673 | G37: =+G25*1.002 -> 532.845 | H37: =+H25*1.002 -> 549.89968 | I37: =+I25*1.002 -> 604.93918 | ... Z37: =+Z25*1.002 -> 16470.418 | AA37: 21 | AB37: =Z37*AA37 -> 345878.78
A38: 46844 | B38: =+B26*1.002 -> 631.41142 | C38: =+C26*1.002 -> 558.38686 | D38: =+D26*1.002 -> 551.82068 | E38: =+E26*1.002 -> 537.81482 | F38: =+F26*1.002 -> 531.60673 | G38: =+G26*1.002 -> 532.845 | H38: =+H26*1.002 -> 549.89968 | I38: =+I26*1.002 -> 604.93918 | ... Z38: =+Z26*1.002 -> 16470.418 | AA38: 30 | AB38: =Z38*AA38 -> 494112.54
A39: 46874 | B39: =+B27*1.002 -> 631.41142 | C39: =+C27*1.002 -> 558.38686 | D39: =+D27*1.002 -> 551.82068 | E39: =+E27*1.002 -> 537.81482 | F39: =+F27*1.002 -> 531.60673 | G39: =+G27*1.002 -> 532.845 | H39: =+H27*1.002 -> 549.89968 | I39: =+I27*1.002 -> 604.93918 | ... Z39: =+Z27*1.002 -> 16470.418 | AA39: 31 | AB39: =Z39*AA39 -> 510582.95
A40: 46905 | B40: =+B28*1.002 -> 631.41142 | C40: =+C28*1.002 -> 558.38686 | D40: =+D28*1.002 -> 551.82068 | E40: =+E28*1.002 -> 537.81482 | F40: =+F28*1.002 -> 531.60673 | G40: =+G28*1.002 -> 532.845 | H40: =+H28*1.002 -> 549.89968 | I40: =+I28*1.002 -> 604.93918 | ... Z40: =+Z28*1.002 -> 16470.418 | AA40: 30 | AB40: =Z40*AA40 -> 494112.54
A41: 46935 | B41: =+B29*1.002 -> 631.41142 | C41: =+C29*1.002 -> 558.38686 | D41: =+D29*1.002 -> 551.82068 | E41: =+E29*1.002 -> 537.81482 | F41: =+F29*1.002 -> 531.60673 | G41: =+G29*1.002 -> 532.845 | H41: =+H29*1.002 -> 549.89968 | I41: =+I29*1.002 -> 604.93918 | ... Z41: =+Z29*1.002 -> 16470.418 | AA41: 31 | AB41: =Z41*AA41 -> 510582.95
A42: 46966 | B42: =+B30*1.002 -> 631.41142 | C42: =+C30*1.002 -> 558.38686 | D42: =+D30*1.002 -> 551.82068 | E42: =+E30*1.002 -> 537.81482 | F42: =+F30*1.002 -> 531.60673 | G42: =+G30*1.002 -> 532.845 | H42: =+H30*1.002 -> 549.89968 | I42: =+I30*1.002 -> 604.93918 | ... Z42: =+Z30*1.002 -> 16470.418 | AA42: 31 | AB42: =Z42*AA42 -> 510582.95
A43: 46997 | B43: =+B31*1.002 -> 631.41142 | C43: =+C31*1.002 -> 558.38686 | D43: =+D31*1.002 -> 551.82068 | E43: =+E31*1.002 -> 537.81482 | F43: =+F31*1.002 -> 531.60673 | G43: =+G31*1.002 -> 532.845 | H43: =+H31*1.002 -> 549.89968 | I43: =+I31*1.002 -> 604.93918 | ... Z43: =+Z31*1.002 -> 16470.418 | AA43: 30 | AB43: =Z43*AA43 -> 494112.54
...

Sheet Oferta Producto 1
B3: EMSEROCCIDENTE SA ESP
B4: CONVOCATORIA PÚBLICA N° CP-ESOC2026-001
B5: ANEXO 4. FORMATO DE OFERTA - PRODUCTO 1
B6: NOMBRE DEL OFERENTE
B7: Precios y cantidades de la energía ofertada
B8: En Pesos de Enero de 2026
B10: OFERTA PRODUCTO 1
B11: Mes | C11: E. Solicitada [kWh-mes] | D11: % E. Ofertado | E11: E. Ofertada [kWh] | F11: $/kWh
B12: 46113 | C12: =+'Cant. Requeridas Producto 1'!AB14 -> 492142 | E12: =+$D$12*C12 -> 0
B13: 46143 | C13: =+'Cant. Requeridas Producto 1'!AB15 -> 508546.73 | E13: =+$D$12*C13 -> 0
B14: 46174 | C14: =+'Cant. Requeridas Producto 1'!AB16 -> 492142 | E14: =+$D$12*C14 -> 0
B15: 46204 | C15: =+'Cant. Requeridas Producto 1'!AB17 -> 508546.73 | E15: =+$D$12*C15 -> 0
B16: 46235 | C16: =+'Cant. Requeridas Producto 1'!AB18 -> 508546.73 | E16: =+$D$12*C16 -> 0
B17: 46266 | C17: =+'Cant. Requeridas Producto 1'!AB19 -> 492142 | E17: =+$D$12*C17 -> 0
B18: 46296 | C18: =+'Cant. Requeridas Producto 1'!AB20 -> 508546.73 | E18: =+$D$12*C18 -> 0
B19: 46327 | C19: =+'Cant. Requeridas Producto 1'!AB21 -> 492142 | E19: =+$D$12*C19 -> 0
B20: 46357 | C20: =+'Cant. Requeridas Producto 1'!AB22 -> 508546.73 | E20: =+$D$12*C20 -> 0
B21: 46388 | C21: =+'Cant. Requeridas Producto 1'!AB23 -> 509563.83 | E21: =+$D$21*C21 -> 0
B22: 46419 | C22: =+'Cant. Requeridas Producto 1'!AB24 -> 460251.2 | E22: =+$D$21*C22 -> 0
B23: 46447 | C23: =+'Cant. Requeridas Producto 1'!AB25 -> 345188.4 | E23: =+$D$21*C23 -> 0
B24: 46478 | C24: =+'Cant. Requeridas Producto 1'!AB26 -> 493126.28 | E24: =+$D$21*C24 -> 0
B25: 46508 | C25: =+'Cant. Requeridas Producto 1'!AB27 -> 509563.83 | E25: =+$D$21*C25 -> 0
B26: 46539 | C26: =+'Cant. Requeridas Producto 1'!AB28 -> 493126.28 | E26: =+$D$21*C26 -> 0
B27: 46569 | C27: =+'Cant. Requeridas Producto 1'!AB29 -> 509563.83 | E27: =+$D$21*C27 -> 0
B28: 46600 | C28: =+'Cant. Requeridas Producto 1'!AB30 -> 509563.83 | E28: =+$D$21*C28 -> 0
B29: 46631 | C29: =+'Cant. Requeridas Producto 1'!AB31 -> 493126.28 | E29: =+$D$21*C29 -> 0
B30: 46661 | C30: =+'Cant. Requeridas Producto 1'!AB32 -> 509563.83 | E30: =+$D$21*C30 -> 0
B31: 46692 | C31: =+'Cant. Requeridas Producto 1'!AB33 -> 493126.28 | E31: =+$D$21*C31 -> 0
B32: 46722 | C32: =+'Cant. Requeridas Producto 1'!AB34 -> 509563.83 | E32: =+$D$21*C32 -> 0
B33: 46753 | C33: =+'Cant. Requeridas Producto 1'!AB35 -> 510582.95 | E33: =+$D$33*C33 -> 0
B34: 46784 | C34: =+'Cant. Requeridas Producto 1'!AB36 -> 461171.7 | E34: =+$D$33*C34 -> 0
B35: 46813 | C35: =+'Cant. Requeridas Producto 1'!AB37 -> 345878.78 | E35: =+$D$33*C35 -> 0
B36: 46844 | C36: =+'Cant. Requeridas Producto 1'!AB38 -> 494112.54 | E36: =+$D$33*C36 -> 0
B37: 46874 | C37: =+'Cant. Requeridas Producto 1'!AB39 -> 510582.95 | E37: =+$D$33*C37 -> 0
B38: 46905 | C38: =+'Cant. Requeridas Producto 1'!AB40 -> 494112.54 | E38: =+$D$33*C38 -> 0
B39: 46935 | C39: =+'Cant. Requeridas Producto 1'!AB41 -> 510582.95 | E39: =+$D$33*C39 -> 0
B40: 46966 | C40: =+'Cant. Requeridas Producto 1'!AB42 -> 510582.95 | E40: =+$D$33*C40 -> 0
B41: 46997 | C41: =+'Cant. Requeridas Producto 1'!AB43 -> 494112.54 | E41: =+$D$33*C41 -> 0
B42: 47027 | C42: =+'Cant. Requeridas Producto 1'!AB44 -> 510582.95 | E42: =+$D$33*C42 -> 0
B43: 47058 | C43: =+'Cant. Requeridas Producto 1'!AB45 -> 494112.54 | E43: =+$D$33*C43 -> 0
...
