Workbook

Sheet Oferta Producto No. 1
D2: ANEXO No. 1 OFERTAS Y CANTIDADES
C3: OFERTA A LA EMPRESA DE ENERGIA DE PEREIRA S.A. ESP. INVITACIÓN PARA EL SUMINISTRO DE ENERGÍA ELÉCTRICA CON DESTINO AL MERCADO REGULADO CONVOCATORIA PÚBLICA No. 005-2026 - CP-EEPC2026-005
D4: PRODUCTO No. 1
C6: EMPRESA: XXXXXXXXXXXXXXXXXXXXXXXXXXXXXX
C7: REPRESENTANTE LEGAL: XXXXXXXXXXXXXXXXXXXXXXXXXXXXXX
C8: TIPO DE AGENTE: (COMERCIALIZADOR/GENERADOR)
C9: ="PRODUCTO OFERTADO: "&D4 -> PRODUCTO OFERTADO: PRODUCTO No. 1
C11: Las tarifas ofertadas están referidas en pesos constantes de septiembre de 2026 provisional
F13: ="Oferta " & PROPER(D4) -> Oferta Producto No. 1
F14: Periodo | G14: Energía requerida (MWh-año) | H14: Energía ofertada (%) | I14: Energía ofertada (MWh-año) | J14: Tarifa monomia ($/kWh)
F15: 46357 | G15: =+SUMIFS('Cantidades Producto No. 1'!$AB$60:$AB$67,'Cantidades Producto No. 1'!$A$60:$A$67,'Oferta Producto No. 1'!F15) -> 3826.36
F16: 46388 | G16: =+SUMIFS('Cantidades Producto No. 1'!$AB$60:$AB$67,'Cantidades Producto No. 1'!$A$60:$A$67,'Oferta Producto No. 1'!F16) -> 4608.25
F17: 46419 | G17: =+SUMIFS('Cantidades Producto No. 1'!$AB$60:$AB$67,'Cantidades Producto No. 1'!$A$60:$A$67,'Oferta Producto No. 1'!F17) -> 4324.36
F18: 46447 | G18: =+SUMIFS('Cantidades Producto No. 1'!$AB$60:$AB$67,'Cantidades Producto No. 1'!$A$60:$A$67,'Oferta Producto No. 1'!F18) -> 4419.2
F19: 46478 | G19: =+SUMIFS('Cantidades Producto No. 1'!$AB$60:$AB$67,'Cantidades Producto No. 1'!$A$60:$A$67,'Oferta Producto No. 1'!F19) -> 4075.96
F20: 46508 | G20: =+SUMIFS('Cantidades Producto No. 1'!$AB$60:$AB$67,'Cantidades Producto No. 1'!$A$60:$A$67,'Oferta Producto No. 1'!F20) -> 3515.72
F21: 46539 | G21: =+SUMIFS('Cantidades Producto No. 1'!$AB$60:$AB$67,'Cantidades Producto No. 1'!$A$60:$A$67,'Oferta Producto No. 1'!F21) -> 3475.57
F22: 46569 | G22: =+SUMIFS('Cantidades Producto No. 1'!$AB$60:$AB$67,'Cantidades Producto No. 1'!$A$60:$A$67,'Oferta Producto No. 1'!F22) -> 3924.58
F23: TOTAL | G23: =SUM(G15:G22) -> 32170
B25: Notas
B27: (1) Oferta válida para la modalidad Pague lo Contratado.
B28: ="(2) Las cantidades se distribuyen de acuerdo a la curva del Anexo 1. Ofertas y Cantidades "& D4 &" de los Pliegos de Condiciones Preliminares." -> (2) Las cantidades se distribuyen de acuerdo a la curva del Anexo 1. Ofertas y Cantidades PRODUCTO No. 1 de los Pliegos de Condiciones Preliminares.
B29: (3) La cantidad de energía es equivalente a un porcentaje de las cantidades de energía requerida por la Empresa de Energía de Pereira S.A. ESP. (para todo el año/para cada mes), de acuerdo con el Anexo No.1 Ofertas y Cantidades PRODUCTO No. 1 de los Pliegos Preliminares, que se aplicarán para todas las 24 horas del día de la curva establecida en dicho Anexo, presentando una tarifa para cada año sin ningún tipo de discriminación por mes, ni tipo de carga ni tipo de día.
B30: (4) Esta oferta NO presenta restricciones tales como adjudicación mínima o total u otras que no permitan la evaluación objetiva e integral del producto ofertado.
B31: (5) Los precios ofertados incluyen todos los pagos, cargos, impuestos, estampillas, etc., que el Proponente deba realizar ante cualquier entidad gubernamental, o empresa pública, privada o mixta para entregar la energía en la frontera con el Sistema de Transmisión Nacional – STN.
B32: (6) Las cantidades ofertadas están sujetas a la adjudicación en la misma proporción respecto a las cantidades ofertadas para todos y cada uno de los meses del año. Es decir, si la Empresa de Energía de Pereira decide adjudicar, por ejemplo, el 50% de lo ofertado en cualesquiera de los meses de alguno de los años, ese mismo porcentaje debe ser adjudicado en el resto de cada uno de los meses de ese año.

Sheet Cantidades Producto No. 1
A2: EMPRESA DE ENERGÍA DE PEREIRA S.A. E.S.P.
A3: PRODUCTO No. 1
A5: DEMANDA DIARIA ESTIMADA DÍA HABIL [MWh]
A7: MES | B7: H1 | C7: H2 | D7: H3 | E7: H4 | F7: H5 | G7: H6 | H7: H7 | I7: H8 | J7: H9 | K7: H10 | L7: H11 | M7: H12 | N7: H13 | O7: H14 | P7: H15 | Q7: H16 | R7: H17 | S7: H18 | T7: H19 | U7: H20 | V7: H21 | W7: H22 | X7: H23 | Y7: H24 | Z7: TOTAL | AA7: Días | AB7: TOTAL
A8: 46357 | B8: 3.97 | C8: 3.67 | D8: 3.52 | E8: 3.45 | F8: 3.53 | G8: 3.77 | H8: 4.24 | I8: 4.77 | J8: 5.38 | K8: 5.76 | L8: 6.08 | M8: 6.42 | N8: 6.45 | O8: 6.42 | P8: 6.52 | Q8: 6.53 | R8: 6.42 | S8: 6.33 | T8: 6.64 | U8: 6.61 | V8: 6.28 | W8: 5.85 | X8: 5.21 | Y8: 4.56 | Z8: =SUM(B8:Y8) -> 128.38 | AA8: 21 | AB8: =+Z8*AA8 -> 2695.98 | AD8: HABIL
A9: 46388 | B9: 4.64 | C9: 4.31 | D9: 4.14 | E9: 4.07 | F9: 4.19 | G9: 4.6 | H9: 5.19 | I9: 5.78 | J9: 6.5 | K9: 7.04 | L9: 7.56 | M9: 8.02 | N9: 7.97 | O9: 7.87 | P9: 7.98 | Q9: 7.96 | R9: 7.82 | S9: 7.61 | T9: 7.86 | U9: 8.05 | V9: 7.69 | W9: 7.15 | X9: 6.28 | Y9: 5.33 | Z9: =SUM(B9:Y9) -> 155.61 | AA9: 19 | AB9: =+Z9*AA9 -> 2956.59 | AD9: HABIL
A10: 46419 | B10: 4.66 | C10: 4.35 | D10: 4.18 | E10: 4.14 | F10: 4.32 | G10: 5.01 | H10: 5.7 | I10: 6.15 | J10: 6.79 | K10: 7.28 | L10: 7.79 | M10: 8.21 | N10: 8.02 | O10: 7.99 | P10: 8.17 | Q10: 8.18 | R10: 8.05 | S10: 7.72 | T10: 7.79 | U10: 8.11 | V10: 7.82 | W10: 7.25 | X10: 6.31 | Y10: 5.33 | Z10: =SUM(B10:Y10) -> 159.32 | AA10: 20 | AB10: =+Z10*AA10 -> 3186.4 | AD10: HABIL
A11: 46447 | B11: 4.34 | C11: 4.06 | D11: 3.91 | E11: 3.86 | F11: 4.03 | G11: 4.66 | H11: 5.28 | I11: 5.78 | J11: 6.39 | K11: 6.82 | L11: 7.3 | M11: 7.68 | N11: 7.55 | O11: 7.47 | P11: 7.62 | Q11: 7.6 | R11: 7.48 | S11: 7.26 | T11: 7.37 | U11: 7.67 | V11: 7.33 | W11: 6.78 | X11: 5.91 | Y11: 5 | Z11: =SUM(B11:Y11) -> 149.15 | AA11: 20 | AB11: =+Z11*AA11 -> 2983 | AD11: HABIL
A12: 46478 | B12: 4.08 | C12: 3.8 | D12: 3.67 | E12: 3.62 | F12: 3.78 | G12: 4.3 | H12: 4.89 | I12: 5.44 | J12: 5.97 | K12: 6.49 | L12: 6.91 | M12: 7.26 | N12: 7.14 | O12: 7.02 | P12: 7.04 | Q12: 7.05 | R12: 6.97 | S12: 6.83 | T12: 7.05 | U12: 7.21 | V12: 6.87 | W12: 6.34 | X12: 5.53 | Y12: 4.7 | Z12: =SUM(B12:Y12) -> 139.96 | AA12: 22 | AB12: =+Z12*AA12 -> 3079.12 | AD12: HABIL
A13: 46508 | B13: 3.46 | C13: 3.23 | D13: 3.11 | E13: 3.06 | F13: 3.21 | G13: 3.62 | H13: 4.16 | I13: 4.62 | J13: 5.12 | K13: 5.5 | L13: 5.89 | M13: 6.21 | N13: 6.09 | O13: 5.99 | P13: 6.06 | Q13: 6.03 | R13: 5.9 | S13: 5.81 | T13: 5.99 | U13: 6.1 | V13: 5.82 | W13: 5.34 | X13: 4.64 | Y13: 3.94 | Z13: =SUM(B13:Y13) -> 118.9 | AA13: 19 | AB13: =+Z13*AA13 -> 2259.1 | AD13: HABIL
A14: 46539 | B14: 3.49 | C14: 3.24 | D14: 3.11 | E14: 3.06 | F14: 3.2 | G14: 3.55 | H14: 4.14 | I14: 4.65 | J14: 5.18 | K14: 5.57 | L14: 5.93 | M14: 6.27 | N14: 6.18 | O14: 6.05 | P14: 6.09 | Q14: 6.07 | R14: 5.98 | S14: 5.87 | T14: 6.01 | U14: 6.24 | V14: 5.95 | W14: 5.45 | X14: 4.71 | Y14: 4.01 | Z14: =SUM(B14:Y14) -> 120 | AA14: 21 | AB14: =+Z14*AA14 -> 2520 | AD14: HABIL
A15: 46569 | B15: 3.8 | C15: 3.56 | D15: 3.41 | E15: 3.36 | F15: 3.51 | G15: 3.96 | H15: 4.53 | I15: 5.08 | J15: 5.67 | K15: 6.12 | L15: 6.51 | M15: 6.89 | N15: 6.76 | O15: 6.64 | P15: 6.72 | Q15: 6.74 | R15: 6.65 | S15: 6.47 | T15: 6.52 | U15: 6.85 | V15: 6.53 | W15: 5.99 | X15: 5.16 | Y15: 4.43 | Z15: =SUM(B15:Y15) -> 131.86 | AA15: 20 | AB15: =+Z15*AA15 -> 2637.2 | AD15: HABIL
A18: DEMANDA DIARIA ESTIMADA DÍA SABADO [MWh]
A20: MES | B20: H1 | C20: H2 | D20: H3 | E20: H4 | F20: H5 | G20: H6 | H20: H7 | I20: H8 | J20: H9 | K20: H10 | L20: H11 | M20: H12 | N20: H13 | O20: H14 | P20: H15 | Q20: H16 | R20: H17 | S20: H18 | T20: H19 | U20: H20 | V20: H21 | W20: H22 | X20: H23 | Y20: H24 | Z20: TOTAL | AA20: Días
A21: 46357 | B21: 4.11 | C21: 3.79 | D21: 3.61 | E21: 3.5 | F21: 3.53 | G21: 3.68 | H21: 4.04 | I21: 4.54 | J21: 5.12 | K21: 5.57 | L21: 5.87 | M21: 6.1 | N21: 6.1 | O21: 5.97 | P21: 5.89 | Q21: 5.83 | R21: 5.8 | S21: 5.82 | T21: 6.25 | U21: 6.23 | V21: 5.92 | W21: 5.55 | X21: 5.08 | Y21: 4.57 | Z21: =SUM(B21:Y21) -> 122.47 | AA21: 4 | AB21: =+Z21*AA21 -> 489.88 | AD21: SABADOS
A22: 46388 | B22: 4.74 | C22: 4.38 | D22: 4.17 | E22: 4.06 | F22: 4.11 | G22: 4.31 | H22: 4.74 | I22: 5.35 | J22: 6.11 | K22: 6.75 | L22: 7.21 | M22: 7.57 | N22: 7.6 | O22: 7.36 | P22: 7.16 | Q22: 7.06 | R22: 6.93 | S22: 6.95 | T22: 7.38 | U22: 7.57 | V22: 7.22 | W22: 6.73 | X22: 6.06 | Y22: 5.37 | Z22: =SUM(B22:Y22) -> 146.89 | AA22: 5 | AB22: =+Z22*AA22 -> 734.45 | AD22: SABADOS
A23: 46419 | B23: 4.74 | C23: 4.41 | D23: 4.21 | E23: 4.11 | F23: 4.17 | G23: 4.46 | H23: 5 | I23: 5.61 | J23: 6.37 | K23: 6.95 | L23: 7.41 | M23: 7.7 | N23: 7.67 | O23: 7.48 | P23: 7.32 | Q23: 7.24 | R23: 7.14 | S23: 7.1 | T23: 7.37 | U23: 7.76 | V23: 7.42 | W23: 6.94 | X23: 6.24 | Y23: 5.54 | Z23: =SUM(B23:Y23) -> 150.36 | AA23: 4 | AB23: =+Z23*AA23 -> 601.44 | AD23: SABADOS
A24: 46447 | B24: 4.42 | C24: 4.09 | D24: 3.91 | E24: 3.82 | F24: 3.89 | G24: 4.16 | H24: 4.6 | I24: 5.25 | J24: 5.99 | K24: 6.5 | L24: 6.91 | M24: 7.27 | N24: 7.24 | O24: 6.99 | P24: 6.81 | Q24: 6.71 | R24: 6.62 | S24: 6.65 | T24: 6.89 | U24: 7.11 | V24: 6.79 | W24: 6.35 | X24: 5.71 | Y24: 5.05 | Z24: =SUM(B24:Y24) -> 139.73 | AA24: 4 | AB24: =+Z24*AA24 -> 558.92 | AD24: SABADOS
A25: 46478 | B25: 4.19 | C25: 3.87 | D25: 3.68 | E25: 3.59 | F25: 3.64 | G25: 3.78 | H25: 4.26 | I25: 4.92 | J25: 5.59 | K25: 6.11 | L25: 6.51 | M25: 6.81 | N25: 6.82 | O25: 6.56 | P25: 6.4 | Q25: 6.32 | R25: 6.18 | S25: 6.21 | T25: 6.56 | U25: 6.76 | V25: 6.45 | W25: 6.01 | X25: 5.43 | Y25: 4.82 | Z25: =SUM(B25:Y25) -> 131.47 | AA25: 4 | AB25: =+Z25*AA25 -> 525.88 | AD25: SABADOS
A26: 46508 | B26: 3.51 | C26: 3.26 | D26: 3.12 | E26: 3.04 | F26: 3.1 | G26: 3.22 | H26: 3.69 | I26: 4.27 | J26: 4.86 | K26: 5.33 | L26: 5.64 | M26: 5.88 | N26: 5.82 | O26: 5.58 | P26: 5.45 | Q26: 5.37 | R26: 5.27 | S26: 5.3 | T26: 5.62 | U26: 5.79 | V26: 5.5 | W26: 5.12 | X26: 4.6 | Y26: 4.07 | Z26: =SUM(B26:Y26) -> 112.41 | AA26: 4 | AB26: =+Z26*AA26 -> 449.64 | AD26: SABADOS
A27: 46539 | B27: 3.55 | C27: 3.28 | D27: 3.13 | E27: 3.06 | F27: 3.12 | G27: 3.27 | H27: 3.67 | I27: 4.24 | J27: 4.84 | K27: 5.32 | L27: 5.63 | M27: 5.89 | N27: 5.9 | O27: 5.71 | P27: 5.54 | Q27: 5.41 | R27: 5.3 | S27: 5.33 | T27: 5.62 | U27: 5.81 | V27: 5.53 | W27: 5.14 | X27: 4.59 | Y27: 4.03 | Z27: =SUM(B27:Y27) -> 112.91 | AA27: 4 | AB27: =+Z27*AA27 -> 451.64 | AD27: SABADOS
A28: 46569 | B28: 3.95 | C28: 3.64 | D28: 3.45 | E28: 3.37 | F28: 3.42 | G28: 3.55 | H28: 4 | I28: 4.6 | J28: 5.3 | K28: 5.83 | L28: 6.19 | M28: 6.49 | N28: 6.5 | O28: 6.27 | P28: 6.06 | Q28: 5.91 | R28: 5.8 | S28: 5.83 | T28: 6.07 | U28: 6.41 | V28: 6.1 | W28: 5.7 | X28: 5.13 | Y28: 4.53 | Z28: =SUM(B28:Y28) -> 124.1 | AA28: 5 | AB28: =+Z28*AA28 -> 620.5 | AD28: SABADOS
A31: DEMANDA DIARIA ESTIMADA DÍA DOMINGO Y FESTIVO DIFERENTE A LUNES [MWh]
A33: MES | B33: H1 | C33: H2 | D33: H3 | E33: H4 | F33: H5 | G33: H6 | H33: H7 | I33: H8 | J33: H9 | K33: H10 | L33: H11 | M33: H12 | N33: H13 | O33: H14 | P33: H15 | Q33: H16 | R33: H17 | S33: H18 | T33: H19 | U33: H20 | V33: H21 | W33: H22 | X33: H23 | Y33: H24 | Z33: TOTAL | AA33: Días
A34: 46357 | B34: 4.12 | C34: 3.82 | D34: 3.62 | E34: 3.49 | F34: 3.42 | G34: 3.41 | H34: 3.47 | I34: 3.5 | J34: 3.82 | K34: 3.84 | L34: 3.9 | M34: 4.37 | N34: 4.62 | O34: 5.08 | P34: 5.13 | Q34: 5.13 | R34: 5.15 | S34: 5.23 | T34: 5.72 | U34: 5.82 | V34: 5.66 | W34: 5.34 | X34: 4.83 | Y34: 4.26 | Z34: =SUM(B34:Y34) -> 106.75 | AA34: 6 | AB34: =+Z34*AA34 -> 640.5 | AD34: DOMINGOS Y FESTIVOS
A35: 46388 | B35: 4.85 | C35: 4.49 | D35: 4.21 | E35: 4.09 | F35: 4.02 | G35: 4.04 | H35: 4.15 | I35: 4.38 | J35: 4.84 | K35: 5.31 | L35: 5.71 | M35: 6.06 | N35: 6.28 | O35: 6.28 | P35: 6.15 | Q35: 6.07 | R35: 6.04 | S35: 6.09 | T35: 6.6 | U35: 7.04 | V35: 6.91 | W35: 6.48 | X35: 5.8 | Y35: 5.12 | Z35: =SUM(B35:Y35) -> 131.01 | AA35: 6 | AB35: =+Z35*AA35 -> 786.06 | AD35: DOMINGOS Y FESTIVOS
A36: 46419 | B36: 4.9 | C36: 4.52 | D36: 4.26 | E36: 4.11 | F36: 4.09 | G36: 4.17 | H36: 4.36 | I36: 4.67 | J36: 5.22 | K36: 5.74 | L36: 6.08 | M36: 6.41 | N36: 6.57 | O36: 6.48 | P36: 6.28 | Q36: 6.15 | R36: 6.07 | S36: 6.15 | T36: 6.53 | U36: 7.17 | V36: 7.02 | W36: 6.53 | X36: 5.72 | Y36: 4.93 | Z36: =SUM(B36:Y36) -> 134.13 | AA36: 4 | AB36: =+Z36*AA36 -> 536.52 | AD36: DOMINGOS Y FESTIVOS
A37: 46447 | B37: 4.52 | C37: 4.17 | D37: 3.96 | E37: 3.83 | F37: 3.79 | G37: 3.87 | H37: 4.04 | I37: 4.36 | J37: 4.84 | K37: 5.29 | L37: 5.6 | M37: 5.87 | N37: 6.06 | O37: 6.03 | P37: 5.84 | Q37: 5.75 | R37: 5.73 | S37: 5.87 | T37: 6.32 | U37: 6.73 | V37: 6.53 | W37: 6.06 | X37: 5.37 | Y37: 4.66 | Z37: =SUM(B37:Y37) -> 125.09 | AA37: 6 | AB37: =+Z37*AA37 -> 750.54 | AD37: DOMINGOS Y FESTIVOS
A38: 46478 | B38: 4.2 | C38: 3.86 | D38: 3.65 | E38: 3.54 | F38: 3.53 | G38: 3.53 | H38: 3.71 | I38: 4.1 | J38: 4.57 | K38: 5.01 | L38: 5.36 | M38: 5.69 | N38: 5.84 | O38: 5.75 | P38: 5.64 | Q38: 5.45 | R38: 5.39 | S38: 5.53 | T38: 5.95 | U38: 6.24 | V38: 6.08 | W38: 5.67 | X38: 5.03 | Y38: 4.42 | Z38: =SUM(B38:Y38) -> 117.74 | AA38: 4 | AB38: =+Z38*AA38 -> 470.96 | AD38: DOMINGOS Y FESTIVOS
A39: 46508 | B39: 3.59 | C39: 3.3 | D39: 3.13 | E39: 3.02 | F39: 2.99 | G39: 2.93 | H39: 3.19 | I39: 3.53 | J39: 3.94 | K39: 4.36 | L39: 4.64 | M39: 4.86 | N39: 4.91 | O39: 4.87 | P39: 4.67 | Q39: 4.66 | R39: 4.64 | S39: 4.71 | T39: 5.05 | U39: 5.39 | V39: 5.27 | W39: 4.91 | X39: 4.33 | Y39: 3.76 | Z39: =SUM(B39:Y39) -> 100.65 | AA39: 6 | AB39: =+Z39*AA39 -> 603.9 | AD39: DOMINGOS Y FESTIVOS
A40: 46539 | B40: 3.56 | C40: 3.27 | D40: 3.1 | E40: 3 | F40: 2.98 | G40: 2.99 | H40: 3.19 | I40: 3.53 | J40: 3.94 | K40: 4.35 | L40: 4.59 | M40: 4.8 | N40: 4.92 | O40: 4.9 | P40: 4.76 | Q40: 4.65 | R40: 4.59 | S40: 4.65 | T40: 4.98 | U40: 5.39 | V40: 5.26 | W40: 4.9 | X40: 4.36 | Y40: 3.79 | Z40: =SUM(B40:Y40) -> 100.45 | AA40: 4 | AB40: =+Z40*AA40 -> 401.8 | AD40: DOMINGOS Y FESTIVOS
A41: 46569 | B41: 3.98 | C41: 3.68 | D41: 3.49 | E41: 3.36 | F41: 3.35 | G41: 3.34 | H41: 3.52 | I41: 3.88 | J41: 4.34 | K41: 4.78 | L41: 5.06 | M41: 5.36 | N41: 5.48 | O41: 5.38 | P41: 5.23 | Q41: 5.13 | R41: 5.11 | S41: 5.18 | T41: 5.47 | U41: 5.94 | V41: 5.81 | W41: 5.41 | X41: 4.79 | Y41: 4.16 | Z41: =SUM(B41:Y41) -> 111.23 | AA41: 5 | AB41: =+Z41*AA41 -> 556.15 | AD41: DOMINGOS Y FESTIVOS
A44: DEMANDA DIARIA ESTIMADA DÍA LUNES FESTIVO [MWh]
A46: MES | B46: H1 | C46: H2 | D46: H3 | E46: H4 | F46: H5 | G46: H6 | H46: H7 | I46: H8 | J46: H9 | K46: H10 | L46: H11 | M46: H12 | N46: H13 | O46: H14 | P46: H15 | Q46: H16 | R46: H17 | S46: H18 | T46: H19 | U46: H20 | V46: H21 | W46: H22 | X46: H23 | Y46: H24 | Z46: TOTAL | AA46: Días
A47: 46357 | B47: 4.12 | C47: 3.82 | D47: 3.62 | E47: 3.49 | F47: 3.42 | G47: 3.41 | H47: 3.47 | I47: 3.5 | J47: 3.82 | K47: 3.84 | L47: 3.9 | M47: 4.37 | N47: 4.62 | O47: 5.08 | P47: 5.13 | Q47: 5.13 | R47: 5.15 | S47: 5.23 | T47: 5.72 | U47: 5.82 | V47: 5.66 | W47: 5.34 | X47: 4.83 | Y47: 4.26 | Z47: =SUM(B47:Y47) -> 106.75 | AA47: 0 | AB47: =+Z47*AA47 -> 0 | AD47: LUNES FESTIVOS
A48: 46388 | B48: 4.58 | C48: 4.23 | D48: 4.01 | E48: 3.89 | F48: 3.89 | G48: 3.98 | H48: 4.21 | I48: 4.5 | J48: 5 | K48: 5.55 | L48: 6.05 | M48: 6.45 | N48: 6.63 | O48: 6.49 | P48: 6.17 | Q48: 6.03 | R48: 6.05 | S48: 6.26 | T48: 6.81 | U48: 7.08 | V48: 6.8 | W48: 6.26 | X48: 5.49 | Y48: 4.74 | Z48: =SUM(B48:Y48) -> 131.15 | AA48: 1 | AB48: =+Z48*AA48 -> 131.15 | AD48: LUNES FESTIVOS
A49: 46419 | B49: 4.9 | C49: 4.52 | D49: 4.26 | E49: 4.11 | F49: 4.09 | G49: 4.17 | H49: 4.36 | I49: 4.67 | J49: 5.22 | K49: 5.74 | L49: 6.08 | M49: 6.41 | N49: 6.57 | O49: 6.48 | P49: 6.28 | Q49: 6.15 | R49: 6.07 | S49: 6.15 | T49: 6.53 | U49: 7.17 | V49: 7.02 | W49: 6.53 | X49: 5.72 | Y49: 4.93 | Z49: =SUM(B49:Y49) -> 134.13 | AA49: 0 | AB49: =+Z49*AA49 -> 0 | AD49: LUNES FESTIVOS
A50: 46447 | B50: 4.35 | C50: 4.03 | D50: 3.84 | E50: 3.73 | F50: 3.71 | G50: 3.8 | H50: 3.95 | I50: 4.38 | J50: 4.94 | K50: 5.41 | L50: 5.81 | M50: 6.17 | N50: 6.28 | O50: 6.2 | P50: 6.05 | Q50: 5.94 | R50: 5.92 | S50: 6.06 | T50: 6.47 | U50: 6.86 | V50: 6.68 | W50: 6.18 | X50: 5.35 | Y50: 4.63 | Z50: =SUM(B50:Y50) -> 126.74 | AA50: 1 | AB50: =+Z50*AA50 -> 126.74 | AD50: LUNES FESTIVOS
A51: 46478 | B51: 4.2 | C51: 3.86 | D51: 3.65 | E51: 3.54 | F51: 3.53 | G51: 3.53 | H51: 3.71 | I51: 4.1 | J51: 4.57 | K51: 5.01 | L51: 5.36 | M51: 5.69 | N51: 5.84 | O51: 5.75 | P51: 5.64 | Q51: 5.45 | R51: 5.39 | S51: 5.53 | T51: 5.95 | U51: 6.24 | V51: 6.08 | W51: 5.67 | X51: 5.03 | Y51: 4.42 | Z51: =SUM(B51:Y51) -> 117.74 | AA51: 0 | AB51: =+Z51*AA51 -> 0 | AD51: LUNES FESTIVOS
A52: 46508 | B52: 3.35 | C52: 3.1 | D52: 2.98 | E52: 2.91 | F52: 2.93 | G52: 2.95 | H52: 3.17 | I52: 3.58 | J52: 4.07 | K52: 4.44 | L52: 4.72 | M52: 5.1 | N52: 5.32 | O52: 5.2 | P52: 4.9 | Q52: 4.78 | R52: 4.72 | S52: 4.8 | T52: 5.06 | U52: 5.46 | V52: 5.28 | W52: 4.87 | X52: 4.22 | Y52: 3.63 | Z52: =SUM(B52:Y52) -> 101.54 | AA52: 2 | AB52: =+Z52*AA52 -> 203.08 | AD52: LUNES FESTIVOS
...

Sheet Oferta Producto No. 2
D2: ANEXO No. 1 OFERTAS Y CANTIDADES
C3: OFERTA A LA EMPRESA DE ENERGIA DE PEREIRA S.A. ESP. INVITACIÓN PARA EL SUMINISTRO DE ENERGÍA ELÉCTRICA CON DESTINO AL MERCADO REGULADO CONVOCATORIA PÚBLICA No. 005-2026 - CP-EEPC2026-005
D4: PRODUCTO No. 2
C6: EMPRESA: XXXXXXXXXXXXXXXXXXXXXXXXXXXXXX
C7: REPRESENTANTE LEGAL: XXXXXXXXXXXXXXXXXXXXXXXXXXXXXX
C8: TIPO DE AGENTE: (COMERCIALIZADOR/GENERADOR)
C9: ="PRODUCTO OFERTADO: "&D4 -> PRODUCTO OFERTADO: PRODUCTO No. 2
C11: Las tarifas ofertadas están referidas en pesos constantes de septiembre de 2026 provisional
F13: ="Oferta " & PROPER(D4) -> Oferta Producto No. 2
F14: Periodo | G14: Energía requerida (MWh-año) | H14: Energía ofertada (%) | I14: Energía ofertada (MWh-año) | J14: Tarifa monomia ($/kWh)
F15: 46357 | G15: =+SUMIFS('Cantidades Producto No. 2'!$AB$29:$AB$29,'Cantidades Producto No. 2'!$A$29:$A$29,'Oferta Producto No. 2'!F15) -> 3826.36
F16: TOTAL | G16: =SUM(G15:G15) -> 3826.36
B18: Notas
B20: (1) Oferta válida para la modalidad Pague lo Contratado.
B21: ="(2) Las cantidades se distribuyen de acuerdo a la curva del Anexo 1. Ofertas y Cantidades "& D4 &" de los Pliegos de Condiciones Preliminares." -> (2) Las cantidades se distribuyen de acuerdo a la curva del Anexo 1. Ofertas y Cantidades PRODUCTO No. 2 de los Pliegos de Condiciones Preliminares.
B22: (3) La cantidad de energía es equivalente a un porcentaje de las cantidades de energía requerida por la Empresa de Energía de Pereira S.A. ESP. (para todo el año/para cada mes), de acuerdo con el Anexo No.1 Ofertas y Cantidades PRODUCTO No. 2 de los Pliegos Preliminares, que se aplicarán para todas las 24 horas del día de la curva establecida en dicho Anexo, presentando una tarifa para cada año sin ningún tipo de discriminación por mes, ni tipo de carga ni tipo de día.
B23: (4) Esta oferta NO presenta restricciones tales como adjudicación mínima o total u otras que no permitan la evaluación objetiva e integral del producto ofertado.
B24: (5) Los precios ofertados incluyen todos los pagos, cargos, impuestos, estampillas, etc., que el Proponente deba realizar ante cualquier entidad gubernamental, o empresa pública, privada o mixta para entregar la energía en la frontera con el Sistema de Transmisión Nacional – STN.
B25: (6) Las cantidades ofertadas están sujetas a la adjudicación en la misma proporción respecto a las cantidades ofertadas para todos y cada uno de los meses del año. Es decir, si la Empresa de Energía de Pereira decide adjudicar, por ejemplo, el 50% de lo ofertado en cualesquiera de los meses de alguno de los años, ese mismo porcentaje debe ser adjudicado en el resto de cada uno de los meses de ese año.

Sheet Cantidades Producto No. 2
A2: EMPRESA DE ENERGÍA DE PEREIRA S.A. E.S.P.
A3: PRODUCTO No. 2
A5: DEMANDA DIARIA ESTIMADA DÍA HABIL [MWh]
A7: MES | B7: H1 | C7: H2 | D7: H3 | E7: H4 | F7: H5 | G7: H6 | H7: H7 | I7: H8 | J7: H9 | K7: H10 | L7: H11 | M7: H12 | N7: H13 | O7: H14 | P7: H15 | Q7: H16 | R7: H17 | S7: H18 | T7: H19 | U7: H20 | V7: H21 | W7: H22 | X7: H23 | Y7: H24 | Z7: TOTAL | AA7: Días
A8: 46357 | B8: 3.97 | C8: 3.67 | D8: 3.52 | E8: 3.45 | F8: 3.53 | G8: 3.77 | H8: 4.24 | I8: 4.77 | J8: 5.38 | K8: 5.76 | L8: 6.08 | M8: 6.42 | N8: 6.45 | O8: 6.42 | P8: 6.52 | Q8: 6.53 | R8: 6.42 | S8: 6.33 | T8: 6.64 | U8: 6.61 | V8: 6.28 | W8: 5.85 | X8: 5.21 | Y8: 4.56 | Z8: =SUM(B8:Y8) -> 128.38 | AA8: 21 | AB8: =+Z8*AA8 -> 2695.98 | AD8: HABIL
A11: DEMANDA DIARIA ESTIMADA DÍA SABADO [MWh]
A13: MES | B13: H1 | C13: H2 | D13: H3 | E13: H4 | F13: H5 | G13: H6 | H13: H7 | I13: H8 | J13: H9 | K13: H10 | L13: H11 | M13: H12 | N13: H13 | O13: H14 | P13: H15 | Q13: H16 | R13: H17 | S13: H18 | T13: H19 | U13: H20 | V13: H21 | W13: H22 | X13: H23 | Y13: H24 | Z13: TOTAL | AA13: Días
A14: 46357 | B14: 4.11 | C14: 3.79 | D14: 3.61 | E14: 3.5 | F14: 3.53 | G14: 3.68 | H14: 4.04 | I14: 4.54 | J14: 5.12 | K14: 5.57 | L14: 5.87 | M14: 6.1 | N14: 6.1 | O14: 5.97 | P14: 5.89 | Q14: 5.83 | R14: 5.8 | S14: 5.82 | T14: 6.25 | U14: 6.23 | V14: 5.92 | W14: 5.55 | X14: 5.08 | Y14: 4.57 | Z14: =SUM(B14:Y14) -> 122.47 | AA14: 4 | AB14: =+Z14*AA14 -> 489.88 | AD14: SABADOS
A16: DEMANDA DIARIA ESTIMADA DÍA DOMINGO Y FESTIVO DIFERENTE A LUNES [MWh]
A18: MES | B18: H1 | C18: H2 | D18: H3 | E18: H4 | F18: H5 | G18: H6 | H18: H7 | I18: H8 | J18: H9 | K18: H10 | L18: H11 | M18: H12 | N18: H13 | O18: H14 | P18: H15 | Q18: H16 | R18: H17 | S18: H18 | T18: H19 | U18: H20 | V18: H21 | W18: H22 | X18: H23 | Y18: H24 | Z18: TOTAL | AA18: Días
A19: 46357 | B19: 4.12 | C19: 3.82 | D19: 3.62 | E19: 3.49 | F19: 3.42 | G19: 3.41 | H19: 3.47 | I19: 3.5 | J19: 3.82 | K19: 3.84 | L19: 3.9 | M19: 4.37 | N19: 4.62 | O19: 5.08 | P19: 5.13 | Q19: 5.13 | R19: 5.15 | S19: 5.23 | T19: 5.72 | U19: 5.82 | V19: 5.66 | W19: 5.34 | X19: 4.83 | Y19: 4.26 | Z19: =SUM(B19:Y19) -> 106.75 | AA19: 6 | AB19: =+Z19*AA19 -> 640.5 | AD19: DOMINGOS Y FESTIVOS
A21: DEMANDA DIARIA ESTIMADA DÍA LUNES FESTIVO [MWh]
A23: MES | B23: H1 | C23: H2 | D23: H3 | E23: H4 | F23: H5 | G23: H6 | H23: H7 | I23: H8 | J23: H9 | K23: H10 | L23: H11 | M23: H12 | N23: H13 | O23: H14 | P23: H15 | Q23: H16 | R23: H17 | S23: H18 | T23: H19 | U23: H20 | V23: H21 | W23: H22 | X23: H23 | Y23: H24 | Z23: TOTAL | AA23: Días
A24: 46357 | B24: 4.12 | C24: 3.82 | D24: 3.62 | E24: 3.49 | F24: 3.42 | G24: 3.41 | H24: 3.47 | I24: 3.5 | J24: 3.82 | K24: 3.84 | L24: 3.9 | M24: 4.37 | N24: 4.62 | O24: 5.08 | P24: 5.13 | Q24: 5.13 | R24: 5.15 | S24: 5.23 | T24: 5.72 | U24: 5.82 | V24: 5.66 | W24: 5.34 | X24: 4.83 | Y24: 4.26 | Z24: =SUM(B24:Y24) -> 106.75 | AA24: 0 | AB24: =+Z24*AA24 -> 0 | AD24: LUNES FESTIVOS
A26: DEMANDA DIARIA ESTIMADA TOTAL [MWh]
A28: MES | B28: H1 | C28: H2 | D28: H3 | E28: H4 | F28: H5 | G28: H6 | H28: H7 | I28: H8 | J28: H9 | K28: H10 | L28: H11 | M28: H12 | N28: H13 | O28: H14 | P28: H15 | Q28: H16 | R28: H17 | S28: H18 | T28: H19 | U28: H20 | V28: H21 | W28: H22 | X28: H23 | Y28: H24 | Z28: TOTAL | AA28: Días
A29: =+A24 -> 46357 | B29: =+B8*$AA8+B14*$AA14+B19*$AA19+B24*$AA24 -> 124.53 | C29: =+C8*$AA8+C14*$AA14+C19*$AA19+C24*$AA24 -> 115.15 | D29: =+D8*$AA8+D14*$AA14+D19*$AA19+D24*$AA24 -> 110.08 | E29: =+E8*$AA8+E14*$AA14+E19*$AA19+E24*$AA24 -> 107.39 | F29: =+F8*$AA8+F14*$AA14+F19*$AA19+F24*$AA24 -> 108.77 | G29: =+G8*$AA8+G14*$AA14+G19*$AA19+G24*$AA24 -> 114.35 | H29: =+H8*$AA8+H14*$AA14+H19*$AA19+H24*$AA24 -> 126.02 | I29: =+I8*$AA8+I14*$AA14+I19*$AA19+I24*$AA24 -> 139.33 | ... Y29: =+Y8*$AA8+Y14*$AA14+Y19*$AA19+Y24*$AA24 -> 139.6 | Z29: =SUM(B29:Y29) -> 3826.36 | AA29: =AA8+AA14+AA19+AA24 -> 31 | AB29: =+AB8+AB14+AB19+AB24 -> 3826.36 | AD29: =+AB29-Z29 -> 0

Sheet Oferta Producto No. 3
D2: ANEXO No. 1 OFERTAS Y CANTIDADES
C3: OFERTA A LA EMPRESA DE ENERGIA DE PEREIRA S.A. ESP. INVITACIÓN PARA EL SUMINISTRO DE ENERGÍA ELÉCTRICA CON DESTINO AL MERCADO REGULADO CONVOCATORIA PÚBLICA No. 005-2026 - CP-EEPC2026-005
D4: PRODUCTO No. 3
C6: EMPRESA: XXXXXXXXXXXXXXXXXXXXXXXXXXXXXX
C7: REPRESENTANTE LEGAL: XXXXXXXXXXXXXXXXXXXXXXXXXXXXXX
C8: TIPO DE AGENTE: (COMERCIALIZADOR/GENERADOR)
C9: ="PRODUCTO OFERTADO: "&D4 -> PRODUCTO OFERTADO: PRODUCTO No. 3
C11: Las tarifas ofertadas están referidas en pesos constantes de septiembre de 2026 provisional
F13: ="Oferta " & PROPER(D4) -> Oferta Producto No. 3
F14: Periodo | G14: Energía requerida (MWh-año) | H14: Energía ofertada (%) | I14: Energía ofertada (MWh-año) | J14: Tarifa monomia ($/kWh)
F15: 46388 | G15: =+SUMIFS('Cantidades Producto No. 3'!$AB$53:$AB$59,'Cantidades Producto No. 3'!$A$53:$A$59,'Oferta Producto No. 3'!F15) -> 4608.25
F16: 46419 | G16: =+SUMIFS('Cantidades Producto No. 3'!$AB$53:$AB$59,'Cantidades Producto No. 3'!$A$53:$A$59,'Oferta Producto No. 3'!F16) -> 4324.36
F17: 46447 | G17: =+SUMIFS('Cantidades Producto No. 3'!$AB$53:$AB$59,'Cantidades Producto No. 3'!$A$53:$A$59,'Oferta Producto No. 3'!F17) -> 4419.2
F18: 46478 | G18: =+SUMIFS('Cantidades Producto No. 3'!$AB$53:$AB$59,'Cantidades Producto No. 3'!$A$53:$A$59,'Oferta Producto No. 3'!F18) -> 4075.96
F19: 46508 | G19: =+SUMIFS('Cantidades Producto No. 3'!$AB$53:$AB$59,'Cantidades Producto No. 3'!$A$53:$A$59,'Oferta Producto No. 3'!F19) -> 3515.72
F20: 46539 | G20: =+SUMIFS('Cantidades Producto No. 3'!$AB$53:$AB$59,'Cantidades Producto No. 3'!$A$53:$A$59,'Oferta Producto No. 3'!F20) -> 3475.57
F21: 46569 | G21: =+SUMIFS('Cantidades Producto No. 3'!$AB$53:$AB$59,'Cantidades Producto No. 3'!$A$53:$A$59,'Oferta Producto No. 3'!F21) -> 3924.58
F22: TOTAL | G22: =SUM(G15:G21) -> 28343.64
B24: Notas
B26: (1) Oferta válida para la modalidad Pague lo Contratado.
B27: ="(2) Las cantidades se distribuyen de acuerdo a la curva del Anexo 1. Ofertas y Cantidades "& D4 &" de los Pliegos de Condiciones Preliminares." -> (2) Las cantidades se distribuyen de acuerdo a la curva del Anexo 1. Ofertas y Cantidades PRODUCTO No. 3 de los Pliegos de Condiciones Preliminares.
B28: (3) La cantidad de energía es equivalente a un porcentaje de las cantidades de energía requerida por la Empresa de Energía de Pereira S.A. ESP. (para todo el año/para cada mes), de acuerdo con el Anexo No.1 Ofertas y Cantidades PRODUCTO No. 3 de los Pliegos Preliminares, que se aplicarán para todas las 24 horas del día de la curva establecida en dicho Anexo, presentando una tarifa para cada año sin ningún tipo de discriminación por mes, ni tipo de carga ni tipo de día.
B29: (4) Esta oferta NO presenta restricciones tales como adjudicación mínima o total u otras que no permitan la evaluación objetiva e integral del producto ofertado.
B30: (5) Los precios ofertados incluyen todos los pagos, cargos, impuestos, estampillas, etc., que el Proponente deba realizar ante cualquier entidad gubernamental, o empresa pública, privada o mixta para entregar la energía en la frontera con el Sistema de Transmisión Nacional – STN.
B31: (6) Las cantidades ofertadas están sujetas a la adjudicación en la misma proporción respecto a las cantidades ofertadas para todos y cada uno de los meses del año. Es decir, si la Empresa de Energía de Pereira decide adjudicar, por ejemplo, el 50% de lo ofertado en cualesquiera de los meses de alguno de los años, ese mismo porcentaje debe ser adjudicado en el resto de cada uno de los meses de ese año

Sheet Cantidades Producto No. 3
A2: EMPRESA DE ENERGÍA DE PEREIRA S.A. E.S.P.
A3: PRODUCTO No. 3
A5: DEMANDA DIARIA ESTIMADA DÍA HABIL [MWh]
A7: MES | B7: H1 | C7: H2 | D7: H3 | E7: H4 | F7: H5 | G7: H6 | H7: H7 | I7: H8 | J7: H9 | K7: H10 | L7: H11 | M7: H12 | N7: H13 | O7: H14 | P7: H15 | Q7: H16 | R7: H17 | S7: H18 | T7: H19 | U7: H20 | V7: H21 | W7: H22 | X7: H23 | Y7: H24 | Z7: TOTAL | AA7: Días | AB7: TOTAL
A8: 46388 | B8: 4.64 | C8: 4.31 | D8: 4.14 | E8: 4.07 | F8: 4.19 | G8: 4.6 | H8: 5.19 | I8: 5.78 | J8: 6.5 | K8: 7.04 | L8: 7.56 | M8: 8.02 | N8: 7.97 | O8: 7.87 | P8: 7.98 | Q8: 7.96 | R8: 7.82 | S8: 7.61 | T8: 7.86 | U8: 8.05 | V8: 7.69 | W8: 7.15 | X8: 6.28 | Y8: 5.33 | Z8: =SUM(B8:Y8) -> 155.61 | AA8: 19 | AB8: =+Z8*AA8 -> 2956.59 | AD8: HABIL
A9: 46419 | B9: 4.66 | C9: 4.35 | D9: 4.18 | E9: 4.14 | F9: 4.32 | G9: 5.01 | H9: 5.7 | I9: 6.15 | J9: 6.79 | K9: 7.28 | L9: 7.79 | M9: 8.21 | N9: 8.02 | O9: 7.99 | P9: 8.17 | Q9: 8.18 | R9: 8.05 | S9: 7.72 | T9: 7.79 | U9: 8.11 | V9: 7.82 | W9: 7.25 | X9: 6.31 | Y9: 5.33 | Z9: =SUM(B9:Y9) -> 159.32 | AA9: 20 | AB9: =+Z9*AA9 -> 3186.4 | AD9: HABIL
A10: 46447 | B10: 4.34 | C10: 4.06 | D10: 3.91 | E10: 3.86 | F10: 4.03 | G10: 4.66 | H10: 5.28 | I10: 5.78 | J10: 6.39 | K10: 6.82 | L10: 7.3 | M10: 7.68 | N10: 7.55 | O10: 7.47 | P10: 7.62 | Q10: 7.6 | R10: 7.48 | S10: 7.26 | T10: 7.37 | U10: 7.67 | V10: 7.33 | W10: 6.78 | X10: 5.91 | Y10: 5 | Z10: =SUM(B10:Y10) -> 149.15 | AA10: 20 | AB10: =+Z10*AA10 -> 2983 | AD10: HABIL
A11: 46478 | B11: 4.08 | C11: 3.8 | D11: 3.67 | E11: 3.62 | F11: 3.78 | G11: 4.3 | H11: 4.89 | I11: 5.44 | J11: 5.97 | K11: 6.49 | L11: 6.91 | M11: 7.26 | N11: 7.14 | O11: 7.02 | P11: 7.04 | Q11: 7.05 | R11: 6.97 | S11: 6.83 | T11: 7.05 | U11: 7.21 | V11: 6.87 | W11: 6.34 | X11: 5.53 | Y11: 4.7 | Z11: =SUM(B11:Y11) -> 139.96 | AA11: 22 | AB11: =+Z11*AA11 -> 3079.12 | AD11: HABIL
A12: 46508 | B12: 3.46 | C12: 3.23 | D12: 3.11 | E12: 3.06 | F12: 3.21 | G12: 3.62 | H12: 4.16 | I12: 4.62 | J12: 5.12 | K12: 5.5 | L12: 5.89 | M12: 6.21 | N12: 6.09 | O12: 5.99 | P12: 6.06 | Q12: 6.03 | R12: 5.9 | S12: 5.81 | T12: 5.99 | U12: 6.1 | V12: 5.82 | W12: 5.34 | X12: 4.64 | Y12: 3.94 | Z12: =SUM(B12:Y12) -> 118.9 | AA12: 19 | AB12: =+Z12*AA12 -> 2259.1 | AD12: HABIL
A13: 46539 | B13: 3.49 | C13: 3.24 | D13: 3.11 | E13: 3.06 | F13: 3.2 | G13: 3.55 | H13: 4.14 | I13: 4.65 | J13: 5.18 | K13: 5.57 | L13: 5.93 | M13: 6.27 | N13: 6.18 | O13: 6.05 | P13: 6.09 | Q13: 6.07 | R13: 5.98 | S13: 5.87 | T13: 6.01 | U13: 6.24 | V13: 5.95 | W13: 5.45 | X13: 4.71 | Y13: 4.01 | Z13: =SUM(B13:Y13) -> 120 | AA13: 21 | AB13: =+Z13*AA13 -> 2520 | AD13: HABIL
A14: 46569 | B14: 3.8 | C14: 3.56 | D14: 3.41 | E14: 3.36 | F14: 3.51 | G14: 3.96 | H14: 4.53 | I14: 5.08 | J14: 5.67 | K14: 6.12 | L14: 6.51 | M14: 6.89 | N14: 6.76 | O14: 6.64 | P14: 6.72 | Q14: 6.74 | R14: 6.65 | S14: 6.47 | T14: 6.52 | U14: 6.85 | V14: 6.53 | W14: 5.99 | X14: 5.16 | Y14: 4.43 | Z14: =SUM(B14:Y14) -> 131.86 | AA14: 20 | AB14: =+Z14*AA14 -> 2637.2 | AD14: HABIL
A17: DEMANDA DIARIA ESTIMADA DÍA SABADO [MWh]
A19: MES | B19: H1 | C19: H2 | D19: H3 | E19: H4 | F19: H5 | G19: H6 | H19: H7 | I19: H8 | J19: H9 | K19: H10 | L19: H11 | M19: H12 | N19: H13 | O19: H14 | P19: H15 | Q19: H16 | R19: H17 | S19: H18 | T19: H19 | U19: H20 | V19: H21 | W19: H22 | X19: H23 | Y19: H24 | Z19: TOTAL | AA19: Días
A20: 46388 | B20: 4.74 | C20: 4.38 | D20: 4.17 | E20: 4.06 | F20: 4.11 | G20: 4.31 | H20: 4.74 | I20: 5.35 | J20: 6.11 | K20: 6.75 | L20: 7.21 | M20: 7.57 | N20: 7.6 | O20: 7.36 | P20: 7.16 | Q20: 7.06 | R20: 6.93 | S20: 6.95 | T20: 7.38 | U20: 7.57 | V20: 7.22 | W20: 6.73 | X20: 6.06 | Y20: 5.37 | Z20: =SUM(B20:Y20) -> 146.89 | AA20: 5 | AB20: =+Z20*AA20 -> 734.45 | AD20: SABADOS
A21: 46419 | B21: 4.74 | C21: 4.41 | D21: 4.21 | E21: 4.11 | F21: 4.17 | G21: 4.46 | H21: 5 | I21: 5.61 | J21: 6.37 | K21: 6.95 | L21: 7.41 | M21: 7.7 | N21: 7.67 | O21: 7.48 | P21: 7.32 | Q21: 7.24 | R21: 7.14 | S21: 7.1 | T21: 7.37 | U21: 7.76 | V21: 7.42 | W21: 6.94 | X21: 6.24 | Y21: 5.54 | Z21: =SUM(B21:Y21) -> 150.36 | AA21: 4 | AB21: =+Z21*AA21 -> 601.44 | AD21: SABADOS
A22: 46447 | B22: 4.42 | C22: 4.09 | D22: 3.91 | E22: 3.82 | F22: 3.89 | G22: 4.16 | H22: 4.6 | I22: 5.25 | J22: 5.99 | K22: 6.5 | L22: 6.91 | M22: 7.27 | N22: 7.24 | O22: 6.99 | P22: 6.81 | Q22: 6.71 | R22: 6.62 | S22: 6.65 | T22: 6.89 | U22: 7.11 | V22: 6.79 | W22: 6.35 | X22: 5.71 | Y22: 5.05 | Z22: =SUM(B22:Y22) -> 139.73 | AA22: 4 | AB22: =+Z22*AA22 -> 558.92 | AD22: SABADOS
A23: 46478 | B23: 4.19 | C23: 3.87 | D23: 3.68 | E23: 3.59 | F23: 3.64 | G23: 3.78 | H23: 4.26 | I23: 4.92 | J23: 5.59 | K23: 6.11 | L23: 6.51 | M23: 6.81 | N23: 6.82 | O23: 6.56 | P23: 6.4 | Q23: 6.32 | R23: 6.18 | S23: 6.21 | T23: 6.56 | U23: 6.76 | V23: 6.45 | W23: 6.01 | X23: 5.43 | Y23: 4.82 | Z23: =SUM(B23:Y23) -> 131.47 | AA23: 4 | AB23: =+Z23*AA23 -> 525.88 | AD23: SABADOS
A24: 46508 | B24: 3.51 | C24: 3.26 | D24: 3.12 | E24: 3.04 | F24: 3.1 | G24: 3.22 | H24: 3.69 | I24: 4.27 | J24: 4.86 | K24: 5.33 | L24: 5.64 | M24: 5.88 | N24: 5.82 | O24: 5.58 | P24: 5.45 | Q24: 5.37 | R24: 5.27 | S24: 5.3 | T24: 5.62 | U24: 5.79 | V24: 5.5 | W24: 5.12 | X24: 4.6 | Y24: 4.07 | Z24: =SUM(B24:Y24) -> 112.41 | AA24: 4 | AB24: =+Z24*AA24 -> 449.64 | AD24: SABADOS
A25: 46539 | B25: 3.55 | C25: 3.28 | D25: 3.13 | E25: 3.06 | F25: 3.12 | G25: 3.27 | H25: 3.67 | I25: 4.24 | J25: 4.84 | K25: 5.32 | L25: 5.63 | M25: 5.89 | N25: 5.9 | O25: 5.71 | P25: 5.54 | Q25: 5.41 | R25: 5.3 | S25: 5.33 | T25: 5.62 | U25: 5.81 | V25: 5.53 | W25: 5.14 | X25: 4.59 | Y25: 4.03 | Z25: =SUM(B25:Y25) -> 112.91 | AA25: 4 | AB25: =+Z25*AA25 -> 451.64 | AD25: SABADOS
A26: 46569 | B26: 3.95 | C26: 3.64 | D26: 3.45 | E26: 3.37 | F26: 3.42 | G26: 3.55 | H26: 4 | I26: 4.6 | J26: 5.3 | K26: 5.83 | L26: 6.19 | M26: 6.49 | N26: 6.5 | O26: 6.27 | P26: 6.06 | Q26: 5.91 | R26: 5.8 | S26: 5.83 | T26: 6.07 | U26: 6.41 | V26: 6.1 | W26: 5.7 | X26: 5.13 | Y26: 4.53 | Z26: =SUM(B26:Y26) -> 124.1 | AA26: 5 | AB26: =+Z26*AA26 -> 620.5 | AD26: SABADOS
A28: DEMANDA DIARIA ESTIMADA DÍA DOMINGO Y FESTIVO DIFERENTE A LUNES [MWh]
A30: MES | B30: H1 | C30: H2 | D30: H3 | E30: H4 | F30: H5 | G30: H6 | H30: H7 | I30: H8 | J30: H9 | K30: H10 | L30: H11 | M30: H12 | N30: H13 | O30: H14 | P30: H15 | Q30: H16 | R30: H17 | S30: H18 | T30: H19 | U30: H20 | V30: H21 | W30: H22 | X30: H23 | Y30: H24 | Z30: TOTAL | AA30: Días
A31: 46388 | B31: 4.85 | C31: 4.49 | D31: 4.21 | E31: 4.09 | F31: 4.02 | G31: 4.04 | H31: 4.15 | I31: 4.38 | J31: 4.84 | K31: 5.31 | L31: 5.71 | M31: 6.06 | N31: 6.28 | O31: 6.28 | P31: 6.15 | Q31: 6.07 | R31: 6.04 | S31: 6.09 | T31: 6.6 | U31: 7.04 | V31: 6.91 | W31: 6.48 | X31: 5.8 | Y31: 5.12 | Z31: =SUM(B31:Y31) -> 131.01 | AA31: 6 | AB31: =+Z31*AA31 -> 786.06 | AD31: DOMINGOS Y FESTIVOS
A32: 46419 | B32: 4.9 | C32: 4.52 | D32: 4.26 | E32: 4.11 | F32: 4.09 | G32: 4.17 | H32: 4.36 | I32: 4.67 | J32: 5.22 | K32: 5.74 | L32: 6.08 | M32: 6.41 | N32: 6.57 | O32: 6.48 | P32: 6.28 | Q32: 6.15 | R32: 6.07 | S32: 6.15 | T32: 6.53 | U32: 7.17 | V32: 7.02 | W32: 6.53 | X32: 5.72 | Y32: 4.93 | Z32: =SUM(B32:Y32) -> 134.13 | AA32: 4 | AB32: =+Z32*AA32 -> 536.52 | AD32: DOMINGOS Y FESTIVOS
A33: 46447 | B33: 4.52 | C33: 4.17 | D33: 3.96 | E33: 3.83 | F33: 3.79 | G33: 3.87 | H33: 4.04 | I33: 4.36 | J33: 4.84 | K33: 5.29 | L33: 5.6 | M33: 5.87 | N33: 6.06 | O33: 6.03 | P33: 5.84 | Q33: 5.75 | R33: 5.73 | S33: 5.87 | T33: 6.32 | U33: 6.73 | V33: 6.53 | W33: 6.06 | X33: 5.37 | Y33: 4.66 | Z33: =SUM(B33:Y33) -> 125.09 | AA33: 6 | AB33: =+Z33*AA33 -> 750.54 | AD33: DOMINGOS Y FESTIVOS
A34: 46478 | B34: 4.2 | C34: 3.86 | D34: 3.65 | E34: 3.54 | F34: 3.53 | G34: 3.53 | H34: 3.71 | I34: 4.1 | J34: 4.57 | K34: 5.01 | L34: 5.36 | M34: 5.69 | N34: 5.84 | O34: 5.75 | P34: 5.64 | Q34: 5.45 | R34: 5.39 | S34: 5.53 | T34: 5.95 | U34: 6.24 | V34: 6.08 | W34: 5.67 | X34: 5.03 | Y34: 4.42 | Z34: =SUM(B34:Y34) -> 117.74 | AA34: 4 | AB34: =+Z34*AA34 -> 470.96 | AD34: DOMINGOS Y FESTIVOS
A35: 46508 | B35: 3.59 | C35: 3.3 | D35: 3.13 | E35: 3.02 | F35: 2.99 | G35: 2.93 | H35: 3.19 | I35: 3.53 | J35: 3.94 | K35: 4.36 | L35: 4.64 | M35: 4.86 | N35: 4.91 | O35: 4.87 | P35: 4.67 | Q35: 4.66 | R35: 4.64 | S35: 4.71 | T35: 5.05 | U35: 5.39 | V35: 5.27 | W35: 4.91 | X35: 4.33 | Y35: 3.76 | Z35: =SUM(B35:Y35) -> 100.65 | AA35: 6 | AB35: =+Z35*AA35 -> 603.9 | AD35: DOMINGOS Y FESTIVOS
A36: 46539 | B36: 3.56 | C36: 3.27 | D36: 3.1 | E36: 3 | F36: 2.98 | G36: 2.99 | H36: 3.19 | I36: 3.53 | J36: 3.94 | K36: 4.35 | L36: 4.59 | M36: 4.8 | N36: 4.92 | O36: 4.9 | P36: 4.76 | Q36: 4.65 | R36: 4.59 | S36: 4.65 | T36: 4.98 | U36: 5.39 | V36: 5.26 | W36: 4.9 | X36: 4.36 | Y36: 3.79 | Z36: =SUM(B36:Y36) -> 100.45 | AA36: 4 | AB36: =+Z36*AA36 -> 401.8 | AD36: DOMINGOS Y FESTIVOS
A37: 46569 | B37: 3.98 | C37: 3.68 | D37: 3.49 | E37: 3.36 | F37: 3.35 | G37: 3.34 | H37: 3.52 | I37: 3.88 | J37: 4.34 | K37: 4.78 | L37: 5.06 | M37: 5.36 | N37: 5.48 | O37: 5.38 | P37: 5.23 | Q37: 5.13 | R37: 5.11 | S37: 5.18 | T37: 5.47 | U37: 5.94 | V37: 5.81 | W37: 5.41 | X37: 4.79 | Y37: 4.16 | Z37: =SUM(B37:Y37) -> 111.23 | AA37: 5 | AB37: =+Z37*AA37 -> 556.15 | AD37: DOMINGOS Y FESTIVOS
A39: DEMANDA DIARIA ESTIMADA DÍA LUNES FESTIVO [MWh]
A41: MES | B41: H1 | C41: H2 | D41: H3 | E41: H4 | F41: H5 | G41: H6 | H41: H7 | I41: H8 | J41: H9 | K41: H10 | L41: H11 | M41: H12 | N41: H13 | O41: H14 | P41: H15 | Q41: H16 | R41: H17 | S41: H18 | T41: H19 | U41: H20 | V41: H21 | W41: H22 | X41: H23 | Y41: H24 | Z41: TOTAL | AA41: Días
A42: 46388 | B42: 4.58 | C42: 4.23 | D42: 4.01 | E42: 3.89 | F42: 3.89 | G42: 3.98 | H42: 4.21 | I42: 4.5 | J42: 5 | K42: 5.55 | L42: 6.05 | M42: 6.45 | N42: 6.63 | O42: 6.49 | P42: 6.17 | Q42: 6.03 | R42: 6.05 | S42: 6.26 | T42: 6.81 | U42: 7.08 | V42: 6.8 | W42: 6.26 | X42: 5.49 | Y42: 4.74 | Z42: =SUM(B42:Y42) -> 131.15 | AA42: 1 | AB42: =+Z42*AA42 -> 131.15 | AD42: LUNES FESTIVOS
A43: 46419 | B43: 4.9 | C43: 4.52 | D43: 4.26 | E43: 4.11 | F43: 4.09 | G43: 4.17 | H43: 4.36 | I43: 4.67 | J43: 5.22 | K43: 5.74 | L43: 6.08 | M43: 6.41 | N43: 6.57 | O43: 6.48 | P43: 6.28 | Q43: 6.15 | R43: 6.07 | S43: 6.15 | T43: 6.53 | U43: 7.17 | V43: 7.02 | W43: 6.53 | X43: 5.72 | Y43: 4.93 | Z43: =SUM(B43:Y43) -> 134.13 | AA43: 0 | AB43: =+Z43*AA43 -> 0 | AD43: LUNES FESTIVOS
A44: 46447 | B44: 4.35 | C44: 4.03 | D44: 3.84 | E44: 3.73 | F44: 3.71 | G44: 3.8 | H44: 3.95 | I44: 4.38 | J44: 4.94 | K44: 5.41 | L44: 5.81 | M44: 6.17 | N44: 6.28 | O44: 6.2 | P44: 6.05 | Q44: 5.94 | R44: 5.92 | S44: 6.06 | T44: 6.47 | U44: 6.86 | V44: 6.68 | W44: 6.18 | X44: 5.35 | Y44: 4.63 | Z44: =SUM(B44:Y44) -> 126.74 | AA44: 1 | AB44: =+Z44*AA44 -> 126.74 | AD44: LUNES FESTIVOS
A45: 46478 | B45: 4.2 | C45: 3.86 | D45: 3.65 | E45: 3.54 | F45: 3.53 | G45: 3.53 | H45: 3.71 | I45: 4.1 | J45: 4.57 | K45: 5.01 | L45: 5.36 | M45: 5.69 | N45: 5.84 | O45: 5.75 | P45: 5.64 | Q45: 5.45 | R45: 5.39 | S45: 5.53 | T45: 5.95 | U45: 6.24 | V45: 6.08 | W45: 5.67 | X45: 5.03 | Y45: 4.42 | Z45: =SUM(B45:Y45) -> 117.74 | AA45: 0 | AB45: =+Z45*AA45 -> 0 | AD45: LUNES FESTIVOS
A46: 46508 | B46: 3.35 | C46: 3.1 | D46: 2.98 | E46: 2.91 | F46: 2.93 | G46: 2.95 | H46: 3.17 | I46: 3.58 | J46: 4.07 | K46: 4.44 | L46: 4.72 | M46: 5.1 | N46: 5.32 | O46: 5.2 | P46: 4.9 | Q46: 4.78 | R46: 4.72 | S46: 4.8 | T46: 5.06 | U46: 5.46 | V46: 5.28 | W46: 4.87 | X46: 4.22 | Y46: 3.63 | Z46: =SUM(B46:Y46) -> 101.54 | AA46: 2 | AB46: =+Z46*AA46 -> 203.08 | AD46: LUNES FESTIVOS
A47: 46539 | B47: 3.42 | C47: 3.15 | D47: 3 | E47: 2.94 | F47: 2.95 | G47: 2.93 | H47: 3.18 | I47: 3.53 | J47: 3.97 | K47: 4.39 | L47: 4.71 | M47: 5.02 | N47: 5.21 | O47: 5.15 | P47: 4.94 | Q47: 4.84 | R47: 4.76 | S47: 4.88 | T47: 5.2 | U47: 5.58 | V47: 5.4 | W47: 4.96 | X47: 4.32 | Y47: 3.7 | Z47: =SUM(B47:Y47) -> 102.13 | AA47: 1 | AB47: =+Z47*AA47 -> 102.13 | AD47: LUNES FESTIVOS
A48: 46569 | B48: 3.88 | C48: 3.59 | D48: 3.4 | E48: 3.31 | F48: 3.3 | G48: 3.29 | H48: 3.51 | I48: 3.89 | J48: 4.36 | K48: 4.79 | L48: 5.19 | M48: 5.58 | N48: 5.78 | O48: 5.61 | P48: 5.24 | Q48: 5.06 | R48: 4.98 | S48: 5.04 | T48: 5.32 | U48: 5.89 | V48: 5.73 | W48: 5.31 | X48: 4.67 | Y48: 4.01 | Z48: =SUM(B48:Y48) -> 110.73 | AA48: 1 | AB48: =+Z48*AA48 -> 110.73 | AD48: LUNES FESTIVOS
A50: DEMANDA DIARIA ESTIMADA TOTAL [MWh]
A52: MES | B52: H1 | C52: H2 | D52: H3 | E52: H4 | F52: H5 | G52: H6 | H52: H7 | I52: H8 | J52: H9 | K52: H10 | L52: H11 | M52: H12 | N52: H13 | O52: H14 | P52: H15 | Q52: H16 | R52: H17 | S52: H18 | T52: H19 | U52: H20 | V52: H21 | W52: H22 | X52: H23 | Y52: H24 | Z52: TOTAL | AA52: Días
...
