Workbook

Sheet Producto No. 1 Plana
A5: ANEXO No. 1. Oferta Producto No. 1 Curva Plana Convocatoria Pública DISPAC S.A. E.S.P.
A8: PROPONENTE
A10: MES | B10: DEMANDA REQUERIDA DISPAC KWh | C10: DEMANDA PERIODO REQUERIDA DISPAC KWh | D10: PORCENTAJE (%) OFERTADO DE LA DEMANDA REQUERIDA | E10: DEMANDA OFERTADA KWh - MES | F10: DEMANDA PERIODO OFERTADA KWh | G10: PRECIO OFERTADO $ kWh (0.00)
A11: 46023 | B11: =+'General Productos No. 1 Plana'!AD2 -> 10118400 | C11: =SUM(B11:B22) -> 92016000 | D11: 0 | E11: =+B11*D11 -> 0 | F11: =SUM(E11:E22) -> 0
A12: 46054 | B12: =+'General Productos No. 1 Plana'!AD5 -> 10416000 | D12: 0 | E12: =+B12*D12 -> 0
A13: 46082 | B13: =+'General Productos No. 1 Plana'!AD8 -> 12573600 | D13: 0 | E13: =+B13*D13 -> 0
A14: 46113 | B14: =+'General Productos No. 1 Plana'!AD11 -> 8640000 | D14: 0 | E14: =+B14*D14 -> 0
A15: 46143 | B15: =+'General Productos No. 1 Plana'!AD14 -> 9672000 | D15: 0 | E15: =+B15*D15 -> 0
A16: 46174 | B16: =+'General Productos No. 1 Plana'!AD17 -> 6120000 | D16: 0 | E16: =+B16*D16 -> 0
A17: 46204 | B17: =+'General Productos No. 1 Plana'!AD20 -> 11904000 | D17: 0 | E17: =+B17*D17 -> 0
A18: 46235 | B18: =+'General Productos No. 1 Plana'!AD23 -> 9672000 | D18: 0 | E18: =+B18*D18 -> 0
A19: 46266 | B19: =+'General Productos No. 1 Plana'!AD26 -> 1800000 | D19: 0 | E19: =+B19*D19 -> 0
A20: 46296 | B20: =+'General Productos No. 1 Plana'!AD29 -> 1860000 | D20: 0 | E20: =+B20*D20 -> 0
A21: 46327 | B21: =+'General Productos No. 1 Plana'!AD32 -> 1800000 | D21: 0 | E21: =+B21*D21 -> 0
A22: 46357 | B22: =+'General Productos No. 1 Plana'!AD35 -> 7440000 | D22: 0 | E22: =+B22*D22 -> 0
A23: 46388 | B23: =+'General Productos No. 1 Plana'!AD38 -> 13392000 | C23: =SUM(B23:B34) -> 93072000 | D23: 0 | E23: =+B23*D23 -> 0 | F23: =SUM(E23:E34) -> 0
A24: 46419 | B24: =+'General Productos No. 1 Plana'!AD41 -> 12096000 | D24: 0 | E24: =+B24*D24 -> 0
A25: 46447 | B25: =+'General Productos No. 1 Plana'!AD44 -> 7440000 | D25: 0 | E25: =+B25*D25 -> 0
A26: 46478 | B26: =+'General Productos No. 1 Plana'!AD47 -> 12960000 | D26: 0 | E26: =+B26*D26 -> 0
A27: 46508 | B27: =+'General Productos No. 1 Plana'!AD50 -> 6696000 | D27: 0 | E27: =+B27*D27 -> 0
A28: 46539 | B28: =+'General Productos No. 1 Plana'!AD53 -> 10080000 | D28: 0 | E28: =+B28*D28 -> 0
A29: 46569 | B29: =+'General Productos No. 1 Plana'!AD56 -> 8928000 | D29: 0 | E29: =+B29*D29 -> 0
A30: 46600 | B30: =+'General Productos No. 1 Plana'!AD59 -> 9672000 | D30: 0 | E30: =+B30*D30 -> 0
A31: 46631 | B31: =+'General Productos No. 1 Plana'!AD62 -> 1440000 | D31: 0 | E31: =+B31*D31 -> 0
A32: 46661 | B32: =+'General Productos No. 1 Plana'!AD65 -> 1488000 | D32: 0 | E32: =+B32*D32 -> 0
A33: 46692 | B33: =+'General Productos No. 1 Plana'!AD68 -> 1440000 | D33: 0 | E33: =+B33*D33 -> 0
A34: 46722 | B34: =+'General Productos No. 1 Plana'!AD71 -> 7440000 | D34: 0 | E34: =+B34*D34 -> 0
A35: 46753 | B35: =+'General Productos No. 1 Plana'!AD74 -> 12276000 | C35: =SUM(B35:B46) -> 78528000 | D35: 0 | E35: =+B35*D35 -> 0 | F35: =SUM(E35:E46) -> 0
A36: 46784 | B36: =+'General Productos No. 1 Plana'!AD77 -> 10788000 | D36: 0 | E36: =+B36*D36 -> 0
A37: 46813 | B37: =+'General Productos No. 1 Plana'!AD80 -> 11904000 | D37: 0 | E37: =+B37*D37 -> 0
A38: 46844 | B38: =+'General Productos No. 1 Plana'!AD83 -> 8280000 | D38: 0 | E38: =+B38*D38 -> 0
A39: 46874 | B39: =+'General Productos No. 1 Plana'!AD86 -> 2232000 | D39: 0 | E39: =+B39*D39 -> 0
A40: 46905 | B40: =+'General Productos No. 1 Plana'!AD89 -> 2160000 | D40: 0 | E40: =+B40*D40 -> 0
A41: 46935 | B41: =+'General Productos No. 1 Plana'!AD92 -> 2232000 | D41: 0 | E41: =+B41*D41 -> 0
A42: 46966 | B42: =+'General Productos No. 1 Plana'!AD95 -> 2976000 | D42: 0 | E42: =+B42*D42 -> 0
A43: 46997 | B43: =+'General Productos No. 1 Plana'!AD98 -> 5400000 | D43: 0 | E43: =+B43*D43 -> 0
A44: 47027 | B44: =+'General Productos No. 1 Plana'!AD101 -> 7440000 | D44: 0 | E44: =+B44*D44 -> 0
A45: 47058 | B45: =+'General Productos No. 1 Plana'!AD104 -> 5400000 | D45: 0 | E45: =+B45*D45 -> 0
A46: 47088 | B46: =+'General Productos No. 1 Plana'!AD107 -> 7440000 | D46: 0 | E46: =+B46*D46 -> 0
A47: TOTALES | B47: =SUM(B11:B46) -> 263616000 | C47: =SUM(C11:C46) -> 263616000 | E47: =SUM(E11:E22) -> 0 | F47: =SUM(F11:F22) -> 0 | G47: =IFERROR(SUMPRODUCT(F11:F22,G11:G22)/SUM(F11:F22),"")
...

Sheet General Productos No. 1 Plana
A1: Año | B1: Mes | C1: # días | D1: TPD | E1: HORA 01 | F1: HORA 02 | G1: HORA 03 | H1: HORA 04 | I1: HORA 05 | J1: HORA 06 | K1: HORA 07 | L1: HORA 08 | M1: HORA 09 | N1: HORA 10 | O1: HORA 11 | P1: HORA 12 | Q1: HORA 13 | R1: HORA 14 | S1: HORA 15 | T1: HORA 16 | U1: HORA 17 | V1: HORA 18 | W1: HORA 19 | X1: HORA 20 | Y1: HORA 21 | Z1: HORA 22 | AA1: HORA 23 | AB1: HORA 24 | AC1: kWh/d | AD1: kWh/mes (plano)
A2: 2026 | B2: 1 | C2: 6 | D2: Festivo | E2: 13600 | F2: 13600 | G2: 13600 | H2: 13600 | I2: 13600 | J2: 13600 | K2: 13600 | L2: 13600 | M2: 13600 | N2: 13600 | O2: 13600 | P2: 13600 | Q2: 13600 | R2: 13600 | S2: 13600 | T2: 13600 | U2: 13600 | V2: 13600 | W2: 13600 | X2: 13600 | Y2: 13600 | Z2: 13600 | AA2: 13600 | AB2: 13600 | AC2: =SUM(E2:AB2) -> 326400 | AD2: =+SUMPRODUCT(AC2:AC4,C2:C4) -> 10118400 | AE2: =+SUM(AD2:AD37) -> 92016000
A3: 2026 | B3: 1 | C3: 20 | D3: Ordinario | E3: 13600 | F3: 13600 | G3: 13600 | H3: 13600 | I3: 13600 | J3: 13600 | K3: 13600 | L3: 13600 | M3: 13600 | N3: 13600 | O3: 13600 | P3: 13600 | Q3: 13600 | R3: 13600 | S3: 13600 | T3: 13600 | U3: 13600 | V3: 13600 | W3: 13600 | X3: 13600 | Y3: 13600 | Z3: 13600 | AA3: 13600 | AB3: 13600 | AC3: =SUM(E3:AB3) -> 326400
A4: 2026 | B4: 1 | C4: 5 | D4: Sábado | E4: 13600 | F4: 13600 | G4: 13600 | H4: 13600 | I4: 13600 | J4: 13600 | K4: 13600 | L4: 13600 | M4: 13600 | N4: 13600 | O4: 13600 | P4: 13600 | Q4: 13600 | R4: 13600 | S4: 13600 | T4: 13600 | U4: 13600 | V4: 13600 | W4: 13600 | X4: 13600 | Y4: 13600 | Z4: 13600 | AA4: 13600 | AB4: 13600 | AC4: =SUM(E4:AB4) -> 326400
A5: 2026 | B5: 2 | C5: 4 | D5: Festivo | E5: 15500 | F5: 15500 | G5: 15500 | H5: 15500 | I5: 15500 | J5: 15500 | K5: 15500 | L5: 15500 | M5: 15500 | N5: 15500 | O5: 15500 | P5: 15500 | Q5: 15500 | R5: 15500 | S5: 15500 | T5: 15500 | U5: 15500 | V5: 15500 | W5: 15500 | X5: 15500 | Y5: 15500 | Z5: 15500 | AA5: 15500 | AB5: 15500 | AC5: =SUM(E5:AB5) -> 372000 | AD5: =+SUMPRODUCT(AC5:AC7,C5:C7) -> 10416000
A6: 2026 | B6: 2 | C6: 20 | D6: Ordinario | E6: 15500 | F6: 15500 | G6: 15500 | H6: 15500 | I6: 15500 | J6: 15500 | K6: 15500 | L6: 15500 | M6: 15500 | N6: 15500 | O6: 15500 | P6: 15500 | Q6: 15500 | R6: 15500 | S6: 15500 | T6: 15500 | U6: 15500 | V6: 15500 | W6: 15500 | X6: 15500 | Y6: 15500 | Z6: 15500 | AA6: 15500 | AB6: 15500 | AC6: =SUM(E6:AB6) -> 372000
A7: 2026 | B7: 2 | C7: 4 | D7: Sábado | E7: 15500 | F7: 15500 | G7: 15500 | H7: 15500 | I7: 15500 | J7: 15500 | K7: 15500 | L7: 15500 | M7: 15500 | N7: 15500 | O7: 15500 | P7: 15500 | Q7: 15500 | R7: 15500 | S7: 15500 | T7: 15500 | U7: 15500 | V7: 15500 | W7: 15500 | X7: 15500 | Y7: 15500 | Z7: 15500 | AA7: 15500 | AB7: 15500 | AC7: =SUM(E7:AB7) -> 372000
A8: 2026 | B8: 3 | C8: 6 | D8: Festivo | E8: 16900 | F8: 16900 | G8: 16900 | H8: 16900 | I8: 16900 | J8: 16900 | K8: 16900 | L8: 16900 | M8: 16900 | N8: 16900 | O8: 16900 | P8: 16900 | Q8: 16900 | R8: 16900 | S8: 16900 | T8: 16900 | U8: 16900 | V8: 16900 | W8: 16900 | X8: 16900 | Y8: 16900 | Z8: 16900 | AA8: 16900 | AB8: 16900 | AC8: =SUM(E8:AB8) -> 405600 | AD8: =+SUMPRODUCT(AC8:AC10,C8:C10) -> 12573600
A9: 2026 | B9: 3 | C9: 21 | D9: Ordinario | E9: 16900 | F9: 16900 | G9: 16900 | H9: 16900 | I9: 16900 | J9: 16900 | K9: 16900 | L9: 16900 | M9: 16900 | N9: 16900 | O9: 16900 | P9: 16900 | Q9: 16900 | R9: 16900 | S9: 16900 | T9: 16900 | U9: 16900 | V9: 16900 | W9: 16900 | X9: 16900 | Y9: 16900 | Z9: 16900 | AA9: 16900 | AB9: 16900 | AC9: =SUM(E9:AB9) -> 405600
A10: 2026 | B10: 3 | C10: 4 | D10: Sábado | E10: 16900 | F10: 16900 | G10: 16900 | H10: 16900 | I10: 16900 | J10: 16900 | K10: 16900 | L10: 16900 | M10: 16900 | N10: 16900 | O10: 16900 | P10: 16900 | Q10: 16900 | R10: 16900 | S10: 16900 | T10: 16900 | U10: 16900 | V10: 16900 | W10: 16900 | X10: 16900 | Y10: 16900 | Z10: 16900 | AA10: 16900 | AB10: 16900 | AC10: =SUM(E10:AB10) -> 405600
A11: 2026 | B11: 4 | C11: 6 | D11: Festivo | E11: 12000 | F11: 12000 | G11: 12000 | H11: 12000 | I11: 12000 | J11: 12000 | K11: 12000 | L11: 12000 | M11: 12000 | N11: 12000 | O11: 12000 | P11: 12000 | Q11: 12000 | R11: 12000 | S11: 12000 | T11: 12000 | U11: 12000 | V11: 12000 | W11: 12000 | X11: 12000 | Y11: 12000 | Z11: 12000 | AA11: 12000 | AB11: 12000 | AC11: =SUM(E11:AB11) -> 288000 | AD11: =+SUMPRODUCT(AC11:AC13,C11:C13) -> 8640000
A12: 2026 | B12: 4 | C12: 20 | D12: Ordinario | E12: 12000 | F12: 12000 | G12: 12000 | H12: 12000 | I12: 12000 | J12: 12000 | K12: 12000 | L12: 12000 | M12: 12000 | N12: 12000 | O12: 12000 | P12: 12000 | Q12: 12000 | R12: 12000 | S12: 12000 | T12: 12000 | U12: 12000 | V12: 12000 | W12: 12000 | X12: 12000 | Y12: 12000 | Z12: 12000 | AA12: 12000 | AB12: 12000 | AC12: =SUM(E12:AB12) -> 288000
A13: 2026 | B13: 4 | C13: 4 | D13: Sábado | E13: 12000 | F13: 12000 | G13: 12000 | H13: 12000 | I13: 12000 | J13: 12000 | K13: 12000 | L13: 12000 | M13: 12000 | N13: 12000 | O13: 12000 | P13: 12000 | Q13: 12000 | R13: 12000 | S13: 12000 | T13: 12000 | U13: 12000 | V13: 12000 | W13: 12000 | X13: 12000 | Y13: 12000 | Z13: 12000 | AA13: 12000 | AB13: 12000 | AC13: =SUM(E13:AB13) -> 288000
A14: 2026 | B14: 5 | C14: 7 | D14: Festivo | E14: 13000 | F14: 13000 | G14: 13000 | H14: 13000 | I14: 13000 | J14: 13000 | K14: 13000 | L14: 13000 | M14: 13000 | N14: 13000 | O14: 13000 | P14: 13000 | Q14: 13000 | R14: 13000 | S14: 13000 | T14: 13000 | U14: 13000 | V14: 13000 | W14: 13000 | X14: 13000 | Y14: 13000 | Z14: 13000 | AA14: 13000 | AB14: 13000 | AC14: =SUM(E14:AB14) -> 312000 | AD14: =+SUMPRODUCT(AC14:AC16,C14:C16) -> 9672000
A15: 2026 | B15: 5 | C15: 19 | D15: Ordinario | E15: 13000 | F15: 13000 | G15: 13000 | H15: 13000 | I15: 13000 | J15: 13000 | K15: 13000 | L15: 13000 | M15: 13000 | N15: 13000 | O15: 13000 | P15: 13000 | Q15: 13000 | R15: 13000 | S15: 13000 | T15: 13000 | U15: 13000 | V15: 13000 | W15: 13000 | X15: 13000 | Y15: 13000 | Z15: 13000 | AA15: 13000 | AB15: 13000 | AC15: =SUM(E15:AB15) -> 312000
A16: 2026 | B16: 5 | C16: 5 | D16: Sábado | E16: 13000 | F16: 13000 | G16: 13000 | H16: 13000 | I16: 13000 | J16: 13000 | K16: 13000 | L16: 13000 | M16: 13000 | N16: 13000 | O16: 13000 | P16: 13000 | Q16: 13000 | R16: 13000 | S16: 13000 | T16: 13000 | U16: 13000 | V16: 13000 | W16: 13000 | X16: 13000 | Y16: 13000 | Z16: 13000 | AA16: 13000 | AB16: 13000 | AC16: =SUM(E16:AB16) -> 312000
A17: 2026 | B17: 6 | C17: 7 | D17: Festivo | E17: 8500 | F17: 8500 | G17: 8500 | H17: 8500 | I17: 8500 | J17: 8500 | K17: 8500 | L17: 8500 | M17: 8500 | N17: 8500 | O17: 8500 | P17: 8500 | Q17: 8500 | R17: 8500 | S17: 8500 | T17: 8500 | U17: 8500 | V17: 8500 | W17: 8500 | X17: 8500 | Y17: 8500 | Z17: 8500 | AA17: 8500 | AB17: 8500 | AC17: =SUM(E17:AB17) -> 204000 | AD17: =+SUMPRODUCT(AC17:AC19,C17:C19) -> 6120000
A18: 2026 | B18: 6 | C18: 19 | D18: Ordinario | E18: 8500 | F18: 8500 | G18: 8500 | H18: 8500 | I18: 8500 | J18: 8500 | K18: 8500 | L18: 8500 | M18: 8500 | N18: 8500 | O18: 8500 | P18: 8500 | Q18: 8500 | R18: 8500 | S18: 8500 | T18: 8500 | U18: 8500 | V18: 8500 | W18: 8500 | X18: 8500 | Y18: 8500 | Z18: 8500 | AA18: 8500 | AB18: 8500 | AC18: =SUM(E18:AB18) -> 204000
A19: 2026 | B19: 6 | C19: 4 | D19: Sábado | E19: 8500 | F19: 8500 | G19: 8500 | H19: 8500 | I19: 8500 | J19: 8500 | K19: 8500 | L19: 8500 | M19: 8500 | N19: 8500 | O19: 8500 | P19: 8500 | Q19: 8500 | R19: 8500 | S19: 8500 | T19: 8500 | U19: 8500 | V19: 8500 | W19: 8500 | X19: 8500 | Y19: 8500 | Z19: 8500 | AA19: 8500 | AB19: 8500 | AC19: =SUM(E19:AB19) -> 204000
A20: 2026 | B20: 7 | C20: 5 | D20: Festivo | E20: 16000 | F20: 16000 | G20: 16000 | H20: 16000 | I20: 16000 | J20: 16000 | K20: 16000 | L20: 16000 | M20: 16000 | N20: 16000 | O20: 16000 | P20: 16000 | Q20: 16000 | R20: 16000 | S20: 16000 | T20: 16000 | U20: 16000 | V20: 16000 | W20: 16000 | X20: 16000 | Y20: 16000 | Z20: 16000 | AA20: 16000 | AB20: 16000 | AC20: =SUM(E20:AB20) -> 384000 | AD20: =+SUMPRODUCT(AC20:AC22,C20:C22) -> 11904000
A21: 2026 | B21: 7 | C21: 22 | D21: Ordinario | E21: 16000 | F21: 16000 | G21: 16000 | H21: 16000 | I21: 16000 | J21: 16000 | K21: 16000 | L21: 16000 | M21: 16000 | N21: 16000 | O21: 16000 | P21: 16000 | Q21: 16000 | R21: 16000 | S21: 16000 | T21: 16000 | U21: 16000 | V21: 16000 | W21: 16000 | X21: 16000 | Y21: 16000 | Z21: 16000 | AA21: 16000 | AB21: 16000 | AC21: =SUM(E21:AB21) -> 384000
A22: 2026 | B22: 7 | C22: 4 | D22: Sábado | E22: 16000 | F22: 16000 | G22: 16000 | H22: 16000 | I22: 16000 | J22: 16000 | K22: 16000 | L22: 16000 | M22: 16000 | N22: 16000 | O22: 16000 | P22: 16000 | Q22: 16000 | R22: 16000 | S22: 16000 | T22: 16000 | U22: 16000 | V22: 16000 | W22: 16000 | X22: 16000 | Y22: 16000 | Z22: 16000 | AA22: 16000 | AB22: 16000 | AC22: =SUM(E22:AB22) -> 384000
A23: 2026 | B23: 8 | C23: 7 | D23: Festivo | E23: 13000 | F23: 13000 | G23: 13000 | H23: 13000 | I23: 13000 | J23: 13000 | K23: 13000 | L23: 13000 | M23: 13000 | N23: 13000 | O23: 13000 | P23: 13000 | Q23: 13000 | R23: 13000 | S23: 13000 | T23: 13000 | U23: 13000 | V23: 13000 | W23: 13000 | X23: 13000 | Y23: 13000 | Z23: 13000 | AA23: 13000 | AB23: 13000 | AC23: =SUM(E23:AB23) -> 312000 | AD23: =+SUMPRODUCT(AC23:AC25,C23:C25) -> 9672000
A24: 2026 | B24: 8 | C24: 19 | D24: Ordinario | E24: 13000 | F24: 13000 | G24: 13000 | H24: 13000 | I24: 13000 | J24: 13000 | K24: 13000 | L24: 13000 | M24: 13000 | N24: 13000 | O24: 13000 | P24: 13000 | Q24: 13000 | R24: 13000 | S24: 13000 | T24: 13000 | U24: 13000 | V24: 13000 | W24: 13000 | X24: 13000 | Y24: 13000 | Z24: 13000 | AA24: 13000 | AB24: 13000 | AC24: =SUM(E24:AB24) -> 312000
A25: 2026 | B25: 8 | C25: 5 | D25: Sábado | E25: 13000 | F25: 13000 | G25: 13000 | H25: 13000 | I25: 13000 | J25: 13000 | K25: 13000 | L25: 13000 | M25: 13000 | N25: 13000 | O25: 13000 | P25: 13000 | Q25: 13000 | R25: 13000 | S25: 13000 | T25: 13000 | U25: 13000 | V25: 13000 | W25: 13000 | X25: 13000 | Y25: 13000 | Z25: 13000 | AA25: 13000 | AB25: 13000 | AC25: =SUM(E25:AB25) -> 312000
A26: 2026 | B26: 9 | C26: 4 | D26: Festivo | E26: 2500 | F26: 2500 | G26: 2500 | H26: 2500 | I26: 2500 | J26: 2500 | K26: 2500 | L26: 2500 | M26: 2500 | N26: 2500 | O26: 2500 | P26: 2500 | Q26: 2500 | R26: 2500 | S26: 2500 | T26: 2500 | U26: 2500 | V26: 2500 | W26: 2500 | X26: 2500 | Y26: 2500 | Z26: 2500 | AA26: 2500 | AB26: 2500 | AC26: =SUM(E26:AB26) -> 60000 | AD26: =+SUMPRODUCT(AC26:AC28,C26:C28) -> 1800000
A27: 2026 | B27: 9 | C27: 22 | D27: Ordinario | E27: 2500 | F27: 2500 | G27: 2500 | H27: 2500 | I27: 2500 | J27: 2500 | K27: 2500 | L27: 2500 | M27: 2500 | N27: 2500 | O27: 2500 | P27: 2500 | Q27: 2500 | R27: 2500 | S27: 2500 | T27: 2500 | U27: 2500 | V27: 2500 | W27: 2500 | X27: 2500 | Y27: 2500 | Z27: 2500 | AA27: 2500 | AB27: 2500 | AC27: =SUM(E27:AB27) -> 60000
A28: 2026 | B28: 9 | C28: 4 | D28: Sábado | E28: 2500 | F28: 2500 | G28: 2500 | H28: 2500 | I28: 2500 | J28: 2500 | K28: 2500 | L28: 2500 | M28: 2500 | N28: 2500 | O28: 2500 | P28: 2500 | Q28: 2500 | R28: 2500 | S28: 2500 | T28: 2500 | U28: 2500 | V28: 2500 | W28: 2500 | X28: 2500 | Y28: 2500 | Z28: 2500 | AA28: 2500 | AB28: 2500 | AC28: =SUM(E28:AB28) -> 60000
A29: 2026 | B29: 10 | C29: 5 | D29: Festivo | E29: 2500 | F29: 2500 | G29: 2500 | H29: 2500 | I29: 2500 | J29: 2500 | K29: 2500 | L29: 2500 | M29: 2500 | N29: 2500 | O29: 2500 | P29: 2500 | Q29: 2500 | R29: 2500 | S29: 2500 | T29: 2500 | U29: 2500 | V29: 2500 | W29: 2500 | X29: 2500 | Y29: 2500 | Z29: 2500 | AA29: 2500 | AB29: 2500 | AC29: =SUM(E29:AB29) -> 60000 | AD29: =+SUMPRODUCT(AC29:AC31,C29:C31) -> 1860000
A30: 2026 | B30: 10 | C30: 21 | D30: Ordinario | E30: 2500 | F30: 2500 | G30: 2500 | H30: 2500 | I30: 2500 | J30: 2500 | K30: 2500 | L30: 2500 | M30: 2500 | N30: 2500 | O30: 2500 | P30: 2500 | Q30: 2500 | R30: 2500 | S30: 2500 | T30: 2500 | U30: 2500 | V30: 2500 | W30: 2500 | X30: 2500 | Y30: 2500 | Z30: 2500 | AA30: 2500 | AB30: 2500 | AC30: =SUM(E30:AB30) -> 60000
A31: 2026 | B31: 10 | C31: 5 | D31: Sábado | E31: 2500 | F31: 2500 | G31: 2500 | H31: 2500 | I31: 2500 | J31: 2500 | K31: 2500 | L31: 2500 | M31: 2500 | N31: 2500 | O31: 2500 | P31: 2500 | Q31: 2500 | R31: 2500 | S31: 2500 | T31: 2500 | U31: 2500 | V31: 2500 | W31: 2500 | X31: 2500 | Y31: 2500 | Z31: 2500 | AA31: 2500 | AB31: 2500 | AC31: =SUM(E31:AB31) -> 60000
A32: 2026 | B32: 11 | C32: 7 | D32: Festivo | E32: 2500 | F32: 2500 | G32: 2500 | H32: 2500 | I32: 2500 | J32: 2500 | K32: 2500 | L32: 2500 | M32: 2500 | N32: 2500 | O32: 2500 | P32: 2500 | Q32: 2500 | R32: 2500 | S32: 2500 | T32: 2500 | U32: 2500 | V32: 2500 | W32: 2500 | X32: 2500 | Y32: 2500 | Z32: 2500 | AA32: 2500 | AB32: 2500 | AC32: =SUM(E32:AB32) -> 60000 | AD32: =+SUMPRODUCT(AC32:AC34,C32:C34) -> 1800000
A33: 2026 | B33: 11 | C33: 19 | D33: Ordinario | E33: 2500 | F33: 2500 | G33: 2500 | H33: 2500 | I33: 2500 | J33: 2500 | K33: 2500 | L33: 2500 | M33: 2500 | N33: 2500 | O33: 2500 | P33: 2500 | Q33: 2500 | R33: 2500 | S33: 2500 | T33: 2500 | U33: 2500 | V33: 2500 | W33: 2500 | X33: 2500 | Y33: 2500 | Z33: 2500 | AA33: 2500 | AB33: 2500 | AC33: =SUM(E33:AB33) -> 60000
A34: 2026 | B34: 11 | C34: 4 | D34: Sábado | E34: 2500 | F34: 2500 | G34: 2500 | H34: 2500 | I34: 2500 | J34: 2500 | K34: 2500 | L34: 2500 | M34: 2500 | N34: 2500 | O34: 2500 | P34: 2500 | Q34: 2500 | R34: 2500 | S34: 2500 | T34: 2500 | U34: 2500 | V34: 2500 | W34: 2500 | X34: 2500 | Y34: 2500 | Z34: 2500 | AA34: 2500 | AB34: 2500 | AC34: =SUM(E34:AB34) -> 60000
A35: 2026 | B35: 12 | C35: 6 | D35: Festivo | E35: 10000 | F35: 10000 | G35: 10000 | H35: 10000 | I35: 10000 | J35: 10000 | K35: 10000 | L35: 10000 | M35: 10000 | N35: 10000 | O35: 10000 | P35: 10000 | Q35: 10000 | R35: 10000 | S35: 10000 | T35: 10000 | U35: 10000 | V35: 10000 | W35: 10000 | X35: 10000 | Y35: 10000 | Z35: 10000 | AA35: 10000 | AB35: 10000 | AC35: =SUM(E35:AB35) -> 240000 | AD35: =+SUMPRODUCT(AC35:AC37,C35:C37) -> 7440000
A36: 2026 | B36: 12 | C36: 21 | D36: Ordinario | E36: 10000 | F36: 10000 | G36: 10000 | H36: 10000 | I36: 10000 | J36: 10000 | K36: 10000 | L36: 10000 | M36: 10000 | N36: 10000 | O36: 10000 | P36: 10000 | Q36: 10000 | R36: 10000 | S36: 10000 | T36: 10000 | U36: 10000 | V36: 10000 | W36: 10000 | X36: 10000 | Y36: 10000 | Z36: 10000 | AA36: 10000 | AB36: 10000 | AC36: =SUM(E36:AB36) -> 240000
A37: 2026 | B37: 12 | C37: 4 | D37: Sábado | E37: 10000 | F37: 10000 | G37: 10000 | H37: 10000 | I37: 10000 | J37: 10000 | K37: 10000 | L37: 10000 | M37: 10000 | N37: 10000 | O37: 10000 | P37: 10000 | Q37: 10000 | R37: 10000 | S37: 10000 | T37: 10000 | U37: 10000 | V37: 10000 | W37: 10000 | X37: 10000 | Y37: 10000 | Z37: 10000 | AA37: 10000 | AB37: 10000 | AC37: =SUM(E37:AB37) -> 240000
A38: 2027 | B38: 1 | C38: 7 | D38: Festivo | E38: 18000 | F38: 18000 | G38: 18000 | H38: 18000 | I38: 18000 | J38: 18000 | K38: 18000 | L38: 18000 | M38: 18000 | N38: 18000 | O38: 18000 | P38: 18000 | Q38: 18000 | R38: 18000 | S38: 18000 | T38: 18000 | U38: 18000 | V38: 18000 | W38: 18000 | X38: 18000 | Y38: 18000 | Z38: 18000 | AA38: 18000 | AB38: 18000 | AC38: =SUM(E38:AB38) -> 432000 | AD38: =+SUMPRODUCT(AC38:AC40,C38:C40) -> 13392000 | AE38: =+SUM(AD38:AD73) -> 93072000
A39: 2027 | B39: 1 | C39: 19 | D39: Ordinario | E39: 18000 | F39: 18000 | G39: 18000 | H39: 18000 | I39: 18000 | J39: 18000 | K39: 18000 | L39: 18000 | M39: 18000 | N39: 18000 | O39: 18000 | P39: 18000 | Q39: 18000 | R39: 18000 | S39: 18000 | T39: 18000 | U39: 18000 | V39: 18000 | W39: 18000 | X39: 18000 | Y39: 18000 | Z39: 18000 | AA39: 18000 | AB39: 18000 | AC39: =SUM(E39:AB39) -> 432000
A40: 2027 | B40: 1 | C40: 5 | D40: Sábado | E40: 18000 | F40: 18000 | G40: 18000 | H40: 18000 | I40: 18000 | J40: 18000 | K40: 18000 | L40: 18000 | M40: 18000 | N40: 18000 | O40: 18000 | P40: 18000 | Q40: 18000 | R40: 18000 | S40: 18000 | T40: 18000 | U40: 18000 | V40: 18000 | W40: 18000 | X40: 18000 | Y40: 18000 | Z40: 18000 | AA40: 18000 | AB40: 18000 | AC40: =SUM(E40:AB40) -> 432000
...

Sheet Producto No. 2 Curva
A5: ANEXO No. 1. Oferta Producto No. 2 Curva Plana Convocatoria Pública DISPAC S.A. E.S.P.
A8: PROPONENTE
A10: MES | B10: DEMANDA REQUERIDA DISPAC KWh | C10: DEMANDA PERIODO REQUERIDA DISPAC KWh | D10: PORCENTAJE (%) OFERTADO DE LA DEMANDA REQUERIDA | E10: DEMANDA OFERTADA KWh - MES | F10: DEMANDA PERIODO OFERTADA KWh | G10: PRECIO OFERTADO $ kWh (0.00)
A11: 46023 | B11: =+'Producto No. 2 (Curva)'!AD2 -> 3731047 | C11: =SUM(B11:B22) -> 63783813 | D11: 0 | E11: =+B11*D11 -> 0 | F11: =SUM(E11:E22) -> 0
A12: 46054 | B12: =+'Producto No. 2 (Curva)'!AD5 -> 3372840 | D12: 0 | E12: =+B12*D12 -> 0
A13: 46082 | B13: =+'Producto No. 2 (Curva)'!AD8 -> 4477313 | D13: 0 | E13: 0
A14: 46113 | B14: =+'Producto No. 2 (Curva)'!AD11 -> 7876062 | D14: 0 | E14: =+B14*D14 -> 0
A15: 46143 | B15: =+'Producto No. 2 (Curva)'!AD14 -> 6714696 | D15: 0 | E15: =+B15*D15 -> 0
A16: 46174 | B16: =+'Producto No. 2 (Curva)'!AD17 -> 9456276 | D16: 0 | E16: =+B16*D16 -> 0
A17: 46204 | B17: =+'Producto No. 2 (Curva)'!AD20 -> 4460345 | D17: 0 | E17: =+B17*D17 -> 0
A18: 46235 | B18: =+'Producto No. 2 (Curva)'!AD23 -> 6255842 | D18: 0 | E18: =+B18*D18 -> 0
A19: 46266 | B19: =+'Producto No. 2 (Curva)'!AD26 -> 2553138 | D19: 0 | E19: =+B19*D19 -> 0
A20: 46296 | B20: =+'Producto No. 2 (Curva)'!AD29 -> 2398451 | D20: 0 | E20: =+B20*D20 -> 0
A21: 46327 | B21: =+'Producto No. 2 (Curva)'!AD32 -> 2758031 | D21: 0 | E21: =+B21*D21 -> 0
A22: 46357 | B22: =+'Producto No. 2 (Curva)'!AD35 -> 9729772 | D22: 0 | E22: =+B22*D22 -> 0
A23: 46388 | B23: =+'Producto No. 2 (Curva)'!AD38 -> 3913842 | C23: =SUM(B23:B34) -> 67871522 | D23: 0 | E23: =+B23*D23 -> 0 | F23: =SUM(E23:E34) -> 0
A24: 46419 | B24: =+'Producto No. 2 (Curva)'!AD41 -> 3319492 | D24: 0 | E24: =+B24*D24 -> 0
A25: 46447 | B25: =+'Producto No. 2 (Curva)'!AD44 -> 10019614 | D25: 0 | E25: =+B25*D25 -> 0
A26: 46478 | B26: =+'Producto No. 2 (Curva)'!AD47 -> 4096284 | D26: 0 | E26: =+B26*D26 -> 0
A27: 46508 | B27: =+'Producto No. 2 (Curva)'!AD50 -> 9564657 | D27: 0 | E27: =+B27*D27 -> 0
A28: 46539 | B28: =+'Producto No. 2 (Curva)'!AD53 -> 4633932 | D28: 0 | E28: =+B28*D28 -> 0
A29: 46569 | B29: =+'Producto No. 2 (Curva)'!AD56 -> 7973639 | D29: 0 | E29: =+B29*D29 -> 0
A30: 46600 | B30: =+'Producto No. 2 (Curva)'!AD59 -> 6832722 | D30: 0 | E30: =+B30*D30 -> 0
A31: 46631 | B31: =+'Producto No. 2 (Curva)'!AD62 -> 2528108 | D31: 0 | E31: =+B31*D31 -> 0
A32: 46661 | B32: =+'Producto No. 2 (Curva)'!AD65 -> 2320125 | D32: 0 | E32: =+B32*D32 -> 0
A33: 46692 | B33: =+'Producto No. 2 (Curva)'!AD68 -> 2665816 | D33: 0 | E33: =+B33*D33 -> 0
A34: 46722 | B34: =+'Producto No. 2 (Curva)'!AD71 -> 10003291 | D34: 0 | E34: =+B34*D34 -> 0
A35: 46753 | B35: =+'Producto No. 2 (Curva)'!AD74 -> 3774561 | C35: =SUM(B35:B46) -> 63351821 | D35: 0 | E35: =+B35*D35 -> 0 | F35: =SUM(E35:E46) -> 0
A36: 46784 | B36: =+'Producto No. 2 (Curva)'!AD77 -> 3526018 | D36: 0 | E36: =+B36*D36 -> 0
A37: 46813 | B37: =+'Producto No. 2 (Curva)'!AD80 -> 4012629 | D37: 0 | E37: =+B37*D37 -> 0
A38: 46844 | B38: =+'Producto No. 2 (Curva)'!AD83 -> 7226259 | D38: 0 | E38: =+B38*D38 -> 0
A39: 46874 | B39: =+'Producto No. 2 (Curva)'!AD86 -> 5462581 | D39: 0 | E39: =+B39*D39 -> 0
A40: 46905 | B40: =+'Producto No. 2 (Curva)'!AD89 -> 4678440 | D40: 0 | E40: =+B40*D40 -> 0
A41: 46935 | B41: =+'Producto No. 2 (Curva)'!AD92 -> 4746122 | D41: 0 | E41: =+B41*D41 -> 0
A42: 46966 | B42: =+'Producto No. 2 (Curva)'!AD95 -> 6365062 | D42: 0 | E42: =+B42*D42 -> 0
A43: 46997 | B43: =+'Producto No. 2 (Curva)'!AD98 -> 4241430 | D43: 0 | E43: =+B43*D43 -> 0
A44: 47027 | B44: =+'Producto No. 2 (Curva)'!AD101 -> 4590692 | D44: 0 | E44: =+B44*D44 -> 0
A45: 47058 | B45: =+'Producto No. 2 (Curva)'!AD104 -> 6281282 | D45: 0 | E45: =+B45*D45 -> 0
A46: 47088 | B46: =+'Producto No. 2 (Curva)'!AD107 -> 8446745 | D46: 0 | E46: =+B46*D46 -> 0
A47: TOTALES | B47: =SUM(B11:B46) -> 195007156 | C47: =SUM(C11:C46) -> 195007156 | E47: =SUM(E11:E22) -> 0 | F47: =SUM(F11:F22) -> 0 | G47: =IFERROR(SUMPRODUCT(F11:F22,G11:G22)/SUM(F11:F22),"")
...

Sheet Producto No. 2 (Curva)
A1: Año | B1: Mes | C1: # días | D1: TPD | E1: HORA 01 | F1: HORA 02 | G1: HORA 03 | H1: HORA 04 | I1: HORA 05 | J1: HORA 06 | K1: HORA 07 | L1: HORA 08 | M1: HORA 09 | N1: HORA 10 | O1: HORA 11 | P1: HORA 12 | Q1: HORA 13 | R1: HORA 14 | S1: HORA 15 | T1: HORA 16 | U1: HORA 17 | V1: HORA 18 | W1: HORA 19 | X1: HORA 20 | Y1: HORA 21 | Z1: HORA 22 | AA1: HORA 23 | AB1: HORA 24 | AC1: kWh/d | AD1: kWh/mes
A2: 2026 | B2: 1 | C2: 6 | D2: Festivo | E2: =VLOOKUP(E$1,'[1]Demanda requerida 2026'!$CB$74:$DL$97,MATCH(_xlfn.CONCAT(TEXT(DATE($A2,$B2,1),"mmm-yy"),$D2),'[1]Demanda requerida 2026'!$CB$39:$DL$39,0),FALSE) -> 359 | F2: =VLOOKUP(F$1,'[1]Demanda requerida 2026'!$CB$74:$DL$97,MATCH(_xlfn.CONCAT(TEXT(DATE($A2,$B2,1),"mmm-yy"),$D2),'[1]Demanda requerida 2026'!$CB$39:$DL$39,0),FALSE) -> 200 | G2: =VLOOKUP(G$1,'[1]Demanda requerida 2026'!$CB$74:$DL$97,MATCH(_xlfn.CONCAT(TEXT(DATE($A2,$B2,1),"mmm-yy"),$D2),'[1]Demanda requerida 2026'!$CB$39:$DL$39,0),FALSE) -> 200 | H2: =VLOOKUP(H$1,'[1]Demanda requerida 2026'!$CB$74:$DL$97,MATCH(_xlfn.CONCAT(TEXT(DATE($A2,$B2,1),"mmm-yy"),$D2),'[1]Demanda requerida 2026'!$CB$39:$DL$39,0),FALSE) -> 200 | I2: =VLOOKUP(I$1,'[1]Demanda requerida 2026'!$CB$74:$DL$97,MATCH(_xlfn.CONCAT(TEXT(DATE($A2,$B2,1),"mmm-yy"),$D2),'[1]Demanda requerida 2026'!$CB$39:$DL$39,0),FALSE) -> 200 | J2: =VLOOKUP(J$1,'[1]Demanda requerida 2026'!$CB$74:$DL$97,MATCH(_xlfn.CONCAT(TEXT(DATE($A2,$B2,1),"mmm-yy"),$D2),'[1]Demanda requerida 2026'!$CB$39:$DL$39,0),FALSE) -> 200 | K2: =VLOOKUP(K$1,'[1]Demanda requerida 2026'!$CB$74:$DL$97,MATCH(_xlfn.CONCAT(TEXT(DATE($A2,$B2,1),"mmm-yy"),$D2),'[1]Demanda requerida 2026'!$CB$39:$DL$39,0),FALSE) -> 200 | L2: =VLOOKUP(L$1,'[1]Demanda requerida 2026'!$CB$74:$DL$97,MATCH(_xlfn.CONCAT(TEXT(DATE($A2,$B2,1),"mmm-yy"),$D2),'[1]Demanda requerida 2026'!$CB$39:$DL$39,0),FALSE) -> 200 | ... AB2: =VLOOKUP(AB$1,'[1]Demanda requerida 2026'!$CB$74:$DL$97,MATCH(_xlfn.CONCAT(TEXT(DATE($A2,$B2,1),"mmm-yy"),$D2),'[1]Demanda requerida 2026'!$CB$39:$DL$39,0),FALSE) -> 2077 | AC2: =SUM(E2:AB2) -> 75547 | AD2: =+SUMPRODUCT(AC2:AC4,C2:C4) -> 3731047 | AE2: =+SUM(AD2:AD37) -> 63783813
A3: 2026 | B3: 1 | C3: 20 | D3: Ordinario | E3: =VLOOKUP(E$1,'[1]Demanda requerida 2026'!$CB$74:$DL$97,MATCH(_xlfn.CONCAT(TEXT(DATE($A3,$B3,1),"mmm-yy"),$D3),'[1]Demanda requerida 2026'!$CB$39:$DL$39,0),FALSE) -> 370 | F3: =VLOOKUP(F$1,'[1]Demanda requerida 2026'!$CB$74:$DL$97,MATCH(_xlfn.CONCAT(TEXT(DATE($A3,$B3,1),"mmm-yy"),$D3),'[1]Demanda requerida 2026'!$CB$39:$DL$39,0),FALSE) -> 200 | G3: =VLOOKUP(G$1,'[1]Demanda requerida 2026'!$CB$74:$DL$97,MATCH(_xlfn.CONCAT(TEXT(DATE($A3,$B3,1),"mmm-yy"),$D3),'[1]Demanda requerida 2026'!$CB$39:$DL$39,0),FALSE) -> 200 | H3: =VLOOKUP(H$1,'[1]Demanda requerida 2026'!$CB$74:$DL$97,MATCH(_xlfn.CONCAT(TEXT(DATE($A3,$B3,1),"mmm-yy"),$D3),'[1]Demanda requerida 2026'!$CB$39:$DL$39,0),FALSE) -> 200 | I3: =VLOOKUP(I$1,'[1]Demanda requerida 2026'!$CB$74:$DL$97,MATCH(_xlfn.CONCAT(TEXT(DATE($A3,$B3,1),"mmm-yy"),$D3),'[1]Demanda requerida 2026'!$CB$39:$DL$39,0),FALSE) -> 200 | J3: =VLOOKUP(J$1,'[1]Demanda requerida 2026'!$CB$74:$DL$97,MATCH(_xlfn.CONCAT(TEXT(DATE($A3,$B3,1),"mmm-yy"),$D3),'[1]Demanda requerida 2026'!$CB$39:$DL$39,0),FALSE) -> 200 | K3: =VLOOKUP(K$1,'[1]Demanda requerida 2026'!$CB$74:$DL$97,MATCH(_xlfn.CONCAT(TEXT(DATE($A3,$B3,1),"mmm-yy"),$D3),'[1]Demanda requerida 2026'!$CB$39:$DL$39,0),FALSE) -> 200 | L3: =VLOOKUP(L$1,'[1]Demanda requerida 2026'!$CB$74:$DL$97,MATCH(_xlfn.CONCAT(TEXT(DATE($A3,$B3,1),"mmm-yy"),$D3),'[1]Demanda requerida 2026'!$CB$39:$DL$39,0),FALSE) -> 1129 | ... AB3: =VLOOKUP(AB$1,'[1]Demanda requerida 2026'!$CB$74:$DL$97,MATCH(_xlfn.CONCAT(TEXT(DATE($A3,$B3,1),"mmm-yy"),$D3),'[1]Demanda requerida 2026'!$CB$39:$DL$39,0),FALSE) -> 3695 | AC3: =SUM(E3:AB3) -> 132574
A4: 2026 | B4: 1 | C4: 5 | D4: Sábado | E4: =VLOOKUP(E$1,'[1]Demanda requerida 2026'!$CB$74:$DL$97,MATCH(_xlfn.CONCAT(TEXT(DATE($A4,$B4,1),"mmm-yy"),$D4),'[1]Demanda requerida 2026'!$CB$39:$DL$39,0),FALSE) -> 320 | F4: =VLOOKUP(F$1,'[1]Demanda requerida 2026'!$CB$74:$DL$97,MATCH(_xlfn.CONCAT(TEXT(DATE($A4,$B4,1),"mmm-yy"),$D4),'[1]Demanda requerida 2026'!$CB$39:$DL$39,0),FALSE) -> 200 | G4: =VLOOKUP(G$1,'[1]Demanda requerida 2026'!$CB$74:$DL$97,MATCH(_xlfn.CONCAT(TEXT(DATE($A4,$B4,1),"mmm-yy"),$D4),'[1]Demanda requerida 2026'!$CB$39:$DL$39,0),FALSE) -> 200 | H4: =VLOOKUP(H$1,'[1]Demanda requerida 2026'!$CB$74:$DL$97,MATCH(_xlfn.CONCAT(TEXT(DATE($A4,$B4,1),"mmm-yy"),$D4),'[1]Demanda requerida 2026'!$CB$39:$DL$39,0),FALSE) -> 200 | I4: =VLOOKUP(I$1,'[1]Demanda requerida 2026'!$CB$74:$DL$97,MATCH(_xlfn.CONCAT(TEXT(DATE($A4,$B4,1),"mmm-yy"),$D4),'[1]Demanda requerida 2026'!$CB$39:$DL$39,0),FALSE) -> 200 | J4: =VLOOKUP(J$1,'[1]Demanda requerida 2026'!$CB$74:$DL$97,MATCH(_xlfn.CONCAT(TEXT(DATE($A4,$B4,1),"mmm-yy"),$D4),'[1]Demanda requerida 2026'!$CB$39:$DL$39,0),FALSE) -> 200 | K4: =VLOOKUP(K$1,'[1]Demanda requerida 2026'!$CB$74:$DL$97,MATCH(_xlfn.CONCAT(TEXT(DATE($A4,$B4,1),"mmm-yy"),$D4),'[1]Demanda requerida 2026'!$CB$39:$DL$39,0),FALSE) -> 200 | L4: =VLOOKUP(L$1,'[1]Demanda requerida 2026'!$CB$74:$DL$97,MATCH(_xlfn.CONCAT(TEXT(DATE($A4,$B4,1),"mmm-yy"),$D4),'[1]Demanda requerida 2026'!$CB$39:$DL$39,0),FALSE) -> 293 | ... AB4: =VLOOKUP(AB$1,'[1]Demanda requerida 2026'!$CB$74:$DL$97,MATCH(_xlfn.CONCAT(TEXT(DATE($A4,$B4,1),"mmm-yy"),$D4),'[1]Demanda requerida 2026'!$CB$39:$DL$39,0),FALSE) -> 3943 | AC4: =SUM(E4:AB4) -> 125257
A5: 2026 | B5: 2 | C5: 4 | D5: Festivo | E5: =VLOOKUP(E$1,'[1]Demanda requerida 2026'!$CB$74:$DL$97,MATCH(_xlfn.CONCAT(TEXT(DATE($A5,$B5,1),"mmm-yy"),$D5),'[1]Demanda requerida 2026'!$CB$39:$DL$39,0),FALSE) -> 363 | F5: =VLOOKUP(F$1,'[1]Demanda requerida 2026'!$CB$74:$DL$97,MATCH(_xlfn.CONCAT(TEXT(DATE($A5,$B5,1),"mmm-yy"),$D5),'[1]Demanda requerida 2026'!$CB$39:$DL$39,0),FALSE) -> 200 | G5: =VLOOKUP(G$1,'[1]Demanda requerida 2026'!$CB$74:$DL$97,MATCH(_xlfn.CONCAT(TEXT(DATE($A5,$B5,1),"mmm-yy"),$D5),'[1]Demanda requerida 2026'!$CB$39:$DL$39,0),FALSE) -> 200 | H5: =VLOOKUP(H$1,'[1]Demanda requerida 2026'!$CB$74:$DL$97,MATCH(_xlfn.CONCAT(TEXT(DATE($A5,$B5,1),"mmm-yy"),$D5),'[1]Demanda requerida 2026'!$CB$39:$DL$39,0),FALSE) -> 200 | I5: =VLOOKUP(I$1,'[1]Demanda requerida 2026'!$CB$74:$DL$97,MATCH(_xlfn.CONCAT(TEXT(DATE($A5,$B5,1),"mmm-yy"),$D5),'[1]Demanda requerida 2026'!$CB$39:$DL$39,0),FALSE) -> 200 | J5: =VLOOKUP(J$1,'[1]Demanda requerida 2026'!$CB$74:$DL$97,MATCH(_xlfn.CONCAT(TEXT(DATE($A5,$B5,1),"mmm-yy"),$D5),'[1]Demanda requerida 2026'!$CB$39:$DL$39,0),FALSE) -> 200 | K5: =VLOOKUP(K$1,'[1]Demanda requerida 2026'!$CB$74:$DL$97,MATCH(_xlfn.CONCAT(TEXT(DATE($A5,$B5,1),"mmm-yy"),$D5),'[1]Demanda requerida 2026'!$CB$39:$DL$39,0),FALSE) -> 200 | L5: =VLOOKUP(L$1,'[1]Demanda requerida 2026'!$CB$74:$DL$97,MATCH(_xlfn.CONCAT(TEXT(DATE($A5,$B5,1),"mmm-yy"),$D5),'[1]Demanda requerida 2026'!$CB$39:$DL$39,0),FALSE) -> 200 | ... AB5: =VLOOKUP(AB$1,'[1]Demanda requerida 2026'!$CB$74:$DL$97,MATCH(_xlfn.CONCAT(TEXT(DATE($A5,$B5,1),"mmm-yy"),$D5),'[1]Demanda requerida 2026'!$CB$39:$DL$39,0),FALSE) -> 2335 | AC5: =SUM(E5:AB5) -> 91958 | AD5: =+SUMPRODUCT(AC5:AC7,C5:C7) -> 3372840
A6: 2026 | B6: 2 | C6: 20 | D6: Ordinario | E6: =VLOOKUP(E$1,'[1]Demanda requerida 2026'!$CB$74:$DL$97,MATCH(_xlfn.CONCAT(TEXT(DATE($A6,$B6,1),"mmm-yy"),$D6),'[1]Demanda requerida 2026'!$CB$39:$DL$39,0),FALSE) -> 200 | F6: =VLOOKUP(F$1,'[1]Demanda requerida 2026'!$CB$74:$DL$97,MATCH(_xlfn.CONCAT(TEXT(DATE($A6,$B6,1),"mmm-yy"),$D6),'[1]Demanda requerida 2026'!$CB$39:$DL$39,0),FALSE) -> 200 | G6: =VLOOKUP(G$1,'[1]Demanda requerida 2026'!$CB$74:$DL$97,MATCH(_xlfn.CONCAT(TEXT(DATE($A6,$B6,1),"mmm-yy"),$D6),'[1]Demanda requerida 2026'!$CB$39:$DL$39,0),FALSE) -> 200 | H6: =VLOOKUP(H$1,'[1]Demanda requerida 2026'!$CB$74:$DL$97,MATCH(_xlfn.CONCAT(TEXT(DATE($A6,$B6,1),"mmm-yy"),$D6),'[1]Demanda requerida 2026'!$CB$39:$DL$39,0),FALSE) -> 200 | I6: =VLOOKUP(I$1,'[1]Demanda requerida 2026'!$CB$74:$DL$97,MATCH(_xlfn.CONCAT(TEXT(DATE($A6,$B6,1),"mmm-yy"),$D6),'[1]Demanda requerida 2026'!$CB$39:$DL$39,0),FALSE) -> 200 | J6: =VLOOKUP(J$1,'[1]Demanda requerida 2026'!$CB$74:$DL$97,MATCH(_xlfn.CONCAT(TEXT(DATE($A6,$B6,1),"mmm-yy"),$D6),'[1]Demanda requerida 2026'!$CB$39:$DL$39,0),FALSE) -> 200 | K6: =VLOOKUP(K$1,'[1]Demanda requerida 2026'!$CB$74:$DL$97,MATCH(_xlfn.CONCAT(TEXT(DATE($A6,$B6,1),"mmm-yy"),$D6),'[1]Demanda requerida 2026'!$CB$39:$DL$39,0),FALSE) -> 731 | L6: =VLOOKUP(L$1,'[1]Demanda requerida 2026'!$CB$74:$DL$97,MATCH(_xlfn.CONCAT(TEXT(DATE($A6,$B6,1),"mmm-yy"),$D6),'[1]Demanda requerida 2026'!$CB$39:$DL$39,0),FALSE) -> 1701 | ... AB6: =VLOOKUP(AB$1,'[1]Demanda requerida 2026'!$CB$74:$DL$97,MATCH(_xlfn.CONCAT(TEXT(DATE($A6,$B6,1),"mmm-yy"),$D6),'[1]Demanda requerida 2026'!$CB$39:$DL$39,0),FALSE) -> 2489 | AC6: =SUM(E6:AB6) -> 127959
A7: 2026 | B7: 2 | C7: 4 | D7: Sábado | E7: =VLOOKUP(E$1,'[1]Demanda requerida 2026'!$CB$74:$DL$97,MATCH(_xlfn.CONCAT(TEXT(DATE($A7,$B7,1),"mmm-yy"),$D7),'[1]Demanda requerida 2026'!$CB$39:$DL$39,0),FALSE) -> 200 | F7: =VLOOKUP(F$1,'[1]Demanda requerida 2026'!$CB$74:$DL$97,MATCH(_xlfn.CONCAT(TEXT(DATE($A7,$B7,1),"mmm-yy"),$D7),'[1]Demanda requerida 2026'!$CB$39:$DL$39,0),FALSE) -> 200 | G7: =VLOOKUP(G$1,'[1]Demanda requerida 2026'!$CB$74:$DL$97,MATCH(_xlfn.CONCAT(TEXT(DATE($A7,$B7,1),"mmm-yy"),$D7),'[1]Demanda requerida 2026'!$CB$39:$DL$39,0),FALSE) -> 200 | H7: =VLOOKUP(H$1,'[1]Demanda requerida 2026'!$CB$74:$DL$97,MATCH(_xlfn.CONCAT(TEXT(DATE($A7,$B7,1),"mmm-yy"),$D7),'[1]Demanda requerida 2026'!$CB$39:$DL$39,0),FALSE) -> 200 | I7: =VLOOKUP(I$1,'[1]Demanda requerida 2026'!$CB$74:$DL$97,MATCH(_xlfn.CONCAT(TEXT(DATE($A7,$B7,1),"mmm-yy"),$D7),'[1]Demanda requerida 2026'!$CB$39:$DL$39,0),FALSE) -> 200 | J7: =VLOOKUP(J$1,'[1]Demanda requerida 2026'!$CB$74:$DL$97,MATCH(_xlfn.CONCAT(TEXT(DATE($A7,$B7,1),"mmm-yy"),$D7),'[1]Demanda requerida 2026'!$CB$39:$DL$39,0),FALSE) -> 200 | K7: =VLOOKUP(K$1,'[1]Demanda requerida 2026'!$CB$74:$DL$97,MATCH(_xlfn.CONCAT(TEXT(DATE($A7,$B7,1),"mmm-yy"),$D7),'[1]Demanda requerida 2026'!$CB$39:$DL$39,0),FALSE) -> 200 | L7: =VLOOKUP(L$1,'[1]Demanda requerida 2026'!$CB$74:$DL$97,MATCH(_xlfn.CONCAT(TEXT(DATE($A7,$B7,1),"mmm-yy"),$D7),'[1]Demanda requerida 2026'!$CB$39:$DL$39,0),FALSE) -> 83 | ... AB7: =VLOOKUP(AB$1,'[1]Demanda requerida 2026'!$CB$74:$DL$97,MATCH(_xlfn.CONCAT(TEXT(DATE($A7,$B7,1),"mmm-yy"),$D7),'[1]Demanda requerida 2026'!$CB$39:$DL$39,0),FALSE) -> 3233 | AC7: =SUM(E7:AB7) -> 111457
A8: 2026 | B8: 3 | C8: 6 | D8: Festivo | E8: =VLOOKUP(E$1,'[1]Demanda requerida 2026'!$CB$74:$DL$97,MATCH(_xlfn.CONCAT(TEXT(DATE($A8,$B8,1),"mmm-yy"),$D8),'[1]Demanda requerida 2026'!$CB$39:$DL$39,0),FALSE) -> 200 | F8: =VLOOKUP(F$1,'[1]Demanda requerida 2026'!$CB$74:$DL$97,MATCH(_xlfn.CONCAT(TEXT(DATE($A8,$B8,1),"mmm-yy"),$D8),'[1]Demanda requerida 2026'!$CB$39:$DL$39,0),FALSE) -> 200 | G8: =VLOOKUP(G$1,'[1]Demanda requerida 2026'!$CB$74:$DL$97,MATCH(_xlfn.CONCAT(TEXT(DATE($A8,$B8,1),"mmm-yy"),$D8),'[1]Demanda requerida 2026'!$CB$39:$DL$39,0),FALSE) -> 200 | H8: =VLOOKUP(H$1,'[1]Demanda requerida 2026'!$CB$74:$DL$97,MATCH(_xlfn.CONCAT(TEXT(DATE($A8,$B8,1),"mmm-yy"),$D8),'[1]Demanda requerida 2026'!$CB$39:$DL$39,0),FALSE) -> 200 | I8: =VLOOKUP(I$1,'[1]Demanda requerida 2026'!$CB$74:$DL$97,MATCH(_xlfn.CONCAT(TEXT(DATE($A8,$B8,1),"mmm-yy"),$D8),'[1]Demanda requerida 2026'!$CB$39:$DL$39,0),FALSE) -> 200 | J8: =VLOOKUP(J$1,'[1]Demanda requerida 2026'!$CB$74:$DL$97,MATCH(_xlfn.CONCAT(TEXT(DATE($A8,$B8,1),"mmm-yy"),$D8),'[1]Demanda requerida 2026'!$CB$39:$DL$39,0),FALSE) -> 200 | K8: =VLOOKUP(K$1,'[1]Demanda requerida 2026'!$CB$74:$DL$97,MATCH(_xlfn.CONCAT(TEXT(DATE($A8,$B8,1),"mmm-yy"),$D8),'[1]Demanda requerida 2026'!$CB$39:$DL$39,0),FALSE) -> 200 | L8: =VLOOKUP(L$1,'[1]Demanda requerida 2026'!$CB$74:$DL$97,MATCH(_xlfn.CONCAT(TEXT(DATE($A8,$B8,1),"mmm-yy"),$D8),'[1]Demanda requerida 2026'!$CB$39:$DL$39,0),FALSE) -> 200 | ... AB8: =VLOOKUP(AB$1,'[1]Demanda requerida 2026'!$CB$74:$DL$97,MATCH(_xlfn.CONCAT(TEXT(DATE($A8,$B8,1),"mmm-yy"),$D8),'[1]Demanda requerida 2026'!$CB$39:$DL$39,0),FALSE) -> 200 | AC8: =SUM(E8:AB8) -> 25913 | AD8: =+SUMPRODUCT(AC8:AC10,C8:C10) -> 4477313
A9: 2026 | B9: 3 | C9: 21 | D9: Ordinario | E9: =VLOOKUP(E$1,'[1]Demanda requerida 2026'!$CB$74:$DL$97,MATCH(_xlfn.CONCAT(TEXT(DATE($A9,$B9,1),"mmm-yy"),$D9),'[1]Demanda requerida 2026'!$CB$39:$DL$39,0),FALSE) -> 1777 | F9: =VLOOKUP(F$1,'[1]Demanda requerida 2026'!$CB$74:$DL$97,MATCH(_xlfn.CONCAT(TEXT(DATE($A9,$B9,1),"mmm-yy"),$D9),'[1]Demanda requerida 2026'!$CB$39:$DL$39,0),FALSE) -> 709 | G9: =VLOOKUP(G$1,'[1]Demanda requerida 2026'!$CB$74:$DL$97,MATCH(_xlfn.CONCAT(TEXT(DATE($A9,$B9,1),"mmm-yy"),$D9),'[1]Demanda requerida 2026'!$CB$39:$DL$39,0),FALSE) -> 200 | H9: =VLOOKUP(H$1,'[1]Demanda requerida 2026'!$CB$74:$DL$97,MATCH(_xlfn.CONCAT(TEXT(DATE($A9,$B9,1),"mmm-yy"),$D9),'[1]Demanda requerida 2026'!$CB$39:$DL$39,0),FALSE) -> 200 | I9: =VLOOKUP(I$1,'[1]Demanda requerida 2026'!$CB$74:$DL$97,MATCH(_xlfn.CONCAT(TEXT(DATE($A9,$B9,1),"mmm-yy"),$D9),'[1]Demanda requerida 2026'!$CB$39:$DL$39,0),FALSE) -> 200 | J9: =VLOOKUP(J$1,'[1]Demanda requerida 2026'!$CB$74:$DL$97,MATCH(_xlfn.CONCAT(TEXT(DATE($A9,$B9,1),"mmm-yy"),$D9),'[1]Demanda requerida 2026'!$CB$39:$DL$39,0),FALSE) -> 938 | K9: =VLOOKUP(K$1,'[1]Demanda requerida 2026'!$CB$74:$DL$97,MATCH(_xlfn.CONCAT(TEXT(DATE($A9,$B9,1),"mmm-yy"),$D9),'[1]Demanda requerida 2026'!$CB$39:$DL$39,0),FALSE) -> 2484 | L9: =VLOOKUP(L$1,'[1]Demanda requerida 2026'!$CB$74:$DL$97,MATCH(_xlfn.CONCAT(TEXT(DATE($A9,$B9,1),"mmm-yy"),$D9),'[1]Demanda requerida 2026'!$CB$39:$DL$39,0),FALSE) -> 3865 | ... AB9: =VLOOKUP(AB$1,'[1]Demanda requerida 2026'!$CB$74:$DL$97,MATCH(_xlfn.CONCAT(TEXT(DATE($A9,$B9,1),"mmm-yy"),$D9),'[1]Demanda requerida 2026'!$CB$39:$DL$39,0),FALSE) -> 5081 | AC9: =SUM(E9:AB9) -> 178963
A10: 2026 | B10: 3 | C10: 4 | D10: Sábado | E10: =VLOOKUP(E$1,'[1]Demanda requerida 2026'!$CB$74:$DL$97,MATCH(_xlfn.CONCAT(TEXT(DATE($A10,$B10,1),"mmm-yy"),$D10),'[1]Demanda requerida 2026'!$CB$39:$DL$39,0),FALSE) -> 424 | F10: =VLOOKUP(F$1,'[1]Demanda requerida 2026'!$CB$74:$DL$97,MATCH(_xlfn.CONCAT(TEXT(DATE($A10,$B10,1),"mmm-yy"),$D10),'[1]Demanda requerida 2026'!$CB$39:$DL$39,0),FALSE) -> 200 | G10: =VLOOKUP(G$1,'[1]Demanda requerida 2026'!$CB$74:$DL$97,MATCH(_xlfn.CONCAT(TEXT(DATE($A10,$B10,1),"mmm-yy"),$D10),'[1]Demanda requerida 2026'!$CB$39:$DL$39,0),FALSE) -> 200 | H10: =VLOOKUP(H$1,'[1]Demanda requerida 2026'!$CB$74:$DL$97,MATCH(_xlfn.CONCAT(TEXT(DATE($A10,$B10,1),"mmm-yy"),$D10),'[1]Demanda requerida 2026'!$CB$39:$DL$39,0),FALSE) -> 200 | I10: =VLOOKUP(I$1,'[1]Demanda requerida 2026'!$CB$74:$DL$97,MATCH(_xlfn.CONCAT(TEXT(DATE($A10,$B10,1),"mmm-yy"),$D10),'[1]Demanda requerida 2026'!$CB$39:$DL$39,0),FALSE) -> 200 | J10: =VLOOKUP(J$1,'[1]Demanda requerida 2026'!$CB$74:$DL$97,MATCH(_xlfn.CONCAT(TEXT(DATE($A10,$B10,1),"mmm-yy"),$D10),'[1]Demanda requerida 2026'!$CB$39:$DL$39,0),FALSE) -> 200 | K10: =VLOOKUP(K$1,'[1]Demanda requerida 2026'!$CB$74:$DL$97,MATCH(_xlfn.CONCAT(TEXT(DATE($A10,$B10,1),"mmm-yy"),$D10),'[1]Demanda requerida 2026'!$CB$39:$DL$39,0),FALSE) -> 200 | L10: =VLOOKUP(L$1,'[1]Demanda requerida 2026'!$CB$74:$DL$97,MATCH(_xlfn.CONCAT(TEXT(DATE($A10,$B10,1),"mmm-yy"),$D10),'[1]Demanda requerida 2026'!$CB$39:$DL$39,0),FALSE) -> 590 | ... AB10: =VLOOKUP(AB$1,'[1]Demanda requerida 2026'!$CB$74:$DL$97,MATCH(_xlfn.CONCAT(TEXT(DATE($A10,$B10,1),"mmm-yy"),$D10),'[1]Demanda requerida 2026'!$CB$39:$DL$39,0),FALSE) -> 5349 | AC10: =SUM(E10:AB10) -> 140903
A11: 2026 | B11: 4 | C11: 6 | D11: Festivo | E11: =VLOOKUP(E$1,'[1]Demanda requerida 2026'!$CB$74:$DL$97,MATCH(_xlfn.CONCAT(TEXT(DATE($A11,$B11,1),"mmm-yy"),$D11),'[1]Demanda requerida 2026'!$CB$39:$DL$39,0),FALSE) -> 200 | F11: =VLOOKUP(F$1,'[1]Demanda requerida 2026'!$CB$74:$DL$97,MATCH(_xlfn.CONCAT(TEXT(DATE($A11,$B11,1),"mmm-yy"),$D11),'[1]Demanda requerida 2026'!$CB$39:$DL$39,0),FALSE) -> 200 | G11: =VLOOKUP(G$1,'[1]Demanda requerida 2026'!$CB$74:$DL$97,MATCH(_xlfn.CONCAT(TEXT(DATE($A11,$B11,1),"mmm-yy"),$D11),'[1]Demanda requerida 2026'!$CB$39:$DL$39,0),FALSE) -> 200 | H11: =VLOOKUP(H$1,'[1]Demanda requerida 2026'!$CB$74:$DL$97,MATCH(_xlfn.CONCAT(TEXT(DATE($A11,$B11,1),"mmm-yy"),$D11),'[1]Demanda requerida 2026'!$CB$39:$DL$39,0),FALSE) -> 200 | I11: =VLOOKUP(I$1,'[1]Demanda requerida 2026'!$CB$74:$DL$97,MATCH(_xlfn.CONCAT(TEXT(DATE($A11,$B11,1),"mmm-yy"),$D11),'[1]Demanda requerida 2026'!$CB$39:$DL$39,0),FALSE) -> 200 | J11: =VLOOKUP(J$1,'[1]Demanda requerida 2026'!$CB$74:$DL$97,MATCH(_xlfn.CONCAT(TEXT(DATE($A11,$B11,1),"mmm-yy"),$D11),'[1]Demanda requerida 2026'!$CB$39:$DL$39,0),FALSE) -> 200 | K11: =VLOOKUP(K$1,'[1]Demanda requerida 2026'!$CB$74:$DL$97,MATCH(_xlfn.CONCAT(TEXT(DATE($A11,$B11,1),"mmm-yy"),$D11),'[1]Demanda requerida 2026'!$CB$39:$DL$39,0),FALSE) -> 200 | L11: =VLOOKUP(L$1,'[1]Demanda requerida 2026'!$CB$74:$DL$97,MATCH(_xlfn.CONCAT(TEXT(DATE($A11,$B11,1),"mmm-yy"),$D11),'[1]Demanda requerida 2026'!$CB$39:$DL$39,0),FALSE) -> 200 | ... AB11: =VLOOKUP(AB$1,'[1]Demanda requerida 2026'!$CB$74:$DL$97,MATCH(_xlfn.CONCAT(TEXT(DATE($A11,$B11,1),"mmm-yy"),$D11),'[1]Demanda requerida 2026'!$CB$39:$DL$39,0),FALSE) -> 200 | AC11: =SUM(E11:AB11) -> 13045 | AD11: =+SUMPRODUCT(AC11:AC13,C11:C13) -> 7876062
A12: 2026 | B12: 4 | C12: 20 | D12: Ordinario | E12: =VLOOKUP(E$1,'[1]Demanda requerida 2026'!$CB$74:$DL$97,MATCH(_xlfn.CONCAT(TEXT(DATE($A12,$B12,1),"mmm-yy"),$D12),'[1]Demanda requerida 2026'!$CB$39:$DL$39,0),FALSE) -> 8911 | F12: =VLOOKUP(F$1,'[1]Demanda requerida 2026'!$CB$74:$DL$97,MATCH(_xlfn.CONCAT(TEXT(DATE($A12,$B12,1),"mmm-yy"),$D12),'[1]Demanda requerida 2026'!$CB$39:$DL$39,0),FALSE) -> 7740 | G12: =VLOOKUP(G$1,'[1]Demanda requerida 2026'!$CB$74:$DL$97,MATCH(_xlfn.CONCAT(TEXT(DATE($A12,$B12,1),"mmm-yy"),$D12),'[1]Demanda requerida 2026'!$CB$39:$DL$39,0),FALSE) -> 6908 | H12: =VLOOKUP(H$1,'[1]Demanda requerida 2026'!$CB$74:$DL$97,MATCH(_xlfn.CONCAT(TEXT(DATE($A12,$B12,1),"mmm-yy"),$D12),'[1]Demanda requerida 2026'!$CB$39:$DL$39,0),FALSE) -> 6373 | I12: =VLOOKUP(I$1,'[1]Demanda requerida 2026'!$CB$74:$DL$97,MATCH(_xlfn.CONCAT(TEXT(DATE($A12,$B12,1),"mmm-yy"),$D12),'[1]Demanda requerida 2026'!$CB$39:$DL$39,0),FALSE) -> 6223 | J12: =VLOOKUP(J$1,'[1]Demanda requerida 2026'!$CB$74:$DL$97,MATCH(_xlfn.CONCAT(TEXT(DATE($A12,$B12,1),"mmm-yy"),$D12),'[1]Demanda requerida 2026'!$CB$39:$DL$39,0),FALSE) -> 7491 | K12: =VLOOKUP(K$1,'[1]Demanda requerida 2026'!$CB$74:$DL$97,MATCH(_xlfn.CONCAT(TEXT(DATE($A12,$B12,1),"mmm-yy"),$D12),'[1]Demanda requerida 2026'!$CB$39:$DL$39,0),FALSE) -> 8911 | L12: =VLOOKUP(L$1,'[1]Demanda requerida 2026'!$CB$74:$DL$97,MATCH(_xlfn.CONCAT(TEXT(DATE($A12,$B12,1),"mmm-yy"),$D12),'[1]Demanda requerida 2026'!$CB$39:$DL$39,0),FALSE) -> 10696 | ... AB12: =VLOOKUP(AB$1,'[1]Demanda requerida 2026'!$CB$74:$DL$97,MATCH(_xlfn.CONCAT(TEXT(DATE($A12,$B12,1),"mmm-yy"),$D12),'[1]Demanda requerida 2026'!$CB$39:$DL$39,0),FALSE) -> 11750 | AC12: =SUM(E12:AB12) -> 343087
A13: 2026 | B13: 4 | C13: 4 | D13: Sábado | E13: =VLOOKUP(E$1,'[1]Demanda requerida 2026'!$CB$74:$DL$97,MATCH(_xlfn.CONCAT(TEXT(DATE($A13,$B13,1),"mmm-yy"),$D13),'[1]Demanda requerida 2026'!$CB$39:$DL$39,0),FALSE) -> 5841 | F13: =VLOOKUP(F$1,'[1]Demanda requerida 2026'!$CB$74:$DL$97,MATCH(_xlfn.CONCAT(TEXT(DATE($A13,$B13,1),"mmm-yy"),$D13),'[1]Demanda requerida 2026'!$CB$39:$DL$39,0),FALSE) -> 4753 | G13: =VLOOKUP(G$1,'[1]Demanda requerida 2026'!$CB$74:$DL$97,MATCH(_xlfn.CONCAT(TEXT(DATE($A13,$B13,1),"mmm-yy"),$D13),'[1]Demanda requerida 2026'!$CB$39:$DL$39,0),FALSE) -> 3911 | H13: =VLOOKUP(H$1,'[1]Demanda requerida 2026'!$CB$74:$DL$97,MATCH(_xlfn.CONCAT(TEXT(DATE($A13,$B13,1),"mmm-yy"),$D13),'[1]Demanda requerida 2026'!$CB$39:$DL$39,0),FALSE) -> 3431 | I13: =VLOOKUP(I$1,'[1]Demanda requerida 2026'!$CB$74:$DL$97,MATCH(_xlfn.CONCAT(TEXT(DATE($A13,$B13,1),"mmm-yy"),$D13),'[1]Demanda requerida 2026'!$CB$39:$DL$39,0),FALSE) -> 3204 | J13: =VLOOKUP(J$1,'[1]Demanda requerida 2026'!$CB$74:$DL$97,MATCH(_xlfn.CONCAT(TEXT(DATE($A13,$B13,1),"mmm-yy"),$D13),'[1]Demanda requerida 2026'!$CB$39:$DL$39,0),FALSE) -> 3368 | K13: =VLOOKUP(K$1,'[1]Demanda requerida 2026'!$CB$74:$DL$97,MATCH(_xlfn.CONCAT(TEXT(DATE($A13,$B13,1),"mmm-yy"),$D13),'[1]Demanda requerida 2026'!$CB$39:$DL$39,0),FALSE) -> 2010 | L13: =VLOOKUP(L$1,'[1]Demanda requerida 2026'!$CB$74:$DL$97,MATCH(_xlfn.CONCAT(TEXT(DATE($A13,$B13,1),"mmm-yy"),$D13),'[1]Demanda requerida 2026'!$CB$39:$DL$39,0),FALSE) -> 6004 | ... AB13: =VLOOKUP(AB$1,'[1]Demanda requerida 2026'!$CB$74:$DL$97,MATCH(_xlfn.CONCAT(TEXT(DATE($A13,$B13,1),"mmm-yy"),$D13),'[1]Demanda requerida 2026'!$CB$39:$DL$39,0),FALSE) -> 9357 | AC13: =SUM(E13:AB13) -> 234013
A14: 2026 | B14: 5 | C14: 7 | D14: Festivo | E14: =VLOOKUP(E$1,'[1]Demanda requerida 2026'!$CB$74:$DL$97,MATCH(_xlfn.CONCAT(TEXT(DATE($A14,$B14,1),"mmm-yy"),$D14),'[1]Demanda requerida 2026'!$CB$39:$DL$39,0),FALSE) -> 200 | F14: =VLOOKUP(F$1,'[1]Demanda requerida 2026'!$CB$74:$DL$97,MATCH(_xlfn.CONCAT(TEXT(DATE($A14,$B14,1),"mmm-yy"),$D14),'[1]Demanda requerida 2026'!$CB$39:$DL$39,0),FALSE) -> 200 | G14: =VLOOKUP(G$1,'[1]Demanda requerida 2026'!$CB$74:$DL$97,MATCH(_xlfn.CONCAT(TEXT(DATE($A14,$B14,1),"mmm-yy"),$D14),'[1]Demanda requerida 2026'!$CB$39:$DL$39,0),FALSE) -> 200 | H14: =VLOOKUP(H$1,'[1]Demanda requerida 2026'!$CB$74:$DL$97,MATCH(_xlfn.CONCAT(TEXT(DATE($A14,$B14,1),"mmm-yy"),$D14),'[1]Demanda requerida 2026'!$CB$39:$DL$39,0),FALSE) -> 200 | I14: =VLOOKUP(I$1,'[1]Demanda requerida 2026'!$CB$74:$DL$97,MATCH(_xlfn.CONCAT(TEXT(DATE($A14,$B14,1),"mmm-yy"),$D14),'[1]Demanda requerida 2026'!$CB$39:$DL$39,0),FALSE) -> 200 | J14: =VLOOKUP(J$1,'[1]Demanda requerida 2026'!$CB$74:$DL$97,MATCH(_xlfn.CONCAT(TEXT(DATE($A14,$B14,1),"mmm-yy"),$D14),'[1]Demanda requerida 2026'!$CB$39:$DL$39,0),FALSE) -> 200 | K14: =VLOOKUP(K$1,'[1]Demanda requerida 2026'!$CB$74:$DL$97,MATCH(_xlfn.CONCAT(TEXT(DATE($A14,$B14,1),"mmm-yy"),$D14),'[1]Demanda requerida 2026'!$CB$39:$DL$39,0),FALSE) -> 200 | L14: =VLOOKUP(L$1,'[1]Demanda requerida 2026'!$CB$74:$DL$97,MATCH(_xlfn.CONCAT(TEXT(DATE($A14,$B14,1),"mmm-yy"),$D14),'[1]Demanda requerida 2026'!$CB$39:$DL$39,0),FALSE) -> 200 | ... AB14: =VLOOKUP(AB$1,'[1]Demanda requerida 2026'!$CB$74:$DL$97,MATCH(_xlfn.CONCAT(TEXT(DATE($A14,$B14,1),"mmm-yy"),$D14),'[1]Demanda requerida 2026'!$CB$39:$DL$39,0),FALSE) -> 200 | AC14: =SUM(E14:AB14) -> 17825 | AD14: =+SUMPRODUCT(AC14:AC16,C14:C16) -> 6714696
A15: 2026 | B15: 5 | C15: 19 | D15: Ordinario | E15: =VLOOKUP(E$1,'[1]Demanda requerida 2026'!$CB$74:$DL$97,MATCH(_xlfn.CONCAT(TEXT(DATE($A15,$B15,1),"mmm-yy"),$D15),'[1]Demanda requerida 2026'!$CB$39:$DL$39,0),FALSE) -> 6143 | F15: =VLOOKUP(F$1,'[1]Demanda requerida 2026'!$CB$74:$DL$97,MATCH(_xlfn.CONCAT(TEXT(DATE($A15,$B15,1),"mmm-yy"),$D15),'[1]Demanda requerida 2026'!$CB$39:$DL$39,0),FALSE) -> 4740 | G15: =VLOOKUP(G$1,'[1]Demanda requerida 2026'!$CB$74:$DL$97,MATCH(_xlfn.CONCAT(TEXT(DATE($A15,$B15,1),"mmm-yy"),$D15),'[1]Demanda requerida 2026'!$CB$39:$DL$39,0),FALSE) -> 3955 | H15: =VLOOKUP(H$1,'[1]Demanda requerida 2026'!$CB$74:$DL$97,MATCH(_xlfn.CONCAT(TEXT(DATE($A15,$B15,1),"mmm-yy"),$D15),'[1]Demanda requerida 2026'!$CB$39:$DL$39,0),FALSE) -> 3534 | I15: =VLOOKUP(I$1,'[1]Demanda requerida 2026'!$CB$74:$DL$97,MATCH(_xlfn.CONCAT(TEXT(DATE($A15,$B15,1),"mmm-yy"),$D15),'[1]Demanda requerida 2026'!$CB$39:$DL$39,0),FALSE) -> 3553 | J15: =VLOOKUP(J$1,'[1]Demanda requerida 2026'!$CB$74:$DL$97,MATCH(_xlfn.CONCAT(TEXT(DATE($A15,$B15,1),"mmm-yy"),$D15),'[1]Demanda requerida 2026'!$CB$39:$DL$39,0),FALSE) -> 4740 | K15: =VLOOKUP(K$1,'[1]Demanda requerida 2026'!$CB$74:$DL$97,MATCH(_xlfn.CONCAT(TEXT(DATE($A15,$B15,1),"mmm-yy"),$D15),'[1]Demanda requerida 2026'!$CB$39:$DL$39,0),FALSE) -> 6235 | L15: =VLOOKUP(L$1,'[1]Demanda requerida 2026'!$CB$74:$DL$97,MATCH(_xlfn.CONCAT(TEXT(DATE($A15,$B15,1),"mmm-yy"),$D15),'[1]Demanda requerida 2026'!$CB$39:$DL$39,0),FALSE) -> 7989 | ... AB15: =VLOOKUP(AB$1,'[1]Demanda requerida 2026'!$CB$74:$DL$97,MATCH(_xlfn.CONCAT(TEXT(DATE($A15,$B15,1),"mmm-yy"),$D15),'[1]Demanda requerida 2026'!$CB$39:$DL$39,0),FALSE) -> 9902 | AC15: =SUM(E15:AB15) -> 291344
A16: 2026 | B16: 5 | C16: 5 | D16: Sábado | E16: =VLOOKUP(E$1,'[1]Demanda requerida 2026'!$CB$74:$DL$97,MATCH(_xlfn.CONCAT(TEXT(DATE($A16,$B16,1),"mmm-yy"),$D16),'[1]Demanda requerida 2026'!$CB$39:$DL$39,0),FALSE) -> 4602 | F16: =VLOOKUP(F$1,'[1]Demanda requerida 2026'!$CB$74:$DL$97,MATCH(_xlfn.CONCAT(TEXT(DATE($A16,$B16,1),"mmm-yy"),$D16),'[1]Demanda requerida 2026'!$CB$39:$DL$39,0),FALSE) -> 3403 | G16: =VLOOKUP(G$1,'[1]Demanda requerida 2026'!$CB$74:$DL$97,MATCH(_xlfn.CONCAT(TEXT(DATE($A16,$B16,1),"mmm-yy"),$D16),'[1]Demanda requerida 2026'!$CB$39:$DL$39,0),FALSE) -> 2648 | H16: =VLOOKUP(H$1,'[1]Demanda requerida 2026'!$CB$74:$DL$97,MATCH(_xlfn.CONCAT(TEXT(DATE($A16,$B16,1),"mmm-yy"),$D16),'[1]Demanda requerida 2026'!$CB$39:$DL$39,0),FALSE) -> 2117 | I16: =VLOOKUP(I$1,'[1]Demanda requerida 2026'!$CB$74:$DL$97,MATCH(_xlfn.CONCAT(TEXT(DATE($A16,$B16,1),"mmm-yy"),$D16),'[1]Demanda requerida 2026'!$CB$39:$DL$39,0),FALSE) -> 1967 | J16: =VLOOKUP(J$1,'[1]Demanda requerida 2026'!$CB$74:$DL$97,MATCH(_xlfn.CONCAT(TEXT(DATE($A16,$B16,1),"mmm-yy"),$D16),'[1]Demanda requerida 2026'!$CB$39:$DL$39,0),FALSE) -> 2200 | K16: =VLOOKUP(K$1,'[1]Demanda requerida 2026'!$CB$74:$DL$97,MATCH(_xlfn.CONCAT(TEXT(DATE($A16,$B16,1),"mmm-yy"),$D16),'[1]Demanda requerida 2026'!$CB$39:$DL$39,0),FALSE) -> 2864 | L16: =VLOOKUP(L$1,'[1]Demanda requerida 2026'!$CB$74:$DL$97,MATCH(_xlfn.CONCAT(TEXT(DATE($A16,$B16,1),"mmm-yy"),$D16),'[1]Demanda requerida 2026'!$CB$39:$DL$39,0),FALSE) -> 4872 | ... AB16: =VLOOKUP(AB$1,'[1]Demanda requerida 2026'!$CB$74:$DL$97,MATCH(_xlfn.CONCAT(TEXT(DATE($A16,$B16,1),"mmm-yy"),$D16),'[1]Demanda requerida 2026'!$CB$39:$DL$39,0),FALSE) -> 7180 | AC16: =SUM(E16:AB16) -> 210877
A17: 2026 | B17: 6 | C17: 7 | D17: Festivo | E17: =VLOOKUP(E$1,'[1]Demanda requerida 2026'!$CB$74:$DL$97,MATCH(_xlfn.CONCAT(TEXT(DATE($A17,$B17,1),"mmm-yy"),$D17),'[1]Demanda requerida 2026'!$CB$39:$DL$39,0),FALSE) -> 200 | F17: =VLOOKUP(F$1,'[1]Demanda requerida 2026'!$CB$74:$DL$97,MATCH(_xlfn.CONCAT(TEXT(DATE($A17,$B17,1),"mmm-yy"),$D17),'[1]Demanda requerida 2026'!$CB$39:$DL$39,0),FALSE) -> 200 | G17: =VLOOKUP(G$1,'[1]Demanda requerida 2026'!$CB$74:$DL$97,MATCH(_xlfn.CONCAT(TEXT(DATE($A17,$B17,1),"mmm-yy"),$D17),'[1]Demanda requerida 2026'!$CB$39:$DL$39,0),FALSE) -> 200 | H17: =VLOOKUP(H$1,'[1]Demanda requerida 2026'!$CB$74:$DL$97,MATCH(_xlfn.CONCAT(TEXT(DATE($A17,$B17,1),"mmm-yy"),$D17),'[1]Demanda requerida 2026'!$CB$39:$DL$39,0),FALSE) -> 200 | I17: =VLOOKUP(I$1,'[1]Demanda requerida 2026'!$CB$74:$DL$97,MATCH(_xlfn.CONCAT(TEXT(DATE($A17,$B17,1),"mmm-yy"),$D17),'[1]Demanda requerida 2026'!$CB$39:$DL$39,0),FALSE) -> 200 | J17: =VLOOKUP(J$1,'[1]Demanda requerida 2026'!$CB$74:$DL$97,MATCH(_xlfn.CONCAT(TEXT(DATE($A17,$B17,1),"mmm-yy"),$D17),'[1]Demanda requerida 2026'!$CB$39:$DL$39,0),FALSE) -> 200 | K17: =VLOOKUP(K$1,'[1]Demanda requerida 2026'!$CB$74:$DL$97,MATCH(_xlfn.CONCAT(TEXT(DATE($A17,$B17,1),"mmm-yy"),$D17),'[1]Demanda requerida 2026'!$CB$39:$DL$39,0),FALSE) -> 200 | L17: =VLOOKUP(L$1,'[1]Demanda requerida 2026'!$CB$74:$DL$97,MATCH(_xlfn.CONCAT(TEXT(DATE($A17,$B17,1),"mmm-yy"),$D17),'[1]Demanda requerida 2026'!$CB$39:$DL$39,0),FALSE) -> 200 | ... AB17: =VLOOKUP(AB$1,'[1]Demanda requerida 2026'!$CB$74:$DL$97,MATCH(_xlfn.CONCAT(TEXT(DATE($A17,$B17,1),"mmm-yy"),$D17),'[1]Demanda requerida 2026'!$CB$39:$DL$39,0),FALSE) -> 200 | AC17: =SUM(E17:AB17) -> 10177 | AD17: =+SUMPRODUCT(AC17:AC19,C17:C19) -> 9456276
A18: 2026 | B18: 6 | C18: 19 | D18: Ordinario | E18: =VLOOKUP(E$1,'[1]Demanda requerida 2026'!$CB$74:$DL$97,MATCH(_xlfn.CONCAT(TEXT(DATE($A18,$B18,1),"mmm-yy"),$D18),'[1]Demanda requerida 2026'!$CB$39:$DL$39,0),FALSE) -> 11434 | F18: =VLOOKUP(F$1,'[1]Demanda requerida 2026'!$CB$74:$DL$97,MATCH(_xlfn.CONCAT(TEXT(DATE($A18,$B18,1),"mmm-yy"),$D18),'[1]Demanda requerida 2026'!$CB$39:$DL$39,0),FALSE) -> 10006 | G18: =VLOOKUP(G$1,'[1]Demanda requerida 2026'!$CB$74:$DL$97,MATCH(_xlfn.CONCAT(TEXT(DATE($A18,$B18,1),"mmm-yy"),$D18),'[1]Demanda requerida 2026'!$CB$39:$DL$39,0),FALSE) -> 9076 | H18: =VLOOKUP(H$1,'[1]Demanda requerida 2026'!$CB$74:$DL$97,MATCH(_xlfn.CONCAT(TEXT(DATE($A18,$B18,1),"mmm-yy"),$D18),'[1]Demanda requerida 2026'!$CB$39:$DL$39,0),FALSE) -> 8564 | I18: =VLOOKUP(I$1,'[1]Demanda requerida 2026'!$CB$74:$DL$97,MATCH(_xlfn.CONCAT(TEXT(DATE($A18,$B18,1),"mmm-yy"),$D18),'[1]Demanda requerida 2026'!$CB$39:$DL$39,0),FALSE) -> 8765 | J18: =VLOOKUP(J$1,'[1]Demanda requerida 2026'!$CB$74:$DL$97,MATCH(_xlfn.CONCAT(TEXT(DATE($A18,$B18,1),"mmm-yy"),$D18),'[1]Demanda requerida 2026'!$CB$39:$DL$39,0),FALSE) -> 9913 | K18: =VLOOKUP(K$1,'[1]Demanda requerida 2026'!$CB$74:$DL$97,MATCH(_xlfn.CONCAT(TEXT(DATE($A18,$B18,1),"mmm-yy"),$D18),'[1]Demanda requerida 2026'!$CB$39:$DL$39,0),FALSE) -> 11616 | L18: =VLOOKUP(L$1,'[1]Demanda requerida 2026'!$CB$74:$DL$97,MATCH(_xlfn.CONCAT(TEXT(DATE($A18,$B18,1),"mmm-yy"),$D18),'[1]Demanda requerida 2026'!$CB$39:$DL$39,0),FALSE) -> 14100 | ... AB18: =VLOOKUP(AB$1,'[1]Demanda requerida 2026'!$CB$74:$DL$97,MATCH(_xlfn.CONCAT(TEXT(DATE($A18,$B18,1),"mmm-yy"),$D18),'[1]Demanda requerida 2026'!$CB$39:$DL$39,0),FALSE) -> 15842 | AC18: =SUM(E18:AB18) -> 430231
A19: 2026 | B19: 6 | C19: 4 | D19: Sábado | E19: =VLOOKUP(E$1,'[1]Demanda requerida 2026'!$CB$74:$DL$97,MATCH(_xlfn.CONCAT(TEXT(DATE($A19,$B19,1),"mmm-yy"),$D19),'[1]Demanda requerida 2026'!$CB$39:$DL$39,0),FALSE) -> 6784 | F19: =VLOOKUP(F$1,'[1]Demanda requerida 2026'!$CB$74:$DL$97,MATCH(_xlfn.CONCAT(TEXT(DATE($A19,$B19,1),"mmm-yy"),$D19),'[1]Demanda requerida 2026'!$CB$39:$DL$39,0),FALSE) -> 6086 | G19: =VLOOKUP(G$1,'[1]Demanda requerida 2026'!$CB$74:$DL$97,MATCH(_xlfn.CONCAT(TEXT(DATE($A19,$B19,1),"mmm-yy"),$D19),'[1]Demanda requerida 2026'!$CB$39:$DL$39,0),FALSE) -> 5703 | H19: =VLOOKUP(H$1,'[1]Demanda requerida 2026'!$CB$74:$DL$97,MATCH(_xlfn.CONCAT(TEXT(DATE($A19,$B19,1),"mmm-yy"),$D19),'[1]Demanda requerida 2026'!$CB$39:$DL$39,0),FALSE) -> 5076 | I19: =VLOOKUP(I$1,'[1]Demanda requerida 2026'!$CB$74:$DL$97,MATCH(_xlfn.CONCAT(TEXT(DATE($A19,$B19,1),"mmm-yy"),$D19),'[1]Demanda requerida 2026'!$CB$39:$DL$39,0),FALSE) -> 4845 | J19: =VLOOKUP(J$1,'[1]Demanda requerida 2026'!$CB$74:$DL$97,MATCH(_xlfn.CONCAT(TEXT(DATE($A19,$B19,1),"mmm-yy"),$D19),'[1]Demanda requerida 2026'!$CB$39:$DL$39,0),FALSE) -> 5455 | K19: =VLOOKUP(K$1,'[1]Demanda requerida 2026'!$CB$74:$DL$97,MATCH(_xlfn.CONCAT(TEXT(DATE($A19,$B19,1),"mmm-yy"),$D19),'[1]Demanda requerida 2026'!$CB$39:$DL$39,0),FALSE) -> 6000 | L19: =VLOOKUP(L$1,'[1]Demanda requerida 2026'!$CB$74:$DL$97,MATCH(_xlfn.CONCAT(TEXT(DATE($A19,$B19,1),"mmm-yy"),$D19),'[1]Demanda requerida 2026'!$CB$39:$DL$39,0),FALSE) -> 8204 | ... AB19: =VLOOKUP(AB$1,'[1]Demanda requerida 2026'!$CB$74:$DL$97,MATCH(_xlfn.CONCAT(TEXT(DATE($A19,$B19,1),"mmm-yy"),$D19),'[1]Demanda requerida 2026'!$CB$39:$DL$39,0),FALSE) -> 13003 | AC19: =SUM(E19:AB19) -> 302662
A20: 2026 | B20: 7 | C20: 5 | D20: Festivo | E20: =VLOOKUP(E$1,'[1]Demanda requerida 2026'!$CB$74:$DL$97,MATCH(_xlfn.CONCAT(TEXT(DATE($A20,$B20,1),"mmm-yy"),$D20),'[1]Demanda requerida 2026'!$CB$39:$DL$39,0),FALSE) -> 200 | F20: =VLOOKUP(F$1,'[1]Demanda requerida 2026'!$CB$74:$DL$97,MATCH(_xlfn.CONCAT(TEXT(DATE($A20,$B20,1),"mmm-yy"),$D20),'[1]Demanda requerida 2026'!$CB$39:$DL$39,0),FALSE) -> 200 | G20: =VLOOKUP(G$1,'[1]Demanda requerida 2026'!$CB$74:$DL$97,MATCH(_xlfn.CONCAT(TEXT(DATE($A20,$B20,1),"mmm-yy"),$D20),'[1]Demanda requerida 2026'!$CB$39:$DL$39,0),FALSE) -> 200 | H20: =VLOOKUP(H$1,'[1]Demanda requerida 2026'!$CB$74:$DL$97,MATCH(_xlfn.CONCAT(TEXT(DATE($A20,$B20,1),"mmm-yy"),$D20),'[1]Demanda requerida 2026'!$CB$39:$DL$39,0),FALSE) -> 200 | I20: =VLOOKUP(I$1,'[1]Demanda requerida 2026'!$CB$74:$DL$97,MATCH(_xlfn.CONCAT(TEXT(DATE($A20,$B20,1),"mmm-yy"),$D20),'[1]Demanda requerida 2026'!$CB$39:$DL$39,0),FALSE) -> 200 | J20: =VLOOKUP(J$1,'[1]Demanda requerida 2026'!$CB$74:$DL$97,MATCH(_xlfn.CONCAT(TEXT(DATE($A20,$B20,1),"mmm-yy"),$D20),'[1]Demanda requerida 2026'!$CB$39:$DL$39,0),FALSE) -> 200 | K20: =VLOOKUP(K$1,'[1]Demanda requerida 2026'!$CB$74:$DL$97,MATCH(_xlfn.CONCAT(TEXT(DATE($A20,$B20,1),"mmm-yy"),$D20),'[1]Demanda requerida 2026'!$CB$39:$DL$39,0),FALSE) -> 200 | L20: =VLOOKUP(L$1,'[1]Demanda requerida 2026'!$CB$74:$DL$97,MATCH(_xlfn.CONCAT(TEXT(DATE($A20,$B20,1),"mmm-yy"),$D20),'[1]Demanda requerida 2026'!$CB$39:$DL$39,0),FALSE) -> 200 | ... AB20: =VLOOKUP(AB$1,'[1]Demanda requerida 2026'!$CB$74:$DL$97,MATCH(_xlfn.CONCAT(TEXT(DATE($A20,$B20,1),"mmm-yy"),$D20),'[1]Demanda requerida 2026'!$CB$39:$DL$39,0),FALSE) -> 200 | AC20: =SUM(E20:AB20) -> 17983 | AD20: =+SUMPRODUCT(AC20:AC22,C20:C22) -> 4460345
A21: 2026 | B21: 7 | C21: 22 | D21: Ordinario | E21: =VLOOKUP(E$1,'[1]Demanda requerida 2026'!$CB$74:$DL$97,MATCH(_xlfn.CONCAT(TEXT(DATE($A21,$B21,1),"mmm-yy"),$D21),'[1]Demanda requerida 2026'!$CB$39:$DL$39,0),FALSE) -> 1980 | F21: =VLOOKUP(F$1,'[1]Demanda requerida 2026'!$CB$74:$DL$97,MATCH(_xlfn.CONCAT(TEXT(DATE($A21,$B21,1),"mmm-yy"),$D21),'[1]Demanda requerida 2026'!$CB$39:$DL$39,0),FALSE) -> 782 | G21: =VLOOKUP(G$1,'[1]Demanda requerida 2026'!$CB$74:$DL$97,MATCH(_xlfn.CONCAT(TEXT(DATE($A21,$B21,1),"mmm-yy"),$D21),'[1]Demanda requerida 2026'!$CB$39:$DL$39,0),FALSE) -> 200 | H21: =VLOOKUP(H$1,'[1]Demanda requerida 2026'!$CB$74:$DL$97,MATCH(_xlfn.CONCAT(TEXT(DATE($A21,$B21,1),"mmm-yy"),$D21),'[1]Demanda requerida 2026'!$CB$39:$DL$39,0),FALSE) -> 200 | I21: =VLOOKUP(I$1,'[1]Demanda requerida 2026'!$CB$74:$DL$97,MATCH(_xlfn.CONCAT(TEXT(DATE($A21,$B21,1),"mmm-yy"),$D21),'[1]Demanda requerida 2026'!$CB$39:$DL$39,0),FALSE) -> 200 | J21: =VLOOKUP(J$1,'[1]Demanda requerida 2026'!$CB$74:$DL$97,MATCH(_xlfn.CONCAT(TEXT(DATE($A21,$B21,1),"mmm-yy"),$D21),'[1]Demanda requerida 2026'!$CB$39:$DL$39,0),FALSE) -> 684 | K21: =VLOOKUP(K$1,'[1]Demanda requerida 2026'!$CB$74:$DL$97,MATCH(_xlfn.CONCAT(TEXT(DATE($A21,$B21,1),"mmm-yy"),$D21),'[1]Demanda requerida 2026'!$CB$39:$DL$39,0),FALSE) -> 2185 | L21: =VLOOKUP(L$1,'[1]Demanda requerida 2026'!$CB$74:$DL$97,MATCH(_xlfn.CONCAT(TEXT(DATE($A21,$B21,1),"mmm-yy"),$D21),'[1]Demanda requerida 2026'!$CB$39:$DL$39,0),FALSE) -> 3769 | ... AB21: =VLOOKUP(AB$1,'[1]Demanda requerida 2026'!$CB$74:$DL$97,MATCH(_xlfn.CONCAT(TEXT(DATE($A21,$B21,1),"mmm-yy"),$D21),'[1]Demanda requerida 2026'!$CB$39:$DL$39,0),FALSE) -> 5126 | AC21: =SUM(E21:AB21) -> 175717
