Workbook

Sheet OF P1 
B1: * La energia a ofertar debe ser expresada únicamente en kilovatio (kWh) redondeado a cero decimales
B4: OFERTA PRODUCTO 1
B5: MES | C5: ENERGIA SOLICITADA (kWh) | D5: % | E5: ENERGIA OFERTADA (kWh) | F5: PRECIO $/kWh
B6: 46023 | C6: =+VLOOKUP(B6,'CURVA P1'!$A$7:$AD$56,30,FALSE) -> 26673174 | D6: % | F6: $/kWh
B7: 46054 | C7: =+VLOOKUP(B7,'CURVA P1'!$A$7:$AD$56,30,FALSE) -> 27446688
B8: 46082 | C8: =+VLOOKUP(B8,'CURVA P1'!$A$7:$AD$56,30,FALSE) -> 26678356
B9: 46113 | C9: =+VLOOKUP(B9,'CURVA P1'!$A$7:$AD$56,30,FALSE) -> 27760442
B10: 46143 | C10: =+VLOOKUP(B10,'CURVA P1'!$A$7:$AD$56,30,FALSE) -> 28373867
B11: 46174 | C11: =+VLOOKUP(B11,'CURVA P1'!$A$7:$AD$56,30,FALSE) -> 28775725
B12: 46204 | C12: =+VLOOKUP(B12,'CURVA P1'!$A$7:$AD$56,30,FALSE) -> 27971551
B13: 46235 | C13: =+VLOOKUP(B13,'CURVA P1'!$A$7:$AD$56,30,FALSE) -> 29060343
B14: 46266 | C14: =+VLOOKUP(B14,'CURVA P1'!$A$7:$AD$56,30,FALSE) -> 29703314
B15: 46296 | C15: =+VLOOKUP(B15,'CURVA P1'!$A$7:$AD$56,30,FALSE) -> 29301634
B16: 46327 | C16: =+VLOOKUP(B16,'CURVA P1'!$A$7:$AD$56,30,FALSE) -> 28803316
B17: 46357 | C17: =+VLOOKUP(B17,'CURVA P1'!$A$7:$AD$56,30,FALSE) -> 28030366
C18: =+SUM(C6:C17) -> 338578776

Sheet CURVA P1
A1: Curva de distribucion en kwh
A2: * La energia a ofertar debe ser expresada únicamente en kilovatio (kWh) redondeado a cero decimales
A4: TOTAL | C4: =+AD55 -> 338578776
A5: MES | B5: DÍA | C5: HORA 01 | D5: HORA 02 | E5: HORA 03 | F5: HORA 04 | G5: HORA 05 | H5: HORA 06 | I5: HORA 07 | J5: HORA 08 | K5: HORA 09 | L5: HORA 10 | M5: HORA 11 | N5: HORA 12 | O5: HORA 13 | P5: HORA 14 | Q5: HORA 15 | R5: HORA 16 | S5: HORA 17 | T5: HORA 18 | U5: HORA 19 | V5: HORA 20 | W5: HORA 21 | X5: HORA 22 | Y5: HORA 23 | Z5: HORA 24 | AA5: TOTAL DÍA | AB5: NUMERO DÍAS | AC5: TOTAL DÍA MES | AD5: TOTAL MES
A7: 46023 | B7: Hábil | C7: 36483 | D7: 35530 | E7: 34091 | F7: 33021 | G7: 32679 | H7: 33265 | I7: 34178 | J7: 35053 | K7: 38371 | L7: 40922 | M7: 43080 | N7: 44425 | O7: 42333 | P7: 45202 | Q7: 49073 | R7: 49850 | S7: 48845 | T7: 33000 | U7: 33611 | V7: 32533 | W7: 31567 | X7: 30791 | Y7: 29414 | Z7: 27515 | AA7: =SUM(C7:Z7) -> 894832 | AB7: 20 | AC7: =+AA7*AB7 -> 17896640 | AD7: =+SUM(AC7:AC10) -> 26673174
A8: 46024 | B8: Sábado | C8: 37377 | D8: 36097 | E8: 34425 | F8: 33232 | G8: 32684 | H8: 32851 | I8: 33460 | J8: 34411 | K8: 38197 | L8: 40946 | M8: 42939 | N8: 43849 | O8: 42448 | P8: 43007 | Q8: 44664 | R8: 45009 | S8: 43876 | T8: 30845 | U8: 32410 | V8: 31557 | W8: 30491 | X8: 29539 | Y8: 28485 | Z8: 26959 | AA8: =SUM(C8:Z8) -> 869758 | AB8: 5 | AC8: =+AA8*AB8 -> 4348790
A9: 46025 | B9: Domingo | C9: 36740 | D9: 35636 | E9: 34091 | F9: 32890 | G9: 32185 | H9: 31809 | I9: 31771 | J9: 30156 | K9: 31360 | L9: 32941 | M9: 33958 | N9: 34857 | O9: 35463 | P9: 35757 | Q9: 36486 | R9: 37026 | S9: 36701 | T9: 25763 | U9: 27737 | V9: 28107 | W9: 28048 | X9: 27805 | Y9: 26801 | Z9: 24924 | AA9: =SUM(C9:Z9) -> 769012 | AB9: 4 | AC9: =+AA9*AB9 -> 3076048
A10: 46026 | B10: Festivo | C10: 30982 | D10: 29952 | E10: 29420 | F10: 28681 | G10: 28350 | H10: 28026 | I10: 27591 | J10: 25828 | K10: 26941 | L10: 28477 | M10: 30028 | N10: 30899 | O10: 31265 | P10: 31774 | Q10: 32497 | R10: 32934 | S10: 32343 | T10: 22982 | U10: 25092 | V10: 25278 | W10: 25160 | X10: 24843 | Y10: 23919 | Z10: 22586 | AA10: =SUM(C10:Z10) -> 675848 | AB10: 2 | AC10: =+AA10*AB10 -> 1351696
A11: 46054 | B11: Hábil | C11: 40714 | D11: 38660 | E11: 37169 | F11: 36236 | G11: 36317 | H11: 38550 | I11: 40311 | J11: 41867 | K11: 45322 | L11: 47873 | M11: 50238 | N11: 50415 | O11: 46583 | P11: 51148 | Q11: 55819 | R11: 56707 | S11: 55412 | T11: 36735 | U11: 36918 | V11: 36405 | W11: 35774 | X11: 34307 | Y11: 31455 | Z11: 28759 | AA11: =SUM(C11:Z11) -> 1009694 | AB11: 20 | AC11: =+AA11*AB11 -> 20193880 | AD11: =+SUM(AC11:AC14) -> 27446688
A12: 46055 | B12: Sábado | C12: 39077 | D12: 37140 | E12: 35692 | F12: 34823 | G12: 34396 | H12: 35067 | I12: 36692 | J12: 38967 | K12: 42909 | L12: 45818 | M12: 47755 | N12: 48495 | O12: 46757 | P12: 46918 | Q12: 48176 | R12: 48567 | S12: 47256 | T12: 32139 | U12: 33979 | V12: 34024 | W12: 32945 | X12: 31780 | Y12: 30241 | Z12: 28439 | AA12: =SUM(C12:Z12) -> 938052 | AB12: 4 | AC12: =+AA12*AB12 -> 3752208
A13: 46056 | B13: Domingo | C13: 40291 | D13: 38238 | E13: 36732 | F13: 35457 | G13: 34864 | H13: 34707 | I13: 35065 | J13: 34200 | K13: 35705 | L13: 37750 | M13: 38979 | N13: 40163 | O13: 40612 | P13: 40725 | Q13: 41775 | R13: 42790 | S13: 42631 | T13: 30082 | U13: 32474 | V13: 33567 | W13: 33682 | X13: 33416 | Y13: 31850 | Z13: 29395 | AA13: =SUM(C13:Z13) -> 875150 | AB13: 4 | AC13: =+AA13*AB13 -> 3500600
A14: 46057 | B14: Festivo | C14: 0 | D14: 0 | E14: 0 | F14: 0 | G14: 0 | H14: 0 | I14: 0 | J14: 0 | K14: 0 | L14: 0 | M14: 0 | N14: 0 | O14: 0 | P14: 0 | Q14: 0 | R14: 0 | S14: 0 | T14: 0 | U14: 0 | V14: 0 | W14: 0 | X14: 0 | Y14: 0 | Z14: 0 | AA14: =SUM(C14:Z14) -> 0 | AB14: 0 | AC14: =+AA14*AB14 -> 0
A15: 46082 | B15: Hábil | C15: 37021 | D15: 35042 | E15: 33649 | F15: 32631 | G15: 32521 | H15: 33969 | I15: 34520 | J15: 35443 | K15: 38367 | L15: 40558 | M15: 42553 | N15: 43035 | O15: 40173 | P15: 44403 | Q15: 48725 | R15: 49439 | S15: 48353 | T15: 31559 | U15: 31768 | V15: 31692 | W15: 31750 | X15: 31202 | Y15: 29092 | Z15: 26820 | AA15: =SUM(C15:Z15) -> 884285 | AB15: 21 | AC15: =+AA15*AB15 -> 18569985 | AD15: =+SUM(AC15:AC18) -> 26678356
B16: Sábado | C16: 38120 | D16: 36123 | E16: 34578 | F16: 33302 | G16: 32635 | H16: 32644 | I16: 33347 | J16: 34826 | K16: 38264 | L16: 40835 | M16: 42748 | N16: 43297 | O16: 41482 | P16: 42049 | Q16: 43818 | R16: 44243 | S16: 43197 | T16: 29876 | U16: 31215 | V16: 31130 | W16: 30754 | X16: 30476 | Y16: 29861 | Z16: 28421 | AA16: =SUM(C16:Z16) -> 867241 | AB16: 4 | AC16: =+AA16*AB16 -> 3468964
B17: Domingo | C17: 38845 | D17: 36799 | E17: 35346 | F17: 34161 | G17: 33370 | H17: 32766 | I17: 32439 | J17: 30809 | K17: 31622 | L17: 32700 | M17: 33303 | N17: 34098 | O17: 34921 | P17: 35461 | Q17: 36548 | R17: 37438 | S17: 37274 | T17: 25914 | U17: 27839 | V17: 29255 | W17: 29841 | X17: 30034 | Y17: 28309 | Z17: 26226 | AA17: =SUM(C17:Z17) -> 785318 | AB17: 5 | AC17: =+AA17*AB17 -> 3926590
B18: Festivo | C18: 31524 | D18: 29493 | E18: 28244 | F18: 27384 | G18: 27117 | H18: 26867 | I18: 27428 | J18: 27427 | K18: 29370 | L18: 31533 | M18: 33612 | N18: 35117 | O18: 34896 | P18: 35808 | Q18: 36319 | R18: 36141 | S18: 35385 | T18: 23607 | U18: 25977 | V18: 27344 | W18: 27611 | X18: 27156 | Y18: 24911 | Z18: 22546 | AA18: =SUM(C18:Z18) -> 712817 | AB18: 1 | AC18: =+AA18*AB18 -> 712817
A19: 46113 | B19: Hábil | C19: 39038 | D19: 36963 | E19: 35545 | F19: 34531 | G19: 34530 | H19: 35569 | I19: 36698 | J19: 38718 | K19: 42539 | L19: 45066 | M19: 47618 | N19: 48409 | O19: 44899 | P19: 49182 | Q19: 54140 | R19: 54709 | S19: 53184 | T19: 35099 | U19: 35537 | V19: 35061 | W19: 34665 | X19: 33820 | Y19: 31629 | Z19: 29038 | AA19: =SUM(C19:Z19) -> 966187 | AB19: 20 | AC19: =+AA19*AB19 -> 19323740 | AD19: =+SUM(AC19:AC22) -> 27760442
B20: Sábado | C20: 39981 | D20: 38014 | E20: 36544 | F20: 35219 | G20: 34747 | H20: 34334 | I20: 35612 | J20: 37290 | K20: 41393 | L20: 43989 | M20: 46288 | N20: 47213 | O20: 45404 | P20: 45786 | Q20: 47274 | R20: 47540 | S20: 46053 | T20: 32108 | U20: 33484 | V20: 32675 | W20: 31752 | X20: 30731 | Y20: 29515 | Z20: 28020 | AA20: =SUM(C20:Z20) -> 920966 | AB20: 4 | AC20: =+AA20*AB20 -> 3683864
B21: Domingo | C21: 39899 | D21: 37653 | E21: 36012 | F21: 34742 | G21: 33934 | H21: 32997 | I21: 33084 | J21: 32296 | K21: 33691 | L21: 35057 | M21: 36139 | N21: 37645 | O21: 38191 | P21: 38586 | Q21: 39691 | R21: 40354 | S21: 39971 | T21: 27676 | U21: 29849 | V21: 30728 | W21: 30168 | X21: 30040 | Y21: 28544 | Z21: 26220 | AA21: =SUM(C21:Z21) -> 823167 | AB21: 4 | AC21: =+AA21*AB21 -> 3292668
B22: Festivo | C22: 37378 | D22: 35313 | E22: 33780 | F22: 32639 | G22: 31802 | H22: 30879 | I22: 31062 | J22: 29297 | K22: 29446 | L22: 29885 | M22: 30425 | N22: 31706 | O22: 32426 | P22: 32795 | Q22: 33886 | R22: 34189 | S22: 33738 | T22: 23686 | U22: 25934 | V22: 26790 | W22: 26399 | X22: 26292 | Y22: 25789 | Z22: 24549 | AA22: =SUM(C22:Z22) -> 730085 | AB22: 2 | AC22: =+AA22*AB22 -> 1460170
A23: 46143 | B23: Hábil | C23: 39885 | D23: 37867 | E23: 36298 | F23: 35183 | G23: 34853 | H23: 34862 | I23: 35908 | J23: 37946 | K23: 41932 | L23: 44653 | M23: 47053 | N23: 47669 | O23: 44273 | P23: 48865 | Q23: 53707 | R23: 53954 | S23: 52271 | T23: 35045 | U23: 34369 | V23: 34106 | W23: 34382 | X23: 33955 | Y23: 32065 | Z23: 29627 | AA23: =SUM(C23:Z23) -> 960728 | AB23: 19 | AC23: =+AA23*AB23 -> 18253832 | AD23: =+SUM(AC23:AC26) -> 28373867
B24: Sábado | C24: 40646 | D24: 38298 | E24: 36467 | F24: 35207 | G24: 34575 | H24: 33520 | I24: 35130 | J24: 36816 | K24: 41070 | L24: 44151 | M24: 46488 | N24: 47072 | O24: 45240 | P24: 45823 | Q24: 47234 | R24: 46808 | S24: 45226 | T24: 30691 | U24: 31707 | V24: 31791 | W24: 30972 | X24: 30416 | Y24: 29588 | Z24: 27879 | AA24: =SUM(C24:Z24) -> 912815 | AB24: 5 | AC24: =+AA24*AB24 -> 4564075
B25: Domingo | C25: 39303 | D25: 37437 | E25: 35899 | F25: 34644 | G25: 33797 | H25: 32192 | I25: 32778 | J25: 31994 | K25: 33173 | L25: 34542 | M25: 35837 | N25: 36680 | O25: 36480 | P25: 36481 | Q25: 37786 | R25: 38299 | S25: 38004 | T25: 26693 | U25: 28502 | V25: 29350 | W25: 29780 | X25: 30317 | Y25: 29392 | Z25: 27488 | AA25: =SUM(C25:Z25) -> 806848 | AB25: 5 | AC25: =+AA25*AB25 -> 4034240
B26: Festivo | C26: 34678 | D26: 32822 | E26: 31456 | F26: 30395 | G26: 29875 | H26: 28639 | I26: 29602 | J26: 29226 | K26: 31009 | L26: 32991 | M26: 34688 | N26: 35935 | O26: 35889 | P26: 36567 | Q26: 37526 | R26: 37937 | S26: 37082 | T26: 24963 | U26: 27231 | V26: 29165 | W26: 29811 | X26: 29881 | Y26: 28038 | Z26: 25454 | AA26: =SUM(C26:Z26) -> 760860 | AB26: 2 | AC26: =+AA26*AB26 -> 1521720
A27: 46174 | B27: Hábil | C27: 41789 | D27: 39664 | E27: 37982 | F27: 36874 | G27: 36520 | H27: 36337 | I27: 38048 | J27: 40608 | K27: 44754 | L27: 47328 | M27: 49698 | N27: 50631 | O27: 46803 | P27: 51004 | Q27: 55402 | R27: 55849 | S27: 54411 | T27: 35690 | U27: 35348 | V27: 35269 | W27: 35211 | X27: 34714 | Y27: 32959 | Z27: 30546 | AA27: =SUM(C27:Z27) -> 1003439 | AB27: 19 | AC27: =+AA27*AB27 -> 19065341 | AD27: =+SUM(AC27:AC30) -> 28775725
B28: Sábado | C28: 41690 | D28: 39621 | E28: 38004 | F28: 36752 | G28: 36320 | H28: 35350 | I28: 37111 | J28: 39502 | K28: 43505 | L28: 46140 | M28: 48108 | N28: 48599 | O28: 46321 | P28: 46484 | Q28: 48783 | R28: 49365 | S28: 47904 | T28: 32927 | U28: 33956 | V28: 33495 | W28: 32753 | X28: 31962 | Y28: 30952 | Z28: 29444 | AA28: =SUM(C28:Z28) -> 955048 | AB28: 4 | AC28: =+AA28*AB28 -> 3820192
B29: Domingo | C29: 41545 | D29: 39717 | E29: 38192 | F29: 36860 | G29: 36121 | H29: 34490 | I29: 34979 | J29: 34330 | K29: 35111 | L29: 36920 | M29: 37430 | N29: 38288 | O29: 38734 | P29: 38990 | Q29: 40089 | R29: 40785 | S29: 40686 | T29: 27825 | U29: 29765 | V29: 31271 | W29: 31726 | X29: 32479 | Y29: 31804 | Z29: 30257 | AA29: =SUM(C29:Z29) -> 858394 | AB29: 4 | AC29: =+AA29*AB29 -> 3433576
B30: Festivo | C30: 37231 | D30: 35422 | E30: 34086 | F30: 32973 | G30: 32485 | H30: 31308 | I30: 32261 | J30: 32753 | K30: 35257 | L30: 37748 | M30: 39402 | N30: 40242 | O30: 39633 | P30: 39834 | Q30: 40635 | R30: 40615 | S30: 39512 | T30: 25910 | U30: 27589 | V30: 29833 | W30: 29845 | X30: 29763 | Y30: 28352 | Z30: 26183 | AA30: =SUM(C30:Z30) -> 818872 | AB30: 3 | AC30: =+AA30*AB30 -> 2456616
A31: 46204 | B31: Hábil | C31: 39220 | D31: 37153 | E31: 35653 | F31: 34432 | G31: 34042 | H31: 34242 | I31: 35481 | J31: 37438 | K31: 41446 | L31: 44011 | M31: 46372 | N31: 46685 | O31: 42892 | P31: 46836 | Q31: 51098 | R31: 51477 | S31: 49800 | T31: 32507 | U31: 32037 | V31: 32397 | W31: 32683 | X31: 32279 | Y31: 30532 | Z31: 28181 | AA31: =SUM(C31:Z31) -> 928894 | AB31: 22 | AC31: =+AA31*AB31 -> 20435668 | AD31: =+SUM(AC31:AC34) -> 27971551
B32: Sábado | C32: 38033 | D32: 36212 | E32: 34811 | F32: 33698 | G32: 33359 | H32: 32594 | I32: 33820 | J32: 35458 | K32: 39120 | L32: 41760 | M32: 43495 | N32: 44437 | O32: 42558 | P32: 43172 | Q32: 45077 | R32: 45035 | S32: 43332 | T32: 28344 | U32: 29909 | V32: 30913 | W32: 30116 | X32: 29849 | Y32: 29403 | Z32: 28305 | AA32: =SUM(C32:Z32) -> 872810 | AB32: 4 | AC32: =+AA32*AB32 -> 3491240
B33: Domingo | C33: 40236 | D33: 38329 | E33: 36645 | F33: 35396 | G33: 34535 | H33: 33160 | I33: 33540 | J33: 31788 | K33: 32829 | L33: 34528 | M33: 35290 | N33: 35872 | O33: 36371 | P33: 36806 | Q33: 37501 | R33: 38292 | S33: 38016 | T33: 27305 | U33: 29042 | V33: 30554 | W33: 30861 | X33: 31230 | Y33: 30346 | Z33: 28724 | AA33: =SUM(C33:Z33) -> 817196 | AB33: 4 | AC33: =+AA33*AB33 -> 3268784
B34: Festivo | C34: 37063 | D34: 35105 | E34: 33539 | F34: 32580 | G34: 32019 | H34: 31076 | I34: 31580 | J34: 31202 | K34: 32949 | L34: 34796 | M34: 36086 | N34: 36668 | O34: 35989 | P34: 36730 | Q34: 37591 | R34: 37986 | S34: 37136 | T34: 24410 | U34: 26460 | V34: 28245 | W34: 28286 | X34: 27815 | Y34: 26229 | Z34: 24319 | AA34: =SUM(C34:Z34) -> 775859 | AB34: 1 | AC34: =+AA34*AB34 -> 775859
A35: 46235 | B35: Hábil | C35: 40968 | D35: 38760 | E35: 37135 | F35: 35858 | G35: 35399 | H35: 35416 | I35: 36446 | J35: 38650 | K35: 42372 | L35: 45321 | M35: 47650 | N35: 48327 | O35: 44507 | P35: 49153 | Q35: 54075 | R35: 54509 | S35: 52988 | T35: 34573 | U35: 34183 | V35: 34670 | W35: 35095 | X35: 35119 | Y35: 33250 | Z35: 31017 | AA35: =SUM(C35:Z35) -> 975441 | AB35: 19 | AC35: =+AA35*AB35 -> 18533379 | AD35: =+SUM(AC35:AC38) -> 29060343
B36: Sábado | C36: 44120 | D36: 41738 | E36: 39857 | F36: 38362 | G36: 37607 | H36: 36466 | I36: 37463 | J36: 39537 | K36: 43087 | L36: 46175 | M36: 47718 | N36: 48991 | O36: 46415 | P36: 47132 | Q36: 48835 | R36: 48785 | S36: 47576 | T36: 32465 | U36: 34032 | V36: 34150 | W36: 33404 | X36: 33748 | Y36: 33272 | Z36: 32077 | AA36: =SUM(C36:Z36) -> 973012 | AB36: 5 | AC36: =+AA36*AB36 -> 4865060
B37: Domingo | C37: 42201 | D37: 40079 | E37: 38358 | F37: 36960 | G37: 35854 | H37: 33971 | I37: 33907 | J37: 32927 | K37: 33633 | L37: 34384 | M37: 35541 | N37: 35608 | O37: 36290 | P37: 37722 | Q37: 38385 | R37: 39140 | S37: 37859 | T37: 25829 | U37: 28180 | V37: 29115 | W37: 29485 | X37: 30225 | Y37: 29301 | Z37: 27660 | AA37: =SUM(C37:Z37) -> 822614 | AB37: 5 | AC37: =+AA37*AB37 -> 4113070
B38: Festivo | C38: 34791 | D38: 33270 | E38: 31936 | F38: 31103 | G38: 30653 | H38: 29902 | I38: 30107 | J38: 29677 | K38: 31439 | L38: 33957 | M38: 35600 | N38: 36863 | O38: 36790 | P38: 37414 | Q38: 38358 | R38: 38934 | S38: 38006 | T38: 24130 | U38: 26817 | V38: 28973 | W38: 29419 | X38: 30554 | Y38: 29362 | Z38: 26362 | AA38: =SUM(C38:Z38) -> 774417 | AB38: 2 | AC38: =+AA38*AB38 -> 1548834
A39: 46266 | B39: Hábil | C39: 42678 | D39: 40251 | E39: 38434 | F39: 37012 | G39: 36467 | H39: 36504 | I39: 37733 | J39: 40145 | K39: 43990 | L39: 47028 | M39: 49568 | N39: 50255 | O39: 46661 | P39: 51664 | Q39: 56120 | R39: 56412 | S39: 54414 | T39: 36218 | U39: 36425 | V39: 35970 | W39: 36297 | X39: 36208 | Y39: 34411 | Z39: 31630 | AA39: =SUM(C39:Z39) -> 1012495 | AB39: 22 | AC39: =+AA39*AB39 -> 22274890 | AD39: =+SUM(AC39:AC42) -> 29703314
B40: Sábado | C40: 42960 | D40: 40770 | E40: 39043 | F40: 37701 | G40: 37017 | H40: 35868 | I40: 37368 | J40: 39849 | K40: 44133 | L40: 46822 | M40: 49072 | N40: 50068 | O40: 47646 | P40: 48652 | Q40: 50649 | R40: 50717 | S40: 49068 | T40: 34625 | U40: 36254 | V40: 35297 | W40: 34286 | X40: 33882 | Y40: 32936 | Z40: 31612 | AA40: =SUM(C40:Z40) -> 986295 | AB40: 4 | AC40: =+AA40*AB40 -> 3945180
B41: Domingo | C41: 42591 | D41: 40570 | E41: 39034 | F41: 37769 | G41: 36782 | H41: 35506 | I41: 35845 | J41: 34712 | K41: 35445 | L41: 36218 | M41: 37661 | N41: 38774 | O41: 38514 | P41: 39430 | Q41: 41178 | R41: 41642 | S41: 41018 | T41: 28769 | U41: 31028 | V41: 31977 | W41: 32440 | X41: 32793 | Y41: 31553 | Z41: 29562 | AA41: =SUM(C41:Z41) -> 870811 | AB41: 4 | AC41: =+AA41*AB41 -> 3483244
B42: Festivo | C42: 0 | D42: 0 | E42: 0 | F42: 0 | G42: 0 | H42: 0 | I42: 0 | J42: 0 | K42: 0 | L42: 0 | M42: 0 | N42: 0 | O42: 0 | P42: 0 | Q42: 0 | R42: 0 | S42: 0 | T42: 0 | U42: 0 | V42: 0 | W42: 0 | X42: 0 | Y42: 0 | Z42: 0 | AA42: =SUM(C42:Z42) -> 0 | AB42: 0 | AC42: =+AA42*AB42 -> 0
...

Sheet OF P2
C1: * La energia a ofertar debe ser expresada únicamente en kilovatio (kWh) redondeado a cero decimales
C4: OFERTA PRODUCTO 2
C5: MES | D5: ENERGIA SOLICITADA (KWh) | E5: % | F5: ENERGIA OFERTADA (KWh) | G5: PRECIO $/kWh
C6: 46388 | D6: =+VLOOKUP(C6,'CURVA P2'!$A$4:$AD$55,30,FALSE) -> 26183284 | E6: % | G6: $/kWh
C7: 46419 | D7: =+VLOOKUP(C7,'CURVA P2'!$A$4:$AD$55,30,FALSE) -> 27076744
C8: 46447 | D8: =+VLOOKUP(C8,'CURVA P2'!$A$4:$AD$55,30,FALSE) -> 26175253
C9: 46478 | D9: =+VLOOKUP(C9,'CURVA P2'!$A$4:$AD$55,30,FALSE) -> 27329640
C10: 46508 | D10: =+VLOOKUP(C10,'CURVA P2'!$A$4:$AD$55,30,FALSE) -> 27682621
C11: 46539 | D11: =+VLOOKUP(C11,'CURVA P2'!$A$4:$AD$55,30,FALSE) -> 28239251
C12: 46569 | D12: =+VLOOKUP(C12,'CURVA P2'!$A$4:$AD$55,30,FALSE) -> 24946557
C13: 46600 | D13: =+VLOOKUP(C13,'CURVA P2'!$A$4:$AD$55,30,FALSE) -> 26544363
C14: 46631 | D14: =+VLOOKUP(C14,'CURVA P2'!$A$4:$AD$55,30,FALSE) -> 27481854
C15: 46661 | D15: =+VLOOKUP(C15,'CURVA P2'!$A$4:$AD$55,30,FALSE) -> 27071840
C16: 46692 | D16: =+VLOOKUP(C16,'CURVA P2'!$A$4:$AD$55,30,FALSE) -> 26729030
C17: 46722 | D17: =+VLOOKUP(C17,'CURVA P2'!$A$4:$AD$55,30,FALSE) -> 25768675
D18: =SUM(D6:D17) -> 321229112

Sheet CURVA P2
A1: Curva de distribucion en kwh
A2: * La energia a ofertar debe ser expresada únicamente en kilovatio (kWh) redondeado a cero decimales
A4: TOTAL | C4: =+AD55 -> 321229112
A5: MES | B5: DÍA | C5: HORA 01 | D5: HORA 02 | E5: HORA 03 | F5: HORA 04 | G5: HORA 05 | H5: HORA 06 | I5: HORA 07 | J5: HORA 08 | K5: HORA 09 | L5: HORA 10 | M5: HORA 11 | N5: HORA 12 | O5: HORA 13 | P5: HORA 14 | Q5: HORA 15 | R5: HORA 16 | S5: HORA 17 | T5: HORA 18 | U5: HORA 19 | V5: HORA 20 | W5: HORA 21 | X5: HORA 22 | Y5: HORA 23 | Z5: HORA 24 | AA5: TOTAL DÍA | AB5: NUMERO DÍAS | AC5: TOTAL DÍA MES | AD5: TOTAL MES
A7: 46388 | B7: Hábil | C7: 40227 | D7: 38779 | E7: 37353 | F7: 36304 | G7: 35978 | H7: 36610 | I7: 37571 | J7: 23640 | K7: 27146 | L7: 29695 | M7: 31892 | N7: 33200 | O7: 31024 | P7: 33744 | Q7: 37342 | R7: 37978 | S7: 36844 | T7: 43998 | U7: 45229 | V7: 44426 | W7: 43550 | X7: 42485 | Y7: 40439 | Z7: 37701 | AA7: =SUM(C7:Z7) -> 883155 | AB7: 19 | AC7: =+AA7*AB7 -> 16779945 | AD7: =+SUM(AC7:AC10) -> 26183284
B8: Sábado | C8: 41175 | D8: 39486 | E8: 37870 | F8: 36692 | G8: 36198 | H8: 36403 | I8: 36994 | J8: 22827 | K8: 26535 | L8: 29139 | M8: 31075 | N8: 32039 | O8: 30692 | P8: 31206 | Q8: 32591 | R8: 32745 | S8: 31565 | T8: 40905 | U8: 43588 | V8: 43106 | W8: 41927 | X8: 40785 | Y8: 39317 | Z8: 37291 | AA8: =SUM(C8:Z8) -> 852151 | AB8: 5 | AC8: =+AA8*AB8 -> 4260755
B9: Domingo | C9: 40654 | D9: 39109 | E9: 37570 | F9: 36361 | G9: 35666 | H9: 35321 | I9: 35235 | J9: 18777 | K9: 20139 | L9: 21735 | M9: 22717 | N9: 23633 | O9: 24137 | P9: 24368 | Q9: 24976 | R9: 25426 | S9: 25049 | T9: 35905 | U9: 39161 | V9: 39986 | W9: 39859 | X9: 39387 | Y9: 37827 | Z9: 35444 | AA9: =SUM(C9:Z9) -> 758442 | AB9: 5 | AC9: =+AA9*AB9 -> 3792210
B10: Festivo | C10: 35315 | D10: 34367 | E10: 33680 | F10: 32903 | G10: 32522 | H10: 32181 | I10: 31716 | J10: 15031 | K10: 16210 | L10: 17782 | M10: 19176 | N10: 20081 | O10: 20516 | P10: 20953 | Q10: 21491 | R10: 21802 | S10: 21158 | T10: 33234 | U10: 36729 | V10: 37283 | W10: 36962 | X10: 36264 | Y10: 34850 | Z10: 32981 | AA10: =SUM(C10:Z10) -> 675187 | AB10: 2 | AC10: =+AA10*AB10 -> 1350374
A11: 46419 | B11: Hábil | C11: 44237 | D11: 42125 | E11: 40625 | F11: 39645 | G11: 39658 | H11: 41620 | I11: 43304 | J11: 29848 | K11: 33433 | L11: 35976 | M11: 38320 | N11: 38720 | O11: 35003 | P11: 39214 | Q11: 43593 | R11: 44346 | S11: 42974 | T11: 48334 | U11: 48925 | V11: 48666 | W11: 47984 | X11: 46495 | Y11: 43433 | Z11: 40014 | AA11: =SUM(C11:Z11) -> 996492 | AB11: 20 | AC11: =+AA11*AB11 -> 19929840 | AD11: =+SUM(AC11:AC14) -> 27076744
B12: Sábado | C12: 43058 | D12: 41032 | E12: 39572 | F12: 38610 | G12: 38237 | H12: 38849 | I12: 40350 | J12: 27261 | K12: 31394 | L12: 34154 | M12: 36092 | N12: 36856 | O12: 34872 | P12: 35077 | Q12: 36396 | R12: 36574 | S12: 35219 | T12: 43288 | U12: 45859 | V12: 46078 | W12: 44862 | X12: 43549 | Y12: 41838 | Z12: 39578 | AA12: =SUM(C12:Z12) -> 928655 | AB12: 4 | AC12: =+AA12*AB12 -> 3714620
B13: Domingo | C13: 44001 | D13: 41859 | E13: 40341 | F13: 39102 | G13: 38454 | H13: 38277 | I13: 38561 | J13: 22651 | K13: 24215 | L13: 26139 | M13: 27321 | N13: 28448 | O13: 28865 | P13: 28961 | Q13: 29815 | R13: 30558 | S13: 30289 | T13: 40041 | U13: 43269 | V13: 44880 | W13: 45059 | X13: 44714 | Y13: 42627 | Z13: 39624 | AA13: =SUM(C13:Z13) -> 858071 | AB13: 4 | AC13: =+AA13*AB13 -> 3432284
B14: Festivo | C14: 0 | D14: 0 | E14: 0 | F14: 0 | G14: 0 | H14: 0 | I14: 0 | J14: 0 | K14: 0 | L14: 0 | M14: 0 | N14: 0 | O14: 0 | P14: 0 | Q14: 0 | R14: 0 | S14: 0 | T14: 0 | U14: 0 | V14: 0 | W14: 0 | X14: 0 | Y14: 0 | Z14: 0 | AA14: =SUM(C14:Z14) -> 0 | AB14: 0 | AC14: =+AA14*AB14 -> 0
A15: 46447 | B15: Hábil | C15: 40470 | D15: 38469 | E15: 37080 | F15: 36076 | G15: 35980 | H15: 37292 | I15: 38078 | J15: 24228 | K15: 27384 | L15: 29561 | M15: 31563 | N15: 32161 | O15: 29253 | P15: 33063 | Q15: 37052 | R15: 37657 | S15: 36558 | T15: 43123 | U15: 43880 | V15: 43805 | W15: 43488 | X15: 42545 | Y15: 40108 | Z15: 37145 | AA15: =SUM(C15:Z15) -> 876019 | AB15: 20 | AC15: =+AA15*AB15 -> 17520380 | AD15: =+SUM(AC15:AC18) -> 26175253
B16: Sábado | C16: 41476 | D16: 39408 | E16: 37900 | F16: 36677 | G16: 36106 | H16: 36193 | I16: 37025 | J16: 23529 | K16: 27045 | L16: 29425 | M16: 31285 | N16: 31824 | O16: 29942 | P16: 30376 | Q16: 31834 | R16: 32083 | S16: 31028 | T16: 40153 | U16: 42465 | V16: 42563 | W16: 41792 | X16: 41040 | Y16: 39926 | Z16: 38060 | AA16: =SUM(C16:Z16) -> 849155 | AB16: 4 | AC16: =+AA16*AB16 -> 3396620
B17: Domingo | C17: 41854 | D17: 39809 | E17: 38361 | F17: 37184 | G17: 36452 | H17: 35961 | I17: 35710 | J17: 19358 | K17: 20483 | L17: 21699 | M17: 22352 | N17: 23306 | O17: 23932 | P17: 24296 | Q17: 25210 | R17: 25842 | S17: 25594 | T17: 36134 | U17: 39060 | V17: 40707 | W17: 41143 | X17: 41061 | Y17: 39082 | Z17: 36491 | AA17: =SUM(C17:Z17) -> 771081 | AB17: 4 | AC17: =+AA17*AB17 -> 3084324
B18: Festivo | C18: 36563 | D18: 34504 | E18: 33202 | F18: 32312 | G18: 31933 | H18: 31772 | I18: 32294 | J18: 17299 | K18: 19382 | L18: 21530 | M18: 23416 | N18: 24685 | O18: 24223 | P18: 25000 | Q18: 25513 | R18: 25362 | S18: 24500 | T18: 34741 | U18: 38101 | V18: 39709 | W18: 39798 | X18: 38998 | Y18: 36326 | Z18: 33480 | AA18: =SUM(C18:Z18) -> 724643 | AB18: 3 | AC18: =+AA18*AB18 -> 2173929
A19: 46478 | B19: Hábil | C19: 41990 | D19: 39893 | E19: 38461 | F19: 37451 | G19: 37386 | H19: 38110 | I19: 39321 | J19: 26236 | K19: 30148 | L19: 32697 | M19: 35148 | N19: 36031 | O19: 32660 | P19: 36560 | Q19: 41010 | R19: 41460 | S19: 39955 | T19: 46007 | U19: 46707 | V19: 46362 | W19: 45936 | X19: 44830 | Y19: 42288 | Z19: 39063 | AA19: =SUM(C19:Z19) -> 935710 | AB19: 22 | AC19: =+AA19*AB19 -> 20585620 | AD19: =+SUM(AC19:AC22) -> 27329640
B20: Sábado | C20: 42708 | D20: 40646 | E20: 39124 | F20: 37899 | G20: 37428 | H20: 36915 | I20: 38174 | J20: 24704 | K20: 28827 | L20: 31449 | M20: 33524 | N20: 34429 | O20: 32676 | P20: 33119 | Q20: 34507 | R20: 34572 | S20: 33105 | T20: 42078 | U20: 44254 | V20: 43730 | W20: 42702 | X20: 41579 | Y20: 40139 | Z20: 38245 | AA20: =SUM(C20:Z20) -> 886533 | AB20: 4 | AC20: =+AA20*AB20 -> 3546132
B21: Domingo | C21: 42769 | D21: 40544 | E21: 38921 | F21: 37646 | G21: 36887 | H21: 35911 | I21: 36113 | J21: 20254 | K21: 21707 | L21: 23202 | M21: 24328 | N21: 25738 | O21: 26204 | P21: 26544 | Q21: 27492 | R21: 27970 | S21: 27466 | T21: 37659 | U21: 40630 | V21: 41835 | W21: 41588 | X21: 41422 | Y21: 39678 | Z21: 36964 | AA21: =SUM(C21:Z21) -> 799472 | AB21: 4 | AC21: =+AA21*AB21 -> 3197888
B22: Festivo | C22: 0 | D22: 0 | E22: 0 | F22: 0 | G22: 0 | H22: 0 | I22: 0 | J22: 0 | K22: 0 | L22: 0 | M22: 0 | N22: 0 | O22: 0 | P22: 0 | Q22: 0 | R22: 0 | S22: 0 | T22: 0 | U22: 0 | V22: 0 | W22: 0 | X22: 0 | Y22: 0 | Z22: 0 | AA22: =SUM(C22:Z22) -> 0 | AB22: 0 | AC22: =+AA22*AB22 -> 0
A23: 46508 | B23: Hábil | C23: 42836 | D23: 40804 | E23: 39277 | F23: 38201 | G23: 37910 | H23: 37775 | I23: 39081 | J23: 26207 | K23: 30367 | L23: 33086 | M23: 35426 | N23: 36147 | O23: 32844 | P23: 36864 | Q23: 41231 | R23: 41394 | S23: 39743 | T23: 45819 | U23: 45919 | V23: 45831 | W23: 45840 | X23: 45046 | Y23: 42700 | Z23: 39640 | AA23: =SUM(C23:Z23) -> 939988 | AB23: 19 | AC23: =+AA23*AB23 -> 17859772 | AD23: =+SUM(AC23:AC26) -> 27682621
B24: Sábado | C24: 44039 | D24: 41722 | E24: 39985 | F24: 38694 | G24: 38125 | H24: 37057 | I24: 38506 | J24: 25149 | K24: 29482 | L24: 32434 | M24: 34550 | N24: 35135 | O24: 33222 | P24: 33693 | Q24: 34910 | R24: 34700 | S24: 33130 | T24: 41334 | U24: 43242 | V24: 43492 | W24: 42627 | X24: 41853 | Y24: 40650 | Z24: 38669 | AA24: =SUM(C24:Z24) -> 896400 | AB24: 4 | AC24: =+AA24*AB24 -> 3585600
B25: Domingo | C25: 42803 | D25: 40858 | E25: 39335 | F25: 38084 | G25: 37269 | H25: 35645 | I25: 36308 | J25: 20405 | K25: 21758 | L25: 23254 | M25: 24524 | N25: 25401 | O25: 25238 | P25: 25274 | Q25: 26391 | R25: 26723 | S25: 26288 | T25: 36758 | U25: 39523 | V25: 40837 | W25: 41202 | X25: 41453 | Y25: 40140 | Z25: 37756 | AA25: =SUM(C25:Z25) -> 793227 | AB25: 5 | AC25: =+AA25*AB25 -> 3966135
B26: Festivo | C26: 38557 | D26: 36633 | E26: 35247 | F26: 34213 | G26: 33725 | H26: 32577 | I26: 33556 | J26: 18288 | K26: 20260 | L26: 22336 | M26: 24083 | N26: 25273 | O26: 25044 | P26: 25663 | Q26: 26597 | R26: 26831 | S26: 25891 | T26: 35724 | U26: 38787 | V26: 40783 | W26: 41192 | X26: 40919 | Y26: 38838 | Z26: 36021 | AA26: =SUM(C26:Z26) -> 757038 | AB26: 3 | AC26: =+AA26*AB26 -> 2271114
A27: 46539 | B27: Hábil | C27: 44238 | D27: 42101 | E27: 40484 | F27: 39392 | G27: 39090 | H27: 38800 | I27: 40634 | J27: 28146 | K27: 32411 | L27: 35007 | M27: 37306 | N27: 38257 | O27: 34593 | P27: 38346 | Q27: 42442 | R27: 42772 | S27: 41329 | T27: 46747 | U27: 46728 | V27: 46929 | W27: 46621 | X27: 45684 | Y27: 43447 | Z27: 40429 | AA27: =SUM(C27:Z27) -> 971933 | AB27: 21 | AC27: =+AA27*AB27 -> 20410593 | AD27: =+SUM(AC27:AC30) -> 28239251
B28: Sábado | C28: 44595 | D28: 42512 | E28: 40923 | F28: 39722 | G28: 39311 | H28: 38314 | I28: 40069 | J28: 27050 | K28: 31192 | L28: 33847 | M28: 35805 | N28: 36396 | O28: 34188 | P28: 34240 | Q28: 36036 | R28: 36359 | S28: 34931 | T28: 43100 | U28: 44738 | V28: 44904 | W28: 43971 | X28: 42980 | Y28: 41668 | Z28: 39791 | AA28: =SUM(C28:Z28) -> 926642 | AB28: 4 | AC28: =+AA28*AB28 -> 3706568
B29: Domingo | C29: 44388 | D29: 42450 | E29: 40948 | F29: 39697 | G29: 38973 | H29: 37390 | I29: 37981 | J29: 22213 | K29: 23203 | L29: 25033 | M29: 25630 | N29: 26459 | O29: 26751 | P29: 26880 | Q29: 27737 | R29: 28173 | S29: 27991 | T29: 37625 | U29: 40318 | V29: 42375 | W29: 42670 | X29: 42894 | Y29: 41776 | Z29: 39695 | AA29: =SUM(C29:Z29) -> 829250 | AB29: 4 | AC29: =+AA29*AB29 -> 3317000
B30: Festivo | C30: 40584 | D30: 38691 | E30: 37350 | F30: 36259 | G30: 35824 | H30: 34665 | I30: 35645 | J30: 20983 | K30: 23498 | L30: 25942 | M30: 27725 | N30: 28677 | O30: 28066 | P30: 28352 | Q30: 29038 | R30: 28874 | S30: 27728 | T30: 36834 | U30: 39349 | V30: 41860 | W30: 41768 | X30: 41278 | Y30: 39385 | Z30: 36715 | AA30: =SUM(C30:Z30) -> 805090 | AB30: 1 | AC30: =+AA30*AB30 -> 805090
A31: 46569 | B31: Hábil | C31: 38731 | D31: 36645 | E31: 35145 | F31: 33969 | G31: 33607 | H31: 33677 | I31: 35122 | J31: 21432 | K31: 25553 | L31: 28142 | M31: 30414 | N31: 30869 | O31: 27163 | P31: 30797 | Q31: 34799 | R31: 35125 | S31: 33498 | T31: 42904 | U31: 42667 | V31: 43430 | W31: 43427 | X31: 42704 | Y31: 40578 | Z31: 37688 | AA31: =SUM(C31:Z31) -> 838086 | AB31: 20 | AC31: =+AA31*AB31 -> 16761720 | AD31: =+SUM(AC31:AC34) -> 24946557
B32: Sábado | C32: 38102 | D32: 36150 | E32: 34744 | F32: 33616 | G32: 33220 | H32: 32450 | I32: 33767 | J32: 19703 | K32: 23560 | L32: 26197 | M32: 27903 | N32: 28832 | O32: 26887 | P32: 27328 | Q32: 28932 | R32: 28805 | S32: 27224 | T32: 38642 | U32: 40536 | V32: 41744 | W32: 40798 | X32: 40131 | Y32: 39247 | Z32: 37691 | AA32: =SUM(C32:Z32) -> 786209 | AB32: 5 | AC32: =+AA32*AB32 -> 3931045
B33: Domingo | C33: 39568 | D33: 37539 | E33: 35931 | F33: 34737 | G33: 33931 | H33: 32584 | I33: 33001 | J33: 15772 | K33: 17011 | L33: 18572 | M33: 19392 | N33: 20004 | O33: 20440 | P33: 20711 | Q33: 21309 | R33: 21962 | S33: 21542 | T33: 35726 | U33: 38006 | V33: 40147 | W33: 40518 | X33: 40645 | Y33: 39359 | Z33: 37235 | AA33: =SUM(C33:Z33) -> 715642 | AB33: 4 | AC33: =+AA33*AB33 -> 2862568
B34: Festivo | C34: 36831 | D34: 34842 | E34: 33315 | F34: 32337 | G34: 31823 | H34: 30892 | I34: 31540 | J34: 15587 | K34: 17572 | L34: 19481 | M34: 20801 | N34: 21453 | O34: 20685 | P34: 21393 | Q34: 22215 | R34: 22518 | S34: 21614 | T34: 34312 | U34: 36890 | V34: 39455 | W34: 39479 | X34: 38947 | Y34: 37100 | Z34: 34530 | AA34: =SUM(C34:Z34) -> 695612 | AB34: 2 | AC34: =+AA34*AB34 -> 1391224
A35: 46600 | B35: Hábil | C35: 40929 | D35: 38769 | E35: 37153 | F35: 35915 | G35: 35491 | H35: 35502 | I35: 36651 | J35: 23226 | K35: 27151 | L35: 30065 | M35: 32390 | N35: 33146 | O35: 29487 | P35: 33713 | Q35: 38246 | R35: 38572 | S35: 37018 | T35: 45072 | U35: 45073 | V35: 45524 | W35: 45658 | X35: 45199 | Y35: 42934 | Z35: 40071 | AA35: =SUM(C35:Z35) -> 892955 | AB35: 21 | AC35: =+AA35*AB35 -> 18752055 | AD35: =+SUM(AC35:AC38) -> 26544363
B36: Sábado | C36: 43469 | D36: 41136 | E36: 39329 | F36: 37914 | G36: 37183 | H36: 36219 | I36: 37252 | J36: 23587 | K36: 27390 | L36: 30341 | M36: 31956 | N36: 33208 | O36: 30785 | P36: 31418 | Q36: 32900 | R36: 32818 | S36: 31497 | T36: 41960 | U36: 44088 | V36: 44342 | W36: 43378 | X36: 43196 | Y36: 42361 | Z36: 40667 | AA36: =SUM(C36:Z36) -> 878394 | AB36: 3 | AC36: =+AA36*AB36 -> 2635182
B37: Domingo | C37: 42150 | D37: 39990 | E37: 38260 | F37: 36905 | G37: 35880 | H37: 34102 | I37: 34105 | J37: 17616 | K37: 18625 | L37: 19642 | M37: 20776 | N37: 21033 | O37: 21590 | P37: 22687 | Q37: 23293 | R37: 23866 | S37: 22680 | T37: 35302 | U37: 38275 | V37: 39767 | W37: 40214 | X37: 40605 | Y37: 39389 | Z37: 37202 | AA37: =SUM(C37:Z37) -> 743954 | AB37: 5 | AC37: =+AA37*AB37 -> 3719770
B38: Festivo | C38: 36331 | D38: 34642 | E38: 33247 | F38: 32329 | G38: 31869 | H38: 31028 | I38: 31400 | J38: 15533 | K38: 17606 | L38: 20129 | M38: 21844 | N38: 23127 | O38: 22851 | P38: 23419 | Q38: 24327 | R38: 24822 | S38: 23776 | T38: 35122 | U38: 38273 | V38: 40248 | W38: 40381 | X38: 40865 | Y38: 39242 | Z38: 36267 | AA38: =SUM(C38:Z38) -> 718678 | AB38: 2 | AC38: =+AA38*AB38 -> 1437356
A39: 46631 | B39: Hábil | C39: 42873 | D39: 40495 | E39: 38732 | F39: 37366 | G39: 36866 | H39: 36808 | I39: 38164 | J39: 25049 | K39: 29172 | L39: 32208 | M39: 34715 | N39: 35514 | O39: 32015 | P39: 36565 | Q39: 40820 | R39: 41002 | S39: 39014 | T39: 47218 | U39: 47734 | V39: 47048 | W39: 47052 | X39: 46587 | Y39: 44374 | Z39: 41094 | AA39: =SUM(C39:Z39) -> 938485 | AB39: 22 | AC39: =+AA39*AB39 -> 20646670 | AD39: =+SUM(AC39:AC42) -> 27481854
B40: Sábado | C40: 43572 | D40: 41392 | E40: 39671 | F40: 38262 | G40: 37568 | H40: 36518 | I40: 37891 | J40: 24645 | K40: 29012 | L40: 31763 | M40: 34030 | N40: 35000 | O40: 32761 | P40: 33573 | Q40: 35256 | R40: 35139 | S40: 33399 | T40: 44365 | U40: 46745 | V40: 45898 | W40: 44662 | X40: 43899 | Y40: 42808 | Z40: 41109 | AA40: =SUM(C40:Z40) -> 908938 | AB40: 4 | AC40: =+AA40*AB40 -> 3635752
B41: Domingo | C41: 43101 | D41: 41029 | E41: 39447 | F41: 38169 | G41: 37246 | H41: 35940 | I41: 36313 | J41: 19725 | K41: 20711 | L41: 21761 | M41: 23105 | N41: 24285 | O41: 24162 | P41: 24966 | Q41: 26380 | R41: 26657 | S41: 25949 | T41: 38428 | U41: 41630 | V41: 42672 | W41: 43224 | X41: 43525 | Y41: 42009 | Z41: 39424 | AA41: =SUM(C41:Z41) -> 799858 | AB41: 4 | AC41: =+AA41*AB41 -> 3199432
B42: Festivo | C42: 0 | D42: 0 | E42: 0 | F42: 0 | G42: 0 | H42: 0 | I42: 0 | J42: 0 | K42: 0 | L42: 0 | M42: 0 | N42: 0 | O42: 0 | P42: 0 | Q42: 0 | R42: 0 | S42: 0 | T42: 0 | U42: 0 | V42: 0 | W42: 0 | X42: 0 | Y42: 0 | Z42: 0 | AA42: =SUM(C42:Z42) -> 0 | AB42: 0 | AC42: =+AA42*AB42 -> 0
...

Sheet OF P3
C1: * La energia a ofertar debe ser expresada únicamente en kilovatio (kWh) redondeado a cero decimales
C4: OFERTA PRODUCTO 3
C5: MES | D5: ENERGIA SOLICITADA (KWh) | E5: % | F5: ENERGIA OFERTADA (KWh) | G5: PRECIO $/kWh
C6: 46753 | D6: =+VLOOKUP(C6,'CURVA P3'!$A$4:$AD$55,30,FALSE) -> 15559781 | E6: % | G6: $/kWh
C7: 46784 | D7: =+VLOOKUP(C7,'CURVA P3'!$A$4:$AD$55,30,FALSE) -> 16225232
C8: 46813 | D8: =+VLOOKUP(C8,'CURVA P3'!$A$4:$AD$55,30,FALSE) -> 15474282
C9: 46844 | D9: =+VLOOKUP(C9,'CURVA P3'!$A$4:$AD$55,30,FALSE) -> 16558763
C10: 46874 | D10: =+VLOOKUP(C10,'CURVA P3'!$A$4:$AD$55,30,FALSE) -> 16869675
C11: 46905 | D11: =+VLOOKUP(C11,'CURVA P3'!$A$4:$AD$55,30,FALSE) -> 17034818
C12: 46935 | D12: =+VLOOKUP(C12,'CURVA P3'!$A$4:$AD$55,30,FALSE) -> 16155256
C13: 46966 | D13: =+VLOOKUP(C13,'CURVA P3'!$A$4:$AD$55,30,FALSE) -> 17338692
C14: 46997 | D14: =+VLOOKUP(C14,'CURVA P3'!$A$4:$AD$55,30,FALSE) -> 18398718
C15: 47027 | D15: =+VLOOKUP(C15,'CURVA P3'!$A$4:$AD$55,30,FALSE) -> 18051075
C16: 47058 | D16: =+VLOOKUP(C16,'CURVA P3'!$A$4:$AD$55,30,FALSE) -> 17882804
C17: 47088 | D17: =+VLOOKUP(C17,'CURVA P3'!$A$4:$AD$55,30,FALSE) -> 17036252
D18: =SUM(D6:D17) -> 202585348

Sheet CURVA P3
A1: Curva de distribucion en kwh
A2: * La energia a ofertar debe ser expresada únicamente en kilovatio (kWh) redondeado a cero decimales
A4: TOTAL | C4: =+AD55 -> 202585348
A5: MES | B5: DÍA | C5: HORA 01 | D5: HORA 02 | E5: HORA 03 | F5: HORA 04 | G5: HORA 05 | H5: HORA 06 | I5: HORA 07 | J5: HORA 08 | K5: HORA 09 | L5: HORA 10 | M5: HORA 11 | N5: HORA 12 | O5: HORA 13 | P5: HORA 14 | Q5: HORA 15 | R5: HORA 16 | S5: HORA 17 | T5: HORA 18 | U5: HORA 19 | V5: HORA 20 | W5: HORA 21 | X5: HORA 22 | Y5: HORA 23 | Z5: HORA 24 | AA5: TOTAL DÍA | AB5: NUMERO DÍAS | AC5: TOTAL DÍA MES | AD5: TOTAL MES
A7: 46753 | B7: Hábil | C7: 26645 | D7: 25397 | E7: 24296 | F7: 23446 | G7: 23132 | H7: 23454 | I7: 6225 | J7: 8666 | K7: 6924 | L7: 7564 | M7: 8787 | N7: 8883 | O7: 7903 | P7: 12026 | Q7: 18672 | R7: 23311 | S7: 42090 | T7: 35001 | U7: 36071 | V7: 35631 | W7: 35233 | X7: 34566 | Y7: 32890 | Z7: 30588 | AA7: =SUM(C7:Z7) -> 537401 | AB7: 20 | AC7: =+AA7*AB7 -> 10748020 | AD7: =+SUM(AC7:AC10) -> 15559781
B8: Sábado | C8: 26998 | D8: 25576 | E8: 24346 | F8: 23463 | G8: 23018 | H8: 23061 | I8: 5600 | J8: 7748 | K8: 6213 | L8: 6820 | M8: 7776 | N8: 7525 | O8: 7273 | P8: 9304 | Q8: 13956 | R8: 18195 | S8: 37007 | T8: 32335 | U8: 34637 | V8: 34348 | W8: 33477 | X8: 32683 | Y8: 31607 | Z8: 29950 | AA8: =SUM(C8:Z8) -> 502916 | AB8: 4 | AC8: =+AA8*AB8 -> 2011664
B9: Domingo | C9: 26570 | D9: 25266 | E9: 24087 | F9: 23166 | G9: 22627 | H9: 22291 | I9: 4377 | J9: 4171 | K9: 348 | L9: 7 | M9: 87 | N9: 5 | O9: 1261 | P9: 3044 | Q9: 7037 | R9: 11629 | S9: 31168 | T9: 28568 | U9: 31344 | V9: 32199 | W9: 32252 | X9: 32011 | Y9: 30742 | Z9: 28726 | AA9: =SUM(C9:Z9) -> 422983 | AB9: 5 | AC9: =+AA9*AB9 -> 2114915
B10: Festivo | C10: 20997 | D10: 20376 | E10: 19845 | F10: 19297 | G10: 19016 | H10: 18775 | I10: 772 | J10: 5 | K10: 5 | L10: 5 | M10: 5 | N10: 5 | O10: 5 | P10: 5 | Q10: 2515 | R10: 6893 | S10: 26263 | T10: 24786 | U10: 27927 | V10: 28496 | W10: 28172 | X10: 27495 | Y10: 26257 | Z10: 24674 | AA10: =SUM(C10:Z10) -> 342591 | AB10: 2 | AC10: =+AA10*AB10 -> 685182
A11: 46784 | B11: Hábil | C11: 27966 | D11: 26416 | E11: 25292 | F11: 24537 | G11: 24475 | H11: 25647 | I11: 8950 | J11: 12201 | K11: 10153 | L11: 10532 | M11: 11732 | N11: 10809 | O11: 8646 | P11: 14019 | Q11: 21527 | R11: 26485 | S11: 45282 | T11: 37018 | U11: 37428 | V11: 37316 | W11: 37087 | X11: 36132 | Y11: 33895 | Z11: 31231 | AA11: =SUM(C11:Z11) -> 584776 | AB11: 21 | AC11: =+AA11*AB11 -> 12280296 | AD11: =+SUM(AC11:AC14) -> 16225232
B12: Sábado | C12: 26490 | D12: 25121 | E12: 24075 | F12: 23416 | G12: 23187 | H12: 23576 | I12: 6671 | J12: 9719 | K12: 8166 | L12: 8653 | M12: 9496 | N12: 8989 | O12: 8109 | P12: 9882 | Q12: 14719 | R12: 19215 | S12: 38109 | T12: 32958 | U12: 35028 | V12: 35200 | W12: 34423 | X12: 33595 | Y12: 32442 | Z12: 30683 | AA12: =SUM(C12:Z12) -> 521922 | AB12: 4 | AC12: =+AA12*AB12 -> 2087688
B13: Domingo | C13: 27397 | D13: 25863 | E13: 24756 | F13: 23839 | G13: 23358 | H13: 23125 | I13: 5391 | J13: 5692 | K13: 1645 | L13: 1514 | M13: 1780 | N13: 1710 | O13: 3190 | P13: 4840 | Q13: 9155 | R13: 14167 | S13: 33991 | T13: 30638 | U13: 33247 | V13: 34646 | W13: 35047 | X13: 34982 | Y13: 33383 | Z13: 30956 | AA13: =SUM(C13:Z13) -> 464312 | AB13: 4 | AC13: =+AA13*AB13 -> 1857248
B14: Festivo | C14: 0 | D14: 0 | E14: 0 | F14: 0 | G14: 0 | H14: 0 | I14: 0 | J14: 0 | K14: 0 | L14: 0 | M14: 0 | N14: 0 | O14: 0 | P14: 0 | Q14: 0 | R14: 0 | S14: 0 | T14: 0 | U14: 0 | V14: 0 | W14: 0 | X14: 0 | Y14: 0 | Z14: 0 | AB14: 0 | AC14: =+AA14*AB14 -> 0
A15: 46813 | B15: Hábil | C15: 26407 | D15: 24868 | E15: 23768 | F15: 22934 | G15: 22729 | H15: 23316 | I15: 6176 | J15: 8751 | K15: 6673 | L15: 6855 | M15: 7845 | N15: 7246 | O15: 5751 | P15: 10704 | Q15: 17558 | R15: 22109 | S15: 40970 | T15: 33718 | U15: 34358 | V15: 34376 | W15: 34392 | X15: 33931 | Y15: 32265 | Z15: 29959 | AA15: =SUM(C15:Z15) -> 517659 | AB15: 22 | AC15: =+AA15*AB15 -> 11388498 | AD15: =+SUM(AC15:AC18) -> 15474282
B16: Sábado | C16: 27391 | D16: 25786 | E16: 24582 | F16: 23613 | G16: 23104 | H16: 23009 | I16: 5786 | J16: 8208 | K16: 6446 | L16: 6738 | M16: 7612 | N16: 6880 | O16: 6174 | P16: 8228 | Q16: 13000 | R16: 17270 | S16: 36151 | T16: 31765 | U16: 33629 | V16: 33732 | W16: 33213 | X16: 32851 | Y16: 32121 | Z16: 30646 | AA16: =SUM(C16:Z16) -> 497935 | AB16: 4 | AC16: =+AA16*AB16 -> 1991740
B17: Domingo | C17: 27547 | D17: 26070 | E17: 24945 | F17: 24051 | G17: 23473 | H17: 22945 | I17: 4931 | J17: 4475 | K17: 422 | L17: 5 | M17: 5 | N17: 5 | O17: 945 | P17: 2841 | Q17: 7198 | R17: 11836 | S17: 31411 | T17: 28919 | U17: 31189 | V17: 32656 | W17: 33389 | X17: 33697 | Y17: 32288 | Z17: 30126 | AA17: =SUM(C17:Z17) -> 435369 | AB17: 4 | AC17: =+AA17*AB17 -> 1741476
B18: Festivo | C18: 21167 | D18: 19781 | E18: 18891 | F18: 18286 | G18: 17991 | H18: 17917 | I18: 578 | J18: 1519 | K18: 5 | L18: 5 | M18: 5 | N18: 5 | O18: 5 | P18: 1459 | Q18: 5333 | R18: 9386 | S18: 28540 | T18: 25346 | U18: 28119 | V18: 29341 | W18: 29323 | X18: 28614 | Y18: 26570 | Z18: 24382 | AA18: =SUM(C18:Z18) -> 352568 | AB18: 1 | AC18: =+AA18*AB18 -> 352568
A19: 46844 | B19: Hábil | C19: 28276 | D19: 26661 | E19: 25542 | F19: 24725 | G19: 24614 | H19: 25031 | I19: 8126 | J19: 11964 | K19: 10644 | L19: 11155 | M19: 12603 | N19: 12212 | O19: 9991 | P19: 15230 | Q19: 22834 | R19: 27453 | S19: 45995 | T19: 37209 | U19: 37767 | V19: 37595 | W19: 37566 | X19: 36844 | Y19: 34820 | Z19: 32158 | AA19: =SUM(C19:Z19) -> 597015 | AB19: 18 | AC19: =+AA19*AB19 -> 10746270 | AD19: =+SUM(AC19:AC22) -> 16558763
B20: Sábado | C20: 28547 | D20: 26957 | E20: 25828 | F20: 24887 | G20: 24446 | H20: 23973 | I20: 7068 | J20: 10239 | K20: 9060 | L20: 9647 | M20: 10631 | N20: 10451 | O20: 9742 | P20: 11836 | Q20: 16651 | R20: 20906 | S20: 39458 | T20: 33750 | U20: 35531 | V20: 35229 | W20: 34574 | X20: 33835 | Y20: 32735 | Z20: 31121 | AA20: =SUM(C20:Z20) -> 547102 | AB20: 5 | AC20: =+AA20*AB20 -> 2735510
B21: Domingo | C21: 28432 | D21: 26793 | E21: 25600 | F21: 24617 | G21: 24016 | H21: 23185 | I21: 5535 | J21: 6106 | K21: 2283 | L21: 1923 | M21: 2148 | N21: 2230 | O21: 3724 | P21: 5667 | Q21: 10042 | R21: 14641 | S21: 34069 | T21: 30320 | U21: 32881 | V21: 34013 | W21: 34076 | X21: 34134 | Y21: 32743 | Z21: 30389 | AA21: =SUM(C21:Z21) -> 469567 | AB21: 5 | AC21: =+AA21*AB21 -> 2347835
B22: Festivo | C22: 24281 | D22: 22838 | E22: 21809 | F22: 21069 | G22: 20581 | H22: 19862 | I22: 2410 | J22: 2015 | K22: 5 | L22: 5 | M22: 5 | N22: 5 | O22: 5 | P22: 5 | Q22: 3176 | R22: 7486 | S22: 27217 | T22: 25036 | U22: 27868 | V22: 28739 | W22: 28566 | X22: 28277 | Y22: 27397 | Z22: 25917 | AA22: =SUM(C22:Z22) -> 364574 | AB22: 2 | AC22: =+AA22*AB22 -> 729148
A23: 46874 | B23: Hábil | C23: 27992 | D23: 26506 | E23: 25371 | F23: 24586 | G23: 24347 | H23: 24146 | I23: 7378 | J23: 11059 | K23: 9958 | L23: 10620 | M23: 11876 | N23: 11409 | O23: 9412 | P23: 14388 | Q23: 21732 | R23: 25982 | S23: 44374 | T23: 35981 | U23: 36443 | V23: 36510 | W23: 36559 | X23: 35992 | Y23: 34188 | Z23: 31674 | AA23: =SUM(C23:Z23) -> 578483 | AB23: 21 | AC23: =+AA23*AB23 -> 12148143 | AD23: =+SUM(AC23:AC26) -> 16869675
B24: Sábado | C24: 29086 | D24: 27312 | E24: 25958 | F24: 24981 | G24: 24533 | H24: 23767 | I24: 6937 | J24: 9948 | K24: 8987 | L24: 9866 | M24: 10809 | N24: 10097 | O24: 9150 | P24: 11022 | Q24: 15444 | R24: 19506 | S24: 38078 | T24: 32239 | U24: 34224 | V24: 34496 | W24: 33882 | X24: 33320 | Y24: 32379 | Z24: 30812 | AA24: =SUM(C24:Z24) -> 536833 | AB24: 4 | AC24: =+AA24*AB24 -> 2147332
B25: Domingo | C25: 27849 | D25: 26436 | E25: 25355 | F25: 24419 | G25: 23792 | H25: 22643 | I25: 5302 | J25: 5665 | K25: 1845 | L25: 1292 | M25: 1645 | N25: 1290 | O25: 2172 | P25: 3581 | Q25: 7921 | R25: 12243 | S25: 31697 | T25: 28297 | U25: 30901 | V25: 32133 | W25: 32496 | X25: 32726 | Y25: 31669 | Z25: 29681 | AA25: =SUM(C25:Z25) -> 443050 | AB25: 4 | AC25: =+AA25*AB25 -> 1772200
B26: Festivo | C26: 23703 | D26: 22336 | E26: 21362 | F26: 20651 | G26: 20324 | H26: 19558 | I26: 2575 | J26: 3371 | K26: 111 | L26: 208 | M26: 1005 | N26: 917 | O26: 1576 | P26: 3601 | Q26: 7858 | R26: 12133 | S26: 31202 | T26: 27333 | U26: 29930 | V26: 31398 | W26: 31580 | X26: 31216 | Y26: 29599 | Z26: 27453 | AA26: =SUM(C26:Z26) -> 401000 | AB26: 2 | AC26: =+AA26*AB26 -> 802000
A27: 46905 | B27: Hábil | C27: 28794 | D27: 27205 | E27: 26003 | F27: 25192 | G27: 24930 | H27: 24607 | I27: 8177 | J27: 12391 | K27: 11368 | L27: 11857 | M27: 13030 | N27: 12704 | O27: 10282 | P27: 15117 | Q27: 22285 | R27: 26744 | S27: 45441 | T27: 36859 | U27: 37148 | V27: 37418 | W27: 37258 | X27: 36584 | Y27: 34806 | Z27: 32319 | AA27: =SUM(C27:Z27) -> 598519 | AB27: 20 | AC27: =+AA27*AB27 -> 11970380 | AD27: =+SUM(AC27:AC30) -> 17034818
B28: Sábado | C28: 29375 | D28: 27860 | E28: 26637 | F28: 25750 | G28: 25414 | H28: 24648 | I28: 8212 | J28: 11699 | K28: 10471 | L28: 10910 | M28: 11897 | N28: 11287 | O28: 10168 | P28: 11564 | Q28: 16695 | R28: 21237 | S28: 39869 | T28: 34372 | U28: 35822 | V28: 36100 | W28: 35353 | X28: 34694 | Y28: 33707 | Z28: 32201 | AA28: =SUM(C28:Z28) -> 565942 | AB28: 4 | AC28: =+AA28*AB28 -> 2263768
B29: Domingo | C29: 29014 | D29: 27574 | E29: 26465 | F29: 25540 | G29: 25004 | H29: 23817 | I29: 6452 | J29: 7156 | K29: 2775 | L29: 2760 | M29: 2278 | N29: 1990 | O29: 3319 | P29: 5042 | Q29: 9376 | R29: 13970 | S29: 33826 | T29: 30336 | U29: 32836 | V29: 34521 | W29: 34773 | X29: 34999 | Y29: 34191 | Z29: 32475 | AA29: =SUM(C29:Z29) -> 480489 | AB29: 4 | AC29: =+AA29*AB29 -> 1921956
B30: Festivo | C30: 25007 | D30: 23628 | E30: 22672 | F30: 21907 | G30: 21618 | H30: 20802 | I30: 3829 | J30: 5282 | K30: 2355 | L30: 2697 | M30: 3584 | N30: 3364 | O30: 3796 | P30: 5654 | Q30: 9738 | R30: 13786 | S30: 32748 | T30: 28721 | U30: 30982 | V30: 32963 | W30: 32845 | X30: 32284 | Y30: 30654 | Z30: 28441 | AA30: =SUM(C30:Z30) -> 439357 | AB30: 2 | AC30: =+AA30*AB30 -> 878714
A31: 46935 | B31: Hábil | C31: 27699 | D31: 26157 | E31: 25027 | F31: 24154 | G31: 23832 | H31: 23780 | I31: 7196 | J31: 10630 | K31: 9484 | L31: 9962 | M31: 11208 | N31: 10464 | O31: 7985 | P31: 12847 | Q31: 20053 | R31: 24443 | S31: 42699 | T31: 35067 | U31: 35085 | V31: 35897 | W31: 35932 | X31: 35437 | Y31: 33755 | Z31: 31325 | AA31: =SUM(C31:Z31) -> 560118 | AB31: 19 | AC31: =+AA31*AB31 -> 10642242 | AD31: =+SUM(AC31:AC34) -> 16155256
B32: Sábado | C32: 26549 | D32: 25155 | E32: 24141 | F32: 23327 | G32: 23016 | H32: 22497 | I32: 5738 | J32: 8668 | K32: 7212 | L32: 7738 | M32: 8378 | N32: 8182 | O32: 7298 | P32: 9150 | Q32: 14083 | R32: 17891 | S32: 36303 | T32: 31228 | U32: 32942 | V32: 33926 | W32: 33225 | X32: 32641 | Y32: 31844 | Z32: 30455 | AA32: =SUM(C32:Z32) -> 501587 | AB32: 5 | AC32: =+AA32*AB32 -> 2507935
B33: Domingo | C33: 27420 | D33: 25983 | E33: 24874 | F33: 24020 | G33: 23440 | H33: 22530 | I33: 5199 | J33: 5108 | K33: 1237 | L33: 799 | M33: 724 | N33: 74 | O33: 1535 | P33: 3195 | Q33: 7011 | R33: 11746 | S33: 30988 | T33: 28468 | U33: 30520 | V33: 32348 | W33: 32614 | X33: 32681 | Y33: 31627 | Z33: 29946 | AA33: =SUM(C33:Z33) -> 434087 | AB33: 5 | AC33: =+AA33*AB33 -> 2170435
B34: Festivo | C34: 24906 | D34: 23469 | E34: 22395 | F34: 21699 | G34: 21352 | H34: 20716 | I34: 3610 | J34: 4638 | K34: 1574 | L34: 1530 | M34: 1954 | N34: 1454 | O34: 1559 | P34: 3774 | Q34: 8040 | R34: 12442 | S34: 31534 | T34: 27905 | U34: 29857 | V34: 31943 | W34: 31910 | X34: 31429 | Y34: 29908 | Z34: 27724 | AA34: =SUM(C34:Z34) -> 417322 | AB34: 2 | AC34: =+AA34*AB34 -> 834644
A35: 46966 | B35: Hábil | C35: 28662 | D35: 27083 | E35: 25877 | F35: 24940 | G35: 24591 | H35: 24508 | I35: 7837 | J35: 11696 | K35: 10248 | L35: 11098 | M35: 12353 | N35: 11961 | O35: 9504 | P35: 14793 | Q35: 22274 | R35: 26583 | S35: 45028 | T35: 36010 | U35: 36276 | V35: 36672 | W35: 36838 | X35: 36453 | Y35: 34719 | Z35: 32326 | AA35: =SUM(C35:Z35) -> 588330 | AB35: 21 | AC35: =+AA35*AB35 -> 12354930 | AD35: =+SUM(AC35:AC38) -> 17338692
B36: Sábado | C36: 30370 | D36: 28736 | E36: 27389 | F36: 26361 | G36: 25794 | H36: 25072 | I36: 8204 | J36: 11884 | K36: 10349 | L36: 11232 | M36: 11663 | N36: 11965 | O36: 10405 | P36: 12550 | Q36: 17280 | R36: 21364 | S36: 40249 | T36: 33595 | U36: 35501 | V36: 35772 | W36: 35123 | X36: 34848 | Y36: 34144 | Z36: 32737 | AA36: =SUM(C36:Z36) -> 572587 | AB36: 4 | AC36: =+AA36*AB36 -> 2290348
B37: Domingo | C37: 29618 | D37: 28069 | E37: 26836 | F37: 25837 | G37: 24990 | H37: 23697 | I37: 6139 | J37: 6704 | K37: 2507 | L37: 1463 | M37: 1800 | N37: 802 | O37: 2210 | P37: 4664 | Q37: 8440 | R37: 13217 | S37: 31987 | T37: 28266 | U37: 30904 | V37: 32390 | W37: 32751 | X37: 33143 | Y37: 32175 | Z37: 30298 | AA37: =SUM(C37:Z37) -> 458907 | AB37: 4 | AC37: =+AA37*AB37 -> 1835628
B38: Festivo | C38: 24573 | D38: 23323 | E38: 22322 | F38: 21645 | G38: 21319 | H38: 20695 | I38: 3348 | J38: 4412 | K38: 1370 | L38: 1845 | M38: 2636 | N38: 2691 | O38: 3293 | P38: 5274 | Q38: 9501 | R38: 14081 | S38: 33022 | T38: 28108 | U38: 30620 | V38: 31967 | W38: 31913 | X38: 31952 | Y38: 30565 | Z38: 28418 | AA38: =SUM(C38:Z38) -> 428893 | AB38: 2 | AC38: =+AA38*AB38 -> 857786
A39: 46997 | B39: Hábil | C39: 30444 | D39: 28705 | E39: 27378 | F39: 26350 | G39: 25967 | H39: 25921 | I39: 9250 | J39: 13719 | K39: 12385 | L39: 13292 | M39: 14691 | N39: 14208 | O39: 11907 | P39: 17594 | Q39: 25018 | R39: 29501 | S39: 47505 | T39: 38269 | U39: 38987 | V39: 38438 | W39: 38524 | X39: 38170 | Y39: 36353 | Z39: 33712 | AA39: =SUM(C39:Z39) -> 636288 | AB39: 21 | AC39: =+AA39*AB39 -> 13362048 | AD39: =+SUM(AC39:AC42) -> 18398718
B40: Sábado | C40: 30382 | D40: 28841 | E40: 27593 | F40: 26558 | G40: 26077 | H40: 25387 | I40: 8719 | J40: 13088 | K40: 11859 | L40: 12321 | M40: 13596 | N40: 13395 | O40: 12274 | P40: 14614 | Q40: 19622 | R40: 23642 | S40: 42015 | T40: 35602 | U40: 37816 | V40: 37160 | W40: 36278 | X40: 35616 | Y40: 34770 | Z40: 33305 | AA40: =SUM(C40:Z40) -> 600530 | AB40: 5 | AC40: =+AA40*AB40 -> 3002650
B41: Domingo | C41: 30509 | D41: 28995 | E41: 27811 | F41: 26846 | G41: 26216 | H41: 25230 | I41: 7831 | J41: 8700 | K41: 4301 | L41: 3188 | M41: 3654 | N41: 3535 | O41: 4286 | P41: 6691 | Q41: 11492 | R41: 15935 | S41: 35330 | T41: 31188 | U41: 34060 | V41: 34898 | W41: 35448 | X41: 35683 | Y41: 34437 | Z41: 32241 | AA41: =SUM(C41:Z41) -> 508505 | AB41: 4 | AC41: =+AA41*AB41 -> 2034020
B42: Festivo | C42: 0 | D42: 0 | E42: 0 | F42: 0 | G42: 0 | H42: 0 | I42: 0 | J42: 0 | K42: 0 | L42: 0 | M42: 0 | N42: 0 | O42: 0 | P42: 0 | Q42: 0 | R42: 0 | S42: 0 | T42: 0 | U42: 0 | V42: 0 | W42: 0 | X42: 0 | Y42: 0 | Z42: 0 | AB42: 0 | AC42: =+AA42*AB42 -> 0
...

Sheet OF P4
C1: * La energia a ofertar debe ser expresada únicamente en kilovatio (kWh) redondeado a cero decimales
C4: OFERTA PRODUCTO 5
C5: MES | D5: ENERGIA SOLICITADA (KWh) | E5: % | F5: ENERGIA OFERTADA (KWh) | G5: PRECIO $/kWh
C6: 47119 | D6: =+VLOOKUP(C6,'CURVA P4'!$A$4:$AD$55,30,FALSE) -> 35484572 | E6: % | G6: $/kWh
C7: 47150 | D7: =+VLOOKUP(C7,'CURVA P4'!$A$4:$AD$55,30,FALSE) -> 36552052
C8: 47178 | D8: =+VLOOKUP(C8,'CURVA P4'!$A$4:$AD$55,30,FALSE) -> 35263004
C9: 47209 | D9: =+VLOOKUP(C9,'CURVA P4'!$A$4:$AD$55,30,FALSE) -> 36938684
C10: 47239 | D10: =+VLOOKUP(C10,'CURVA P4'!$A$4:$AD$55,30,FALSE) -> 37563901
C11: 47270 | D11: =+VLOOKUP(C11,'CURVA P4'!$A$4:$AD$55,30,FALSE) -> 37841320
C12: 47300 | D12: =+VLOOKUP(C12,'CURVA P4'!$A$4:$AD$55,30,FALSE) -> 36528245
C13: 47331 | D13: =+VLOOKUP(C13,'CURVA P4'!$A$4:$AD$55,30,FALSE) -> 38495261
C14: 47362 | D14: =+VLOOKUP(C14,'CURVA P4'!$A$4:$AD$55,30,FALSE) -> 39826410
C15: 47392 | D15: =+VLOOKUP(C15,'CURVA P4'!$A$4:$AD$55,30,FALSE) -> 39475538
C16: 47423 | D16: =+VLOOKUP(C16,'CURVA P4'!$A$4:$AD$55,30,FALSE) -> 38895632
C17: 47453 | D17: =+VLOOKUP(C17,'CURVA P4'!$A$4:$AD$55,30,FALSE) -> 37752062
D18: =SUM(D6:D17) -> 450616681

Sheet CURVA P4
A1: Curva de distribucion en kwh
A2: * La energia a ofertar debe ser expresada únicamente en kilovatio (kWh) redondeado a cero decimales
A4: TOTAL | C4: =+AD55 -> 450616681
A5: MES | B5: DÍA | C5: HORA 01 | D5: HORA 02 | E5: HORA 03 | F5: HORA 04 | G5: HORA 05 | H5: HORA 06 | I5: HORA 07 | J5: HORA 08 | K5: HORA 09 | L5: HORA 10 | M5: HORA 11 | N5: HORA 12 | O5: HORA 13 | P5: HORA 14 | Q5: HORA 15 | R5: HORA 16 | S5: HORA 17 | T5: HORA 18 | U5: HORA 19 | V5: HORA 20 | W5: HORA 21 | X5: HORA 22 | Y5: HORA 23 | Z5: HORA 24 | AA5: TOTAL DÍA | AB5: NUMERO DÍAS | AC5: TOTAL DÍA MES | AD5: TOTAL MES
A7: 47119 | B7: Hábil | C7: 53586 | D7: 51076 | E7: 49090 | F7: 47632 | G7: 47176 | H7: 48067 | I7: 32722 | J7: 28201 | K7: 28287 | L7: 29841 | M7: 32121 | N7: 32645 | O7: 30512 | P7: 36160 | Q7: 45198 | R7: 50901 | S7: 68414 | T7: 70572 | U7: 72978 | V7: 72161 | W7: 71075 | X7: 69303 | Y7: 65697 | Z7: 60917 | AA7: =SUM(C7:Z7) -> 1194332 | AB7: 21 | AC7: =+AA7*AB7 -> 25080972 | AD7: =+SUM(AC7:AC10) -> 35484572
B8: Sábado | C8: 54879 | D8: 52115 | E8: 49908 | F8: 48277 | G8: 47621 | H8: 47917 | I8: 32003 | J8: 26819 | K8: 26884 | L8: 28345 | M8: 30127 | N8: 30233 | O8: 29471 | P8: 31956 | Q8: 37733 | R8: 42680 | S8: 60226 | T8: 65166 | U8: 70161 | V8: 69876 | W8: 68098 | X8: 66303 | Y8: 63813 | Z8: 60409 | AA8: =SUM(C8:Z8) -> 1141020 | AB8: 4 | AC8: =+AA8*AB8 -> 4564080
B9: Domingo | C9: 54249 | D9: 51660 | E9: 49510 | F9: 47814 | G9: 46849 | H9: 46378 | I9: 29507 | J9: 21274 | K9: 17908 | L9: 18049 | M9: 18442 | N9: 18440 | O9: 20249 | P9: 22300 | Q9: 27100 | R9: 32607 | S9: 51338 | T9: 58178 | U9: 64163 | V9: 65848 | W9: 65631 | X9: 64757 | Y9: 61963 | Z9: 58025 | AA9: =SUM(C9:Z9) -> 1012239 | AB9: 4 | AC9: =+AA9*AB9 -> 4048956
B10: Festivo | C10: 46843 | D10: 45614 | E10: 44511 | F10: 43398 | G10: 42822 | H10: 42333 | I10: 24991 | J10: 16296 | K10: 12440 | L10: 12557 | M10: 13404 | N10: 13400 | O10: 15300 | P10: 17621 | Q10: 22220 | R10: 27465 | S10: 45811 | T10: 54103 | U10: 60573 | V10: 61767 | W10: 61088 | X10: 59676 | Y10: 57138 | Z10: 53911 | AA10: =SUM(C10:Z10) -> 895282 | AB10: 2 | AC10: =+AA10*AB10 -> 1790564
A11: 47150 | B11: Hábil | C11: 58903 | D11: 55883 | E11: 53760 | F11: 52328 | G11: 52269 | H11: 54721 | I11: 40256 | J11: 36120 | K11: 35850 | L11: 37163 | M11: 39500 | N11: 38802 | O11: 34707 | P11: 42546 | Q11: 53197 | R11: 59596 | S11: 77125 | T11: 77736 | U11: 78986 | V11: 78894 | W11: 77933 | X11: 75823 | Y11: 71250 | Z11: 65607 | AA11: =SUM(C11:Z11) -> 1348955 | AB11: 20 | AC11: =+AA11*AB11 -> 26979100 | AD11: =+SUM(AC11:AC14) -> 36552052
B12: Sábado | C12: 57525 | D12: 54622 | E12: 52565 | F12: 51139 | G12: 50670 | H12: 51466 | I12: 36684 | J12: 32661 | K12: 33180 | L12: 34645 | M12: 36403 | N12: 36052 | O12: 34092 | P12: 36390 | Q12: 42881 | R12: 48348 | S12: 65961 | T12: 70001 | U12: 74451 | V12: 74944 | W12: 73098 | X12: 71109 | Y12: 68522 | Z12: 64813 | AA12: =SUM(C12:Z12) -> 1252222 | AB12: 4 | AC12: =+AA12*AB12 -> 5008888
B13: Domingo | C13: 58651 | D13: 55566 | E13: 53424 | F13: 51713 | G13: 50751 | H13: 50461 | I13: 34031 | J13: 26203 | K13: 22494 | L13: 22775 | M13: 23378 | N13: 23503 | O13: 25396 | P13: 27460 | Q13: 32955 | R13: 39204 | S13: 58350 | T13: 64180 | U13: 69686 | V13: 72561 | W13: 72947 | X13: 72419 | Y13: 68899 | Z13: 64009 | AA13: =SUM(C13:Z13) -> 1141016 | AB13: 4 | AC13: =+AA13*AB13 -> 4564064
B14: Festivo | C14: 0 | D14: 0 | E14: 0 | F14: 0 | G14: 0 | H14: 0 | I14: 0 | J14: 0 | K14: 0 | L14: 0 | M14: 0 | N14: 0 | O14: 0 | P14: 0 | Q14: 0 | R14: 0 | S14: 0 | T14: 0 | U14: 0 | V14: 0 | W14: 0 | X14: 0 | Y14: 0 | Z14: 0 | AA14: =SUM(C14:Z14) -> 0 | AB14: 0 | AC14: =+AA14*AB14 -> 0
A15: 47178 | B15: Hábil | C15: 53565 | D15: 50736 | E15: 48779 | F15: 47369 | G15: 47218 | H15: 48845 | I15: 33478 | J15: 29176 | K15: 28843 | L15: 29824 | M15: 31778 | N15: 31412 | O15: 28259 | P15: 35210 | Q15: 44751 | R15: 50427 | S15: 68121 | T15: 69903 | U15: 71550 | V15: 71461 | W15: 70692 | X15: 69009 | Y15: 65261 | Z15: 60339 | AA15: =SUM(C15:Z15) -> 1186006 | AB15: 19 | AC15: =+AA15*AB15 -> 22534114 | AD15: =+SUM(AC15:AC18) -> 35263004
B16: Sábado | C16: 54938 | D16: 51968 | E16: 49872 | F16: 48197 | G16: 47467 | H16: 47627 | I16: 32200 | J16: 28118 | K16: 28105 | L16: 29179 | M16: 30864 | N16: 30258 | O16: 28570 | P16: 30866 | Q16: 36728 | R16: 41814 | S16: 59571 | T16: 64452 | U16: 68747 | V16: 69080 | W16: 67598 | X16: 66098 | Y16: 64041 | Z16: 60944 | AA16: =SUM(C16:Z16) -> 1137302 | AB16: 5 | AC16: =+AA16*AB16 -> 5686510
B17: Domingo | C17: 55125 | D17: 52274 | E17: 50245 | F17: 48600 | G17: 47622 | H17: 47004 | I17: 30020 | J17: 22006 | K17: 18458 | L17: 18183 | M17: 18200 | N17: 18426 | O17: 20309 | P17: 22432 | Q17: 27650 | R17: 33224 | S17: 52088 | T17: 58733 | U17: 63917 | V17: 66538 | W17: 67099 | X17: 66793 | Y17: 63746 | Z17: 59504 | AA17: =SUM(C17:Z17) -> 1028196 | AB17: 4 | AC17: =+AA17*AB17 -> 4112784
B18: Festivo | C18: 49028 | D18: 46155 | E18: 44303 | F18: 43044 | G18: 42407 | H18: 42275 | I18: 26287 | J18: 20072 | K18: 17822 | L18: 18733 | M18: 20271 | N18: 20490 | O18: 20684 | P18: 23433 | Q18: 28220 | R18: 32965 | S18: 50923 | T18: 57092 | U18: 62918 | V18: 65446 | W18: 65373 | X18: 63864 | Y18: 59632 | Z18: 55095 | AA18: =SUM(C18:Z18) -> 976532 | AB18: 3 | AC18: =+AA18*AB18 -> 2929596
A19: 47209 | B19: Hábil | C19: 56152 | D19: 53168 | E19: 51126 | F19: 49694 | G19: 49533 | H19: 50249 | I19: 35319 | J19: 32028 | K19: 32633 | L19: 34177 | M19: 36701 | N19: 36697 | O19: 32971 | P19: 40246 | Q19: 50522 | R19: 56135 | S19: 73330 | T19: 74117 | U19: 75385 | V19: 75042 | W19: 74468 | X19: 72653 | Y19: 68646 | Z19: 63352 | AA19: =SUM(C19:Z19) -> 1274344 | AB19: 21 | AC19: =+AA19*AB19 -> 26761224 | AD19: =+SUM(AC19:AC22) -> 36938684
B20: Sábado | C20: 56907 | D20: 53909 | E20: 51721 | F20: 50076 | G20: 49396 | H20: 48569 | I20: 33607 | J20: 29628 | K20: 30393 | L20: 32056 | M20: 33861 | N20: 33811 | O20: 32426 | P20: 34999 | Q20: 41125 | R20: 46077 | S20: 63321 | T20: 67457 | U20: 71392 | V20: 70946 | W20: 69399 | X20: 67712 | Y20: 65427 | Z20: 62280 | AA20: =SUM(C20:Z20) -> 1196495 | AB20: 4 | AC20: =+AA20*AB20 -> 4785980
B21: Domingo | C21: 57083 | D21: 53973 | E21: 51708 | F21: 49900 | G21: 48867 | H21: 47435 | I21: 31117 | J21: 23708 | K21: 20299 | L21: 20396 | M21: 21087 | N21: 21673 | O21: 23502 | P21: 25786 | Q21: 31186 | R21: 36766 | S21: 55299 | T21: 61121 | U21: 66236 | V21: 68332 | W21: 68343 | X21: 68111 | Y21: 65354 | Z21: 61014 | AA21: =SUM(C21:Z21) -> 1078296 | AB21: 5 | AC21: =+AA21*AB21 -> 5391480
B22: Festivo | C22: 0 | D22: 0 | E22: 0 | F22: 0 | G22: 0 | H22: 0 | I22: 0 | J22: 0 | K22: 0 | L22: 0 | M22: 0 | N22: 0 | O22: 0 | P22: 0 | Q22: 0 | R22: 0 | S22: 0 | T22: 0 | U22: 0 | V22: 0 | W22: 0 | X22: 0 | Y22: 0 | Z22: 0 | AA22: =SUM(C22:Z22) -> 0 | AB22: 0 | AC22: =+AA22*AB22 -> 0
A23: 47239 | B23: Hábil | C23: 56310 | D23: 53483 | E23: 51404 | F23: 49950 | G23: 49577 | H23: 49238 | I23: 34601 | J23: 31558 | K23: 32669 | L23: 34426 | M23: 36774 | N23: 36572 | O23: 32990 | P23: 40013 | Q23: 49945 | R23: 55022 | S23: 71975 | T23: 72495 | U23: 73504 | V23: 73588 | W23: 73341 | X23: 71861 | Y23: 68092 | Z23: 63111 | AA23: =SUM(C23:Z23) -> 1262499 | AB23: 21 | AC23: =+AA23*AB23 -> 26512479 | AD23: =+SUM(AC23:AC26) -> 37563901
B24: Sábado | C24: 58422 | D24: 55224 | E24: 52885 | F24: 51062 | G24: 50325 | H24: 48837 | I24: 33983 | J24: 30085 | K24: 31311 | L24: 33274 | M24: 35097 | N24: 34561 | O24: 32792 | P24: 35114 | Q24: 40706 | R24: 45585 | S24: 62657 | T24: 65962 | U24: 69674 | V24: 70212 | W24: 68955 | X24: 67652 | Y24: 65574 | Z24: 62496 | AA24: =SUM(C24:Z24) -> 1202445 | AB24: 4 | AC24: =+AA24*AB24 -> 4809780
B25: Domingo | C25: 56733 | D25: 53973 | E25: 51883 | F25: 50149 | G25: 49044 | H25: 46787 | I25: 31074 | J25: 23428 | K25: 20118 | L25: 20196 | M25: 21019 | N25: 20965 | O25: 21945 | P25: 23773 | Q25: 29226 | R25: 34427 | S25: 52974 | T25: 58827 | U25: 63801 | V25: 66174 | W25: 66644 | X25: 66719 | Y25: 64465 | Z25: 60581 | AA25: =SUM(C25:Z25) -> 1054925 | AB25: 4 | AC25: =+AA25*AB25 -> 4219700
B26: Festivo | C26: 50969 | D26: 48254 | E26: 46327 | F26: 44928 | G26: 44288 | H26: 42794 | I26: 27490 | J26: 20963 | K26: 18552 | L26: 19468 | M26: 21076 | N26: 21382 | O26: 21995 | P26: 24597 | Q26: 29973 | R26: 35046 | S26: 52924 | T26: 58025 | U26: 63207 | V26: 66068 | W26: 66379 | X26: 65612 | Y26: 62430 | Z26: 58224 | AA26: =SUM(C26:Z26) -> 1010971 | AB26: 2 | AC26: =+AA26*AB26 -> 2021942
A27: 47270 | B27: Hábil | C27: 58310 | D27: 55280 | E27: 53057 | F27: 51528 | G27: 51141 | H27: 50611 | I27: 36608 | J27: 34091 | K27: 35337 | L27: 36948 | M27: 39250 | N27: 39275 | O27: 35146 | P27: 42079 | Q27: 52025 | R27: 57450 | S27: 74729 | T27: 75325 | U27: 75695 | V27: 76293 | W27: 75615 | X27: 73836 | Y27: 70119 | Z27: 65131 | AA27: =SUM(C27:Z27) -> 1314879 | AB27: 19 | AC27: =+AA27*AB27 -> 24982701 | AD27: =+SUM(AC27:AC30) -> 37841320
B28: Sábado | C28: 59294 | D28: 56347 | E28: 54119 | F28: 52470 | G28: 51901 | H28: 50464 | I28: 36245 | J28: 32598 | K28: 33588 | L28: 35264 | M28: 37146 | N28: 36729 | O28: 34673 | P28: 36409 | Q28: 42707 | R28: 47988 | S28: 65313 | T28: 69263 | U28: 72277 | V28: 73183 | W28: 71641 | X28: 70038 | Y28: 67852 | Z28: 64768 | AA28: =SUM(C28:Z28) -> 1252277 | AB28: 5 | AC28: =+AA28*AB28 -> 6261385
B29: Domingo | C29: 58901 | D29: 56064 | E29: 53964 | F29: 52274 | G29: 51265 | H29: 49071 | I29: 33290 | J29: 25888 | K29: 21963 | L29: 22463 | M29: 22365 | N29: 22185 | O29: 23673 | P29: 25559 | Q29: 30742 | R29: 36183 | S29: 55268 | T29: 61053 | U29: 65788 | V29: 69324 | W29: 69595 | X29: 69393 | Y29: 67350 | Z29: 63795 | AA29: =SUM(C29:Z29) -> 1107416 | AB29: 4 | AC29: =+AA29*AB29 -> 4429664
B30: Festivo | C30: 53730 | D30: 50986 | E30: 49097 | F30: 47588 | G30: 47030 | H30: 45420 | I30: 30144 | J30: 24242 | K30: 22417 | L30: 23725 | M30: 25508 | N30: 25658 | O30: 25938 | P30: 28284 | Q30: 33327 | R30: 37992 | S30: 55671 | T30: 60816 | U30: 65350 | V30: 69244 | W30: 68995 | X30: 67834 | Y30: 64585 | Z30: 60204 | AA30: =SUM(C30:Z30) -> 1083785 | AB30: 2 | AC30: =+AA30*AB30 -> 2167570
