Workbook

Sheet Basis
B3: EXPEDIENTE: | D3: CP-CEOC-2025-001
B4: CANTIDAD EN: | D4: kWh
B5: MODALIDAD: | D5: PLC - Pague Lo Contratado
B6: Pesos de: | D6: 45748
B8: PRODUCTOS: | C8: 1
B9: AÑO | C9: 2026
B10: Curva Plana | C10: =1/24 -> 0.041666667
B11: Curva Horaria
B12: MES | C12: Tipo de día | D12: N° días mes | E12: H1 | F12: H2 | G12: H3 | H12: H4 | I12: H5 | J12: H6 | K12: H7 | L12: H8 | M12: H9 | N12: H10 | O12: H11 | P12: H12 | Q12: H13 | R12: H14 | S12: H15 | T12: H16 | U12: H17 | V12: H18 | W12: H19 | X12: H20 | Y12: H21 | Z12: H22 | AA12: H23 | AB12: H24
B13: 44927 | C13: ORD. | D13: 21 | E13: 0.019001807 | F13: 0.015724578 | G13: 0.013880005 | H13: 0.013793242 | I13: 0.017893597 | J13: 0.026334738 | K13: 0.033174491 | L13: 0.033755201 | M13: 0.03764105 | N13: 0.040405931 | O13: 0.043876241 | P13: 0.047992291 | Q13: 0.046808039 | R13: 0.043509924 | S13: 0.043568002 | T13: 0.045478991 | U13: 0.047150818 | V13: 0.059136095 | W13: 0.076418399 | X13: 0.082632005 | Y13: 0.074388348 | Z13: 0.061615699 | AA13: 0.044850157 | AB13: 0.03097035 | AC13: =+SUM(E13:AB13)*D13 -> 21
C14: SAB. | D14: 4 | E14: 0.021689491 | F14: 0.017161159 | G14: 0.015507481 | H14: 0.015252109 | I14: 0.017494435 | J14: 0.023502608 | K14: 0.031307885 | L14: 0.033201632 | M14: 0.038507498 | N14: 0.041713828 | O14: 0.045165509 | P14: 0.048641585 | Q14: 0.048120921 | R14: 0.044490629 | S14: 0.043267251 | T14: 0.043651178 | U14: 0.044759856 | V14: 0.056873245 | W14: 0.074786002 | X14: 0.081495515 | Y14: 0.073641035 | Z14: 0.060361301 | AA14: 0.045327065 | AB14: 0.034080783 | AC14: =+SUM(E14:AB14)*D14 -> 4
C15: DOM. | D15: 5 | E15: 0.015051671 | F15: 0.02238003 | G15: 0.01975765 | H15: 0.018804298 | I15: 0.019321816 | J15: 0.023835999 | K15: 0.028934412 | L15: 0.031397674 | M15: 0.036145685 | N15: 0.039407306 | O15: 0.042427705 | P15: 0.046405931 | Q15: 0.047292099 | R15: 0.043863491 | S15: 0.041906622 | T15: 0.042329663 | U15: 0.044035686 | V15: 0.05695443 | W15: 0.075855718 | X15: 0.08437196 | Y15: 0.076149292 | Z15: 0.061649073 | AA15: 0.046944526 | AB15: 0.034777263 | AC15: =+SUM(E15:AB15)*D15 -> 5
C16: FES. | D16: 1 | E16: 0.015051671 | F16: 0.02238003 | G16: 0.01975765 | H16: 0.018804298 | I16: 0.019321816 | J16: 0.023835999 | K16: 0.028934412 | L16: 0.031397674 | M16: 0.036145685 | N16: 0.039407306 | O16: 0.042427705 | P16: 0.046405931 | Q16: 0.047292099 | R16: 0.043863491 | S16: 0.041906622 | T16: 0.042329663 | U16: 0.044035686 | V16: 0.05695443 | W16: 0.075855718 | X16: 0.08437196 | Y16: 0.076149292 | Z16: 0.061649073 | AA16: 0.046944526 | AB16: 0.034777263 | AC16: =+SUM(E16:AB16)*D16 -> 1
C17: TOTAL | D17: =+SUM(D13:D16) -> 31 | E17: =+SUMPRODUCT(E13:E16,$D13:$D16) -> 0.57610594 | F17: =+SUMPRODUCT(F13:F16,$D13:$D16) -> 0.53314095 | G17: =+SUMPRODUCT(G13:G16,$D13:$D16) -> 0.47205592 | H17: =+SUMPRODUCT(H13:H16,$D13:$D16) -> 0.46349231 | I17: =+SUMPRODUCT(I13:I16,$D13:$D16) -> 0.56167417 | J17: =+SUMPRODUCT(J13:J16,$D13:$D16) -> 0.79005592 | K17: =+SUMPRODUCT(K13:K16,$D13:$D16) -> 0.99550233 | L17: =+SUMPRODUCT(L13:L16,$D13:$D16) -> 1.0300518 | ... AB17: =+SUMPRODUCT(AB13:AB16,$D13:$D16) -> 0.99536405 | AC17: =+SUM(E17:AB17) -> 31
B18: =+EDATE(B13,1) -> 44958 | C18: ORD. | D18: 20 | E18: 0.019312065 | F18: 0.016086855 | G18: 0.014273523 | H18: 0.014191026 | I18: 0.018242634 | J18: 0.026619043 | K18: 0.033398163 | L18: 0.03394894 | M18: 0.037735615 | N18: 0.040444209 | O18: 0.043872988 | P18: 0.047926761 | Q18: 0.046745049 | R18: 0.043507224 | S18: 0.043577469 | T18: 0.045464185 | U18: 0.047122197 | V18: 0.058791631 | W18: 0.075802804 | X18: 0.082010321 | Y18: 0.073878053 | Z18: 0.061270625 | AA18: 0.044734731 | AB18: 0.031043888 | AC18: =+SUM(E18:AB18)*D18 -> 20
C19: SAB. | D19: 4 | E19: 0.021952698 | F19: 0.017511624 | G19: 0.015879558 | H19: 0.015627243 | I19: 0.017840421 | J19: 0.023778268 | K19: 0.031474518 | L19: 0.033386385 | M19: 0.038597725 | N19: 0.041744458 | O19: 0.045152238 | P19: 0.048577176 | Q19: 0.048054803 | R19: 0.044495677 | S19: 0.043284473 | T19: 0.043667307 | U19: 0.04476593 | V19: 0.056554557 | W19: 0.074192853 | X19: 0.080894646 | Y19: 0.073153051 | Z19: 0.060061541 | AA19: 0.045227182 | AB19: 0.034125669 | AC19: =+SUM(E19:AB19)*D19 -> 4
C20: DOM. | D20: 4 | E20: 0.026352118 | F20: 0.022114401 | G20: 0.019579103 | H20: 0.018784522 | I20: 0.018297569 | J20: 0.021441964 | K20: 0.027514899 | L20: 0.031816057 | M20: 0.037135796 | N20: 0.040291587 | O20: 0.042717715 | P20: 0.046506841 | Q20: 0.046769932 | R20: 0.043413376 | S20: 0.041481212 | T20: 0.041777654 | U20: 0.043315162 | V20: 0.055539125 | W20: 0.074545063 | X20: 0.083159001 | Y20: 0.075496552 | Z20: 0.061324227 | AA20: 0.046565132 | AB20: 0.034060993 | AC20: =+SUM(E20:AB20)*D20 -> 4
C21: FES. | D21: 0 | E21: 0.026352118 | F21: 0.022114401 | G21: 0.019579103 | H21: 0.018784522 | I21: 0.018297569 | J21: 0.021441964 | K21: 0.027514899 | L21: 0.031816057 | M21: 0.037135796 | N21: 0.040291587 | O21: 0.042717715 | P21: 0.046506841 | Q21: 0.046769932 | R21: 0.043413376 | S21: 0.041481212 | T21: 0.041777654 | U21: 0.043315162 | V21: 0.055539125 | W21: 0.074545063 | X21: 0.083159001 | Y21: 0.075496552 | Z21: 0.061324227 | AA21: 0.046565132 | AB21: 0.034060993 | AC21: =+SUM(E21:AB21)*D21 -> 0
C22: TOTAL | D22: =+SUM(D18:D21) -> 28 | E22: =+SUMPRODUCT(E18:E21,$D18:$D21) -> 0.57946057 | F22: =+SUMPRODUCT(F18:F21,$D18:$D21) -> 0.4802412 | G22: =+SUMPRODUCT(G18:G21,$D18:$D21) -> 0.4273051 | H22: =+SUMPRODUCT(H18:H21,$D18:$D21) -> 0.42146757 | I22: =+SUMPRODUCT(I18:I21,$D18:$D21) -> 0.50940463 | J22: =+SUMPRODUCT(J18:J21,$D18:$D21) -> 0.71326179 | K22: =+SUMPRODUCT(K18:K21,$D18:$D21) -> 0.90392093 | L22: =+SUMPRODUCT(L18:L21,$D18:$D21) -> 0.93978857 | ... AB22: =+SUMPRODUCT(AB18:AB21,$D18:$D21) -> 0.8936244 | AC22: =+SUM(E22:AB22) -> 28
B23: =+EDATE(B18,1) -> 44986 | C23: ORD. | D23: 22 | E23: 0.052643358 | F23: 0.021954713 | G23: 0.019492126 | H23: 0.018587449 | I23: 0.019085789 | J23: 0.023330656 | K23: 0.028150809 | L23: 0.030535556 | M23: 0.034999992 | N23: 0.038060289 | O23: 0.04090395 | P23: 0.044628634 | Q23: 0.045442401 | R23: 0.042244821 | S23: 0.04040261 | T23: 0.040800449 | U23: 0.042401027 | V23: 0.054339487 | W23: 0.07210186 | X23: 0.080207526 | Y23: 0.072457077 | Z23: 0.058805176 | AA23: 0.044938795 | AB23: 0.033485453 | AC23: =+SUM(E23:AB23)*D23 -> 22
C24: SAB. | D24: 4 | E24: 0.022237422 | F24: 0.017906314 | G24: 0.016297579 | H24: 0.016048394 | I24: 0.018230187 | J24: 0.02409663 | K24: 0.031671212 | L24: 0.033600778 | M24: 0.038695932 | N24: 0.041768414 | O24: 0.045129427 | P24: 0.048495931 | Q24: 0.047966938 | R24: 0.044497953 | S24: 0.043297772 | T24: 0.043681635 | U24: 0.044771874 | V24: 0.056182065 | W24: 0.073501323 | X24: 0.080239491 | Y24: 0.072625566 | Z24: 0.059745559 | AA24: 0.045128982 | AB24: 0.034182622 | AC24: =+SUM(E24:AB24)*D24 -> 4
C25: DOM. | D25: 4 | E25: 0.052643358 | F25: 0.021954713 | G25: 0.019492126 | H25: 0.018587449 | I25: 0.019085789 | J25: 0.023330656 | K25: 0.028150809 | L25: 0.030535556 | M25: 0.034999992 | N25: 0.038060289 | O25: 0.04090395 | P25: 0.044628634 | Q25: 0.045442401 | R25: 0.042244821 | S25: 0.04040261 | T25: 0.040800449 | U25: 0.042401027 | V25: 0.054339487 | W25: 0.07210186 | X25: 0.080207526 | Y25: 0.072457077 | Z25: 0.058805176 | AA25: 0.044938795 | AB25: 0.033485453 | AC25: =+SUM(E25:AB25)*D25 -> 4
C26: FES. | D26: 1 | E26: 0.052643358 | F26: 0.021954713 | G26: 0.019492126 | H26: 0.018587449 | I26: 0.019085789 | J26: 0.023330656 | K26: 0.028150809 | L26: 0.030535556 | M26: 0.034999992 | N26: 0.038060289 | O26: 0.04090395 | P26: 0.044628634 | Q26: 0.045442401 | R26: 0.042244821 | S26: 0.04040261 | T26: 0.040800449 | U26: 0.042401027 | V26: 0.054339487 | W26: 0.07210186 | X26: 0.080207526 | Y26: 0.072457077 | Z26: 0.058805176 | AA26: 0.044938795 | AB26: 0.033485453 | AC26: =+SUM(E26:AB26)*D26 -> 1
C27: TOTAL | D27: =+SUM(D23:D26) -> 31 | E27: =+SUMPRODUCT(E23:E26,$D23:$D26) -> 1.5103203 | F27: =+SUMPRODUCT(F23:F26,$D23:$D26) -> 0.6644025 | G27: =+SUMPRODUCT(G23:G26,$D23:$D26) -> 0.59147771 | H27: =+SUMPRODUCT(H23:H26,$D23:$D26) -> 0.56605469 | I27: =+SUMPRODUCT(I23:I26,$D23:$D26) -> 0.58823705 | J27: =+SUMPRODUCT(J23:J26,$D23:$D26) -> 0.72631423 | K27: =+SUMPRODUCT(K23:K26,$D23:$D26) -> 0.88675669 | L27: =+SUMPRODUCT(L23:L26,$D23:$D26) -> 0.95886312 | ... AB27: =+SUMPRODUCT(AB23:AB26,$D23:$D26) -> 1.0408377 | AC27: =+SUM(E27:AB27) -> 31
B28: =+EDATE(B23,1) -> 45017 | C28: ORD. | D28: 18 | E28: 0.018931194 | F28: 0.01564526 | G28: 0.013796154 | H28: 0.013709731 | I28: 0.017824203 | J28: 0.026301412 | K28: 0.033168787 | L28: 0.033727412 | M28: 0.037616229 | N28: 0.040386026 | O28: 0.04386823 | P28: 0.047995823 | Q28: 0.046805232 | R28: 0.043499914 | S28: 0.043560713 | T28: 0.045477968 | U28: 0.047156735 | V28: 0.05919873 | W28: 0.076527624 | X28: 0.082775954 | Y28: 0.074506537 | Z28: 0.061692543 | AA28: 0.044875249 | AB28: 0.030952342 | AC28: =+SUM(E28:AB28)*D28 -> 18
C29: SAB. | D29: 5 | E29: 0.021625172 | F29: 0.017087813 | G29: 0.015428824 | H29: 0.015172586 | I29: 0.017422131 | J29: 0.023451225 | K29: 0.031280178 | L29: 0.033168877 | M29: 0.038486827 | N29: 0.041699974 | O29: 0.04516298 | P29: 0.048649088 | Q29: 0.048125085 | R29: 0.044487797 | S29: 0.043259741 | T29: 0.043645674 | U29: 0.044758794 | V29: 0.056927863 | W29: 0.074890207 | X29: 0.081636984 | Y29: 0.073759292 | Z29: 0.060439801 | AA29: 0.04535796 | AB29: 0.034075126 | AC29: =+SUM(E29:AB29)*D29 -> 5
C30: DOM. | D30: 5 | E30: 0.026060253 | F30: 0.021750584 | G30: 0.019234802 | H30: 0.018376006 | I30: 0.017499975 | J30: 0.02059002 | K30: 0.026990743 | L30: 0.032011434 | M30: 0.037536099 | N30: 0.040467118 | O30: 0.042683604 | P30: 0.046436433 | Q30: 0.046739851 | R30: 0.043398878 | S30: 0.041236733 | T30: 0.041440635 | U30: 0.043086796 | V30: 0.055440703 | W30: 0.074544475 | X30: 0.084159547 | Y30: 0.076593639 | Z30: 0.062273006 | AA30: 0.047127709 | AB30: 0.034320956 | AC30: =+SUM(E30:AB30)*D30 -> 5
C31: FES. | D31: 2 | E31: 0.026060253 | F31: 0.021750584 | G31: 0.019234802 | H31: 0.018376006 | I31: 0.017499975 | J31: 0.02059002 | K31: 0.026990743 | L31: 0.032011434 | M31: 0.037536099 | N31: 0.040467118 | O31: 0.042683604 | P31: 0.046436433 | Q31: 0.046739851 | R31: 0.043398878 | S31: 0.041236733 | T31: 0.041440635 | U31: 0.043086796 | V31: 0.055440703 | W31: 0.074544475 | X31: 0.084159547 | Y31: 0.076593639 | Z31: 0.062273006 | AA31: 0.047127709 | AB31: 0.034320956 | AC31: =+SUM(E31:AB31)*D31 -> 2
C32: TOTAL | D32: =+SUM(D28:D31) -> 30 | E32: =+SUMPRODUCT(E28:E31,$D28:$D31) -> 0.63130912 | F32: =+SUMPRODUCT(F28:F31,$D28:$D31) -> 0.51930783 | G32: =+SUMPRODUCT(G28:G31,$D28:$D31) -> 0.46011851 | H32: =+SUMPRODUCT(H28:H31,$D28:$D31) -> 0.45127012 | I32: =+SUMPRODUCT(I28:I31,$D28:$D31) -> 0.53044613 | J32: =+SUMPRODUCT(J28:J31,$D28:$D31) -> 0.73481169 | K32: =+SUMPRODUCT(K28:K31,$D28:$D31) -> 0.94237425 | L32: =+SUMPRODUCT(L28:L31,$D28:$D31) -> 0.99701784 | ... AB32: =+SUMPRODUCT(AB28:AB31,$D28:$D31) -> 0.96776447 | AC32: =+SUM(E32:AB32) -> 30
B33: =+EDATE(B28,1) -> 45047 | C33: ORD. | D33: 21 | E33: 0.0192947 | F33: 0.016029744 | G33: 0.014184046 | H33: 0.014085931 | I33: 0.018104571 | J33: 0.026232823 | K33: 0.032852268 | L33: 0.033748278 | M33: 0.037771907 | N33: 0.040576821 | O33: 0.043979095 | P33: 0.048067323 | Q33: 0.046953582 | R33: 0.043635545 | S33: 0.043640237 | T33: 0.045519423 | U33: 0.047133307 | V33: 0.058993206 | W33: 0.07619792 | X33: 0.082012333 | Y33: 0.07387854 | Z33: 0.061306104 | AA33: 0.044751448 | AB33: 0.031050848 | AC33: =+SUM(E33:AB33)*D33 -> 21
C34: SAB. | D34: 4 | E34: 0.021990147 | F34: 0.017416254 | G34: 0.015787624 | H34: 0.015537281 | I34: 0.017745017 | J34: 0.023629032 | K34: 0.031344715 | L34: 0.033268981 | M34: 0.038596855 | N34: 0.04182654 | O34: 0.045221132 | P34: 0.048667775 | Q34: 0.048189617 | R34: 0.044517891 | S34: 0.043328493 | T34: 0.043690661 | U34: 0.044764556 | V34: 0.056779977 | W34: 0.074585648 | X34: 0.080868828 | Y34: 0.073091597 | Z34: 0.059953228 | AA34: 0.045132658 | AB34: 0.034065491 | AC34: =+SUM(E34:AB34)*D34 -> 4
C35: DOM. | D35: 4 | E35: 0.052209548 | F35: 0.02156115 | G35: 0.019022282 | H35: 0.018134488 | I35: 0.018589411 | J35: 0.022938267 | K35: 0.02775319 | L35: 0.030145517 | M35: 0.034720812 | N35: 0.037888234 | O35: 0.040785068 | P35: 0.044678169 | Q35: 0.045604859 | R35: 0.04220288 | S35: 0.040325422 | T35: 0.04073289 | U35: 0.042390154 | V35: 0.054922596 | W35: 0.073173951 | X35: 0.081014141 | Y35: 0.073161069 | Z35: 0.059254368 | AA35: 0.045234287 | AB35: 0.033557245 | AC35: =+SUM(E35:AB35)*D35 -> 4
C36: FES. | D36: 2 | E36: 0.052209548 | F36: 0.02156115 | G36: 0.019022282 | H36: 0.018134488 | I36: 0.018589411 | J36: 0.022938267 | K36: 0.02775319 | L36: 0.030145517 | M36: 0.034720812 | N36: 0.037888234 | O36: 0.040785068 | P36: 0.044678169 | Q36: 0.045604859 | R36: 0.04220288 | S36: 0.040325422 | T36: 0.04073289 | U36: 0.042390154 | V36: 0.054922596 | W36: 0.073173951 | X36: 0.081014141 | Y36: 0.073161069 | Z36: 0.059254368 | AA36: 0.045234287 | AB36: 0.033557245 | AC36: =+SUM(E36:AB36)*D36 -> 2
C37: TOTAL | D37: =+SUM(D33:D36) -> 31 | E37: =+SUMPRODUCT(E33:E36,$D33:$D36) -> 0.80640657 | F37: =+SUMPRODUCT(F33:F36,$D33:$D36) -> 0.53565655 | G37: =+SUMPRODUCT(G33:G36,$D33:$D36) -> 0.47514915 | H37: =+SUMPRODUCT(H33:H36,$D33:$D36) -> 0.46676061 | I37: =+SUMPRODUCT(I33:I36,$D33:$D36) -> 0.56271253 | J37: =+SUMPRODUCT(J33:J36,$D33:$D36) -> 0.78303501 | K37: =+SUMPRODUCT(K33:K36,$D33:$D36) -> 0.98179562 | L37: =+SUMPRODUCT(L33:L36,$D33:$D36) -> 1.0226629 | ... AB37: =+SUMPRODUCT(AB33:AB36,$D33:$D36) -> 0.98967325 | AC37: =+SUM(E37:AB37) -> 31
B38: =+EDATE(B33,1) -> 45078 | C38: ORD. | D38: 20 | E38: 0.018158969 | F38: 0.014702893 | G38: 0.012742208 | H38: 0.012628212 | I38: 0.016824599 | J38: 0.025184953 | K38: 0.032023177 | L38: 0.033035673 | M38: 0.037426827 | N38: 0.040439595 | O38: 0.043993341 | P38: 0.048310132 | Q38: 0.047188426 | R38: 0.043648195 | S38: 0.043607109 | T38: 0.045574946 | U38: 0.047238513 | V38: 0.060257286 | W38: 0.078457958 | X38: 0.084287029 | Y38: 0.075745553 | Z38: 0.062569172 | AA38: 0.045173795 | AB38: 0.03078144 | AC38: =+SUM(E38:AB38)*D38 -> 20
C39: SAB. | D39: 4 | E39: 0.021027643 | F39: 0.016131836 | G39: 0.014424221 | H39: 0.014162752 | I39: 0.01647702 | J39: 0.022617399 | K39: 0.030732406 | L39: 0.032590895 | M39: 0.038266926 | N39: 0.041716288 | O39: 0.045271335 | P39: 0.048905533 | Q39: 0.048434499 | R39: 0.044500176 | S39: 0.043266617 | T39: 0.043632366 | U39: 0.044742587 | V39: 0.057950154 | W39: 0.076763465 | X39: 0.08306681 | Y39: 0.074875762 | Z39: 0.061047707 | AA39: 0.045495964 | AB39: 0.033899641 | AC39: =+SUM(E39:AB39)*D39 -> 4
C40: DOM. | D40: 4 | E40: 0.050784811 | F40: 0.020560525 | G40: 0.017872608 | H40: 0.016956026 | I40: 0.017407069 | J40: 0.021996946 | K40: 0.027014241 | L40: 0.029372501 | M40: 0.034202135 | N40: 0.037561937 | O40: 0.040610682 | P40: 0.044759905 | Q40: 0.045786595 | R40: 0.042130129 | S40: 0.040153802 | T40: 0.040583797 | U40: 0.042342046 | V40: 0.056081432 | W40: 0.075372486 | X40: 0.083404528 | Y40: 0.075161839 | Z40: 0.06052603 | AA40: 0.045826204 | AB40: 0.033531729 | AC40: =+SUM(E40:AB40)*D40 -> 4
C41: FES. | D41: 2 | E41: 0.050784811 | F41: 0.020560525 | G41: 0.017872608 | H41: 0.016956026 | I41: 0.017407069 | J41: 0.021996946 | K41: 0.027014241 | L41: 0.029372501 | M41: 0.034202135 | N41: 0.037561937 | O41: 0.040610682 | P41: 0.044759905 | Q41: 0.045786595 | R41: 0.042130129 | S41: 0.040153802 | T41: 0.040583797 | U41: 0.042342046 | V41: 0.056081432 | W41: 0.075372486 | X41: 0.083404528 | Y41: 0.075161839 | Z41: 0.06052603 | AA41: 0.045826204 | AB41: 0.033531729 | AC41: =+SUM(E41:AB41)*D41 -> 2
C42: TOTAL | D42: =+SUM(D38:D41) -> 30 | E42: =+SUMPRODUCT(E38:E41,$D38:$D41) -> 0.75199882 | F42: =+SUMPRODUCT(F38:F41,$D38:$D41) -> 0.48194834 | G42: =+SUMPRODUCT(G38:G41,$D38:$D41) -> 0.41977669 | H42: =+SUMPRODUCT(H38:H41,$D38:$D41) -> 0.4109514 | I42: =+SUMPRODUCT(I38:I41,$D38:$D41) -> 0.50684247 | J42: =+SUMPRODUCT(J38:J41,$D38:$D41) -> 0.72615032 | K42: =+SUMPRODUCT(K38:K41,$D38:$D41) -> 0.92547861 | L42: =+SUMPRODUCT(L38:L41,$D38:$D41) -> 0.96731204 | ... AB42: =+SUMPRODUCT(AB38:AB41,$D38:$D41) -> 0.95241773 | AC42: =+SUM(E42:AB42) -> 30
B43: =+EDATE(B38,1) -> 45108 | C43: ORD. | D43: 19 | E43: 0.017823732 | F43: 0.014338465 | G43: 0.012377434 | H43: 0.012297984 | I43: 0.016577265 | J43: 0.025149083 | K43: 0.032088163 | L43: 0.033048075 | M43: 0.037441165 | N43: 0.040453974 | O43: 0.044034912 | P43: 0.048422533 | Q43: 0.047273176 | R43: 0.043660234 | S43: 0.042622937 | T43: 0.045683447 | U43: 0.047384292 | V43: 0.060606171 | W43: 0.078943455 | X43: 0.08470045 | Y43: 0.076120955 | Z43: 0.062879561 | AA43: 0.045320652 | AB43: 0.030751883 | AC43: =+SUM(E43:AB43)*D43 -> 19
...

Sheet Prod- 1
B2: EXPEDIENTE: | D2: =+Basis!D3 -> CP-CEOC-2025-001
B3: PRODUCTO: | D3: Producto 01 - Curva Horaria / Plana
B5: CANTIDAD EN: | D5: =+Basis!D4 -> kWh
B6: MODALIDAD: | D6: =+Basis!D5 -> PLC - Pague Lo Contratado
B7: OFERENTE:
B9: MES DE SUMINISTRO | C9: ENERGÍA SOLICITADA (kWh) | D9: PORCENTAJE ENERGÍA OFRECIDA | E9: ENERGÍA OFRECIDA (kWh) | F9: PRECIO OFERTADO ($/kWh)
B10: 45658 | D10: 1 | E10: =+C10*D10 -> 0
B11: =+EDATE(B10,1) -> 45689 | D11: =+D10 -> 1 | E11: =+C11*D11 -> 0
B12: =+EDATE(B11,1) -> 45717 | D12: =+D11 -> 1 | E12: =+C12*D12 -> 0
B13: =+EDATE(B12,1) -> 45748 | D13: =+D12 -> 1 | E13: =+C13*D13 -> 0
B14: =+EDATE(B13,1) -> 45778 | D14: =+D13 -> 1 | E14: =+C14*D14 -> 0
B15: =+EDATE(B14,1) -> 45809 | D15: =+D14 -> 1 | E15: =+C15*D15 -> 0
B16: =+EDATE(B15,1) -> 45839 | D16: =+D15 -> 1 | E16: =+C16*D16 -> 0
B17: =+EDATE(B16,1) -> 45870 | D17: =+D16 -> 1 | E17: =+C17*D17 -> 0
B18: =+EDATE(B17,1) -> 45901 | D18: =+D17 -> 1 | E18: =+C18*D18 -> 0
B19: =+EDATE(B18,1) -> 45931 | D19: =+D18 -> 1 | E19: =+C19*D19 -> 0
B20: =+EDATE(B19,1) -> 45962 | D20: =+D19 -> 1 | E20: =+C20*D20 -> 0
B21: =+EDATE(B20,1) -> 45992 | D21: =+D20 -> 1 | E21: =+C21*D21 -> 0
B22: =+EDATE(B21,1) -> 46023 | C22: 1000000 | D22: =+D21 -> 1 | E22: =+C22*D22 -> 1000000
B23: =+EDATE(B22,1) -> 46054 | C23: 1000000 | D23: =+D22 -> 1 | E23: =+C23*D23 -> 1000000
B24: =+EDATE(B23,1) -> 46082 | C24: 1000000 | D24: =+D23 -> 1 | E24: =+C24*D24 -> 1000000
B25: =+EDATE(B24,1) -> 46113 | C25: 1000000 | D25: =+D24 -> 1 | E25: =+C25*D25 -> 1000000
B26: =+EDATE(B25,1) -> 46143 | C26: 1000000 | D26: =+D25 -> 1 | E26: =+C26*D26 -> 1000000
B27: =+EDATE(B26,1) -> 46174 | C27: 2080480 | D27: =+D26 -> 1 | E27: =+C27*D27 -> 2080480
B28: =+EDATE(B27,1) -> 46204 | C28: 3039264 | D28: =+D27 -> 1 | E28: =+C28*D28 -> 3039264
B29: =+EDATE(B28,1) -> 46235 | C29: 1162567 | D29: =+D28 -> 1 | E29: =+C29*D29 -> 1162567
B30: =+EDATE(B29,1) -> 46266 | C30: 0 | D30: =+D29 -> 1 | E30: =+C30*D30 -> 0 | I30: =+ROUND(J30,2) -> 0
B31: =+EDATE(B30,1) -> 46296 | C31: 0 | D31: =+D30 -> 1 | E31: =+C31*D31 -> 0 | I31: =+ROUND(J31,2) -> 0
B32: =+EDATE(B31,1) -> 46327 | C32: 0 | D32: =+D31 -> 1 | E32: =+C32*D32 -> 0 | I32: =+ROUND(J32,2) -> 0
B33: =+EDATE(B32,1) -> 46357 | C33: 0 | D33: =+D32 -> 1 | E33: =+C33*D33 -> 0 | H33: =+SUM(E22:E33)-'Cant. P01'!AF128 -> 0 | I33: =+ROUND(J33,2) -> 0
B34: =+EDATE(B33,1) -> 46388 | D34: =+D33 -> 1 | E34: =+C34*D34 -> 0 | I34: =+ROUND(J34,2) -> 0
B35: =+EDATE(B34,1) -> 46419 | D35: =+D34 -> 1 | E35: =+C35*D35 -> 0 | I35: =+ROUND(J35,2) -> 0
B36: =+EDATE(B35,1) -> 46447 | D36: =+D35 -> 1 | E36: =+C36*D36 -> 0 | I36: =+ROUND(J36,2) -> 0
B37: =+EDATE(B36,1) -> 46478 | D37: =+D36 -> 1 | E37: =+C37*D37 -> 0 | I37: =+ROUND(J37,2) -> 0
B38: =+EDATE(B37,1) -> 46508 | D38: =+D37 -> 1 | E38: =+C38*D38 -> 0 | I38: =+ROUND(J38,2) -> 0
B39: =+EDATE(B38,1) -> 46539 | D39: =+D38 -> 1 | E39: =+C39*D39 -> 0 | I39: =+ROUND(J39,2) -> 0
B40: =+EDATE(B39,1) -> 46569 | D40: =+D39 -> 1 | E40: =+C40*D40 -> 0 | I40: =+ROUND(J40,2) -> 0
B41: =+EDATE(B40,1) -> 46600 | D41: =+D40 -> 1 | E41: =+C41*D41 -> 0 | I41: =+ROUND(J41,2) -> 0
B42: =+EDATE(B41,1) -> 46631 | D42: =+D41 -> 1 | E42: =+C42*D42 -> 0 | I42: =+ROUND(J42,2) -> 0
B43: =+EDATE(B42,1) -> 46661 | D43: =+D42 -> 1 | E43: =+C43*D43 -> 0 | I43: =+ROUND(J43,2) -> 0
...

Sheet Cant. P01
B2: =+"CUADRO DE CANTIDADES HORARIAS OFRECIDAS "&'Prod- 1'!D3 -> CUADRO DE CANTIDADES HORARIAS OFRECIDAS Producto 01 - Curva Horaria / Plana
B3: CANTIDADES DE ENERGIA Y PRECIO
B4: =+'Prod- 1'!D6 -> PLC - Pague Lo Contratado
B6: OFERENTE: | C6: =+'Prod- 1'!D7 -> 0
C8: Cantidad Ofrecida | D8: Tipo de día | E8: N° días mes | F8: H1 | G8: H2 | H8: H3 | I8: H4 | J8: H5 | K8: H6 | L8: H7 | M8: H8 | N8: H9 | O8: H10 | P8: H11 | Q8: H12 | R8: H13 | S8: H14 | T8: H15 | U8: H16 | V8: H17 | W8: H18 | X8: H19 | Y8: H20 | Z8: H21 | AA8: H22 | AB8: H23 | AC8: H24 | AD8: TOTAL
B9: =+'Prod- 1'!B10 -> 45658 | C9: =IFERROR(VLOOKUP(B9,'Prod- 1'!$B$10:$E$81,4,0),0) -> 0 | D9: ORD. | E9: =+Basis!D133 -> 21 | F9: =+(Basis!E133/(EOMONTH($B9,0)-$B9+1)*$C9) -> 0 | G9: =+(Basis!F133/(EOMONTH($B9,0)-$B9+1)*$C9) -> 0 | H9: =+(Basis!G133/(EOMONTH($B9,0)-$B9+1)*$C9) -> 0 | I9: =+(Basis!H133/(EOMONTH($B9,0)-$B9+1)*$C9) -> 0 | J9: =+(Basis!I133/(EOMONTH($B9,0)-$B9+1)*$C9) -> 0 | K9: =+(Basis!J133/(EOMONTH($B9,0)-$B9+1)*$C9) -> 0 | L9: =+(Basis!K133/(EOMONTH($B9,0)-$B9+1)*$C9) -> 0 | M9: =+(Basis!L133/(EOMONTH($B9,0)-$B9+1)*$C9) -> 0 | ... AC9: =+(Basis!AB133/(EOMONTH($B9,0)-$B9+1)*$C9) -> 0 | AD9: =+SUM(F9:AC9)*E9 -> 0
B10: =+B9 -> 45658 | C10: =IFERROR(VLOOKUP(B10,'Prod- 1'!$B$10:$E$81,4,0),0) -> 0 | D10: SAB. | E10: =+Basis!D134 -> 4 | F10: =+(Basis!E134/(EOMONTH($B10,0)-$B10+1)*$C10) -> 0 | G10: =+(Basis!F134/(EOMONTH($B10,0)-$B10+1)*$C10) -> 0 | H10: =+(Basis!G134/(EOMONTH($B10,0)-$B10+1)*$C10) -> 0 | I10: =+(Basis!H134/(EOMONTH($B10,0)-$B10+1)*$C10) -> 0 | J10: =+(Basis!I134/(EOMONTH($B10,0)-$B10+1)*$C10) -> 0 | K10: =+(Basis!J134/(EOMONTH($B10,0)-$B10+1)*$C10) -> 0 | L10: =+(Basis!K134/(EOMONTH($B10,0)-$B10+1)*$C10) -> 0 | M10: =+(Basis!L134/(EOMONTH($B10,0)-$B10+1)*$C10) -> 0 | ... AC10: =+(Basis!AB134/(EOMONTH($B10,0)-$B10+1)*$C10) -> 0 | AD10: =+SUM(F10:AC10)*E10 -> 0
B11: =+B10 -> 45658 | C11: =IFERROR(VLOOKUP(B11,'Prod- 1'!$B$10:$E$81,4,0),0) -> 0 | D11: DOM. | E11: =+Basis!D135 -> 4 | F11: =+(Basis!E135/(EOMONTH($B11,0)-$B11+1)*$C11) -> 0 | G11: =+(Basis!F135/(EOMONTH($B11,0)-$B11+1)*$C11) -> 0 | H11: =+(Basis!G135/(EOMONTH($B11,0)-$B11+1)*$C11) -> 0 | I11: =+(Basis!H135/(EOMONTH($B11,0)-$B11+1)*$C11) -> 0 | J11: =+(Basis!I135/(EOMONTH($B11,0)-$B11+1)*$C11) -> 0 | K11: =+(Basis!J135/(EOMONTH($B11,0)-$B11+1)*$C11) -> 0 | L11: =+(Basis!K135/(EOMONTH($B11,0)-$B11+1)*$C11) -> 0 | M11: =+(Basis!L135/(EOMONTH($B11,0)-$B11+1)*$C11) -> 0 | ... AC11: =+(Basis!AB135/(EOMONTH($B11,0)-$B11+1)*$C11) -> 0 | AD11: =+SUM(F11:AC11)*E11 -> 0
B12: =+B11 -> 45658 | C12: =IFERROR(VLOOKUP(B12,'Prod- 1'!$B$10:$E$81,4,0),0) -> 0 | D12: FES. | E12: =+Basis!D136 -> 2 | F12: =+(Basis!E136/(EOMONTH($B12,0)-$B12+1)*$C12) -> 0 | G12: =+(Basis!F136/(EOMONTH($B12,0)-$B12+1)*$C12) -> 0 | H12: =+(Basis!G136/(EOMONTH($B12,0)-$B12+1)*$C12) -> 0 | I12: =+(Basis!H136/(EOMONTH($B12,0)-$B12+1)*$C12) -> 0 | J12: =+(Basis!I136/(EOMONTH($B12,0)-$B12+1)*$C12) -> 0 | K12: =+(Basis!J136/(EOMONTH($B12,0)-$B12+1)*$C12) -> 0 | L12: =+(Basis!K136/(EOMONTH($B12,0)-$B12+1)*$C12) -> 0 | M12: =+(Basis!L136/(EOMONTH($B12,0)-$B12+1)*$C12) -> 0 | ... AC12: =+(Basis!AB136/(EOMONTH($B12,0)-$B12+1)*$C12) -> 0 | AD12: =+SUM(F12:AC12)*E12 -> 0
D13: TOTAL | E13: =+SUM(E9:E12) -> 31 | F13: =+SUMPRODUCT(F9:F12,$E9:$E12) -> 0 | G13: =+SUMPRODUCT(G9:G12,$E9:$E12) -> 0 | H13: =+SUMPRODUCT(H9:H12,$E9:$E12) -> 0 | I13: =+SUMPRODUCT(I9:I12,$E9:$E12) -> 0 | J13: =+SUMPRODUCT(J9:J12,$E9:$E12) -> 0 | K13: =+SUMPRODUCT(K9:K12,$E9:$E12) -> 0 | L13: =+SUMPRODUCT(L9:L12,$E9:$E12) -> 0 | M13: =+SUMPRODUCT(M9:M12,$E9:$E12) -> 0 | ... AC13: =+SUMPRODUCT(AC9:AC12,$E9:$E12) -> 0 | AD13: =+SUM(AD9:AD12) -> 0 | AE13: =+AD13-C9 -> 0 | AG13: =+AD13/24/E13 -> 0
B14: =+EDATE(B9,1) -> 45689 | C14: =IFERROR(VLOOKUP(B14,'Prod- 1'!$B$10:$E$81,4,0),0) -> 0 | D14: ORD. | E14: =+Basis!D138 -> 20 | F14: =+(Basis!E138/(EOMONTH($B14,0)-$B14+1)*$C14) -> 0 | G14: =+(Basis!F138/(EOMONTH($B14,0)-$B14+1)*$C14) -> 0 | H14: =+(Basis!G138/(EOMONTH($B14,0)-$B14+1)*$C14) -> 0 | I14: =+(Basis!H138/(EOMONTH($B14,0)-$B14+1)*$C14) -> 0 | J14: =+(Basis!I138/(EOMONTH($B14,0)-$B14+1)*$C14) -> 0 | K14: =+(Basis!J138/(EOMONTH($B14,0)-$B14+1)*$C14) -> 0 | L14: =+(Basis!K138/(EOMONTH($B14,0)-$B14+1)*$C14) -> 0 | M14: =+(Basis!L138/(EOMONTH($B14,0)-$B14+1)*$C14) -> 0 | ... AC14: =+(Basis!AB138/(EOMONTH($B14,0)-$B14+1)*$C14) -> 0 | AD14: =+SUM(F14:AC14)*E14 -> 0
B15: =+B14 -> 45689 | C15: =IFERROR(VLOOKUP(B15,'Prod- 1'!$B$10:$E$81,4,0),0) -> 0 | D15: SAB. | E15: =+Basis!D139 -> 4 | F15: =+(Basis!E139/(EOMONTH($B15,0)-$B15+1)*$C15) -> 0 | G15: =+(Basis!F139/(EOMONTH($B15,0)-$B15+1)*$C15) -> 0 | H15: =+(Basis!G139/(EOMONTH($B15,0)-$B15+1)*$C15) -> 0 | I15: =+(Basis!H139/(EOMONTH($B15,0)-$B15+1)*$C15) -> 0 | J15: =+(Basis!I139/(EOMONTH($B15,0)-$B15+1)*$C15) -> 0 | K15: =+(Basis!J139/(EOMONTH($B15,0)-$B15+1)*$C15) -> 0 | L15: =+(Basis!K139/(EOMONTH($B15,0)-$B15+1)*$C15) -> 0 | M15: =+(Basis!L139/(EOMONTH($B15,0)-$B15+1)*$C15) -> 0 | ... AC15: =+(Basis!AB139/(EOMONTH($B15,0)-$B15+1)*$C15) -> 0 | AD15: =+SUM(F15:AC15)*E15 -> 0
B16: =+B15 -> 45689 | C16: =IFERROR(VLOOKUP(B16,'Prod- 1'!$B$10:$E$81,4,0),0) -> 0 | D16: DOM. | E16: =+Basis!D140 -> 4 | F16: =+(Basis!E140/(EOMONTH($B16,0)-$B16+1)*$C16) -> 0 | G16: =+(Basis!F140/(EOMONTH($B16,0)-$B16+1)*$C16) -> 0 | H16: =+(Basis!G140/(EOMONTH($B16,0)-$B16+1)*$C16) -> 0 | I16: =+(Basis!H140/(EOMONTH($B16,0)-$B16+1)*$C16) -> 0 | J16: =+(Basis!I140/(EOMONTH($B16,0)-$B16+1)*$C16) -> 0 | K16: =+(Basis!J140/(EOMONTH($B16,0)-$B16+1)*$C16) -> 0 | L16: =+(Basis!K140/(EOMONTH($B16,0)-$B16+1)*$C16) -> 0 | M16: =+(Basis!L140/(EOMONTH($B16,0)-$B16+1)*$C16) -> 0 | ... AC16: =+(Basis!AB140/(EOMONTH($B16,0)-$B16+1)*$C16) -> 0 | AD16: =+SUM(F16:AC16)*E16 -> 0
B17: =+B16 -> 45689 | C17: =IFERROR(VLOOKUP(B17,'Prod- 1'!$B$10:$E$81,4,0),0) -> 0 | D17: FES. | E17: =+Basis!D141 -> 0 | F17: =+(Basis!E141/(EOMONTH($B17,0)-$B17+1)*$C17) -> 0 | G17: =+(Basis!F141/(EOMONTH($B17,0)-$B17+1)*$C17) -> 0 | H17: =+(Basis!G141/(EOMONTH($B17,0)-$B17+1)*$C17) -> 0 | I17: =+(Basis!H141/(EOMONTH($B17,0)-$B17+1)*$C17) -> 0 | J17: =+(Basis!I141/(EOMONTH($B17,0)-$B17+1)*$C17) -> 0 | K17: =+(Basis!J141/(EOMONTH($B17,0)-$B17+1)*$C17) -> 0 | L17: =+(Basis!K141/(EOMONTH($B17,0)-$B17+1)*$C17) -> 0 | M17: =+(Basis!L141/(EOMONTH($B17,0)-$B17+1)*$C17) -> 0 | ... AC17: =+(Basis!AB141/(EOMONTH($B17,0)-$B17+1)*$C17) -> 0 | AD17: =+SUM(F17:AC17)*E17 -> 0
D18: TOTAL | E18: =+SUM(E14:E17) -> 28 | F18: =+SUMPRODUCT(F14:F17,$E14:$E17) -> 0 | G18: =+SUMPRODUCT(G14:G17,$E14:$E17) -> 0 | H18: =+SUMPRODUCT(H14:H17,$E14:$E17) -> 0 | I18: =+SUMPRODUCT(I14:I17,$E14:$E17) -> 0 | J18: =+SUMPRODUCT(J14:J17,$E14:$E17) -> 0 | K18: =+SUMPRODUCT(K14:K17,$E14:$E17) -> 0 | L18: =+SUMPRODUCT(L14:L17,$E14:$E17) -> 0 | M18: =+SUMPRODUCT(M14:M17,$E14:$E17) -> 0 | ... AC18: =+SUMPRODUCT(AC14:AC17,$E14:$E17) -> 0 | AD18: =+SUM(AD14:AD17) -> 0 | AE18: =+AD18-C14 -> 0 | AG18: =+AD18/24/E18 -> 0
B19: =+EDATE(B14,1) -> 45717 | C19: =IFERROR(VLOOKUP(B19,'Prod- 1'!$B$10:$E$81,4,0),0) -> 0 | D19: ORD. | E19: =+Basis!D143 -> 20 | F19: =+(Basis!E143/(EOMONTH($B19,0)-$B19+1)*$C19) -> 0 | G19: =+(Basis!F143/(EOMONTH($B19,0)-$B19+1)*$C19) -> 0 | H19: =+(Basis!G143/(EOMONTH($B19,0)-$B19+1)*$C19) -> 0 | I19: =+(Basis!H143/(EOMONTH($B19,0)-$B19+1)*$C19) -> 0 | J19: =+(Basis!I143/(EOMONTH($B19,0)-$B19+1)*$C19) -> 0 | K19: =+(Basis!J143/(EOMONTH($B19,0)-$B19+1)*$C19) -> 0 | L19: =+(Basis!K143/(EOMONTH($B19,0)-$B19+1)*$C19) -> 0 | M19: =+(Basis!L143/(EOMONTH($B19,0)-$B19+1)*$C19) -> 0 | ... AC19: =+(Basis!AB143/(EOMONTH($B19,0)-$B19+1)*$C19) -> 0 | AD19: =+SUM(F19:AC19)*E19 -> 0
B20: =+B19 -> 45717 | C20: =IFERROR(VLOOKUP(B20,'Prod- 1'!$B$10:$E$81,4,0),0) -> 0 | D20: SAB. | E20: =+Basis!D144 -> 5 | F20: =+(Basis!E144/(EOMONTH($B20,0)-$B20+1)*$C20) -> 0 | G20: =+(Basis!F144/(EOMONTH($B20,0)-$B20+1)*$C20) -> 0 | H20: =+(Basis!G144/(EOMONTH($B20,0)-$B20+1)*$C20) -> 0 | I20: =+(Basis!H144/(EOMONTH($B20,0)-$B20+1)*$C20) -> 0 | J20: =+(Basis!I144/(EOMONTH($B20,0)-$B20+1)*$C20) -> 0 | K20: =+(Basis!J144/(EOMONTH($B20,0)-$B20+1)*$C20) -> 0 | L20: =+(Basis!K144/(EOMONTH($B20,0)-$B20+1)*$C20) -> 0 | M20: =+(Basis!L144/(EOMONTH($B20,0)-$B20+1)*$C20) -> 0 | ... AC20: =+(Basis!AB144/(EOMONTH($B20,0)-$B20+1)*$C20) -> 0 | AD20: =+SUM(F20:AC20)*E20 -> 0
B21: =+B20 -> 45717 | C21: =IFERROR(VLOOKUP(B21,'Prod- 1'!$B$10:$E$81,4,0),0) -> 0 | D21: DOM. | E21: =+Basis!D145 -> 5 | F21: =+(Basis!E145/(EOMONTH($B21,0)-$B21+1)*$C21) -> 0 | G21: =+(Basis!F145/(EOMONTH($B21,0)-$B21+1)*$C21) -> 0 | H21: =+(Basis!G145/(EOMONTH($B21,0)-$B21+1)*$C21) -> 0 | I21: =+(Basis!H145/(EOMONTH($B21,0)-$B21+1)*$C21) -> 0 | J21: =+(Basis!I145/(EOMONTH($B21,0)-$B21+1)*$C21) -> 0 | K21: =+(Basis!J145/(EOMONTH($B21,0)-$B21+1)*$C21) -> 0 | L21: =+(Basis!K145/(EOMONTH($B21,0)-$B21+1)*$C21) -> 0 | M21: =+(Basis!L145/(EOMONTH($B21,0)-$B21+1)*$C21) -> 0 | ... AC21: =+(Basis!AB145/(EOMONTH($B21,0)-$B21+1)*$C21) -> 0 | AD21: =+SUM(F21:AC21)*E21 -> 0
B22: =+B21 -> 45717 | C22: =IFERROR(VLOOKUP(B22,'Prod- 1'!$B$10:$E$81,4,0),0) -> 0 | D22: FES. | E22: =+Basis!D146 -> 1 | F22: =+(Basis!E146/(EOMONTH($B22,0)-$B22+1)*$C22) -> 0 | G22: =+(Basis!F146/(EOMONTH($B22,0)-$B22+1)*$C22) -> 0 | H22: =+(Basis!G146/(EOMONTH($B22,0)-$B22+1)*$C22) -> 0 | I22: =+(Basis!H146/(EOMONTH($B22,0)-$B22+1)*$C22) -> 0 | J22: =+(Basis!I146/(EOMONTH($B22,0)-$B22+1)*$C22) -> 0 | K22: =+(Basis!J146/(EOMONTH($B22,0)-$B22+1)*$C22) -> 0 | L22: =+(Basis!K146/(EOMONTH($B22,0)-$B22+1)*$C22) -> 0 | M22: =+(Basis!L146/(EOMONTH($B22,0)-$B22+1)*$C22) -> 0 | ... AC22: =+(Basis!AB146/(EOMONTH($B22,0)-$B22+1)*$C22) -> 0 | AD22: =+SUM(F22:AC22)*E22 -> 0
D23: TOTAL | E23: =+SUM(E19:E22) -> 31 | F23: =+SUMPRODUCT(F19:F22,$E19:$E22) -> 0 | G23: =+SUMPRODUCT(G19:G22,$E19:$E22) -> 0 | H23: =+SUMPRODUCT(H19:H22,$E19:$E22) -> 0 | I23: =+SUMPRODUCT(I19:I22,$E19:$E22) -> 0 | J23: =+SUMPRODUCT(J19:J22,$E19:$E22) -> 0 | K23: =+SUMPRODUCT(K19:K22,$E19:$E22) -> 0 | L23: =+SUMPRODUCT(L19:L22,$E19:$E22) -> 0 | M23: =+SUMPRODUCT(M19:M22,$E19:$E22) -> 0 | ... AC23: =+SUMPRODUCT(AC19:AC22,$E19:$E22) -> 0 | AD23: =+SUM(AD19:AD22) -> 0 | AE23: =+AD23-C19 -> 0 | AG23: =+AD23/24/E23 -> 0
B24: =+EDATE(B19,1) -> 45748 | C24: =IFERROR(VLOOKUP(B24,'Prod- 1'!$B$10:$E$81,4,0),0) -> 0 | D24: ORD. | E24: =+Basis!D148 -> 20 | F24: =+(Basis!E148/(EOMONTH($B24,0)-$B24+1)*$C24) -> 0 | G24: =+(Basis!F148/(EOMONTH($B24,0)-$B24+1)*$C24) -> 0 | H24: =+(Basis!G148/(EOMONTH($B24,0)-$B24+1)*$C24) -> 0 | I24: =+(Basis!H148/(EOMONTH($B24,0)-$B24+1)*$C24) -> 0 | J24: =+(Basis!I148/(EOMONTH($B24,0)-$B24+1)*$C24) -> 0 | K24: =+(Basis!J148/(EOMONTH($B24,0)-$B24+1)*$C24) -> 0 | L24: =+(Basis!K148/(EOMONTH($B24,0)-$B24+1)*$C24) -> 0 | M24: =+(Basis!L148/(EOMONTH($B24,0)-$B24+1)*$C24) -> 0 | ... AC24: =+(Basis!AB148/(EOMONTH($B24,0)-$B24+1)*$C24) -> 0 | AD24: =+SUM(F24:AC24)*E24 -> 0
B25: =+B24 -> 45748 | C25: =IFERROR(VLOOKUP(B25,'Prod- 1'!$B$10:$E$81,4,0),0) -> 0 | D25: SAB. | E25: =+Basis!D149 -> 4 | F25: =+(Basis!E149/(EOMONTH($B25,0)-$B25+1)*$C25) -> 0 | G25: =+(Basis!F149/(EOMONTH($B25,0)-$B25+1)*$C25) -> 0 | H25: =+(Basis!G149/(EOMONTH($B25,0)-$B25+1)*$C25) -> 0 | I25: =+(Basis!H149/(EOMONTH($B25,0)-$B25+1)*$C25) -> 0 | J25: =+(Basis!I149/(EOMONTH($B25,0)-$B25+1)*$C25) -> 0 | K25: =+(Basis!J149/(EOMONTH($B25,0)-$B25+1)*$C25) -> 0 | L25: =+(Basis!K149/(EOMONTH($B25,0)-$B25+1)*$C25) -> 0 | M25: =+(Basis!L149/(EOMONTH($B25,0)-$B25+1)*$C25) -> 0 | ... AC25: =+(Basis!AB149/(EOMONTH($B25,0)-$B25+1)*$C25) -> 0 | AD25: =+SUM(F25:AC25)*E25 -> 0
B26: =+B25 -> 45748 | C26: =IFERROR(VLOOKUP(B26,'Prod- 1'!$B$10:$E$81,4,0),0) -> 0 | D26: DOM. | E26: =+Basis!D150 -> 4 | F26: =+(Basis!E150/(EOMONTH($B26,0)-$B26+1)*$C26) -> 0 | G26: =+(Basis!F150/(EOMONTH($B26,0)-$B26+1)*$C26) -> 0 | H26: =+(Basis!G150/(EOMONTH($B26,0)-$B26+1)*$C26) -> 0 | I26: =+(Basis!H150/(EOMONTH($B26,0)-$B26+1)*$C26) -> 0 | J26: =+(Basis!I150/(EOMONTH($B26,0)-$B26+1)*$C26) -> 0 | K26: =+(Basis!J150/(EOMONTH($B26,0)-$B26+1)*$C26) -> 0 | L26: =+(Basis!K150/(EOMONTH($B26,0)-$B26+1)*$C26) -> 0 | M26: =+(Basis!L150/(EOMONTH($B26,0)-$B26+1)*$C26) -> 0 | ... AC26: =+(Basis!AB150/(EOMONTH($B26,0)-$B26+1)*$C26) -> 0 | AD26: =+SUM(F26:AC26)*E26 -> 0
B27: =+B26 -> 45748 | C27: =IFERROR(VLOOKUP(B27,'Prod- 1'!$B$10:$E$81,4,0),0) -> 0 | D27: FES. | E27: =+Basis!D151 -> 2 | F27: =+(Basis!E151/(EOMONTH($B27,0)-$B27+1)*$C27) -> 0 | G27: =+(Basis!F151/(EOMONTH($B27,0)-$B27+1)*$C27) -> 0 | H27: =+(Basis!G151/(EOMONTH($B27,0)-$B27+1)*$C27) -> 0 | I27: =+(Basis!H151/(EOMONTH($B27,0)-$B27+1)*$C27) -> 0 | J27: =+(Basis!I151/(EOMONTH($B27,0)-$B27+1)*$C27) -> 0 | K27: =+(Basis!J151/(EOMONTH($B27,0)-$B27+1)*$C27) -> 0 | L27: =+(Basis!K151/(EOMONTH($B27,0)-$B27+1)*$C27) -> 0 | M27: =+(Basis!L151/(EOMONTH($B27,0)-$B27+1)*$C27) -> 0 | ... AC27: =+(Basis!AB151/(EOMONTH($B27,0)-$B27+1)*$C27) -> 0 | AD27: =+SUM(F27:AC27)*E27 -> 0
D28: TOTAL | E28: =+SUM(E24:E27) -> 30 | F28: =+SUMPRODUCT(F24:F27,$E24:$E27) -> 0 | G28: =+SUMPRODUCT(G24:G27,$E24:$E27) -> 0 | H28: =+SUMPRODUCT(H24:H27,$E24:$E27) -> 0 | I28: =+SUMPRODUCT(I24:I27,$E24:$E27) -> 0 | J28: =+SUMPRODUCT(J24:J27,$E24:$E27) -> 0 | K28: =+SUMPRODUCT(K24:K27,$E24:$E27) -> 0 | L28: =+SUMPRODUCT(L24:L27,$E24:$E27) -> 0 | M28: =+SUMPRODUCT(M24:M27,$E24:$E27) -> 0 | ... AC28: =+SUMPRODUCT(AC24:AC27,$E24:$E27) -> 0 | AD28: =+SUM(AD24:AD27) -> 0 | AE28: =+AD28-C24 -> 0 | AG28: =+AD28/24/E28 -> 0
B29: =+EDATE(B24,1) -> 45778 | C29: =IFERROR(VLOOKUP(B29,'Prod- 1'!$B$10:$E$81,4,0),0) -> 0 | D29: ORD. | E29: =+Basis!D153 -> 21 | F29: =+(Basis!E153/(EOMONTH($B29,0)-$B29+1)*$C29) -> 0 | G29: =+(Basis!F153/(EOMONTH($B29,0)-$B29+1)*$C29) -> 0 | H29: =+(Basis!G153/(EOMONTH($B29,0)-$B29+1)*$C29) -> 0 | I29: =+(Basis!H153/(EOMONTH($B29,0)-$B29+1)*$C29) -> 0 | J29: =+(Basis!I153/(EOMONTH($B29,0)-$B29+1)*$C29) -> 0 | K29: =+(Basis!J153/(EOMONTH($B29,0)-$B29+1)*$C29) -> 0 | L29: =+(Basis!K153/(EOMONTH($B29,0)-$B29+1)*$C29) -> 0 | M29: =+(Basis!L153/(EOMONTH($B29,0)-$B29+1)*$C29) -> 0 | ... AC29: =+(Basis!AB153/(EOMONTH($B29,0)-$B29+1)*$C29) -> 0 | AD29: =+SUM(F29:AC29)*E29 -> 0
B30: =+B29 -> 45778 | C30: =IFERROR(VLOOKUP(B30,'Prod- 1'!$B$10:$E$81,4,0),0) -> 0 | D30: SAB. | E30: =+Basis!D154 -> 5 | F30: =+(Basis!E154/(EOMONTH($B30,0)-$B30+1)*$C30) -> 0 | G30: =+(Basis!F154/(EOMONTH($B30,0)-$B30+1)*$C30) -> 0 | H30: =+(Basis!G154/(EOMONTH($B30,0)-$B30+1)*$C30) -> 0 | I30: =+(Basis!H154/(EOMONTH($B30,0)-$B30+1)*$C30) -> 0 | J30: =+(Basis!I154/(EOMONTH($B30,0)-$B30+1)*$C30) -> 0 | K30: =+(Basis!J154/(EOMONTH($B30,0)-$B30+1)*$C30) -> 0 | L30: =+(Basis!K154/(EOMONTH($B30,0)-$B30+1)*$C30) -> 0 | M30: =+(Basis!L154/(EOMONTH($B30,0)-$B30+1)*$C30) -> 0 | ... AC30: =+(Basis!AB154/(EOMONTH($B30,0)-$B30+1)*$C30) -> 0 | AD30: =+SUM(F30:AC30)*E30 -> 0
B31: =+B30 -> 45778 | C31: =IFERROR(VLOOKUP(B31,'Prod- 1'!$B$10:$E$81,4,0),0) -> 0 | D31: DOM. | E31: =+Basis!D155 -> 4 | F31: =+(Basis!E155/(EOMONTH($B31,0)-$B31+1)*$C31) -> 0 | G31: =+(Basis!F155/(EOMONTH($B31,0)-$B31+1)*$C31) -> 0 | H31: =+(Basis!G155/(EOMONTH($B31,0)-$B31+1)*$C31) -> 0 | I31: =+(Basis!H155/(EOMONTH($B31,0)-$B31+1)*$C31) -> 0 | J31: =+(Basis!I155/(EOMONTH($B31,0)-$B31+1)*$C31) -> 0 | K31: =+(Basis!J155/(EOMONTH($B31,0)-$B31+1)*$C31) -> 0 | L31: =+(Basis!K155/(EOMONTH($B31,0)-$B31+1)*$C31) -> 0 | M31: =+(Basis!L155/(EOMONTH($B31,0)-$B31+1)*$C31) -> 0 | ... AC31: =+(Basis!AB155/(EOMONTH($B31,0)-$B31+1)*$C31) -> 0 | AD31: =+SUM(F31:AC31)*E31 -> 0
B32: =+B31 -> 45778 | C32: =IFERROR(VLOOKUP(B32,'Prod- 1'!$B$10:$E$81,4,0),0) -> 0 | D32: FES. | E32: =+Basis!D156 -> 1 | F32: =+(Basis!E156/(EOMONTH($B32,0)-$B32+1)*$C32) -> 0 | G32: =+(Basis!F156/(EOMONTH($B32,0)-$B32+1)*$C32) -> 0 | H32: =+(Basis!G156/(EOMONTH($B32,0)-$B32+1)*$C32) -> 0 | I32: =+(Basis!H156/(EOMONTH($B32,0)-$B32+1)*$C32) -> 0 | J32: =+(Basis!I156/(EOMONTH($B32,0)-$B32+1)*$C32) -> 0 | K32: =+(Basis!J156/(EOMONTH($B32,0)-$B32+1)*$C32) -> 0 | L32: =+(Basis!K156/(EOMONTH($B32,0)-$B32+1)*$C32) -> 0 | M32: =+(Basis!L156/(EOMONTH($B32,0)-$B32+1)*$C32) -> 0 | ... AC32: =+(Basis!AB156/(EOMONTH($B32,0)-$B32+1)*$C32) -> 0 | AD32: =+SUM(F32:AC32)*E32 -> 0
D33: TOTAL | E33: =+SUM(E29:E32) -> 31 | F33: =+SUMPRODUCT(F29:F32,$E29:$E32) -> 0 | G33: =+SUMPRODUCT(G29:G32,$E29:$E32) -> 0 | H33: =+SUMPRODUCT(H29:H32,$E29:$E32) -> 0 | I33: =+SUMPRODUCT(I29:I32,$E29:$E32) -> 0 | J33: =+SUMPRODUCT(J29:J32,$E29:$E32) -> 0 | K33: =+SUMPRODUCT(K29:K32,$E29:$E32) -> 0 | L33: =+SUMPRODUCT(L29:L32,$E29:$E32) -> 0 | M33: =+SUMPRODUCT(M29:M32,$E29:$E32) -> 0 | ... AC33: =+SUMPRODUCT(AC29:AC32,$E29:$E32) -> 0 | AD33: =+SUM(AD29:AD32) -> 0 | AE33: =+AD33-C29 -> 0 | AG33: =+AD33/24/E33 -> 0
B34: =+EDATE(B29,1) -> 45809 | C34: =IFERROR(VLOOKUP(B34,'Prod- 1'!$B$10:$E$81,4,0),0) -> 0 | D34: ORD. | E34: =+Basis!D158 -> 18 | F34: =+(Basis!E158/(EOMONTH($B34,0)-$B34+1)*$C34) -> 0 | G34: =+(Basis!F158/(EOMONTH($B34,0)-$B34+1)*$C34) -> 0 | H34: =+(Basis!G158/(EOMONTH($B34,0)-$B34+1)*$C34) -> 0 | I34: =+(Basis!H158/(EOMONTH($B34,0)-$B34+1)*$C34) -> 0 | J34: =+(Basis!I158/(EOMONTH($B34,0)-$B34+1)*$C34) -> 0 | K34: =+(Basis!J158/(EOMONTH($B34,0)-$B34+1)*$C34) -> 0 | L34: =+(Basis!K158/(EOMONTH($B34,0)-$B34+1)*$C34) -> 0 | M34: =+(Basis!L158/(EOMONTH($B34,0)-$B34+1)*$C34) -> 0 | ... AC34: =+(Basis!AB158/(EOMONTH($B34,0)-$B34+1)*$C34) -> 0 | AD34: =+SUM(F34:AC34)*E34 -> 0
B35: =+B34 -> 45809 | C35: =IFERROR(VLOOKUP(B35,'Prod- 1'!$B$10:$E$81,4,0),0) -> 0 | D35: SAB. | E35: =+Basis!D159 -> 4 | F35: =+(Basis!E159/(EOMONTH($B35,0)-$B35+1)*$C35) -> 0 | G35: =+(Basis!F159/(EOMONTH($B35,0)-$B35+1)*$C35) -> 0 | H35: =+(Basis!G159/(EOMONTH($B35,0)-$B35+1)*$C35) -> 0 | I35: =+(Basis!H159/(EOMONTH($B35,0)-$B35+1)*$C35) -> 0 | J35: =+(Basis!I159/(EOMONTH($B35,0)-$B35+1)*$C35) -> 0 | K35: =+(Basis!J159/(EOMONTH($B35,0)-$B35+1)*$C35) -> 0 | L35: =+(Basis!K159/(EOMONTH($B35,0)-$B35+1)*$C35) -> 0 | M35: =+(Basis!L159/(EOMONTH($B35,0)-$B35+1)*$C35) -> 0 | ... AC35: =+(Basis!AB159/(EOMONTH($B35,0)-$B35+1)*$C35) -> 0 | AD35: =+SUM(F35:AC35)*E35 -> 0
B36: =+B35 -> 45809 | C36: =IFERROR(VLOOKUP(B36,'Prod- 1'!$B$10:$E$81,4,0),0) -> 0 | D36: DOM. | E36: =+Basis!D160 -> 5 | F36: =+(Basis!E160/(EOMONTH($B36,0)-$B36+1)*$C36) -> 0 | G36: =+(Basis!F160/(EOMONTH($B36,0)-$B36+1)*$C36) -> 0 | H36: =+(Basis!G160/(EOMONTH($B36,0)-$B36+1)*$C36) -> 0 | I36: =+(Basis!H160/(EOMONTH($B36,0)-$B36+1)*$C36) -> 0 | J36: =+(Basis!I160/(EOMONTH($B36,0)-$B36+1)*$C36) -> 0 | K36: =+(Basis!J160/(EOMONTH($B36,0)-$B36+1)*$C36) -> 0 | L36: =+(Basis!K160/(EOMONTH($B36,0)-$B36+1)*$C36) -> 0 | M36: =+(Basis!L160/(EOMONTH($B36,0)-$B36+1)*$C36) -> 0 | ... AC36: =+(Basis!AB160/(EOMONTH($B36,0)-$B36+1)*$C36) -> 0 | AD36: =+SUM(F36:AC36)*E36 -> 0
B37: =+B36 -> 45809 | C37: =IFERROR(VLOOKUP(B37,'Prod- 1'!$B$10:$E$81,4,0),0) -> 0 | D37: FES. | E37: =+Basis!D161 -> 3 | F37: =+(Basis!E161/(EOMONTH($B37,0)-$B37+1)*$C37) -> 0 | G37: =+(Basis!F161/(EOMONTH($B37,0)-$B37+1)*$C37) -> 0 | H37: =+(Basis!G161/(EOMONTH($B37,0)-$B37+1)*$C37) -> 0 | I37: =+(Basis!H161/(EOMONTH($B37,0)-$B37+1)*$C37) -> 0 | J37: =+(Basis!I161/(EOMONTH($B37,0)-$B37+1)*$C37) -> 0 | K37: =+(Basis!J161/(EOMONTH($B37,0)-$B37+1)*$C37) -> 0 | L37: =+(Basis!K161/(EOMONTH($B37,0)-$B37+1)*$C37) -> 0 | M37: =+(Basis!L161/(EOMONTH($B37,0)-$B37+1)*$C37) -> 0 | ... AC37: =+(Basis!AB161/(EOMONTH($B37,0)-$B37+1)*$C37) -> 0 | AD37: =+SUM(F37:AC37)*E37 -> 0
D38: TOTAL | E38: =+SUM(E34:E37) -> 30 | F38: =+SUMPRODUCT(F34:F37,$E34:$E37) -> 0 | G38: =+SUMPRODUCT(G34:G37,$E34:$E37) -> 0 | H38: =+SUMPRODUCT(H34:H37,$E34:$E37) -> 0 | I38: =+SUMPRODUCT(I34:I37,$E34:$E37) -> 0 | J38: =+SUMPRODUCT(J34:J37,$E34:$E37) -> 0 | K38: =+SUMPRODUCT(K34:K37,$E34:$E37) -> 0 | L38: =+SUMPRODUCT(L34:L37,$E34:$E37) -> 0 | M38: =+SUMPRODUCT(M34:M37,$E34:$E37) -> 0 | ... AC38: =+SUMPRODUCT(AC34:AC37,$E34:$E37) -> 0 | AD38: =+SUM(AD34:AD37) -> 0 | AE38: =+AD38-C34 -> 0 | AG38: =+AD38/24/E38 -> 0
B39: =+EDATE(B34,1) -> 45839 | C39: =IFERROR(VLOOKUP(B39,'Prod- 1'!$B$10:$E$81,4,0),0) -> 0 | D39: ORD. | E39: =+Basis!D163 -> 23 | F39: =+(Basis!E163/(EOMONTH($B39,0)-$B39+1)*$C39) -> 0 | G39: =+(Basis!F163/(EOMONTH($B39,0)-$B39+1)*$C39) -> 0 | H39: =+(Basis!G163/(EOMONTH($B39,0)-$B39+1)*$C39) -> 0 | I39: =+(Basis!H163/(EOMONTH($B39,0)-$B39+1)*$C39) -> 0 | J39: =+(Basis!I163/(EOMONTH($B39,0)-$B39+1)*$C39) -> 0 | K39: =+(Basis!J163/(EOMONTH($B39,0)-$B39+1)*$C39) -> 0 | L39: =+(Basis!K163/(EOMONTH($B39,0)-$B39+1)*$C39) -> 0 | M39: =+(Basis!L163/(EOMONTH($B39,0)-$B39+1)*$C39) -> 0 | ... AC39: =+(Basis!AB163/(EOMONTH($B39,0)-$B39+1)*$C39) -> 0 | AD39: =+SUM(F39:AC39)*E39 -> 0
B40: =+B39 -> 45839 | C40: =IFERROR(VLOOKUP(B40,'Prod- 1'!$B$10:$E$81,4,0),0) -> 0 | D40: SAB. | E40: =+Basis!D164 -> 4 | F40: =+(Basis!E164/(EOMONTH($B40,0)-$B40+1)*$C40) -> 0 | G40: =+(Basis!F164/(EOMONTH($B40,0)-$B40+1)*$C40) -> 0 | H40: =+(Basis!G164/(EOMONTH($B40,0)-$B40+1)*$C40) -> 0 | I40: =+(Basis!H164/(EOMONTH($B40,0)-$B40+1)*$C40) -> 0 | J40: =+(Basis!I164/(EOMONTH($B40,0)-$B40+1)*$C40) -> 0 | K40: =+(Basis!J164/(EOMONTH($B40,0)-$B40+1)*$C40) -> 0 | L40: =+(Basis!K164/(EOMONTH($B40,0)-$B40+1)*$C40) -> 0 | M40: =+(Basis!L164/(EOMONTH($B40,0)-$B40+1)*$C40) -> 0 | ... AC40: =+(Basis!AB164/(EOMONTH($B40,0)-$B40+1)*$C40) -> 0 | AD40: =+SUM(F40:AC40)*E40 -> 0
B41: =+B40 -> 45839 | C41: =IFERROR(VLOOKUP(B41,'Prod- 1'!$B$10:$E$81,4,0),0) -> 0 | D41: DOM. | E41: =+Basis!D165 -> 4 | F41: =+(Basis!E165/(EOMONTH($B41,0)-$B41+1)*$C41) -> 0 | G41: =+(Basis!F165/(EOMONTH($B41,0)-$B41+1)*$C41) -> 0 | H41: =+(Basis!G165/(EOMONTH($B41,0)-$B41+1)*$C41) -> 0 | I41: =+(Basis!H165/(EOMONTH($B41,0)-$B41+1)*$C41) -> 0 | J41: =+(Basis!I165/(EOMONTH($B41,0)-$B41+1)*$C41) -> 0 | K41: =+(Basis!J165/(EOMONTH($B41,0)-$B41+1)*$C41) -> 0 | L41: =+(Basis!K165/(EOMONTH($B41,0)-$B41+1)*$C41) -> 0 | M41: =+(Basis!L165/(EOMONTH($B41,0)-$B41+1)*$C41) -> 0 | ... AC41: =+(Basis!AB165/(EOMONTH($B41,0)-$B41+1)*$C41) -> 0 | AD41: =+SUM(F41:AC41)*E41 -> 0
B42: =+B41 -> 45839 | C42: =IFERROR(VLOOKUP(B42,'Prod- 1'!$B$10:$E$81,4,0),0) -> 0 | D42: FES. | E42: =+Basis!D166 -> 0 | F42: =+(Basis!E166/(EOMONTH($B42,0)-$B42+1)*$C42) -> 0 | G42: =+(Basis!F166/(EOMONTH($B42,0)-$B42+1)*$C42) -> 0 | H42: =+(Basis!G166/(EOMONTH($B42,0)-$B42+1)*$C42) -> 0 | I42: =+(Basis!H166/(EOMONTH($B42,0)-$B42+1)*$C42) -> 0 | J42: =+(Basis!I166/(EOMONTH($B42,0)-$B42+1)*$C42) -> 0 | K42: =+(Basis!J166/(EOMONTH($B42,0)-$B42+1)*$C42) -> 0 | L42: =+(Basis!K166/(EOMONTH($B42,0)-$B42+1)*$C42) -> 0 | M42: =+(Basis!L166/(EOMONTH($B42,0)-$B42+1)*$C42) -> 0 | ... AC42: =+(Basis!AB166/(EOMONTH($B42,0)-$B42+1)*$C42) -> 0 | AD42: =+SUM(F42:AC42)*E42 -> 0
D43: TOTAL | E43: =+SUM(E39:E42) -> 31 | F43: =+SUMPRODUCT(F39:F42,$E39:$E42) -> 0 | G43: =+SUMPRODUCT(G39:G42,$E39:$E42) -> 0 | H43: =+SUMPRODUCT(H39:H42,$E39:$E42) -> 0 | I43: =+SUMPRODUCT(I39:I42,$E39:$E42) -> 0 | J43: =+SUMPRODUCT(J39:J42,$E39:$E42) -> 0 | K43: =+SUMPRODUCT(K39:K42,$E39:$E42) -> 0 | L43: =+SUMPRODUCT(L39:L42,$E39:$E42) -> 0 | M43: =+SUMPRODUCT(M39:M42,$E39:$E42) -> 0 | ... AC43: =+SUMPRODUCT(AC39:AC42,$E39:$E42) -> 0 | AD43: =+SUM(AD39:AD42) -> 0 | AE43: =+AD43-C39 -> 0 | AG43: =+AD43/24/E43 -> 0
...

Sheet Prod- 2
B2: EXPEDIENTE: | D2: =+Basis!D3 -> CP-CEOC-2025-001
B3: PRODUCTO: | D3: Producto 02 - Curva Horaria / Plana
B5: CANTIDAD EN: | D5: =+Basis!D4 -> kWh
B6: MODALIDAD: | D6: =+Basis!D5 -> PLC - Pague Lo Contratado
B7: OFERENTE:
B9: MES DE SUMINISTRO | C9: ENERGÍA SOLICITADA (kWh) | D9: PORCENTAJE ENERGÍA OFRECIDA | E9: ENERGÍA OFRECIDA (kWh) | F9: PRECIO OFERTADO ($/kWh)
B10: 45658 | D10: 1 | E10: =+C10*D10 -> 0
B11: =+EDATE(B10,1) -> 45689 | D11: =+D10 -> 1 | E11: =+C11*D11 -> 0
B12: =+EDATE(B11,1) -> 45717 | D12: =+D11 -> 1 | E12: =+C12*D12 -> 0
B13: =+EDATE(B12,1) -> 45748 | D13: =+D12 -> 1 | E13: =+C13*D13 -> 0
B14: =+EDATE(B13,1) -> 45778 | D14: =+D13 -> 1 | E14: =+C14*D14 -> 0
B15: =+EDATE(B14,1) -> 45809 | D15: =+D14 -> 1 | E15: =+C15*D15 -> 0
B16: =+EDATE(B15,1) -> 45839 | D16: =+D15 -> 1 | E16: =+C16*D16 -> 0
B17: =+EDATE(B16,1) -> 45870 | D17: =+D16 -> 1 | E17: =+C17*D17 -> 0
B18: =+EDATE(B17,1) -> 45901 | D18: =+D17 -> 1 | E18: =+C18*D18 -> 0
B19: =+EDATE(B18,1) -> 45931 | D19: =+D18 -> 1 | E19: =+C19*D19 -> 0
B20: =+EDATE(B19,1) -> 45962 | D20: =+D19 -> 1 | E20: =+C20*D20 -> 0
B21: =+EDATE(B20,1) -> 45992 | D21: =+D20 -> 1 | E21: =+C21*D21 -> 0
B22: =+EDATE(B21,1) -> 46023 | D22: =+D21 -> 1 | E22: =+C22*D22 -> 0
... B29: =+EDATE(B28,1) -> 46235 | D29: =+D28 -> 1 | E29: =+C29*D29 -> 0
B30: =+EDATE(B29,1) -> 46266 | D30: =+D29 -> 1 | E30: =+C30*D30 -> 0 | I30: =+ROUND(J30,2) -> 0
B31: =+EDATE(B30,1) -> 46296 | D31: =+D30 -> 1 | E31: =+C31*D31 -> 0 | I31: =+ROUND(J31,2) -> 0
B32: =+EDATE(B31,1) -> 46327 | D32: =+D31 -> 1 | E32: =+C32*D32 -> 0 | I32: =+ROUND(J32,2) -> 0
B33: =+EDATE(B32,1) -> 46357 | D33: =+D32 -> 1 | E33: =+C33*D33 -> 0 | H33: =+SUM(E22:E33)-'Cant. P02'!AF128 -> 0 | I33: =+ROUND(J33,2) -> 0
B34: =+EDATE(B33,1) -> 46388 | C34: 13025481 | D34: =+D33 -> 1 | E34: =+C34*D34 -> 13025481 | I34: =+ROUND(J34,2) -> 0
B35: =+EDATE(B34,1) -> 46419 | C35: 11919243 | D35: =+D34 -> 1 | E35: =+C35*D35 -> 11919243 | I35: =+ROUND(J35,2) -> 0
B36: =+EDATE(B35,1) -> 46447 | C36: 14688099 | D36: =+D35 -> 1 | E36: =+C36*D36 -> 14688099 | I36: =+ROUND(J36,2) -> 0
B37: =+EDATE(B36,1) -> 46478 | C37: 13139119 | D37: =+D36 -> 1 | E37: =+C37*D37 -> 13139119 | I37: =+ROUND(J37,2) -> 0
B38: =+EDATE(B37,1) -> 46508 | C38: 13897351 | D38: =+D37 -> 1 | E38: =+C38*D38 -> 13897351 | I38: =+ROUND(J38,2) -> 0
B39: =+EDATE(B38,1) -> 46539 | C39: 11194967 | D39: =+D38 -> 1 | E39: =+C39*D39 -> 11194967 | I39: =+ROUND(J39,2) -> 0
B40: =+EDATE(B39,1) -> 46569 | C40: 11459069 | D40: =+D39 -> 1 | E40: =+C40*D40 -> 11459069 | I40: =+ROUND(J40,2) -> 0
B41: =+EDATE(B40,1) -> 46600 | C41: 11563890 | D41: =+D40 -> 1 | E41: =+C41*D41 -> 11563890 | I41: =+ROUND(J41,2) -> 0
B42: =+EDATE(B41,1) -> 46631 | C42: 11073933 | D42: =+D41 -> 1 | E42: =+C42*D42 -> 11073933 | I42: =+ROUND(J42,2) -> 0
B43: =+EDATE(B42,1) -> 46661 | C43: 11362531 | D43: =+D42 -> 1 | E43: =+C43*D43 -> 11362531 | I43: =+ROUND(J43,2) -> 0
B44: =+EDATE(B43,1) -> 46692 | C44: 10678219 | D44: =+D43 -> 1 | E44: =+C44*D44 -> 10678219 | I44: =+ROUND(J44,2) -> 0
B45: =+EDATE(B44,1) -> 46722 | C45: 11377950 | D45: =+D44 -> 1 | E45: =+C45*D45 -> 11377950 | H45: =+SUM(E34:E45)-'Cant. P02'!AF188 -> 0 | I45: =+ROUND(J45,2) -> 0
B46: =+EDATE(B45,1) -> 46753 | D46: =+D45 -> 1 | E46: =+C46*D46 -> 0 | I46: =+ROUND(J46,2) -> 0
B47: =+EDATE(B46,1) -> 46784 | D47: =+D46 -> 1 | E47: =+C47*D47 -> 0 | I47: =+ROUND(J47,2) -> 0
B48: =+EDATE(B47,1) -> 46813 | D48: =+D47 -> 1 | E48: =+C48*D48 -> 0 | I48: =+ROUND(J48,2) -> 0
B49: =+EDATE(B48,1) -> 46844 | D49: =+D48 -> 1 | E49: =+C49*D49 -> 0 | I49: =+ROUND(J49,2) -> 0
...

Sheet Cant. P02
B2: =+"CUADRO DE CANTIDADES HORARIAS OFRECIDAS "&'Prod- 2'!D3 -> CUADRO DE CANTIDADES HORARIAS OFRECIDAS Producto 02 - Curva Horaria / Plana
B3: CANTIDADES DE ENERGIA Y PRECIO
B4: =+'Prod- 2'!D6 -> PLC - Pague Lo Contratado
B6: OFERENTE: | C6: =+'Prod- 2'!D7 -> 0
C8: Cantidad Ofrecida | D8: Tipo de día | E8: N° días mes | F8: H1 | G8: H2 | H8: H3 | I8: H4 | J8: H5 | K8: H6 | L8: H7 | M8: H8 | N8: H9 | O8: H10 | P8: H11 | Q8: H12 | R8: H13 | S8: H14 | T8: H15 | U8: H16 | V8: H17 | W8: H18 | X8: H19 | Y8: H20 | Z8: H21 | AA8: H22 | AB8: H23 | AC8: H24 | AD8: TOTAL
B9: =+'Prod- 2'!B10 -> 45658 | C9: =IFERROR(VLOOKUP(B9,'Prod- 2'!$B$10:$E$81,4,0),0) -> 0 | D9: ORD. | E9: =+Basis!D133 -> 21 | F9: =+(Basis!E133/(EOMONTH($B9,0)-$B9+1)*$C9) -> 0 | G9: =+(Basis!F133/(EOMONTH($B9,0)-$B9+1)*$C9) -> 0 | H9: =+(Basis!G133/(EOMONTH($B9,0)-$B9+1)*$C9) -> 0 | I9: =+(Basis!H133/(EOMONTH($B9,0)-$B9+1)*$C9) -> 0 | J9: =+(Basis!I133/(EOMONTH($B9,0)-$B9+1)*$C9) -> 0 | K9: =+(Basis!J133/(EOMONTH($B9,0)-$B9+1)*$C9) -> 0 | L9: =+(Basis!K133/(EOMONTH($B9,0)-$B9+1)*$C9) -> 0 | M9: =+(Basis!L133/(EOMONTH($B9,0)-$B9+1)*$C9) -> 0 | ... AC9: =+(Basis!AB133/(EOMONTH($B9,0)-$B9+1)*$C9) -> 0 | AD9: =+SUM(F9:AC9)*E9 -> 0
B10: =+B9 -> 45658 | C10: =IFERROR(VLOOKUP(B10,'Prod- 2'!$B$10:$E$81,4,0),0) -> 0 | D10: SAB. | E10: =+Basis!D134 -> 4 | F10: =+(Basis!E134/(EOMONTH($B10,0)-$B10+1)*$C10) -> 0 | G10: =+(Basis!F134/(EOMONTH($B10,0)-$B10+1)*$C10) -> 0 | H10: =+(Basis!G134/(EOMONTH($B10,0)-$B10+1)*$C10) -> 0 | I10: =+(Basis!H134/(EOMONTH($B10,0)-$B10+1)*$C10) -> 0 | J10: =+(Basis!I134/(EOMONTH($B10,0)-$B10+1)*$C10) -> 0 | K10: =+(Basis!J134/(EOMONTH($B10,0)-$B10+1)*$C10) -> 0 | L10: =+(Basis!K134/(EOMONTH($B10,0)-$B10+1)*$C10) -> 0 | M10: =+(Basis!L134/(EOMONTH($B10,0)-$B10+1)*$C10) -> 0 | ... AC10: =+(Basis!AB134/(EOMONTH($B10,0)-$B10+1)*$C10) -> 0 | AD10: =+SUM(F10:AC10)*E10 -> 0
B11: =+B10 -> 45658 | C11: =IFERROR(VLOOKUP(B11,'Prod- 2'!$B$10:$E$81,4,0),0) -> 0 | D11: DOM. | E11: =+Basis!D135 -> 4 | F11: =+(Basis!E135/(EOMONTH($B11,0)-$B11+1)*$C11) -> 0 | G11: =+(Basis!F135/(EOMONTH($B11,0)-$B11+1)*$C11) -> 0 | H11: =+(Basis!G135/(EOMONTH($B11,0)-$B11+1)*$C11) -> 0 | I11: =+(Basis!H135/(EOMONTH($B11,0)-$B11+1)*$C11) -> 0 | J11: =+(Basis!I135/(EOMONTH($B11,0)-$B11+1)*$C11) -> 0 | K11: =+(Basis!J135/(EOMONTH($B11,0)-$B11+1)*$C11) -> 0 | L11: =+(Basis!K135/(EOMONTH($B11,0)-$B11+1)*$C11) -> 0 | M11: =+(Basis!L135/(EOMONTH($B11,0)-$B11+1)*$C11) -> 0 | ... AC11: =+(Basis!AB135/(EOMONTH($B11,0)-$B11+1)*$C11) -> 0 | AD11: =+SUM(F11:AC11)*E11 -> 0
B12: =+B11 -> 45658 | C12: =IFERROR(VLOOKUP(B12,'Prod- 2'!$B$10:$E$81,4,0),0) -> 0 | D12: FES. | E12: =+Basis!D136 -> 2 | F12: =+(Basis!E136/(EOMONTH($B12,0)-$B12+1)*$C12) -> 0 | G12: =+(Basis!F136/(EOMONTH($B12,0)-$B12+1)*$C12) -> 0 | H12: =+(Basis!G136/(EOMONTH($B12,0)-$B12+1)*$C12) -> 0 | I12: =+(Basis!H136/(EOMONTH($B12,0)-$B12+1)*$C12) -> 0 | J12: =+(Basis!I136/(EOMONTH($B12,0)-$B12+1)*$C12) -> 0 | K12: =+(Basis!J136/(EOMONTH($B12,0)-$B12+1)*$C12) -> 0 | L12: =+(Basis!K136/(EOMONTH($B12,0)-$B12+1)*$C12) -> 0 | M12: =+(Basis!L136/(EOMONTH($B12,0)-$B12+1)*$C12) -> 0 | ... AC12: =+(Basis!AB136/(EOMONTH($B12,0)-$B12+1)*$C12) -> 0 | AD12: =+SUM(F12:AC12)*E12 -> 0
D13: TOTAL | E13: =+SUM(E9:E12) -> 31 | F13: =+SUMPRODUCT(F9:F12,$E9:$E12) -> 0 | G13: =+SUMPRODUCT(G9:G12,$E9:$E12) -> 0 | H13: =+SUMPRODUCT(H9:H12,$E9:$E12) -> 0 | I13: =+SUMPRODUCT(I9:I12,$E9:$E12) -> 0 | J13: =+SUMPRODUCT(J9:J12,$E9:$E12) -> 0 | K13: =+SUMPRODUCT(K9:K12,$E9:$E12) -> 0 | L13: =+SUMPRODUCT(L9:L12,$E9:$E12) -> 0 | M13: =+SUMPRODUCT(M9:M12,$E9:$E12) -> 0 | ... AC13: =+SUMPRODUCT(AC9:AC12,$E9:$E12) -> 0 | AD13: =+SUM(AD9:AD12) -> 0 | AE13: =+AD13-C9 -> 0 | AG13: =+AD13/24/E13 -> 0
B14: =+EDATE(B9,1) -> 45689 | C14: =IFERROR(VLOOKUP(B14,'Prod- 2'!$B$10:$E$81,4,0),0) -> 0 | D14: ORD. | E14: =+Basis!D138 -> 20 | F14: =+(Basis!E138/(EOMONTH($B14,0)-$B14+1)*$C14) -> 0 | G14: =+(Basis!F138/(EOMONTH($B14,0)-$B14+1)*$C14) -> 0 | H14: =+(Basis!G138/(EOMONTH($B14,0)-$B14+1)*$C14) -> 0 | I14: =+(Basis!H138/(EOMONTH($B14,0)-$B14+1)*$C14) -> 0 | J14: =+(Basis!I138/(EOMONTH($B14,0)-$B14+1)*$C14) -> 0 | K14: =+(Basis!J138/(EOMONTH($B14,0)-$B14+1)*$C14) -> 0 | L14: =+(Basis!K138/(EOMONTH($B14,0)-$B14+1)*$C14) -> 0 | M14: =+(Basis!L138/(EOMONTH($B14,0)-$B14+1)*$C14) -> 0 | ... AC14: =+(Basis!AB138/(EOMONTH($B14,0)-$B14+1)*$C14) -> 0 | AD14: =+SUM(F14:AC14)*E14 -> 0
B15: =+B14 -> 45689 | C15: =IFERROR(VLOOKUP(B15,'Prod- 2'!$B$10:$E$81,4,0),0) -> 0 | D15: SAB. | E15: =+Basis!D139 -> 4 | F15: =+(Basis!E139/(EOMONTH($B15,0)-$B15+1)*$C15) -> 0 | G15: =+(Basis!F139/(EOMONTH($B15,0)-$B15+1)*$C15) -> 0 | H15: =+(Basis!G139/(EOMONTH($B15,0)-$B15+1)*$C15) -> 0 | I15: =+(Basis!H139/(EOMONTH($B15,0)-$B15+1)*$C15) -> 0 | J15: =+(Basis!I139/(EOMONTH($B15,0)-$B15+1)*$C15) -> 0 | K15: =+(Basis!J139/(EOMONTH($B15,0)-$B15+1)*$C15) -> 0 | L15: =+(Basis!K139/(EOMONTH($B15,0)-$B15+1)*$C15) -> 0 | M15: =+(Basis!L139/(EOMONTH($B15,0)-$B15+1)*$C15) -> 0 | ... AC15: =+(Basis!AB139/(EOMONTH($B15,0)-$B15+1)*$C15) -> 0 | AD15: =+SUM(F15:AC15)*E15 -> 0
B16: =+B15 -> 45689 | C16: =IFERROR(VLOOKUP(B16,'Prod- 2'!$B$10:$E$81,4,0),0) -> 0 | D16: DOM. | E16: =+Basis!D140 -> 4 | F16: =+(Basis!E140/(EOMONTH($B16,0)-$B16+1)*$C16) -> 0 | G16: =+(Basis!F140/(EOMONTH($B16,0)-$B16+1)*$C16) -> 0 | H16: =+(Basis!G140/(EOMONTH($B16,0)-$B16+1)*$C16) -> 0 | I16: =+(Basis!H140/(EOMONTH($B16,0)-$B16+1)*$C16) -> 0 | J16: =+(Basis!I140/(EOMONTH($B16,0)-$B16+1)*$C16) -> 0 | K16: =+(Basis!J140/(EOMONTH($B16,0)-$B16+1)*$C16) -> 0 | L16: =+(Basis!K140/(EOMONTH($B16,0)-$B16+1)*$C16) -> 0 | M16: =+(Basis!L140/(EOMONTH($B16,0)-$B16+1)*$C16) -> 0 | ... AC16: =+(Basis!AB140/(EOMONTH($B16,0)-$B16+1)*$C16) -> 0 | AD16: =+SUM(F16:AC16)*E16 -> 0
B17: =+B16 -> 45689 | C17: =IFERROR(VLOOKUP(B17,'Prod- 2'!$B$10:$E$81,4,0),0) -> 0 | D17: FES. | E17: =+Basis!D141 -> 0 | F17: =+(Basis!E141/(EOMONTH($B17,0)-$B17+1)*$C17) -> 0 | G17: =+(Basis!F141/(EOMONTH($B17,0)-$B17+1)*$C17) -> 0 | H17: =+(Basis!G141/(EOMONTH($B17,0)-$B17+1)*$C17) -> 0 | I17: =+(Basis!H141/(EOMONTH($B17,0)-$B17+1)*$C17) -> 0 | J17: =+(Basis!I141/(EOMONTH($B17,0)-$B17+1)*$C17) -> 0 | K17: =+(Basis!J141/(EOMONTH($B17,0)-$B17+1)*$C17) -> 0 | L17: =+(Basis!K141/(EOMONTH($B17,0)-$B17+1)*$C17) -> 0 | M17: =+(Basis!L141/(EOMONTH($B17,0)-$B17+1)*$C17) -> 0 | ... AC17: =+(Basis!AB141/(EOMONTH($B17,0)-$B17+1)*$C17) -> 0 | AD17: =+SUM(F17:AC17)*E17 -> 0
D18: TOTAL | E18: =+SUM(E14:E17) -> 28 | F18: =+SUMPRODUCT(F14:F17,$E14:$E17) -> 0 | G18: =+SUMPRODUCT(G14:G17,$E14:$E17) -> 0 | H18: =+SUMPRODUCT(H14:H17,$E14:$E17) -> 0 | I18: =+SUMPRODUCT(I14:I17,$E14:$E17) -> 0 | J18: =+SUMPRODUCT(J14:J17,$E14:$E17) -> 0 | K18: =+SUMPRODUCT(K14:K17,$E14:$E17) -> 0 | L18: =+SUMPRODUCT(L14:L17,$E14:$E17) -> 0 | M18: =+SUMPRODUCT(M14:M17,$E14:$E17) -> 0 | ... AC18: =+SUMPRODUCT(AC14:AC17,$E14:$E17) -> 0 | AD18: =+SUM(AD14:AD17) -> 0 | AE18: =+AD18-C14 -> 0 | AG18: =+AD18/24/E18 -> 0
B19: =+EDATE(B14,1) -> 45717 | C19: =IFERROR(VLOOKUP(B19,'Prod- 2'!$B$10:$E$81,4,0),0) -> 0 | D19: ORD. | E19: =+Basis!D143 -> 20 | F19: =+(Basis!E143/(EOMONTH($B19,0)-$B19+1)*$C19) -> 0 | G19: =+(Basis!F143/(EOMONTH($B19,0)-$B19+1)*$C19) -> 0 | H19: =+(Basis!G143/(EOMONTH($B19,0)-$B19+1)*$C19) -> 0 | I19: =+(Basis!H143/(EOMONTH($B19,0)-$B19+1)*$C19) -> 0 | J19: =+(Basis!I143/(EOMONTH($B19,0)-$B19+1)*$C19) -> 0 | K19: =+(Basis!J143/(EOMONTH($B19,0)-$B19+1)*$C19) -> 0 | L19: =+(Basis!K143/(EOMONTH($B19,0)-$B19+1)*$C19) -> 0 | M19: =+(Basis!L143/(EOMONTH($B19,0)-$B19+1)*$C19) -> 0 | ... AC19: =+(Basis!AB143/(EOMONTH($B19,0)-$B19+1)*$C19) -> 0 | AD19: =+SUM(F19:AC19)*E19 -> 0
B20: =+B19 -> 45717 | C20: =IFERROR(VLOOKUP(B20,'Prod- 2'!$B$10:$E$81,4,0),0) -> 0 | D20: SAB. | E20: =+Basis!D144 -> 5 | F20: =+(Basis!E144/(EOMONTH($B20,0)-$B20+1)*$C20) -> 0 | G20: =+(Basis!F144/(EOMONTH($B20,0)-$B20+1)*$C20) -> 0 | H20: =+(Basis!G144/(EOMONTH($B20,0)-$B20+1)*$C20) -> 0 | I20: =+(Basis!H144/(EOMONTH($B20,0)-$B20+1)*$C20) -> 0 | J20: =+(Basis!I144/(EOMONTH($B20,0)-$B20+1)*$C20) -> 0 | K20: =+(Basis!J144/(EOMONTH($B20,0)-$B20+1)*$C20) -> 0 | L20: =+(Basis!K144/(EOMONTH($B20,0)-$B20+1)*$C20) -> 0 | M20: =+(Basis!L144/(EOMONTH($B20,0)-$B20+1)*$C20) -> 0 | ... AC20: =+(Basis!AB144/(EOMONTH($B20,0)-$B20+1)*$C20) -> 0 | AD20: =+SUM(F20:AC20)*E20 -> 0
B21: =+B20 -> 45717 | C21: =IFERROR(VLOOKUP(B21,'Prod- 2'!$B$10:$E$81,4,0),0) -> 0 | D21: DOM. | E21: =+Basis!D145 -> 5 | F21: =+(Basis!E145/(EOMONTH($B21,0)-$B21+1)*$C21) -> 0 | G21: =+(Basis!F145/(EOMONTH($B21,0)-$B21+1)*$C21) -> 0 | H21: =+(Basis!G145/(EOMONTH($B21,0)-$B21+1)*$C21) -> 0 | I21: =+(Basis!H145/(EOMONTH($B21,0)-$B21+1)*$C21) -> 0 | J21: =+(Basis!I145/(EOMONTH($B21,0)-$B21+1)*$C21) -> 0 | K21: =+(Basis!J145/(EOMONTH($B21,0)-$B21+1)*$C21) -> 0 | L21: =+(Basis!K145/(EOMONTH($B21,0)-$B21+1)*$C21) -> 0 | M21: =+(Basis!L145/(EOMONTH($B21,0)-$B21+1)*$C21) -> 0 | ... AC21: =+(Basis!AB145/(EOMONTH($B21,0)-$B21+1)*$C21) -> 0 | AD21: =+SUM(F21:AC21)*E21 -> 0
B22: =+B21 -> 45717 | C22: =IFERROR(VLOOKUP(B22,'Prod- 2'!$B$10:$E$81,4,0),0) -> 0 | D22: FES. | E22: =+Basis!D146 -> 1 | F22: =+(Basis!E146/(EOMONTH($B22,0)-$B22+1)*$C22) -> 0 | G22: =+(Basis!F146/(EOMONTH($B22,0)-$B22+1)*$C22) -> 0 | H22: =+(Basis!G146/(EOMONTH($B22,0)-$B22+1)*$C22) -> 0 | I22: =+(Basis!H146/(EOMONTH($B22,0)-$B22+1)*$C22) -> 0 | J22: =+(Basis!I146/(EOMONTH($B22,0)-$B22+1)*$C22) -> 0 | K22: =+(Basis!J146/(EOMONTH($B22,0)-$B22+1)*$C22) -> 0 | L22: =+(Basis!K146/(EOMONTH($B22,0)-$B22+1)*$C22) -> 0 | M22: =+(Basis!L146/(EOMONTH($B22,0)-$B22+1)*$C22) -> 0 | ... AC22: =+(Basis!AB146/(EOMONTH($B22,0)-$B22+1)*$C22) -> 0 | AD22: =+SUM(F22:AC22)*E22 -> 0
D23: TOTAL | E23: =+SUM(E19:E22) -> 31 | F23: =+SUMPRODUCT(F19:F22,$E19:$E22) -> 0 | G23: =+SUMPRODUCT(G19:G22,$E19:$E22) -> 0 | H23: =+SUMPRODUCT(H19:H22,$E19:$E22) -> 0 | I23: =+SUMPRODUCT(I19:I22,$E19:$E22) -> 0 | J23: =+SUMPRODUCT(J19:J22,$E19:$E22) -> 0 | K23: =+SUMPRODUCT(K19:K22,$E19:$E22) -> 0 | L23: =+SUMPRODUCT(L19:L22,$E19:$E22) -> 0 | M23: =+SUMPRODUCT(M19:M22,$E19:$E22) -> 0 | ... AC23: =+SUMPRODUCT(AC19:AC22,$E19:$E22) -> 0 | AD23: =+SUM(AD19:AD22) -> 0 | AE23: =+AD23-C19 -> 0 | AG23: =+AD23/24/E23 -> 0
B24: =+EDATE(B19,1) -> 45748 | C24: =IFERROR(VLOOKUP(B24,'Prod- 2'!$B$10:$E$81,4,0),0) -> 0 | D24: ORD. | E24: =+Basis!D148 -> 20 | F24: =+(Basis!E148/(EOMONTH($B24,0)-$B24+1)*$C24) -> 0 | G24: =+(Basis!F148/(EOMONTH($B24,0)-$B24+1)*$C24) -> 0 | H24: =+(Basis!G148/(EOMONTH($B24,0)-$B24+1)*$C24) -> 0 | I24: =+(Basis!H148/(EOMONTH($B24,0)-$B24+1)*$C24) -> 0 | J24: =+(Basis!I148/(EOMONTH($B24,0)-$B24+1)*$C24) -> 0 | K24: =+(Basis!J148/(EOMONTH($B24,0)-$B24+1)*$C24) -> 0 | L24: =+(Basis!K148/(EOMONTH($B24,0)-$B24+1)*$C24) -> 0 | M24: =+(Basis!L148/(EOMONTH($B24,0)-$B24+1)*$C24) -> 0 | ... AC24: =+(Basis!AB148/(EOMONTH($B24,0)-$B24+1)*$C24) -> 0 | AD24: =+SUM(F24:AC24)*E24 -> 0
B25: =+B24 -> 45748 | C25: =IFERROR(VLOOKUP(B25,'Prod- 2'!$B$10:$E$81,4,0),0) -> 0 | D25: SAB. | E25: =+Basis!D149 -> 4 | F25: =+(Basis!E149/(EOMONTH($B25,0)-$B25+1)*$C25) -> 0 | G25: =+(Basis!F149/(EOMONTH($B25,0)-$B25+1)*$C25) -> 0 | H25: =+(Basis!G149/(EOMONTH($B25,0)-$B25+1)*$C25) -> 0 | I25: =+(Basis!H149/(EOMONTH($B25,0)-$B25+1)*$C25) -> 0 | J25: =+(Basis!I149/(EOMONTH($B25,0)-$B25+1)*$C25) -> 0 | K25: =+(Basis!J149/(EOMONTH($B25,0)-$B25+1)*$C25) -> 0 | L25: =+(Basis!K149/(EOMONTH($B25,0)-$B25+1)*$C25) -> 0 | M25: =+(Basis!L149/(EOMONTH($B25,0)-$B25+1)*$C25) -> 0 | ... AC25: =+(Basis!AB149/(EOMONTH($B25,0)-$B25+1)*$C25) -> 0 | AD25: =+SUM(F25:AC25)*E25 -> 0
B26: =+B25 -> 45748 | C26: =IFERROR(VLOOKUP(B26,'Prod- 2'!$B$10:$E$81,4,0),0) -> 0 | D26: DOM. | E26: =+Basis!D150 -> 4 | F26: =+(Basis!E150/(EOMONTH($B26,0)-$B26+1)*$C26) -> 0 | G26: =+(Basis!F150/(EOMONTH($B26,0)-$B26+1)*$C26) -> 0 | H26: =+(Basis!G150/(EOMONTH($B26,0)-$B26+1)*$C26) -> 0 | I26: =+(Basis!H150/(EOMONTH($B26,0)-$B26+1)*$C26) -> 0 | J26: =+(Basis!I150/(EOMONTH($B26,0)-$B26+1)*$C26) -> 0 | K26: =+(Basis!J150/(EOMONTH($B26,0)-$B26+1)*$C26) -> 0 | L26: =+(Basis!K150/(EOMONTH($B26,0)-$B26+1)*$C26) -> 0 | M26: =+(Basis!L150/(EOMONTH($B26,0)-$B26+1)*$C26) -> 0 | ... AC26: =+(Basis!AB150/(EOMONTH($B26,0)-$B26+1)*$C26) -> 0 | AD26: =+SUM(F26:AC26)*E26 -> 0
B27: =+B26 -> 45748 | C27: =IFERROR(VLOOKUP(B27,'Prod- 2'!$B$10:$E$81,4,0),0) -> 0 | D27: FES. | E27: =+Basis!D151 -> 2 | F27: =+(Basis!E151/(EOMONTH($B27,0)-$B27+1)*$C27) -> 0 | G27: =+(Basis!F151/(EOMONTH($B27,0)-$B27+1)*$C27) -> 0 | H27: =+(Basis!G151/(EOMONTH($B27,0)-$B27+1)*$C27) -> 0 | I27: =+(Basis!H151/(EOMONTH($B27,0)-$B27+1)*$C27) -> 0 | J27: =+(Basis!I151/(EOMONTH($B27,0)-$B27+1)*$C27) -> 0 | K27: =+(Basis!J151/(EOMONTH($B27,0)-$B27+1)*$C27) -> 0 | L27: =+(Basis!K151/(EOMONTH($B27,0)-$B27+1)*$C27) -> 0 | M27: =+(Basis!L151/(EOMONTH($B27,0)-$B27+1)*$C27) -> 0 | ... AC27: =+(Basis!AB151/(EOMONTH($B27,0)-$B27+1)*$C27) -> 0 | AD27: =+SUM(F27:AC27)*E27 -> 0
