Workbook
Name _bookmark27: P1_Anexo_1_2026!#REF!

Sheet RESUMEN
B2: MERCADO REGULADO CONVOCATORIA EMIC2025-003
B3: PRODUCTO | C3: AÑO | D3: CURVA / PLANO | E3: ENERGÍA SOLICITADA (GWh/Año)
B4: 1 | C4: 2026 | D4: Plano | E4: =P1_Anexo_2_2026!D14/1000 -> 700.8
B5: 2 | C5: 2027 | D5: Plano | E5: =P2_Anexo_2_2027!D14/1000 -> 769.0404
B6: 3 | C6: 2028 | D6: Plano | E6: =P3_Anexo_2_2028!D14/1000 -> 695.78064
B7: 4 | C7: 2028 | D7: Curva | E7: =P4_Anexo_2_2028!D14/1000 -> 833.75818
B8: 5 | C8: 2029 | D8: Plano | E8: =P5_Anexo_2_2029!D14/1000 -> 673.5564
B9: 6 | C9: 2029 | D9: Curva | E9: =P6_Anexo_2_2029!D14/1000 -> 807.89054
B10: 7 | C10: 2030 | D10: Plano | E10: =P7_Anexo_2_2030!D14/1000 -> 562.1292
B11: 8 | C11: 2030 | D11: Curva | E11: =P8_Anexo_2_2030!D14/1000 -> 675.43635
B12: 9 | C12: 2031 | D12: Plano | E12: =P9_Anexo_2_2031!D14/1000 -> 450.702
B13: 10 | C13: 2031 | D13: Curva | E13: =P10_Anexo_2_2031!D13/1000 -> 541.01554
B14: 11 | C14: 2032 | D14: Plano | E14: =P11_Anexo_2_2032!D14/1000 -> 338.184
B15: 12 | C15: 2032 | D15: Curva | E15: =P12_Anexo_2_2032!D14/1000 -> 405.85487
B16: Total | E16: =SUM(E4:E15) -> 7454.1481
B17: NOTAS:
B18: Una sola convocatoria através del SICEP

Sheet P1_Anexo_1_2026
B2: ANEXO No. 1 - CANTIDADES DE ENERGÍA HORARIA Y MENSUAL A CONTRATAR
B3: PRODUCTO 1 - 1 DE ENERO A 31 DE DICIEMBRE 2026
B5: ENERGÍA PLANA A SOLICITAR AÑO 2026 PARA MERCADO REGULADO (MWh)
B6: MES | C6: DÍA | D6: H1 | E6: H2 | F6: H3 | G6: H4 | H6: H5 | I6: H6 | J6: H7 | K6: H8 | L6: H9 | M6: H10 | N6: H11 | O6: H12 | P6: H13 | Q6: H14 | R6: H15 | S6: H16 | T6: H17 | U6: H18 | V6: H19 | W6: H20 | X6: H21 | Y6: H22 | Z6: H23 | AA6: H24 | AB6: TOTAL | AC6: No. Dias | AD6: TOTAL MES
B7: 46023 | C7: ORDINARIO | D7: 80 | E7: 80 | F7: 80 | G7: 80 | H7: 80 | I7: 80 | J7: 80 | K7: 80 | L7: 80 | M7: 80 | N7: 80 | O7: 80 | P7: 80 | Q7: 80 | R7: 80 | S7: 80 | T7: 80 | U7: 80 | V7: 80 | W7: 80 | X7: 80 | Y7: 80 | Z7: 80 | AA7: 80 | AB7: =SUM(D7:AA7) -> 1920 | AC7: 20 | AD7: =+AB7*AC7+AB8*AC8+AB9*AC9 -> 59520
C8: SABADO | D8: 80 | E8: 80 | F8: 80 | G8: 80 | H8: 80 | I8: 80 | J8: 80 | K8: 80 | L8: 80 | M8: 80 | N8: 80 | O8: 80 | P8: 80 | Q8: 80 | R8: 80 | S8: 80 | T8: 80 | U8: 80 | V8: 80 | W8: 80 | X8: 80 | Y8: 80 | Z8: 80 | AA8: 80 | AB8: =SUM(D8:AA8) -> 1920 | AC8: 5
C9: FESTIVO | D9: 80 | E9: 80 | F9: 80 | G9: 80 | H9: 80 | I9: 80 | J9: 80 | K9: 80 | L9: 80 | M9: 80 | N9: 80 | O9: 80 | P9: 80 | Q9: 80 | R9: 80 | S9: 80 | T9: 80 | U9: 80 | V9: 80 | W9: 80 | X9: 80 | Y9: 80 | Z9: 80 | AA9: 80 | AB9: =SUM(D9:AA9) -> 1920 | AC9: 6
B10: 46054 | C10: ORDINARIO | D10: 80 | E10: 80 | F10: 80 | G10: 80 | H10: 80 | I10: 80 | J10: 80 | K10: 80 | L10: 80 | M10: 80 | N10: 80 | O10: 80 | P10: 80 | Q10: 80 | R10: 80 | S10: 80 | T10: 80 | U10: 80 | V10: 80 | W10: 80 | X10: 80 | Y10: 80 | Z10: 80 | AA10: 80 | AB10: =SUM(D10:AA10) -> 1920 | AC10: 20 | AD10: =+AB10*AC10+AB11*AC11+AB12*AC12 -> 53760
C11: SABADO | D11: 80 | E11: 80 | F11: 80 | G11: 80 | H11: 80 | I11: 80 | J11: 80 | K11: 80 | L11: 80 | M11: 80 | N11: 80 | O11: 80 | P11: 80 | Q11: 80 | R11: 80 | S11: 80 | T11: 80 | U11: 80 | V11: 80 | W11: 80 | X11: 80 | Y11: 80 | Z11: 80 | AA11: 80 | AB11: =SUM(D11:AA11) -> 1920 | AC11: 4
C12: FESTIVO | D12: 80 | E12: 80 | F12: 80 | G12: 80 | H12: 80 | I12: 80 | J12: 80 | K12: 80 | L12: 80 | M12: 80 | N12: 80 | O12: 80 | P12: 80 | Q12: 80 | R12: 80 | S12: 80 | T12: 80 | U12: 80 | V12: 80 | W12: 80 | X12: 80 | Y12: 80 | Z12: 80 | AA12: 80 | AB12: =SUM(D12:AA12) -> 1920 | AC12: 4
B13: 46082 | C13: ORDINARIO | D13: 80 | E13: 80 | F13: 80 | G13: 80 | H13: 80 | I13: 80 | J13: 80 | K13: 80 | L13: 80 | M13: 80 | N13: 80 | O13: 80 | P13: 80 | Q13: 80 | R13: 80 | S13: 80 | T13: 80 | U13: 80 | V13: 80 | W13: 80 | X13: 80 | Y13: 80 | Z13: 80 | AA13: 80 | AB13: =SUM(D13:AA13) -> 1920 | AC13: 21 | AD13: =+AB13*AC13+AB14*AC14+AB15*AC15 -> 59520
C14: SABADO | D14: 80 | E14: 80 | F14: 80 | G14: 80 | H14: 80 | I14: 80 | J14: 80 | K14: 80 | L14: 80 | M14: 80 | N14: 80 | O14: 80 | P14: 80 | Q14: 80 | R14: 80 | S14: 80 | T14: 80 | U14: 80 | V14: 80 | W14: 80 | X14: 80 | Y14: 80 | Z14: 80 | AA14: 80 | AB14: =SUM(D14:AA14) -> 1920 | AC14: 4
C15: FESTIVO | D15: 80 | E15: 80 | F15: 80 | G15: 80 | H15: 80 | I15: 80 | J15: 80 | K15: 80 | L15: 80 | M15: 80 | N15: 80 | O15: 80 | P15: 80 | Q15: 80 | R15: 80 | S15: 80 | T15: 80 | U15: 80 | V15: 80 | W15: 80 | X15: 80 | Y15: 80 | Z15: 80 | AA15: 80 | AB15: =SUM(D15:AA15) -> 1920 | AC15: 6
B16: 46113 | C16: ORDINARIO | D16: 80 | E16: 80 | F16: 80 | G16: 80 | H16: 80 | I16: 80 | J16: 80 | K16: 80 | L16: 80 | M16: 80 | N16: 80 | O16: 80 | P16: 80 | Q16: 80 | R16: 80 | S16: 80 | T16: 80 | U16: 80 | V16: 80 | W16: 80 | X16: 80 | Y16: 80 | Z16: 80 | AA16: 80 | AB16: =SUM(D16:AA16) -> 1920 | AC16: 20 | AD16: =+AB16*AC16+AB17*AC17+AB18*AC18 -> 57600
C17: SABADO | D17: 80 | E17: 80 | F17: 80 | G17: 80 | H17: 80 | I17: 80 | J17: 80 | K17: 80 | L17: 80 | M17: 80 | N17: 80 | O17: 80 | P17: 80 | Q17: 80 | R17: 80 | S17: 80 | T17: 80 | U17: 80 | V17: 80 | W17: 80 | X17: 80 | Y17: 80 | Z17: 80 | AA17: 80 | AB17: =SUM(D17:AA17) -> 1920 | AC17: 4
C18: FESTIVO | D18: 80 | E18: 80 | F18: 80 | G18: 80 | H18: 80 | I18: 80 | J18: 80 | K18: 80 | L18: 80 | M18: 80 | N18: 80 | O18: 80 | P18: 80 | Q18: 80 | R18: 80 | S18: 80 | T18: 80 | U18: 80 | V18: 80 | W18: 80 | X18: 80 | Y18: 80 | Z18: 80 | AA18: 80 | AB18: =SUM(D18:AA18) -> 1920 | AC18: 6
B19: 46143 | C19: ORDINARIO | D19: 80 | E19: 80 | F19: 80 | G19: 80 | H19: 80 | I19: 80 | J19: 80 | K19: 80 | L19: 80 | M19: 80 | N19: 80 | O19: 80 | P19: 80 | Q19: 80 | R19: 80 | S19: 80 | T19: 80 | U19: 80 | V19: 80 | W19: 80 | X19: 80 | Y19: 80 | Z19: 80 | AA19: 80 | AB19: =SUM(D19:AA19) -> 1920 | AC19: 19 | AD19: =+AB19*AC19+AB20*AC20+AB21*AC21 -> 59520
C20: SABADO | D20: 80 | E20: 80 | F20: 80 | G20: 80 | H20: 80 | I20: 80 | J20: 80 | K20: 80 | L20: 80 | M20: 80 | N20: 80 | O20: 80 | P20: 80 | Q20: 80 | R20: 80 | S20: 80 | T20: 80 | U20: 80 | V20: 80 | W20: 80 | X20: 80 | Y20: 80 | Z20: 80 | AA20: 80 | AB20: =SUM(D20:AA20) -> 1920 | AC20: 5
C21: FESTIVO | D21: 80 | E21: 80 | F21: 80 | G21: 80 | H21: 80 | I21: 80 | J21: 80 | K21: 80 | L21: 80 | M21: 80 | N21: 80 | O21: 80 | P21: 80 | Q21: 80 | R21: 80 | S21: 80 | T21: 80 | U21: 80 | V21: 80 | W21: 80 | X21: 80 | Y21: 80 | Z21: 80 | AA21: 80 | AB21: =SUM(D21:AA21) -> 1920 | AC21: 7
B22: 46174 | C22: ORDINARIO | D22: 80 | E22: 80 | F22: 80 | G22: 80 | H22: 80 | I22: 80 | J22: 80 | K22: 80 | L22: 80 | M22: 80 | N22: 80 | O22: 80 | P22: 80 | Q22: 80 | R22: 80 | S22: 80 | T22: 80 | U22: 80 | V22: 80 | W22: 80 | X22: 80 | Y22: 80 | Z22: 80 | AA22: 80 | AB22: =SUM(D22:AA22) -> 1920 | AC22: 19 | AD22: =+AB22*AC22+AB23*AC23+AB24*AC24 -> 57600
C23: SABADO | D23: 80 | E23: 80 | F23: 80 | G23: 80 | H23: 80 | I23: 80 | J23: 80 | K23: 80 | L23: 80 | M23: 80 | N23: 80 | O23: 80 | P23: 80 | Q23: 80 | R23: 80 | S23: 80 | T23: 80 | U23: 80 | V23: 80 | W23: 80 | X23: 80 | Y23: 80 | Z23: 80 | AA23: 80 | AB23: =SUM(D23:AA23) -> 1920 | AC23: 4
C24: FESTIVO | D24: 80 | E24: 80 | F24: 80 | G24: 80 | H24: 80 | I24: 80 | J24: 80 | K24: 80 | L24: 80 | M24: 80 | N24: 80 | O24: 80 | P24: 80 | Q24: 80 | R24: 80 | S24: 80 | T24: 80 | U24: 80 | V24: 80 | W24: 80 | X24: 80 | Y24: 80 | Z24: 80 | AA24: 80 | AB24: =SUM(D24:AA24) -> 1920 | AC24: 7
B25: 46204 | C25: ORDINARIO | D25: 80 | E25: 80 | F25: 80 | G25: 80 | H25: 80 | I25: 80 | J25: 80 | K25: 80 | L25: 80 | M25: 80 | N25: 80 | O25: 80 | P25: 80 | Q25: 80 | R25: 80 | S25: 80 | T25: 80 | U25: 80 | V25: 80 | W25: 80 | X25: 80 | Y25: 80 | Z25: 80 | AA25: 80 | AB25: =SUM(D25:AA25) -> 1920 | AC25: 22 | AD25: =+AB25*AC25+AB26*AC26+AB27*AC27 -> 59520
C26: SABADO | D26: 80 | E26: 80 | F26: 80 | G26: 80 | H26: 80 | I26: 80 | J26: 80 | K26: 80 | L26: 80 | M26: 80 | N26: 80 | O26: 80 | P26: 80 | Q26: 80 | R26: 80 | S26: 80 | T26: 80 | U26: 80 | V26: 80 | W26: 80 | X26: 80 | Y26: 80 | Z26: 80 | AA26: 80 | AB26: =SUM(D26:AA26) -> 1920 | AC26: 4
C27: FESTIVO | D27: 80 | E27: 80 | F27: 80 | G27: 80 | H27: 80 | I27: 80 | J27: 80 | K27: 80 | L27: 80 | M27: 80 | N27: 80 | O27: 80 | P27: 80 | Q27: 80 | R27: 80 | S27: 80 | T27: 80 | U27: 80 | V27: 80 | W27: 80 | X27: 80 | Y27: 80 | Z27: 80 | AA27: 80 | AB27: =SUM(D27:AA27) -> 1920 | AC27: 5
B28: 46235 | C28: ORDINARIO | D28: 80 | E28: 80 | F28: 80 | G28: 80 | H28: 80 | I28: 80 | J28: 80 | K28: 80 | L28: 80 | M28: 80 | N28: 80 | O28: 80 | P28: 80 | Q28: 80 | R28: 80 | S28: 80 | T28: 80 | U28: 80 | V28: 80 | W28: 80 | X28: 80 | Y28: 80 | Z28: 80 | AA28: 80 | AB28: =SUM(D28:AA28) -> 1920 | AC28: 19 | AD28: =+AB28*AC28+AB29*AC29+AB30*AC30 -> 59520
C29: SABADO | D29: 80 | E29: 80 | F29: 80 | G29: 80 | H29: 80 | I29: 80 | J29: 80 | K29: 80 | L29: 80 | M29: 80 | N29: 80 | O29: 80 | P29: 80 | Q29: 80 | R29: 80 | S29: 80 | T29: 80 | U29: 80 | V29: 80 | W29: 80 | X29: 80 | Y29: 80 | Z29: 80 | AA29: 80 | AB29: =SUM(D29:AA29) -> 1920 | AC29: 5
C30: FESTIVO | D30: 80 | E30: 80 | F30: 80 | G30: 80 | H30: 80 | I30: 80 | J30: 80 | K30: 80 | L30: 80 | M30: 80 | N30: 80 | O30: 80 | P30: 80 | Q30: 80 | R30: 80 | S30: 80 | T30: 80 | U30: 80 | V30: 80 | W30: 80 | X30: 80 | Y30: 80 | Z30: 80 | AA30: 80 | AB30: =SUM(D30:AA30) -> 1920 | AC30: 7
B31: 46266 | C31: ORDINARIO | D31: 80 | E31: 80 | F31: 80 | G31: 80 | H31: 80 | I31: 80 | J31: 80 | K31: 80 | L31: 80 | M31: 80 | N31: 80 | O31: 80 | P31: 80 | Q31: 80 | R31: 80 | S31: 80 | T31: 80 | U31: 80 | V31: 80 | W31: 80 | X31: 80 | Y31: 80 | Z31: 80 | AA31: 80 | AB31: =SUM(D31:AA31) -> 1920 | AC31: 22 | AD31: =+AB31*AC31+AB32*AC32+AB33*AC33 -> 57600
C32: SABADO | D32: 80 | E32: 80 | F32: 80 | G32: 80 | H32: 80 | I32: 80 | J32: 80 | K32: 80 | L32: 80 | M32: 80 | N32: 80 | O32: 80 | P32: 80 | Q32: 80 | R32: 80 | S32: 80 | T32: 80 | U32: 80 | V32: 80 | W32: 80 | X32: 80 | Y32: 80 | Z32: 80 | AA32: 80 | AB32: =SUM(D32:AA32) -> 1920 | AC32: 4
C33: FESTIVO | D33: 80 | E33: 80 | F33: 80 | G33: 80 | H33: 80 | I33: 80 | J33: 80 | K33: 80 | L33: 80 | M33: 80 | N33: 80 | O33: 80 | P33: 80 | Q33: 80 | R33: 80 | S33: 80 | T33: 80 | U33: 80 | V33: 80 | W33: 80 | X33: 80 | Y33: 80 | Z33: 80 | AA33: 80 | AB33: =SUM(D33:AA33) -> 1920 | AC33: 4
B34: 46296 | C34: ORDINARIO | D34: 80 | E34: 80 | F34: 80 | G34: 80 | H34: 80 | I34: 80 | J34: 80 | K34: 80 | L34: 80 | M34: 80 | N34: 80 | O34: 80 | P34: 80 | Q34: 80 | R34: 80 | S34: 80 | T34: 80 | U34: 80 | V34: 80 | W34: 80 | X34: 80 | Y34: 80 | Z34: 80 | AA34: 80 | AB34: =SUM(D34:AA34) -> 1920 | AC34: 21 | AD34: =+AB34*AC34+AB35*AC35+AB36*AC36 -> 59520
C35: SABADO | D35: 80 | E35: 80 | F35: 80 | G35: 80 | H35: 80 | I35: 80 | J35: 80 | K35: 80 | L35: 80 | M35: 80 | N35: 80 | O35: 80 | P35: 80 | Q35: 80 | R35: 80 | S35: 80 | T35: 80 | U35: 80 | V35: 80 | W35: 80 | X35: 80 | Y35: 80 | Z35: 80 | AA35: 80 | AB35: =SUM(D35:AA35) -> 1920 | AC35: 5
C36: FESTIVO | D36: 80 | E36: 80 | F36: 80 | G36: 80 | H36: 80 | I36: 80 | J36: 80 | K36: 80 | L36: 80 | M36: 80 | N36: 80 | O36: 80 | P36: 80 | Q36: 80 | R36: 80 | S36: 80 | T36: 80 | U36: 80 | V36: 80 | W36: 80 | X36: 80 | Y36: 80 | Z36: 80 | AA36: 80 | AB36: =SUM(D36:AA36) -> 1920 | AC36: 5
B37: 46327 | C37: ORDINARIO | D37: 80 | E37: 80 | F37: 80 | G37: 80 | H37: 80 | I37: 80 | J37: 80 | K37: 80 | L37: 80 | M37: 80 | N37: 80 | O37: 80 | P37: 80 | Q37: 80 | R37: 80 | S37: 80 | T37: 80 | U37: 80 | V37: 80 | W37: 80 | X37: 80 | Y37: 80 | Z37: 80 | AA37: 80 | AB37: =SUM(D37:AA37) -> 1920 | AC37: 19 | AD37: =+AB37*AC37+AB38*AC38+AB39*AC39 -> 57600
C38: SABADO | D38: 80 | E38: 80 | F38: 80 | G38: 80 | H38: 80 | I38: 80 | J38: 80 | K38: 80 | L38: 80 | M38: 80 | N38: 80 | O38: 80 | P38: 80 | Q38: 80 | R38: 80 | S38: 80 | T38: 80 | U38: 80 | V38: 80 | W38: 80 | X38: 80 | Y38: 80 | Z38: 80 | AA38: 80 | AB38: =SUM(D38:AA38) -> 1920 | AC38: 4
C39: FESTIVO | D39: 80 | E39: 80 | F39: 80 | G39: 80 | H39: 80 | I39: 80 | J39: 80 | K39: 80 | L39: 80 | M39: 80 | N39: 80 | O39: 80 | P39: 80 | Q39: 80 | R39: 80 | S39: 80 | T39: 80 | U39: 80 | V39: 80 | W39: 80 | X39: 80 | Y39: 80 | Z39: 80 | AA39: 80 | AB39: =SUM(D39:AA39) -> 1920 | AC39: 7
B40: 46357 | C40: ORDINARIO | D40: 80 | E40: 80 | F40: 80 | G40: 80 | H40: 80 | I40: 80 | J40: 80 | K40: 80 | L40: 80 | M40: 80 | N40: 80 | O40: 80 | P40: 80 | Q40: 80 | R40: 80 | S40: 80 | T40: 80 | U40: 80 | V40: 80 | W40: 80 | X40: 80 | Y40: 80 | Z40: 80 | AA40: 80 | AB40: =SUM(D40:AA40) -> 1920 | AC40: 21 | AD40: =+AB40*AC40+AB41*AC41+AB42*AC42 -> 59520
C41: SABADO | D41: 80 | E41: 80 | F41: 80 | G41: 80 | H41: 80 | I41: 80 | J41: 80 | K41: 80 | L41: 80 | M41: 80 | N41: 80 | O41: 80 | P41: 80 | Q41: 80 | R41: 80 | S41: 80 | T41: 80 | U41: 80 | V41: 80 | W41: 80 | X41: 80 | Y41: 80 | Z41: 80 | AA41: 80 | AB41: =SUM(D41:AA41) -> 1920 | AC41: 4
C42: FESTIVO | D42: 80 | E42: 80 | F42: 80 | G42: 80 | H42: 80 | I42: 80 | J42: 80 | K42: 80 | L42: 80 | M42: 80 | N42: 80 | O42: 80 | P42: 80 | Q42: 80 | R42: 80 | S42: 80 | T42: 80 | U42: 80 | V42: 80 | W42: 80 | X42: 80 | Y42: 80 | Z42: 80 | AA42: 80 | AB42: =SUM(D42:AA42) -> 1920 | AC42: 6
...

Sheet P1_Anexo_2_2026
C3: EMPRESAS MUNICIPALES DE CALI- EMCALI EICE ESP
C4: CONVOCATORIA PÚBLICA PARA COMPRA DE ENERGÍA
C5: Código de Convocatoria SICEP No. CP-EMIC2025-003
C7: ANEXO No. 2 CANTIDADES Y PRECIOS OFERTADOS
C9: PRODUCTO 1 - 1 DE ENERO A 31 DE DICIEMBRE 2026 - PLANO
C12: AÑO | D12: Energía solicitada (MWh) | E12: Energía Ofertada (MWh) | F12: $/kWh
C13: 2026 | D13: =P1_Anexo_1_2026!AD43 -> 700800
C14: Total año | D14: =SUM(D13:D13) -> 700800
C17: NOTAS:
C18: 1- Se debe ofertar todo el año, la misma cantidad horaria por período
C19: 2- Se debe ofertar mínimo quince (15) MWh para cada período horario ofertado
C20: 3- La energía y los precios a ofertar deben ofrecerse en la modalidad monomia.
C21: 4- Precios en pesos constantes del mes de agosto de 2025.

Sheet P2_Anexo_ 1_2027
B2: ANEXO No. 1 - CANTIDADES DE ENERGÍA HORARIA Y MENSUAL A CONTRATAR
B3: PRODUCTO 2 - 1 DE ENERO A 31 DE DICIEMBRE 2027
B5: ENERGÍA PLANA A SOLICITAR AÑO 2027 PARA MERCADO REGULADO (MWh)
B6: MES | C6: DÍA | D6: H1 | E6: H2 | F6: H3 | G6: H4 | H6: H5 | I6: H6 | J6: H7 | K6: H8 | L6: H9 | M6: H10 | N6: H11 | O6: H12 | P6: H13 | Q6: H14 | R6: H15 | S6: H16 | T6: H17 | U6: H18 | V6: H19 | W6: H20 | X6: H21 | Y6: H22 | Z6: H23 | AA6: H24 | AB6: TOTAL | AC6: No. Dias | AD6: TOTAL MES
B7: 46388 | C7: ORDINARIO | D7: 87.79 | E7: 87.79 | F7: 87.79 | G7: 87.79 | H7: 87.79 | I7: 87.79 | J7: 87.79 | K7: 87.79 | L7: 87.79 | M7: 87.79 | N7: 87.79 | O7: 87.79 | P7: 87.79 | Q7: 87.79 | R7: 87.79 | S7: 87.79 | T7: 87.79 | U7: 87.79 | V7: 87.79 | W7: 87.79 | X7: 87.79 | Y7: 87.79 | Z7: 87.79 | AA7: 87.79 | AB7: =SUM(D7:AA7) -> 2106.96 | AC7: 19 | AD7: =+AB7*AC7+AB8*AC8+AB9*AC9 -> 65315.76
C8: SABADO | D8: 87.79 | E8: 87.79 | F8: 87.79 | G8: 87.79 | H8: 87.79 | I8: 87.79 | J8: 87.79 | K8: 87.79 | L8: 87.79 | M8: 87.79 | N8: 87.79 | O8: 87.79 | P8: 87.79 | Q8: 87.79 | R8: 87.79 | S8: 87.79 | T8: 87.79 | U8: 87.79 | V8: 87.79 | W8: 87.79 | X8: 87.79 | Y8: 87.79 | Z8: 87.79 | AA8: 87.79 | AB8: =SUM(D8:AA8) -> 2106.96 | AC8: 5
C9: FESTIVO | D9: 87.79 | E9: 87.79 | F9: 87.79 | G9: 87.79 | H9: 87.79 | I9: 87.79 | J9: 87.79 | K9: 87.79 | L9: 87.79 | M9: 87.79 | N9: 87.79 | O9: 87.79 | P9: 87.79 | Q9: 87.79 | R9: 87.79 | S9: 87.79 | T9: 87.79 | U9: 87.79 | V9: 87.79 | W9: 87.79 | X9: 87.79 | Y9: 87.79 | Z9: 87.79 | AA9: 87.79 | AB9: =SUM(D9:AA9) -> 2106.96 | AC9: 7
B10: 46419 | C10: ORDINARIO | D10: 87.79 | E10: 87.79 | F10: 87.79 | G10: 87.79 | H10: 87.79 | I10: 87.79 | J10: 87.79 | K10: 87.79 | L10: 87.79 | M10: 87.79 | N10: 87.79 | O10: 87.79 | P10: 87.79 | Q10: 87.79 | R10: 87.79 | S10: 87.79 | T10: 87.79 | U10: 87.79 | V10: 87.79 | W10: 87.79 | X10: 87.79 | Y10: 87.79 | Z10: 87.79 | AA10: 87.79 | AB10: =SUM(D10:AA10) -> 2106.96 | AC10: 20 | AD10: =+AB10*AC10+AB11*AC11+AB12*AC12 -> 58994.88
C11: SABADO | D11: 87.79 | E11: 87.79 | F11: 87.79 | G11: 87.79 | H11: 87.79 | I11: 87.79 | J11: 87.79 | K11: 87.79 | L11: 87.79 | M11: 87.79 | N11: 87.79 | O11: 87.79 | P11: 87.79 | Q11: 87.79 | R11: 87.79 | S11: 87.79 | T11: 87.79 | U11: 87.79 | V11: 87.79 | W11: 87.79 | X11: 87.79 | Y11: 87.79 | Z11: 87.79 | AA11: 87.79 | AB11: =SUM(D11:AA11) -> 2106.96 | AC11: 4
C12: FESTIVO | D12: 87.79 | E12: 87.79 | F12: 87.79 | G12: 87.79 | H12: 87.79 | I12: 87.79 | J12: 87.79 | K12: 87.79 | L12: 87.79 | M12: 87.79 | N12: 87.79 | O12: 87.79 | P12: 87.79 | Q12: 87.79 | R12: 87.79 | S12: 87.79 | T12: 87.79 | U12: 87.79 | V12: 87.79 | W12: 87.79 | X12: 87.79 | Y12: 87.79 | Z12: 87.79 | AA12: 87.79 | AB12: =SUM(D12:AA12) -> 2106.96 | AC12: 4
B13: 46447 | C13: ORDINARIO | D13: 87.79 | E13: 87.79 | F13: 87.79 | G13: 87.79 | H13: 87.79 | I13: 87.79 | J13: 87.79 | K13: 87.79 | L13: 87.79 | M13: 87.79 | N13: 87.79 | O13: 87.79 | P13: 87.79 | Q13: 87.79 | R13: 87.79 | S13: 87.79 | T13: 87.79 | U13: 87.79 | V13: 87.79 | W13: 87.79 | X13: 87.79 | Y13: 87.79 | Z13: 87.79 | AA13: 87.79 | AB13: =SUM(D13:AA13) -> 2106.96 | AC13: 20 | AD13: =+AB13*AC13+AB14*AC14+AB15*AC15 -> 65315.76
C14: SABADO | D14: 87.79 | E14: 87.79 | F14: 87.79 | G14: 87.79 | H14: 87.79 | I14: 87.79 | J14: 87.79 | K14: 87.79 | L14: 87.79 | M14: 87.79 | N14: 87.79 | O14: 87.79 | P14: 87.79 | Q14: 87.79 | R14: 87.79 | S14: 87.79 | T14: 87.79 | U14: 87.79 | V14: 87.79 | W14: 87.79 | X14: 87.79 | Y14: 87.79 | Z14: 87.79 | AA14: 87.79 | AB14: =SUM(D14:AA14) -> 2106.96 | AC14: 4
C15: FESTIVO | D15: 87.79 | E15: 87.79 | F15: 87.79 | G15: 87.79 | H15: 87.79 | I15: 87.79 | J15: 87.79 | K15: 87.79 | L15: 87.79 | M15: 87.79 | N15: 87.79 | O15: 87.79 | P15: 87.79 | Q15: 87.79 | R15: 87.79 | S15: 87.79 | T15: 87.79 | U15: 87.79 | V15: 87.79 | W15: 87.79 | X15: 87.79 | Y15: 87.79 | Z15: 87.79 | AA15: 87.79 | AB15: =SUM(D15:AA15) -> 2106.96 | AC15: 7
B16: 46478 | C16: ORDINARIO | D16: 87.79 | E16: 87.79 | F16: 87.79 | G16: 87.79 | H16: 87.79 | I16: 87.79 | J16: 87.79 | K16: 87.79 | L16: 87.79 | M16: 87.79 | N16: 87.79 | O16: 87.79 | P16: 87.79 | Q16: 87.79 | R16: 87.79 | S16: 87.79 | T16: 87.79 | U16: 87.79 | V16: 87.79 | W16: 87.79 | X16: 87.79 | Y16: 87.79 | Z16: 87.79 | AA16: 87.79 | AB16: =SUM(D16:AA16) -> 2106.96 | AC16: 22 | AD16: =+AB16*AC16+AB17*AC17+AB18*AC18 -> 63208.8
C17: SABADO | D17: 87.79 | E17: 87.79 | F17: 87.79 | G17: 87.79 | H17: 87.79 | I17: 87.79 | J17: 87.79 | K17: 87.79 | L17: 87.79 | M17: 87.79 | N17: 87.79 | O17: 87.79 | P17: 87.79 | Q17: 87.79 | R17: 87.79 | S17: 87.79 | T17: 87.79 | U17: 87.79 | V17: 87.79 | W17: 87.79 | X17: 87.79 | Y17: 87.79 | Z17: 87.79 | AA17: 87.79 | AB17: =SUM(D17:AA17) -> 2106.96 | AC17: 4
C18: FESTIVO | D18: 87.79 | E18: 87.79 | F18: 87.79 | G18: 87.79 | H18: 87.79 | I18: 87.79 | J18: 87.79 | K18: 87.79 | L18: 87.79 | M18: 87.79 | N18: 87.79 | O18: 87.79 | P18: 87.79 | Q18: 87.79 | R18: 87.79 | S18: 87.79 | T18: 87.79 | U18: 87.79 | V18: 87.79 | W18: 87.79 | X18: 87.79 | Y18: 87.79 | Z18: 87.79 | AA18: 87.79 | AB18: =SUM(D18:AA18) -> 2106.96 | AC18: 4
B19: 46508 | C19: ORDINARIO | D19: 87.79 | E19: 87.79 | F19: 87.79 | G19: 87.79 | H19: 87.79 | I19: 87.79 | J19: 87.79 | K19: 87.79 | L19: 87.79 | M19: 87.79 | N19: 87.79 | O19: 87.79 | P19: 87.79 | Q19: 87.79 | R19: 87.79 | S19: 87.79 | T19: 87.79 | U19: 87.79 | V19: 87.79 | W19: 87.79 | X19: 87.79 | Y19: 87.79 | Z19: 87.79 | AA19: 87.79 | AB19: =SUM(D19:AA19) -> 2106.96 | AC19: 19 | AD19: =+AB19*AC19+AB20*AC20+AB21*AC21 -> 65315.76
C20: SABADO | D20: 87.79 | E20: 87.79 | F20: 87.79 | G20: 87.79 | H20: 87.79 | I20: 87.79 | J20: 87.79 | K20: 87.79 | L20: 87.79 | M20: 87.79 | N20: 87.79 | O20: 87.79 | P20: 87.79 | Q20: 87.79 | R20: 87.79 | S20: 87.79 | T20: 87.79 | U20: 87.79 | V20: 87.79 | W20: 87.79 | X20: 87.79 | Y20: 87.79 | Z20: 87.79 | AA20: 87.79 | AB20: =SUM(D20:AA20) -> 2106.96 | AC20: 4
C21: FESTIVO | D21: 87.79 | E21: 87.79 | F21: 87.79 | G21: 87.79 | H21: 87.79 | I21: 87.79 | J21: 87.79 | K21: 87.79 | L21: 87.79 | M21: 87.79 | N21: 87.79 | O21: 87.79 | P21: 87.79 | Q21: 87.79 | R21: 87.79 | S21: 87.79 | T21: 87.79 | U21: 87.79 | V21: 87.79 | W21: 87.79 | X21: 87.79 | Y21: 87.79 | Z21: 87.79 | AA21: 87.79 | AB21: =SUM(D21:AA21) -> 2106.96 | AC21: 8
B22: 46539 | C22: ORDINARIO | D22: 87.79 | E22: 87.79 | F22: 87.79 | G22: 87.79 | H22: 87.79 | I22: 87.79 | J22: 87.79 | K22: 87.79 | L22: 87.79 | M22: 87.79 | N22: 87.79 | O22: 87.79 | P22: 87.79 | Q22: 87.79 | R22: 87.79 | S22: 87.79 | T22: 87.79 | U22: 87.79 | V22: 87.79 | W22: 87.79 | X22: 87.79 | Y22: 87.79 | Z22: 87.79 | AA22: 87.79 | AB22: =SUM(D22:AA22) -> 2106.96 | AC22: 21 | AD22: =+AB22*AC22+AB23*AC23+AB24*AC24 -> 63208.8
C23: SABADO | D23: 87.79 | E23: 87.79 | F23: 87.79 | G23: 87.79 | H23: 87.79 | I23: 87.79 | J23: 87.79 | K23: 87.79 | L23: 87.79 | M23: 87.79 | N23: 87.79 | O23: 87.79 | P23: 87.79 | Q23: 87.79 | R23: 87.79 | S23: 87.79 | T23: 87.79 | U23: 87.79 | V23: 87.79 | W23: 87.79 | X23: 87.79 | Y23: 87.79 | Z23: 87.79 | AA23: 87.79 | AB23: =SUM(D23:AA23) -> 2106.96 | AC23: 4
C24: FESTIVO | D24: 87.79 | E24: 87.79 | F24: 87.79 | G24: 87.79 | H24: 87.79 | I24: 87.79 | J24: 87.79 | K24: 87.79 | L24: 87.79 | M24: 87.79 | N24: 87.79 | O24: 87.79 | P24: 87.79 | Q24: 87.79 | R24: 87.79 | S24: 87.79 | T24: 87.79 | U24: 87.79 | V24: 87.79 | W24: 87.79 | X24: 87.79 | Y24: 87.79 | Z24: 87.79 | AA24: 87.79 | AB24: =SUM(D24:AA24) -> 2106.96 | AC24: 5
B25: 46569 | C25: ORDINARIO | D25: 87.79 | E25: 87.79 | F25: 87.79 | G25: 87.79 | H25: 87.79 | I25: 87.79 | J25: 87.79 | K25: 87.79 | L25: 87.79 | M25: 87.79 | N25: 87.79 | O25: 87.79 | P25: 87.79 | Q25: 87.79 | R25: 87.79 | S25: 87.79 | T25: 87.79 | U25: 87.79 | V25: 87.79 | W25: 87.79 | X25: 87.79 | Y25: 87.79 | Z25: 87.79 | AA25: 87.79 | AB25: =SUM(D25:AA25) -> 2106.96 | AC25: 20 | AD25: =+AB25*AC25+AB26*AC26+AB27*AC27 -> 65315.76
C26: SABADO | D26: 87.79 | E26: 87.79 | F26: 87.79 | G26: 87.79 | H26: 87.79 | I26: 87.79 | J26: 87.79 | K26: 87.79 | L26: 87.79 | M26: 87.79 | N26: 87.79 | O26: 87.79 | P26: 87.79 | Q26: 87.79 | R26: 87.79 | S26: 87.79 | T26: 87.79 | U26: 87.79 | V26: 87.79 | W26: 87.79 | X26: 87.79 | Y26: 87.79 | Z26: 87.79 | AA26: 87.79 | AB26: =SUM(D26:AA26) -> 2106.96 | AC26: 5
C27: FESTIVO | D27: 87.79 | E27: 87.79 | F27: 87.79 | G27: 87.79 | H27: 87.79 | I27: 87.79 | J27: 87.79 | K27: 87.79 | L27: 87.79 | M27: 87.79 | N27: 87.79 | O27: 87.79 | P27: 87.79 | Q27: 87.79 | R27: 87.79 | S27: 87.79 | T27: 87.79 | U27: 87.79 | V27: 87.79 | W27: 87.79 | X27: 87.79 | Y27: 87.79 | Z27: 87.79 | AA27: 87.79 | AB27: =SUM(D27:AA27) -> 2106.96 | AC27: 6
B28: 46600 | C28: ORDINARIO | D28: 87.79 | E28: 87.79 | F28: 87.79 | G28: 87.79 | H28: 87.79 | I28: 87.79 | J28: 87.79 | K28: 87.79 | L28: 87.79 | M28: 87.79 | N28: 87.79 | O28: 87.79 | P28: 87.79 | Q28: 87.79 | R28: 87.79 | S28: 87.79 | T28: 87.79 | U28: 87.79 | V28: 87.79 | W28: 87.79 | X28: 87.79 | Y28: 87.79 | Z28: 87.79 | AA28: 87.79 | AB28: =SUM(D28:AA28) -> 2106.96 | AC28: 21 | AD28: =+AB28*AC28+AB29*AC29+AB30*AC30 -> 65315.76
C29: SABADO | D29: 87.79 | E29: 87.79 | F29: 87.79 | G29: 87.79 | H29: 87.79 | I29: 87.79 | J29: 87.79 | K29: 87.79 | L29: 87.79 | M29: 87.79 | N29: 87.79 | O29: 87.79 | P29: 87.79 | Q29: 87.79 | R29: 87.79 | S29: 87.79 | T29: 87.79 | U29: 87.79 | V29: 87.79 | W29: 87.79 | X29: 87.79 | Y29: 87.79 | Z29: 87.79 | AA29: 87.79 | AB29: =SUM(D29:AA29) -> 2106.96 | AC29: 3
C30: FESTIVO | D30: 87.79 | E30: 87.79 | F30: 87.79 | G30: 87.79 | H30: 87.79 | I30: 87.79 | J30: 87.79 | K30: 87.79 | L30: 87.79 | M30: 87.79 | N30: 87.79 | O30: 87.79 | P30: 87.79 | Q30: 87.79 | R30: 87.79 | S30: 87.79 | T30: 87.79 | U30: 87.79 | V30: 87.79 | W30: 87.79 | X30: 87.79 | Y30: 87.79 | Z30: 87.79 | AA30: 87.79 | AB30: =SUM(D30:AA30) -> 2106.96 | AC30: 7
B31: 46631 | C31: ORDINARIO | D31: 87.79 | E31: 87.79 | F31: 87.79 | G31: 87.79 | H31: 87.79 | I31: 87.79 | J31: 87.79 | K31: 87.79 | L31: 87.79 | M31: 87.79 | N31: 87.79 | O31: 87.79 | P31: 87.79 | Q31: 87.79 | R31: 87.79 | S31: 87.79 | T31: 87.79 | U31: 87.79 | V31: 87.79 | W31: 87.79 | X31: 87.79 | Y31: 87.79 | Z31: 87.79 | AA31: 87.79 | AB31: =SUM(D31:AA31) -> 2106.96 | AC31: 22 | AD31: =+AB31*AC31+AB32*AC32+AB33*AC33 -> 63208.8
C32: SABADO | D32: 87.79 | E32: 87.79 | F32: 87.79 | G32: 87.79 | H32: 87.79 | I32: 87.79 | J32: 87.79 | K32: 87.79 | L32: 87.79 | M32: 87.79 | N32: 87.79 | O32: 87.79 | P32: 87.79 | Q32: 87.79 | R32: 87.79 | S32: 87.79 | T32: 87.79 | U32: 87.79 | V32: 87.79 | W32: 87.79 | X32: 87.79 | Y32: 87.79 | Z32: 87.79 | AA32: 87.79 | AB32: =SUM(D32:AA32) -> 2106.96 | AC32: 4
C33: FESTIVO | D33: 87.79 | E33: 87.79 | F33: 87.79 | G33: 87.79 | H33: 87.79 | I33: 87.79 | J33: 87.79 | K33: 87.79 | L33: 87.79 | M33: 87.79 | N33: 87.79 | O33: 87.79 | P33: 87.79 | Q33: 87.79 | R33: 87.79 | S33: 87.79 | T33: 87.79 | U33: 87.79 | V33: 87.79 | W33: 87.79 | X33: 87.79 | Y33: 87.79 | Z33: 87.79 | AA33: 87.79 | AB33: =SUM(D33:AA33) -> 2106.96 | AC33: 4
B34: 46661 | C34: ORDINARIO | D34: 87.79 | E34: 87.79 | F34: 87.79 | G34: 87.79 | H34: 87.79 | I34: 87.79 | J34: 87.79 | K34: 87.79 | L34: 87.79 | M34: 87.79 | N34: 87.79 | O34: 87.79 | P34: 87.79 | Q34: 87.79 | R34: 87.79 | S34: 87.79 | T34: 87.79 | U34: 87.79 | V34: 87.79 | W34: 87.79 | X34: 87.79 | Y34: 87.79 | Z34: 87.79 | AA34: 87.79 | AB34: =SUM(D34:AA34) -> 2106.96 | AC34: 20 | AD34: =+AB34*AC34+AB35*AC35+AB36*AC36 -> 65315.76
C35: SABADO | D35: 87.79 | E35: 87.79 | F35: 87.79 | G35: 87.79 | H35: 87.79 | I35: 87.79 | J35: 87.79 | K35: 87.79 | L35: 87.79 | M35: 87.79 | N35: 87.79 | O35: 87.79 | P35: 87.79 | Q35: 87.79 | R35: 87.79 | S35: 87.79 | T35: 87.79 | U35: 87.79 | V35: 87.79 | W35: 87.79 | X35: 87.79 | Y35: 87.79 | Z35: 87.79 | AA35: 87.79 | AB35: =SUM(D35:AA35) -> 2106.96 | AC35: 5
C36: FESTIVO | D36: 87.79 | E36: 87.79 | F36: 87.79 | G36: 87.79 | H36: 87.79 | I36: 87.79 | J36: 87.79 | K36: 87.79 | L36: 87.79 | M36: 87.79 | N36: 87.79 | O36: 87.79 | P36: 87.79 | Q36: 87.79 | R36: 87.79 | S36: 87.79 | T36: 87.79 | U36: 87.79 | V36: 87.79 | W36: 87.79 | X36: 87.79 | Y36: 87.79 | Z36: 87.79 | AA36: 87.79 | AB36: =SUM(D36:AA36) -> 2106.96 | AC36: 6
B37: 46692 | C37: ORDINARIO | D37: 87.79 | E37: 87.79 | F37: 87.79 | G37: 87.79 | H37: 87.79 | I37: 87.79 | J37: 87.79 | K37: 87.79 | L37: 87.79 | M37: 87.79 | N37: 87.79 | O37: 87.79 | P37: 87.79 | Q37: 87.79 | R37: 87.79 | S37: 87.79 | T37: 87.79 | U37: 87.79 | V37: 87.79 | W37: 87.79 | X37: 87.79 | Y37: 87.79 | Z37: 87.79 | AA37: 87.79 | AB37: =SUM(D37:AA37) -> 2106.96 | AC37: 20 | AD37: =+AB37*AC37+AB38*AC38+AB39*AC39 -> 63208.8
C38: SABADO | D38: 87.79 | E38: 87.79 | F38: 87.79 | G38: 87.79 | H38: 87.79 | I38: 87.79 | J38: 87.79 | K38: 87.79 | L38: 87.79 | M38: 87.79 | N38: 87.79 | O38: 87.79 | P38: 87.79 | Q38: 87.79 | R38: 87.79 | S38: 87.79 | T38: 87.79 | U38: 87.79 | V38: 87.79 | W38: 87.79 | X38: 87.79 | Y38: 87.79 | Z38: 87.79 | AA38: 87.79 | AB38: =SUM(D38:AA38) -> 2106.96 | AC38: 4
C39: FESTIVO | D39: 87.79 | E39: 87.79 | F39: 87.79 | G39: 87.79 | H39: 87.79 | I39: 87.79 | J39: 87.79 | K39: 87.79 | L39: 87.79 | M39: 87.79 | N39: 87.79 | O39: 87.79 | P39: 87.79 | Q39: 87.79 | R39: 87.79 | S39: 87.79 | T39: 87.79 | U39: 87.79 | V39: 87.79 | W39: 87.79 | X39: 87.79 | Y39: 87.79 | Z39: 87.79 | AA39: 87.79 | AB39: =SUM(D39:AA39) -> 2106.96 | AC39: 6
B40: 46722 | C40: ORDINARIO | D40: 87.79 | E40: 87.79 | F40: 87.79 | G40: 87.79 | H40: 87.79 | I40: 87.79 | J40: 87.79 | K40: 87.79 | L40: 87.79 | M40: 87.79 | N40: 87.79 | O40: 87.79 | P40: 87.79 | Q40: 87.79 | R40: 87.79 | S40: 87.79 | T40: 87.79 | U40: 87.79 | V40: 87.79 | W40: 87.79 | X40: 87.79 | Y40: 87.79 | Z40: 87.79 | AA40: 87.79 | AB40: =SUM(D40:AA40) -> 2106.96 | AC40: 22 | AD40: =+AB40*AC40+AB41*AC41+AB42*AC42 -> 65315.76
C41: SABADO | D41: 87.79 | E41: 87.79 | F41: 87.79 | G41: 87.79 | H41: 87.79 | I41: 87.79 | J41: 87.79 | K41: 87.79 | L41: 87.79 | M41: 87.79 | N41: 87.79 | O41: 87.79 | P41: 87.79 | Q41: 87.79 | R41: 87.79 | S41: 87.79 | T41: 87.79 | U41: 87.79 | V41: 87.79 | W41: 87.79 | X41: 87.79 | Y41: 87.79 | Z41: 87.79 | AA41: 87.79 | AB41: =SUM(D41:AA41) -> 2106.96 | AC41: 3
C42: FESTIVO | D42: 87.79 | E42: 87.79 | F42: 87.79 | G42: 87.79 | H42: 87.79 | I42: 87.79 | J42: 87.79 | K42: 87.79 | L42: 87.79 | M42: 87.79 | N42: 87.79 | O42: 87.79 | P42: 87.79 | Q42: 87.79 | R42: 87.79 | S42: 87.79 | T42: 87.79 | U42: 87.79 | V42: 87.79 | W42: 87.79 | X42: 87.79 | Y42: 87.79 | Z42: 87.79 | AA42: 87.79 | AB42: =SUM(D42:AA42) -> 2106.96 | AC42: 6
...

Sheet P2_Anexo_2_2027
C3: EMPRESAS MUNICIPALES DE CALI- EMCALI EICE ESP
C4: CONVOCATORIA PÚBLICA PARA COMPRA DE ENERGÍA
C5: Código de Convocatoria SICEP No. CP-EMIC2025-003
C7: ANEXO No. 2 CANTIDADES Y PRECIOS OFERTADOS
C9: PRODUCTO 2 - 1 DE ENERO A 31 DE DICIEMBRE 2027 - PLANO
C12: AÑO | D12: Energía solicitada (MWh) | E12: Energía Ofertada (MWh) | F12: $/kWh
C13: 2027 | D13: ='P2_Anexo_ 1_2027'!AD43 -> 769040.4
C14: Total año | D14: =SUM(D13:D13) -> 769040.4
C17: NOTAS:
C18: 1- Se debe ofertar todo el año, la misma cantidad horaria por período
C19: 2- Se debe ofertar mínimo quince (15) MWh para cada período horario ofertado
C20: 3- La energía y los precios a ofertar deben ofrecerse en la modalidad monomia.
C21: 4- Precios en pesos constantes del mes de agosto de 2025.

Sheet P3_Anexo_1_2028
B2: ANEXO No. 1 - CANTIDADES DE ENERGÍA HORARIA Y MENSUAL A CONTRATAR
B3: PRODUCTO 3 - 1 DE ENERO A 31 DE DICIEMBRE 2028
B5: ENERGÍA PLANA A SOLICITAR AÑO 2028 PARA MERCADO REGULADO (MWh)
B6: MES | C6: DÍA | D6: H1 | E6: H2 | F6: H3 | G6: H4 | H6: H5 | I6: H6 | J6: H7 | K6: H8 | L6: H9 | M6: H10 | N6: H11 | O6: H12 | P6: H13 | Q6: H14 | R6: H15 | S6: H16 | T6: H17 | U6: H18 | V6: H19 | W6: H20 | X6: H21 | Y6: H22 | Z6: H23 | AA6: H24 | AB6: TOTAL | AC6: No. Dias | AD6: TOTAL MES
B7: 46753 | C7: ORDINARIO | D7: 79.21 | E7: 79.21 | F7: 79.21 | G7: 79.21 | H7: 79.21 | I7: 79.21 | J7: 79.21 | K7: 79.21 | L7: 79.21 | M7: 79.21 | N7: 79.21 | O7: 79.21 | P7: 79.21 | Q7: 79.21 | R7: 79.21 | S7: 79.21 | T7: 79.21 | U7: 79.21 | V7: 79.21 | W7: 79.21 | X7: 79.21 | Y7: 79.21 | Z7: 79.21 | AA7: 79.21 | AB7: =SUM(D7:AA7) -> 1901.04 | AC7: 20 | AD7: =+AB7*AC7+AB8*AC8+AB9*AC9 -> 58932.24
C8: SABADO | D8: 79.21 | E8: 79.21 | F8: 79.21 | G8: 79.21 | H8: 79.21 | I8: 79.21 | J8: 79.21 | K8: 79.21 | L8: 79.21 | M8: 79.21 | N8: 79.21 | O8: 79.21 | P8: 79.21 | Q8: 79.21 | R8: 79.21 | S8: 79.21 | T8: 79.21 | U8: 79.21 | V8: 79.21 | W8: 79.21 | X8: 79.21 | Y8: 79.21 | Z8: 79.21 | AA8: 79.21 | AB8: =SUM(D8:AA8) -> 1901.04 | AC8: 4
C9: FESTIVO | D9: 79.21 | E9: 79.21 | F9: 79.21 | G9: 79.21 | H9: 79.21 | I9: 79.21 | J9: 79.21 | K9: 79.21 | L9: 79.21 | M9: 79.21 | N9: 79.21 | O9: 79.21 | P9: 79.21 | Q9: 79.21 | R9: 79.21 | S9: 79.21 | T9: 79.21 | U9: 79.21 | V9: 79.21 | W9: 79.21 | X9: 79.21 | Y9: 79.21 | Z9: 79.21 | AA9: 79.21 | AB9: =SUM(D9:AA9) -> 1901.04 | AC9: 7
B10: 46784 | C10: ORDINARIO | D10: 79.21 | E10: 79.21 | F10: 79.21 | G10: 79.21 | H10: 79.21 | I10: 79.21 | J10: 79.21 | K10: 79.21 | L10: 79.21 | M10: 79.21 | N10: 79.21 | O10: 79.21 | P10: 79.21 | Q10: 79.21 | R10: 79.21 | S10: 79.21 | T10: 79.21 | U10: 79.21 | V10: 79.21 | W10: 79.21 | X10: 79.21 | Y10: 79.21 | Z10: 79.21 | AA10: 79.21 | AB10: =SUM(D10:AA10) -> 1901.04 | AC10: 21 | AD10: =+AB10*AC10+AB11*AC11+AB12*AC12 -> 55130.16
C11: SABADO | D11: 79.21 | E11: 79.21 | F11: 79.21 | G11: 79.21 | H11: 79.21 | I11: 79.21 | J11: 79.21 | K11: 79.21 | L11: 79.21 | M11: 79.21 | N11: 79.21 | O11: 79.21 | P11: 79.21 | Q11: 79.21 | R11: 79.21 | S11: 79.21 | T11: 79.21 | U11: 79.21 | V11: 79.21 | W11: 79.21 | X11: 79.21 | Y11: 79.21 | Z11: 79.21 | AA11: 79.21 | AB11: =SUM(D11:AA11) -> 1901.04 | AC11: 4
C12: FESTIVO | D12: 79.21 | E12: 79.21 | F12: 79.21 | G12: 79.21 | H12: 79.21 | I12: 79.21 | J12: 79.21 | K12: 79.21 | L12: 79.21 | M12: 79.21 | N12: 79.21 | O12: 79.21 | P12: 79.21 | Q12: 79.21 | R12: 79.21 | S12: 79.21 | T12: 79.21 | U12: 79.21 | V12: 79.21 | W12: 79.21 | X12: 79.21 | Y12: 79.21 | Z12: 79.21 | AA12: 79.21 | AB12: =SUM(D12:AA12) -> 1901.04 | AC12: 4
B13: 46813 | C13: ORDINARIO | D13: 79.21 | E13: 79.21 | F13: 79.21 | G13: 79.21 | H13: 79.21 | I13: 79.21 | J13: 79.21 | K13: 79.21 | L13: 79.21 | M13: 79.21 | N13: 79.21 | O13: 79.21 | P13: 79.21 | Q13: 79.21 | R13: 79.21 | S13: 79.21 | T13: 79.21 | U13: 79.21 | V13: 79.21 | W13: 79.21 | X13: 79.21 | Y13: 79.21 | Z13: 79.21 | AA13: 79.21 | AB13: =SUM(D13:AA13) -> 1901.04 | AC13: 22 | AD13: =+AB13*AC13+AB14*AC14+AB15*AC15 -> 58932.24
C14: SABADO | D14: 79.21 | E14: 79.21 | F14: 79.21 | G14: 79.21 | H14: 79.21 | I14: 79.21 | J14: 79.21 | K14: 79.21 | L14: 79.21 | M14: 79.21 | N14: 79.21 | O14: 79.21 | P14: 79.21 | Q14: 79.21 | R14: 79.21 | S14: 79.21 | T14: 79.21 | U14: 79.21 | V14: 79.21 | W14: 79.21 | X14: 79.21 | Y14: 79.21 | Z14: 79.21 | AA14: 79.21 | AB14: =SUM(D14:AA14) -> 1901.04 | AC14: 4
C15: FESTIVO | D15: 79.21 | E15: 79.21 | F15: 79.21 | G15: 79.21 | H15: 79.21 | I15: 79.21 | J15: 79.21 | K15: 79.21 | L15: 79.21 | M15: 79.21 | N15: 79.21 | O15: 79.21 | P15: 79.21 | Q15: 79.21 | R15: 79.21 | S15: 79.21 | T15: 79.21 | U15: 79.21 | V15: 79.21 | W15: 79.21 | X15: 79.21 | Y15: 79.21 | Z15: 79.21 | AA15: 79.21 | AB15: =SUM(D15:AA15) -> 1901.04 | AC15: 5
B16: 46844 | C16: ORDINARIO | D16: 79.21 | E16: 79.21 | F16: 79.21 | G16: 79.21 | H16: 79.21 | I16: 79.21 | J16: 79.21 | K16: 79.21 | L16: 79.21 | M16: 79.21 | N16: 79.21 | O16: 79.21 | P16: 79.21 | Q16: 79.21 | R16: 79.21 | S16: 79.21 | T16: 79.21 | U16: 79.21 | V16: 79.21 | W16: 79.21 | X16: 79.21 | Y16: 79.21 | Z16: 79.21 | AA16: 79.21 | AB16: =SUM(D16:AA16) -> 1901.04 | AC16: 18 | AD16: =+AB16*AC16+AB17*AC17+AB18*AC18 -> 57031.2
C17: SABADO | D17: 79.21 | E17: 79.21 | F17: 79.21 | G17: 79.21 | H17: 79.21 | I17: 79.21 | J17: 79.21 | K17: 79.21 | L17: 79.21 | M17: 79.21 | N17: 79.21 | O17: 79.21 | P17: 79.21 | Q17: 79.21 | R17: 79.21 | S17: 79.21 | T17: 79.21 | U17: 79.21 | V17: 79.21 | W17: 79.21 | X17: 79.21 | Y17: 79.21 | Z17: 79.21 | AA17: 79.21 | AB17: =SUM(D17:AA17) -> 1901.04 | AC17: 5
C18: FESTIVO | D18: 79.21 | E18: 79.21 | F18: 79.21 | G18: 79.21 | H18: 79.21 | I18: 79.21 | J18: 79.21 | K18: 79.21 | L18: 79.21 | M18: 79.21 | N18: 79.21 | O18: 79.21 | P18: 79.21 | Q18: 79.21 | R18: 79.21 | S18: 79.21 | T18: 79.21 | U18: 79.21 | V18: 79.21 | W18: 79.21 | X18: 79.21 | Y18: 79.21 | Z18: 79.21 | AA18: 79.21 | AB18: =SUM(D18:AA18) -> 1901.04 | AC18: 7
B19: 46874 | C19: ORDINARIO | D19: 79.21 | E19: 79.21 | F19: 79.21 | G19: 79.21 | H19: 79.21 | I19: 79.21 | J19: 79.21 | K19: 79.21 | L19: 79.21 | M19: 79.21 | N19: 79.21 | O19: 79.21 | P19: 79.21 | Q19: 79.21 | R19: 79.21 | S19: 79.21 | T19: 79.21 | U19: 79.21 | V19: 79.21 | W19: 79.21 | X19: 79.21 | Y19: 79.21 | Z19: 79.21 | AA19: 79.21 | AB19: =SUM(D19:AA19) -> 1901.04 | AC19: 21 | AD19: =+AB19*AC19+AB20*AC20+AB21*AC21 -> 58932.24
C20: SABADO | D20: 79.21 | E20: 79.21 | F20: 79.21 | G20: 79.21 | H20: 79.21 | I20: 79.21 | J20: 79.21 | K20: 79.21 | L20: 79.21 | M20: 79.21 | N20: 79.21 | O20: 79.21 | P20: 79.21 | Q20: 79.21 | R20: 79.21 | S20: 79.21 | T20: 79.21 | U20: 79.21 | V20: 79.21 | W20: 79.21 | X20: 79.21 | Y20: 79.21 | Z20: 79.21 | AA20: 79.21 | AB20: =SUM(D20:AA20) -> 1901.04 | AC20: 4
C21: FESTIVO | D21: 79.21 | E21: 79.21 | F21: 79.21 | G21: 79.21 | H21: 79.21 | I21: 79.21 | J21: 79.21 | K21: 79.21 | L21: 79.21 | M21: 79.21 | N21: 79.21 | O21: 79.21 | P21: 79.21 | Q21: 79.21 | R21: 79.21 | S21: 79.21 | T21: 79.21 | U21: 79.21 | V21: 79.21 | W21: 79.21 | X21: 79.21 | Y21: 79.21 | Z21: 79.21 | AA21: 79.21 | AB21: =SUM(D21:AA21) -> 1901.04 | AC21: 6
B22: 46905 | C22: ORDINARIO | D22: 79.21 | E22: 79.21 | F22: 79.21 | G22: 79.21 | H22: 79.21 | I22: 79.21 | J22: 79.21 | K22: 79.21 | L22: 79.21 | M22: 79.21 | N22: 79.21 | O22: 79.21 | P22: 79.21 | Q22: 79.21 | R22: 79.21 | S22: 79.21 | T22: 79.21 | U22: 79.21 | V22: 79.21 | W22: 79.21 | X22: 79.21 | Y22: 79.21 | Z22: 79.21 | AA22: 79.21 | AB22: =SUM(D22:AA22) -> 1901.04 | AC22: 20 | AD22: =+AB22*AC22+AB23*AC23+AB24*AC24 -> 57031.2
C23: SABADO | D23: 79.21 | E23: 79.21 | F23: 79.21 | G23: 79.21 | H23: 79.21 | I23: 79.21 | J23: 79.21 | K23: 79.21 | L23: 79.21 | M23: 79.21 | N23: 79.21 | O23: 79.21 | P23: 79.21 | Q23: 79.21 | R23: 79.21 | S23: 79.21 | T23: 79.21 | U23: 79.21 | V23: 79.21 | W23: 79.21 | X23: 79.21 | Y23: 79.21 | Z23: 79.21 | AA23: 79.21 | AB23: =SUM(D23:AA23) -> 1901.04 | AC23: 4
C24: FESTIVO | D24: 79.21 | E24: 79.21 | F24: 79.21 | G24: 79.21 | H24: 79.21 | I24: 79.21 | J24: 79.21 | K24: 79.21 | L24: 79.21 | M24: 79.21 | N24: 79.21 | O24: 79.21 | P24: 79.21 | Q24: 79.21 | R24: 79.21 | S24: 79.21 | T24: 79.21 | U24: 79.21 | V24: 79.21 | W24: 79.21 | X24: 79.21 | Y24: 79.21 | Z24: 79.21 | AA24: 79.21 | AB24: =SUM(D24:AA24) -> 1901.04 | AC24: 6
B25: 46935 | C25: ORDINARIO | D25: 79.21 | E25: 79.21 | F25: 79.21 | G25: 79.21 | H25: 79.21 | I25: 79.21 | J25: 79.21 | K25: 79.21 | L25: 79.21 | M25: 79.21 | N25: 79.21 | O25: 79.21 | P25: 79.21 | Q25: 79.21 | R25: 79.21 | S25: 79.21 | T25: 79.21 | U25: 79.21 | V25: 79.21 | W25: 79.21 | X25: 79.21 | Y25: 79.21 | Z25: 79.21 | AA25: 79.21 | AB25: =SUM(D25:AA25) -> 1901.04 | AC25: 19 | AD25: =+AB25*AC25+AB26*AC26+AB27*AC27 -> 58932.24
C26: SABADO | D26: 79.21 | E26: 79.21 | F26: 79.21 | G26: 79.21 | H26: 79.21 | I26: 79.21 | J26: 79.21 | K26: 79.21 | L26: 79.21 | M26: 79.21 | N26: 79.21 | O26: 79.21 | P26: 79.21 | Q26: 79.21 | R26: 79.21 | S26: 79.21 | T26: 79.21 | U26: 79.21 | V26: 79.21 | W26: 79.21 | X26: 79.21 | Y26: 79.21 | Z26: 79.21 | AA26: 79.21 | AB26: =SUM(D26:AA26) -> 1901.04 | AC26: 5
C27: FESTIVO | D27: 79.21 | E27: 79.21 | F27: 79.21 | G27: 79.21 | H27: 79.21 | I27: 79.21 | J27: 79.21 | K27: 79.21 | L27: 79.21 | M27: 79.21 | N27: 79.21 | O27: 79.21 | P27: 79.21 | Q27: 79.21 | R27: 79.21 | S27: 79.21 | T27: 79.21 | U27: 79.21 | V27: 79.21 | W27: 79.21 | X27: 79.21 | Y27: 79.21 | Z27: 79.21 | AA27: 79.21 | AB27: =SUM(D27:AA27) -> 1901.04 | AC27: 7
B28: 46966 | C28: ORDINARIO | D28: 79.21 | E28: 79.21 | F28: 79.21 | G28: 79.21 | H28: 79.21 | I28: 79.21 | J28: 79.21 | K28: 79.21 | L28: 79.21 | M28: 79.21 | N28: 79.21 | O28: 79.21 | P28: 79.21 | Q28: 79.21 | R28: 79.21 | S28: 79.21 | T28: 79.21 | U28: 79.21 | V28: 79.21 | W28: 79.21 | X28: 79.21 | Y28: 79.21 | Z28: 79.21 | AA28: 79.21 | AB28: =SUM(D28:AA28) -> 1901.04 | AC28: 21 | AD28: =+AB28*AC28+AB29*AC29+AB30*AC30 -> 58932.24
C29: SABADO | D29: 79.21 | E29: 79.21 | F29: 79.21 | G29: 79.21 | H29: 79.21 | I29: 79.21 | J29: 79.21 | K29: 79.21 | L29: 79.21 | M29: 79.21 | N29: 79.21 | O29: 79.21 | P29: 79.21 | Q29: 79.21 | R29: 79.21 | S29: 79.21 | T29: 79.21 | U29: 79.21 | V29: 79.21 | W29: 79.21 | X29: 79.21 | Y29: 79.21 | Z29: 79.21 | AA29: 79.21 | AB29: =SUM(D29:AA29) -> 1901.04 | AC29: 4
C30: FESTIVO | D30: 79.21 | E30: 79.21 | F30: 79.21 | G30: 79.21 | H30: 79.21 | I30: 79.21 | J30: 79.21 | K30: 79.21 | L30: 79.21 | M30: 79.21 | N30: 79.21 | O30: 79.21 | P30: 79.21 | Q30: 79.21 | R30: 79.21 | S30: 79.21 | T30: 79.21 | U30: 79.21 | V30: 79.21 | W30: 79.21 | X30: 79.21 | Y30: 79.21 | Z30: 79.21 | AA30: 79.21 | AB30: =SUM(D30:AA30) -> 1901.04 | AC30: 6
B31: 46997 | C31: ORDINARIO | D31: 79.21 | E31: 79.21 | F31: 79.21 | G31: 79.21 | H31: 79.21 | I31: 79.21 | J31: 79.21 | K31: 79.21 | L31: 79.21 | M31: 79.21 | N31: 79.21 | O31: 79.21 | P31: 79.21 | Q31: 79.21 | R31: 79.21 | S31: 79.21 | T31: 79.21 | U31: 79.21 | V31: 79.21 | W31: 79.21 | X31: 79.21 | Y31: 79.21 | Z31: 79.21 | AA31: 79.21 | AB31: =SUM(D31:AA31) -> 1901.04 | AC31: 21 | AD31: =+AB31*AC31+AB32*AC32+AB33*AC33 -> 57031.2
C32: SABADO | D32: 79.21 | E32: 79.21 | F32: 79.21 | G32: 79.21 | H32: 79.21 | I32: 79.21 | J32: 79.21 | K32: 79.21 | L32: 79.21 | M32: 79.21 | N32: 79.21 | O32: 79.21 | P32: 79.21 | Q32: 79.21 | R32: 79.21 | S32: 79.21 | T32: 79.21 | U32: 79.21 | V32: 79.21 | W32: 79.21 | X32: 79.21 | Y32: 79.21 | Z32: 79.21 | AA32: 79.21 | AB32: =SUM(D32:AA32) -> 1901.04 | AC32: 5
C33: FESTIVO | D33: 79.21 | E33: 79.21 | F33: 79.21 | G33: 79.21 | H33: 79.21 | I33: 79.21 | J33: 79.21 | K33: 79.21 | L33: 79.21 | M33: 79.21 | N33: 79.21 | O33: 79.21 | P33: 79.21 | Q33: 79.21 | R33: 79.21 | S33: 79.21 | T33: 79.21 | U33: 79.21 | V33: 79.21 | W33: 79.21 | X33: 79.21 | Y33: 79.21 | Z33: 79.21 | AA33: 79.21 | AB33: =SUM(D33:AA33) -> 1901.04 | AC33: 4
B34: 47027 | C34: ORDINARIO | D34: 79.21 | E34: 79.21 | F34: 79.21 | G34: 79.21 | H34: 79.21 | I34: 79.21 | J34: 79.21 | K34: 79.21 | L34: 79.21 | M34: 79.21 | N34: 79.21 | O34: 79.21 | P34: 79.21 | Q34: 79.21 | R34: 79.21 | S34: 79.21 | T34: 79.21 | U34: 79.21 | V34: 79.21 | W34: 79.21 | X34: 79.21 | Y34: 79.21 | Z34: 79.21 | AA34: 79.21 | AB34: =SUM(D34:AA34) -> 1901.04 | AC34: 21 | AD34: =+AB34*AC34+AB35*AC35+AB36*AC36 -> 58932.24
C35: SABADO | D35: 79.21 | E35: 79.21 | F35: 79.21 | G35: 79.21 | H35: 79.21 | I35: 79.21 | J35: 79.21 | K35: 79.21 | L35: 79.21 | M35: 79.21 | N35: 79.21 | O35: 79.21 | P35: 79.21 | Q35: 79.21 | R35: 79.21 | S35: 79.21 | T35: 79.21 | U35: 79.21 | V35: 79.21 | W35: 79.21 | X35: 79.21 | Y35: 79.21 | Z35: 79.21 | AA35: 79.21 | AB35: =SUM(D35:AA35) -> 1901.04 | AC35: 4
C36: FESTIVO | D36: 79.21 | E36: 79.21 | F36: 79.21 | G36: 79.21 | H36: 79.21 | I36: 79.21 | J36: 79.21 | K36: 79.21 | L36: 79.21 | M36: 79.21 | N36: 79.21 | O36: 79.21 | P36: 79.21 | Q36: 79.21 | R36: 79.21 | S36: 79.21 | T36: 79.21 | U36: 79.21 | V36: 79.21 | W36: 79.21 | X36: 79.21 | Y36: 79.21 | Z36: 79.21 | AA36: 79.21 | AB36: =SUM(D36:AA36) -> 1901.04 | AC36: 6
B37: 47058 | C37: ORDINARIO | D37: 79.21 | E37: 79.21 | F37: 79.21 | G37: 79.21 | H37: 79.21 | I37: 79.21 | J37: 79.21 | K37: 79.21 | L37: 79.21 | M37: 79.21 | N37: 79.21 | O37: 79.21 | P37: 79.21 | Q37: 79.21 | R37: 79.21 | S37: 79.21 | T37: 79.21 | U37: 79.21 | V37: 79.21 | W37: 79.21 | X37: 79.21 | Y37: 79.21 | Z37: 79.21 | AA37: 79.21 | AB37: =SUM(D37:AA37) -> 1901.04 | AC37: 20 | AD37: =+AB37*AC37+AB38*AC38+AB39*AC39 -> 57031.2
C38: SABADO | D38: 79.21 | E38: 79.21 | F38: 79.21 | G38: 79.21 | H38: 79.21 | I38: 79.21 | J38: 79.21 | K38: 79.21 | L38: 79.21 | M38: 79.21 | N38: 79.21 | O38: 79.21 | P38: 79.21 | Q38: 79.21 | R38: 79.21 | S38: 79.21 | T38: 79.21 | U38: 79.21 | V38: 79.21 | W38: 79.21 | X38: 79.21 | Y38: 79.21 | Z38: 79.21 | AA38: 79.21 | AB38: =SUM(D38:AA38) -> 1901.04 | AC38: 4
C39: FESTIVO | D39: 79.21 | E39: 79.21 | F39: 79.21 | G39: 79.21 | H39: 79.21 | I39: 79.21 | J39: 79.21 | K39: 79.21 | L39: 79.21 | M39: 79.21 | N39: 79.21 | O39: 79.21 | P39: 79.21 | Q39: 79.21 | R39: 79.21 | S39: 79.21 | T39: 79.21 | U39: 79.21 | V39: 79.21 | W39: 79.21 | X39: 79.21 | Y39: 79.21 | Z39: 79.21 | AA39: 79.21 | AB39: =SUM(D39:AA39) -> 1901.04 | AC39: 6
B40: 47088 | C40: ORDINARIO | D40: 79.21 | E40: 79.21 | F40: 79.21 | G40: 79.21 | H40: 79.21 | I40: 79.21 | J40: 79.21 | K40: 79.21 | L40: 79.21 | M40: 79.21 | N40: 79.21 | O40: 79.21 | P40: 79.21 | Q40: 79.21 | R40: 79.21 | S40: 79.21 | T40: 79.21 | U40: 79.21 | V40: 79.21 | W40: 79.21 | X40: 79.21 | Y40: 79.21 | Z40: 79.21 | AA40: 79.21 | AB40: =SUM(D40:AA40) -> 1901.04 | AC40: 19 | AD40: =+AB40*AC40+AB41*AC41+AB42*AC42 -> 58932.24
C41: SABADO | D41: 79.21 | E41: 79.21 | F41: 79.21 | G41: 79.21 | H41: 79.21 | I41: 79.21 | J41: 79.21 | K41: 79.21 | L41: 79.21 | M41: 79.21 | N41: 79.21 | O41: 79.21 | P41: 79.21 | Q41: 79.21 | R41: 79.21 | S41: 79.21 | T41: 79.21 | U41: 79.21 | V41: 79.21 | W41: 79.21 | X41: 79.21 | Y41: 79.21 | Z41: 79.21 | AA41: 79.21 | AB41: =SUM(D41:AA41) -> 1901.04 | AC41: 5
C42: FESTIVO | D42: 79.21 | E42: 79.21 | F42: 79.21 | G42: 79.21 | H42: 79.21 | I42: 79.21 | J42: 79.21 | K42: 79.21 | L42: 79.21 | M42: 79.21 | N42: 79.21 | O42: 79.21 | P42: 79.21 | Q42: 79.21 | R42: 79.21 | S42: 79.21 | T42: 79.21 | U42: 79.21 | V42: 79.21 | W42: 79.21 | X42: 79.21 | Y42: 79.21 | Z42: 79.21 | AA42: 79.21 | AB42: =SUM(D42:AA42) -> 1901.04 | AC42: 7
...

Sheet P3_Anexo_2_2028
C3: EMPRESAS MUNICIPALES DE CALI- EMCALI EICE ESP
C4: CONVOCATORIA PÚBLICA PARA COMPRA DE ENERGÍA
C5: Código de Convocatoria SICEP No. CP-EMIC2025-003
C7: ANEXO No. 2 CANTIDADES Y PRECIOS OFERTADOS
C9: PRODUCTO 3 - 1 DE ENERO A 31 DE DICIEMBRE 2028 - PLANO
C12: AÑO | D12: Energía solicitada (MWh) | E12: Energía Ofertada (MWh) | F12: $/kWh
C13: 2028 | D13: =P3_Anexo_1_2028!AD43 -> 695780.64
C14: Total año | D14: =SUM(D13:D13) -> 695780.64
C17: NOTAS:
C18: 1- Se debe ofertar todo el año, la misma cantidad horaria por período
C19: 2- Se debe ofertar mínimo quince (15) MWh para cada período horario ofertado
C20: 3- La energía y los precios a ofertar deben ofrecerse en la modalidad monomia.
C21: 4- Precios en pesos constantes del mes de agosto de 2025.

Sheet P4_Anexo_1_2028
B2: ANEXO No. 1 - CANTIDADES DE ENERGÍA HORARIA Y MENSUAL A CONTRATAR | AG2: 1 DE ENERO A 31 DE DICIEMBRE 2028
B3: PRODUCTO 4 - 1 DE ENERO A 31 DE DICIEMBRE 2028
B5: ENERGÍA CURVA A SOLICITAR AÑO 2028 PARA MERCADO REGULADO (MWh)
B6: MES | C6: DÍA | D6: H1 | E6: H2 | F6: H3 | G6: H4 | H6: H5 | I6: H6 | J6: H7 | K6: H8 | L6: H9 | M6: H10 | N6: H11 | O6: H12 | P6: H13 | Q6: H14 | R6: H15 | S6: H16 | T6: H17 | U6: H18 | V6: H19 | W6: H20 | X6: H21 | Y6: H22 | Z6: H23 | AA6: H24 | AB6: TOTAL | AC6: No. Dias | AD6: TOTAL MES
B7: 46753 | C7: ORDINARIO | D7: 61.43 | E7: 43.53 | F7: 27.34 | G7: 22.17 | H7: 21.06 | I7: 19.32 | J7: 38.82 | K7: 36 | L7: 59.86 | M7: 76.76 | N7: 98.2 | O7: 121.05 | P7: 138.02 | Q7: 126.98 | R7: 116.35 | S7: 113.11 | T7: 116.11 | U7: 161.68 | V7: 174.21 | W7: 216.23 | X7: 213.64 | Y7: 197.65 | Z7: 159.32 | AA7: 79.99 | AB7: =SUM(D7:AA7) -> 2438.83 | AC7: 20 | AD7: =+AB7*AC7+AB8*AC8+AB9*AC9 -> 70038.93
C8: SABADO | D8: 53.92 | E8: 36.64 | F8: 21.02 | G8: 16.03 | H8: 14.96 | I8: 13.28 | J8: 32.09 | K8: 28.65 | L8: 51.58 | M8: 67.77 | N8: 88.4 | O8: 110.41 | P8: 126.82 | Q8: 116.23 | R8: 105.98 | S8: 102.91 | T8: 105.89 | U8: 151.34 | V8: 163.43 | W8: 203.98 | X8: 201.48 | Y8: 186.04 | Z8: 149.06 | AA8: 79.99 | AB8: =SUM(D8:AA8) -> 2227.9 | AC8: 4
C9: FESTIVO | D9: 37.41 | E9: 21.5 | F9: 7.13 | G9: 2.52 | H9: 1.55 | I9: 0 | J9: 17.32 | K9: 12.48 | L9: 33.38 | M9: 48.05 | N9: 66.85 | O9: 87.04 | P9: 102.22 | Q9: 92.59 | R9: 83.2 | S9: 80.5 | T9: 83.44 | U9: 128.61 | V9: 139.73 | W9: 177.06 | X9: 174.76 | Y9: 160.55 | Z9: 126.51 | AA9: 79.99 | AB9: =SUM(D9:AA9) -> 1764.39 | AC9: 7
B10: 46784 | C10: ORDINARIO | D10: 61.43 | E10: 43.53 | F10: 27.34 | G10: 22.17 | H10: 21.06 | I10: 19.32 | J10: 38.82 | K10: 36 | L10: 59.86 | M10: 76.76 | N10: 98.2 | O10: 121.05 | P10: 138.02 | Q10: 126.98 | R10: 116.35 | S10: 113.11 | T10: 116.11 | U10: 161.68 | V10: 174.21 | W10: 216.23 | X10: 213.64 | Y10: 197.65 | Z10: 159.32 | AA10: 79.99 | AB10: =SUM(D10:AA10) -> 2438.83 | AC10: 21 | AD10: =+AB10*AC10+AB11*AC11+AB12*AC12 -> 67184.59
C11: SABADO | D11: 53.92 | E11: 36.64 | F11: 21.02 | G11: 16.03 | H11: 14.96 | I11: 13.28 | J11: 32.09 | K11: 28.65 | L11: 51.58 | M11: 67.77 | N11: 88.4 | O11: 110.41 | P11: 126.82 | Q11: 116.23 | R11: 105.98 | S11: 102.91 | T11: 105.89 | U11: 151.34 | V11: 163.43 | W11: 203.98 | X11: 201.48 | Y11: 186.04 | Z11: 149.06 | AA11: 79.99 | AB11: =SUM(D11:AA11) -> 2227.9 | AC11: 4
C12: FESTIVO | D12: 37.41 | E12: 21.5 | F12: 7.13 | G12: 2.52 | H12: 1.55 | I12: 0 | J12: 17.32 | K12: 12.48 | L12: 33.38 | M12: 48.05 | N12: 66.85 | O12: 87.04 | P12: 102.22 | Q12: 92.59 | R12: 83.2 | S12: 80.5 | T12: 83.44 | U12: 128.61 | V12: 139.73 | W12: 177.06 | X12: 174.76 | Y12: 160.55 | Z12: 126.51 | AA12: 79.99 | AB12: =SUM(D12:AA12) -> 1764.39 | AC12: 4
B13: 46813 | C13: ORDINARIO | D13: 61.43 | E13: 43.53 | F13: 27.34 | G13: 22.17 | H13: 21.06 | I13: 19.32 | J13: 38.82 | K13: 36 | L13: 59.86 | M13: 76.76 | N13: 98.2 | O13: 121.05 | P13: 138.02 | Q13: 126.98 | R13: 116.35 | S13: 113.11 | T13: 116.11 | U13: 161.68 | V13: 174.21 | W13: 216.23 | X13: 213.64 | Y13: 197.65 | Z13: 159.32 | AA13: 79.99 | AB13: =SUM(D13:AA13) -> 2438.83 | AC13: 22 | AD13: =+AB13*AC13+AB14*AC14+AB15*AC15 -> 71387.81
C14: SABADO | D14: 53.92 | E14: 36.64 | F14: 21.02 | G14: 16.03 | H14: 14.96 | I14: 13.28 | J14: 32.09 | K14: 28.65 | L14: 51.58 | M14: 67.77 | N14: 88.4 | O14: 110.41 | P14: 126.82 | Q14: 116.23 | R14: 105.98 | S14: 102.91 | T14: 105.89 | U14: 151.34 | V14: 163.43 | W14: 203.98 | X14: 201.48 | Y14: 186.04 | Z14: 149.06 | AA14: 79.99 | AB14: =SUM(D14:AA14) -> 2227.9 | AC14: 4
C15: FESTIVO | D15: 37.41 | E15: 21.5 | F15: 7.13 | G15: 2.52 | H15: 1.55 | I15: 0 | J15: 17.32 | K15: 12.48 | L15: 33.38 | M15: 48.05 | N15: 66.85 | O15: 87.04 | P15: 102.22 | Q15: 92.59 | R15: 83.2 | S15: 80.5 | T15: 83.44 | U15: 128.61 | V15: 139.73 | W15: 177.06 | X15: 174.76 | Y15: 160.55 | Z15: 126.51 | AA15: 79.99 | AB15: =SUM(D15:AA15) -> 1764.39 | AC15: 5
B16: 46844 | C16: ORDINARIO | D16: 61.43 | E16: 43.53 | F16: 27.34 | G16: 22.17 | H16: 21.06 | I16: 19.32 | J16: 38.82 | K16: 36 | L16: 59.86 | M16: 76.76 | N16: 98.2 | O16: 121.05 | P16: 138.02 | Q16: 126.98 | R16: 116.35 | S16: 113.11 | T16: 116.11 | U16: 161.68 | V16: 174.21 | W16: 216.23 | X16: 213.64 | Y16: 197.65 | Z16: 159.32 | AA16: 79.99 | AB16: =SUM(D16:AA16) -> 2438.83 | AC16: 18 | AD16: =+AB16*AC16+AB17*AC17+AB18*AC18 -> 67389.17
C17: SABADO | D17: 53.92 | E17: 36.64 | F17: 21.02 | G17: 16.03 | H17: 14.96 | I17: 13.28 | J17: 32.09 | K17: 28.65 | L17: 51.58 | M17: 67.77 | N17: 88.4 | O17: 110.41 | P17: 126.82 | Q17: 116.23 | R17: 105.98 | S17: 102.91 | T17: 105.89 | U17: 151.34 | V17: 163.43 | W17: 203.98 | X17: 201.48 | Y17: 186.04 | Z17: 149.06 | AA17: 79.99 | AB17: =SUM(D17:AA17) -> 2227.9 | AC17: 5
C18: FESTIVO | D18: 37.41 | E18: 21.5 | F18: 7.13 | G18: 2.52 | H18: 1.55 | I18: 0 | J18: 17.32 | K18: 12.48 | L18: 33.38 | M18: 48.05 | N18: 66.85 | O18: 87.04 | P18: 102.22 | Q18: 92.59 | R18: 83.2 | S18: 80.5 | T18: 83.44 | U18: 128.61 | V18: 139.73 | W18: 177.06 | X18: 174.76 | Y18: 160.55 | Z18: 126.51 | AA18: 79.99 | AB18: =SUM(D18:AA18) -> 1764.39 | AC18: 7
B19: 46874 | C19: ORDINARIO | D19: 61.43 | E19: 43.53 | F19: 27.34 | G19: 22.17 | H19: 21.06 | I19: 19.32 | J19: 38.82 | K19: 36 | L19: 59.86 | M19: 76.76 | N19: 98.2 | O19: 121.05 | P19: 138.02 | Q19: 126.98 | R19: 116.35 | S19: 113.11 | T19: 116.11 | U19: 161.68 | V19: 174.21 | W19: 216.23 | X19: 213.64 | Y19: 197.65 | Z19: 159.32 | AA19: 79.99 | AB19: =SUM(D19:AA19) -> 2438.83 | AC19: 21 | AD19: =+AB19*AC19+AB20*AC20+AB21*AC21 -> 70713.37
C20: SABADO | D20: 53.92 | E20: 36.64 | F20: 21.02 | G20: 16.03 | H20: 14.96 | I20: 13.28 | J20: 32.09 | K20: 28.65 | L20: 51.58 | M20: 67.77 | N20: 88.4 | O20: 110.41 | P20: 126.82 | Q20: 116.23 | R20: 105.98 | S20: 102.91 | T20: 105.89 | U20: 151.34 | V20: 163.43 | W20: 203.98 | X20: 201.48 | Y20: 186.04 | Z20: 149.06 | AA20: 79.99 | AB20: =SUM(D20:AA20) -> 2227.9 | AC20: 4
C21: FESTIVO | D21: 37.41 | E21: 21.5 | F21: 7.13 | G21: 2.52 | H21: 1.55 | I21: 0 | J21: 17.32 | K21: 12.48 | L21: 33.38 | M21: 48.05 | N21: 66.85 | O21: 87.04 | P21: 102.22 | Q21: 92.59 | R21: 83.2 | S21: 80.5 | T21: 83.44 | U21: 128.61 | V21: 139.73 | W21: 177.06 | X21: 174.76 | Y21: 160.55 | Z21: 126.51 | AA21: 79.99 | AB21: =SUM(D21:AA21) -> 1764.39 | AC21: 6
B22: 46905 | C22: ORDINARIO | D22: 61.43 | E22: 43.53 | F22: 27.34 | G22: 22.17 | H22: 21.06 | I22: 19.32 | J22: 38.82 | K22: 36 | L22: 59.86 | M22: 76.76 | N22: 98.2 | O22: 121.05 | P22: 138.02 | Q22: 126.98 | R22: 116.35 | S22: 113.11 | T22: 116.11 | U22: 161.68 | V22: 174.21 | W22: 216.23 | X22: 213.64 | Y22: 197.65 | Z22: 159.32 | AA22: 79.99 | AB22: =SUM(D22:AA22) -> 2438.83 | AC22: 20 | AD22: =+AB22*AC22+AB23*AC23+AB24*AC24 -> 68274.54
C23: SABADO | D23: 53.92 | E23: 36.64 | F23: 21.02 | G23: 16.03 | H23: 14.96 | I23: 13.28 | J23: 32.09 | K23: 28.65 | L23: 51.58 | M23: 67.77 | N23: 88.4 | O23: 110.41 | P23: 126.82 | Q23: 116.23 | R23: 105.98 | S23: 102.91 | T23: 105.89 | U23: 151.34 | V23: 163.43 | W23: 203.98 | X23: 201.48 | Y23: 186.04 | Z23: 149.06 | AA23: 79.99 | AB23: =SUM(D23:AA23) -> 2227.9 | AC23: 4
C24: FESTIVO | D24: 37.41 | E24: 21.5 | F24: 7.13 | G24: 2.52 | H24: 1.55 | I24: 0 | J24: 17.32 | K24: 12.48 | L24: 33.38 | M24: 48.05 | N24: 66.85 | O24: 87.04 | P24: 102.22 | Q24: 92.59 | R24: 83.2 | S24: 80.5 | T24: 83.44 | U24: 128.61 | V24: 139.73 | W24: 177.06 | X24: 174.76 | Y24: 160.55 | Z24: 126.51 | AA24: 79.99 | AB24: =SUM(D24:AA24) -> 1764.39 | AC24: 6
B25: 46935 | C25: ORDINARIO | D25: 61.43 | E25: 43.53 | F25: 27.34 | G25: 22.17 | H25: 21.06 | I25: 19.32 | J25: 38.82 | K25: 36 | L25: 59.86 | M25: 76.76 | N25: 98.2 | O25: 121.05 | P25: 138.02 | Q25: 126.98 | R25: 116.35 | S25: 113.11 | T25: 116.11 | U25: 161.68 | V25: 174.21 | W25: 216.23 | X25: 213.64 | Y25: 197.65 | Z25: 159.32 | AA25: 79.99 | AB25: =SUM(D25:AA25) -> 2438.83 | AC25: 19 | AD25: =+AB25*AC25+AB26*AC26+AB27*AC27 -> 69828
C26: SABADO | D26: 53.92 | E26: 36.64 | F26: 21.02 | G26: 16.03 | H26: 14.96 | I26: 13.28 | J26: 32.09 | K26: 28.65 | L26: 51.58 | M26: 67.77 | N26: 88.4 | O26: 110.41 | P26: 126.82 | Q26: 116.23 | R26: 105.98 | S26: 102.91 | T26: 105.89 | U26: 151.34 | V26: 163.43 | W26: 203.98 | X26: 201.48 | Y26: 186.04 | Z26: 149.06 | AA26: 79.99 | AB26: =SUM(D26:AA26) -> 2227.9 | AC26: 5
C27: FESTIVO | D27: 37.41 | E27: 21.5 | F27: 7.13 | G27: 2.52 | H27: 1.55 | I27: 0 | J27: 17.32 | K27: 12.48 | L27: 33.38 | M27: 48.05 | N27: 66.85 | O27: 87.04 | P27: 102.22 | Q27: 92.59 | R27: 83.2 | S27: 80.5 | T27: 83.44 | U27: 128.61 | V27: 139.73 | W27: 177.06 | X27: 174.76 | Y27: 160.55 | Z27: 126.51 | AA27: 79.99 | AB27: =SUM(D27:AA27) -> 1764.39 | AC27: 7
B28: 46966 | C28: ORDINARIO | D28: 61.43 | E28: 43.53 | F28: 27.34 | G28: 22.17 | H28: 21.06 | I28: 19.32 | J28: 38.82 | K28: 36 | L28: 59.86 | M28: 76.76 | N28: 98.2 | O28: 121.05 | P28: 138.02 | Q28: 126.98 | R28: 116.35 | S28: 113.11 | T28: 116.11 | U28: 161.68 | V28: 174.21 | W28: 216.23 | X28: 213.64 | Y28: 197.65 | Z28: 159.32 | AA28: 79.99 | AB28: =SUM(D28:AA28) -> 2438.83 | AC28: 21 | AD28: =+AB28*AC28+AB29*AC29+AB30*AC30 -> 70713.37
C29: SABADO | D29: 53.92 | E29: 36.64 | F29: 21.02 | G29: 16.03 | H29: 14.96 | I29: 13.28 | J29: 32.09 | K29: 28.65 | L29: 51.58 | M29: 67.77 | N29: 88.4 | O29: 110.41 | P29: 126.82 | Q29: 116.23 | R29: 105.98 | S29: 102.91 | T29: 105.89 | U29: 151.34 | V29: 163.43 | W29: 203.98 | X29: 201.48 | Y29: 186.04 | Z29: 149.06 | AA29: 79.99 | AB29: =SUM(D29:AA29) -> 2227.9 | AC29: 4
C30: FESTIVO | D30: 37.41 | E30: 21.5 | F30: 7.13 | G30: 2.52 | H30: 1.55 | I30: 0 | J30: 17.32 | K30: 12.48 | L30: 33.38 | M30: 48.05 | N30: 66.85 | O30: 87.04 | P30: 102.22 | Q30: 92.59 | R30: 83.2 | S30: 80.5 | T30: 83.44 | U30: 128.61 | V30: 139.73 | W30: 177.06 | X30: 174.76 | Y30: 160.55 | Z30: 126.51 | AA30: 79.99 | AB30: =SUM(D30:AA30) -> 1764.39 | AC30: 6
B31: 46997 | C31: ORDINARIO | D31: 61.43 | E31: 43.53 | F31: 27.34 | G31: 22.17 | H31: 21.06 | I31: 19.32 | J31: 38.82 | K31: 36 | L31: 59.86 | M31: 76.76 | N31: 98.2 | O31: 121.05 | P31: 138.02 | Q31: 126.98 | R31: 116.35 | S31: 113.11 | T31: 116.11 | U31: 161.68 | V31: 174.21 | W31: 216.23 | X31: 213.64 | Y31: 197.65 | Z31: 159.32 | AA31: 79.99 | AB31: =SUM(D31:AA31) -> 2438.83 | AC31: 21 | AD31: =+AB31*AC31+AB32*AC32+AB33*AC33 -> 69412.49
C32: SABADO | D32: 53.92 | E32: 36.64 | F32: 21.02 | G32: 16.03 | H32: 14.96 | I32: 13.28 | J32: 32.09 | K32: 28.65 | L32: 51.58 | M32: 67.77 | N32: 88.4 | O32: 110.41 | P32: 126.82 | Q32: 116.23 | R32: 105.98 | S32: 102.91 | T32: 105.89 | U32: 151.34 | V32: 163.43 | W32: 203.98 | X32: 201.48 | Y32: 186.04 | Z32: 149.06 | AA32: 79.99 | AB32: =SUM(D32:AA32) -> 2227.9 | AC32: 5
C33: FESTIVO | D33: 37.41 | E33: 21.5 | F33: 7.13 | G33: 2.52 | H33: 1.55 | I33: 0 | J33: 17.32 | K33: 12.48 | L33: 33.38 | M33: 48.05 | N33: 66.85 | O33: 87.04 | P33: 102.22 | Q33: 92.59 | R33: 83.2 | S33: 80.5 | T33: 83.44 | U33: 128.61 | V33: 139.73 | W33: 177.06 | X33: 174.76 | Y33: 160.55 | Z33: 126.51 | AA33: 79.99 | AB33: =SUM(D33:AA33) -> 1764.39 | AC33: 4
B34: 47027 | C34: ORDINARIO | D34: 61.43 | E34: 43.53 | F34: 27.34 | G34: 22.17 | H34: 21.06 | I34: 19.32 | J34: 38.82 | K34: 36 | L34: 59.86 | M34: 76.76 | N34: 98.2 | O34: 121.05 | P34: 138.02 | Q34: 126.98 | R34: 116.35 | S34: 113.11 | T34: 116.11 | U34: 161.68 | V34: 174.21 | W34: 216.23 | X34: 213.64 | Y34: 197.65 | Z34: 159.32 | AA34: 79.99 | AB34: =SUM(D34:AA34) -> 2438.83 | AC34: 21 | AD34: =+AB34*AC34+AB35*AC35+AB36*AC36 -> 70713.37
C35: SABADO | D35: 53.92 | E35: 36.64 | F35: 21.02 | G35: 16.03 | H35: 14.96 | I35: 13.28 | J35: 32.09 | K35: 28.65 | L35: 51.58 | M35: 67.77 | N35: 88.4 | O35: 110.41 | P35: 126.82 | Q35: 116.23 | R35: 105.98 | S35: 102.91 | T35: 105.89 | U35: 151.34 | V35: 163.43 | W35: 203.98 | X35: 201.48 | Y35: 186.04 | Z35: 149.06 | AA35: 79.99 | AB35: =SUM(D35:AA35) -> 2227.9 | AC35: 4
C36: FESTIVO | D36: 37.41 | E36: 21.5 | F36: 7.13 | G36: 2.52 | H36: 1.55 | I36: 0 | J36: 17.32 | K36: 12.48 | L36: 33.38 | M36: 48.05 | N36: 66.85 | O36: 87.04 | P36: 102.22 | Q36: 92.59 | R36: 83.2 | S36: 80.5 | T36: 83.44 | U36: 128.61 | V36: 139.73 | W36: 177.06 | X36: 174.76 | Y36: 160.55 | Z36: 126.51 | AA36: 79.99 | AB36: =SUM(D36:AA36) -> 1764.39 | AC36: 6
B37: 47058 | C37: ORDINARIO | D37: 61.43 | E37: 43.53 | F37: 27.34 | G37: 22.17 | H37: 21.06 | I37: 19.32 | J37: 38.82 | K37: 36 | L37: 59.86 | M37: 76.76 | N37: 98.2 | O37: 121.05 | P37: 138.02 | Q37: 126.98 | R37: 116.35 | S37: 113.11 | T37: 116.11 | U37: 161.68 | V37: 174.21 | W37: 216.23 | X37: 213.64 | Y37: 197.65 | Z37: 159.32 | AA37: 79.99 | AB37: =SUM(D37:AA37) -> 2438.83 | AC37: 20 | AD37: =+AB37*AC37+AB38*AC38+AB39*AC39 -> 68274.54
C38: SABADO | D38: 53.92 | E38: 36.64 | F38: 21.02 | G38: 16.03 | H38: 14.96 | I38: 13.28 | J38: 32.09 | K38: 28.65 | L38: 51.58 | M38: 67.77 | N38: 88.4 | O38: 110.41 | P38: 126.82 | Q38: 116.23 | R38: 105.98 | S38: 102.91 | T38: 105.89 | U38: 151.34 | V38: 163.43 | W38: 203.98 | X38: 201.48 | Y38: 186.04 | Z38: 149.06 | AA38: 79.99 | AB38: =SUM(D38:AA38) -> 2227.9 | AC38: 4
C39: FESTIVO | D39: 37.41 | E39: 21.5 | F39: 7.13 | G39: 2.52 | H39: 1.55 | I39: 0 | J39: 17.32 | K39: 12.48 | L39: 33.38 | M39: 48.05 | N39: 66.85 | O39: 87.04 | P39: 102.22 | Q39: 92.59 | R39: 83.2 | S39: 80.5 | T39: 83.44 | U39: 128.61 | V39: 139.73 | W39: 177.06 | X39: 174.76 | Y39: 160.55 | Z39: 126.51 | AA39: 79.99 | AB39: =SUM(D39:AA39) -> 1764.39 | AC39: 6
B40: 47088 | C40: ORDINARIO | D40: 61.43 | E40: 43.53 | F40: 27.34 | G40: 22.17 | H40: 21.06 | I40: 19.32 | J40: 38.82 | K40: 36 | L40: 59.86 | M40: 76.76 | N40: 98.2 | O40: 121.05 | P40: 138.02 | Q40: 126.98 | R40: 116.35 | S40: 113.11 | T40: 116.11 | U40: 161.68 | V40: 174.21 | W40: 216.23 | X40: 213.64 | Y40: 197.65 | Z40: 159.32 | AA40: 79.99 | AB40: =SUM(D40:AA40) -> 2438.83 | AC40: 19 | AD40: =+AB40*AC40+AB41*AC41+AB42*AC42 -> 69828
C41: SABADO | D41: 53.92 | E41: 36.64 | F41: 21.02 | G41: 16.03 | H41: 14.96 | I41: 13.28 | J41: 32.09 | K41: 28.65 | L41: 51.58 | M41: 67.77 | N41: 88.4 | O41: 110.41 | P41: 126.82 | Q41: 116.23 | R41: 105.98 | S41: 102.91 | T41: 105.89 | U41: 151.34 | V41: 163.43 | W41: 203.98 | X41: 201.48 | Y41: 186.04 | Z41: 149.06 | AA41: 79.99 | AB41: =SUM(D41:AA41) -> 2227.9 | AC41: 5
C42: FESTIVO | D42: 37.41 | E42: 21.5 | F42: 7.13 | G42: 2.52 | H42: 1.55 | I42: 0 | J42: 17.32 | K42: 12.48 | L42: 33.38 | M42: 48.05 | N42: 66.85 | O42: 87.04 | P42: 102.22 | Q42: 92.59 | R42: 83.2 | S42: 80.5 | T42: 83.44 | U42: 128.61 | V42: 139.73 | W42: 177.06 | X42: 174.76 | Y42: 160.55 | Z42: 126.51 | AA42: 79.99 | AB42: =SUM(D42:AA42) -> 1764.39 | AC42: 7
...

Sheet P4_Anexo_2_2028
C3: EMPRESAS MUNICIPALES DE CALI- EMCALI EICE ESP
C4: CONVOCATORIA PÚBLICA PARA COMPRA DE ENERGÍA
C5: Código de Convocatoria SICEP No. CP-EMIC2025-003
C7: ANEXO No. 2 CANTIDADES Y PRECIOS OFERTADOS
C9: PRODUCTO 4 - 1 DE ENERO A 31 DE DICIEMBRE 2028 - CURVA
C12: AÑO | D12: Energía solicitada (MWh) | E12: Energía Ofertada (MWh) | F12: $/kWh
C13: 2028 | D13: =P4_Anexo_1_2028!AD43 -> 833758.18
C14: Total año | D14: =SUM(D13:D13) -> 833758.18
C17: NOTAS:
C18: 1- La cantidad a ofertar puede ser parcial o total de la energía solicitada.
C19: 2- Precios en pesos constantes del mes de agosto de 2025.
C20: 3- La energía y los precios a ofertar deben ofrecerse en la modalidad monomia.
C21: 4- Las cantidades ofertadas siguen la curva indicada en los términos de referencia

Sheet P5_Anexo_1_2029
