Workbook
Name _Toc148954622: 'Banco de Preguntas'!#REF!
Name _Toc148954623: 'Banco de Preguntas'!#REF!
Name _Toc148954624: 'Banco de Preguntas'!#REF!
Name _Toc148954625: 'Banco de Preguntas'!#REF!
Name aaa: [1]Hoja9!$A$1,[1]Hoja9!$A$3,[1]Hoja9!$A$5,[1]Hoja9!$B$6,[1]Hoja9!$C$7
Name aaa: [1]Hoja9!$A$1,[1]Hoja9!$A$3,[1]Hoja9!$A$5,[1]Hoja9!$B$6,[1]Hoja9!$C$7
Name aaa: [1]Hoja9!$A$1,[1]Hoja9!$A$3,[1]Hoja9!$A$5,[1]Hoja9!$B$6,[1]Hoja9!$C$7
Name aaa: #REF!,#REF!,#REF!,#REF!,#REF!
Name AAAA: #REF!
Name Criterio_Extraer_Dem_Reg: #REF!
Name Criterio_Extraer_Dem_Reg: #REF!
Name Criterio_Extraer_Dem_Reg: #REF!
Name Criterio_Extraer_Dem_Reg: #REF!
Name Criterio_Extraer_Dem_Reg: #REF!
Name Criterio_Extraer_Dem_Reg: #REF!
Name Criterio_Extraer_Dem_Reg: #REF!
Name Criterio_Extraer_Dem_Reg: #REF!
Name Cuadro: #REF!
Name Cuadro: #REF!
Name Cuadro: #REF!
Name Cuadro: #REF!
Name Cuadro: #REF!
Name Cuadro: #REF!
Name Cuadro: #REF!
Name Cuadro: #REF!
Name eeee: #REF!
Name eeee: [2]Comparación!#REF!
Name eeee: #REF!
Name eeee: #REF!
Name eeee: #REF!
Name eeee: [2]Comparación!#REF!
Name eeee: [2]Comparación!#REF!
Name eeee: #REF!
Name Meses: [3]Evaluación_Mensual!$S$2:$S$25
Name Meses: [3]Evaluación_Mensual!$S$2:$S$25
Name Meses: [3]Evaluación_Mensual!$S$2:$S$25
Name Meses: [4]Evaluación_Mensual!$S$2:$S$25
Name Meses: #REF!
Name Precio_Estación: #REF!
Name Precio_Estación: #REF!
Name Precio_Estación: #REF!
Name Precio_Estación: #REF!
Name Precio_Estación: #REF!
Name Precio_Estación: #REF!
Name Precio_Estación: #REF!
Name Precio_Estación: #N/A
Name Precio_Estación: #REF!
Name Precio_Global: #REF!
Name Precio_Global: #REF!
Name Precio_Global: #REF!
Name Precio_Global: #REF!
Name Precio_Global: #REF!
Name Precio_Global: #REF!
Name Precio_Global: #REF!
Name Precio_Global: #N/A
Name Precio_Global: #REF!
Name Precio_Mes: #REF!
Name Precio_Mes: #REF!
Name Precio_Mes: #REF!
Name Precio_Mes: #REF!

Sheet Listas desplegables
A2: Tipo de agente: | B2: Tipo de oferta:
A3: Comercializador | B3: CURVA
A4: Generador | B4: CURVA SOLAR
B5: CURVA FNCER
B6: PLANA SOLAR
B7: MIXTA
B8: PLANA

Sheet Banco de Preguntas
A2: Consolidado banco de preguntas y respuestas agentes convocatorias ESSA
A3: N° Convocatoria
A4: Nombre remitente correo:
A5: Correo electrónico
A6: Teléfono de contacto:
A9: AGENTE | B9: N° pregunta | C9: PREGUNTA | D9: RESPUESTA

Sheet Factor garantia
A2: 12. TABLA Factores de Indexación IPP serie oferta interna
A4: Mes | B4: Factor
A5: 46388 | B5: 0.99
A6: 46419 | B6: 0.99
A7: 46447 | B7: 0.99
A8: 46478 | B8: 0.99
A9: 46508 | B9: 1
A10: 46539 | B10: 1
A11: 46569 | B11: 1
A12: 46600 | B12: 1
A13: 46631 | B13: 1
A14: 46661 | B14: 1
A15: 46692 | B15: 1.01
A16: 46722 | B16: 1.01
... A184: 51836 | B184: 1.52

Sheet Cantidades suministrar P1_27-29
B2: ANEXO 10.1 CANTIDADES DE ENERGÍA REQUERIDA PRODUCTO 1
B3: AÑOS 2027 -2029
B6: Oferta Básica, para la Solicitud Pública de Ofertas No. CP-ESSC2026-002, del 1 de enero de 2027 a 31 de diciembre de 2029.
B8: OFERENTE: | D8: Diligenciar
B9: Tipo de agente: | D9: Elegir de la lista desplegable
B10: Oferta No.: | D10: Diligenciar
B11: Tipo de oferta: | C11: CURVA | D11: Fijo
B12: Franja Horaria | C12: H1-H24
B13: % de su oferta con FNCER: | D13: Diligenciar
B15: Mes-año | C15: Energia Solicitada (kWh) | D15: % a ofertar | E15: Energia Oferta kWh | F15: Precio $ / kWh
A17: 31 | B17: 46388 | C17: =+'Cantidades 1_(2027-2029)'!AD14 -> 40000179 | D17: 0 | E17: =+C17*$D$17 -> 0 | F17: 0
A18: 28 | B18: 46419 | C18: =+'Cantidades 1_(2027-2029)'!AD15 -> 37298925 | E18: =+C18*$D$17 -> 0
A19: 31 | B19: 46447 | C19: =+'Cantidades 1_(2027-2029)'!AD16 -> 40073324 | E19: =+C19*$D$17 -> 0
A20: 30 | B20: 46478 | C20: =+'Cantidades 1_(2027-2029)'!AD17 -> 34634589 | E20: =+C20*$D$17 -> 0
A21: 31 | B21: 46508 | C21: =+'Cantidades 1_(2027-2029)'!AD18 -> 36094806 | E21: =+C21*$D$17 -> 0
A22: 30 | B22: 46539 | C22: =+'Cantidades 1_(2027-2029)'!AD19 -> 24337483 | E22: =+C22*$D$17 -> 0
A23: 31 | B23: 46569 | C23: =+'Cantidades 1_(2027-2029)'!AD20 -> 26662099 | E23: =+C23*$D$17 -> 0
A24: 31 | B24: 46600 | C24: =+'Cantidades 1_(2027-2029)'!AD21 -> 30317581 | E24: =+C24*$D$17 -> 0
A25: 30 | B25: 46631 | C25: =+'Cantidades 1_(2027-2029)'!AD22 -> 28465750 | E25: =+C25*$D$17 -> 0
A26: 31 | B26: 46661 | C26: =+'Cantidades 1_(2027-2029)'!AD23 -> 29190980 | E26: =+C26*$D$17 -> 0
A27: 30 | B27: 46692 | C27: =+'Cantidades 1_(2027-2029)'!AD24 -> 25956770 | E27: =+C27*$D$17 -> 0
A28: =SUM(C17:C28)/1000 -> 391858.95 | B28: 46722 | C28: =+'Cantidades 1_(2027-2029)'!AD25 -> 38826463 | E28: =+C28*$D$17 -> 0
A29: 31 | B29: 46753 | C29: =+'Cantidades 1_(2027-2029)'!AD64 -> 39835760 | E29: =+C29*$D$17 -> 0 | F29: 0
A30: 29 | B30: 46784 | C30: =+'Cantidades 1_(2027-2029)'!AD65 -> 35879987 | E30: =+C30*$D$17 -> 0
A31: 31 | B31: 46813 | C31: =+'Cantidades 1_(2027-2029)'!AD66 -> 39320426 | E31: =+C31*$D$17 -> 0
A32: 30 | B32: 46844 | C32: =+'Cantidades 1_(2027-2029)'!AD67 -> 33025771 | E32: =+C32*$D$17 -> 0
A33: 31 | B33: 46874 | C33: =+'Cantidades 1_(2027-2029)'!AD68 -> 33934182 | E33: =+C33*$D$17 -> 0
A34: 30 | B34: 46905 | C34: =+'Cantidades 1_(2027-2029)'!AD69 -> 37087131 | E34: =+C34*$D$17 -> 0
A35: 31 | B35: 46935 | C35: =+'Cantidades 1_(2027-2029)'!AD70 -> 29299461 | E35: =+C35*$D$17 -> 0
A36: 31 | B36: 46966 | C36: =+'Cantidades 1_(2027-2029)'!AD71 -> 29361381 | E36: =+C36*$D$17 -> 0
A37: 30 | B37: 46997 | C37: =+'Cantidades 1_(2027-2029)'!AD72 -> 28481782 | E37: =+C37*$D$17 -> 0
A38: 31 | B38: 47027 | C38: =+'Cantidades 1_(2027-2029)'!AD73 -> 28604598 | E38: =+C38*$D$17 -> 0
A39: 30 | B39: 47058 | C39: =+'Cantidades 1_(2027-2029)'!AD74 -> 23500228 | E39: =+C39*$D$17 -> 0
A40: =SUM(C29:C40)/1000 -> 393168.75 | B40: 47088 | C40: =+'Cantidades 1_(2027-2029)'!AD75 -> 34838046 | E40: =+C40*$D$17 -> 0
A41: 31 | B41: 47119 | C41: =+'Cantidades 1_(2027-2029)'!AD114 -> 37156387 | E41: =+C41*$D$17 -> 0 | F41: 0
A42: 29 | B42: 47150 | C42: =+'Cantidades 1_(2027-2029)'!AD115 -> 34422858 | E42: =+C42*$D$17 -> 0
A43: 31 | B43: 47178 | C43: =+'Cantidades 1_(2027-2029)'!AD116 -> 36772721 | E43: =+C43*$D$17 -> 0
A44: 30 | B44: 47209 | C44: =+'Cantidades 1_(2027-2029)'!AD117 -> 31506565 | E44: =+C44*$D$17 -> 0
A45: 31 | B45: 47239 | C45: =+'Cantidades 1_(2027-2029)'!AD118 -> 32474757 | E45: =+C45*$D$17 -> 0
A46: 30 | B46: 47270 | C46: =+'Cantidades 1_(2027-2029)'!AD119 -> 34495275 | E46: =+C46*$D$17 -> 0
...

Sheet Cantidades suministrar P2_30-31
B2: ANEXO 10.2 CANTIDADES DE ENERGÍA REQUERIDA PRODUCTO 2
B3: AÑOS 2030 -2031
B6: Oferta Básica, para la Solicitud Pública de Ofertas No. CP-ESSC2026-002, del 1 de enero de 2030 a 31 de diciembre de 2031.
B8: OFERENTE: | D8: Diligenciar
B9: Tipo de agente: | D9: Elegir de la lista desplegable
B10: Oferta No.: | D10: Diligenciar
B11: Tipo de oferta: | C11: CURVA | D11: Fijo
B12: Franja Horaria | C12: H1-H24
B13: % de su oferta con FNCER: | D13: Diligenciar
B15: Mes-año | C15: Energia Solicitada (kWh) | D15: % a ofertar | E15: Energia Oferta kWh | F15: Precio $ / kWh
A17: 31 | B17: 47484 | C17: =+'Cantidades P2_(2030-2031)'!AD14 -> 48414877 | D17: 0 | E17: =+C17*$D$17 -> 0 | F17: 0
A18: 28 | B18: 47515 | C18: =+'Cantidades P2_(2030-2031)'!AD15 -> 45905373 | E18: =+C18*$D$17 -> 0
A19: 31 | B19: 47543 | C19: =+'Cantidades P2_(2030-2031)'!AD16 -> 48268391 | E19: =+C19*$D$17 -> 0
A20: 30 | B20: 47574 | C20: =+'Cantidades P2_(2030-2031)'!AD17 -> 42393441 | E20: =+C20*$D$17 -> 0
A21: 31 | B21: 47604 | C21: =+'Cantidades P2_(2030-2031)'!AD18 -> 43697880 | E21: =+C21*$D$17 -> 0
A22: 30 | B22: 47635 | C22: =+'Cantidades P2_(2030-2031)'!AD19 -> 44636350 | E22: =+C22*$D$17 -> 0
A23: 31 | B23: 47665 | C23: =+'Cantidades P2_(2030-2031)'!AD20 -> 43953037 | E23: =+C23*$D$17 -> 0
A24: 31 | B24: 47696 | C24: =+'Cantidades P2_(2030-2031)'!AD21 -> 43863427 | E24: =+C24*$D$17 -> 0
A25: 30 | B25: 47727 | C25: =+'Cantidades P2_(2030-2031)'!AD22 -> 41663131 | E25: =+C25*$D$17 -> 0
A26: 31 | B26: 47757 | C26: =+'Cantidades P2_(2030-2031)'!AD23 -> 41935169 | E26: =+C26*$D$17 -> 0
A27: 30 | B27: 47788 | C27: =+'Cantidades P2_(2030-2031)'!AD24 -> 37031374 | E27: =+C27*$D$17 -> 0
A28: =SUM(C17:C28)/1000 -> 525234.64 | B28: 47818 | C28: =+'Cantidades P2_(2030-2031)'!AD25 -> 43472186 | E28: =+C28*$D$17 -> 0
A29: 31 | B29: 47849 | C29: =+'Cantidades P2_(2030-2031)'!AD64 -> 47139199 | E29: =+C29*$D$17 -> 0 | F29: 0
A30: 29 | B30: 47880 | C30: =+'Cantidades P2_(2030-2031)'!AD65 -> 45127186 | E30: =+C30*$D$17 -> 0
A31: 31 | B31: 47908 | C31: =+'Cantidades P2_(2030-2031)'!AD66 -> 47341171 | E31: =+C31*$D$17 -> 0
A32: 30 | B32: 47939 | C32: =+'Cantidades P2_(2030-2031)'!AD67 -> 43245047 | E32: =+C32*$D$17 -> 0
A33: 31 | B33: 47969 | C33: =+'Cantidades P2_(2030-2031)'!AD68 -> 44593126 | E33: =+C33*$D$17 -> 0
A34: 30 | B34: 48000 | C34: =+'Cantidades P2_(2030-2031)'!AD69 -> 43761735 | E34: =+C34*$D$17 -> 0
A35: 31 | B35: 48030 | C35: =+'Cantidades P2_(2030-2031)'!AD70 -> 44341110 | E35: =+C35*$D$17 -> 0
A36: 31 | B36: 48061 | C36: =+'Cantidades P2_(2030-2031)'!AD71 -> 44277468 | E36: =+C36*$D$17 -> 0
A37: 30 | B37: 48092 | C37: =+'Cantidades P2_(2030-2031)'!AD72 -> 42192654 | E37: =+C37*$D$17 -> 0
A38: 31 | B38: 48122 | C38: =+'Cantidades P2_(2030-2031)'!AD73 -> 42687347 | E38: =+C38*$D$17 -> 0
A39: 30 | B39: 48153 | C39: =+'Cantidades P2_(2030-2031)'!AD74 -> 39381211 | E39: =+C39*$D$17 -> 0
A40: =SUM(C29:C40)/1000 -> 528432.98 | B40: 48183 | C40: =+'Cantidades P2_(2030-2031)'!AD75 -> 44345728 | E40: =+C40*$D$17 -> 0
A41: =SUM(#REF!) -> #REF! | B41: TOTAL | C41: =SUM(C17:C40) -> 1.0536676e+09 | E41: =SUM(E17:E40) -> 0 | F41: =(SUM(E17:E28)*F17+SUM(E29:E40)*F29)/E41 -> #DIV/0!
B44: Notas:
B45: (1) La Energía Ofertada se distribuye en forma horaria de acuerdo con la curva de carga presentada en la tabla 9.2. TABLAS CANTIDADES DE ENERGÍA REQUERIDA PRODUCTO 2 AÑOS 2030 A 2031 del pliego de condiciones.
B47: (2) Tipo de Contrato: pague lo contratado.
B48: (3) Precio ofertado en $kWh, en pesos de Abril 2026 (IPP Provisional)
B49: (4) El precio igual para todos los meses por año e Independiente por año del producto, con dos cifras decimales
...

Sheet Hoja9
B2: Mes | C2: AÑO 2026 Energia Solicitada (kWh) | D2: AÑO 2027 Energia Solicitada (kWh) | E2: AÑO 2028 Energia Solicitada (kWh) | F2: AÑO 2029 Energia Solicitada (kWh) | G2: AÑO 2030 Energia Solicitada (kWh) | H2: AÑO 2031 Energia Solicitada (kWh) | I2: AÑO 2032 Energia Solicitada (kWh) | J2: AÑO 2033 Energia Solicitada (kWh) | K2: AÑO 2034 Energia Solicitada (kWh) | L2: AÑO 2035 Energia Solicitada (kWh) | M2: TOTAL PRODUCTO 2 Energia Solicitada (kWh)
B3: CURVA | C3: La misma curva de la tabla 9.1.2 del producto 1 | D3: La misma curva de la tabla 9.1.3 del producto 1 | E3: La misma curva de la tabla 9.1.4 del producto 1 | F3: La misma curva de la tabla 9.1.5 del producto 1 | G3: La misma curva de la tabla 9.1.6 del producto 1 | H3: La misma curva de la tabla 9.1.7 del producto 1 | I3: La misma curva de la tabla 9.1.8 del producto 1 | J3: La misma curva de la tabla 9.1.9 del producto 1 | K3: La misma curva de la tabla 9.1.10 del producto 1 | L3: La misma curva de la tabla 9.1.11 del producto 1
B4: ene | C4: =+#REF! -> #REF! | D4: =+#REF! -> #REF! | E4: =+#REF! -> #REF! | F4: =+#REF! -> #REF! | G4: =+#REF! -> #REF! | H4: =+#REF! -> #REF! | I4: =+#REF! -> #REF! | J4: =+#REF! -> #REF! | ... L4: =+#REF! -> #REF! | M4: =SUM(C4:L4) -> #REF!
B5: feb | C5: =+#REF! -> #REF! | D5: =+#REF! -> #REF! | E5: =+#REF! -> #REF! | F5: =+#REF! -> #REF! | G5: =+#REF! -> #REF! | H5: =+#REF! -> #REF! | I5: =+#REF! -> #REF! | J5: =+#REF! -> #REF! | ... L5: =+#REF! -> #REF! | M5: =SUM(C5:L5) -> #REF!
B6: mar | C6: =+#REF! -> #REF! | D6: =+#REF! -> #REF! | E6: =+#REF! -> #REF! | F6: =+#REF! -> #REF! | G6: =+#REF! -> #REF! | H6: =+#REF! -> #REF! | I6: =+#REF! -> #REF! | J6: =+#REF! -> #REF! | ... L6: =+#REF! -> #REF! | M6: =SUM(C6:L6) -> #REF!
B7: abr | C7: =+#REF! -> #REF! | D7: =+#REF! -> #REF! | E7: =+#REF! -> #REF! | F7: =+#REF! -> #REF! | G7: =+#REF! -> #REF! | H7: =+#REF! -> #REF! | I7: =+#REF! -> #REF! | J7: =+#REF! -> #REF! | ... L7: =+#REF! -> #REF! | M7: =SUM(C7:L7) -> #REF!
B8: may | C8: =+#REF! -> #REF! | D8: =+#REF! -> #REF! | E8: =+#REF! -> #REF! | F8: =+#REF! -> #REF! | G8: =+#REF! -> #REF! | H8: =+#REF! -> #REF! | I8: =+#REF! -> #REF! | J8: =+#REF! -> #REF! | ... L8: =+#REF! -> #REF! | M8: =SUM(C8:L8) -> #REF!
B9: jun | C9: =+#REF! -> #REF! | D9: =+#REF! -> #REF! | E9: =+#REF! -> #REF! | F9: =+#REF! -> #REF! | G9: =+#REF! -> #REF! | H9: =+#REF! -> #REF! | I9: =+#REF! -> #REF! | J9: =+#REF! -> #REF! | ... L9: =+#REF! -> #REF! | M9: =SUM(C9:L9) -> #REF!
B10: jul | C10: =+#REF! -> #REF! | D10: =+#REF! -> #REF! | E10: =+#REF! -> #REF! | F10: =+#REF! -> #REF! | G10: =+#REF! -> #REF! | H10: =+#REF! -> #REF! | I10: =+#REF! -> #REF! | J10: =+#REF! -> #REF! | ... L10: =+#REF! -> #REF! | M10: =SUM(C10:L10) -> #REF!
B11: ago | C11: =+#REF! -> #REF! | D11: =+#REF! -> #REF! | E11: =+#REF! -> #REF! | F11: =+#REF! -> #REF! | G11: =+#REF! -> #REF! | H11: =+#REF! -> #REF! | I11: =+#REF! -> #REF! | J11: =+#REF! -> #REF! | ... L11: =+#REF! -> #REF! | M11: =SUM(C11:L11) -> #REF!
B12: sep | C12: =+#REF! -> #REF! | D12: =+#REF! -> #REF! | E12: =+#REF! -> #REF! | F12: =+#REF! -> #REF! | G12: =+#REF! -> #REF! | H12: =+#REF! -> #REF! | I12: =+#REF! -> #REF! | J12: =+#REF! -> #REF! | ... L12: =+#REF! -> #REF! | M12: =SUM(C12:L12) -> #REF!
B13: oct | C13: =+#REF! -> #REF! | D13: =+#REF! -> #REF! | E13: =+#REF! -> #REF! | F13: =+#REF! -> #REF! | G13: =+#REF! -> #REF! | H13: =+#REF! -> #REF! | I13: =+#REF! -> #REF! | J13: =+#REF! -> #REF! | ... L13: =+#REF! -> #REF! | M13: =SUM(C13:L13) -> #REF!
B14: nov | C14: =+#REF! -> #REF! | D14: =+#REF! -> #REF! | E14: =+#REF! -> #REF! | F14: =+#REF! -> #REF! | G14: =+#REF! -> #REF! | H14: =+#REF! -> #REF! | I14: =+#REF! -> #REF! | J14: =+#REF! -> #REF! | ... L14: =+#REF! -> #REF! | M14: =SUM(C14:L14) -> #REF!
B15: dic | C15: =+#REF! -> #REF! | D15: =+#REF! -> #REF! | E15: =+#REF! -> #REF! | F15: =+#REF! -> #REF! | G15: =+#REF! -> #REF! | H15: =+#REF! -> #REF! | I15: =+#REF! -> #REF! | J15: =+#REF! -> #REF! | ... L15: =+#REF! -> #REF! | M15: =SUM(C15:L15) -> #REF!
B16: TOTAL | C16: =SUM(C4:C15) -> #REF! | D16: =SUM(D4:D15) -> #REF! | E16: =SUM(E4:E15) -> #REF! | F16: =SUM(F4:F15) -> #REF! | G16: =SUM(G4:G15) -> #REF! | H16: =SUM(H4:H15) -> #REF! | I16: =SUM(I4:I15) -> #REF! | J16: =SUM(J4:J15) -> #REF! | ... M16: =SUM(M4:M15) -> #REF!
M17: =+M16-#REF! -> #REF!

Sheet Hoja9 (2)
B2: Mes | C2: AÑO 2027 Energia Solicitada (kWh) | D2: AÑO 2028 Energia Solicitada (kWh) | E2: AÑO 2029 Energia Solicitada (kWh) | F2: AÑO 2030 Energia Solicitada (kWh) | G2: AÑO 2031 Energia Solicitada (kWh) | H2: AÑO 2032 Energia Solicitada (kWh) | I2: AÑO 2033 Energia Solicitada (kWh) | J2: AÑO 2034 Energia Solicitada (kWh) | K2: AÑO 2035 Energia Solicitada (kWh) | L2: AÑO 2036 Energia Solicitada (kWh) | M2: TOTAL PRODUCTO 3 Energia Solicitada (kWh)
B3: CURVA | C3: La misma curva de la tabla 9.1.3 del producto 1 | D3: La misma curva de la tabla 9.1.4 del producto 1 | E3: La misma curva de la tabla 9.1.5 del producto 1 | F3: La misma curva de la tabla 9.1.6 del producto 1 | G3: La misma curva de la tabla 9.1.7 del producto 1 | H3: La misma curva de la tabla 9.1.8 del producto 1 | I3: La misma curva de la tabla 9.1.9 del producto 1 | J3: La misma curva de la tabla 9.1.10 del producto 1 | K3: La misma curva de la tabla 9.1.11 del producto 1 | L3: La misma curva de la tabla 9.1.12 del producto 1
B4: ene | C4: =+#REF! -> #REF! | D4: =+#REF! -> #REF! | E4: =+#REF! -> #REF! | F4: =+#REF! -> #REF! | G4: =+#REF! -> #REF! | H4: =+#REF! -> #REF! | I4: =+#REF! -> #REF! | J4: =+#REF! -> #REF! | ... L4: =+#REF! -> #REF! | M4: =SUM(C4:L4) -> #REF!
B5: feb | C5: =+#REF! -> #REF! | D5: =+#REF! -> #REF! | E5: =+#REF! -> #REF! | F5: =+#REF! -> #REF! | G5: =+#REF! -> #REF! | H5: =+#REF! -> #REF! | I5: =+#REF! -> #REF! | J5: =+#REF! -> #REF! | ... L5: =+#REF! -> #REF! | M5: =SUM(C5:L5) -> #REF!
B6: mar | C6: =+#REF! -> #REF! | D6: =+#REF! -> #REF! | E6: =+#REF! -> #REF! | F6: =+#REF! -> #REF! | G6: =+#REF! -> #REF! | H6: =+#REF! -> #REF! | I6: =+#REF! -> #REF! | J6: =+#REF! -> #REF! | ... L6: =+#REF! -> #REF! | M6: =SUM(C6:L6) -> #REF!
B7: abr | C7: =+#REF! -> #REF! | D7: =+#REF! -> #REF! | E7: =+#REF! -> #REF! | F7: =+#REF! -> #REF! | G7: =+#REF! -> #REF! | H7: =+#REF! -> #REF! | I7: =+#REF! -> #REF! | J7: =+#REF! -> #REF! | ... L7: =+#REF! -> #REF! | M7: =SUM(C7:L7) -> #REF!
B8: may | C8: =+#REF! -> #REF! | D8: =+#REF! -> #REF! | E8: =+#REF! -> #REF! | F8: =+#REF! -> #REF! | G8: =+#REF! -> #REF! | H8: =+#REF! -> #REF! | I8: =+#REF! -> #REF! | J8: =+#REF! -> #REF! | ... L8: =+#REF! -> #REF! | M8: =SUM(C8:L8) -> #REF!
B9: jun | C9: =+#REF! -> #REF! | D9: =+#REF! -> #REF! | E9: =+#REF! -> #REF! | F9: =+#REF! -> #REF! | G9: =+#REF! -> #REF! | H9: =+#REF! -> #REF! | I9: =+#REF! -> #REF! | J9: =+#REF! -> #REF! | ... L9: =+#REF! -> #REF! | M9: =SUM(C9:L9) -> #REF!
B10: jul | C10: =+#REF! -> #REF! | D10: =+#REF! -> #REF! | E10: =+#REF! -> #REF! | F10: =+#REF! -> #REF! | G10: =+#REF! -> #REF! | H10: =+#REF! -> #REF! | I10: =+#REF! -> #REF! | J10: =+#REF! -> #REF! | ... L10: =+#REF! -> #REF! | M10: =SUM(C10:L10) -> #REF!
B11: ago | C11: =+#REF! -> #REF! | D11: =+#REF! -> #REF! | E11: =+#REF! -> #REF! | F11: =+#REF! -> #REF! | G11: =+#REF! -> #REF! | H11: =+#REF! -> #REF! | I11: =+#REF! -> #REF! | J11: =+#REF! -> #REF! | ... L11: =+#REF! -> #REF! | M11: =SUM(C11:L11) -> #REF!
B12: sep | C12: =+#REF! -> #REF! | D12: =+#REF! -> #REF! | E12: =+#REF! -> #REF! | F12: =+#REF! -> #REF! | G12: =+#REF! -> #REF! | H12: =+#REF! -> #REF! | I12: =+#REF! -> #REF! | J12: =+#REF! -> #REF! | ... L12: =+#REF! -> #REF! | M12: =SUM(C12:L12) -> #REF!
B13: oct | C13: =+#REF! -> #REF! | D13: =+#REF! -> #REF! | E13: =+#REF! -> #REF! | F13: =+#REF! -> #REF! | G13: =+#REF! -> #REF! | H13: =+#REF! -> #REF! | I13: =+#REF! -> #REF! | J13: =+#REF! -> #REF! | ... L13: =+#REF! -> #REF! | M13: =SUM(C13:L13) -> #REF!
B14: nov | C14: =+#REF! -> #REF! | D14: =+#REF! -> #REF! | E14: =+#REF! -> #REF! | F14: =+#REF! -> #REF! | G14: =+#REF! -> #REF! | H14: =+#REF! -> #REF! | I14: =+#REF! -> #REF! | J14: =+#REF! -> #REF! | ... L14: =+#REF! -> #REF! | M14: =SUM(C14:L14) -> #REF!
B15: dic | C15: =+#REF! -> #REF! | D15: =+#REF! -> #REF! | E15: =+#REF! -> #REF! | F15: =+#REF! -> #REF! | G15: =+#REF! -> #REF! | H15: =+#REF! -> #REF! | I15: =+#REF! -> #REF! | J15: =+#REF! -> #REF! | ... L15: =+#REF! -> #REF! | M15: =SUM(C15:L15) -> #REF!
B16: TOTAL | C16: =SUM(C4:C15) -> #REF! | D16: =SUM(D4:D15) -> #REF! | E16: =SUM(E4:E15) -> #REF! | F16: =SUM(F4:F15) -> #REF! | G16: =SUM(G4:G15) -> #REF! | H16: =SUM(H4:H15) -> #REF! | I16: =SUM(I4:I15) -> #REF! | J16: =SUM(J4:J15) -> #REF! | ... M16: =SUM(M4:M15) -> #REF!
M17: =+M16-#REF! -> #REF!

Sheet Cant suministrar P3_32-41
B2: ANEXO 10.3 CANTIDADES DE ENERGÍA A SUMINISTRAR PRODUCTO 3
B3: AÑO 2032 al 2041
B6: Oferta Básica, para la Solicitud Pública de Ofertas No. CP-ESSC2026-002, del 1 de enero de 2032 a 31 de diciembre de 2041.
B7: OFERENTE: | K7: Diligenciar
B8: Tipo de agente: | K8: Elegir de la lista desplegable
B9: Oferta No: | K9: Diligenciar
B10: Tipo de oferta: | C10: CURVA | K10: Elegir de la lista desplegable
B11: % de su oferta con FNCER: | K11: Diligenciar
B13: Mes-año | C13: Energia Solicitada (kWh) | D13: % a ofertar | E13: Energia Oferta kWh | F13: Precio $ / kWh | H13: Mes-año | I13: Energia Solicitada (kWh) | J13: % a ofertar | K13: Energia Oferta kWh | L13: Precio $ / kWh
A15: 31 | B15: 48214 | C15: =+'Cantidades P3_(2032-2041)'!$AC$11 -> 25535865 | D15: 0 | E15: =+C15*$D$15 -> 0 | H15: 50041 | I15: =+'Cantidades P3_(2032-2041)'!$AC$256 -> 23759509 | J15: =+$D$15 -> 0 | K15: =+I15*$J$15 -> 0
A16: 29 | B16: 48245 | C16: =+'Cantidades P3_(2032-2041)'!$AC$15 -> 24337017 | E16: =+C16*$D$15 -> 0 | H16: 50072 | I16: =+'Cantidades P3_(2032-2041)'!$AC$260 -> 22903448 | K16: =+I16*$J$15 -> 0
A17: 31 | B17: 48274 | C17: =+'Cantidades P3_(2032-2041)'!$AC$19 -> 25639513 | E17: =+C17*$D$15 -> 0 | H17: 50100 | I17: =+'Cantidades P3_(2032-2041)'!$AC$264 -> 23854591 | K17: =+I17*$J$15 -> 0
A18: 30 | B18: 48305 | C18: =+'Cantidades P3_(2032-2041)'!$AC$23 -> 23442969 | E18: =+C18*$D$15 -> 0 | H18: 50131 | I18: =+'Cantidades P3_(2032-2041)'!$AC$268 -> 22445857 | K18: =+I18*$J$15 -> 0
A19: 31 | B19: 48335 | C19: =+'Cantidades P3_(2032-2041)'!$AC$27 -> 24110566 | E19: =+C19*$D$15 -> 0 | H19: 50161 | I19: =+'Cantidades P3_(2032-2041)'!$AC$272 -> 23058763 | K19: =+I19*$J$15 -> 0
A20: 30 | B20: 48366 | C20: =+'Cantidades P3_(2032-2041)'!$AC$31 -> 23651156 | E20: =+C20*$D$15 -> 0 | H20: 50192 | I20: =+'Cantidades P3_(2032-2041)'!$AC$276 -> 22163487 | K20: =+I20*$J$15 -> 0
A21: 31 | B21: 48396 | C21: =+'Cantidades P3_(2032-2041)'!$AC$35 -> 23714593 | E21: =+C21*$D$15 -> 0 | H21: 50222 | I21: =+'Cantidades P3_(2032-2041)'!$AC$280 -> 22659466 | K21: =+I21*$J$15 -> 0
A22: 31 | B22: 48427 | C22: =+'Cantidades P3_(2032-2041)'!$AC$39 -> 23872913 | E22: =+C22*$D$15 -> 0 | H22: 50253 | I22: =+'Cantidades P3_(2032-2041)'!$AC$284 -> 22778904 | K22: =+I22*$J$15 -> 0
A23: 30 | B23: 48458 | C23: =+'Cantidades P3_(2032-2041)'!$AC$43 -> 22858420 | E23: =+C23*$D$15 -> 0 | H23: 50284 | I23: =+'Cantidades P3_(2032-2041)'!$AC$288 -> 21876542 | K23: =+I23*$J$15 -> 0
A24: 31 | B24: 48488 | C24: =+'Cantidades P3_(2032-2041)'!$AC$47 -> 23065744 | E24: =+C24*$D$15 -> 0 | H24: 50314 | I24: =+'Cantidades P3_(2032-2041)'!$AC$292 -> 22146231 | K24: =+I24*$J$15 -> 0
A25: 30 | B25: 48519 | C25: =+'Cantidades P3_(2032-2041)'!$AC$51 -> 21325926 | E25: =+C25*$D$15 -> 0 | H25: 50345 | I25: =+'Cantidades P3_(2032-2041)'!$AC$296 -> 20985825 | K25: =+I25*$J$15 -> 0
A26: 31 | B26: 48549 | C26: =+'Cantidades P3_(2032-2041)'!$AC$55 -> 23824689 | E26: =+C26*$D$15 -> 0 | H26: 50375 | I26: =+'Cantidades P3_(2032-2041)'!$AC$300 -> 22896078 | K26: =+I26*$J$15 -> 0
A27: 31 | B27: 48580 | C27: =+'Cantidades P3_(2032-2041)'!$AC$60 -> 23800303 | D27: =+$D$15 -> 0 | E27: =+C27*$D$27 -> 0 | H27: 50406 | I27: =+'Cantidades P3_(2032-2041)'!$AC$305 -> 23690733 | J27: =+$D$15 -> 0 | K27: =+I27*$J$27 -> 0
A28: 28 | B28: 48611 | C28: =+'Cantidades P3_(2032-2041)'!$AC$64 -> 22785937 | E28: =+C28*$D$27 -> 0 | H28: 50437 | I28: =+'Cantidades P3_(2032-2041)'!$AC$309 -> 22854249 | K28: =+I28*$J$27 -> 0
A29: 31 | B29: 48639 | C29: =+'Cantidades P3_(2032-2041)'!$AC$68 -> 23870209 | E29: =+C29*$D$27 -> 0 | H29: 50465 | I29: =+'Cantidades P3_(2032-2041)'!$AC$313 -> 23784037 | K29: =+I29*$J$27 -> 0
A30: 30 | B30: 48670 | C30: =+'Cantidades P3_(2032-2041)'!$AC$72 -> 21981869 | E30: =+C30*$D$27 -> 0 | H30: 50496 | I30: =+'Cantidades P3_(2032-2041)'!$AC$317 -> 22406466 | K30: =+I30*$J$27 -> 0
A31: 31 | B31: 48700 | C31: =+'Cantidades P3_(2032-2041)'!$AC$76 -> 22624603 | E31: =+C31*$D$27 -> 0 | H31: 50526 | I31: =+'Cantidades P3_(2032-2041)'!$AC$321 -> 23005062 | K31: =+I31*$J$27 -> 0
A32: 30 | B32: 48731 | C32: =+'Cantidades P3_(2032-2041)'!$AC$80 -> 22028553 | E32: =+C32*$D$27 -> 0 | H32: 50557 | I32: =+'Cantidades P3_(2032-2041)'!$AC$325 -> 22130031 | K32: =+I32*$J$27 -> 0
A33: 31 | B33: 48761 | C33: =+'Cantidades P3_(2032-2041)'!$AC$84 -> 22314603 | E33: =+C33*$D$27 -> 0 | H33: 50587 | I33: =+'Cantidades P3_(2032-2041)'!$AC$329 -> 22614457 | K33: =+I33*$J$27 -> 0
A34: 31 | B34: 48792 | C34: =+'Cantidades P3_(2032-2041)'!$AC$88 -> 22463034 | E34: =+C34*$D$27 -> 0 | H34: 50618 | I34: =+'Cantidades P3_(2032-2041)'!$AC$333 -> 22731544 | K34: =+I34*$J$27 -> 0
A35: 30 | B35: 48823 | C35: =+'Cantidades P3_(2032-2041)'!$AC$92 -> 21556561 | E35: =+C35*$D$27 -> 0 | H35: 50649 | I35: =+'Cantidades P3_(2032-2041)'!$AC$337 -> 21848933 | K35: =+I35*$J$27 -> 0
A36: 31 | B36: 48853 | C36: =+'Cantidades P3_(2032-2041)'!$AC$96 -> 21752954 | E36: =+C36*$D$27 -> 0 | H36: 50679 | I36: =+'Cantidades P3_(2032-2041)'!$AC$341 -> 22112723 | K36: =+I36*$J$27 -> 0
A37: 30 | B37: 48884 | C37: =+'Cantidades P3_(2032-2041)'!$AC$100 -> 20207510 | E37: =+C37*$D$27 -> 0 | H37: 50710 | I37: =+'Cantidades P3_(2032-2041)'!$AC$345 -> 20978009 | K37: =+I37*$J$27 -> 0
A38: 31 | B38: 48914 | C38: =+'Cantidades P3_(2032-2041)'!$AC$104 -> 22476423 | E38: =+C38*$D$27 -> 0 | H38: 50740 | I38: =+'Cantidades P3_(2032-2041)'!$AC$349 -> 22846475 | K38: =+I38*$J$27 -> 0
A39: 31 | B39: 48945 | C39: =+'Cantidades P3_(2032-2041)'!$AC$109 -> 23965361 | D39: =+$D$15 -> 0 | E39: =+C39*$D$39 -> 0 | H39: 50771 | I39: =+'Cantidades P3_(2032-2041)'!$AC$354 -> 23596055 | J39: =+$D$15 -> 0 | K39: =+I39*$J$39 -> 0
A40: 28 | B40: 48976 | C40: =+'Cantidades P3_(2032-2041)'!$AC$113 -> 23025746 | E40: =+C40*$D$39 -> 0 | H40: 50802 | I40: =+'Cantidades P3_(2032-2041)'!$AC$358 -> 22779151 | K40: =+I40*$J$39 -> 0
A41: 31 | B41: 49004 | C41: =+'Cantidades P3_(2032-2041)'!$AC$117 -> 24061751 | E41: =+C41*$D$39 -> 0 | H41: 50830 | I41: =+'Cantidades P3_(2032-2041)'!$AC$362 -> 23687436 | K41: =+I41*$J$39 -> 0
A42: 30 | B42: 49035 | C42: =+'Cantidades P3_(2032-2041)'!$AC$121 -> 22358689 | E42: =+C42*$D$39 -> 0 | H42: 50861 | I42: =+'Cantidades P3_(2032-2041)'!$AC$366 -> 22341305 | K42: =+I42*$J$39 -> 0
A43: 31 | B43: 49065 | C43: =+'Cantidades P3_(2032-2041)'!$AC$125 -> 23005892 | E43: =+C43*$D$39 -> 0 | H43: 50891 | I43: =+'Cantidades P3_(2032-2041)'!$AC$370 -> 22925518 | K43: =+I43*$J$39 -> 0
A44: 30 | B44: 49096 | C44: =+'Cantidades P3_(2032-2041)'!$AC$129 -> 22210492 | E44: =+C44*$D$39 -> 0 | H44: 50922 | I44: =+'Cantidades P3_(2032-2041)'!$AC$374 -> 22070885 | K44: =+I44*$J$39 -> 0
A45: 31 | B45: 49126 | C45: =+'Cantidades P3_(2032-2041)'!$AC$133 -> 22628981 | E45: =+C45*$D$39 -> 0 | H45: 50952 | I45: =+'Cantidades P3_(2032-2041)'!$AC$378 -> 22543702 | K45: =+I45*$J$39 -> 0
...

Sheet Cantidades 1_(2027-2029)
B4: 9.1 TABLAS CANTIDADES DE ENERGÍA REQUERIDA PRODUCTO 1 AÑO 2027 -2029 (kWh)
B5: ELETRIFICADORA DE SANTANDER S.A E.S.P.
B6: SOLICITUD PÚBLICA DE OFERTAS CP-ESSC2026-002
B7: PAGUELO CONTRATADO
B10: Mes | C10: Tipo Día | D10: Días | E10: H1 | F10: H2 | G10: H3 | H10: H4 | I10: H5 | J10: H6 | K10: H7 | L10: H8 | M10: H9 | N10: H10 | O10: H11 | P10: H12 | Q10: H13 | R10: H14 | S10: H15 | T10: H16 | U10: H17 | V10: H18 | W10: H19 | X10: H20 | Y10: H21 | Z10: H22 | AA10: H23 | AB10: H24 | AC10: TOTAL MES kWh | AE10: =+AC10 -> TOTAL MES kWh
B11: 46388 | C11: Ordinario | D11: 19 | E11: 48314.84 | F11: 45847.48 | G11: 43991.41 | H11: 42644.2 | I11: 42409.14 | J11: 43828.32 | K11: 43432.68 | L11: 48451.47 | M11: 53786.29 | N11: 56558.63 | O11: 59559.93 | P11: 62016.71 | Q11: 60318.63 | R11: 61979.36 | S11: 64854.42 | T11: 65199.2 | U11: 64120.94 | V11: 61758.07 | W11: 66065.51 | X11: 66301.08 | Y11: 64559.5 | Z11: 61728.63 | AA11: 57352.36 | AB11: 52680.23 | AC11: =SUM(E11:AB11)*D11+SUM(E12:AB12)*D12+SUM(E13:AB13)*D13+SUM(E14:AB14)*D14 -> 40000179
C12: Sábado | D12: 5 | E12: 47964.63 | F12: 45660.97 | G12: 43851.57 | H12: 42469.69 | I12: 42051.43 | J12: 42387.82 | K12: 41295.41 | L12: 45375.35 | M12: 50420.34 | N12: 53761.66 | O12: 56390.44 | P12: 57812.97 | Q12: 57307.47 | R12: 56094.09 | S12: 56358.79 | T12: 56554.29 | U12: 55993.85 | V12: 56196.69 | W12: 62425.83 | X12: 62872.86 | Y12: 61003.97 | Z12: 58532 | AA12: 55319.59 | AB12: 51757.15
C13: Domingo | D13: 5 | E13: 48282.53 | F13: 45910.4 | G13: 43997.62 | H13: 42594.28 | I13: 41903.6 | J13: 41683.79 | K13: 39438 | L13: 41197.43 | M13: 44017.7 | N13: 46189.21 | O13: 48266.73 | P13: 49947.36 | Q13: 51092.8 | R13: 51230.63 | S13: 51256.59 | T13: 51432.94 | U13: 51459.07 | V13: 52002.49 | W13: 58791.32 | X13: 60475.3 | Y13: 59835.44 | Z13: 57867.16 | AA13: 54342.24 | AB13: 50137.21
C14: Festivo | D14: 2 | E14: 48282.53 | F14: 45910.4 | G14: 43997.62 | H14: 42594.28 | I14: 41903.6 | J14: 41683.79 | K14: 39438 | L14: 41197.43 | M14: 44017.7 | N14: 46189.21 | O14: 48266.73 | P14: 49947.36 | Q14: 51092.8 | R14: 51230.63 | S14: 51256.59 | T14: 51432.94 | U14: 51459.07 | V14: 52002.49 | W14: 58791.32 | X14: 60475.3 | Y14: 59835.44 | Z14: 57867.16 | AA14: 54342.24 | AB14: 50137.21 | AD14: =+AC11 -> 40000179
B15: 46419 | C15: Ordinario | D15: 20 | E15: 49247 | F15: 46829.49 | G15: 44899.6 | H15: 43500.6 | I15: 43451.87 | J15: 46063.59 | K15: 45620.11 | L15: 50060.45 | M15: 54945.49 | N15: 57315.78 | O15: 60178.72 | P15: 62442.7 | Q15: 60354.16 | R15: 62522.6 | S15: 66006.49 | T15: 66546.2 | U15: 65553 | V15: 62880.28 | W15: 66607.61 | X15: 67549.42 | Y15: 66093.16 | Z15: 63178.43 | AA15: 58202.42 | AB15: 53268.66 | AC15: =SUM(E15:AB15)*D15+SUM(E16:AB16)*D16+SUM(E17:AB17)*D17+SUM(E18:AB18)*D18 -> 37298925 | AD15: =+AC15 -> 37298925
B16: Feb | C16: Sábado | D16: 4 | E16: 49926.17 | F16: 47226.69 | G16: 45466.25 | H16: 43792.83 | I16: 43265.67 | J16: 43768.41 | K16: 42992.28 | L16: 46965 | M16: 51828.05 | N16: 54716.2 | O16: 57370.83 | P16: 58705.24 | Q16: 57768.8 | R16: 57019.82 | S16: 57282.18 | T16: 57446.12 | U16: 57042.34 | V16: 56874.75 | W16: 62779.31 | X16: 63688.87 | Y16: 62199.96 | Z16: 59830.37 | AA16: 56702.24 | AB16: 52977.42 | AD16: =+AC19 -> 40073324
B17: Feb | C17: Domingo | D17: 4 | E17: 49787.17 | F17: 47381.9 | G17: 45439.73 | H17: 43997.67 | I17: 43255.34 | J17: 43207.16 | K17: 40939.73 | L17: 42705.45 | M17: 45399.46 | N17: 47307.96 | O17: 49251.01 | P17: 51055.84 | Q17: 52254.35 | R17: 52565.07 | S17: 53088.76 | T17: 53500.45 | U17: 53327.91 | V17: 53000.39 | W17: 59899.34 | X17: 62383.57 | Y17: 62360.42 | Z17: 60879.68 | AA17: 55938.14 | AB17: 51579.74 | AD17: =+AC23 -> 34634589
B18: Feb | C18: Festivo | D18: 0 | E18: 0 | F18: 0 | G18: 0 | H18: 0 | I18: 0 | J18: 0 | K18: 0 | L18: 0 | M18: 0 | N18: 0 | O18: 0 | P18: 0 | Q18: 0 | R18: 0 | S18: 0 | T18: 0 | U18: 0 | V18: 0 | W18: 0 | X18: 0 | Y18: 0 | Z18: 0 | AA18: 0 | AB18: 0 | AD18: =+AC27 -> 36094806
B19: 46447 | C19: Ordinario | D19: 20 | E19: 47295.54 | F19: 44956.12 | G19: 43211.05 | H19: 42065.64 | I19: 42258.68 | J19: 44515.19 | K19: 44518.76 | L19: 49345.44 | M19: 54104.99 | N19: 56572.72 | O19: 59398.01 | P19: 61250.52 | Q19: 58479.45 | R19: 60408.28 | S19: 63727.82 | T19: 64429.02 | U19: 63725.47 | V19: 61486.16 | W19: 65245.9 | X19: 65829.74 | Y19: 63901.88 | Z19: 60713.97 | AA19: 55923.45 | AB19: 51060.11 | AC19: =SUM(E19:AB19)*D19+SUM(E20:AB20)*D20+SUM(E21:AB21)*D21+SUM(E22:AB22)*D22 -> 40073324 | AD19: =+AC31 -> 24337483
C20: Sábado | D20: 4 | E20: 47572.42 | F20: 45225.47 | G20: 43374.08 | H20: 42148.6 | I20: 41838.97 | J20: 42315.41 | K20: 42112 | L20: 46540.79 | M20: 51693.18 | N20: 54691.1 | O20: 57380.41 | P20: 58980.1 | Q20: 57966.4 | R20: 57193.51 | S20: 57646.51 | T20: 57722.01 | U20: 57210.08 | V20: 56858.33 | W20: 62787.52 | X20: 63799.8 | Y20: 62026.57 | Z20: 59610.59 | AA20: 56249.56 | AB20: 52564.07 | AD20: =+AC35 -> 26662099
C21: Domingo | D21: 4 | E21: 48847.92 | F21: 46333.56 | G21: 44379.85 | H21: 42979.75 | I21: 42275.94 | J21: 41959.72 | K21: 40374.32 | L21: 42512.54 | M21: 45516.61 | N21: 47691.16 | O21: 49634.84 | P21: 51309.53 | Q21: 52372.76 | R21: 52563.45 | S21: 52765.22 | T21: 53342.21 | U21: 53142.52 | V21: 53405.6 | W21: 59707.35 | X21: 61886.21 | Y21: 61656.84 | Z21: 59847.96 | AA21: 55921.28 | AB21: 51403.74 | AD21: =+AC39 -> 30317581
C22: Festivo | D22: 3 | E22: 48847.92 | F22: 46333.56 | G22: 44379.85 | H22: 42979.75 | I22: 42275.94 | J22: 41959.72 | K22: 40374.32 | L22: 42512.54 | M22: 45516.61 | N22: 47691.16 | O22: 49634.84 | P22: 51309.53 | Q22: 52372.76 | R22: 52563.45 | S22: 52765.22 | T22: 53342.21 | U22: 53142.52 | V22: 53405.6 | W22: 59707.35 | X22: 61886.21 | Y22: 61656.84 | Z22: 59847.96 | AA22: 55921.28 | AB22: 51403.74 | AD22: =+AC43 -> 28465750
B23: 46478 | C23: Ordinario | D23: 22 | E23: 42099.98 | F23: 40003.3 | G23: 38469.66 | H23: 37425.08 | I23: 37585.1 | J23: 38788.77 | K23: 39217.79 | L23: 43684.47 | M23: 48282.48 | N23: 50406.86 | O23: 52772.61 | P23: 54774.34 | Q23: 52628.13 | R23: 54175.36 | S23: 57188.63 | T23: 57554.6 | U23: 56682.63 | V23: 55210.67 | W23: 58621.34 | X23: 58799.35 | Y23: 57039.93 | Z23: 54299.83 | AA23: 50184.71 | AB23: 45691.51 | AC23: =SUM(E23:AB23)*D23+SUM(E24:AB24)*D24+SUM(E25:AB25)*D25+SUM(E26:AB26)*D26 -> 34634589 | AD23: =+AC47 -> 29190980
B24: Feb | C24: Sábado | D24: 4 | E24: 41674.87 | F24: 39502.28 | G24: 37888.51 | H24: 36786.45 | I24: 36508.09 | J24: 36497.01 | K24: 36410.57 | L24: 40134.52 | M24: 44468.8 | N24: 46789.96 | O24: 49062.94 | P24: 50476.39 | Q24: 49818.83 | R24: 49282.61 | S24: 49556.97 | T24: 49651.15 | U24: 49371.4 | V24: 49673.65 | W24: 55169.4 | X24: 55288.7 | Y24: 53755.73 | Z24: 51499.58 | AA24: 48648.83 | AB24: 45391.16 | AD24: =+AC51 -> 25956770
B25: Feb | C25: Domingo | D25: 4 | E25: 42488.92 | F25: 40398.59 | G25: 38670.05 | H25: 37487.53 | I25: 36989.2 | J25: 36332.22 | K25: 35570.17 | L25: 37537.57 | M25: 39623.2 | N25: 41484.54 | O25: 43215.69 | P25: 44589.15 | Q25: 45357.18 | R25: 45568.77 | S25: 45847.43 | T25: 46258.04 | U25: 46423.94 | V25: 46992.68 | W25: 52204.83 | X25: 53783.15 | Y25: 53606.28 | Z25: 52289.74 | AA25: 48934.66 | AB25: 44956.13 | AD25: =+AC55 -> 38826463
B26: Feb | C26: Festivo | D26: 0 | E26: 0 | F26: 0 | G26: 0 | H26: 0 | I26: 0 | J26: 0 | K26: 0 | L26: 0 | M26: 0 | N26: 0 | O26: 0 | P26: 0 | Q26: 0 | R26: 0 | S26: 0 | T26: 0 | U26: 0 | V26: 0 | W26: 0 | X26: 0 | Y26: 0 | Z26: 0 | AA26: 0 | AB26: 0
B27: 46508 | C27: Ordinario | D27: 19 | E27: 42341.38 | F27: 40330.97 | G27: 38809.34 | H27: 37767.87 | I27: 37952.96 | J27: 39004.12 | K27: 39888.85 | L27: 44550.34 | M27: 49343.31 | N27: 51587.81 | O27: 54264.26 | P27: 56012.33 | Q27: 53736.88 | R27: 55209.59 | S27: 58073.23 | T27: 58359.88 | U27: 57524.82 | V27: 55645.18 | W27: 59106.85 | X27: 59341.1 | Y27: 57510.87 | Z27: 54471.05 | AA27: 50189.17 | AB27: 45814.93 | AC27: =SUM(E27:AB27)*D27+SUM(E28:AB28)*D28+SUM(E29:AB29)*D29+SUM(E30:AB30)*D30 -> 36094806
C28: Sábado | D28: 4 | E28: 43076.23 | F28: 40570.19 | G28: 38875.05 | H28: 37783.19 | I28: 37583.73 | J28: 37175.17 | K28: 37533.26 | L28: 41830.37 | M28: 46623.7 | N28: 49313.44 | O28: 51365.33 | P28: 52741.28 | Q28: 51663.38 | R28: 50948.83 | S28: 51322.15 | T28: 51415.72 | U28: 51123.96 | V28: 51495.41 | W28: 56978.97 | X28: 57625.64 | Y28: 55920.48 | Z28: 53400.63 | AA28: 50480.57 | AB28: 47093.85
C29: Domingo | D29: 5 | E29: 43584.72 | F29: 41525.33 | G29: 39884.62 | H29: 38707.86 | I29: 38206.39 | J29: 37054.19 | K29: 36495.05 | L29: 38672.95 | M29: 41634.76 | N29: 43976.58 | O29: 45580.89 | P29: 46776.24 | Q29: 47457.61 | R29: 47602.1 | S29: 47800.61 | T29: 48327.62 | U29: 48189.57 | V29: 48960.22 | W29: 54642.84 | X29: 56144.03 | Y29: 55838.69 | Z29: 54046.3 | AA29: 50428.71 | AB29: 45854.57
C30: Festivo | D30: 3 | E30: 43584.72 | F30: 41525.33 | G30: 39884.62 | H30: 38707.86 | I30: 38206.39 | J30: 37054.19 | K30: 36495.05 | L30: 38672.95 | M30: 41634.76 | N30: 43976.58 | O30: 45580.89 | P30: 46776.24 | Q30: 47457.61 | R30: 47602.1 | S30: 47800.61 | T30: 48327.62 | U30: 48189.57 | V30: 48960.22 | W30: 54642.84 | X30: 56144.03 | Y30: 55838.69 | Z30: 54046.3 | AA30: 50428.71 | AB30: 45854.57
B31: 46539 | C31: Ordinario | D31: 21 | E31: 29555.37 | F31: 28071.12 | G31: 27039.7 | H31: 26232.67 | I31: 26313.48 | J31: 26675.78 | K31: 27251.77 | L31: 30683.48 | M31: 34024.11 | N31: 35677.82 | O31: 37590.94 | P31: 38848.41 | Q31: 37467.23 | R31: 38289.05 | S31: 40171.7 | T31: 40394.98 | U31: 39993.35 | V31: 38744 | W31: 41005.38 | X31: 41524.94 | Y31: 40168.22 | Z31: 38109.33 | AA31: 35045.73 | AB31: 31956.28 | AC31: =SUM(E31:AB31)*D31+SUM(E32:AB32)*D32+SUM(E33:AB33)*D33+SUM(E34:AB34)*D34 -> 24337483
B32: Feb | C32: Sábado | D32: 4 | E32: 29628.03 | F32: 28172.66 | G32: 27091.15 | H32: 26348.87 | I32: 26218.69 | J32: 25887.04 | K32: 26140.85 | L32: 29156.64 | M32: 32466.12 | N32: 34356.01 | O32: 35975.48 | P32: 36956.31 | Q32: 36281.29 | R32: 35551.86 | S32: 35662.47 | T32: 35685.31 | U32: 35270.51 | V32: 35412.76 | W32: 38473.18 | X32: 39280.25 | Y32: 38152.42 | Z32: 36248.8 | AA32: 34037.06 | AB32: 31751.31
B33: Feb | C33: Domingo | D33: 4 | E33: 30075.61 | F33: 28552.31 | G33: 27369.09 | H33: 26591.4 | I33: 26288.07 | J33: 25462.2 | K33: 24902.65 | L33: 26267.97 | M33: 28067.95 | N33: 29573.2 | O33: 30638.45 | P33: 31485.49 | Q33: 32147.88 | R33: 32088.16 | S33: 32198.84 | T33: 32460.34 | U33: 32512.4 | V33: 32881.94 | W33: 36662.11 | X33: 38431.45 | Y33: 37945.71 | Z33: 36730.76 | AA33: 34507.09 | AB33: 31985.06
B34: Feb | C34: Festivo | D34: 1 | E34: 30075.61 | F34: 28552.31 | G34: 27369.09 | H34: 26591.4 | I34: 26288.07 | J34: 25462.2 | K34: 24902.65 | L34: 26267.97 | M34: 28067.95 | N34: 29573.2 | O34: 30638.45 | P34: 31485.49 | Q34: 32147.88 | R34: 32088.16 | S34: 32198.84 | T34: 32460.34 | U34: 32512.4 | V34: 32881.94 | W34: 36662.11 | X34: 38431.45 | Y34: 37945.71 | Z34: 36730.76 | AA34: 34507.09 | AB34: 31985.06
B35: 46569 | C35: Ordinario | D35: 20 | E35: 31605.92 | F35: 29990.22 | G35: 28784.34 | H35: 27979.09 | I35: 27949.4 | J35: 28668.18 | K35: 29040.77 | L35: 32617.81 | M35: 36124.99 | N35: 37928.89 | O35: 40025.4 | P35: 41597.79 | Q35: 40114.88 | R35: 41464.57 | S35: 43825.46 | T35: 44085.02 | U35: 43486.72 | V35: 41638.81 | W35: 43485.4 | X35: 44498.99 | Y35: 43293.37 | Z35: 41141 | AA35: 37776.42 | AB35: 34520.65 | AC35: =SUM(E35:AB35)*D35+SUM(E36:AB36)*D36+SUM(E37:AB37)*D37+SUM(E38:AB38)*D38 -> 26662099
C36: Sábado | D36: 5 | E36: 32195.24 | F36: 30375.41 | G36: 29066.05 | H36: 28272.58 | I36: 27896.93 | J36: 27613.84 | K36: 27737.86 | L36: 30775.55 | M36: 34342.02 | N36: 36401.76 | O36: 38339.37 | P36: 39307.79 | Q36: 38679.61 | R36: 38120.42 | S36: 38117.68 | T36: 37892.49 | U36: 37529.78 | V36: 37654.84 | W36: 40016.36 | X36: 40917.67 | Y36: 39576.95 | Z36: 37919.68 | AA36: 35817.25 | AB36: 33408.76
C37: Domingo | D37: 4 | E37: 30276.97 | F37: 28861.33 | G37: 27626.79 | H37: 26872.84 | I37: 26567.98 | J37: 25918.29 | K37: 25346.2 | L37: 26912.9 | M37: 28839.16 | N37: 30391.15 | O37: 31714.87 | P37: 32843.06 | Q37: 33658.78 | R37: 33865.76 | S37: 34058.08 | T37: 34508.4 | U37: 34447.56 | V37: 34610.69 | W37: 38536.06 | X37: 40738.09 | Y37: 40122.11 | Z37: 38473.48 | AA37: 35512.08 | AB37: 32520.3
C38: Festivo | D38: 2 | E38: 30276.97 | F38: 28861.33 | G38: 27626.79 | H38: 26872.84 | I38: 26567.98 | J38: 25918.29 | K38: 25346.2 | L38: 26912.9 | M38: 28839.16 | N38: 30391.15 | O38: 31714.87 | P38: 32843.06 | Q38: 33658.78 | R38: 33865.76 | S38: 34058.08 | T38: 34508.4 | U38: 34447.56 | V38: 34610.69 | W38: 38536.06 | X38: 40738.09 | Y38: 40122.11 | Z38: 38473.48 | AA38: 35512.08 | AB38: 32520.3
B39: 46600 | C39: Ordinario | D39: 21 | E39: 35863.18 | F39: 33901.34 | G39: 32512.23 | H39: 31564.7 | I39: 31532.24 | J39: 32585.97 | K39: 32969.31 | L39: 36675.25 | M39: 40669.95 | N39: 42671.14 | O39: 45159.29 | P39: 47219.9 | Q39: 45321.65 | R39: 46803.75 | S39: 49617.91 | T39: 49936.59 | U39: 49080.22 | V39: 47282.44 | W39: 50112.79 | X39: 50894.3 | Y39: 49464.1 | Z39: 46934.47 | AA39: 43038 | AB39: 39357.42 | AC39: =SUM(E39:AB39)*D39+SUM(E40:AB40)*D40+SUM(E41:AB41)*D41+SUM(E42:AB42)*D42 -> 30317581
B40: Feb | C40: Sábado | D40: 3 | E40: 36354.17 | F40: 34484.82 | G40: 33098.76 | H40: 32046.77 | I40: 31415.97 | J40: 31145.12 | K40: 31193.69 | L40: 34530.94 | M40: 38186.48 | N40: 40511.7 | O40: 42420.88 | P40: 43067.01 | Q40: 42327.46 | R40: 41747.59 | S40: 42208.24 | T40: 42391.78 | U40: 42112.62 | V40: 42437.92 | W40: 46844.07 | X40: 47216.38 | Y40: 45495.16 | Z40: 43431.09 | AA40: 40766.44 | AB40: 37859.06
B41: Feb | C41: Domingo | D41: 5 | E41: 35477.07 | F41: 33750.85 | G41: 32254.72 | H41: 31387.51 | I41: 30935.4 | J41: 30464.44 | K41: 29645.53 | L41: 31324.62 | M41: 33340.72 | N41: 35054.38 | O41: 36507.93 | P41: 37719.56 | Q41: 38442 | R41: 38593.33 | S41: 38826.12 | T41: 39106.45 | U41: 39101.64 | V41: 39757.19 | W41: 44740.27 | X41: 46671.85 | Y41: 46289.56 | Z41: 44635.5 | AA41: 41368.67 | AB41: 37914.33
B42: Feb | C42: Festivo | D42: 2 | E42: 35477.07 | F42: 33750.85 | G42: 32254.72 | H42: 31387.51 | I42: 30935.4 | J42: 30464.44 | K42: 29645.53 | L42: 31324.62 | M42: 33340.72 | N42: 35054.38 | O42: 36507.93 | P42: 37719.56 | Q42: 38442 | R42: 38593.33 | S42: 38826.12 | T42: 39106.45 | U42: 39101.64 | V42: 39757.19 | W42: 44740.27 | X42: 46671.85 | Y42: 46289.56 | Z42: 44635.5 | AA42: 41368.67 | AB42: 37914.33
B43: 46631 | C43: Ordinario | D43: 22 | E43: 34618.44 | F43: 32802.58 | G43: 31464.89 | H43: 30485.14 | I43: 30450.53 | J43: 31435.99 | K43: 31880.3 | L43: 35529.85 | M43: 39460.42 | N43: 41422.96 | O43: 43532.56 | P43: 45335.35 | Q43: 43696.77 | R43: 44973.57 | S43: 47524.45 | T43: 47849.7 | U43: 47110.39 | V43: 45912.53 | W43: 48983.95 | X43: 48521.33 | Y43: 46972.12 | Z43: 44438.67 | AA43: 40637.53 | AB43: 37140.72 | AC43: =SUM(E43:AB43)*D43+SUM(E44:AB44)*D44+SUM(E45:AB45)*D45+SUM(E46:AB46)*D46 -> 28465750
C44: Sábado | D44: 4 | E44: 33717.61 | F44: 32013.3 | G44: 30733.02 | H44: 29789.39 | I44: 29538.5 | J44: 29368.42 | K44: 29705.15 | L44: 33091.7 | M44: 36879.52 | N44: 38745.31 | O44: 41014.5 | P44: 42024.66 | Q44: 41556.73 | R44: 41048.42 | S44: 41332.08 | T44: 41243.84 | U44: 40753.52 | V44: 41753.29 | W44: 46394.4 | X44: 46050.95 | Y44: 44425.27 | Z44: 42381.1 | AA44: 40039 | AB44: 37240.47
C45: Domingo | D45: 4 | E45: 34511.22 | F45: 32752.49 | G45: 31242.46 | H45: 30242.89 | I45: 29819.78 | J45: 29010.56 | K45: 28252.3 | L45: 30028.71 | M45: 31959.56 | N45: 33832.48 | O45: 35265.82 | P45: 36207.36 | Q45: 37014.28 | R45: 37127.87 | S45: 37150.11 | T45: 37612.29 | U45: 37572.43 | V45: 38794.55 | W45: 43868.2 | X45: 44597.95 | Y45: 44021.87 | Z45: 42359.56 | AA45: 39305.42 | AB45: 36053.05
...

Sheet Cantidades P2_(2030-2031)
B4: 9.2. TABLAS CANTIDADES DE ENERGÍA REQUERIDA PRODUCTO 2 AÑO 2030-2031 (kWh)
B5: ELETRIFICADORA DE SANTANDER S.A E.S.P.
B6: SOLICITUD PÚBLICA DE OFERTAS CP-ESSC2026-002
B7: PAGUELO CONTRATADO
BE8: 1000
B10: Mes | C10: Tipo Día | D10: Días | E10: H1 | F10: H2 | G10: H3 | H10: H4 | I10: H5 | J10: H6 | K10: H7 | L10: H8 | M10: H9 | N10: H10 | O10: H11 | P10: H12 | Q10: H13 | R10: H14 | S10: H15 | T10: H16 | U10: H17 | V10: H18 | W10: H19 | X10: H20 | Y10: H21 | Z10: H22 | AA10: H23 | AB10: H24 | AC10: TOTAL MES kWh | AF10: PERIODO | AG10: H1 | AH10: H2 | AI10: H3 | AJ10: H4 | AK10: H5 | AL10: H6 | AM10: H7 | AN10: H8 | AO10: H9 | AP10: H10 | AQ10: H11 | AR10: H12 | AS10: H13 | AT10: H14 | AU10: H15 | AV10: H16 | AW10: H17 | AX10: H18 | AY10: H19 | AZ10: H20 | BA10: H21 | BB10: H22 | BC10: H23 | BD10: H24 | BE10: TOTAL DIA | BF10: TOTAL AÑO | BH10: Año 2024 | BI10: =(+#REF!)/1000 -> #REF! | BJ10: MWh-año
B11: 47484 | C11: Ordinario | D11: 21 | E11: 61153.19 | F11: 57478.65 | G11: 54492.9 | H11: 52241.51 | I11: 51451.8 | J11: 52960.35 | K11: 51228.02 | L11: 53605.69 | M11: 57256.91 | N11: 58868.56 | O11: 61962.89 | P11: 65472.21 | Q11: 63480.85 | R11: 67265.03 | S11: 72573.31 | T11: 74318.48 | U11: 75836.98 | V11: 83341.62 | W11: 89826.42 | X11: 90474.85 | Y11: 89054.03 | Z11: 85406.16 | AA11: 79551.7 | AB11: 73757 | AC11: =SUM(E11:AB11)*D11+SUM(E12:AB12)*D12+SUM(E13:AB13)*D13+SUM(E14:AB14)*D14 -> 48414877
C12: Sábado | D12: 4 | E12: 60046.11 | F12: 56888.44 | G12: 54036.8 | H12: 51801.87 | I12: 50776.5 | J12: 50623.36 | K12: 47682.74 | L12: 48797.09 | M12: 51839.27 | N12: 54609.88 | O12: 56819.35 | P12: 58060.66 | Q12: 57738.87 | R12: 56089.77 | S12: 57838.93 | T12: 59979.51 | U12: 62774.67 | V12: 75044.03 | W12: 84054.69 | X12: 84361.66 | Y12: 82570.88 | Z12: 79802.2 | AA12: 76081.95 | AB12: 71417.45 | BG12: =+AC59/1000 -> 525234.64
C13: Domingo | D13: 4 | E13: 60791.49 | F13: 57493.54 | G13: 54409.11 | H13: 52119.17 | I13: 50984.16 | J13: 50248.65 | K13: 45964.88 | L13: 43905.77 | M13: 43576.33 | N13: 43514.79 | O13: 45379.13 | P13: 47465.8 | Q13: 49733.67 | R13: 50836.48 | S13: 52198.71 | T13: 54095.89 | U13: 57633.92 | V13: 69306.74 | W13: 79148.53 | X13: 81211.53 | Y13: 80810.49 | Z13: 79033.27 | AA13: 74039.25 | AB13: 68016.83 | BG13: =(+AC109)/1000 -> 528432.98
C14: Festivo | D14: 2 | E14: 60705.69 | F14: 57225.99 | G14: 54053.55 | H14: 51762.87 | I14: 50689.89 | J14: 50135.24 | K14: 46182.71 | L14: 44381.29 | M14: 44297.83 | N14: 44344.64 | O14: 46148.65 | P14: 48126.59 | Q14: 50338 | R14: 51522.42 | S14: 52997.62 | T14: 55019.78 | U14: 58532.73 | V14: 69967.21 | W14: 79661.54 | X14: 81812.91 | Y14: 81461.95 | Z14: 79701.13 | AA14: 74562.33 | AB14: 68375.48 | AD14: =+AC11 -> 48414877 | BG14: =(+#REF!)/1000 -> #REF!
B15: 47515 | C15: Ordinario | D15: 20 | E15: 64763 | F15: 61167.45 | G15: 57832.71 | H15: 55318.55 | I15: 54473.84 | J15: 57336.35 | K15: 55551.2 | L15: 58016.58 | M15: 60434.62 | N15: 60413.83 | O15: 62807.47 | P15: 65969.88 | Q15: 63825.29 | R15: 68036.22 | S15: 74478.42 | T15: 76742.26 | U15: 78552.59 | V15: 85731.75 | W15: 91890.2 | X15: 93895.71 | Y15: 93309.35 | Z15: 89941.25 | AA15: 82962.68 | AB15: 76536.1 | AC15: =SUM(E15:AB15)*D15+SUM(E16:AB16)*D16+SUM(E17:AB17)*D17+SUM(E18:AB18)*D18 -> 45905373 | AD15: =+AC15 -> 45905373 | BG15: =(+#REF!)/1000 -> #REF!
B16: Feb | C16: Sábado | D16: 4 | E16: 63822.06 | F16: 59589.81 | G16: 57185.85 | H16: 54124.69 | I16: 53002.43 | J16: 53382.08 | K16: 51144.08 | L16: 52157.75 | M16: 53662.54 | N16: 54046.51 | O16: 56178.72 | P16: 57223.13 | Q16: 56273.86 | R16: 56714.86 | S16: 58867.25 | T16: 61639.03 | U16: 64925.18 | V16: 76044.79 | W16: 85980.24 | X16: 86744.29 | Y16: 85958.54 | Z16: 83212.32 | AA16: 79304.85 | AB16: 74292.26 | AD16: =+AC19 -> 48268391 | BG16: =(+#REF!)/1000 -> #REF!
B17: Feb | C17: Domingo | D17: 4 | E17: 64429.24 | F17: 61309 | G17: 58140.38 | H17: 55946.43 | I17: 54787.07 | J17: 54471.61 | K17: 50094.86 | L17: 48404.07 | M17: 47590.78 | N17: 46263.58 | O17: 47582.28 | P17: 50309.55 | Q17: 52718.69 | R17: 54617.73 | S17: 57056.94 | T17: 59348.42 | U17: 61962.1 | V17: 70782.59 | W17: 82496.16 | X17: 86130.29 | Y17: 87352.18 | Z17: 87123.98 | AA17: 79185.35 | AB17: 72826.46 | AD17: =+AC23 -> 42393441 | BG17: =(+#REF!)/1000 -> #REF!
B18: Feb | C18: Festivo | D18: 0 | E18: 0 | F18: 0 | G18: 0 | H18: 0 | I18: 0 | J18: 0 | K18: 0 | L18: 0 | M18: 0 | N18: 0 | O18: 0 | P18: 0 | Q18: 0 | R18: 0 | S18: 0 | T18: 0 | U18: 0 | V18: 0 | W18: 0 | X18: 0 | Y18: 0 | Z18: 0 | AA18: 0 | AB18: 0 | AD18: =+AC27 -> 43697880 | BG18: =(+#REF!)/1000 -> #REF!
B19: 47543 | C19: Ordinario | D19: 20 | E19: 60007.69 | F19: 56445.09 | G19: 53480.34 | H19: 51576.56 | I19: 51197.13 | J19: 53291.21 | K19: 52399.79 | L19: 55520.37 | M19: 58273.7 | N19: 58729.97 | O19: 61036.06 | P19: 63038.64 | Q19: 58718.88 | R19: 62094.58 | S19: 68120.98 | T19: 71012.53 | U19: 73771.16 | V19: 81226.36 | W19: 87761.3 | X19: 88502.39 | Y19: 86802.79 | Z19: 82750.22 | AA19: 76360.73 | AB19: 70267.24 | AC19: =SUM(E19:AB19)*D19+SUM(E20:AB20)*D20+SUM(E21:AB21)*D21+SUM(E22:AB22)*D22 -> 48268391 | AD19: =+AC31 -> 44636350 | BG19: =(+#REF!)/1000 -> #REF!
C20: Sábado | D20: 5 | E20: 59076.02 | F20: 55897.13 | G20: 52762.98 | H20: 51039.15 | I20: 50344.07 | J20: 50235.15 | K20: 49222.27 | L20: 50863.3 | M20: 54053.97 | N20: 55454.34 | O20: 57695.81 | P20: 59339.49 | Q20: 58111.29 | R20: 58179.33 | S20: 60474.15 | T20: 62601.06 | U20: 66207.01 | V20: 76111.91 | W20: 85829.9 | X20: 87192.33 | Y20: 85545.11 | Z20: 83022.44 | AA20: 78552.61 | AB20: 74215.24 | AD20: =+AC35 -> 43953037 | BG20: =+#REF!/1000 -> #REF!
C21: Domingo | D21: 5 | E21: 62661.3 | F21: 59039.72 | G21: 55784.77 | H21: 53519.06 | I21: 52157.01 | J21: 51248.11 | K21: 48306.4 | L21: 47926.51 | M21: 48657.66 | N21: 48518.17 | O21: 50459.23 | P21: 53187.82 | Q21: 55334.15 | R21: 56909.81 | S21: 58822.57 | T21: 61840.48 | U21: 64272.76 | V21: 73612.94 | W21: 83504.02 | X21: 86579.69 | Y21: 87748.77 | Z21: 86794.2 | AA21: 82076.38 | AB21: 74959.03 | AD21: =+AC39 -> 43863427 | BG21: =(+#REF!)/1000 -> #REF!
C22: Festivo | D22: 1 | E22: 63107.01 | F22: 59344.1 | G22: 56037.5 | H22: 54192.76 | I22: 52420.23 | J22: 51391.13 | K22: 48359.12 | L22: 47781.75 | M22: 48555.92 | N22: 48409.17 | O22: 49721.1 | P22: 52119.67 | Q22: 54172.28 | R22: 55694.94 | S22: 57594.82 | T22: 60694.55 | U22: 63322.36 | V22: 72826.21 | W22: 82471 | X22: 85466.62 | Y22: 86576.27 | Z22: 85745.04 | AA22: 81031.72 | AB22: 73908.58 | AD22: =+AC43 -> 41663131 | BG22: =(+#REF!)/1000 -> #REF!
B23: 47574 | C23: Ordinario | D23: 20 | E23: 55086.6 | F23: 51743.42 | G23: 49078.31 | H23: 47527.98 | I23: 47283.82 | J23: 47966.79 | K23: 47544.85 | L23: 50338.81 | M23: 53876.74 | N23: 54508.1 | O23: 56366.26 | P23: 59000.89 | Q23: 55932.94 | R23: 59514.62 | S23: 65580.3 | T23: 67373.78 | U23: 68842.89 | V23: 77845 | W23: 83071.35 | X23: 83289.35 | Y23: 81559.93 | Z23: 78230.28 | AA23: 72737.7 | AB23: 66272.59 | AC23: =SUM(E23:AB23)*D23+SUM(E24:AB24)*D24+SUM(E25:AB25)*D25+SUM(E26:AB26)*D26 -> 42393441 | AD23: =+AC47 -> 41935169 | BG23: =(+#REF!)/1000 -> #REF!
B24: Feb | C24: Sábado | D24: 4 | E24: 52522.15 | F24: 49030.06 | G24: 46093.01 | H24: 44226.66 | I24: 43375.36 | J24: 43392.38 | K24: 41446.17 | L24: 41888.39 | M24: 44763.84 | N24: 44927.79 | O24: 46529.66 | P24: 48220.7 | Q24: 47570.23 | R24: 47698.61 | S24: 49330.27 | T24: 51474.54 | U24: 54908.33 | V24: 66646.15 | W24: 75630.81 | X24: 75436.75 | Y24: 74233.15 | Z24: 71784.9 | AA24: 68392.76 | AB24: 63690.62 | AD24: =+AC51 -> 37031374
B25: Feb | C25: Domingo | D25: 4 | E25: 52804.76 | F25: 50049.99 | G25: 47746.05 | H25: 45698.51 | I25: 45101.14 | J25: 43746.24 | K25: 42166.65 | L25: 41075.91 | M25: 39698.52 | N25: 39543.01 | O25: 41057.44 | P25: 42641.55 | Q25: 44208.52 | R25: 45613.85 | S25: 47258.17 | T25: 49654.41 | U25: 53190.91 | V25: 64750.16 | W25: 72127.26 | X25: 74362.18 | Y25: 75382.29 | Z25: 75705.97 | AA25: 71723.19 | AB25: 65283.98 | AD25: =+AC55 -> 43472186 | BG25: =+AC110/1000 -> 1053667.6
B26: Feb | C26: Festivo | D26: 2 | E26: 52264 | F26: 49514.02 | G26: 47040.64 | H26: 45106.21 | I26: 44445.9 | J26: 43253.03 | K26: 41746.34 | L26: 40811.03 | M26: 39714.85 | N26: 39920.79 | O26: 41121.54 | P26: 42493.4 | Q26: 43814.14 | R26: 45183.07 | S26: 46868.3 | T26: 49505.82 | U26: 53276.23 | V26: 65059.37 | W26: 72432.2 | X26: 74452.5 | Y26: 75373.2 | Z26: 75240 | AA26: 70677.9 | AB26: 64065 | BG26: 1000
B27: 47604 | C27: Ordinario | D27: 22 | E27: 52261.6 | F27: 49434.3 | G27: 46979.59 | H27: 45331 | I27: 45221.21 | J27: 46383.03 | K27: 45992.49 | L27: 48716.16 | M27: 52941.59 | N27: 53853.6 | O27: 56849.19 | P27: 58825.04 | Q27: 55333.68 | R27: 58182.66 | S27: 63798.17 | T27: 65922.67 | U27: 67404.81 | V27: 74844.73 | W27: 80592.78 | X27: 80643.81 | Y27: 78665.58 | Z27: 74832.88 | AA27: 69297.21 | AB27: 63599.41 | AC27: =SUM(E27:AB27)*D27+SUM(E28:AB28)*D28+SUM(E29:AB29)*D29+SUM(E30:AB30)*D30 -> 43697880
C28: Sábado | D28: 4 | E28: 54992.32 | F28: 50400.59 | G28: 47605.93 | H28: 45572.31 | I28: 44829.41 | J28: 44213.65 | K28: 42578.6 | L28: 44426.19 | M28: 48212.96 | N28: 49763.39 | O28: 50975.6 | P28: 52420.29 | Q28: 50676.42 | R28: 50866.34 | S28: 53749.63 | T28: 56111 | U28: 59175.81 | V28: 70936.64 | W28: 79869.09 | X28: 80293.39 | Y28: 78368.37 | Z28: 75419.89 | AA28: 72103.3 | AB28: 67583.92
C29: Domingo | D29: 4 | E29: 55714.76 | F29: 52679.1 | G29: 50061.87 | H29: 47951.2 | I29: 47071.36 | J29: 45323.12 | K29: 42945.4 | L29: 42077.27 | M29: 43687.53 | N29: 44537.75 | O29: 45405.92 | P29: 46593.05 | Q29: 48514.94 | R29: 49989.52 | S29: 51008.82 | T29: 53594.72 | U29: 55588.19 | V29: 67156.5 | W29: 75905.96 | X29: 77099.7 | Y29: 77511.48 | Z29: 75904.07 | AA29: 70952.73 | AB29: 63227.53
C30: Festivo | D30: 1 | E30: 55617.6 | F30: 52581.53 | G30: 49979.21 | H30: 47883.65 | I30: 46790.03 | J30: 44487.01 | K30: 41905.74 | L30: 40641.98 | M30: 41869.98 | N30: 42737.08 | O30: 43384.03 | P30: 44395.23 | Q30: 46829.23 | R30: 47892.66 | S30: 48462.78 | T30: 51109.74 | U30: 53519.97 | V30: 65599.44 | W30: 74505.92 | X30: 75922.73 | Y30: 76586.81 | Z30: 75167.21 | AA30: 70456.07 | AB30: 63005.94
B31: 47635 | C31: Ordinario | D31: 18 | E31: 57418.65 | F31: 54027.85 | G31: 51516.73 | H31: 49095.2 | I31: 48772.48 | J31: 48756.9 | K31: 47749.3 | L31: 50724.1 | M31: 54864.16 | N31: 56507.85 | O31: 59980.18 | P31: 62385.41 | Q31: 59748.27 | R31: 62534.35 | S31: 68208.85 | T31: 69971.69 | U31: 72215.17 | V31: 79034.6 | W31: 85082.12 | X31: 86010.13 | Y31: 83743.59 | Z31: 80193.78 | AA31: 73949.77 | AB31: 67563.04 | AC31: =SUM(E31:AB31)*D31+SUM(E32:AB32)*D32+SUM(E33:AB33)*D33+SUM(E34:AB34)*D34 -> 44636350
B32: Feb | C32: Sábado | D32: 5 | E32: 56324.58 | F32: 53066.04 | G32: 50793.01 | H32: 49314.76 | I32: 48546.32 | J32: 47120.72 | K32: 45790.61 | L32: 48224.66 | M32: 51924 | N32: 53954.23 | O32: 56577.86 | P32: 58774.19 | Q32: 57768.1 | R32: 57053.41 | S32: 59127.75 | T32: 61293.72 | U32: 63267.72 | V32: 73205.68 | W32: 79382.8 | X32: 81083.59 | Y32: 79908.55 | Z32: 76247.23 | AA32: 72426.18 | AB32: 68227.36
B33: Feb | C33: Domingo | D33: 5 | E33: 60116.93 | F33: 56438.69 | G33: 53255.17 | H33: 51250.38 | I33: 50359.25 | J33: 47609.67 | K33: 45114.68 | L33: 43710 | M33: 44348.84 | N33: 45452.99 | O33: 46958.11 | P33: 48663.77 | Q33: 51055.81 | R33: 52304.59 | S33: 54711.56 | T33: 57025.35 | U33: 59393.04 | V33: 68766.33 | W33: 77834.26 | X33: 82063.72 | Y33: 81954.25 | Z33: 80746.2 | AA33: 76934.43 | AB33: 71326.64
B34: Feb | C34: Festivo | D34: 2 | E34: 60828.62 | F34: 57069.77 | G34: 53848.32 | H34: 51770.65 | I34: 50781.11 | J34: 48115.75 | K34: 45513.15 | L34: 43915.11 | M34: 44352.43 | N34: 45197.14 | O34: 46316.82 | P34: 47761.36 | Q34: 50076.12 | R34: 51398.61 | S34: 53952.05 | T34: 56454.9 | U34: 59096.07 | V34: 68604.9 | W34: 77677.64 | X34: 81763.02 | Y34: 81822.46 | Z34: 80785.97 | AA34: 77044.57 | AB34: 71546.81
B35: 47665 | C35: Ordinario | D35: 22 | E35: 55879.92 | F35: 52456.81 | G35: 49646.86 | H35: 47751.64 | I35: 46878.12 | J35: 46991.27 | K35: 45681.88 | L35: 48182.45 | M35: 51904.28 | N35: 53222.03 | O35: 56706.87 | P35: 60149.21 | Q35: 58076.67 | R35: 62266.1 | S35: 69243.73 | T35: 70993.98 | U35: 72382.08 | V35: 77881.1 | W35: 82271.83 | X35: 84397.77 | Y35: 83140.64 | Z35: 79899.23 | AA35: 73795.17 | AB35: 67327.74 | AC35: =SUM(E35:AB35)*D35+SUM(E36:AB36)*D36+SUM(E37:AB37)*D37+SUM(E38:AB38)*D38 -> 43953037
C36: Sábado | D36: 3 | E36: 56366.36 | F36: 52341.95 | G36: 49149.35 | H36: 47632.74 | I36: 46143.32 | J36: 45332.3 | K36: 43623.03 | L36: 43910.55 | M36: 47017.56 | N36: 48932 | O36: 52001.19 | P36: 53469.96 | Q36: 52502.55 | R36: 52551.04 | S36: 54005.32 | T36: 54379.87 | U36: 56421.79 | V36: 67661.63 | W36: 71423.18 | X36: 71997.21 | Y36: 69893.32 | Z36: 67181.24 | AA36: 64125.27 | AB36: 59964.34
C37: Domingo | D37: 4 | E37: 46887.81 | F37: 44507.67 | G37: 41795.46 | H37: 40503.81 | I37: 40088.87 | J37: 38796.66 | K37: 36868.62 | L37: 35150.66 | M37: 34753.61 | N37: 34950.33 | O37: 36843.94 | P37: 38894.55 | Q37: 41390.03 | R37: 43479.63 | S37: 45797.93 | T37: 48888.91 | U37: 51684.56 | V37: 61179.56 | W37: 70317.41 | X37: 74618.7 | Y37: 73416.61 | Z37: 70313.86 | AA37: 64585.63 | AB37: 58844.47
C38: Festivo | D38: 2 | E38: 46906.56 | F38: 44526.57 | G38: 41862.56 | H38: 40527.92 | I38: 40020.61 | J38: 38630.4 | K38: 36629.86 | L38: 34732.87 | M38: 34260.1 | N38: 34400.23 | O38: 36104.59 | P38: 38079.36 | Q38: 40744.02 | R38: 42881.14 | S38: 45344.56 | T38: 48457.21 | U38: 51271.85 | V38: 60843.54 | W38: 69946.75 | X38: 74122.86 | Y38: 73078.75 | Z38: 70238.58 | AA38: 64531.28 | AB38: 58815.76
B39: 47696 | C39: Ordinario | D39: 20 | E39: 55199.49 | F39: 51381.24 | G39: 48541.35 | H39: 46558.62 | I39: 45568.67 | J39: 46158.51 | K39: 45285.03 | L39: 46837.73 | M39: 50397.3 | N39: 51680.64 | O39: 55264.34 | P39: 59656.24 | Q39: 56767.26 | R39: 60147.24 | S39: 67150.01 | T39: 68935.67 | U39: 69696.47 | V39: 76881.67 | W39: 83242.04 | X39: 85060.2 | Y39: 83841.05 | Z39: 80119.98 | AA39: 74010.31 | AB39: 67900.33 | AC39: =SUM(E39:AB39)*D39+SUM(E40:AB40)*D40+SUM(E41:AB41)*D41+SUM(E42:AB42)*D42 -> 43863427
B40: Feb | C40: Sábado | D40: 5 | E40: 54617.02 | F40: 51399.12 | G40: 48896.06 | H40: 46910.15 | I40: 44741.69 | J40: 43459.32 | K40: 41984.96 | L40: 42344.53 | M40: 44631.1 | N40: 46450.71 | O40: 48789.09 | P40: 48736.61 | Q40: 47812.77 | R40: 48453.53 | S40: 51781.3 | T40: 54532.89 | U40: 56453.49 | V40: 67675.75 | W40: 76822.43 | X40: 76934.64 | Y40: 74305.22 | Z40: 71781.88 | AA40: 67636.12 | AB40: 63202.51
B41: Feb | C41: Domingo | D41: 4 | E41: 52686.3 | F41: 50532.27 | G41: 47337.29 | H41: 45743.46 | I41: 44631.97 | J41: 43763.35 | K41: 41650.61 | L41: 40019.55 | M41: 39674.01 | N41: 39978.71 | O41: 41550.01 | P41: 43398.2 | Q41: 44852.68 | R41: 46407.13 | S41: 48653.62 | T41: 51050.65 | U41: 53730.12 | V41: 64737.1 | W41: 74889.72 | X41: 79234.21 | Y41: 79879.63 | Z41: 78342.76 | AA41: 73133.81 | AB41: 66468.58
B42: Feb | C42: Festivo | D42: 2 | E42: 53520.48 | F42: 51014.12 | G42: 47807.09 | H42: 46127.71 | I42: 44963.98 | J42: 44043.67 | K42: 41765.83 | L42: 39989.56 | M42: 39426.25 | N42: 39360.66 | O42: 40928.52 | P42: 42592.6 | Q42: 44093.22 | R42: 45610.37 | S42: 47828.28 | T42: 50202.18 | U42: 52880.23 | V42: 64195.74 | W42: 74381.54 | X42: 78310.05 | Y42: 78877.93 | Z42: 77390.23 | AA42: 72225.45 | AB42: 65790.18
B43: 47727 | C43: Ordinario | D43: 21 | E43: 54523.92 | F43: 50887 | G43: 48048.98 | H43: 45758.98 | I43: 44619.41 | J43: 45182.04 | K43: 43863.16 | L43: 45779.77 | M43: 50269.38 | N43: 51800.32 | O43: 54404.44 | P43: 58232.47 | Q43: 56175.25 | R43: 59039.93 | S43: 65331.82 | T43: 67237.96 | U43: 68365.41 | V43: 76242.18 | W43: 82222.59 | X43: 81854.4 | Y43: 80521.13 | Z43: 76726.83 | AA43: 70357.58 | AB43: 64496.29 | AC43: =SUM(E43:AB43)*D43+SUM(E44:AB44)*D44+SUM(E45:AB45)*D45+SUM(E46:AB46)*D46 -> 41663131
C44: Sábado | D44: 4 | E44: 48875.67 | F44: 45795.42 | G44: 43298.14 | H44: 41489.2 | I44: 40602.99 | J44: 39822.15 | K44: 38798.68 | L44: 39925.85 | M44: 43174.28 | N44: 43613.5 | O44: 46774.47 | P44: 47924.35 | Q44: 48245.21 | R44: 48297.6 | S44: 50707.77 | T44: 52337.94 | U44: 54352.64 | V44: 68038.56 | W44: 77287.84 | X44: 76814.22 | Y44: 75364.55 | Z44: 73264.39 | AA44: 71336.03 | AB44: 66695.2
...

Sheet Cantidades P3_(2032-2041)
B4: 9.7. TABLAS CANTIDADES DE ENERGÍA SOLICITADA PRODUCTO 3 AÑO 2032-2041 (kWh)
B5: ELETRIFICADORA DE SANTANDER S.A E.S.P.
B6: SOLICITUD PÚBLICA DE OFERTAS CP-ESSC2026-002
B7: PAGUELO CONTRATADO
BE8: 1000
B10: Mes | C10: Tipo Día | D10: Días | E10: H1 | F10: H2 | G10: H3 | H10: H4 | I10: H5 | J10: H6 | K10: H7 | L10: H8 | M10: H9 | N10: H10 | O10: H11 | P10: H12 | Q10: H13 | R10: H14 | S10: H15 | T10: H16 | U10: H17 | V10: H18 | W10: H19 | X10: H20 | Y10: H21 | Z10: H22 | AA10: H23 | AB10: H24 | AC10: TOTAL MES kWh | AF10: PERIODO | AG10: H1 | AH10: H2 | AI10: H3 | AJ10: H4 | AK10: H5 | AL10: H6 | AM10: H7 | AN10: H8 | AO10: H9 | AP10: H10 | AQ10: H11 | AR10: H12 | AS10: H13 | AT10: H14 | AU10: H15 | AV10: H16 | AW10: H17 | AX10: H18 | AY10: H19 | AZ10: H20 | BA10: H21 | BB10: H22 | BC10: H23 | BD10: H24 | BE10: TOTAL DIA | BF10: TOTAL AÑO | BH10: Año 2024 | BI10: =(+#REF!)/1000 -> #REF! | BJ10: MWh-año
B11: 48214 | C11: Ordinario | D11: 20 | E11: 31631.52 | F11: 29809.9 | G11: 28398.83 | H11: 27357.81 | I11: 27094.98 | J11: 27920.4 | K11: 27344.94 | L11: 29070.53 | M11: 31475.56 | N11: 32667.63 | O11: 34357.88 | P11: 36009.59 | Q11: 34915.59 | R11: 36440.49 | S11: 38788.39 | T11: 39432.51 | U11: 39695.84 | V11: 42847.01 | W11: 46288.03 | X11: 46484.96 | Y11: 45450.44 | Z11: 43511.9 | AA11: 40462.54 | AB11: 37282.54 | AC11: =SUM(E11:AB11)*D11+SUM(E12:AB12)*D12+SUM(E13:AB13)*D13+SUM(E14:AB14)*D14 -> 25535865
C12: Sábado | D12: 5 | E12: 31216.31 | F12: 29569.88 | G12: 28201.02 | H12: 27151.5 | I12: 26767 | J12: 26823.03 | K12: 25724.23 | L12: 26799.53 | M12: 28970.42 | N12: 30637.54 | O12: 31999.71 | P12: 32760.01 | Q12: 32492.35 | R12: 31704.25 | S12: 32279.52 | T12: 32945 | U12: 33683.77 | V12: 38815.27 | W12: 43574.5 | X12: 43793.08 | Y12: 42607.62 | Z12: 40984.55 | AA12: 38856.03 | AB12: 36393.15
