Workbook

Sheet 2026
A1: CANTIDADES DE ENERGÍA A SUMINISTRAR
A3: PRODUCTO 1:
A5: AÑO | B5: MES | C5: Energía solicitada kWh | D5: % Ofertado | E5: Energía Ofertada kWh | F5: Precio energía ofertada ($/kWh)
A6: =+Curva2026!A4 -> 2026 | B6: {=_xlfn._xlws.SORT(_xlfn.UNIQUE(Curva2026!B4:B49,FALSE,TRUE))} -> 1 | C6: =_xlfn.XLOOKUP(B6,Curva2026!$B$4:$B$49,Curva2026!$AE$4:$AE$49,"88",0) -> 7569582 | E6: =C6*$D$6 -> 0
B7: 2 | C7: =_xlfn.XLOOKUP(B7,Curva2026!$B$4:$B$49,Curva2026!$AE$4:$AE$49,"88",0) -> 8595696 | E7: =C7*$D$6 -> 0
B8: 3 | C8: =_xlfn.XLOOKUP(B8,Curva2026!$B$4:$B$49,Curva2026!$AE$4:$AE$49,"88",0) -> 8612292 | E8: =C8*$D$6 -> 0
B9: 4 | C9: =_xlfn.XLOOKUP(B9,Curva2026!$B$4:$B$49,Curva2026!$AE$4:$AE$49,"88",0) -> 5034448 | E9: =C9*$D$6 -> 0
B10: 5 | C10: =_xlfn.XLOOKUP(B10,Curva2026!$B$4:$B$49,Curva2026!$AE$4:$AE$49,"88",0) -> 0 | E10: =C10*$D$6 -> 0
B11: 6 | C11: =_xlfn.XLOOKUP(B11,Curva2026!$B$4:$B$49,Curva2026!$AE$4:$AE$49,"88",0) -> 0 | E11: =C11*$D$6 -> 0
B12: 7 | C12: =_xlfn.XLOOKUP(B12,Curva2026!$B$4:$B$49,Curva2026!$AE$4:$AE$49,"88",0) -> 0 | E12: =C12*$D$6 -> 0
B13: 8 | C13: =_xlfn.XLOOKUP(B13,Curva2026!$B$4:$B$49,Curva2026!$AE$4:$AE$49,"88",0) -> 0 | E13: =C13*$D$6 -> 0
B14: 9 | C14: =_xlfn.XLOOKUP(B14,Curva2026!$B$4:$B$49,Curva2026!$AE$4:$AE$49,"88",0) -> 0 | E14: =C14*$D$6 -> 0
B15: 10 | C15: =_xlfn.XLOOKUP(B15,Curva2026!$B$4:$B$49,Curva2026!$AE$4:$AE$49,"88",0) -> 2612804 | E15: =C15*$D$6 -> 0
B16: 11 | C16: =_xlfn.XLOOKUP(B16,Curva2026!$B$4:$B$49,Curva2026!$AE$4:$AE$49,"88",0) -> 4423376 | E16: =C16*$D$6 -> 0
B17: 12 | C17: =_xlfn.XLOOKUP(B17,Curva2026!$B$4:$B$49,Curva2026!$AE$4:$AE$49,"88",0) -> 8951506 | E17: =C17*$D$6 -> 0
B18: TOTAL | C18: =SUM(C6:C17) -> 45799704 | E18: =SUM(E6:E17) -> 0
A20: Notas:
B21: 1. La Energía Ofertada dada en el Anexo 7.1
B22: 2. Modalidad: pague lo contratado.
B23: 3. Precio ofertado en $kWh en pesos de Agosto 2025.
B24: 4. El % y el precio debe ser el mismo para todos los meses del año.

Sheet Curva2026
E1: NECESIDADES DE COMPRA DE ENERGIA - POR AÑO / MES / TIPO DE DIA / HORA
A3: AÑO | B3: MES | C3: TD | D3: CD | E3: H01 | F3: H02 | G3: H03 | H3: H04 | I3: H05 | J3: H06 | K3: H07 | L3: H08 | M3: H09 | N3: H10 | O3: H11 | P3: H12 | Q3: H13 | R3: H14 | S3: H15 | T3: H16 | U3: H17 | V3: H18 | W3: H19 | X3: H20 | Y3: H21 | Z3: H22 | AA3: H23 | AB3: H24 | AC3: TOTAL DIARIO | AD3: TOTAL DIAS MES | AE3: TOTAL MES
A4: 2026 | B4: 1 | C4: OR | D4: 20 | E4: 6593 | F4: 4528 | G4: 2952 | H4: 1846 | I4: 1297 | J4: 924 | K4: 500 | L4: 978 | M4: 6172 | N4: 9494 | O4: 12170 | P4: 13954 | Q4: 11545 | R4: 13935 | S4: 18092 | T4: 18460 | U4: 16968 | V4: 22467 | W4: 26900 | X4: 27768 | Y4: 26397 | Z4: 24188 | AA4: 20588 | AB4: 16809 | AC4: =SUM(E4:AB4) -> 305525 | AD4: =AC4*D4 -> 6110500 | AE4: =SUM(AD4:AD7) -> 7569582
C5: SA | D5: 5 | E5: 500 | F5: 500 | G5: 500 | H5: 500 | I5: 500 | J5: 500 | K5: 500 | L5: 500 | M5: 500 | N5: 500 | O5: 500 | P5: 500 | Q5: 500 | R5: 500 | S5: 500 | T5: 500 | U5: 500 | V5: 5488 | W5: 10367 | X5: 11114 | Y5: 9992 | Z5: 8416 | AA5: 5980 | AB5: 3771 | AC5: =SUM(E5:AB5) -> 63628 | AD5: =AC5*D5 -> 318140
C6: DO | D6: 4 | E6: 7456 | F6: 5313 | G6: 3694 | H6: 2530 | I6: 1869 | J6: 1126 | K6: 500 | L6: 500 | M6: 1004 | N6: 3059 | O6: 5003 | P6: 6448 | Q6: 6799 | R6: 6715 | S6: 6441 | T6: 6640 | U6: 6953 | V6: 15284 | W6: 22550 | X6: 24746 | Y6: 24417 | Z6: 22261 | AA6: 19216 | AB6: 15781 | AC6: =SUM(E6:AB6) -> 216305 | AD6: =AC6*D6 -> 865220
C7: FE | D7: 2 | E7: 1882 | F7: 699 | G7: 500 | H7: 500 | I7: 500 | J7: 500 | K7: 500 | L7: 500 | M7: 500 | N7: 500 | O7: 1650 | P7: 2978 | Q7: 3024 | R7: 2474 | S7: 2383 | T7: 2342 | U7: 2260 | V7: 10927 | W7: 18230 | X7: 19809 | Y7: 19467 | Z7: 17754 | AA7: 15284 | AB7: 12698 | AC7: =SUM(E7:AB7) -> 137861 | AD7: =AC7*D7 -> 275722
B8: 2 | C8: OR | D8: 20 | E8: 7767 | F8: 5785 | G8: 4177 | H8: 2957 | I8: 2351 | J8: 3376 | K8: 807 | L8: 3019 | M8: 7877 | N8: 10915 | O8: 13309 | P8: 14918 | Q8: 11550 | R8: 14360 | S8: 19381 | T8: 20127 | U8: 18683 | V8: 23937 | W8: 27943 | X8: 29341 | Y8: 28524 | Z8: 26123 | AA8: 21982 | AB8: 18042 | AC8: =SUM(E8:AB8) -> 337251 | AD8: =AC8*D8 -> 6745020 | AE8: =SUM(AD8:AD10) -> 8595696
C9: SA | D9: 4 | E9: 6730 | F9: 4828 | G9: 3391 | H9: 2216 | I9: 1556 | J9: 1083 | K9: 500 | L9: 500 | M9: 4855 | N9: 8349 | O9: 10793 | P9: 12116 | Q9: 11069 | R9: 10506 | S9: 11419 | T9: 11347 | U9: 10558 | V9: 17552 | W9: 23404 | X9: 24707 | Y9: 23627 | Z9: 21121 | AA9: 18235 | AB9: 15338 | AC9: =SUM(E9:AB9) -> 255800 | AD9: =AC9*D9 -> 1023200
C10: DO | D10: 4 | E10: 6072 | F10: 4346 | G10: 2868 | H10: 1799 | I10: 1117 | J10: 500 | K10: 500 | L10: 500 | M10: 500 | N10: 1900 | O10: 3924 | P10: 5818 | Q10: 6192 | R10: 6364 | S10: 6934 | T10: 7478 | U10: 7144 | V10: 15166 | W10: 21649 | X10: 24384 | Y10: 24723 | Z10: 22548 | AA10: 19059 | AB10: 15384 | AC10: =SUM(E10:AB10) -> 206869 | AD10: =AC10*D10 -> 827476
B11: 3 | C11: OR | D11: 21 | E11: 5421 | F11: 3563 | G11: 2279 | H11: 1182 | I11: 674 | J11: 1083 | K11: 500 | L11: 1165 | M11: 5457 | N11: 8236 | O11: 10559 | P11: 12151 | Q11: 9029 | R11: 11283 | S11: 15219 | T11: 15843 | U11: 14423 | V11: 19607 | W11: 23718 | X11: 24831 | Y11: 23936 | Z11: 21633 | AA11: 17967 | AB11: 14755 | AC11: =SUM(E11:AB11) -> 264514 | AD11: =AC11*D11 -> 5554794 | AE11: =SUM(AD11:AD14) -> 8612292
C12: SA | D12: 4 | E12: 13539 | F12: 11570 | G12: 10016 | H12: 8708 | I12: 7796 | J12: 7146 | K12: 4475 | L12: 6493 | M12: 11646 | N12: 15249 | O12: 18131 | P12: 19614 | Q12: 17829 | R12: 17020 | S12: 17417 | T12: 17803 | U12: 16584 | V12: 23650 | W12: 30522 | X12: 31555 | Y12: 30190 | Z12: 28096 | AA12: 25068 | AB12: 22339 | AC12: =SUM(E12:AB12) -> 412456 | AD12: =AC12*D12 -> 1649824
C13: DO | D13: 5 | E13: 1832 | F13: 410 | G13: 500 | H13: 500 | I13: 500 | J13: 500 | K13: 500 | L13: 500 | M13: 500 | N13: 500 | O13: 500 | P13: 863 | Q13: 1539 | R13: 1468 | S13: 2265 | T13: 1640 | U13: 873 | V13: 9660 | W13: 15453 | X13: 17312 | Y13: 17316 | Z13: 15737 | AA13: 13237 | AB13: 10004 | AC13: =SUM(E13:AB13) -> 114109 | AD13: =AC13*D13 -> 570545
C14: FE | D14: 1 | E14: 31343 | F14: 28232 | G14: 26088 | H14: 24521 | I14: 23705 | J14: 21853 | K14: 18701 | L14: 20712 | M14: 24454 | N14: 27756 | O14: 31073 | P14: 34664 | Q14: 35667 | R14: 35981 | S14: 35927 | T14: 35844 | U14: 34955 | V14: 42361 | W14: 52136 | X14: 55349 | Y14: 55073 | Z14: 52175 | AA14: 47132 | AB14: 41427 | AC14: =SUM(E14:AB14) -> 837129 | AD14: =AC14*D14 -> 837129
B15: 4 | C15: OR | D15: 20 | E15: 2608 | F15: 1574 | G15: 837 | H15: 500 | I15: 500 | J15: 500 | K15: 500 | L15: 723 | M15: 3626 | N15: 5807 | O15: 7350 | P15: 7774 | Q15: 6177 | R15: 7796 | S15: 10224 | T15: 10211 | U15: 8764 | V15: 12871 | W15: 15612 | X15: 16011 | Y15: 15051 | Z15: 13362 | AA15: 10977 | AB15: 8550 | AC15: =SUM(E15:AB15) -> 167905 | AD15: =AC15*D15 -> 3358100 | AE15: =SUM(AD15:AD18) -> 5034448
C16: SA | D16: 4 | E16: 6678 | F16: 5441 | G16: 4479 | H16: 3724 | I16: 3329 | J16: 2472 | K16: 1399 | L16: 3156 | M16: 5952 | N16: 7795 | O16: 9467 | P16: 10745 | Q16: 10259 | R16: 10082 | S16: 10767 | T16: 10903 | U16: 10293 | V16: 15109 | W16: 19508 | X16: 20001 | Y16: 19012 | Z16: 17517 | AA16: 15347 | AB16: 13388 | AC16: =SUM(E16:AB16) -> 236823 | AD16: =AC16*D16 -> 947292
C17: DO | D17: 4 | E17: 5556 | F17: 4360 | G17: 3390 | H17: 2657 | I17: 2133 | J17: 1117 | K17: 500 | L17: 339 | M17: 1997 | N17: 3204 | O17: 4222 | P17: 5469 | Q17: 5996 | R17: 6234 | S17: 6748 | T17: 7085 | U17: 6759 | V17: 11754 | W17: 16241 | X17: 17311 | Y17: 17150 | Z17: 15553 | AA17: 12979 | AB17: 10633 | AC17: =SUM(E17:AB17) -> 169387 | AD17: =AC17*D17 -> 677548
C18: FE | D18: 2 | E18: 500 | F18: 500 | G18: 500 | H18: 500 | I18: 500 | J18: 500 | K18: 500 | L18: 500 | M18: 500 | N18: 500 | O18: 500 | P18: 500 | Q18: 500 | R18: 500 | S18: 500 | T18: 500 | U18: 500 | V18: 500 | W18: 3135 | X18: 3916 | Y18: 3736 | Z18: 3071 | AA18: 2014 | AB18: 882 | AC18: =SUM(E18:AB18) -> 25754 | AD18: =AC18*D18 -> 51508
B19: 5 | C19: OR | D19: 19 | E19: 0 | F19: 0 | G19: 0 | H19: 0 | I19: 0 | J19: 0 | K19: 0 | L19: 0 | M19: 0 | N19: 0 | O19: 0 | P19: 0 | Q19: 0 | R19: 0 | S19: 0 | T19: 0 | U19: 0 | V19: 0 | W19: 0 | X19: 0 | Y19: 0 | Z19: 0 | AA19: 0 | AB19: 0 | AC19: =SUM(E19:AB19) -> 0 | AD19: =AC19*D19 -> 0 | AE19: =SUM(AD19:AD22) -> 0
C20: SA | D20: 5 | E20: 0 | F20: 0 | G20: 0 | H20: 0 | I20: 0 | J20: 0 | K20: 0 | L20: 0 | M20: 0 | N20: 0 | O20: 0 | P20: 0 | Q20: 0 | R20: 0 | S20: 0 | T20: 0 | U20: 0 | V20: 0 | W20: 0 | X20: 0 | Y20: 0 | Z20: 0 | AA20: 0 | AB20: 0 | AC20: =SUM(E20:AB20) -> 0 | AD20: =AC20*D20 -> 0
C21: DO | D21: 5 | E21: 0 | F21: 0 | G21: 0 | H21: 0 | I21: 0 | J21: 0 | K21: 0 | L21: 0 | M21: 0 | N21: 0 | O21: 0 | P21: 0 | Q21: 0 | R21: 0 | S21: 0 | T21: 0 | U21: 0 | V21: 0 | W21: 0 | X21: 0 | Y21: 0 | Z21: 0 | AA21: 0 | AB21: 0 | AC21: =SUM(E21:AB21) -> 0 | AD21: =AC21*D21 -> 0
C22: FE | D22: 2 | E22: 0 | F22: 0 | G22: 0 | H22: 0 | I22: 0 | J22: 0 | K22: 0 | L22: 0 | M22: 0 | N22: 0 | O22: 0 | P22: 0 | Q22: 0 | R22: 0 | S22: 0 | T22: 0 | U22: 0 | V22: 0 | W22: 0 | X22: 0 | Y22: 0 | Z22: 0 | AA22: 0 | AB22: 0 | AC22: =SUM(E22:AB22) -> 0 | AD22: =AC22*D22 -> 0
B23: 6 | C23: OR | D23: 19 | E23: 0 | F23: 0 | G23: 0 | H23: 0 | I23: 0 | J23: 0 | K23: 0 | L23: 0 | M23: 0 | N23: 0 | O23: 0 | P23: 0 | Q23: 0 | R23: 0 | S23: 0 | T23: 0 | U23: 0 | V23: 0 | W23: 0 | X23: 0 | Y23: 0 | Z23: 0 | AA23: 0 | AB23: 0 | AC23: =SUM(E23:AB23) -> 0 | AD23: =AC23*D23 -> 0 | AE23: =SUM(AD23:AD26) -> 0
C24: SA | D24: 4 | E24: 0 | F24: 0 | G24: 0 | H24: 0 | I24: 0 | J24: 0 | K24: 0 | L24: 0 | M24: 0 | N24: 0 | O24: 0 | P24: 0 | Q24: 0 | R24: 0 | S24: 0 | T24: 0 | U24: 0 | V24: 0 | W24: 0 | X24: 0 | Y24: 0 | Z24: 0 | AA24: 0 | AB24: 0 | AC24: =SUM(E24:AB24) -> 0 | AD24: =AC24*D24 -> 0
C25: DO | D25: 4 | E25: 0 | F25: 0 | G25: 0 | H25: 0 | I25: 0 | J25: 0 | K25: 0 | L25: 0 | M25: 0 | N25: 0 | O25: 0 | P25: 0 | Q25: 0 | R25: 0 | S25: 0 | T25: 0 | U25: 0 | V25: 0 | W25: 0 | X25: 0 | Y25: 0 | Z25: 0 | AA25: 0 | AB25: 0 | AC25: =SUM(E25:AB25) -> 0 | AD25: =AC25*D25 -> 0
C26: FE | D26: 3 | E26: 0 | F26: 0 | G26: 0 | H26: 0 | I26: 0 | J26: 0 | K26: 0 | L26: 0 | M26: 0 | N26: 0 | O26: 0 | P26: 0 | Q26: 0 | R26: 0 | S26: 0 | T26: 0 | U26: 0 | V26: 0 | W26: 0 | X26: 0 | Y26: 0 | Z26: 0 | AA26: 0 | AB26: 0 | AC26: =SUM(E26:AB26) -> 0 | AD26: =AC26*D26 -> 0
B27: 7 | C27: OR | D27: 22 | E27: 0 | F27: 0 | G27: 0 | H27: 0 | I27: 0 | J27: 0 | K27: 0 | L27: 0 | M27: 0 | N27: 0 | O27: 0 | P27: 0 | Q27: 0 | R27: 0 | S27: 0 | T27: 0 | U27: 0 | V27: 0 | W27: 0 | X27: 0 | Y27: 0 | Z27: 0 | AA27: 0 | AB27: 0 | AC27: =SUM(E27:AB27) -> 0 | AD27: =AC27*D27 -> 0 | AE27: =SUM(AD27:AD30) -> 0
C28: SA | D28: 4 | E28: 0 | F28: 0 | G28: 0 | H28: 0 | I28: 0 | J28: 0 | K28: 0 | L28: 0 | M28: 0 | N28: 0 | O28: 0 | P28: 0 | Q28: 0 | R28: 0 | S28: 0 | T28: 0 | U28: 0 | V28: 0 | W28: 0 | X28: 0 | Y28: 0 | Z28: 0 | AA28: 0 | AB28: 0 | AC28: =SUM(E28:AB28) -> 0 | AD28: =AC28*D28 -> 0
C29: DO | D29: 4 | E29: 0 | F29: 0 | G29: 0 | H29: 0 | I29: 0 | J29: 0 | K29: 0 | L29: 0 | M29: 0 | N29: 0 | O29: 0 | P29: 0 | Q29: 0 | R29: 0 | S29: 0 | T29: 0 | U29: 0 | V29: 0 | W29: 0 | X29: 0 | Y29: 0 | Z29: 0 | AA29: 0 | AB29: 0 | AC29: =SUM(E29:AB29) -> 0 | AD29: =AC29*D29 -> 0
C30: FE | D30: 1 | E30: 0 | F30: 0 | G30: 0 | H30: 0 | I30: 0 | J30: 0 | K30: 0 | L30: 0 | M30: 0 | N30: 0 | O30: 0 | P30: 0 | Q30: 0 | R30: 0 | S30: 0 | T30: 0 | U30: 0 | V30: 0 | W30: 0 | X30: 0 | Y30: 0 | Z30: 0 | AA30: 0 | AB30: 0 | AC30: =SUM(E30:AB30) -> 0 | AD30: =AC30*D30 -> 0
B31: 8 | C31: OR | D31: 19 | E31: 0 | F31: 0 | G31: 0 | H31: 0 | I31: 0 | J31: 0 | K31: 0 | L31: 0 | M31: 0 | N31: 0 | O31: 0 | P31: 0 | Q31: 0 | R31: 0 | S31: 0 | T31: 0 | U31: 0 | V31: 0 | W31: 0 | X31: 0 | Y31: 0 | Z31: 0 | AA31: 0 | AB31: 0 | AC31: =SUM(E31:AB31) -> 0 | AD31: =AC31*D31 -> 0 | AE31: =SUM(AD31:AD34) -> 0
C32: SA | D32: 5 | E32: 0 | F32: 0 | G32: 0 | H32: 0 | I32: 0 | J32: 0 | K32: 0 | L32: 0 | M32: 0 | N32: 0 | O32: 0 | P32: 0 | Q32: 0 | R32: 0 | S32: 0 | T32: 0 | U32: 0 | V32: 0 | W32: 0 | X32: 0 | Y32: 0 | Z32: 0 | AA32: 0 | AB32: 0 | AC32: =SUM(E32:AB32) -> 0 | AD32: =AC32*D32 -> 0
C33: DO | D33: 5 | E33: 0 | F33: 0 | G33: 0 | H33: 0 | I33: 0 | J33: 0 | K33: 0 | L33: 0 | M33: 0 | N33: 0 | O33: 0 | P33: 0 | Q33: 0 | R33: 0 | S33: 0 | T33: 0 | U33: 0 | V33: 0 | W33: 0 | X33: 0 | Y33: 0 | Z33: 0 | AA33: 0 | AB33: 0 | AC33: =SUM(E33:AB33) -> 0 | AD33: =AC33*D33 -> 0
C34: FE | D34: 2 | E34: 0 | F34: 0 | G34: 0 | H34: 0 | I34: 0 | J34: 0 | K34: 0 | L34: 0 | M34: 0 | N34: 0 | O34: 0 | P34: 0 | Q34: 0 | R34: 0 | S34: 0 | T34: 0 | U34: 0 | V34: 0 | W34: 0 | X34: 0 | Y34: 0 | Z34: 0 | AA34: 0 | AB34: 0 | AC34: =SUM(E34:AB34) -> 0 | AD34: =AC34*D34 -> 0
B35: 9 | C35: OR | D35: 22 | E35: 0 | F35: 0 | G35: 0 | H35: 0 | I35: 0 | J35: 0 | K35: 0 | L35: 0 | M35: 0 | N35: 0 | O35: 0 | P35: 0 | Q35: 0 | R35: 0 | S35: 0 | T35: 0 | U35: 0 | V35: 0 | W35: 0 | X35: 0 | Y35: 0 | Z35: 0 | AA35: 0 | AB35: 0 | AC35: =SUM(E35:AB35) -> 0 | AD35: =AC35*D35 -> 0 | AE35: =SUM(AD35:AD37) -> 0
C36: SA | D36: 4 | E36: 0 | F36: 0 | G36: 0 | H36: 0 | I36: 0 | J36: 0 | K36: 0 | L36: 0 | M36: 0 | N36: 0 | O36: 0 | P36: 0 | Q36: 0 | R36: 0 | S36: 0 | T36: 0 | U36: 0 | V36: 0 | W36: 0 | X36: 0 | Y36: 0 | Z36: 0 | AA36: 0 | AB36: 0 | AC36: =SUM(E36:AB36) -> 0 | AD36: =AC36*D36 -> 0
C37: DO | D37: 4 | E37: 0 | F37: 0 | G37: 0 | H37: 0 | I37: 0 | J37: 0 | K37: 0 | L37: 0 | M37: 0 | N37: 0 | O37: 0 | P37: 0 | Q37: 0 | R37: 0 | S37: 0 | T37: 0 | U37: 0 | V37: 0 | W37: 0 | X37: 0 | Y37: 0 | Z37: 0 | AA37: 0 | AB37: 0 | AC37: =SUM(E37:AB37) -> 0 | AD37: =AC37*D37 -> 0
B38: 10 | C38: OR | D38: 21 | E38: 500 | F38: 500 | G38: 500 | H38: 500 | I38: 500 | J38: 500 | K38: 500 | L38: 500 | M38: 443 | N38: 2117 | O38: 3546 | P38: 4354 | Q38: 2967 | R38: 4004 | S38: 6086 | T38: 6057 | U38: 5030 | V38: 8561 | W38: 10314 | X38: 10052 | Y38: 9384 | Z38: 8195 | AA38: 6167 | AB38: 4457 | AC38: =SUM(E38:AB38) -> 95734 | AD38: =AC38*D38 -> 2010414 | AE38: =SUM(AD38:AD41) -> 2612804
C39: SA | D39: 5 | E39: 500 | F39: 500 | G39: 500 | H39: 500 | I39: 500 | J39: 500 | K39: 500 | L39: 500 | M39: 500 | N39: 500 | O39: 500 | P39: 500 | Q39: 500 | R39: 500 | S39: 500 | T39: 500 | U39: 500 | V39: 2234 | W39: 4384 | X39: 4137 | Y39: 3489 | Z39: 2680 | AA39: 1527 | AB39: 401 | AC39: =SUM(E39:AB39) -> 27352 | AD39: =AC39*D39 -> 136760
C40: DO | D40: 4 | E40: 4076 | F40: 2852 | G40: 1743 | H40: 937 | I40: 440 | J40: 500 | K40: 500 | L40: 500 | M40: 500 | N40: 1154 | O40: 1951 | P40: 2903 | Q40: 3266 | R40: 2964 | S40: 3221 | T40: 3680 | U40: 3464 | V40: 8625 | W40: 12283 | X40: 12226 | Y40: 11713 | Z40: 10697 | AA40: 8960 | AB40: 7309 | AC40: =SUM(E40:AB40) -> 106464 | AD40: =AC40*D40 -> 425856
C41: FE | D41: 1 | E41: 500 | F41: 500 | G41: 500 | H41: 500 | I41: 500 | J41: 500 | K41: 500 | L41: 500 | M41: 500 | N41: 500 | O41: 500 | P41: 798 | Q41: 972 | R41: 600 | S41: 286 | T41: 500 | U41: 500 | V41: 4758 | W41: 6286 | X41: 6608 | Y41: 5448 | Z41: 3924 | AA41: 2442 | AB41: 1152 | AC41: =SUM(E41:AB41) -> 39774 | AD41: =AC41*D41 -> 39774
...

Sheet 2027
A1: CANTIDADES DE ENERGÍA A SUMINISTRAR
A3: PRODUCTO 1:
A5: AÑO | B5: MES | C5: Energía solicitada kWh | D5: % Ofertado | E5: Energía Ofertada kWh | F5: Precio energía ofertada ($/kWh)
A6: =+Curva2027!A4 -> 2027 | B6: {=_xlfn._xlws.SORT(_xlfn.UNIQUE(Curva2027!B4:B49,FALSE,TRUE))} -> 1 | C6: =_xlfn.XLOOKUP(B6,Curva2027!$B$4:$B$49,Curva2027!$AE$4:$AE$49,"88",0) -> 8254332 | E6: =C6*$D$6 -> 0
B7: 2 | C7: =_xlfn.XLOOKUP(B7,Curva2027!$B$4:$B$49,Curva2027!$AE$4:$AE$49,"88",0) -> 8114548 | E7: =C7*$D$6 -> 0
B8: 3 | C8: =_xlfn.XLOOKUP(B8,Curva2027!$B$4:$B$49,Curva2027!$AE$4:$AE$49,"88",0) -> 9933912 | E8: =C8*$D$6 -> 0
B9: 4 | C9: =_xlfn.XLOOKUP(B9,Curva2027!$B$4:$B$49,Curva2027!$AE$4:$AE$49,"88",0) -> 4126772 | E9: =C9*$D$6 -> 0
B10: 5 | C10: =_xlfn.XLOOKUP(B10,Curva2027!$B$4:$B$49,Curva2027!$AE$4:$AE$49,"88",0) -> 0 | E10: =C10*$D$6 -> 0
B11: 6 | C11: =_xlfn.XLOOKUP(B11,Curva2027!$B$4:$B$49,Curva2027!$AE$4:$AE$49,"88",0) -> 0 | E11: =C11*$D$6 -> 0
B12: 7 | C12: =_xlfn.XLOOKUP(B12,Curva2027!$B$4:$B$49,Curva2027!$AE$4:$AE$49,"88",0) -> 0 | E12: =C12*$D$6 -> 0
B13: 8 | C13: =_xlfn.XLOOKUP(B13,Curva2027!$B$4:$B$49,Curva2027!$AE$4:$AE$49,"88",0) -> 0 | E13: =C13*$D$6 -> 0
B14: 9 | C14: =_xlfn.XLOOKUP(B14,Curva2027!$B$4:$B$49,Curva2027!$AE$4:$AE$49,"88",0) -> 0 | E14: =C14*$D$6 -> 0
B15: 10 | C15: =_xlfn.XLOOKUP(B15,Curva2027!$B$4:$B$49,Curva2027!$AE$4:$AE$49,"88",0) -> 4415947 | E15: =C15*$D$6 -> 0
B16: 11 | C16: =_xlfn.XLOOKUP(B16,Curva2027!$B$4:$B$49,Curva2027!$AE$4:$AE$49,"88",0) -> 5051510 | E16: =C16*$D$6 -> 0
B17: 12 | C17: =_xlfn.XLOOKUP(B17,Curva2027!$B$4:$B$49,Curva2027!$AE$4:$AE$49,"88",0) -> 9160476 | E17: =C17*$D$6 -> 0
B18: TOTAL | C18: =SUM(C6:C17) -> 49057497 | E18: =SUM(E6:E17) -> 0 | G18: =+C18+'2026'!C18 -> 94857201
A20: Notas:
B21: 1. La Energía Ofertada dada en el Anexo 7.1
B22: 2. Modalidad: pague lo contratado.
B23: 3. Precio ofertado en $kWh en pesos de Agosto 2025.
B24: 4. El % y el precio debe ser el mismo para todos los meses del año.

Sheet Curva2027
E1: NECESIDADES DE COMPRA DE ENERGIA - POR AÑO / MES / TIPO DE DIA / HORA
A3: AÑO | B3: MES | C3: TD | D3: CD | E3: H01 | F3: H02 | G3: H03 | H3: H04 | I3: H05 | J3: H06 | K3: H07 | L3: H08 | M3: H09 | N3: H10 | O3: H11 | P3: H12 | Q3: H13 | R3: H14 | S3: H15 | T3: H16 | U3: H17 | V3: H18 | W3: H19 | X3: H20 | Y3: H21 | Z3: H22 | AA3: H23 | AB3: H24 | AC3: TOTAL DIARIO | AD3: TOTAL DIAS MES | AE3: TOTAL MES
A4: 2027 | B4: 1 | C4: OR | D4: 19 | E4: 13905 | F4: 12606 | G4: 11552 | H4: 10815 | I4: 10407 | J4: 9966 | K4: 7798 | L4: 9241 | M4: 12181 | N4: 14243 | O4: 15778 | P4: 16860 | Q4: 15785 | R4: 17846 | S4: 20518 | T4: 20726 | U4: 19717 | V4: 21827 | W4: 23876 | X4: 24328 | Y4: 23548 | Z4: 22477 | AA4: 20737 | AB4: 18928 | AC4: =SUM(E4:AB4) -> 395665 | AD4: =AC4*D4 -> 7517635 | AE4: =SUM(AD4:AD7) -> 8254332
C5: SA | D5: 5 | E5: 500 | F5: 500 | G5: 500 | H5: 500 | I5: 500 | J5: 500 | K5: 500 | L5: 500 | M5: 500 | N5: 500 | O5: 500 | P5: 500 | Q5: 500 | R5: 500 | S5: 500 | T5: 500 | U5: 500 | V5: 2895 | W5: 3988 | X5: 3860 | Y5: 3309 | Z5: 3114 | AA5: 2476 | AB5: 1976 | AC5: =SUM(E5:AB5) -> 30118 | AD5: =AC5*D5 -> 150590
C6: DO | D6: 5 | E6: 500 | F6: 500 | G6: 500 | H6: 500 | I6: 500 | J6: 500 | K6: 500 | L6: 500 | M6: 500 | N6: 500 | O6: 500 | P6: 500 | Q6: 500 | R6: 500 | S6: 500 | T6: 500 | U6: 500 | V6: 2929 | W6: 4778 | X6: 5443 | Y6: 5593 | Z6: 5045 | AA6: 4504 | AB6: 3533 | AC6: =SUM(E6:AB6) -> 40325 | AD6: =AC6*D6 -> 201625
C7: FE | D7: 2 | E7: 6575 | F7: 6118 | G7: 5707 | H7: 5316 | I7: 5008 | J7: 4461 | K7: 2617 | L7: 2772 | M7: 4360 | N7: 5672 | O7: 6598 | P7: 7337 | Q7: 7341 | R7: 6900 | S7: 6796 | T7: 6810 | U7: 6970 | V7: 10988 | W7: 14070 | X7: 14739 | Y7: 14993 | Z7: 14351 | AA7: 13430 | AB7: 12312 | AC7: =SUM(E7:AB7) -> 192241 | AD7: =AC7*D7 -> 384482
B8: 2 | C8: OR | D8: 20 | E8: 10352 | F8: 9429 | G8: 8483 | H8: 7653 | I8: 7052 | J8: 7408 | K8: 5946 | L8: 6806 | M8: 9386 | N8: 11055 | O8: 12072 | P8: 12881 | Q8: 11274 | R8: 12922 | S8: 15834 | T8: 16528 | U8: 15468 | V8: 17662 | W8: 19228 | X8: 19662 | Y8: 19484 | Z8: 18424 | AA8: 16553 | AB8: 14929 | AC8: =SUM(E8:AB8) -> 306491 | AD8: =AC8*D8 -> 6129820 | AE8: =SUM(AD8:AD10) -> 8114548
C9: SA | D9: 4 | E9: 8645 | F9: 7736 | G9: 7103 | H9: 6615 | I9: 6253 | J9: 5879 | K9: 4193 | L9: 4788 | M9: 7219 | N9: 9305 | O9: 10532 | P9: 11046 | Q9: 10926 | R9: 10807 | S9: 12430 | T9: 11306 | U9: 11130 | V9: 14051 | W9: 16544 | X9: 16692 | Y9: 16041 | Z9: 14654 | AA9: 13416 | AB9: 12212 | AC9: =SUM(E9:AB9) -> 249523 | AD9: =AC9*D9 -> 998092
C10: DO | D10: 4 | E10: 8856 | F10: 8046 | G10: 7290 | H10: 6797 | I10: 6457 | J10: 5911 | K10: 3717 | L10: 4466 | M10: 5569 | N10: 6932 | O10: 8090 | P10: 9378 | Q10: 9576 | R10: 9830 | S10: 10346 | T10: 10636 | U10: 10411 | V10: 14067 | W10: 16876 | X10: 17727 | Y10: 18282 | Z10: 17323 | AA10: 15960 | AB10: 14116 | AC10: =SUM(E10:AB10) -> 246659 | AD10: =AC10*D10 -> 986636
B11: 3 | C11: OR | D11: 20 | E11: 12378 | F11: 11182 | G11: 10419 | H11: 9638 | I11: 9180 | J11: 9270 | K11: 7664 | L11: 9023 | M11: 11902 | N11: 13846 | O11: 15108 | P11: 16423 | Q11: 14384 | R11: 15981 | S11: 18576 | T11: 18995 | U11: 17881 | V11: 19855 | W11: 21881 | X11: 22356 | Y11: 22023 | Z11: 20742 | AA11: 18664 | AB11: 17489 | AC11: =SUM(E11:AB11) -> 364860 | AD11: =AC11*D11 -> 7297200 | AE11: =SUM(AD11:AD14) -> 9933912
C12: SA | D12: 4 | E12: 9853 | F12: 9051 | G12: 8165 | H12: 7765 | I12: 6868 | J12: 6286 | K12: 4505 | L12: 5250 | M12: 8510 | N12: 10576 | O12: 12267 | P12: 13227 | Q12: 11932 | R12: 11150 | S12: 10934 | T12: 11349 | U12: 10695 | V12: 14123 | W12: 17063 | X12: 17107 | Y12: 16527 | Z12: 15770 | AA12: 14724 | AB12: 15581 | AC12: =SUM(E12:AB12) -> 269278 | AD12: =AC12*D12 -> 1077112
C13: DO | D13: 4 | E13: 15099 | F13: 14208 | G13: 13311 | H13: 12584 | I13: 12082 | J13: 11235 | K13: 9331 | L13: 9833 | M13: 9830 | N13: 9259 | O13: 12862 | P13: 14697 | Q13: 15387 | R13: 15443 | S13: 16321 | T13: 15329 | U13: 14377 | V13: 19605 | W13: 23405 | X13: 24449 | Y13: 24641 | Z13: 23804 | AA13: 22420 | AB13: 21388 | AC13: =SUM(E13:AB13) -> 380900 | AD13: =AC13*D13 -> 1523600
C14: FE | D14: 3 | E14: 500 | F14: 500 | G14: 500 | H14: 500 | I14: 500 | J14: 500 | K14: 500 | L14: 500 | M14: 500 | N14: 500 | O14: 500 | P14: 500 | Q14: 500 | R14: 500 | S14: 500 | T14: 500 | U14: 500 | V14: 500 | W14: 500 | X14: 500 | Y14: 500 | Z14: 500 | AA14: 500 | AB14: 500 | AC14: =SUM(E14:AB14) -> 12000 | AD14: =AC14*D14 -> 36000
B15: 4 | C15: OR | D15: 22 | E15: 3941 | F15: 3563 | G15: 3260 | H15: 2919 | I15: 2774 | J15: 2707 | K15: 2182 | L15: 2894 | M15: 4241 | N15: 5373 | O15: 6005 | P15: 5811 | Q15: 4994 | R15: 5970 | S15: 7311 | T15: 7284 | U15: 6380 | V15: 8097 | W15: 8807 | X15: 8912 | Y15: 8605 | Z15: 8022 | AA15: 7165 | AB15: 6241 | AC15: =SUM(E15:AB15) -> 133458 | AD15: =AC15*D15 -> 2936076 | AE15: =SUM(AD15:AD18) -> 4126772
C16: SA | D16: 4 | E16: 7634 | F16: 7059 | G16: 6516 | H16: 6049 | I16: 5812 | J16: 5429 | K16: 4730 | L16: 5755 | M16: 7180 | N16: 8031 | O16: 8913 | P16: 9671 | Q16: 9371 | R16: 9469 | S16: 9774 | T16: 9889 | U16: 9579 | V16: 11485 | W16: 13201 | X16: 13260 | Y16: 12812 | Z16: 12253 | AA16: 11410 | AB16: 10552 | AC16: =SUM(E16:AB16) -> 215834 | AD16: =AC16*D16 -> 863336
C17: DO | D17: 4 | E17: 3127 | F17: 2707 | G17: 2308 | H17: 2014 | I17: 1758 | J17: 1429 | K17: 625 | L17: 674 | M17: 1226 | N17: 1318 | O17: 1621 | P17: 2069 | Q17: 2396 | R17: 2835 | S17: 3565 | T17: 4062 | U17: 3852 | V17: 5661 | W17: 6839 | X17: 6964 | Y17: 7115 | Z17: 6709 | AA17: 5897 | AB17: 5069 | AC17: =SUM(E17:AB17) -> 81840 | AD17: =AC17*D17 -> 327360
C18: FE | D18: 0 | E18: 500 | F18: 500 | G18: 500 | H18: 500 | I18: 500 | J18: 500 | K18: 500 | L18: 500 | M18: 500 | N18: 500 | O18: 500 | P18: 500 | Q18: 500 | R18: 500 | S18: 500 | T18: 500 | U18: 500 | V18: 500 | W18: 500 | X18: 500 | Y18: 500 | Z18: 500 | AA18: 500 | AB18: 500 | AC18: =SUM(E18:AB18) -> 12000 | AD18: =AC18*D18 -> 0
B19: 5 | C19: OR | D19: 19 | E19: 0 | F19: 0 | G19: 0 | H19: 0 | I19: 0 | J19: 0 | K19: 0 | L19: 0 | M19: 0 | N19: 0 | O19: 0 | P19: 0 | Q19: 0 | R19: 0 | S19: 0 | T19: 0 | U19: 0 | V19: 0 | W19: 0 | X19: 0 | Y19: 0 | Z19: 0 | AA19: 0 | AB19: 0 | AC19: =SUM(E19:AB19) -> 0 | AD19: =AC19*D19 -> 0 | AE19: =SUM(AD19:AD22) -> 0
C20: SA | D20: 4 | E20: 0 | F20: 0 | G20: 0 | H20: 0 | I20: 0 | J20: 0 | K20: 0 | L20: 0 | M20: 0 | N20: 0 | O20: 0 | P20: 0 | Q20: 0 | R20: 0 | S20: 0 | T20: 0 | U20: 0 | V20: 0 | W20: 0 | X20: 0 | Y20: 0 | Z20: 0 | AA20: 0 | AB20: 0 | AC20: =SUM(E20:AB20) -> 0 | AD20: =AC20*D20 -> 0
C21: DO | D21: 5 | E21: 0 | F21: 0 | G21: 0 | H21: 0 | I21: 0 | J21: 0 | K21: 0 | L21: 0 | M21: 0 | N21: 0 | O21: 0 | P21: 0 | Q21: 0 | R21: 0 | S21: 0 | T21: 0 | U21: 0 | V21: 0 | W21: 0 | X21: 0 | Y21: 0 | Z21: 0 | AA21: 0 | AB21: 0 | AC21: =SUM(E21:AB21) -> 0 | AD21: =AC21*D21 -> 0
C22: FE | D22: 3 | E22: 0 | F22: 0 | G22: 0 | H22: 0 | I22: 0 | J22: 0 | K22: 0 | L22: 0 | M22: 0 | N22: 0 | O22: 0 | P22: 0 | Q22: 0 | R22: 0 | S22: 0 | T22: 0 | U22: 0 | V22: 0 | W22: 0 | X22: 0 | Y22: 0 | Z22: 0 | AA22: 0 | AB22: 0 | AC22: =SUM(E22:AB22) -> 0 | AD22: =AC22*D22 -> 0
B23: 6 | C23: OR | D23: 21 | E23: 0 | F23: 0 | G23: 0 | H23: 0 | I23: 0 | J23: 0 | K23: 0 | L23: 0 | M23: 0 | N23: 0 | O23: 0 | P23: 0 | Q23: 0 | R23: 0 | S23: 0 | T23: 0 | U23: 0 | V23: 0 | W23: 0 | X23: 0 | Y23: 0 | Z23: 0 | AA23: 0 | AB23: 0 | AC23: =SUM(E23:AB23) -> 0 | AD23: =AC23*D23 -> 0 | AE23: =SUM(AD23:AD26) -> 0
C24: SA | D24: 4 | E24: 0 | F24: 0 | G24: 0 | H24: 0 | I24: 0 | J24: 0 | K24: 0 | L24: 0 | M24: 0 | N24: 0 | O24: 0 | P24: 0 | Q24: 0 | R24: 0 | S24: 0 | T24: 0 | U24: 0 | V24: 0 | W24: 0 | X24: 0 | Y24: 0 | Z24: 0 | AA24: 0 | AB24: 0 | AC24: =SUM(E24:AB24) -> 0 | AD24: =AC24*D24 -> 0
C25: DO | D25: 4 | E25: 0 | F25: 0 | G25: 0 | H25: 0 | I25: 0 | J25: 0 | K25: 0 | L25: 0 | M25: 0 | N25: 0 | O25: 0 | P25: 0 | Q25: 0 | R25: 0 | S25: 0 | T25: 0 | U25: 0 | V25: 0 | W25: 0 | X25: 0 | Y25: 0 | Z25: 0 | AA25: 0 | AB25: 0 | AC25: =SUM(E25:AB25) -> 0 | AD25: =AC25*D25 -> 0
C26: FE | D26: 1 | E26: 0 | F26: 0 | G26: 0 | H26: 0 | I26: 0 | J26: 0 | K26: 0 | L26: 0 | M26: 0 | N26: 0 | O26: 0 | P26: 0 | Q26: 0 | R26: 0 | S26: 0 | T26: 0 | U26: 0 | V26: 0 | W26: 0 | X26: 0 | Y26: 0 | Z26: 0 | AA26: 0 | AB26: 0 | AC26: =SUM(E26:AB26) -> 0 | AD26: =AC26*D26 -> 0
B27: 7 | C27: OR | D27: 20 | E27: 0 | F27: 0 | G27: 0 | H27: 0 | I27: 0 | J27: 0 | K27: 0 | L27: 0 | M27: 0 | N27: 0 | O27: 0 | P27: 0 | Q27: 0 | R27: 0 | S27: 0 | T27: 0 | U27: 0 | V27: 0 | W27: 0 | X27: 0 | Y27: 0 | Z27: 0 | AA27: 0 | AB27: 0 | AC27: =SUM(E27:AB27) -> 0 | AD27: =AC27*D27 -> 0 | AE27: =SUM(AD27:AD30) -> 0
C28: SA | D28: 5 | E28: 0 | F28: 0 | G28: 0 | H28: 0 | I28: 0 | J28: 0 | K28: 0 | L28: 0 | M28: 0 | N28: 0 | O28: 0 | P28: 0 | Q28: 0 | R28: 0 | S28: 0 | T28: 0 | U28: 0 | V28: 0 | W28: 0 | X28: 0 | Y28: 0 | Z28: 0 | AA28: 0 | AB28: 0 | AC28: =SUM(E28:AB28) -> 0 | AD28: =AC28*D28 -> 0
C29: DO | D29: 4 | E29: 0 | F29: 0 | G29: 0 | H29: 0 | I29: 0 | J29: 0 | K29: 0 | L29: 0 | M29: 0 | N29: 0 | O29: 0 | P29: 0 | Q29: 0 | R29: 0 | S29: 0 | T29: 0 | U29: 0 | V29: 0 | W29: 0 | X29: 0 | Y29: 0 | Z29: 0 | AA29: 0 | AB29: 0 | AC29: =SUM(E29:AB29) -> 0 | AD29: =AC29*D29 -> 0
C30: FE | D30: 2 | E30: 0 | F30: 0 | G30: 0 | H30: 0 | I30: 0 | J30: 0 | K30: 0 | L30: 0 | M30: 0 | N30: 0 | O30: 0 | P30: 0 | Q30: 0 | R30: 0 | S30: 0 | T30: 0 | U30: 0 | V30: 0 | W30: 0 | X30: 0 | Y30: 0 | Z30: 0 | AA30: 0 | AB30: 0 | AC30: =SUM(E30:AB30) -> 0 | AD30: =AC30*D30 -> 0
B31: 8 | C31: OR | D31: 21 | E31: 0 | F31: 0 | G31: 0 | H31: 0 | I31: 0 | J31: 0 | K31: 0 | L31: 0 | M31: 0 | N31: 0 | O31: 0 | P31: 0 | Q31: 0 | R31: 0 | S31: 0 | T31: 0 | U31: 0 | V31: 0 | W31: 0 | X31: 0 | Y31: 0 | Z31: 0 | AA31: 0 | AB31: 0 | AC31: =SUM(E31:AB31) -> 0 | AD31: =AC31*D31 -> 0 | AE31: =SUM(AD31:AD34) -> 0
C32: SA | D32: 3 | E32: 0 | F32: 0 | G32: 0 | H32: 0 | I32: 0 | J32: 0 | K32: 0 | L32: 0 | M32: 0 | N32: 0 | O32: 0 | P32: 0 | Q32: 0 | R32: 0 | S32: 0 | T32: 0 | U32: 0 | V32: 0 | W32: 0 | X32: 0 | Y32: 0 | Z32: 0 | AA32: 0 | AB32: 0 | AC32: =SUM(E32:AB32) -> 0 | AD32: =AC32*D32 -> 0
C33: DO | D33: 5 | E33: 0 | F33: 0 | G33: 0 | H33: 0 | I33: 0 | J33: 0 | K33: 0 | L33: 0 | M33: 0 | N33: 0 | O33: 0 | P33: 0 | Q33: 0 | R33: 0 | S33: 0 | T33: 0 | U33: 0 | V33: 0 | W33: 0 | X33: 0 | Y33: 0 | Z33: 0 | AA33: 0 | AB33: 0 | AC33: =SUM(E33:AB33) -> 0 | AD33: =AC33*D33 -> 0
C34: FE | D34: 2 | E34: 0 | F34: 0 | G34: 0 | H34: 0 | I34: 0 | J34: 0 | K34: 0 | L34: 0 | M34: 0 | N34: 0 | O34: 0 | P34: 0 | Q34: 0 | R34: 0 | S34: 0 | T34: 0 | U34: 0 | V34: 0 | W34: 0 | X34: 0 | Y34: 0 | Z34: 0 | AA34: 0 | AB34: 0 | AC34: =SUM(E34:AB34) -> 0 | AD34: =AC34*D34 -> 0
B35: 9 | C35: OR | D35: 22 | E35: 0 | F35: 0 | G35: 0 | H35: 0 | I35: 0 | J35: 0 | K35: 0 | L35: 0 | M35: 0 | N35: 0 | O35: 0 | P35: 0 | Q35: 0 | R35: 0 | S35: 0 | T35: 0 | U35: 0 | V35: 0 | W35: 0 | X35: 0 | Y35: 0 | Z35: 0 | AA35: 0 | AB35: 0 | AC35: =SUM(E35:AB35) -> 0 | AD35: =AC35*D35 -> 0 | AE35: =SUM(AD35:AD37) -> 0
C36: SA | D36: 4 | E36: 0 | F36: 0 | G36: 0 | H36: 0 | I36: 0 | J36: 0 | K36: 0 | L36: 0 | M36: 0 | N36: 0 | O36: 0 | P36: 0 | Q36: 0 | R36: 0 | S36: 0 | T36: 0 | U36: 0 | V36: 0 | W36: 0 | X36: 0 | Y36: 0 | Z36: 0 | AA36: 0 | AB36: 0 | AC36: =SUM(E36:AB36) -> 0 | AD36: =AC36*D36 -> 0
C37: DO | D37: 4 | E37: 0 | F37: 0 | G37: 0 | H37: 0 | I37: 0 | J37: 0 | K37: 0 | L37: 0 | M37: 0 | N37: 0 | O37: 0 | P37: 0 | Q37: 0 | R37: 0 | S37: 0 | T37: 0 | U37: 0 | V37: 0 | W37: 0 | X37: 0 | Y37: 0 | Z37: 0 | AA37: 0 | AB37: 0 | AC37: =SUM(E37:AB37) -> 0 | AD37: =AC37*D37 -> 0
B38: 10 | C38: OR | D38: 20 | E38: 4079 | F38: 3366 | G38: 2802 | H38: 2341 | I38: 1788 | J38: 1151 | K38: 591 | L38: 1879 | M38: 4100 | N38: 5333 | O38: 6422 | P38: 6992 | Q38: 6144 | R38: 7410 | S38: 9606 | T38: 9316 | U38: 8116 | V38: 9892 | W38: 10572 | X38: 10390 | Y38: 10243 | Z38: 9923 | AA38: 8887 | AB38: 8160 | AC38: =SUM(E38:AB38) -> 149503 | AD38: =AC38*D38 -> 2990060 | AE38: =SUM(AD38:AD41) -> 4415947
C39: SA | D39: 5 | E39: 4447 | F39: 3837 | G39: 2803 | H39: 1856 | I39: 932 | J39: 500 | K39: 500 | L39: 1649 | M39: 3762 | N39: 4906 | O39: 5779 | P39: 5995 | Q39: 5428 | R39: 5351 | S39: 6037 | T39: 6071 | U39: 5395 | V39: 8107 | W39: 9542 | X39: 9205 | Y39: 8735 | Z39: 8407 | AA39: 7751 | AB39: 7041 | AC39: =SUM(E39:AB39) -> 124036 | AD39: =AC39*D39 -> 620180
C40: DO | D40: 5 | E40: 7201 | F40: 6214 | G40: 4963 | H40: 3933 | I40: 3289 | J40: 1985 | K40: 843 | L40: 1152 | M40: 2657 | N40: 3316 | O40: 3645 | P40: 4247 | Q40: 4555 | R40: 4333 | S40: 4921 | T40: 5588 | U40: 5485 | V40: 8891 | W40: 11299 | X40: 11125 | Y40: 10831 | Z40: 10508 | AA40: 9667 | AB40: 8655 | AC40: =SUM(E40:AB40) -> 139303 | AD40: =AC40*D40 -> 696515
C41: FE | D41: 1 | E41: 4040 | F41: 3766 | G41: 3505 | H41: 3292 | I41: 2857 | J41: 2408 | K41: 1776 | L41: 1595 | M41: 2633 | N41: 3565 | O41: 5519 | P41: 5879 | Q41: 6061 | R41: 5519 | S41: 4859 | T41: 4400 | U41: 4447 | V41: 7951 | W41: 7513 | X41: 7367 | Y41: 6196 | Z41: 5136 | AA41: 4707 | AB41: 4201 | AC41: =SUM(E41:AB41) -> 109192 | AD41: =AC41*D41 -> 109192
...
