Workbook
Name _bookmark27: 'P1_ANEXO 1 -2027 a 2037'!#REF!

Sheet P1_ANEXO 1 -2027 a 2037
B1: ANEXO No. 1 - CANTIDADES DE ENERGÍA HORARIA Y MENSUAL A CONTRATAR
B2: PRODUCTO 1 - ENERO 2027 A DICIEMBRE 2037
B4: ENERGÍA PLANA 24 HORAS A SOLICITAR AÑO 2027 PARA MERCADO REGULADO (MWh)
B5: MES | C5: DÍA | D5: H1 | E5: H2 | F5: H3 | G5: H4 | H5: H5 | I5: H6 | J5: H7 | K5: H8 | L5: H9 | M5: H10 | N5: H11 | O5: H12 | P5: H13 | Q5: H14 | R5: H15 | S5: H16 | T5: H17 | U5: H18 | V5: H19 | W5: H20 | X5: H21 | Y5: H22 | Z5: H23 | AA5: H24 | AB5: TOTAL | AC5: No. Dias | AD5: TOTAL MES
B6: 46388 | C6: ORDINARIO | D6: 30.0228 | E6: 30.0228 | F6: 30.0228 | G6: 30.0228 | H6: 30.0228 | I6: 30.0228 | J6: 30.0228 | K6: 30.0228 | L6: 30.0228 | M6: 30.0228 | N6: 30.0228 | O6: 30.0228 | P6: 30.0228 | Q6: 30.0228 | R6: 30.0228 | S6: 30.0228 | T6: 30.0228 | U6: 30.0228 | V6: 30.0228 | W6: 30.0228 | X6: 30.0228 | Y6: 30.0228 | Z6: 30.0228 | AA6: 30.0228 | AB6: =SUM(D6:AA6) -> 720.5472 | AC6: 19 | AD6: =+AB6*AC6+AB7*AC7+AB8*AC8 -> 22336.963
C7: SABADO | D7: 30.0228 | E7: 30.0228 | F7: 30.0228 | G7: 30.0228 | H7: 30.0228 | I7: 30.0228 | J7: 30.0228 | K7: 30.0228 | L7: 30.0228 | M7: 30.0228 | N7: 30.0228 | O7: 30.0228 | P7: 30.0228 | Q7: 30.0228 | R7: 30.0228 | S7: 30.0228 | T7: 30.0228 | U7: 30.0228 | V7: 30.0228 | W7: 30.0228 | X7: 30.0228 | Y7: 30.0228 | Z7: 30.0228 | AA7: 30.0228 | AB7: =SUM(D7:AA7) -> 720.5472 | AC7: 5
C8: DOMINGO | D8: 30.0228 | E8: 30.0228 | F8: 30.0228 | G8: 30.0228 | H8: 30.0228 | I8: 30.0228 | J8: 30.0228 | K8: 30.0228 | L8: 30.0228 | M8: 30.0228 | N8: 30.0228 | O8: 30.0228 | P8: 30.0228 | Q8: 30.0228 | R8: 30.0228 | S8: 30.0228 | T8: 30.0228 | U8: 30.0228 | V8: 30.0228 | W8: 30.0228 | X8: 30.0228 | Y8: 30.0228 | Z8: 30.0228 | AA8: 30.0228 | AB8: =SUM(D8:AA8) -> 720.5472 | AC8: 7
B9: 46419 | C9: ORDINARIO | D9: 30.0228 | E9: 30.0228 | F9: 30.0228 | G9: 30.0228 | H9: 30.0228 | I9: 30.0228 | J9: 30.0228 | K9: 30.0228 | L9: 30.0228 | M9: 30.0228 | N9: 30.0228 | O9: 30.0228 | P9: 30.0228 | Q9: 30.0228 | R9: 30.0228 | S9: 30.0228 | T9: 30.0228 | U9: 30.0228 | V9: 30.0228 | W9: 30.0228 | X9: 30.0228 | Y9: 30.0228 | Z9: 30.0228 | AA9: 30.0228 | AB9: =SUM(D9:AA9) -> 720.5472 | AC9: 20 | AD9: =+AB9*AC9+AB10*AC10+AB11*AC11 -> 20175.322
C10: SABADO | D10: 30.0228 | E10: 30.0228 | F10: 30.0228 | G10: 30.0228 | H10: 30.0228 | I10: 30.0228 | J10: 30.0228 | K10: 30.0228 | L10: 30.0228 | M10: 30.0228 | N10: 30.0228 | O10: 30.0228 | P10: 30.0228 | Q10: 30.0228 | R10: 30.0228 | S10: 30.0228 | T10: 30.0228 | U10: 30.0228 | V10: 30.0228 | W10: 30.0228 | X10: 30.0228 | Y10: 30.0228 | Z10: 30.0228 | AA10: 30.0228 | AB10: =SUM(D10:AA10) -> 720.5472 | AC10: 4
C11: DOMINGO | D11: 30.0228 | E11: 30.0228 | F11: 30.0228 | G11: 30.0228 | H11: 30.0228 | I11: 30.0228 | J11: 30.0228 | K11: 30.0228 | L11: 30.0228 | M11: 30.0228 | N11: 30.0228 | O11: 30.0228 | P11: 30.0228 | Q11: 30.0228 | R11: 30.0228 | S11: 30.0228 | T11: 30.0228 | U11: 30.0228 | V11: 30.0228 | W11: 30.0228 | X11: 30.0228 | Y11: 30.0228 | Z11: 30.0228 | AA11: 30.0228 | AB11: =SUM(D11:AA11) -> 720.5472 | AC11: 4
B12: 46447 | C12: ORDINARIO | D12: 30.0228 | E12: 30.0228 | F12: 30.0228 | G12: 30.0228 | H12: 30.0228 | I12: 30.0228 | J12: 30.0228 | K12: 30.0228 | L12: 30.0228 | M12: 30.0228 | N12: 30.0228 | O12: 30.0228 | P12: 30.0228 | Q12: 30.0228 | R12: 30.0228 | S12: 30.0228 | T12: 30.0228 | U12: 30.0228 | V12: 30.0228 | W12: 30.0228 | X12: 30.0228 | Y12: 30.0228 | Z12: 30.0228 | AA12: 30.0228 | AB12: =SUM(D12:AA12) -> 720.5472 | AC12: 20 | AD12: =+AB12*AC12+AB13*AC13+AB14*AC14 -> 22336.963
C13: SABADO | D13: 30.0228 | E13: 30.0228 | F13: 30.0228 | G13: 30.0228 | H13: 30.0228 | I13: 30.0228 | J13: 30.0228 | K13: 30.0228 | L13: 30.0228 | M13: 30.0228 | N13: 30.0228 | O13: 30.0228 | P13: 30.0228 | Q13: 30.0228 | R13: 30.0228 | S13: 30.0228 | T13: 30.0228 | U13: 30.0228 | V13: 30.0228 | W13: 30.0228 | X13: 30.0228 | Y13: 30.0228 | Z13: 30.0228 | AA13: 30.0228 | AB13: =SUM(D13:AA13) -> 720.5472 | AC13: 4
C14: DOMINGO | D14: 30.0228 | E14: 30.0228 | F14: 30.0228 | G14: 30.0228 | H14: 30.0228 | I14: 30.0228 | J14: 30.0228 | K14: 30.0228 | L14: 30.0228 | M14: 30.0228 | N14: 30.0228 | O14: 30.0228 | P14: 30.0228 | Q14: 30.0228 | R14: 30.0228 | S14: 30.0228 | T14: 30.0228 | U14: 30.0228 | V14: 30.0228 | W14: 30.0228 | X14: 30.0228 | Y14: 30.0228 | Z14: 30.0228 | AA14: 30.0228 | AB14: =SUM(D14:AA14) -> 720.5472 | AC14: 7
B15: 46478 | C15: ORDINARIO | D15: 30.0228 | E15: 30.0228 | F15: 30.0228 | G15: 30.0228 | H15: 30.0228 | I15: 30.0228 | J15: 30.0228 | K15: 30.0228 | L15: 30.0228 | M15: 30.0228 | N15: 30.0228 | O15: 30.0228 | P15: 30.0228 | Q15: 30.0228 | R15: 30.0228 | S15: 30.0228 | T15: 30.0228 | U15: 30.0228 | V15: 30.0228 | W15: 30.0228 | X15: 30.0228 | Y15: 30.0228 | Z15: 30.0228 | AA15: 30.0228 | AB15: =SUM(D15:AA15) -> 720.5472 | AC15: 22 | AD15: =+AB15*AC15+AB16*AC16+AB17*AC17 -> 21616.416
C16: SABADO | D16: 30.0228 | E16: 30.0228 | F16: 30.0228 | G16: 30.0228 | H16: 30.0228 | I16: 30.0228 | J16: 30.0228 | K16: 30.0228 | L16: 30.0228 | M16: 30.0228 | N16: 30.0228 | O16: 30.0228 | P16: 30.0228 | Q16: 30.0228 | R16: 30.0228 | S16: 30.0228 | T16: 30.0228 | U16: 30.0228 | V16: 30.0228 | W16: 30.0228 | X16: 30.0228 | Y16: 30.0228 | Z16: 30.0228 | AA16: 30.0228 | AB16: =SUM(D16:AA16) -> 720.5472 | AC16: 4
C17: DOMINGO | D17: 30.0228 | E17: 30.0228 | F17: 30.0228 | G17: 30.0228 | H17: 30.0228 | I17: 30.0228 | J17: 30.0228 | K17: 30.0228 | L17: 30.0228 | M17: 30.0228 | N17: 30.0228 | O17: 30.0228 | P17: 30.0228 | Q17: 30.0228 | R17: 30.0228 | S17: 30.0228 | T17: 30.0228 | U17: 30.0228 | V17: 30.0228 | W17: 30.0228 | X17: 30.0228 | Y17: 30.0228 | Z17: 30.0228 | AA17: 30.0228 | AB17: =SUM(D17:AA17) -> 720.5472 | AC17: 4
B18: 46508 | C18: ORDINARIO | D18: 30.0228 | E18: 30.0228 | F18: 30.0228 | G18: 30.0228 | H18: 30.0228 | I18: 30.0228 | J18: 30.0228 | K18: 30.0228 | L18: 30.0228 | M18: 30.0228 | N18: 30.0228 | O18: 30.0228 | P18: 30.0228 | Q18: 30.0228 | R18: 30.0228 | S18: 30.0228 | T18: 30.0228 | U18: 30.0228 | V18: 30.0228 | W18: 30.0228 | X18: 30.0228 | Y18: 30.0228 | Z18: 30.0228 | AA18: 30.0228 | AB18: =SUM(D18:AA18) -> 720.5472 | AC18: 20 | AD18: =+AB18*AC18+AB19*AC19+AB20*AC20 -> 22336.963
C19: SABADO | D19: 30.0228 | E19: 30.0228 | F19: 30.0228 | G19: 30.0228 | H19: 30.0228 | I19: 30.0228 | J19: 30.0228 | K19: 30.0228 | L19: 30.0228 | M19: 30.0228 | N19: 30.0228 | O19: 30.0228 | P19: 30.0228 | Q19: 30.0228 | R19: 30.0228 | S19: 30.0228 | T19: 30.0228 | U19: 30.0228 | V19: 30.0228 | W19: 30.0228 | X19: 30.0228 | Y19: 30.0228 | Z19: 30.0228 | AA19: 30.0228 | AB19: =SUM(D19:AA19) -> 720.5472 | AC19: 4
C20: DOMINGO | D20: 30.0228 | E20: 30.0228 | F20: 30.0228 | G20: 30.0228 | H20: 30.0228 | I20: 30.0228 | J20: 30.0228 | K20: 30.0228 | L20: 30.0228 | M20: 30.0228 | N20: 30.0228 | O20: 30.0228 | P20: 30.0228 | Q20: 30.0228 | R20: 30.0228 | S20: 30.0228 | T20: 30.0228 | U20: 30.0228 | V20: 30.0228 | W20: 30.0228 | X20: 30.0228 | Y20: 30.0228 | Z20: 30.0228 | AA20: 30.0228 | AB20: =SUM(D20:AA20) -> 720.5472 | AC20: 7
B21: 46539 | C21: ORDINARIO | D21: 30.0228 | E21: 30.0228 | F21: 30.0228 | G21: 30.0228 | H21: 30.0228 | I21: 30.0228 | J21: 30.0228 | K21: 30.0228 | L21: 30.0228 | M21: 30.0228 | N21: 30.0228 | O21: 30.0228 | P21: 30.0228 | Q21: 30.0228 | R21: 30.0228 | S21: 30.0228 | T21: 30.0228 | U21: 30.0228 | V21: 30.0228 | W21: 30.0228 | X21: 30.0228 | Y21: 30.0228 | Z21: 30.0228 | AA21: 30.0228 | AB21: =SUM(D21:AA21) -> 720.5472 | AC21: 21 | AD21: =+AB21*AC21+AB22*AC22+AB23*AC23 -> 21616.416
C22: SABADO | D22: 30.0228 | E22: 30.0228 | F22: 30.0228 | G22: 30.0228 | H22: 30.0228 | I22: 30.0228 | J22: 30.0228 | K22: 30.0228 | L22: 30.0228 | M22: 30.0228 | N22: 30.0228 | O22: 30.0228 | P22: 30.0228 | Q22: 30.0228 | R22: 30.0228 | S22: 30.0228 | T22: 30.0228 | U22: 30.0228 | V22: 30.0228 | W22: 30.0228 | X22: 30.0228 | Y22: 30.0228 | Z22: 30.0228 | AA22: 30.0228 | AB22: =SUM(D22:AA22) -> 720.5472 | AC22: 4
C23: DOMINGO | D23: 30.0228 | E23: 30.0228 | F23: 30.0228 | G23: 30.0228 | H23: 30.0228 | I23: 30.0228 | J23: 30.0228 | K23: 30.0228 | L23: 30.0228 | M23: 30.0228 | N23: 30.0228 | O23: 30.0228 | P23: 30.0228 | Q23: 30.0228 | R23: 30.0228 | S23: 30.0228 | T23: 30.0228 | U23: 30.0228 | V23: 30.0228 | W23: 30.0228 | X23: 30.0228 | Y23: 30.0228 | Z23: 30.0228 | AA23: 30.0228 | AB23: =SUM(D23:AA23) -> 720.5472 | AC23: 5
B24: 46569 | C24: ORDINARIO | D24: 30.0228 | E24: 30.0228 | F24: 30.0228 | G24: 30.0228 | H24: 30.0228 | I24: 30.0228 | J24: 30.0228 | K24: 30.0228 | L24: 30.0228 | M24: 30.0228 | N24: 30.0228 | O24: 30.0228 | P24: 30.0228 | Q24: 30.0228 | R24: 30.0228 | S24: 30.0228 | T24: 30.0228 | U24: 30.0228 | V24: 30.0228 | W24: 30.0228 | X24: 30.0228 | Y24: 30.0228 | Z24: 30.0228 | AA24: 30.0228 | AB24: =SUM(D24:AA24) -> 720.5472 | AC24: 20 | AD24: =+AB24*AC24+AB25*AC25+AB26*AC26 -> 22336.963
C25: SABADO | D25: 30.0228 | E25: 30.0228 | F25: 30.0228 | G25: 30.0228 | H25: 30.0228 | I25: 30.0228 | J25: 30.0228 | K25: 30.0228 | L25: 30.0228 | M25: 30.0228 | N25: 30.0228 | O25: 30.0228 | P25: 30.0228 | Q25: 30.0228 | R25: 30.0228 | S25: 30.0228 | T25: 30.0228 | U25: 30.0228 | V25: 30.0228 | W25: 30.0228 | X25: 30.0228 | Y25: 30.0228 | Z25: 30.0228 | AA25: 30.0228 | AB25: =SUM(D25:AA25) -> 720.5472 | AC25: 5
C26: DOMINGO | D26: 30.0228 | E26: 30.0228 | F26: 30.0228 | G26: 30.0228 | H26: 30.0228 | I26: 30.0228 | J26: 30.0228 | K26: 30.0228 | L26: 30.0228 | M26: 30.0228 | N26: 30.0228 | O26: 30.0228 | P26: 30.0228 | Q26: 30.0228 | R26: 30.0228 | S26: 30.0228 | T26: 30.0228 | U26: 30.0228 | V26: 30.0228 | W26: 30.0228 | X26: 30.0228 | Y26: 30.0228 | Z26: 30.0228 | AA26: 30.0228 | AB26: =SUM(D26:AA26) -> 720.5472 | AC26: 6
B27: 46600 | C27: ORDINARIO | D27: 30.0228 | E27: 30.0228 | F27: 30.0228 | G27: 30.0228 | H27: 30.0228 | I27: 30.0228 | J27: 30.0228 | K27: 30.0228 | L27: 30.0228 | M27: 30.0228 | N27: 30.0228 | O27: 30.0228 | P27: 30.0228 | Q27: 30.0228 | R27: 30.0228 | S27: 30.0228 | T27: 30.0228 | U27: 30.0228 | V27: 30.0228 | W27: 30.0228 | X27: 30.0228 | Y27: 30.0228 | Z27: 30.0228 | AA27: 30.0228 | AB27: =SUM(D27:AA27) -> 720.5472 | AC27: 21 | AD27: =+AB27*AC27+AB28*AC28+AB29*AC29 -> 22336.963
C28: SABADO | D28: 30.0228 | E28: 30.0228 | F28: 30.0228 | G28: 30.0228 | H28: 30.0228 | I28: 30.0228 | J28: 30.0228 | K28: 30.0228 | L28: 30.0228 | M28: 30.0228 | N28: 30.0228 | O28: 30.0228 | P28: 30.0228 | Q28: 30.0228 | R28: 30.0228 | S28: 30.0228 | T28: 30.0228 | U28: 30.0228 | V28: 30.0228 | W28: 30.0228 | X28: 30.0228 | Y28: 30.0228 | Z28: 30.0228 | AA28: 30.0228 | AB28: =SUM(D28:AA28) -> 720.5472 | AC28: 3
C29: DOMINGO | D29: 30.0228 | E29: 30.0228 | F29: 30.0228 | G29: 30.0228 | H29: 30.0228 | I29: 30.0228 | J29: 30.0228 | K29: 30.0228 | L29: 30.0228 | M29: 30.0228 | N29: 30.0228 | O29: 30.0228 | P29: 30.0228 | Q29: 30.0228 | R29: 30.0228 | S29: 30.0228 | T29: 30.0228 | U29: 30.0228 | V29: 30.0228 | W29: 30.0228 | X29: 30.0228 | Y29: 30.0228 | Z29: 30.0228 | AA29: 30.0228 | AB29: =SUM(D29:AA29) -> 720.5472 | AC29: 7
B30: 46631 | C30: ORDINARIO | D30: 30.0228 | E30: 30.0228 | F30: 30.0228 | G30: 30.0228 | H30: 30.0228 | I30: 30.0228 | J30: 30.0228 | K30: 30.0228 | L30: 30.0228 | M30: 30.0228 | N30: 30.0228 | O30: 30.0228 | P30: 30.0228 | Q30: 30.0228 | R30: 30.0228 | S30: 30.0228 | T30: 30.0228 | U30: 30.0228 | V30: 30.0228 | W30: 30.0228 | X30: 30.0228 | Y30: 30.0228 | Z30: 30.0228 | AA30: 30.0228 | AB30: =SUM(D30:AA30) -> 720.5472 | AC30: 22 | AD30: =+AB30*AC30+AB31*AC31+AB32*AC32 -> 21616.416
C31: SABADO | D31: 30.0228 | E31: 30.0228 | F31: 30.0228 | G31: 30.0228 | H31: 30.0228 | I31: 30.0228 | J31: 30.0228 | K31: 30.0228 | L31: 30.0228 | M31: 30.0228 | N31: 30.0228 | O31: 30.0228 | P31: 30.0228 | Q31: 30.0228 | R31: 30.0228 | S31: 30.0228 | T31: 30.0228 | U31: 30.0228 | V31: 30.0228 | W31: 30.0228 | X31: 30.0228 | Y31: 30.0228 | Z31: 30.0228 | AA31: 30.0228 | AB31: =SUM(D31:AA31) -> 720.5472 | AC31: 4
C32: DOMINGO | D32: 30.0228 | E32: 30.0228 | F32: 30.0228 | G32: 30.0228 | H32: 30.0228 | I32: 30.0228 | J32: 30.0228 | K32: 30.0228 | L32: 30.0228 | M32: 30.0228 | N32: 30.0228 | O32: 30.0228 | P32: 30.0228 | Q32: 30.0228 | R32: 30.0228 | S32: 30.0228 | T32: 30.0228 | U32: 30.0228 | V32: 30.0228 | W32: 30.0228 | X32: 30.0228 | Y32: 30.0228 | Z32: 30.0228 | AA32: 30.0228 | AB32: =SUM(D32:AA32) -> 720.5472 | AC32: 4
B33: 46661 | C33: ORDINARIO | D33: 30.0228 | E33: 30.0228 | F33: 30.0228 | G33: 30.0228 | H33: 30.0228 | I33: 30.0228 | J33: 30.0228 | K33: 30.0228 | L33: 30.0228 | M33: 30.0228 | N33: 30.0228 | O33: 30.0228 | P33: 30.0228 | Q33: 30.0228 | R33: 30.0228 | S33: 30.0228 | T33: 30.0228 | U33: 30.0228 | V33: 30.0228 | W33: 30.0228 | X33: 30.0228 | Y33: 30.0228 | Z33: 30.0228 | AA33: 30.0228 | AB33: =SUM(D33:AA33) -> 720.5472 | AC33: 20 | AD33: =+AB33*AC33+AB34*AC34+AB35*AC35 -> 22336.963
C34: SABADO | D34: 30.0228 | E34: 30.0228 | F34: 30.0228 | G34: 30.0228 | H34: 30.0228 | I34: 30.0228 | J34: 30.0228 | K34: 30.0228 | L34: 30.0228 | M34: 30.0228 | N34: 30.0228 | O34: 30.0228 | P34: 30.0228 | Q34: 30.0228 | R34: 30.0228 | S34: 30.0228 | T34: 30.0228 | U34: 30.0228 | V34: 30.0228 | W34: 30.0228 | X34: 30.0228 | Y34: 30.0228 | Z34: 30.0228 | AA34: 30.0228 | AB34: =SUM(D34:AA34) -> 720.5472 | AC34: 5
C35: DOMINGO | D35: 30.0228 | E35: 30.0228 | F35: 30.0228 | G35: 30.0228 | H35: 30.0228 | I35: 30.0228 | J35: 30.0228 | K35: 30.0228 | L35: 30.0228 | M35: 30.0228 | N35: 30.0228 | O35: 30.0228 | P35: 30.0228 | Q35: 30.0228 | R35: 30.0228 | S35: 30.0228 | T35: 30.0228 | U35: 30.0228 | V35: 30.0228 | W35: 30.0228 | X35: 30.0228 | Y35: 30.0228 | Z35: 30.0228 | AA35: 30.0228 | AB35: =SUM(D35:AA35) -> 720.5472 | AC35: 6
B36: 46692 | C36: ORDINARIO | D36: 30.0228 | E36: 30.0228 | F36: 30.0228 | G36: 30.0228 | H36: 30.0228 | I36: 30.0228 | J36: 30.0228 | K36: 30.0228 | L36: 30.0228 | M36: 30.0228 | N36: 30.0228 | O36: 30.0228 | P36: 30.0228 | Q36: 30.0228 | R36: 30.0228 | S36: 30.0228 | T36: 30.0228 | U36: 30.0228 | V36: 30.0228 | W36: 30.0228 | X36: 30.0228 | Y36: 30.0228 | Z36: 30.0228 | AA36: 30.0228 | AB36: =SUM(D36:AA36) -> 720.5472 | AC36: 20 | AD36: =+AB36*AC36+AB37*AC37+AB38*AC38 -> 21616.416
C37: SABADO | D37: 30.0228 | E37: 30.0228 | F37: 30.0228 | G37: 30.0228 | H37: 30.0228 | I37: 30.0228 | J37: 30.0228 | K37: 30.0228 | L37: 30.0228 | M37: 30.0228 | N37: 30.0228 | O37: 30.0228 | P37: 30.0228 | Q37: 30.0228 | R37: 30.0228 | S37: 30.0228 | T37: 30.0228 | U37: 30.0228 | V37: 30.0228 | W37: 30.0228 | X37: 30.0228 | Y37: 30.0228 | Z37: 30.0228 | AA37: 30.0228 | AB37: =SUM(D37:AA37) -> 720.5472 | AC37: 4
C38: DOMINGO | D38: 30.0228 | E38: 30.0228 | F38: 30.0228 | G38: 30.0228 | H38: 30.0228 | I38: 30.0228 | J38: 30.0228 | K38: 30.0228 | L38: 30.0228 | M38: 30.0228 | N38: 30.0228 | O38: 30.0228 | P38: 30.0228 | Q38: 30.0228 | R38: 30.0228 | S38: 30.0228 | T38: 30.0228 | U38: 30.0228 | V38: 30.0228 | W38: 30.0228 | X38: 30.0228 | Y38: 30.0228 | Z38: 30.0228 | AA38: 30.0228 | AB38: =SUM(D38:AA38) -> 720.5472 | AC38: 6
B39: 46722 | C39: ORDINARIO | D39: 30.0228 | E39: 30.0228 | F39: 30.0228 | G39: 30.0228 | H39: 30.0228 | I39: 30.0228 | J39: 30.0228 | K39: 30.0228 | L39: 30.0228 | M39: 30.0228 | N39: 30.0228 | O39: 30.0228 | P39: 30.0228 | Q39: 30.0228 | R39: 30.0228 | S39: 30.0228 | T39: 30.0228 | U39: 30.0228 | V39: 30.0228 | W39: 30.0228 | X39: 30.0228 | Y39: 30.0228 | Z39: 30.0228 | AA39: 30.0228 | AB39: =SUM(D39:AA39) -> 720.5472 | AC39: 22 | AD39: =+AB39*AC39+AB40*AC40+AB41*AC41 -> 22336.963
C40: SABADO | D40: 30.0228 | E40: 30.0228 | F40: 30.0228 | G40: 30.0228 | H40: 30.0228 | I40: 30.0228 | J40: 30.0228 | K40: 30.0228 | L40: 30.0228 | M40: 30.0228 | N40: 30.0228 | O40: 30.0228 | P40: 30.0228 | Q40: 30.0228 | R40: 30.0228 | S40: 30.0228 | T40: 30.0228 | U40: 30.0228 | V40: 30.0228 | W40: 30.0228 | X40: 30.0228 | Y40: 30.0228 | Z40: 30.0228 | AA40: 30.0228 | AB40: =SUM(D40:AA40) -> 720.5472 | AC40: 3
C41: DOMINGO | D41: 30.0228 | E41: 30.0228 | F41: 30.0228 | G41: 30.0228 | H41: 30.0228 | I41: 30.0228 | J41: 30.0228 | K41: 30.0228 | L41: 30.0228 | M41: 30.0228 | N41: 30.0228 | O41: 30.0228 | P41: 30.0228 | Q41: 30.0228 | R41: 30.0228 | S41: 30.0228 | T41: 30.0228 | U41: 30.0228 | V41: 30.0228 | W41: 30.0228 | X41: 30.0228 | Y41: 30.0228 | Z41: 30.0228 | AA41: 30.0228 | AB41: =SUM(D41:AA41) -> 720.5472 | AC41: 6
...

Sheet P1_ANEXO_2 - 2027 al 2037
D2: EMPRESAS MUNICIPALES DE CALI- EMCALI EICE ESP
D3: CONVOCATORIA PÚBLICA PARA COMPRA DE ENERGÍA
D4: Código de Convocatoria SICEP No. CP-EMIC2026-001
D6: ANEXO No. 2 CANTIDADES Y PRECIOS OFERTADOS
D8: PRODUCTO 1 - ENERO 2027 A DICIEMBRE 2037
D11: AÑO | E11: Energía solicitada (MWh) | F11: % ofertado | G11: $/kWh | J11: MES AÑO 2027 | K11: Energía solicitada (MWh) | L11: % ofertado | M11: $/kWh
D12: 2027 | E12: ='P1_ANEXO 1 -2027 a 2037'!AD42 -> 262999.73 | F12: =+SUMPRODUCT(K12:K23,L12:L23)/E12 -> 0 | G12: =+M12 -> 0 | J12: ENERO | K12: =+'P1_ANEXO 1 -2027 a 2037'!$AD$6 -> 22336.963
D13: 2028 | E13: ='P1_ANEXO 1 -2027 a 2037'!AD82 -> 200275.2 | J13: FEBRERO | K13: =+'P1_ANEXO 1 -2027 a 2037'!$AD$9 -> 20175.322
D14: 2029 | E14: ='P1_ANEXO 1 -2027 a 2037'!AD122 -> 297840 | J14: MARZO | K14: =+'P1_ANEXO 1 -2027 a 2037'!$AD$12 -> 22336.963
D15: 2030 | E15: ='P1_ANEXO 1 -2027 a 2037'!AD162 -> 113880 | J15: ABRIL | K15: =+'P1_ANEXO 1 -2027 a 2037'!$AD$15 -> 21616.416
D16: 2031 | E16: ='P1_ANEXO 1 -2027 a 2037'!AD202 -> 192720 | J16: MAYO | K16: =+'P1_ANEXO 1 -2027 a 2037'!$AD$18 -> 22336.963
D17: 2032 | E17: ='P1_ANEXO 1 -2027 a 2037'!AD242 -> 281088 | J17: JUNIO | K17: =+'P1_ANEXO 1 -2027 a 2037'!$AD$21 -> 21616.416
D18: 2033 | E18: ='P1_ANEXO 1 -2027 a 2037'!AD282 -> 259996.8 | J18: JULIO | K18: =+'P1_ANEXO 1 -2027 a 2037'!$AD$24 -> 22336.963
D19: 2034 | E19: ='P1_ANEXO 1 -2027 a 2037'!AD322 -> 259996.8 | J19: AGOSTO | K19: =+'P1_ANEXO 1 -2027 a 2037'!$AD$27 -> 22336.963
D20: 2035 | E20: ='P1_ANEXO 1 -2027 a 2037'!AD362 -> 259996.8 | J20: SEPTIEMBRE | K20: =+'P1_ANEXO 1 -2027 a 2037'!$AD$30 -> 21616.416
D21: 2036 | E21: ='P1_ANEXO 1 -2027 a 2037'!AD402 -> 260709.12 | J21: OCTUBRE | K21: =+'P1_ANEXO 1 -2027 a 2037'!$AD$33 -> 22336.963
D22: 2037 | E22: ='P1_ANEXO 1 -2027 a 2037'!AD442 -> 259996.8 | J22: NOVIEMBRE | K22: =+'P1_ANEXO 1 -2027 a 2037'!$AD$36 -> 21616.416
D23: Total año | E23: =SUM(E12:E22) -> 2649499.2 | J23: DICIEMBRE | K23: =+'P1_ANEXO 1 -2027 a 2037'!$AD$39 -> 22336.963
C26: NOTAS:
C27: 1 | D27: Para el año 2027 se deben ofertar mínimo 8 meses, cada mes podrá ofertarse con porcentaje diferente, el cual debera ser minimo el 15 % de la necesidad de cada mes.
C28: 2 | D28: A partir del año 2028 y hasta 2037 se debe ofertar el mismo porcentaje para todos y cada uno de los años de este producto.
C29: 3 | D29: Se debe ofertar minimo el 30% de la energia requerida para todos y cada uno de los años del producto
C30: 4 | D30: El precio puede ser diferente para cada año ofertado. Para el año 2027 el precio debe ser el mismo para todos los meses ofertados.
C31: 5 | D31: La energía y los precios a ofertar deben ofrecerse en la modalidad monomia.
C32: 6 | D32: Precios en pesos constantes del mes de mayo de 2026.

Sheet P2_ANEXO 1 -2028 a 2032
B1: ANEXO No. 1 - CANTIDADES DE ENERGÍA HORARIA Y MENSUAL A CONTRATAR
B2: PRODUCTO 2 - ENERO 2028 A DICIEMBRE 2032
B4: ENERGÍA PLANA (H07 A H18) A SOLICITAR AÑO 2028 PARA MERCADO REGULADO (MWh)
B5: MES | C5: DÍA | D5: H1 | E5: H2 | F5: H3 | G5: H4 | H5: H5 | I5: H6 | J5: H7 | K5: H8 | L5: H9 | M5: H10 | N5: H11 | O5: H12 | P5: H13 | Q5: H14 | R5: H15 | S5: H16 | T5: H17 | U5: H18 | V5: H19 | W5: H20 | X5: H21 | Y5: H22 | Z5: H23 | AA5: H24 | AB5: TOTAL | AC5: No. Dias | AD5: TOTAL MES
B6: 46753 | C6: ORDINARIO | J6: 21 | K6: 21 | L6: 21 | M6: 21 | N6: 21 | O6: 21 | P6: 21 | Q6: 21 | R6: 21 | S6: 21 | T6: 21 | U6: 21 | AB6: =SUM(D6:AA6) -> 252 | AC6: 20 | AD6: =+AB6*AC6+AB7*AC7+AB8*AC8 -> 7812
C7: SABADO | J7: 21 | K7: 21 | L7: 21 | M7: 21 | N7: 21 | O7: 21 | P7: 21 | Q7: 21 | R7: 21 | S7: 21 | T7: 21 | U7: 21 | AB7: =SUM(D7:AA7) -> 252 | AC7: 4
C8: DOMINGO | J8: 21 | K8: 21 | L8: 21 | M8: 21 | N8: 21 | O8: 21 | P8: 21 | Q8: 21 | R8: 21 | S8: 21 | T8: 21 | U8: 21 | AB8: =SUM(D8:AA8) -> 252 | AC8: 7
B9: 46784 | C9: ORDINARIO | J9: 21 | K9: 21 | L9: 21 | M9: 21 | N9: 21 | O9: 21 | P9: 21 | Q9: 21 | R9: 21 | S9: 21 | T9: 21 | U9: 21 | AB9: =SUM(D9:AA9) -> 252 | AC9: 21 | AD9: =+AB9*AC9+AB10*AC10+AB11*AC11 -> 7308
C10: SABADO | J10: 21 | K10: 21 | L10: 21 | M10: 21 | N10: 21 | O10: 21 | P10: 21 | Q10: 21 | R10: 21 | S10: 21 | T10: 21 | U10: 21 | AB10: =SUM(D10:AA10) -> 252 | AC10: 4
C11: DOMINGO | J11: 21 | K11: 21 | L11: 21 | M11: 21 | N11: 21 | O11: 21 | P11: 21 | Q11: 21 | R11: 21 | S11: 21 | T11: 21 | U11: 21 | AB11: =SUM(D11:AA11) -> 252 | AC11: 4
B12: 46813 | C12: ORDINARIO | J12: 21 | K12: 21 | L12: 21 | M12: 21 | N12: 21 | O12: 21 | P12: 21 | Q12: 21 | R12: 21 | S12: 21 | T12: 21 | U12: 21 | AB12: =SUM(D12:AA12) -> 252 | AC12: 22 | AD12: =+AB12*AC12+AB13*AC13+AB14*AC14 -> 7812
C13: SABADO | J13: 21 | K13: 21 | L13: 21 | M13: 21 | N13: 21 | O13: 21 | P13: 21 | Q13: 21 | R13: 21 | S13: 21 | T13: 21 | U13: 21 | AB13: =SUM(D13:AA13) -> 252 | AC13: 4
C14: DOMINGO | J14: 21 | K14: 21 | L14: 21 | M14: 21 | N14: 21 | O14: 21 | P14: 21 | Q14: 21 | R14: 21 | S14: 21 | T14: 21 | U14: 21 | AB14: =SUM(D14:AA14) -> 252 | AC14: 5
B15: 46844 | C15: ORDINARIO | J15: 21 | K15: 21 | L15: 21 | M15: 21 | N15: 21 | O15: 21 | P15: 21 | Q15: 21 | R15: 21 | S15: 21 | T15: 21 | U15: 21 | AB15: =SUM(D15:AA15) -> 252 | AC15: 18 | AD15: =+AB15*AC15+AB16*AC16+AB17*AC17 -> 7560
C16: SABADO | J16: 21 | K16: 21 | L16: 21 | M16: 21 | N16: 21 | O16: 21 | P16: 21 | Q16: 21 | R16: 21 | S16: 21 | T16: 21 | U16: 21 | AB16: =SUM(D16:AA16) -> 252 | AC16: 5
C17: DOMINGO | J17: 21 | K17: 21 | L17: 21 | M17: 21 | N17: 21 | O17: 21 | P17: 21 | Q17: 21 | R17: 21 | S17: 21 | T17: 21 | U17: 21 | AB17: =SUM(D17:AA17) -> 252 | AC17: 7
B18: 46874 | C18: ORDINARIO | J18: 21 | K18: 21 | L18: 21 | M18: 21 | N18: 21 | O18: 21 | P18: 21 | Q18: 21 | R18: 21 | S18: 21 | T18: 21 | U18: 21 | AB18: =SUM(D18:AA18) -> 252 | AC18: 21 | AD18: =+AB18*AC18+AB19*AC19+AB20*AC20 -> 7812
C19: SABADO | J19: 21 | K19: 21 | L19: 21 | M19: 21 | N19: 21 | O19: 21 | P19: 21 | Q19: 21 | R19: 21 | S19: 21 | T19: 21 | U19: 21 | AB19: =SUM(D19:AA19) -> 252 | AC19: 4
C20: DOMINGO | J20: 21 | K20: 21 | L20: 21 | M20: 21 | N20: 21 | O20: 21 | P20: 21 | Q20: 21 | R20: 21 | S20: 21 | T20: 21 | U20: 21 | AB20: =SUM(D20:AA20) -> 252 | AC20: 6
B21: 46905 | C21: ORDINARIO | J21: 21 | K21: 21 | L21: 21 | M21: 21 | N21: 21 | O21: 21 | P21: 21 | Q21: 21 | R21: 21 | S21: 21 | T21: 21 | U21: 21 | AB21: =SUM(D21:AA21) -> 252 | AC21: 20 | AD21: =+AB21*AC21+AB22*AC22+AB23*AC23 -> 7560
C22: SABADO | J22: 21 | K22: 21 | L22: 21 | M22: 21 | N22: 21 | O22: 21 | P22: 21 | Q22: 21 | R22: 21 | S22: 21 | T22: 21 | U22: 21 | AB22: =SUM(D22:AA22) -> 252 | AC22: 4
C23: DOMINGO | J23: 21 | K23: 21 | L23: 21 | M23: 21 | N23: 21 | O23: 21 | P23: 21 | Q23: 21 | R23: 21 | S23: 21 | T23: 21 | U23: 21 | AB23: =SUM(D23:AA23) -> 252 | AC23: 6
B24: 46935 | C24: ORDINARIO | J24: 21 | K24: 21 | L24: 21 | M24: 21 | N24: 21 | O24: 21 | P24: 21 | Q24: 21 | R24: 21 | S24: 21 | T24: 21 | U24: 21 | AB24: =SUM(D24:AA24) -> 252 | AC24: 19 | AD24: =+AB24*AC24+AB25*AC25+AB26*AC26 -> 7812
C25: SABADO | J25: 21 | K25: 21 | L25: 21 | M25: 21 | N25: 21 | O25: 21 | P25: 21 | Q25: 21 | R25: 21 | S25: 21 | T25: 21 | U25: 21 | AB25: =SUM(D25:AA25) -> 252 | AC25: 5
C26: DOMINGO | J26: 21 | K26: 21 | L26: 21 | M26: 21 | N26: 21 | O26: 21 | P26: 21 | Q26: 21 | R26: 21 | S26: 21 | T26: 21 | U26: 21 | AB26: =SUM(D26:AA26) -> 252 | AC26: 7
B27: 46966 | C27: ORDINARIO | J27: 21 | K27: 21 | L27: 21 | M27: 21 | N27: 21 | O27: 21 | P27: 21 | Q27: 21 | R27: 21 | S27: 21 | T27: 21 | U27: 21 | AB27: =SUM(D27:AA27) -> 252 | AC27: 21 | AD27: =+AB27*AC27+AB28*AC28+AB29*AC29 -> 7812
C28: SABADO | J28: 21 | K28: 21 | L28: 21 | M28: 21 | N28: 21 | O28: 21 | P28: 21 | Q28: 21 | R28: 21 | S28: 21 | T28: 21 | U28: 21 | AB28: =SUM(D28:AA28) -> 252 | AC28: 4
C29: DOMINGO | J29: 21 | K29: 21 | L29: 21 | M29: 21 | N29: 21 | O29: 21 | P29: 21 | Q29: 21 | R29: 21 | S29: 21 | T29: 21 | U29: 21 | AB29: =SUM(D29:AA29) -> 252 | AC29: 6
B30: 46997 | C30: ORDINARIO | J30: 21 | K30: 21 | L30: 21 | M30: 21 | N30: 21 | O30: 21 | P30: 21 | Q30: 21 | R30: 21 | S30: 21 | T30: 21 | U30: 21 | AB30: =SUM(D30:AA30) -> 252 | AC30: 21 | AD30: =+AB30*AC30+AB31*AC31+AB32*AC32 -> 7560
C31: SABADO | J31: 21 | K31: 21 | L31: 21 | M31: 21 | N31: 21 | O31: 21 | P31: 21 | Q31: 21 | R31: 21 | S31: 21 | T31: 21 | U31: 21 | AB31: =SUM(D31:AA31) -> 252 | AC31: 5
C32: DOMINGO | J32: 21 | K32: 21 | L32: 21 | M32: 21 | N32: 21 | O32: 21 | P32: 21 | Q32: 21 | R32: 21 | S32: 21 | T32: 21 | U32: 21 | AB32: =SUM(D32:AA32) -> 252 | AC32: 4
B33: 47027 | C33: ORDINARIO | J33: 21 | K33: 21 | L33: 21 | M33: 21 | N33: 21 | O33: 21 | P33: 21 | Q33: 21 | R33: 21 | S33: 21 | T33: 21 | U33: 21 | AB33: =SUM(D33:AA33) -> 252 | AC33: 21 | AD33: =+AB33*AC33+AB34*AC34+AB35*AC35 -> 7812
C34: SABADO | J34: 21 | K34: 21 | L34: 21 | M34: 21 | N34: 21 | O34: 21 | P34: 21 | Q34: 21 | R34: 21 | S34: 21 | T34: 21 | U34: 21 | AB34: =SUM(D34:AA34) -> 252 | AC34: 4
C35: DOMINGO | J35: 21 | K35: 21 | L35: 21 | M35: 21 | N35: 21 | O35: 21 | P35: 21 | Q35: 21 | R35: 21 | S35: 21 | T35: 21 | U35: 21 | AB35: =SUM(D35:AA35) -> 252 | AC35: 6
B36: 47058 | C36: ORDINARIO | J36: 21 | K36: 21 | L36: 21 | M36: 21 | N36: 21 | O36: 21 | P36: 21 | Q36: 21 | R36: 21 | S36: 21 | T36: 21 | U36: 21 | AB36: =SUM(D36:AA36) -> 252 | AC36: 20 | AD36: =+AB36*AC36+AB37*AC37+AB38*AC38 -> 7560
C37: SABADO | J37: 21 | K37: 21 | L37: 21 | M37: 21 | N37: 21 | O37: 21 | P37: 21 | Q37: 21 | R37: 21 | S37: 21 | T37: 21 | U37: 21 | AB37: =SUM(D37:AA37) -> 252 | AC37: 4
C38: DOMINGO | J38: 21 | K38: 21 | L38: 21 | M38: 21 | N38: 21 | O38: 21 | P38: 21 | Q38: 21 | R38: 21 | S38: 21 | T38: 21 | U38: 21 | AB38: =SUM(D38:AA38) -> 252 | AC38: 6
B39: 47088 | C39: ORDINARIO | J39: 21 | K39: 21 | L39: 21 | M39: 21 | N39: 21 | O39: 21 | P39: 21 | Q39: 21 | R39: 21 | S39: 21 | T39: 21 | U39: 21 | AB39: =SUM(D39:AA39) -> 252 | AC39: 19 | AD39: =+AB39*AC39+AB40*AC40+AB41*AC41 -> 7812
C40: SABADO | J40: 21 | K40: 21 | L40: 21 | M40: 21 | N40: 21 | O40: 21 | P40: 21 | Q40: 21 | R40: 21 | S40: 21 | T40: 21 | U40: 21 | AB40: =SUM(D40:AA40) -> 252 | AC40: 5
C41: DOMINGO | J41: 21 | K41: 21 | L41: 21 | M41: 21 | N41: 21 | O41: 21 | P41: 21 | Q41: 21 | R41: 21 | S41: 21 | T41: 21 | U41: 21 | AB41: =SUM(D41:AA41) -> 252 | AC41: 7
...

Sheet P2_ANEXO_2 - 2028 al 2037
D2: EMPRESAS MUNICIPALES DE CALI- EMCALI EICE ESP
D3: CONVOCATORIA PÚBLICA PARA COMPRA DE ENERGÍA
D4: Código de Convocatoria SICEP No. CP-EMIC2026-001
D6: ANEXO No. 2 CANTIDADES Y PRECIOS OFERTADOS
D8: PRODUCTO 2 - ENERO 2028 A DICIEMBRE 2032
D11: AÑO | E11: Energía solicitada (MWh) | F11: % ofertado | G11: $/kWh
D12: 2028 | E12: ='P2_ANEXO 1 -2028 a 2032'!AD42 -> 92232
D13: 2029 | E13: ='P2_ANEXO 1 -2028 a 2032'!AD82 -> 87600
D14: 2030 | E14: ='P2_ANEXO 1 -2028 a 2032'!AD122 -> 87600
D15: 2031 | E15: ='P2_ANEXO 1 -2028 a 2032'!AD162 -> 91104
D16: 2032 | E16: ='P2_ANEXO 1 -2028 a 2032'!AD202 -> 87840
D17: Total año | E17: =SUM(E12:E16) -> 446376
C20: NOTAS:
C21: 1 | D21: Se debe ofertar el mismo porcentaje de la cantidad solicitada para todos los años.
C22: 2 | D22: Se debe ofertar mínimo el 50% de la energía solicitada
C23: 3 | D23: La energía y los precios a ofertar deben ofrecerse en la modalidad monomia.
C24: 4 | D24: Precios en pesos constantes del mes de mayo de 2026.

Sheet P3_ANEXO 1 -2033 a 2037
B1: ANEXO No. 1 - CANTIDADES DE ENERGÍA HORARIA Y MENSUAL A CONTRATAR
B2: PRODUCTO 3 - ENERO 2033 A DICIEMBRE 2037
B4: ENERGÍA PLANA (H07 A H18) A SOLICITAR AÑO 2033 PARA MERCADO REGULADO (MWh)
B5: MES | C5: DÍA | D5: H1 | E5: H2 | F5: H3 | G5: H4 | H5: H5 | I5: H6 | J5: H7 | K5: H8 | L5: H9 | M5: H10 | N5: H11 | O5: H12 | P5: H13 | Q5: H14 | R5: H15 | S5: H16 | T5: H17 | U5: H18 | V5: H19 | W5: H20 | X5: H21 | Y5: H22 | Z5: H23 | AA5: H24 | AB5: TOTAL | AC5: No. Dias | AD5: TOTAL MES
B6: 48580 | C6: ORDINARIO | J6: 9.86 | K6: 9.86 | L6: 9.86 | M6: 9.86 | N6: 9.86 | O6: 9.86 | P6: 9.86 | Q6: 9.86 | R6: 9.86 | S6: 9.86 | T6: 9.86 | U6: 9.86 | AB6: =SUM(D6:AA6) -> 118.32 | AC6: 19 | AD6: =+AB6*AC6+AB7*AC7+AB8*AC8 -> 3667.92
C7: SABADO | J7: 9.86 | K7: 9.86 | L7: 9.86 | M7: 9.86 | N7: 9.86 | O7: 9.86 | P7: 9.86 | Q7: 9.86 | R7: 9.86 | S7: 9.86 | T7: 9.86 | U7: 9.86 | AB7: =SUM(D7:AA7) -> 118.32 | AC7: 4
C8: DOMINGO | J8: 9.86 | K8: 9.86 | L8: 9.86 | M8: 9.86 | N8: 9.86 | O8: 9.86 | P8: 9.86 | Q8: 9.86 | R8: 9.86 | S8: 9.86 | T8: 9.86 | U8: 9.86 | AB8: =SUM(D8:AA8) -> 118.32 | AC8: 8
B9: 48611 | C9: ORDINARIO | J9: 9.86 | K9: 9.86 | L9: 9.86 | M9: 9.86 | N9: 9.86 | O9: 9.86 | P9: 9.86 | Q9: 9.86 | R9: 9.86 | S9: 9.86 | T9: 9.86 | U9: 9.86 | AB9: =SUM(D9:AA9) -> 118.32 | AC9: 20 | AD9: =+AB9*AC9+AB10*AC10+AB11*AC11 -> 3312.96
C10: SABADO | J10: 9.86 | K10: 9.86 | L10: 9.86 | M10: 9.86 | N10: 9.86 | O10: 9.86 | P10: 9.86 | Q10: 9.86 | R10: 9.86 | S10: 9.86 | T10: 9.86 | U10: 9.86 | AB10: =SUM(D10:AA10) -> 118.32 | AC10: 4
C11: DOMINGO | J11: 9.86 | K11: 9.86 | L11: 9.86 | M11: 9.86 | N11: 9.86 | O11: 9.86 | P11: 9.86 | Q11: 9.86 | R11: 9.86 | S11: 9.86 | T11: 9.86 | U11: 9.86 | AB11: =SUM(D11:AA11) -> 118.32 | AC11: 4
B12: 48639 | C12: ORDINARIO | J12: 9.86 | K12: 9.86 | L12: 9.86 | M12: 9.86 | N12: 9.86 | O12: 9.86 | P12: 9.86 | Q12: 9.86 | R12: 9.86 | S12: 9.86 | T12: 9.86 | U12: 9.86 | AB12: =SUM(D12:AA12) -> 118.32 | AC12: 22 | AD12: =+AB12*AC12+AB13*AC13+AB14*AC14 -> 3667.92
C13: SABADO | J13: 9.86 | K13: 9.86 | L13: 9.86 | M13: 9.86 | N13: 9.86 | O13: 9.86 | P13: 9.86 | Q13: 9.86 | R13: 9.86 | S13: 9.86 | T13: 9.86 | U13: 9.86 | AB13: =SUM(D13:AA13) -> 118.32 | AC13: 3
C14: DOMINGO | J14: 9.86 | K14: 9.86 | L14: 9.86 | M14: 9.86 | N14: 9.86 | O14: 9.86 | P14: 9.86 | Q14: 9.86 | R14: 9.86 | S14: 9.86 | T14: 9.86 | U14: 9.86 | AB14: =SUM(D14:AA14) -> 118.32 | AC14: 6
B15: 48670 | C15: ORDINARIO | J15: 9.86 | K15: 9.86 | L15: 9.86 | M15: 9.86 | N15: 9.86 | O15: 9.86 | P15: 9.86 | Q15: 9.86 | R15: 9.86 | S15: 9.86 | T15: 9.86 | U15: 9.86 | AB15: =SUM(D15:AA15) -> 118.32 | AC15: 19 | AD15: =+AB15*AC15+AB16*AC16+AB17*AC17 -> 3549.6
C16: SABADO | J16: 9.86 | K16: 9.86 | L16: 9.86 | M16: 9.86 | N16: 9.86 | O16: 9.86 | P16: 9.86 | Q16: 9.86 | R16: 9.86 | S16: 9.86 | T16: 9.86 | U16: 9.86 | AB16: =SUM(D16:AA16) -> 118.32 | AC16: 5
C17: DOMINGO | J17: 9.86 | K17: 9.86 | L17: 9.86 | M17: 9.86 | N17: 9.86 | O17: 9.86 | P17: 9.86 | Q17: 9.86 | R17: 9.86 | S17: 9.86 | T17: 9.86 | U17: 9.86 | AB17: =SUM(D17:AA17) -> 118.32 | AC17: 6
B18: 48700 | C18: ORDINARIO | J18: 9.86 | K18: 9.86 | L18: 9.86 | M18: 9.86 | N18: 9.86 | O18: 9.86 | P18: 9.86 | Q18: 9.86 | R18: 9.86 | S18: 9.86 | T18: 9.86 | U18: 9.86 | AB18: =SUM(D18:AA18) -> 118.32 | AC18: 20 | AD18: =+AB18*AC18+AB19*AC19+AB20*AC20 -> 3667.92
C19: SABADO | J19: 9.86 | K19: 9.86 | L19: 9.86 | M19: 9.86 | N19: 9.86 | O19: 9.86 | P19: 9.86 | Q19: 9.86 | R19: 9.86 | S19: 9.86 | T19: 9.86 | U19: 9.86 | AB19: =SUM(D19:AA19) -> 118.32 | AC19: 4
C20: DOMINGO | J20: 9.86 | K20: 9.86 | L20: 9.86 | M20: 9.86 | N20: 9.86 | O20: 9.86 | P20: 9.86 | Q20: 9.86 | R20: 9.86 | S20: 9.86 | T20: 9.86 | U20: 9.86 | AB20: =SUM(D20:AA20) -> 118.32 | AC20: 7
B21: 48731 | C21: ORDINARIO | J21: 9.86 | K21: 9.86 | L21: 9.86 | M21: 9.86 | N21: 9.86 | O21: 9.86 | P21: 9.86 | Q21: 9.86 | R21: 9.86 | S21: 9.86 | T21: 9.86 | U21: 9.86 | AB21: =SUM(D21:AA21) -> 118.32 | AC21: 19 | AD21: =+AB21*AC21+AB22*AC22+AB23*AC23 -> 3549.6
C22: SABADO | J22: 9.86 | K22: 9.86 | L22: 9.86 | M22: 9.86 | N22: 9.86 | O22: 9.86 | P22: 9.86 | Q22: 9.86 | R22: 9.86 | S22: 9.86 | T22: 9.86 | U22: 9.86 | AB22: =SUM(D22:AA22) -> 118.32 | AC22: 4
C23: DOMINGO | J23: 9.86 | K23: 9.86 | L23: 9.86 | M23: 9.86 | N23: 9.86 | O23: 9.86 | P23: 9.86 | Q23: 9.86 | R23: 9.86 | S23: 9.86 | T23: 9.86 | U23: 9.86 | AB23: =SUM(D23:AA23) -> 118.32 | AC23: 7
B24: 48761 | C24: ORDINARIO | J24: 9.86 | K24: 9.86 | L24: 9.86 | M24: 9.86 | N24: 9.86 | O24: 9.86 | P24: 9.86 | Q24: 9.86 | R24: 9.86 | S24: 9.86 | T24: 9.86 | U24: 9.86 | AB24: =SUM(D24:AA24) -> 118.32 | AC24: 19 | AD24: =+AB24*AC24+AB25*AC25+AB26*AC26 -> 3667.92
C25: SABADO | J25: 9.86 | K25: 9.86 | L25: 9.86 | M25: 9.86 | N25: 9.86 | O25: 9.86 | P25: 9.86 | Q25: 9.86 | R25: 9.86 | S25: 9.86 | T25: 9.86 | U25: 9.86 | AB25: =SUM(D25:AA25) -> 118.32 | AC25: 5
C26: DOMINGO | J26: 9.86 | K26: 9.86 | L26: 9.86 | M26: 9.86 | N26: 9.86 | O26: 9.86 | P26: 9.86 | Q26: 9.86 | R26: 9.86 | S26: 9.86 | T26: 9.86 | U26: 9.86 | AB26: =SUM(D26:AA26) -> 118.32 | AC26: 7
B27: 48792 | C27: ORDINARIO | J27: 9.86 | K27: 9.86 | L27: 9.86 | M27: 9.86 | N27: 9.86 | O27: 9.86 | P27: 9.86 | Q27: 9.86 | R27: 9.86 | S27: 9.86 | T27: 9.86 | U27: 9.86 | AB27: =SUM(D27:AA27) -> 118.32 | AC27: 22 | AD27: =+AB27*AC27+AB28*AC28+AB29*AC29 -> 3667.92
C28: SABADO | J28: 9.86 | K28: 9.86 | L28: 9.86 | M28: 9.86 | N28: 9.86 | O28: 9.86 | P28: 9.86 | Q28: 9.86 | R28: 9.86 | S28: 9.86 | T28: 9.86 | U28: 9.86 | AB28: =SUM(D28:AA28) -> 118.32 | AC28: 4
C29: DOMINGO | J29: 9.86 | K29: 9.86 | L29: 9.86 | M29: 9.86 | N29: 9.86 | O29: 9.86 | P29: 9.86 | Q29: 9.86 | R29: 9.86 | S29: 9.86 | T29: 9.86 | U29: 9.86 | AB29: =SUM(D29:AA29) -> 118.32 | AC29: 5
B30: 48823 | C30: ORDINARIO | J30: 9.86 | K30: 9.86 | L30: 9.86 | M30: 9.86 | N30: 9.86 | O30: 9.86 | P30: 9.86 | Q30: 9.86 | R30: 9.86 | S30: 9.86 | T30: 9.86 | U30: 9.86 | AB30: =SUM(D30:AA30) -> 118.32 | AC30: 22 | AD30: =+AB30*AC30+AB31*AC31+AB32*AC32 -> 3549.6
C31: SABADO | J31: 9.86 | K31: 9.86 | L31: 9.86 | M31: 9.86 | N31: 9.86 | O31: 9.86 | P31: 9.86 | Q31: 9.86 | R31: 9.86 | S31: 9.86 | T31: 9.86 | U31: 9.86 | AB31: =SUM(D31:AA31) -> 118.32 | AC31: 4
C32: DOMINGO | J32: 9.86 | K32: 9.86 | L32: 9.86 | M32: 9.86 | N32: 9.86 | O32: 9.86 | P32: 9.86 | Q32: 9.86 | R32: 9.86 | S32: 9.86 | T32: 9.86 | U32: 9.86 | AB32: =SUM(D32:AA32) -> 118.32 | AC32: 4
B33: 48853 | C33: ORDINARIO | J33: 9.86 | K33: 9.86 | L33: 9.86 | M33: 9.86 | N33: 9.86 | O33: 9.86 | P33: 9.86 | Q33: 9.86 | R33: 9.86 | S33: 9.86 | T33: 9.86 | U33: 9.86 | AB33: =SUM(D33:AA33) -> 118.32 | AC33: 19 | AD33: =+AB33*AC33+AB34*AC34+AB35*AC35 -> 3667.92
C34: SABADO | J34: 9.86 | K34: 9.86 | L34: 9.86 | M34: 9.86 | N34: 9.86 | O34: 9.86 | P34: 9.86 | Q34: 9.86 | R34: 9.86 | S34: 9.86 | T34: 9.86 | U34: 9.86 | AB34: =SUM(D34:AA34) -> 118.32 | AC34: 5
C35: DOMINGO | J35: 9.86 | K35: 9.86 | L35: 9.86 | M35: 9.86 | N35: 9.86 | O35: 9.86 | P35: 9.86 | Q35: 9.86 | R35: 9.86 | S35: 9.86 | T35: 9.86 | U35: 9.86 | AB35: =SUM(D35:AA35) -> 118.32 | AC35: 7
B36: 48884 | C36: ORDINARIO | J36: 9.86 | K36: 9.86 | L36: 9.86 | M36: 9.86 | N36: 9.86 | O36: 9.86 | P36: 9.86 | Q36: 9.86 | R36: 9.86 | S36: 9.86 | T36: 9.86 | U36: 9.86 | AB36: =SUM(D36:AA36) -> 118.32 | AC36: 19 | AD36: =+AB36*AC36+AB37*AC37+AB38*AC38 -> 3549.6
C37: SABADO | J37: 9.86 | K37: 9.86 | L37: 9.86 | M37: 9.86 | N37: 9.86 | O37: 9.86 | P37: 9.86 | Q37: 9.86 | R37: 9.86 | S37: 9.86 | T37: 9.86 | U37: 9.86 | AB37: =SUM(D37:AA37) -> 118.32 | AC37: 4
C38: DOMINGO | J38: 9.86 | K38: 9.86 | L38: 9.86 | M38: 9.86 | N38: 9.86 | O38: 9.86 | P38: 9.86 | Q38: 9.86 | R38: 9.86 | S38: 9.86 | T38: 9.86 | U38: 9.86 | AB38: =SUM(D38:AA38) -> 118.32 | AC38: 7
B39: 48914 | C39: ORDINARIO | J39: 9.86 | K39: 9.86 | L39: 9.86 | M39: 9.86 | N39: 9.86 | O39: 9.86 | P39: 9.86 | Q39: 9.86 | R39: 9.86 | S39: 9.86 | T39: 9.86 | U39: 9.86 | AB39: =SUM(D39:AA39) -> 118.32 | AC39: 21 | AD39: =+AB39*AC39+AB40*AC40+AB41*AC41 -> 3667.92
C40: SABADO | J40: 9.86 | K40: 9.86 | L40: 9.86 | M40: 9.86 | N40: 9.86 | O40: 9.86 | P40: 9.86 | Q40: 9.86 | R40: 9.86 | S40: 9.86 | T40: 9.86 | U40: 9.86 | AB40: =SUM(D40:AA40) -> 118.32 | AC40: 5
C41: DOMINGO | J41: 9.86 | K41: 9.86 | L41: 9.86 | M41: 9.86 | N41: 9.86 | O41: 9.86 | P41: 9.86 | Q41: 9.86 | R41: 9.86 | S41: 9.86 | T41: 9.86 | U41: 9.86 | AB41: =SUM(D41:AA41) -> 118.32 | AC41: 5
...

Sheet P3_ANEXO_2 - 2033 al 2037
D2: EMPRESAS MUNICIPALES DE CALI- EMCALI EICE ESP
D3: CONVOCATORIA PÚBLICA PARA COMPRA DE ENERGÍA
D4: Código de Convocatoria SICEP No. CP-EMIC2026-001
D6: ANEXO No. 2 CANTIDADES Y PRECIOS OFERTADOS
D8: PRODUCTO 3 - ENERO 2033 A DICIEMBRE 2037
D11: AÑO | E11: Energía solicitada (MWh) | F11: % ofertado | G11: $/kWh
D12: 2033 | E12: ='P3_ANEXO 1 -2033 a 2037'!AD42 -> 43186.8
D13: 2034 | E13: ='P3_ANEXO 1 -2033 a 2037'!AD82 -> 43800
D14: 2035 | E14: ='P3_ANEXO 1 -2033 a 2037'!AD122 -> 43800
D15: 2036 | E15: ='P3_ANEXO 1 -2033 a 2037'!AD162 -> 43920
D16: 2037 | E16: ='P3_ANEXO 1 -2033 a 2037'!AD202 -> 43800
D17: Total año | E17: =SUM(E12:E16) -> 218506.8
C20: NOTAS:
C21: 1 | D21: Se debe ofertar el mismo porcentaje de la cantidad solicitada para todos los años
C22: 2 | D22: Se debe ofertar mínimo el 50% de la energía solicitada
C23: 3 | D23: La energía y los precios a ofertar deben ofrecerse en la modalidad monomia.
C24: 4 | D24: Precios en pesos constantes del mes de mayo de 2026.

Sheet P4_ANEXO 1 -2033 a 2037
B1: ANEXO No. 1 - CANTIDADES DE ENERGÍA HORARIA Y MENSUAL A CONTRATAR
B2: PRODUCTO 4 - ENERO 2033 A DICIEMBRE 2037
B4: ENERGÍA PLANA 24 HORAS A SOLICITAR AÑO 2033 PARA MERCADO REGULADO (MWh)
B5: MES | C5: DÍA | D5: H1 | E5: H2 | F5: H3 | G5: H4 | H5: H5 | I5: H6 | J5: H7 | K5: H8 | L5: H9 | M5: H10 | N5: H11 | O5: H12 | P5: H13 | Q5: H14 | R5: H15 | S5: H16 | T5: H17 | U5: H18 | V5: H19 | W5: H20 | X5: H21 | Y5: H22 | Z5: H23 | AA5: H24 | AB5: TOTAL | AC5: No. Dias | AD5: TOTAL MES
B6: 48580 | C6: ORDINARIO | D6: 22.83 | E6: 22.83 | F6: 22.83 | G6: 22.83 | H6: 22.83 | I6: 22.83 | J6: 22.83 | K6: 22.83 | L6: 22.83 | M6: 22.83 | N6: 22.83 | O6: 22.83 | P6: 22.83 | Q6: 22.83 | R6: 22.83 | S6: 22.83 | T6: 22.83 | U6: 22.83 | V6: 22.83 | W6: 22.83 | X6: 22.83 | Y6: 22.83 | Z6: 22.83 | AA6: 22.83 | AB6: =SUM(D6:AA6) -> 547.92 | AC6: 19 | AD6: =+AB6*AC6+AB7*AC7+AB8*AC8 -> 16985.52
C7: SABADO | D7: 22.83 | E7: 22.83 | F7: 22.83 | G7: 22.83 | H7: 22.83 | I7: 22.83 | J7: 22.83 | K7: 22.83 | L7: 22.83 | M7: 22.83 | N7: 22.83 | O7: 22.83 | P7: 22.83 | Q7: 22.83 | R7: 22.83 | S7: 22.83 | T7: 22.83 | U7: 22.83 | V7: 22.83 | W7: 22.83 | X7: 22.83 | Y7: 22.83 | Z7: 22.83 | AA7: 22.83 | AB7: =SUM(D7:AA7) -> 547.92 | AC7: 4
C8: DOMINGO | D8: 22.83 | E8: 22.83 | F8: 22.83 | G8: 22.83 | H8: 22.83 | I8: 22.83 | J8: 22.83 | K8: 22.83 | L8: 22.83 | M8: 22.83 | N8: 22.83 | O8: 22.83 | P8: 22.83 | Q8: 22.83 | R8: 22.83 | S8: 22.83 | T8: 22.83 | U8: 22.83 | V8: 22.83 | W8: 22.83 | X8: 22.83 | Y8: 22.83 | Z8: 22.83 | AA8: 22.83 | AB8: =SUM(D8:AA8) -> 547.92 | AC8: 8
B9: 48611 | C9: ORDINARIO | D9: 22.83 | E9: 22.83 | F9: 22.83 | G9: 22.83 | H9: 22.83 | I9: 22.83 | J9: 22.83 | K9: 22.83 | L9: 22.83 | M9: 22.83 | N9: 22.83 | O9: 22.83 | P9: 22.83 | Q9: 22.83 | R9: 22.83 | S9: 22.83 | T9: 22.83 | U9: 22.83 | V9: 22.83 | W9: 22.83 | X9: 22.83 | Y9: 22.83 | Z9: 22.83 | AA9: 22.83 | AB9: =SUM(D9:AA9) -> 547.92 | AC9: 20 | AD9: =+AB9*AC9+AB10*AC10+AB11*AC11 -> 15341.76
C10: SABADO | D10: 22.83 | E10: 22.83 | F10: 22.83 | G10: 22.83 | H10: 22.83 | I10: 22.83 | J10: 22.83 | K10: 22.83 | L10: 22.83 | M10: 22.83 | N10: 22.83 | O10: 22.83 | P10: 22.83 | Q10: 22.83 | R10: 22.83 | S10: 22.83 | T10: 22.83 | U10: 22.83 | V10: 22.83 | W10: 22.83 | X10: 22.83 | Y10: 22.83 | Z10: 22.83 | AA10: 22.83 | AB10: =SUM(D10:AA10) -> 547.92 | AC10: 4
C11: DOMINGO | D11: 22.83 | E11: 22.83 | F11: 22.83 | G11: 22.83 | H11: 22.83 | I11: 22.83 | J11: 22.83 | K11: 22.83 | L11: 22.83 | M11: 22.83 | N11: 22.83 | O11: 22.83 | P11: 22.83 | Q11: 22.83 | R11: 22.83 | S11: 22.83 | T11: 22.83 | U11: 22.83 | V11: 22.83 | W11: 22.83 | X11: 22.83 | Y11: 22.83 | Z11: 22.83 | AA11: 22.83 | AB11: =SUM(D11:AA11) -> 547.92 | AC11: 4
B12: 48639 | C12: ORDINARIO | D12: 22.83 | E12: 22.83 | F12: 22.83 | G12: 22.83 | H12: 22.83 | I12: 22.83 | J12: 22.83 | K12: 22.83 | L12: 22.83 | M12: 22.83 | N12: 22.83 | O12: 22.83 | P12: 22.83 | Q12: 22.83 | R12: 22.83 | S12: 22.83 | T12: 22.83 | U12: 22.83 | V12: 22.83 | W12: 22.83 | X12: 22.83 | Y12: 22.83 | Z12: 22.83 | AA12: 22.83 | AB12: =SUM(D12:AA12) -> 547.92 | AC12: 22 | AD12: =+AB12*AC12+AB13*AC13+AB14*AC14 -> 16985.52
C13: SABADO | D13: 22.83 | E13: 22.83 | F13: 22.83 | G13: 22.83 | H13: 22.83 | I13: 22.83 | J13: 22.83 | K13: 22.83 | L13: 22.83 | M13: 22.83 | N13: 22.83 | O13: 22.83 | P13: 22.83 | Q13: 22.83 | R13: 22.83 | S13: 22.83 | T13: 22.83 | U13: 22.83 | V13: 22.83 | W13: 22.83 | X13: 22.83 | Y13: 22.83 | Z13: 22.83 | AA13: 22.83 | AB13: =SUM(D13:AA13) -> 547.92 | AC13: 3
C14: DOMINGO | D14: 22.83 | E14: 22.83 | F14: 22.83 | G14: 22.83 | H14: 22.83 | I14: 22.83 | J14: 22.83 | K14: 22.83 | L14: 22.83 | M14: 22.83 | N14: 22.83 | O14: 22.83 | P14: 22.83 | Q14: 22.83 | R14: 22.83 | S14: 22.83 | T14: 22.83 | U14: 22.83 | V14: 22.83 | W14: 22.83 | X14: 22.83 | Y14: 22.83 | Z14: 22.83 | AA14: 22.83 | AB14: =SUM(D14:AA14) -> 547.92 | AC14: 6
B15: 48670 | C15: ORDINARIO | D15: 22.83 | E15: 22.83 | F15: 22.83 | G15: 22.83 | H15: 22.83 | I15: 22.83 | J15: 22.83 | K15: 22.83 | L15: 22.83 | M15: 22.83 | N15: 22.83 | O15: 22.83 | P15: 22.83 | Q15: 22.83 | R15: 22.83 | S15: 22.83 | T15: 22.83 | U15: 22.83 | V15: 22.83 | W15: 22.83 | X15: 22.83 | Y15: 22.83 | Z15: 22.83 | AA15: 22.83 | AB15: =SUM(D15:AA15) -> 547.92 | AC15: 19 | AD15: =+AB15*AC15+AB16*AC16+AB17*AC17 -> 16437.6
C16: SABADO | D16: 22.83 | E16: 22.83 | F16: 22.83 | G16: 22.83 | H16: 22.83 | I16: 22.83 | J16: 22.83 | K16: 22.83 | L16: 22.83 | M16: 22.83 | N16: 22.83 | O16: 22.83 | P16: 22.83 | Q16: 22.83 | R16: 22.83 | S16: 22.83 | T16: 22.83 | U16: 22.83 | V16: 22.83 | W16: 22.83 | X16: 22.83 | Y16: 22.83 | Z16: 22.83 | AA16: 22.83 | AB16: =SUM(D16:AA16) -> 547.92 | AC16: 5
C17: DOMINGO | D17: 22.83 | E17: 22.83 | F17: 22.83 | G17: 22.83 | H17: 22.83 | I17: 22.83 | J17: 22.83 | K17: 22.83 | L17: 22.83 | M17: 22.83 | N17: 22.83 | O17: 22.83 | P17: 22.83 | Q17: 22.83 | R17: 22.83 | S17: 22.83 | T17: 22.83 | U17: 22.83 | V17: 22.83 | W17: 22.83 | X17: 22.83 | Y17: 22.83 | Z17: 22.83 | AA17: 22.83 | AB17: =SUM(D17:AA17) -> 547.92 | AC17: 6
B18: 48700 | C18: ORDINARIO | D18: 22.83 | E18: 22.83 | F18: 22.83 | G18: 22.83 | H18: 22.83 | I18: 22.83 | J18: 22.83 | K18: 22.83 | L18: 22.83 | M18: 22.83 | N18: 22.83 | O18: 22.83 | P18: 22.83 | Q18: 22.83 | R18: 22.83 | S18: 22.83 | T18: 22.83 | U18: 22.83 | V18: 22.83 | W18: 22.83 | X18: 22.83 | Y18: 22.83 | Z18: 22.83 | AA18: 22.83 | AB18: =SUM(D18:AA18) -> 547.92 | AC18: 20 | AD18: =+AB18*AC18+AB19*AC19+AB20*AC20 -> 16985.52
C19: SABADO | D19: 22.83 | E19: 22.83 | F19: 22.83 | G19: 22.83 | H19: 22.83 | I19: 22.83 | J19: 22.83 | K19: 22.83 | L19: 22.83 | M19: 22.83 | N19: 22.83 | O19: 22.83 | P19: 22.83 | Q19: 22.83 | R19: 22.83 | S19: 22.83 | T19: 22.83 | U19: 22.83 | V19: 22.83 | W19: 22.83 | X19: 22.83 | Y19: 22.83 | Z19: 22.83 | AA19: 22.83 | AB19: =SUM(D19:AA19) -> 547.92 | AC19: 4
C20: DOMINGO | D20: 22.83 | E20: 22.83 | F20: 22.83 | G20: 22.83 | H20: 22.83 | I20: 22.83 | J20: 22.83 | K20: 22.83 | L20: 22.83 | M20: 22.83 | N20: 22.83 | O20: 22.83 | P20: 22.83 | Q20: 22.83 | R20: 22.83 | S20: 22.83 | T20: 22.83 | U20: 22.83 | V20: 22.83 | W20: 22.83 | X20: 22.83 | Y20: 22.83 | Z20: 22.83 | AA20: 22.83 | AB20: =SUM(D20:AA20) -> 547.92 | AC20: 7
B21: 48731 | C21: ORDINARIO | D21: 22.83 | E21: 22.83 | F21: 22.83 | G21: 22.83 | H21: 22.83 | I21: 22.83 | J21: 22.83 | K21: 22.83 | L21: 22.83 | M21: 22.83 | N21: 22.83 | O21: 22.83 | P21: 22.83 | Q21: 22.83 | R21: 22.83 | S21: 22.83 | T21: 22.83 | U21: 22.83 | V21: 22.83 | W21: 22.83 | X21: 22.83 | Y21: 22.83 | Z21: 22.83 | AA21: 22.83 | AB21: =SUM(D21:AA21) -> 547.92 | AC21: 19 | AD21: =+AB21*AC21+AB22*AC22+AB23*AC23 -> 16437.6
C22: SABADO | D22: 22.83 | E22: 22.83 | F22: 22.83 | G22: 22.83 | H22: 22.83 | I22: 22.83 | J22: 22.83 | K22: 22.83 | L22: 22.83 | M22: 22.83 | N22: 22.83 | O22: 22.83 | P22: 22.83 | Q22: 22.83 | R22: 22.83 | S22: 22.83 | T22: 22.83 | U22: 22.83 | V22: 22.83 | W22: 22.83 | X22: 22.83 | Y22: 22.83 | Z22: 22.83 | AA22: 22.83 | AB22: =SUM(D22:AA22) -> 547.92 | AC22: 4
C23: DOMINGO | D23: 22.83 | E23: 22.83 | F23: 22.83 | G23: 22.83 | H23: 22.83 | I23: 22.83 | J23: 22.83 | K23: 22.83 | L23: 22.83 | M23: 22.83 | N23: 22.83 | O23: 22.83 | P23: 22.83 | Q23: 22.83 | R23: 22.83 | S23: 22.83 | T23: 22.83 | U23: 22.83 | V23: 22.83 | W23: 22.83 | X23: 22.83 | Y23: 22.83 | Z23: 22.83 | AA23: 22.83 | AB23: =SUM(D23:AA23) -> 547.92 | AC23: 7
B24: 48761 | C24: ORDINARIO | D24: 22.83 | E24: 22.83 | F24: 22.83 | G24: 22.83 | H24: 22.83 | I24: 22.83 | J24: 22.83 | K24: 22.83 | L24: 22.83 | M24: 22.83 | N24: 22.83 | O24: 22.83 | P24: 22.83 | Q24: 22.83 | R24: 22.83 | S24: 22.83 | T24: 22.83 | U24: 22.83 | V24: 22.83 | W24: 22.83 | X24: 22.83 | Y24: 22.83 | Z24: 22.83 | AA24: 22.83 | AB24: =SUM(D24:AA24) -> 547.92 | AC24: 19 | AD24: =+AB24*AC24+AB25*AC25+AB26*AC26 -> 16985.52
C25: SABADO | D25: 22.83 | E25: 22.83 | F25: 22.83 | G25: 22.83 | H25: 22.83 | I25: 22.83 | J25: 22.83 | K25: 22.83 | L25: 22.83 | M25: 22.83 | N25: 22.83 | O25: 22.83 | P25: 22.83 | Q25: 22.83 | R25: 22.83 | S25: 22.83 | T25: 22.83 | U25: 22.83 | V25: 22.83 | W25: 22.83 | X25: 22.83 | Y25: 22.83 | Z25: 22.83 | AA25: 22.83 | AB25: =SUM(D25:AA25) -> 547.92 | AC25: 5
C26: DOMINGO | D26: 22.83 | E26: 22.83 | F26: 22.83 | G26: 22.83 | H26: 22.83 | I26: 22.83 | J26: 22.83 | K26: 22.83 | L26: 22.83 | M26: 22.83 | N26: 22.83 | O26: 22.83 | P26: 22.83 | Q26: 22.83 | R26: 22.83 | S26: 22.83 | T26: 22.83 | U26: 22.83 | V26: 22.83 | W26: 22.83 | X26: 22.83 | Y26: 22.83 | Z26: 22.83 | AA26: 22.83 | AB26: =SUM(D26:AA26) -> 547.92 | AC26: 7
B27: 48792 | C27: ORDINARIO | D27: 22.83 | E27: 22.83 | F27: 22.83 | G27: 22.83 | H27: 22.83 | I27: 22.83 | J27: 22.83 | K27: 22.83 | L27: 22.83 | M27: 22.83 | N27: 22.83 | O27: 22.83 | P27: 22.83 | Q27: 22.83 | R27: 22.83 | S27: 22.83 | T27: 22.83 | U27: 22.83 | V27: 22.83 | W27: 22.83 | X27: 22.83 | Y27: 22.83 | Z27: 22.83 | AA27: 22.83 | AB27: =SUM(D27:AA27) -> 547.92 | AC27: 22 | AD27: =+AB27*AC27+AB28*AC28+AB29*AC29 -> 16985.52
C28: SABADO | D28: 22.83 | E28: 22.83 | F28: 22.83 | G28: 22.83 | H28: 22.83 | I28: 22.83 | J28: 22.83 | K28: 22.83 | L28: 22.83 | M28: 22.83 | N28: 22.83 | O28: 22.83 | P28: 22.83 | Q28: 22.83 | R28: 22.83 | S28: 22.83 | T28: 22.83 | U28: 22.83 | V28: 22.83 | W28: 22.83 | X28: 22.83 | Y28: 22.83 | Z28: 22.83 | AA28: 22.83 | AB28: =SUM(D28:AA28) -> 547.92 | AC28: 4
C29: DOMINGO | D29: 22.83 | E29: 22.83 | F29: 22.83 | G29: 22.83 | H29: 22.83 | I29: 22.83 | J29: 22.83 | K29: 22.83 | L29: 22.83 | M29: 22.83 | N29: 22.83 | O29: 22.83 | P29: 22.83 | Q29: 22.83 | R29: 22.83 | S29: 22.83 | T29: 22.83 | U29: 22.83 | V29: 22.83 | W29: 22.83 | X29: 22.83 | Y29: 22.83 | Z29: 22.83 | AA29: 22.83 | AB29: =SUM(D29:AA29) -> 547.92 | AC29: 5
B30: 48823 | C30: ORDINARIO | D30: 22.83 | E30: 22.83 | F30: 22.83 | G30: 22.83 | H30: 22.83 | I30: 22.83 | J30: 22.83 | K30: 22.83 | L30: 22.83 | M30: 22.83 | N30: 22.83 | O30: 22.83 | P30: 22.83 | Q30: 22.83 | R30: 22.83 | S30: 22.83 | T30: 22.83 | U30: 22.83 | V30: 22.83 | W30: 22.83 | X30: 22.83 | Y30: 22.83 | Z30: 22.83 | AA30: 22.83 | AB30: =SUM(D30:AA30) -> 547.92 | AC30: 22 | AD30: =+AB30*AC30+AB31*AC31+AB32*AC32 -> 16437.6
C31: SABADO | D31: 22.83 | E31: 22.83 | F31: 22.83 | G31: 22.83 | H31: 22.83 | I31: 22.83 | J31: 22.83 | K31: 22.83 | L31: 22.83 | M31: 22.83 | N31: 22.83 | O31: 22.83 | P31: 22.83 | Q31: 22.83 | R31: 22.83 | S31: 22.83 | T31: 22.83 | U31: 22.83 | V31: 22.83 | W31: 22.83 | X31: 22.83 | Y31: 22.83 | Z31: 22.83 | AA31: 22.83 | AB31: =SUM(D31:AA31) -> 547.92 | AC31: 4
C32: DOMINGO | D32: 22.83 | E32: 22.83 | F32: 22.83 | G32: 22.83 | H32: 22.83 | I32: 22.83 | J32: 22.83 | K32: 22.83 | L32: 22.83 | M32: 22.83 | N32: 22.83 | O32: 22.83 | P32: 22.83 | Q32: 22.83 | R32: 22.83 | S32: 22.83 | T32: 22.83 | U32: 22.83 | V32: 22.83 | W32: 22.83 | X32: 22.83 | Y32: 22.83 | Z32: 22.83 | AA32: 22.83 | AB32: =SUM(D32:AA32) -> 547.92 | AC32: 4
B33: 48853 | C33: ORDINARIO | D33: 22.83 | E33: 22.83 | F33: 22.83 | G33: 22.83 | H33: 22.83 | I33: 22.83 | J33: 22.83 | K33: 22.83 | L33: 22.83 | M33: 22.83 | N33: 22.83 | O33: 22.83 | P33: 22.83 | Q33: 22.83 | R33: 22.83 | S33: 22.83 | T33: 22.83 | U33: 22.83 | V33: 22.83 | W33: 22.83 | X33: 22.83 | Y33: 22.83 | Z33: 22.83 | AA33: 22.83 | AB33: =SUM(D33:AA33) -> 547.92 | AC33: 19 | AD33: =+AB33*AC33+AB34*AC34+AB35*AC35 -> 16985.52
C34: SABADO | D34: 22.83 | E34: 22.83 | F34: 22.83 | G34: 22.83 | H34: 22.83 | I34: 22.83 | J34: 22.83 | K34: 22.83 | L34: 22.83 | M34: 22.83 | N34: 22.83 | O34: 22.83 | P34: 22.83 | Q34: 22.83 | R34: 22.83 | S34: 22.83 | T34: 22.83 | U34: 22.83 | V34: 22.83 | W34: 22.83 | X34: 22.83 | Y34: 22.83 | Z34: 22.83 | AA34: 22.83 | AB34: =SUM(D34:AA34) -> 547.92 | AC34: 5
C35: DOMINGO | D35: 22.83 | E35: 22.83 | F35: 22.83 | G35: 22.83 | H35: 22.83 | I35: 22.83 | J35: 22.83 | K35: 22.83 | L35: 22.83 | M35: 22.83 | N35: 22.83 | O35: 22.83 | P35: 22.83 | Q35: 22.83 | R35: 22.83 | S35: 22.83 | T35: 22.83 | U35: 22.83 | V35: 22.83 | W35: 22.83 | X35: 22.83 | Y35: 22.83 | Z35: 22.83 | AA35: 22.83 | AB35: =SUM(D35:AA35) -> 547.92 | AC35: 7
B36: 48884 | C36: ORDINARIO | D36: 22.83 | E36: 22.83 | F36: 22.83 | G36: 22.83 | H36: 22.83 | I36: 22.83 | J36: 22.83 | K36: 22.83 | L36: 22.83 | M36: 22.83 | N36: 22.83 | O36: 22.83 | P36: 22.83 | Q36: 22.83 | R36: 22.83 | S36: 22.83 | T36: 22.83 | U36: 22.83 | V36: 22.83 | W36: 22.83 | X36: 22.83 | Y36: 22.83 | Z36: 22.83 | AA36: 22.83 | AB36: =SUM(D36:AA36) -> 547.92 | AC36: 19 | AD36: =+AB36*AC36+AB37*AC37+AB38*AC38 -> 16437.6
C37: SABADO | D37: 22.83 | E37: 22.83 | F37: 22.83 | G37: 22.83 | H37: 22.83 | I37: 22.83 | J37: 22.83 | K37: 22.83 | L37: 22.83 | M37: 22.83 | N37: 22.83 | O37: 22.83 | P37: 22.83 | Q37: 22.83 | R37: 22.83 | S37: 22.83 | T37: 22.83 | U37: 22.83 | V37: 22.83 | W37: 22.83 | X37: 22.83 | Y37: 22.83 | Z37: 22.83 | AA37: 22.83 | AB37: =SUM(D37:AA37) -> 547.92 | AC37: 4
C38: DOMINGO | D38: 22.83 | E38: 22.83 | F38: 22.83 | G38: 22.83 | H38: 22.83 | I38: 22.83 | J38: 22.83 | K38: 22.83 | L38: 22.83 | M38: 22.83 | N38: 22.83 | O38: 22.83 | P38: 22.83 | Q38: 22.83 | R38: 22.83 | S38: 22.83 | T38: 22.83 | U38: 22.83 | V38: 22.83 | W38: 22.83 | X38: 22.83 | Y38: 22.83 | Z38: 22.83 | AA38: 22.83 | AB38: =SUM(D38:AA38) -> 547.92 | AC38: 7
B39: 48914 | C39: ORDINARIO | D39: 22.83 | E39: 22.83 | F39: 22.83 | G39: 22.83 | H39: 22.83 | I39: 22.83 | J39: 22.83 | K39: 22.83 | L39: 22.83 | M39: 22.83 | N39: 22.83 | O39: 22.83 | P39: 22.83 | Q39: 22.83 | R39: 22.83 | S39: 22.83 | T39: 22.83 | U39: 22.83 | V39: 22.83 | W39: 22.83 | X39: 22.83 | Y39: 22.83 | Z39: 22.83 | AA39: 22.83 | AB39: =SUM(D39:AA39) -> 547.92 | AC39: 21 | AD39: =+AB39*AC39+AB40*AC40+AB41*AC41 -> 16985.52
C40: SABADO | D40: 22.83 | E40: 22.83 | F40: 22.83 | G40: 22.83 | H40: 22.83 | I40: 22.83 | J40: 22.83 | K40: 22.83 | L40: 22.83 | M40: 22.83 | N40: 22.83 | O40: 22.83 | P40: 22.83 | Q40: 22.83 | R40: 22.83 | S40: 22.83 | T40: 22.83 | U40: 22.83 | V40: 22.83 | W40: 22.83 | X40: 22.83 | Y40: 22.83 | Z40: 22.83 | AA40: 22.83 | AB40: =SUM(D40:AA40) -> 547.92 | AC40: 5
C41: DOMINGO | D41: 22.83 | E41: 22.83 | F41: 22.83 | G41: 22.83 | H41: 22.83 | I41: 22.83 | J41: 22.83 | K41: 22.83 | L41: 22.83 | M41: 22.83 | N41: 22.83 | O41: 22.83 | P41: 22.83 | Q41: 22.83 | R41: 22.83 | S41: 22.83 | T41: 22.83 | U41: 22.83 | V41: 22.83 | W41: 22.83 | X41: 22.83 | Y41: 22.83 | Z41: 22.83 | AA41: 22.83 | AB41: =SUM(D41:AA41) -> 547.92 | AC41: 5
...

Sheet P4_ANEXO_2 - 2033 al 2037
D2: EMPRESAS MUNICIPALES DE CALI- EMCALI EICE ESP
D3: CONVOCATORIA PÚBLICA PARA COMPRA DE ENERGÍA
D4: Código de Convocatoria SICEP No. CP-EMIC2026-001
D6: ANEXO No. 2 CANTIDADES Y PRECIOS OFERTADOS
D8: PRODUCTO 4 - ENERO 2033 A DICIEMBRE 2037
D11: AÑO | E11: Energía solicitada (MWh) | F11: % ofertado | G11: $/kWh
D12: 2033 | E12: ='P4_ANEXO 1 -2033 a 2037'!AD42 -> 199990.8
D13: 2034 | E13: ='P4_ANEXO 1 -2033 a 2037'!AD82 -> 199990.8
D14: 2035 | E14: ='P4_ANEXO 1 -2033 a 2037'!AD122 -> 199990.8
D15: 2036 | E15: ='P4_ANEXO 1 -2033 a 2037'!AD162 -> 200538.72
D16: 2037 | E16: ='P4_ANEXO 1 -2033 a 2037'!AD202 -> 199990.8
D17: Total año | E17: =SUM(E12:E16) -> 1000501.9
C20: NOTAS:
C21: 1 | D21: Se debe ofertar el mismo porcentaje de la cantidad solicitada para todos los años
C22: 2 | D22: Se debe ofertar mínimo el 30% de la energía solicitada
C23: 3 | D23: La energía y los precios a ofertar deben ofrecerse en la modalidad monomia.
C24: 4 | D24: Precios en pesos constantes del mes de mayo de 2026.

Sheet P5_ANEXO 1 -2028 a 2037
B1: ANEXO No. 1 - CANTIDADES DE ENERGÍA HORARIA Y MENSUAL A CONTRATAR
B2: PRODUCTO 5 - ENERO 2027 A DICIEMBRE 2037
B4: ENERGÍA CURVA A SOLICITAR AÑO 2028 PARA MERCADO REGULADO (MWh)
B5: MES | C5: DÍA | D5: H1 | E5: H2 | F5: H3 | G5: H4 | H5: H5 | I5: H6 | J5: H7 | K5: H8 | L5: H9 | M5: H10 | N5: H11 | O5: H12 | P5: H13 | Q5: H14 | R5: H15 | S5: H16 | T5: H17 | U5: H18 | V5: H19 | W5: H20 | X5: H21 | Y5: H22 | Z5: H23 | AA5: H24 | AB5: TOTAL | AC5: No. Dias | AD5: TOTAL MES
B6: 46753 | C6: ORDINARIO | D6: 16.03 | E6: 13.1 | F6: 0 | G6: 0 | H6: 0 | I6: 0 | J6: 0.28 | K6: 0 | L6: 3.59 | M6: 12.66 | N6: 18.38 | O6: 31.43 | P6: 36.86 | Q6: 36 | R6: 52.7 | S6: 54.15 | T6: 57.11 | U6: 82.43 | V6: 88.91 | W6: 95.76 | X6: 84.76 | Y6: 81.81 | Z6: 57.67 | AA6: 41.1 | AB6: =SUM(D6:AA6) -> 864.73 | AC6: 20 | AD6: =+AB6*AC6+AB7*AC7+AB8*AC8 -> 26806.63
C7: SABADO | D7: 16.03 | E7: 13.1 | F7: 0 | G7: 0 | H7: 0 | I7: 0 | J7: 0.28 | K7: 0 | L7: 3.59 | M7: 12.66 | N7: 18.38 | O7: 31.43 | P7: 36.86 | Q7: 36 | R7: 52.7 | S7: 54.15 | T7: 57.11 | U7: 82.43 | V7: 88.91 | W7: 95.76 | X7: 84.76 | Y7: 81.81 | Z7: 57.67 | AA7: 41.1 | AB7: =SUM(D7:AA7) -> 864.73 | AC7: 4
C8: DOMINGO | D8: 16.03 | E8: 13.1 | F8: 0 | G8: 0 | H8: 0 | I8: 0 | J8: 0.28 | K8: 0 | L8: 3.59 | M8: 12.66 | N8: 18.38 | O8: 31.43 | P8: 36.86 | Q8: 36 | R8: 52.7 | S8: 54.15 | T8: 57.11 | U8: 82.43 | V8: 88.91 | W8: 95.76 | X8: 84.76 | Y8: 81.81 | Z8: 57.67 | AA8: 41.1 | AB8: =SUM(D8:AA8) -> 864.73 | AC8: 7
B9: 46784 | C9: ORDINARIO | D9: 16.03 | E9: 13.1 | F9: 0 | G9: 0 | H9: 0 | I9: 0 | J9: 0.28 | K9: 0 | L9: 3.59 | M9: 12.66 | N9: 18.38 | O9: 31.43 | P9: 36.86 | Q9: 36 | R9: 52.7 | S9: 54.15 | T9: 57.11 | U9: 82.43 | V9: 88.91 | W9: 95.76 | X9: 84.76 | Y9: 81.81 | Z9: 57.67 | AA9: 41.1 | AB9: =SUM(D9:AA9) -> 864.73 | AC9: 21 | AD9: =+AB9*AC9+AB10*AC10+AB11*AC11 -> 25077.17
C10: SABADO | D10: 16.03 | E10: 13.1 | F10: 0 | G10: 0 | H10: 0 | I10: 0 | J10: 0.28 | K10: 0 | L10: 3.59 | M10: 12.66 | N10: 18.38 | O10: 31.43 | P10: 36.86 | Q10: 36 | R10: 52.7 | S10: 54.15 | T10: 57.11 | U10: 82.43 | V10: 88.91 | W10: 95.76 | X10: 84.76 | Y10: 81.81 | Z10: 57.67 | AA10: 41.1 | AB10: =SUM(D10:AA10) -> 864.73 | AC10: 4
C11: DOMINGO | D11: 16.03 | E11: 13.1 | F11: 0 | G11: 0 | H11: 0 | I11: 0 | J11: 0.28 | K11: 0 | L11: 3.59 | M11: 12.66 | N11: 18.38 | O11: 31.43 | P11: 36.86 | Q11: 36 | R11: 52.7 | S11: 54.15 | T11: 57.11 | U11: 82.43 | V11: 88.91 | W11: 95.76 | X11: 84.76 | Y11: 81.81 | Z11: 57.67 | AA11: 41.1 | AB11: =SUM(D11:AA11) -> 864.73 | AC11: 4
B12: 46813 | C12: ORDINARIO | D12: 16.03 | E12: 13.1 | F12: 0 | G12: 0 | H12: 0 | I12: 0 | J12: 0.28 | K12: 0 | L12: 3.59 | M12: 12.66 | N12: 18.38 | O12: 31.43 | P12: 36.86 | Q12: 36 | R12: 52.7 | S12: 54.15 | T12: 57.11 | U12: 82.43 | V12: 88.91 | W12: 95.76 | X12: 84.76 | Y12: 81.81 | Z12: 57.67 | AA12: 41.1 | AB12: =SUM(D12:AA12) -> 864.73 | AC12: 22 | AD12: =+AB12*AC12+AB13*AC13+AB14*AC14 -> 26806.63
C13: SABADO | D13: 16.03 | E13: 13.1 | F13: 0 | G13: 0 | H13: 0 | I13: 0 | J13: 0.28 | K13: 0 | L13: 3.59 | M13: 12.66 | N13: 18.38 | O13: 31.43 | P13: 36.86 | Q13: 36 | R13: 52.7 | S13: 54.15 | T13: 57.11 | U13: 82.43 | V13: 88.91 | W13: 95.76 | X13: 84.76 | Y13: 81.81 | Z13: 57.67 | AA13: 41.1 | AB13: =SUM(D13:AA13) -> 864.73 | AC13: 4
C14: DOMINGO | D14: 16.03 | E14: 13.1 | F14: 0 | G14: 0 | H14: 0 | I14: 0 | J14: 0.28 | K14: 0 | L14: 3.59 | M14: 12.66 | N14: 18.38 | O14: 31.43 | P14: 36.86 | Q14: 36 | R14: 52.7 | S14: 54.15 | T14: 57.11 | U14: 82.43 | V14: 88.91 | W14: 95.76 | X14: 84.76 | Y14: 81.81 | Z14: 57.67 | AA14: 41.1 | AB14: =SUM(D14:AA14) -> 864.73 | AC14: 5
B15: 46844 | C15: ORDINARIO | D15: 16.03 | E15: 13.1 | F15: 0 | G15: 0 | H15: 0 | I15: 0 | J15: 0.28 | K15: 0 | L15: 3.59 | M15: 12.66 | N15: 18.38 | O15: 31.43 | P15: 36.86 | Q15: 36 | R15: 52.7 | S15: 54.15 | T15: 57.11 | U15: 82.43 | V15: 88.91 | W15: 95.76 | X15: 84.76 | Y15: 81.81 | Z15: 57.67 | AA15: 41.1 | AB15: =SUM(D15:AA15) -> 864.73 | AC15: 18 | AD15: =+AB15*AC15+AB16*AC16+AB17*AC17 -> 25941.9
C16: SABADO | D16: 16.03 | E16: 13.1 | F16: 0 | G16: 0 | H16: 0 | I16: 0 | J16: 0.28 | K16: 0 | L16: 3.59 | M16: 12.66 | N16: 18.38 | O16: 31.43 | P16: 36.86 | Q16: 36 | R16: 52.7 | S16: 54.15 | T16: 57.11 | U16: 82.43 | V16: 88.91 | W16: 95.76 | X16: 84.76 | Y16: 81.81 | Z16: 57.67 | AA16: 41.1 | AB16: =SUM(D16:AA16) -> 864.73 | AC16: 5
C17: DOMINGO | D17: 16.03 | E17: 13.1 | F17: 0 | G17: 0 | H17: 0 | I17: 0 | J17: 0.28 | K17: 0 | L17: 3.59 | M17: 12.66 | N17: 18.38 | O17: 31.43 | P17: 36.86 | Q17: 36 | R17: 52.7 | S17: 54.15 | T17: 57.11 | U17: 82.43 | V17: 88.91 | W17: 95.76 | X17: 84.76 | Y17: 81.81 | Z17: 57.67 | AA17: 41.1 | AB17: =SUM(D17:AA17) -> 864.73 | AC17: 7
B18: 46874 | C18: ORDINARIO | D18: 16.03 | E18: 13.1 | F18: 0 | G18: 0 | H18: 0 | I18: 0 | J18: 0.28 | K18: 0 | L18: 3.59 | M18: 12.66 | N18: 18.38 | O18: 31.43 | P18: 36.86 | Q18: 36 | R18: 52.7 | S18: 54.15 | T18: 57.11 | U18: 82.43 | V18: 88.91 | W18: 95.76 | X18: 84.76 | Y18: 81.81 | Z18: 57.67 | AA18: 41.1 | AB18: =SUM(D18:AA18) -> 864.73 | AC18: 21 | AD18: =+AB18*AC18+AB19*AC19+AB20*AC20 -> 26806.63
C19: SABADO | D19: 16.03 | E19: 13.1 | F19: 0 | G19: 0 | H19: 0 | I19: 0 | J19: 0.28 | K19: 0 | L19: 3.59 | M19: 12.66 | N19: 18.38 | O19: 31.43 | P19: 36.86 | Q19: 36 | R19: 52.7 | S19: 54.15 | T19: 57.11 | U19: 82.43 | V19: 88.91 | W19: 95.76 | X19: 84.76 | Y19: 81.81 | Z19: 57.67 | AA19: 41.1 | AB19: =SUM(D19:AA19) -> 864.73 | AC19: 4
C20: DOMINGO | D20: 16.03 | E20: 13.1 | F20: 0 | G20: 0 | H20: 0 | I20: 0 | J20: 0.28 | K20: 0 | L20: 3.59 | M20: 12.66 | N20: 18.38 | O20: 31.43 | P20: 36.86 | Q20: 36 | R20: 52.7 | S20: 54.15 | T20: 57.11 | U20: 82.43 | V20: 88.91 | W20: 95.76 | X20: 84.76 | Y20: 81.81 | Z20: 57.67 | AA20: 41.1 | AB20: =SUM(D20:AA20) -> 864.73 | AC20: 6
B21: 46905 | C21: ORDINARIO | D21: 16.03 | E21: 13.1 | F21: 0 | G21: 0 | H21: 0 | I21: 0 | J21: 0.28 | K21: 0 | L21: 3.59 | M21: 12.66 | N21: 18.38 | O21: 31.43 | P21: 36.86 | Q21: 36 | R21: 52.7 | S21: 54.15 | T21: 57.11 | U21: 82.43 | V21: 88.91 | W21: 95.76 | X21: 84.76 | Y21: 81.81 | Z21: 57.67 | AA21: 41.1 | AB21: =SUM(D21:AA21) -> 864.73 | AC21: 20 | AD21: =+AB21*AC21+AB22*AC22+AB23*AC23 -> 25941.9
C22: SABADO | D22: 16.03 | E22: 13.1 | F22: 0 | G22: 0 | H22: 0 | I22: 0 | J22: 0.28 | K22: 0 | L22: 3.59 | M22: 12.66 | N22: 18.38 | O22: 31.43 | P22: 36.86 | Q22: 36 | R22: 52.7 | S22: 54.15 | T22: 57.11 | U22: 82.43 | V22: 88.91 | W22: 95.76 | X22: 84.76 | Y22: 81.81 | Z22: 57.67 | AA22: 41.1 | AB22: =SUM(D22:AA22) -> 864.73 | AC22: 4
C23: DOMINGO | D23: 16.03 | E23: 13.1 | F23: 0 | G23: 0 | H23: 0 | I23: 0 | J23: 0.28 | K23: 0 | L23: 3.59 | M23: 12.66 | N23: 18.38 | O23: 31.43 | P23: 36.86 | Q23: 36 | R23: 52.7 | S23: 54.15 | T23: 57.11 | U23: 82.43 | V23: 88.91 | W23: 95.76 | X23: 84.76 | Y23: 81.81 | Z23: 57.67 | AA23: 41.1 | AB23: =SUM(D23:AA23) -> 864.73 | AC23: 6
B24: 46935 | C24: ORDINARIO | D24: 16.03 | E24: 13.1 | F24: 0 | G24: 0 | H24: 0 | I24: 0 | J24: 0.28 | K24: 0 | L24: 3.59 | M24: 12.66 | N24: 18.38 | O24: 31.43 | P24: 36.86 | Q24: 36 | R24: 52.7 | S24: 54.15 | T24: 57.11 | U24: 82.43 | V24: 88.91 | W24: 95.76 | X24: 84.76 | Y24: 81.81 | Z24: 57.67 | AA24: 41.1 | AB24: =SUM(D24:AA24) -> 864.73 | AC24: 19 | AD24: =+AB24*AC24+AB25*AC25+AB26*AC26 -> 26806.63
