Workbook

Sheet Oferta Producto No. 1
D2: ANEXO No. 1 OFERTAS Y CANTIDADES
C3: OFERTA MERCANTIL IRREVOCABLE A LA EMPRESA DE ENERGIA DE PEREIRA S.A. ESP. INVITACIÓN PARA EL SUMINISTRO DE ENERGÍA ELÉCTRICA CON DESTINO AL MERCADO REGULADO CONVOCATORIA PÚBLICA No. 004-2025 - CP-EEPC2025-004
D4: PRODUCTO No. 1
C6: EMPRESA: XXXXXXXXXXXXXXXXXXXXXXXXXXXXXX
C7: REPRESENTANTE LEGAL: XXXXXXXXXXXXXXXXXXXXXXXXXXXXXX
C8: TIPO DE AGENTE: (COMERCIALIZADOR/GENERADOR)
C9: ="PRODUCTO OFERTADO: "&D4 -> PRODUCTO OFERTADO: PRODUCTO No. 1
C11: Las tarifas ofertadas están referidas en pesos constantes de abril de 2025 provisional
F13: ="Oferta " & PROPER(D4) -> Oferta Producto No. 1
F14: Periodo | G14: Energía requerida (MWh-mes) | H14: Energía ofertada (%) | I14: Energía ofertada (MWh-mes) | J14: Tarifa monomia ($/kWh)
A15: 22.85 | B15: 31 | F15: =+'Cantidades Producto No. 1'!A72 -> 46023 | G15: =+'Cantidades Producto No. 1'!AB72 -> 9248.09
B16: 28 | F16: =+'Cantidades Producto No. 1'!A73 -> 46054 | G16: =+'Cantidades Producto No. 1'!AB73 -> 8346.08
B17: 31 | F17: =+'Cantidades Producto No. 1'!A74 -> 46082 | G17: =+'Cantidades Producto No. 1'!AB74 -> 9252.47
B18: 30 | F18: =+'Cantidades Producto No. 1'!A75 -> 46113 | G18: =+'Cantidades Producto No. 1'!AB75 -> 8898.28
B19: 31 | F19: =+'Cantidades Producto No. 1'!A76 -> 46143 | G19: =+'Cantidades Producto No. 1'!AB76 -> 9175.74
B20: 30 | F20: =+'Cantidades Producto No. 1'!A77 -> 46174 | G20: =+'Cantidades Producto No. 1'!AB77 -> 8791.42
B21: 31 | F21: =+'Cantidades Producto No. 1'!A78 -> 46204 | G21: =+'Cantidades Producto No. 1'!AB78 -> 9200.37
B22: 31 | F22: =+'Cantidades Producto No. 1'!A79 -> 46235 | G22: =+'Cantidades Producto No. 1'!AB79 -> 9151.28
B23: 30 | F23: =+'Cantidades Producto No. 1'!A80 -> 46266 | G23: =+'Cantidades Producto No. 1'!AB80 -> 8891.64
B24: 31 | F24: =+'Cantidades Producto No. 1'!A81 -> 46296 | G24: =+'Cantidades Producto No. 1'!AB81 -> 9147.02
B25: 30 | F25: =+'Cantidades Producto No. 1'!A82 -> 46327 | G25: =+'Cantidades Producto No. 1'!AB82 -> 8834
B26: 31 | F26: =+'Cantidades Producto No. 1'!A83 -> 46357 | G26: =+'Cantidades Producto No. 1'!AB83 -> 9347.76
F27: TOTAL | G27: =SUM(G15:G26) -> 108284.15
B29: Notas
B31: (1) Oferta válida para la modalidad Pague lo Contratado.
B32: ="(2) Las cantidades se distribuyen de acuerdo a la curva del Anexo 1. Ofertas y Cantidades "& D4 &" de los Pliegos de Condiciones definitivos" -> (2) Las cantidades se distribuyen de acuerdo a la curva del Anexo 1. Ofertas y Cantidades PRODUCTO No. 1 de los Pliegos de Condiciones definitivos
B33: (3) La cantidad de energía es equivalente a un porcentaje de las cantidades de energía requerida por la Empresa de Energía de Pereira S.A. ESP. (para todo el año/para cada mes), de acuerdo con el Anexo No.1 Ofertas y Cantidades PRODUCTO No. 1 de los Pliegos definitivos, que se aplicarán para todas las 24 horas del día de la curva establecida en dicho Anexo, presentando una tarifa para cada año sin ningún tipo de discriminación por mes, ni tipo de carga ni tipo de día.
B34: (4) Esta oferta NO presenta restricciones tales como adjudicación mínima o total u otras que no permitan la evaluación objetiva e integral del producto ofertado.
B35: (5) Los precios ofertados incluyen todos los pagos, cargos, impuestos, estampillas, etc., que el Proponente deba realizar ante cualquier entidad gubernamental, o empresa pública, privada o mixta para entregar la energía en la frontera con el Sistema de Transmisión Nacional – STN.
B36: (6) Las cantidades ofertadas están sujetas a la adjudicación en la misma proporción respecto a las cantidades ofertadas para todos y cada uno de los meses del año. Es decir, si la Empresa de Energía de Pereira decide adjudicar, por ejemplo, el 50% de lo ofertado en cualesquiera de los meses de alguno de los años, ese mismo porcentaje debe ser adjudicado en el resto de cada uno de los meses de ese año.

Sheet Cantidades Producto No. 1
A2: EMPRESA DE ENERGÍA DE PEREIRA S.A. E.S.P.
A3: PRODUCTO No. 1
A5: DEMANDA DIARIA ESTIMADA DÍA HABIL [MWh]
A7: MES | B7: H1 | C7: H2 | D7: H3 | E7: H4 | F7: H5 | G7: H6 | H7: H7 | I7: H8 | J7: H9 | K7: H10 | L7: H11 | M7: H12 | N7: H13 | O7: H14 | P7: H15 | Q7: H16 | R7: H17 | S7: H18 | T7: H19 | U7: H20 | V7: H21 | W7: H22 | X7: H23 | Y7: H24 | Z7: TOTAL | AA7: Días
A8: 46023 | B8: 9.32 | C8: 8.39 | D8: 7.89 | E8: 7.71 | F8: 8.02 | G8: 9.1 | H8: 11.04 | I8: 9.18 | J8: 11.1 | K8: 12.56 | L8: 13.98 | M8: 15.31 | N8: 15.34 | O8: 15.09 | P8: 15.34 | Q8: 15.26 | R8: 14.83 | S8: 18.36 | T8: 18.7 | U8: 19.19 | V8: 18.26 | W8: 16.74 | X8: 14.41 | Y8: 11.78 | Z8: =SUM(B8:Y8) -> 316.9 | AA8: 20 | AB8: =+Z8*AA8 -> 6338 | AD8: HABIL
A9: 46054 | B9: 8.99 | C9: 8.17 | D9: 7.72 | E9: 7.59 | F9: 8.04 | G9: 9.79 | H9: 11.9 | I9: 9.8 | J9: 11.37 | K9: 12.64 | L9: 13.94 | M9: 15.13 | N9: 14.74 | O9: 14.69 | P9: 15.13 | Q9: 15.17 | R9: 14.78 | S9: 17.67 | T9: 17.49 | U9: 18.27 | V9: 17.63 | W9: 16.15 | X9: 13.77 | Y9: 11.25 | Z9: =SUM(B9:Y9) -> 311.82 | AA9: 20 | AB9: =+Z9*AA9 -> 6236.4 | AD9: HABIL
A10: 46082 | B10: 9 | C10: 8.17 | D10: 7.76 | E10: 7.6 | F10: 8.08 | G10: 9.87 | H10: 11.93 | I10: 9.98 | J10: 11.62 | K10: 12.82 | L10: 14.17 | M10: 15.32 | N10: 15.08 | O10: 14.86 | P10: 15.22 | Q10: 15.13 | R10: 14.8 | S10: 18.12 | T10: 18.1 | U10: 18.96 | V10: 18.01 | W10: 16.45 | X10: 14.02 | Y10: 11.43 | Z10: =SUM(B10:Y10) -> 316.5 | AA10: 21 | AB10: =+Z10*AA10 -> 6646.5 | AD10: HABIL
A11: 46113 | B11: 8.99 | C11: 8.13 | D11: 7.72 | E11: 7.56 | F11: 8.04 | G11: 9.62 | H11: 11.72 | I11: 9.95 | J11: 11.42 | K11: 13.06 | L11: 14.27 | M11: 15.4 | N11: 15.18 | O11: 14.78 | P11: 14.72 | Q11: 14.78 | R11: 14.5 | S11: 18.16 | T11: 18.43 | U11: 18.92 | V11: 17.91 | W11: 16.33 | X11: 13.93 | Y11: 11.46 | Z11: =SUM(B11:Y11) -> 314.98 | AA11: 20 | AB11: =+Z11*AA11 -> 6299.6 | AD11: HABIL
A12: 46143 | B12: 9 | C12: 8.16 | D12: 7.73 | E12: 7.54 | F12: 8.04 | G12: 9.5 | H12: 11.76 | I12: 9.89 | J12: 11.64 | K12: 13 | L12: 14.39 | M12: 15.66 | N12: 15.37 | O12: 15 | P12: 15.19 | Q12: 15.05 | R12: 14.49 | S12: 18.26 | T12: 18.5 | U12: 18.89 | V12: 17.88 | W12: 16.16 | X12: 13.69 | Y12: 11.27 | Z12: =SUM(B12:Y12) -> 316.06 | AA12: 19 | AB12: =+Z12*AA12 -> 6005.14 | AD12: HABIL
A13: 46174 | B13: 8.88 | C13: 8.02 | D13: 7.52 | E13: 7.35 | F13: 7.83 | G13: 9.15 | H13: 11.56 | I13: 9.91 | J13: 11.66 | K13: 13.01 | L13: 14.24 | M13: 15.49 | N13: 15.33 | O13: 14.86 | P13: 14.87 | Q13: 14.75 | R13: 14.44 | S13: 18.11 | T13: 18.32 | U13: 19.13 | V13: 18.1 | W13: 16.3 | X13: 13.67 | Y13: 11.24 | Z13: =SUM(B13:Y13) -> 313.74 | AA13: 19 | AB13: =+Z13*AA13 -> 5961.06 | AD13: HABIL
A14: 46204 | B14: 8.69 | C14: 7.94 | D14: 7.46 | E14: 7.29 | F14: 7.77 | G14: 9.16 | H14: 11.33 | I14: 9.67 | J14: 11.48 | K14: 12.9 | L14: 14.12 | M14: 15.46 | N14: 15.19 | O14: 14.8 | P14: 14.97 | Q14: 15.03 | R14: 14.75 | S14: 18.11 | T14: 17.93 | U14: 18.95 | V14: 17.92 | W14: 16.17 | X14: 13.53 | Y14: 11.32 | Z14: =SUM(B14:Y14) -> 311.94 | AA14: 22 | AB14: =+Z14*AA14 -> 6862.68 | AD14: HABIL
A15: 46235 | B15: 8.9 | C15: 8.07 | D15: 7.62 | E15: 7.47 | F15: 7.95 | G15: 9.56 | H15: 11.71 | I15: 9.95 | J15: 11.68 | K15: 12.96 | L15: 14.4 | M15: 15.7 | N15: 15.44 | O15: 15.12 | P15: 15.28 | Q15: 15.18 | R15: 14.86 | S15: 18.24 | T15: 18.22 | U15: 19 | V15: 17.9 | W15: 16.16 | X15: 13.47 | Y15: 11.25 | Z15: =SUM(B15:Y15) -> 316.09 | AA15: 19 | AB15: =+Z15*AA15 -> 6005.71 | AD15: HABIL
A16: 46266 | B16: 8.77 | C16: 7.93 | D16: 7.5 | E16: 7.36 | F16: 7.87 | G16: 9.44 | H16: 11.63 | I16: 9.79 | J16: 11.01 | K16: 12.45 | L16: 14.08 | M16: 15.3 | N16: 15 | O16: 14.67 | P16: 14.94 | Q16: 14.89 | R16: 14.53 | S16: 18.01 | T16: 18.51 | U16: 18.49 | V16: 17.38 | W16: 15.71 | X16: 13.15 | Y16: 10.95 | Z16: =SUM(B16:Y16) -> 309.36 | AA16: 22 | AB16: =+Z16*AA16 -> 6805.92 | AD16: HABIL
A17: 46296 | B17: 8.68 | C17: 7.82 | D17: 7.42 | E17: 7.29 | F17: 7.66 | G17: 8.5 | H17: 10.86 | I17: 9.45 | J17: 11.43 | K17: 12.97 | L17: 14.41 | M17: 15.59 | N17: 15.38 | O17: 15.07 | P17: 15.24 | Q17: 14.99 | R17: 14.67 | S17: 18.49 | T17: 18.99 | U17: 18.39 | V17: 17.31 | W17: 15.63 | X17: 13.3 | Y17: 11.1 | Z17: =SUM(B17:Y17) -> 310.64 | AA17: 21 | AB17: =+Z17*AA17 -> 6523.44 | AD17: HABIL
A18: 46327 | B18: 8.91 | C18: 8.05 | D18: 7.58 | E18: 7.43 | F18: 7.8 | G18: 8.87 | H18: 11.11 | I18: 9.73 | J18: 11.57 | K18: 12.88 | L18: 14.18 | M18: 15.38 | N18: 15.26 | O18: 14.96 | P18: 15.34 | Q18: 15.18 | R18: 14.85 | S18: 18.86 | T18: 19.18 | U18: 18.67 | V18: 17.62 | W18: 15.95 | X18: 13.54 | Y18: 11.27 | Z18: =SUM(B18:Y18) -> 314.17 | AA18: 19 | AB18: =+Z18*AA18 -> 5969.23 | AD18: HABIL
A19: 46357 | B19: 9.52 | C19: 8.5 | D19: 7.95 | E19: 7.73 | F19: 8 | G19: 8.87 | H19: 10.94 | I19: 9.57 | J19: 11.56 | K19: 12.87 | L19: 14.14 | M19: 15.29 | N19: 15.35 | O19: 15.14 | P19: 15.31 | Q19: 15.16 | R19: 14.7 | S19: 18.2 | T19: 18.88 | U19: 18.81 | V19: 17.8 | W19: 16.41 | X19: 14.35 | Y19: 12.17 | Z19: =SUM(B19:Y19) -> 317.22 | AA19: 21 | AB19: =+Z19*AA19 -> 6661.62 | AD19: HABIL
A21: DEMANDA DIARIA ESTIMADA DÍA SABADO [MWh]
A23: MES | B23: H1 | C23: H2 | D23: H3 | E23: H4 | F23: H5 | G23: H6 | H23: H7 | I23: H8 | J23: H9 | K23: H10 | L23: H11 | M23: H12 | N23: H13 | O23: H14 | P23: H15 | Q23: H16 | R23: H17 | S23: H18 | T23: H19 | U23: H20 | V23: H21 | W23: H22 | X23: H23 | Y23: H24 | Z23: TOTAL | AA23: Días
A24: =+A8 -> 46023 | B24: 9.45 | C24: 8.47 | D24: 7.89 | E24: 7.58 | F24: 7.69 | G24: 8.27 | H24: 9.76 | I24: 7.96 | J24: 10 | K24: 11.78 | L24: 12.96 | M24: 13.98 | N24: 14.13 | O24: 13.54 | P24: 13.04 | Q24: 12.84 | R24: 12.47 | S24: 16.7 | T24: 17.42 | U24: 17.75 | V24: 16.75 | W24: 15.36 | X24: 13.56 | Y24: 11.71 | Z24: =SUM(B24:Y24) -> 291.06 | AA24: 5 | AB24: =+Z24*AA24 -> 1455.3 | AD24: SABADOS
A25: =+A9 -> 46054 | B25: 9.05 | C25: 8.18 | D25: 7.68 | E25: 7.42 | F25: 7.56 | G25: 8.35 | H25: 10.06 | I25: 8.35 | J25: 10.3 | K25: 11.72 | L25: 12.87 | M25: 13.59 | N25: 13.59 | O25: 13.22 | P25: 12.91 | Q25: 12.71 | R25: 12.49 | S25: 16.19 | T25: 16.45 | U25: 17.34 | V25: 16.47 | W25: 15.24 | X25: 13.45 | Y25: 11.69 | Z25: =SUM(B25:Y25) -> 286.88 | AA25: 4 | AB25: =+Z25*AA25 -> 1147.52 | AD25: SABADOS
A26: =+A10 -> 46082 | B26: 9.1 | C26: 8.18 | D26: 7.67 | E26: 7.41 | F26: 7.64 | G26: 8.4 | H26: 9.94 | I26: 8.41 | J26: 10.49 | K26: 11.85 | L26: 12.99 | M26: 14.07 | N26: 14.04 | O26: 13.35 | P26: 12.88 | Q26: 12.64 | R26: 12.4 | S26: 16.58 | T26: 16.75 | U26: 17.15 | V26: 16.24 | W26: 15.02 | X26: 13.21 | Y26: 11.42 | Z26: =SUM(B26:Y26) -> 287.83 | AA26: 4 | AB26: =+Z26*AA26 -> 1151.32 | AD26: SABADOS
A27: =+A11 -> 46113 | B27: 9.22 | C27: 8.24 | D27: 7.67 | E27: 7.38 | F27: 7.53 | G27: 7.93 | H27: 9.72 | I27: 8.29 | J27: 10.27 | K27: 11.81 | L27: 12.97 | M27: 13.9 | N27: 13.98 | O27: 13.26 | P27: 12.88 | Q27: 12.66 | R27: 12.25 | S27: 16.35 | T27: 16.89 | U27: 17.4 | V27: 16.49 | W27: 15.19 | X27: 13.46 | Y27: 11.68 | Z27: =SUM(B27:Y27) -> 287.42 | AA27: 4 | AB27: =+Z27*AA27 -> 1149.68 | AD27: SABADOS
A28: =+A12 -> 46143 | B28: 8.99 | C28: 8.12 | D28: 7.62 | E28: 7.36 | F28: 7.56 | G28: 8.01 | H28: 10.04 | I28: 8.64 | J28: 10.7 | K28: 12.39 | L28: 13.46 | M28: 14.34 | N28: 14.15 | O28: 13.3 | P28: 12.97 | Q28: 12.71 | R28: 12.34 | S28: 16.54 | T28: 17.14 | U28: 17.68 | V28: 16.64 | W28: 15.33 | X28: 13.51 | Y28: 11.66 | Z28: =SUM(B28:Y28) -> 291.2 | AA28: 5 | AB28: =+Z28*AA28 -> 1456 | AD28: SABADOS
A29: =+A13 -> 46174 | B29: 8.95 | C29: 8.02 | D29: 7.5 | E29: 7.26 | F29: 7.45 | G29: 8.08 | H29: 9.77 | I29: 8.34 | J29: 10.41 | K29: 12.05 | L29: 13.08 | M29: 14.08 | N29: 14.21 | O29: 13.6 | P29: 13.02 | Q29: 12.57 | R29: 12.19 | S29: 16.33 | T29: 16.96 | U29: 17.47 | V29: 16.42 | W29: 15.02 | X29: 13.11 | Y29: 11.17 | Z29: =SUM(B29:Y29) -> 287.06 | AA29: 4 | AB29: =+Z29*AA29 -> 1148.24 | AD29: SABADOS
A30: =+A14 -> 46204 | B30: 9.09 | C30: 8.1 | D30: 7.46 | E30: 7.23 | F30: 7.39 | G30: 7.8 | H30: 9.59 | I30: 8.09 | J30: 10.28 | K30: 11.96 | L30: 13.05 | M30: 14.08 | N30: 14.22 | O30: 13.53 | P30: 12.87 | Q30: 12.33 | R30: 12 | S30: 16.14 | T30: 16.43 | U30: 17.42 | V30: 16.37 | W30: 15.1 | X30: 13.33 | Y30: 11.47 | Z30: =SUM(B30:Y30) -> 285.33 | AA30: 4 | AB30: =+Z30*AA30 -> 1141.32 | AD30: SABADOS
A31: =+A15 -> 46235 | B31: 9.27 | C31: 8.34 | D31: 7.77 | E31: 7.47 | F31: 7.67 | G31: 8.24 | H31: 10.09 | I31: 8.5 | J31: 10.54 | K31: 12.12 | L31: 13.24 | M31: 14.2 | N31: 14.23 | O31: 13.51 | P31: 12.93 | Q31: 12.38 | R31: 11.98 | S31: 15.97 | T31: 16.46 | U31: 17.17 | V31: 16.21 | W31: 14.96 | X31: 13.22 | Y31: 11.35 | Z31: =SUM(B31:Y31) -> 287.82 | AA31: 5 | AB31: =+Z31*AA31 -> 1439.1 | AD31: SABADOS
A32: =+A16 -> 46266 | B32: 8.82 | C32: 7.95 | D32: 7.43 | E32: 7.13 | F32: 7.34 | G32: 7.86 | H32: 9.69 | I32: 8.44 | J32: 10.47 | K32: 11.9 | L32: 13.14 | M32: 14.14 | N32: 13.7 | O32: 13.41 | P32: 12.73 | Q32: 12.4 | R32: 11.94 | S32: 16.49 | T32: 17.19 | U32: 16.96 | V32: 15.89 | W32: 14.54 | X32: 12.7 | Y32: 10.93 | Z32: =SUM(B32:Y32) -> 283.19 | AA32: 4 | AB32: =+Z32*AA32 -> 1132.76 | AD32: SABADOS
A33: =+A17 -> 46296 | B33: 8.95 | C33: 8.02 | D33: 7.5 | E33: 7.3 | F33: 7.5 | G33: 7.75 | H33: 9.69 | I33: 8.34 | J33: 10.47 | K33: 11.96 | L33: 13.12 | M33: 14.11 | N33: 14.11 | O33: 13.52 | P33: 13.06 | Q33: 12.61 | R33: 12.15 | S33: 16.58 | T33: 17.47 | U33: 16.99 | V33: 15.74 | W33: 14.5 | X33: 12.91 | Y33: 11.15 | Z33: =SUM(B33:Y33) -> 285.5 | AA33: 5 | AB33: =+Z33*AA33 -> 1427.5 | AD33: SABADOS
A34: =+A18 -> 46327 | B34: 9.03 | C34: 8.1 | D34: 7.57 | E34: 7.28 | F34: 7.48 | G34: 7.8 | H34: 9.75 | I34: 8.55 | J34: 10.59 | K34: 12.06 | L34: 13.28 | M34: 14.37 | N34: 14.34 | O34: 13.59 | P34: 13.04 | Q34: 12.8 | R34: 12.49 | S34: 16.57 | T34: 17.72 | U34: 17.43 | V34: 16.29 | W34: 15.12 | X34: 13.29 | Y34: 11.45 | Z34: =SUM(B34:Y34) -> 289.99 | AA34: 4 | AB34: =+Z34*AA34 -> 1159.96 | AD34: SABADOS
A35: =+A19 -> 46357 | B35: 9.6 | C35: 8.57 | D35: 7.96 | E35: 7.65 | F35: 7.84 | G35: 8.28 | H35: 10.14 | I35: 8.8 | J35: 10.94 | K35: 12.43 | L35: 13.6 | M35: 14.66 | N35: 14.64 | O35: 13.83 | P35: 13.12 | Q35: 12.76 | R35: 12.61 | S35: 16.91 | T35: 17.77 | U35: 17.57 | V35: 16.5 | W35: 15.18 | X35: 13.43 | Y35: 11.67 | Z35: =SUM(B35:Y35) -> 296.46 | AA35: 4 | AB35: =+Z35*AA35 -> 1185.84 | AD35: SABADOS
A37: DEMANDA DIARIA ESTIMADA DÍA DOMINGO Y FESTIVO DIFERENTE A LUNES [MWh]
A39: MES | B39: H1 | C39: H2 | D39: H3 | E39: H4 | F39: H5 | G39: H6 | H39: H7 | I39: H8 | J39: H9 | K39: H10 | L39: H11 | M39: H12 | N39: H13 | O39: H14 | P39: H15 | Q39: H16 | R39: H17 | S39: H18 | T39: H19 | U39: H20 | V39: H21 | W39: H22 | X39: H23 | Y39: H24 | Z39: TOTAL | AA39: Días
A40: =+A24 -> 46023 | B40: 9.67 | C40: 8.71 | D40: 7.9 | E40: 7.59 | F40: 7.39 | G40: 7.47 | H40: 8.05 | I40: 5.04 | J40: 6.18 | K40: 7.44 | L40: 8.51 | M40: 9.51 | N40: 10.21 | O40: 10.31 | P40: 10.04 | Q40: 9.9 | R40: 9.85 | S40: 14.04 | T40: 14.9 | U40: 16.03 | V40: 15.69 | W40: 14.52 | X40: 12.82 | Y40: 11.11 | Z40: =SUM(B40:Y40) -> 242.88 | AA40: 5 | AB40: =+Z40*AA40 -> 1214.4 | AD40: DOMINGOS Y FESTIVOS
A41: =+A25 -> 46054 | B41: 9.34 | C41: 8.38 | D41: 7.69 | E41: 7.32 | F41: 7.27 | G41: 7.56 | H41: 8.38 | I41: 5.8 | J41: 7.2 | K41: 8.54 | L41: 9.33 | M41: 10.21 | N41: 10.64 | O41: 10.44 | P41: 9.95 | Q41: 9.63 | R41: 9.43 | S41: 13.46 | T41: 13.8 | U41: 15.55 | V41: 15.15 | W41: 13.84 | X41: 11.81 | Y41: 9.82 | Z41: =SUM(B41:Y41) -> 240.54 | AA41: 4 | AB41: =+Z41*AA41 -> 962.16 | AD41: DOMINGOS Y FESTIVOS
A42: =+A26 -> 46082 | B42: 9.2 | C42: 8.24 | D42: 7.66 | E42: 7.32 | F42: 7.21 | G42: 7.54 | H42: 8.32 | I42: 5.78 | J42: 7.07 | K42: 8.31 | L42: 9.08 | M42: 9.83 | N42: 10.43 | O42: 10.42 | P42: 9.91 | Q42: 9.69 | R42: 9.71 | S42: 14.13 | T42: 14.85 | U42: 15.91 | V42: 15.28 | W42: 13.93 | X42: 12.08 | Y42: 10.17 | Z42: =SUM(B42:Y42) -> 242.07 | AA42: 5 | AB42: =+Z42*AA42 -> 1210.35 | AD42: DOMINGOS Y FESTIVOS
A43: =+A27 -> 46113 | B43: 8.97 | C43: 7.97 | D43: 7.35 | E43: 7.02 | F43: 7.02 | G43: 7.04 | H43: 7.93 | I43: 5.69 | J43: 7.06 | K43: 8.38 | L43: 9.39 | M43: 10.44 | N43: 10.95 | O43: 10.69 | P43: 10.45 | Q43: 9.81 | R43: 9.67 | S43: 14.17 | T43: 14.83 | U43: 15.56 | V43: 15.02 | W43: 13.79 | X43: 12 | Y43: 10.3 | Z43: =SUM(B43:Y43) -> 241.5 | AA43: 6 | AB43: =+Z43*AA43 -> 1449 | AD43: DOMINGOS Y FESTIVOS
A44: =+A28 -> 46143 | B44: 9.09 | C44: 8.08 | D44: 7.51 | E44: 7.11 | F44: 7 | G44: 6.75 | H44: 8.13 | I44: 5.89 | J44: 7.35 | K44: 8.85 | L44: 9.82 | M44: 10.58 | N44: 10.69 | O44: 10.61 | P44: 9.85 | Q44: 9.98 | R44: 9.95 | S44: 14.28 | T44: 14.88 | U44: 16.01 | V44: 15.57 | W44: 14.26 | X44: 12.26 | Y44: 10.36 | Z44: =SUM(B44:Y44) -> 244.86 | AA44: 6 | AB44: =+Z44*AA44 -> 1469.16 | AD44: DOMINGOS Y FESTIVOS
A45: =+A29 -> 46174 | B45: 8.76 | C45: 7.76 | D45: 7.21 | E45: 6.85 | F45: 6.82 | G45: 6.89 | H45: 7.96 | I45: 5.76 | J45: 7.2 | K45: 8.6 | L45: 9.38 | M45: 10.08 | N45: 10.52 | O45: 10.51 | P45: 10.07 | Q45: 9.72 | R45: 9.52 | S45: 13.7 | T45: 14.23 | U45: 15.71 | V45: 15.22 | W45: 13.92 | X45: 12.15 | Y45: 10.25 | Z45: =SUM(B45:Y45) -> 238.79 | AA45: 4 | AB45: =+Z45*AA45 -> 955.16 | AD45: DOMINGOS Y FESTIVOS
A46: =+A30 -> 46204 | B46: 8.96 | C46: 8.05 | D46: 7.46 | E46: 7.08 | F46: 7.04 | G46: 7.05 | H46: 7.95 | I46: 5.74 | J46: 7.17 | K46: 8.54 | L46: 9.38 | M46: 10.36 | N46: 10.73 | O46: 10.42 | P46: 9.99 | Q46: 9.71 | R46: 9.72 | S46: 13.85 | T46: 14.12 | U46: 15.6 | V46: 15.19 | W46: 13.9 | X46: 12.04 | Y46: 10.15 | Z46: =SUM(B46:Y46) -> 240.2 | AA46: 4 | AB46: =+Z46*AA46 -> 960.8 | AD46: DOMINGOS Y FESTIVOS
A47: =+A31 -> 46235 | B47: 9.13 | C47: 8.16 | D47: 7.6 | E47: 7.26 | F47: 7.19 | G47: 7.21 | H47: 7.92 | I47: 5.64 | J47: 7.11 | K47: 8.49 | L47: 9.53 | M47: 10.39 | N47: 10.9 | O47: 10.84 | P47: 10.41 | Q47: 10.09 | R47: 9.76 | S47: 13.86 | T47: 14.46 | U47: 15.82 | V47: 15.41 | W47: 14.07 | X47: 12.12 | Y47: 10.23 | Z47: =SUM(B47:Y47) -> 243.6 | AA47: 6 | AB47: =+Z47*AA47 -> 1461.6 | AD47: DOMINGOS Y FESTIVOS
...

Sheet Oferta Producto No. 2
D2: ANEXO No. 1 OFERTAS Y CANTIDADES
C3: OFERTA MERCANTIL IRREVOCABLE A LA EMPRESA DE ENERGIA DE PEREIRA S.A. ESP. INVITACIÓN PARA EL SUMINISTRO DE ENERGÍA ELÉCTRICA CON DESTINO AL MERCADO REGULADO CONVOCATORIA PÚBLICA No. 004-2025 - CP-EEPC2025-004
D4: PRODUCTO No. 2
C6: EMPRESA: XXXXXXXXXXXXXXXXXXXXXXXXXXXXXX
C7: REPRESENTANTE LEGAL: XXXXXXXXXXXXXXXXXXXXXXXXXXXXXX
C8: TIPO DE AGENTE: (COMERCIALIZADOR/GENERADOR)
C9: ="PRODUCTO OFERTADO: "&D4 -> PRODUCTO OFERTADO: PRODUCTO No. 2
C11: Las tarifas ofertadas están referidas en pesos constantes de abril de 2025 provisional
F13: ="Oferta " & PROPER(D4) -> Oferta Producto No. 2
F14: Periodo | G14: Energía requerida (MWh-mes) | H14: Energía ofertada (%) | I14: Energía ofertada (MWh-mes) | J14: Tarifa monomia ($/kWh)
A15: 22.85 | B15: 31 | F15: =+'Cantidades Producto No. 2'!A72 -> 46388 | G15: =+'Cantidades Producto No. 2'!AB72 -> 10296.93
B16: 28 | F16: =+'Cantidades Producto No. 2'!A73 -> 46419 | G16: =+'Cantidades Producto No. 2'!AB73 -> 10115.76
B17: 31 | F17: =+'Cantidades Producto No. 2'!A74 -> 46447 | G17: =+'Cantidades Producto No. 2'!AB74 -> 10519.32
B18: 30 | F18: =+'Cantidades Producto No. 2'!A75 -> 46478 | G18: =+'Cantidades Producto No. 2'!AB75 -> 10817.48
B19: 31 | F19: =+'Cantidades Producto No. 2'!A76 -> 46508 | G19: =+'Cantidades Producto No. 2'!AB76 -> 10606.63
B20: 30 | F20: =+'Cantidades Producto No. 2'!A77 -> 46539 | G20: =+'Cantidades Producto No. 2'!AB77 -> 10597.17
B21: 31 | F21: =+'Cantidades Producto No. 2'!A78 -> 46569 | G21: =+'Cantidades Producto No. 2'!AB78 -> 10183.38
B22: 31 | F22: =+'Cantidades Producto No. 2'!A79 -> 46600 | G22: =+'Cantidades Producto No. 2'!AB79 -> 10622.07
B23: 30 | F23: =+'Cantidades Producto No. 2'!A80 -> 46631 | G23: =+'Cantidades Producto No. 2'!AB80 -> 10607.8
B24: 31 | F24: =+'Cantidades Producto No. 2'!A81 -> 46661 | G24: =+'Cantidades Producto No. 2'!AB81 -> 10615.38
B25: 30 | F25: =+'Cantidades Producto No. 2'!A82 -> 46692 | G25: =+'Cantidades Producto No. 2'!AB82 -> 10602.5
B26: 31 | F26: =+'Cantidades Producto No. 2'!A83 -> 46722 | G26: =+'Cantidades Producto No. 2'!AB83 -> 10381.11
F27: TOTAL | G27: =SUM(G15:G26) -> 125965.53
B29: Notas
B31: (1) Oferta válida para la modalidad Pague lo Contratado.
B32: ="(2) Las cantidades se distribuyen de acuerdo a la curva del Anexo 1. Ofertas y Cantidades "& D4 &" de los Pliegos de Condiciones definitivos" -> (2) Las cantidades se distribuyen de acuerdo a la curva del Anexo 1. Ofertas y Cantidades PRODUCTO No. 2 de los Pliegos de Condiciones definitivos
B33: (3) La cantidad de energía es equivalente a un porcentaje de las cantidades de energía requerida por la Empresa de Energía de Pereira S.A. ESP. (para todo el año/para cada mes), de acuerdo con el Anexo No.1 Ofertas y Cantidades PRODUCTO No. 2 de los Pliegos definitivos, que se aplicarán para todas las 24 horas del día de la curva establecida en dicho Anexo, presentando una tarifa para cada año sin ningún tipo de discriminación por mes, ni tipo de carga ni tipo de día.
B34: (4) Esta oferta NO presenta restricciones tales como adjudicación mínima o total u otras que no permitan la evaluación objetiva e integral del producto ofertado.
B35: (5) Los precios ofertados incluyen todos los pagos, cargos, impuestos, estampillas, etc., que el Proponente deba realizar ante cualquier entidad gubernamental, o empresa pública, privada o mixta para entregar la energía en la frontera con el Sistema de Transmisión Nacional – STN.
B36: (6) Las cantidades ofertadas están sujetas a la adjudicación en la misma proporción respecto a las cantidades ofertadas para todos y cada uno de los meses del año. Es decir, si la Empresa de Energía de Pereira decide adjudicar, por ejemplo, el 50% de lo ofertado en cualesquiera de los meses de alguno de los años, ese mismo porcentaje debe ser adjudicado en el resto de cada uno de los meses de ese año.

Sheet Cantidades Producto No. 2
A2: EMPRESA DE ENERGÍA DE PEREIRA S.A. E.S.P.
A3: PRODUCTO No. 2
A5: DEMANDA DIARIA ESTIMADA DÍA HABIL [MWh]
A7: MES | B7: H1 | C7: H2 | D7: H3 | E7: H4 | F7: H5 | G7: H6 | H7: H7 | I7: H8 | J7: H9 | K7: H10 | L7: H11 | M7: H12 | N7: H13 | O7: H14 | P7: H15 | Q7: H16 | R7: H17 | S7: H18 | T7: H19 | U7: H20 | V7: H21 | W7: H22 | X7: H23 | Y7: H24 | Z7: TOTAL | AA7: Días
A8: 46388 | B8: 9.55 | C8: 8.71 | D8: 7.87 | E8: 7.56 | F8: 8.09 | G8: 9.93 | H8: 12.51 | I8: 9.16 | J8: 11.44 | K8: 13.84 | L8: 16.16 | M8: 18.32 | N8: 18.34 | O8: 17.91 | P8: 18.33 | Q8: 18.21 | R8: 17.5 | S8: 22.89 | T8: 23.28 | U8: 24.06 | V8: 22.6 | W8: 20.26 | X8: 16.65 | Y8: 13.95 | Z8: =SUM(B8:Y8) -> 367.12 | AA8: 19 | AB8: =+Z8*AA8 -> 6975.28 | AD8: HABIL
A9: 46419 | B9: 9.76 | C9: 9.02 | D9: 8.22 | E9: 7.99 | F9: 8.8 | G9: 11.93 | H9: 14.92 | I9: 11 | J9: 12.81 | K9: 15 | L9: 17.24 | M9: 19.27 | N9: 18.58 | O9: 18.47 | P9: 19.23 | Q9: 19.31 | R9: 18.64 | S9: 23.32 | T9: 22.92 | U9: 24.21 | V9: 23.14 | W9: 20.73 | X9: 16.84 | Y9: 14.08 | Z9: =SUM(B9:Y9) -> 385.43 | AA9: 20 | AB9: =+Z9*AA9 -> 7708.6 | AD9: HABIL
A10: 46447 | B10: 9.28 | C10: 8.55 | D10: 7.86 | E10: 7.59 | F10: 8.41 | G10: 11.44 | H10: 14.2 | I10: 10.74 | J10: 12.56 | K10: 14.53 | L10: 16.74 | M10: 18.6 | N10: 18.18 | O10: 17.82 | P10: 18.41 | Q10: 18.27 | R10: 17.73 | S10: 22.86 | T10: 22.72 | U10: 24.05 | V10: 22.57 | W10: 20.16 | X10: 16.39 | Y10: 13.65 | Z10: =SUM(B10:Y10) -> 373.31 | AA10: 20 | AB10: =+Z10*AA10 -> 7466.2 | AD10: HABIL
A11: 46478 | B11: 9.57 | C11: 8.77 | D11: 8.05 | E11: 7.77 | F11: 8.62 | G11: 11.39 | H11: 14.33 | I11: 11.06 | J11: 12.67 | K11: 15.44 | L11: 17.5 | M11: 19.41 | N11: 19.01 | O11: 18.32 | P11: 18.26 | Q11: 18.35 | R11: 17.88 | S11: 23.72 | T11: 24.07 | U11: 24.85 | V11: 23.22 | W11: 20.68 | X11: 16.8 | Y11: 14.16 | Z11: =SUM(B11:Y11) -> 383.9 | AA11: 22 | AB11: =+Z11*AA11 -> 8445.8 | AD11: HABIL
A12: 46508 | B12: 9.38 | C12: 8.63 | D12: 7.88 | E12: 7.56 | F12: 8.44 | G12: 11 | H12: 14.2 | I12: 10.76 | J12: 12.78 | K12: 15.08 | L12: 17.44 | M12: 19.56 | N12: 19.04 | O12: 18.42 | P12: 18.75 | Q12: 18.52 | R12: 17.59 | S12: 23.55 | T12: 23.82 | U12: 24.45 | V12: 22.83 | W12: 20.09 | X12: 16.13 | Y12: 13.61 | Z12: =SUM(B12:Y12) -> 379.51 | AA12: 19 | AB12: =+Z12*AA12 -> 7210.69 | AD12: HABIL
A13: 46539 | B13: 9.32 | C13: 8.52 | D13: 7.64 | E13: 7.33 | F13: 8.2 | G13: 10.54 | H13: 14.04 | I13: 10.92 | J13: 12.99 | K13: 15.33 | L13: 17.45 | M13: 19.6 | N13: 19.3 | O13: 18.48 | P13: 18.52 | Q13: 18.32 | R13: 17.77 | S13: 23.67 | T13: 23.88 | U13: 25.22 | V13: 23.52 | W13: 20.61 | X13: 16.33 | Y13: 13.77 | Z13: =SUM(B13:Y13) -> 381.27 | AA13: 21 | AB13: =+Z13*AA13 -> 8006.67 | AD13: HABIL
A14: 46569 | B14: 7.8 | C14: 7.16 | D14: 6.26 | E14: 5.96 | F14: 6.85 | G14: 9.47 | H14: 12.7 | I14: 9.08 | J14: 11.36 | K14: 13.91 | L14: 16.12 | M14: 18.49 | N14: 17.98 | O14: 17.27 | P14: 17.58 | Q14: 17.69 | R14: 17.19 | S14: 24.33 | T14: 23.89 | U14: 25.64 | V14: 23.88 | W14: 20.91 | X14: 16.43 | Y14: 14.12 | Z14: =SUM(B14:Y14) -> 362.07 | AA14: 20 | AB14: =+Z14*AA14 -> 7241.4 | AD14: HABIL
A15: 46600 | B15: 8.48 | C15: 7.67 | D15: 6.85 | E15: 6.56 | F15: 7.47 | G15: 10.47 | H15: 13.66 | I15: 9.9 | J15: 12.08 | K15: 14.38 | L15: 16.97 | M15: 19.27 | N15: 18.77 | O15: 18.2 | P15: 18.49 | Q15: 18.32 | R15: 17.77 | S15: 24.9 | T15: 24.76 | U15: 26.09 | V15: 24.22 | W15: 21.26 | X15: 16.68 | Y15: 14.3 | Z15: =SUM(B15:Y15) -> 377.52 | AA15: 21 | AB15: =+Z15*AA15 -> 7927.92 | AD15: HABIL
A16: 46631 | B16: 8.54 | C16: 7.7 | D16: 6.86 | E16: 6.59 | F16: 7.59 | G16: 10.6 | H16: 13.98 | I16: 9.97 | J16: 11.28 | K16: 13.97 | L16: 16.97 | M16: 19.2 | N16: 18.61 | O16: 18 | P16: 18.5 | Q16: 18.42 | R16: 17.76 | S16: 25.31 | T16: 26.07 | U16: 26.06 | V16: 24.1 | W16: 21.16 | X16: 16.68 | Y16: 14.22 | Z16: =SUM(B16:Y16) -> 378.14 | AA16: 22 | AB16: =+Z16*AA16 -> 8319.08 | AD16: HABIL
A17: 46661 | B17: 8.29 | C17: 7.4 | D17: 6.65 | E17: 6.41 | F17: 7.12 | G17: 8.75 | H17: 12.44 | I17: 9.25 | J17: 11.92 | K17: 14.71 | L17: 17.35 | M17: 19.48 | N17: 19.05 | O17: 18.47 | P17: 18.79 | Q17: 18.37 | R17: 17.77 | S17: 25.83 | T17: 26.58 | U17: 25.56 | V17: 23.69 | W17: 20.79 | X17: 16.73 | Y17: 14.3 | Z17: =SUM(B17:Y17) -> 375.7 | AA17: 20 | AB17: =+Z17*AA17 -> 7514 | AD17: HABIL
A18: 46692 | B18: 8.77 | C18: 7.88 | D18: 7 | E18: 6.72 | F18: 7.45 | G18: 9.5 | H18: 13.02 | I18: 9.85 | J18: 12.26 | K18: 14.71 | L18: 17.11 | M18: 19.33 | N18: 19.06 | O18: 18.5 | P18: 19.19 | Q18: 18.9 | R18: 18.31 | S18: 26.78 | T18: 27.24 | U18: 26.35 | V18: 24.51 | W18: 21.56 | X18: 17.33 | Y18: 14.77 | Z18: =SUM(B18:Y18) -> 386.1 | AA18: 20 | AB18: =+Z18*AA18 -> 7722 | AD18: HABIL
A19: 46722 | B19: 9.1 | C19: 8.03 | D19: 7.07 | E19: 6.67 | F19: 7.16 | G19: 8.72 | H19: 11.66 | I19: 8.73 | J19: 11.26 | K19: 13.53 | L19: 15.72 | M19: 17.67 | N19: 17.76 | O19: 17.38 | P19: 17.67 | Q19: 17.4 | R19: 16.64 | S19: 23.69 | T19: 24.7 | U19: 24.58 | V19: 22.94 | W19: 20.67 | X19: 17.3 | Y19: 15.18 | Z19: =SUM(B19:Y19) -> 361.23 | AA19: 22 | AB19: =+Z19*AA19 -> 7947.06 | AD19: HABIL
A21: DEMANDA DIARIA ESTIMADA DÍA SABADO [MWh]
A23: MES | B23: H1 | C23: H2 | D23: H3 | E23: H4 | F23: H5 | G23: H6 | H23: H7 | I23: H8 | J23: H9 | K23: H10 | L23: H11 | M23: H12 | N23: H13 | O23: H14 | P23: H15 | Q23: H16 | R23: H17 | S23: H18 | T23: H19 | U23: H20 | V23: H21 | W23: H22 | X23: H23 | Y23: H24 | Z23: TOTAL | AA23: Días
A24: =+A8 -> 46388 | B24: 9.76 | C24: 8.83 | D24: 7.86 | E24: 7.33 | F24: 7.52 | G24: 8.5 | H24: 10.39 | I24: 7.06 | J24: 9.59 | K24: 12.49 | L24: 14.43 | M24: 16.08 | N24: 16.33 | O24: 15.34 | P24: 14.49 | Q24: 14.15 | R24: 13.55 | S24: 20.22 | T24: 21.24 | U24: 21.77 | V24: 20.23 | W24: 18.1 | X24: 15.32 | Y24: 13.83 | Z24: =SUM(B24:Y24) -> 324.41 | AA24: 5 | AB24: =+Z24*AA24 -> 1622.05 | AD24: SABADOS
A25: =+A9 -> 46419 | B25: 9.87 | C25: 9.03 | D25: 8.14 | E25: 7.68 | F25: 7.94 | G25: 9.33 | H25: 11.7 | I25: 8.37 | J25: 10.89 | K25: 13.36 | L25: 15.34 | M25: 16.6 | N25: 16.57 | O25: 15.92 | P25: 15.34 | Q25: 14.98 | R25: 14.59 | S25: 20.84 | T25: 21.16 | U25: 22.63 | V25: 21.21 | W25: 19.21 | X25: 16.3 | Y25: 14.81 | Z25: =SUM(B25:Y25) -> 341.81 | AA25: 4 | AB25: =+Z25*AA25 -> 1367.24 | AD25: SABADOS
A26: =+A10 -> 46447 | B26: 9.44 | C26: 8.55 | D26: 7.69 | E26: 7.24 | F26: 7.64 | G26: 8.93 | H26: 10.92 | I26: 8.05 | J26: 10.66 | K26: 12.89 | L26: 14.76 | M26: 16.5 | N26: 16.45 | O26: 15.3 | P26: 14.52 | Q26: 14.12 | R26: 13.72 | S26: 20.37 | T26: 20.56 | U26: 21.21 | V26: 19.8 | W26: 17.9 | X26: 15.11 | Y26: 13.62 | Z26: =SUM(B26:Y26) -> 325.95 | AA26: 4 | AB26: =+Z26*AA26 -> 1303.8 | AD26: SABADOS
A27: =+A11 -> 46478 | B27: 9.94 | C27: 8.94 | D27: 7.95 | E27: 7.44 | F27: 7.71 | G27: 8.41 | H27: 10.91 | I27: 8.1 | J27: 10.64 | K27: 13.27 | L27: 15.24 | M27: 16.82 | N27: 16.94 | O27: 15.69 | P27: 15.03 | Q27: 14.64 | R27: 13.94 | S27: 20.75 | T27: 21.52 | U27: 22.34 | V27: 20.88 | W27: 18.8 | X27: 16.02 | Y27: 14.52 | Z27: =SUM(B27:Y27) -> 336.44 | AA27: 4 | AB27: =+Z27*AA27 -> 1345.76 | AD27: SABADOS
A28: =+A12 -> 46508 | B28: 9.36 | C28: 8.57 | D28: 7.68 | E28: 7.24 | F28: 7.59 | G28: 8.36 | H28: 11.24 | I28: 8.51 | J28: 11.12 | K28: 13.99 | L28: 15.8 | M28: 17.28 | N28: 16.95 | O28: 15.51 | P28: 14.92 | Q28: 14.46 | R28: 13.83 | S28: 20.73 | T28: 21.58 | U28: 22.44 | V28: 20.79 | W28: 18.69 | X28: 15.78 | Y28: 14.23 | Z28: =SUM(B28:Y28) -> 336.65 | AA28: 4 | AB28: =+Z28*AA28 -> 1346.6 | AD28: SABADOS
A29: =+A13 -> 46539 | B29: 9.43 | C29: 8.53 | D29: 7.6 | E29: 7.17 | F29: 7.51 | G29: 8.61 | H29: 10.95 | I29: 8.1 | J29: 10.79 | K29: 13.63 | L29: 15.4 | M29: 17.1 | N29: 17.31 | O29: 16.23 | P29: 15.22 | Q29: 14.45 | R29: 13.78 | S29: 20.69 | T29: 21.59 | U29: 22.44 | V29: 20.74 | W29: 18.48 | X29: 15.36 | Y29: 13.65 | Z29: =SUM(B29:Y29) -> 334.76 | AA29: 4 | AB29: =+Z29*AA29 -> 1339.04 | AD29: SABADOS
A30: =+A14 -> 46569 | B30: 8.51 | C30: 7.45 | D30: 6.26 | E30: 5.82 | F30: 6.13 | G30: 6.89 | H30: 9.52 | I30: 6.1 | J30: 9.14 | K30: 12.17 | L30: 14.12 | M30: 15.96 | N30: 16.19 | O30: 14.93 | P30: 13.73 | Q30: 12.76 | R30: 12.17 | S30: 20.91 | T30: 21.28 | U30: 22.97 | V30: 21.2 | W30: 19.04 | X30: 16.04 | Y30: 14.37 | Z30: =SUM(B30:Y30) -> 313.66 | AA30: 5 | AB30: =+Z30*AA30 -> 1568.3 | AD30: SABADOS
A31: =+A15 -> 46600 | B31: 9.12 | C31: 8.14 | D31: 7.09 | E31: 6.54 | F31: 6.91 | G31: 7.96 | H31: 10.67 | I31: 7.18 | J31: 9.96 | K31: 12.81 | L31: 14.82 | M31: 16.54 | N31: 16.57 | O31: 15.26 | P31: 14.2 | Q31: 13.23 | R31: 12.52 | S31: 20.97 | T31: 21.68 | U31: 22.92 | V31: 21.28 | W31: 19.17 | X31: 16.21 | Y31: 14.44 | Z31: =SUM(B31:Y31) -> 326.19 | AA31: 3 | AB31: =+Z31*AA31 -> 978.57 | AD31: SABADOS
A32: =+A16 -> 46631 | B32: 8.62 | C32: 7.71 | D32: 6.72 | E32: 6.16 | F32: 6.55 | G32: 7.54 | H32: 10.35 | I32: 7.34 | J32: 10.19 | K32: 12.88 | L32: 15.16 | M32: 17 | N32: 16.2 | O32: 15.58 | P32: 14.33 | Q32: 13.71 | R32: 12.86 | S32: 22.54 | T32: 23.67 | U32: 23.29 | V32: 21.44 | W32: 19.07 | X32: 15.85 | Y32: 14.18 | Z32: =SUM(B32:Y32) -> 328.94 | AA32: 4 | AB32: =+Z32*AA32 -> 1315.76 | AD32: SABADOS
A33: =+A17 -> 46661 | B33: 8.78 | C33: 7.78 | D33: 6.8 | E33: 6.4 | F33: 6.78 | G33: 7.27 | H33: 10.23 | I33: 7.1 | J33: 10.1 | K33: 12.83 | L33: 14.94 | M33: 16.73 | N33: 16.72 | O33: 15.62 | P33: 14.74 | Q33: 13.92 | R33: 13.09 | S33: 22.44 | T33: 23.89 | U33: 23.08 | V33: 20.93 | W33: 18.78 | X33: 16.02 | Y33: 14.38 | Z33: =SUM(B33:Y33) -> 329.35 | AA33: 5 | AB33: =+Z33*AA33 -> 1646.75 | AD33: SABADOS
A34: =+A18 -> 46692 | B34: 9 | C34: 7.98 | D34: 6.97 | E34: 6.43 | F34: 6.81 | G34: 7.44 | H34: 10.44 | I34: 7.54 | J34: 10.41 | K34: 13.15 | L34: 15.4 | M34: 17.38 | N34: 17.29 | O34: 15.91 | P34: 14.87 | Q34: 14.43 | R34: 13.84 | S34: 22.7 | T34: 24.6 | U34: 24.1 | V34: 22.12 | W34: 20.07 | X34: 16.85 | Y34: 15.09 | Z34: =SUM(B34:Y34) -> 340.82 | AA34: 4 | AB34: =+Z34*AA34 -> 1363.28 | AD34: SABADOS
A35: =+A19 -> 46722 | B35: 9.25 | C35: 8.16 | D35: 7.09 | E35: 6.53 | F35: 6.86 | G35: 7.67 | H35: 10.27 | I35: 7.3 | J35: 10.11 | K35: 12.69 | L35: 14.69 | M35: 16.49 | N35: 16.45 | O35: 15.06 | P35: 13.84 | Q35: 13.21 | R35: 12.94 | S35: 21.5 | T35: 22.83 | U35: 22.53 | V35: 20.8 | W35: 18.65 | X35: 15.81 | Y35: 14.34 | Z35: =SUM(B35:Y35) -> 325.07 | AA35: 3 | AB35: =+Z35*AA35 -> 975.21 | AD35: SABADOS
A37: DEMANDA DIARIA ESTIMADA DÍA DOMINGO Y FESTIVO DIFERENTE A LUNES [MWh]
A39: MES | B39: H1 | C39: H2 | D39: H3 | E39: H4 | F39: H5 | G39: H6 | H39: H7 | I39: H8 | J39: H9 | K39: H10 | L39: H11 | M39: H12 | N39: H13 | O39: H14 | P39: H15 | Q39: H16 | R39: H17 | S39: H18 | T39: H19 | U39: H20 | V39: H21 | W39: H22 | X39: H23 | Y39: H24 | Z39: TOTAL | AA39: Días
A40: =+A24 -> 46388 | B40: 10 | C40: 9.12 | D40: 7.76 | E40: 7.24 | F40: 6.91 | G40: 7.04 | H40: 7.48 | I40: 2.05 | J40: 3.26 | K40: 5.32 | L40: 7.05 | M40: 8.66 | N40: 9.78 | O40: 9.92 | P40: 9.45 | Q40: 9.22 | R40: 9.12 | S40: 15.99 | T40: 17.2 | U40: 18.94 | V40: 18.43 | W40: 16.64 | X40: 14.01 | Y40: 12.67 | Z40: =SUM(B40:Y40) -> 243.26 | AA40: 6 | AB40: =+Z40*AA40 -> 1459.56 | AD40: DOMINGOS Y FESTIVOS
A41: =+A25 -> 46419 | B41: 10.26 | C41: 9.29 | D41: 8.06 | E41: 7.41 | F41: 7.32 | G41: 7.81 | H41: 8.69 | I41: 3.73 | J41: 5.44 | K41: 7.73 | L41: 9.1 | M41: 10.6 | N41: 11.32 | O41: 10.97 | P41: 10.13 | Q41: 9.58 | R41: 9.23 | S41: 16.28 | T41: 16.73 | U41: 19.56 | V41: 18.92 | W41: 16.8 | X41: 13.5 | Y41: 11.52 | Z41: =SUM(B41:Y41) -> 259.98 | AA41: 4 | AB41: =+Z41*AA41 -> 1039.92 | AD41: DOMINGOS Y FESTIVOS
A42: =+A26 -> 46447 | B42: 9.51 | C42: 8.59 | D42: 7.6 | E42: 7.02 | F42: 6.84 | G42: 7.37 | H42: 8.15 | I42: 3.53 | J42: 4.98 | K42: 6.99 | L42: 8.26 | M42: 9.48 | N42: 10.44 | O42: 10.4 | P42: 9.57 | Q42: 9.2 | R42: 9.22 | S42: 16.48 | T42: 17.5 | U42: 19.14 | V42: 18.17 | W42: 16.1 | X42: 13.25 | Y42: 11.47 | Z42: =SUM(B42:Y42) -> 249.26 | AA42: 6 | AB42: =+Z42*AA42 -> 1495.56 | AD42: DOMINGOS Y FESTIVOS
A43: =+A27 -> 46478 | B43: 9.46 | C43: 8.42 | D43: 7.34 | E43: 6.76 | F43: 6.75 | G43: 6.78 | H43: 7.78 | I43: 3.45 | J43: 5.08 | K43: 7.32 | L43: 9.02 | M43: 10.77 | N43: 11.62 | O43: 11.18 | P43: 10.75 | Q43: 9.69 | R43: 9.46 | S43: 17.09 | T43: 18.07 | U43: 19.24 | V43: 18.39 | W43: 16.44 | X43: 13.55 | Y43: 12.07 | Z43: =SUM(B43:Y43) -> 256.48 | AA43: 4 | AB43: =+Z43*AA43 -> 1025.92 | AD43: DOMINGOS Y FESTIVOS
A44: =+A28 -> 46508 | B44: 9.44 | C44: 8.42 | D44: 7.41 | E44: 6.72 | F44: 6.54 | G44: 6.1 | H44: 7.9 | I44: 3.58 | J44: 5.3 | K44: 7.83 | L44: 9.48 | M44: 10.74 | N44: 10.94 | O44: 10.79 | P44: 9.5 | Q44: 9.7 | R44: 9.63 | S44: 16.96 | T44: 17.81 | U44: 19.61 | V44: 18.9 | W44: 16.84 | X44: 13.65 | Y44: 11.91 | Z44: =SUM(B44:Y44) -> 255.7 | AA44: 6 | AB44: =+Z44*AA44 -> 1534.2 | AD44: DOMINGOS Y FESTIVOS
A45: =+A29 -> 46539 | B45: 9 | C45: 7.98 | D45: 6.99 | E45: 6.35 | F45: 6.3 | G45: 6.41 | H45: 7.72 | I45: 3.37 | J45: 5.1 | K45: 7.49 | L45: 8.83 | M45: 10.03 | N45: 10.79 | O45: 10.77 | P45: 10 | Q45: 9.38 | R45: 9.04 | S45: 16.28 | T45: 17.01 | U45: 19.4 | V45: 18.62 | W45: 16.52 | X45: 13.64 | Y45: 11.9 | Z45: =SUM(B45:Y45) -> 248.92 | AA45: 4 | AB45: =+Z45*AA45 -> 995.68 | AD45: DOMINGOS Y FESTIVOS
A46: =+A30 -> 46569 | B46: 8.18 | C46: 7.26 | D46: 6.17 | E46: 5.45 | F46: 5.38 | G46: 5.41 | H46: 6.47 | I46: 1.59 | J46: 3.41 | K46: 5.85 | L46: 7.36 | M46: 9.1 | N46: 9.77 | O46: 9.2 | P46: 8.42 | Q46: 7.9 | R46: 7.91 | S46: 16.89 | T46: 17.23 | U46: 19.72 | V46: 19.04 | W46: 16.86 | X46: 13.7 | Y46: 11.88 | Z46: =SUM(B46:Y46) -> 230.15 | AA46: 5 | AB46: =+Z46*AA46 -> 1150.75 | AD46: DOMINGOS Y FESTIVOS
A47: =+A31 -> 46600 | B47: 8.78 | C47: 7.76 | D47: 6.71 | E47: 6.08 | F47: 5.94 | G47: 5.98 | H47: 6.74 | I47: 1.79 | J47: 3.7 | K47: 6.16 | L47: 8.01 | M47: 9.55 | N47: 10.45 | O47: 10.33 | P47: 9.55 | Q47: 8.98 | R47: 8.38 | S47: 17.26 | T47: 18.17 | U47: 20.46 | V47: 19.77 | W47: 17.51 | X47: 14.21 | Y47: 12.32 | Z47: =SUM(B47:Y47) -> 244.59 | AA47: 6 | AB47: =+Z47*AA47 -> 1467.54 | AD47: DOMINGOS Y FESTIVOS
...

Sheet Oferta Producto No. 3
D2: ANEXO No. 1 OFERTAS Y CANTIDADES
C3: OFERTA MERCANTIL IRREVOCABLE A LA EMPRESA DE ENERGIA DE PEREIRA S.A. ESP. INVITACIÓN PARA EL SUMINISTRO DE ENERGÍA ELÉCTRICA CON DESTINO AL MERCADO REGULADO CONVOCATORIA PÚBLICA No. 004-2025 - CP-EEPC2025-004
D4: PRODUCTO No. 3
C6: EMPRESA: XXXXXXXXXXXXXXXXXXXXXXXXXXXXXX
C7: REPRESENTANTE LEGAL: XXXXXXXXXXXXXXXXXXXXXXXXXXXXXX
C8: TIPO DE AGENTE: (COMERCIALIZADOR/GENERADOR)
C9: ="PRODUCTO OFERTADO: "&D4 -> PRODUCTO OFERTADO: PRODUCTO No. 3
C11: Las tarifas ofertadas están referidas en pesos constantes de abril de 2025 provisional
F13: ="Oferta " & PROPER(D4) -> Oferta Producto No. 3
F14: Periodo | G14: Energía requerida (MWh-mes) | H14: Energía ofertada (%) | I14: Energía ofertada (MWh-mes) | J14: Tarifa monomia ($/kWh)
A15: 22.85 | B15: 31 | F15: =+'Cantidades Producto No. 3'!A72 -> 46753 | G15: =+'Cantidades Producto No. 3'!AB72 -> 10044.82
B16: 28 | F16: =+'Cantidades Producto No. 3'!A73 -> 46784 | G16: =+'Cantidades Producto No. 3'!AB73 -> 9711.74
B17: 31 | F17: =+'Cantidades Producto No. 3'!A74 -> 46813 | G17: =+'Cantidades Producto No. 3'!AB74 -> 10267.16
B18: 30 | F18: =+'Cantidades Producto No. 3'!A75 -> 46844 | G18: =+'Cantidades Producto No. 3'!AB75 -> 9693.56
B19: 31 | F19: =+'Cantidades Producto No. 3'!A76 -> 46874 | G19: =+'Cantidades Producto No. 3'!AB76 -> 10108.63
B20: 30 | F20: =+'Cantidades Producto No. 3'!A77 -> 46905 | G20: =+'Cantidades Producto No. 3'!AB77 -> 9795.14
B21: 31 | F21: =+'Cantidades Producto No. 3'!A78 -> 46935 | G21: =+'Cantidades Producto No. 3'!AB78 -> 10102.98
B22: 31 | F22: =+'Cantidades Producto No. 3'!A79 -> 46966 | G22: =+'Cantidades Producto No. 3'!AB79 -> 10281.11
B23: 30 | F23: =+'Cantidades Producto No. 3'!A80 -> 46997 | G23: =+'Cantidades Producto No. 3'!AB80 -> 9996.64
B24: 31 | F24: =+'Cantidades Producto No. 3'!A81 -> 47027 | G24: =+'Cantidades Producto No. 3'!AB81 -> 10158.1
B25: 30 | F25: =+'Cantidades Producto No. 3'!A82 -> 47058 | G25: =+'Cantidades Producto No. 3'!AB82 -> 9930.38
B26: 31 | F26: =+'Cantidades Producto No. 3'!A83 -> 47088 | G26: =+'Cantidades Producto No. 3'!AB83 -> 10327.17
F27: TOTAL | G27: =SUM(G15:G26) -> 120417.43
B29: Notas
B31: (1) Oferta válida para la modalidad Pague lo Contratado.
B32: ="(2) Las cantidades se distribuyen de acuerdo a la curva del Anexo 1. Ofertas y Cantidades "& D4 &" de los Pliegos de Condiciones definitivos" -> (2) Las cantidades se distribuyen de acuerdo a la curva del Anexo 1. Ofertas y Cantidades PRODUCTO No. 3 de los Pliegos de Condiciones definitivos
B33: (3) La cantidad de energía es equivalente a un porcentaje de las cantidades de energía requerida por la Empresa de Energía de Pereira S.A. ESP. (para todo el año/para cada mes), de acuerdo con el Anexo No.1 Ofertas y Cantidades PRODUCTO No. 3 de los Pliegos definitivos, que se aplicarán para todas las 24 horas del día de la curva establecida en dicho Anexo, presentando una tarifa para cada año sin ningún tipo de discriminación por mes, ni tipo de carga ni tipo de día.
B34: (4) Esta oferta NO presenta restricciones tales como adjudicación mínima o total u otras que no permitan la evaluación objetiva e integral del producto ofertado.
B35: (5) Los precios ofertados incluyen todos los pagos, cargos, impuestos, estampillas, etc., que el Proponente deba realizar ante cualquier entidad gubernamental, o empresa pública, privada o mixta para entregar la energía en la frontera con el Sistema de Transmisión Nacional – STN.
B36: (6) Las cantidades ofertadas están sujetas a la adjudicación en la misma proporción respecto a las cantidades ofertadas para todos y cada uno de los meses del año. Es decir, si la Empresa de Energía de Pereira decide adjudicar, por ejemplo, el 50% de lo ofertado en cualesquiera de los meses de alguno de los años, ese mismo porcentaje debe ser adjudicado en el resto de cada uno de los meses de ese año.

Sheet Cantidades Producto No. 3
A2: EMPRESA DE ENERGÍA DE PEREIRA S.A. E.S.P.
A3: PRODUCTO No. 3
A5: DEMANDA DIARIA ESTIMADA DÍA HABIL [MWh]
A7: MES | B7: H1 | C7: H2 | D7: H3 | E7: H4 | F7: H5 | G7: H6 | H7: H7 | I7: H8 | J7: H9 | K7: H10 | L7: H11 | M7: H12 | N7: H13 | O7: H14 | P7: H15 | Q7: H16 | R7: H17 | S7: H18 | T7: H19 | U7: H20 | V7: H21 | W7: H22 | X7: H23 | Y7: H24 | Z7: TOTAL | AA7: Días
A8: 46753 | B8: 9.91 | C8: 8.98 | D8: 8.36 | E8: 8.14 | F8: 8.54 | G8: 9.93 | H8: 12 | I8: 11.28 | J8: 13.43 | K8: 15.26 | L8: 17.04 | M8: 18.64 | N8: 18.59 | O8: 18.26 | P8: 18.6 | Q8: 18.52 | R8: 17.99 | S8: 20.71 | T8: 21.28 | U8: 21.91 | V8: 20.73 | W8: 18.9 | X8: 16.02 | Y8: 13.26 | Z8: =SUM(B8:Y8) -> 366.28 | AA8: 20 | AB8: =+Z8*AA8 -> 7325.6 | AD8: HABIL
A9: 46784 | B9: 9.56 | C9: 8.73 | D9: 8.17 | E9: 8.02 | F9: 8.61 | G9: 10.87 | H9: 13.16 | I9: 12.02 | J9: 13.76 | K9: 15.37 | L9: 17.02 | M9: 18.46 | N9: 17.91 | O9: 17.81 | P9: 18.39 | Q9: 18.44 | R9: 17.96 | S9: 20.12 | T9: 20.07 | U9: 21.07 | V9: 20.21 | W9: 18.37 | X9: 15.41 | Y9: 12.71 | Z9: =SUM(B9:Y9) -> 362.22 | AA9: 21 | AB9: =+Z9*AA9 -> 7606.62 | AD9: HABIL
A10: 46813 | B10: 9.47 | C10: 8.65 | D10: 8.14 | E10: 7.94 | F10: 8.55 | G10: 10.81 | H10: 12.99 | I10: 12.12 | J10: 13.9 | K10: 15.41 | L10: 17.1 | M10: 18.48 | N10: 18.09 | O10: 17.82 | P10: 18.3 | Q10: 18.2 | R10: 17.8 | S10: 20.33 | T10: 20.45 | U10: 21.49 | V10: 20.32 | W10: 18.43 | X10: 15.46 | Y10: 12.74 | Z10: =SUM(B10:Y10) -> 362.99 | AA10: 22 | AB10: =+Z10*AA10 -> 7985.78 | AD10: HABIL
A11: 46844 | B11: 9.65 | C11: 8.78 | D11: 8.26 | E11: 8.06 | F11: 8.68 | G11: 10.71 | H11: 12.99 | I11: 12.36 | J11: 14.02 | K11: 16.05 | L11: 17.61 | M11: 19 | N11: 18.64 | O11: 18.13 | P11: 18.14 | Q11: 18.21 | R11: 17.86 | S11: 20.81 | T11: 21.32 | U11: 21.93 | V11: 20.66 | W11: 18.69 | X11: 15.68 | Y11: 13.03 | Z11: =SUM(B11:Y11) -> 369.27 | AA11: 18 | AB11: =+Z11*AA11 -> 6646.86 | AD11: HABIL
A12: 46874 | B12: 9.4 | C12: 8.58 | D12: 8.04 | E12: 7.82 | F12: 8.45 | G12: 10.28 | H12: 12.71 | I12: 11.99 | J12: 13.89 | K12: 15.57 | L12: 17.28 | M12: 18.77 | N12: 18.33 | O12: 17.88 | P12: 18.16 | Q12: 18.01 | R12: 17.37 | S12: 20.37 | T12: 20.84 | U12: 21.32 | V12: 20.09 | W12: 18.04 | X12: 15.03 | Y12: 12.49 | Z12: =SUM(B12:Y12) -> 360.71 | AA12: 21 | AB12: =+Z12*AA12 -> 7574.91 | AD12: HABIL
A13: 46905 | B13: 9.46 | C13: 8.59 | D13: 7.97 | E13: 7.75 | F13: 8.37 | G13: 10.01 | H13: 12.63 | I13: 12.19 | J13: 14.15 | K13: 15.87 | L13: 17.44 | M13: 18.97 | N13: 18.68 | O13: 18.1 | P13: 18.19 | Q13: 18.05 | R13: 17.66 | S13: 20.6 | T13: 20.98 | U13: 21.99 | V13: 20.7 | W13: 18.53 | X13: 15.32 | Y13: 12.73 | Z13: =SUM(B13:Y13) -> 364.93 | AA13: 20 | AB13: =+Z13*AA13 -> 7298.6 | AD13: HABIL
A14: 46935 | B14: 9.42 | C14: 8.66 | D14: 8.04 | E14: 7.84 | F14: 8.46 | G14: 10.3 | H14: 12.68 | I14: 12.14 | J14: 14.21 | K14: 16.03 | L14: 17.62 | M14: 19.24 | N14: 18.8 | O14: 18.3 | P14: 18.57 | Q14: 18.63 | R14: 18.29 | S14: 20.98 | T14: 20.9 | U14: 22.21 | V14: 20.92 | W14: 18.75 | X14: 15.44 | Y14: 13.03 | Z14: =SUM(B14:Y14) -> 369.46 | AA14: 19 | AB14: =+Z14*AA14 -> 7019.74 | AD14: HABIL
A15: 46966 | B15: 9.49 | C15: 8.65 | D15: 8.09 | E15: 7.89 | F15: 8.52 | G15: 10.58 | H15: 12.89 | I15: 12.23 | J15: 14.16 | K15: 15.8 | L15: 17.61 | M15: 19.16 | N15: 18.73 | O15: 18.33 | P15: 18.59 | Q15: 18.48 | R15: 18.12 | S15: 20.76 | T15: 20.92 | U15: 21.88 | V15: 20.54 | W15: 18.41 | X15: 15.11 | Y15: 12.75 | Z15: =SUM(B15:Y15) -> 367.69 | AA15: 21 | AB15: =+Z15*AA15 -> 7721.49 | AD15: HABIL
A16: 46997 | B16: 9.37 | C16: 8.53 | D16: 7.98 | E16: 7.81 | F16: 8.48 | G16: 10.48 | H16: 12.87 | I16: 12.1 | J16: 13.47 | K16: 15.3 | L16: 17.31 | M16: 18.79 | N16: 18.31 | O16: 17.91 | P16: 18.28 | Q16: 18.22 | R16: 17.78 | S16: 20.64 | T16: 21.46 | U16: 21.45 | V16: 20.07 | W16: 18.01 | X16: 14.83 | Y16: 12.45 | Z16: =SUM(B16:Y16) -> 361.9 | AA16: 21 | AB16: =+Z16*AA16 -> 7599.9 | AD16: HABIL
A17: 47027 | B17: 9.26 | C17: 8.39 | D17: 7.89 | E17: 7.73 | F17: 8.22 | G17: 9.39 | H17: 12 | I17: 11.75 | J17: 13.95 | K17: 15.87 | L17: 17.69 | M17: 19.13 | N17: 18.75 | O17: 18.35 | P17: 18.61 | Q17: 18.33 | R17: 17.94 | S17: 21.21 | T17: 22.02 | U17: 21.3 | V17: 19.96 | W17: 17.9 | X17: 14.97 | Y17: 12.6 | Z17: =SUM(B17:Y17) -> 363.21 | AA17: 21 | AB17: =+Z17*AA17 -> 7627.41 | AD17: HABIL
A18: 47058 | B18: 9.5 | C18: 8.64 | D18: 8.06 | E18: 7.88 | F18: 8.39 | G18: 9.77 | H18: 12.25 | I18: 12.03 | J18: 14.06 | K18: 15.74 | L18: 17.37 | M18: 18.85 | N18: 18.59 | O18: 18.2 | P18: 18.68 | Q18: 18.51 | R18: 18.11 | S18: 21.6 | T18: 22.21 | U18: 21.6 | V18: 20.29 | W18: 18.22 | X18: 15.2 | Y18: 12.77 | Z18: =SUM(B18:Y18) -> 366.52 | AA18: 20 | AB18: =+Z18*AA18 -> 7330.4 | AD18: HABIL
A19: 47088 | B19: 10.3 | C19: 9.23 | D19: 8.55 | E19: 8.26 | F19: 8.62 | G19: 9.75 | H19: 12 | I19: 11.82 | J19: 14.1 | K19: 15.79 | L19: 17.41 | M19: 18.82 | N19: 18.81 | O19: 18.53 | P19: 18.75 | Q19: 18.57 | R19: 18.01 | S19: 20.88 | T19: 21.95 | U19: 21.88 | V19: 20.63 | W19: 18.89 | X19: 16.26 | Y19: 13.96 | Z19: =SUM(B19:Y19) -> 371.77 | AA19: 19 | AB19: =+Z19*AA19 -> 7063.63 | AD19: HABIL
A21: DEMANDA DIARIA ESTIMADA DÍA SABADO [MWh]
A23: MES | B23: H1 | C23: H2 | D23: H3 | E23: H4 | F23: H5 | G23: H6 | H23: H7 | I23: H8 | J23: H9 | K23: H10 | L23: H11 | M23: H12 | N23: H13 | O23: H14 | P23: H15 | Q23: H16 | R23: H17 | S23: H18 | T23: H19 | U23: H20 | V23: H21 | W23: H22 | X23: H23 | Y23: H24 | Z23: TOTAL | AA23: Días
A24: =+A8 -> 46753 | B24: 9.47 | C24: 8.52 | D24: 7.85 | E24: 7.49 | F24: 7.62 | G24: 8.3 | H24: 9.7 | I24: 9.07 | J24: 11.23 | K24: 13.29 | L24: 14.71 | M24: 15.87 | N24: 16.01 | O24: 15.27 | P24: 14.66 | Q24: 14.38 | R24: 13.96 | S24: 17.31 | T24: 18.34 | U24: 18.82 | V24: 17.71 | W24: 16.16 | X24: 14.1 | Y24: 12.38 | Z24: =SUM(B24:Y24) -> 312.22 | AA24: 4 | AB24: =+Z24*AA24 -> 1248.88 | AD24: SABADOS
A25: =+A9 -> 46784 | B25: 9.11 | C25: 8.28 | D25: 7.68 | E25: 7.38 | F25: 7.54 | G25: 8.46 | H25: 10.16 | I25: 9.54 | J25: 11.62 | K25: 13.35 | L25: 14.72 | M25: 15.6 | N25: 15.56 | O25: 15.04 | P25: 14.61 | Q25: 14.35 | R25: 14.06 | S25: 17.06 | T25: 17.58 | U25: 18.66 | V25: 17.65 | W25: 16.23 | X25: 14.16 | Y25: 12.48 | Z25: =SUM(B25:Y25) -> 310.88 | AA25: 4 | AB25: =+Z25*AA25 -> 1243.52 | AD25: SABADOS
A26: =+A10 -> 46813 | B26: 8.96 | C26: 8.09 | D26: 7.49 | E26: 7.17 | F26: 7.44 | G26: 8.34 | H26: 9.8 | I26: 9.42 | J26: 11.58 | K26: 13.2 | L26: 14.53 | M26: 15.73 | N26: 15.67 | O26: 14.85 | P26: 14.28 | Q26: 13.99 | R26: 13.69 | S26: 16.99 | T26: 17.42 | U26: 18 | V26: 16.98 | W26: 15.6 | X26: 13.56 | Y26: 11.9 | Z26: =SUM(B26:Y26) -> 304.68 | AA26: 4 | AB26: =+Z26*AA26 -> 1218.72 | AD26: SABADOS
A27: =+A11 -> 46844 | B27: 9.25 | C27: 8.31 | D27: 7.64 | E27: 7.31 | F27: 7.48 | G27: 7.97 | H27: 9.74 | I27: 9.51 | J27: 11.62 | K27: 13.45 | L27: 14.83 | M27: 15.92 | N27: 15.97 | O27: 15.09 | P27: 14.57 | Q27: 14.3 | R27: 13.82 | S27: 17.14 | T27: 18.02 | U27: 18.65 | V27: 17.6 | W27: 16.1 | X27: 14.09 | Y27: 12.41 | Z27: =SUM(B27:Y27) -> 310.79 | AA27: 5 | AB27: =+Z27*AA27 -> 1553.95 | AD27: SABADOS
A28: =+A12 -> 46874 | B28: 8.89 | C28: 8.07 | D28: 7.46 | E28: 7.17 | F28: 7.4 | G28: 7.92 | H28: 9.92 | I28: 9.76 | J28: 11.91 | K28: 13.86 | L28: 15.12 | M28: 16.12 | N28: 15.88 | O28: 14.89 | P28: 14.44 | Q28: 14.12 | R28: 13.69 | S28: 17.06 | T28: 17.98 | U28: 18.62 | V28: 17.47 | W28: 15.96 | X28: 13.88 | Y28: 12.17 | Z28: =SUM(B28:Y28) -> 309.76 | AA28: 4 | AB28: =+Z28*AA28 -> 1239.04 | AD28: SABADOS
A29: =+A13 -> 46905 | B29: 8.96 | C29: 8.06 | D29: 7.44 | E29: 7.15 | F29: 7.39 | G29: 8.08 | H29: 9.75 | I29: 9.53 | J29: 11.73 | K29: 13.66 | L29: 14.89 | M29: 16.03 | N29: 16.12 | O29: 15.36 | P29: 14.66 | Q29: 14.14 | R29: 13.69 | S29: 17.03 | T29: 17.92 | U29: 18.6 | V29: 17.43 | W29: 15.85 | X29: 13.67 | Y29: 11.83 | Z29: =SUM(B29:Y29) -> 308.97 | AA29: 4 | AB29: =+Z29*AA29 -> 1235.88 | AD29: SABADOS
A30: =+A14 -> 46935 | B30: 9.29 | C30: 8.32 | D30: 7.56 | E30: 7.26 | F30: 7.47 | G30: 7.95 | H30: 9.75 | I30: 9.42 | J30: 11.8 | K30: 13.82 | L30: 15.15 | M30: 16.33 | N30: 16.43 | O30: 15.57 | P30: 14.77 | Q30: 14.16 | R30: 13.76 | S30: 17.19 | T30: 17.73 | U30: 18.96 | V30: 17.77 | W30: 16.28 | X30: 14.2 | Y30: 12.42 | Z30: =SUM(B30:Y30) -> 313.36 | AA30: 5 | AB30: =+Z30*AA30 -> 1566.8 | AD30: SABADOS
A31: =+A15 -> 46966 | B31: 9.27 | C31: 8.38 | D31: 7.72 | E31: 7.37 | F31: 7.61 | G31: 8.26 | H31: 10.07 | I31: 9.67 | J31: 11.83 | K31: 13.71 | L31: 15.04 | M31: 16.14 | N31: 16.12 | O31: 15.25 | P31: 14.55 | Q31: 13.93 | R31: 13.48 | S31: 16.68 | T31: 17.44 | U31: 18.34 | V31: 17.23 | W31: 15.8 | X31: 13.79 | Y31: 12.04 | Z31: =SUM(B31:Y31) -> 309.72 | AA31: 4 | AB31: =+Z31*AA31 -> 1238.88 | AD31: SABADOS
A32: =+A16 -> 46997 | B32: 8.88 | C32: 8.03 | D32: 7.42 | E32: 7.07 | F32: 7.31 | G32: 7.91 | H32: 9.76 | I32: 9.68 | J32: 11.86 | K32: 13.61 | L32: 15.07 | M32: 16.21 | N32: 15.7 | O32: 15.26 | P32: 14.46 | Q32: 14.05 | R32: 13.52 | S32: 17.4 | T32: 18.47 | U32: 18.3 | V32: 17.09 | W32: 15.53 | X32: 13.4 | Y32: 11.71 | Z32: =SUM(B32:Y32) -> 307.7 | AA32: 5 | AB32: =+Z32*AA32 -> 1538.5 | AD32: SABADOS
A33: =+A17 -> 47027 | B33: 9.05 | C33: 8.16 | D33: 7.54 | E33: 7.27 | F33: 7.5 | G33: 7.84 | H33: 9.79 | I33: 9.65 | J33: 11.93 | K33: 13.71 | L33: 15.09 | M33: 16.22 | N33: 16.18 | O33: 15.43 | P33: 14.84 | Q33: 14.31 | R33: 13.78 | S33: 17.58 | T33: 18.83 | U33: 18.34 | V33: 16.95 | W33: 15.5 | X33: 13.61 | Y33: 11.93 | Z33: =SUM(B33:Y33) -> 311.03 | AA33: 4 | AB33: =+Z33*AA33 -> 1244.12 | AD33: SABADOS
A34: =+A18 -> 47058 | B34: 9.16 | C34: 8.26 | D34: 7.63 | E34: 7.29 | F34: 7.52 | G34: 7.92 | H34: 9.91 | I34: 9.9 | J34: 12.09 | K34: 13.87 | L34: 15.32 | M34: 16.53 | N34: 16.45 | O34: 15.55 | P34: 14.87 | Q34: 14.57 | R34: 14.2 | S34: 17.66 | T34: 19.19 | U34: 18.87 | V34: 17.62 | W34: 16.22 | X34: 14.07 | Y34: 12.3 | Z34: =SUM(B34:Y34) -> 316.97 | AA34: 4 | AB34: =+Z34*AA34 -> 1267.88 | AD34: SABADOS
A35: =+A19 -> 47088 | B35: 9.99 | C35: 8.94 | D35: 8.21 | E35: 7.83 | F35: 8.04 | G35: 8.6 | H35: 10.47 | I35: 10.26 | J35: 12.58 | K35: 14.4 | L35: 15.82 | M35: 17.04 | N35: 16.99 | O35: 16.03 | P35: 15.17 | Q35: 14.73 | R35: 14.53 | S35: 18.21 | T35: 19.54 | U35: 19.41 | V35: 18.2 | W35: 16.66 | X35: 14.56 | Y35: 12.83 | Z35: =SUM(B35:Y35) -> 329.04 | AA35: 5 | AB35: =+Z35*AA35 -> 1645.2 | AD35: SABADOS
A37: DEMANDA DIARIA ESTIMADA DÍA DOMINGO Y FESTIVO DIFERENTE A LUNES [MWh]
A39: MES | B39: H1 | C39: H2 | D39: H3 | E39: H4 | F39: H5 | G39: H6 | H39: H7 | I39: H8 | J39: H9 | K39: H10 | L39: H11 | M39: H12 | N39: H13 | O39: H14 | P39: H15 | Q39: H16 | R39: H17 | S39: H18 | T39: H19 | U39: H20 | V39: H21 | W39: H22 | X39: H23 | Y39: H24 | Z39: TOTAL | AA39: Días
A40: =+A24 -> 46753 | B40: 7.95 | C40: 7.19 | D40: 6.42 | E40: 6.11 | F40: 5.93 | G40: 5.99 | H40: 6.31 | I40: 4.69 | J40: 5.66 | K40: 6.87 | L40: 7.89 | M40: 8.82 | N40: 9.44 | O40: 9.49 | P40: 9.18 | Q40: 9.01 | R40: 8.94 | S40: 11.76 | T40: 12.77 | U40: 13.84 | V40: 13.53 | W40: 12.44 | X40: 10.79 | Y40: 9.45 | Z40: =SUM(B40:Y40) -> 210.47 | AA40: 6 | AB40: =+Z40*AA40 -> 1262.82 | AD40: DOMINGOS Y FESTIVOS
A41: =+A25 -> 46784 | B41: 7.94 | C41: 7.14 | D41: 6.45 | E41: 6.08 | F41: 6.03 | G41: 6.26 | H41: 6.81 | I41: 5.44 | J41: 6.66 | K41: 7.99 | L41: 8.8 | M41: 9.67 | N41: 10.07 | O41: 9.87 | P41: 9.37 | Q41: 9.04 | R41: 8.84 | S41: 11.72 | T41: 12.31 | U41: 13.96 | V41: 13.58 | W41: 12.33 | X41: 10.34 | Y41: 8.7 | Z41: =SUM(B41:Y41) -> 215.4 | AA41: 4 | AB41: =+Z41*AA41 -> 861.6 | AD41: DOMINGOS Y FESTIVOS
A42: =+A26 -> 46813 | B42: 7.61 | C42: 6.84 | D42: 6.27 | E42: 5.92 | F42: 5.82 | G42: 6.09 | H42: 6.58 | I42: 5.32 | J42: 6.42 | K42: 7.62 | L42: 8.4 | M42: 9.13 | N42: 9.67 | O42: 9.62 | P42: 9.13 | Q42: 8.89 | R42: 8.87 | S42: 11.94 | T42: 12.83 | U42: 13.87 | V42: 13.3 | W42: 12.05 | X42: 10.28 | Y42: 8.74 | Z42: =SUM(B42:Y42) -> 211.21 | AA42: 4 | AB42: =+Z42*AA42 -> 844.84 | AD42: DOMINGOS Y FESTIVOS
A43: =+A27 -> 46844 | B43: 7.5 | C43: 6.69 | D43: 6.07 | E43: 5.74 | F43: 5.73 | G43: 5.74 | H43: 6.32 | I43: 5.31 | J43: 6.49 | K43: 7.78 | L43: 8.77 | M43: 9.75 | N43: 10.23 | O43: 9.97 | P43: 9.69 | Q43: 9.1 | R43: 8.96 | S43: 12.1 | T43: 12.96 | U43: 13.73 | V43: 13.25 | W43: 12.08 | X43: 10.33 | Y43: 8.96 | Z43: =SUM(B43:Y43) -> 213.25 | AA43: 7 | AB43: =+Z43*AA43 -> 1492.75 | AD43: DOMINGOS Y FESTIVOS
A44: =+A28 -> 46874 | B44: 7.55 | C44: 6.74 | D44: 6.17 | E44: 5.78 | F44: 5.68 | G44: 5.45 | H44: 6.45 | I44: 5.46 | J44: 6.69 | K44: 8.13 | L44: 9.08 | M44: 9.81 | N44: 9.95 | O44: 9.84 | P44: 9.12 | Q44: 9.18 | R44: 9.13 | S44: 12.11 | T44: 12.91 | U44: 14.01 | V44: 13.59 | W44: 12.38 | X44: 10.47 | Y44: 8.94 | Z44: =SUM(B44:Y44) -> 214.62 | AA44: 4 | AB44: =+Z44*AA44 -> 858.48 | AD44: DOMINGOS Y FESTIVOS
A45: =+A29 -> 46905 | B45: 7.19 | C45: 6.38 | D45: 5.84 | E45: 5.48 | F45: 5.45 | G45: 5.5 | H45: 6.23 | I45: 5.27 | J45: 6.48 | K45: 7.81 | L45: 8.59 | M45: 9.27 | N45: 9.67 | O45: 9.63 | P45: 9.19 | Q45: 8.85 | R45: 8.65 | S45: 11.49 | T45: 12.23 | U45: 13.6 | V45: 13.16 | W45: 11.96 | X45: 10.25 | Y45: 8.74 | Z45: =SUM(B45:Y45) -> 206.91 | AA45: 4 | AB45: =+Z45*AA45 -> 827.64 | AD45: DOMINGOS Y FESTIVOS
A46: =+A30 -> 46935 | B46: 7.7 | C46: 6.93 | D46: 6.34 | E46: 5.94 | F46: 5.89 | G46: 5.9 | H46: 6.52 | I46: 5.48 | J46: 6.74 | K46: 8.1 | L46: 8.97 | M46: 9.92 | N46: 10.3 | O46: 9.98 | P46: 9.53 | Q46: 9.23 | R46: 9.2 | S46: 12.18 | T46: 12.71 | U46: 14.14 | V46: 13.75 | W46: 12.5 | X46: 10.64 | Y46: 9.07 | Z46: =SUM(B46:Y46) -> 217.66 | AA46: 6 | AB46: =+Z46*AA46 -> 1305.96 | AD46: DOMINGOS Y FESTIVOS
A47: =+A31 -> 46966 | B47: 7.76 | C47: 6.97 | D47: 6.39 | E47: 6.04 | F47: 5.97 | G47: 5.98 | H47: 6.43 | I47: 5.34 | J47: 6.63 | K47: 7.98 | L47: 9.02 | M47: 9.86 | N47: 10.34 | O47: 10.25 | P47: 9.8 | Q47: 9.48 | R47: 9.16 | S47: 12.06 | T47: 12.87 | U47: 14.18 | V47: 13.78 | W47: 12.52 | X47: 10.6 | Y47: 9.05 | Z47: =SUM(B47:Y47) -> 218.46 | AA47: 4 | AB47: =+Z47*AA47 -> 873.84 | AD47: DOMINGOS Y FESTIVOS
...
