Workbook

Sheet Dis Horaria Solicita Produc 1
A1: Distribución Horaria Solicitada (kWh)
A2: Producto No. 1 - 01 al 31 de enero de 2026
A4: Oferente:
A6: Mes | B6: Tipo Dia | C6: Dias | D6: H1 | E6: H2 | F6: H3 | G6: H4 | H6: H5 | I6: H6 | J6: H7 | K6: H8 | L6: H9 | M6: H10 | N6: H11 | O6: H12 | P6: H13 | Q6: H14 | R6: H15 | S6: H16 | T6: H17 | U6: H18 | V6: H19 | W6: H20 | X6: H21 | Y6: H22 | Z6: H23 | AA6: H24 | AB6: total Mes
A7: 46023 | B7: Laboral | C7: 20 | D7: 10636 | E7: 9870 | F7: 9434 | G7: 9289 | H7: 9568 | I7: 10996 | J7: 11308 | K7: 12814 | L7: 14006 | M7: 14879 | N7: 15650 | O7: 16886 | P7: 17063 | Q7: 16801 | R7: 17092 | S7: 17248 | T7: 17148 | U7: 17463 | V7: 19683 | W7: 20368 | X7: 19522 | Y7: 17827 | Z7: 15220 | AA7: 13117 | AB7: =+SUM(D7:AA7)*C7+SUM(D8:AA8)*C8+SUM(D9:AA9)*C9+SUM(D10:AA10)*C10 -> 10580849
B8: Sábado | C8: 5 | D8: 10747 | E8: 9881 | F8: 9423 | G8: 9140 | H8: 9229 | I8: 9828 | J8: 9642 | K8: 11569 | L8: 12971 | M8: 14064 | N8: 14941 | O8: 15762 | P8: 16256 | Q8: 15800 | R8: 15470 | S8: 15166 | T8: 15233 | U8: 15948 | V8: 18251 | W8: 19154 | X8: 18246 | Y8: 16988 | Z8: 15099 | AA8: 13255
B9: Domingo | C9: 4 | D9: 11030 | E9: 10038 | F9: 9418 | G9: 8989 | H9: 8934 | I9: 9148 | J9: 8390 | K9: 9372 | L9: 10614 | M9: 11740 | N9: 12653 | O9: 13480 | P9: 14310 | Q9: 14492 | R9: 14164 | S9: 14060 | T9: 14260 | U9: 15163 | V9: 17736 | W9: 18761 | X9: 18056 | Y9: 16585 | Z9: 14512 | AA9: 12257
B10: Festivo | C10: 2 | D10: 11453 | E10: 10567 | F10: 9890 | G10: 9384 | H10: 9269 | I10: 9361 | J10: 8349 | K10: 9244 | L10: 10171 | M10: 11131 | N10: 12156 | O10: 13310 | P10: 14096 | Q10: 14058 | R10: 13832 | S10: 13867 | T10: 13765 | U10: 14669 | V10: 17562 | W10: 18289 | X10: 17710 | Y10: 16207 | Z10: 14343 | AA10: 12380
Z11: Total Año kWh | AB11: =+SUM(AB7:AB10) -> 10580849

Sheet Cantidad-Precio Ofertado Pr 1
A1: Precios y Cantidades de Energía Oferta (kWh) | I1: Curva
A2: Producto No. 1 - 01 al 31 de enero de 2026 | I2: Plana
A3: $ mayo 2025
A5: Oferente:
A6: Tipo de oferta:
B8: Oferta Producto 1
B9: MES | C9: Energía solicitada kWh | D9: % | E9: Energía ofertada mes kWh | F9: Precio ofertado mes $/kWh
B10: 46023 | C10: =+'Dis Horaria Solicita Produc 1'!AB11 -> 10580849
B11: Total | C11: =SUM(C10:C10) -> 10580849 | E11: =SUM(E10:E10) -> 0
A13: Notas: | B13: 1. La Energía Ofertada se distribuye en forma horaria de acuerdo con la carga curva o plana presentada en el Anexo 8.1. 2. Tipo de Contrato: pague lo contratado. 3. Precio ofertado en $kWh, en pesos de mayo 2025.

Sheet Dis Horaria Solicita Produc 2
A1: Distribución Horaria Solicitada (kWh)
A2: Producto No. 2 - 01 al 28 de febrero de 2026
A4: Oferente:
A6: Mes | B6: Tipo Dia | C6: Dias | D6: H1 | E6: H2 | F6: H3 | G6: H4 | H6: H5 | I6: H6 | J6: H7 | K6: H8 | L6: H9 | M6: H10 | N6: H11 | O6: H12 | P6: H13 | Q6: H14 | R6: H15 | S6: H16 | T6: H17 | U6: H18 | V6: H19 | W6: H20 | X6: H21 | Y6: H22 | Z6: H23 | AA6: H24 | AB6: total Mes
A7: 46054 | B7: Laboral | C7: 20 | D7: 9679 | E7: 9016 | F7: 8760 | G7: 8663 | H7: 9106 | I7: 11132 | J7: 11492 | K7: 12684 | L7: 13560 | M7: 14087 | N7: 14731 | O7: 15812 | P7: 15863 | Q7: 15386 | R7: 15681 | S7: 15772 | T7: 15764 | U7: 16465 | V7: 18601 | W7: 18927 | X7: 18013 | Y7: 16258 | Z7: 13957 | AA7: 12010 | AB7: =+SUM(D7:AA7)*C7+SUM(D8:AA8)*C8+SUM(D9:AA9)*C9+SUM(D10:AA10)*C10 -> 9113012
B8: Sábado | C8: 4 | D8: 10655 | E8: 9860 | F8: 9454 | G8: 9229 | H8: 9381 | I8: 9882 | J8: 10207 | K8: 11556 | L8: 13087 | M8: 13969 | N8: 14433 | O8: 15137 | P8: 15488 | Q8: 14933 | R8: 14332 | S8: 14374 | T8: 14488 | U8: 15852 | V8: 18293 | W8: 18642 | X8: 17633 | Y8: 16328 | Z8: 14422 | AA8: 12532
B9: Domingo | C9: 4 | D9: 10488 | E9: 9605 | F9: 9164 | G9: 8872 | H9: 8782 | I9: 9003 | J9: 8444 | K9: 9286 | L9: 10566 | M9: 11634 | N9: 12242 | O9: 13197 | P9: 14061 | Q9: 13878 | R9: 13659 | S9: 13517 | T9: 13593 | U9: 14630 | V9: 17181 | W9: 17835 | X9: 17073 | Y9: 15596 | Z9: 13393 | AA9: 11292
B10: Festivo | C10: 0 | D10: 0 | E10: 0 | F10: 0 | G10: 0 | H10: 0 | I10: 0 | J10: 0 | K10: 0 | L10: 0 | M10: 0 | N10: 0 | O10: 0 | P10: 0 | Q10: 0 | R10: 0 | S10: 0 | T10: 0 | U10: 0 | V10: 0 | W10: 0 | X10: 0 | Y10: 0 | Z10: 0 | AA10: 0
Z11: Total Año kWh | AB11: =+SUM(AB7:AB10) -> 9113012

Sheet Cantidad-Precio Ofertado Pr 2
A1: Precios y Cantidades de Energía Oferta (kWh) | I1: Curva
A2: Producto No. 2 - 01 al 28 de febrero de 2026 | I2: Plana
A3: $ mayo 2025
A5: Oferente:
A6: Tipo de oferta:
B8: Oferta Producto 2
B9: MES | C9: Energía solicitada kWh | D9: % | E9: Energía ofertada mes kWh | F9: Precio ofertado mes $/kWh
B10: 46054 | C10: =+'Dis Horaria Solicita Produc 2'!AB11 -> 9113012
B11: Total | C11: =SUM(C10:C10) -> 9113012 | E11: =SUM(E10:E10) -> 0
A13: Notas: | B13: 1. La Energía Ofertada se distribuye en forma horaria de acuerdo con la carga curva o plana presentada en el Anexo 8.2. 2. Tipo de Contrato: pague lo contratado. 3. Precio ofertado en $kWh, en pesos de mayo 2025.

Sheet Dis Horaria Solicita Produc 3
A1: Distribución Horaria Solicitada (kWh)
A2: Producto No. 3 - 01 al 31 de marzo de 2026
A4: Oferente:
A6: Mes | B6: Tipo Dia | C6: Dias | D6: H1 | E6: H2 | F6: H3 | G6: H4 | H6: H5 | I6: H6 | J6: H7 | K6: H8 | L6: H9 | M6: H10 | N6: H11 | O6: H12 | P6: H13 | Q6: H14 | R6: H15 | S6: H16 | T6: H17 | U6: H18 | V6: H19 | W6: H20 | X6: H21 | Y6: H22 | Z6: H23 | AA6: H24 | AB6: total Mes
A7: 46082 | B7: Laboral | C7: 21 | D7: 9510 | E7: 8854 | F7: 8633 | G7: 8530 | H7: 9001 | I7: 10913 | J7: 11143 | K7: 12330 | L7: 13238 | M7: 13752 | N7: 14362 | O7: 15474 | P7: 15409 | Q7: 14998 | R7: 15452 | S7: 15567 | T7: 15599 | U7: 16326 | V7: 18543 | W7: 18791 | X7: 17751 | Y7: 15938 | Z7: 13776 | AA7: 11799 | AB7: =+SUM(D7:AA7)*C7+SUM(D8:AA8)*C8+SUM(D9:AA9)*C9+SUM(D10:AA10)*C10 -> 9947144
B8: Sábado | C8: 4 | D8: 10215 | E8: 9388 | F8: 8965 | G8: 8719 | H8: 8893 | I8: 9562 | J8: 9655 | K8: 11319 | L8: 12677 | M8: 13863 | N8: 14443 | O8: 15084 | P8: 15266 | Q8: 14826 | R8: 14511 | S8: 14663 | T8: 14717 | U8: 15905 | V8: 18614 | W8: 18690 | X8: 17857 | Y8: 16505 | Z8: 14666 | AA8: 12821
B9: Domingo | C9: 5 | D9: 10572 | E9: 9662 | F9: 9152 | G9: 8796 | H9: 8734 | I9: 8920 | J9: 8179 | K9: 9283 | L9: 10548 | M9: 11373 | N9: 12116 | O9: 13075 | P9: 13923 | Q9: 13690 | R9: 13515 | S9: 13566 | T9: 13873 | U9: 14955 | V9: 17241 | W9: 18060 | X9: 17314 | Y9: 15873 | Z9: 13877 | AA9: 11707
B10: Festivo | C10: 1 | D10: 11262 | E10: 10278 | F10: 9752 | G10: 9449 | H10: 9548 | I10: 9601 | J10: 9078 | K10: 10380 | L10: 11823 | M10: 13220 | N10: 14160 | O10: 15603 | P10: 16216 | Q10: 16139 | R10: 15845 | S10: 15387 | T10: 15507 | U10: 16638 | V10: 19108 | W10: 19488 | X10: 18448 | Y10: 16715 | Z10: 14611 | AA10: 12103
Z11: Total Año kWh | AB11: =+SUM(AB7:AB10) -> 9947144

Sheet Cantidad-Precio Ofertado Pr 3
A1: Precios y Cantidades de Energía Oferta (kWh) | I1: Curva
A2: Producto No. 3 - 01 al 31 de marzo de 2026 | I2: Plana
A3: $ mayo 2025
A5: Oferente:
A6: Tipo de oferta:
B8: Oferta Producto 3
B9: MES | C9: Energía solicitada kWh | D9: % | E9: Energía ofertada mes kWh | F9: Precio ofertado mes $/kWh
B10: 46082 | C10: =+'Dis Horaria Solicita Produc 3'!AB11 -> 9947144
B11: Total | C11: =SUM(C10:C10) -> 9947144 | E11: =SUM(E10:E10) -> 0
A13: Notas: | B13: 1. La Energía Ofertada se distribuye en forma horaria de acuerdo con la carga curva o plana presentada en el Anexo 8.3. 2. Tipo de Contrato: pague lo contratado. 3. Precio ofertado en $kWh, en pesos de mayo 2025.

Sheet Dis Horaria Solicita Produc 4
A1: Distribución Horaria Solicitada (kWh)
A2: Producto No. 4 - 01 al 30 de noviembre de 2026
A4: Oferente:
A6: Mes | B6: Tipo Dia | C6: Dias | D6: H1 | E6: H2 | F6: H3 | G6: H4 | H6: H5 | I6: H6 | J6: H7 | K6: H8 | L6: H9 | M6: H10 | N6: H11 | O6: H12 | P6: H13 | Q6: H14 | R6: H15 | S6: H16 | T6: H17 | U6: H18 | V6: H19 | W6: H20 | X6: H21 | Y6: H22 | Z6: H23 | AA6: H24 | AB6: total Mes
A7: 46327 | B7: Laboral | C7: 19 | D7: 10020 | E7: 9256 | F7: 8853 | G7: 8759 | H7: 9136 | I7: 10403 | J7: 10981 | K7: 12548 | L7: 13604 | M7: 14332 | N7: 15116 | O7: 16249 | P7: 16259 | Q7: 16025 | R7: 16175 | S7: 16324 | T7: 16348 | U7: 17198 | V7: 19729 | W7: 19419 | X7: 18164 | Y7: 16572 | Z7: 14452 | AA7: 12392 | AB7: =+SUM(D7:AA7)*C7+SUM(D8:AA8)*C8+SUM(D9:AA9)*C9+SUM(D10:AA10)*C10 -> 9824957
B8: Sábado | C8: 4 | D8: 10380 | E8: 9484 | F8: 9045 | G8: 8808 | H8: 8946 | I8: 9471 | J8: 9294 | K8: 11172 | L8: 12774 | M8: 13793 | N8: 14341 | O8: 15269 | P8: 15592 | Q8: 15291 | R8: 15071 | S8: 15109 | T8: 15310 | U8: 16222 | V8: 19117 | W8: 19220 | X8: 18252 | Y8: 16658 | Z8: 15165 | AA8: 13239
B9: Domingo | C9: 5 | D9: 10713 | E9: 9771 | F9: 9248 | G9: 8900 | H9: 8936 | I9: 9097 | J9: 8441 | K9: 9467 | L9: 10473 | M9: 11415 | N9: 12048 | O9: 12919 | P9: 13518 | Q9: 13677 | R9: 13464 | S9: 13391 | T9: 13750 | U9: 15169 | V9: 17850 | W9: 18020 | X9: 17251 | Y9: 15923 | Z9: 14224 | AA9: 12306
B10: Festivo | C10: 2 | D10: 10274 | E10: 9455 | F10: 8927 | G10: 8595 | H10: 8578 | I10: 8803 | J10: 8212 | K10: 9368 | L10: 10624 | M10: 11688 | N10: 12310 | O10: 13258 | P10: 14127 | Q10: 13804 | R10: 13450 | S10: 13276 | T10: 13556 | U10: 14380 | V10: 17614 | W10: 17702 | X10: 16883 | Y10: 15300 | Z10: 13117 | AA10: 11221
Z11: Total Año kWh | AB11: =+SUM(AB7:AB10) -> 9824957

Sheet Cantidad-Precio Ofertado Pr 4
A1: Precios y Cantidades de Energía Oferta (kWh) | I1: Curva
A2: Producto No. 4 - 01 al 30 de noviembre de 2026 | I2: Plana
A3: $ mayo 2025
A5: Oferente:
A6: Tipo de oferta:
B8: Oferta Producto 4
B9: MES | C9: Energía solicitada kWh | D9: % | E9: Energía ofertada mes kWh | F9: Precio ofertado mes $/kWh
B10: 46327 | C10: =+'Dis Horaria Solicita Produc 4'!AB11 -> 9824957
B11: Total | C11: =SUM(C10:C10) -> 9824957 | E11: =SUM(E10:E10) -> 0
A13: Notas: | B13: 1. La Energía Ofertada se distribuye en forma horaria de acuerdo con la carga curva o plana presentada en el Anexo 8.4. 2. Tipo de Contrato: pague lo contratado. 3. Precio ofertado en $kWh, en pesos de mayo 2025.

Sheet Dis Horaria Solicita Produc 5
A1: Distribución Horaria Solicitada (kWh)
A2: Producto No. 5 - 01 al 31 de diciembre de 2026
A4: Oferente:
A6: Mes | B6: Tipo Dia | C6: Dias | D6: H1 | E6: H2 | F6: H3 | G6: H4 | H6: H5 | I6: H6 | J6: H7 | K6: H8 | L6: H9 | M6: H10 | N6: H11 | O6: H12 | P6: H13 | Q6: H14 | R6: H15 | S6: H16 | T6: H17 | U6: H18 | V6: H19 | W6: H20 | X6: H21 | Y6: H22 | Z6: H23 | AA6: H24 | AB6: total Mes
A7: 46357 | B7: Laboral | C7: 21 | D7: 9071 | E7: 8371 | F7: 7945 | G7: 7792 | H7: 7973 | I7: 8725 | J7: 8886 | K7: 10345 | L7: 11565 | M7: 12411 | N7: 13039 | O7: 14185 | P7: 14462 | Q7: 14147 | R7: 14447 | S7: 14359 | T7: 13997 | U7: 14664 | V7: 16846 | W7: 16882 | X7: 15833 | Y7: 14552 | Z7: 12915 | AA7: 11200 | AB7: =+SUM(D7:AA7)*C7+SUM(D8:AA8)*C8+SUM(D9:AA9)*C9+SUM(D10:AA10)*C10 -> 8862854
B8: Sábado | C8: 4 | D8: 9412 | E8: 8557 | F8: 8143 | G8: 7798 | H8: 7906 | I8: 8350 | J8: 8244 | K8: 9616 | L8: 11141 | M8: 11832 | N8: 12516 | O8: 13413 | P8: 13795 | Q8: 13491 | R8: 13110 | S8: 12744 | T8: 12578 | U8: 13506 | V8: 16112 | W8: 15859 | X8: 14935 | Y8: 13929 | Z8: 12766 | AA8: 11371
B9: Domingo | C9: 4 | D9: 9714 | E9: 8757 | F9: 8250 | G9: 7913 | H9: 7840 | I9: 7912 | J9: 7360 | K9: 8258 | L9: 9262 | M9: 10106 | N9: 10815 | O9: 11379 | P9: 12031 | Q9: 12121 | R9: 12000 | S9: 12044 | T9: 12039 | U9: 12793 | V9: 15191 | W9: 15635 | X9: 14968 | Y9: 13888 | Z9: 12298 | AA9: 10582
B10: Festivo | C10: 2 | D10: 9827 | E10: 8925 | F10: 8303 | G10: 7842 | H10: 7695 | I10: 7631 | J10: 6564 | K10: 7223 | L10: 7980 | M10: 8663 | N10: 9490 | O10: 10218 | P10: 10961 | Q10: 10949 | R10: 11245 | S10: 11310 | T10: 11410 | U10: 12437 | V10: 14940 | W10: 15023 | X10: 14487 | Y10: 13599 | Z10: 12158 | AA10: 10561
Z11: Total Año kWh | AB11: =+SUM(AB7:AB10) -> 8862854

Sheet Cantidad-Precio Ofertado Pr 5
A1: Precios y Cantidades de Energía Oferta (kWh) | I1: Curva
A2: Producto No. 5 - 01 al 31 de diciembre de 2026 | I2: Plana
A3: $ mayo 2025
A5: Oferente:
A6: Tipo de oferta:
B8: Oferta Producto 5
B9: MES | C9: Energía solicitada kWh | D9: % | E9: Energía ofertada mes kWh | F9: Precio ofertado mes $/kWh
B10: 46357 | C10: =+'Dis Horaria Solicita Produc 5'!AB11 -> 8862854
B11: Total | C11: =SUM(C10:C10) -> 8862854 | E11: =SUM(E10:E10) -> 0
A13: Notas: | B13: 1. La Energía Ofertada se distribuye en forma horaria de acuerdo con la carga curva o plana presentada en el Anexo 8.5. 2. Tipo de Contrato: pague lo contratado. 3. Precio ofertado en $kWh, en pesos de mayo 2025.

Sheet Dis Horaria Solicita Produc 6
A1: Distribución Horaria Solicitada (kWh)
A2: Producto No. 6 - 01 de enero al 31 de diciembre de 2027
A4: Oferente:
A6: Mes | B6: Tipo Dia | C6: Dias | D6: H1 | E6: H2 | F6: H3 | G6: H4 | H6: H5 | I6: H6 | J6: H7 | K6: H8 | L6: H9 | M6: H10 | N6: H11 | O6: H12 | P6: H13 | Q6: H14 | R6: H15 | S6: H16 | T6: H17 | U6: H18 | V6: H19 | W6: H20 | X6: H21 | Y6: H22 | Z6: H23 | AA6: H24 | AB6: total Mes
A7: 46388 | B7: Laboral | C7: 19 | D7: 553 | E7: 502 | F7: 474 | G7: 466 | H7: 486 | I7: 587 | J7: 676 | K7: 801 | L7: 875 | M7: 931 | N7: 984 | O7: 1059 | P7: 1061 | Q7: 1057 | R7: 1092 | S7: 1106 | T7: 1099 | U7: 1035 | V7: 1122 | W7: 1182 | X7: 1127 | Y7: 1013 | Z7: 834 | AA7: 685 | AB7: =+SUM(D7:AA7)*C7+SUM(D8:AA8)*C8+SUM(D9:AA9)*C9+SUM(D10:AA10)*C10 -> 616591
B8: Sábado | C8: 5 | D8: 564 | E8: 507 | F8: 479 | G8: 463 | H8: 471 | I8: 522 | J8: 594 | K8: 785 | L8: 882 | M8: 948 | N8: 1012 | O8: 1067 | P8: 1077 | Q8: 1045 | R8: 1033 | S8: 1021 | T8: 1025 | U8: 985 | V8: 1067 | W8: 1133 | X8: 1065 | Y8: 982 | Z8: 866 | AA8: 741
B9: Domingo | C9: 5 | D9: 633 | E9: 558 | F9: 508 | G9: 471 | H9: 456 | I9: 438 | J9: 425 | K9: 520 | L9: 599 | M9: 672 | N9: 724 | O9: 765 | P9: 833 | Q9: 856 | R9: 826 | S9: 820 | T9: 835 | U9: 822 | V9: 948 | W9: 1031 | X9: 1000 | Y9: 910 | Z9: 776 | AA9: 630
B10: Festivo | C10: 2 | D10: 634 | E10: 572 | F10: 525 | G10: 487 | H10: 471 | I10: 461 | J10: 441 | K10: 524 | L10: 586 | M10: 651 | N10: 720 | O10: 792 | P10: 850 | Q10: 848 | R10: 831 | S10: 843 | T10: 835 | U10: 825 | V10: 968 | W10: 1019 | X10: 982 | Y10: 890 | Z10: 768 | AA10: 631
A11: 46419 | B11: Laboral | C11: 20 | D11: 486 | E11: 442 | F11: 426 | G11: 420 | H11: 453 | I11: 606 | J11: 696 | K11: 794 | L11: 847 | M11: 877 | N11: 918 | O11: 982 | P11: 977 | Q11: 954 | R11: 981 | S11: 992 | T11: 999 | U11: 966 | V11: 1051 | W11: 1084 | X11: 1018 | Y11: 895 | Z11: 728 | AA11: 602 | AB11: =+SUM(D11:AA11)*C11+SUM(D12:AA12)*C12+SUM(D13:AA13)*C13+SUM(D14:AA14)*C14 -> 527364
B12: Sábado | C12: 4 | D12: 542 | E12: 510 | F12: 484 | G12: 469 | H12: 481 | I12: 515 | J12: 598 | K12: 721 | L12: 820 | M12: 877 | N12: 909 | O12: 952 | P12: 970 | Q12: 936 | R12: 900 | S12: 906 | T12: 918 | U12: 927 | V12: 1020 | W12: 1059 | X12: 991 | Y12: 905 | Z12: 777 | AA12: 644
B13: Domingo | C13: 4 | D13: 549 | E13: 491 | F13: 458 | G13: 438 | H13: 432 | I13: 448 | J13: 480 | K13: 572 | L13: 652 | M13: 715 | N13: 752 | O13: 816 | P13: 873 | Q13: 866 | R13: 856 | S13: 851 | T13: 863 | U13: 839 | V13: 955 | W13: 1017 | X13: 968 | Y13: 871 | Z13: 713 | AA13: 565
B14: Festivo | C14: 0 | D14: 0 | E14: 0 | F14: 0 | G14: 0 | H14: 0 | I14: 0 | J14: 0 | K14: 0 | L14: 0 | M14: 0 | N14: 0 | O14: 0 | P14: 0 | Q14: 0 | R14: 0 | S14: 0 | T14: 0 | U14: 0 | V14: 0 | W14: 0 | X14: 0 | Y14: 0 | Z14: 0 | AA14: 0
A15: 46447 | B15: Laboral | C15: 20 | D15: 477 | E15: 436 | F15: 423 | G15: 417 | H15: 452 | I15: 598 | J15: 684 | K15: 779 | L15: 828 | M15: 857 | N15: 898 | O15: 961 | P15: 948 | Q15: 928 | R15: 972 | S15: 983 | T15: 991 | U15: 963 | V15: 1051 | W15: 1076 | X15: 1010 | Y15: 882 | Z15: 721 | AA15: 589 | AB15: =+SUM(D15:AA15)*C15+SUM(D16:AA16)*C16+SUM(D17:AA17)*C17+SUM(D18:AA18)*C18 -> 578636
B16: Sábado | C16: 4 | D16: 527 | E16: 474 | F16: 445 | G16: 428 | H16: 441 | I16: 487 | J16: 568 | K16: 704 | L16: 787 | M16: 862 | N16: 902 | O16: 939 | P16: 950 | Q16: 927 | R16: 906 | S16: 919 | T16: 922 | U16: 914 | V16: 1047 | W16: 1071 | X16: 1019 | Y16: 928 | Z16: 809 | AA16: 678
B17: Domingo | C17: 4 | D17: 563 | E17: 501 | F17: 465 | G17: 439 | H17: 434 | I17: 449 | J17: 466 | K17: 581 | L17: 661 | M17: 711 | N17: 757 | O17: 817 | P17: 871 | Q17: 858 | R17: 850 | S17: 856 | T17: 882 | U17: 873 | V17: 953 | W17: 1021 | X17: 972 | Y17: 871 | Z17: 726 | AA17: 579
B18: Festivo | C18: 3 | D18: 573 | E18: 510 | F18: 478 | G18: 458 | H18: 471 | I18: 473 | J18: 493 | K18: 633 | L18: 725 | M18: 814 | N18: 878 | O18: 967 | P18: 994 | Q18: 1001 | R18: 993 | S18: 966 | T18: 975 | U18: 969 | V18: 1081 | W18: 1118 | X18: 1052 | Y18: 943 | Z18: 789 | AA18: 618
A19: 46478 | B19: Laboral | C19: 22 | D19: 374 | E19: 332 | F19: 317 | G19: 311 | H19: 341 | I19: 460 | J19: 529 | K19: 617 | L19: 659 | M19: 690 | N19: 720 | O19: 776 | P19: 776 | Q19: 770 | R19: 802 | S19: 811 | T19: 816 | U19: 789 | V19: 860 | W19: 880 | X19: 821 | Y19: 723 | Z19: 599 | AA19: 476 | AB19: =+SUM(D19:AA19)*C19+SUM(D20:AA20)*C20+SUM(D21:AA21)*C21+SUM(D22:AA22)*C22 -> 446862
B20: Sábado | C20: 4 | D20: 422 | E20: 375 | F20: 350 | G20: 341 | H20: 350 | I20: 381 | J20: 440 | K20: 579 | L20: 641 | M20: 696 | N20: 718 | O20: 757 | P20: 784 | Q20: 773 | R20: 791 | S20: 773 | T20: 766 | U20: 720 | V20: 788 | W20: 795 | X20: 742 | Y20: 669 | Z20: 577 | AA20: 485
B21: Domingo | C21: 4 | D21: 407 | E21: 362 | F21: 339 | G21: 322 | H21: 321 | I21: 336 | J21: 361 | K21: 462 | L21: 506 | M21: 525 | N21: 538 | O21: 587 | P21: 637 | Q21: 632 | R21: 644 | S21: 678 | T21: 696 | U21: 703 | V21: 784 | W21: 805 | X21: 771 | Y21: 689 | Z21: 574 | AA21: 454
B22: Festivo | C22: 0 | D22: 0 | E22: 0 | F22: 0 | G22: 0 | H22: 0 | I22: 0 | J22: 0 | K22: 0 | L22: 0 | M22: 0 | N22: 0 | O22: 0 | P22: 0 | Q22: 0 | R22: 0 | S22: 0 | T22: 0 | U22: 0 | V22: 0 | W22: 0 | X22: 0 | Y22: 0 | Z22: 0 | AA22: 0
A23: 46508 | B23: Laboral | C23: 19 | D23: 262 | E23: 231 | F23: 224 | G23: 221 | H23: 244 | I23: 319 | J23: 379 | K23: 427 | L23: 449 | M23: 473 | N23: 505 | O23: 543 | P23: 534 | Q23: 532 | R23: 561 | S23: 583 | T23: 591 | U23: 570 | V23: 614 | W23: 628 | X23: 580 | Y23: 508 | Z23: 424 | AA23: 333 | AB23: =+SUM(D23:AA23)*C23+SUM(D24:AA24)*C24+SUM(D25:AA25)*C25+SUM(D26:AA26)*C26 -> 323476
B24: Sábado | C24: 4 | D24: 304 | E24: 268 | F24: 254 | G24: 243 | H24: 254 | I24: 270 | J24: 326 | K24: 409 | L24: 454 | M24: 484 | N24: 497 | O24: 533 | P24: 536 | Q24: 516 | R24: 517 | S24: 537 | T24: 549 | U24: 548 | V24: 587 | W24: 615 | X24: 581 | Y24: 535 | Z24: 465 | AA24: 391
B25: Domingo | C25: 5 | D25: 322 | E25: 286 | F25: 261 | G25: 244 | H25: 246 | I25: 236 | J25: 261 | K25: 337 | L25: 382 | M25: 385 | N25: 407 | O25: 425 | P25: 456 | Q25: 454 | R25: 439 | S25: 454 | T25: 479 | U25: 482 | V25: 567 | W25: 555 | X25: 523 | Y25: 454 | Z25: 361 | AA25: 274
B26: Festivo | C26: 3 | D26: 286 | E26: 247 | F26: 236 | G26: 229 | H26: 242 | I26: 289 | J26: 326 | K26: 412 | L26: 428 | M26: 452 | N26: 460 | O26: 493 | P26: 506 | Q26: 489 | R26: 497 | S26: 522 | T26: 568 | U26: 575 | V26: 598 | W26: 549 | X26: 523 | Y26: 479 | Z26: 402 | AA26: 315
A27: 46539 | B27: Laboral | C27: 21 | D27: 177 | E27: 154 | F27: 148 | G27: 147 | H27: 161 | I27: 205 | J27: 243 | K27: 286 | L27: 296 | M27: 302 | N27: 313 | O27: 334 | P27: 334 | Q27: 348 | R27: 383 | S27: 397 | T27: 410 | U27: 383 | V27: 413 | W27: 415 | X27: 378 | Y27: 325 | Z27: 262 | AA27: 218 | AB27: =+SUM(D27:AA27)*C27+SUM(D28:AA28)*C28+SUM(D29:AA29)*C29+SUM(D30:AA30)*C30 -> 202575
B28: Sábado | C28: 4 | D28: 177 | E28: 155 | F28: 145 | G28: 139 | H28: 148 | I28: 156 | J28: 201 | K28: 246 | L28: 260 | M28: 272 | N28: 294 | O28: 311 | P28: 308 | Q28: 272 | R28: 285 | S28: 297 | T28: 322 | U28: 321 | V28: 337 | W28: 387 | X28: 358 | Y28: 319 | Z28: 281 | AA28: 236
B29: Domingo | C29: 4 | D29: 196 | E29: 174 | F29: 165 | G29: 150 | H29: 149 | I29: 143 | J29: 167 | K29: 209 | L29: 235 | M29: 230 | N29: 223 | O29: 247 | P29: 269 | Q29: 294 | R29: 302 | S29: 321 | T29: 356 | U29: 345 | V29: 352 | W29: 370 | X29: 360 | Y29: 318 | Z29: 261 | AA29: 217
B30: Festivo | C30: 1 | D30: 163 | E30: 142 | F30: 134 | G30: 125 | H30: 129 | I30: 144 | J30: 163 | K30: 198 | L30: 184 | M30: 216 | N30: 236 | O30: 249 | P30: 262 | Q30: 271 | R30: 290 | S30: 267 | T30: 298 | U30: 301 | V30: 321 | W30: 394 | X30: 388 | Y30: 365 | Z30: 302 | AA30: 241
A31: 46569 | B31: Laboral | C31: 20 | D31: 222 | E31: 191 | F31: 178 | G31: 173 | H31: 186 | I31: 241 | J31: 283 | K31: 332 | L31: 369 | M31: 400 | N31: 433 | O31: 471 | P31: 470 | Q31: 466 | R31: 490 | S31: 493 | T31: 487 | U31: 515 | V31: 536 | W31: 567 | X31: 536 | Y31: 481 | Z31: 401 | AA31: 321 | AB31: =+SUM(D31:AA31)*C31+SUM(D32:AA32)*C32+SUM(D33:AA33)*C33+SUM(D34:AA34)*C34 -> 274192
B32: Sábado | C32: 5 | D32: 196 | E32: 170 | F32: 158 | G32: 151 | H32: 155 | I32: 171 | J32: 211 | K32: 287 | L32: 335 | M32: 374 | N32: 394 | O32: 420 | P32: 428 | Q32: 418 | R32: 409 | S32: 414 | T32: 426 | U32: 469 | V32: 473 | W32: 531 | X32: 500 | Y32: 457 | Z32: 402 | AA32: 335
B33: Domingo | C33: 4 | D33: 240 | E33: 210 | F33: 191 | G33: 177 | H33: 173 | I33: 175 | J33: 188 | K33: 238 | L33: 287 | M33: 325 | N33: 361 | O33: 390 | P33: 413 | Q33: 411 | R33: 412 | S33: 407 | T33: 408 | U33: 448 | V33: 466 | W33: 514 | X33: 482 | Y33: 445 | Z33: 389 | AA33: 335
B34: Festivo | C34: 2 | D34: 196 | E34: 169 | F34: 154 | G34: 143 | H34: 142 | I34: 157 | J34: 182 | K34: 244 | L34: 292 | M34: 328 | N34: 356 | O34: 388 | P34: 407 | Q34: 404 | R34: 402 | S34: 408 | T34: 405 | U34: 431 | V34: 452 | W34: 497 | X34: 478 | Y34: 443 | Z34: 389 | AA34: 329
A35: 46600 | B35: Laboral | C35: 21 | D35: 244 | E35: 213 | F35: 200 | G35: 195 | H35: 209 | I35: 272 | J35: 318 | K35: 381 | L35: 418 | M35: 456 | N35: 490 | O35: 530 | P35: 526 | Q35: 530 | R35: 551 | S35: 552 | T35: 544 | U35: 559 | V35: 585 | W35: 618 | X35: 587 | Y35: 529 | Z35: 441 | AA35: 359 | AB35: =+SUM(D35:AA35)*C35+SUM(D36:AA36)*C36+SUM(D37:AA37)*C37+SUM(D38:AA38)*C38 -> 308615
B36: Sábado | C36: 3 | D36: 270 | E36: 237 | F36: 221 | G36: 211 | H36: 214 | I36: 224 | J36: 264 | K36: 348 | L36: 405 | M36: 452 | N36: 468 | O36: 495 | P36: 510 | Q36: 498 | R36: 492 | S36: 488 | T36: 487 | U36: 533 | V36: 580 | W36: 606 | X36: 567 | Y36: 521 | Z36: 457 | AA36: 388
B37: Domingo | C37: 5 | D37: 276 | E37: 244 | F37: 224 | G37: 207 | H37: 204 | I37: 211 | J37: 221 | K37: 272 | L37: 313 | M37: 347 | N37: 376 | O37: 410 | P37: 434 | Q37: 436 | R37: 426 | S37: 424 | T37: 437 | U37: 489 | V37: 527 | W37: 559 | X37: 533 | Y37: 479 | Z37: 397 | AA37: 326
B38: Festivo | C38: 2 | D38: 260 | E38: 226 | F38: 207 | G38: 195 | H38: 197 | I38: 205 | J38: 230 | K38: 290 | L38: 330 | M38: 371 | N38: 412 | O38: 458 | P38: 491 | Q38: 476 | R38: 464 | S38: 467 | T38: 460 | U38: 494 | V38: 554 | W38: 596 | X38: 583 | Y38: 519 | Z38: 429 | AA38: 336
A39: 46631 | B39: Laboral | C39: 22 | D39: 286 | E39: 253 | F39: 238 | G39: 231 | H39: 241 | I39: 297 | J39: 338 | K39: 403 | L39: 441 | M39: 481 | N39: 525 | O39: 569 | P39: 578 | Q39: 585 | R39: 614 | S39: 616 | T39: 607 | U39: 598 | V39: 646 | W39: 660 | X39: 625 | Y39: 570 | Z39: 481 | AA39: 396 | AB39: =+SUM(D39:AA39)*C39+SUM(D40:AA40)*C40+SUM(D41:AA41)*C41+SUM(D42:AA42)*C42 -> 326102
B40: Sábado | C40: 4 | D40: 309 | E40: 268 | F40: 250 | G40: 240 | H40: 241 | I40: 248 | J40: 283 | K40: 369 | L40: 423 | M40: 456 | N40: 488 | O40: 514 | P40: 534 | Q40: 530 | R40: 511 | S40: 510 | T40: 520 | U40: 549 | V40: 604 | W40: 605 | X40: 561 | Y40: 512 | Z40: 444 | AA40: 381
B41: Domingo | C41: 4 | D41: 284 | E41: 249 | F41: 229 | G41: 213 | H41: 212 | I41: 215 | J41: 229 | K41: 285 | L41: 322 | M41: 350 | N41: 380 | O41: 415 | P41: 447 | Q41: 457 | R41: 457 | S41: 468 | T41: 476 | U41: 494 | V41: 551 | W41: 574 | X41: 551 | Y41: 502 | Z41: 427 | AA41: 354
B42: Festivo | C42: 0 | D42: 0 | E42: 0 | F42: 0 | G42: 0 | H42: 0 | I42: 0 | J42: 0 | K42: 0 | L42: 0 | M42: 0 | N42: 0 | O42: 0 | P42: 0 | Q42: 0 | R42: 0 | S42: 0 | T42: 0 | U42: 0 | V42: 0 | W42: 0 | X42: 0 | Y42: 0 | Z42: 0 | AA42: 0
...

Sheet Cantidad-Precio Ofertado Pr 6
A1: Precios y Cantidades de Energía Oferta (kWh) | I1: CURVA
A2: Producto No. 6 - 01 de enero al 31 de diciembre de 2027 | I2: PLANA
A3: $ mayo 2025
A5: Oferente:
A6: Tipo de oferta:
B8: Oferta Producto 6
B9: MES | C9: Energía solicitada kWh | D9: % | E9: Energía ofertada mes kWh | F9: Precio ofertado mes $/kWh
B10: 46388 | C10: =+'Dis Horaria Solicita Produc 6'!AB7 -> 616591
B11: 46419 | C11: =+'Dis Horaria Solicita Produc 6'!AB11 -> 527364
B12: 46447 | C12: =+'Dis Horaria Solicita Produc 6'!AB15 -> 578636
B13: 46478 | C13: =+'Dis Horaria Solicita Produc 6'!AB19 -> 446862
B14: 46508 | C14: =+'Dis Horaria Solicita Produc 6'!AB23 -> 323476
B15: 46539 | C15: =+'Dis Horaria Solicita Produc 6'!AB27 -> 202575
B16: 46569 | C16: =+'Dis Horaria Solicita Produc 6'!AB31 -> 274192
B17: 46600 | C17: =+'Dis Horaria Solicita Produc 6'!AB35 -> 308615
B18: 46631 | C18: =+'Dis Horaria Solicita Produc 6'!AB39 -> 326102
B19: 46661 | C19: =+'Dis Horaria Solicita Produc 6'!AB43 -> 478661
B20: 46692 | C20: =+'Dis Horaria Solicita Produc 6'!AB47 -> 493200
B21: 46722 | C21: =+'Dis Horaria Solicita Produc 6'!AB51 -> 482941
B22: Total | C22: =SUM(C10:C21) -> 5059215 | E22: =SUM(E10:E21) -> 0
A24: Notas: | B24: 1. La Energía Ofertada se distribuye en forma horaria de acuerdo con la carga curva o plana presentada en el Anexo 8.6. 2. Tipo de Contrato: pague lo contratado. 3. Precio ofertado en $kWh, en pesos de mayo 2025.

Sheet Dis Horaria Solicita Produc 7
A1: Distribución Horaria Solicitada (kWh)
A2: Producto No. 7 - 01 de enero al 31 de diciembre de 2028
A4: Oferente:
A6: Mes | B6: Tipo Dia | C6: Dias | D6: H1 | E6: H2 | F6: H3 | G6: H4 | H6: H5 | I6: H6 | J6: H7 | K6: H8 | L6: H9 | M6: H10 | N6: H11 | O6: H12 | P6: H13 | Q6: H14 | R6: H15 | S6: H16 | T6: H17 | U6: H18 | V6: H19 | W6: H20 | X6: H21 | Y6: H22 | Z6: H23 | AA6: H24 | AB6: total Mes
A7: 46753 | B7: Laboral | C7: 20 | D7: 349 | E7: 233 | F7: 173 | G7: 152 | H7: 191 | I7: 373 | J7: 566 | K7: 733 | L7: 915 | M7: 1055 | N7: 1186 | O7: 1346 | P7: 1343 | Q7: 1317 | R7: 1365 | S7: 1380 | T7: 1363 | U7: 1548 | V7: 1731 | W7: 1857 | X7: 1742 | Y7: 1512 | Z7: 1149 | AA7: 814 | AB7: =+SUM(D7:AA7)*C7+SUM(D8:AA8)*C8+SUM(D9:AA9)*C9+SUM(D10:AA10)*C10 -> 707398
B8: Sábado | C8: 4 | D8: 374 | E8: 249 | F8: 180 | G8: 144 | H8: 154 | I8: 234 | J8: 352 | K8: 580 | L8: 797 | M8: 964 | N8: 1108 | O8: 1228 | P8: 1270 | Q8: 1213 | R8: 1167 | S8: 1134 | T8: 1126 | U8: 1344 | V8: 1549 | W8: 1714 | X8: 1589 | Y8: 1413 | Z8: 1145 | AA8: 875
B9: Domingo | C9: 5 | D9: 412 | E9: 267 | F9: 181 | G9: 129 | H9: 123 | I9: 158 | J9: 207 | K9: 326 | L9: 515 | M9: 683 | N9: 817 | O9: 930 | P9: 1016 | Q9: 1026 | R9: 977 | S9: 957 | T9: 970 | U9: 1231 | V9: 1463 | W9: 1631 | X9: 1549 | Y9: 1348 | Z9: 1045 | AA9: 723
B10: Festivo | C10: 2 | D10: 642 | E10: 505 | F10: 387 | G10: 296 | H10: 252 | I10: 245 | J10: 227 | K10: 277 | L10: 412 | M10: 564 | N10: 716 | O10: 871 | P10: 975 | Q10: 989 | R10: 956 | S10: 953 | T10: 929 | U10: 1217 | V10: 1508 | W10: 1625 | X10: 1546 | Y10: 1344 | Z10: 1056 | AA10: 761
A11: 46784 | B11: Laboral | C11: 21 | D11: 126 | E11: 59 | F11: 31 | G11: 21 | H11: 64 | I11: 260 | J11: 403 | K11: 478 | L11: 572 | M11: 636 | N11: 711 | O11: 807 | P11: 790 | Q11: 758 | R11: 790 | S11: 800 | T11: 800 | U11: 972 | V11: 1084 | W11: 1151 | X11: 1061 | Y11: 891 | Z11: 651 | AA11: 443 | AB11: =+SUM(D11:AA11)*C11+SUM(D12:AA12)*C12+SUM(D13:AA13)*C13+SUM(D14:AA14)*C14 -> 400231
B12: Sábado | C12: 4 | D12: 212 | E12: 130 | F12: 90 | G12: 69 | H12: 84 | I12: 138 | J12: 261 | K12: 370 | L12: 526 | M12: 625 | N12: 689 | O12: 760 | P12: 781 | Q12: 728 | R12: 677 | S12: 673 | T12: 678 | U12: 901 | V12: 1034 | W12: 1107 | X12: 1015 | Y12: 890 | Z12: 701 | AA12: 504
B13: Domingo | C13: 4 | D13: 211 | E13: 120 | F13: 69 | G13: 40 | H13: 33 | I13: 56 | J13: 103 | K13: 161 | L13: 292 | M13: 402 | N13: 470 | O13: 561 | P13: 631 | Q13: 616 | R13: 591 | S13: 574 | T13: 576 | U13: 776 | V13: 933 | W13: 1033 | X13: 969 | Y13: 828 | Z13: 600 | AA13: 385
B14: Festivo | C14: 0 | D14: 0 | E14: 0 | F14: 0 | G14: 0 | H14: 0 | I14: 0 | J14: 0 | K14: 0 | L14: 0 | M14: 0 | N14: 0 | O14: 0 | P14: 0 | Q14: 0 | R14: 0 | S14: 0 | T14: 0 | U14: 0 | V14: 0 | W14: 0 | X14: 0 | Y14: 0 | Z14: 0 | AA14: 0
A15: 46813 | B15: Laboral | C15: 22 | D15: 160 | E15: 92 | F15: 66 | G15: 56 | H15: 103 | I15: 300 | J15: 444 | K15: 527 | L15: 622 | M15: 687 | N15: 765 | O15: 865 | P15: 837 | Q15: 806 | R15: 852 | S15: 863 | T15: 865 | U15: 1043 | V15: 1167 | W15: 1221 | X15: 1124 | Y15: 942 | Z15: 698 | AA15: 476 | AB15: =+SUM(D15:AA15)*C15+SUM(D16:AA16)*C16+SUM(D17:AA17)*C17+SUM(D18:AA18)*C18 -> 467875
B16: Sábado | C16: 4 | D16: 225 | E16: 141 | F16: 96 | G16: 72 | H16: 89 | I16: 158 | J16: 281 | K16: 418 | L16: 564 | M16: 685 | N16: 760 | O16: 826 | P16: 837 | Q16: 793 | R16: 757 | S16: 761 | T16: 756 | U16: 961 | V16: 1138 | W16: 1197 | X16: 1116 | Y16: 979 | Z16: 790 | AA16: 587
B17: Domingo | C17: 4 | D17: 274 | E17: 178 | F17: 121 | G17: 85 | H17: 79 | I17: 101 | J17: 137 | K17: 225 | L17: 363 | M17: 460 | N17: 541 | O17: 632 | P17: 702 | Q17: 678 | R17: 653 | S17: 648 | T17: 668 | U17: 876 | V17: 1006 | W17: 1119 | X17: 1052 | Y17: 902 | Z17: 681 | AA17: 456
B18: Festivo | C18: 1 | D18: 272 | E18: 177 | F18: 127 | G18: 100 | H18: 115 | I18: 131 | J18: 177 | K18: 291 | L18: 436 | M18: 579 | N18: 685 | O18: 813 | P18: 853 | Q18: 840 | R18: 806 | S18: 763 | T18: 765 | U18: 974 | V18: 1139 | W18: 1226 | X18: 1135 | Y18: 971 | Z18: 735 | AA18: 487
A19: 46844 | B19: Laboral | C19: 18 | D19: 57 | E19: 0 | F19: 0 | G19: 0 | H19: 0 | I19: 144 | J19: 270 | K19: 358 | L19: 447 | M19: 518 | N19: 584 | O19: 677 | P19: 666 | Q19: 647 | R19: 679 | S19: 687 | T19: 686 | U19: 854 | V19: 966 | W19: 1007 | X19: 919 | Y19: 765 | Z19: 557 | AA19: 349 | AB19: =+SUM(D19:AA19)*C19+SUM(D20:AA20)*C20+SUM(D21:AA21)*C21+SUM(D22:AA22)*C22 -> 335208
B20: Sábado | C20: 5 | D20: 113 | E20: 36 | F20: 0 | G20: 0 | H20: 0 | I20: 43 | J20: 144 | K20: 285 | L20: 409 | M20: 509 | N20: 568 | O20: 637 | P20: 672 | Q20: 641 | R20: 640 | S20: 613 | T20: 596 | U20: 749 | V20: 871 | W20: 906 | X20: 825 | Y20: 707 | Z20: 548 | AA20: 385
B21: Domingo | C21: 5 | D21: 117 | E21: 37 | F21: 0 | G21: 0 | H21: 0 | I21: 0 | J21: 27 | K21: 107 | L21: 208 | M21: 282 | N21: 331 | O21: 413 | P21: 479 | Q21: 461 | R21: 456 | S21: 476 | T21: 485 | U21: 696 | V21: 838 | W21: 891 | X21: 839 | Y21: 707 | Z21: 514 | AA21: 317
B22: Festivo | C22: 2 | D22: 40 | E22: 0 | F22: 0 | G22: 0 | H22: 4 | I22: 172 | J22: 332 | K22: 438 | L22: 532 | M22: 591 | N22: 649 | O22: 699 | P22: 674 | Q22: 643 | R22: 689 | S22: 702 | T22: 682 | U22: 841 | V22: 943 | W22: 944 | X22: 888 | Y22: 744 | Z22: 553 | AA22: 366
A23: 46874 | B23: Laboral | C23: 21 | D23: 47 | E23: 0 | F23: 0 | G23: 0 | H23: 0 | I23: 130 | J23: 249 | K23: 357 | L23: 454 | M23: 542 | N23: 619 | O23: 704 | P23: 678 | Q23: 657 | R23: 686 | S23: 694 | T23: 683 | U23: 818 | V23: 934 | W23: 971 | X23: 891 | Y23: 752 | Z23: 541 | AA23: 346 | AB23: =+SUM(D23:AA23)*C23+SUM(D24:AA24)*C24+SUM(D25:AA25)*C25+SUM(D26:AA26)*C26 -> 342009
B24: Sábado | C24: 4 | D24: 101 | E24: 18 | F24: 0 | G24: 0 | H24: 0 | I24: 11 | J24: 118 | K24: 280 | L24: 426 | M24: 542 | N24: 626 | O24: 685 | P24: 689 | Q24: 632 | R24: 605 | S24: 561 | T24: 553 | U24: 741 | V24: 880 | W24: 927 | X24: 842 | Y24: 721 | Z24: 548 | AA24: 380
B25: Domingo | C25: 4 | D25: 108 | E25: 26 | F25: 0 | G25: 0 | H25: 0 | I25: 0 | J25: 0 | K25: 71 | L25: 198 | M25: 326 | N25: 385 | O25: 449 | P25: 490 | Q25: 477 | R25: 450 | S25: 435 | T25: 432 | U25: 627 | V25: 754 | W25: 819 | X25: 776 | Y25: 669 | Z25: 500 | AA25: 309
B26: Festivo | C26: 2 | D26: 38 | E26: 0 | F26: 0 | G26: 0 | H26: 0 | I26: 0 | J26: 0 | K26: 82 | L26: 209 | M26: 341 | N26: 426 | O26: 528 | P26: 583 | Q26: 549 | R26: 531 | S26: 519 | T26: 515 | U26: 689 | V26: 849 | W26: 906 | X26: 854 | Y26: 735 | Z26: 542 | AA26: 328
A27: 46905 | B27: Laboral | C27: 20 | D27: 0 | E27: 0 | F27: 0 | G27: 0 | H27: 0 | I27: 10 | J27: 137 | K27: 256 | L27: 359 | M27: 446 | N27: 527 | O27: 625 | P27: 617 | Q27: 588 | R27: 609 | S27: 605 | T27: 590 | U27: 742 | V27: 826 | W27: 889 | X27: 811 | Y27: 679 | Z27: 491 | AA27: 303 | AB27: =+SUM(D27:AA27)*C27+SUM(D28:AA28)*C28+SUM(D29:AA29)*C29+SUM(D30:AA30)*C30 -> 286548
B28: Sábado | C28: 4 | D28: 55 | E28: 0 | F28: 0 | G28: 0 | H28: 0 | I28: 0 | J28: 63 | K28: 198 | L28: 340 | M28: 439 | N28: 498 | O28: 566 | P28: 579 | Q28: 550 | R28: 543 | S28: 541 | T28: 540 | U28: 750 | V28: 826 | W28: 893 | X28: 816 | Y28: 705 | Z28: 553 | AA28: 383
B29: Domingo | C29: 4 | D29: 94 | E29: 12 | F29: 0 | G29: 0 | H29: 0 | I29: 0 | J29: 0 | K29: 37 | L29: 152 | M29: 248 | N29: 312 | O29: 384 | P29: 429 | Q29: 396 | R29: 370 | S29: 355 | T29: 314 | U29: 527 | V29: 655 | W29: 744 | X29: 696 | Y29: 605 | Z29: 448 | AA29: 273
B30: Festivo | C30: 2 | D30: 76 | E30: 0 | F30: 0 | G30: 0 | H30: 0 | I30: 0 | J30: 0 | K30: 93 | L30: 241 | M30: 314 | N30: 395 | O30: 482 | P30: 533 | Q30: 510 | R30: 487 | S30: 476 | T30: 452 | U30: 669 | V30: 787 | W30: 826 | X30: 759 | Y30: 621 | Z30: 433 | AA30: 242
A31: 46935 | B31: Laboral | C31: 19 | D31: 63 | E31: 0 | F31: 0 | G31: 0 | H31: 0 | I31: 100 | J31: 233 | K31: 340 | L31: 459 | M31: 558 | N31: 660 | O31: 768 | P31: 754 | Q31: 735 | R31: 781 | S31: 786 | T31: 768 | U31: 913 | V31: 979 | W31: 1078 | X31: 992 | Y31: 838 | Z31: 605 | AA31: 372 | AB31: =+SUM(D31:AA31)*C31+SUM(D32:AA32)*C32+SUM(D33:AA33)*C33+SUM(D34:AA34)*C34 -> 363639
B32: Sábado | C32: 5 | D32: 31 | E32: 0 | F32: 0 | G32: 0 | H32: 0 | I32: 0 | J32: 68 | K32: 232 | L32: 382 | M32: 499 | N32: 571 | O32: 647 | P32: 665 | Q32: 627 | R32: 592 | S32: 594 | T32: 613 | U32: 798 | V32: 845 | W32: 993 | X32: 905 | Y32: 781 | Z32: 610 | AA32: 416
B33: Domingo | C33: 5 | D33: 121 | E33: 30 | F33: 0 | G33: 0 | H33: 0 | I33: 0 | J33: 0 | K33: 74 | L33: 219 | M33: 339 | N33: 439 | O33: 522 | P33: 577 | Q33: 564 | R33: 551 | S33: 531 | T33: 528 | U33: 712 | V33: 786 | W33: 924 | X33: 847 | Y33: 737 | Z33: 559 | AA33: 382
B34: Festivo | C34: 2 | D34: 25 | E34: 0 | F34: 0 | G34: 0 | H34: 0 | I34: 0 | J34: 0 | K34: 104 | L34: 250 | M34: 370 | N34: 466 | O34: 562 | P34: 611 | Q34: 589 | R34: 563 | S34: 560 | T34: 548 | U34: 699 | V34: 782 | W34: 920 | X34: 865 | Y34: 749 | Z34: 570 | AA34: 380
A35: 46966 | B35: Laboral | C35: 21 | D35: 107 | E35: 35 | F35: 1 | G35: 0 | H35: 21 | I35: 163 | J35: 288 | K35: 397 | L35: 499 | M35: 596 | N35: 686 | O35: 785 | P35: 765 | Q35: 760 | R35: 796 | S35: 795 | T35: 777 | U35: 901 | V35: 978 | W35: 1059 | X35: 984 | Y35: 839 | Z35: 618 | AA35: 407 | AB35: =+SUM(D35:AA35)*C35+SUM(D36:AA36)*C36+SUM(D37:AA37)*C37+SUM(D38:AA38)*C38 -> 387847
B36: Sábado | C36: 4 | D36: 159 | E36: 79 | F36: 36 | G36: 16 | H36: 22 | I36: 58 | J36: 158 | K36: 313 | L36: 459 | M36: 579 | N36: 639 | O36: 709 | P36: 733 | Q36: 693 | R36: 667 | S36: 654 | T36: 643 | U36: 820 | V36: 946 | W36: 1016 | X36: 927 | Y36: 810 | Z36: 644 | AA36: 467
B37: Domingo | C37: 4 | D37: 185 | E37: 101 | F37: 48 | G37: 13 | H37: 7 | I37: 23 | J37: 54 | K37: 134 | L37: 249 | M37: 351 | N37: 427 | O37: 509 | P37: 561 | Q37: 555 | R37: 521 | S37: 506 | T37: 522 | U37: 711 | V37: 820 | W37: 914 | X37: 858 | Y37: 730 | Z37: 533 | AA37: 348
B38: Festivo | C38: 2 | D38: 148 | E38: 63 | F38: 17 | G38: 0 | H38: 0 | I38: 20 | J38: 82 | K38: 190 | L38: 310 | M38: 424 | N38: 530 | O38: 631 | P38: 691 | Q38: 647 | R38: 605 | S38: 607 | T38: 592 | U38: 753 | V38: 881 | W38: 985 | X38: 942 | Y38: 796 | Z38: 585 | AA38: 372
A39: 46997 | B39: Laboral | C39: 21 | D39: 240 | E39: 162 | F39: 126 | G39: 111 | H39: 138 | I39: 268 | J39: 391 | K39: 508 | L39: 613 | M39: 716 | N39: 823 | O39: 932 | P39: 932 | Q39: 932 | R39: 984 | S39: 985 | T39: 968 | U39: 1053 | V39: 1174 | W39: 1205 | X39: 1121 | Y39: 977 | Z39: 750 | AA39: 535 | AB39: =+SUM(D39:AA39)*C39+SUM(D40:AA40)*C40+SUM(D41:AA41)*C41+SUM(D42:AA42)*C42 -> 472634
B40: Sábado | C40: 5 | D40: 300 | E40: 205 | F40: 159 | G40: 136 | H40: 142 | I40: 168 | J40: 269 | K40: 431 | L40: 580 | M40: 679 | N40: 767 | O40: 837 | P40: 869 | Q40: 841 | R40: 793 | S40: 780 | T40: 788 | U40: 945 | V40: 1084 | W40: 1097 | X40: 998 | Y40: 873 | Z40: 703 | AA40: 534
B41: Domingo | C41: 4 | D41: 270 | E41: 179 | F41: 128 | G41: 90 | H41: 86 | I41: 89 | J41: 132 | K41: 224 | L41: 337 | M41: 433 | N41: 515 | O41: 602 | P41: 662 | Q41: 666 | R41: 652 | S41: 656 | T41: 661 | U41: 812 | V41: 962 | W41: 1016 | X41: 960 | Y41: 833 | Z41: 641 | AA41: 449
B42: Festivo | C42: 0 | D42: 0 | E42: 0 | F42: 0 | G42: 0 | H42: 0 | I42: 0 | J42: 0 | K42: 0 | L42: 0 | M42: 0 | N42: 0 | O42: 0 | P42: 0 | Q42: 0 | R42: 0 | S42: 0 | T42: 0 | U42: 0 | V42: 0 | W42: 0 | X42: 0 | Y42: 0 | Z42: 0 | AA42: 0
...

Sheet Cantidad-Precio Ofertado Pr 7
A1: Precios y Cantidades de Energía Oferta (kWh) | I1: CURVA
A2: Producto No. 7 - 01 de enero al 31 de diciembre de 2028 | I2: PLANA
A3: $ mayo 2025
A5: Oferente:
A6: Tipo de oferta:
B8: Oferta Producto 7
B9: MES | C9: Energía solicitada kWh | D9: % | E9: Energía ofertada mes kWh | F9: Precio ofertado mes $/kWh
B10: 46753 | C10: =+'Dis Horaria Solicita Produc 7'!AB7 -> 707398
B11: 46784 | C11: =+'Dis Horaria Solicita Produc 7'!AB11 -> 400231
B12: 46813 | C12: =+'Dis Horaria Solicita Produc 7'!AB15 -> 467875
B13: 46844 | C13: =+'Dis Horaria Solicita Produc 7'!AB19 -> 335208
B14: 46874 | C14: =+'Dis Horaria Solicita Produc 7'!AB23 -> 342009
B15: 46905 | C15: =+'Dis Horaria Solicita Produc 7'!AB27 -> 286548
B16: 46935 | C16: =+'Dis Horaria Solicita Produc 7'!AB31 -> 363639
B17: 46966 | C17: =+'Dis Horaria Solicita Produc 7'!AB35 -> 387847
B18: 46997 | C18: =+'Dis Horaria Solicita Produc 7'!AB39 -> 472634
B19: 47027 | C19: =+'Dis Horaria Solicita Produc 7'!AB43 -> 417841
B20: 47058 | C20: =+'Dis Horaria Solicita Produc 7'!AB47 -> 436138
B21: 47088 | C21: =+'Dis Horaria Solicita Produc 7'!AB51 -> 433816
B22: Total | C22: =SUM(C10:C21) -> 5051184 | E22: =SUM(E10:E21) -> 0
A24: Notas: | B24: 1. La Energía Ofertada se distribuye en forma horaria de acuerdo con la carga curva o plana presentada en el Anexo 8.7. 2. Tipo de Contrato: pague lo contratado. 3. Precio ofertado en $kWh, en pesos de mayo 2025.

Sheet Dis Horaria Solicita Produc 8
A1: Distribución Horaria Solicitada (kWh)
A2: Producto No. 8 - 01 de enero al 31 de diciembre de 2029
A4: Oferente:
A6: Mes | B6: Tipo Dia | C6: Dias | D6: H1 | E6: H2 | F6: H3 | G6: H4 | H6: H5 | I6: H6 | J6: H7 | K6: H8 | L6: H9 | M6: H10 | N6: H11 | O6: H12 | P6: H13 | Q6: H14 | R6: H15 | S6: H16 | T6: H17 | U6: H18 | V6: H19 | W6: H20 | X6: H21 | Y6: H22 | Z6: H23 | AA6: H24 | AB6: total Mes
A7: 47119 | B7: Laboral | C7: 21 | D7: 293 | E7: 229 | F7: 196 | G7: 185 | H7: 207 | I7: 307 | J7: 421 | K7: 478 | L7: 583 | M7: 665 | N7: 741 | O7: 829 | P7: 823 | Q7: 802 | R7: 819 | S7: 823 | T7: 812 | U7: 966 | V7: 1067 | W7: 1135 | X7: 1070 | Y7: 943 | Z7: 744 | AA7: 557 | AB7: =+SUM(D7:AA7)*C7+SUM(D8:AA8)*C8+SUM(D9:AA9)*C9+SUM(D10:AA10)*C10 -> 462901
B8: Sábado | C8: 4 | D8: 316 | E8: 243 | F8: 206 | G8: 185 | H8: 192 | I8: 238 | J8: 314 | K8: 400 | L8: 527 | M8: 623 | N8: 702 | O8: 773 | P8: 792 | Q8: 755 | R8: 723 | S8: 703 | T8: 698 | U8: 876 | V8: 985 | W8: 1063 | X8: 997 | Y8: 895 | Z8: 743 | AA8: 587
B9: Domingo | C9: 4 | D9: 340 | E9: 260 | F9: 211 | G9: 182 | H9: 178 | I9: 195 | J9: 224 | K9: 248 | L9: 358 | M9: 457 | N9: 533 | O9: 598 | P9: 645 | Q9: 642 | R9: 611 | S9: 594 | T9: 596 | U9: 788 | V9: 919 | W9: 1009 | X9: 964 | Y9: 855 | Z9: 688 | AA9: 513
B10: Festivo | C10: 2 | D10: 397 | E10: 323 | F10: 266 | G10: 225 | H10: 209 | I10: 214 | J10: 220 | K10: 220 | L10: 308 | M10: 396 | N10: 482 | O10: 566 | P10: 617 | Q10: 610 | R10: 586 | S10: 576 | T10: 568 | U10: 773 | V10: 917 | W10: 981 | X10: 930 | Y10: 819 | Z10: 661 | AA10: 501
A11: 47150 | B11: Laboral | C11: 20 | D11: 249 | E11: 194 | F11: 170 | G11: 162 | H11: 196 | I11: 356 | J11: 480 | K11: 503 | L11: 581 | M11: 642 | N11: 710 | O11: 788 | P11: 764 | Q11: 738 | R11: 759 | S11: 763 | T11: 759 | U11: 936 | V11: 1028 | W11: 1089 | X11: 1018 | Y11: 884 | Z11: 688 | AA11: 506 | AB11: =+SUM(D11:AA11)*C11+SUM(D12:AA12)*C12+SUM(D13:AA13)*C13+SUM(D14:AA14)*C14 -> 405384
B12: Sábado | C12: 4 | D12: 305 | E12: 239 | F12: 205 | G12: 188 | H12: 201 | I12: 248 | J12: 353 | K12: 415 | L12: 547 | M12: 634 | N12: 691 | O12: 750 | P12: 765 | Q12: 719 | R12: 677 | S12: 670 | T12: 668 | U12: 876 | V12: 987 | W12: 1052 | X12: 982 | Y12: 876 | Z12: 720 | AA12: 558
B13: Domingo | C13: 4 | D13: 316 | E13: 240 | F13: 199 | G13: 174 | H13: 170 | I13: 188 | J13: 229 | K13: 245 | L13: 359 | M13: 457 | N13: 518 | O13: 589 | P13: 638 | Q13: 621 | R13: 594 | S13: 578 | T13: 575 | U13: 777 | V13: 899 | W13: 986 | X13: 938 | Y13: 820 | Z13: 634 | AA13: 461
B14: Festivo | C14: 0 | D14: 0 | E14: 0 | F14: 0 | G14: 0 | H14: 0 | I14: 0 | J14: 0 | K14: 0 | L14: 0 | M14: 0 | N14: 0 | O14: 0 | P14: 0 | Q14: 0 | R14: 0 | S14: 0 | T14: 0 | U14: 0 | V14: 0 | W14: 0 | X14: 0 | Y14: 0 | Z14: 0 | AA14: 0
A15: 47178 | B15: Laboral | C15: 19 | D15: 276 | E15: 216 | F15: 192 | G15: 183 | H15: 222 | I15: 393 | J15: 520 | K15: 555 | L15: 641 | M15: 706 | N15: 779 | O15: 865 | P15: 833 | Q15: 806 | R15: 835 | S15: 841 | T15: 842 | U15: 1035 | V15: 1138 | W15: 1194 | X15: 1114 | Y15: 964 | Z15: 752 | AA15: 551 | AB15: =+SUM(D15:AA15)*C15+SUM(D16:AA16)*C16+SUM(D17:AA17)*C17+SUM(D18:AA18)*C18 -> 492951
B16: Sábado | C16: 5 | D16: 328 | E16: 255 | F16: 217 | G16: 198 | H16: 213 | I16: 272 | J16: 380 | K16: 470 | L16: 604 | M16: 709 | N16: 781 | O16: 842 | P16: 846 | Q16: 803 | R16: 765 | S16: 759 | T16: 753 | U16: 975 | V16: 1109 | W16: 1165 | X16: 1094 | Y16: 976 | Z16: 805 | AA16: 632
B17: Domingo | C17: 4 | D17: 365 | E17: 285 | F17: 237 | G17: 207 | H17: 204 | I17: 223 | J17: 263 | K17: 296 | L17: 417 | M17: 511 | N17: 582 | O17: 656 | P17: 708 | Q17: 686 | R17: 658 | S17: 644 | T17: 653 | U17: 881 | V17: 1002 | W17: 1091 | X17: 1035 | Y17: 907 | Z17: 715 | AA17: 528
B18: Festivo | C18: 3 | D18: 357 | E18: 278 | F18: 235 | G18: 214 | H18: 223 | I18: 245 | J18: 292 | K18: 342 | L18: 472 | M18: 599 | N18: 695 | O18: 801 | P18: 833 | Q18: 807 | R18: 763 | S18: 728 | T18: 731 | U18: 951 | V18: 1089 | W18: 1176 | X18: 1106 | Y18: 960 | Z18: 749 | AA18: 545
A19: 47209 | B19: Laboral | C19: 21 | D19: 192 | E19: 138 | F19: 115 | G19: 107 | H19: 137 | I19: 254 | J19: 362 | K19: 405 | L19: 487 | M19: 551 | N19: 611 | O19: 687 | P19: 671 | Q19: 651 | R19: 670 | S19: 673 | T19: 668 | U19: 845 | V19: 937 | W19: 975 | X19: 907 | Y19: 784 | Z19: 610 | AA19: 436 | AB19: =+SUM(D19:AA19)*C19+SUM(D20:AA20)*C20+SUM(D21:AA21)*C21+SUM(D22:AA22)*C22 -> 371198
B20: Sábado | C20: 4 | D20: 234 | E20: 171 | F20: 138 | G20: 126 | H20: 137 | I20: 174 | J20: 260 | K20: 341 | L20: 453 | M20: 540 | N20: 597 | O20: 657 | P20: 679 | Q20: 646 | R20: 633 | S20: 610 | T20: 593 | U20: 764 | V20: 866 | W20: 907 | X20: 844 | Y20: 747 | Z20: 613 | AA20: 475
B21: Domingo | C21: 5 | D21: 248 | E21: 181 | F21: 142 | G21: 121 | H21: 120 | I21: 131 | J21: 167 | K21: 201 | L21: 298 | M21: 376 | N21: 426 | O21: 491 | P21: 536 | Q21: 518 | R21: 499 | S21: 497 | T21: 500 | U21: 711 | V21: 826 | W21: 879 | X21: 836 | Y21: 729 | Z21: 567 | AA21: 409
B22: Festivo | C22: 0 | D22: 0 | E22: 0 | F22: 0 | G22: 0 | H22: 0 | I22: 0 | J22: 0 | K22: 0 | L22: 0 | M22: 0 | N22: 0 | O22: 0 | P22: 0 | Q22: 0 | R22: 0 | S22: 0 | T22: 0 | U22: 0 | V22: 0 | W22: 0 | X22: 0 | Y22: 0 | Z22: 0 | AA22: 0
A23: 47239 | B23: Laboral | C23: 21 | D23: 215 | E23: 159 | F23: 136 | G23: 128 | H23: 160 | I23: 273 | J23: 392 | K23: 436 | L23: 515 | M23: 586 | N23: 658 | O23: 734 | P23: 711 | Q23: 692 | R23: 712 | S23: 721 | T23: 716 | U23: 878 | V23: 971 | W23: 1011 | X23: 936 | Y23: 812 | Z23: 636 | AA23: 461 | AB23: =+SUM(D23:AA23)*C23+SUM(D24:AA24)*C24+SUM(D25:AA25)*C25+SUM(D26:AA26)*C26 -> 406113
B24: Sábado | C24: 4 | D24: 262 | E24: 196 | F24: 164 | G24: 147 | H24: 159 | I24: 192 | J24: 292 | K24: 376 | L24: 498 | M24: 583 | N24: 641 | O24: 702 | P24: 706 | Q24: 660 | R24: 634 | S24: 624 | T24: 620 | U24: 817 | V24: 920 | W24: 969 | X24: 903 | Y24: 805 | Z24: 665 | AA24: 519
B25: Domingo | C25: 4 | D25: 284 | E25: 215 | F25: 170 | G25: 144 | H25: 145 | I25: 140 | J25: 189 | K25: 231 | L25: 343 | M25: 420 | N25: 476 | O25: 526 | P25: 562 | Q25: 546 | R25: 515 | S25: 508 | T25: 514 | U25: 713 | V25: 840 | W25: 888 | X25: 845 | Y25: 736 | Z25: 573 | AA25: 414
B26: Festivo | C26: 2 | D26: 231 | E26: 164 | F26: 136 | G26: 122 | H26: 136 | I26: 171 | J26: 233 | K26: 288 | L26: 379 | M26: 469 | N26: 534 | O26: 612 | P26: 647 | Q26: 611 | R26: 584 | S26: 583 | T26: 601 | U26: 800 | V26: 902 | W26: 914 | X26: 862 | Y26: 758 | Z26: 594 | AA26: 429
A27: 47270 | B27: Laboral | C27: 19 | D27: 183 | E27: 131 | F27: 108 | G27: 100 | H27: 125 | I27: 205 | J27: 309 | K27: 363 | L27: 439 | M27: 500 | N27: 561 | O27: 632 | P27: 618 | Q27: 602 | R27: 622 | S27: 625 | T27: 622 | U27: 775 | V27: 846 | W27: 895 | X27: 830 | Y27: 720 | Z27: 560 | AA27: 413 | AB27: =+SUM(D27:AA27)*C27+SUM(D28:AA28)*C28+SUM(D29:AA29)*C29+SUM(D30:AA30)*C30 -> 336231
B28: Sábado | C28: 5 | D28: 212 | E28: 154 | F28: 123 | G28: 108 | H28: 120 | I28: 148 | J28: 236 | K28: 303 | L28: 403 | M28: 476 | N28: 535 | O28: 589 | P28: 593 | Q28: 550 | R28: 533 | S28: 529 | T28: 532 | U28: 718 | V28: 795 | W28: 864 | X28: 802 | Y28: 711 | Z28: 586 | AA28: 457
B29: Domingo | C29: 4 | D29: 239 | E29: 175 | F29: 139 | G29: 114 | H29: 113 | I29: 113 | J29: 149 | K29: 178 | L29: 274 | M29: 342 | N29: 383 | O29: 440 | P29: 475 | Q29: 467 | R29: 445 | S29: 437 | T29: 442 | U29: 630 | V29: 718 | W29: 787 | X29: 753 | Y29: 666 | Z29: 529 | AA29: 394
B30: Festivo | C30: 2 | D30: 194 | E30: 138 | F30: 108 | G30: 91 | H30: 98 | I30: 114 | J30: 157 | K30: 188 | L30: 270 | M30: 355 | N30: 426 | O30: 494 | P30: 526 | Q30: 507 | R30: 482 | S30: 455 | T30: 458 | U30: 649 | V30: 745 | W30: 825 | X30: 782 | Y30: 687 | Z30: 534 | AA30: 388
A31: 47300 | B31: Laboral | C31: 20 | D31: 268 | E31: 203 | F31: 173 | G31: 162 | H31: 188 | I31: 297 | J31: 408 | K31: 461 | L31: 557 | M31: 638 | N31: 721 | O31: 805 | P31: 786 | Q31: 766 | R31: 793 | S31: 794 | T31: 780 | U31: 938 | V31: 993 | W31: 1078 | X31: 1011 | Y31: 888 | Z31: 701 | AA31: 520 | AB31: =+SUM(D31:AA31)*C31+SUM(D32:AA32)*C32+SUM(D33:AA33)*C33+SUM(D34:AA34)*C34 -> 439121
B32: Sábado | C32: 4 | D32: 261 | E32: 198 | F32: 165 | G32: 148 | H32: 158 | I32: 195 | J32: 289 | K32: 381 | L32: 506 | M32: 601 | N32: 663 | O32: 724 | P32: 736 | Q32: 701 | R32: 668 | S32: 662 | T32: 668 | U32: 858 | V32: 908 | W32: 1016 | X32: 949 | Y32: 850 | Z32: 710 | AA32: 557
B33: Domingo | C33: 5 | D33: 317 | E33: 244 | F33: 200 | G33: 173 | H33: 167 | I33: 173 | J33: 207 | K33: 246 | L33: 365 | M33: 465 | N33: 540 | O33: 604 | P33: 644 | Q33: 631 | R33: 610 | S33: 592 | T33: 587 | U33: 776 | V33: 845 | W33: 956 | X33: 904 | Y33: 814 | Z33: 667 | AA33: 522
B34: Festivo | C34: 2 | D34: 260 | E34: 193 | F34: 155 | G34: 133 | H34: 138 | I34: 163 | J34: 220 | K34: 282 | L34: 403 | M34: 504 | N34: 584 | O34: 663 | P34: 699 | Q34: 672 | R34: 640 | S34: 628 | T34: 618 | U34: 785 | V34: 857 | W34: 968 | X34: 923 | Y34: 825 | Z34: 674 | AA34: 517
A35: 47331 | B35: Laboral | C35: 21 | D35: 252 | E35: 195 | F35: 167 | G35: 157 | H35: 184 | I35: 301 | J35: 408 | K35: 460 | L35: 549 | M35: 629 | N35: 706 | O35: 787 | P35: 763 | Q35: 751 | R35: 773 | S35: 772 | T35: 758 | U35: 907 | V35: 976 | W35: 1043 | X35: 980 | Y35: 861 | Z35: 677 | AA35: 502 | AB35: =+SUM(D35:AA35)*C35+SUM(D36:AA36)*C36+SUM(D37:AA37)*C37+SUM(D38:AA38)*C38 -> 431694
B36: Sábado | C36: 4 | D36: 292 | E36: 226 | F36: 191 | G36: 174 | H36: 181 | I36: 214 | J36: 298 | K36: 384 | L36: 511 | M36: 609 | N36: 669 | O36: 727 | P36: 739 | Q36: 700 | R36: 672 | S36: 656 | T36: 644 | U36: 827 | V36: 931 | W36: 994 | X36: 924 | Y36: 828 | Z36: 688 | AA36: 541
B37: Domingo | C37: 4 | D37: 311 | E37: 241 | F37: 198 | G37: 172 | H37: 168 | I37: 180 | J37: 212 | K37: 247 | L37: 354 | M37: 445 | N37: 509 | O37: 570 | P37: 606 | Q37: 594 | R37: 565 | S37: 546 | T37: 551 | U37: 742 | V37: 832 | W37: 919 | X37: 876 | Y37: 771 | Z37: 608 | AA37: 453
B38: Festivo | C38: 2 | D38: 277 | E38: 209 | F38: 171 | G38: 152 | H38: 155 | I38: 177 | J38: 225 | K38: 283 | L38: 391 | M38: 492 | N38: 577 | O38: 661 | P38: 697 | Q38: 660 | R38: 621 | S38: 613 | T38: 598 | U38: 766 | V38: 868 | W38: 965 | X38: 926 | Y38: 809 | Z38: 639 | AA38: 476
A39: 47362 | B39: Laboral | C39: 20 | D39: 305 | E39: 242 | F39: 213 | G39: 201 | H39: 227 | I39: 349 | J39: 464 | K39: 523 | L39: 615 | M39: 702 | N39: 793 | O39: 888 | P39: 875 | Q39: 866 | R39: 900 | S39: 901 | T39: 887 | U39: 1024 | V39: 1127 | W39: 1149 | X39: 1074 | Y39: 947 | Z39: 750 | AA39: 567 | AB39: =+SUM(D39:AA39)*C39+SUM(D40:AA40)*C40+SUM(D41:AA41)*C41+SUM(D42:AA42)*C42 -> 469945
B40: Sábado | C40: 5 | D40: 364 | E40: 286 | F40: 246 | G40: 225 | H40: 229 | I40: 245 | J40: 334 | K40: 444 | L40: 584 | M40: 677 | N40: 751 | O40: 814 | P40: 839 | Q40: 799 | R40: 746 | S40: 727 | T40: 725 | U40: 922 | V40: 1045 | W40: 1055 | X40: 974 | Y40: 870 | Z40: 731 | AA40: 592
B41: Domingo | C41: 5 | D41: 354 | E41: 277 | F41: 229 | G41: 196 | H41: 187 | I41: 175 | J41: 202 | K41: 242 | L41: 353 | M41: 446 | N41: 515 | O41: 586 | P41: 642 | Q41: 632 | R41: 599 | S41: 588 | T41: 587 | U41: 783 | V41: 922 | W41: 978 | X41: 934 | Y41: 824 | Z41: 660 | AA41: 498
B42: Festivo | C42: 0 | D42: 0 | E42: 0 | F42: 0 | G42: 0 | H42: 0 | I42: 0 | J42: 0 | K42: 0 | L42: 0 | M42: 0 | N42: 0 | O42: 0 | P42: 0 | Q42: 0 | R42: 0 | S42: 0 | T42: 0 | U42: 0 | V42: 0 | W42: 0 | X42: 0 | Y42: 0 | Z42: 0 | AA42: 0
...

Sheet Cantidad-Precio Ofertado Pr 8
A1: Precios y Cantidades de Energía Oferta (kWh) | I1: CURVA
A2: Producto No. 8 - 01 de enero al 31 de diciembre de 2029 | I2: PLANA
A3: $ mayo 2025
A5: Oferente:
A6: Tipo de oferta:
B8: Oferta Producto 8
B9: MES | C9: Energía solicitada kWh | D9: % | E9: Energía ofertada mes kWh | F9: Precio ofertado mes $/kWh
B10: 47119 | C10: =+'Dis Horaria Solicita Produc 8'!AB7 -> 462901
B11: 47150 | C11: =+'Dis Horaria Solicita Produc 8'!AB11 -> 405384
B12: 47178 | C12: =+'Dis Horaria Solicita Produc 8'!AB15 -> 492951
B13: 47209 | C13: =+'Dis Horaria Solicita Produc 8'!AB19 -> 371198
B14: 47239 | C14: =+'Dis Horaria Solicita Produc 8'!AB23 -> 406113
B15: 47270 | C15: =+'Dis Horaria Solicita Produc 8'!AB27 -> 336231
B16: 47300 | C16: =+'Dis Horaria Solicita Produc 8'!AB31 -> 439121
B17: 47331 | C17: =+'Dis Horaria Solicita Produc 8'!AB35 -> 431694
B18: 47362 | C18: =+'Dis Horaria Solicita Produc 8'!AB39 -> 469945
B19: 47392 | C19: =+'Dis Horaria Solicita Produc 8'!AB43 -> 416733
B20: 47423 | C20: =+'Dis Horaria Solicita Produc 8'!AB47 -> 408288
B21: 47453 | C21: =+'Dis Horaria Solicita Produc 8'!AB51 -> 434022
B22: TOTAL | C22: =SUM(C10:C21) -> 5074581 | E22: =SUM(E10:E21) -> 0
A24: Notas: | B24: 1. La Energía Ofertada se distribuye en forma horaria de acuerdo con la carga curva o plana presentada en el Anexo 8.8. 2. Tipo de Contrato: pague lo contratado. 3. Precio ofertado en $kWh, en pesos de mayo 2025.

Sheet Oferta Horaria Productos 1 al 5
A1: Distribución Horaria de la Oferta (kWh)
A2: Producto No.____ - Desde: ______________________ hasta:
A4: Oferente:
A6: Mes | B6: Tipo Dia | C6: Dias | D6: H1 | E6: H2 | F6: H3 | G6: H4 | H6: H5 | I6: H6 | J6: H7 | K6: H8 | L6: H9 | M6: H10 | N6: H11 | O6: H12 | P6: H13 | Q6: H14 | R6: H15 | S6: H16 | T6: H17 | U6: H18 | V6: H19 | W6: H20 | X6: H21 | Y6: H22 | Z6: H23 | AA6: H24 | AB6: total Mes
A7: Mes | B7: Laboral | AB7: =+SUM(D7:AA7)*C7+SUM(D8:AA8)*C8+SUM(D9:AA9)*C9+SUM(D10:AA10)*C10 -> 0
B8: Sábado
B9: Domingo
B10: Festivo
Z11: Total Año kWh | AB11: =SUM(AB7:AB10) -> 0

Sheet Oferta Horaria Productos 6 al 8
A1: Distribución Horaria de la Oferta (kWh)
A2: Producto No.____ - Desde: ______________________ hasta:
A4: Oferente:
A6: Mes | B6: Tipo Dia | C6: Dias | D6: H1 | E6: H2 | F6: H3 | G6: H4 | H6: H5 | I6: H6 | J6: H7 | K6: H8 | L6: H9 | M6: H10 | N6: H11 | O6: H12 | P6: H13 | Q6: H14 | R6: H15 | S6: H16 | T6: H17 | U6: H18 | V6: H19 | W6: H20 | X6: H21 | Y6: H22 | Z6: H23 | AA6: H24 | AB6: total Mes
A7: Ene | B7: Laboral | AB7: =+SUM(D7:AA7)*C7+SUM(D8:AA8)*C8+SUM(D9:AA9)*C9+SUM(D10:AA10)*C10 -> 0
B8: Sábado
B9: Domingo
B10: Festivo
A11: Feb | B11: Laboral | AB11: =+SUM(D11:AA11)*C11+SUM(D12:AA12)*C12+SUM(D13:AA13)*C13+SUM(D14:AA14)*C14 -> 0
B12: Sábado
B13: Domingo
B14: Festivo
A15: Mar | B15: Laboral | AB15: =+SUM(D15:AA15)*C15+SUM(D16:AA16)*C16+SUM(D17:AA17)*C17+SUM(D18:AA18)*C18 -> 0
B16: Sábado
B17: Domingo
B18: Festivo
A19: Abr | B19: Laboral | AB19: =+SUM(D19:AA19)*C19+SUM(D20:AA20)*C20+SUM(D21:AA21)*C21+SUM(D22:AA22)*C22 -> 0
B20: Sábado
B21: Domingo
B22: Festivo
A23: May | B23: Laboral | AB23: =+SUM(D23:AA23)*C23+SUM(D24:AA24)*C24+SUM(D25:AA25)*C25+SUM(D26:AA26)*C26 -> 0
B24: Sábado
B25: Domingo
B26: Festivo
A27: Jun | B27: Laboral | AB27: =+SUM(D27:AA27)*C27+SUM(D28:AA28)*C28+SUM(D29:AA29)*C29+SUM(D30:AA30)*C30 -> 0
B28: Sábado
B29: Domingo
B30: Festivo
A31: Jul | B31: Laboral | AB31: =+SUM(D31:AA31)*C31+SUM(D32:AA32)*C32+SUM(D33:AA33)*C33+SUM(D34:AA34)*C34 -> 0
B32: Sábado
B33: Domingo
B34: Festivo
A35: Ago | B35: Laboral | AB35: =+SUM(D35:AA35)*C35+SUM(D36:AA36)*C36+SUM(D37:AA37)*C37+SUM(D38:AA38)*C38 -> 0
B36: Sábado
B37: Domingo
B38: Festivo
A39: Sep | B39: Laboral | AB39: =+SUM(D39:AA39)*C39+SUM(D40:AA40)*C40+SUM(D41:AA41)*C41+SUM(D42:AA42)*C42 -> 0
B40: Sábado
B41: Domingo
B42: Festivo
...

Sheet Hoja1
A2: 24 horas
A3: Bloque 2
