Workbook

Sheet Formato -Producto N° 1  plano 
A5: Formato Oferta Producto No. 1 Carga Plana Convocatoria Pública DISPAC S.A. E.S.P.
A8: PROPONENTE
A10: MES | B10: DEMANDA REQUERIDA DISPAC KWh | C10: DEMANDA PERIODO REQUERIDA DISPAC KWh | D10: PORCENTAJE (%) OFERTADO DE LA DEMANDA REQUERIDA | E10: DEMANDA OFERTADA KWh - MES | F10: DEMANDA PERIODO OFERTADA KWh | G10: PRECIO OFERTADO $ kWh (0.00)
A11: 46235 | B11: 8928000 | C11: 25500000 | D11: 0
A12: 46266 | B12: 2520000 | D12: 0
A13: 46296 | B13: 2604000 | D13: 0
A14: 46327 | B14: 2520000 | D14: 0
A15: 46357 | B15: 8928000 | D15: 0
A16: 46388 | B16: ='Cantidades -Producto 1'!AG22 -> 8928000 | C16: =SUM(B16:B27) -> 86556000 | D16: 0
A17: 46419 | B17: ='Cantidades -Producto 1'!AG23 -> 8064000 | D17: 0
A18: 46447 | B18: ='Cantidades -Producto 1'!AG24 -> 8928000 | D18: 0
A19: 46478 | B19: ='Cantidades -Producto 1'!AG25 -> 8640000 | D19: 0
A20: 46508 | B20: ='Cantidades -Producto 1'!AG26 -> 8928000 | D20: 0
A21: 46539 | B21: ='Cantidades -Producto 1'!AG27 -> 8640000 | D21: 0
A22: 46569 | B22: ='Cantidades -Producto 1'!AG28 -> 8928000 | D22: 0
A23: 46600 | B23: ='Cantidades -Producto 1'!AG29 -> 8928000 | D23: 0
A24: 46631 | B24: ='Cantidades -Producto 1'!AG30 -> 2520000 | D24: 0
A25: 46661 | B25: ='Cantidades -Producto 1'!AG31 -> 2604000 | D25: 0
A26: 46692 | B26: ='Cantidades -Producto 1'!AG32 -> 2520000 | D26: 0
A27: 46722 | B27: ='Cantidades -Producto 1'!AG33 -> 8928000 | D27: 0
A28: 46753 | B28: ='Cantidades -Producto 1'!AG61 -> 8928000 | C28: =SUM(B28:B39) -> 79440000 | D28: 0
A29: 46784 | B29: ='Cantidades -Producto 1'!AG62 -> 8064000 | D29: 0
A30: 46813 | B30: ='Cantidades -Producto 1'!AG63 -> 8928000 | D30: 0
A31: 46844 | B31: ='Cantidades -Producto 1'!AG64 -> 8640000 | D31: 0
A32: 46874 | B32: ='Cantidades -Producto 1'!AG65 -> 5208000 | D32: 0
A33: 46905 | B33: ='Cantidades -Producto 1'!AG66 -> 5040000 | D33: 0
A34: 46935 | B34: ='Cantidades -Producto 1'!AG67 -> 5208000 | D34: 0
A35: 46966 | B35: ='Cantidades -Producto 1'!AG68 -> 5208000 | D35: 0
A36: 46997 | B36: ='Cantidades -Producto 1'!AG69 -> 5040000 | D36: 0
A37: 47027 | B37: ='Cantidades -Producto 1'!AG70 -> 5208000 | D37: 0
A38: 47058 | B38: ='Cantidades -Producto 1'!AG71 -> 5040000 | D38: 0
A39: 47088 | B39: ='Cantidades -Producto 1'!AG72 -> 8928000 | D39: 0
A40: 47119 | B40: ='Cantidades -Producto 1'!AG100 -> 11160000 | C40: =SUM(B40:B51) -> 131400000 | D40: 0
A41: 47150 | B41: ='Cantidades -Producto 1'!AG101 -> 10080000 | D41: 0
A42: 47178 | B42: ='Cantidades -Producto 1'!AG102 -> 11160000 | D42: 0
A43: 47209 | B43: ='Cantidades -Producto 1'!AG103 -> 10800000 | D43: 0
A44: 47239 | B44: ='Cantidades -Producto 1'!AG104 -> 11160000 | D44: 0
A45: 47270 | B45: ='Cantidades -Producto 1'!AG105 -> 10800000 | D45: 0
A46: 47300 | B46: ='Cantidades -Producto 1'!AG106 -> 11160000 | D46: 0
A47: 47331 | B47: ='Cantidades -Producto 1'!AG107 -> 11160000 | D47: 0
...

Sheet Cantidades -Producto 1
A2: PRODUCTO 1 | AF2: MES | AG2: DEMANDA REQUERIDA DISPAC KWh
A3: Mes | B3: Tipo de día | C3: No. de Días | D3: HORA 01 | E3: HORA 02 | F3: HORA 03 | G3: HORA 04 | H3: HORA 05 | I3: HORA 06 | J3: HORA 07 | K3: HORA 08 | L3: HORA 09 | M3: HORA 10 | N3: HORA 11 | O3: HORA 12 | P3: HORA 13 | Q3: HORA 14 | R3: HORA 15 | S3: HORA 16 | T3: HORA 17 | U3: HORA 18 | V3: HORA 19 | W3: HORA 20 | X3: HORA 21 | Y3: HORA 22 | Z3: HORA 23 | AA3: HORA 24 | AB3: Total | AF3: 46235 | AG3: =AC4 -> 8928000
A4: 46235 | B4: SÁBADO | C4: 5 | D4: 12000 | E4: 12000 | F4: 12000 | G4: 12000 | H4: 12000 | I4: 12000 | J4: 12000 | K4: 12000 | L4: 12000 | M4: 12000 | N4: 12000 | O4: 12000 | P4: 12000 | Q4: 12000 | R4: 12000 | S4: 12000 | T4: 12000 | U4: 12000 | V4: 12000 | W4: 12000 | X4: 12000 | Y4: 12000 | Z4: 12000 | AA4: 12000 | AB4: =SUM(D4:AA4)*C4 -> 1440000 | AC4: =+AB4+AB5+AB6 -> 8928000 | AF4: 46266 | AG4: =AC7 -> 2520000
B5: FESTIVO | C5: 5 | D5: 12000 | E5: 12000 | F5: 12000 | G5: 12000 | H5: 12000 | I5: 12000 | J5: 12000 | K5: 12000 | L5: 12000 | M5: 12000 | N5: 12000 | O5: 12000 | P5: 12000 | Q5: 12000 | R5: 12000 | S5: 12000 | T5: 12000 | U5: 12000 | V5: 12000 | W5: 12000 | X5: 12000 | Y5: 12000 | Z5: 12000 | AA5: 12000 | AB5: =SUM(D5:AA5)*C5 -> 1440000 | AF5: 46296 | AG5: =AC10 -> 2604000
B6: ORDINARIO | C6: 21 | D6: 12000 | E6: 12000 | F6: 12000 | G6: 12000 | H6: 12000 | I6: 12000 | J6: 12000 | K6: 12000 | L6: 12000 | M6: 12000 | N6: 12000 | O6: 12000 | P6: 12000 | Q6: 12000 | R6: 12000 | S6: 12000 | T6: 12000 | U6: 12000 | V6: 12000 | W6: 12000 | X6: 12000 | Y6: 12000 | Z6: 12000 | AA6: 12000 | AB6: =SUM(D6:AA6)*C6 -> 6048000 | AF6: 46327 | AG6: =AC13 -> 2520000
A7: 46266 | B7: SÁBADO | C7: 4 | D7: 3500 | E7: 3500 | F7: 3500 | G7: 3500 | H7: 3500 | I7: 3500 | J7: 3500 | K7: 3500 | L7: 3500 | M7: 3500 | N7: 3500 | O7: 3500 | P7: 3500 | Q7: 3500 | R7: 3500 | S7: 3500 | T7: 3500 | U7: 3500 | V7: 3500 | W7: 3500 | X7: 3500 | Y7: 3500 | Z7: 3500 | AA7: 3500 | AB7: =SUM(D7:AA7)*C7 -> 336000 | AC7: =+AB7+AB8+AB9 -> 2520000 | AF7: 46357 | AG7: =AC16 -> 8928000
B8: FESTIVO | C8: 4 | D8: 3500 | E8: 3500 | F8: 3500 | G8: 3500 | H8: 3500 | I8: 3500 | J8: 3500 | K8: 3500 | L8: 3500 | M8: 3500 | N8: 3500 | O8: 3500 | P8: 3500 | Q8: 3500 | R8: 3500 | S8: 3500 | T8: 3500 | U8: 3500 | V8: 3500 | W8: 3500 | X8: 3500 | Y8: 3500 | Z8: 3500 | AA8: 3500 | AB8: =SUM(D8:AA8)*C8 -> 336000
B9: ORDINARIO | C9: 22 | D9: 3500 | E9: 3500 | F9: 3500 | G9: 3500 | H9: 3500 | I9: 3500 | J9: 3500 | K9: 3500 | L9: 3500 | M9: 3500 | N9: 3500 | O9: 3500 | P9: 3500 | Q9: 3500 | R9: 3500 | S9: 3500 | T9: 3500 | U9: 3500 | V9: 3500 | W9: 3500 | X9: 3500 | Y9: 3500 | Z9: 3500 | AA9: 3500 | AB9: =SUM(D9:AA9)*C9 -> 1848000
A10: 46296 | B10: SÁBADO | C10: 5 | D10: 3500 | E10: 3500 | F10: 3500 | G10: 3500 | H10: 3500 | I10: 3500 | J10: 3500 | K10: 3500 | L10: 3500 | M10: 3500 | N10: 3500 | O10: 3500 | P10: 3500 | Q10: 3500 | R10: 3500 | S10: 3500 | T10: 3500 | U10: 3500 | V10: 3500 | W10: 3500 | X10: 3500 | Y10: 3500 | Z10: 3500 | AA10: 3500 | AB10: =SUM(D10:AA10)*C10 -> 420000 | AC10: =+AB10+AB11+AB12 -> 2604000
B11: FESTIVO | C11: 4 | D11: 3500 | E11: 3500 | F11: 3500 | G11: 3500 | H11: 3500 | I11: 3500 | J11: 3500 | K11: 3500 | L11: 3500 | M11: 3500 | N11: 3500 | O11: 3500 | P11: 3500 | Q11: 3500 | R11: 3500 | S11: 3500 | T11: 3500 | U11: 3500 | V11: 3500 | W11: 3500 | X11: 3500 | Y11: 3500 | Z11: 3500 | AA11: 3500 | AB11: =SUM(D11:AA11)*C11 -> 336000
B12: ORDINARIO | C12: 22 | D12: 3500 | E12: 3500 | F12: 3500 | G12: 3500 | H12: 3500 | I12: 3500 | J12: 3500 | K12: 3500 | L12: 3500 | M12: 3500 | N12: 3500 | O12: 3500 | P12: 3500 | Q12: 3500 | R12: 3500 | S12: 3500 | T12: 3500 | U12: 3500 | V12: 3500 | W12: 3500 | X12: 3500 | Y12: 3500 | Z12: 3500 | AA12: 3500 | AB12: =SUM(D12:AA12)*C12 -> 1848000
A13: 46327 | B13: SÁBADO | C13: 4 | D13: 3500 | E13: 3500 | F13: 3500 | G13: 3500 | H13: 3500 | I13: 3500 | J13: 3500 | K13: 3500 | L13: 3500 | M13: 3500 | N13: 3500 | O13: 3500 | P13: 3500 | Q13: 3500 | R13: 3500 | S13: 3500 | T13: 3500 | U13: 3500 | V13: 3500 | W13: 3500 | X13: 3500 | Y13: 3500 | Z13: 3500 | AA13: 3500 | AB13: =SUM(D13:AA13)*C13 -> 336000 | AC13: =+AB13+AB14+AB15 -> 2520000
B14: FESTIVO | C14: 5 | D14: 3500 | E14: 3500 | F14: 3500 | G14: 3500 | H14: 3500 | I14: 3500 | J14: 3500 | K14: 3500 | L14: 3500 | M14: 3500 | N14: 3500 | O14: 3500 | P14: 3500 | Q14: 3500 | R14: 3500 | S14: 3500 | T14: 3500 | U14: 3500 | V14: 3500 | W14: 3500 | X14: 3500 | Y14: 3500 | Z14: 3500 | AA14: 3500 | AB14: =SUM(D14:AA14)*C14 -> 420000
B15: ORDINARIO | C15: 21 | D15: 3500 | E15: 3500 | F15: 3500 | G15: 3500 | H15: 3500 | I15: 3500 | J15: 3500 | K15: 3500 | L15: 3500 | M15: 3500 | N15: 3500 | O15: 3500 | P15: 3500 | Q15: 3500 | R15: 3500 | S15: 3500 | T15: 3500 | U15: 3500 | V15: 3500 | W15: 3500 | X15: 3500 | Y15: 3500 | Z15: 3500 | AA15: 3500 | AB15: =SUM(D15:AA15)*C15 -> 1764000
A16: 46357 | B16: SÁBADO | C16: 4 | D16: 12000 | E16: 12000 | F16: 12000 | G16: 12000 | H16: 12000 | I16: 12000 | J16: 12000 | K16: 12000 | L16: 12000 | M16: 12000 | N16: 12000 | O16: 12000 | P16: 12000 | Q16: 12000 | R16: 12000 | S16: 12000 | T16: 12000 | U16: 12000 | V16: 12000 | W16: 12000 | X16: 12000 | Y16: 12000 | Z16: 12000 | AA16: 12000 | AB16: =SUM(D16:AA16)*C16 -> 1152000 | AC16: =+AB16+AB17+AB18 -> 8928000
B17: FESTIVO | C17: 4 | D17: 12000 | E17: 12000 | F17: 12000 | G17: 12000 | H17: 12000 | I17: 12000 | J17: 12000 | K17: 12000 | L17: 12000 | M17: 12000 | N17: 12000 | O17: 12000 | P17: 12000 | Q17: 12000 | R17: 12000 | S17: 12000 | T17: 12000 | U17: 12000 | V17: 12000 | W17: 12000 | X17: 12000 | Y17: 12000 | Z17: 12000 | AA17: 12000 | AB17: =SUM(D17:AA17)*C17 -> 1152000
B18: ORDINARIO | C18: 23 | D18: 12000 | E18: 12000 | F18: 12000 | G18: 12000 | H18: 12000 | I18: 12000 | J18: 12000 | K18: 12000 | L18: 12000 | M18: 12000 | N18: 12000 | O18: 12000 | P18: 12000 | Q18: 12000 | R18: 12000 | S18: 12000 | T18: 12000 | U18: 12000 | V18: 12000 | W18: 12000 | X18: 12000 | Y18: 12000 | Z18: 12000 | AA18: 12000 | AB18: =SUM(D18:AA18)*C18 -> 6624000
A21: Mes | B21: Tipo de día | C21: No. de Días | D21: HORA 01 | E21: HORA 02 | F21: HORA 03 | G21: HORA 04 | H21: HORA 05 | I21: HORA 06 | J21: HORA 07 | K21: HORA 08 | L21: HORA 09 | M21: HORA 10 | N21: HORA 11 | O21: HORA 12 | P21: HORA 13 | Q21: HORA 14 | R21: HORA 15 | S21: HORA 16 | T21: HORA 17 | U21: HORA 18 | V21: HORA 19 | W21: HORA 20 | X21: HORA 21 | Y21: HORA 22 | Z21: HORA 23 | AA21: HORA 24 | AB21: Total
A22: 46388 | B22: SÁBADO | C22: 5 | D22: 12000 | E22: 12000 | F22: 12000 | G22: 12000 | H22: 12000 | I22: 12000 | J22: 12000 | K22: 12000 | L22: 12000 | M22: 12000 | N22: 12000 | O22: 12000 | P22: 12000 | Q22: 12000 | R22: 12000 | S22: 12000 | T22: 12000 | U22: 12000 | V22: 12000 | W22: 12000 | X22: 12000 | Y22: 12000 | Z22: 12000 | AA22: 12000 | AB22: =SUM(D22:AA22)*C22 -> 1440000 | AC22: =+AB22+AB23+AB24 -> 8928000 | AF22: 46388 | AG22: =AC22 -> 8928000
B23: FESTIVO | C23: 7 | D23: 12000 | E23: 12000 | F23: 12000 | G23: 12000 | H23: 12000 | I23: 12000 | J23: 12000 | K23: 12000 | L23: 12000 | M23: 12000 | N23: 12000 | O23: 12000 | P23: 12000 | Q23: 12000 | R23: 12000 | S23: 12000 | T23: 12000 | U23: 12000 | V23: 12000 | W23: 12000 | X23: 12000 | Y23: 12000 | Z23: 12000 | AA23: 12000 | AB23: =SUM(D23:AA23)*C23 -> 2016000 | AF23: 46419 | AG23: =AC25 -> 8064000
B24: ORDINARIO | C24: 19 | D24: 12000 | E24: 12000 | F24: 12000 | G24: 12000 | H24: 12000 | I24: 12000 | J24: 12000 | K24: 12000 | L24: 12000 | M24: 12000 | N24: 12000 | O24: 12000 | P24: 12000 | Q24: 12000 | R24: 12000 | S24: 12000 | T24: 12000 | U24: 12000 | V24: 12000 | W24: 12000 | X24: 12000 | Y24: 12000 | Z24: 12000 | AA24: 12000 | AB24: =SUM(D24:AA24)*C24 -> 5472000 | AF24: 46447 | AG24: =AC28 -> 8928000
A25: 46419 | B25: SÁBADO | C25: 4 | D25: 12000 | E25: 12000 | F25: 12000 | G25: 12000 | H25: 12000 | I25: 12000 | J25: 12000 | K25: 12000 | L25: 12000 | M25: 12000 | N25: 12000 | O25: 12000 | P25: 12000 | Q25: 12000 | R25: 12000 | S25: 12000 | T25: 12000 | U25: 12000 | V25: 12000 | W25: 12000 | X25: 12000 | Y25: 12000 | Z25: 12000 | AA25: 12000 | AB25: =SUM(D25:AA25)*C25 -> 1152000 | AC25: =+AB25+AB26+AB27 -> 8064000 | AF25: 46478 | AG25: =AC31 -> 8640000
B26: FESTIVO | C26: 4 | D26: 12000 | E26: 12000 | F26: 12000 | G26: 12000 | H26: 12000 | I26: 12000 | J26: 12000 | K26: 12000 | L26: 12000 | M26: 12000 | N26: 12000 | O26: 12000 | P26: 12000 | Q26: 12000 | R26: 12000 | S26: 12000 | T26: 12000 | U26: 12000 | V26: 12000 | W26: 12000 | X26: 12000 | Y26: 12000 | Z26: 12000 | AA26: 12000 | AB26: =SUM(D26:AA26)*C26 -> 1152000 | AF26: 46508 | AG26: =AC34 -> 8928000
B27: ORDINARIO | C27: 20 | D27: 12000 | E27: 12000 | F27: 12000 | G27: 12000 | H27: 12000 | I27: 12000 | J27: 12000 | K27: 12000 | L27: 12000 | M27: 12000 | N27: 12000 | O27: 12000 | P27: 12000 | Q27: 12000 | R27: 12000 | S27: 12000 | T27: 12000 | U27: 12000 | V27: 12000 | W27: 12000 | X27: 12000 | Y27: 12000 | Z27: 12000 | AA27: 12000 | AB27: =SUM(D27:AA27)*C27 -> 5760000 | AF27: 46539 | AG27: =AC37 -> 8640000
A28: 46447 | B28: SÁBADO | C28: 4 | D28: 12000 | E28: 12000 | F28: 12000 | G28: 12000 | H28: 12000 | I28: 12000 | J28: 12000 | K28: 12000 | L28: 12000 | M28: 12000 | N28: 12000 | O28: 12000 | P28: 12000 | Q28: 12000 | R28: 12000 | S28: 12000 | T28: 12000 | U28: 12000 | V28: 12000 | W28: 12000 | X28: 12000 | Y28: 12000 | Z28: 12000 | AA28: 12000 | AB28: =SUM(D28:AA28)*C28 -> 1152000 | AC28: =+AB28+AB29+AB30 -> 8928000 | AF28: 46569 | AG28: =AC40 -> 8928000
B29: FESTIVO | C29: 4 | D29: 12000 | E29: 12000 | F29: 12000 | G29: 12000 | H29: 12000 | I29: 12000 | J29: 12000 | K29: 12000 | L29: 12000 | M29: 12000 | N29: 12000 | O29: 12000 | P29: 12000 | Q29: 12000 | R29: 12000 | S29: 12000 | T29: 12000 | U29: 12000 | V29: 12000 | W29: 12000 | X29: 12000 | Y29: 12000 | Z29: 12000 | AA29: 12000 | AB29: =SUM(D29:AA29)*C29 -> 1152000 | AF29: 46600 | AG29: =AC43 -> 8928000
B30: ORDINARIO | C30: 23 | D30: 12000 | E30: 12000 | F30: 12000 | G30: 12000 | H30: 12000 | I30: 12000 | J30: 12000 | K30: 12000 | L30: 12000 | M30: 12000 | N30: 12000 | O30: 12000 | P30: 12000 | Q30: 12000 | R30: 12000 | S30: 12000 | T30: 12000 | U30: 12000 | V30: 12000 | W30: 12000 | X30: 12000 | Y30: 12000 | Z30: 12000 | AA30: 12000 | AB30: =SUM(D30:AA30)*C30 -> 6624000 | AF30: 46631 | AG30: =AC46 -> 2520000
A31: 46478 | B31: SÁBADO | C31: 4 | D31: 12000 | E31: 12000 | F31: 12000 | G31: 12000 | H31: 12000 | I31: 12000 | J31: 12000 | K31: 12000 | L31: 12000 | M31: 12000 | N31: 12000 | O31: 12000 | P31: 12000 | Q31: 12000 | R31: 12000 | S31: 12000 | T31: 12000 | U31: 12000 | V31: 12000 | W31: 12000 | X31: 12000 | Y31: 12000 | Z31: 12000 | AA31: 12000 | AB31: =SUM(D31:AA31)*C31 -> 1152000 | AC31: =+AB31+AB32+AB33 -> 8640000 | AF31: 46661 | AG31: =AC49 -> 2604000
B32: FESTIVO | C32: 4 | D32: 12000 | E32: 12000 | F32: 12000 | G32: 12000 | H32: 12000 | I32: 12000 | J32: 12000 | K32: 12000 | L32: 12000 | M32: 12000 | N32: 12000 | O32: 12000 | P32: 12000 | Q32: 12000 | R32: 12000 | S32: 12000 | T32: 12000 | U32: 12000 | V32: 12000 | W32: 12000 | X32: 12000 | Y32: 12000 | Z32: 12000 | AA32: 12000 | AB32: =SUM(D32:AA32)*C32 -> 1152000 | AF32: 46692 | AG32: =AC52 -> 2520000
B33: ORDINARIO | C33: 22 | D33: 12000 | E33: 12000 | F33: 12000 | G33: 12000 | H33: 12000 | I33: 12000 | J33: 12000 | K33: 12000 | L33: 12000 | M33: 12000 | N33: 12000 | O33: 12000 | P33: 12000 | Q33: 12000 | R33: 12000 | S33: 12000 | T33: 12000 | U33: 12000 | V33: 12000 | W33: 12000 | X33: 12000 | Y33: 12000 | Z33: 12000 | AA33: 12000 | AB33: =SUM(D33:AA33)*C33 -> 6336000 | AF33: 46722 | AG33: =AC55 -> 8928000
A34: 46508 | B34: SÁBADO | C34: 5 | D34: 12000 | E34: 12000 | F34: 12000 | G34: 12000 | H34: 12000 | I34: 12000 | J34: 12000 | K34: 12000 | L34: 12000 | M34: 12000 | N34: 12000 | O34: 12000 | P34: 12000 | Q34: 12000 | R34: 12000 | S34: 12000 | T34: 12000 | U34: 12000 | V34: 12000 | W34: 12000 | X34: 12000 | Y34: 12000 | Z34: 12000 | AA34: 12000 | AB34: =SUM(D34:AA34)*C34 -> 1440000 | AC34: =+AB34+AB35+AB36 -> 8928000
B35: FESTIVO | C35: 5 | D35: 12000 | E35: 12000 | F35: 12000 | G35: 12000 | H35: 12000 | I35: 12000 | J35: 12000 | K35: 12000 | L35: 12000 | M35: 12000 | N35: 12000 | O35: 12000 | P35: 12000 | Q35: 12000 | R35: 12000 | S35: 12000 | T35: 12000 | U35: 12000 | V35: 12000 | W35: 12000 | X35: 12000 | Y35: 12000 | Z35: 12000 | AA35: 12000 | AB35: =SUM(D35:AA35)*C35 -> 1440000
B36: ORDINARIO | C36: 21 | D36: 12000 | E36: 12000 | F36: 12000 | G36: 12000 | H36: 12000 | I36: 12000 | J36: 12000 | K36: 12000 | L36: 12000 | M36: 12000 | N36: 12000 | O36: 12000 | P36: 12000 | Q36: 12000 | R36: 12000 | S36: 12000 | T36: 12000 | U36: 12000 | V36: 12000 | W36: 12000 | X36: 12000 | Y36: 12000 | Z36: 12000 | AA36: 12000 | AB36: =SUM(D36:AA36)*C36 -> 6048000
A37: 46539 | B37: SÁBADO | C37: 4 | D37: 12000 | E37: 12000 | F37: 12000 | G37: 12000 | H37: 12000 | I37: 12000 | J37: 12000 | K37: 12000 | L37: 12000 | M37: 12000 | N37: 12000 | O37: 12000 | P37: 12000 | Q37: 12000 | R37: 12000 | S37: 12000 | T37: 12000 | U37: 12000 | V37: 12000 | W37: 12000 | X37: 12000 | Y37: 12000 | Z37: 12000 | AA37: 12000 | AB37: =SUM(D37:AA37)*C37 -> 1152000 | AC37: =+AB37+AB38+AB39 -> 8640000
B38: FESTIVO | C38: 4 | D38: 12000 | E38: 12000 | F38: 12000 | G38: 12000 | H38: 12000 | I38: 12000 | J38: 12000 | K38: 12000 | L38: 12000 | M38: 12000 | N38: 12000 | O38: 12000 | P38: 12000 | Q38: 12000 | R38: 12000 | S38: 12000 | T38: 12000 | U38: 12000 | V38: 12000 | W38: 12000 | X38: 12000 | Y38: 12000 | Z38: 12000 | AA38: 12000 | AB38: =SUM(D38:AA38)*C38 -> 1152000
B39: ORDINARIO | C39: 22 | D39: 12000 | E39: 12000 | F39: 12000 | G39: 12000 | H39: 12000 | I39: 12000 | J39: 12000 | K39: 12000 | L39: 12000 | M39: 12000 | N39: 12000 | O39: 12000 | P39: 12000 | Q39: 12000 | R39: 12000 | S39: 12000 | T39: 12000 | U39: 12000 | V39: 12000 | W39: 12000 | X39: 12000 | Y39: 12000 | Z39: 12000 | AA39: 12000 | AB39: =SUM(D39:AA39)*C39 -> 6336000
A40: 46569 | B40: SÁBADO | C40: 5 | D40: 12000 | E40: 12000 | F40: 12000 | G40: 12000 | H40: 12000 | I40: 12000 | J40: 12000 | K40: 12000 | L40: 12000 | M40: 12000 | N40: 12000 | O40: 12000 | P40: 12000 | Q40: 12000 | R40: 12000 | S40: 12000 | T40: 12000 | U40: 12000 | V40: 12000 | W40: 12000 | X40: 12000 | Y40: 12000 | Z40: 12000 | AA40: 12000 | AB40: =SUM(D40:AA40)*C40 -> 1440000 | AC40: =+AB40+AB41+AB42 -> 8928000
B41: FESTIVO | C41: 4 | D41: 12000 | E41: 12000 | F41: 12000 | G41: 12000 | H41: 12000 | I41: 12000 | J41: 12000 | K41: 12000 | L41: 12000 | M41: 12000 | N41: 12000 | O41: 12000 | P41: 12000 | Q41: 12000 | R41: 12000 | S41: 12000 | T41: 12000 | U41: 12000 | V41: 12000 | W41: 12000 | X41: 12000 | Y41: 12000 | Z41: 12000 | AA41: 12000 | AB41: =SUM(D41:AA41)*C41 -> 1152000
B42: ORDINARIO | C42: 22 | D42: 12000 | E42: 12000 | F42: 12000 | G42: 12000 | H42: 12000 | I42: 12000 | J42: 12000 | K42: 12000 | L42: 12000 | M42: 12000 | N42: 12000 | O42: 12000 | P42: 12000 | Q42: 12000 | R42: 12000 | S42: 12000 | T42: 12000 | U42: 12000 | V42: 12000 | W42: 12000 | X42: 12000 | Y42: 12000 | Z42: 12000 | AA42: 12000 | AB42: =SUM(D42:AA42)*C42 -> 6336000
A43: 46600 | B43: SÁBADO | C43: 4 | D43: 12000 | E43: 12000 | F43: 12000 | G43: 12000 | H43: 12000 | I43: 12000 | J43: 12000 | K43: 12000 | L43: 12000 | M43: 12000 | N43: 12000 | O43: 12000 | P43: 12000 | Q43: 12000 | R43: 12000 | S43: 12000 | T43: 12000 | U43: 12000 | V43: 12000 | W43: 12000 | X43: 12000 | Y43: 12000 | Z43: 12000 | AA43: 12000 | AB43: =SUM(D43:AA43)*C43 -> 1152000 | AC43: =+AB43+AB44+AB45 -> 8928000
...

Sheet Formato -Producto N° 2  Curva
A5: Formato No. 1. Oferta Producto No. 2 Curva Convocatoria Pública DISPAC S.A. E.S.P.
A8: PROPONENTE
A10: MES | B10: DEMANDA REQUERIDA DISPAC KWh | C10: DEMANDA PERIODO REQUERIDA DISPAC KWh | D10: PORCENTAJE (%) OFERTADO DE LA DEMANDA REQUERIDA | E10: DEMANDA OFERTADA KWh - MES | F10: DEMANDA PERIODO OFERTADA KWh | G10: PRECIO OFERTADO $ kWh (0.00)
A11: 46235 | B11: 7024968.8 | C11: =SUM(B11:B15) -> 22523730 | D11: 0
A12: 46266 | B12: 2275335.9 | D12: 0
A13: 46296 | B13: 2149277.1 | D13: 0
A14: 46327 | B14: 2095521.4 | D14: 0
A15: 46357 | B15: 8978626.9 | D15: 0
A16: 46388 | B16: ='Cantidades -Producto 2'!AG22 -> 7839429.9 | C16: =SUM(B16:B27) -> 75224915 | D16: 0
A17: 46419 | B17: ='Cantidades -Producto 2'!AG23 -> 6751684.7 | D17: 0
A18: 46447 | B18: ='Cantidades -Producto 2'!AG24 -> 8300034.2 | D18: 0
A19: 46478 | B19: ='Cantidades -Producto 2'!AG25 -> 7930619.7 | D19: 0
A20: 46508 | B20: ='Cantidades -Producto 2'!AG26 -> 7510979.5 | D20: 0
A21: 46539 | B21: ='Cantidades -Producto 2'!AG27 -> 7268434 | D21: 0
A22: 46569 | B22: ='Cantidades -Producto 2'!AG28 -> 7399601.8 | D22: 0
A23: 46600 | B23: ='Cantidades -Producto 2'!AG29 -> 7183515.3 | D23: 0
A24: 46631 | B24: ='Cantidades -Producto 2'!AG30 -> 2065944.3 | D24: 0
A25: 46661 | B25: ='Cantidades -Producto 2'!AG31 -> 1878101 | D25: 0
A26: 46692 | B26: ='Cantidades -Producto 2'!AG32 -> 1922771.6 | D26: 0
A27: 46722 | B27: ='Cantidades -Producto 2'!AG33 -> 9173799.3 | D27: 0
A28: 46753 | B28: ='Cantidades -Producto 2'!AG61 -> 6921496.2 | C28: =SUM(B28:B39) -> 76156871 | D28: 0
A29: 46784 | B29: ='Cantidades -Producto 2'!AG62 -> 5803036.3 | D29: 0
A30: 46813 | B30: ='Cantidades -Producto 2'!AG63 -> 7335720.2 | D30: 0
A31: 46844 | B31: ='Cantidades -Producto 2'!AG64 -> 6914373.1 | D31: 0
A32: 46874 | B32: ='Cantidades -Producto 2'!AG65 -> 4526703.4 | D32: 0
A33: 46905 | B33: ='Cantidades -Producto 2'!AG66 -> 4322879.6 | D33: 0
A34: 46935 | B34: ='Cantidades -Producto 2'!AG67 -> 4291029.3 | D34: 0
A35: 46966 | B35: ='Cantidades -Producto 2'!AG68 -> 6546836.8 | D35: 0
A36: 46997 | B36: ='Cantidades -Producto 2'!AG69 -> 6870287.5 | D36: 0
A37: 47027 | B37: ='Cantidades -Producto 2'!AG70 -> 7266240.7 | D37: 0
A38: 47058 | B38: ='Cantidades -Producto 2'!AG71 -> 7127709.9 | D38: 0
A39: 47088 | B39: ='Cantidades -Producto 2'!AG72 -> 8230558 | D39: 0
A40: 47119 | B40: ='Cantidades -Producto 2'!AG100 -> 6809640.7 | C40: =SUM(B40:B51) -> 86260492 | D40: 0
A41: 47150 | B41: ='Cantidades -Producto 2'!AG101 -> 5723692.4 | D41: 0
A42: 47178 | B42: ='Cantidades -Producto 2'!AG102 -> 7092058.5 | D42: 0
A43: 47209 | B43: ='Cantidades -Producto 2'!AG103 -> 6778314 | D43: 0
A44: 47239 | B44: ='Cantidades -Producto 2'!AG104 -> 7580413.9 | D44: 0
A45: 47270 | B45: ='Cantidades -Producto 2'!AG105 -> 7278300.6 | D45: 0
A46: 47300 | B46: ='Cantidades -Producto 2'!AG106 -> 7391065.4 | D46: 0
A47: 47331 | B47: ='Cantidades -Producto 2'!AG107 -> 7218033.1 | D47: 0
...

Sheet Cantidades -Producto 2
A2: PRODUCTO 2
A3: Mes | B3: Tipo de día | C3: No. de Días | D3: HORA 01 | E3: HORA 02 | F3: HORA 03 | G3: HORA 04 | H3: HORA 05 | I3: HORA 06 | J3: HORA 07 | K3: HORA 08 | L3: HORA 09 | M3: HORA 10 | N3: HORA 11 | O3: HORA 12 | P3: HORA 13 | Q3: HORA 14 | R3: HORA 15 | S3: HORA 16 | T3: HORA 17 | U3: HORA 18 | V3: HORA 19 | W3: HORA 20 | X3: HORA 21 | Y3: HORA 22 | Z3: HORA 23 | AA3: HORA 24 | AB3: Total
A4: 46235 | B4: SÁBADO | C4: 5 | D4: 6655.8915 | E4: 5098.4853 | F4: 4540.3207 | G4: 4119.1307 | H4: 4032.7905 | I4: 4176.3429 | J4: 4834.8828 | K4: 6323.5222 | L4: 8568.8617 | M4: 9560.2106 | N4: 11205.755 | O4: 12404.361 | P4: 12792.348 | Q4: 12646.441 | R4: 12212.81 | S4: 12047.187 | T4: 11734.815 | U4: 11247.929 | V4: 12789.276 | W4: 13483.546 | X4: 12833.886 | Y4: 11280.739 | Z4: 9254.1347 | AA4: 7766.5713 | AB4: =SUM(D4:AA4)*C4 -> 1108051.2 | AC4: =+AB4+AB5+AB6 -> 7024968.8
B5: FESTIVO | C5: 5 | D5: 6571.5688 | E5: 5859.9659 | F5: 5166.8701 | G5: 4610.2769 | H5: 4246.3436 | I5: 4327.8315 | J5: 4731.191 | K5: 6251.709 | L5: 8128.0515 | M5: 9363.0921 | N5: 10087.772 | O5: 11154.556 | P5: 11804.192 | Q5: 11731.971 | R5: 11079.07 | S5: 10660.833 | T5: 10373.152 | U5: 10122.717 | V5: 11069.617 | W5: 12617.149 | X5: 12122.304 | Y5: 10700.708 | Z5: 8925.8007 | AA5: 7346.7666 | AB5: =SUM(D5:AA5)*C5 -> 1045267.5 | AF5: MES | AG5: DEMANDA REQUERIDA DISPAC KWh
B6: ORDINARIO | C6: 21 | D6: 6612.0713 | E6: 5856.6634 | F6: 5341.0986 | G6: 4990.0866 | H6: 4882.5114 | I6: 5649.3782 | J6: 6703.4592 | K6: 7987.4049 | L6: 9724.1351 | M6: 10969.14 | N6: 11638.729 | O6: 11758.439 | P6: 11102.089 | Q6: 11480.265 | R6: 11823.165 | S6: 11881.225 | T6: 12967.356 | U6: 12457.592 | V6: 12671.562 | W6: 13306.391 | X6: 12831.818 | Y6: 11633.734 | Z6: 9771.6858 | AA6: 7943.3366 | AB6: =SUM(D6:AA6)*C6 -> 4871650.1 | AF6: 46235 | AG6: =AC4 -> 7024968.8
A7: 46266 | B7: SÁBADO | C7: 4 | D7: 1995.8493 | E7: 1903.5485 | F7: 1741.9735 | G7: 1651.3014 | H7: 1639.5365 | I7: 1680.9493 | J7: 1869.2305 | K7: 2458.9738 | L7: 3114.5501 | M7: 3530.0926 | N7: 3839.9754 | O7: 4169.7478 | P7: 4287.6735 | Q7: 4248.0771 | R7: 4118.1641 | S7: 3936.186 | T7: 3782.265 | U7: 3720.8176 | V7: 4157.759 | W7: 4324.155 | X7: 4114.7351 | Y7: 3711.1627 | Z7: 3243.3569 | AA7: 2745.1674 | AB7: =SUM(D7:AA7)*C7 -> 303940.99 | AC7: =+AB7+AB8+AB9 -> 2275335.9 | AF7: 46266 | AG7: =AC7 -> 2275335.9
B8: FESTIVO | C8: 4 | D8: 2371.2536 | E8: 2108.3313 | F8: 1915.1711 | G8: 1799.8288 | H8: 1714.7492 | I8: 1704.7121 | J8: 1752.7084 | K8: 2145.1167 | L8: 2656.5851 | M8: 2936.8946 | N8: 3181.0164 | O8: 3537.0109 | P8: 3705.3896 | Q8: 3585.5179 | R8: 3315.3409 | S8: 3191.7289 | T8: 3079.619 | U8: 3124.2599 | V8: 3699.626 | W8: 3916.7319 | X8: 3778.0726 | Y8: 3449.1398 | Z8: 2907.9168 | AA8: 2432.5337 | AB8: =SUM(D8:AA8)*C8 -> 272037.02 | AF8: 46296 | AG8: =AC10 -> 2149277.1
B9: ORDINARIO | C9: 22 | D9: 2083.7031 | E9: 1890.607 | F9: 1745.6189 | G9: 1610.5085 | H9: 1638.7102 | I9: 1903.1409 | J9: 2252.1277 | K9: 2638.8079 | L9: 3201.8121 | M9: 3498.1403 | N9: 3738.7915 | O9: 4059.1052 | P9: 4114.131 | Q9: 4162.0085 | R9: 4267.7888 | S9: 4226.7811 | T9: 4155.8542 | U9: 4015.1461 | V9: 4333.8665 | W9: 4429.813 | X9: 4179.6027 | Y9: 3670.2184 | Z9: 2987.3946 | AA9: 2439.8599 | AB9: =SUM(D9:AA9)*C9 -> 1699357.8 | AF9: 46327 | AG9: =AC13 -> 2095521.4
A10: 46296 | B10: SÁBADO | C10: 5 | D10: 1876.9936 | E10: 1670.3156 | F10: 1537.4479 | G10: 1416.6354 | H10: 1358.9881 | I10: 1395.9471 | J10: 1504.3773 | K10: 2042.5884 | L10: 2702.1127 | M10: 3193.6563 | N10: 3542.9084 | O10: 3914.4735 | P10: 4007.5011 | Q10: 3902.312 | R10: 3786.6444 | S10: 3629.2463 | T10: 3495.9897 | U10: 3490.5993 | V10: 3821.006 | W10: 3859.779 | X10: 3720.1107 | Y10: 3384.8929 | Z10: 2917.6038 | AA10: 2453.0632 | AB10: =SUM(D10:AA10)*C10 -> 343125.96 | AC10: =+AB10+AB11+AB12 -> 2149277.1 | AF10: 46357 | AG10: =AC16 -> 8978626.9
B11: FESTIVO | C11: 4 | D11: 2009.6729 | E11: 1769.9382 | F11: 1592.5844 | G11: 1492.7507 | H11: 1445.435 | I11: 1460.3636 | J11: 1498.2843 | K11: 1894.599 | L11: 2347.6272 | M11: 2686.1667 | N11: 2867.6029 | O11: 3284.9312 | P11: 3507.1369 | Q11: 3443.2045 | R11: 3158.1157 | S11: 2817.24 | T11: 2869.3859 | U11: 3004.9894 | V11: 3538.8105 | W11: 3647.6333 | X11: 3377.8069 | Y11: 2956.0978 | Z11: 2439.9414 | AA11: 2014.7688 | AB11: =SUM(D11:AA11)*C11 -> 244500.35
B12: ORDINARIO | C12: 22 | D12: 1904.8269 | E12: 1700.0784 | F12: 1550.5538 | G12: 1396.7978 | H12: 1446.975 | I12: 1651.3989 | J12: 1935.9218 | K12: 2388.1025 | L12: 2886.7683 | M12: 3192.8532 | N12: 3388.8737 | O12: 3622.2765 | P12: 3812.8134 | Q12: 3816.2657 | R12: 3931.6314 | S12: 3976.8457 | T12: 3938.3377 | U12: 3755.3932 | V12: 4153.282 | W12: 4130.716 | X12: 3909.2975 | Y12: 3400.3405 | Z12: 2800.3742 | AA12: 2293.4023 | AB12: =SUM(D12:AA12)*C12 -> 1561650.8
A13: 46327 | B13: SÁBADO | C13: 4 | D13: 1815.6678 | E13: 1745.0633 | F13: 1568.1195 | G13: 1425.3553 | H13: 1423.366 | I13: 1481.9407 | J13: 1631.6561 | K13: 2164.0416 | L13: 2864.4358 | M13: 3290.4323 | N13: 3562.5532 | O13: 3841.3237 | P13: 3968.9502 | Q13: 3889.6187 | R13: 3769.4954 | S13: 3615.7998 | T13: 3477.7518 | U13: 3554.3074 | V13: 4002.8463 | W13: 4015.8501 | X13: 3827.4511 | Y13: 3432.2921 | Z13: 2961.9795 | AA13: 2490.4443 | AB13: =SUM(D13:AA13)*C13 -> 279282.97 | AC13: =+AB13+AB14+AB15 -> 2095521.4
B14: FESTIVO | C14: 5 | D14: 2066.5216 | E14: 1834.7903 | F14: 1697.1509 | G14: 1583.0877 | H14: 1539.2364 | I14: 1556.1221 | J14: 1646.6465 | K14: 2040.3889 | L14: 2559.6896 | M14: 2882.2177 | N14: 3064.7564 | O14: 3303.0161 | P14: 3432.4984 | Q14: 3332.8545 | R14: 3127.0937 | S14: 2973.6002 | T14: 2915.3065 | U14: 2969.188 | V14: 3577.523 | W14: 3725.6314 | X14: 3501.0205 | Y14: 3111.5363 | Z14: 2655.458 | AA14: 2241.5885 | AB14: =SUM(D14:AA14)*C14 -> 316684.62
B15: ORDINARIO | C15: 21 | D15: 1904.2589 | E15: 1696.9282 | F15: 1563.7304 | G15: 1476.0198 | H15: 1470.1933 | I15: 1667.2948 | J15: 1989.7803 | K15: 2464.6609 | L15: 2975.2143 | M15: 3250.569 | N15: 3521.9378 | O15: 3807.5629 | P15: 3898.7359 | Q15: 3865.5107 | R15: 3955.3398 | S15: 3856.137 | T15: 3720.9613 | U15: 3663.6588 | V15: 4094.7803 | W15: 4036.5066 | X15: 3884.0726 | Y15: 3462.9055 | Z15: 2853.7346 | AA15: 2326.8294 | AB15: =SUM(D15:AA15)*C15 -> 1499553.8
A16: 46357 | B16: SÁBADO | C16: 4 | D16: 8696.0576 | E16: 7748.4034 | F16: 7253.1108 | G16: 6926.1405 | H16: 6835.462 | I16: 7188.8053 | J16: 7646.0629 | K16: 9390.2012 | L16: 11738.856 | M16: 13040.321 | N16: 13919.369 | O16: 14798.957 | P16: 15094.698 | Q16: 15035.84 | R16: 14548.416 | S16: 14146.644 | T16: 13803.863 | U16: 13746.476 | V16: 15557.057 | W16: 15812.561 | X16: 15124.312 | Y16: 13953.932 | Z16: 12304.827 | AA16: 10815.897 | AB16: =SUM(D16:AA16)*C16 -> 1140505.1 | AC16: =+AB16+AB17+AB18 -> 8978626.9
B17: FESTIVO | C17: 4 | D17: 9628.4129 | E17: 8775.5904 | F17: 8180.0392 | G17: 7707.9188 | H17: 7499.8902 | I17: 7607.6222 | J17: 7635.3178 | K17: 8947.9855 | L17: 10602.419 | M17: 11991.614 | N17: 12683.249 | O17: 13703.438 | P17: 14212.662 | Q17: 14227.638 | R17: 13638.363 | S17: 13024.943 | T17: 12738.92 | U17: 12630.797 | V17: 14664.533 | W17: 15300.135 | X17: 14320.735 | Y17: 13014.263 | Z17: 12029.801 | AA17: 10591.872 | AB17: =SUM(D17:AA17)*C17 -> 1101432.6
B18: ORDINARIO | C18: 23 | D18: 9028.7515 | E18: 8140.113 | F18: 7576.1334 | G18: 7174.1144 | H18: 7077.4298 | I18: 7470.7272 | J18: 8256.9084 | K18: 10145.498 | L18: 12394.149 | M18: 13195.971 | N18: 13684.349 | O18: 14626.491 | P18: 14708.813 | Q18: 14806.114 | R18: 14816.162 | S18: 14849.092 | T18: 14562.906 | U18: 14380.941 | V18: 16349.38 | W18: 16540.68 | X18: 15773.257 | Y18: 14259.476 | Z18: 12420.26 | AA18: 10661.812 | AB18: =SUM(D18:AA18)*C18 -> 6736689.2
A21: Mes | B21: Tipo de día | C21: No. de Días | D21: HORA 01 | E21: HORA 02 | F21: HORA 03 | G21: HORA 04 | H21: HORA 05 | I21: HORA 06 | J21: HORA 07 | K21: HORA 08 | L21: HORA 09 | M21: HORA 10 | N21: HORA 11 | O21: HORA 12 | P21: HORA 13 | Q21: HORA 14 | R21: HORA 15 | S21: HORA 16 | T21: HORA 17 | U21: HORA 18 | V21: HORA 19 | W21: HORA 20 | X21: HORA 21 | Y21: HORA 22 | Z21: HORA 23 | AA21: HORA 24 | AB21: Total
A22: 46388 | B22: SÁBADO | C22: 5 | D22: 7310.7867 | E22: 6523.7313 | F22: 6036.1581 | G22: 5583.7552 | H22: 5525.8676 | I22: 5691.2791 | J22: 6023.8439 | K22: 7601.418 | L22: 9976.1894 | M22: 11424.443 | N22: 12274.86 | O22: 13501.914 | P22: 13867.56 | Q22: 13484.78 | R22: 12975.861 | S22: 13083.556 | T22: 12706.656 | U22: 12437.639 | V22: 13721.342 | W22: 14622.668 | X22: 14056.222 | Y22: 12747.661 | Z22: 10938.14 | AA22: 9231.6895 | AB22: =SUM(D22:AA22)*C22 -> 1256740.1 | AC22: =+AB22+AB23+AB24 -> 7839429.9 | AF22: 46388 | AG22: =AC22 -> 7839429.9
B23: FESTIVO | C23: 7 | D23: 7633.0562 | E23: 6872.0968 | F23: 6176.1075 | G23: 5802.8932 | H23: 5468.3145 | I23: 5435.2751 | J23: 5502.8447 | K23: 6508.1104 | L23: 8212.4685 | M23: 9371.6878 | N23: 9960.7627 | O23: 10933.605 | P23: 11546.043 | Q23: 11494.96 | R23: 10688.351 | S23: 10334.838 | T23: 10068.339 | U23: 9928.7518 | V23: 11903.505 | W23: 13193.259 | X23: 12642.69 | Y23: 11150.5 | Z23: 9528.643 | AA23: 7982.2172 | AB23: =SUM(D23:AA23)*C23 -> 1528375.2 | AF23: 46419 | AG23: =AC25 -> 6751684.7
B24: ORDINARIO | C24: 19 | D24: 7714.2867 | E24: 6819.783 | F24: 6303.2985 | G24: 5996.7637 | H24: 5953.0172 | I24: 6460.1664 | J24: 7189.1724 | K24: 8675.0232 | L24: 10932.986 | M24: 11848.403 | N24: 12673.088 | O24: 13927.139 | P24: 14327.474 | Q24: 14281.857 | R24: 14298.399 | S24: 14202.947 | T24: 13836.841 | U24: 13400.791 | V24: 14218.831 | W24: 15087.572 | X24: 14460.177 | Y24: 13111.769 | Z24: 11105.216 | AA24: 9191.5568 | AB24: =SUM(D24:AA24)*C24 -> 5054314.6 | AF24: 46447 | AG24: =AC28 -> 8300034.2
A25: 46419 | B25: SÁBADO | C25: 4 | D25: 6751.5849 | E25: 5861.7392 | F25: 5437.2705 | G25: 4975.9365 | H25: 4875.1653 | I25: 5036.2755 | J25: 5618.0038 | K25: 7300.7972 | L25: 9699.1755 | M25: 10718.368 | N25: 11453.692 | O25: 12436.464 | P25: 12684.705 | Q25: 12894.647 | R25: 12608.101 | S25: 11374.428 | T25: 11636.539 | U25: 11557.072 | V25: 12781.76 | W25: 13606.421 | X25: 13194.288 | Y25: 11784.286 | Z25: 9886.4337 | AA25: 8301.2649 | AB25: =SUM(D25:AA25)*C25 -> 929897.67 | AC25: =+AB25+AB26+AB27 -> 6751684.7 | AF25: 46478 | AG25: =AC31 -> 7930619.7
B26: FESTIVO | C26: 4 | D26: 7118.6521 | E26: 6422.8471 | F26: 5746.3833 | G26: 5382.4665 | H26: 5206.6016 | I26: 5336.3499 | J26: 5568.0926 | K26: 6839.9936 | L26: 8654.1562 | M26: 9729.7942 | N26: 10398.786 | O26: 11395.639 | P26: 12292.747 | Q26: 12185.014 | R26: 11328.489 | S26: 10844.029 | T26: 10257.002 | U26: 10368.565 | V26: 12055.071 | W26: 12274.676 | X26: 12275.617 | Y26: 11097.475 | Z26: 9467.3956 | AA26: 7650.0657 | AB26: =SUM(D26:AA26)*C26 -> 879583.63 | AF26: 46508 | AG26: =AC34 -> 7510979.5
B27: ORDINARIO | C27: 20 | D27: 6599.4807 | E27: 5901.3231 | F27: 5446.8501 | G27: 5018.2222 | H27: 5075.0299 | I27: 6180.9773 | J27: 7386.0734 | K27: 8473.9573 | L27: 10132.192 | M27: 10841.266 | N27: 11955.434 | O27: 13056.356 | P27: 13316.841 | Q27: 13159.038 | R27: 13432.276 | S27: 13453.579 | T27: 13266.991 | U27: 12679.073 | V27: 13595.614 | W27: 14434.665 | X27: 13813.205 | Y27: 12167.847 | Z27: 9961.5929 | AA27: 7762.2858 | AB27: =SUM(D27:AA27)*C27 -> 4942203.4 | AF27: 46539 | AG27: =AC37 -> 7268434
A28: 46447 | B28: SÁBADO | C28: 4 | D28: 7808.2171 | E28: 6897.4848 | F28: 6343.7033 | G28: 5918.8423 | H28: 5859.8527 | I28: 6125.4038 | J28: 6732.1826 | K28: 8418.448 | L28: 10862.328 | M28: 12170.097 | N28: 13180.068 | O28: 14519.704 | P28: 14952.86 | Q28: 14921.5 | R28: 14836.221 | S28: 14564.061 | T28: 13769.722 | U28: 13393.137 | V28: 14562.672 | W28: 15595.672 | X28: 14987.653 | Y28: 13785.93 | Z28: 11955.584 | AA28: 10290.704 | AB28: =SUM(D28:AA28)*C28 -> 1089808.2 | AC28: =+AB28+AB29+AB30 -> 8300034.2 | AF28: 46569 | AG28: =AC40 -> 7399601.8
B29: FESTIVO | C29: 4 | D29: 8888.1474 | E29: 7953.2608 | F29: 7246.4114 | G29: 6656.8556 | H29: 6278.797 | I29: 6423.9699 | J29: 6449.4673 | K29: 7806.5453 | L29: 9236.018 | M29: 10307.034 | N29: 11297.332 | O29: 12315.979 | P29: 13178.494 | Q29: 13015.581 | R29: 12130.866 | S29: 11596.422 | T29: 11193.9 | U29: 11039.506 | V29: 12629.487 | W29: 14217.674 | X29: 13824.319 | Y29: 12463.214 | Z29: 10417.062 | AA29: 8646.6742 | AB29: =SUM(D29:AA29)*C29 -> 980852.07 | AF29: 46600 | AG29: =AC43 -> 7183515.3
B30: ORDINARIO | C30: 23 | D30: 7437.5016 | E30: 6687.9562 | F30: 6185.4122 | G30: 5863.3984 | H30: 5852.4792 | I30: 6848.8959 | J30: 7933.7612 | K30: 9258.2838 | L30: 11007.219 | M30: 11971.653 | N30: 12946.381 | O30: 13996.082 | P30: 14097.443 | Q30: 14116.441 | R30: 14764.598 | S30: 14786.131 | T30: 14631.967 | U30: 14026.52 | V30: 14851.64 | W30: 15693.492 | X30: 14812.127 | Y30: 13171.292 | Z30: 10973.029 | AA30: 8928.6393 | AB30: =SUM(D30:AA30)*C30 -> 6229373.9 | AF30: 46631 | AG30: =AC46 -> 2065944.3
A31: 46478 | B31: SÁBADO | C31: 4 | D31: 7711.8254 | E31: 6913.0307 | F31: 6295.371 | G31: 5942.8263 | H31: 5776.2613 | I31: 5896.1598 | J31: 4899.3483 | K31: 8221.1511 | L31: 10502.264 | M31: 11890.599 | N31: 12536.461 | O31: 13565.874 | P31: 13890.112 | Q31: 14447.174 | R31: 14223.448 | S31: 13608.953 | T31: 12552.867 | U31: 12060.175 | V31: 12300.851 | W31: 12761.059 | X31: 12646.855 | Y31: 12522.91 | Z31: 10940.943 | AA31: 9383.2913 | AB31: =SUM(D31:AA31)*C31 -> 1005959.2 | AC31: =+AB31+AB32+AB33 -> 7930619.7 | AF31: 46661 | AG31: =AC49 -> 1878101
B32: FESTIVO | C32: 4 | D32: 7183.2241 | E32: 6312.8224 | F32: 5833.4439 | G32: 5343.7005 | H32: 5175.4633 | I32: 4268.9805 | J32: 5494.2954 | K32: 6828.4824 | L32: 8296.3502 | M32: 9234.2527 | N32: 9960.804 | O32: 10650.261 | P32: 11254.143 | Q32: 11174.19 | R32: 10984.859 | S32: 10791.435 | T32: 10505.821 | U32: 10281.862 | V32: 10746.151 | W32: 12609.958 | X32: 12635.535 | Y32: 11964.395 | Z32: 10793.058 | AA32: 9028.6932 | AB32: =SUM(D32:AA32)*C32 -> 869408.72 | AF32: 46692 | AG32: =AC52 -> 1922771.6
B33: ORDINARIO | C33: 22 | D33: 7968.6713 | E33: 7187.1973 | F33: 6631.9586 | G33: 6274.7926 | H33: 6174.8355 | I33: 7021.3435 | J33: 7968.4932 | K33: 9514.2069 | L33: 11424.811 | M33: 12564.915 | N33: 13523.701 | O33: 14653.821 | P33: 14862.991 | Q33: 15056.282 | R33: 15400.244 | S33: 15106.117 | T33: 14346.439 | U33: 13961.614 | V33: 13763.476 | W33: 14689.779 | X33: 14315.813 | Y33: 12832.934 | Z33: 10957.616 | AA33: 9036.6627 | AB33: =SUM(D33:AA33)*C33 -> 6055251.7 | AF33: 46722 | AG33: =AC55 -> 9173799.3
A34: 46508 | B34: SÁBADO | C34: 5 | D34: 7427.8298 | E34: 6597.0007 | F34: 6074.0933 | G34: 5706.092 | H34: 5602.6943 | I34: 5763.9757 | J34: 6223.9797 | K34: 7982.6191 | L34: 10225.541 | M34: 11412.171 | N34: 12251.597 | O34: 13126.965 | P34: 13687.009 | Q34: 13517.787 | R34: 13266.513 | S34: 12854.58 | T34: 12057.799 | U34: 12060.155 | V34: 12986.491 | W34: 13645.069 | X34: 13002.008 | Y34: 11753.482 | Z34: 9912.5336 | AA34: 8354.7183 | AB34: =SUM(D34:AA34)*C34 -> 1227463.5 | AC34: =+AB34+AB35+AB36 -> 7510979.5
B35: FESTIVO | C35: 5 | D35: 7087.2072 | E35: 5923.9358 | F35: 5321.8088 | G35: 5011.1076 | H35: 4813.4426 | I35: 4863.233 | J35: 5075.2594 | K35: 6723.8889 | L35: 8538.0933 | M35: 9660.6178 | N35: 10692.522 | O35: 11329.824 | P35: 12091.582 | Q35: 11745.416 | R35: 11003.256 | S35: 10439.814 | T35: 10171.318 | U35: 10036.963 | V35: 11389.859 | W35: 12610.539 | X35: 12147.717 | Y35: 11044.906 | Z35: 9324.0518 | AA35: 7741.5689 | AB35: =SUM(D35:AA35)*C35 -> 1073939.7
B36: ORDINARIO | C36: 21 | D36: 6675.9841 | E36: 5796.3851 | F36: 5304.3216 | G36: 5040.8385 | H36: 5052.7501 | I36: 5796.84 | J36: 6733.1222 | K36: 8200.1916 | L36: 10229.284 | M36: 11321.56 | N36: 12286.845 | O36: 13372.463 | P36: 13457.672 | Q36: 13420.663 | R36: 13649.473 | S36: 13588.288 | T36: 13270.888 | U36: 12962.59 | V36: 13697.422 | W36: 14373.849 | X36: 13547.364 | Y36: 12020.576 | Z36: 10102.2 | AA36: 8173.4922 | AB36: =SUM(D36:AA36)*C36 -> 5209576.3
A37: 46539 | B37: SÁBADO | C37: 4 | D37: 6168.2099 | E37: 5684.8976 | F37: 5419.7179 | G37: 4985.0098 | H37: 4824.7844 | I37: 5247.4142 | J37: 5625.0855 | K37: 7519.476 | L37: 10003.854 | M37: 11286.513 | N37: 11872.087 | O37: 13018.137 | P37: 13205.585 | Q37: 12630.151 | R37: 12986.78 | S37: 12581.963 | T37: 11604.943 | U37: 11699.712 | V37: 13602.301 | W37: 15035.173 | X37: 14009.373 | Y37: 12773.723 | Z37: 11166.006 | AA37: 9617.4256 | AB37: =SUM(D37:AA37)*C37 -> 970273.3 | AC37: =+AB37+AB38+AB39 -> 7268434
B38: FESTIVO | C38: 4 | D38: 8129.4246 | E38: 7062.7202 | F38: 6270.5718 | G38: 5831.2771 | H38: 5653.7297 | I38: 5816.0535 | J38: 5873.6825 | K38: 7638.7435 | L38: 9446.9964 | M38: 10330.297 | N38: 10940.92 | O38: 11935.901 | P38: 12398.165 | Q38: 11904.801 | R38: 11237.659 | S38: 10647.38 | T38: 10149.586 | U38: 10052.228 | V38: 11934.226 | W38: 13278.332 | X38: 12293.184 | Y38: 10794.153 | Z38: 9223.662 | AA38: 7543.103 | AB38: =SUM(D38:AA38)*C38 -> 905547.18
B39: ORDINARIO | C39: 22 | D39: 6409.0264 | E39: 5555.0665 | F39: 4998.3998 | G39: 4692.1839 | H39: 4812.5552 | I39: 5499.4167 | J39: 6517.7355 | K39: 8304.9292 | L39: 10314.453 | M39: 11406.532 | N39: 12363.642 | O39: 13338.807 | P39: 13540.52 | Q39: 13692.306 | R39: 13754.559 | S39: 13567.154 | T39: 13190.419 | U39: 12896.269 | V39: 13460.905 | W39: 13953.567 | X39: 13226.097 | Y39: 11595.454 | Z39: 9684.9175 | AA39: 8343.8832 | AB39: =SUM(D39:AA39)*C39 -> 5392613.6
A40: 46569 | B40: SÁBADO | C40: 5 | D40: 6204.7271 | E40: 5477.2942 | F40: 5043.9031 | G40: 4628.9337 | H40: 4515.2299 | I40: 4719.1311 | J40: 5158.1177 | K40: 7081.7249 | L40: 9283.6216 | M40: 10119.715 | N40: 10620.042 | O40: 12022.22 | P40: 12463.474 | Q40: 12350.546 | R40: 12211.065 | S40: 12116 | T40: 11823.869 | U40: 11650.003 | V40: 12625.046 | W40: 13474.815 | X40: 12886.3 | Y40: 11604.89 | Z40: 10030.124 | AA40: 8269.2925 | AB40: =SUM(D40:AA40)*C40 -> 1131900.4 | AC40: =+AB40+AB41+AB42 -> 7399601.8
B41: FESTIVO | C41: 4 | D41: 7044.981 | E41: 6144.6993 | F41: 5515.1237 | G41: 4976.9611 | H41: 4790.9459 | I41: 4888.7445 | J41: 5212.5412 | K41: 6522.5101 | L41: 8157.2883 | M41: 8558.2105 | N41: 9615.6138 | O41: 11038.247 | P41: 11839.647 | Q41: 11773.109 | R41: 11210.543 | S41: 11088.241 | T41: 10750.634 | U41: 10418.588 | V41: 11090.898 | W41: 13197.566 | X41: 12689.303 | Y41: 11324.458 | Z41: 9399.5785 | AA41: 7777.7708 | AB41: =SUM(D41:AA41)*C41 -> 860104.81
B42: ORDINARIO | C42: 22 | D42: 6852.9741 | E42: 6060.6626 | F42: 5507.4972 | G42: 5217.6854 | H42: 5209.3173 | I42: 5995.8586 | J42: 6988.3793 | K42: 8402.2224 | L42: 10125.349 | M42: 10788.236 | N42: 11617.071 | O42: 12756.837 | P42: 12642.912 | Q42: 13049.184 | R42: 13735.117 | S42: 13778.742 | T42: 13175.088 | U42: 12703.053 | V42: 13336.201 | W42: 14302.254 | X42: 13709.154 | Y42: 11947.06 | Z42: 9822.7773 | AA42: 8076.2138 | AB42: =SUM(D42:AA42)*C42 -> 5407596.6
A43: 46600 | B43: SÁBADO | C43: 4 | D43: 6829.0574 | E43: 5257.1953 | F43: 4693.8497 | G43: 4268.7501 | H43: 4181.6085 | I43: 4326.4934 | J43: 4991.146 | K43: 6493.603 | L43: 8759.784 | M43: 9760.3347 | N43: 11421.153 | O43: 12630.884 | P43: 13022.473 | Q43: 12875.212 | R43: 12437.556 | S43: 12270.395 | T43: 11955.124 | U43: 11463.719 | V43: 13019.373 | W43: 13720.087 | X43: 13064.397 | Y43: 11496.833 | Z43: 9451.4178 | AA43: 7950.0466 | AB43: =SUM(D43:AA43)*C43 -> 905361.97 | AC43: =+AB43+AB44+AB45 -> 7183515.3
...
