Workbook

Sheet PRODUCTO 01
C1: CP-GNCC2026-002
C2: CP-GNCC2026-002-PROD01
C3: CANTIDAD EN: | D3: KWh
C4: MODALIDAD: | D4: PAGUE LO CONTRATADO
C5: OFERENTE:
C9: MES DE SUMINISTRO | D9: ENERGÍA SOLICITADA (KWh) | E9: % ENERGÍA OFRECIDA | F9: ENERGÍA OFRECIDA (KWh) | G9: PRECIO OFERTADO ($/KWh)
C10: 46388 | D10: =+_xlfn.XLOOKUP(_xlfn.CONCAT(C10,"TOTAL"),'Cantidades horarias PROD 01'!D:D,'Cantidades horarias PROD 01'!AG:AG) -> 15171217 | E10: 1 | F10: =ROUND(D10*$E10,2) -> 15171217
C11: 46419 | D11: =+_xlfn.XLOOKUP(_xlfn.CONCAT(C11,"TOTAL"),'Cantidades horarias PROD 01'!D:D,'Cantidades horarias PROD 01'!AG:AG) -> 12711745 | E11: 1 | F11: =ROUND(D11*$E11,2) -> 12711745
C12: 46447 | D12: =+_xlfn.XLOOKUP(_xlfn.CONCAT(C12,"TOTAL"),'Cantidades horarias PROD 01'!D:D,'Cantidades horarias PROD 01'!AG:AG) -> 14682660 | E12: 1 | F12: =ROUND(D12*$E12,2) -> 14682660
C13: 46478 | D13: =+_xlfn.XLOOKUP(_xlfn.CONCAT(C13,"TOTAL"),'Cantidades horarias PROD 01'!D:D,'Cantidades horarias PROD 01'!AG:AG) -> 14589509 | E13: 1 | F13: =ROUND(D13*$E13,2) -> 14589509
C14: 46508 | D14: =+_xlfn.XLOOKUP(_xlfn.CONCAT(C14,"TOTAL"),'Cantidades horarias PROD 01'!D:D,'Cantidades horarias PROD 01'!AG:AG) -> 15388919 | E14: 1 | F14: =ROUND(D14*$E14,2) -> 15388919
C15: 46539 | D15: =+_xlfn.XLOOKUP(_xlfn.CONCAT(C15,"TOTAL"),'Cantidades horarias PROD 01'!D:D,'Cantidades horarias PROD 01'!AG:AG) -> 17759558 | E15: 1 | F15: =ROUND(D15*$E15,2) -> 17759558
C16: 46569 | D16: =+_xlfn.XLOOKUP(_xlfn.CONCAT(C16,"TOTAL"),'Cantidades horarias PROD 01'!D:D,'Cantidades horarias PROD 01'!AG:AG) -> 18217389 | E16: 1 | F16: =ROUND(D16*$E16,2) -> 18217389
C17: 46600 | D17: =+_xlfn.XLOOKUP(_xlfn.CONCAT(C17,"TOTAL"),'Cantidades horarias PROD 01'!D:D,'Cantidades horarias PROD 01'!AG:AG) -> 18148729 | E17: 1 | F17: =ROUND(D17*$E17,2) -> 18148729
C18: 46631 | D18: =+_xlfn.XLOOKUP(_xlfn.CONCAT(C18,"TOTAL"),'Cantidades horarias PROD 01'!D:D,'Cantidades horarias PROD 01'!AG:AG) -> 17907128 | E18: 1 | F18: =ROUND(D18*$E18,2) -> 17907128
C19: 46661 | D19: =+_xlfn.XLOOKUP(_xlfn.CONCAT(C19,"TOTAL"),'Cantidades horarias PROD 01'!D:D,'Cantidades horarias PROD 01'!AG:AG) -> 19277289 | E19: 1 | F19: =ROUND(D19*$E19,2) -> 19277289
C20: 46692 | D20: =+_xlfn.XLOOKUP(_xlfn.CONCAT(C20,"TOTAL"),'Cantidades horarias PROD 01'!D:D,'Cantidades horarias PROD 01'!AG:AG) -> 17098386 | E20: 1 | F20: =ROUND(D20*$E20,2) -> 17098386
C21: 46722 | D21: =+_xlfn.XLOOKUP(_xlfn.CONCAT(C21,"TOTAL"),'Cantidades horarias PROD 01'!D:D,'Cantidades horarias PROD 01'!AG:AG) -> 18753075 | E21: 1 | F21: =ROUND(D21*$E21,2) -> 18753075
... C57: 47818 | D57: =+_xlfn.XLOOKUP(_xlfn.CONCAT(C57,"TOTAL"),'Cantidades horarias PROD 01'!D:D,'Cantidades horarias PROD 01'!AG:AG) -> 61879258 | E57: 1 | F57: =ROUND(D57*$E57,2) -> 61879258
C58: TOTAL | D58: =SUM(D10:D57) -> 1.968427e+09 | E58: =IFERROR(F58/D58,0) -> 1 | F58: =SUM(F10:F57) -> 1.968427e+09 | G58: =+(+SUM(F10:F21)*G10+SUM(F22:F33)*G22+SUM(F34:F45)*G34+SUM(F46:F57)*G46)/F58 -> 0
C60: Nota
C61: 1. $/kWh expresados en pesos de abril de 2026. (IPP)
C62: 2. La energia ofertada se despachara conforme a las cantidades horarias de este anexo
C66: XXXXXXXXXXXXXXXXXXXXXXXX
C67: REPRESENTANTE LEGAL
C68: XXXXXXXXXXXXXXXXXX.SA.E.S.P
C74: XXXXXXXXXXXXXXXXXXXXXX S.A E.S.P
C76: Nota
C77: 1. $/kWh expresados en pesos de octubre 2025.
C78: 2. La energia ofertada se despachara conforme a las cantidades horarias de este anexo
C82: XXXXXXXXXXXXXXXXXXXXXXXX
C83: REPRESENTANTE LEGAL
C84: XXXXXXXXXXXXXXXXXXXXXX S.A E.S.P

Sheet Cantidades horarias PROD 01
E1: CUADRO DE CANTIDADES HORARIAS OFRECIDAS
E2: CANTIDADES DE ENERGIA (KWh) - PRODUCTO 1
E3: PAGUE LO CONTRATADO
E5: OFERENTE:
B8: MES | C8: AÑO | D8: LLAVE | F8: Cantidad Ofrecida | G8: Tipo de día | H8: N° días mes | I8: H1 | J8: H2 | K8: H3 | L8: H4 | M8: H5 | N8: H6 | O8: H7 | P8: H8 | Q8: H9 | R8: H10 | S8: H11 | T8: H12 | U8: H13 | V8: H14 | W8: H15 | X8: H16 | Y8: H17 | Z8: H18 | AA8: H19 | AB8: H20 | AC8: H21 | AD8: H22 | AE8: H23 | AF8: H24 | AG8: TOTAL
B9: =+MONTH(E9) -> 1 | C9: =+YEAR(E9) -> 2027 | D9: =+_xlfn.CONCAT(B9:C9,G9) -> 12027OR | E9: 46388 | F9: =+AG13 -> 15171217 | G9: OR | H9: 19 | I9: 19965.961 | J9: 19620.256 | K9: 19414.116 | L9: 19356.877 | M9: 19358.285 | N9: 19689.037 | O9: 20595.899 | P9: 21039.504 | Q9: 20088.393 | R9: 18958.479 | S9: 19202.535 | T9: 19409.485 | U9: 19245.924 | V9: 19713.234 | W9: 20731.208 | X9: 22281.642 | Y9: 24817.741 | Z9: 25730.181 | AA9: 25093.599 | AB9: 24550.411 | AC9: 23577.079 | AD9: 22281.692 | AE9: 21179.417 | AF9: 20603.496 | AG9: =ROUND(SUM(I9:AF9)*H9,2) -> 9623584.6
B10: =+MONTH(E10) -> 1 | C10: =+YEAR(E10) -> 2027 | D10: =+_xlfn.CONCAT(B10:C10,G10) -> 12027SA | E10: 46388 | G10: SA | H10: 5 | I10: 19961.155 | J10: 19594.576 | K10: 19369.063 | L10: 19273.063 | M10: 19236.89 | N10: 19398.554 | O10: 19939.733 | P10: 19919.949 | Q10: 19534.964 | R10: 18991.677 | S10: 18689.938 | T10: 18805.861 | U10: 18768.254 | V10: 18491.782 | W10: 18160.749 | X10: 19608.377 | Y10: 22324.102 | Z10: 23809.614 | AA10: 23640.024 | AB10: 23346.662 | AC10: 22574.955 | AD10: 21380.828 | AE10: 20359.647 | AF10: 19790.508 | AG10: =ROUND(SUM(I10:AF10)*H10,2) -> 2424854.6
B11: =+MONTH(E11) -> 1 | C11: =+YEAR(E11) -> 2027 | D11: =+_xlfn.CONCAT(B11:C11,G11) -> 12027DO | E11: 46388 | G11: DO | H11: 5 | I11: 19079.334 | J11: 18791.877 | K11: 18602.104 | L11: 18475.94 | M11: 18467.269 | N11: 18301.684 | O11: 17909.626 | P11: 18456.986 | Q11: 18223.014 | R11: 17911.821 | S11: 17111.572 | T11: 16724.083 | U11: 16323.23 | V11: 15628.197 | W11: 14908.369 | X11: 16399.548 | Y11: 19306.883 | Z11: 20873.874 | AA11: 21094.896 | AB11: 21045.771 | AC11: 20502.419 | AD11: 19905.257 | AE11: 19405.893 | AF11: 19024.744 | AG11: =ROUND(SUM(I11:AF11)*H11,2) -> 2212371.9
B12: =+MONTH(E12) -> 1 | C12: =+YEAR(E12) -> 2027 | D12: =+_xlfn.CONCAT(B12:C12,G12) -> 12027FE | E12: 46388 | G12: FE | H12: 2 | I12: 19408.967 | J12: 19131.398 | K12: 18957.291 | L12: 18841.938 | M12: 18828.98 | N12: 18529.052 | O12: 18130.127 | P12: 18456.831 | Q12: 20366.872 | R12: 20894.74 | S12: 19728.259 | T12: 17785.793 | U12: 16121.355 | V12: 15354.743 | W12: 15224.01 | X12: 16744.94 | Y12: 19572.68 | Z12: 21166.978 | AA12: 21353.817 | AB12: 21325.078 | AC12: 20701.026 | AD12: 20027.969 | AE12: 19476.23 | AF12: 19074.06 | AG12: =ROUND(SUM(I12:AF12)*H12,2) -> 910406.27
B13: =+MONTH(E13) -> 1 | C13: =+YEAR(E13) -> 2027 | D13: =+_xlfn.CONCAT(E13,G13) -> 46388TOTAL | E13: 46388 | G13: TOTAL | H13: =+SUM(H9:H12) -> 31 | I13: =+SUMPRODUCT(I9:I12,$H9:$H12) -> 613373.64 | J13: =+SUMPRODUCT(J9:J12,$H9:$H12) -> 602979.92 | K13: =+SUMPRODUCT(K9:K12,$H9:$H12) -> 596638.62 | L13: =+SUMPRODUCT(L9:L12,$H9:$H12) -> 594209.56 | M13: =+SUMPRODUCT(M9:M12,$H9:$H12) -> 593986.17 | N13: =+SUMPRODUCT(N9:N12,$H9:$H12) -> 599651.01 | O13: =+SUMPRODUCT(O9:O12,$H9:$H12) -> 616829.12 | P13: =+SUMPRODUCT(P9:P12,$H9:$H12) -> 628548.92 | ... AF13: =+SUMPRODUCT(AF9:AF12,$H9:$H12) -> 623690.8 | AG13: =SUM(I13:AF13) -> 15171217
B14: =+MONTH(E14) -> 2 | C14: =+YEAR(E14) -> 2027 | D14: =+_xlfn.CONCAT(B14:C14,G14) -> 22027OR | E14: 46419 | F14: =+AG18 -> 12711745 | G14: OR | H14: 20 | I14: 18524.491 | J14: 18157.624 | K14: 17922.182 | L14: 17850.942 | M14: 17763.002 | N14: 18012.802 | O14: 18451.229 | P14: 18327.724 | Q14: 17170.884 | R14: 15615.126 | S14: 15639.705 | T14: 16377.52 | U14: 16828.28 | V14: 18365.421 | W14: 18529.449 | X14: 19271.847 | Y14: 21854.498 | Z14: 23440.928 | AA14: 23209.821 | AB14: 22860.507 | AC14: 21917.781 | AD14: 20784.749 | AE14: 19843.919 | AF14: 19315.186 | AG14: =+SUM(I14:AF14)*H14 -> 9120712.3
B15: =+MONTH(E15) -> 2 | C15: =+YEAR(E15) -> 2027 | D15: =+_xlfn.CONCAT(B15:C15,G15) -> 22027SA | E15: 46419 | G15: SA | H15: 4 | I15: 18651.049 | J15: 18309.441 | K15: 18136.567 | L15: 18043.271 | M15: 18035.115 | N15: 18309.579 | O15: 19105.14 | P15: 19438.474 | Q15: 19523.218 | R15: 18890.495 | S15: 18650.609 | T15: 19231.072 | U15: 19314.027 | V15: 20206.282 | W15: 19984.08 | X15: 20326.334 | Y15: 22733.989 | Z15: 23890.6 | AA15: 23378.067 | AB15: 22994.453 | AC15: 22100.828 | AD15: 20811.955 | AE15: 19703.969 | AF15: 19101.055 | AG15: =+SUM(I15:AF15)*H15 -> 1915478.7
B16: =+MONTH(E16) -> 2 | C16: =+YEAR(E16) -> 2027 | D16: =+_xlfn.CONCAT(B16:C16,G16) -> 22027DO | E16: 46419 | G16: DO | H16: 4 | I16: 18067.435 | J16: 17775.931 | K16: 17578.429 | L16: 17449.189 | M16: 17444.837 | N16: 17271.482 | O16: 16858.52 | P16: 17258.217 | Q16: 17082.429 | R16: 16743.956 | S16: 15920.696 | T16: 15816.441 | U16: 15492.722 | V16: 15530.451 | W16: 14686.7 | X16: 15371.023 | Y16: 18089.448 | Z16: 19755.247 | AA16: 20013.555 | AB16: 20012.475 | AC16: 19462.943 | AD16: 18864.252 | AE16: 18363.641 | AF16: 17978.498 | AG16: =+SUM(I16:AF16)*H16 -> 1675554.1
B17: =+MONTH(E17) -> 2 | C17: =+YEAR(E17) -> 2027 | D17: =+_xlfn.CONCAT(B17:C17,G17) -> 22027FE | E17: 46419 | G17: FE | H17: 0 | I17: 0 | J17: 0 | K17: 0 | L17: 0 | M17: 0 | N17: 0 | O17: 0 | P17: 0 | Q17: 0 | R17: 0 | S17: 0 | T17: 0 | U17: 0 | V17: 0 | W17: 0 | X17: 0 | Y17: 0 | Z17: 0 | AA17: 0 | AB17: 0 | AC17: 0 | AD17: 0 | AE17: 0 | AF17: 0 | AG17: =+SUM(I17:AF17)*H17 -> 0
B18: =+MONTH(E18) -> 2 | C18: =+YEAR(E18) -> 2027 | D18: =+_xlfn.CONCAT(E18,G18) -> 46419TOTAL | E18: 46419 | G18: TOTAL | H18: =+SUM(H14:H17) -> 28 | I18: =+SUMPRODUCT(I14:I17,$H14:$H17) -> 517363.76 | J18: =+SUMPRODUCT(J14:J17,$H14:$H17) -> 507493.96 | K18: =+SUMPRODUCT(K14:K17,$H14:$H17) -> 501303.62 | L18: =+SUMPRODUCT(L14:L17,$H14:$H17) -> 498988.68 | M18: =+SUMPRODUCT(M14:M17,$H14:$H17) -> 497179.85 | N18: =+SUMPRODUCT(N14:N17,$H14:$H17) -> 502580.28 | O18: =+SUMPRODUCT(O14:O17,$H14:$H17) -> 512879.22 | P18: =+SUMPRODUCT(P14:P17,$H14:$H17) -> 513341.24 | ... AF18: =+SUMPRODUCT(AF14:AF17,$H14:$H17) -> 534621.93 | AG18: =SUM(I18:AF18) -> 12711745
B19: =+MONTH(E19) -> 3 | C19: =+YEAR(E19) -> 2027 | D19: =+_xlfn.CONCAT(B19:C19,G19) -> 32027OR | E19: 46447 | F19: =+AG23 -> 14682660 | G19: OR | H19: 20 | I19: 19319.795 | J19: 18975.52 | K19: 18767.013 | L19: 18710.302 | M19: 18701.265 | N19: 19009.725 | O19: 19807.361 | P19: 20316.913 | Q19: 19855.533 | R19: 18865.096 | S19: 19041.343 | T19: 19152.849 | U19: 18884.346 | V19: 19363.292 | W19: 20146.545 | X19: 21811.105 | Y19: 24017.67 | Z19: 24909.801 | AA19: 24300.656 | AB19: 23824.588 | AC19: 22861.784 | AD19: 21589.221 | AE19: 20509.113 | AF19: 19939.316 | AG19: =+SUM(I19:AF19)*H19 -> 9853603
B20: =+MONTH(E20) -> 3 | C20: =+YEAR(E20) -> 2027 | D20: =+_xlfn.CONCAT(B20:C20,G20) -> 32027SA | E20: 46447 | G20: SA | H20: 4 | I20: 19352.369 | J20: 18991.819 | K20: 18771.569 | L20: 18680.364 | M20: 18635.666 | N20: 18780.979 | O20: 19234.309 | P20: 19290.595 | Q20: 18551.975 | R20: 17573.331 | S20: 17619.546 | T20: 17659.213 | U20: 17352.075 | V20: 17432.517 | W20: 17710.312 | X20: 19269.219 | Y20: 21655.749 | Z20: 23111.581 | AA20: 22952.624 | AB20: 22727.844 | AC20: 21965.353 | AD20: 20783.834 | AE20: 19774.2 | AF20: 19212.545 | AG20: =+SUM(I20:AF20)*H20 -> 1868358.4
B21: =+MONTH(E21) -> 3 | C21: =+YEAR(E21) -> 2027 | D21: =+_xlfn.CONCAT(B21:C21,G21) -> 32027DO | E21: 46447 | G21: DO | H21: 4 | I21: 18672.503 | J21: 18380.59 | K21: 18180.915 | L21: 18056.653 | M21: 18019.948 | N21: 17743.467 | O21: 17183.986 | P21: 16356.395 | Q21: 16298.809 | R21: 16223.866 | S21: 16002.686 | T21: 15557.042 | U21: 14847.286 | V21: 14274.549 | W21: 14400.705 | X21: 16015.86 | Y21: 18560.658 | Z21: 20156.521 | AA21: 20397.014 | AB21: 20430.44 | AC21: 19857.64 | AD21: 19263.331 | AE21: 18754.824 | AF21: 18378.477 | AG21: =+SUM(I21:AF21)*H21 -> 1688056.7
B22: =+MONTH(E22) -> 3 | C22: =+YEAR(E22) -> 2027 | D22: =+_xlfn.CONCAT(B22:C22,G22) -> 32027FE | E22: 46447 | G22: FE | H22: 3 | I22: 18742.816 | J22: 18468.295 | K22: 18288.429 | L22: 18177.661 | M22: 18150.383 | N22: 17801.571 | O22: 17277.928 | P22: 16439.803 | Q22: 16026.567 | R22: 17179.594 | S22: 16847.036 | T22: 15014.093 | U22: 14333.685 | V22: 14357.02 | W22: 14569.61 | X22: 16204.101 | Y22: 18685.191 | Z22: 20298.071 | AA22: 20492.528 | AB22: 20559.362 | AC22: 19938.958 | AD22: 19279.825 | AE22: 18735.081 | AF22: 18346.423 | AG22: =+SUM(I22:AF22)*H22 -> 1272642.1
B23: =+MONTH(E23) -> 3 | C23: =+YEAR(E23) -> 2027 | D23: =+_xlfn.CONCAT(E23,G23) -> 46447TOTAL | E23: 46447 | G23: TOTAL | H23: =+SUM(H19:H22) -> 31 | I23: =+SUMPRODUCT(I19:I22,$H19:$H22) -> 594723.83 | J23: =+SUMPRODUCT(J19:J22,$H19:$H22) -> 584404.92 | K23: =+SUMPRODUCT(K19:K22,$H19:$H22) -> 578015.47 | L23: =+SUMPRODUCT(L19:L22,$H19:$H22) -> 575687.08 | M23: =+SUMPRODUCT(M19:M22,$H19:$H22) -> 575098.91 | N23: =+SUMPRODUCT(N19:N22,$H19:$H22) -> 579696.99 | O23: =+SUMPRODUCT(O19:O22,$H19:$H22) -> 593654.18 | P23: =+SUMPRODUCT(P19:P22,$H19:$H22) -> 598245.64 | ... AF23: =+SUMPRODUCT(AF19:AF22,$H19:$H22) -> 604189.68 | AG23: =SUM(I23:AF23) -> 14682660
B24: =+MONTH(E24) -> 4 | C24: =+YEAR(E24) -> 2027 | D24: =+_xlfn.CONCAT(B24:C24,G24) -> 42027OR | E24: 46478 | F24: =+AG28 -> 14589509 | G24: OR | H24: 22 | I24: 19779.417 | J24: 19410.448 | K24: 19171.649 | L24: 19094.894 | M24: 19007.991 | N24: 19233.854 | O24: 19593.148 | P24: 19630.752 | Q24: 19374.739 | R24: 18371.679 | S24: 18392.824 | T24: 18807.659 | U24: 18873.651 | V24: 19074.592 | W24: 20132.551 | X24: 20804.959 | Y24: 22915.684 | Z24: 24783.128 | AA24: 24504.024 | AB24: 24124.41 | AC24: 23174.344 | AD24: 22041.966 | AE24: 21101.432 | AF24: 20569.324 | AG24: =+SUM(I24:AF24)*H24 -> 10823321
B25: =+MONTH(E25) -> 4 | C25: =+YEAR(E25) -> 2027 | D25: =+_xlfn.CONCAT(B25:C25,G25) -> 42027SA | E25: 46478 | G25: SA | H25: 4 | I25: 19734.404 | J25: 19391.376 | K25: 19219.732 | L25: 19130.66 | M25: 19124.799 | N25: 19379.274 | O25: 20096.354 | P25: 20582.261 | Q25: 20542.621 | R25: 19520.246 | S25: 19559.204 | T25: 19924.36 | U25: 19773.402 | V25: 20232.937 | W25: 21048.776 | X25: 21687.603 | Y25: 23620.795 | Z25: 25059.937 | AA25: 24508.764 | AB25: 24091.446 | AC25: 23191.766 | AD25: 21899.278 | AE25: 20790.136 | AF25: 20188.447 | AG25: =+SUM(I25:AF25)*H25 -> 2009194.3
B26: =+MONTH(E26) -> 4 | C26: =+YEAR(E26) -> 2027 | D26: =+_xlfn.CONCAT(B26:C26,G26) -> 42027DO | E26: 46478 | G26: DO | H26: 4 | I26: 19138.496 | J26: 18848.642 | K26: 18645.822 | L26: 18520.317 | M26: 18510.507 | N26: 18339.739 | O26: 17858.214 | P26: 17195.251 | Q26: 17108.957 | R26: 16806.571 | S26: 16453.448 | T26: 16501.347 | U26: 15933.648 | V26: 15506.178 | W26: 16102.461 | X26: 16707.314 | Y26: 18955.241 | Z26: 20913.315 | AA26: 21123.606 | AB26: 21087.822 | AC26: 20537.496 | AD26: 19945.851 | AE26: 19443.028 | AF26: 19065.186 | AG26: =+SUM(I26:AF26)*H26 -> 1756993.8
B27: =+MONTH(E27) -> 4 | C27: =+YEAR(E27) -> 2027 | D27: =+_xlfn.CONCAT(B27:C27,G27) -> 42027FE | E27: 46478 | G27: FE | H27: 0 | I27: 0 | J27: 0 | K27: 0 | L27: 0 | M27: 0 | N27: 0 | O27: 0 | P27: 0 | Q27: 0 | R27: 0 | S27: 0 | T27: 0 | U27: 0 | V27: 0 | W27: 0 | X27: 0 | Y27: 0 | Z27: 0 | AA27: 0 | AB27: 0 | AC27: 0 | AD27: 0 | AE27: 0 | AF27: 0 | AG27: =+SUM(I27:AF27)*H27 -> 0
B28: =+MONTH(E28) -> 4 | C28: =+YEAR(E28) -> 2027 | D28: =+_xlfn.CONCAT(E28,G28) -> 46478TOTAL | E28: 46478 | G28: TOTAL | H28: =+SUM(H24:H27) -> 30 | I28: =+SUMPRODUCT(I24:I27,$H24:$H27) -> 590638.77 | J28: =+SUMPRODUCT(J24:J27,$H24:$H27) -> 579989.92 | K28: =+SUMPRODUCT(K24:K27,$H24:$H27) -> 573238.49 | L28: =+SUMPRODUCT(L24:L27,$H24:$H27) -> 570691.56 | M28: =+SUMPRODUCT(M24:M27,$H24:$H27) -> 568717.04 | N28: =+SUMPRODUCT(N24:N27,$H24:$H27) -> 574020.85 | O28: =+SUMPRODUCT(O24:O27,$H24:$H27) -> 582867.52 | P28: =+SUMPRODUCT(P24:P27,$H24:$H27) -> 582986.6 | ... AF28: =+SUMPRODUCT(AF24:AF27,$H24:$H27) -> 609539.66 | AG28: =SUM(I28:AF28) -> 14589509
B29: =+MONTH(E29) -> 5 | C29: =+YEAR(E29) -> 2027 | D29: =+_xlfn.CONCAT(B29:C29,G29) -> 52027OR | E29: 46508 | F29: =+AG33 -> 15388919 | G29: OR | H29: 19 | I29: 20298.447 | J29: 19951.723 | K29: 19740.089 | L29: 19680.724 | M29: 19668.301 | N29: 19948.334 | O29: 20690.161 | P29: 20837.714 | Q29: 19902.659 | R29: 19610.702 | S29: 20606.829 | T29: 21187.017 | U29: 21065.199 | V29: 21831.057 | W29: 22256.043 | X29: 22921.375 | Y29: 24220.365 | Z29: 25910.286 | AA29: 25322.892 | AB29: 24821.369 | AC29: 23851.968 | AD29: 22575.711 | AE29: 21493.353 | AF29: 20921.066 | AG29: =+SUM(I29:AF29)*H29 -> 9866954.3
B30: =+MONTH(E30) -> 5 | C30: =+YEAR(E30) -> 2027 | D30: =+_xlfn.CONCAT(B30:C30,G30) -> 52027SA | E30: 46508 | G30: SA | H30: 4 | I30: 20288.088 | J30: 19926.579 | K30: 19706.934 | L30: 19616.212 | M30: 19568.118 | N30: 19682.316 | O30: 20075.264 | P30: 19762.101 | Q30: 18540.933 | R30: 18205.515 | S30: 19121.998 | T30: 19571.874 | U30: 19457.262 | V30: 19840.031 | W30: 19752.92 | X30: 20309.79 | Y30: 21789.534 | Z30: 24048 | AA30: 23919.407 | AB30: 23673.064 | AC30: 22906.151 | AD30: 21719.032 | AE30: 20704.096 | AF30: 20143.264 | AG30: =+SUM(I30:AF30)*H30 -> 1969313.9
B31: =+MONTH(E31) -> 5 | C31: =+YEAR(E31) -> 2027 | D31: =+_xlfn.CONCAT(B31:C31,G31) -> 52027DO | E31: 46508 | G31: DO | H31: 5 | I31: 19465.167 | J31: 19179.542 | K31: 18975.624 | L31: 18853.479 | M31: 18841.956 | N31: 18663.31 | O31: 18134.698 | P31: 17053.23 | Q31: 16372.97 | R31: 16216.279 | S31: 16719.925 | T31: 16724.841 | U31: 16230.169 | V31: 16663.87 | W31: 16525.823 | X31: 17133.422 | Y31: 18805.488 | Z31: 21169.442 | AA31: 21413.071 | AB31: 21403.403 | AC31: 20863.408 | AD31: 20283.555 | AE31: 19785.054 | AF31: 19413.592 | AG31: =+SUM(I31:AF31)*H31 -> 2224456.6
B32: =+MONTH(E32) -> 5 | C32: =+YEAR(E32) -> 2027 | D32: =+_xlfn.CONCAT(B32:C32,G32) -> 52027FE | E32: 46508 | G32: FE | H32: 3 | I32: 19649.794 | J32: 19373.189 | K32: 19189.564 | L32: 19079.688 | M32: 19046.597 | N32: 18663.948 | O32: 18056.277 | P32: 16843.062 | Q32: 15814.799 | R32: 15654.801 | S32: 16213.808 | T32: 15909.254 | U32: 16235.655 | V32: 16687.034 | W32: 16525.485 | X32: 17155.699 | Y32: 18724.849 | Z32: 21165.494 | AA32: 21391.676 | AB32: 21455.322 | AC32: 20834.648 | AD32: 20175.623 | AE32: 19633.95 | AF32: 19251.058 | AG32: =+SUM(I32:AF32)*H32 -> 1328193.8
B33: =+MONTH(E33) -> 5 | C33: =+YEAR(E33) -> 2027 | D33: =+_xlfn.CONCAT(E33,G33) -> 46508TOTAL | E33: 46508 | G33: TOTAL | H33: =+SUM(H29:H32) -> 31 | I33: =+SUMPRODUCT(I29:I32,$H29:$H32) -> 623098.06 | J33: =+SUMPRODUCT(J29:J32,$H29:$H32) -> 612806.34 | K33: =+SUMPRODUCT(K29:K32,$H29:$H32) -> 606336.24 | L33: =+SUMPRODUCT(L29:L32,$H29:$H32) -> 603905.05 | M33: =+SUMPRODUCT(M29:M32,$H29:$H32) -> 603319.76 | N33: =+SUMPRODUCT(N29:N32,$H29:$H32) -> 607056 | O33: =+SUMPRODUCT(O29:O32,$H29:$H32) -> 618256.44 | P33: =+SUMPRODUCT(P29:P32,$H29:$H32) -> 610760.3 | ... AF33: =+SUMPRODUCT(AF29:AF32,$H29:$H32) -> 632894.45 | AG33: =SUM(I33:AF33) -> 15388919
B34: =+MONTH(E34) -> 6 | C34: =+YEAR(E34) -> 2027 | D34: =+_xlfn.CONCAT(B34:C34,G34) -> 62027OR | E34: 46539 | F34: =+AG38 -> 17759558 | G34: OR | H34: 21 | I34: 23885.398 | J34: 23538.175 | K34: 23326.196 | L34: 23267.753 | M34: 23252.812 | N34: 23539.181 | O34: 24309.208 | P34: 24919.934 | Q34: 24678.694 | R34: 23456.049 | S34: 23683.168 | T34: 24170.986 | U34: 23621.793 | V34: 24971.161 | W34: 26560.266 | X34: 28127.646 | Y34: 28931.631 | Z34: 29557.236 | AA34: 28901.596 | AB34: 28414.553 | AC34: 27444.662 | AD34: 26166.042 | AE34: 25082.322 | AF34: 24510.126 | AG34: =+SUM(I34:AF34)*H34 -> 12774648
B35: =+MONTH(E35) -> 6 | C35: =+YEAR(E35) -> 2027 | D35: =+_xlfn.CONCAT(B35:C35,G35) -> 62027SA | E35: 46539 | G35: SA | H35: 4 | I35: 23896.453 | J35: 23534.29 | K35: 23313.592 | L35: 23220.597 | M35: 23169.988 | N35: 23288.531 | O35: 23709.649 | P35: 23861.547 | Q35: 23334.411 | R35: 22066.131 | S35: 22216.013 | T35: 22573.558 | U35: 22030.446 | V35: 22993.167 | W35: 24069.529 | X35: 25530.3 | Y35: 26516.466 | Z35: 27712.005 | AA35: 27515.154 | AB35: 27284.412 | AC35: 26515.218 | AD35: 25323.414 | AE35: 24303.145 | AF35: 23741.281 | AG35: =+SUM(I35:AF35)*H35 -> 2326877.2
B36: =+MONTH(E36) -> 6 | C36: =+YEAR(E36) -> 2027 | D36: =+_xlfn.CONCAT(B36:C36,G36) -> 62027DO | E36: 46539 | G36: DO | H36: 4 | I36: 23054.398 | J36: 22766.666 | K36: 22561.902 | L36: 22438.651 | M36: 22428.829 | N36: 22249.988 | O36: 21740.453 | P36: 20872.106 | Q36: 20296.962 | R36: 19739.364 | S36: 19749.277 | T36: 19194.927 | U36: 18712.048 | V36: 19779.19 | W36: 20805.938 | X36: 22321.026 | Y36: 23498.321 | Z36: 24801.387 | AA36: 24978.89 | AB36: 24987.408 | AC36: 24445.917 | AD36: 23864.833 | AE36: 23366.203 | AF36: 22992.994 | AG36: =+SUM(I36:AF36)*H36 -> 2126590.7
B37: =+MONTH(E37) -> 6 | C37: =+YEAR(E37) -> 2027 | D37: =+_xlfn.CONCAT(B37:C37,G37) -> 62027FE | E37: 46539 | G37: FE | H37: 1 | I37: 23279.354 | J37: 22999.831 | K37: 22815.353 | L37: 22703.799 | M37: 22672.619 | N37: 22290.149 | O37: 21703.173 | P37: 20950.876 | Q37: 19829.737 | R37: 19272.071 | S37: 19343.123 | T37: 18864.294 | U37: 18819.273 | V37: 19854.185 | W37: 20856.497 | X37: 22394.12 | Y37: 23468.599 | Z37: 24846.537 | AA37: 25007.264 | AB37: 25086.231 | AC37: 24461.555 | AD37: 23798.565 | AE37: 23255.388 | AF37: 22869.625 | AG37: =+SUM(I37:AF37)*H37 -> 531442.22
B38: =+MONTH(E38) -> 6 | C38: =+YEAR(E38) -> 2027 | D38: =+_xlfn.CONCAT(E38,G38) -> 46539TOTAL | E38: 46539 | G38: TOTAL | H38: =+SUM(H34:H37) -> 30 | I38: =+SUMPRODUCT(I34:I37,$H34:$H37) -> 712676.11 | J38: =+SUMPRODUCT(J34:J37,$H34:$H37) -> 702505.33 | K38: =+SUMPRODUCT(K34:K37,$H34:$H37) -> 696167.44 | L38: =+SUMPRODUCT(L34:L37,$H34:$H37) -> 693963.59 | M38: =+SUMPRODUCT(M34:M37,$H34:$H37) -> 693376.95 | N38: =+SUMPRODUCT(N34:N37,$H34:$H37) -> 698767.02 | O38: =+SUMPRODUCT(O34:O37,$H34:$H37) -> 713996.94 | P38: =+SUMPRODUCT(P34:P37,$H34:$H37) -> 723204.1 | ... AF38: =+SUMPRODUCT(AF34:AF37,$H34:$H37) -> 724519.38 | AG38: =SUM(I38:AF38) -> 17759558
B39: =+MONTH(E39) -> 7 | C39: =+YEAR(E39) -> 2027 | D39: =+_xlfn.CONCAT(B39:C39,G39) -> 72027OR | E39: 46569 | F39: =+AG43 -> 18217389 | G39: OR | H39: 20 | I39: 23921.793 | J39: 23574.917 | K39: 23363.121 | L39: 23303.564 | M39: 23291.282 | N39: 23591.694 | O39: 24345.601 | P39: 24876.574 | Q39: 24587.191 | R39: 23212.848 | S39: 23849.379 | T39: 24161.656 | U39: 23676.881 | V39: 25397.471 | W39: 26373.609 | X39: 27025.964 | Y39: 28568.059 | Z39: 29519.25 | AA39: 28900.813 | AB39: 28448.145 | AC39: 27478.521 | AD39: 26201.204 | AE39: 25117.916 | AF39: 24545.26 | AG39: =+SUM(I39:AF39)*H39 -> 12146654
B40: =+MONTH(E40) -> 7 | C40: =+YEAR(E40) -> 2027 | D40: =+_xlfn.CONCAT(B40:C40,G40) -> 72027SA | E40: 46569 | G40: SA | H40: 5 | I40: 23907.329 | J40: 23545.624 | K40: 23325.809 | L40: 23234.947 | M40: 23186.886 | N40: 23321.029 | O40: 23724.996 | P40: 23794.396 | Q40: 23218.154 | R40: 21799.977 | S40: 22356.56 | T40: 22538.156 | U40: 22060.526 | V40: 23397.76 | W40: 23861.506 | X40: 24405.368 | Y40: 26128.296 | Z40: 27648.536 | AA40: 27489.919 | AB40: 27292.659 | AC40: 26525.792 | AD40: 25337.825 | AE40: 24322.139 | AF40: 23761.109 | AG40: =+SUM(I40:AF40)*H40 -> 2900926.5
B41: =+MONTH(E41) -> 7 | C41: =+YEAR(E41) -> 2027 | D41: =+_xlfn.CONCAT(B41:C41,G41) -> 72027DO | E41: 46569 | G41: DO | H41: 4 | I41: 23022.007 | J41: 22737.539 | K41: 22533.476 | L41: 22412.141 | M41: 22400.764 | N41: 22243.618 | O41: 21724.798 | P41: 20776.214 | Q41: 19704.412 | R41: 19117.428 | S41: 19181.861 | T41: 19088.87 | U41: 18707.184 | V41: 20145.208 | W41: 20559.638 | X41: 21154.36 | Y41: 23070.137 | Z41: 24697.928 | AA41: 24910.255 | AB41: 24953.66 | AC41: 24418.205 | AD41: 23842.316 | AE41: 23345.77 | AF41: 22975.901 | AG41: =+SUM(I41:AF41)*H41 -> 2110894.8
B42: =+MONTH(E42) -> 7 | C42: =+YEAR(E42) -> 2027 | D42: =+_xlfn.CONCAT(B42:C42,G42) -> 72027FE | E42: 46569 | G42: FE | H42: 2 | I42: 23294.194 | J42: 23017.099 | K42: 22833.377 | L42: 22723.059 | M42: 22690.994 | N42: 22332.614 | O42: 21739.746 | P42: 20910.788 | Q42: 19697.105 | R42: 18779.947 | S42: 18912.39 | T42: 18862.922 | U42: 18879.465 | V42: 20285.684 | W42: 20674.526 | X42: 21291.364 | Y42: 23104.937 | Z42: 24804.844 | AA42: 25000.939 | AB42: 25111.244 | AC42: 24490.274 | AD42: 23829.266 | AE42: 23286.801 | AF42: 22903.119 | AG42: =+SUM(I42:AF42)*H42 -> 1058913.4
B43: =+MONTH(E43) -> 7 | C43: =+YEAR(E43) -> 2027 | D43: =+_xlfn.CONCAT(E43,G43) -> 46569TOTAL | E43: 46569 | G43: TOTAL | H43: =+SUM(H39:H42) -> 31 | I43: =+SUMPRODUCT(I39:I42,$H39:$H42) -> 736648.93 | J43: =+SUMPRODUCT(J39:J42,$H39:$H42) -> 726210.82 | K43: =+SUMPRODUCT(K39:K42,$H39:$H42) -> 719692.12 | L43: =+SUMPRODUCT(L39:L42,$H39:$H42) -> 717340.7 | M43: =+SUMPRODUCT(M39:M42,$H39:$H42) -> 716745.12 | N43: =+SUMPRODUCT(N39:N42,$H39:$H42) -> 722078.72 | O43: =+SUMPRODUCT(O39:O42,$H39:$H42) -> 735915.68 | P43: =+SUMPRODUCT(P39:P42,$H39:$H42) -> 741429.9 | ... AF43: =+SUMPRODUCT(AF39:AF42,$H39:$H42) -> 747420.58 | AG43: =SUM(I43:AF43) -> 18217389
...

Sheet PRODUCTO 2
C1: CP-GNCC2026-002
C2: CP-GNCC2026-002-PROD02
C3: CANTIDAD EN: | D3: KWh
C4: MODALIDAD: | D4: PAGUE LO CONTRATADO
C5: OFERENTE:
C9: MES DE SUMINISTRO | D9: ENERGÍA SOLICITADA (KWh) | E9: % ENERGÍA OFRECIDA | F9: ENERGÍA OFRECIDA (KWh) | G9: PRECIO OFERTADO ($/KWh)
C10: 46388 | D10: =+_xlfn.XLOOKUP(_xlfn.CONCAT(C10,"TOTAL"),'Cantidades horarias PROD 02'!D:D,'Cantidades horarias PROD 02'!AG:AG) -> 3065513.9 | E10: 1 | F10: =ROUND(D10*$E10,2) -> 3065513.9
C11: 46419 | D11: =+_xlfn.XLOOKUP(_xlfn.CONCAT(C11,"TOTAL"),'Cantidades horarias PROD 02'!D:D,'Cantidades horarias PROD 02'!AG:AG) -> 2787686.4 | E11: 1 | F11: =ROUND(D11*$E11,2) -> 2787686.4
C12: 46447 | D12: =+_xlfn.XLOOKUP(_xlfn.CONCAT(C12,"TOTAL"),'Cantidades horarias PROD 02'!D:D,'Cantidades horarias PROD 02'!AG:AG) -> 3260243.7 | E12: 1 | F12: =ROUND(D12*$E12,2) -> 3260243.7
C13: 46478 | D13: =+_xlfn.XLOOKUP(_xlfn.CONCAT(C13,"TOTAL"),'Cantidades horarias PROD 02'!D:D,'Cantidades horarias PROD 02'!AG:AG) -> 4045630.7 | E13: 1 | F13: =ROUND(D13*$E13,2) -> 4045630.7
C14: 46508 | D14: =+_xlfn.XLOOKUP(_xlfn.CONCAT(C14,"TOTAL"),'Cantidades horarias PROD 02'!D:D,'Cantidades horarias PROD 02'!AG:AG) -> 4895874 | E14: 1 | F14: =ROUND(D14*$E14,2) -> 4895874
C15: 46539 | D15: =+_xlfn.XLOOKUP(_xlfn.CONCAT(C15,"TOTAL"),'Cantidades horarias PROD 02'!D:D,'Cantidades horarias PROD 02'!AG:AG) -> 5151912.8 | E15: 1 | F15: =ROUND(D15*$E15,2) -> 5151912.8
C16: 46569 | D16: =+_xlfn.XLOOKUP(_xlfn.CONCAT(C16,"TOTAL"),'Cantidades horarias PROD 02'!D:D,'Cantidades horarias PROD 02'!AG:AG) -> 5223724.7 | E16: 1 | F16: =ROUND(D16*$E16,2) -> 5223724.7
C17: 46600 | D17: =+_xlfn.XLOOKUP(_xlfn.CONCAT(C17,"TOTAL"),'Cantidades horarias PROD 02'!D:D,'Cantidades horarias PROD 02'!AG:AG) -> 4262962.6 | E17: 1 | F17: =ROUND(D17*$E17,2) -> 4262962.5
C18: 46631 | D18: =+_xlfn.XLOOKUP(_xlfn.CONCAT(C18,"TOTAL"),'Cantidades horarias PROD 02'!D:D,'Cantidades horarias PROD 02'!AG:AG) -> 4192126.6 | E18: 1 | F18: =ROUND(D18*$E18,2) -> 4192126.6
C19: 46661 | D19: =+_xlfn.XLOOKUP(_xlfn.CONCAT(C19,"TOTAL"),'Cantidades horarias PROD 02'!D:D,'Cantidades horarias PROD 02'!AG:AG) -> 4154381 | E19: 1 | F19: =ROUND(D19*$E19,2) -> 4154381
C20: 46692 | D20: =+_xlfn.XLOOKUP(_xlfn.CONCAT(C20,"TOTAL"),'Cantidades horarias PROD 02'!D:D,'Cantidades horarias PROD 02'!AG:AG) -> 4343197.7 | E20: 1 | F20: =ROUND(D20*$E20,2) -> 4343197.7
C21: 46722 | D21: =+_xlfn.XLOOKUP(_xlfn.CONCAT(C21,"TOTAL"),'Cantidades horarias PROD 02'!D:D,'Cantidades horarias PROD 02'!AG:AG) -> 4433241.9 | E21: 1 | F21: =ROUND(D21*$E21,2) -> 4433241.9
... C57: 47818 | D57: =+_xlfn.XLOOKUP(_xlfn.CONCAT(C57,"TOTAL"),'Cantidades horarias PROD 02'!D:D,'Cantidades horarias PROD 02'!AG:AG) -> 4585005.4 | E57: 1 | F57: =ROUND(D57*$E57,2) -> 4585005.4
C58: TOTAL | D58: =SUM(D10:D57) -> 2.0970857e+08 | E58: =IFERROR(F58/D58,0) -> 1 | F58: =SUM(F10:F57) -> 2.0970857e+08 | G58: =+(+SUM(F10:F21)*G10+SUM(F22:F33)*G22+SUM(F34:F45)*G34+SUM(F46:F57)*G46)/F58 -> 0
C60: Nota
C61: 1. $/kWh expresados en pesos de abril de 2026. (IPP)
C62: 2. La energia ofertada se despachara conforme a las cantidades horarias de este anexo
C66: XXXXXXXXXXXXXXXXXXXXXXXX
C67: REPRESENTANTE LEGAL
C68: XXXXXXXXXXXXXXXXXX.SA.E.S.P
C74: XXXXXXXXXXXXXXXXXXXXXX S.A E.S.P
C76: Nota
C77: 1. $/kWh expresados en pesos de octubre 2025.
C78: 2. La energia ofertada se despachara conforme a las cantidades horarias de este anexo
C82: XXXXXXXXXXXXXXXXXXXXXXXX
C83: REPRESENTANTE LEGAL
C84: XXXXXXXXXXXXXXXXXXXXXX S.A E.S.P

Sheet Cantidades horarias PROD 02
E1: CUADRO DE CANTIDADES HORARIAS OFRECIDAS
E2: CANTIDADES DE ENERGIA (KWh) - PRODUCTO 1
E3: PAGUE LO CONTRATADO
E5: OFERENTE:
B8: MES | C8: AÑO | D8: LLAVE | F8: Cantidad Ofrecida | G8: Tipo de día | H8: N° días mes | I8: H1 | J8: H2 | K8: H3 | L8: H4 | M8: H5 | N8: H6 | O8: H7 | P8: H8 | Q8: H9 | R8: H10 | S8: H11 | T8: H12 | U8: H13 | V8: H14 | W8: H15 | X8: H16 | Y8: H17 | Z8: H18 | AA8: H19 | AB8: H20 | AC8: H21 | AD8: H22 | AE8: H23 | AF8: H24 | AG8: TOTAL
B9: =+MONTH(E9) -> 1 | C9: =+YEAR(E9) -> 2027 | D9: =+_xlfn.CONCAT(B9:C9,G9) -> 12027OR | E9: 46388 | F9: =+AG13 -> 3065513.9 | G9: OR | H9: 19 | I9: 4120.3144 | J9: 4120.3144 | K9: 4120.3144 | L9: 4120.3144 | M9: 4120.3144 | N9: 4120.3144 | O9: 4120.3144 | P9: 4120.3144 | Q9: 4120.3144 | R9: 4120.3144 | S9: 4120.3144 | T9: 4120.3144 | U9: 4120.3144 | V9: 4120.3144 | W9: 4120.3144 | X9: 4120.3144 | Y9: 4120.3144 | Z9: 4120.3144 | AA9: 4120.3144 | AB9: 4120.3144 | AC9: 4120.3144 | AD9: 4120.3144 | AE9: 4120.3144 | AF9: 4120.3144 | AG9: =ROUND(SUM(I9:AF9)*H9,2) -> 1878863.4
B10: =+MONTH(E10) -> 1 | C10: =+YEAR(E10) -> 2027 | D10: =+_xlfn.CONCAT(B10:C10,G10) -> 12027SA | E10: 46388 | G10: SA | H10: 5 | I10: 4120.3144 | J10: 4120.3144 | K10: 4120.3144 | L10: 4120.3144 | M10: 4120.3144 | N10: 4120.3144 | O10: 4120.3144 | P10: 4120.3144 | Q10: 4120.3144 | R10: 4120.3144 | S10: 4120.3144 | T10: 4120.3144 | U10: 4120.3144 | V10: 4120.3144 | W10: 4120.3144 | X10: 4120.3144 | Y10: 4120.3144 | Z10: 4120.3144 | AA10: 4120.3144 | AB10: 4120.3144 | AC10: 4120.3144 | AD10: 4120.3144 | AE10: 4120.3144 | AF10: 4120.3144 | AG10: =ROUND(SUM(I10:AF10)*H10,2) -> 494437.72
B11: =+MONTH(E11) -> 1 | C11: =+YEAR(E11) -> 2027 | D11: =+_xlfn.CONCAT(B11:C11,G11) -> 12027DO | E11: 46388 | G11: DO | H11: 5 | I11: 4120.3144 | J11: 4120.3144 | K11: 4120.3144 | L11: 4120.3144 | M11: 4120.3144 | N11: 4120.3144 | O11: 4120.3144 | P11: 4120.3144 | Q11: 4120.3144 | R11: 4120.3144 | S11: 4120.3144 | T11: 4120.3144 | U11: 4120.3144 | V11: 4120.3144 | W11: 4120.3144 | X11: 4120.3144 | Y11: 4120.3144 | Z11: 4120.3144 | AA11: 4120.3144 | AB11: 4120.3144 | AC11: 4120.3144 | AD11: 4120.3144 | AE11: 4120.3144 | AF11: 4120.3144 | AG11: =ROUND(SUM(I11:AF11)*H11,2) -> 494437.72
B12: =+MONTH(E12) -> 1 | C12: =+YEAR(E12) -> 2027 | D12: =+_xlfn.CONCAT(B12:C12,G12) -> 12027FE | E12: 46388 | G12: FE | H12: 2 | I12: 4120.3144 | J12: 4120.3144 | K12: 4120.3144 | L12: 4120.3144 | M12: 4120.3144 | N12: 4120.3144 | O12: 4120.3144 | P12: 4120.3144 | Q12: 4120.3144 | R12: 4120.3144 | S12: 4120.3144 | T12: 4120.3144 | U12: 4120.3144 | V12: 4120.3144 | W12: 4120.3144 | X12: 4120.3144 | Y12: 4120.3144 | Z12: 4120.3144 | AA12: 4120.3144 | AB12: 4120.3144 | AC12: 4120.3144 | AD12: 4120.3144 | AE12: 4120.3144 | AF12: 4120.3144 | AG12: =ROUND(SUM(I12:AF12)*H12,2) -> 197775.09
B13: =+MONTH(E13) -> 1 | C13: =+YEAR(E13) -> 2027 | D13: =+_xlfn.CONCAT(E13,G13) -> 46388TOTAL | E13: 46388 | G13: TOTAL | H13: =+SUM(H9:H12) -> 31 | I13: =+SUMPRODUCT(I9:I12,$H9:$H12) -> 127729.75 | J13: =+SUMPRODUCT(J9:J12,$H9:$H12) -> 127729.75 | K13: =+SUMPRODUCT(K9:K12,$H9:$H12) -> 127729.75 | L13: =+SUMPRODUCT(L9:L12,$H9:$H12) -> 127729.75 | M13: =+SUMPRODUCT(M9:M12,$H9:$H12) -> 127729.75 | N13: =+SUMPRODUCT(N9:N12,$H9:$H12) -> 127729.75 | O13: =+SUMPRODUCT(O9:O12,$H9:$H12) -> 127729.75 | P13: =+SUMPRODUCT(P9:P12,$H9:$H12) -> 127729.75 | ... AF13: =+SUMPRODUCT(AF9:AF12,$H9:$H12) -> 127729.75 | AG13: =SUM(I13:AF13) -> 3065513.9
B14: =+MONTH(E14) -> 2 | C14: =+YEAR(E14) -> 2027 | D14: =+_xlfn.CONCAT(B14:C14,G14) -> 22027OR | E14: 46419 | F14: =+AG18 -> 2787686.4 | G14: OR | H14: 20 | I14: 4148.3428 | J14: 4148.3428 | K14: 4148.3428 | L14: 4148.3428 | M14: 4148.3428 | N14: 4148.3428 | O14: 4148.3428 | P14: 4148.3428 | Q14: 4148.3428 | R14: 4148.3428 | S14: 4148.3428 | T14: 4148.3428 | U14: 4148.3428 | V14: 4148.3428 | W14: 4148.3428 | X14: 4148.3428 | Y14: 4148.3428 | Z14: 4148.3428 | AA14: 4148.3428 | AB14: 4148.3428 | AC14: 4148.3428 | AD14: 4148.3428 | AE14: 4148.3428 | AF14: 4148.3428 | AG14: =+SUM(I14:AF14)*H14 -> 1991204.5
B15: =+MONTH(E15) -> 2 | C15: =+YEAR(E15) -> 2027 | D15: =+_xlfn.CONCAT(B15:C15,G15) -> 22027SA | E15: 46419 | G15: SA | H15: 4 | I15: 4148.3428 | J15: 4148.3428 | K15: 4148.3428 | L15: 4148.3428 | M15: 4148.3428 | N15: 4148.3428 | O15: 4148.3428 | P15: 4148.3428 | Q15: 4148.3428 | R15: 4148.3428 | S15: 4148.3428 | T15: 4148.3428 | U15: 4148.3428 | V15: 4148.3428 | W15: 4148.3428 | X15: 4148.3428 | Y15: 4148.3428 | Z15: 4148.3428 | AA15: 4148.3428 | AB15: 4148.3428 | AC15: 4148.3428 | AD15: 4148.3428 | AE15: 4148.3428 | AF15: 4148.3428 | AG15: =+SUM(I15:AF15)*H15 -> 398240.91
B16: =+MONTH(E16) -> 2 | C16: =+YEAR(E16) -> 2027 | D16: =+_xlfn.CONCAT(B16:C16,G16) -> 22027DO | E16: 46419 | G16: DO | H16: 4 | I16: 4148.3428 | J16: 4148.3428 | K16: 4148.3428 | L16: 4148.3428 | M16: 4148.3428 | N16: 4148.3428 | O16: 4148.3428 | P16: 4148.3428 | Q16: 4148.3428 | R16: 4148.3428 | S16: 4148.3428 | T16: 4148.3428 | U16: 4148.3428 | V16: 4148.3428 | W16: 4148.3428 | X16: 4148.3428 | Y16: 4148.3428 | Z16: 4148.3428 | AA16: 4148.3428 | AB16: 4148.3428 | AC16: 4148.3428 | AD16: 4148.3428 | AE16: 4148.3428 | AF16: 4148.3428 | AG16: =+SUM(I16:AF16)*H16 -> 398240.91
B17: =+MONTH(E17) -> 2 | C17: =+YEAR(E17) -> 2027 | D17: =+_xlfn.CONCAT(B17:C17,G17) -> 22027FE | E17: 46419 | G17: FE | H17: 0 | I17: 0 | J17: 0 | K17: 0 | L17: 0 | M17: 0 | N17: 0 | O17: 0 | P17: 0 | Q17: 0 | R17: 0 | S17: 0 | T17: 0 | U17: 0 | V17: 0 | W17: 0 | X17: 0 | Y17: 0 | Z17: 0 | AA17: 0 | AB17: 0 | AC17: 0 | AD17: 0 | AE17: 0 | AF17: 0 | AG17: =+SUM(I17:AF17)*H17 -> 0
B18: =+MONTH(E18) -> 2 | C18: =+YEAR(E18) -> 2027 | D18: =+_xlfn.CONCAT(E18,G18) -> 46419TOTAL | E18: 46419 | G18: TOTAL | H18: =+SUM(H14:H17) -> 28 | I18: =+SUMPRODUCT(I14:I17,$H14:$H17) -> 116153.6 | J18: =+SUMPRODUCT(J14:J17,$H14:$H17) -> 116153.6 | K18: =+SUMPRODUCT(K14:K17,$H14:$H17) -> 116153.6 | L18: =+SUMPRODUCT(L14:L17,$H14:$H17) -> 116153.6 | M18: =+SUMPRODUCT(M14:M17,$H14:$H17) -> 116153.6 | N18: =+SUMPRODUCT(N14:N17,$H14:$H17) -> 116153.6 | O18: =+SUMPRODUCT(O14:O17,$H14:$H17) -> 116153.6 | P18: =+SUMPRODUCT(P14:P17,$H14:$H17) -> 116153.6 | ... AF18: =+SUMPRODUCT(AF14:AF17,$H14:$H17) -> 116153.6 | AG18: =SUM(I18:AF18) -> 2787686.4
B19: =+MONTH(E19) -> 3 | C19: =+YEAR(E19) -> 2027 | D19: =+_xlfn.CONCAT(B19:C19,G19) -> 32027OR | E19: 46447 | F19: =+AG23 -> 3260243.7 | G19: OR | H19: 20 | I19: 4382.048 | J19: 4382.048 | K19: 4382.048 | L19: 4382.048 | M19: 4382.048 | N19: 4382.048 | O19: 4382.048 | P19: 4382.048 | Q19: 4382.048 | R19: 4382.048 | S19: 4382.048 | T19: 4382.048 | U19: 4382.048 | V19: 4382.048 | W19: 4382.048 | X19: 4382.048 | Y19: 4382.048 | Z19: 4382.048 | AA19: 4382.048 | AB19: 4382.048 | AC19: 4382.048 | AD19: 4382.048 | AE19: 4382.048 | AF19: 4382.048 | AG19: =+SUM(I19:AF19)*H19 -> 2103383
B20: =+MONTH(E20) -> 3 | C20: =+YEAR(E20) -> 2027 | D20: =+_xlfn.CONCAT(B20:C20,G20) -> 32027SA | E20: 46447 | G20: SA | H20: 4 | I20: 4382.048 | J20: 4382.048 | K20: 4382.048 | L20: 4382.048 | M20: 4382.048 | N20: 4382.048 | O20: 4382.048 | P20: 4382.048 | Q20: 4382.048 | R20: 4382.048 | S20: 4382.048 | T20: 4382.048 | U20: 4382.048 | V20: 4382.048 | W20: 4382.048 | X20: 4382.048 | Y20: 4382.048 | Z20: 4382.048 | AA20: 4382.048 | AB20: 4382.048 | AC20: 4382.048 | AD20: 4382.048 | AE20: 4382.048 | AF20: 4382.048 | AG20: =+SUM(I20:AF20)*H20 -> 420676.61
B21: =+MONTH(E21) -> 3 | C21: =+YEAR(E21) -> 2027 | D21: =+_xlfn.CONCAT(B21:C21,G21) -> 32027DO | E21: 46447 | G21: DO | H21: 4 | I21: 4382.048 | J21: 4382.048 | K21: 4382.048 | L21: 4382.048 | M21: 4382.048 | N21: 4382.048 | O21: 4382.048 | P21: 4382.048 | Q21: 4382.048 | R21: 4382.048 | S21: 4382.048 | T21: 4382.048 | U21: 4382.048 | V21: 4382.048 | W21: 4382.048 | X21: 4382.048 | Y21: 4382.048 | Z21: 4382.048 | AA21: 4382.048 | AB21: 4382.048 | AC21: 4382.048 | AD21: 4382.048 | AE21: 4382.048 | AF21: 4382.048 | AG21: =+SUM(I21:AF21)*H21 -> 420676.61
B22: =+MONTH(E22) -> 3 | C22: =+YEAR(E22) -> 2027 | D22: =+_xlfn.CONCAT(B22:C22,G22) -> 32027FE | E22: 46447 | G22: FE | H22: 3 | I22: 4382.048 | J22: 4382.048 | K22: 4382.048 | L22: 4382.048 | M22: 4382.048 | N22: 4382.048 | O22: 4382.048 | P22: 4382.048 | Q22: 4382.048 | R22: 4382.048 | S22: 4382.048 | T22: 4382.048 | U22: 4382.048 | V22: 4382.048 | W22: 4382.048 | X22: 4382.048 | Y22: 4382.048 | Z22: 4382.048 | AA22: 4382.048 | AB22: 4382.048 | AC22: 4382.048 | AD22: 4382.048 | AE22: 4382.048 | AF22: 4382.048 | AG22: =+SUM(I22:AF22)*H22 -> 315507.46
B23: =+MONTH(E23) -> 3 | C23: =+YEAR(E23) -> 2027 | D23: =+_xlfn.CONCAT(E23,G23) -> 46447TOTAL | E23: 46447 | G23: TOTAL | H23: =+SUM(H19:H22) -> 31 | I23: =+SUMPRODUCT(I19:I22,$H19:$H22) -> 135843.49 | J23: =+SUMPRODUCT(J19:J22,$H19:$H22) -> 135843.49 | K23: =+SUMPRODUCT(K19:K22,$H19:$H22) -> 135843.49 | L23: =+SUMPRODUCT(L19:L22,$H19:$H22) -> 135843.49 | M23: =+SUMPRODUCT(M19:M22,$H19:$H22) -> 135843.49 | N23: =+SUMPRODUCT(N19:N22,$H19:$H22) -> 135843.49 | O23: =+SUMPRODUCT(O19:O22,$H19:$H22) -> 135843.49 | P23: =+SUMPRODUCT(P19:P22,$H19:$H22) -> 135843.49 | ... AF23: =+SUMPRODUCT(AF19:AF22,$H19:$H22) -> 135843.49 | AG23: =SUM(I23:AF23) -> 3260243.7
B24: =+MONTH(E24) -> 4 | C24: =+YEAR(E24) -> 2027 | D24: =+_xlfn.CONCAT(B24:C24,G24) -> 42027OR | E24: 46478 | F24: =+AG28 -> 4045630.7 | G24: OR | H24: 22 | I24: 5618.9316 | J24: 5618.9316 | K24: 5618.9316 | L24: 5618.9316 | M24: 5618.9316 | N24: 5618.9316 | O24: 5618.9316 | P24: 5618.9316 | Q24: 5618.9316 | R24: 5618.9316 | S24: 5618.9316 | T24: 5618.9316 | U24: 5618.9316 | V24: 5618.9316 | W24: 5618.9316 | X24: 5618.9316 | Y24: 5618.9316 | Z24: 5618.9316 | AA24: 5618.9316 | AB24: 5618.9316 | AC24: 5618.9316 | AD24: 5618.9316 | AE24: 5618.9316 | AF24: 5618.9316 | AG24: =+SUM(I24:AF24)*H24 -> 2966795.9
B25: =+MONTH(E25) -> 4 | C25: =+YEAR(E25) -> 2027 | D25: =+_xlfn.CONCAT(B25:C25,G25) -> 42027SA | E25: 46478 | G25: SA | H25: 4 | I25: 5618.9316 | J25: 5618.9316 | K25: 5618.9316 | L25: 5618.9316 | M25: 5618.9316 | N25: 5618.9316 | O25: 5618.9316 | P25: 5618.9316 | Q25: 5618.9316 | R25: 5618.9316 | S25: 5618.9316 | T25: 5618.9316 | U25: 5618.9316 | V25: 5618.9316 | W25: 5618.9316 | X25: 5618.9316 | Y25: 5618.9316 | Z25: 5618.9316 | AA25: 5618.9316 | AB25: 5618.9316 | AC25: 5618.9316 | AD25: 5618.9316 | AE25: 5618.9316 | AF25: 5618.9316 | AG25: =+SUM(I25:AF25)*H25 -> 539417.43
B26: =+MONTH(E26) -> 4 | C26: =+YEAR(E26) -> 2027 | D26: =+_xlfn.CONCAT(B26:C26,G26) -> 42027DO | E26: 46478 | G26: DO | H26: 4 | I26: 5618.9316 | J26: 5618.9316 | K26: 5618.9316 | L26: 5618.9316 | M26: 5618.9316 | N26: 5618.9316 | O26: 5618.9316 | P26: 5618.9316 | Q26: 5618.9316 | R26: 5618.9316 | S26: 5618.9316 | T26: 5618.9316 | U26: 5618.9316 | V26: 5618.9316 | W26: 5618.9316 | X26: 5618.9316 | Y26: 5618.9316 | Z26: 5618.9316 | AA26: 5618.9316 | AB26: 5618.9316 | AC26: 5618.9316 | AD26: 5618.9316 | AE26: 5618.9316 | AF26: 5618.9316 | AG26: =+SUM(I26:AF26)*H26 -> 539417.43
B27: =+MONTH(E27) -> 4 | C27: =+YEAR(E27) -> 2027 | D27: =+_xlfn.CONCAT(B27:C27,G27) -> 42027FE | E27: 46478 | G27: FE | H27: 0 | I27: 0 | J27: 0 | K27: 0 | L27: 0 | M27: 0 | N27: 0 | O27: 0 | P27: 0 | Q27: 0 | R27: 0 | S27: 0 | T27: 0 | U27: 0 | V27: 0 | W27: 0 | X27: 0 | Y27: 0 | Z27: 0 | AA27: 0 | AB27: 0 | AC27: 0 | AD27: 0 | AE27: 0 | AF27: 0 | AG27: =+SUM(I27:AF27)*H27 -> 0
B28: =+MONTH(E28) -> 4 | C28: =+YEAR(E28) -> 2027 | D28: =+_xlfn.CONCAT(E28,G28) -> 46478TOTAL | E28: 46478 | G28: TOTAL | H28: =+SUM(H24:H27) -> 30 | I28: =+SUMPRODUCT(I24:I27,$H24:$H27) -> 168567.95 | J28: =+SUMPRODUCT(J24:J27,$H24:$H27) -> 168567.95 | K28: =+SUMPRODUCT(K24:K27,$H24:$H27) -> 168567.95 | L28: =+SUMPRODUCT(L24:L27,$H24:$H27) -> 168567.95 | M28: =+SUMPRODUCT(M24:M27,$H24:$H27) -> 168567.95 | N28: =+SUMPRODUCT(N24:N27,$H24:$H27) -> 168567.95 | O28: =+SUMPRODUCT(O24:O27,$H24:$H27) -> 168567.95 | P28: =+SUMPRODUCT(P24:P27,$H24:$H27) -> 168567.95 | ... AF28: =+SUMPRODUCT(AF24:AF27,$H24:$H27) -> 168567.95 | AG28: =SUM(I28:AF28) -> 4045630.7
B29: =+MONTH(E29) -> 5 | C29: =+YEAR(E29) -> 2027 | D29: =+_xlfn.CONCAT(B29:C29,G29) -> 52027OR | E29: 46508 | F29: =+AG33 -> 4895874 | G29: OR | H29: 19 | I29: 6580.4759 | J29: 6580.4759 | K29: 6580.4759 | L29: 6580.4759 | M29: 6580.4759 | N29: 6580.4759 | O29: 6580.4759 | P29: 6580.4759 | Q29: 6580.4759 | R29: 6580.4759 | S29: 6580.4759 | T29: 6580.4759 | U29: 6580.4759 | V29: 6580.4759 | W29: 6580.4759 | X29: 6580.4759 | Y29: 6580.4759 | Z29: 6580.4759 | AA29: 6580.4759 | AB29: 6580.4759 | AC29: 6580.4759 | AD29: 6580.4759 | AE29: 6580.4759 | AF29: 6580.4759 | AG29: =+SUM(I29:AF29)*H29 -> 3000697
B30: =+MONTH(E30) -> 5 | C30: =+YEAR(E30) -> 2027 | D30: =+_xlfn.CONCAT(B30:C30,G30) -> 52027SA | E30: 46508 | G30: SA | H30: 4 | I30: 6580.4759 | J30: 6580.4759 | K30: 6580.4759 | L30: 6580.4759 | M30: 6580.4759 | N30: 6580.4759 | O30: 6580.4759 | P30: 6580.4759 | Q30: 6580.4759 | R30: 6580.4759 | S30: 6580.4759 | T30: 6580.4759 | U30: 6580.4759 | V30: 6580.4759 | W30: 6580.4759 | X30: 6580.4759 | Y30: 6580.4759 | Z30: 6580.4759 | AA30: 6580.4759 | AB30: 6580.4759 | AC30: 6580.4759 | AD30: 6580.4759 | AE30: 6580.4759 | AF30: 6580.4759 | AG30: =+SUM(I30:AF30)*H30 -> 631725.68
B31: =+MONTH(E31) -> 5 | C31: =+YEAR(E31) -> 2027 | D31: =+_xlfn.CONCAT(B31:C31,G31) -> 52027DO | E31: 46508 | G31: DO | H31: 5 | I31: 6580.4759 | J31: 6580.4759 | K31: 6580.4759 | L31: 6580.4759 | M31: 6580.4759 | N31: 6580.4759 | O31: 6580.4759 | P31: 6580.4759 | Q31: 6580.4759 | R31: 6580.4759 | S31: 6580.4759 | T31: 6580.4759 | U31: 6580.4759 | V31: 6580.4759 | W31: 6580.4759 | X31: 6580.4759 | Y31: 6580.4759 | Z31: 6580.4759 | AA31: 6580.4759 | AB31: 6580.4759 | AC31: 6580.4759 | AD31: 6580.4759 | AE31: 6580.4759 | AF31: 6580.4759 | AG31: =+SUM(I31:AF31)*H31 -> 789657.1
B32: =+MONTH(E32) -> 5 | C32: =+YEAR(E32) -> 2027 | D32: =+_xlfn.CONCAT(B32:C32,G32) -> 52027FE | E32: 46508 | G32: FE | H32: 3 | I32: 6580.4759 | J32: 6580.4759 | K32: 6580.4759 | L32: 6580.4759 | M32: 6580.4759 | N32: 6580.4759 | O32: 6580.4759 | P32: 6580.4759 | Q32: 6580.4759 | R32: 6580.4759 | S32: 6580.4759 | T32: 6580.4759 | U32: 6580.4759 | V32: 6580.4759 | W32: 6580.4759 | X32: 6580.4759 | Y32: 6580.4759 | Z32: 6580.4759 | AA32: 6580.4759 | AB32: 6580.4759 | AC32: 6580.4759 | AD32: 6580.4759 | AE32: 6580.4759 | AF32: 6580.4759 | AG32: =+SUM(I32:AF32)*H32 -> 473794.26
B33: =+MONTH(E33) -> 5 | C33: =+YEAR(E33) -> 2027 | D33: =+_xlfn.CONCAT(E33,G33) -> 46508TOTAL | E33: 46508 | G33: TOTAL | H33: =+SUM(H29:H32) -> 31 | I33: =+SUMPRODUCT(I29:I32,$H29:$H32) -> 203994.75 | J33: =+SUMPRODUCT(J29:J32,$H29:$H32) -> 203994.75 | K33: =+SUMPRODUCT(K29:K32,$H29:$H32) -> 203994.75 | L33: =+SUMPRODUCT(L29:L32,$H29:$H32) -> 203994.75 | M33: =+SUMPRODUCT(M29:M32,$H29:$H32) -> 203994.75 | N33: =+SUMPRODUCT(N29:N32,$H29:$H32) -> 203994.75 | O33: =+SUMPRODUCT(O29:O32,$H29:$H32) -> 203994.75 | P33: =+SUMPRODUCT(P29:P32,$H29:$H32) -> 203994.75 | ... AF33: =+SUMPRODUCT(AF29:AF32,$H29:$H32) -> 203994.75 | AG33: =SUM(I33:AF33) -> 4895874
B34: =+MONTH(E34) -> 6 | C34: =+YEAR(E34) -> 2027 | D34: =+_xlfn.CONCAT(B34:C34,G34) -> 62027OR | E34: 46539 | F34: =+AG38 -> 5151912.8 | G34: OR | H34: 21 | I34: 7155.4344 | J34: 7155.4344 | K34: 7155.4344 | L34: 7155.4344 | M34: 7155.4344 | N34: 7155.4344 | O34: 7155.4344 | P34: 7155.4344 | Q34: 7155.4344 | R34: 7155.4344 | S34: 7155.4344 | T34: 7155.4344 | U34: 7155.4344 | V34: 7155.4344 | W34: 7155.4344 | X34: 7155.4344 | Y34: 7155.4344 | Z34: 7155.4344 | AA34: 7155.4344 | AB34: 7155.4344 | AC34: 7155.4344 | AD34: 7155.4344 | AE34: 7155.4344 | AF34: 7155.4344 | AG34: =+SUM(I34:AF34)*H34 -> 3606338.9
B35: =+MONTH(E35) -> 6 | C35: =+YEAR(E35) -> 2027 | D35: =+_xlfn.CONCAT(B35:C35,G35) -> 62027SA | E35: 46539 | G35: SA | H35: 4 | I35: 7155.4344 | J35: 7155.4344 | K35: 7155.4344 | L35: 7155.4344 | M35: 7155.4344 | N35: 7155.4344 | O35: 7155.4344 | P35: 7155.4344 | Q35: 7155.4344 | R35: 7155.4344 | S35: 7155.4344 | T35: 7155.4344 | U35: 7155.4344 | V35: 7155.4344 | W35: 7155.4344 | X35: 7155.4344 | Y35: 7155.4344 | Z35: 7155.4344 | AA35: 7155.4344 | AB35: 7155.4344 | AC35: 7155.4344 | AD35: 7155.4344 | AE35: 7155.4344 | AF35: 7155.4344 | AG35: =+SUM(I35:AF35)*H35 -> 686921.7
B36: =+MONTH(E36) -> 6 | C36: =+YEAR(E36) -> 2027 | D36: =+_xlfn.CONCAT(B36:C36,G36) -> 62027DO | E36: 46539 | G36: DO | H36: 4 | I36: 7155.4344 | J36: 7155.4344 | K36: 7155.4344 | L36: 7155.4344 | M36: 7155.4344 | N36: 7155.4344 | O36: 7155.4344 | P36: 7155.4344 | Q36: 7155.4344 | R36: 7155.4344 | S36: 7155.4344 | T36: 7155.4344 | U36: 7155.4344 | V36: 7155.4344 | W36: 7155.4344 | X36: 7155.4344 | Y36: 7155.4344 | Z36: 7155.4344 | AA36: 7155.4344 | AB36: 7155.4344 | AC36: 7155.4344 | AD36: 7155.4344 | AE36: 7155.4344 | AF36: 7155.4344 | AG36: =+SUM(I36:AF36)*H36 -> 686921.7
B37: =+MONTH(E37) -> 6 | C37: =+YEAR(E37) -> 2027 | D37: =+_xlfn.CONCAT(B37:C37,G37) -> 62027FE | E37: 46539 | G37: FE | H37: 1 | I37: 7155.4344 | J37: 7155.4344 | K37: 7155.4344 | L37: 7155.4344 | M37: 7155.4344 | N37: 7155.4344 | O37: 7155.4344 | P37: 7155.4344 | Q37: 7155.4344 | R37: 7155.4344 | S37: 7155.4344 | T37: 7155.4344 | U37: 7155.4344 | V37: 7155.4344 | W37: 7155.4344 | X37: 7155.4344 | Y37: 7155.4344 | Z37: 7155.4344 | AA37: 7155.4344 | AB37: 7155.4344 | AC37: 7155.4344 | AD37: 7155.4344 | AE37: 7155.4344 | AF37: 7155.4344 | AG37: =+SUM(I37:AF37)*H37 -> 171730.43
B38: =+MONTH(E38) -> 6 | C38: =+YEAR(E38) -> 2027 | D38: =+_xlfn.CONCAT(E38,G38) -> 46539TOTAL | E38: 46539 | G38: TOTAL | H38: =+SUM(H34:H37) -> 30 | I38: =+SUMPRODUCT(I34:I37,$H34:$H37) -> 214663.03 | J38: =+SUMPRODUCT(J34:J37,$H34:$H37) -> 214663.03 | K38: =+SUMPRODUCT(K34:K37,$H34:$H37) -> 214663.03 | L38: =+SUMPRODUCT(L34:L37,$H34:$H37) -> 214663.03 | M38: =+SUMPRODUCT(M34:M37,$H34:$H37) -> 214663.03 | N38: =+SUMPRODUCT(N34:N37,$H34:$H37) -> 214663.03 | O38: =+SUMPRODUCT(O34:O37,$H34:$H37) -> 214663.03 | P38: =+SUMPRODUCT(P34:P37,$H34:$H37) -> 214663.03 | ... AF38: =+SUMPRODUCT(AF34:AF37,$H34:$H37) -> 214663.03 | AG38: =SUM(I38:AF38) -> 5151912.8
B39: =+MONTH(E39) -> 7 | C39: =+YEAR(E39) -> 2027 | D39: =+_xlfn.CONCAT(B39:C39,G39) -> 72027OR | E39: 46569 | F39: =+AG43 -> 5223724.7 | G39: OR | H39: 20 | I39: 7021.1354 | J39: 7021.1354 | K39: 7021.1354 | L39: 7021.1354 | M39: 7021.1354 | N39: 7021.1354 | O39: 7021.1354 | P39: 7021.1354 | Q39: 7021.1354 | R39: 7021.1354 | S39: 7021.1354 | T39: 7021.1354 | U39: 7021.1354 | V39: 7021.1354 | W39: 7021.1354 | X39: 7021.1354 | Y39: 7021.1354 | Z39: 7021.1354 | AA39: 7021.1354 | AB39: 7021.1354 | AC39: 7021.1354 | AD39: 7021.1354 | AE39: 7021.1354 | AF39: 7021.1354 | AG39: =+SUM(I39:AF39)*H39 -> 3370145
B40: =+MONTH(E40) -> 7 | C40: =+YEAR(E40) -> 2027 | D40: =+_xlfn.CONCAT(B40:C40,G40) -> 72027SA | E40: 46569 | G40: SA | H40: 5 | I40: 7021.1354 | J40: 7021.1354 | K40: 7021.1354 | L40: 7021.1354 | M40: 7021.1354 | N40: 7021.1354 | O40: 7021.1354 | P40: 7021.1354 | Q40: 7021.1354 | R40: 7021.1354 | S40: 7021.1354 | T40: 7021.1354 | U40: 7021.1354 | V40: 7021.1354 | W40: 7021.1354 | X40: 7021.1354 | Y40: 7021.1354 | Z40: 7021.1354 | AA40: 7021.1354 | AB40: 7021.1354 | AC40: 7021.1354 | AD40: 7021.1354 | AE40: 7021.1354 | AF40: 7021.1354 | AG40: =+SUM(I40:AF40)*H40 -> 842536.25
B41: =+MONTH(E41) -> 7 | C41: =+YEAR(E41) -> 2027 | D41: =+_xlfn.CONCAT(B41:C41,G41) -> 72027DO | E41: 46569 | G41: DO | H41: 4 | I41: 7021.1354 | J41: 7021.1354 | K41: 7021.1354 | L41: 7021.1354 | M41: 7021.1354 | N41: 7021.1354 | O41: 7021.1354 | P41: 7021.1354 | Q41: 7021.1354 | R41: 7021.1354 | S41: 7021.1354 | T41: 7021.1354 | U41: 7021.1354 | V41: 7021.1354 | W41: 7021.1354 | X41: 7021.1354 | Y41: 7021.1354 | Z41: 7021.1354 | AA41: 7021.1354 | AB41: 7021.1354 | AC41: 7021.1354 | AD41: 7021.1354 | AE41: 7021.1354 | AF41: 7021.1354 | AG41: =+SUM(I41:AF41)*H41 -> 674029
B42: =+MONTH(E42) -> 7 | C42: =+YEAR(E42) -> 2027 | D42: =+_xlfn.CONCAT(B42:C42,G42) -> 72027FE | E42: 46569 | G42: FE | H42: 2 | I42: 7021.1354 | J42: 7021.1354 | K42: 7021.1354 | L42: 7021.1354 | M42: 7021.1354 | N42: 7021.1354 | O42: 7021.1354 | P42: 7021.1354 | Q42: 7021.1354 | R42: 7021.1354 | S42: 7021.1354 | T42: 7021.1354 | U42: 7021.1354 | V42: 7021.1354 | W42: 7021.1354 | X42: 7021.1354 | Y42: 7021.1354 | Z42: 7021.1354 | AA42: 7021.1354 | AB42: 7021.1354 | AC42: 7021.1354 | AD42: 7021.1354 | AE42: 7021.1354 | AF42: 7021.1354 | AG42: =+SUM(I42:AF42)*H42 -> 337014.5
B43: =+MONTH(E43) -> 7 | C43: =+YEAR(E43) -> 2027 | D43: =+_xlfn.CONCAT(E43,G43) -> 46569TOTAL | E43: 46569 | G43: TOTAL | H43: =+SUM(H39:H42) -> 31 | I43: =+SUMPRODUCT(I39:I42,$H39:$H42) -> 217655.2 | J43: =+SUMPRODUCT(J39:J42,$H39:$H42) -> 217655.2 | K43: =+SUMPRODUCT(K39:K42,$H39:$H42) -> 217655.2 | L43: =+SUMPRODUCT(L39:L42,$H39:$H42) -> 217655.2 | M43: =+SUMPRODUCT(M39:M42,$H39:$H42) -> 217655.2 | N43: =+SUMPRODUCT(N39:N42,$H39:$H42) -> 217655.2 | O43: =+SUMPRODUCT(O39:O42,$H39:$H42) -> 217655.2 | P43: =+SUMPRODUCT(P39:P42,$H39:$H42) -> 217655.2 | ... AF43: =+SUMPRODUCT(AF39:AF42,$H39:$H42) -> 217655.2 | AG43: =SUM(I43:AF43) -> 5223724.7
...

Sheet PRODUCTO 3
C1: CP-GNCC2026-002
C2: CP-GNCC2026-002-PROD03
C3: CANTIDAD EN: | D3: KWh
C4: MODALIDAD: | D4: PAGUE LO CONTRATADO
C5: OFERENTE:
C9: MES DE SUMINISTRO | D9: ENERGÍA SOLICITADA (KWh) | E9: % ENERGÍA OFRECIDA | F9: ENERGÍA OFRECIDA (KWh) | G9: PRECIO OFERTADO ($/KWh)
C10: 46753 | D10: =+_xlfn.XLOOKUP(_xlfn.CONCAT(C10,"TOTAL"),'Cantidades horarias PROD 03'!D:D,'Cantidades horarias PROD 03'!AG:AG) -> 11107108 | E10: 1 | F10: =ROUND(D10*$E10,2) -> 11107108
C11: 46784 | D11: =+_xlfn.XLOOKUP(_xlfn.CONCAT(C11,"TOTAL"),'Cantidades horarias PROD 03'!D:D,'Cantidades horarias PROD 03'!AG:AG) -> 10059541 | E11: 1 | F11: =ROUND(D11*$E11,2) -> 10059541
C12: 46813 | D12: =+_xlfn.XLOOKUP(_xlfn.CONCAT(C12,"TOTAL"),'Cantidades horarias PROD 03'!D:D,'Cantidades horarias PROD 03'!AG:AG) -> 10288924 | E12: 1 | F12: =ROUND(D12*$E12,2) -> 10288924
C13: 46844 | D13: =+_xlfn.XLOOKUP(_xlfn.CONCAT(C13,"TOTAL"),'Cantidades horarias PROD 03'!D:D,'Cantidades horarias PROD 03'!AG:AG) -> 10089497 | E13: 1 | F13: =ROUND(D13*$E13,2) -> 10089497
C14: 46874 | D14: =+_xlfn.XLOOKUP(_xlfn.CONCAT(C14,"TOTAL"),'Cantidades horarias PROD 03'!D:D,'Cantidades horarias PROD 03'!AG:AG) -> 10379974 | E14: 1 | F14: =ROUND(D14*$E14,2) -> 10379974
C15: 46905 | D15: =+_xlfn.XLOOKUP(_xlfn.CONCAT(C15,"TOTAL"),'Cantidades horarias PROD 03'!D:D,'Cantidades horarias PROD 03'!AG:AG) -> 9859792.7 | E15: 1 | F15: =ROUND(D15*$E15,2) -> 9859792.7
C16: 46935 | D16: =+_xlfn.XLOOKUP(_xlfn.CONCAT(C16,"TOTAL"),'Cantidades horarias PROD 03'!D:D,'Cantidades horarias PROD 03'!AG:AG) -> 9929795.3 | E16: 1 | F16: =ROUND(D16*$E16,2) -> 9929795.3
C17: 46966 | D17: =+_xlfn.XLOOKUP(_xlfn.CONCAT(C17,"TOTAL"),'Cantidades horarias PROD 03'!D:D,'Cantidades horarias PROD 03'!AG:AG) -> 10454619 | E17: 1 | F17: =ROUND(D17*$E17,2) -> 10454619
C18: 46997 | D18: =+_xlfn.XLOOKUP(_xlfn.CONCAT(C18,"TOTAL"),'Cantidades horarias PROD 03'!D:D,'Cantidades horarias PROD 03'!AG:AG) -> 10771006 | E18: 1 | F18: =ROUND(D18*$E18,2) -> 10771006
C19: 47027 | D19: =+_xlfn.XLOOKUP(_xlfn.CONCAT(C19,"TOTAL"),'Cantidades horarias PROD 03'!D:D,'Cantidades horarias PROD 03'!AG:AG) -> 10534963 | E19: 1 | F19: =ROUND(D19*$E19,2) -> 10534963
C20: 47058 | D20: =+_xlfn.XLOOKUP(_xlfn.CONCAT(C20,"TOTAL"),'Cantidades horarias PROD 03'!D:D,'Cantidades horarias PROD 03'!AG:AG) -> 10051817 | E20: 1 | F20: =ROUND(D20*$E20,2) -> 10051817
C21: 47088 | D21: =+_xlfn.XLOOKUP(_xlfn.CONCAT(C21,"TOTAL"),'Cantidades horarias PROD 03'!D:D,'Cantidades horarias PROD 03'!AG:AG) -> 10503336 | E21: 1 | F21: =ROUND(D21*$E21,2) -> 10503336
... C45: 47818 | D45: =+_xlfn.XLOOKUP(_xlfn.CONCAT(C45,"TOTAL"),'Cantidades horarias PROD 03'!D:D,'Cantidades horarias PROD 03'!AG:AG) -> 10986164 | E45: 1 | F45: =ROUND(D45*$E45,2) -> 10986164
C46: TOTAL | D46: =SUM(D10:D45) -> 3.734612e+08 | E46: =IFERROR(F46/D46,0) -> 1 | F46: =SUM(F10:F45) -> 3.734612e+08 | G46: =+(SUM(F10:F21)*G10+SUM(F22:F33)*G22+SUM(F34:F45)*G34)/F46 -> 0
C48: Nota
C49: 1. $/kWh expresados en pesos de abril de 2026. (IPC)
C50: 2. La energia ofertada se despachara conforme a las cantidades horarias de este anexo
C54: XXXXXXXXXXXXXXXXXXXXXXXX
C55: REPRESENTANTE LEGAL
C56: XXXXXXXXXXXXXXXXXX.SA.E.S.P
C62: XXXXXXXXXXXXXXXXXXXXXX S.A E.S.P
C64: Nota
C65: 1. $/kWh expresados en pesos de octubre 2025.
C66: 2. La energia ofertada se despachara conforme a las cantidades horarias de este anexo
C70: XXXXXXXXXXXXXXXXXXXXXXXX
C71: REPRESENTANTE LEGAL
C72: XXXXXXXXXXXXXXXXXXXXXX S.A E.S.P

Sheet Cantidades horarias PROD 03
E1: CUADRO DE CANTIDADES HORARIAS OFRECIDAS
E2: CANTIDADES DE ENERGIA (KWh) - PRODUCTO 1
E3: PAGUE LO CONTRATADO
E5: OFERENTE:
B8: MES | C8: AÑO | D8: LLAVE | F8: Cantidad Ofrecida | G8: Tipo de día | H8: N° días mes | I8: H1 | J8: H2 | K8: H3 | L8: H4 | M8: H5 | N8: H6 | O8: H7 | P8: H8 | Q8: H9 | R8: H10 | S8: H11 | T8: H12 | U8: H13 | V8: H14 | W8: H15 | X8: H16 | Y8: H17 | Z8: H18 | AA8: H19 | AB8: H20 | AC8: H21 | AD8: H22 | AE8: H23 | AF8: H24 | AG8: TOTAL
B9: =+MONTH(E9) -> 1 | C9: =+YEAR(E9) -> 2028 | D9: =+_xlfn.CONCAT(B9:C9,G9) -> 12028OR | E9: 46753 | F9: =+AG13 -> 11107108 | G9: OR | H9: 20 | I9: 14764.321 | J9: 14346.188 | K9: 13975.594 | L9: 14302.462 | M9: 13836.29 | N9: 14474.152 | O9: 16203.354 | P9: 19551.48 | Q9: 21899.198 | R9: 22666.385 | S9: 23295.621 | T9: 23633.325 | U9: 22599.214 | V9: 23683.597 | W9: 24167.112 | X9: 24352.52 | Y9: 23379.689 | Z9: 21578.566 | AA9: 19524.037 | AB9: 19406.706 | AC9: 17616.195 | AD9: 16945.611 | AE9: 15588.899 | AF9: 15650.732 | AG9: =ROUND(SUM(I9:AF9)*H9,2) -> 9148825
B10: =+MONTH(E10) -> 1 | C10: =+YEAR(E10) -> 2028 | D10: =+_xlfn.CONCAT(B10:C10,G10) -> 12028SA | E10: 46753 | G10: SA | H10: 4 | I10: 12489.809 | J10: 11800.523 | K10: 11951.131 | L10: 12441.385 | M10: 12155.534 | N10: 12577.8 | O10: 12742.689 | P10: 15264.797 | Q10: 16873.498 | R10: 17266.357 | S10: 17242.066 | T10: 17377.607 | U10: 16596.05 | V10: 16820.066 | W10: 16290.505 | X10: 15877.061 | Y10: 15140.48 | Z10: 14840.684 | AA10: 14026.768 | AB10: 14564.096 | AC10: 13934.157 | AD10: 13143.13 | AE10: 12130.198 | AF10: 11445.314 | AG10: =ROUND(SUM(I10:AF10)*H10,2) -> 1379966.8
B11: =+MONTH(E11) -> 1 | C11: =+YEAR(E11) -> 2028 | D11: =+_xlfn.CONCAT(B11:C11,G11) -> 12028DO | E11: 46753 | G11: DO | H11: 5 | I11: 3916.3529 | J11: 3904.0317 | K11: 3693.3717 | L11: 3638.5546 | M11: 3515.9453 | N11: 3774.9584 | O11: 2803.9402 | P11: 2906.6064 | Q11: 3113.0281 | R11: 3263.3577 | S11: 2661.2483 | T11: 2424.268 | U11: 1870.5008 | V11: 1738.9864 | W11: 1689.9234 | X11: 2447.6751 | Y11: 2716.8108 | Z11: 2957.7148 | AA11: 2431.221 | AB11: 3204.3882 | AC11: 3033.8558 | AD11: 3041.691 | AE11: 3133.8713 | AF11: 3125.7546 | AG11: =ROUND(SUM(I11:AF11)*H11,2) -> 355040.28
B12: =+MONTH(E12) -> 1 | C12: =+YEAR(E12) -> 2028 | D12: =+_xlfn.CONCAT(B12:C12,G12) -> 12028FE | E12: 46753 | G12: FE | H12: 2 | I12: 8595.1619 | J12: 8401.5555 | K12: 8141.2464 | L12: 8041.342 | M12: 7482.9482 | N12: 5794.2898 | O12: 3334.7723 | P12: 3526.3197 | Q12: 4217.1101 | R12: 4481.5573 | S12: 4190.3875 | T12: 3537.0249 | U12: 2822.7711 | V12: 2762.1959 | W12: 2540.8729 | X12: 3508.6727 | Y12: 3236.9344 | Z12: 4078.3907 | AA12: 3935.5887 | AB12: 4812.3791 | AC12: 3885.2399 | AD12: 3618.4771 | AE12: 3409.0765 | AF12: 3283.541 | AG12: =ROUND(SUM(I12:AF12)*H12,2) -> 223275.71
B13: =+MONTH(E13) -> 1 | C13: =+YEAR(E13) -> 2028 | D13: =+_xlfn.CONCAT(E13,G13) -> 46753TOTAL | E13: 46753 | G13: TOTAL | H13: 31 | I13: =+SUMPRODUCT(I9:I12,$H9:$H12) -> 382017.74 | J13: =+SUMPRODUCT(J9:J12,$H9:$H12) -> 370449.13 | K13: =+SUMPRODUCT(K9:K12,$H9:$H12) -> 362065.76 | L13: =+SUMPRODUCT(L9:L12,$H9:$H12) -> 370090.23 | M13: =+SUMPRODUCT(M9:M12,$H9:$H12) -> 357893.55 | N13: =+SUMPRODUCT(N9:N12,$H9:$H12) -> 370257.62 | O13: =+SUMPRODUCT(O9:O12,$H9:$H12) -> 395727.07 | P13: =+SUMPRODUCT(P9:P12,$H9:$H12) -> 473674.46 | ... AF13: =+SUMPRODUCT(AF9:AF12,$H9:$H12) -> 380991.76 | AG13: =SUM(I13:AF13) -> 11107108
B14: =+MONTH(E14) -> 2 | C14: =+YEAR(E14) -> 2028 | D14: =+_xlfn.CONCAT(B14:C14,G14) -> 22028OR | E14: 46784 | F14: =+AG18 -> 10059541 | G14: OR | H14: 21 | I14: 13298.873 | J14: 12900.972 | K14: 12524.134 | L14: 12862.524 | M14: 12346.032 | N14: 12898.291 | O14: 14379.536 | P14: 17578.205 | Q14: 19786.251 | R14: 20469.05 | S14: 20971.944 | T14: 21250.752 | U14: 20251.912 | V14: 21367.507 | W14: 21842.948 | X14: 22022.079 | Y14: 21053.877 | Z14: 19328.02 | AA14: 17414.924 | AB14: 17428.006 | AC14: 15712.998 | AD14: 15186.498 | AE14: 13965.909 | AF14: 14071.736 | AG14: =+SUM(I14:AF14)*H14 -> 8629172.6
B15: =+MONTH(E15) -> 2 | C15: =+YEAR(E15) -> 2028 | D15: =+_xlfn.CONCAT(B15:C15,G15) -> 22028SA | E15: 46784 | G15: SA | H15: 4 | I15: 11203.372 | J15: 10562.143 | K15: 10743.913 | L15: 11264.79 | M15: 10934.168 | N15: 11304.467 | O15: 11344.485 | P15: 13784.802 | Q15: 15303.246 | R15: 15671.018 | S15: 15539.806 | T15: 15687.579 | U15: 14970.232 | V15: 15291.003 | W15: 14743.722 | X15: 14321.407 | Y15: 13593.188 | Z15: 13293.758 | AA15: 12491.853 | AB15: 13171.411 | AC15: 12621.665 | AD15: 11938.567 | AE15: 11025.452 | AF15: 10387.661 | AG15: =+SUM(I15:AF15)*H15 -> 1244774.8
B16: =+MONTH(E16) -> 2 | C16: =+YEAR(E16) -> 2028 | D16: =+_xlfn.CONCAT(B16:C16,G16) -> 22028DO | E16: 46784 | G16: DO | H16: 4 | I16: 2978.9649 | J16: 3006.8829 | K16: 2755.9566 | L16: 2716.4534 | M16: 2587.1334 | N16: 2893.3295 | O16: 1911.3807 | P16: 1947.7569 | Q16: 2070.656 | R16: 2185.3888 | S16: 1546.0725 | T16: 1297.6923 | U16: 742.90707 | V16: 564.70013 | W16: 528.99811 | X16: 1271.7022 | Y16: 1543.7611 | Z16: 1847.6603 | AA16: 1263.8009 | AB16: 2138.2145 | AC16: 2021.2722 | AD16: 2106.4635 | AE16: 2221.8228 | AF16: 2249.4278 | AG16: =+SUM(I16:AF16)*H16 -> 185593.59
B17: =+MONTH(E17) -> 2 | C17: =+YEAR(E17) -> 2028 | D17: =+_xlfn.CONCAT(B17:C17,G17) -> 22028FE | E17: 46784 | G17: FE | H17: 0 | I17: 0 | J17: 0 | K17: 0 | L17: 0 | M17: 0 | N17: 0 | O17: 0 | P17: 0 | Q17: 0 | R17: 0 | S17: 0 | T17: 0 | U17: 0 | V17: 0 | W17: 0 | X17: 0 | Y17: 0 | Z17: 0 | AA17: 0 | AB17: 0 | AC17: 0 | AD17: 0 | AE17: 0 | AF17: 0 | AG17: =+SUM(I17:AF17)*H17 -> 0
B18: =+MONTH(E18) -> 2 | C18: =+YEAR(E18) -> 2028 | D18: =+_xlfn.CONCAT(E18,G18) -> 46784TOTAL | E18: 46784 | G18: TOTAL | H18: 29 | I18: =+SUMPRODUCT(I14:I17,$H14:$H17) -> 336005.69 | J18: =+SUMPRODUCT(J14:J17,$H14:$H17) -> 325196.53 | K18: =+SUMPRODUCT(K14:K17,$H14:$H17) -> 317006.29 | L18: =+SUMPRODUCT(L14:L17,$H14:$H17) -> 326037.97 | M18: =+SUMPRODUCT(M14:M17,$H14:$H17) -> 313351.88 | N18: =+SUMPRODUCT(N14:N17,$H14:$H17) -> 327655.3 | O18: =+SUMPRODUCT(O14:O17,$H14:$H17) -> 354993.71 | P18: =+SUMPRODUCT(P14:P17,$H14:$H17) -> 432072.55 | ... AF18: =+SUMPRODUCT(AF14:AF17,$H14:$H17) -> 346054.8 | AG18: =SUM(I18:AF18) -> 10059541
B19: =+MONTH(E19) -> 3 | C19: =+YEAR(E19) -> 2028 | D19: =+_xlfn.CONCAT(B19:C19,G19) -> 32028OR | E19: 46813 | F19: =+AG23 -> 10288924 | G19: OR | H19: 22 | I19: 13072.822 | J19: 12666.417 | K19: 12276.627 | L19: 12607.742 | M19: 12056.873 | N19: 12537.403 | O19: 13927.898 | P19: 17139.192 | Q19: 19364.083 | R19: 20081.289 | S19: 20555.369 | T19: 20828.36 | U19: 19819.423 | V19: 20964.678 | W19: 21451.766 | X19: 21618.141 | Y19: 20635.334 | Z19: 18898.774 | AA19: 16997.292 | AB19: 17069.748 | AC19: 15364.135 | AD19: 14878.695 | AE19: 13701.829 | AF19: 13813.192 | AG19: =+SUM(I19:AF19)*H19 -> 8851195.8
