Workbook

Sheet Producto No. 1 Plana 2025-2033
A5: ANEXO No. 1. Oferta Producto No. 1 Curva Plana (agosto de 2025 a diciembre año 2033) Convocatoria Pública DISPAC S.A. E.S.P.
A8: PROPONENTE
A10: MES | B10: DEMANDA REQUERIDA DISPAC KWh | C10: DEMANDA PERIODO REQUERIDA DISPAC KWh | D10: PORCENTAJE (%) OFERTADO DE LA DEMANDA REQUERIDA | E10: DEMANDA OFERTADA KWh - MES | F10: DEMANDA PERIODO OFERTADA KWh | G10: PRECIO OFERTADO $ kWh (0.00)
A11: AGOSTO DE 2025 | B11: =+'Despacho Horario Producto No. 1'!AD2 -> 550800 | C11: =+SUM(B11:B15) -> 10213200 | E11: =+$D$11*B11 -> 0 | F11: =+SUM(E11:E15) -> 0
A12: SEPTIEMBRE DE 2025 | B12: =+'Despacho Horario Producto No. 1'!AD5 -> 2376000 | E12: =+$D$11*B12 -> 0
A13: OCTUBRE DE 2025 | B13: =+'Despacho Horario Producto No. 1'!AD8 -> 2455200 | E13: =+$D$11*B13 -> 0
A14: NOVIEMBRE DE 2025 | B14: =+'Despacho Horario Producto No. 1'!AD11 -> 2376000 | E14: =+$D$11*B14 -> 0
A15: DICIEMBRE DE 2025 | B15: =+'Despacho Horario Producto No. 1'!AD14 -> 2455200 | E15: =+$D$11*B15 -> 0
A16: ENERO DE 2026 | B16: ='Despacho Horario Producto No. 1'!AD17 -> 9672000 | C16: =SUM(B16:B27) -> 113880000 | E16: =+$D$11*B16 -> 0 | F16: =SUM(E16:E27) -> 0
A17: FEBRERO DE 2026 | B17: ='Despacho Horario Producto No. 1'!AD20 -> 8736000 | E17: =+$D$11*B17 -> 0
A18: MARZO DE 2026 | B18: ='Despacho Horario Producto No. 1'!AD23 -> 9672000 | E18: =+$D$11*B18 -> 0
A19: ABRIL DE 2026 | B19: ='Despacho Horario Producto No. 1'!AD26 -> 9360000 | E19: =+$D$11*B19 -> 0
A20: MAYO DE 2026 | B20: ='Despacho Horario Producto No. 1'!AD29 -> 9672000 | E20: =+$D$11*B20 -> 0
A21: JUNIO DE 2026 | B21: ='Despacho Horario Producto No. 1'!AD32 -> 9360000 | E21: =+$D$11*B21 -> 0
A22: JULIO DE 2026 | B22: ='Despacho Horario Producto No. 1'!AD35 -> 9672000 | E22: =+$D$11*B22 -> 0
A23: AGOSTO DE 2026 | B23: ='Despacho Horario Producto No. 1'!AD38 -> 9672000 | E23: =+$D$11*B23 -> 0
A24: SEPTIEMBRE DE 2026 | B24: ='Despacho Horario Producto No. 1'!AD41 -> 9360000 | E24: =+$D$11*B24 -> 0
A25: OCTUBRE DE 2026 | B25: ='Despacho Horario Producto No. 1'!AD44 -> 9672000 | E25: =+$D$11*B25 -> 0
A26: NOVIEMBRE DE 2026 | B26: ='Despacho Horario Producto No. 1'!AD47 -> 9360000 | E26: =+$D$11*B26 -> 0
A27: DICIEMBRE DE 2026 | B27: ='Despacho Horario Producto No. 1'!AD50 -> 9672000 | E27: =+$D$11*B27 -> 0
A28: ENERO DE 2027 | B28: ='Despacho Horario Producto No. 1'!AD53 -> 9672000 | C28: =SUM(B28:B39) -> 113880000 | E28: =+$D$11*B28 -> 0 | F28: =SUM(E28:E39) -> 0
A29: FEBRERO DE 2027 | B29: ='Despacho Horario Producto No. 1'!AD56 -> 8736000 | E29: =+$D$11*B29 -> 0
A30: MARZO DE 2027 | B30: ='Despacho Horario Producto No. 1'!AD59 -> 9672000 | E30: =+$D$11*B30 -> 0
A31: ABRIL DE 2027 | B31: ='Despacho Horario Producto No. 1'!AD62 -> 9360000 | E31: =+$D$11*B31 -> 0
A32: MAYO DE 2027 | B32: ='Despacho Horario Producto No. 1'!AD65 -> 9672000 | E32: =+$D$11*B32 -> 0
A33: JUNIO DE 2027 | B33: ='Despacho Horario Producto No. 1'!AD68 -> 9360000 | E33: =+$D$11*B33 -> 0
A34: JULIO DE 2027 | B34: ='Despacho Horario Producto No. 1'!AD71 -> 9672000 | E34: =+$D$11*B34 -> 0
A35: AGOSTO DE 2027 | B35: ='Despacho Horario Producto No. 1'!AD74 -> 9672000 | E35: =+$D$11*B35 -> 0
A36: SEPTIEMBRE DE 2027 | B36: ='Despacho Horario Producto No. 1'!AD77 -> 9360000 | E36: =+$D$11*B36 -> 0
A37: OCTUBRE DE 2027 | B37: ='Despacho Horario Producto No. 1'!AD80 -> 9672000 | E37: =+$D$11*B37 -> 0
A38: NOVIEMBRE DE 2027 | B38: ='Despacho Horario Producto No. 1'!AD83 -> 9360000 | E38: =+$D$11*B38 -> 0
A39: DICIEMBRE DE 2027 | B39: ='Despacho Horario Producto No. 1'!AD86 -> 9672000 | E39: =+$D$11*B39 -> 0
A40: ENERO DE 2028 | B40: ='Despacho Horario Producto No. 1'!AD89 -> 9672000 | C40: =SUM(B40:B51) -> 114192000 | E40: =+$D$11*B40 -> 0 | F40: =SUM(E40:E51) -> 0
A41: FEBRERO DE 2028 | B41: ='Despacho Horario Producto No. 1'!AD92 -> 9048000 | E41: =+$D$11*B41 -> 0
A42: MARZO DE 2028 | B42: ='Despacho Horario Producto No. 1'!AD95 -> 9672000 | E42: =+$D$11*B42 -> 0
A43: ABRIL DE 2028 | B43: ='Despacho Horario Producto No. 1'!AD98 -> 9360000 | E43: =+$D$11*B43 -> 0
A44: MAYO DE 2028 | B44: ='Despacho Horario Producto No. 1'!AD101 -> 9672000 | E44: =+$D$11*B44 -> 0
A45: JUNIO DE 2028 | B45: ='Despacho Horario Producto No. 1'!AD104 -> 9360000 | E45: =+$D$11*B45 -> 0
A46: JULIO DE 2028 | B46: ='Despacho Horario Producto No. 1'!AD107 -> 9672000 | E46: =+$D$11*B46 -> 0
A47: AGOSTO DE 2028 | B47: ='Despacho Horario Producto No. 1'!AD110 -> 9672000 | E47: =+$D$11*B47 -> 0
...

Sheet Despacho Horario Producto No. 1
A1: Año | B1: Mes | C1: # días | D1: TPD | E1: H1 | F1: H2 | G1: H3 | H1: H4 | I1: H5 | J1: H6 | K1: H7 | L1: H8 | M1: H9 | N1: H10 | O1: H11 | P1: H12 | Q1: H13 | R1: H14 | S1: H15 | T1: H16 | U1: H17 | V1: H18 | W1: H19 | X1: H20 | Y1: H21 | Z1: H22 | AA1: H23 | AB1: H24 | AC1: kWh/d | AD1: kWh/mes
A2: 2025 | B2: 8 | C2: 4 | D2: Festivo | E2: 1350 | F2: 1350 | G2: 1350 | H2: 1350 | I2: 1350 | J2: 1350 | K2: 1350 | L2: 1350 | M2: 1350 | N2: 1350 | O2: 1350 | P2: 1350 | Q2: 1350 | R2: 1350 | S2: 1350 | T2: 1350 | U2: 1350 | V2: 1350 | W2: 1350 | X2: 1350 | Y2: 1350 | Z2: 1350 | AA2: 1350 | AB2: 1350 | AC2: =+SUM(E2:AB2) -> 32400 | AD2: =+SUMPRODUCT(AC2:AC4,C2:C4) -> 550800
A3: 2025 | B3: 8 | C3: 10 | D3: Hábil | E3: 1350 | F3: 1350 | G3: 1350 | H3: 1350 | I3: 1350 | J3: 1350 | K3: 1350 | L3: 1350 | M3: 1350 | N3: 1350 | O3: 1350 | P3: 1350 | Q3: 1350 | R3: 1350 | S3: 1350 | T3: 1350 | U3: 1350 | V3: 1350 | W3: 1350 | X3: 1350 | Y3: 1350 | Z3: 1350 | AA3: 1350 | AB3: 1350 | AC3: =+SUM(E3:AB3) -> 32400
A4: 2025 | B4: 8 | C4: 3 | D4: Sábado | E4: 1350 | F4: 1350 | G4: 1350 | H4: 1350 | I4: 1350 | J4: 1350 | K4: 1350 | L4: 1350 | M4: 1350 | N4: 1350 | O4: 1350 | P4: 1350 | Q4: 1350 | R4: 1350 | S4: 1350 | T4: 1350 | U4: 1350 | V4: 1350 | W4: 1350 | X4: 1350 | Y4: 1350 | Z4: 1350 | AA4: 1350 | AB4: 1350 | AC4: =+SUM(E4:AB4) -> 32400
A5: 2025 | B5: 9 | C5: 4 | D5: Festivo | E5: 3300 | F5: 3300 | G5: 3300 | H5: 3300 | I5: 3300 | J5: 3300 | K5: 3300 | L5: 3300 | M5: 3300 | N5: 3300 | O5: 3300 | P5: 3300 | Q5: 3300 | R5: 3300 | S5: 3300 | T5: 3300 | U5: 3300 | V5: 3300 | W5: 3300 | X5: 3300 | Y5: 3300 | Z5: 3300 | AA5: 3300 | AB5: 3300 | AC5: =+SUM(E5:AB5) -> 79200 | AD5: =+SUMPRODUCT(AC5:AC7,C5:C7) -> 2376000
A6: 2025 | B6: 9 | C6: 22 | D6: Hábil | E6: 3300 | F6: 3300 | G6: 3300 | H6: 3300 | I6: 3300 | J6: 3300 | K6: 3300 | L6: 3300 | M6: 3300 | N6: 3300 | O6: 3300 | P6: 3300 | Q6: 3300 | R6: 3300 | S6: 3300 | T6: 3300 | U6: 3300 | V6: 3300 | W6: 3300 | X6: 3300 | Y6: 3300 | Z6: 3300 | AA6: 3300 | AB6: 3300 | AC6: =+SUM(E6:AB6) -> 79200
A7: 2025 | B7: 9 | C7: 4 | D7: Sábado | E7: 3300 | F7: 3300 | G7: 3300 | H7: 3300 | I7: 3300 | J7: 3300 | K7: 3300 | L7: 3300 | M7: 3300 | N7: 3300 | O7: 3300 | P7: 3300 | Q7: 3300 | R7: 3300 | S7: 3300 | T7: 3300 | U7: 3300 | V7: 3300 | W7: 3300 | X7: 3300 | Y7: 3300 | Z7: 3300 | AA7: 3300 | AB7: 3300 | AC7: =+SUM(E7:AB7) -> 79200
A8: 2025 | B8: 10 | C8: 5 | D8: Festivo | E8: 3300 | F8: 3300 | G8: 3300 | H8: 3300 | I8: 3300 | J8: 3300 | K8: 3300 | L8: 3300 | M8: 3300 | N8: 3300 | O8: 3300 | P8: 3300 | Q8: 3300 | R8: 3300 | S8: 3300 | T8: 3300 | U8: 3300 | V8: 3300 | W8: 3300 | X8: 3300 | Y8: 3300 | Z8: 3300 | AA8: 3300 | AB8: 3300 | AC8: =+SUM(E8:AB8) -> 79200 | AD8: =+SUMPRODUCT(AC8:AC10,C8:C10) -> 2455200
A9: 2025 | B9: 10 | C9: 22 | D9: Hábil | E9: 3300 | F9: 3300 | G9: 3300 | H9: 3300 | I9: 3300 | J9: 3300 | K9: 3300 | L9: 3300 | M9: 3300 | N9: 3300 | O9: 3300 | P9: 3300 | Q9: 3300 | R9: 3300 | S9: 3300 | T9: 3300 | U9: 3300 | V9: 3300 | W9: 3300 | X9: 3300 | Y9: 3300 | Z9: 3300 | AA9: 3300 | AB9: 3300 | AC9: =+SUM(E9:AB9) -> 79200
A10: 2025 | B10: 10 | C10: 4 | D10: Sábado | E10: 3300 | F10: 3300 | G10: 3300 | H10: 3300 | I10: 3300 | J10: 3300 | K10: 3300 | L10: 3300 | M10: 3300 | N10: 3300 | O10: 3300 | P10: 3300 | Q10: 3300 | R10: 3300 | S10: 3300 | T10: 3300 | U10: 3300 | V10: 3300 | W10: 3300 | X10: 3300 | Y10: 3300 | Z10: 3300 | AA10: 3300 | AB10: 3300 | AC10: =+SUM(E10:AB10) -> 79200
A11: 2025 | B11: 11 | C11: 7 | D11: Festivo | E11: 3300 | F11: 3300 | G11: 3300 | H11: 3300 | I11: 3300 | J11: 3300 | K11: 3300 | L11: 3300 | M11: 3300 | N11: 3300 | O11: 3300 | P11: 3300 | Q11: 3300 | R11: 3300 | S11: 3300 | T11: 3300 | U11: 3300 | V11: 3300 | W11: 3300 | X11: 3300 | Y11: 3300 | Z11: 3300 | AA11: 3300 | AB11: 3300 | AC11: =+SUM(E11:AB11) -> 79200 | AD11: =+SUMPRODUCT(AC11:AC13,C11:C13) -> 2376000
A12: 2025 | B12: 11 | C12: 18 | D12: Hábil | E12: 3300 | F12: 3300 | G12: 3300 | H12: 3300 | I12: 3300 | J12: 3300 | K12: 3300 | L12: 3300 | M12: 3300 | N12: 3300 | O12: 3300 | P12: 3300 | Q12: 3300 | R12: 3300 | S12: 3300 | T12: 3300 | U12: 3300 | V12: 3300 | W12: 3300 | X12: 3300 | Y12: 3300 | Z12: 3300 | AA12: 3300 | AB12: 3300 | AC12: =+SUM(E12:AB12) -> 79200
A13: 2025 | B13: 11 | C13: 5 | D13: Sábado | E13: 3300 | F13: 3300 | G13: 3300 | H13: 3300 | I13: 3300 | J13: 3300 | K13: 3300 | L13: 3300 | M13: 3300 | N13: 3300 | O13: 3300 | P13: 3300 | Q13: 3300 | R13: 3300 | S13: 3300 | T13: 3300 | U13: 3300 | V13: 3300 | W13: 3300 | X13: 3300 | Y13: 3300 | Z13: 3300 | AA13: 3300 | AB13: 3300 | AC13: =+SUM(E13:AB13) -> 79200
A14: 2025 | B14: 12 | C14: 6 | D14: Festivo | E14: 3300 | F14: 3300 | G14: 3300 | H14: 3300 | I14: 3300 | J14: 3300 | K14: 3300 | L14: 3300 | M14: 3300 | N14: 3300 | O14: 3300 | P14: 3300 | Q14: 3300 | R14: 3300 | S14: 3300 | T14: 3300 | U14: 3300 | V14: 3300 | W14: 3300 | X14: 3300 | Y14: 3300 | Z14: 3300 | AA14: 3300 | AB14: 3300 | AC14: =+SUM(E14:AB14) -> 79200 | AD14: =+SUMPRODUCT(AC14:AC16,C14:C16) -> 2455200
A15: 2025 | B15: 12 | C15: 21 | D15: Hábil | E15: 3300 | F15: 3300 | G15: 3300 | H15: 3300 | I15: 3300 | J15: 3300 | K15: 3300 | L15: 3300 | M15: 3300 | N15: 3300 | O15: 3300 | P15: 3300 | Q15: 3300 | R15: 3300 | S15: 3300 | T15: 3300 | U15: 3300 | V15: 3300 | W15: 3300 | X15: 3300 | Y15: 3300 | Z15: 3300 | AA15: 3300 | AB15: 3300 | AC15: =+SUM(E15:AB15) -> 79200
A16: 2025 | B16: 12 | C16: 4 | D16: Sábado | E16: 3300 | F16: 3300 | G16: 3300 | H16: 3300 | I16: 3300 | J16: 3300 | K16: 3300 | L16: 3300 | M16: 3300 | N16: 3300 | O16: 3300 | P16: 3300 | Q16: 3300 | R16: 3300 | S16: 3300 | T16: 3300 | U16: 3300 | V16: 3300 | W16: 3300 | X16: 3300 | Y16: 3300 | Z16: 3300 | AA16: 3300 | AB16: 3300 | AC16: =+SUM(E16:AB16) -> 79200
A17: 2026 | B17: 1 | C17: 6 | D17: Festivo | E17: 13000 | F17: 13000 | G17: 13000 | H17: 13000 | I17: 13000 | J17: 13000 | K17: 13000 | L17: 13000 | M17: 13000 | N17: 13000 | O17: 13000 | P17: 13000 | Q17: 13000 | R17: 13000 | S17: 13000 | T17: 13000 | U17: 13000 | V17: 13000 | W17: 13000 | X17: 13000 | Y17: 13000 | Z17: 13000 | AA17: 13000 | AB17: 13000 | AC17: =+SUM(E17:AB17) -> 312000 | AD17: =+SUMPRODUCT(AC17:AC19,C17:C19) -> 9672000
A18: 2026 | B18: 1 | C18: 20 | D18: Hábil | E18: 13000 | F18: 13000 | G18: 13000 | H18: 13000 | I18: 13000 | J18: 13000 | K18: 13000 | L18: 13000 | M18: 13000 | N18: 13000 | O18: 13000 | P18: 13000 | Q18: 13000 | R18: 13000 | S18: 13000 | T18: 13000 | U18: 13000 | V18: 13000 | W18: 13000 | X18: 13000 | Y18: 13000 | Z18: 13000 | AA18: 13000 | AB18: 13000 | AC18: =+SUM(E18:AB18) -> 312000
A19: 2026 | B19: 1 | C19: 5 | D19: Sábado | E19: 13000 | F19: 13000 | G19: 13000 | H19: 13000 | I19: 13000 | J19: 13000 | K19: 13000 | L19: 13000 | M19: 13000 | N19: 13000 | O19: 13000 | P19: 13000 | Q19: 13000 | R19: 13000 | S19: 13000 | T19: 13000 | U19: 13000 | V19: 13000 | W19: 13000 | X19: 13000 | Y19: 13000 | Z19: 13000 | AA19: 13000 | AB19: 13000 | AC19: =+SUM(E19:AB19) -> 312000
A20: 2026 | B20: 2 | C20: 4 | D20: Festivo | E20: 13000 | F20: 13000 | G20: 13000 | H20: 13000 | I20: 13000 | J20: 13000 | K20: 13000 | L20: 13000 | M20: 13000 | N20: 13000 | O20: 13000 | P20: 13000 | Q20: 13000 | R20: 13000 | S20: 13000 | T20: 13000 | U20: 13000 | V20: 13000 | W20: 13000 | X20: 13000 | Y20: 13000 | Z20: 13000 | AA20: 13000 | AB20: 13000 | AC20: =+SUM(E20:AB20) -> 312000 | AD20: =+SUMPRODUCT(AC20:AC22,C20:C22) -> 8736000
A21: 2026 | B21: 2 | C21: 20 | D21: Hábil | E21: 13000 | F21: 13000 | G21: 13000 | H21: 13000 | I21: 13000 | J21: 13000 | K21: 13000 | L21: 13000 | M21: 13000 | N21: 13000 | O21: 13000 | P21: 13000 | Q21: 13000 | R21: 13000 | S21: 13000 | T21: 13000 | U21: 13000 | V21: 13000 | W21: 13000 | X21: 13000 | Y21: 13000 | Z21: 13000 | AA21: 13000 | AB21: 13000 | AC21: =+SUM(E21:AB21) -> 312000
A22: 2026 | B22: 2 | C22: 4 | D22: Sábado | E22: 13000 | F22: 13000 | G22: 13000 | H22: 13000 | I22: 13000 | J22: 13000 | K22: 13000 | L22: 13000 | M22: 13000 | N22: 13000 | O22: 13000 | P22: 13000 | Q22: 13000 | R22: 13000 | S22: 13000 | T22: 13000 | U22: 13000 | V22: 13000 | W22: 13000 | X22: 13000 | Y22: 13000 | Z22: 13000 | AA22: 13000 | AB22: 13000 | AC22: =+SUM(E22:AB22) -> 312000
A23: 2026 | B23: 3 | C23: 6 | D23: Festivo | E23: 13000 | F23: 13000 | G23: 13000 | H23: 13000 | I23: 13000 | J23: 13000 | K23: 13000 | L23: 13000 | M23: 13000 | N23: 13000 | O23: 13000 | P23: 13000 | Q23: 13000 | R23: 13000 | S23: 13000 | T23: 13000 | U23: 13000 | V23: 13000 | W23: 13000 | X23: 13000 | Y23: 13000 | Z23: 13000 | AA23: 13000 | AB23: 13000 | AC23: =+SUM(E23:AB23) -> 312000 | AD23: =+SUMPRODUCT(AC23:AC25,C23:C25) -> 9672000
A24: 2026 | B24: 3 | C24: 21 | D24: Hábil | E24: 13000 | F24: 13000 | G24: 13000 | H24: 13000 | I24: 13000 | J24: 13000 | K24: 13000 | L24: 13000 | M24: 13000 | N24: 13000 | O24: 13000 | P24: 13000 | Q24: 13000 | R24: 13000 | S24: 13000 | T24: 13000 | U24: 13000 | V24: 13000 | W24: 13000 | X24: 13000 | Y24: 13000 | Z24: 13000 | AA24: 13000 | AB24: 13000 | AC24: =+SUM(E24:AB24) -> 312000
A25: 2026 | B25: 3 | C25: 4 | D25: Sábado | E25: 13000 | F25: 13000 | G25: 13000 | H25: 13000 | I25: 13000 | J25: 13000 | K25: 13000 | L25: 13000 | M25: 13000 | N25: 13000 | O25: 13000 | P25: 13000 | Q25: 13000 | R25: 13000 | S25: 13000 | T25: 13000 | U25: 13000 | V25: 13000 | W25: 13000 | X25: 13000 | Y25: 13000 | Z25: 13000 | AA25: 13000 | AB25: 13000 | AC25: =+SUM(E25:AB25) -> 312000
A26: 2026 | B26: 4 | C26: 6 | D26: Festivo | E26: 13000 | F26: 13000 | G26: 13000 | H26: 13000 | I26: 13000 | J26: 13000 | K26: 13000 | L26: 13000 | M26: 13000 | N26: 13000 | O26: 13000 | P26: 13000 | Q26: 13000 | R26: 13000 | S26: 13000 | T26: 13000 | U26: 13000 | V26: 13000 | W26: 13000 | X26: 13000 | Y26: 13000 | Z26: 13000 | AA26: 13000 | AB26: 13000 | AC26: =+SUM(E26:AB26) -> 312000 | AD26: =+SUMPRODUCT(AC26:AC28,C26:C28) -> 9360000
A27: 2026 | B27: 4 | C27: 20 | D27: Hábil | E27: 13000 | F27: 13000 | G27: 13000 | H27: 13000 | I27: 13000 | J27: 13000 | K27: 13000 | L27: 13000 | M27: 13000 | N27: 13000 | O27: 13000 | P27: 13000 | Q27: 13000 | R27: 13000 | S27: 13000 | T27: 13000 | U27: 13000 | V27: 13000 | W27: 13000 | X27: 13000 | Y27: 13000 | Z27: 13000 | AA27: 13000 | AB27: 13000 | AC27: =+SUM(E27:AB27) -> 312000
A28: 2026 | B28: 4 | C28: 4 | D28: Sábado | E28: 13000 | F28: 13000 | G28: 13000 | H28: 13000 | I28: 13000 | J28: 13000 | K28: 13000 | L28: 13000 | M28: 13000 | N28: 13000 | O28: 13000 | P28: 13000 | Q28: 13000 | R28: 13000 | S28: 13000 | T28: 13000 | U28: 13000 | V28: 13000 | W28: 13000 | X28: 13000 | Y28: 13000 | Z28: 13000 | AA28: 13000 | AB28: 13000 | AC28: =+SUM(E28:AB28) -> 312000
A29: 2026 | B29: 5 | C29: 7 | D29: Festivo | E29: 13000 | F29: 13000 | G29: 13000 | H29: 13000 | I29: 13000 | J29: 13000 | K29: 13000 | L29: 13000 | M29: 13000 | N29: 13000 | O29: 13000 | P29: 13000 | Q29: 13000 | R29: 13000 | S29: 13000 | T29: 13000 | U29: 13000 | V29: 13000 | W29: 13000 | X29: 13000 | Y29: 13000 | Z29: 13000 | AA29: 13000 | AB29: 13000 | AC29: =+SUM(E29:AB29) -> 312000 | AD29: =+SUMPRODUCT(AC29:AC31,C29:C31) -> 9672000
A30: 2026 | B30: 5 | C30: 19 | D30: Hábil | E30: 13000 | F30: 13000 | G30: 13000 | H30: 13000 | I30: 13000 | J30: 13000 | K30: 13000 | L30: 13000 | M30: 13000 | N30: 13000 | O30: 13000 | P30: 13000 | Q30: 13000 | R30: 13000 | S30: 13000 | T30: 13000 | U30: 13000 | V30: 13000 | W30: 13000 | X30: 13000 | Y30: 13000 | Z30: 13000 | AA30: 13000 | AB30: 13000 | AC30: =+SUM(E30:AB30) -> 312000
A31: 2026 | B31: 5 | C31: 5 | D31: Sábado | E31: 13000 | F31: 13000 | G31: 13000 | H31: 13000 | I31: 13000 | J31: 13000 | K31: 13000 | L31: 13000 | M31: 13000 | N31: 13000 | O31: 13000 | P31: 13000 | Q31: 13000 | R31: 13000 | S31: 13000 | T31: 13000 | U31: 13000 | V31: 13000 | W31: 13000 | X31: 13000 | Y31: 13000 | Z31: 13000 | AA31: 13000 | AB31: 13000 | AC31: =+SUM(E31:AB31) -> 312000
A32: 2026 | B32: 6 | C32: 6 | D32: Festivo | E32: 13000 | F32: 13000 | G32: 13000 | H32: 13000 | I32: 13000 | J32: 13000 | K32: 13000 | L32: 13000 | M32: 13000 | N32: 13000 | O32: 13000 | P32: 13000 | Q32: 13000 | R32: 13000 | S32: 13000 | T32: 13000 | U32: 13000 | V32: 13000 | W32: 13000 | X32: 13000 | Y32: 13000 | Z32: 13000 | AA32: 13000 | AB32: 13000 | AC32: =+SUM(E32:AB32) -> 312000 | AD32: =+SUMPRODUCT(AC32:AC34,C32:C34) -> 9360000
A33: 2026 | B33: 6 | C33: 20 | D33: Hábil | E33: 13000 | F33: 13000 | G33: 13000 | H33: 13000 | I33: 13000 | J33: 13000 | K33: 13000 | L33: 13000 | M33: 13000 | N33: 13000 | O33: 13000 | P33: 13000 | Q33: 13000 | R33: 13000 | S33: 13000 | T33: 13000 | U33: 13000 | V33: 13000 | W33: 13000 | X33: 13000 | Y33: 13000 | Z33: 13000 | AA33: 13000 | AB33: 13000 | AC33: =+SUM(E33:AB33) -> 312000
A34: 2026 | B34: 6 | C34: 4 | D34: Sábado | E34: 13000 | F34: 13000 | G34: 13000 | H34: 13000 | I34: 13000 | J34: 13000 | K34: 13000 | L34: 13000 | M34: 13000 | N34: 13000 | O34: 13000 | P34: 13000 | Q34: 13000 | R34: 13000 | S34: 13000 | T34: 13000 | U34: 13000 | V34: 13000 | W34: 13000 | X34: 13000 | Y34: 13000 | Z34: 13000 | AA34: 13000 | AB34: 13000 | AC34: =+SUM(E34:AB34) -> 312000
A35: 2026 | B35: 7 | C35: 6 | D35: Festivo | E35: 13000 | F35: 13000 | G35: 13000 | H35: 13000 | I35: 13000 | J35: 13000 | K35: 13000 | L35: 13000 | M35: 13000 | N35: 13000 | O35: 13000 | P35: 13000 | Q35: 13000 | R35: 13000 | S35: 13000 | T35: 13000 | U35: 13000 | V35: 13000 | W35: 13000 | X35: 13000 | Y35: 13000 | Z35: 13000 | AA35: 13000 | AB35: 13000 | AC35: =+SUM(E35:AB35) -> 312000 | AD35: =+SUMPRODUCT(AC35:AC37,C35:C37) -> 9672000
A36: 2026 | B36: 7 | C36: 21 | D36: Hábil | E36: 13000 | F36: 13000 | G36: 13000 | H36: 13000 | I36: 13000 | J36: 13000 | K36: 13000 | L36: 13000 | M36: 13000 | N36: 13000 | O36: 13000 | P36: 13000 | Q36: 13000 | R36: 13000 | S36: 13000 | T36: 13000 | U36: 13000 | V36: 13000 | W36: 13000 | X36: 13000 | Y36: 13000 | Z36: 13000 | AA36: 13000 | AB36: 13000 | AC36: =+SUM(E36:AB36) -> 312000
A37: 2026 | B37: 7 | C37: 4 | D37: Sábado | E37: 13000 | F37: 13000 | G37: 13000 | H37: 13000 | I37: 13000 | J37: 13000 | K37: 13000 | L37: 13000 | M37: 13000 | N37: 13000 | O37: 13000 | P37: 13000 | Q37: 13000 | R37: 13000 | S37: 13000 | T37: 13000 | U37: 13000 | V37: 13000 | W37: 13000 | X37: 13000 | Y37: 13000 | Z37: 13000 | AA37: 13000 | AB37: 13000 | AC37: =+SUM(E37:AB37) -> 312000
A38: 2026 | B38: 8 | C38: 7 | D38: Festivo | E38: 13000 | F38: 13000 | G38: 13000 | H38: 13000 | I38: 13000 | J38: 13000 | K38: 13000 | L38: 13000 | M38: 13000 | N38: 13000 | O38: 13000 | P38: 13000 | Q38: 13000 | R38: 13000 | S38: 13000 | T38: 13000 | U38: 13000 | V38: 13000 | W38: 13000 | X38: 13000 | Y38: 13000 | Z38: 13000 | AA38: 13000 | AB38: 13000 | AC38: =+SUM(E38:AB38) -> 312000 | AD38: =+SUMPRODUCT(AC38:AC40,C38:C40) -> 9672000
A39: 2026 | B39: 8 | C39: 19 | D39: Hábil | E39: 13000 | F39: 13000 | G39: 13000 | H39: 13000 | I39: 13000 | J39: 13000 | K39: 13000 | L39: 13000 | M39: 13000 | N39: 13000 | O39: 13000 | P39: 13000 | Q39: 13000 | R39: 13000 | S39: 13000 | T39: 13000 | U39: 13000 | V39: 13000 | W39: 13000 | X39: 13000 | Y39: 13000 | Z39: 13000 | AA39: 13000 | AB39: 13000 | AC39: =+SUM(E39:AB39) -> 312000
A40: 2026 | B40: 8 | C40: 5 | D40: Sábado | E40: 13000 | F40: 13000 | G40: 13000 | H40: 13000 | I40: 13000 | J40: 13000 | K40: 13000 | L40: 13000 | M40: 13000 | N40: 13000 | O40: 13000 | P40: 13000 | Q40: 13000 | R40: 13000 | S40: 13000 | T40: 13000 | U40: 13000 | V40: 13000 | W40: 13000 | X40: 13000 | Y40: 13000 | Z40: 13000 | AA40: 13000 | AB40: 13000 | AC40: =+SUM(E40:AB40) -> 312000
...

Sheet Producto No. 2 Curva 2026-2033
A5: ANEXO No. 1. Oferta Producto No. 2 Curva (Enero de 2026 a diciembre año 2033) Convocatoria Pública DISPAC S.A. E.S.P.
A8: PROPONENTE
A10: MES | B10: DEMANDA REQUERIDA DISPAC KWh | C10: DEMANDA PERIODO REQUERIDA DISPAC KWh | D10: PORCENTAJE (%) OFERTADO DE LA DEMANDA REQUERIDA | E10: DEMANDA OFERTADA KWh - MES | F10: DEMANDA PERIODO OFERTADA KWh | G10: PRECIO OFERTADO $ kWh (0.00)
A11: ENERO DE 2026 | B11: ='Despacho Horario Producto No, 2'!AD2 -> 4166702 | C11: =SUM(B11:B22) -> 38713630 | E11: =+$D$11*B11 -> 0 | F11: =SUM(E11:E22) -> 0
A12: FEBRERO DE 2026 | B12: ='Despacho Horario Producto No, 2'!AD5 -> 4120884.4 | E12: =+$D$11*B12 -> 0
A13: MARZO DE 2026 | B13: ='Despacho Horario Producto No, 2'!AD8 -> 4663890.8 | E13: =+$D$11*B13 -> 0
A14: ABRIL DE 2026 | B14: ='Despacho Horario Producto No, 2'!AD11 -> 4125328.2 | E14: =+$D$11*B14 -> 0
A15: MAYO DE 2026 | B15: ='Despacho Horario Producto No, 2'!AD14 -> 4694989 | E15: =+$D$11*B15 -> 0
A16: JUNIO DE 2026 | B16: ='Despacho Horario Producto No, 2'!AD17 -> 4033377.8 | E16: =+$D$11*B16 -> 0
A17: JULIO DE 2026 | B17: ='Despacho Horario Producto No, 2'!AD20 -> 4425238.2 | E17: =+$D$11*B17 -> 0
A18: AGOSTO DE 2026 | B18: ='Despacho Horario Producto No, 2'!AD23 -> 0 | E18: =+$D$11*B18 -> 0
A19: SEPTIEMBRE DE 2026 | B19: ='Despacho Horario Producto No, 2'!AD26 -> 0 | E19: =+$D$11*B19 -> 0
A20: OCTUBRE DE 2026 | B20: ='Despacho Horario Producto No, 2'!AD29 -> 0 | E20: =+$D$11*B20 -> 0
A21: NOVIEMBRE DE 2026 | B21: ='Despacho Horario Producto No, 2'!AD32 -> 4072572.2 | E21: =+$D$11*B21 -> 0
A22: DICIEMBRE DE 2026 | B22: ='Despacho Horario Producto No, 2'!AD35 -> 4410647.3 | E22: =+$D$11*B22 -> 0
A23: ENERO DE 2027 | B23: ='Despacho Horario Producto No, 2'!AD38 -> 4309001.1 | C23: =SUM(B23:B34) -> 33291869 | E23: =+$D$23*B23 -> 0 | F23: =SUM(E23:E34) -> 0
A24: FEBRERO DE 2027 | B24: ='Despacho Horario Producto No, 2'!AD41 -> 3102795.8 | E24: =+$D$23*B24 -> 0
A25: MARZO DE 2027 | B25: ='Despacho Horario Producto No, 2'!AD44 -> 3909486.4 | E25: =+$D$23*B25 -> 0
A26: ABRIL DE 2027 | B26: ='Despacho Horario Producto No, 2'!AD47 -> 3499668.7 | E26: =+$D$23*B26 -> 0
A27: MAYO DE 2027 | B27: ='Despacho Horario Producto No, 2'!AD50 -> 3990561.1 | E27: =+$D$23*B27 -> 0
A28: JUNIO DE 2027 | B28: ='Despacho Horario Producto No, 2'!AD53 -> 3355721.8 | E28: =+$D$23*B28 -> 0
A29: JULIO DE 2027 | B29: ='Despacho Horario Producto No, 2'!AD56 -> 3719326.8 | E29: =+$D$23*B29 -> 0
A30: AGOSTO DE 2027 | B30: ='Despacho Horario Producto No, 2'!AD59 -> 0 | E30: =+$D$23*B30 -> 0
A31: SEPTIEMBRE DE 2027 | B31: ='Despacho Horario Producto No, 2'!AD62 -> 0 | E31: =+$D$23*B31 -> 0
A32: OCTUBRE DE 2027 | B32: ='Despacho Horario Producto No, 2'!AD65 -> 0 | E32: =+$D$23*B32 -> 0
A33: NOVIEMBRE DE 2027 | B33: ='Despacho Horario Producto No, 2'!AD68 -> 3389657.3 | E33: =+$D$23*B33 -> 0
A34: DICIEMBRE DE 2027 | B34: ='Despacho Horario Producto No, 2'!AD71 -> 4015650.2 | E34: =+$D$23*B34 -> 0
A35: ENERO DE 2028 | B35: ='Despacho Horario Producto No, 2'!AD74 -> 4664066 | C35: =SUM(B35:B46) -> 49336295 | E35: =+$D$35*B35 -> 0 | F35: =SUM(E35:E46) -> 0
A36: FEBRERO DE 2028 | B36: ='Despacho Horario Producto No, 2'!AD77 -> 3763314.2 | E36: =+$D$35*B36 -> 0
A37: MARZO DE 2028 | B37: ='Despacho Horario Producto No, 2'!AD80 -> 4349346.7 | E37: =+$D$35*B37 -> 0
A38: ABRIL DE 2028 | B38: ='Despacho Horario Producto No, 2'!AD83 -> 3815278.6 | E38: =+$D$35*B38 -> 0
A39: MAYO DE 2028 | B39: ='Despacho Horario Producto No, 2'!AD86 -> 4368914.2 | E39: =+$D$35*B39 -> 0
A40: JUNIO DE 2028 | B40: ='Despacho Horario Producto No, 2'!AD89 -> 3724343.2 | E40: =+$D$35*B40 -> 0
A41: JULIO DE 2028 | B41: ='Despacho Horario Producto No, 2'!AD92 -> 4100617.1 | E41: =+$D$35*B41 -> 0
A42: AGOSTO DE 2028 | B42: ='Despacho Horario Producto No, 2'!AD95 -> 4242356.2 | E42: =+$D$35*B42 -> 0
A43: SEPTIEMBRE DE 2028 | B43: ='Despacho Horario Producto No, 2'!AD98 -> 3958090.5 | E43: =+$D$35*B43 -> 0
A44: OCTUBRE DE 2028 | B44: ='Despacho Horario Producto No, 2'!AD101 -> 4205647.1 | E44: =+$D$35*B44 -> 0
A45: NOVIEMBRE DE 2028 | B45: ='Despacho Horario Producto No, 2'!AD104 -> 3758465 | E45: =+$D$35*B45 -> 0
A46: DICIEMBRE DE 2028 | B46: ='Despacho Horario Producto No, 2'!AD107 -> 4385856.1 | E46: =+$D$35*B46 -> 0
A47: ENERO DE 2029 | B47: ='Despacho Horario Producto No, 2'!AD110 -> 5070005.8 | C47: =SUM(B47:B58) -> 53544167 | E47: =+$D$47*B47 -> 0 | F47: =SUM(E47:E58) -> 0
...

Sheet Despacho Horario Producto No, 2
A1: Año | B1: Mes | C1: # días | D1: TPD | E1: H1 | F1: H2 | G1: H3 | H1: H4 | I1: H5 | J1: H6 | K1: H7 | L1: H8 | M1: H9 | N1: H10 | O1: H11 | P1: H12 | Q1: H13 | R1: H14 | S1: H15 | T1: H16 | U1: H17 | V1: H18 | W1: H19 | X1: H20 | Y1: H21 | Z1: H22 | AA1: H23 | AB1: H24 | AC1: kWh/d | AD1: kWh/mes
A2: 2026 | B2: 1 | C2: 6 | D2: Festivo | E2: 3492.3228 | F2: 2788.9359 | G2: 2232.8087 | H2: 1904.4924 | I2: 1744.5994 | J2: 1748.2336 | K2: 1614.8319 | L2: 2366.3359 | M2: 3490.5116 | N2: 4492.667 | O2: 4982.3334 | P2: 5650.0256 | Q2: 6149.8096 | R2: 6108.4311 | S2: 5447.5972 | T2: 5160.4368 | U2: 4926.5063 | V2: 4811.8723 | W2: 6413.3869 | X2: 7702.4791 | Y2: 7586.1546 | Z2: 6653.7126 | AA2: 5384.1357 | AB2: 4212.4385 | AC2: 107065.06 | AD2: =+SUMPRODUCT(AC2:AC4,C2:C4) -> 4166702
A3: 2026 | B3: 1 | C3: 20 | D3: Hábil | E3: 3554.4765 | F3: 2894.8443 | G3: 2360.7787 | H3: 2015.7464 | I3: 1960.4837 | J3: 2354.0223 | K3: 2811.4721 | L3: 4014.3453 | M3: 5724.6639 | N3: 6594.9933 | O3: 7303.1893 | P3: 8290.4465 | Q3: 8405.3837 | R3: 8288.0915 | S3: 8230.2361 | T3: 8080.6593 | U3: 7963.6105 | V3: 7448.5901 | W3: 8224.167 | X3: 9115.3639 | Y3: 8792.6934 | Z3: 7717.9754 | AA3: 6181.8572 | AB3: 4734.6307 | AC3: 143062.72
A4: 2026 | B4: 1 | C4: 5 | D4: Sábado | E4: 3324.9927 | F4: 2625.6047 | G4: 2261.514 | H4: 1949.6499 | I4: 1654.769 | J4: 1758.5466 | K4: 1871.7617 | L4: 3140.9481 | M4: 4932.3031 | N4: 5859.6888 | O4: 6680.6026 | P4: 7596.7138 | Q4: 8009.6581 | R4: 7895.8207 | S4: 7615.9551 | T4: 7390.9658 | U4: 7048.0783 | V4: 6846.3585 | W4: 7961.6813 | X4: 8881.6315 | Y4: 8527.084 | Z4: 7630.8781 | AA4: 6233.4657 | AB4: 4912.7715 | AC4: 132611.44
A5: 2026 | B5: 2 | C5: 4 | D5: Festivo | E5: 3981.6918 | F5: 3275.2529 | G5: 2748.4648 | H5: 2282.0927 | I5: 1666.4552 | J5: 1539.8202 | K5: 1813.1707 | L5: 3118.4516 | M5: 4588.6554 | N5: 5506.0067 | O5: 6090.416 | P5: 6824.1105 | Q5: 7435.1075 | R5: 7310.5979 | S5: 6655.5756 | T5: 6116.0513 | U5: 5837.7361 | V5: 5533.1604 | W5: 6753.2891 | X5: 8068.7136 | Y5: 8171.2729 | Z5: 7222.4043 | AA5: 5661.0142 | AB5: 4223.6012 | AC5: 122423.11 | AD5: =+SUMPRODUCT(AC5:AC7,C5:C7) -> 4120884.4
A6: 2026 | B6: 2 | C6: 20 | D6: Hábil | E6: 3419.974 | F6: 2853.0529 | G6: 2384.566 | H6: 2139.5607 | I6: 2094.993 | J6: 2859.0669 | K6: 3620.4027 | L6: 4481.4742 | M6: 6033.6386 | N6: 6798.1565 | O6: 7581.6241 | P6: 8590.8742 | Q6: 8648.5125 | R6: 8611.2485 | S6: 8986.53 | T6: 8952.3072 | U6: 8788.742 | V6: 8325.9646 | W6: 8892.22 | X6: 9980.6752 | Y6: 9538.9197 | Z6: 7730.711 | AA6: 6180.0468 | AB6: 4579.8583 | AC6: 152073.12
A7: 2026 | B7: 2 | C7: 4 | D7: Sábado | E7: 3758.8194 | F7: 3034.7636 | G7: 2562.6995 | H7: 1915.2654 | I7: 2071.0271 | J7: 2334.8436 | K7: 2700.0241 | L7: 4200.0351 | M7: 5574.0418 | N7: 6367.3833 | O7: 7382.8064 | P7: 8107.9439 | Q7: 8714.0658 | R7: 8543.3406 | S7: 8161.0022 | T7: 8198.847 | U7: 7998.0373 | V7: 7718.7217 | W7: 8463.5848 | X7: 9568.2738 | Y7: 9310.551 | Z7: 8337.6407 | AA7: 6937.8625 | AB7: 5470.8077 | AC7: 147432.39
A8: 2026 | B8: 3 | C8: 6 | D8: Festivo | E8: 3043.7496 | F8: 3285.9474 | G8: 2514.6548 | H8: 2155.6465 | I8: 2028.0201 | J8: 2067.3892 | K8: 2077.8047 | L8: 3070.7487 | M8: 4636.064 | N8: 5440.8192 | O8: 6147.9689 | P8: 7017.1765 | Q8: 7660.1254 | R8: 7322.7644 | S8: 4893.8854 | T8: 5939.2751 | U8: 5626.5105 | V8: 5483.6219 | W8: 6939.9727 | X8: 9212.9593 | Y8: 9312.4369 | Z8: 8591.6775 | AA8: 7267.1733 | AB8: 5642.7507 | AC8: 127379.14 | AD8: =+SUMPRODUCT(AC8:AC10,C8:C10) -> 4663890.8
A9: 2026 | B9: 3 | C9: 21 | D9: Hábil | E9: 3887.2575 | F9: 3200.429 | G9: 2706.4874 | H9: 2393.6843 | I9: 2268.6524 | J9: 2984.3771 | K9: 3762.6246 | L9: 4731.3206 | M9: 6358.5091 | N9: 7195.0473 | O9: 7812.2002 | P9: 8669.185 | Q9: 8681.2272 | R9: 8649.3973 | S9: 8739.2021 | T9: 8850.0596 | U9: 8848.087 | V9: 8292.0945 | W9: 9085.1395 | X9: 10183.022 | Y9: 9797.3167 | Z9: 8621.6098 | AA9: 6819.6522 | AB9: 5188.6077 | AC9: 157725.19
A10: 2026 | B10: 3 | C10: 4 | D10: Sábado | E10: 4087.9557 | F10: 3217.7579 | G10: 2747.095 | H10: 2454.2012 | I10: 2331.6434 | J10: 2458.4716 | K10: 2541.1581 | L10: 3788.9613 | M10: 6288.7973 | N10: 7206.3328 | O10: 7751.7627 | P10: 8504.4838 | Q10: 8763.1971 | R10: 8501.7549 | S10: 8283.4742 | T10: 8114.084 | U10: 7784.3191 | V10: 7513.1054 | W10: 8623.4447 | X10: 9632.2023 | Y10: 9336.8113 | Z10: 7099.7934 | AA10: 5682.7261 | AB10: 4133.1983 | AC10: 146846.73
A11: 2026 | B11: 4 | C11: 6 | D11: Festivo | E11: 3295.587 | F11: 2519.7151 | G11: 2163.3523 | H11: 1708.7226 | I11: 1580.6571 | J11: 1567.6905 | K11: 1576.3892 | L11: 2707.8696 | M11: 4261.3756 | N11: 5272.1971 | O11: 6003.2942 | P11: 6839.8573 | Q11: 7467.3934 | R11: 7266.4919 | S11: 6349.7292 | T11: 5819.9546 | U11: 5489.8615 | V11: 5471.1336 | W11: 7034.1433 | X11: 8213.8399 | Y11: 7903.7852 | Z11: 6985.5384 | AA11: 5421.8773 | AB11: 3959.2883 | AC11: 116879.74 | AD11: =+SUMPRODUCT(AC11:AC13,C11:C13) -> 4125328.2
A12: 2026 | B12: 4 | C12: 20 | D12: Hábil | E12: 2949.6345 | F12: 2215.4495 | G12: 1847.4648 | H12: 1535.1662 | I12: 1441.9752 | J12: 2169.2516 | K12: 2934.0929 | L12: 4094.5275 | M12: 5678.3364 | N12: 6433.5951 | O12: 6927.8383 | P12: 8020.1506 | Q12: 8074.9784 | R12: 8348.4156 | S12: 8876.2349 | T12: 9030.1107 | U12: 8789.9768 | V12: 8353.6675 | W12: 9125.4642 | X12: 9929.0425 | Y12: 9348.338 | Z12: 8078.5015 | AA12: 6339.8037 | AB12: 4269.5514 | AC12: 144811.57
A13: 2026 | B13: 4 | C13: 4 | D13: Sábado | E13: 3420.7339 | F13: 2778.08 | G13: 2215.9452 | H13: 1864.3387 | I13: 882.83167 | J13: 1936.7423 | K13: 2041.6874 | L13: 3535.3773 | M13: 5496.6353 | N13: 6510.515 | O13: 7143.8771 | P13: 8129.3388 | Q13: 8396.9423 | R13: 8106.3581 | S13: 7672.6348 | T13: 7084.3284 | U13: 6780.7653 | V13: 6710.9325 | W13: 7890.0009 | X13: 8490.1011 | Y13: 8182.6102 | Z13: 7145.3836 | AA13: 5605.4035 | AB13: 3933.0183 | AC13: 131954.58
A14: 2026 | B14: 5 | C14: 7 | D14: Festivo | E14: 4242.5333 | F14: 3340.8988 | G14: 2932.621 | H14: 2659.5508 | I14: 2468.229 | J14: 2543.7633 | K14: 2631.5765 | L14: 3937.1456 | M14: 5623.9345 | N14: 6735.6517 | O14: 7505.4023 | P14: 8337.4877 | Q14: 8861.5176 | R14: 8689.5859 | S14: 7928.6044 | T14: 7437.3608 | U14: 7007.4595 | V14: 7124.9051 | W14: 8507.9376 | X14: 9363.1347 | Y14: 9226.8087 | Z14: 8032.0366 | AA14: 6389.4506 | AB14: 5016.54 | AC14: 146544.14 | AD14: =+SUMPRODUCT(AC14:AC16,C14:C16) -> 4694989
A15: 2026 | B15: 5 | C15: 19 | D15: Hábil | E15: 3352.3766 | F15: 2711.9769 | G15: 2241.8626 | H15: 2016.0595 | I15: 1846.2587 | J15: 2533.5279 | K15: 3270.9655 | L15: 4483.8043 | M15: 5992.6532 | N15: 6940.9868 | O15: 7713.4889 | P15: 8645.4888 | Q15: 8843.7429 | R15: 8943.3414 | S15: 9125.1625 | T15: 9050.3039 | U15: 8934.046 | V15: 8585.6801 | W15: 9469.0279 | X15: 10214.03 | Y15: 9681.2787 | Z15: 8147.2387 | AA15: 6337.2154 | AB15: 4643.5632 | AC15: 153724.08
A16: 2026 | B16: 5 | C16: 5 | D16: Sábado | E16: 3682.4701 | F16: 2964.4443 | G16: 2507.4286 | H16: 2186.5242 | I16: 2077.7838 | J16: 2067.0518 | K16: 2352.6495 | L16: 4051.7276 | M16: 6097.5257 | N16: 7402.8168 | O16: 8472.6684 | P16: 8895.1445 | Q16: 9366.8827 | R16: 9119.3766 | S16: 8615.3794 | T16: 8342.6186 | U16: 7759.9078 | V16: 7738.895 | W16: 8097.364 | X16: 9292.2789 | Y16: 8894.5675 | Z16: 7867.4331 | AA16: 6531.6654 | AB16: 5299.9047 | AC16: 149684.51
A17: 2026 | B17: 6 | C17: 6 | D17: Festivo | E17: 3496.7475 | F17: 2877.2798 | G17: 2353.2234 | H17: 1945.8228 | I17: 869.751 | J17: 1495.5644 | K17: 1529.7122 | L17: 2743.587 | M17: 4239.3981 | N17: 5148.2759 | O17: 5690.0059 | P17: 6217.6838 | Q17: 6818.0812 | R17: 6512.8606 | S17: 5968.7229 | T17: 5416.2062 | U17: 5103.0546 | V17: 5474.1306 | W17: 6885.4434 | X17: 8049.1678 | Y17: 7759.4566 | Z17: 6613.9377 | AA17: 5432.5667 | AB17: 4161.0967 | AC17: 112801.78 | AD17: =+SUMPRODUCT(AC17:AC19,C17:C19) -> 4033377.8
A18: 2026 | B18: 6 | C18: 20 | D18: Hábil | E18: 2787.0521 | F18: 2208.769 | G18: 1703.7615 | H18: 1444.514 | I18: 1386.6073 | J18: 1829.2487 | K18: 2536.9872 | L18: 4162.3702 | M18: 6109.3994 | N18: 6903.3298 | O18: 7586.425 | P18: 8916.4469 | Q18: 9123.0992 | R18: 8702.248 | S18: 8476.5747 | T18: 8307.7895 | U18: 8058.0329 | V18: 7771.9503 | W18: 8406.5891 | X18: 9081.644 | Y18: 8489.2025 | Z18: 7156.853 | AA18: 5521.1199 | AB18: 3941.3002 | AC18: 140611.31
A19: 2026 | B19: 6 | C19: 4 | D19: Sábado | E19: 3316.251 | F19: 2746.4229 | G19: 2142.7735 | H19: 1826.1572 | I19: 1715.7727 | J19: 1894.4693 | K19: 2216.9405 | L19: 3688.704 | M19: 5637.8445 | N19: 6576.7296 | O19: 7282.0606 | P19: 8175.028 | Q19: 8222.3346 | R19: 7864.1387 | S19: 7415.5986 | T19: 6992.3816 | U19: 6967.1737 | V19: 7219.158 | W19: 8260.0255 | X19: 9066.3839 | Y19: 8680.996 | Z19: 7461.4805 | AA19: 6055.716 | AB19: 4660.6604 | AC19: 136085.2
A20: 2026 | B20: 7 | C20: 6 | D20: Festivo | E20: 3226.7132 | F20: 2609.5696 | G20: 2086.0175 | H20: 1770.6324 | I20: 1626.6937 | J20: 1777.2643 | K20: 1757.7717 | L20: 3078.5144 | M20: 4666.4132 | N20: 5841.028 | O20: 6515.8113 | P20: 7575.0465 | Q20: 8229.8972 | R20: 8038.1315 | S20: 7415.694 | T20: 7031.6081 | U20: 6736.6876 | V20: 6582.1507 | W20: 7491.4699 | X20: 8745.0713 | Y20: 8204.8437 | Z20: 6902.9699 | AA20: 5409.0594 | AB20: 3954.9185 | AC20: 127273.98 | AD20: =+SUMPRODUCT(AC20:AC22,C20:C22) -> 4425238.2
A21: 2026 | B21: 7 | C21: 21 | D21: Hábil | E21: 3175.267 | F21: 2586.6833 | G21: 2097.7725 | H21: 1759.4579 | I21: 1733.3783 | J21: 2408.1888 | K21: 3139.3883 | L21: 4434.0955 | M21: 5912.3169 | N21: 6787.969 | O21: 7725.6503 | P21: 8675.614 | Q21: 8720.7075 | R21: 8912.6361 | S21: 9102.9684 | T21: 8306.8506 | U21: 8008.0017 | V21: 8081.513 | W21: 8803.6661 | X21: 9890.0088 | Y21: 9294.2821 | Z21: 7805.2064 | AA21: 5767.9544 | AB21: 4068.9149 | AC21: 147198.49
A22: 2026 | B22: 7 | C22: 4 | D22: Sábado | E22: 2544.1781 | F22: 1837.3856 | G22: 1379.0144 | H22: 1032.3066 | I22: 1040.5786 | J22: 1233.7899 | K22: 1589.7596 | L22: 3219.4358 | M22: 5398.9314 | N22: 6836.1708 | O22: 7956.9249 | P22: 8963.3134 | Q22: 9550.6497 | R22: 9331.1281 | S22: 8929.4635 | T22: 8622.6799 | U22: 8299.1848 | V22: 7971.5976 | W22: 8634.8932 | X22: 9592.5455 | Y22: 9052.9552 | Z22: 8058.8157 | AA22: 6550.9441 | AB22: 4979.8605 | AC22: 142606.51
A23: 2026 | B23: 8 | C23: 7 | D23: Festivo | E23: 0 | F23: 0 | G23: 0 | H23: 0 | I23: 0 | J23: 0 | K23: 0 | L23: 0 | M23: 0 | N23: 0 | O23: 0 | P23: 0 | Q23: 0 | R23: 0 | S23: 0 | T23: 0 | U23: 0 | V23: 0 | W23: 0 | X23: 0 | Y23: 0 | Z23: 0 | AA23: 0 | AB23: 0 | AC23: 0 | AD23: =+SUMPRODUCT(AC23:AC25,C23:C25) -> 0
A24: 2026 | B24: 8 | C24: 19 | D24: Hábil | E24: 0 | F24: 0 | G24: 0 | H24: 0 | I24: 0 | J24: 0 | K24: 0 | L24: 0 | M24: 0 | N24: 0 | O24: 0 | P24: 0 | Q24: 0 | R24: 0 | S24: 0 | T24: 0 | U24: 0 | V24: 0 | W24: 0 | X24: 0 | Y24: 0 | Z24: 0 | AA24: 0 | AB24: 0 | AC24: 0
A25: 2026 | B25: 8 | C25: 5 | D25: Sábado | E25: 0 | F25: 0 | G25: 0 | H25: 0 | I25: 0 | J25: 0 | K25: 0 | L25: 0 | M25: 0 | N25: 0 | O25: 0 | P25: 0 | Q25: 0 | R25: 0 | S25: 0 | T25: 0 | U25: 0 | V25: 0 | W25: 0 | X25: 0 | Y25: 0 | Z25: 0 | AA25: 0 | AB25: 0 | AC25: 0
A26: 2026 | B26: 9 | C26: 4 | D26: Festivo | E26: 0 | F26: 0 | G26: 0 | H26: 0 | I26: 0 | J26: 0 | K26: 0 | L26: 0 | M26: 0 | N26: 0 | O26: 0 | P26: 0 | Q26: 0 | R26: 0 | S26: 0 | T26: 0 | U26: 0 | V26: 0 | W26: 0 | X26: 0 | Y26: 0 | Z26: 0 | AA26: 0 | AB26: 0 | AC26: 0 | AD26: =+SUMPRODUCT(AC26:AC28,C26:C28) -> 0
A27: 2026 | B27: 9 | C27: 22 | D27: Hábil | E27: 0 | F27: 0 | G27: 0 | H27: 0 | I27: 0 | J27: 0 | K27: 0 | L27: 0 | M27: 0 | N27: 0 | O27: 0 | P27: 0 | Q27: 0 | R27: 0 | S27: 0 | T27: 0 | U27: 0 | V27: 0 | W27: 0 | X27: 0 | Y27: 0 | Z27: 0 | AA27: 0 | AB27: 0 | AC27: 0
A28: 2026 | B28: 9 | C28: 4 | D28: Sábado | E28: 0 | F28: 0 | G28: 0 | H28: 0 | I28: 0 | J28: 0 | K28: 0 | L28: 0 | M28: 0 | N28: 0 | O28: 0 | P28: 0 | Q28: 0 | R28: 0 | S28: 0 | T28: 0 | U28: 0 | V28: 0 | W28: 0 | X28: 0 | Y28: 0 | Z28: 0 | AA28: 0 | AB28: 0 | AC28: 0
A29: 2026 | B29: 10 | C29: 5 | D29: Festivo | E29: 0 | F29: 0 | G29: 0 | H29: 0 | I29: 0 | J29: 0 | K29: 0 | L29: 0 | M29: 0 | N29: 0 | O29: 0 | P29: 0 | Q29: 0 | R29: 0 | S29: 0 | T29: 0 | U29: 0 | V29: 0 | W29: 0 | X29: 0 | Y29: 0 | Z29: 0 | AA29: 0 | AB29: 0 | AC29: 0 | AD29: =+SUMPRODUCT(AC29:AC31,C29:C31) -> 0
A30: 2026 | B30: 10 | C30: 21 | D30: Hábil | E30: 0 | F30: 0 | G30: 0 | H30: 0 | I30: 0 | J30: 0 | K30: 0 | L30: 0 | M30: 0 | N30: 0 | O30: 0 | P30: 0 | Q30: 0 | R30: 0 | S30: 0 | T30: 0 | U30: 0 | V30: 0 | W30: 0 | X30: 0 | Y30: 0 | Z30: 0 | AA30: 0 | AB30: 0 | AC30: 0
A31: 2026 | B31: 10 | C31: 5 | D31: Sábado | E31: 0 | F31: 0 | G31: 0 | H31: 0 | I31: 0 | J31: 0 | K31: 0 | L31: 0 | M31: 0 | N31: 0 | O31: 0 | P31: 0 | Q31: 0 | R31: 0 | S31: 0 | T31: 0 | U31: 0 | V31: 0 | W31: 0 | X31: 0 | Y31: 0 | Z31: 0 | AA31: 0 | AB31: 0 | AC31: 0
A32: 2026 | B32: 11 | C32: 7 | D32: Festivo | E32: 3113.7894 | F32: 2372.6581 | G32: 1766.4824 | H32: 1579.4036 | I32: 1370.1005 | J32: 1524.7243 | K32: 1683.9559 | L32: 3021.8528 | M32: 4723.7959 | N32: 5697.2286 | O32: 6383.7284 | P32: 7321.6981 | Q32: 7865.0977 | R32: 7613.1262 | S32: 6640.2264 | T32: 6116.7901 | U32: 5840.2224 | V32: 6140.4288 | W32: 8192.6519 | X32: 8287.9482 | Y32: 7841.4254 | Z32: 6667.9976 | AA32: 5148.8977 | AB32: 3688.3144 | AC32: 120602.54 | AD32: =+SUMPRODUCT(AC32:AC34,C32:C34) -> 4072572.2
A33: 2026 | B33: 11 | C33: 19 | D33: Hábil | E33: 2902.3608 | F33: 2236.221 | G33: 1830.196 | H33: 1481.4357 | I33: 1433.1717 | J33: 2080.5676 | K33: 3074.21 | L33: 4477.8611 | M33: 5965.5098 | N33: 7008.7311 | O33: 7686.2896 | P33: 8600.3968 | Q33: 8564.853 | R33: 8582.0554 | S33: 8423.4125 | T33: 8407.5312 | U33: 8151.1912 | V33: 7949.0319 | W33: 9308.5242 | X33: 9215.7889 | Y33: 8487.67 | Z33: 7115.0539 | AA33: 5411.3322 | AB33: 3851.9607 | AC33: 142245.36
A34: 2026 | B34: 11 | C34: 4 | D34: Sábado | E34: 2624.7841 | F34: 2017.8629 | G34: 1509.9547 | H34: 775.3193 | I34: 782.51624 | J34: 1397.3699 | K34: 1886.2053 | L34: 3396.4827 | M34: 5480.7824 | N34: 6577.9593 | O34: 7383.6113 | P34: 8163.9463 | Q34: 8506.7264 | R34: 8204.6074 | S34: 7767.6941 | T34: 7376.8831 | U34: 6899.0521 | V34: 7214.2412 | W34: 8967.9606 | X34: 8927.9449 | Y34: 8303.3039 | Z34: 7131.7514 | AA34: 5819.2203 | AB34: 4306.9623 | AC34: 131423.14
A35: 2026 | B35: 12 | C35: 6 | D35: Festivo | E35: 3915.3174 | F35: 3042.3495 | G35: 2493.8058 | H35: 2091.8877 | I35: 1862.277 | J35: 1872.6364 | K35: 2068.1522 | L35: 3115.9657 | M35: 4478.7353 | N35: 5436.3621 | O35: 6108.4835 | P35: 6786.4432 | Q35: 7333.8488 | R35: 7346.5459 | S35: 6768.8542 | T35: 6263.5221 | U35: 5961.2372 | V35: 6077.5099 | W35: 7711.4539 | X35: 8055.2744 | Y35: 7657.5348 | Z35: 6810.1334 | AA35: 5552.2166 | AB35: 4175.9093 | AC35: 122986.46 | AD35: =+SUMPRODUCT(AC35:AC37,C35:C37) -> 4410647.3
A36: 2026 | B36: 12 | C36: 21 | D36: Hábil | E36: 3520.7343 | F36: 2852.5905 | G36: 2350.5638 | H36: 2015.3999 | I36: 1955.3027 | J36: 2350.3173 | K36: 3038.7292 | L36: 4654.265 | M36: 5994.4399 | N36: 6582.4382 | O36: 8168.5711 | P36: 7968.8136 | Q36: 8448.8046 | R36: 8137.9128 | S36: 8069.9543 | T36: 8490.4501 | U36: 8248.7913 | V36: 8402.3736 | W36: 9717.7298 | X36: 9792.2238 | Y36: 9096.6279 | Z36: 7853.5308 | AA36: 6249.5726 | AB36: 4704.858 | AC36: 148665
A37: 2026 | B37: 12 | C37: 4 | D37: Sábado | E37: 3408.0603 | F37: 2614.6337 | G37: 2148.6254 | H37: 1734.8188 | I37: 1561.9077 | J37: 1688.6582 | K37: 2253.7817 | L37: 3589.4368 | M37: 5485.411 | N37: 6548.4477 | O37: 7252.4285 | P37: 7938.8174 | Q37: 8118.8801 | R37: 7915.642 | S37: 7619.4233 | T37: 7443.2891 | U37: 7250.8407 | V37: 7438.2059 | W37: 9036.1063 | X37: 9311.792 | Y37: 8566.2188 | Z37: 7508.9657 | AA37: 6305.7988 | AB37: 4950.7228 | AC37: 137690.91
A38: 2027 | B38: 1 | C38: 7 | D38: Festivo | E38: 3705.3628 | F38: 2992.8899 | G38: 2429.5789 | H38: 2097.0215 | I38: 1935.0631 | J38: 1938.7443 | K38: 1803.6194 | L38: 2564.831 | M38: 3703.5282 | N38: 4718.629 | O38: 5214.6206 | P38: 5890.9377 | Q38: 6397.1778 | R38: 6355.2647 | S38: 5685.8945 | T38: 5395.0246 | U38: 5158.0723 | V38: 5041.9575 | W38: 6664.1598 | X38: 7969.9039 | Y38: 7852.0767 | Z38: 6907.5899 | AA38: 5621.6132 | AB38: 4434.7806 | AC38: 112478.34 | AD38: =+SUMPRODUCT(AC38:AC40,C38:C40) -> 4309001.1
A39: 2027 | B39: 1 | C39: 19 | D39: Hábil | E39: 3768.3193 | F39: 3100.1663 | G39: 2559.2019 | H39: 2209.7127 | I39: 2153.7362 | J39: 2552.3582 | K39: 3015.7172 | L39: 4234.1286 | M39: 5966.5402 | N39: 6848.1121 | O39: 7565.4563 | P39: 8565.4664 | Q39: 8681.8882 | R39: 8563.0809 | S39: 8504.4781 | T39: 8352.9692 | U39: 8234.4085 | V39: 7712.7353 | W39: 8498.3307 | X39: 9401.0397 | Y39: 9074.2011 | Z39: 7985.6004 | AA39: 6429.6393 | AB39: 4963.7182 | AC39: 148941
A40: 2027 | B40: 1 | C40: 5 | D40: Sábado | E40: 3535.8712 | F40: 2827.4488 | G40: 2458.655 | H40: 2142.7624 | I40: 1844.0724 | J40: 1949.1904 | K40: 2063.868 | L40: 3349.4492 | M40: 5163.9441 | N40: 6103.3093 | O40: 6934.8273 | P40: 7862.7723 | Q40: 8281.0508 | R40: 8165.743 | S40: 7882.2622 | T40: 7654.3666 | U40: 7307.0499 | V40: 7102.7243 | W40: 8232.4543 | X40: 9164.288 | Y40: 8805.1607 | Z40: 7897.3779 | AA40: 6481.9145 | AB40: 5144.1602 | AC40: 138354.72
...

Sheet Producto No. 3 Curva 2026-2035
A5: ANEXO No. 1. Oferta Producto No. 3 Curva (junio de 2026 a diciembre año 2035) Convocatoria Pública DISPAC S.A. E.S.P.
A8: PROPONENTE
A10: MES | B10: DEMANDA REQUERIDA DISPAC KWh | C10: DEMANDA PERIODO REQUERIDA DISPAC KWh | D10: PORCENTAJE (%) OFERTADO DE LA DEMANDA REQUERIDA | E10: DEMANDA OFERTADA KWh - MES | F10: DEMANDA PERIODO OFERTADA KWh | G10: PRECIO OFERTADO $ kWh (0.00)
A11: JUNIO DE 2026 | B11: =+'Despacho Horario Producto No. 3'!AB2 -> 1752241.1 | C11: =+SUM(B11:B17) -> 12562647 | E11: =+$D$11*B11 -> 0 | F11: =+SUM(E11:E17) -> 0
A12: JULIO DE 2026 | B12: =+'Despacho Horario Producto No. 3'!AB3 -> 1816398 | E12: =+$D$11*B12 -> 0
A13: AGOSTO DE 2026 | B13: =+'Despacho Horario Producto No. 3'!AB4 -> 1814297 | E13: =+$D$11*B13 -> 0
A14: SEPTIEMBRE DE 2026 | B14: =+'Despacho Horario Producto No. 3'!AB5 -> 1770367.8 | E14: =+$D$11*B14 -> 0
A15: OCTUBRE DE 2026 | B15: =+'Despacho Horario Producto No. 3'!AB6 -> 1808727.3 | E15: =+$D$11*B15 -> 0
A16: NOVIEMBRE DE 2026 | B16: =+'Despacho Horario Producto No. 3'!AB7 -> 1754745.6 | E16: =+$D$11*B16 -> 0
A17: DICIEMBRE DE 2026 | B17: =+'Despacho Horario Producto No. 3'!AB8 -> 1845870.6 | E17: =+$D$11*B17 -> 0
A18: ENERO DE 2027 | B18: =+'Despacho Horario Producto No. 3'!AB9 -> 1864971.9 | C18: =SUM(B18:B29) -> 21906724 | E18: =+$D$18*B18 -> 0 | F18: =SUM(E18:E29) -> 0
A19: FEBRERO DE 2027 | B19: =+'Despacho Horario Producto No. 3'!AB10 -> 1697293.2 | E19: =+$D$18*B19 -> 0
A20: MARZO DE 2027 | B20: =+'Despacho Horario Producto No. 3'!AB11 -> 1860913.9 | E20: =+$D$18*B20 -> 0
A21: ABRIL DE 2027 | B21: =+'Despacho Horario Producto No. 3'!AB12 -> 1798120.2 | E21: =+$D$18*B21 -> 0
A22: MAYO DE 2027 | B22: =+'Despacho Horario Producto No. 3'!AB13 -> 1861354 | E22: =+$D$18*B22 -> 0
A23: JUNIO DE 2027 | B23: =+'Despacho Horario Producto No. 3'!AB14 -> 1789118.5 | E23: =+$D$18*B23 -> 0
A24: JULIO DE 2027 | B24: =+'Despacho Horario Producto No. 3'!AB15 -> 1854369.5 | E24: =+$D$18*B24 -> 0
A25: AGOSTO DE 2027 | B25: =+'Despacho Horario Producto No. 3'!AB16 -> 1852159.3 | E25: =+$D$18*B25 -> 0
A26: SEPTIEMBRE DE 2027 | B26: =+'Despacho Horario Producto No. 3'!AB17 -> 1806857.2 | E26: =+$D$18*B26 -> 0
A27: OCTUBRE DE 2027 | B27: =+'Despacho Horario Producto No. 3'!AB18 -> 1846490.7 | E27: =+$D$18*B27 -> 0
A28: NOVIEMBRE DE 2027 | B28: =+'Despacho Horario Producto No. 3'!AB19 -> 1791306.1 | E28: =+$D$18*B28 -> 0
A29: DICIEMBRE DE 2027 | B29: =+'Despacho Horario Producto No. 3'!AB20 -> 1883769.6 | E29: =+$D$18*B29 -> 0
A30: ENERO DE 2028 | B30: =+'Despacho Horario Producto No. 3'!AB21 -> 1902739.3 | C30: =SUM(B30:B41) -> 22413439 | E30: =+$D$30*B30 -> 0 | F30: =SUM(E30:E41) -> 0
A31: FEBRERO DE 2028 | B31: =+'Despacho Horario Producto No. 3'!AB22 -> 1793344.4 | E31: =+$D$30*B31 -> 0
A32: MARZO DE 2028 | B32: =+'Despacho Horario Producto No. 3'!AB23 -> 1898745.8 | E32: =+$D$30*B32 -> 0
A33: ABRIL DE 2028 | B33: =+'Despacho Horario Producto No. 3'!AB24 -> 1834698.4 | E33: =+$D$30*B33 -> 0
A34: MAYO DE 2028 | B34: =+'Despacho Horario Producto No. 3'!AB25 -> 1899138.2 | E34: =+$D$30*B34 -> 0
A35: JUNIO DE 2028 | B35: =+'Despacho Horario Producto No. 3'!AB26 -> 1825676.8 | E35: =+$D$30*B35 -> 0
A36: JULIO DE 2028 | B36: =+'Despacho Horario Producto No. 3'!AB27 -> 1892139.7 | E36: =+$D$30*B36 -> 0
A37: AGOSTO DE 2028 | B37: =+'Despacho Horario Producto No. 3'!AB28 -> 1889924.1 | E37: =+$D$30*B37 -> 0
A38: SEPTIEMBRE DE 2028 | B38: =+'Despacho Horario Producto No. 3'!AB29 -> 1843396.4 | E38: =+$D$30*B38 -> 0
A39: OCTUBRE DE 2028 | B39: =+'Despacho Horario Producto No. 3'!AB30 -> 1884250.7 | E39: =+$D$30*B39 -> 0
A40: NOVIEMBRE DE 2028 | B40: =+'Despacho Horario Producto No. 3'!AB31 -> 1827848.7 | E40: =+$D$30*B40 -> 0
A41: DICIEMBRE DE 2028 | B41: =+'Despacho Horario Producto No. 3'!AB32 -> 1921536.3 | E41: =+$D$30*B41 -> 0
A42: ENERO DE 2029 | B42: =+'Despacho Horario Producto No. 3'!AB33 -> 1940499.5 | C42: =SUM(B42:B53) -> 22796204 | E42: =+$D$42*B42 -> 0 | F42: =SUM(E42:E53) -> 0
A43: FEBRERO DE 2029 | B43: =+'Despacho Horario Producto No. 3'!AB34 -> 1765615.8 | E43: =+$D$42*B43 -> 0
A44: MARZO DE 2029 | B44: =+'Despacho Horario Producto No. 3'!AB35 -> 1936509.1 | E44: =+$D$42*B44 -> 0
A45: ABRIL DE 2029 | B45: =+'Despacho Horario Producto No. 3'!AB36 -> 1871241.9 | E45: =+$D$42*B45 -> 0
A46: MAYO DE 2029 | B46: =+'Despacho Horario Producto No. 3'!AB37 -> 1936899.2 | E46: =+$D$42*B46 -> 0
A47: JUNIO DE 2029 | B47: =+'Despacho Horario Producto No. 3'!AB38 -> 1862219.3 | E47: =+$D$42*B47 -> 0
...

Sheet Despacho Horario Producto No. 3
A1: Año | B1: Mes | C1: Total Mes | D1: H1 | E1: H2 | F1: H3 | G1: H4 | H1: H5 | I1: H6 | J1: H7 | K1: H8 | L1: H9 | M1: H10 | N1: H11 | O1: H12 | P1: H13 | Q1: H14 | R1: H15 | S1: H16 | T1: H17 | U1: H18 | V1: H19 | W1: H20 | X1: H21 | Y1: H22 | Z1: H23 | AA1: H24 | AB1: kWh/mes
A2: =+YEAR(B2) -> 2026 | B2: 46174 | C2: 1752241.1 | D2: 0 | E2: 0 | F2: 0 | G2: 0 | H2: 0 | I2: 1.3751514 | J2: 221.84282 | K2: 2256.6262 | L2: 4960.2043 | M2: 6407.6538 | N2: 7181.2815 | O2: 7378.0394 | P2: 7318.0573 | Q2: 6945.3204 | R2: 6408.609 | S2: 5441.9307 | T2: 3261.8619 | U2: 624.5931 | V2: 0.64062085 | W2: 0 | X2: 0 | Y2: 0 | Z2: 0 | AA2: 0 | AB2: =SUM(D2:AA2)*_xlfn.DAYS(B3,B2) -> 1752241.1
A3: =+YEAR(B3) -> 2026 | B3: 46204 | C3: 1816398 | D3: 0 | E3: 0 | F3: 0 | G3: 0 | H3: 0 | I3: 1.3795176 | J3: 222.54718 | K3: 2263.7911 | L3: 4975.9532 | M3: 6427.9984 | N3: 7204.0824 | O3: 7401.465 | P3: 7341.2926 | Q3: 6967.3721 | R3: 6428.9567 | S3: 5459.2091 | T3: 3272.2185 | U3: 626.57622 | V3: 0.64265485 | W3: 0 | X3: 0 | Y3: 0 | Z3: 0 | AA3: 0 | AB3: =SUM(D3:AA3)*_xlfn.DAYS(B4,B3) -> 1816398
A4: =+YEAR(B4) -> 2026 | B4: 46235 | C4: 1814297 | D4: 0 | E4: 0 | F4: 0 | G4: 0 | H4: 0 | I4: 1.3779219 | J4: 222.28975 | K4: 2261.1725 | L4: 4970.1975 | M4: 6420.563 | N4: 7195.7493 | O4: 7392.9036 | P4: 7332.8007 | Q4: 6959.3128 | R4: 6421.5202 | S4: 5452.8943 | T4: 3268.4335 | U4: 625.85144 | V4: 0.64191148 | W4: 0 | X4: 0 | Y4: 0 | Z4: 0 | AA4: 0 | AB4: =SUM(D4:AA4)*_xlfn.DAYS(B5,B4) -> 1814297
A5: =+YEAR(B5) -> 2026 | B5: 46266 | C5: 1770367.8 | D5: 0 | E5: 0 | F5: 0 | G5: 0 | H5: 0 | I5: 1.3893772 | J5: 224.13775 | K5: 2279.9706 | L5: 5011.5169 | M5: 6473.94 | N5: 7255.5708 | O5: 7454.3641 | P5: 7393.7616 | Q5: 7017.1687 | R5: 6474.9052 | S5: 5498.2267 | T5: 3295.6054 | U5: 631.05443 | V5: 0.64724798 | W5: 0 | X5: 0 | Y5: 0 | Z5: 0 | AA5: 0 | AB5: =SUM(D5:AA5)*_xlfn.DAYS(B6,B5) -> 1770367.8
A6: =+YEAR(B6) -> 2026 | B6: 46296 | C6: 1808727.3 | D6: 0 | E6: 0 | F6: 0 | G6: 0 | H6: 0 | I6: 1.3736918 | J6: 221.60735 | K6: 2254.231 | L6: 4954.9395 | M6: 6400.8526 | N6: 7173.6592 | O6: 7370.2083 | P6: 7310.2899 | Q6: 6937.9486 | R6: 6401.8069 | S6: 5436.1546 | T6: 3258.3998 | U6: 623.93015 | V6: 0.63994089 | W6: 0 | X6: 0 | Y6: 0 | Z6: 0 | AA6: 0 | AB6: =SUM(D6:AA6)*_xlfn.DAYS(B7,B6) -> 1808727.3
A7: =+YEAR(B7) -> 2026 | B7: 46327 | C7: 1754745.6 | D7: 0 | E7: 0 | F7: 0 | G7: 0 | H7: 0 | I7: 1.377117 | J7: 222.1599 | K7: 2259.8516 | L7: 4967.2941 | M7: 6416.8124 | N7: 7191.5458 | O7: 7388.585 | P7: 7328.5172 | Q7: 6955.2475 | R7: 6417.769 | S7: 5449.709 | T7: 3266.5242 | U7: 625.48584 | V7: 0.6415365 | W7: 0 | X7: 0 | Y7: 0 | Z7: 0 | AA7: 0 | AB7: =SUM(D7:AA7)*_xlfn.DAYS(B8,B7) -> 1754745.6
A8: =+YEAR(B8) -> 2026 | B8: 46357 | C8: 1845870.6 | D8: 0 | E8: 0 | F8: 0 | G8: 0 | H8: 0 | I8: 1.4019014 | J8: 226.15819 | K8: 2300.5229 | L8: 5056.6922 | M8: 6532.2979 | N8: 7320.9745 | O8: 7521.5599 | P8: 7460.411 | Q8: 7080.4235 | R8: 6533.2718 | S8: 5547.7893 | T8: 3325.3129 | U8: 636.74293 | V8: 0.65308245 | W8: 0 | X8: 0 | Y8: 0 | Z8: 0 | AA8: 0 | AB8: =SUM(D8:AA8)*_xlfn.DAYS(B9,B8) -> 1845870.6
A9: =+YEAR(B9) -> 2027 | B9: 46388 | C9: 1864971.9 | D9: 0 | E9: 0 | F9: 0 | G9: 0 | H9: 0 | I9: 1.4164085 | J9: 228.49851 | K9: 2324.3291 | L9: 5109.0195 | M9: 6599.8951 | N9: 7396.7331 | O9: 7599.3941 | P9: 7537.6125 | Q9: 7153.6927 | R9: 6600.879 | S9: 5605.1986 | T9: 3359.7238 | U9: 643.33204 | V9: 0.65984065 | W9: 0 | X9: 0 | Y9: 0 | Z9: 0 | AA9: 0 | AB9: =SUM(D9:AA9)*_xlfn.DAYS(B10,B9) -> 1864971.9
A10: =+YEAR(B10) -> 2027 | B10: 46419 | C10: 1697293.2 | D10: 0 | E10: 0 | F10: 0 | G10: 0 | H10: 0 | I10: 1.4271735 | J10: 230.23514 | K10: 2341.9944 | L10: 5147.8491 | M10: 6650.0556 | N10: 7452.9497 | O10: 7657.1509 | P10: 7594.8998 | Q10: 7208.0622 | R10: 6651.047 | S10: 5647.7992 | T10: 3385.2583 | U10: 648.22148 | V10: 0.66485556 | W10: 0 | X10: 0 | Y10: 0 | Z10: 0 | AA10: 0 | AB10: =SUM(D10:AA10)*_xlfn.DAYS(B11,B10) -> 1697293.2
A11: =+YEAR(B11) -> 2027 | B11: 46447 | C11: 1860913.9 | D11: 0 | E11: 0 | F11: 0 | G11: 0 | H11: 0 | I11: 1.4133265 | J11: 228.00131 | K11: 2319.2716 | L11: 5097.9028 | M11: 6585.5344 | N11: 7380.6385 | O11: 7582.8585 | P11: 7521.2113 | Q11: 7138.127 | R11: 6586.5161 | S11: 5593.0022 | T11: 3352.4133 | U11: 641.93221 | V11: 0.6584049 | W11: 0 | X11: 0 | Y11: 0 | Z11: 0 | AA11: 0 | AB11: =SUM(D11:AA11)*_xlfn.DAYS(B12,B11) -> 1860913.9
A12: =+YEAR(B12) -> 2027 | B12: 46478 | C12: 1798120.2 | D12: 0 | E12: 0 | F12: 0 | G12: 0 | H12: 0 | I12: 1.4111571 | J12: 227.65134 | K12: 2315.7116 | L12: 5090.0778 | M12: 6575.4259 | N12: 7369.3095 | O12: 7571.2192 | P12: 7509.6666 | Q12: 7127.1703 | R12: 6576.4061 | S12: 5584.4172 | T12: 3347.2675 | U12: 640.94687 | V12: 0.65739427 | W12: 0 | X12: 0 | Y12: 0 | Z12: 0 | AA12: 0 | AB12: =SUM(D12:AA12)*_xlfn.DAYS(B13,B12) -> 1798120.2
A13: =+YEAR(B13) -> 2027 | B13: 46508 | C13: 1861354 | D13: 0 | E13: 0 | F13: 0 | G13: 0 | H13: 0 | I13: 1.4136608 | J13: 228.05524 | K13: 2319.8201 | L13: 5099.1085 | M13: 6587.0919 | N13: 7382.384 | O13: 7584.6519 | P13: 7522.9901 | Q13: 7139.8152 | R13: 6588.0739 | S13: 5594.325 | T13: 3353.2062 | U13: 642.08403 | V13: 0.65856061 | W13: 0 | X13: 0 | Y13: 0 | Z13: 0 | AA13: 0 | AB13: =SUM(D13:AA13)*_xlfn.DAYS(B14,B13) -> 1861354
... A116: =+YEAR(B116) -> 2035 | B116: 49644 | C116: 2185855 | D116: 0 | E116: 0 | F116: 0 | G116: 0 | H116: 0 | I116: 1.6601127 | J116: 267.81348 | K116: 2724.2482 | L116: 5988.0667 | M116: 7735.4591 | N116: 8669.3994 | O116: 8906.9298 | P116: 8834.5182 | Q116: 8384.542 | R116: 7736.6124 | S116: 6569.6173 | T116: 3937.7908 | U116: 754.02239 | V116: 0.77337144 | W116: 0 | X116: 0 | Y116: 0 | Z116: 0 | AA116: 0 | AB116: =SUM(D116:AA116)*_xlfn.DAYS(B117,B116) -> 2185855
B117: 49675 | C117: =+SUM(C2:C116) -> 2.2585936e+08 | AB117: =+SUM(AB2:AB116) -> 2.2585936e+08
