Workbook

Sheet Oferta Producto 1
B3: PRODUCTO No. 1
B4: PAGUE LO CONTRATADO PERIODO 2026 A 2035
B5: PRECIO OFERTADO EN $ / kWh DE ABRIL DE 2025
B8: AÑO | C8: ENERGIA SOLICITADA kWh/AÑO | D8: % OFERTADO | E8: ENERGIA OFERTADA kWh/AÑO | F8: PRECIO OFERTADO $/kWh
B10: 2026 | C10: =SUMIF('Curvas Prod 1'!A:AC,'Oferta Producto 1'!B10,'Curvas Prod 1'!AC:AC) -> 84419347 | E10: =C10*D10 -> 0
B11: 2027 | C11: =SUMIF('Curvas Prod 1'!A:AC,'Oferta Producto 1'!B11,'Curvas Prod 1'!AC:AC) -> 1.2873655e+08 | E11: =C11*D11 -> 0
B12: 2028 | C12: =SUMIF('Curvas Prod 1'!A:AC,'Oferta Producto 1'!B12,'Curvas Prod 1'!AC:AC) -> 1.645992e+08 | E12: =C12*D12 -> 0
B13: 2029 | C13: =SUMIF('Curvas Prod 1'!A:AC,'Oferta Producto 1'!B13,'Curvas Prod 1'!AC:AC) -> 66339313 | E13: =C13*D13 -> 0
B14: 2030 | C14: =SUMIF('Curvas Prod 1'!A:AC,'Oferta Producto 1'!B14,'Curvas Prod 1'!AC:AC) -> 66334636 | E14: =C14*D14 -> 0
B15: 2031 | C15: =SUMIF('Curvas Prod 1'!A:AC,'Oferta Producto 1'!B15,'Curvas Prod 1'!AC:AC) -> 66334636 | E15: =C15*D15 -> 0
B16: 2032 | C16: =SUMIF('Curvas Prod 1'!A:AC,'Oferta Producto 1'!B16,'Curvas Prod 1'!AC:AC) -> 66197930 | E16: =C16*D16 -> 0
B17: 2033 | C17: =SUMIF('Curvas Prod 1'!A:AC,'Oferta Producto 1'!B17,'Curvas Prod 1'!AC:AC) -> 81677320 | E17: =C17*D17 -> 0
B18: 2034 | C18: =SUMIF('Curvas Prod 1'!A:AC,'Oferta Producto 1'!B18,'Curvas Prod 1'!AC:AC) -> 1.8055904e+08 | E18: =C18*D18 -> 0
B19: 2035 | C19: =SUMIF('Curvas Prod 1'!A:AC,'Oferta Producto 1'!B19,'Curvas Prod 1'!AC:AC) -> 1.8122404e+08 | E19: =C19*D19 -> 0
B20: TOTAL | C20: =+SUM(C10:C19) -> 1.086422e+09 | D20: =(E20/C20) -> 0 | E20: =SUM(E10:E19) -> 0 | F20: =IFERROR(((SUM(E10:E14)*F10)+(SUM(E15:E19)*F15))/SUM(E10:E19),0) -> 0
B22: Términos y condiciones
B23: Cantidad de Energía Ofertada
B24: Los interesados deberán indicar, para cada año del período 2026 a 2035, el porcentaje de energía eléctrica que están en capacidad de suministrar con relación a la energía solicitada para ese año. - Este porcentaje podrá variar año a año. - El valor mínimo de oferta permitido para cada año será del 10% de la energía solicitada correspondiente. - Los % ofertados se aplicaran a la curva de distribución de la hoja Curva de la oferta Prod 1 - Las ofertas de Producto 1 y Producto 2 se consideran mutuamente excluyentes, para efectos de comparación se determinará el Precio Promedio Ponderado (PPP) hecho por los oferentes. ENERBIT adjudicará el producto cuya oferta presente el menor PPP, siempre que cumpla con los requisitos de porcentaje mínimo. - En caso de empate en PPP, se preferirá la oferta con mayor porcentaje global promedio ofertado sobre el período completo.
B25: Precio Ofertado
B26: Los oferentes deberán indicar el precio unitario por kWh ofertado, el cual será válido para bloques quinquenales - Periodo 2026–2030 - Periodo 2031–2035
B27: El precio del producto corresponderá al precio promedio ponderado de los años que componen el producto.

Sheet Curvas Prod 1
B1: CURVAS REQUERIDAS PRODUCTO 1 PERIODO 2026 A 2035 MODALIDAD PAGUE LO CONTRATADO - kWh
B4: Periodo | C4: H00 | D4: H01 | E4: H02 | F4: H03 | G4: H04 | H4: H05 | I4: H06 | J4: H07 | K4: H08 | L4: H09 | M4: H10 | N4: H11 | O4: H12 | P4: H13 | Q4: H14 | R4: H15 | S4: H16 | T4: H17 | U4: H18 | V4: H19 | W4: H20 | X4: H21 | Y4: H22 | Z4: H23 | AA4: TOTAL DÍA | AB4: Días/ | AC4: TOTAL MES
AB5: mes
A6: =YEAR(B6) -> 2026 | B6: 46023 | C6: =($AC6/$AB6)/24 -> 5721.8129 | D6: =($AC6/$AB6)/24 -> 5721.8129 | E6: =($AC6/$AB6)/24 -> 5721.8129 | F6: =($AC6/$AB6)/24 -> 5721.8129 | G6: =($AC6/$AB6)/24 -> 5721.8129 | H6: =($AC6/$AB6)/24 -> 5721.8129 | I6: =($AC6/$AB6)/24 -> 5721.8129 | J6: =($AC6/$AB6)/24 -> 5721.8129 | ... Z6: =($AC6/$AB6)/24 -> 5721.8129 | AA6: =SUM(C6:Z6) -> 137323.51 | AB6: =DAY(EOMONTH(B6,0)) -> 31 | AC6: 4257028.8
A7: =YEAR(B7) -> 2026 | B7: 46054 | C7: =($AC7/$AB7)/24 -> 7740.4846 | D7: =($AC7/$AB7)/24 -> 7740.4846 | E7: =($AC7/$AB7)/24 -> 7740.4846 | F7: =($AC7/$AB7)/24 -> 7740.4846 | G7: =($AC7/$AB7)/24 -> 7740.4846 | H7: =($AC7/$AB7)/24 -> 7740.4846 | I7: =($AC7/$AB7)/24 -> 7740.4846 | J7: =($AC7/$AB7)/24 -> 7740.4846 | ... Z7: =($AC7/$AB7)/24 -> 7740.4846 | AA7: =SUM(C7:Z7) -> 185771.63 | AB7: =DAY(EOMONTH(B7,0)) -> 28 | AC7: 5201605.7
A8: =YEAR(B8) -> 2026 | B8: 46082 | C8: =($AC8/$AB8)/24 -> 6873.9053 | D8: =($AC8/$AB8)/24 -> 6873.9053 | E8: =($AC8/$AB8)/24 -> 6873.9053 | F8: =($AC8/$AB8)/24 -> 6873.9053 | G8: =($AC8/$AB8)/24 -> 6873.9053 | H8: =($AC8/$AB8)/24 -> 6873.9053 | I8: =($AC8/$AB8)/24 -> 6873.9053 | J8: =($AC8/$AB8)/24 -> 6873.9053 | ... Z8: =($AC8/$AB8)/24 -> 6873.9053 | AA8: =SUM(C8:Z8) -> 164973.73 | AB8: =DAY(EOMONTH(B8,0)) -> 31 | AC8: 5114185.6
A9: =YEAR(B9) -> 2026 | B9: 46113 | C9: =($AC9/$AB9)/24 -> 6188.1757 | D9: =($AC9/$AB9)/24 -> 6188.1757 | E9: =($AC9/$AB9)/24 -> 6188.1757 | F9: =($AC9/$AB9)/24 -> 6188.1757 | G9: =($AC9/$AB9)/24 -> 6188.1757 | H9: =($AC9/$AB9)/24 -> 6188.1757 | I9: =($AC9/$AB9)/24 -> 6188.1757 | J9: =($AC9/$AB9)/24 -> 6188.1757 | ... Z9: =($AC9/$AB9)/24 -> 6188.1757 | AA9: =SUM(C9:Z9) -> 148516.22 | AB9: =DAY(EOMONTH(B9,0)) -> 30 | AC9: 4455486.5
A10: =YEAR(B10) -> 2026 | B10: 46143 | C10: =($AC10/$AB10)/24 -> 6877.9681 | D10: =($AC10/$AB10)/24 -> 6877.9681 | E10: =($AC10/$AB10)/24 -> 6877.9681 | F10: =($AC10/$AB10)/24 -> 6877.9681 | G10: =($AC10/$AB10)/24 -> 6877.9681 | H10: =($AC10/$AB10)/24 -> 6877.9681 | I10: =($AC10/$AB10)/24 -> 6877.9681 | J10: =($AC10/$AB10)/24 -> 6877.9681 | ... Z10: =($AC10/$AB10)/24 -> 6877.9681 | AA10: =SUM(C10:Z10) -> 165071.23 | AB10: =DAY(EOMONTH(B10,0)) -> 31 | AC10: 5117208.2
A11: =YEAR(B11) -> 2026 | B11: 46174 | C11: =($AC11/$AB11)/24 -> 7482.9277 | D11: =($AC11/$AB11)/24 -> 7482.9277 | E11: =($AC11/$AB11)/24 -> 7482.9277 | F11: =($AC11/$AB11)/24 -> 7482.9277 | G11: =($AC11/$AB11)/24 -> 7482.9277 | H11: =($AC11/$AB11)/24 -> 7482.9277 | I11: =($AC11/$AB11)/24 -> 7482.9277 | J11: =($AC11/$AB11)/24 -> 7482.9277 | ... Z11: =($AC11/$AB11)/24 -> 7482.9277 | AA11: =SUM(C11:Z11) -> 179590.27 | AB11: =DAY(EOMONTH(B11,0)) -> 30 | AC11: 5387708
A12: =YEAR(B12) -> 2026 | B12: 46204 | C12: =($AC12/$AB12)/24 -> 7202.6484 | D12: =($AC12/$AB12)/24 -> 7202.6484 | E12: =($AC12/$AB12)/24 -> 7202.6484 | F12: =($AC12/$AB12)/24 -> 7202.6484 | G12: =($AC12/$AB12)/24 -> 7202.6484 | H12: =($AC12/$AB12)/24 -> 7202.6484 | I12: =($AC12/$AB12)/24 -> 7202.6484 | J12: =($AC12/$AB12)/24 -> 7202.6484 | ... Z12: =($AC12/$AB12)/24 -> 7202.6484 | AA12: =SUM(C12:Z12) -> 172863.56 | AB12: =DAY(EOMONTH(B12,0)) -> 31 | AC12: 5358770.4
A13: =YEAR(B13) -> 2026 | B13: 46235 | C13: =($AC13/$AB13)/24 -> 8996.9085 | D13: =($AC13/$AB13)/24 -> 8996.9085 | E13: =($AC13/$AB13)/24 -> 8996.9085 | F13: =($AC13/$AB13)/24 -> 8996.9085 | G13: =($AC13/$AB13)/24 -> 8996.9085 | H13: =($AC13/$AB13)/24 -> 8996.9085 | I13: =($AC13/$AB13)/24 -> 8996.9085 | J13: =($AC13/$AB13)/24 -> 8996.9085 | ... Z13: =($AC13/$AB13)/24 -> 8996.9085 | AA13: =SUM(C13:Z13) -> 215925.8 | AB13: =DAY(EOMONTH(B13,0)) -> 31 | AC13: 6693699.9
A14: =YEAR(B14) -> 2026 | B14: 46266 | C14: =($AC14/$AB14)/24 -> 15036.653 | D14: =($AC14/$AB14)/24 -> 15036.653 | E14: =($AC14/$AB14)/24 -> 15036.653 | F14: =($AC14/$AB14)/24 -> 15036.653 | G14: =($AC14/$AB14)/24 -> 15036.653 | H14: =($AC14/$AB14)/24 -> 15036.653 | I14: =($AC14/$AB14)/24 -> 15036.653 | J14: =($AC14/$AB14)/24 -> 15036.653 | ... Z14: =($AC14/$AB14)/24 -> 15036.653 | AA14: =SUM(C14:Z14) -> 360879.68 | AB14: =DAY(EOMONTH(B14,0)) -> 30 | AC14: 10826390
A15: =YEAR(B15) -> 2026 | B15: 46296 | C15: =($AC15/$AB15)/24 -> 14234.458 | D15: =($AC15/$AB15)/24 -> 14234.458 | E15: =($AC15/$AB15)/24 -> 14234.458 | F15: =($AC15/$AB15)/24 -> 14234.458 | G15: =($AC15/$AB15)/24 -> 14234.458 | H15: =($AC15/$AB15)/24 -> 14234.458 | I15: =($AC15/$AB15)/24 -> 14234.458 | J15: =($AC15/$AB15)/24 -> 14234.458 | ... Z15: =($AC15/$AB15)/24 -> 14234.458 | AA15: =SUM(C15:Z15) -> 341626.99 | AB15: =DAY(EOMONTH(B15,0)) -> 31 | AC15: 10590437
A16: =YEAR(B16) -> 2026 | B16: 46327 | C16: =($AC16/$AB16)/24 -> 15036.653 | D16: =($AC16/$AB16)/24 -> 15036.653 | E16: =($AC16/$AB16)/24 -> 15036.653 | F16: =($AC16/$AB16)/24 -> 15036.653 | G16: =($AC16/$AB16)/24 -> 15036.653 | H16: =($AC16/$AB16)/24 -> 15036.653 | I16: =($AC16/$AB16)/24 -> 15036.653 | J16: =($AC16/$AB16)/24 -> 15036.653 | ... Z16: =($AC16/$AB16)/24 -> 15036.653 | AA16: =SUM(C16:Z16) -> 360879.68 | AB16: =DAY(EOMONTH(B16,0)) -> 30 | AC16: 10826390
A17: =YEAR(B17) -> 2026 | B17: 46357 | C17: =($AC17/$AB17)/24 -> 14234.458 | D17: =($AC17/$AB17)/24 -> 14234.458 | E17: =($AC17/$AB17)/24 -> 14234.458 | F17: =($AC17/$AB17)/24 -> 14234.458 | G17: =($AC17/$AB17)/24 -> 14234.458 | H17: =($AC17/$AB17)/24 -> 14234.458 | I17: =($AC17/$AB17)/24 -> 14234.458 | J17: =($AC17/$AB17)/24 -> 14234.458 | ... Z17: =($AC17/$AB17)/24 -> 14234.458 | AA17: =SUM(C17:Z17) -> 341626.99 | AB17: =DAY(EOMONTH(B17,0)) -> 31 | AC17: 10590437
... A125: =YEAR(B125) -> 2035 | B125: 49644 | C125: =($AC125/$AB125)/24 -> 20223.69 | D125: =($AC125/$AB125)/24 -> 20223.69 | E125: =($AC125/$AB125)/24 -> 20223.69 | F125: =($AC125/$AB125)/24 -> 20223.69 | G125: =($AC125/$AB125)/24 -> 20223.69 | H125: =($AC125/$AB125)/24 -> 20223.69 | I125: =($AC125/$AB125)/24 -> 20223.69 | J125: =($AC125/$AB125)/24 -> 20223.69 | ... Z125: =($AC125/$AB125)/24 -> 20223.69 | AA125: =SUM(C125:Z125) -> 485368.56 | AB125: =DAY(EOMONTH(B125,0)) -> 31 | AC125: 15046425
B126: TOTAL PERIODO | C126: =+SUM(C6:C125) -> 1489377.4 | D126: =+SUM(D6:D125) -> 1489377.4 | E126: =+SUM(E6:E125) -> 1489377.4 | F126: =+SUM(F6:F125) -> 1489377.4 | G126: =+SUM(G6:G125) -> 1489377.4 | H126: =+SUM(H6:H125) -> 1489377.4 | I126: =+SUM(I6:I125) -> 1489377.4 | J126: =+SUM(J6:J125) -> 1489377.4 | ... AC126: =+SUM(AC6:AC125) -> 1.086422e+09

Sheet Curva de la oferta Prod 1
B1: CURVAS REQUERIDAS PRODUCTO 1 PERIODO 2026 A 2035 MODALIDAD PAGUE LO CONTRATADO - kWh
B4: Periodo | C4: H00 | D4: H01 | E4: H02 | F4: H03 | G4: H04 | H4: H05 | I4: H06 | J4: H07 | K4: H08 | L4: H09 | M4: H10 | N4: H11 | O4: H12 | P4: H13 | Q4: H14 | R4: H15 | S4: H16 | T4: H17 | U4: H18 | V4: H19 | W4: H20 | X4: H21 | Y4: H22 | Z4: H23 | AA4: TOTAL DÍA | AB4: Días/ | AC4: TOTAL MES | AD4: % Distribución oferta
AB5: mes
A6: =YEAR(B6) -> 2026 | B6: 46023 | C6: =(((_xlfn.XLOOKUP(YEAR($B6),'Oferta Producto 1'!$B$8:$B$19,'Oferta Producto 1'!$E$8:$E$19))*$AD6)/$AB6)/24 -> 0 | D6: =(((_xlfn.XLOOKUP(YEAR($B6),'Oferta Producto 1'!$B$8:$B$19,'Oferta Producto 1'!$E$8:$E$19))*$AD6)/$AB6)/24 -> 0 | E6: =(((_xlfn.XLOOKUP(YEAR($B6),'Oferta Producto 1'!$B$8:$B$19,'Oferta Producto 1'!$E$8:$E$19))*$AD6)/$AB6)/24 -> 0 | F6: =(((_xlfn.XLOOKUP(YEAR($B6),'Oferta Producto 1'!$B$8:$B$19,'Oferta Producto 1'!$E$8:$E$19))*$AD6)/$AB6)/24 -> 0 | G6: =(((_xlfn.XLOOKUP(YEAR($B6),'Oferta Producto 1'!$B$8:$B$19,'Oferta Producto 1'!$E$8:$E$19))*$AD6)/$AB6)/24 -> 0 | H6: =(((_xlfn.XLOOKUP(YEAR($B6),'Oferta Producto 1'!$B$8:$B$19,'Oferta Producto 1'!$E$8:$E$19))*$AD6)/$AB6)/24 -> 0 | I6: =(((_xlfn.XLOOKUP(YEAR($B6),'Oferta Producto 1'!$B$8:$B$19,'Oferta Producto 1'!$E$8:$E$19))*$AD6)/$AB6)/24 -> 0 | J6: =(((_xlfn.XLOOKUP(YEAR($B6),'Oferta Producto 1'!$B$8:$B$19,'Oferta Producto 1'!$E$8:$E$19))*$AD6)/$AB6)/24 -> 0 | ... Z6: =(((_xlfn.XLOOKUP(YEAR($B6),'Oferta Producto 1'!$B$8:$B$19,'Oferta Producto 1'!$E$8:$E$19))*$AD6)/$AB6)/24 -> 0 | AA6: =SUM(C6:Z6) -> 0 | AB6: =DAY(EOMONTH(B6,0)) -> 31 | AC6: =AA6*AB6 -> 0 | AD6: 0.050427171
A7: =YEAR(B7) -> 2026 | B7: 46054 | C7: =(((_xlfn.XLOOKUP(YEAR($B7),'Oferta Producto 1'!$B$8:$B$19,'Oferta Producto 1'!$E$8:$E$19))*$AD7)/$AB7)/24 -> 0 | D7: =(((_xlfn.XLOOKUP(YEAR($B7),'Oferta Producto 1'!$B$8:$B$19,'Oferta Producto 1'!$E$8:$E$19))*$AD7)/$AB7)/24 -> 0 | E7: =(((_xlfn.XLOOKUP(YEAR($B7),'Oferta Producto 1'!$B$8:$B$19,'Oferta Producto 1'!$E$8:$E$19))*$AD7)/$AB7)/24 -> 0 | F7: =(((_xlfn.XLOOKUP(YEAR($B7),'Oferta Producto 1'!$B$8:$B$19,'Oferta Producto 1'!$E$8:$E$19))*$AD7)/$AB7)/24 -> 0 | G7: =(((_xlfn.XLOOKUP(YEAR($B7),'Oferta Producto 1'!$B$8:$B$19,'Oferta Producto 1'!$E$8:$E$19))*$AD7)/$AB7)/24 -> 0 | H7: =(((_xlfn.XLOOKUP(YEAR($B7),'Oferta Producto 1'!$B$8:$B$19,'Oferta Producto 1'!$E$8:$E$19))*$AD7)/$AB7)/24 -> 0 | I7: =(((_xlfn.XLOOKUP(YEAR($B7),'Oferta Producto 1'!$B$8:$B$19,'Oferta Producto 1'!$E$8:$E$19))*$AD7)/$AB7)/24 -> 0 | J7: =(((_xlfn.XLOOKUP(YEAR($B7),'Oferta Producto 1'!$B$8:$B$19,'Oferta Producto 1'!$E$8:$E$19))*$AD7)/$AB7)/24 -> 0 | ... Z7: =(((_xlfn.XLOOKUP(YEAR($B7),'Oferta Producto 1'!$B$8:$B$19,'Oferta Producto 1'!$E$8:$E$19))*$AD7)/$AB7)/24 -> 0 | AA7: =SUM(C7:Z7) -> 0 | AB7: =DAY(EOMONTH(B7,0)) -> 28 | AC7: =AA7*AB7 -> 0 | AD7: 0.061616274
A8: =YEAR(B8) -> 2026 | B8: 46082 | C8: =(((_xlfn.XLOOKUP(YEAR($B8),'Oferta Producto 1'!$B$8:$B$19,'Oferta Producto 1'!$E$8:$E$19))*$AD8)/$AB8)/24 -> 0 | D8: =(((_xlfn.XLOOKUP(YEAR($B8),'Oferta Producto 1'!$B$8:$B$19,'Oferta Producto 1'!$E$8:$E$19))*$AD8)/$AB8)/24 -> 0 | E8: =(((_xlfn.XLOOKUP(YEAR($B8),'Oferta Producto 1'!$B$8:$B$19,'Oferta Producto 1'!$E$8:$E$19))*$AD8)/$AB8)/24 -> 0 | F8: =(((_xlfn.XLOOKUP(YEAR($B8),'Oferta Producto 1'!$B$8:$B$19,'Oferta Producto 1'!$E$8:$E$19))*$AD8)/$AB8)/24 -> 0 | G8: =(((_xlfn.XLOOKUP(YEAR($B8),'Oferta Producto 1'!$B$8:$B$19,'Oferta Producto 1'!$E$8:$E$19))*$AD8)/$AB8)/24 -> 0 | H8: =(((_xlfn.XLOOKUP(YEAR($B8),'Oferta Producto 1'!$B$8:$B$19,'Oferta Producto 1'!$E$8:$E$19))*$AD8)/$AB8)/24 -> 0 | I8: =(((_xlfn.XLOOKUP(YEAR($B8),'Oferta Producto 1'!$B$8:$B$19,'Oferta Producto 1'!$E$8:$E$19))*$AD8)/$AB8)/24 -> 0 | J8: =(((_xlfn.XLOOKUP(YEAR($B8),'Oferta Producto 1'!$B$8:$B$19,'Oferta Producto 1'!$E$8:$E$19))*$AD8)/$AB8)/24 -> 0 | ... Z8: =(((_xlfn.XLOOKUP(YEAR($B8),'Oferta Producto 1'!$B$8:$B$19,'Oferta Producto 1'!$E$8:$E$19))*$AD8)/$AB8)/24 -> 0 | AA8: =SUM(C8:Z8) -> 0 | AB8: =DAY(EOMONTH(B8,0)) -> 31 | AC8: =AA8*AB8 -> 0 | AD8: 0.060580729
A9: =YEAR(B9) -> 2026 | B9: 46113 | C9: =(((_xlfn.XLOOKUP(YEAR($B9),'Oferta Producto 1'!$B$8:$B$19,'Oferta Producto 1'!$E$8:$E$19))*$AD9)/$AB9)/24 -> 0 | D9: =(((_xlfn.XLOOKUP(YEAR($B9),'Oferta Producto 1'!$B$8:$B$19,'Oferta Producto 1'!$E$8:$E$19))*$AD9)/$AB9)/24 -> 0 | E9: =(((_xlfn.XLOOKUP(YEAR($B9),'Oferta Producto 1'!$B$8:$B$19,'Oferta Producto 1'!$E$8:$E$19))*$AD9)/$AB9)/24 -> 0 | F9: =(((_xlfn.XLOOKUP(YEAR($B9),'Oferta Producto 1'!$B$8:$B$19,'Oferta Producto 1'!$E$8:$E$19))*$AD9)/$AB9)/24 -> 0 | G9: =(((_xlfn.XLOOKUP(YEAR($B9),'Oferta Producto 1'!$B$8:$B$19,'Oferta Producto 1'!$E$8:$E$19))*$AD9)/$AB9)/24 -> 0 | H9: =(((_xlfn.XLOOKUP(YEAR($B9),'Oferta Producto 1'!$B$8:$B$19,'Oferta Producto 1'!$E$8:$E$19))*$AD9)/$AB9)/24 -> 0 | I9: =(((_xlfn.XLOOKUP(YEAR($B9),'Oferta Producto 1'!$B$8:$B$19,'Oferta Producto 1'!$E$8:$E$19))*$AD9)/$AB9)/24 -> 0 | J9: =(((_xlfn.XLOOKUP(YEAR($B9),'Oferta Producto 1'!$B$8:$B$19,'Oferta Producto 1'!$E$8:$E$19))*$AD9)/$AB9)/24 -> 0 | ... Z9: =(((_xlfn.XLOOKUP(YEAR($B9),'Oferta Producto 1'!$B$8:$B$19,'Oferta Producto 1'!$E$8:$E$19))*$AD9)/$AB9)/24 -> 0 | AA9: =SUM(C9:Z9) -> 0 | AB9: =DAY(EOMONTH(B9,0)) -> 30 | AC9: =AA9*AB9 -> 0 | AD9: 0.052778026
A10: =YEAR(B10) -> 2026 | B10: 46143 | C10: =(((_xlfn.XLOOKUP(YEAR($B10),'Oferta Producto 1'!$B$8:$B$19,'Oferta Producto 1'!$E$8:$E$19))*$AD10)/$AB10)/24 -> 0 | D10: =(((_xlfn.XLOOKUP(YEAR($B10),'Oferta Producto 1'!$B$8:$B$19,'Oferta Producto 1'!$E$8:$E$19))*$AD10)/$AB10)/24 -> 0 | E10: =(((_xlfn.XLOOKUP(YEAR($B10),'Oferta Producto 1'!$B$8:$B$19,'Oferta Producto 1'!$E$8:$E$19))*$AD10)/$AB10)/24 -> 0 | F10: =(((_xlfn.XLOOKUP(YEAR($B10),'Oferta Producto 1'!$B$8:$B$19,'Oferta Producto 1'!$E$8:$E$19))*$AD10)/$AB10)/24 -> 0 | G10: =(((_xlfn.XLOOKUP(YEAR($B10),'Oferta Producto 1'!$B$8:$B$19,'Oferta Producto 1'!$E$8:$E$19))*$AD10)/$AB10)/24 -> 0 | H10: =(((_xlfn.XLOOKUP(YEAR($B10),'Oferta Producto 1'!$B$8:$B$19,'Oferta Producto 1'!$E$8:$E$19))*$AD10)/$AB10)/24 -> 0 | I10: =(((_xlfn.XLOOKUP(YEAR($B10),'Oferta Producto 1'!$B$8:$B$19,'Oferta Producto 1'!$E$8:$E$19))*$AD10)/$AB10)/24 -> 0 | J10: =(((_xlfn.XLOOKUP(YEAR($B10),'Oferta Producto 1'!$B$8:$B$19,'Oferta Producto 1'!$E$8:$E$19))*$AD10)/$AB10)/24 -> 0 | ... Z10: =(((_xlfn.XLOOKUP(YEAR($B10),'Oferta Producto 1'!$B$8:$B$19,'Oferta Producto 1'!$E$8:$E$19))*$AD10)/$AB10)/24 -> 0 | AA10: =SUM(C10:Z10) -> 0 | AB10: =DAY(EOMONTH(B10,0)) -> 31 | AC10: =AA10*AB10 -> 0 | AD10: 0.060616534
A11: =YEAR(B11) -> 2026 | B11: 46174 | C11: =(((_xlfn.XLOOKUP(YEAR($B11),'Oferta Producto 1'!$B$8:$B$19,'Oferta Producto 1'!$E$8:$E$19))*$AD11)/$AB11)/24 -> 0 | D11: =(((_xlfn.XLOOKUP(YEAR($B11),'Oferta Producto 1'!$B$8:$B$19,'Oferta Producto 1'!$E$8:$E$19))*$AD11)/$AB11)/24 -> 0 | E11: =(((_xlfn.XLOOKUP(YEAR($B11),'Oferta Producto 1'!$B$8:$B$19,'Oferta Producto 1'!$E$8:$E$19))*$AD11)/$AB11)/24 -> 0 | F11: =(((_xlfn.XLOOKUP(YEAR($B11),'Oferta Producto 1'!$B$8:$B$19,'Oferta Producto 1'!$E$8:$E$19))*$AD11)/$AB11)/24 -> 0 | G11: =(((_xlfn.XLOOKUP(YEAR($B11),'Oferta Producto 1'!$B$8:$B$19,'Oferta Producto 1'!$E$8:$E$19))*$AD11)/$AB11)/24 -> 0 | H11: =(((_xlfn.XLOOKUP(YEAR($B11),'Oferta Producto 1'!$B$8:$B$19,'Oferta Producto 1'!$E$8:$E$19))*$AD11)/$AB11)/24 -> 0 | I11: =(((_xlfn.XLOOKUP(YEAR($B11),'Oferta Producto 1'!$B$8:$B$19,'Oferta Producto 1'!$E$8:$E$19))*$AD11)/$AB11)/24 -> 0 | J11: =(((_xlfn.XLOOKUP(YEAR($B11),'Oferta Producto 1'!$B$8:$B$19,'Oferta Producto 1'!$E$8:$E$19))*$AD11)/$AB11)/24 -> 0 | ... Z11: =(((_xlfn.XLOOKUP(YEAR($B11),'Oferta Producto 1'!$B$8:$B$19,'Oferta Producto 1'!$E$8:$E$19))*$AD11)/$AB11)/24 -> 0 | AA11: =SUM(C11:Z11) -> 0 | AB11: =DAY(EOMONTH(B11,0)) -> 30 | AC11: =AA11*AB11 -> 0 | AD11: 0.063820773
A12: =YEAR(B12) -> 2026 | B12: 46204 | C12: =(((_xlfn.XLOOKUP(YEAR($B12),'Oferta Producto 1'!$B$8:$B$19,'Oferta Producto 1'!$E$8:$E$19))*$AD12)/$AB12)/24 -> 0 | D12: =(((_xlfn.XLOOKUP(YEAR($B12),'Oferta Producto 1'!$B$8:$B$19,'Oferta Producto 1'!$E$8:$E$19))*$AD12)/$AB12)/24 -> 0 | E12: =(((_xlfn.XLOOKUP(YEAR($B12),'Oferta Producto 1'!$B$8:$B$19,'Oferta Producto 1'!$E$8:$E$19))*$AD12)/$AB12)/24 -> 0 | F12: =(((_xlfn.XLOOKUP(YEAR($B12),'Oferta Producto 1'!$B$8:$B$19,'Oferta Producto 1'!$E$8:$E$19))*$AD12)/$AB12)/24 -> 0 | G12: =(((_xlfn.XLOOKUP(YEAR($B12),'Oferta Producto 1'!$B$8:$B$19,'Oferta Producto 1'!$E$8:$E$19))*$AD12)/$AB12)/24 -> 0 | H12: =(((_xlfn.XLOOKUP(YEAR($B12),'Oferta Producto 1'!$B$8:$B$19,'Oferta Producto 1'!$E$8:$E$19))*$AD12)/$AB12)/24 -> 0 | I12: =(((_xlfn.XLOOKUP(YEAR($B12),'Oferta Producto 1'!$B$8:$B$19,'Oferta Producto 1'!$E$8:$E$19))*$AD12)/$AB12)/24 -> 0 | J12: =(((_xlfn.XLOOKUP(YEAR($B12),'Oferta Producto 1'!$B$8:$B$19,'Oferta Producto 1'!$E$8:$E$19))*$AD12)/$AB12)/24 -> 0 | ... Z12: =(((_xlfn.XLOOKUP(YEAR($B12),'Oferta Producto 1'!$B$8:$B$19,'Oferta Producto 1'!$E$8:$E$19))*$AD12)/$AB12)/24 -> 0 | AA12: =SUM(C12:Z12) -> 0 | AB12: =DAY(EOMONTH(B12,0)) -> 31 | AC12: =AA12*AB12 -> 0 | AD12: 0.063477989
A13: =YEAR(B13) -> 2026 | B13: 46235 | C13: =(((_xlfn.XLOOKUP(YEAR($B13),'Oferta Producto 1'!$B$8:$B$19,'Oferta Producto 1'!$E$8:$E$19))*$AD13)/$AB13)/24 -> 0 | D13: =(((_xlfn.XLOOKUP(YEAR($B13),'Oferta Producto 1'!$B$8:$B$19,'Oferta Producto 1'!$E$8:$E$19))*$AD13)/$AB13)/24 -> 0 | E13: =(((_xlfn.XLOOKUP(YEAR($B13),'Oferta Producto 1'!$B$8:$B$19,'Oferta Producto 1'!$E$8:$E$19))*$AD13)/$AB13)/24 -> 0 | F13: =(((_xlfn.XLOOKUP(YEAR($B13),'Oferta Producto 1'!$B$8:$B$19,'Oferta Producto 1'!$E$8:$E$19))*$AD13)/$AB13)/24 -> 0 | G13: =(((_xlfn.XLOOKUP(YEAR($B13),'Oferta Producto 1'!$B$8:$B$19,'Oferta Producto 1'!$E$8:$E$19))*$AD13)/$AB13)/24 -> 0 | H13: =(((_xlfn.XLOOKUP(YEAR($B13),'Oferta Producto 1'!$B$8:$B$19,'Oferta Producto 1'!$E$8:$E$19))*$AD13)/$AB13)/24 -> 0 | I13: =(((_xlfn.XLOOKUP(YEAR($B13),'Oferta Producto 1'!$B$8:$B$19,'Oferta Producto 1'!$E$8:$E$19))*$AD13)/$AB13)/24 -> 0 | J13: =(((_xlfn.XLOOKUP(YEAR($B13),'Oferta Producto 1'!$B$8:$B$19,'Oferta Producto 1'!$E$8:$E$19))*$AD13)/$AB13)/24 -> 0 | ... Z13: =(((_xlfn.XLOOKUP(YEAR($B13),'Oferta Producto 1'!$B$8:$B$19,'Oferta Producto 1'!$E$8:$E$19))*$AD13)/$AB13)/24 -> 0 | AA13: =SUM(C13:Z13) -> 0 | AB13: =DAY(EOMONTH(B13,0)) -> 31 | AC13: =AA13*AB13 -> 0 | AD13: 0.079291064
A14: =YEAR(B14) -> 2026 | B14: 46266 | C14: =(((_xlfn.XLOOKUP(YEAR($B14),'Oferta Producto 1'!$B$8:$B$19,'Oferta Producto 1'!$E$8:$E$19))*$AD14)/$AB14)/24 -> 0 | D14: =(((_xlfn.XLOOKUP(YEAR($B14),'Oferta Producto 1'!$B$8:$B$19,'Oferta Producto 1'!$E$8:$E$19))*$AD14)/$AB14)/24 -> 0 | E14: =(((_xlfn.XLOOKUP(YEAR($B14),'Oferta Producto 1'!$B$8:$B$19,'Oferta Producto 1'!$E$8:$E$19))*$AD14)/$AB14)/24 -> 0 | F14: =(((_xlfn.XLOOKUP(YEAR($B14),'Oferta Producto 1'!$B$8:$B$19,'Oferta Producto 1'!$E$8:$E$19))*$AD14)/$AB14)/24 -> 0 | G14: =(((_xlfn.XLOOKUP(YEAR($B14),'Oferta Producto 1'!$B$8:$B$19,'Oferta Producto 1'!$E$8:$E$19))*$AD14)/$AB14)/24 -> 0 | H14: =(((_xlfn.XLOOKUP(YEAR($B14),'Oferta Producto 1'!$B$8:$B$19,'Oferta Producto 1'!$E$8:$E$19))*$AD14)/$AB14)/24 -> 0 | I14: =(((_xlfn.XLOOKUP(YEAR($B14),'Oferta Producto 1'!$B$8:$B$19,'Oferta Producto 1'!$E$8:$E$19))*$AD14)/$AB14)/24 -> 0 | J14: =(((_xlfn.XLOOKUP(YEAR($B14),'Oferta Producto 1'!$B$8:$B$19,'Oferta Producto 1'!$E$8:$E$19))*$AD14)/$AB14)/24 -> 0 | ... Z14: =(((_xlfn.XLOOKUP(YEAR($B14),'Oferta Producto 1'!$B$8:$B$19,'Oferta Producto 1'!$E$8:$E$19))*$AD14)/$AB14)/24 -> 0 | AA14: =SUM(C14:Z14) -> 0 | AB14: =DAY(EOMONTH(B14,0)) -> 30 | AC14: =AA14*AB14 -> 0 | AD14: 0.12824537
A15: =YEAR(B15) -> 2026 | B15: 46296 | C15: =(((_xlfn.XLOOKUP(YEAR($B15),'Oferta Producto 1'!$B$8:$B$19,'Oferta Producto 1'!$E$8:$E$19))*$AD15)/$AB15)/24 -> 0 | D15: =(((_xlfn.XLOOKUP(YEAR($B15),'Oferta Producto 1'!$B$8:$B$19,'Oferta Producto 1'!$E$8:$E$19))*$AD15)/$AB15)/24 -> 0 | E15: =(((_xlfn.XLOOKUP(YEAR($B15),'Oferta Producto 1'!$B$8:$B$19,'Oferta Producto 1'!$E$8:$E$19))*$AD15)/$AB15)/24 -> 0 | F15: =(((_xlfn.XLOOKUP(YEAR($B15),'Oferta Producto 1'!$B$8:$B$19,'Oferta Producto 1'!$E$8:$E$19))*$AD15)/$AB15)/24 -> 0 | G15: =(((_xlfn.XLOOKUP(YEAR($B15),'Oferta Producto 1'!$B$8:$B$19,'Oferta Producto 1'!$E$8:$E$19))*$AD15)/$AB15)/24 -> 0 | H15: =(((_xlfn.XLOOKUP(YEAR($B15),'Oferta Producto 1'!$B$8:$B$19,'Oferta Producto 1'!$E$8:$E$19))*$AD15)/$AB15)/24 -> 0 | I15: =(((_xlfn.XLOOKUP(YEAR($B15),'Oferta Producto 1'!$B$8:$B$19,'Oferta Producto 1'!$E$8:$E$19))*$AD15)/$AB15)/24 -> 0 | J15: =(((_xlfn.XLOOKUP(YEAR($B15),'Oferta Producto 1'!$B$8:$B$19,'Oferta Producto 1'!$E$8:$E$19))*$AD15)/$AB15)/24 -> 0 | ... Z15: =(((_xlfn.XLOOKUP(YEAR($B15),'Oferta Producto 1'!$B$8:$B$19,'Oferta Producto 1'!$E$8:$E$19))*$AD15)/$AB15)/24 -> 0 | AA15: =SUM(C15:Z15) -> 0 | AB15: =DAY(EOMONTH(B15,0)) -> 31 | AC15: =AA15*AB15 -> 0 | AD15: 0.12545035
A16: =YEAR(B16) -> 2026 | B16: 46327 | C16: =(((_xlfn.XLOOKUP(YEAR($B16),'Oferta Producto 1'!$B$8:$B$19,'Oferta Producto 1'!$E$8:$E$19))*$AD16)/$AB16)/24 -> 0 | D16: =(((_xlfn.XLOOKUP(YEAR($B16),'Oferta Producto 1'!$B$8:$B$19,'Oferta Producto 1'!$E$8:$E$19))*$AD16)/$AB16)/24 -> 0 | E16: =(((_xlfn.XLOOKUP(YEAR($B16),'Oferta Producto 1'!$B$8:$B$19,'Oferta Producto 1'!$E$8:$E$19))*$AD16)/$AB16)/24 -> 0 | F16: =(((_xlfn.XLOOKUP(YEAR($B16),'Oferta Producto 1'!$B$8:$B$19,'Oferta Producto 1'!$E$8:$E$19))*$AD16)/$AB16)/24 -> 0 | G16: =(((_xlfn.XLOOKUP(YEAR($B16),'Oferta Producto 1'!$B$8:$B$19,'Oferta Producto 1'!$E$8:$E$19))*$AD16)/$AB16)/24 -> 0 | H16: =(((_xlfn.XLOOKUP(YEAR($B16),'Oferta Producto 1'!$B$8:$B$19,'Oferta Producto 1'!$E$8:$E$19))*$AD16)/$AB16)/24 -> 0 | I16: =(((_xlfn.XLOOKUP(YEAR($B16),'Oferta Producto 1'!$B$8:$B$19,'Oferta Producto 1'!$E$8:$E$19))*$AD16)/$AB16)/24 -> 0 | J16: =(((_xlfn.XLOOKUP(YEAR($B16),'Oferta Producto 1'!$B$8:$B$19,'Oferta Producto 1'!$E$8:$E$19))*$AD16)/$AB16)/24 -> 0 | ... Z16: =(((_xlfn.XLOOKUP(YEAR($B16),'Oferta Producto 1'!$B$8:$B$19,'Oferta Producto 1'!$E$8:$E$19))*$AD16)/$AB16)/24 -> 0 | AA16: =SUM(C16:Z16) -> 0 | AB16: =DAY(EOMONTH(B16,0)) -> 30 | AC16: =AA16*AB16 -> 0 | AD16: 0.12824537
A17: =YEAR(B17) -> 2026 | B17: 46357 | C17: =(((_xlfn.XLOOKUP(YEAR($B17),'Oferta Producto 1'!$B$8:$B$19,'Oferta Producto 1'!$E$8:$E$19))*$AD17)/$AB17)/24 -> 0 | D17: =(((_xlfn.XLOOKUP(YEAR($B17),'Oferta Producto 1'!$B$8:$B$19,'Oferta Producto 1'!$E$8:$E$19))*$AD17)/$AB17)/24 -> 0 | E17: =(((_xlfn.XLOOKUP(YEAR($B17),'Oferta Producto 1'!$B$8:$B$19,'Oferta Producto 1'!$E$8:$E$19))*$AD17)/$AB17)/24 -> 0 | F17: =(((_xlfn.XLOOKUP(YEAR($B17),'Oferta Producto 1'!$B$8:$B$19,'Oferta Producto 1'!$E$8:$E$19))*$AD17)/$AB17)/24 -> 0 | G17: =(((_xlfn.XLOOKUP(YEAR($B17),'Oferta Producto 1'!$B$8:$B$19,'Oferta Producto 1'!$E$8:$E$19))*$AD17)/$AB17)/24 -> 0 | H17: =(((_xlfn.XLOOKUP(YEAR($B17),'Oferta Producto 1'!$B$8:$B$19,'Oferta Producto 1'!$E$8:$E$19))*$AD17)/$AB17)/24 -> 0 | I17: =(((_xlfn.XLOOKUP(YEAR($B17),'Oferta Producto 1'!$B$8:$B$19,'Oferta Producto 1'!$E$8:$E$19))*$AD17)/$AB17)/24 -> 0 | J17: =(((_xlfn.XLOOKUP(YEAR($B17),'Oferta Producto 1'!$B$8:$B$19,'Oferta Producto 1'!$E$8:$E$19))*$AD17)/$AB17)/24 -> 0 | ... Z17: =(((_xlfn.XLOOKUP(YEAR($B17),'Oferta Producto 1'!$B$8:$B$19,'Oferta Producto 1'!$E$8:$E$19))*$AD17)/$AB17)/24 -> 0 | AA17: =SUM(C17:Z17) -> 0 | AB17: =DAY(EOMONTH(B17,0)) -> 31 | AC17: =AA17*AB17 -> 0 | AD17: 0.12545035
... A125: =YEAR(B125) -> 2035 | B125: 49644 | C125: =(((_xlfn.XLOOKUP(YEAR($B125),'Oferta Producto 1'!$B$8:$B$19,'Oferta Producto 1'!$E$8:$E$19))*$AD125)/$AB125)/24 -> 0 | D125: =(((_xlfn.XLOOKUP(YEAR($B125),'Oferta Producto 1'!$B$8:$B$19,'Oferta Producto 1'!$E$8:$E$19))*$AD125)/$AB125)/24 -> 0 | E125: =(((_xlfn.XLOOKUP(YEAR($B125),'Oferta Producto 1'!$B$8:$B$19,'Oferta Producto 1'!$E$8:$E$19))*$AD125)/$AB125)/24 -> 0 | F125: =(((_xlfn.XLOOKUP(YEAR($B125),'Oferta Producto 1'!$B$8:$B$19,'Oferta Producto 1'!$E$8:$E$19))*$AD125)/$AB125)/24 -> 0 | G125: =(((_xlfn.XLOOKUP(YEAR($B125),'Oferta Producto 1'!$B$8:$B$19,'Oferta Producto 1'!$E$8:$E$19))*$AD125)/$AB125)/24 -> 0 | H125: =(((_xlfn.XLOOKUP(YEAR($B125),'Oferta Producto 1'!$B$8:$B$19,'Oferta Producto 1'!$E$8:$E$19))*$AD125)/$AB125)/24 -> 0 | I125: =(((_xlfn.XLOOKUP(YEAR($B125),'Oferta Producto 1'!$B$8:$B$19,'Oferta Producto 1'!$E$8:$E$19))*$AD125)/$AB125)/24 -> 0 | J125: =(((_xlfn.XLOOKUP(YEAR($B125),'Oferta Producto 1'!$B$8:$B$19,'Oferta Producto 1'!$E$8:$E$19))*$AD125)/$AB125)/24 -> 0 | ... Z125: =(((_xlfn.XLOOKUP(YEAR($B125),'Oferta Producto 1'!$B$8:$B$19,'Oferta Producto 1'!$E$8:$E$19))*$AD125)/$AB125)/24 -> 0 | AA125: =SUM(C125:Z125) -> 0 | AB125: =DAY(EOMONTH(B125,0)) -> 31 | AC125: =AA125*AB125 -> 0 | AD125: 0.083026652
B126: TOTAL PERIODO | C126: =+SUM(C6:C125) -> 0 | D126: =+SUM(D6:D125) -> 0 | E126: =+SUM(E6:E125) -> 0 | F126: =+SUM(F6:F125) -> 0 | G126: =+SUM(G6:G125) -> 0 | H126: =+SUM(H6:H125) -> 0 | I126: =+SUM(I6:I125) -> 0 | J126: =+SUM(J6:J125) -> 0 | ... AC126: =+SUM(AC6:AC125) -> 0

Sheet Oferta Producto 2
B3: PRODUCTO No. 2
B4: PAGUE LO CONTRATADO PERIODO 2026 A 2035
B5: PRECIO OFERTADO EN $ / kWh DE ABRIL DE 2025
B8: AÑO | C8: ENERGIA SOLICITADA kWh/AÑO | D8: % OFERTADO | E8: ENERGIA OFERTADA kWh/AÑO | F8: PRECIO OFERTADO $/kWh
B10: 2026 | C10: =SUMIF('Curvas Prod 2'!A:AC,'Oferta Producto 2'!B10,'Curvas Prod 2'!AC:AC) -> 70349456 | E10: =ROUND(C10*D10,2) -> 0
B11: 2027 | C11: =SUMIF('Curvas Prod 2'!A:AC,'Oferta Producto 2'!B11,'Curvas Prod 2'!AC:AC) -> 1.0728046e+08 | E11: =ROUND(C11*D10,2) -> 0
B12: 2028 | C12: =SUMIF('Curvas Prod 2'!A:AC,'Oferta Producto 2'!B12,'Curvas Prod 2'!AC:AC) -> 1.37166e+08 | E12: =ROUND(C12*D10,2) -> 0
B13: 2029 | C13: =SUMIF('Curvas Prod 2'!A:AC,'Oferta Producto 2'!B13,'Curvas Prod 2'!AC:AC) -> 55282761 | E13: =ROUND(C13*D10,2) -> 0
B14: 2030 | C14: =SUMIF('Curvas Prod 2'!A:AC,'Oferta Producto 2'!B14,'Curvas Prod 2'!AC:AC) -> 55278863 | E14: =ROUND(C14*D10,2) -> 0
B15: 2031 | C15: =SUMIF('Curvas Prod 2'!A:AC,'Oferta Producto 2'!B15,'Curvas Prod 2'!AC:AC) -> 55278863 | E15: =ROUND(C15*D15,2) -> 0
B16: 2032 | C16: =SUMIF('Curvas Prod 2'!A:AC,'Oferta Producto 2'!B16,'Curvas Prod 2'!AC:AC) -> 55164942 | E16: =ROUND(C16*D15,2) -> 0
B17: 2033 | C17: =SUMIF('Curvas Prod 2'!A:AC,'Oferta Producto 2'!B17,'Curvas Prod 2'!AC:AC) -> 68064433 | E17: =ROUND(C17*D15,2) -> 0
B18: 2034 | C18: =SUMIF('Curvas Prod 2'!A:AC,'Oferta Producto 2'!B18,'Curvas Prod 2'!AC:AC) -> 1.5046587e+08 | E18: =ROUND(C18*D15,2) -> 0
B19: 2035 | C19: =SUMIF('Curvas Prod 2'!A:AC,'Oferta Producto 2'!B19,'Curvas Prod 2'!AC:AC) -> 1.5102003e+08 | E19: =ROUND(C19*D15,2) -> 0
B20: TOTAL | C20: =+SUM(C10:C19) -> 9.0535167e+08 | E20: =SUM(E10:E19) -> 0 | F20: =IFERROR(ROUND((SUM(E10:E14)*F10+SUM(E15:E19)*F10)/E20,2),0) -> 0
B22: Términos y condiciones
B23: Cantidad de Energía Ofertada
B24: Los interesados deberán indicar, para cada quinquenio, el porcentaje de energía eléctrica que están en capacidad de suministrar con relación a la energía solicitada para ese año. - Este porcentaje podrá variar para cada bloque de 5 años. - El valor mínimo de oferta permitido para cada quinquenio será del 10% de la energía solicitada correspondiente. - Los % ofertados se aplicaran a la curva de distribución de la hoja Curvas Prod 2 - Las ofertas de Producto 1 y Producto 2 se consideran mutuamente excluyentes, para efectos de comparación se determinará el Precio Promedio Ponderado (PPP) hecho por los oferentes. ENERBIT adjudicará el producto cuya oferta presente el menor PPP, siempre que cumpla con los requisitos de porcentaje mínimo. - En caso de empate en PPP, se preferirá la oferta con mayor porcentaje global promedio ofertado sobre el período completo.
B25: Precio Ofertado
B26: Los oferentes deberán indicar el precio unitario por kWh ofertado, el cual será válido para los 10 años de oferta (2026–2035)

Sheet Curvas Prod 2
B1: CURVAS REQUERIDAS PRODUCTO 2 PERIODO 2026 A 2035 MODALIDAD PAGUE LO CONTRATADO - kWh
B4: Periodo | C4: H00 | D4: H01 | E4: H02 | F4: H03 | G4: H04 | H4: H05 | I4: H06 | J4: H07 | K4: H08 | L4: H09 | M4: H10 | N4: H11 | O4: H12 | P4: H13 | Q4: H14 | R4: H15 | S4: H16 | T4: H17 | U4: H18 | V4: H19 | W4: H20 | X4: H21 | Y4: H22 | Z4: H23 | AA4: TOTAL DÍA | AB4: Días/ | AC4: TOTAL MES
AB5: mes
A6: =YEAR(B6) -> 2026 | B6: 46023 | C6: =($AC6/$AB6)/24 -> 4768.1774 | D6: =($AC6/$AB6)/24 -> 4768.1774 | E6: =($AC6/$AB6)/24 -> 4768.1774 | F6: =($AC6/$AB6)/24 -> 4768.1774 | G6: =($AC6/$AB6)/24 -> 4768.1774 | H6: =($AC6/$AB6)/24 -> 4768.1774 | I6: =($AC6/$AB6)/24 -> 4768.1774 | J6: =($AC6/$AB6)/24 -> 4768.1774 | ... Z6: =($AC6/$AB6)/24 -> 4768.1774 | AA6: =SUM(C6:Z6) -> 114436.26 | AB6: =DAY(EOMONTH(B6,0)) -> 31 | AC6: 3547524
A7: =YEAR(B7) -> 2026 | B7: 46054 | C7: =($AC7/$AB7)/24 -> 6450.4038 | D7: =($AC7/$AB7)/24 -> 6450.4038 | E7: =($AC7/$AB7)/24 -> 6450.4038 | F7: =($AC7/$AB7)/24 -> 6450.4038 | G7: =($AC7/$AB7)/24 -> 6450.4038 | H7: =($AC7/$AB7)/24 -> 6450.4038 | I7: =($AC7/$AB7)/24 -> 6450.4038 | J7: =($AC7/$AB7)/24 -> 6450.4038 | ... Z7: =($AC7/$AB7)/24 -> 6450.4038 | AA7: =SUM(C7:Z7) -> 154809.69 | AB7: =DAY(EOMONTH(B7,0)) -> 28 | AC7: 4334671.4
A8: =YEAR(B8) -> 2026 | B8: 46082 | C8: =($AC8/$AB8)/24 -> 5728.2544 | D8: =($AC8/$AB8)/24 -> 5728.2544 | E8: =($AC8/$AB8)/24 -> 5728.2544 | F8: =($AC8/$AB8)/24 -> 5728.2544 | G8: =($AC8/$AB8)/24 -> 5728.2544 | H8: =($AC8/$AB8)/24 -> 5728.2544 | I8: =($AC8/$AB8)/24 -> 5728.2544 | J8: =($AC8/$AB8)/24 -> 5728.2544 | ... Z8: =($AC8/$AB8)/24 -> 5728.2544 | AA8: =SUM(C8:Z8) -> 137478.11 | AB8: =DAY(EOMONTH(B8,0)) -> 31 | AC8: 4261821.3
A9: =YEAR(B9) -> 2026 | B9: 46113 | C9: =($AC9/$AB9)/24 -> 5156.8131 | D9: =($AC9/$AB9)/24 -> 5156.8131 | E9: =($AC9/$AB9)/24 -> 5156.8131 | F9: =($AC9/$AB9)/24 -> 5156.8131 | G9: =($AC9/$AB9)/24 -> 5156.8131 | H9: =($AC9/$AB9)/24 -> 5156.8131 | I9: =($AC9/$AB9)/24 -> 5156.8131 | J9: =($AC9/$AB9)/24 -> 5156.8131 | ... Z9: =($AC9/$AB9)/24 -> 5156.8131 | AA9: =SUM(C9:Z9) -> 123763.51 | AB9: =DAY(EOMONTH(B9,0)) -> 30 | AC9: 3712905.4
A10: =YEAR(B10) -> 2026 | B10: 46143 | C10: =($AC10/$AB10)/24 -> 5731.64 | D10: =($AC10/$AB10)/24 -> 5731.64 | E10: =($AC10/$AB10)/24 -> 5731.64 | F10: =($AC10/$AB10)/24 -> 5731.64 | G10: =($AC10/$AB10)/24 -> 5731.64 | H10: =($AC10/$AB10)/24 -> 5731.64 | I10: =($AC10/$AB10)/24 -> 5731.64 | J10: =($AC10/$AB10)/24 -> 5731.64 | ... Z10: =($AC10/$AB10)/24 -> 5731.64 | AA10: =SUM(C10:Z10) -> 137559.36 | AB10: =DAY(EOMONTH(B10,0)) -> 31 | AC10: 4264340.2
A11: =YEAR(B11) -> 2026 | B11: 46174 | C11: =($AC11/$AB11)/24 -> 6235.7731 | D11: =($AC11/$AB11)/24 -> 6235.7731 | E11: =($AC11/$AB11)/24 -> 6235.7731 | F11: =($AC11/$AB11)/24 -> 6235.7731 | G11: =($AC11/$AB11)/24 -> 6235.7731 | H11: =($AC11/$AB11)/24 -> 6235.7731 | I11: =($AC11/$AB11)/24 -> 6235.7731 | J11: =($AC11/$AB11)/24 -> 6235.7731 | ... Z11: =($AC11/$AB11)/24 -> 6235.7731 | AA11: =SUM(C11:Z11) -> 149658.55 | AB11: =DAY(EOMONTH(B11,0)) -> 30 | AC11: 4489756.6
A12: =YEAR(B12) -> 2026 | B12: 46204 | C12: =($AC12/$AB12)/24 -> 6002.207 | D12: =($AC12/$AB12)/24 -> 6002.207 | E12: =($AC12/$AB12)/24 -> 6002.207 | F12: =($AC12/$AB12)/24 -> 6002.207 | G12: =($AC12/$AB12)/24 -> 6002.207 | H12: =($AC12/$AB12)/24 -> 6002.207 | I12: =($AC12/$AB12)/24 -> 6002.207 | J12: =($AC12/$AB12)/24 -> 6002.207 | ... Z12: =($AC12/$AB12)/24 -> 6002.207 | AA12: =SUM(C12:Z12) -> 144052.97 | AB12: =DAY(EOMONTH(B12,0)) -> 31 | AC12: 4465642
A13: =YEAR(B13) -> 2026 | B13: 46235 | C13: =($AC13/$AB13)/24 -> 7497.4237 | D13: =($AC13/$AB13)/24 -> 7497.4237 | E13: =($AC13/$AB13)/24 -> 7497.4237 | F13: =($AC13/$AB13)/24 -> 7497.4237 | G13: =($AC13/$AB13)/24 -> 7497.4237 | H13: =($AC13/$AB13)/24 -> 7497.4237 | I13: =($AC13/$AB13)/24 -> 7497.4237 | J13: =($AC13/$AB13)/24 -> 7497.4237 | ... Z13: =($AC13/$AB13)/24 -> 7497.4237 | AA13: =SUM(C13:Z13) -> 179938.17 | AB13: =DAY(EOMONTH(B13,0)) -> 31 | AC13: 5578083.2
A14: =YEAR(B14) -> 2026 | B14: 46266 | C14: =($AC14/$AB14)/24 -> 12530.544 | D14: =($AC14/$AB14)/24 -> 12530.544 | E14: =($AC14/$AB14)/24 -> 12530.544 | F14: =($AC14/$AB14)/24 -> 12530.544 | G14: =($AC14/$AB14)/24 -> 12530.544 | H14: =($AC14/$AB14)/24 -> 12530.544 | I14: =($AC14/$AB14)/24 -> 12530.544 | J14: =($AC14/$AB14)/24 -> 12530.544 | ... Z14: =($AC14/$AB14)/24 -> 12530.544 | AA14: =SUM(C14:Z14) -> 300733.07 | AB14: =DAY(EOMONTH(B14,0)) -> 30 | AC14: 9021992
A15: =YEAR(B15) -> 2026 | B15: 46296 | C15: =($AC15/$AB15)/24 -> 11862.048 | D15: =($AC15/$AB15)/24 -> 11862.048 | E15: =($AC15/$AB15)/24 -> 11862.048 | F15: =($AC15/$AB15)/24 -> 11862.048 | G15: =($AC15/$AB15)/24 -> 11862.048 | H15: =($AC15/$AB15)/24 -> 11862.048 | I15: =($AC15/$AB15)/24 -> 11862.048 | J15: =($AC15/$AB15)/24 -> 11862.048 | ... Z15: =($AC15/$AB15)/24 -> 11862.048 | AA15: =SUM(C15:Z15) -> 284689.16 | AB15: =DAY(EOMONTH(B15,0)) -> 31 | AC15: 8825363.9
A16: =YEAR(B16) -> 2026 | B16: 46327 | C16: =($AC16/$AB16)/24 -> 12530.544 | D16: =($AC16/$AB16)/24 -> 12530.544 | E16: =($AC16/$AB16)/24 -> 12530.544 | F16: =($AC16/$AB16)/24 -> 12530.544 | G16: =($AC16/$AB16)/24 -> 12530.544 | H16: =($AC16/$AB16)/24 -> 12530.544 | I16: =($AC16/$AB16)/24 -> 12530.544 | J16: =($AC16/$AB16)/24 -> 12530.544 | ... Z16: =($AC16/$AB16)/24 -> 12530.544 | AA16: =SUM(C16:Z16) -> 300733.07 | AB16: =DAY(EOMONTH(B16,0)) -> 30 | AC16: 9021992
A17: =YEAR(B17) -> 2026 | B17: 46357 | C17: =($AC17/$AB17)/24 -> 11862.048 | D17: =($AC17/$AB17)/24 -> 11862.048 | E17: =($AC17/$AB17)/24 -> 11862.048 | F17: =($AC17/$AB17)/24 -> 11862.048 | G17: =($AC17/$AB17)/24 -> 11862.048 | H17: =($AC17/$AB17)/24 -> 11862.048 | I17: =($AC17/$AB17)/24 -> 11862.048 | J17: =($AC17/$AB17)/24 -> 11862.048 | ... Z17: =($AC17/$AB17)/24 -> 11862.048 | AA17: =SUM(C17:Z17) -> 284689.16 | AB17: =DAY(EOMONTH(B17,0)) -> 31 | AC17: 8825363.9
... A125: =YEAR(B125) -> 2035 | B125: 49644 | C125: =($AC125/$AB125)/24 -> 16853.075 | D125: =($AC125/$AB125)/24 -> 16853.075 | E125: =($AC125/$AB125)/24 -> 16853.075 | F125: =($AC125/$AB125)/24 -> 16853.075 | G125: =($AC125/$AB125)/24 -> 16853.075 | H125: =($AC125/$AB125)/24 -> 16853.075 | I125: =($AC125/$AB125)/24 -> 16853.075 | J125: =($AC125/$AB125)/24 -> 16853.075 | ... Z125: =($AC125/$AB125)/24 -> 16853.075 | AA125: =SUM(C125:Z125) -> 404473.8 | AB125: =DAY(EOMONTH(B125,0)) -> 31 | AC125: 12538688
B126: TOTAL PERIODO | C126: =+SUM(C6:C125) -> 1241147.8 | D126: =+SUM(D6:D125) -> 1241147.8 | E126: =+SUM(E6:E125) -> 1241147.8 | F126: =+SUM(F6:F125) -> 1241147.8 | G126: =+SUM(G6:G125) -> 1241147.8 | H126: =+SUM(H6:H125) -> 1241147.8 | I126: =+SUM(I6:I125) -> 1241147.8 | J126: =+SUM(J6:J125) -> 1241147.8 | ... AC126: =+SUM(AC6:AC125) -> 9.0535167e+08

Sheet Curva de la oferta Prod 2
B1: CURVAS REQUERIDAS PRODUCTO 2 PERIODO 2026 A 2035 MODALIDAD PAGUE LO CONTRATADO - kWh
B4: Periodo | C4: H00 | D4: H01 | E4: H02 | F4: H03 | G4: H04 | H4: H05 | I4: H06 | J4: H07 | K4: H08 | L4: H09 | M4: H10 | N4: H11 | O4: H12 | P4: H13 | Q4: H14 | R4: H15 | S4: H16 | T4: H17 | U4: H18 | V4: H19 | W4: H20 | X4: H21 | Y4: H22 | Z4: H23 | AA4: TOTAL DÍA | AB4: Días/ | AC4: TOTAL MES | AD4: % Distribución oferta
AB5: mes
A6: =YEAR(B6) -> 2026 | B6: 46023 | C6: =(((_xlfn.XLOOKUP(YEAR($B6),'Oferta Producto 2'!$B$8:$B$19,'Oferta Producto 2'!$E$8:$E$19))*$AD6)/$AB6)/24 -> 0 | D6: =(((_xlfn.XLOOKUP(YEAR($B6),'Oferta Producto 2'!$B$8:$B$19,'Oferta Producto 2'!$E$8:$E$19))*$AD6)/$AB6)/24 -> 0 | E6: =(((_xlfn.XLOOKUP(YEAR($B6),'Oferta Producto 2'!$B$8:$B$19,'Oferta Producto 2'!$E$8:$E$19))*$AD6)/$AB6)/24 -> 0 | F6: =(((_xlfn.XLOOKUP(YEAR($B6),'Oferta Producto 2'!$B$8:$B$19,'Oferta Producto 2'!$E$8:$E$19))*$AD6)/$AB6)/24 -> 0 | G6: =(((_xlfn.XLOOKUP(YEAR($B6),'Oferta Producto 2'!$B$8:$B$19,'Oferta Producto 2'!$E$8:$E$19))*$AD6)/$AB6)/24 -> 0 | H6: =(((_xlfn.XLOOKUP(YEAR($B6),'Oferta Producto 2'!$B$8:$B$19,'Oferta Producto 2'!$E$8:$E$19))*$AD6)/$AB6)/24 -> 0 | I6: =(((_xlfn.XLOOKUP(YEAR($B6),'Oferta Producto 2'!$B$8:$B$19,'Oferta Producto 2'!$E$8:$E$19))*$AD6)/$AB6)/24 -> 0 | J6: =(((_xlfn.XLOOKUP(YEAR($B6),'Oferta Producto 2'!$B$8:$B$19,'Oferta Producto 2'!$E$8:$E$19))*$AD6)/$AB6)/24 -> 0 | ... Z6: =(((_xlfn.XLOOKUP(YEAR($B6),'Oferta Producto 2'!$B$8:$B$19,'Oferta Producto 2'!$E$8:$E$19))*$AD6)/$AB6)/24 -> 0 | AA6: =SUM(C6:Z6) -> 0 | AB6: =DAY(EOMONTH(B6,0)) -> 31 | AC6: =AA6*AB6 -> 0 | AD6: 0.050427171
A7: =YEAR(B7) -> 2026 | B7: 46054 | C7: =(((_xlfn.XLOOKUP(YEAR($B7),'Oferta Producto 2'!$B$8:$B$19,'Oferta Producto 2'!$E$8:$E$19))*$AD7)/$AB7)/24 -> 0 | D7: =(((_xlfn.XLOOKUP(YEAR($B7),'Oferta Producto 2'!$B$8:$B$19,'Oferta Producto 2'!$E$8:$E$19))*$AD7)/$AB7)/24 -> 0 | E7: =(((_xlfn.XLOOKUP(YEAR($B7),'Oferta Producto 2'!$B$8:$B$19,'Oferta Producto 2'!$E$8:$E$19))*$AD7)/$AB7)/24 -> 0 | F7: =(((_xlfn.XLOOKUP(YEAR($B7),'Oferta Producto 2'!$B$8:$B$19,'Oferta Producto 2'!$E$8:$E$19))*$AD7)/$AB7)/24 -> 0 | G7: =(((_xlfn.XLOOKUP(YEAR($B7),'Oferta Producto 2'!$B$8:$B$19,'Oferta Producto 2'!$E$8:$E$19))*$AD7)/$AB7)/24 -> 0 | H7: =(((_xlfn.XLOOKUP(YEAR($B7),'Oferta Producto 2'!$B$8:$B$19,'Oferta Producto 2'!$E$8:$E$19))*$AD7)/$AB7)/24 -> 0 | I7: =(((_xlfn.XLOOKUP(YEAR($B7),'Oferta Producto 2'!$B$8:$B$19,'Oferta Producto 2'!$E$8:$E$19))*$AD7)/$AB7)/24 -> 0 | J7: =(((_xlfn.XLOOKUP(YEAR($B7),'Oferta Producto 2'!$B$8:$B$19,'Oferta Producto 2'!$E$8:$E$19))*$AD7)/$AB7)/24 -> 0 | ... Z7: =(((_xlfn.XLOOKUP(YEAR($B7),'Oferta Producto 2'!$B$8:$B$19,'Oferta Producto 2'!$E$8:$E$19))*$AD7)/$AB7)/24 -> 0 | AA7: =SUM(C7:Z7) -> 0 | AB7: =DAY(EOMONTH(B7,0)) -> 28 | AC7: =AA7*AB7 -> 0 | AD7: 0.061616274
A8: =YEAR(B8) -> 2026 | B8: 46082 | C8: =(((_xlfn.XLOOKUP(YEAR($B8),'Oferta Producto 2'!$B$8:$B$19,'Oferta Producto 2'!$E$8:$E$19))*$AD8)/$AB8)/24 -> 0 | D8: =(((_xlfn.XLOOKUP(YEAR($B8),'Oferta Producto 2'!$B$8:$B$19,'Oferta Producto 2'!$E$8:$E$19))*$AD8)/$AB8)/24 -> 0 | E8: =(((_xlfn.XLOOKUP(YEAR($B8),'Oferta Producto 2'!$B$8:$B$19,'Oferta Producto 2'!$E$8:$E$19))*$AD8)/$AB8)/24 -> 0 | F8: =(((_xlfn.XLOOKUP(YEAR($B8),'Oferta Producto 2'!$B$8:$B$19,'Oferta Producto 2'!$E$8:$E$19))*$AD8)/$AB8)/24 -> 0 | G8: =(((_xlfn.XLOOKUP(YEAR($B8),'Oferta Producto 2'!$B$8:$B$19,'Oferta Producto 2'!$E$8:$E$19))*$AD8)/$AB8)/24 -> 0 | H8: =(((_xlfn.XLOOKUP(YEAR($B8),'Oferta Producto 2'!$B$8:$B$19,'Oferta Producto 2'!$E$8:$E$19))*$AD8)/$AB8)/24 -> 0 | I8: =(((_xlfn.XLOOKUP(YEAR($B8),'Oferta Producto 2'!$B$8:$B$19,'Oferta Producto 2'!$E$8:$E$19))*$AD8)/$AB8)/24 -> 0 | J8: =(((_xlfn.XLOOKUP(YEAR($B8),'Oferta Producto 2'!$B$8:$B$19,'Oferta Producto 2'!$E$8:$E$19))*$AD8)/$AB8)/24 -> 0 | ... Z8: =(((_xlfn.XLOOKUP(YEAR($B8),'Oferta Producto 2'!$B$8:$B$19,'Oferta Producto 2'!$E$8:$E$19))*$AD8)/$AB8)/24 -> 0 | AA8: =SUM(C8:Z8) -> 0 | AB8: =DAY(EOMONTH(B8,0)) -> 31 | AC8: =AA8*AB8 -> 0 | AD8: 0.060580729
A9: =YEAR(B9) -> 2026 | B9: 46113 | C9: =(((_xlfn.XLOOKUP(YEAR($B9),'Oferta Producto 2'!$B$8:$B$19,'Oferta Producto 2'!$E$8:$E$19))*$AD9)/$AB9)/24 -> 0 | D9: =(((_xlfn.XLOOKUP(YEAR($B9),'Oferta Producto 2'!$B$8:$B$19,'Oferta Producto 2'!$E$8:$E$19))*$AD9)/$AB9)/24 -> 0 | E9: =(((_xlfn.XLOOKUP(YEAR($B9),'Oferta Producto 2'!$B$8:$B$19,'Oferta Producto 2'!$E$8:$E$19))*$AD9)/$AB9)/24 -> 0 | F9: =(((_xlfn.XLOOKUP(YEAR($B9),'Oferta Producto 2'!$B$8:$B$19,'Oferta Producto 2'!$E$8:$E$19))*$AD9)/$AB9)/24 -> 0 | G9: =(((_xlfn.XLOOKUP(YEAR($B9),'Oferta Producto 2'!$B$8:$B$19,'Oferta Producto 2'!$E$8:$E$19))*$AD9)/$AB9)/24 -> 0 | H9: =(((_xlfn.XLOOKUP(YEAR($B9),'Oferta Producto 2'!$B$8:$B$19,'Oferta Producto 2'!$E$8:$E$19))*$AD9)/$AB9)/24 -> 0 | I9: =(((_xlfn.XLOOKUP(YEAR($B9),'Oferta Producto 2'!$B$8:$B$19,'Oferta Producto 2'!$E$8:$E$19))*$AD9)/$AB9)/24 -> 0 | J9: =(((_xlfn.XLOOKUP(YEAR($B9),'Oferta Producto 2'!$B$8:$B$19,'Oferta Producto 2'!$E$8:$E$19))*$AD9)/$AB9)/24 -> 0 | ... Z9: =(((_xlfn.XLOOKUP(YEAR($B9),'Oferta Producto 2'!$B$8:$B$19,'Oferta Producto 2'!$E$8:$E$19))*$AD9)/$AB9)/24 -> 0 | AA9: =SUM(C9:Z9) -> 0 | AB9: =DAY(EOMONTH(B9,0)) -> 30 | AC9: =AA9*AB9 -> 0 | AD9: 0.052778026
A10: =YEAR(B10) -> 2026 | B10: 46143 | C10: =(((_xlfn.XLOOKUP(YEAR($B10),'Oferta Producto 2'!$B$8:$B$19,'Oferta Producto 2'!$E$8:$E$19))*$AD10)/$AB10)/24 -> 0 | D10: =(((_xlfn.XLOOKUP(YEAR($B10),'Oferta Producto 2'!$B$8:$B$19,'Oferta Producto 2'!$E$8:$E$19))*$AD10)/$AB10)/24 -> 0 | E10: =(((_xlfn.XLOOKUP(YEAR($B10),'Oferta Producto 2'!$B$8:$B$19,'Oferta Producto 2'!$E$8:$E$19))*$AD10)/$AB10)/24 -> 0 | F10: =(((_xlfn.XLOOKUP(YEAR($B10),'Oferta Producto 2'!$B$8:$B$19,'Oferta Producto 2'!$E$8:$E$19))*$AD10)/$AB10)/24 -> 0 | G10: =(((_xlfn.XLOOKUP(YEAR($B10),'Oferta Producto 2'!$B$8:$B$19,'Oferta Producto 2'!$E$8:$E$19))*$AD10)/$AB10)/24 -> 0 | H10: =(((_xlfn.XLOOKUP(YEAR($B10),'Oferta Producto 2'!$B$8:$B$19,'Oferta Producto 2'!$E$8:$E$19))*$AD10)/$AB10)/24 -> 0 | I10: =(((_xlfn.XLOOKUP(YEAR($B10),'Oferta Producto 2'!$B$8:$B$19,'Oferta Producto 2'!$E$8:$E$19))*$AD10)/$AB10)/24 -> 0 | J10: =(((_xlfn.XLOOKUP(YEAR($B10),'Oferta Producto 2'!$B$8:$B$19,'Oferta Producto 2'!$E$8:$E$19))*$AD10)/$AB10)/24 -> 0 | ... Z10: =(((_xlfn.XLOOKUP(YEAR($B10),'Oferta Producto 2'!$B$8:$B$19,'Oferta Producto 2'!$E$8:$E$19))*$AD10)/$AB10)/24 -> 0 | AA10: =SUM(C10:Z10) -> 0 | AB10: =DAY(EOMONTH(B10,0)) -> 31 | AC10: =AA10*AB10 -> 0 | AD10: 0.060616534
A11: =YEAR(B11) -> 2026 | B11: 46174 | C11: =(((_xlfn.XLOOKUP(YEAR($B11),'Oferta Producto 2'!$B$8:$B$19,'Oferta Producto 2'!$E$8:$E$19))*$AD11)/$AB11)/24 -> 0 | D11: =(((_xlfn.XLOOKUP(YEAR($B11),'Oferta Producto 2'!$B$8:$B$19,'Oferta Producto 2'!$E$8:$E$19))*$AD11)/$AB11)/24 -> 0 | E11: =(((_xlfn.XLOOKUP(YEAR($B11),'Oferta Producto 2'!$B$8:$B$19,'Oferta Producto 2'!$E$8:$E$19))*$AD11)/$AB11)/24 -> 0 | F11: =(((_xlfn.XLOOKUP(YEAR($B11),'Oferta Producto 2'!$B$8:$B$19,'Oferta Producto 2'!$E$8:$E$19))*$AD11)/$AB11)/24 -> 0 | G11: =(((_xlfn.XLOOKUP(YEAR($B11),'Oferta Producto 2'!$B$8:$B$19,'Oferta Producto 2'!$E$8:$E$19))*$AD11)/$AB11)/24 -> 0 | H11: =(((_xlfn.XLOOKUP(YEAR($B11),'Oferta Producto 2'!$B$8:$B$19,'Oferta Producto 2'!$E$8:$E$19))*$AD11)/$AB11)/24 -> 0 | I11: =(((_xlfn.XLOOKUP(YEAR($B11),'Oferta Producto 2'!$B$8:$B$19,'Oferta Producto 2'!$E$8:$E$19))*$AD11)/$AB11)/24 -> 0 | J11: =(((_xlfn.XLOOKUP(YEAR($B11),'Oferta Producto 2'!$B$8:$B$19,'Oferta Producto 2'!$E$8:$E$19))*$AD11)/$AB11)/24 -> 0 | ... Z11: =(((_xlfn.XLOOKUP(YEAR($B11),'Oferta Producto 2'!$B$8:$B$19,'Oferta Producto 2'!$E$8:$E$19))*$AD11)/$AB11)/24 -> 0 | AA11: =SUM(C11:Z11) -> 0 | AB11: =DAY(EOMONTH(B11,0)) -> 30 | AC11: =AA11*AB11 -> 0 | AD11: 0.063820773
A12: =YEAR(B12) -> 2026 | B12: 46204 | C12: =(((_xlfn.XLOOKUP(YEAR($B12),'Oferta Producto 2'!$B$8:$B$19,'Oferta Producto 2'!$E$8:$E$19))*$AD12)/$AB12)/24 -> 0 | D12: =(((_xlfn.XLOOKUP(YEAR($B12),'Oferta Producto 2'!$B$8:$B$19,'Oferta Producto 2'!$E$8:$E$19))*$AD12)/$AB12)/24 -> 0 | E12: =(((_xlfn.XLOOKUP(YEAR($B12),'Oferta Producto 2'!$B$8:$B$19,'Oferta Producto 2'!$E$8:$E$19))*$AD12)/$AB12)/24 -> 0 | F12: =(((_xlfn.XLOOKUP(YEAR($B12),'Oferta Producto 2'!$B$8:$B$19,'Oferta Producto 2'!$E$8:$E$19))*$AD12)/$AB12)/24 -> 0 | G12: =(((_xlfn.XLOOKUP(YEAR($B12),'Oferta Producto 2'!$B$8:$B$19,'Oferta Producto 2'!$E$8:$E$19))*$AD12)/$AB12)/24 -> 0 | H12: =(((_xlfn.XLOOKUP(YEAR($B12),'Oferta Producto 2'!$B$8:$B$19,'Oferta Producto 2'!$E$8:$E$19))*$AD12)/$AB12)/24 -> 0 | I12: =(((_xlfn.XLOOKUP(YEAR($B12),'Oferta Producto 2'!$B$8:$B$19,'Oferta Producto 2'!$E$8:$E$19))*$AD12)/$AB12)/24 -> 0 | J12: =(((_xlfn.XLOOKUP(YEAR($B12),'Oferta Producto 2'!$B$8:$B$19,'Oferta Producto 2'!$E$8:$E$19))*$AD12)/$AB12)/24 -> 0 | ... Z12: =(((_xlfn.XLOOKUP(YEAR($B12),'Oferta Producto 2'!$B$8:$B$19,'Oferta Producto 2'!$E$8:$E$19))*$AD12)/$AB12)/24 -> 0 | AA12: =SUM(C12:Z12) -> 0 | AB12: =DAY(EOMONTH(B12,0)) -> 31 | AC12: =AA12*AB12 -> 0 | AD12: 0.063477989
A13: =YEAR(B13) -> 2026 | B13: 46235 | C13: =(((_xlfn.XLOOKUP(YEAR($B13),'Oferta Producto 2'!$B$8:$B$19,'Oferta Producto 2'!$E$8:$E$19))*$AD13)/$AB13)/24 -> 0 | D13: =(((_xlfn.XLOOKUP(YEAR($B13),'Oferta Producto 2'!$B$8:$B$19,'Oferta Producto 2'!$E$8:$E$19))*$AD13)/$AB13)/24 -> 0 | E13: =(((_xlfn.XLOOKUP(YEAR($B13),'Oferta Producto 2'!$B$8:$B$19,'Oferta Producto 2'!$E$8:$E$19))*$AD13)/$AB13)/24 -> 0 | F13: =(((_xlfn.XLOOKUP(YEAR($B13),'Oferta Producto 2'!$B$8:$B$19,'Oferta Producto 2'!$E$8:$E$19))*$AD13)/$AB13)/24 -> 0 | G13: =(((_xlfn.XLOOKUP(YEAR($B13),'Oferta Producto 2'!$B$8:$B$19,'Oferta Producto 2'!$E$8:$E$19))*$AD13)/$AB13)/24 -> 0 | H13: =(((_xlfn.XLOOKUP(YEAR($B13),'Oferta Producto 2'!$B$8:$B$19,'Oferta Producto 2'!$E$8:$E$19))*$AD13)/$AB13)/24 -> 0 | I13: =(((_xlfn.XLOOKUP(YEAR($B13),'Oferta Producto 2'!$B$8:$B$19,'Oferta Producto 2'!$E$8:$E$19))*$AD13)/$AB13)/24 -> 0 | J13: =(((_xlfn.XLOOKUP(YEAR($B13),'Oferta Producto 2'!$B$8:$B$19,'Oferta Producto 2'!$E$8:$E$19))*$AD13)/$AB13)/24 -> 0 | ... Z13: =(((_xlfn.XLOOKUP(YEAR($B13),'Oferta Producto 2'!$B$8:$B$19,'Oferta Producto 2'!$E$8:$E$19))*$AD13)/$AB13)/24 -> 0 | AA13: =SUM(C13:Z13) -> 0 | AB13: =DAY(EOMONTH(B13,0)) -> 31 | AC13: =AA13*AB13 -> 0 | AD13: 0.079291064
A14: =YEAR(B14) -> 2026 | B14: 46266 | C14: =(((_xlfn.XLOOKUP(YEAR($B14),'Oferta Producto 2'!$B$8:$B$19,'Oferta Producto 2'!$E$8:$E$19))*$AD14)/$AB14)/24 -> 0 | D14: =(((_xlfn.XLOOKUP(YEAR($B14),'Oferta Producto 2'!$B$8:$B$19,'Oferta Producto 2'!$E$8:$E$19))*$AD14)/$AB14)/24 -> 0 | E14: =(((_xlfn.XLOOKUP(YEAR($B14),'Oferta Producto 2'!$B$8:$B$19,'Oferta Producto 2'!$E$8:$E$19))*$AD14)/$AB14)/24 -> 0 | F14: =(((_xlfn.XLOOKUP(YEAR($B14),'Oferta Producto 2'!$B$8:$B$19,'Oferta Producto 2'!$E$8:$E$19))*$AD14)/$AB14)/24 -> 0 | G14: =(((_xlfn.XLOOKUP(YEAR($B14),'Oferta Producto 2'!$B$8:$B$19,'Oferta Producto 2'!$E$8:$E$19))*$AD14)/$AB14)/24 -> 0 | H14: =(((_xlfn.XLOOKUP(YEAR($B14),'Oferta Producto 2'!$B$8:$B$19,'Oferta Producto 2'!$E$8:$E$19))*$AD14)/$AB14)/24 -> 0 | I14: =(((_xlfn.XLOOKUP(YEAR($B14),'Oferta Producto 2'!$B$8:$B$19,'Oferta Producto 2'!$E$8:$E$19))*$AD14)/$AB14)/24 -> 0 | J14: =(((_xlfn.XLOOKUP(YEAR($B14),'Oferta Producto 2'!$B$8:$B$19,'Oferta Producto 2'!$E$8:$E$19))*$AD14)/$AB14)/24 -> 0 | ... Z14: =(((_xlfn.XLOOKUP(YEAR($B14),'Oferta Producto 2'!$B$8:$B$19,'Oferta Producto 2'!$E$8:$E$19))*$AD14)/$AB14)/24 -> 0 | AA14: =SUM(C14:Z14) -> 0 | AB14: =DAY(EOMONTH(B14,0)) -> 30 | AC14: =AA14*AB14 -> 0 | AD14: 0.12824537
A15: =YEAR(B15) -> 2026 | B15: 46296 | C15: =(((_xlfn.XLOOKUP(YEAR($B15),'Oferta Producto 2'!$B$8:$B$19,'Oferta Producto 2'!$E$8:$E$19))*$AD15)/$AB15)/24 -> 0 | D15: =(((_xlfn.XLOOKUP(YEAR($B15),'Oferta Producto 2'!$B$8:$B$19,'Oferta Producto 2'!$E$8:$E$19))*$AD15)/$AB15)/24 -> 0 | E15: =(((_xlfn.XLOOKUP(YEAR($B15),'Oferta Producto 2'!$B$8:$B$19,'Oferta Producto 2'!$E$8:$E$19))*$AD15)/$AB15)/24 -> 0 | F15: =(((_xlfn.XLOOKUP(YEAR($B15),'Oferta Producto 2'!$B$8:$B$19,'Oferta Producto 2'!$E$8:$E$19))*$AD15)/$AB15)/24 -> 0 | G15: =(((_xlfn.XLOOKUP(YEAR($B15),'Oferta Producto 2'!$B$8:$B$19,'Oferta Producto 2'!$E$8:$E$19))*$AD15)/$AB15)/24 -> 0 | H15: =(((_xlfn.XLOOKUP(YEAR($B15),'Oferta Producto 2'!$B$8:$B$19,'Oferta Producto 2'!$E$8:$E$19))*$AD15)/$AB15)/24 -> 0 | I15: =(((_xlfn.XLOOKUP(YEAR($B15),'Oferta Producto 2'!$B$8:$B$19,'Oferta Producto 2'!$E$8:$E$19))*$AD15)/$AB15)/24 -> 0 | J15: =(((_xlfn.XLOOKUP(YEAR($B15),'Oferta Producto 2'!$B$8:$B$19,'Oferta Producto 2'!$E$8:$E$19))*$AD15)/$AB15)/24 -> 0 | ... Z15: =(((_xlfn.XLOOKUP(YEAR($B15),'Oferta Producto 2'!$B$8:$B$19,'Oferta Producto 2'!$E$8:$E$19))*$AD15)/$AB15)/24 -> 0 | AA15: =SUM(C15:Z15) -> 0 | AB15: =DAY(EOMONTH(B15,0)) -> 31 | AC15: =AA15*AB15 -> 0 | AD15: 0.12545035
A16: =YEAR(B16) -> 2026 | B16: 46327 | C16: =(((_xlfn.XLOOKUP(YEAR($B16),'Oferta Producto 2'!$B$8:$B$19,'Oferta Producto 2'!$E$8:$E$19))*$AD16)/$AB16)/24 -> 0 | D16: =(((_xlfn.XLOOKUP(YEAR($B16),'Oferta Producto 2'!$B$8:$B$19,'Oferta Producto 2'!$E$8:$E$19))*$AD16)/$AB16)/24 -> 0 | E16: =(((_xlfn.XLOOKUP(YEAR($B16),'Oferta Producto 2'!$B$8:$B$19,'Oferta Producto 2'!$E$8:$E$19))*$AD16)/$AB16)/24 -> 0 | F16: =(((_xlfn.XLOOKUP(YEAR($B16),'Oferta Producto 2'!$B$8:$B$19,'Oferta Producto 2'!$E$8:$E$19))*$AD16)/$AB16)/24 -> 0 | G16: =(((_xlfn.XLOOKUP(YEAR($B16),'Oferta Producto 2'!$B$8:$B$19,'Oferta Producto 2'!$E$8:$E$19))*$AD16)/$AB16)/24 -> 0 | H16: =(((_xlfn.XLOOKUP(YEAR($B16),'Oferta Producto 2'!$B$8:$B$19,'Oferta Producto 2'!$E$8:$E$19))*$AD16)/$AB16)/24 -> 0 | I16: =(((_xlfn.XLOOKUP(YEAR($B16),'Oferta Producto 2'!$B$8:$B$19,'Oferta Producto 2'!$E$8:$E$19))*$AD16)/$AB16)/24 -> 0 | J16: =(((_xlfn.XLOOKUP(YEAR($B16),'Oferta Producto 2'!$B$8:$B$19,'Oferta Producto 2'!$E$8:$E$19))*$AD16)/$AB16)/24 -> 0 | ... Z16: =(((_xlfn.XLOOKUP(YEAR($B16),'Oferta Producto 2'!$B$8:$B$19,'Oferta Producto 2'!$E$8:$E$19))*$AD16)/$AB16)/24 -> 0 | AA16: =SUM(C16:Z16) -> 0 | AB16: =DAY(EOMONTH(B16,0)) -> 30 | AC16: =AA16*AB16 -> 0 | AD16: 0.12824537
A17: =YEAR(B17) -> 2026 | B17: 46357 | C17: =(((_xlfn.XLOOKUP(YEAR($B17),'Oferta Producto 2'!$B$8:$B$19,'Oferta Producto 2'!$E$8:$E$19))*$AD17)/$AB17)/24 -> 0 | D17: =(((_xlfn.XLOOKUP(YEAR($B17),'Oferta Producto 2'!$B$8:$B$19,'Oferta Producto 2'!$E$8:$E$19))*$AD17)/$AB17)/24 -> 0 | E17: =(((_xlfn.XLOOKUP(YEAR($B17),'Oferta Producto 2'!$B$8:$B$19,'Oferta Producto 2'!$E$8:$E$19))*$AD17)/$AB17)/24 -> 0 | F17: =(((_xlfn.XLOOKUP(YEAR($B17),'Oferta Producto 2'!$B$8:$B$19,'Oferta Producto 2'!$E$8:$E$19))*$AD17)/$AB17)/24 -> 0 | G17: =(((_xlfn.XLOOKUP(YEAR($B17),'Oferta Producto 2'!$B$8:$B$19,'Oferta Producto 2'!$E$8:$E$19))*$AD17)/$AB17)/24 -> 0 | H17: =(((_xlfn.XLOOKUP(YEAR($B17),'Oferta Producto 2'!$B$8:$B$19,'Oferta Producto 2'!$E$8:$E$19))*$AD17)/$AB17)/24 -> 0 | I17: =(((_xlfn.XLOOKUP(YEAR($B17),'Oferta Producto 2'!$B$8:$B$19,'Oferta Producto 2'!$E$8:$E$19))*$AD17)/$AB17)/24 -> 0 | J17: =(((_xlfn.XLOOKUP(YEAR($B17),'Oferta Producto 2'!$B$8:$B$19,'Oferta Producto 2'!$E$8:$E$19))*$AD17)/$AB17)/24 -> 0 | ... Z17: =(((_xlfn.XLOOKUP(YEAR($B17),'Oferta Producto 2'!$B$8:$B$19,'Oferta Producto 2'!$E$8:$E$19))*$AD17)/$AB17)/24 -> 0 | AA17: =SUM(C17:Z17) -> 0 | AB17: =DAY(EOMONTH(B17,0)) -> 31 | AC17: =AA17*AB17 -> 0 | AD17: 0.12545035
... A125: =YEAR(B125) -> 2035 | B125: 49644 | C125: =(((_xlfn.XLOOKUP(YEAR($B125),'Oferta Producto 2'!$B$8:$B$19,'Oferta Producto 2'!$E$8:$E$19))*$AD125)/$AB125)/24 -> 0 | D125: =(((_xlfn.XLOOKUP(YEAR($B125),'Oferta Producto 2'!$B$8:$B$19,'Oferta Producto 2'!$E$8:$E$19))*$AD125)/$AB125)/24 -> 0 | E125: =(((_xlfn.XLOOKUP(YEAR($B125),'Oferta Producto 2'!$B$8:$B$19,'Oferta Producto 2'!$E$8:$E$19))*$AD125)/$AB125)/24 -> 0 | F125: =(((_xlfn.XLOOKUP(YEAR($B125),'Oferta Producto 2'!$B$8:$B$19,'Oferta Producto 2'!$E$8:$E$19))*$AD125)/$AB125)/24 -> 0 | G125: =(((_xlfn.XLOOKUP(YEAR($B125),'Oferta Producto 2'!$B$8:$B$19,'Oferta Producto 2'!$E$8:$E$19))*$AD125)/$AB125)/24 -> 0 | H125: =(((_xlfn.XLOOKUP(YEAR($B125),'Oferta Producto 2'!$B$8:$B$19,'Oferta Producto 2'!$E$8:$E$19))*$AD125)/$AB125)/24 -> 0 | I125: =(((_xlfn.XLOOKUP(YEAR($B125),'Oferta Producto 2'!$B$8:$B$19,'Oferta Producto 2'!$E$8:$E$19))*$AD125)/$AB125)/24 -> 0 | J125: =(((_xlfn.XLOOKUP(YEAR($B125),'Oferta Producto 2'!$B$8:$B$19,'Oferta Producto 2'!$E$8:$E$19))*$AD125)/$AB125)/24 -> 0 | ... Z125: =(((_xlfn.XLOOKUP(YEAR($B125),'Oferta Producto 2'!$B$8:$B$19,'Oferta Producto 2'!$E$8:$E$19))*$AD125)/$AB125)/24 -> 0 | AA125: =SUM(C125:Z125) -> 0 | AB125: =DAY(EOMONTH(B125,0)) -> 31 | AC125: =AA125*AB125 -> 0 | AD125: 0.083026652
B126: TOTAL PERIODO | C126: =+SUM(C6:C125) -> 0 | D126: =+SUM(D6:D125) -> 0 | E126: =+SUM(E6:E125) -> 0 | F126: =+SUM(F6:F125) -> 0 | G126: =+SUM(G6:G125) -> 0 | H126: =+SUM(H6:H125) -> 0 | I126: =+SUM(I6:I125) -> 0 | J126: =+SUM(J6:J125) -> 0 | ... AC126: =+SUM(AC6:AC125) -> 0

Sheet Oferta Producto 3
B3: PRODUCTO No. 3
B4: PAGUE LO CONTRATADO PERIODO 2026 A 2037
B5: PRECIO OFERTADO EN $ / kWh DE ABRIL DE 2025
B8: AÑO | C8: ENERGIA SOLICITADA kWh/AÑO | D8: % OFERTADO | E8: ENERGIA OFERTADA kWh/AÑO | F8: PRECIO OFERTADO $/kWh
B10: 2026 | C10: =SUMIF('Curvas Prod 3'!A:AC,'Oferta Producto 3'!B10,'Curvas Prod 3'!AC:AC) -> 36500000 | E10: =ROUND(C10*D10,2) -> 0
B11: 2027 | C11: =SUMIF('Curvas Prod 3'!A:AC,'Oferta Producto 3'!B11,'Curvas Prod 3'!AC:AC) -> 36500000 | E11: =ROUND(C11*D11,2) -> 0
B12: 2028 | C12: =SUMIF('Curvas Prod 3'!A:AC,'Oferta Producto 3'!B12,'Curvas Prod 3'!AC:AC) -> 36600000 | E12: =ROUND(C12*$D$12,2) -> 0
B13: 2029 | C13: =SUMIF('Curvas Prod 3'!A:AC,'Oferta Producto 3'!B13,'Curvas Prod 3'!AC:AC) -> 36500000 | E13: =ROUND(C13*$D$12,2) -> 0
B14: 2030 | C14: =SUMIF('Curvas Prod 3'!A:AC,'Oferta Producto 3'!B14,'Curvas Prod 3'!AC:AC) -> 36500000 | E14: =ROUND(C14*$D$12,2) -> 0
B15: 2031 | C15: =SUMIF('Curvas Prod 3'!A:AC,'Oferta Producto 3'!B15,'Curvas Prod 3'!AC:AC) -> 36500000 | E15: =ROUND(C15*$D$12,2) -> 0
B16: 2032 | C16: =SUMIF('Curvas Prod 3'!A:AC,'Oferta Producto 3'!B16,'Curvas Prod 3'!AC:AC) -> 36600000 | E16: =ROUND(C16*$D$12,2) -> 0
B17: 2033 | C17: =SUMIF('Curvas Prod 3'!A:AC,'Oferta Producto 3'!B17,'Curvas Prod 3'!AC:AC) -> 36500000 | E17: =ROUND(C17*$D$12,2) -> 0
B18: 2034 | C18: =SUMIF('Curvas Prod 3'!A:AC,'Oferta Producto 3'!B18,'Curvas Prod 3'!AC:AC) -> 36500000 | E18: =ROUND(C18*$D$12,2) -> 0
B19: 2035 | C19: =SUMIF('Curvas Prod 3'!A:AC,'Oferta Producto 3'!B19,'Curvas Prod 3'!AC:AC) -> 36500000 | E19: =ROUND(C19*$D$12,2) -> 0
B20: 2036 | C20: =SUMIF('Curvas Prod 3'!A:AC,'Oferta Producto 3'!B20,'Curvas Prod 3'!AC:AC) -> 36600000 | E20: =ROUND(C20*D20,2) -> 0
B21: 2037 | C21: =SUMIF('Curvas Prod 3'!A:AC,'Oferta Producto 3'!B21,'Curvas Prod 3'!AC:AC) -> 36500000 | E21: =ROUND(C21*D21,2) -> 0
B22: TOTAL | C22: =+SUM(C10:C19) -> 365200000 | E22: =SUM(E10:E19) -> 0 | F22: =F10 -> 0
B24: * La energia ofertada deberá ser entregada en el bloque horario comprendido entre las 08:00 y las 17:00 horas.
B25: * Se aceptan ofertas de minimo 10 años consecutivos
B26: * El oferente deberá proponer un precio unitario en $/kWh, para los diez años.
B27: * El porcentaje ofertado se aplicará a las curvas de carga de la hoja Curvas Prod 3

Sheet Curvas Prod 3
A1: =COLUMN() -> 1 | B1: =COLUMN() -> 2 | C1: =COLUMN() -> 3 | D1: =COLUMN() -> 4 | E1: =COLUMN() -> 5 | F1: =COLUMN() -> 6 | G1: =COLUMN() -> 7 | H1: =COLUMN() -> 8 | ... AC1: =COLUMN() -> 29
B3: CURVAS REQUERIDAS PRODUCTO 3 PERIODO 2026 A 2037 MODALIDAD PAGUE LO CONTRATADO - kWh
C5: 0 | D5: 0 | E5: 0 | F5: 0 | G5: 0 | H5: 0 | I5: 0 | J5: 0 | K5: 0.082251752 | L5: 0.090581344 | M5: 0.099397224 | N5: 0.10310271 | O5: 0.10414477 | P5: 0.1055245 | Q5: 0.10652898 | R5: 0.10595709 | S5: 0.10375343 | T5: 0.098758206 | U5: 0 | V5: 0 | W5: 0 | X5: 0 | Y5: 0 | Z5: 0
B6: Periodo | C6: H00 | D6: H01 | E6: H02 | F6: H03 | G6: H04 | H6: H05 | I6: H06 | J6: H07 | K6: H08 | L6: H09 | M6: H10 | N6: H11 | O6: H12 | P6: H13 | Q6: H14 | R6: H15 | S6: H16 | T6: H17 | U6: H18 | V6: H19 | W6: H20 | X6: H21 | Y6: H22 | Z6: H23 | AA6: TOTAL DÍA | AB6: Días/ | AC6: TOTAL MES
AB7: mes
A8: =YEAR(B8) -> 2026 | B8: 46023 | C8: =IF(AND(COLUMN()>=11,COLUMN()<=20),($AC8/$AB8)*C$5,0) -> 0 | D8: =IF(AND(COLUMN()>=11,COLUMN()<=20),($AC8/$AB8)*D$5,0) -> 0 | E8: =IF(AND(COLUMN()>=11,COLUMN()<=20),($AC8/$AB8)*E$5,0) -> 0 | F8: =IF(AND(COLUMN()>=11,COLUMN()<=20),($AC8/$AB8)*F$5,0) -> 0 | G8: =IF(AND(COLUMN()>=11,COLUMN()<=20),($AC8/$AB8)*G$5,0) -> 0 | H8: =IF(AND(COLUMN()>=11,COLUMN()<=20),($AC8/$AB8)*H$5,0) -> 0 | I8: =IF(AND(COLUMN()>=11,COLUMN()<=20),($AC8/$AB8)*I$5,0) -> 0 | J8: =IF(AND(COLUMN()>=11,COLUMN()<=20),($AC8/$AB8)*J$5,0) -> 0 | ... Z8: =IF(AND(COLUMN()>=11,COLUMN()<=20),($AC8/$AB8)*Z$5,0) -> 0 | AA8: =SUM(C8:Z8) -> 100000 | AB8: =DAY(EOMONTH(B8,0)) -> 31 | AC8: =100000*AB8 -> 3100000
A9: =YEAR(B9) -> 2026 | B9: 46054 | C9: =IF(AND(COLUMN()>=11,COLUMN()<=20),($AC9/$AB9)*C$5,0) -> 0 | D9: =IF(AND(COLUMN()>=11,COLUMN()<=20),($AC9/$AB9)*D$5,0) -> 0 | E9: =IF(AND(COLUMN()>=11,COLUMN()<=20),($AC9/$AB9)*E$5,0) -> 0 | F9: =IF(AND(COLUMN()>=11,COLUMN()<=20),($AC9/$AB9)*F$5,0) -> 0 | G9: =IF(AND(COLUMN()>=11,COLUMN()<=20),($AC9/$AB9)*G$5,0) -> 0 | H9: =IF(AND(COLUMN()>=11,COLUMN()<=20),($AC9/$AB9)*H$5,0) -> 0 | I9: =IF(AND(COLUMN()>=11,COLUMN()<=20),($AC9/$AB9)*I$5,0) -> 0 | J9: =IF(AND(COLUMN()>=11,COLUMN()<=20),($AC9/$AB9)*J$5,0) -> 0 | ... Z9: =IF(AND(COLUMN()>=11,COLUMN()<=20),($AC9/$AB9)*Z$5,0) -> 0 | AA9: =SUM(C9:Z9) -> 100000 | AB9: =DAY(EOMONTH(B9,0)) -> 28 | AC9: =100000*AB9 -> 2800000
A10: =YEAR(B10) -> 2026 | B10: 46082 | C10: =IF(AND(COLUMN()>=11,COLUMN()<=20),($AC10/$AB10)*C$5,0) -> 0 | D10: =IF(AND(COLUMN()>=11,COLUMN()<=20),($AC10/$AB10)*D$5,0) -> 0 | E10: =IF(AND(COLUMN()>=11,COLUMN()<=20),($AC10/$AB10)*E$5,0) -> 0 | F10: =IF(AND(COLUMN()>=11,COLUMN()<=20),($AC10/$AB10)*F$5,0) -> 0 | G10: =IF(AND(COLUMN()>=11,COLUMN()<=20),($AC10/$AB10)*G$5,0) -> 0 | H10: =IF(AND(COLUMN()>=11,COLUMN()<=20),($AC10/$AB10)*H$5,0) -> 0 | I10: =IF(AND(COLUMN()>=11,COLUMN()<=20),($AC10/$AB10)*I$5,0) -> 0 | J10: =IF(AND(COLUMN()>=11,COLUMN()<=20),($AC10/$AB10)*J$5,0) -> 0 | ... Z10: =IF(AND(COLUMN()>=11,COLUMN()<=20),($AC10/$AB10)*Z$5,0) -> 0 | AA10: =SUM(C10:Z10) -> 100000 | AB10: =DAY(EOMONTH(B10,0)) -> 31 | AC10: =100000*AB10 -> 3100000
A11: =YEAR(B11) -> 2026 | B11: 46113 | C11: =IF(AND(COLUMN()>=11,COLUMN()<=20),($AC11/$AB11)*C$5,0) -> 0 | D11: =IF(AND(COLUMN()>=11,COLUMN()<=20),($AC11/$AB11)*D$5,0) -> 0 | E11: =IF(AND(COLUMN()>=11,COLUMN()<=20),($AC11/$AB11)*E$5,0) -> 0 | F11: =IF(AND(COLUMN()>=11,COLUMN()<=20),($AC11/$AB11)*F$5,0) -> 0 | G11: =IF(AND(COLUMN()>=11,COLUMN()<=20),($AC11/$AB11)*G$5,0) -> 0 | H11: =IF(AND(COLUMN()>=11,COLUMN()<=20),($AC11/$AB11)*H$5,0) -> 0 | I11: =IF(AND(COLUMN()>=11,COLUMN()<=20),($AC11/$AB11)*I$5,0) -> 0 | J11: =IF(AND(COLUMN()>=11,COLUMN()<=20),($AC11/$AB11)*J$5,0) -> 0 | ... Z11: =IF(AND(COLUMN()>=11,COLUMN()<=20),($AC11/$AB11)*Z$5,0) -> 0 | AA11: =SUM(C11:Z11) -> 100000 | AB11: =DAY(EOMONTH(B11,0)) -> 30 | AC11: =100000*AB11 -> 3000000
A12: =YEAR(B12) -> 2026 | B12: 46143 | C12: =IF(AND(COLUMN()>=11,COLUMN()<=20),($AC12/$AB12)*C$5,0) -> 0 | D12: =IF(AND(COLUMN()>=11,COLUMN()<=20),($AC12/$AB12)*D$5,0) -> 0 | E12: =IF(AND(COLUMN()>=11,COLUMN()<=20),($AC12/$AB12)*E$5,0) -> 0 | F12: =IF(AND(COLUMN()>=11,COLUMN()<=20),($AC12/$AB12)*F$5,0) -> 0 | G12: =IF(AND(COLUMN()>=11,COLUMN()<=20),($AC12/$AB12)*G$5,0) -> 0 | H12: =IF(AND(COLUMN()>=11,COLUMN()<=20),($AC12/$AB12)*H$5,0) -> 0 | I12: =IF(AND(COLUMN()>=11,COLUMN()<=20),($AC12/$AB12)*I$5,0) -> 0 | J12: =IF(AND(COLUMN()>=11,COLUMN()<=20),($AC12/$AB12)*J$5,0) -> 0 | ... Z12: =IF(AND(COLUMN()>=11,COLUMN()<=20),($AC12/$AB12)*Z$5,0) -> 0 | AA12: =SUM(C12:Z12) -> 100000 | AB12: =DAY(EOMONTH(B12,0)) -> 31 | AC12: =100000*AB12 -> 3100000
