Workbook

Sheet Producto 1 Plano 26-30
B2: ANEXO 1 - CANTIDADES DE ENERGÍA SOLICITADA EN kWh
B3: PRODUCTO 1
B4: PERIODO 01 DE ENERO DEL 2026 A DICIEMBRE 31 DE 2030
C5: DIA | D5: 1 | E5: 2 | F5: 3 | G5: 4 | H5: 5 | I5: 6 | J5: 7 | K5: 8 | L5: 9 | M5: 10 | N5: 11 | O5: 12 | P5: 13 | Q5: 14 | R5: 15 | S5: 16 | T5: 17 | U5: 18 | V5: 19 | W5: 20 | X5: 21 | Y5: 22 | Z5: 23 | AA5: 24 | AB5: Total | AC5: No. DÍAS | AD5: Total
B6: 46023 | C6: Hábil | D6: 5750 | E6: 5750 | F6: 5750 | G6: 5750 | H6: 5750 | I6: 5750 | J6: 5750 | K6: 5750 | L6: 5750 | M6: 5750 | N6: 5750 | O6: 5750 | P6: 5750 | Q6: 5750 | R6: 5750 | S6: 5750 | T6: 5750 | U6: 5750 | V6: 5750 | W6: 5750 | X6: 5750 | Y6: 5750 | Z6: 5750 | AA6: 5750 | AB6: =(SUM(D6:AA6)) -> 138000 | AC6: 20 | AD6: =(AB6*AC6)+(AB7*AC7)+(AB8*AC8)+(AB9*AC9) -> 4278000 | AE6: =+AD6 -> 4278000
C7: Sábado | D7: 5750 | E7: 5750 | F7: 5750 | G7: 5750 | H7: 5750 | I7: 5750 | J7: 5750 | K7: 5750 | L7: 5750 | M7: 5750 | N7: 5750 | O7: 5750 | P7: 5750 | Q7: 5750 | R7: 5750 | S7: 5750 | T7: 5750 | U7: 5750 | V7: 5750 | W7: 5750 | X7: 5750 | Y7: 5750 | Z7: 5750 | AA7: 5750 | AB7: =(SUM(D7:AA7)) -> 138000 | AC7: 5 | AE7: =+AD10 -> 3864000
C8: Domingo | D8: 5750 | E8: 5750 | F8: 5750 | G8: 5750 | H8: 5750 | I8: 5750 | J8: 5750 | K8: 5750 | L8: 5750 | M8: 5750 | N8: 5750 | O8: 5750 | P8: 5750 | Q8: 5750 | R8: 5750 | S8: 5750 | T8: 5750 | U8: 5750 | V8: 5750 | W8: 5750 | X8: 5750 | Y8: 5750 | Z8: 5750 | AA8: 5750 | AB8: =(SUM(D8:AA8)) -> 138000 | AC8: 4 | AE8: =+AD14 -> 4278000
C9: Festivo | D9: 5750 | E9: 5750 | F9: 5750 | G9: 5750 | H9: 5750 | I9: 5750 | J9: 5750 | K9: 5750 | L9: 5750 | M9: 5750 | N9: 5750 | O9: 5750 | P9: 5750 | Q9: 5750 | R9: 5750 | S9: 5750 | T9: 5750 | U9: 5750 | V9: 5750 | W9: 5750 | X9: 5750 | Y9: 5750 | Z9: 5750 | AA9: 5750 | AB9: =(SUM(D9:AA9)) -> 138000 | AC9: 2 | AE9: =+AD18 -> 4140000
B10: 46054 | C10: Hábil | D10: 5750 | E10: 5750 | F10: 5750 | G10: 5750 | H10: 5750 | I10: 5750 | J10: 5750 | K10: 5750 | L10: 5750 | M10: 5750 | N10: 5750 | O10: 5750 | P10: 5750 | Q10: 5750 | R10: 5750 | S10: 5750 | T10: 5750 | U10: 5750 | V10: 5750 | W10: 5750 | X10: 5750 | Y10: 5750 | Z10: 5750 | AA10: 5750 | AB10: =(SUM(D10:AA10)) -> 138000 | AC10: 20 | AD10: =(AB10*AC10)+(AB11*AC11)+(AB12*AC12)+(AB13*AC13) -> 3864000 | AE10: =+AD22 -> 4278000
C11: Sábado | D11: 5750 | E11: 5750 | F11: 5750 | G11: 5750 | H11: 5750 | I11: 5750 | J11: 5750 | K11: 5750 | L11: 5750 | M11: 5750 | N11: 5750 | O11: 5750 | P11: 5750 | Q11: 5750 | R11: 5750 | S11: 5750 | T11: 5750 | U11: 5750 | V11: 5750 | W11: 5750 | X11: 5750 | Y11: 5750 | Z11: 5750 | AA11: 5750 | AB11: =(SUM(D11:AA11)) -> 138000 | AC11: 4 | AE11: =+AD26 -> 4140000
C12: Domingo | D12: 5750 | E12: 5750 | F12: 5750 | G12: 5750 | H12: 5750 | I12: 5750 | J12: 5750 | K12: 5750 | L12: 5750 | M12: 5750 | N12: 5750 | O12: 5750 | P12: 5750 | Q12: 5750 | R12: 5750 | S12: 5750 | T12: 5750 | U12: 5750 | V12: 5750 | W12: 5750 | X12: 5750 | Y12: 5750 | Z12: 5750 | AA12: 5750 | AB12: =(SUM(D12:AA12)) -> 138000 | AC12: 4 | AE12: =+AD30 -> 4278000
C13: Festivo | D13: 5750 | E13: 5750 | F13: 5750 | G13: 5750 | H13: 5750 | I13: 5750 | J13: 5750 | K13: 5750 | L13: 5750 | M13: 5750 | N13: 5750 | O13: 5750 | P13: 5750 | Q13: 5750 | R13: 5750 | S13: 5750 | T13: 5750 | U13: 5750 | V13: 5750 | W13: 5750 | X13: 5750 | Y13: 5750 | Z13: 5750 | AA13: 5750 | AB13: =(SUM(D13:AA13)) -> 138000 | AC13: 0 | AE13: =+AD34 -> 4278000
B14: 46082 | C14: Hábil | D14: 5750 | E14: 5750 | F14: 5750 | G14: 5750 | H14: 5750 | I14: 5750 | J14: 5750 | K14: 5750 | L14: 5750 | M14: 5750 | N14: 5750 | O14: 5750 | P14: 5750 | Q14: 5750 | R14: 5750 | S14: 5750 | T14: 5750 | U14: 5750 | V14: 5750 | W14: 5750 | X14: 5750 | Y14: 5750 | Z14: 5750 | AA14: 5750 | AB14: =(SUM(D14:AA14)) -> 138000 | AC14: 21 | AD14: =(AB14*AC14)+(AB15*AC15)+(AB16*AC16)+(AB17*AC17) -> 4278000 | AE14: =+AD38 -> 4140000
C15: Sábado | D15: 5750 | E15: 5750 | F15: 5750 | G15: 5750 | H15: 5750 | I15: 5750 | J15: 5750 | K15: 5750 | L15: 5750 | M15: 5750 | N15: 5750 | O15: 5750 | P15: 5750 | Q15: 5750 | R15: 5750 | S15: 5750 | T15: 5750 | U15: 5750 | V15: 5750 | W15: 5750 | X15: 5750 | Y15: 5750 | Z15: 5750 | AA15: 5750 | AB15: =(SUM(D15:AA15)) -> 138000 | AC15: 4 | AE15: =+AD42 -> 4278000
C16: Domingo | D16: 5750 | E16: 5750 | F16: 5750 | G16: 5750 | H16: 5750 | I16: 5750 | J16: 5750 | K16: 5750 | L16: 5750 | M16: 5750 | N16: 5750 | O16: 5750 | P16: 5750 | Q16: 5750 | R16: 5750 | S16: 5750 | T16: 5750 | U16: 5750 | V16: 5750 | W16: 5750 | X16: 5750 | Y16: 5750 | Z16: 5750 | AA16: 5750 | AB16: =(SUM(D16:AA16)) -> 138000 | AC16: 5 | AE16: =+AD46 -> 4140000
C17: Festivo | D17: 5750 | E17: 5750 | F17: 5750 | G17: 5750 | H17: 5750 | I17: 5750 | J17: 5750 | K17: 5750 | L17: 5750 | M17: 5750 | N17: 5750 | O17: 5750 | P17: 5750 | Q17: 5750 | R17: 5750 | S17: 5750 | T17: 5750 | U17: 5750 | V17: 5750 | W17: 5750 | X17: 5750 | Y17: 5750 | Z17: 5750 | AA17: 5750 | AB17: =(SUM(D17:AA17)) -> 138000 | AC17: 1 | AE17: =+AD50 -> 4278000
B18: 46113 | C18: Hábil | D18: 5750 | E18: 5750 | F18: 5750 | G18: 5750 | H18: 5750 | I18: 5750 | J18: 5750 | K18: 5750 | L18: 5750 | M18: 5750 | N18: 5750 | O18: 5750 | P18: 5750 | Q18: 5750 | R18: 5750 | S18: 5750 | T18: 5750 | U18: 5750 | V18: 5750 | W18: 5750 | X18: 5750 | Y18: 5750 | Z18: 5750 | AA18: 5750 | AB18: =(SUM(D18:AA18)) -> 138000 | AC18: 20 | AD18: =(AB18*AC18)+(AB19*AC19)+(AB20*AC20)+(AB21*AC21) -> 4140000 | AE18: =+AD54 -> 3682800
C19: Sábado | D19: 5750 | E19: 5750 | F19: 5750 | G19: 5750 | H19: 5750 | I19: 5750 | J19: 5750 | K19: 5750 | L19: 5750 | M19: 5750 | N19: 5750 | O19: 5750 | P19: 5750 | Q19: 5750 | R19: 5750 | S19: 5750 | T19: 5750 | U19: 5750 | V19: 5750 | W19: 5750 | X19: 5750 | Y19: 5750 | Z19: 5750 | AA19: 5750 | AB19: =(SUM(D19:AA19)) -> 138000 | AC19: 4 | AE19: =+AD58 -> 3445200
C20: Domingo | D20: 5750 | E20: 5750 | F20: 5750 | G20: 5750 | H20: 5750 | I20: 5750 | J20: 5750 | K20: 5750 | L20: 5750 | M20: 5750 | N20: 5750 | O20: 5750 | P20: 5750 | Q20: 5750 | R20: 5750 | S20: 5750 | T20: 5750 | U20: 5750 | V20: 5750 | W20: 5750 | X20: 5750 | Y20: 5750 | Z20: 5750 | AA20: 5750 | AB20: =(SUM(D20:AA20)) -> 138000 | AC20: 4 | AE20: =+AD62 -> 3682800
C21: Festivo | D21: 5750 | E21: 5750 | F21: 5750 | G21: 5750 | H21: 5750 | I21: 5750 | J21: 5750 | K21: 5750 | L21: 5750 | M21: 5750 | N21: 5750 | O21: 5750 | P21: 5750 | Q21: 5750 | R21: 5750 | S21: 5750 | T21: 5750 | U21: 5750 | V21: 5750 | W21: 5750 | X21: 5750 | Y21: 5750 | Z21: 5750 | AA21: 5750 | AB21: =(SUM(D21:AA21)) -> 138000 | AC21: 2 | AE21: =+AD66 -> 3564000
B22: 46143 | C22: Hábil | D22: 5750 | E22: 5750 | F22: 5750 | G22: 5750 | H22: 5750 | I22: 5750 | J22: 5750 | K22: 5750 | L22: 5750 | M22: 5750 | N22: 5750 | O22: 5750 | P22: 5750 | Q22: 5750 | R22: 5750 | S22: 5750 | T22: 5750 | U22: 5750 | V22: 5750 | W22: 5750 | X22: 5750 | Y22: 5750 | Z22: 5750 | AA22: 5750 | AB22: =(SUM(D22:AA22)) -> 138000 | AC22: 19 | AD22: =(AB22*AC22)+(AB23*AC23)+(AB24*AC24)+(AB25*AC25) -> 4278000 | AE22: =+AD70 -> 3682800
C23: Sábado | D23: 5750 | E23: 5750 | F23: 5750 | G23: 5750 | H23: 5750 | I23: 5750 | J23: 5750 | K23: 5750 | L23: 5750 | M23: 5750 | N23: 5750 | O23: 5750 | P23: 5750 | Q23: 5750 | R23: 5750 | S23: 5750 | T23: 5750 | U23: 5750 | V23: 5750 | W23: 5750 | X23: 5750 | Y23: 5750 | Z23: 5750 | AA23: 5750 | AB23: =(SUM(D23:AA23)) -> 138000 | AC23: 5 | AE23: =+AD74 -> 3564000
C24: Domingo | D24: 5750 | E24: 5750 | F24: 5750 | G24: 5750 | H24: 5750 | I24: 5750 | J24: 5750 | K24: 5750 | L24: 5750 | M24: 5750 | N24: 5750 | O24: 5750 | P24: 5750 | Q24: 5750 | R24: 5750 | S24: 5750 | T24: 5750 | U24: 5750 | V24: 5750 | W24: 5750 | X24: 5750 | Y24: 5750 | Z24: 5750 | AA24: 5750 | AB24: =(SUM(D24:AA24)) -> 138000 | AC24: 5 | AE24: =+AD78 -> 3682800
C25: Festivo | D25: 5750 | E25: 5750 | F25: 5750 | G25: 5750 | H25: 5750 | I25: 5750 | J25: 5750 | K25: 5750 | L25: 5750 | M25: 5750 | N25: 5750 | O25: 5750 | P25: 5750 | Q25: 5750 | R25: 5750 | S25: 5750 | T25: 5750 | U25: 5750 | V25: 5750 | W25: 5750 | X25: 5750 | Y25: 5750 | Z25: 5750 | AA25: 5750 | AB25: =(SUM(D25:AA25)) -> 138000 | AC25: 2 | AE25: =+AD82 -> 3682800
B26: 46174 | C26: Hábil | D26: 5750 | E26: 5750 | F26: 5750 | G26: 5750 | H26: 5750 | I26: 5750 | J26: 5750 | K26: 5750 | L26: 5750 | M26: 5750 | N26: 5750 | O26: 5750 | P26: 5750 | Q26: 5750 | R26: 5750 | S26: 5750 | T26: 5750 | U26: 5750 | V26: 5750 | W26: 5750 | X26: 5750 | Y26: 5750 | Z26: 5750 | AA26: 5750 | AB26: =(SUM(D26:AA26)) -> 138000 | AC26: 19 | AD26: =(AB26*AC26)+(AB27*AC27)+(AB28*AC28)+(AB29*AC29) -> 4140000 | AE26: =+AD86 -> 3564000
C27: Sábado | D27: 5750 | E27: 5750 | F27: 5750 | G27: 5750 | H27: 5750 | I27: 5750 | J27: 5750 | K27: 5750 | L27: 5750 | M27: 5750 | N27: 5750 | O27: 5750 | P27: 5750 | Q27: 5750 | R27: 5750 | S27: 5750 | T27: 5750 | U27: 5750 | V27: 5750 | W27: 5750 | X27: 5750 | Y27: 5750 | Z27: 5750 | AA27: 5750 | AB27: =(SUM(D27:AA27)) -> 138000 | AC27: 4 | AE27: =+AD90 -> 3682800
C28: Domingo | D28: 5750 | E28: 5750 | F28: 5750 | G28: 5750 | H28: 5750 | I28: 5750 | J28: 5750 | K28: 5750 | L28: 5750 | M28: 5750 | N28: 5750 | O28: 5750 | P28: 5750 | Q28: 5750 | R28: 5750 | S28: 5750 | T28: 5750 | U28: 5750 | V28: 5750 | W28: 5750 | X28: 5750 | Y28: 5750 | Z28: 5750 | AA28: 5750 | AB28: =(SUM(D28:AA28)) -> 138000 | AC28: 4 | AE28: =+AD94 -> 3564000
C29: Festivo | D29: 5750 | E29: 5750 | F29: 5750 | G29: 5750 | H29: 5750 | I29: 5750 | J29: 5750 | K29: 5750 | L29: 5750 | M29: 5750 | N29: 5750 | O29: 5750 | P29: 5750 | Q29: 5750 | R29: 5750 | S29: 5750 | T29: 5750 | U29: 5750 | V29: 5750 | W29: 5750 | X29: 5750 | Y29: 5750 | Z29: 5750 | AA29: 5750 | AB29: =(SUM(D29:AA29)) -> 138000 | AC29: 3 | AE29: =+AD98 -> 3682800
B30: 46204 | C30: Hábil | D30: 5750 | E30: 5750 | F30: 5750 | G30: 5750 | H30: 5750 | I30: 5750 | J30: 5750 | K30: 5750 | L30: 5750 | M30: 5750 | N30: 5750 | O30: 5750 | P30: 5750 | Q30: 5750 | R30: 5750 | S30: 5750 | T30: 5750 | U30: 5750 | V30: 5750 | W30: 5750 | X30: 5750 | Y30: 5750 | Z30: 5750 | AA30: 5750 | AB30: =(SUM(D30:AA30)) -> 138000 | AC30: 22 | AD30: =(AB30*AC30)+(AB31*AC31)+(AB32*AC32)+(AB33*AC33) -> 4278000 | AE30: =+AD102 -> 6286800
C31: Sábado | D31: 5750 | E31: 5750 | F31: 5750 | G31: 5750 | H31: 5750 | I31: 5750 | J31: 5750 | K31: 5750 | L31: 5750 | M31: 5750 | N31: 5750 | O31: 5750 | P31: 5750 | Q31: 5750 | R31: 5750 | S31: 5750 | T31: 5750 | U31: 5750 | V31: 5750 | W31: 5750 | X31: 5750 | Y31: 5750 | Z31: 5750 | AA31: 5750 | AB31: =(SUM(D31:AA31)) -> 138000 | AC31: 4 | AE31: =+AD106 -> 5678400
C32: domingo | D32: 5750 | E32: 5750 | F32: 5750 | G32: 5750 | H32: 5750 | I32: 5750 | J32: 5750 | K32: 5750 | L32: 5750 | M32: 5750 | N32: 5750 | O32: 5750 | P32: 5750 | Q32: 5750 | R32: 5750 | S32: 5750 | T32: 5750 | U32: 5750 | V32: 5750 | W32: 5750 | X32: 5750 | Y32: 5750 | Z32: 5750 | AA32: 5750 | AB32: =(SUM(D32:AA32)) -> 138000 | AC32: 4 | AE32: =+AD110 -> 6286800
C33: Festivo | D33: 5750 | E33: 5750 | F33: 5750 | G33: 5750 | H33: 5750 | I33: 5750 | J33: 5750 | K33: 5750 | L33: 5750 | M33: 5750 | N33: 5750 | O33: 5750 | P33: 5750 | Q33: 5750 | R33: 5750 | S33: 5750 | T33: 5750 | U33: 5750 | V33: 5750 | W33: 5750 | X33: 5750 | Y33: 5750 | Z33: 5750 | AA33: 5750 | AB33: =(SUM(D33:AA33)) -> 138000 | AC33: 1 | AE33: =+AD114 -> 6084000
B34: 46235 | C34: Hábil | D34: 5750 | E34: 5750 | F34: 5750 | G34: 5750 | H34: 5750 | I34: 5750 | J34: 5750 | K34: 5750 | L34: 5750 | M34: 5750 | N34: 5750 | O34: 5750 | P34: 5750 | Q34: 5750 | R34: 5750 | S34: 5750 | T34: 5750 | U34: 5750 | V34: 5750 | W34: 5750 | X34: 5750 | Y34: 5750 | Z34: 5750 | AA34: 5750 | AB34: =(SUM(D34:AA34)) -> 138000 | AC34: 19 | AD34: =(AB34*AC34)+(AB35*AC35)+(AB36*AC36)+(AB37*AC37) -> 4278000 | AE34: =+AD118 -> 6286800
C35: Sábado | D35: 5750 | E35: 5750 | F35: 5750 | G35: 5750 | H35: 5750 | I35: 5750 | J35: 5750 | K35: 5750 | L35: 5750 | M35: 5750 | N35: 5750 | O35: 5750 | P35: 5750 | Q35: 5750 | R35: 5750 | S35: 5750 | T35: 5750 | U35: 5750 | V35: 5750 | W35: 5750 | X35: 5750 | Y35: 5750 | Z35: 5750 | AA35: 5750 | AB35: =(SUM(D35:AA35)) -> 138000 | AC35: 5 | AE35: =+AD122 -> 6084000
C36: Domingo | D36: 5750 | E36: 5750 | F36: 5750 | G36: 5750 | H36: 5750 | I36: 5750 | J36: 5750 | K36: 5750 | L36: 5750 | M36: 5750 | N36: 5750 | O36: 5750 | P36: 5750 | Q36: 5750 | R36: 5750 | S36: 5750 | T36: 5750 | U36: 5750 | V36: 5750 | W36: 5750 | X36: 5750 | Y36: 5750 | Z36: 5750 | AA36: 5750 | AB36: =(SUM(D36:AA36)) -> 138000 | AC36: 5 | AE36: =+AD126 -> 6286800
C37: Festivo | D37: 5750 | E37: 5750 | F37: 5750 | G37: 5750 | H37: 5750 | I37: 5750 | J37: 5750 | K37: 5750 | L37: 5750 | M37: 5750 | N37: 5750 | O37: 5750 | P37: 5750 | Q37: 5750 | R37: 5750 | S37: 5750 | T37: 5750 | U37: 5750 | V37: 5750 | W37: 5750 | X37: 5750 | Y37: 5750 | Z37: 5750 | AA37: 5750 | AB37: =(SUM(D37:AA37)) -> 138000 | AC37: 2 | AE37: =+AD130 -> 6286800
B38: 46266 | C38: Hábil | D38: 5750 | E38: 5750 | F38: 5750 | G38: 5750 | H38: 5750 | I38: 5750 | J38: 5750 | K38: 5750 | L38: 5750 | M38: 5750 | N38: 5750 | O38: 5750 | P38: 5750 | Q38: 5750 | R38: 5750 | S38: 5750 | T38: 5750 | U38: 5750 | V38: 5750 | W38: 5750 | X38: 5750 | Y38: 5750 | Z38: 5750 | AA38: 5750 | AB38: =(SUM(D38:AA38)) -> 138000 | AC38: 22 | AD38: =(AB38*AC38)+(AB39*AC39)+(AB40*AC40)+(AB41*AC41) -> 4140000 | AE38: =+AD134 -> 6084000
C39: Sábado | D39: 5750 | E39: 5750 | F39: 5750 | G39: 5750 | H39: 5750 | I39: 5750 | J39: 5750 | K39: 5750 | L39: 5750 | M39: 5750 | N39: 5750 | O39: 5750 | P39: 5750 | Q39: 5750 | R39: 5750 | S39: 5750 | T39: 5750 | U39: 5750 | V39: 5750 | W39: 5750 | X39: 5750 | Y39: 5750 | Z39: 5750 | AA39: 5750 | AB39: =(SUM(D39:AA39)) -> 138000 | AC39: 4 | AE39: =+AD138 -> 6286800
C40: Domingo | D40: 5750 | E40: 5750 | F40: 5750 | G40: 5750 | H40: 5750 | I40: 5750 | J40: 5750 | K40: 5750 | L40: 5750 | M40: 5750 | N40: 5750 | O40: 5750 | P40: 5750 | Q40: 5750 | R40: 5750 | S40: 5750 | T40: 5750 | U40: 5750 | V40: 5750 | W40: 5750 | X40: 5750 | Y40: 5750 | Z40: 5750 | AA40: 5750 | AB40: =(SUM(D40:AA40)) -> 138000 | AC40: 4 | AE40: =+AD142 -> 6084000
C41: Festivo | D41: 5750 | E41: 5750 | F41: 5750 | G41: 5750 | H41: 5750 | I41: 5750 | J41: 5750 | K41: 5750 | L41: 5750 | M41: 5750 | N41: 5750 | O41: 5750 | P41: 5750 | Q41: 5750 | R41: 5750 | S41: 5750 | T41: 5750 | U41: 5750 | V41: 5750 | W41: 5750 | X41: 5750 | Y41: 5750 | Z41: 5750 | AA41: 5750 | AB41: =(SUM(D41:AA41)) -> 138000 | AC41: 0 | AE41: =+AD146 -> 6286800
...

Sheet Anexo 2 Producto 1
B4: ANEXO 2 - OFERTA PRODUCTO 1
B5: NOMBRE DEL OFERENTE
B6: PRECIOS Y CANTIDADES DE ENERGIA OFERTADA
B7: EN PESOS DE ABRIL 2025
B8: PRODUCTO 1
B9: AÑO | C9: MES | D9: PERIODO 2026 - 2030
D10: E. Solicitada [kWh] | E10: % E. Ofertado | F10: E. Ofertada [kWh] | G10: $/kWh
B11: 2026 | C11: Enero | D11: =+'Producto 1 Plano 26-30'!AE6 -> 4278000 | F11: =+E11*D11 -> 0
B12: 2026 | C12: Febrero | D12: =+'Producto 1 Plano 26-30'!AE7 -> 3864000 | F12: =+E12*D12 -> 0
B13: 2026 | C13: Marzo | D13: =+'Producto 1 Plano 26-30'!AE8 -> 4278000 | F13: =+E13*D13 -> 0
B14: 2026 | C14: Abril | D14: =+'Producto 1 Plano 26-30'!AE9 -> 4140000 | F14: =+E14*D14 -> 0
B15: 2026 | C15: Mayo | D15: =+'Producto 1 Plano 26-30'!AE10 -> 4278000 | F15: =+E15*D15 -> 0
B16: 2026 | C16: Junio | D16: =+'Producto 1 Plano 26-30'!AE11 -> 4140000 | F16: =+E16*D16 -> 0
B17: 2026 | C17: Julio | D17: =+'Producto 1 Plano 26-30'!AE12 -> 4278000 | F17: =+E17*D17 -> 0
B18: 2026 | C18: Agosto | D18: =+'Producto 1 Plano 26-30'!AE13 -> 4278000 | F18: =+E18*D18 -> 0
B19: 2026 | C19: Septiembre | D19: =+'Producto 1 Plano 26-30'!AE14 -> 4140000 | F19: =+E19*D19 -> 0
B20: 2026 | C20: Octubre | D20: =+'Producto 1 Plano 26-30'!AE15 -> 4278000 | F20: =+E20*D20 -> 0
B21: 2026 | C21: Noviembre | D21: =+'Producto 1 Plano 26-30'!AE16 -> 4140000 | F21: =+E21*D21 -> 0
B22: 2026 | C22: Diciembre | D22: =+'Producto 1 Plano 26-30'!AE17 -> 4278000 | F22: =+E22*D22 -> 0 | H22: =SUM(D11:D22) -> 50370000
B23: 2028 | C23: Enero | D23: =+'Producto 1 Plano 26-30'!AE18 -> 3682800 | F23: =+E23*D23 -> 0
B24: 2028 | C24: Febrero | D24: =+'Producto 1 Plano 26-30'!AE19 -> 3445200 | F24: =+E24*D24 -> 0
B25: 2028 | C25: Marzo | D25: =+'Producto 1 Plano 26-30'!AE20 -> 3682800 | F25: =+E25*D25 -> 0
B26: 2028 | C26: Abril | D26: =+'Producto 1 Plano 26-30'!AE21 -> 3564000 | F26: =+E26*D26 -> 0
B27: 2028 | C27: Mayo | D27: =+'Producto 1 Plano 26-30'!AE22 -> 3682800 | F27: =+E27*D27 -> 0
B28: 2028 | C28: Junio | D28: =+'Producto 1 Plano 26-30'!AE23 -> 3564000 | F28: =+E28*D28 -> 0
B29: 2028 | C29: Julio | D29: =+'Producto 1 Plano 26-30'!AE24 -> 3682800 | F29: =+E29*D29 -> 0
B30: 2028 | C30: Agosto | D30: =+'Producto 1 Plano 26-30'!AE25 -> 3682800 | F30: =+E30*D30 -> 0
B31: 2028 | C31: Septiembre | D31: =+'Producto 1 Plano 26-30'!AE26 -> 3564000 | F31: =+E31*D31 -> 0
B32: 2028 | C32: Octubre | D32: =+'Producto 1 Plano 26-30'!AE27 -> 3682800 | F32: =+E32*D32 -> 0
B33: 2028 | C33: Noviembre | D33: =+'Producto 1 Plano 26-30'!AE28 -> 3564000 | F33: =+E33*D33 -> 0
B34: 2028 | C34: Diciembre | D34: =+'Producto 1 Plano 26-30'!AE29 -> 3682800 | F34: =+E34*D34 -> 0 | H34: =SUM(D23:D34) -> 43480800
B35: 2029 | C35: Enero | D35: =+'Producto 1 Plano 26-30'!AE30 -> 6286800 | F35: =+E35*D35 -> 0
B36: 2029 | C36: Febrero | D36: =+'Producto 1 Plano 26-30'!AE31 -> 5678400 | F36: =+E36*D36 -> 0
B37: 2029 | C37: Marzo | D37: =+'Producto 1 Plano 26-30'!AE32 -> 6286800 | F37: =+E37*D37 -> 0
B38: 2029 | C38: Abril | D38: =+'Producto 1 Plano 26-30'!AE33 -> 6084000 | F38: =+E38*D38 -> 0
B39: 2029 | C39: Mayo | D39: =+'Producto 1 Plano 26-30'!AE34 -> 6286800 | F39: =+E39*D39 -> 0
B40: 2029 | C40: Junio | D40: =+'Producto 1 Plano 26-30'!AE35 -> 6084000 | F40: =+E40*D40 -> 0
B41: 2029 | C41: Julio | D41: =+'Producto 1 Plano 26-30'!AE36 -> 6286800 | F41: =+E41*D41 -> 0
B42: 2029 | C42: Agosto | D42: =+'Producto 1 Plano 26-30'!AE37 -> 6286800 | F42: =+E42*D42 -> 0
B43: 2029 | C43: Septiembre | D43: =+'Producto 1 Plano 26-30'!AE38 -> 6084000 | F43: =+E43*D43 -> 0
...

Sheet Producto 2 Curvo 26-30
B2: ANEXO 1 - CANTIDADES DE ENERGÍA SOLICITADA EN kWh
B3: PRODUCTO 2
B4: PERIODO 01 DE ENERO DEL 2027 A DICIEMBRE 31 DE 2027
C5: DIA | D5: 1 | E5: 2 | F5: 3 | G5: 4 | H5: 5 | I5: 6 | J5: 7 | K5: 8 | L5: 9 | M5: 10 | N5: 11 | O5: 12 | P5: 13 | Q5: 14 | R5: 15 | S5: 16 | T5: 17 | U5: 18 | V5: 19 | W5: 20 | X5: 21 | Y5: 22 | Z5: 23 | AA5: 24 | AB5: Total | AC5: No. DÍAS | AD5: Total
B6: 46388 | C6: Hábil | D6: 0 | E6: 0 | F6: 0 | G6: 0 | H6: 0 | I6: 0 | J6: 0 | K6: 647.46011 | L6: 1004.4905 | M6: 1167.5439 | N6: 1461.8984 | O6: 1476.6907 | P6: 1225.309 | Q6: 1597.7785 | R6: 1870.6237 | S6: 1922.1172 | T6: 1664.5898 | U6: 1241.1439 | V6: 985.97171 | W6: 645.24689 | X6: 81.457715 | Y6: 0 | Z6: 0 | AA6: 0 | AB6: =(SUM(D6:AA6)) -> 16992.322 | AC6: 19 | AD6: =(AB6*AC6)+(AB7*AC7)+(AB8*AC8)+(AB9*AC9) -> 326421.35 | AE6: =+AD6 -> 326421.35
C7: Sábado | D7: 0 | E7: 0 | F7: 0 | G7: 0 | H7: 0 | I7: 0 | J7: 0 | K7: 0 | L7: 36.173115 | M7: 133.56901 | N7: 304.88109 | O7: 158.30986 | P7: 0 | Q7: 0 | R7: 0 | S7: 0 | T7: 0 | U7: 34.31919 | V7: 46.19514 | W7: 0 | X7: 0 | Y7: 0 | Z7: 0 | AA7: 0 | AB7: =(SUM(D7:AA7)) -> 713.44741 | AC7: 5 | AE7: =+AD10 -> 434392.41
C8: Domingo | D8: 0 | E8: 0 | F8: 0 | G8: 0 | H8: 0 | I8: 0 | J8: 0 | K8: 0 | L8: 0 | M8: 0 | N8: 0 | O8: 0 | P8: 0 | Q8: 0 | R8: 0 | S8: 0 | T8: 0 | U8: 0 | V8: 0 | W8: 0 | X8: 0 | Y8: 0 | Z8: 0 | AA8: 0 | AB8: =(SUM(D8:AA8)) -> 0 | AC8: 5 | AE8: =+AD14 -> 495573.34
C9: Festivo | D9: 0 | E9: 0 | F9: 0 | G9: 0 | H9: 0 | I9: 0 | J9: 0 | K9: 0 | L9: 0 | M9: 0 | N9: 0 | O9: 0 | P9: 0 | Q9: 0 | R9: 0 | S9: 0 | T9: 0 | U9: 0 | V9: 0 | W9: 0 | X9: 0 | Y9: 0 | Z9: 0 | AA9: 0 | AB9: =(SUM(D9:AA9)) -> 0 | AC9: 2 | AE9: =+AD18 -> 377862.62
B10: 46419 | C10: Hábil | D10: 0 | E10: 0 | F10: 0 | G10: 0 | H10: 0 | I10: 0 | J10: 163.48152 | K10: 1258.6462 | L10: 1628.6697 | M10: 1685.4243 | N10: 1871.5925 | O10: 1763.1138 | P10: 1479.0136 | Q10: 1836.4811 | R10: 2095.0374 | S10: 2098.0518 | T10: 1957.583 | U10: 1453.9364 | V10: 1028.9766 | W10: 747.17491 | X10: 218.0043 | Y10: 0 | Z10: 0 | AA10: 0 | AB10: =(SUM(D10:AA10)) -> 21285.187 | AC10: 20 | AD10: =(AB10*AC10)+(AB11*AC11)+(AB12*AC12)+(AB13*AC13) -> 434392.41 | AE10: =+AD22 -> 827761.93
C11: Sábado | D11: 0 | E11: 0 | F11: 0 | G11: 0 | H11: 0 | I11: 0 | J11: 0 | K11: 81.84669 | L11: 385.80916 | M11: 556.05391 | N11: 676.87396 | O11: 457.46244 | P11: 14.120715 | Q11: 0 | R11: 0 | S11: 0 | T11: 0 | U11: 0 | V11: 0 | W11: 0 | X11: 0 | Y11: 0 | Z11: 0 | AA11: 0 | AB11: =(SUM(D11:AA11)) -> 2172.1669 | AC11: 4 | AE11: =+AD26 -> 708535.19
C12: Domingo | D12: 0 | E12: 0 | F12: 0 | G12: 0 | H12: 0 | I12: 0 | J12: 0 | K12: 0 | L12: 0 | M12: 0 | N12: 0 | O12: 0 | P12: 0 | Q12: 0 | R12: 0 | S12: 0 | T12: 0 | U12: 0 | V12: 0 | W12: 0 | X12: 0 | Y12: 0 | Z12: 0 | AA12: 0 | AB12: =(SUM(D12:AA12)) -> 0 | AC12: 4 | AE12: =+AD30 -> 765698.3
C13: Festivo | D13: 0 | E13: 0 | F13: 0 | G13: 0 | H13: 0 | I13: 0 | J13: 0 | K13: 0 | L13: 0 | M13: 0 | N13: 0 | O13: 0 | P13: 0 | Q13: 0 | R13: 0 | S13: 0 | T13: 0 | U13: 0 | V13: 0 | W13: 0 | X13: 0 | Y13: 0 | Z13: 0 | AA13: 0 | AB13: =(SUM(D13:AA13)) -> 0 | AC13: 0 | AE13: =+AD34 -> 823563.37
B14: 46447 | C14: Hábil | D14: 0 | E14: 0 | F14: 0 | G14: 0 | H14: 0 | I14: 0 | J14: 468.22713 | K14: 1568.4585 | L14: 1974.9928 | M14: 2098.6953 | N14: 2085.3362 | O14: 1918.542 | P14: 1911.3206 | Q14: 2017.4435 | R14: 2208.5232 | S14: 2319.9291 | T14: 2147.4922 | U14: 1019.3168 | V14: 740.0302 | W14: 482.74389 | X14: 285.43867 | Y14: 67.05087 | Z14: 0 | AA14: 0 | AB14: =(SUM(D14:AA14)) -> 23313.541 | AC14: 20 | AD14: =(AB14*AC14)+(AB15*AC15)+(AB16*AC16)+(AB17*AC17) -> 495573.34 | AE14: =+AD38 -> 755928.84
C15: Sábado | D15: 0 | E15: 0 | F15: 0 | G15: 0 | H15: 0 | I15: 0 | J15: 0 | K15: 497.23243 | L15: 764.90215 | M15: 841.65721 | N15: 1060.9909 | O15: 751.09447 | P15: 390.41785 | Q15: 291.08281 | R15: 303.41875 | S15: 357.34303 | T15: 480.57247 | U15: 416.79745 | V15: 187.72699 | W15: 74.901195 | X15: 0 | Y15: 0 | Z15: 0 | AA15: 0 | AB15: =(SUM(D15:AA15)) -> 6418.1378 | AC15: 4 | AE15: =+AD42 -> 563447.77
C16: Domingo | D16: 0 | E16: 0 | F16: 0 | G16: 0 | H16: 0 | I16: 0 | J16: 0 | K16: 0 | L16: 0 | M16: 0 | N16: 0 | O16: 0 | P16: 0 | Q16: 0 | R16: 0 | S16: 0 | T16: 0 | U16: 0 | V16: 0 | W16: 0 | X16: 0 | Y16: 0 | Z16: 0 | AA16: 0 | AB16: =(SUM(D16:AA16)) -> 0 | AC16: 4 | AE16: =+AD46 -> 839712.9
C17: Festivo | D17: 0 | E17: 0 | F17: 0 | G17: 0 | H17: 0 | I17: 0 | J17: 0 | K17: 0 | L17: 0 | M17: 0 | N17: 0 | O17: 0 | P17: 0 | Q17: 0 | R17: 0 | S17: 0 | T17: 0 | U17: 260.74171 | V17: 510.09961 | W17: 359.57971 | X17: 79.567215 | Y17: 0 | Z17: 0 | AA17: 0 | AB17: =(SUM(D17:AA17)) -> 1209.9883 | AC17: 3 | AE17: =+AD50 -> 482777.1
B18: 46478 | C18: Hábil | D18: 0 | E18: 0 | F18: 0 | G18: 0 | H18: 0 | I18: 0 | J18: 0 | K18: 834.53927 | L18: 1320.9293 | M18: 1336.5246 | N18: 1498.9464 | O18: 1515.6848 | P18: 1600.932 | Q18: 1582.3285 | R18: 1735.453 | S18: 1724.9975 | T18: 1633.8562 | U18: 427.6239 | V18: 137.43272 | W18: 2.8604448 | X18: 0 | Y18: 0 | Z18: 0 | AA18: 0 | AB18: =(SUM(D18:AA18)) -> 15352.109 | AC18: 22 | AD18: =(AB18*AC18)+(AB19*AC19)+(AB20*AC20)+(AB21*AC21) -> 377862.62
C19: Sábado | D19: 0 | E19: 0 | F19: 0 | G19: 0 | H19: 0 | I19: 0 | J19: 0 | K19: 376.50497 | L19: 872.51462 | M19: 1049.0338 | N19: 1328.8202 | O19: 1363.1678 | P19: 1181.8524 | Q19: 987.09551 | R19: 858.53094 | S19: 814.5831 | T19: 724.8176 | U19: 291.20757 | V19: 150.29787 | W19: 30.629636 | X19: 0 | Y19: 0 | Z19: 0 | AA19: 0 | AB19: =(SUM(D19:AA19)) -> 10029.056 | AC19: 4
C20: Domingo | D20: 0 | E20: 0 | F20: 0 | G20: 0 | H20: 0 | I20: 0 | J20: 0 | K20: 0 | L20: 0 | M20: 0 | N20: 0 | O20: 0 | P20: 0 | Q20: 0 | R20: 0 | S20: 0 | T20: 0 | U20: 0 | V20: 0 | W20: 0 | X20: 0 | Y20: 0 | Z20: 0 | AA20: 0 | AB20: =(SUM(D20:AA20)) -> 0 | AC20: 4
C21: Festivo | D21: 0 | E21: 0 | F21: 0 | G21: 0 | H21: 0 | I21: 0 | J21: 0 | K21: 0 | L21: 0 | M21: 0 | N21: 0 | O21: 0 | P21: 0 | Q21: 0 | R21: 0 | S21: 0 | T21: 0 | U21: 64.118414 | V21: 254.88631 | W21: 154.39939 | X21: 0 | Y21: 0 | Z21: 0 | AA21: 0 | AB21: =(SUM(D21:AA21)) -> 473.40411 | AC21: 0
B22: 46508 | C22: Hábil | D22: 0 | E22: 0 | F22: 0 | G22: 0 | H22: 0 | I22: 0 | J22: 135.45399 | K22: 1249.2613 | L22: 1853.9755 | M22: 1878.2595 | N22: 2066.4484 | O22: 2091.8149 | P22: 2161.7065 | Q22: 2153.5087 | R22: 2323.158 | S22: 2308.728 | T22: 2207.7908 | U22: 960.88412 | V22: 654.38626 | W22: 500.64754 | X22: 361.55823 | Y22: 193.32588 | Z22: 0 | AA22: 0 | AB22: =(SUM(D22:AA22)) -> 23100.908 | AC22: 19 | AD22: =(AB22*AC22)+(AB23*AC23)+(AB24*AC24)+(AB25*AC25) -> 827761.93
C23: Sábado | D23: 0 | E23: 0 | F23: 0 | G23: 0 | H23: 0 | I23: 0 | J23: 0 | K23: 0 | L23: 258.44566 | M23: 416.97879 | N23: 668.25683 | O23: 699.10469 | P23: 536.26403 | Q23: 361.35155 | R23: 245.88683 | S23: 206.41697 | T23: 125.79795 | U23: 0 | V23: 0 | W23: 0 | X23: 0 | Y23: 0 | Z23: 0 | AA23: 0 | AB23: =(SUM(D23:AA23)) -> 3518.5033 | AC23: 4
C24: Domingo | D24: 0 | E24: 0 | F24: 0 | G24: 0 | H24: 0 | I24: 0 | J24: 0 | K24: 0 | L24: 0 | M24: 89.519762 | N24: 132.27316 | O24: 202.19707 | P24: 643.18186 | Q24: 480.21968 | R24: 381.26797 | S24: 475.25184 | T24: 568.70016 | U24: 0 | V24: 97.091691 | W24: 299.84227 | X24: 411.29459 | Y24: 227.35111 | Z24: 0 | AA24: 0 | AB24: =(SUM(D24:AA24)) -> 4008.1912 | AC24: 5
C25: Festivo | D25: 3491.2212 | E25: 3158.4393 | F25: 3016.6287 | G25: 2952.2883 | H25: 2707.8751 | I25: 2794.3571 | J25: 3251.3058 | K25: 4032.5691 | L25: 4647.8032 | M25: 4984.0927 | N25: 5693.8972 | O25: 5956.4775 | P25: 6205.4072 | Q25: 6225.5381 | R25: 6308.0567 | S25: 6368.6722 | T25: 6369.2109 | U25: 6551.3375 | V25: 6979.6624 | W25: 6754.0425 | X25: 6249.5576 | Y25: 5078.9896 | Z25: 4425.2413 | AA25: 4040.5689 | AB25: =(SUM(D25:AA25)) -> 118243.24 | AC25: 3
B26: 46539 | C26: Hábil | D26: 0 | E26: 0 | F26: 0 | G26: 0 | H26: 0 | I26: 0 | J26: 525.22544 | K26: 1729.3322 | L26: 2354.0062 | M26: 2388.4956 | N26: 2609.9161 | O26: 2645.2758 | P26: 2695.5542 | Q26: 2701.5379 | R26: 2890.9734 | S26: 2872.3214 | T26: 2758.5289 | U26: 1460.6103 | V26: 1135.1667 | W26: 957.65887 | X26: 775.78567 | Y26: 562.93082 | Z26: 200.87345 | AA26: 0 | AB26: =(SUM(D26:AA26)) -> 31264.193 | AC26: 21 | AD26: =(AB26*AC26)+(AB27*AC27)+(AB28*AC28)+(AB29*AC29) -> 708535.19
C27: Sábado | D27: 0 | E27: 0 | F27: 0 | G27: 0 | H27: 0 | I27: 0 | J27: 0 | K27: 561.24793 | L27: 1076.8328 | M27: 1260.3184 | N27: 1551.1466 | O27: 1586.8498 | P27: 1398.3787 | Q27: 1195.9357 | R27: 1062.2972 | S27: 1016.615 | T27: 923.30685 | U27: 534.41749 | V27: 395.76748 | W27: 266.96742 | X27: 166.70442 | Y27: 0 | Z27: 0 | AA27: 0 | AB27: =(SUM(D27:AA27)) -> 12996.786 | AC27: 4
C28: Domingo | D28: 0 | E28: 0 | F28: 0 | G28: 0 | H28: 0 | I28: 0 | J28: 0 | K28: 0 | L28: 0 | M28: 0 | N28: 0 | O28: 0 | P28: 0 | Q28: 0 | R28: 0 | S28: 0 | T28: 0 | U28: 0 | V28: 0 | W28: 0 | X28: 0 | Y28: 0 | Z28: 0 | AA28: 0 | AB28: =(SUM(D28:AA28)) -> 0 | AC28: 4
C29: Festivo | D29: 0 | E29: 0 | F29: 0 | G29: 0 | H29: 0 | I29: 0 | J29: 0 | K29: 0 | L29: 0 | M29: 0 | N29: 0 | O29: 0 | P29: 0 | Q29: 0 | R29: 0 | S29: 0 | T29: 0 | U29: 0 | V29: 0 | W29: 0 | X29: 0 | Y29: 0 | Z29: 0 | AA29: 0 | AB29: =(SUM(D29:AA29)) -> 0 | AC29: 1
B30: 46569 | C30: Hábil | D30: 0 | E30: 0 | F30: 0 | G30: 0 | H30: 0 | I30: 0 | J30: 0 | K30: 643.61128 | L30: 1195.8928 | M30: 1208.4476 | N30: 1361.083 | O30: 1375.5716 | P30: 1466.1924 | Q30: 1443.748 | R30: 1591.2893 | S30: 1581.4551 | T30: 1494.5113 | U30: 302.51257 | V30: 17.25826 | W30: 0 | X30: 0 | Y30: 0 | Z30: 0 | AA30: 0 | AB30: =(SUM(D30:AA30)) -> 13681.573 | AC30: 20 | AD30: =(AB30*AC30)+(AB31*AC31)+(AB32*AC32)+(AB33*AC33) -> 765698.3
C31: Sábado | D31: 0 | E31: 0 | F31: 0 | G31: 0 | H31: 0 | I31: 0 | J31: 137.79798 | K31: 1006.5646 | L31: 1563.1677 | M31: 1761.2509 | N31: 2075.2164 | O31: 2113.7601 | P31: 1910.2948 | Q31: 1691.746 | R31: 1547.4758 | S31: 1498.1592 | T31: 1397.4277 | U31: 1041.4658 | V31: 908.74518 | W31: 761.38011 | X31: 631.46447 | Y31: 185.37592 | Z31: 0 | AA31: 0 | AB31: =(SUM(D31:AA31)) -> 20231.293 | AC31: 5
C32: domingo | D32: 1147.6426 | E32: 850.11873 | F32: 687.78353 | G32: 574.36736 | H32: 488.0878 | I32: 452.08313 | J32: 761.49179 | K32: 1212.1028 | L32: 1572.9489 | M32: 1789.0836 | N32: 1944.3245 | O32: 2060.0901 | P32: 2547.4808 | Q32: 2391.7457 | R32: 2283.955 | S32: 2393.6603 | T32: 2500.5654 | U32: 1892.2557 | V32: 2110.1871 | W32: 2307.7599 | X32: 2339.0779 | Y32: 1974.8035 | Z32: 1599.4878 | AA32: 1329.7132 | AB32: =(SUM(D32:AA32)) -> 39210.817 | AC32: 4
C33: Festivo | D33: 3441.4226 | E33: 3108.7806 | F33: 2967.0295 | G33: 2902.7162 | H33: 2658.4057 | I33: 2744.8513 | J33: 3201.608 | K33: 3982.5382 | L33: 4597.5138 | M33: 4933.662 | N33: 5643.1682 | O33: 5905.6382 | P33: 6154.4633 | Q33: 6174.5858 | R33: 6257.0697 | S33: 6317.6597 | T33: 6318.1982 | U33: 6500.2532 | V33: 6928.3981 | W33: 6702.873 | X33: 6198.6 | Y33: 5028.5238 | Z33: 4375.0502 | AA33: 3990.5395 | AB33: =(SUM(D33:AA33)) -> 117033.55 | AC33: 2
B34: 46600 | C34: Hábil | D34: 0 | E34: 0 | F34: 0 | G34: 0 | H34: 0 | I34: 0 | J34: 754.86923 | K34: 2014.5442 | L34: 2736.9131 | M34: 2811.6633 | N34: 3052.6131 | O34: 3094.1224 | P34: 3133.2521 | Q34: 3147.6119 | R34: 3348.6534 | S34: 3327.4033 | T34: 3205.7 | U34: 1877.3105 | V34: 1539.2874 | W34: 1347.7226 | X34: 1139.872 | Y34: 898.63667 | Z34: 415.69171 | AA34: 110.93594 | AB34: =(SUM(D34:AA34)) -> 37956.803 | AC34: 21 | AD34: =(AB34*AC34)+(AB35*AC35)+(AB36*AC36)+(AB37*AC37) -> 823563.37
C35: Sábado | D35: 0 | E35: 0 | F35: 0 | G35: 0 | H35: 0 | I35: 0 | J35: 0 | K35: 0 | L35: 312.75601 | M35: 474.7816 | N35: 731.59525 | O35: 763.12269 | P35: 596.69468 | Q35: 417.9289 | R35: 299.92051 | S35: 259.58114 | T35: 177.18609 | U35: 0 | V35: 0 | W35: 0 | X35: 0 | Y35: 0 | Z35: 0 | AA35: 0 | AB35: =(SUM(D35:AA35)) -> 4033.5669 | AC35: 3
C36: Domingo | D36: 0 | E36: 0 | F36: 0 | G36: 0 | H36: 0 | I36: 0 | J36: 0 | K36: 0 | L36: 0 | M36: 0 | N36: 0 | O36: 0 | P36: 0 | Q36: 0 | R36: 0 | S36: 0 | T36: 0 | U36: 0 | V36: 0 | W36: 0 | X36: 0 | Y36: 0 | Z36: 0 | AA36: 0 | AB36: =(SUM(D36:AA36)) -> 0 | AC36: 5
C37: Festivo | D37: 0 | E37: 0 | F37: 0 | G37: 0 | H37: 0 | I37: 0 | J37: 0 | K37: 0 | L37: 0 | M37: 0 | N37: 323.23564 | O37: 457.41809 | P37: 584.62488 | Q37: 594.9121 | R37: 637.08032 | S37: 668.05574 | T37: 668.33102 | U37: 767.07801 | V37: 985.95843 | W37: 870.66325 | X37: 612.86395 | Y37: 14.686222 | Z37: 0 | AA37: 0 | AB37: =(SUM(D37:AA37)) -> 7184.9076 | AC37: 2
B38: 46631 | C38: Hábil | D38: 0 | E38: 0 | F38: 0 | G38: 0 | H38: 0 | I38: 0 | J38: 0 | K38: 750.60848 | L38: 1350.2408 | M38: 1431.1358 | N38: 1593.9567 | O38: 1611.5616 | P38: 1696.2438 | Q38: 1678.0441 | R38: 1831.7556 | S38: 1820.6049 | T38: 1729.6522 | U38: 521.92332 | V38: 230.58311 | W38: 95.875632 | X38: 0 | Y38: 0 | Z38: 0 | AA38: 0 | AB38: =(SUM(D38:AA38)) -> 16342.186 | AC38: 22 | AD38: =(AB38*AC38)+(AB39*AC39)+(AB40*AC40)+(AB41*AC41) -> 755928.84
C39: Sábado | D39: 1672.1537 | E39: 1409.62 | F39: 1235.9471 | G39: 1185.8152 | H39: 1125.6971 | I39: 1267.3779 | J39: 2220.032 | K39: 3441.6063 | L39: 4221.266 | M39: 4498.7302 | N39: 4938.5162 | O39: 4992.5061 | P39: 4707.5028 | Q39: 4401.3716 | R39: 4199.2856 | S39: 4130.2055 | T39: 3989.1064 | U39: 3719.4547 | V39: 3618.9778 | W39: 3367.557 | X39: 3076.3909 | Y39: 2286.6766 | Z39: 1806.1816 | AA39: 1467.6338 | AB39: =(SUM(D39:AA39)) -> 72979.612 | AC39: 4
C40: Domingo | D40: 610.59158 | E40: 335.77458 | F40: 185.82874 | G40: 81.068454 | H40: 1.3737213 | I40: 0 | J40: 253.91161 | K40: 669.246 | L40: 1002.5525 | M40: 1202.1918 | N40: 1420.4247 | O40: 1522.3524 | P40: 1946.9342 | Q40: 1837.4401 | R40: 1732.3511 | S40: 1837.251 | T40: 1940.0429 | U40: 1327.5821 | V40: 1524.8354 | W40: 1723.9909 | X40: 1779.803 | Y40: 1378.3093 | Z40: 1027.9521 | AA40: 778.76658 | AB40: =(SUM(D40:AA40)) -> 26120.575 | AC40: 4
C41: Festivo | D41: 0 | E41: 0 | F41: 0 | G41: 0 | H41: 0 | I41: 0 | J41: 0 | K41: 0 | L41: 0 | M41: 0 | N41: 0 | O41: 0 | P41: 0 | Q41: 0 | R41: 0 | S41: 0 | T41: 0 | U41: 0 | V41: 0 | W41: 0 | X41: 0 | Y41: 0 | Z41: 0 | AA41: 0 | AB41: =(SUM(D41:AA41)) -> 0 | AC41: 0
...

Sheet Anexo 2 Producto 2
B4: ANEXO 2 - OFERTA PRODUCTO 2
B5: NOMBRE DEL OFERENTE
B6: PRECIOS Y CANTIDADES DE ENERGIA OFERTADA
B7: EN PESOS DE ABRIL 2025
B8: PRODUCTO 2
B9: AÑO | C9: MES | D9: PERIODO 2027
D10: E. Solicitada [kWh] | E10: % E. Ofertado | F10: E. Ofertada [kWh] | G10: $/kWh
B11: 2027 | C11: Enero | D11: =+'Producto 2 Curvo 26-30'!AE6 -> 326421.35 | F11: =+E11*D11 -> 0
B12: 2027 | C12: Febrero | D12: =+'Producto 2 Curvo 26-30'!AE7 -> 434392.41 | F12: =+E12*D12 -> 0
B13: 2027 | C13: Marzo | D13: =+'Producto 2 Curvo 26-30'!AE8 -> 495573.34 | F13: =+E13*D13 -> 0
B14: 2027 | C14: Abril | D14: =+'Producto 2 Curvo 26-30'!AE9 -> 377862.62 | F14: =+E14*D14 -> 0
B15: 2027 | C15: Mayo | D15: =+'Producto 2 Curvo 26-30'!AE10 -> 827761.93 | F15: =+E15*D15 -> 0
B16: 2027 | C16: Junio | D16: =+'Producto 2 Curvo 26-30'!AE11 -> 708535.19 | F16: =+E16*D16 -> 0
B17: 2027 | C17: Julio | D17: =+'Producto 2 Curvo 26-30'!AE12 -> 765698.3 | F17: =+E17*D17 -> 0
B18: 2027 | C18: Agosto | D18: =+'Producto 2 Curvo 26-30'!AE13 -> 823563.37 | F18: =+E18*D18 -> 0
B19: 2027 | C19: Septiembre | D19: =+'Producto 2 Curvo 26-30'!AE14 -> 755928.84 | F19: =+E19*D19 -> 0
B20: 2027 | C20: Octubre | D20: =+'Producto 2 Curvo 26-30'!AE15 -> 563447.77 | F20: =+E20*D20 -> 0
B21: 2027 | C21: Noviembre | D21: =+'Producto 2 Curvo 26-30'!AE16 -> 839712.9 | F21: =+E21*D21 -> 0
B22: 2027 | C22: Diciembre | D22: =+'Producto 2 Curvo 26-30'!AE17 -> 482777.1 | F22: =+E22*D22 -> 0 | H22: =SUM(D11:D22) -> 7401675.1
B23: Total Producto 2 | D23: =+SUM(D11:D22) -> 7401675.1
B25: E. Solicitada = Energía solicitada por RUITOQUE para el producto.
B26: % E. Ofertado = Porcentaje de energía ofertado por el agente respecto a la E. Solicitada.
B27: E. Ofertada = Energía ofertada por el agente, producto de la E. Solicitada y el % E. Ofertado.
B28: $/kWh = Tarifa de la oferta para todas las horas del mes.
