Workbook

Sheet Producto 1 Plano 26
B2: ANEXO 1 - CANTIDADES DE ENERGÍA SOLICITADA EN kWh
B3: PRODUCTO 1
B4: PERIODO 10 DE SEPTIEMBRE DEL 2026 A DICIEMBRE 31 DE 2026
C5: DIA | D5: 1 | E5: 2 | F5: 3 | G5: 4 | H5: 5 | I5: 6 | J5: 7 | K5: 8 | L5: 9 | M5: 10 | N5: 11 | O5: 12 | P5: 13 | Q5: 14 | R5: 15 | S5: 16 | T5: 17 | U5: 18 | V5: 19 | W5: 20 | X5: 21 | Y5: 22 | Z5: 23 | AA5: 24 | AB5: Total | AC5: No. DÍAS | AD5: Total
B6: 46023 | C6: Hábil | D6: 0 | E6: 0 | F6: 0 | G6: 0 | H6: 0 | I6: 0 | J6: 0 | K6: 0 | L6: 0 | M6: 0 | N6: 0 | O6: 0 | P6: 0 | Q6: 0 | R6: 0 | S6: 0 | T6: 0 | U6: 0 | V6: 0 | W6: 0 | X6: 0 | Y6: 0 | Z6: 0 | AA6: 0 | AB6: =(SUM(D6:AA6)) -> 0 | AC6: 20 | AD6: =(AB6*AC6)+(AB7*AC7)+(AB8*AC8)+(AB9*AC9) -> 0 | AE6: =+AD6 -> 0
C7: Sábado | D7: 0 | E7: 0 | F7: 0 | G7: 0 | H7: 0 | I7: 0 | J7: 0 | K7: 0 | L7: 0 | M7: 0 | N7: 0 | O7: 0 | P7: 0 | Q7: 0 | R7: 0 | S7: 0 | T7: 0 | U7: 0 | V7: 0 | W7: 0 | X7: 0 | Y7: 0 | Z7: 0 | AA7: 0 | AB7: =(SUM(D7:AA7)) -> 0 | AC7: 5 | AE7: =+AD10 -> 0
C8: Domingo | D8: 0 | E8: 0 | F8: 0 | G8: 0 | H8: 0 | I8: 0 | J8: 0 | K8: 0 | L8: 0 | M8: 0 | N8: 0 | O8: 0 | P8: 0 | Q8: 0 | R8: 0 | S8: 0 | T8: 0 | U8: 0 | V8: 0 | W8: 0 | X8: 0 | Y8: 0 | Z8: 0 | AA8: 0 | AB8: =(SUM(D8:AA8)) -> 0 | AC8: 4 | AE8: =+AD14 -> 0
C9: Festivo | D9: 0 | E9: 0 | F9: 0 | G9: 0 | H9: 0 | I9: 0 | J9: 0 | K9: 0 | L9: 0 | M9: 0 | N9: 0 | O9: 0 | P9: 0 | Q9: 0 | R9: 0 | S9: 0 | T9: 0 | U9: 0 | V9: 0 | W9: 0 | X9: 0 | Y9: 0 | Z9: 0 | AA9: 0 | AB9: =(SUM(D9:AA9)) -> 0 | AC9: 2 | AE9: =+AD18 -> 0
B10: 46054 | C10: Hábil | D10: 0 | E10: 0 | F10: 0 | G10: 0 | H10: 0 | I10: 0 | J10: 0 | K10: 0 | L10: 0 | M10: 0 | N10: 0 | O10: 0 | P10: 0 | Q10: 0 | R10: 0 | S10: 0 | T10: 0 | U10: 0 | V10: 0 | W10: 0 | X10: 0 | Y10: 0 | Z10: 0 | AA10: 0 | AB10: =(SUM(D10:AA10)) -> 0 | AC10: 20 | AD10: =(AB10*AC10)+(AB11*AC11)+(AB12*AC12)+(AB13*AC13) -> 0 | AE10: =+AD22 -> 0
C11: Sábado | D11: 0 | E11: 0 | F11: 0 | G11: 0 | H11: 0 | I11: 0 | J11: 0 | K11: 0 | L11: 0 | M11: 0 | N11: 0 | O11: 0 | P11: 0 | Q11: 0 | R11: 0 | S11: 0 | T11: 0 | U11: 0 | V11: 0 | W11: 0 | X11: 0 | Y11: 0 | Z11: 0 | AA11: 0 | AB11: =(SUM(D11:AA11)) -> 0 | AC11: 4 | AE11: =+AD26 -> 0
C12: Domingo | D12: 0 | E12: 0 | F12: 0 | G12: 0 | H12: 0 | I12: 0 | J12: 0 | K12: 0 | L12: 0 | M12: 0 | N12: 0 | O12: 0 | P12: 0 | Q12: 0 | R12: 0 | S12: 0 | T12: 0 | U12: 0 | V12: 0 | W12: 0 | X12: 0 | Y12: 0 | Z12: 0 | AA12: 0 | AB12: =(SUM(D12:AA12)) -> 0 | AC12: 4 | AE12: =+AD30 -> 0
C13: Festivo | D13: 0 | E13: 0 | F13: 0 | G13: 0 | H13: 0 | I13: 0 | J13: 0 | K13: 0 | L13: 0 | M13: 0 | N13: 0 | O13: 0 | P13: 0 | Q13: 0 | R13: 0 | S13: 0 | T13: 0 | U13: 0 | V13: 0 | W13: 0 | X13: 0 | Y13: 0 | Z13: 0 | AA13: 0 | AB13: =(SUM(D13:AA13)) -> 0 | AC13: 0 | AE13: =+AD34 -> 0
B14: 46082 | C14: Hábil | D14: 0 | E14: 0 | F14: 0 | G14: 0 | H14: 0 | I14: 0 | J14: 0 | K14: 0 | L14: 0 | M14: 0 | N14: 0 | O14: 0 | P14: 0 | Q14: 0 | R14: 0 | S14: 0 | T14: 0 | U14: 0 | V14: 0 | W14: 0 | X14: 0 | Y14: 0 | Z14: 0 | AA14: 0 | AB14: =(SUM(D14:AA14)) -> 0 | AC14: 21 | AD14: =(AB14*AC14)+(AB15*AC15)+(AB16*AC16)+(AB17*AC17) -> 0 | AE14: =+AD38 -> 676277.28
C15: Sábado | D15: 0 | E15: 0 | F15: 0 | G15: 0 | H15: 0 | I15: 0 | J15: 0 | K15: 0 | L15: 0 | M15: 0 | N15: 0 | O15: 0 | P15: 0 | Q15: 0 | R15: 0 | S15: 0 | T15: 0 | U15: 0 | V15: 0 | W15: 0 | X15: 0 | Y15: 0 | Z15: 0 | AA15: 0 | AB15: =(SUM(D15:AA15)) -> 0 | AC15: 4 | AE15: =+AD42 -> 766870.56
C16: Domingo | D16: 0 | E16: 0 | F16: 0 | G16: 0 | H16: 0 | I16: 0 | J16: 0 | K16: 0 | L16: 0 | M16: 0 | N16: 0 | O16: 0 | P16: 0 | Q16: 0 | R16: 0 | S16: 0 | T16: 0 | U16: 0 | V16: 0 | W16: 0 | X16: 0 | Y16: 0 | Z16: 0 | AA16: 0 | AB16: =(SUM(D16:AA16)) -> 0 | AC16: 5 | AE16: =+AD46 -> 2223705.6
C17: Festivo | D17: 0 | E17: 0 | F17: 0 | G17: 0 | H17: 0 | I17: 0 | J17: 0 | K17: 0 | L17: 0 | M17: 0 | N17: 0 | O17: 0 | P17: 0 | Q17: 0 | R17: 0 | S17: 0 | T17: 0 | U17: 0 | V17: 0 | W17: 0 | X17: 0 | Y17: 0 | Z17: 0 | AA17: 0 | AB17: =(SUM(D17:AA17)) -> 0 | AC17: 1 | AE17: =+AD50 -> 5945490
B18: 46113 | C18: Hábil | D18: 0 | E18: 0 | F18: 0 | G18: 0 | H18: 0 | I18: 0 | J18: 0 | K18: 0 | L18: 0 | M18: 0 | N18: 0 | O18: 0 | P18: 0 | Q18: 0 | R18: 0 | S18: 0 | T18: 0 | U18: 0 | V18: 0 | W18: 0 | X18: 0 | Y18: 0 | Z18: 0 | AA18: 0 | AB18: =(SUM(D18:AA18)) -> 0 | AC18: 20 | AD18: =(AB18*AC18)+(AB19*AC19)+(AB20*AC20)+(AB21*AC21) -> 0
C19: Sábado | D19: 0 | E19: 0 | F19: 0 | G19: 0 | H19: 0 | I19: 0 | J19: 0 | K19: 0 | L19: 0 | M19: 0 | N19: 0 | O19: 0 | P19: 0 | Q19: 0 | R19: 0 | S19: 0 | T19: 0 | U19: 0 | V19: 0 | W19: 0 | X19: 0 | Y19: 0 | Z19: 0 | AA19: 0 | AB19: =(SUM(D19:AA19)) -> 0 | AC19: 4
C20: Domingo | D20: 0 | E20: 0 | F20: 0 | G20: 0 | H20: 0 | I20: 0 | J20: 0 | K20: 0 | L20: 0 | M20: 0 | N20: 0 | O20: 0 | P20: 0 | Q20: 0 | R20: 0 | S20: 0 | T20: 0 | U20: 0 | V20: 0 | W20: 0 | X20: 0 | Y20: 0 | Z20: 0 | AA20: 0 | AB20: =(SUM(D20:AA20)) -> 0 | AC20: 4
C21: Festivo | D21: 0 | E21: 0 | F21: 0 | G21: 0 | H21: 0 | I21: 0 | J21: 0 | K21: 0 | L21: 0 | M21: 0 | N21: 0 | O21: 0 | P21: 0 | Q21: 0 | R21: 0 | S21: 0 | T21: 0 | U21: 0 | V21: 0 | W21: 0 | X21: 0 | Y21: 0 | Z21: 0 | AA21: 0 | AB21: =(SUM(D21:AA21)) -> 0 | AC21: 2
B22: 46143 | C22: Hábil | D22: 0 | E22: 0 | F22: 0 | G22: 0 | H22: 0 | I22: 0 | J22: 0 | K22: 0 | L22: 0 | M22: 0 | N22: 0 | O22: 0 | P22: 0 | Q22: 0 | R22: 0 | S22: 0 | T22: 0 | U22: 0 | V22: 0 | W22: 0 | X22: 0 | Y22: 0 | Z22: 0 | AA22: 0 | AB22: =(SUM(D22:AA22)) -> 0 | AC22: 19 | AD22: =(AB22*AC22)+(AB23*AC23)+(AB24*AC24)+(AB25*AC25) -> 0
C23: Sábado | D23: 0 | E23: 0 | F23: 0 | G23: 0 | H23: 0 | I23: 0 | J23: 0 | K23: 0 | L23: 0 | M23: 0 | N23: 0 | O23: 0 | P23: 0 | Q23: 0 | R23: 0 | S23: 0 | T23: 0 | U23: 0 | V23: 0 | W23: 0 | X23: 0 | Y23: 0 | Z23: 0 | AA23: 0 | AB23: =(SUM(D23:AA23)) -> 0 | AC23: 5
C24: Domingo | D24: 0 | E24: 0 | F24: 0 | G24: 0 | H24: 0 | I24: 0 | J24: 0 | K24: 0 | L24: 0 | M24: 0 | N24: 0 | O24: 0 | P24: 0 | Q24: 0 | R24: 0 | S24: 0 | T24: 0 | U24: 0 | V24: 0 | W24: 0 | X24: 0 | Y24: 0 | Z24: 0 | AA24: 0 | AB24: =(SUM(D24:AA24)) -> 0 | AC24: 5
C25: Festivo | D25: 0 | E25: 0 | F25: 0 | G25: 0 | H25: 0 | I25: 0 | J25: 0 | K25: 0 | L25: 0 | M25: 0 | N25: 0 | O25: 0 | P25: 0 | Q25: 0 | R25: 0 | S25: 0 | T25: 0 | U25: 0 | V25: 0 | W25: 0 | X25: 0 | Y25: 0 | Z25: 0 | AA25: 0 | AB25: =(SUM(D25:AA25)) -> 0 | AC25: 2
B26: 46174 | C26: Hábil | D26: 0 | E26: 0 | F26: 0 | G26: 0 | H26: 0 | I26: 0 | J26: 0 | K26: 0 | L26: 0 | M26: 0 | N26: 0 | O26: 0 | P26: 0 | Q26: 0 | R26: 0 | S26: 0 | T26: 0 | U26: 0 | V26: 0 | W26: 0 | X26: 0 | Y26: 0 | Z26: 0 | AA26: 0 | AB26: =(SUM(D26:AA26)) -> 0 | AC26: 19 | AD26: =(AB26*AC26)+(AB27*AC27)+(AB28*AC28)+(AB29*AC29) -> 0
C27: Sábado | D27: 0 | E27: 0 | F27: 0 | G27: 0 | H27: 0 | I27: 0 | J27: 0 | K27: 0 | L27: 0 | M27: 0 | N27: 0 | O27: 0 | P27: 0 | Q27: 0 | R27: 0 | S27: 0 | T27: 0 | U27: 0 | V27: 0 | W27: 0 | X27: 0 | Y27: 0 | Z27: 0 | AA27: 0 | AB27: =(SUM(D27:AA27)) -> 0 | AC27: 4
C28: Domingo | D28: 0 | E28: 0 | F28: 0 | G28: 0 | H28: 0 | I28: 0 | J28: 0 | K28: 0 | L28: 0 | M28: 0 | N28: 0 | O28: 0 | P28: 0 | Q28: 0 | R28: 0 | S28: 0 | T28: 0 | U28: 0 | V28: 0 | W28: 0 | X28: 0 | Y28: 0 | Z28: 0 | AA28: 0 | AB28: =(SUM(D28:AA28)) -> 0 | AC28: 4
C29: Festivo | D29: 0 | E29: 0 | F29: 0 | G29: 0 | H29: 0 | I29: 0 | J29: 0 | K29: 0 | L29: 0 | M29: 0 | N29: 0 | O29: 0 | P29: 0 | Q29: 0 | R29: 0 | S29: 0 | T29: 0 | U29: 0 | V29: 0 | W29: 0 | X29: 0 | Y29: 0 | Z29: 0 | AA29: 0 | AB29: =(SUM(D29:AA29)) -> 0 | AC29: 3
B30: 46204 | C30: Hábil | D30: 0 | E30: 0 | F30: 0 | G30: 0 | H30: 0 | I30: 0 | J30: 0 | K30: 0 | L30: 0 | M30: 0 | N30: 0 | O30: 0 | P30: 0 | Q30: 0 | R30: 0 | S30: 0 | T30: 0 | U30: 0 | V30: 0 | W30: 0 | X30: 0 | Y30: 0 | Z30: 0 | AA30: 0 | AB30: =(SUM(D30:AA30)) -> 0 | AC30: 21 | AD30: =(AB30*AC30)+(AB31*AC31)+(AB32*AC32)+(AB33*AC33) -> 0
C31: Sábado | D31: 0 | E31: 0 | F31: 0 | G31: 0 | H31: 0 | I31: 0 | J31: 0 | K31: 0 | L31: 0 | M31: 0 | N31: 0 | O31: 0 | P31: 0 | Q31: 0 | R31: 0 | S31: 0 | T31: 0 | U31: 0 | V31: 0 | W31: 0 | X31: 0 | Y31: 0 | Z31: 0 | AA31: 0 | AB31: =(SUM(D31:AA31)) -> 0 | AC31: 4
C32: domingo | D32: 0 | E32: 0 | F32: 0 | G32: 0 | H32: 0 | I32: 0 | J32: 0 | K32: 0 | L32: 0 | M32: 0 | N32: 0 | O32: 0 | P32: 0 | Q32: 0 | R32: 0 | S32: 0 | T32: 0 | U32: 0 | V32: 0 | W32: 0 | X32: 0 | Y32: 0 | Z32: 0 | AA32: 0 | AB32: =(SUM(D32:AA32)) -> 0 | AC32: 4
C33: Festivo | D33: 0 | E33: 0 | F33: 0 | G33: 0 | H33: 0 | I33: 0 | J33: 0 | K33: 0 | L33: 0 | M33: 0 | N33: 0 | O33: 0 | P33: 0 | Q33: 0 | R33: 0 | S33: 0 | T33: 0 | U33: 0 | V33: 0 | W33: 0 | X33: 0 | Y33: 0 | Z33: 0 | AA33: 0 | AB33: =(SUM(D33:AA33)) -> 0 | AC33: 1
B34: 46235 | C34: Hábil | D34: 0 | E34: 0 | F34: 0 | G34: 0 | H34: 0 | I34: 0 | J34: 0 | K34: 0 | L34: 0 | M34: 0 | N34: 0 | O34: 0 | P34: 0 | Q34: 0 | R34: 0 | S34: 0 | T34: 0 | U34: 0 | V34: 0 | W34: 0 | X34: 0 | Y34: 0 | Z34: 0 | AA34: 0 | AB34: =(SUM(D34:AA34)) -> 0 | AC34: 19 | AD34: =(AB34*AC34)+(AB35*AC35)+(AB36*AC36)+(AB37*AC37) -> 0
C35: Sábado | D35: 0 | E35: 0 | F35: 0 | G35: 0 | H35: 0 | I35: 0 | J35: 0 | K35: 0 | L35: 0 | M35: 0 | N35: 0 | O35: 0 | P35: 0 | Q35: 0 | R35: 0 | S35: 0 | T35: 0 | U35: 0 | V35: 0 | W35: 0 | X35: 0 | Y35: 0 | Z35: 0 | AA35: 0 | AB35: =(SUM(D35:AA35)) -> 0 | AC35: 5
C36: Domingo | D36: 0 | E36: 0 | F36: 0 | G36: 0 | H36: 0 | I36: 0 | J36: 0 | K36: 0 | L36: 0 | M36: 0 | N36: 0 | O36: 0 | P36: 0 | Q36: 0 | R36: 0 | S36: 0 | T36: 0 | U36: 0 | V36: 0 | W36: 0 | X36: 0 | Y36: 0 | Z36: 0 | AA36: 0 | AB36: =(SUM(D36:AA36)) -> 0 | AC36: 5
C37: Festivo | D37: 0 | E37: 0 | F37: 0 | G37: 0 | H37: 0 | I37: 0 | J37: 0 | K37: 0 | L37: 0 | M37: 0 | N37: 0 | O37: 0 | P37: 0 | Q37: 0 | R37: 0 | S37: 0 | T37: 0 | U37: 0 | V37: 0 | W37: 0 | X37: 0 | Y37: 0 | Z37: 0 | AA37: 0 | AB37: =(SUM(D37:AA37)) -> 0 | AC37: 2
B38: 46266 | C38: Hábil | D38: 1341.82 | E38: 1341.82 | F38: 1341.82 | G38: 1341.82 | H38: 1341.82 | I38: 1341.82 | J38: 1341.82 | K38: 1341.82 | L38: 1341.82 | M38: 1341.82 | N38: 1341.82 | O38: 1341.82 | P38: 1341.82 | Q38: 1341.82 | R38: 1341.82 | S38: 1341.82 | T38: 1341.82 | U38: 1341.82 | V38: 1341.82 | W38: 1341.82 | X38: 1341.82 | Y38: 1341.82 | Z38: 1341.82 | AA38: 1341.82 | AB38: =(SUM(D38:AA38)) -> 32203.68 | AC38: =22-7 -> 15 | AD38: =(AB38*AC38)+(AB39*AC39)+(AB40*AC40)+(AB41*AC41) -> 676277.28
C39: Sábado | D39: 1341.82 | E39: 1341.82 | F39: 1341.82 | G39: 1341.82 | H39: 1341.82 | I39: 1341.82 | J39: 1341.82 | K39: 1341.82 | L39: 1341.82 | M39: 1341.82 | N39: 1341.82 | O39: 1341.82 | P39: 1341.82 | Q39: 1341.82 | R39: 1341.82 | S39: 1341.82 | T39: 1341.82 | U39: 1341.82 | V39: 1341.82 | W39: 1341.82 | X39: 1341.82 | Y39: 1341.82 | Z39: 1341.82 | AA39: 1341.82 | AB39: =(SUM(D39:AA39)) -> 32203.68 | AC39: 3
C40: Domingo | D40: 1341.82 | E40: 1341.82 | F40: 1341.82 | G40: 1341.82 | H40: 1341.82 | I40: 1341.82 | J40: 1341.82 | K40: 1341.82 | L40: 1341.82 | M40: 1341.82 | N40: 1341.82 | O40: 1341.82 | P40: 1341.82 | Q40: 1341.82 | R40: 1341.82 | S40: 1341.82 | T40: 1341.82 | U40: 1341.82 | V40: 1341.82 | W40: 1341.82 | X40: 1341.82 | Y40: 1341.82 | Z40: 1341.82 | AA40: 1341.82 | AB40: =(SUM(D40:AA40)) -> 32203.68 | AC40: 3
C41: Festivo | D41: 1341.82 | E41: 1341.82 | F41: 1341.82 | G41: 1341.82 | H41: 1341.82 | I41: 1341.82 | J41: 1341.82 | K41: 1341.82 | L41: 1341.82 | M41: 1341.82 | N41: 1341.82 | O41: 1341.82 | P41: 1341.82 | Q41: 1341.82 | R41: 1341.82 | S41: 1341.82 | T41: 1341.82 | U41: 1341.82 | V41: 1341.82 | W41: 1341.82 | X41: 1341.82 | Y41: 1341.82 | Z41: 1341.82 | AA41: 1341.82 | AB41: =(SUM(D41:AA41)) -> 32203.68 | AC41: 0
...

Sheet Anexo 2 Producto 1
B4: ANEXO 2 - OFERTA PRODUCTO 1
B5: NOMBRE DEL OFERENTE
B6: PRECIOS Y CANTIDADES DE ENERGIA OFERTADA
B7: EN PESOS DE MAYO 2026
B8: PRODUCTO 1
B9: AÑO | C9: MES | D9: PERIODO 2026
D10: E. Solicitada [kWh] | E10: % E. Ofertado | F10: E. Ofertada [kWh] | G10: $/kWh
B11: 2026 | C11: Enero | D11: =+'Producto 1 Plano 26'!AE6 -> 0 | F11: =+E11*D11 -> 0
B12: 2026 | C12: Febrero | D12: =+'Producto 1 Plano 26'!AE7 -> 0 | F12: =+E12*D12 -> 0
B13: 2026 | C13: Marzo | D13: =+'Producto 1 Plano 26'!AE8 -> 0 | F13: =+E13*D13 -> 0
B14: 2026 | C14: Abril | D14: =+'Producto 1 Plano 26'!AE9 -> 0 | F14: =+E14*D14 -> 0
B15: 2026 | C15: Mayo | D15: =+'Producto 1 Plano 26'!AE10 -> 0 | F15: =+E15*D15 -> 0
B16: 2026 | C16: Junio | D16: =+'Producto 1 Plano 26'!AE11 -> 0 | F16: =+E16*D16 -> 0
B17: 2026 | C17: Julio | D17: =+'Producto 1 Plano 26'!AE12 -> 0 | F17: =+E17*D17 -> 0
B18: 2026 | C18: Agosto | D18: =+'Producto 1 Plano 26'!AE13 -> 0 | F18: =+E18*D18 -> 0
B19: 2026 | C19: Septiembre | D19: =+'Producto 1 Plano 26'!AE14 -> 676277.28 | F19: =+E19*D19 -> 0
B20: 2026 | C20: Octubre | D20: =+'Producto 1 Plano 26'!AE15 -> 766870.56 | F20: =+E20*D20 -> 0
B21: 2026 | C21: Noviembre | D21: =+'Producto 1 Plano 26'!AE16 -> 2223705.6 | F21: =+E21*D21 -> 0
B22: 2026 | C22: Diciembre | D22: =+'Producto 1 Plano 26'!AE17 -> 5945490 | F22: =+E22*D22 -> 0 | H22: =SUM(D11:D22) -> 9612343.4 | I22: =+H22/1000 -> 9612.3434
B23: Total Producto 1 | D23: =+SUM(D11:D22) -> 9612343.4 | I23: =+D23/1000 -> 9612.3434
B25: E. Solicitada = Energía solicitada por RUITOQUE para el producto.
B26: % E. Ofertado = Porcentaje de energía ofertado por el agente respecto a la E. Solicitada.
B27: E. Ofertada = Energía ofertada por el agente, producto de la E. Solicitada y el % E. Ofertado.
B28: $/kWh = Tarifa de la oferta para todas las horas del mes.

Sheet Producto 2 Plano 26
B2: ANEXO 1 - CANTIDADES DE ENERGÍA SOLICITADA EN kWh
B3: PRODUCTO 2
B4: PERIODO 10 DE SEPTIEMBRE DEL 2026 A DICIEMBRE 31 DE 2026
C5: DIA | D5: 1 | E5: 2 | F5: 3 | G5: 4 | H5: 5 | I5: 6 | J5: 7 | K5: 8 | L5: 9 | M5: 10 | N5: 11 | O5: 12 | P5: 13 | Q5: 14 | R5: 15 | S5: 16 | T5: 17 | U5: 18 | V5: 19 | W5: 20 | X5: 21 | Y5: 22 | Z5: 23 | AA5: 24 | AB5: Total | AC5: No. DÍAS | AD5: Total
B6: 46023 | C6: Hábil | D6: 0 | E6: 0 | F6: 0 | G6: 0 | H6: 0 | I6: 0 | J6: 0 | K6: 0 | L6: 0 | M6: 0 | N6: 0 | O6: 0 | P6: 0 | Q6: 0 | R6: 0 | S6: 0 | T6: 0 | U6: 0 | V6: 0 | W6: 0 | X6: 0 | Y6: 0 | Z6: 0 | AA6: 0 | AB6: =(SUM(D6:AA6)) -> 0 | AC6: 20 | AD6: =(AB6*AC6)+(AB7*AC7)+(AB8*AC8)+(AB9*AC9) -> 0 | AE6: =+AD6 -> 0
C7: Sábado | D7: 0 | E7: 0 | F7: 0 | G7: 0 | H7: 0 | I7: 0 | J7: 0 | K7: 0 | L7: 0 | M7: 0 | N7: 0 | O7: 0 | P7: 0 | Q7: 0 | R7: 0 | S7: 0 | T7: 0 | U7: 0 | V7: 0 | W7: 0 | X7: 0 | Y7: 0 | Z7: 0 | AA7: 0 | AB7: =(SUM(D7:AA7)) -> 0 | AC7: 5 | AE7: =+AD10 -> 0
C8: Domingo | D8: 0 | E8: 0 | F8: 0 | G8: 0 | H8: 0 | I8: 0 | J8: 0 | K8: 0 | L8: 0 | M8: 0 | N8: 0 | O8: 0 | P8: 0 | Q8: 0 | R8: 0 | S8: 0 | T8: 0 | U8: 0 | V8: 0 | W8: 0 | X8: 0 | Y8: 0 | Z8: 0 | AA8: 0 | AB8: =(SUM(D8:AA8)) -> 0 | AC8: 4 | AE8: =+AD14 -> 0
C9: Festivo | D9: 0 | E9: 0 | F9: 0 | G9: 0 | H9: 0 | I9: 0 | J9: 0 | K9: 0 | L9: 0 | M9: 0 | N9: 0 | O9: 0 | P9: 0 | Q9: 0 | R9: 0 | S9: 0 | T9: 0 | U9: 0 | V9: 0 | W9: 0 | X9: 0 | Y9: 0 | Z9: 0 | AA9: 0 | AB9: =(SUM(D9:AA9)) -> 0 | AC9: 2 | AE9: =+AD18 -> 0
B10: 46054 | C10: Hábil | D10: 0 | E10: 0 | F10: 0 | G10: 0 | H10: 0 | I10: 0 | J10: 0 | K10: 0 | L10: 0 | M10: 0 | N10: 0 | O10: 0 | P10: 0 | Q10: 0 | R10: 0 | S10: 0 | T10: 0 | U10: 0 | V10: 0 | W10: 0 | X10: 0 | Y10: 0 | Z10: 0 | AA10: 0 | AB10: =(SUM(D10:AA10)) -> 0 | AC10: 20 | AD10: =(AB10*AC10)+(AB11*AC11)+(AB12*AC12)+(AB13*AC13) -> 0 | AE10: =+AD22 -> 0
C11: Sábado | D11: 0 | E11: 0 | F11: 0 | G11: 0 | H11: 0 | I11: 0 | J11: 0 | K11: 0 | L11: 0 | M11: 0 | N11: 0 | O11: 0 | P11: 0 | Q11: 0 | R11: 0 | S11: 0 | T11: 0 | U11: 0 | V11: 0 | W11: 0 | X11: 0 | Y11: 0 | Z11: 0 | AA11: 0 | AB11: =(SUM(D11:AA11)) -> 0 | AC11: 4 | AE11: =+AD26 -> 0
C12: Domingo | D12: 0 | E12: 0 | F12: 0 | G12: 0 | H12: 0 | I12: 0 | J12: 0 | K12: 0 | L12: 0 | M12: 0 | N12: 0 | O12: 0 | P12: 0 | Q12: 0 | R12: 0 | S12: 0 | T12: 0 | U12: 0 | V12: 0 | W12: 0 | X12: 0 | Y12: 0 | Z12: 0 | AA12: 0 | AB12: =(SUM(D12:AA12)) -> 0 | AC12: 4 | AE12: =+AD30 -> 0
C13: Festivo | D13: 0 | E13: 0 | F13: 0 | G13: 0 | H13: 0 | I13: 0 | J13: 0 | K13: 0 | L13: 0 | M13: 0 | N13: 0 | O13: 0 | P13: 0 | Q13: 0 | R13: 0 | S13: 0 | T13: 0 | U13: 0 | V13: 0 | W13: 0 | X13: 0 | Y13: 0 | Z13: 0 | AA13: 0 | AB13: =(SUM(D13:AA13)) -> 0 | AC13: 0 | AE13: =+AD34 -> 0
B14: 46082 | C14: Hábil | D14: 0 | E14: 0 | F14: 0 | G14: 0 | H14: 0 | I14: 0 | J14: 0 | K14: 0 | L14: 0 | M14: 0 | N14: 0 | O14: 0 | P14: 0 | Q14: 0 | R14: 0 | S14: 0 | T14: 0 | U14: 0 | V14: 0 | W14: 0 | X14: 0 | Y14: 0 | Z14: 0 | AA14: 0 | AB14: =(SUM(D14:AA14)) -> 0 | AC14: 21 | AD14: =(AB14*AC14)+(AB15*AC15)+(AB16*AC16)+(AB17*AC17) -> 0 | AE14: =+AD38 -> 695152.08
C15: Sábado | D15: 0 | E15: 0 | F15: 0 | G15: 0 | H15: 0 | I15: 0 | J15: 0 | K15: 0 | L15: 0 | M15: 0 | N15: 0 | O15: 0 | P15: 0 | Q15: 0 | R15: 0 | S15: 0 | T15: 0 | U15: 0 | V15: 0 | W15: 0 | X15: 0 | Y15: 0 | Z15: 0 | AA15: 0 | AB15: =(SUM(D15:AA15)) -> 0 | AC15: 4 | AE15: =+AD42 -> 1378103.8
C16: Domingo | D16: 0 | E16: 0 | F16: 0 | G16: 0 | H16: 0 | I16: 0 | J16: 0 | K16: 0 | L16: 0 | M16: 0 | N16: 0 | O16: 0 | P16: 0 | Q16: 0 | R16: 0 | S16: 0 | T16: 0 | U16: 0 | V16: 0 | W16: 0 | X16: 0 | Y16: 0 | Z16: 0 | AA16: 0 | AB16: =(SUM(D16:AA16)) -> 0 | AC16: 5 | AE16: =+AD46 -> 1422676.8
C17: Festivo | D17: 0 | E17: 0 | F17: 0 | G17: 0 | H17: 0 | I17: 0 | J17: 0 | K17: 0 | L17: 0 | M17: 0 | N17: 0 | O17: 0 | P17: 0 | Q17: 0 | R17: 0 | S17: 0 | T17: 0 | U17: 0 | V17: 0 | W17: 0 | X17: 0 | Y17: 0 | Z17: 0 | AA17: 0 | AB17: =(SUM(D17:AA17)) -> 0 | AC17: 1 | AE17: =+AD50 -> 1538101
B18: 46113 | C18: Hábil | D18: 0 | E18: 0 | F18: 0 | G18: 0 | H18: 0 | I18: 0 | J18: 0 | K18: 0 | L18: 0 | M18: 0 | N18: 0 | O18: 0 | P18: 0 | Q18: 0 | R18: 0 | S18: 0 | T18: 0 | U18: 0 | V18: 0 | W18: 0 | X18: 0 | Y18: 0 | Z18: 0 | AA18: 0 | AB18: =(SUM(D18:AA18)) -> 0 | AC18: 20 | AD18: =(AB18*AC18)+(AB19*AC19)+(AB20*AC20)+(AB21*AC21) -> 0 | AE18: =+#REF! -> #REF!
C19: Sábado | D19: 0 | E19: 0 | F19: 0 | G19: 0 | H19: 0 | I19: 0 | J19: 0 | K19: 0 | L19: 0 | M19: 0 | N19: 0 | O19: 0 | P19: 0 | Q19: 0 | R19: 0 | S19: 0 | T19: 0 | U19: 0 | V19: 0 | W19: 0 | X19: 0 | Y19: 0 | Z19: 0 | AA19: 0 | AB19: =(SUM(D19:AA19)) -> 0 | AC19: 4 | AE19: =+#REF! -> #REF!
C20: Domingo | D20: 0 | E20: 0 | F20: 0 | G20: 0 | H20: 0 | I20: 0 | J20: 0 | K20: 0 | L20: 0 | M20: 0 | N20: 0 | O20: 0 | P20: 0 | Q20: 0 | R20: 0 | S20: 0 | T20: 0 | U20: 0 | V20: 0 | W20: 0 | X20: 0 | Y20: 0 | Z20: 0 | AA20: 0 | AB20: =(SUM(D20:AA20)) -> 0 | AC20: 4 | AE20: =+#REF! -> #REF!
C21: Festivo | D21: 0 | E21: 0 | F21: 0 | G21: 0 | H21: 0 | I21: 0 | J21: 0 | K21: 0 | L21: 0 | M21: 0 | N21: 0 | O21: 0 | P21: 0 | Q21: 0 | R21: 0 | S21: 0 | T21: 0 | U21: 0 | V21: 0 | W21: 0 | X21: 0 | Y21: 0 | Z21: 0 | AA21: 0 | AB21: =(SUM(D21:AA21)) -> 0 | AC21: 2 | AE21: =+#REF! -> #REF!
B22: 46143 | C22: Hábil | D22: 0 | E22: 0 | F22: 0 | G22: 0 | H22: 0 | I22: 0 | J22: 0 | K22: 0 | L22: 0 | M22: 0 | N22: 0 | O22: 0 | P22: 0 | Q22: 0 | R22: 0 | S22: 0 | T22: 0 | U22: 0 | V22: 0 | W22: 0 | X22: 0 | Y22: 0 | Z22: 0 | AA22: 0 | AB22: =(SUM(D22:AA22)) -> 0 | AC22: 19 | AD22: =(AB22*AC22)+(AB23*AC23)+(AB24*AC24)+(AB25*AC25) -> 0 | AE22: =+#REF! -> #REF!
C23: Sábado | D23: 0 | E23: 0 | F23: 0 | G23: 0 | H23: 0 | I23: 0 | J23: 0 | K23: 0 | L23: 0 | M23: 0 | N23: 0 | O23: 0 | P23: 0 | Q23: 0 | R23: 0 | S23: 0 | T23: 0 | U23: 0 | V23: 0 | W23: 0 | X23: 0 | Y23: 0 | Z23: 0 | AA23: 0 | AB23: =(SUM(D23:AA23)) -> 0 | AC23: 5 | AE23: =+#REF! -> #REF!
C24: Domingo | D24: 0 | E24: 0 | F24: 0 | G24: 0 | H24: 0 | I24: 0 | J24: 0 | K24: 0 | L24: 0 | M24: 0 | N24: 0 | O24: 0 | P24: 0 | Q24: 0 | R24: 0 | S24: 0 | T24: 0 | U24: 0 | V24: 0 | W24: 0 | X24: 0 | Y24: 0 | Z24: 0 | AA24: 0 | AB24: =(SUM(D24:AA24)) -> 0 | AC24: 5 | AE24: =+#REF! -> #REF!
C25: Festivo | D25: 0 | E25: 0 | F25: 0 | G25: 0 | H25: 0 | I25: 0 | J25: 0 | K25: 0 | L25: 0 | M25: 0 | N25: 0 | O25: 0 | P25: 0 | Q25: 0 | R25: 0 | S25: 0 | T25: 0 | U25: 0 | V25: 0 | W25: 0 | X25: 0 | Y25: 0 | Z25: 0 | AA25: 0 | AB25: =(SUM(D25:AA25)) -> 0 | AC25: 2 | AE25: =+#REF! -> #REF!
B26: 46174 | C26: Hábil | D26: 0 | E26: 0 | F26: 0 | G26: 0 | H26: 0 | I26: 0 | J26: 0 | K26: 0 | L26: 0 | M26: 0 | N26: 0 | O26: 0 | P26: 0 | Q26: 0 | R26: 0 | S26: 0 | T26: 0 | U26: 0 | V26: 0 | W26: 0 | X26: 0 | Y26: 0 | Z26: 0 | AA26: 0 | AB26: =(SUM(D26:AA26)) -> 0 | AC26: 19 | AD26: =(AB26*AC26)+(AB27*AC27)+(AB28*AC28)+(AB29*AC29) -> 0 | AE26: =+#REF! -> #REF!
C27: Sábado | D27: 0 | E27: 0 | F27: 0 | G27: 0 | H27: 0 | I27: 0 | J27: 0 | K27: 0 | L27: 0 | M27: 0 | N27: 0 | O27: 0 | P27: 0 | Q27: 0 | R27: 0 | S27: 0 | T27: 0 | U27: 0 | V27: 0 | W27: 0 | X27: 0 | Y27: 0 | Z27: 0 | AA27: 0 | AB27: =(SUM(D27:AA27)) -> 0 | AC27: 4 | AE27: =+#REF! -> #REF!
C28: Domingo | D28: 0 | E28: 0 | F28: 0 | G28: 0 | H28: 0 | I28: 0 | J28: 0 | K28: 0 | L28: 0 | M28: 0 | N28: 0 | O28: 0 | P28: 0 | Q28: 0 | R28: 0 | S28: 0 | T28: 0 | U28: 0 | V28: 0 | W28: 0 | X28: 0 | Y28: 0 | Z28: 0 | AA28: 0 | AB28: =(SUM(D28:AA28)) -> 0 | AC28: 4 | AE28: =+#REF! -> #REF!
C29: Festivo | D29: 0 | E29: 0 | F29: 0 | G29: 0 | H29: 0 | I29: 0 | J29: 0 | K29: 0 | L29: 0 | M29: 0 | N29: 0 | O29: 0 | P29: 0 | Q29: 0 | R29: 0 | S29: 0 | T29: 0 | U29: 0 | V29: 0 | W29: 0 | X29: 0 | Y29: 0 | Z29: 0 | AA29: 0 | AB29: =(SUM(D29:AA29)) -> 0 | AC29: 3 | AE29: =+#REF! -> #REF!
B30: 46204 | C30: Hábil | D30: 0 | E30: 0 | F30: 0 | G30: 0 | H30: 0 | I30: 0 | J30: 0 | K30: 0 | L30: 0 | M30: 0 | N30: 0 | O30: 0 | P30: 0 | Q30: 0 | R30: 0 | S30: 0 | T30: 0 | U30: 0 | V30: 0 | W30: 0 | X30: 0 | Y30: 0 | Z30: 0 | AA30: 0 | AB30: =(SUM(D30:AA30)) -> 0 | AC30: 21 | AD30: =(AB30*AC30)+(AB31*AC31)+(AB32*AC32)+(AB33*AC33) -> 0 | AE30: =+#REF! -> #REF!
C31: Sábado | D31: 0 | E31: 0 | F31: 0 | G31: 0 | H31: 0 | I31: 0 | J31: 0 | K31: 0 | L31: 0 | M31: 0 | N31: 0 | O31: 0 | P31: 0 | Q31: 0 | R31: 0 | S31: 0 | T31: 0 | U31: 0 | V31: 0 | W31: 0 | X31: 0 | Y31: 0 | Z31: 0 | AA31: 0 | AB31: =(SUM(D31:AA31)) -> 0 | AC31: 4 | AE31: =+#REF! -> #REF!
C32: domingo | D32: 0 | E32: 0 | F32: 0 | G32: 0 | H32: 0 | I32: 0 | J32: 0 | K32: 0 | L32: 0 | M32: 0 | N32: 0 | O32: 0 | P32: 0 | Q32: 0 | R32: 0 | S32: 0 | T32: 0 | U32: 0 | V32: 0 | W32: 0 | X32: 0 | Y32: 0 | Z32: 0 | AA32: 0 | AB32: =(SUM(D32:AA32)) -> 0 | AC32: 4 | AE32: =+#REF! -> #REF!
C33: Festivo | D33: 0 | E33: 0 | F33: 0 | G33: 0 | H33: 0 | I33: 0 | J33: 0 | K33: 0 | L33: 0 | M33: 0 | N33: 0 | O33: 0 | P33: 0 | Q33: 0 | R33: 0 | S33: 0 | T33: 0 | U33: 0 | V33: 0 | W33: 0 | X33: 0 | Y33: 0 | Z33: 0 | AA33: 0 | AB33: =(SUM(D33:AA33)) -> 0 | AC33: 1 | AE33: =+#REF! -> #REF!
B34: 46235 | C34: Hábil | D34: 0 | E34: 0 | F34: 0 | G34: 0 | H34: 0 | I34: 0 | J34: 0 | K34: 0 | L34: 0 | M34: 0 | N34: 0 | O34: 0 | P34: 0 | Q34: 0 | R34: 0 | S34: 0 | T34: 0 | U34: 0 | V34: 0 | W34: 0 | X34: 0 | Y34: 0 | Z34: 0 | AA34: 0 | AB34: =(SUM(D34:AA34)) -> 0 | AC34: 19 | AD34: =(AB34*AC34)+(AB35*AC35)+(AB36*AC36)+(AB37*AC37) -> 0 | AE34: =+#REF! -> #REF!
C35: Sábado | D35: 0 | E35: 0 | F35: 0 | G35: 0 | H35: 0 | I35: 0 | J35: 0 | K35: 0 | L35: 0 | M35: 0 | N35: 0 | O35: 0 | P35: 0 | Q35: 0 | R35: 0 | S35: 0 | T35: 0 | U35: 0 | V35: 0 | W35: 0 | X35: 0 | Y35: 0 | Z35: 0 | AA35: 0 | AB35: =(SUM(D35:AA35)) -> 0 | AC35: 5 | AE35: =+#REF! -> #REF!
C36: Domingo | D36: 0 | E36: 0 | F36: 0 | G36: 0 | H36: 0 | I36: 0 | J36: 0 | K36: 0 | L36: 0 | M36: 0 | N36: 0 | O36: 0 | P36: 0 | Q36: 0 | R36: 0 | S36: 0 | T36: 0 | U36: 0 | V36: 0 | W36: 0 | X36: 0 | Y36: 0 | Z36: 0 | AA36: 0 | AB36: =(SUM(D36:AA36)) -> 0 | AC36: 5 | AE36: =+#REF! -> #REF!
C37: Festivo | D37: 0 | E37: 0 | F37: 0 | G37: 0 | H37: 0 | I37: 0 | J37: 0 | K37: 0 | L37: 0 | M37: 0 | N37: 0 | O37: 0 | P37: 0 | Q37: 0 | R37: 0 | S37: 0 | T37: 0 | U37: 0 | V37: 0 | W37: 0 | X37: 0 | Y37: 0 | Z37: 0 | AA37: 0 | AB37: =(SUM(D37:AA37)) -> 0 | AC37: 2 | AE37: =+#REF! -> #REF!
B38: 46266 | C38: Hábil | D38: 1379.27 | E38: 1379.27 | F38: 1379.27 | G38: 1379.27 | H38: 1379.27 | I38: 1379.27 | J38: 1379.27 | K38: 1379.27 | L38: 1379.27 | M38: 1379.27 | N38: 1379.27 | O38: 1379.27 | P38: 1379.27 | Q38: 1379.27 | R38: 1379.27 | S38: 1379.27 | T38: 1379.27 | U38: 1379.27 | V38: 1379.27 | W38: 1379.27 | X38: 1379.27 | Y38: 1379.27 | Z38: 1379.27 | AA38: 1379.27 | AB38: =(SUM(D38:AA38)) -> 33102.48 | AC38: 15 | AD38: =(AB38*AC38)+(AB39*AC39)+(AB40*AC40)+(AB41*AC41) -> 695152.08 | AE38: =+#REF! -> #REF!
C39: Sábado | D39: 1379.27 | E39: 1379.27 | F39: 1379.27 | G39: 1379.27 | H39: 1379.27 | I39: 1379.27 | J39: 1379.27 | K39: 1379.27 | L39: 1379.27 | M39: 1379.27 | N39: 1379.27 | O39: 1379.27 | P39: 1379.27 | Q39: 1379.27 | R39: 1379.27 | S39: 1379.27 | T39: 1379.27 | U39: 1379.27 | V39: 1379.27 | W39: 1379.27 | X39: 1379.27 | Y39: 1379.27 | Z39: 1379.27 | AA39: 1379.27 | AB39: =(SUM(D39:AA39)) -> 33102.48 | AC39: 3 | AE39: =+#REF! -> #REF!
C40: Domingo | D40: 1379.27 | E40: 1379.27 | F40: 1379.27 | G40: 1379.27 | H40: 1379.27 | I40: 1379.27 | J40: 1379.27 | K40: 1379.27 | L40: 1379.27 | M40: 1379.27 | N40: 1379.27 | O40: 1379.27 | P40: 1379.27 | Q40: 1379.27 | R40: 1379.27 | S40: 1379.27 | T40: 1379.27 | U40: 1379.27 | V40: 1379.27 | W40: 1379.27 | X40: 1379.27 | Y40: 1379.27 | Z40: 1379.27 | AA40: 1379.27 | AB40: =(SUM(D40:AA40)) -> 33102.48 | AC40: 3 | AE40: =+#REF! -> #REF!
C41: Festivo | D41: 1379.27 | E41: 1379.27 | F41: 1379.27 | G41: 1379.27 | H41: 1379.27 | I41: 1379.27 | J41: 1379.27 | K41: 1379.27 | L41: 1379.27 | M41: 1379.27 | N41: 1379.27 | O41: 1379.27 | P41: 1379.27 | Q41: 1379.27 | R41: 1379.27 | S41: 1379.27 | T41: 1379.27 | U41: 1379.27 | V41: 1379.27 | W41: 1379.27 | X41: 1379.27 | Y41: 1379.27 | Z41: 1379.27 | AA41: 1379.27 | AB41: =(SUM(D41:AA41)) -> 33102.48 | AC41: 0 | AE41: =+#REF! -> #REF!
...

Sheet Anexo 2 Producto 2
B4: ANEXO 2 - OFERTA PRODUCTO 2
B5: NOMBRE DEL OFERENTE
B6: PRECIOS Y CANTIDADES DE ENERGIA OFERTADA
B7: EN PESOS DE MAYO 2026
B8: PRODUCTO 2
B9: AÑO | C9: MES | D9: PERIODO 2026
D10: E. Solicitada [kWh] | E10: % E. Ofertado | F10: E. Ofertada [kWh] | G10: $/kWh
B11: 2026 | C11: Enero | D11: =+'Producto 2 Plano 26'!AE6 -> 0 | F11: =+E11*D11 -> 0
B12: 2026 | C12: Febrero | D12: =+'Producto 2 Plano 26'!AE7 -> 0 | F12: =+E12*D12 -> 0
B13: 2026 | C13: Marzo | D13: =+'Producto 2 Plano 26'!AE8 -> 0 | F13: =+E13*D13 -> 0
B14: 2026 | C14: Abril | D14: =+'Producto 2 Plano 26'!AE9 -> 0 | F14: =+E14*D14 -> 0
B15: 2026 | C15: Mayo | D15: =+'Producto 2 Plano 26'!AE10 -> 0 | F15: =+E15*D15 -> 0
B16: 2026 | C16: Junio | D16: =+'Producto 2 Plano 26'!AE11 -> 0 | F16: =+E16*D16 -> 0
B17: 2026 | C17: Julio | D17: =+'Producto 2 Plano 26'!AE12 -> 0 | F17: =+E17*D17 -> 0
B18: 2026 | C18: Agosto | D18: =+'Producto 2 Plano 26'!AE13 -> 0 | F18: =+E18*D18 -> 0
B19: 2026 | C19: Septiembre | D19: =+'Producto 2 Plano 26'!AE14 -> 695152.08 | F19: =+E19*D19 -> 0
B20: 2026 | C20: Octubre | D20: =+'Producto 2 Plano 26'!AE15 -> 1378103.8 | F20: =+E20*D20 -> 0
B21: 2026 | C21: Noviembre | D21: =+'Producto 2 Plano 26'!AE16 -> 1422676.8 | F21: =+E21*D21 -> 0
B22: 2026 | C22: Diciembre | D22: =+'Producto 2 Plano 26'!AE17 -> 1538101 | F22: =+E22*D22 -> 0 | H22: =SUM(D11:D22) -> 5034033.6 | I22: =+H22/1000 -> 5034.0336
B23: Total Producto 2 | D23: =+SUM(D11:D22) -> 5034033.6 | I23: =+D23/1000 -> 5034.0336
B25: E. Solicitada = Energía solicitada por RUITOQUE para el producto.
B26: % E. Ofertado = Porcentaje de energía ofertado por el agente respecto a la E. Solicitada.
B27: E. Ofertada = Energía ofertada por el agente, producto de la E. Solicitada y el % E. Ofertado.
B28: $/kWh = Tarifa de la oferta para todas las horas del mes.

Sheet Producto 3 Plano 27
B2: ANEXO 1 - CANTIDADES DE ENERGÍA SOLICITADA EN kWh
B3: PRODUCTO 3
B4: PERIODO 01 DE ENERO DEL 2027 A JULIO 31 DE 2027
C5: DIA | D5: 1 | E5: 2 | F5: 3 | G5: 4 | H5: 5 | I5: 6 | J5: 7 | K5: 8 | L5: 9 | M5: 10 | N5: 11 | O5: 12 | P5: 13 | Q5: 14 | R5: 15 | S5: 16 | T5: 17 | U5: 18 | V5: 19 | W5: 20 | X5: 21 | Y5: 22 | Z5: 23 | AA5: 24 | AB5: Total | AC5: No. DÍAS | AD5: Total
B6: 46388 | C6: Hábil | D6: 10884.85 | E6: =+$D$6 -> 10884.85 | F6: =+$D$6 -> 10884.85 | G6: =+$D$6 -> 10884.85 | H6: =+$D$6 -> 10884.85 | I6: =+$D$6 -> 10884.85 | J6: =+$D$6 -> 10884.85 | K6: =+$D$6 -> 10884.85 | L6: =+$D$6 -> 10884.85 | ... AA6: =+$D$6 -> 10884.85 | AB6: =(SUM(D6:AA6)) -> 261236.4 | AC6: 19 | AD6: =(AB6*AC6)+(AB7*AC7)+(AB8*AC8)+(AB9*AC9) -> 8098328.4 | AE6: =+AD6 -> 8098328.4
C7: Sábado | D7: =+$D$6 -> 10884.85 | E7: =+$D$6 -> 10884.85 | F7: =+$D$6 -> 10884.85 | G7: =+$D$6 -> 10884.85 | H7: =+$D$6 -> 10884.85 | I7: =+$D$6 -> 10884.85 | J7: =+$D$6 -> 10884.85 | K7: =+$D$6 -> 10884.85 | ... AA7: =+$D$6 -> 10884.85 | AB7: =(SUM(D7:AA7)) -> 261236.4 | AC7: 5 | AE7: =+AD10 -> 8342712
C8: Domingo | D8: =+$D$6 -> 10884.85 | E8: =+$D$6 -> 10884.85 | F8: =+$D$6 -> 10884.85 | G8: =+$D$6 -> 10884.85 | H8: =+$D$6 -> 10884.85 | I8: =+$D$6 -> 10884.85 | J8: =+$D$6 -> 10884.85 | K8: =+$D$6 -> 10884.85 | ... AA8: =+$D$6 -> 10884.85 | AB8: =(SUM(D8:AA8)) -> 261236.4 | AC8: 5 | AE8: =+AD14 -> 7888260
C9: Festivo | D9: =+$D$6 -> 10884.85 | E9: =+$D$6 -> 10884.85 | F9: =+$D$6 -> 10884.85 | G9: =+$D$6 -> 10884.85 | H9: =+$D$6 -> 10884.85 | I9: =+$D$6 -> 10884.85 | J9: =+$D$6 -> 10884.85 | K9: =+$D$6 -> 10884.85 | ... AA9: =+$D$6 -> 10884.85 | AB9: =(SUM(D9:AA9)) -> 261236.4 | AC9: 2 | AE9: =+AD18 -> 8281728
B10: 46419 | C10: Hábil | D10: 12414.75 | E10: =+D10 -> 12414.75 | F10: =+D10 -> 12414.75 | G10: =+D10 -> 12414.75 | H10: =+D10 -> 12414.75 | I10: =+D10 -> 12414.75 | J10: =+D10 -> 12414.75 | K10: =+D10 -> 12414.75 | L10: =+D10 -> 12414.75 | M10: =+D10 -> 12414.75 | N10: =+D10 -> 12414.75 | O10: =+D10 -> 12414.75 | P10: =+D10 -> 12414.75 | Q10: =+D10 -> 12414.75 | R10: =+D10 -> 12414.75 | S10: =+D10 -> 12414.75 | T10: =+D10 -> 12414.75 | U10: =+D10 -> 12414.75 | V10: =+D10 -> 12414.75 | W10: =+D10 -> 12414.75 | X10: =+D10 -> 12414.75 | Y10: =+D10 -> 12414.75 | Z10: =+D10 -> 12414.75 | AA10: =+D10 -> 12414.75 | AB10: =(SUM(D10:AA10)) -> 297954 | AC10: 20 | AD10: =(AB10*AC10)+(AB11*AC11)+(AB12*AC12)+(AB13*AC13) -> 8342712 | AE10: =+AD22 -> 4722450.7
C11: Sábado | D11: =+D10 -> 12414.75 | E11: =+D10 -> 12414.75 | F11: =+D10 -> 12414.75 | G11: =+D10 -> 12414.75 | H11: =+D10 -> 12414.75 | I11: =+D10 -> 12414.75 | J11: =+D10 -> 12414.75 | K11: =+D10 -> 12414.75 | L11: =+D10 -> 12414.75 | M11: =+D10 -> 12414.75 | N11: =+D10 -> 12414.75 | O11: =+D10 -> 12414.75 | P11: =+D10 -> 12414.75 | Q11: =+D10 -> 12414.75 | R11: =+D10 -> 12414.75 | S11: =+D10 -> 12414.75 | T11: =+D10 -> 12414.75 | U11: =+D10 -> 12414.75 | V11: =+D10 -> 12414.75 | W11: =+D10 -> 12414.75 | X11: =+D10 -> 12414.75 | Y11: =+D10 -> 12414.75 | Z11: =+D10 -> 12414.75 | AA11: =+D10 -> 12414.75 | AB11: =(SUM(D11:AA11)) -> 297954 | AC11: 4 | AE11: =+AD26 -> 5344408.8
C12: Domingo | D12: =+D10 -> 12414.75 | E12: =+D10 -> 12414.75 | F12: =+D10 -> 12414.75 | G12: =+D10 -> 12414.75 | H12: =+D10 -> 12414.75 | I12: =+D10 -> 12414.75 | J12: =+D10 -> 12414.75 | K12: =+D10 -> 12414.75 | L12: =+D10 -> 12414.75 | M12: =+D10 -> 12414.75 | N12: =+D10 -> 12414.75 | O12: =+D10 -> 12414.75 | P12: =+D10 -> 12414.75 | Q12: =+D10 -> 12414.75 | R12: =+D10 -> 12414.75 | S12: =+D10 -> 12414.75 | T12: =+D10 -> 12414.75 | U12: =+D10 -> 12414.75 | V12: =+D10 -> 12414.75 | W12: =+D10 -> 12414.75 | X12: =+D10 -> 12414.75 | Y12: =+D10 -> 12414.75 | Z12: =+D10 -> 12414.75 | AA12: =+D10 -> 12414.75 | AB12: =(SUM(D12:AA12)) -> 297954 | AC12: 4 | AE12: =+AD30 -> 4659277.7
C13: Festivo | D13: =+D10 -> 12414.75 | E13: =+D10 -> 12414.75 | F13: =+D10 -> 12414.75 | G13: =+D10 -> 12414.75 | H13: =+D10 -> 12414.75 | I13: =+D10 -> 12414.75 | J13: =+D10 -> 12414.75 | K13: =+D10 -> 12414.75 | L13: =+D10 -> 12414.75 | M13: =+D10 -> 12414.75 | N13: =+D10 -> 12414.75 | O13: =+D10 -> 12414.75 | P13: =+D10 -> 12414.75 | Q13: =+D10 -> 12414.75 | R13: =+D10 -> 12414.75 | S13: =+D10 -> 12414.75 | T13: =+D10 -> 12414.75 | U13: =+D10 -> 12414.75 | V13: =+D10 -> 12414.75 | W13: =+D10 -> 12414.75 | X13: =+D10 -> 12414.75 | Y13: =+D10 -> 12414.75 | Z13: =+D10 -> 12414.75 | AA13: =+D10 -> 12414.75 | AB13: =(SUM(D13:AA13)) -> 297954 | AC13: 0 | AE13: =+#REF! -> #REF!
B14: 46447 | C14: Hábil | D14: 10602.5 | E14: =+D14 -> 10602.5 | F14: =+D14 -> 10602.5 | G14: =+D14 -> 10602.5 | H14: =+D14 -> 10602.5 | I14: =+D14 -> 10602.5 | J14: =+D14 -> 10602.5 | K14: =+D14 -> 10602.5 | L14: =+D14 -> 10602.5 | M14: =+D14 -> 10602.5 | N14: =+D14 -> 10602.5 | O14: =+D14 -> 10602.5 | P14: =+D14 -> 10602.5 | Q14: =+D14 -> 10602.5 | R14: =+D14 -> 10602.5 | S14: =+D14 -> 10602.5 | T14: =+D14 -> 10602.5 | U14: =+D14 -> 10602.5 | V14: =+D14 -> 10602.5 | W14: =+D14 -> 10602.5 | X14: =+D14 -> 10602.5 | Y14: =+D14 -> 10602.5 | Z14: =+D14 -> 10602.5 | AA14: =+D14 -> 10602.5 | AB14: =(SUM(D14:AA14)) -> 254460 | AC14: 20 | AD14: =(AB14*AC14)+(AB15*AC15)+(AB16*AC16)+(AB17*AC17) -> 7888260 | AE14: =+#REF! -> #REF!
C15: Sábado | D15: =+D14 -> 10602.5 | E15: =+D14 -> 10602.5 | F15: =+D14 -> 10602.5 | G15: =+D14 -> 10602.5 | H15: =+D14 -> 10602.5 | I15: =+D14 -> 10602.5 | J15: =+D14 -> 10602.5 | K15: =+D14 -> 10602.5 | L15: =+D14 -> 10602.5 | M15: =+D14 -> 10602.5 | N15: =+D14 -> 10602.5 | O15: =+D14 -> 10602.5 | P15: =+D14 -> 10602.5 | Q15: =+D14 -> 10602.5 | R15: =+D14 -> 10602.5 | S15: =+D14 -> 10602.5 | T15: =+D14 -> 10602.5 | U15: =+D14 -> 10602.5 | V15: =+D14 -> 10602.5 | W15: =+D14 -> 10602.5 | X15: =+D14 -> 10602.5 | Y15: =+D14 -> 10602.5 | Z15: =+D14 -> 10602.5 | AA15: =+D14 -> 10602.5 | AB15: =(SUM(D15:AA15)) -> 254460 | AC15: 4 | AE15: =+#REF! -> #REF!
C16: Domingo | D16: =+D14 -> 10602.5 | E16: =+D14 -> 10602.5 | F16: =+D14 -> 10602.5 | G16: =+D14 -> 10602.5 | H16: =+D14 -> 10602.5 | I16: =+D14 -> 10602.5 | J16: =+D14 -> 10602.5 | K16: =+D14 -> 10602.5 | L16: =+D14 -> 10602.5 | M16: =+D14 -> 10602.5 | N16: =+D14 -> 10602.5 | O16: =+D14 -> 10602.5 | P16: =+D14 -> 10602.5 | Q16: =+D14 -> 10602.5 | R16: =+D14 -> 10602.5 | S16: =+D14 -> 10602.5 | T16: =+D14 -> 10602.5 | U16: =+D14 -> 10602.5 | V16: =+D14 -> 10602.5 | W16: =+D14 -> 10602.5 | X16: =+D14 -> 10602.5 | Y16: =+D14 -> 10602.5 | Z16: =+D14 -> 10602.5 | AA16: =+D14 -> 10602.5 | AB16: =(SUM(D16:AA16)) -> 254460 | AC16: 4 | AE16: =+#REF! -> #REF!
C17: Festivo | D17: =+D14 -> 10602.5 | E17: =+D14 -> 10602.5 | F17: =+D14 -> 10602.5 | G17: =+D14 -> 10602.5 | H17: =+D14 -> 10602.5 | I17: =+D14 -> 10602.5 | J17: =+D14 -> 10602.5 | K17: =+D14 -> 10602.5 | L17: =+D14 -> 10602.5 | M17: =+D14 -> 10602.5 | N17: =+D14 -> 10602.5 | O17: =+D14 -> 10602.5 | P17: =+D14 -> 10602.5 | Q17: =+D14 -> 10602.5 | R17: =+D14 -> 10602.5 | S17: =+D14 -> 10602.5 | T17: =+D14 -> 10602.5 | U17: =+D14 -> 10602.5 | V17: =+D14 -> 10602.5 | W17: =+D14 -> 10602.5 | X17: =+D14 -> 10602.5 | Y17: =+D14 -> 10602.5 | Z17: =+D14 -> 10602.5 | AA17: =+D14 -> 10602.5 | AB17: =(SUM(D17:AA17)) -> 254460 | AC17: 3 | AE17: =+#REF! -> #REF!
B18: 46478 | C18: Hábil | D18: 11502.4 | E18: =+D18 -> 11502.4 | F18: =+D18 -> 11502.4 | G18: =+D18 -> 11502.4 | H18: =+D18 -> 11502.4 | I18: =+D18 -> 11502.4 | J18: =+D18 -> 11502.4 | K18: =+D18 -> 11502.4 | L18: =+D18 -> 11502.4 | M18: =+D18 -> 11502.4 | N18: =+D18 -> 11502.4 | O18: =+D18 -> 11502.4 | P18: =+D18 -> 11502.4 | Q18: =+D18 -> 11502.4 | R18: =+D18 -> 11502.4 | S18: =+D18 -> 11502.4 | T18: =+D18 -> 11502.4 | U18: =+D18 -> 11502.4 | V18: =+D18 -> 11502.4 | W18: =+D18 -> 11502.4 | X18: =+D18 -> 11502.4 | Y18: =+D18 -> 11502.4 | Z18: =+D18 -> 11502.4 | AA18: =+D18 -> 11502.4 | AB18: =(SUM(D18:AA18)) -> 276057.6 | AC18: 22 | AD18: =(AB18*AC18)+(AB19*AC19)+(AB20*AC20)+(AB21*AC21) -> 8281728
C19: Sábado | D19: =+D18 -> 11502.4 | E19: =+D18 -> 11502.4 | F19: =+D18 -> 11502.4 | G19: =+D18 -> 11502.4 | H19: =+D18 -> 11502.4 | I19: =+D18 -> 11502.4 | J19: =+D18 -> 11502.4 | K19: =+D18 -> 11502.4 | L19: =+D18 -> 11502.4 | M19: =+D18 -> 11502.4 | N19: =+D18 -> 11502.4 | O19: =+D18 -> 11502.4 | P19: =+D18 -> 11502.4 | Q19: =+D18 -> 11502.4 | R19: =+D18 -> 11502.4 | S19: =+D18 -> 11502.4 | T19: =+D18 -> 11502.4 | U19: =+D18 -> 11502.4 | V19: =+D18 -> 11502.4 | W19: =+D18 -> 11502.4 | X19: =+D18 -> 11502.4 | Y19: =+D18 -> 11502.4 | Z19: =+D18 -> 11502.4 | AA19: =+D18 -> 11502.4 | AB19: =(SUM(D19:AA19)) -> 276057.6 | AC19: 4
C20: Domingo | D20: =+D18 -> 11502.4 | E20: =+D18 -> 11502.4 | F20: =+D18 -> 11502.4 | G20: =+D18 -> 11502.4 | H20: =+D18 -> 11502.4 | I20: =+D18 -> 11502.4 | J20: =+D18 -> 11502.4 | K20: =+D18 -> 11502.4 | L20: =+D18 -> 11502.4 | M20: =+D18 -> 11502.4 | N20: =+D18 -> 11502.4 | O20: =+D18 -> 11502.4 | P20: =+D18 -> 11502.4 | Q20: =+D18 -> 11502.4 | R20: =+D18 -> 11502.4 | S20: =+D18 -> 11502.4 | T20: =+D18 -> 11502.4 | U20: =+D18 -> 11502.4 | V20: =+D18 -> 11502.4 | W20: =+D18 -> 11502.4 | X20: =+D18 -> 11502.4 | Y20: =+D18 -> 11502.4 | Z20: =+D18 -> 11502.4 | AA20: =+D18 -> 11502.4 | AB20: =(SUM(D20:AA20)) -> 276057.6 | AC20: 4
C21: Festivo | D21: =+D18 -> 11502.4 | E21: =+D18 -> 11502.4 | F21: =+D18 -> 11502.4 | G21: =+D18 -> 11502.4 | H21: =+D18 -> 11502.4 | I21: =+D18 -> 11502.4 | J21: =+D18 -> 11502.4 | K21: =+D18 -> 11502.4 | L21: =+D18 -> 11502.4 | M21: =+D18 -> 11502.4 | N21: =+D18 -> 11502.4 | O21: =+D18 -> 11502.4 | P21: =+D18 -> 11502.4 | Q21: =+D18 -> 11502.4 | R21: =+D18 -> 11502.4 | S21: =+D18 -> 11502.4 | T21: =+D18 -> 11502.4 | U21: =+D18 -> 11502.4 | V21: =+D18 -> 11502.4 | W21: =+D18 -> 11502.4 | X21: =+D18 -> 11502.4 | Y21: =+D18 -> 11502.4 | Z21: =+D18 -> 11502.4 | AA21: =+D18 -> 11502.4 | AB21: =(SUM(D21:AA21)) -> 276057.6 | AC21: 0
B22: 46508 | C22: Hábil | D22: 6347.38 | E22: =+D22 -> 6347.38 | F22: =+D22 -> 6347.38 | G22: =+D22 -> 6347.38 | H22: =+D22 -> 6347.38 | I22: =+D22 -> 6347.38 | J22: =+D22 -> 6347.38 | K22: =+D22 -> 6347.38 | L22: =+D22 -> 6347.38 | M22: =+D22 -> 6347.38 | N22: =+D22 -> 6347.38 | O22: =+D22 -> 6347.38 | P22: =+D22 -> 6347.38 | Q22: =+D22 -> 6347.38 | R22: =+D22 -> 6347.38 | S22: =+D22 -> 6347.38 | T22: =+D22 -> 6347.38 | U22: =+D22 -> 6347.38 | V22: =+D22 -> 6347.38 | W22: =+D22 -> 6347.38 | X22: =+D22 -> 6347.38 | Y22: =+D22 -> 6347.38 | Z22: =+D22 -> 6347.38 | AA22: =+D22 -> 6347.38 | AB22: =(SUM(D22:AA22)) -> 152337.12 | AC22: 19 | AD22: =(AB22*AC22)+(AB23*AC23)+(AB24*AC24)+(AB25*AC25) -> 4722450.7
C23: Sábado | D23: =+D22 -> 6347.38 | E23: =+D22 -> 6347.38 | F23: =+D22 -> 6347.38 | G23: =+D22 -> 6347.38 | H23: =+D22 -> 6347.38 | I23: =+D22 -> 6347.38 | J23: =+D22 -> 6347.38 | K23: =+D22 -> 6347.38 | L23: =+D22 -> 6347.38 | M23: =+D22 -> 6347.38 | N23: =+D22 -> 6347.38 | O23: =+D22 -> 6347.38 | P23: =+D22 -> 6347.38 | Q23: =+D22 -> 6347.38 | R23: =+D22 -> 6347.38 | S23: =+D22 -> 6347.38 | T23: =+D22 -> 6347.38 | U23: =+D22 -> 6347.38 | V23: =+D22 -> 6347.38 | W23: =+D22 -> 6347.38 | X23: =+D22 -> 6347.38 | Y23: =+D22 -> 6347.38 | Z23: =+D22 -> 6347.38 | AA23: =+D22 -> 6347.38 | AB23: =(SUM(D23:AA23)) -> 152337.12 | AC23: 4
C24: Domingo | D24: =+D22 -> 6347.38 | E24: =+D22 -> 6347.38 | F24: =+D22 -> 6347.38 | G24: =+D22 -> 6347.38 | H24: =+D22 -> 6347.38 | I24: =+D22 -> 6347.38 | J24: =+D22 -> 6347.38 | K24: =+D22 -> 6347.38 | L24: =+D22 -> 6347.38 | M24: =+D22 -> 6347.38 | N24: =+D22 -> 6347.38 | O24: =+D22 -> 6347.38 | P24: =+D22 -> 6347.38 | Q24: =+D22 -> 6347.38 | R24: =+D22 -> 6347.38 | S24: =+D22 -> 6347.38 | T24: =+D22 -> 6347.38 | U24: =+D22 -> 6347.38 | V24: =+D22 -> 6347.38 | W24: =+D22 -> 6347.38 | X24: =+D22 -> 6347.38 | Y24: =+D22 -> 6347.38 | Z24: =+D22 -> 6347.38 | AA24: =+D22 -> 6347.38 | AB24: =(SUM(D24:AA24)) -> 152337.12 | AC24: 5
C25: Festivo | D25: =+D22 -> 6347.38 | E25: =+D22 -> 6347.38 | F25: =+D22 -> 6347.38 | G25: =+D22 -> 6347.38 | H25: =+D22 -> 6347.38 | I25: =+D22 -> 6347.38 | J25: =+D22 -> 6347.38 | K25: =+D22 -> 6347.38 | L25: =+D22 -> 6347.38 | M25: =+D22 -> 6347.38 | N25: =+D22 -> 6347.38 | O25: =+D22 -> 6347.38 | P25: =+D22 -> 6347.38 | Q25: =+D22 -> 6347.38 | R25: =+D22 -> 6347.38 | S25: =+D22 -> 6347.38 | T25: =+D22 -> 6347.38 | U25: =+D22 -> 6347.38 | V25: =+D22 -> 6347.38 | W25: =+D22 -> 6347.38 | X25: =+D22 -> 6347.38 | Y25: =+D22 -> 6347.38 | Z25: =+D22 -> 6347.38 | AA25: =+D22 -> 6347.38 | AB25: =(SUM(D25:AA25)) -> 152337.12 | AC25: 3
B26: 46539 | C26: Hábil | D26: 7422.79 | E26: =+D26 -> 7422.79 | F26: =+D26 -> 7422.79 | G26: =+D26 -> 7422.79 | H26: =+D26 -> 7422.79 | I26: =+D26 -> 7422.79 | J26: =+D26 -> 7422.79 | K26: =+D26 -> 7422.79 | L26: =+D26 -> 7422.79 | M26: =+D26 -> 7422.79 | N26: =+D26 -> 7422.79 | O26: =+D26 -> 7422.79 | P26: =+D26 -> 7422.79 | Q26: =+D26 -> 7422.79 | R26: =+D26 -> 7422.79 | S26: =+D26 -> 7422.79 | T26: =+D26 -> 7422.79 | U26: =+D26 -> 7422.79 | V26: =+D26 -> 7422.79 | W26: =+D26 -> 7422.79 | X26: =+D26 -> 7422.79 | Y26: =+D26 -> 7422.79 | Z26: =+D26 -> 7422.79 | AA26: =+D26 -> 7422.79 | AB26: =(SUM(D26:AA26)) -> 178146.96 | AC26: 21 | AD26: =(AB26*AC26)+(AB27*AC27)+(AB28*AC28)+(AB29*AC29) -> 5344408.8
C27: Sábado | D27: =+D26 -> 7422.79 | E27: =+D26 -> 7422.79 | F27: =+D26 -> 7422.79 | G27: =+D26 -> 7422.79 | H27: =+D26 -> 7422.79 | I27: =+D26 -> 7422.79 | J27: =+D26 -> 7422.79 | K27: =+D26 -> 7422.79 | L27: =+D26 -> 7422.79 | M27: =+D26 -> 7422.79 | N27: =+D26 -> 7422.79 | O27: =+D26 -> 7422.79 | P27: =+D26 -> 7422.79 | Q27: =+D26 -> 7422.79 | R27: =+D26 -> 7422.79 | S27: =+D26 -> 7422.79 | T27: =+D26 -> 7422.79 | U27: =+D26 -> 7422.79 | V27: =+D26 -> 7422.79 | W27: =+D26 -> 7422.79 | X27: =+D26 -> 7422.79 | Y27: =+D26 -> 7422.79 | Z27: =+D26 -> 7422.79 | AA27: =+D26 -> 7422.79 | AB27: =(SUM(D27:AA27)) -> 178146.96 | AC27: 4
C28: Domingo | D28: =+D26 -> 7422.79 | E28: =+D26 -> 7422.79 | F28: =+D26 -> 7422.79 | G28: =+D26 -> 7422.79 | H28: =+D26 -> 7422.79 | I28: =+D26 -> 7422.79 | J28: =+D26 -> 7422.79 | K28: =+D26 -> 7422.79 | L28: =+D26 -> 7422.79 | M28: =+D26 -> 7422.79 | N28: =+D26 -> 7422.79 | O28: =+D26 -> 7422.79 | P28: =+D26 -> 7422.79 | Q28: =+D26 -> 7422.79 | R28: =+D26 -> 7422.79 | S28: =+D26 -> 7422.79 | T28: =+D26 -> 7422.79 | U28: =+D26 -> 7422.79 | V28: =+D26 -> 7422.79 | W28: =+D26 -> 7422.79 | X28: =+D26 -> 7422.79 | Y28: =+D26 -> 7422.79 | Z28: =+D26 -> 7422.79 | AA28: =+D26 -> 7422.79 | AB28: =(SUM(D28:AA28)) -> 178146.96 | AC28: 4
C29: Festivo | D29: =+D26 -> 7422.79 | E29: =+D26 -> 7422.79 | F29: =+D26 -> 7422.79 | G29: =+D26 -> 7422.79 | H29: =+D26 -> 7422.79 | I29: =+D26 -> 7422.79 | J29: =+D26 -> 7422.79 | K29: =+D26 -> 7422.79 | L29: =+D26 -> 7422.79 | M29: =+D26 -> 7422.79 | N29: =+D26 -> 7422.79 | O29: =+D26 -> 7422.79 | P29: =+D26 -> 7422.79 | Q29: =+D26 -> 7422.79 | R29: =+D26 -> 7422.79 | S29: =+D26 -> 7422.79 | T29: =+D26 -> 7422.79 | U29: =+D26 -> 7422.79 | V29: =+D26 -> 7422.79 | W29: =+D26 -> 7422.79 | X29: =+D26 -> 7422.79 | Y29: =+D26 -> 7422.79 | Z29: =+D26 -> 7422.79 | AA29: =+D26 -> 7422.79 | AB29: =(SUM(D29:AA29)) -> 178146.96 | AC29: 1
B30: 46569 | C30: Hábil | D30: 6262.47 | E30: =+D30 -> 6262.47 | F30: =+D30 -> 6262.47 | G30: =+D30 -> 6262.47 | H30: =+D30 -> 6262.47 | I30: =+D30 -> 6262.47 | J30: =+D30 -> 6262.47 | K30: =+D30 -> 6262.47 | L30: =+D30 -> 6262.47 | M30: =+D30 -> 6262.47 | N30: =+D30 -> 6262.47 | O30: =+D30 -> 6262.47 | P30: =+D30 -> 6262.47 | Q30: =+D30 -> 6262.47 | R30: =+D30 -> 6262.47 | S30: =+D30 -> 6262.47 | T30: =+D30 -> 6262.47 | U30: =+D30 -> 6262.47 | V30: =+D30 -> 6262.47 | W30: =+D30 -> 6262.47 | X30: =+D30 -> 6262.47 | Y30: =+D30 -> 6262.47 | Z30: =+D30 -> 6262.47 | AA30: =+D30 -> 6262.47 | AB30: =(SUM(D30:AA30)) -> 150299.28 | AC30: 20 | AD30: =(AB30*AC30)+(AB31*AC31)+(AB32*AC32)+(AB33*AC33) -> 4659277.7
C31: Sábado | D31: =+D30 -> 6262.47 | E31: =+D30 -> 6262.47 | F31: =+D30 -> 6262.47 | G31: =+D30 -> 6262.47 | H31: =+D30 -> 6262.47 | I31: =+D30 -> 6262.47 | J31: =+D30 -> 6262.47 | K31: =+D30 -> 6262.47 | L31: =+D30 -> 6262.47 | M31: =+D30 -> 6262.47 | N31: =+D30 -> 6262.47 | O31: =+D30 -> 6262.47 | P31: =+D30 -> 6262.47 | Q31: =+D30 -> 6262.47 | R31: =+D30 -> 6262.47 | S31: =+D30 -> 6262.47 | T31: =+D30 -> 6262.47 | U31: =+D30 -> 6262.47 | V31: =+D30 -> 6262.47 | W31: =+D30 -> 6262.47 | X31: =+D30 -> 6262.47 | Y31: =+D30 -> 6262.47 | Z31: =+D30 -> 6262.47 | AA31: =+D30 -> 6262.47 | AB31: =(SUM(D31:AA31)) -> 150299.28 | AC31: 5
C32: domingo | D32: =+D30 -> 6262.47 | E32: =+D30 -> 6262.47 | F32: =+D30 -> 6262.47 | G32: =+D30 -> 6262.47 | H32: =+D30 -> 6262.47 | I32: =+D30 -> 6262.47 | J32: =+D30 -> 6262.47 | K32: =+D30 -> 6262.47 | L32: =+D30 -> 6262.47 | M32: =+D30 -> 6262.47 | N32: =+D30 -> 6262.47 | O32: =+D30 -> 6262.47 | P32: =+D30 -> 6262.47 | Q32: =+D30 -> 6262.47 | R32: =+D30 -> 6262.47 | S32: =+D30 -> 6262.47 | T32: =+D30 -> 6262.47 | U32: =+D30 -> 6262.47 | V32: =+D30 -> 6262.47 | W32: =+D30 -> 6262.47 | X32: =+D30 -> 6262.47 | Y32: =+D30 -> 6262.47 | Z32: =+D30 -> 6262.47 | AA32: =+D30 -> 6262.47 | AB32: =(SUM(D32:AA32)) -> 150299.28 | AC32: 4
C33: Festivo | D33: =+D30 -> 6262.47 | E33: =+D30 -> 6262.47 | F33: =+D30 -> 6262.47 | G33: =+D30 -> 6262.47 | H33: =+D30 -> 6262.47 | I33: =+D30 -> 6262.47 | J33: =+D30 -> 6262.47 | K33: =+D30 -> 6262.47 | L33: =+D30 -> 6262.47 | M33: =+D30 -> 6262.47 | N33: =+D30 -> 6262.47 | O33: =+D30 -> 6262.47 | P33: =+D30 -> 6262.47 | Q33: =+D30 -> 6262.47 | R33: =+D30 -> 6262.47 | S33: =+D30 -> 6262.47 | T33: =+D30 -> 6262.47 | U33: =+D30 -> 6262.47 | V33: =+D30 -> 6262.47 | W33: =+D30 -> 6262.47 | X33: =+D30 -> 6262.47 | Y33: =+D30 -> 6262.47 | Z33: =+D30 -> 6262.47 | AA33: =+D30 -> 6262.47 | AB33: =(SUM(D33:AA33)) -> 150299.28 | AC33: 2
AD34: =SUM(AD6:AD33) -> 47337166

Sheet Anexo 2 Producto 3
B4: ANEXO 2 - OFERTA PRODUCTO 3
B5: NOMBRE DEL OFERENTE
B6: PRECIOS Y CANTIDADES DE ENERGIA OFERTADA
B7: EN PESOS DE MAYO 2026
B8: PRODUCTO 3
B9: 2027 | C9: Enero | D9: =+'Producto 3 Plano 27'!AE6 -> 8098328.4 | F9: =+E9*D9 -> 0
B10: =+B9 -> 2027 | C10: Febrero | D10: =+'Producto 3 Plano 27'!AE7 -> 8342712 | F10: =+E10*D10 -> 0
B11: =+B10 -> 2027 | C11: Marzo | D11: =+'Producto 3 Plano 27'!AE8 -> 7888260 | F11: =+E11*D11 -> 0
B12: =+B11 -> 2027 | C12: Abril | D12: =+'Producto 3 Plano 27'!AE9 -> 8281728 | F12: =+E12*D12 -> 0
B13: =+B12 -> 2027 | C13: Mayo | D13: =+'Producto 3 Plano 27'!AE10 -> 4722450.7 | F13: =+E13*D13 -> 0
B14: =+B13 -> 2027 | C14: Junio | D14: =+'Producto 3 Plano 27'!AE11 -> 5344408.8 | F14: =+E14*D14 -> 0
B15: =+B14 -> 2027 | C15: Julio | D15: =+'Producto 3 Plano 27'!AE12 -> 4659277.7 | F15: =+E15*D15 -> 0
B16: =+B15 -> 2027 | C16: Agosto | D16: 0 | F16: =+E16*D16 -> 0
B17: =+B16 -> 2027 | C17: Septiembre | D17: 0 | F17: =+E17*D17 -> 0
B18: =+B17 -> 2027 | C18: Octubre | D18: 0 | F18: =+E18*D18 -> 0
B19: =+B18 -> 2027 | C19: Noviembre | D19: 0 | F19: =+E19*D19 -> 0
B20: =+B19 -> 2027 | C20: Diciembre | D20: 0 | F20: =+E20*D20 -> 0
B21: Total Producto 3 | D21: =+SUM(D9:D20) -> 47337166
B23: E. Solicitada = Energía solicitada por RUITOQUE para el producto.
B24: % E. Ofertado = Porcentaje de energía ofertado por el agente respecto a la E. Solicitada.
B25: E. Ofertada = Energía ofertada por el agente, producto de la E. Solicitada y el % E. Ofertado.
B26: $/kWh = Tarifa de la oferta para todas las horas del mes.
