Workbook

Sheet OF P1
C1: * La energia a ofertar debe ser expresada únicamente en kilovatio (kWh) redondeado a cero decimales
C4: OFERTA PRODUCTO 1
C5: MES | D5: ENERGIA SOLICITADA (KWh) | E5: % | F5: ENERGIA OFERTADA (KWh) | G5: PRECIO $/kWh
C6: 46388 | D6: =+VLOOKUP(C6,'CURVA P1'!$A$4:$AD$55,30,FALSE) -> 25304277 | E6: % | G6: $/kWh
C7: 46419 | D7: =+VLOOKUP(C7,'CURVA P1'!$A$4:$AD$55,30,FALSE) -> 28029704
C8: 46447 | D8: =+VLOOKUP(C8,'CURVA P1'!$A$4:$AD$55,30,FALSE) -> 25291862
C9: 46478 | D9: =+VLOOKUP(C9,'CURVA P1'!$A$4:$AD$55,30,FALSE) -> 27525548
C10: 46508 | D10: =+VLOOKUP(C10,'CURVA P1'!$A$4:$AD$55,30,FALSE) -> 13154393
C11: 46539 | D11: =+VLOOKUP(C11,'CURVA P1'!$A$4:$AD$55,30,FALSE) -> 17074122
C12: 46569 | D12: =+VLOOKUP(C12,'CURVA P1'!$A$4:$AD$55,30,FALSE) -> 17311574
C13: 46600 | D13: =+VLOOKUP(C13,'CURVA P1'!$A$4:$AD$55,30,FALSE) -> 15080035
C14: 46631 | D14: =+VLOOKUP(C14,'CURVA P1'!$A$4:$AD$55,30,FALSE) -> 18243088
C15: 46661 | D15: =+VLOOKUP(C15,'CURVA P1'!$A$4:$AD$55,30,FALSE) -> 15262944
C16: 46692 | D16: =+VLOOKUP(C16,'CURVA P1'!$A$4:$AD$55,30,FALSE) -> 16004038
C17: 46722 | D17: =+VLOOKUP(C17,'CURVA P1'!$A$4:$AD$55,30,FALSE) -> 27710319
D18: =SUM(D6:D17) -> 245991904

Sheet CURVA P1
A1: Curva de distribucion en kwh
A2: * La energia a ofertar debe ser expresada únicamente en kilovatio (kWh) redondeado a cero decimales
A4: TOTAL | C4: =+AD55 -> 245991904
A5: MES | B5: DÍA | C5: HORA 01 | D5: HORA 02 | E5: HORA 03 | F5: HORA 04 | G5: HORA 05 | H5: HORA 06 | I5: HORA 07 | J5: HORA 08 | K5: HORA 09 | L5: HORA 10 | M5: HORA 11 | N5: HORA 12 | O5: HORA 13 | P5: HORA 14 | Q5: HORA 15 | R5: HORA 16 | S5: HORA 17 | T5: HORA 18 | U5: HORA 19 | V5: HORA 20 | W5: HORA 21 | X5: HORA 22 | Y5: HORA 23 | Z5: HORA 24 | AA5: TOTAL DÍA | AB5: NUMERO DÍAS | AC5: TOTAL DÍA MES | AD5: TOTAL MES
A7: 46388 | B7: Hábil | C7: 37248 | D7: 35118 | E7: 32896 | F7: 31262 | G7: 30750 | H7: 31722 | I7: 32412 | J7: 28281 | K7: 30447 | L7: 31240 | M7: 32281 | N7: 32734 | O7: 29379 | P7: 36827 | Q7: 46494 | R7: 50740 | S7: 51409 | T7: 41632 | U7: 43396 | V7: 42080 | W7: 40696 | X7: 39109 | Y7: 36089 | Z7: 32035 | AA7: =SUM(C7:Z7) -> 876277 | AB7: 19 | AC7: =+AA7*AB7 -> 16649263 | AD7: =+SUM(AC7:AC10) -> 25304277
B8: Sábado | C8: 38710 | D8: 36183 | E8: 33656 | F8: 31822 | G8: 31041 | H8: 31349 | I8: 31480 | J8: 27052 | K8: 29594 | L8: 30506 | M8: 31160 | N8: 31056 | O8: 28964 | P8: 32947 | Q8: 39165 | R8: 42672 | S8: 43251 | T8: 37051 | U8: 40950 | V8: 40111 | W8: 38305 | X8: 36574 | Y8: 34391 | Z8: 31362 | AA8: =SUM(C8:Z8) -> 829352 | AB8: 5 | AC8: =+AA8*AB8 -> 4146760
B9: Domingo | C9: 37871 | D9: 35577 | E9: 33182 | F9: 31304 | G9: 30221 | H9: 29677 | I9: 28762 | J9: 20692 | K9: 19523 | L9: 18827 | M9: 17990 | N9: 17819 | O9: 18647 | P9: 22195 | Q9: 27165 | R9: 31111 | S9: 32943 | T9: 29254 | U9: 34005 | V9: 35178 | W9: 34996 | X9: 34318 | Y9: 32027 | Z9: 28444 | AA9: =SUM(C9:Z9) -> 681728 | AB9: 5 | AC9: =+AA9*AB9 -> 3408640
B10: Festivo | C10: 29468 | D10: 27973 | E10: 26944 | F10: 25745 | G10: 25165 | H10: 24639 | I10: 23131 | J10: 14721 | K10: 13287 | L10: 12548 | M10: 12382 | N10: 12189 | O10: 12871 | P10: 16743 | Q10: 21618 | R10: 25356 | S10: 26770 | T10: 25073 | U10: 30174 | V10: 30945 | W10: 30495 | X10: 29502 | Y10: 27422 | Z10: 24646 | AA10: =SUM(C10:Z10) -> 549807 | AB10: 2 | AC10: =+AA10*AB10 -> 1099614
A11: 46419 | B11: Hábil | C11: 43294 | D11: 40025 | E11: 37696 | F11: 36185 | G11: 36222 | H11: 39336 | I11: 41181 | J11: 37842 | K11: 40129 | L11: 40909 | M11: 42188 | N11: 41164 | O11: 35366 | P11: 45184 | Q11: 56077 | R11: 60514 | S11: 60806 | T11: 47984 | U11: 48803 | V11: 48340 | W11: 47291 | X11: 44982 | Y11: 40273 | Z11: 35135 | AA11: =SUM(C11:Z11) -> 1046926 | AB11: 20 | AC11: =+AA11*AB11 -> 20938520 | AD11: =+SUM(AC11:AC14) -> 28029704
B12: Sábado | C12: 41350 | D12: 38223 | E12: 35957 | F12: 34485 | G12: 33891 | H12: 34857 | I12: 36427 | J12: 33741 | K12: 36867 | L12: 38016 | M12: 38658 | N12: 38247 | O12: 35231 | P12: 38717 | Q12: 44762 | R12: 48320 | S12: 48632 | T12: 40250 | U12: 44069 | V12: 44367 | W12: 42510 | X12: 40505 | Y12: 37888 | Z12: 34485 | AA12: =SUM(C12:Z12) -> 940455 | AB12: 4 | AC12: =+AA12*AB12 -> 3761820
B13: Domingo | C13: 42881 | D13: 39574 | E13: 37218 | F13: 35283 | G13: 34290 | H13: 34020 | I13: 33687 | J13: 26521 | K13: 25675 | L13: 25515 | M13: 24991 | N13: 25163 | O13: 25840 | P13: 29171 | Q13: 34548 | R13: 39001 | S13: 41019 | T13: 35491 | U13: 40305 | V13: 42684 | W13: 42946 | X13: 42429 | Y13: 39312 | Z13: 34777 | AA13: =SUM(C13:Z13) -> 832341 | AB13: 4 | AC13: =+AA13*AB13 -> 3329364
B14: Festivo | C14: 0 | D14: 0 | E14: 0 | F14: 0 | G14: 0 | H14: 0 | I14: 0 | J14: 0 | K14: 0 | L14: 0 | M14: 0 | N14: 0 | O14: 0 | P14: 0 | Q14: 0 | R14: 0 | S14: 0 | T14: 0 | U14: 0 | V14: 0 | W14: 0 | X14: 0 | Y14: 0 | Z14: 0 | AA14: =SUM(C14:Z14) -> 0 | AB14: 0 | AC14: =+AA14*AB14 -> 0
A15: 46447 | B15: Hábil | C15: 37729 | D15: 34621 | E15: 32460 | F15: 30894 | G15: 30741 | H15: 32816 | I15: 33190 | J15: 29179 | K15: 30792 | L15: 31010 | M15: 31754 | N15: 31065 | O15: 26560 | P15: 35769 | Q15: 46061 | R15: 50253 | S15: 50950 | T15: 40177 | U15: 41222 | V15: 41105 | W15: 40703 | X15: 39329 | Y15: 35616 | Z15: 31174 | AA15: =SUM(C15:Z15) -> 865170 | AB15: 20 | AC15: =+AA15*AB15 -> 17303400 | AD15: =+SUM(AC15:AC18) -> 25291862
B16: Sábado | C16: 39316 | D16: 36116 | E16: 33761 | F16: 31847 | G16: 30935 | H16: 31051 | I16: 31522 | J16: 28107 | K16: 30316 | L16: 30890 | M16: 31428 | N16: 30676 | O16: 27774 | P16: 31654 | Q16: 37994 | R16: 41646 | S16: 42410 | T16: 35865 | U16: 39228 | V16: 39337 | W16: 38231 | X16: 37177 | Y16: 35563 | Z16: 32763 | AA16: =SUM(C16:Z16) -> 825607 | AB16: 4 | AC16: =+AA16*AB16 -> 3302428
B17: Domingo | C17: 39988 | D17: 36807 | E17: 34552 | F17: 32720 | G17: 31567 | H17: 30776 | I17: 29575 | J17: 21638 | K17: 20065 | L17: 18749 | M17: 17380 | N17: 17238 | O17: 18278 | P17: 22057 | Q17: 27518 | R17: 31786 | S17: 33826 | T17: 29626 | U17: 33937 | V17: 36445 | W17: 37159 | X17: 37096 | Y17: 34079 | Z17: 30171 | AA17: =SUM(C17:Z17) -> 703033 | AB17: 4 | AC17: =+AA17*AB17 -> 2812132
B18: Festivo | C18: 31268 | D18: 28072 | E18: 26059 | F18: 24682 | G18: 24119 | H18: 23847 | I18: 23876 | J18: 18128 | K18: 18088 | L18: 18261 | M18: 18869 | N18: 19308 | O18: 18659 | P18: 23077 | Q18: 27871 | R18: 30854 | S18: 31939 | T18: 27241 | U18: 32230 | V18: 34672 | W18: 34854 | X18: 33693 | Y18: 29639 | Z18: 25328 | AA18: =SUM(C18:Z18) -> 624634 | AB18: 3 | AC18: =+AA18*AB18 -> 1873902
A19: 46478 | B19: Hábil | C19: 39930 | D19: 36681 | E19: 34461 | F19: 32893 | G19: 32807 | H19: 34006 | I19: 35074 | J19: 32283 | K19: 35085 | L19: 35862 | M19: 37322 | N19: 37078 | O19: 31824 | P19: 41151 | Q19: 52186 | R19: 56141 | S19: 56206 | T19: 44555 | U19: 45580 | V19: 45013 | W19: 44359 | X19: 42704 | Y19: 38842 | Z19: 33987 | AA19: =SUM(C19:Z19) -> 956030 | AB19: 22 | AC19: =+AA19*AB19 -> 21032660 | AD19: =+SUM(AC19:AC22) -> 27525548
B20: Sábado | C20: 41098 | D20: 37921 | E20: 35570 | F20: 33645 | G20: 32914 | H20: 32142 | I20: 33307 | J20: 29923 | K20: 33068 | L20: 33959 | M20: 34859 | N20: 34676 | O20: 31955 | P20: 35807 | Q20: 41988 | R20: 45363 | S20: 45488 | T20: 38680 | U20: 41868 | V20: 40987 | W20: 39417 | X20: 37697 | Y20: 35515 | Z20: 32670 | AA20: =SUM(C20:Z20) -> 880517 | AB20: 4 | AC20: =+AA20*AB20 -> 3522068
B21: Domingo | C21: 41160 | D21: 37701 | E21: 35178 | F21: 33199 | G21: 32011 | H21: 30505 | I21: 29999 | J21: 22879 | K21: 21862 | L21: 20976 | M21: 20343 | N21: 20961 | O21: 21724 | P21: 25440 | Q21: 30949 | R21: 34963 | S21: 36616 | T21: 31819 | U21: 36241 | V21: 38034 | W21: 37577 | X21: 37328 | Y21: 34680 | Z21: 30560 | AA21: =SUM(C21:Z21) -> 742705 | AB21: 4 | AC21: =+AA21*AB21 -> 2970820
B22: Festivo | C22: 0 | D22: 0 | E22: 0 | F22: 0 | G22: 0 | H22: 0 | I22: 0 | J22: 0 | K22: 0 | L22: 0 | M22: 0 | N22: 0 | O22: 0 | P22: 0 | Q22: 0 | R22: 0 | S22: 0 | T22: 0 | U22: 0 | V22: 0 | W22: 0 | X22: 0 | Y22: 0 | Z22: 0 | AA22: =SUM(C22:Z22) -> 0 | AB22: 0 | AC22: =+AA22*AB22 -> 0
A23: 46508 | B23: Hábil | C23: 21976 | D23: 18820 | E23: 16436 | F23: 14753 | G23: 14291 | H23: 14117 | I23: 15292 | J23: 12834 | K23: 16021 | L23: 17078 | M23: 18363 | N23: 17868 | O23: 12718 | P23: 22287 | Q23: 33197 | R23: 36694 | S23: 36520 | T23: 24993 | U23: 24959 | V23: 24780 | W23: 24859 | X23: 23713 | Y23: 20177 | Z23: 15570 | AA23: =SUM(C23:Z23) -> 498316 | AB23: 19 | AC23: =+AA23*AB23 -> 9468004 | AD23: =+SUM(AC23:AC26) -> 13154393
B24: Sábado | C24: 23737 | D24: 20128 | E24: 17405 | F24: 15406 | G24: 14505 | H24: 12848 | I24: 14347 | J24: 11169 | K24: 14647 | L24: 16096 | M24: 17069 | N24: 16385 | O24: 13441 | P24: 17375 | Q24: 23311 | R24: 26158 | S24: 26115 | T24: 18052 | U24: 20800 | V24: 21149 | W24: 19815 | X24: 18665 | Y24: 16886 | Z24: 13872 | AA24: =SUM(C24:Z24) -> 429381 | AB24: 4 | AC24: =+AA24*AB24 -> 1717524
B25: Domingo | C25: 21790 | D25: 18786 | E25: 16414 | F25: 14468 | G25: 13193 | H25: 10673 | I25: 10893 | J25: 3758 | K25: 2568 | L25: 1691 | M25: 1301 | N25: 1064 | O25: 820 | P25: 4043 | Q25: 9822 | R25: 13605 | S25: 15366 | T25: 11078 | U25: 15143 | V25: 17073 | W25: 17657 | X25: 18116 | Y25: 16169 | Z25: 12579 | AA25: =SUM(C25:Z25) -> 268070 | AB25: 5 | AC25: =+AA25*AB25 -> 1340350
B26: Festivo | C26: 15097 | D26: 12124 | E26: 9974 | F26: 8359 | G26: 7592 | H26: 5786 | I26: 6513 | J26: 309 | K26: 83 | L26: 116 | M26: 453 | N26: 725 | O26: 429 | P26: 4580 | Q26: 10037 | R26: 13666 | S26: 14628 | T26: 9301 | U26: 13869 | V26: 16958 | W26: 17652 | X26: 17311 | Y26: 14133 | Z26: 9810 | AA26: =SUM(C26:Z26) -> 209505 | AB26: 3 | AC26: =+AA26*AB26 -> 628515
A27: 46539 | B27: Hábil | C27: 27060 | D27: 23746 | E27: 21220 | F27: 19521 | G27: 19040 | H27: 18615 | I27: 20641 | J27: 18786 | K27: 22131 | L27: 22982 | M27: 24200 | N27: 24079 | O27: 18361 | P27: 27477 | Q27: 37916 | R27: 41685 | S27: 41851 | T27: 29163 | U27: 29055 | V27: 29300 | W27: 28881 | X27: 27533 | Y27: 24177 | Z27: 19638 | AA27: =SUM(C27:Z27) -> 617058 | AB27: 21 | AC27: =+AA27*AB27 -> 12958218 | AD27: =+SUM(AC27:AC30) -> 17074122
B28: Sábado | C28: 27503 | D28: 24274 | E28: 21800 | F28: 19925 | G28: 19281 | H28: 17741 | I28: 19674 | J28: 17077 | K28: 20227 | L28: 21172 | M28: 21844 | N28: 21145 | O28: 17713 | P28: 20995 | Q28: 27901 | R28: 31690 | S28: 31872 | T28: 23714 | U28: 26110 | V28: 26218 | W28: 24814 | X28: 23324 | Y28: 21361 | Z28: 18536 | AA28: =SUM(C28:Z28) -> 545911 | AB28: 4 | AC28: =+AA28*AB28 -> 2183644
B29: Domingo | C29: 27197 | D29: 24216 | E29: 21879 | F29: 19918 | G29: 18790 | H29: 16322 | I29: 16422 | J29: 9476 | K29: 7706 | L29: 7365 | M29: 5898 | N29: 5599 | O29: 6108 | P29: 9512 | Q29: 14899 | R29: 18865 | S29: 21011 | T29: 15305 | U29: 19305 | V29: 22365 | W29: 22862 | X29: 23335 | Y29: 21707 | Z29: 18605 | AA29: =SUM(C29:Z29) -> 394667 | AB29: 4 | AC29: =+AA29*AB29 -> 1578668
B30: Festivo | C30: 21171 | D30: 18253 | E30: 16174 | F30: 14474 | G30: 13786 | H30: 11984 | I30: 12705 | J30: 7484 | K30: 8131 | L30: 8762 | M30: 9131 | N30: 8991 | O30: 8061 | P30: 11662 | Q30: 16754 | R30: 19759 | S30: 20396 | T30: 13809 | U30: 17510 | V30: 21344 | W30: 21227 | X30: 20564 | Y30: 17742 | Z30: 13718 | AA30: =SUM(C30:Z30) -> 353592 | AB30: 1 | AC30: =+AA30*AB30 -> 353592
A31: 46569 | B31: Hábil | C31: 27686 | D31: 24446 | E31: 22113 | F31: 20273 | G31: 19703 | H31: 19844 | I31: 21250 | J31: 18731 | K31: 21875 | L31: 22724 | M31: 23911 | N31: 22993 | O31: 17214 | P31: 26125 | Q31: 36418 | R31: 40162 | S31: 40022 | T31: 27964 | U31: 27539 | V31: 28628 | W31: 28693 | X31: 27646 | Y31: 24430 | Z31: 20066 | AA31: =SUM(C31:Z31) -> 610456 | AB31: 20 | AC31: =+AA31*AB31 -> 12209120 | AD31: =+SUM(AC31:AC34) -> 17311574
B32: Sábado | C32: 26572 | D32: 23568 | E32: 21383 | F32: 19632 | G32: 19030 | H32: 17834 | I32: 19068 | J32: 15978 | K32: 18691 | L32: 19623 | M32: 19913 | N32: 19769 | O32: 16771 | P32: 20672 | Q32: 27236 | R32: 30281 | S32: 30195 | T32: 21360 | U32: 24225 | V32: 26054 | W32: 24620 | X32: 23678 | Y32: 22409 | Z32: 20100 | AA32: =SUM(C32:Z32) -> 528662 | AB32: 5 | AC32: =+AA32*AB32 -> 2643310
B33: Domingo | C33: 29032 | D33: 25906 | E33: 23386 | F33: 21516 | G33: 20250 | H33: 18147 | I33: 17995 | J33: 9909 | K33: 8539 | L33: 7823 | M33: 6712 | N33: 6066 | O33: 6779 | P33: 10410 | Q33: 15361 | R33: 19635 | S33: 21420 | T33: 17278 | U33: 20694 | V33: 23871 | W33: 24432 | X33: 24689 | Y33: 22786 | Z33: 19604 | AA33: =SUM(C33:Z33) -> 422240 | AB33: 4 | AC33: =+AA33*AB33 -> 1688960
B34: Festivo | C34: 24649 | D34: 21567 | E34: 19184 | F34: 17666 | G34: 16856 | H34: 15399 | I34: 15566 | J34: 9488 | K34: 9257 | L34: 9036 | M34: 8709 | N34: 8114 | O34: 6975 | P34: 11244 | Q34: 16506 | R34: 20221 | S34: 21235 | T34: 14589 | U34: 18530 | V34: 22383 | W34: 22438 | X34: 21641 | Y34: 18842 | Z34: 14997 | AA34: =SUM(C34:Z34) -> 385092 | AB34: 2 | AC34: =+AA34*AB34 -> 770184
A35: 46600 | B35: Hábil | C35: 24587 | D35: 21217 | E35: 18704 | F35: 16771 | G35: 16104 | H35: 16122 | I35: 17088 | J35: 14713 | K35: 17524 | L35: 18891 | M35: 20138 | N35: 19704 | O35: 13986 | P35: 23837 | Q35: 34983 | R35: 38740 | S35: 38734 | T35: 25832 | U35: 25739 | V35: 26448 | W35: 26727 | X35: 26129 | Y35: 22703 | Z35: 18404 | AA35: =SUM(C35:Z35) -> 543825 | AB35: 21 | AC35: =+AA35*AB35 -> 11420325 | AD35: =+SUM(AC35:AC38) -> 15080035
B36: Sábado | C36: 28680 | D36: 25043 | E36: 22218 | F36: 19999 | G36: 18857 | H36: 17316 | I36: 18121 | J36: 15395 | K36: 18004 | L36: 19451 | M36: 19575 | N36: 19935 | O36: 16144 | P36: 20324 | Q36: 26679 | R36: 29783 | S36: 30157 | T36: 21235 | U36: 24409 | V36: 24770 | W36: 23324 | X36: 23168 | Y36: 21955 | Z36: 19442 | AA36: =SUM(C36:Z36) -> 523984 | AB36: 3 | AC36: =+AA36*AB36 -> 1571952
B37: Domingo | C37: 26487 | D37: 23139 | E37: 20453 | F37: 18336 | G37: 16724 | H37: 13935 | I37: 13131 | J37: 5949 | K37: 4194 | L37: 2538 | M37: 1934 | N37: 697 | O37: 1611 | P37: 6569 | Q37: 11522 | R37: 15680 | S37: 16219 | T37: 10892 | U37: 15364 | V37: 17550 | W37: 18226 | X37: 18916 | Y37: 17096 | Z37: 13828 | AA37: =SUM(C37:Z37) -> 310990 | AB37: 5 | AC37: =+AA37*AB37 -> 1554950
B38: Festivo | C38: 17062 | D38: 14477 | E38: 12324 | F38: 10918 | G38: 10205 | H38: 8921 | I38: 8666 | J38: 2442 | K38: 2344 | L38: 3092 | M38: 3372 | N38: 3770 | O38: 3406 | P38: 7476 | Q38: 12896 | R38: 16910 | S38: 17715 | T38: 10249 | U38: 15035 | V38: 18148 | W38: 18430 | X38: 19338 | Y38: 16919 | Z38: 12289 | AA38: =SUM(C38:Z38) -> 266404 | AB38: 2 | AC38: =+AA38*AB38 -> 532808
A39: 46631 | B39: Hábil | C39: 28765 | D39: 25060 | E39: 22307 | F39: 20172 | G39: 19383 | H39: 19316 | I39: 20600 | J39: 18614 | K39: 21712 | L39: 23259 | M39: 24797 | N39: 24420 | O39: 18967 | P39: 29332 | Q39: 40004 | R39: 43540 | S39: 42850 | T39: 30544 | U39: 31271 | V39: 30261 | W39: 30344 | X39: 29712 | Y39: 26374 | Z39: 21398 | AA39: =SUM(C39:Z39) -> 643002 | AB39: 22 | AC39: =+AA39*AB39 -> 14146044 | AD39: =+SUM(AC39:AC42) -> 18243088
B40: Sábado | C40: 29751 | D40: 26362 | E40: 23687 | F40: 21514 | G40: 20438 | H40: 18783 | I40: 20154 | J40: 18009 | K40: 21532 | L40: 22620 | M40: 23771 | N40: 23693 | O40: 20183 | P40: 24667 | Q40: 31357 | R40: 34444 | S40: 34164 | T40: 26414 | U40: 29932 | V40: 28589 | W40: 26721 | X40: 25622 | Y40: 23963 | Z40: 21413 | AA40: =SUM(C40:Z40) -> 597783 | AB40: 4 | AC40: =+AA40*AB40 -> 2391132
B41: Domingo | C41: 29045 | D41: 25838 | E41: 23390 | F41: 21408 | G41: 19958 | H41: 17936 | I41: 17714 | J41: 10297 | K41: 8512 | L41: 6903 | M41: 6644 | N41: 6871 | O41: 6668 | P41: 11120 | Q41: 17396 | R41: 21098 | S41: 22423 | T41: 17208 | U41: 21955 | V41: 23552 | W41: 24389 | X41: 24868 | Y41: 22579 | Z41: 18706 | AA41: =SUM(C41:Z41) -> 426478 | AB41: 4 | AC41: =+AA41*AB41 -> 1705912
B42: Festivo | C42: 0 | D42: 0 | E42: 0 | F42: 0 | G42: 0 | H42: 0 | I42: 0 | J42: 0 | K42: 0 | L42: 0 | M42: 0 | N42: 0 | O42: 0 | P42: 0 | Q42: 0 | R42: 0 | S42: 0 | T42: 0 | U42: 0 | V42: 0 | W42: 0 | X42: 0 | Y42: 0 | Z42: 0 | AA42: =SUM(C42:Z42) -> 0 | AB42: 0 | AC42: =+AA42*AB42 -> 0
...

Sheet OF P2
C1: * La energia a ofertar debe ser expresada únicamente en kilovatio (kWh) redondeado a cero decimales - PLANA
C4: OFERTA PRODUCTO 2
C5: MES | D5: ENERGIA SOLICITADA (KWh) | E5: % | F5: ENERGIA OFERTADA (KWh) | G5: PRECIO $/kWh
C6: 46388 | D6: =+VLOOKUP(C6,'PLANA P2'!$A$4:$AD$55,30,FALSE) -> 24552000 | E6: % | G6: $/kWh
C7: 46419 | D7: =+VLOOKUP(C7,'PLANA P2'!$A$4:$AD$55,30,FALSE) -> 22176000
C8: 46447 | D8: =+VLOOKUP(C8,'PLANA P2'!$A$4:$AD$55,30,FALSE) -> 24552000
C9: 46478 | D9: =+VLOOKUP(C9,'PLANA P2'!$A$4:$AD$55,30,FALSE) -> 23760000
C10: 46508 | D10: =+VLOOKUP(C10,'PLANA P2'!$A$4:$AD$55,30,FALSE) -> 24552000
C11: 46539 | D11: =+VLOOKUP(C11,'PLANA P2'!$A$4:$AD$55,30,FALSE) -> 23760000
C12: 46569 | D12: =+VLOOKUP(C12,'PLANA P2'!$A$4:$AD$55,30,FALSE) -> 24552000
C13: 46600 | D13: =+VLOOKUP(C13,'PLANA P2'!$A$4:$AD$55,30,FALSE) -> 24552000
C14: 46631 | D14: =+VLOOKUP(C14,'PLANA P2'!$A$4:$AD$55,30,FALSE) -> 23760000
C15: 46661 | D15: =+VLOOKUP(C15,'PLANA P2'!$A$4:$AD$55,30,FALSE) -> 24552000
C16: 46692 | D16: =+VLOOKUP(C16,'PLANA P2'!$A$4:$AD$55,30,FALSE) -> 23760000
C17: 46722 | D17: =+VLOOKUP(C17,'PLANA P2'!$A$4:$AD$55,30,FALSE) -> 24552000
D18: =SUM(D6:D17) -> 289080000

Sheet PLANA P2
A1: Curva de distribucion en kwh
A2: * La energia a ofertar debe ser expresada únicamente en kilovatio (kWh) redondeado a cero decimales
A4: TOTAL | C4: =+AD55 -> 289080000
A5: MES | B5: DÍA | C5: HORA 01 | D5: HORA 02 | E5: HORA 03 | F5: HORA 04 | G5: HORA 05 | H5: HORA 06 | I5: HORA 07 | J5: HORA 08 | K5: HORA 09 | L5: HORA 10 | M5: HORA 11 | N5: HORA 12 | O5: HORA 13 | P5: HORA 14 | Q5: HORA 15 | R5: HORA 16 | S5: HORA 17 | T5: HORA 18 | U5: HORA 19 | V5: HORA 20 | W5: HORA 21 | X5: HORA 22 | Y5: HORA 23 | Z5: HORA 24 | AA5: TOTAL DÍA | AB5: NUMERO DÍAS | AC5: TOTAL DÍA MES | AD5: TOTAL MES
A7: 46388 | B7: Hábil | C7: 33000 | D7: 33000 | E7: 33000 | F7: 33000 | G7: 33000 | H7: 33000 | I7: 33000 | J7: 33000 | K7: 33000 | L7: 33000 | M7: 33000 | N7: 33000 | O7: 33000 | P7: 33000 | Q7: 33000 | R7: 33000 | S7: 33000 | T7: 33000 | U7: 33000 | V7: 33000 | W7: 33000 | X7: 33000 | Y7: 33000 | Z7: 33000 | AA7: =SUM(C7:Z7) -> 792000 | AB7: 19 | AC7: =+AA7*AB7 -> 15048000 | AD7: =+SUM(AC7:AC10) -> 24552000
B8: Sábado | C8: 33000 | D8: 33000 | E8: 33000 | F8: 33000 | G8: 33000 | H8: 33000 | I8: 33000 | J8: 33000 | K8: 33000 | L8: 33000 | M8: 33000 | N8: 33000 | O8: 33000 | P8: 33000 | Q8: 33000 | R8: 33000 | S8: 33000 | T8: 33000 | U8: 33000 | V8: 33000 | W8: 33000 | X8: 33000 | Y8: 33000 | Z8: 33000 | AA8: =SUM(C8:Z8) -> 792000 | AB8: 5 | AC8: =+AA8*AB8 -> 3960000
B9: Domingo | C9: 33000 | D9: 33000 | E9: 33000 | F9: 33000 | G9: 33000 | H9: 33000 | I9: 33000 | J9: 33000 | K9: 33000 | L9: 33000 | M9: 33000 | N9: 33000 | O9: 33000 | P9: 33000 | Q9: 33000 | R9: 33000 | S9: 33000 | T9: 33000 | U9: 33000 | V9: 33000 | W9: 33000 | X9: 33000 | Y9: 33000 | Z9: 33000 | AA9: =SUM(C9:Z9) -> 792000 | AB9: 5 | AC9: =+AA9*AB9 -> 3960000
B10: Festivo | C10: 33000 | D10: 33000 | E10: 33000 | F10: 33000 | G10: 33000 | H10: 33000 | I10: 33000 | J10: 33000 | K10: 33000 | L10: 33000 | M10: 33000 | N10: 33000 | O10: 33000 | P10: 33000 | Q10: 33000 | R10: 33000 | S10: 33000 | T10: 33000 | U10: 33000 | V10: 33000 | W10: 33000 | X10: 33000 | Y10: 33000 | Z10: 33000 | AA10: =SUM(C10:Z10) -> 792000 | AB10: 2 | AC10: =+AA10*AB10 -> 1584000
A11: 46419 | B11: Hábil | C11: 33000 | D11: 33000 | E11: 33000 | F11: 33000 | G11: 33000 | H11: 33000 | I11: 33000 | J11: 33000 | K11: 33000 | L11: 33000 | M11: 33000 | N11: 33000 | O11: 33000 | P11: 33000 | Q11: 33000 | R11: 33000 | S11: 33000 | T11: 33000 | U11: 33000 | V11: 33000 | W11: 33000 | X11: 33000 | Y11: 33000 | Z11: 33000 | AA11: =SUM(C11:Z11) -> 792000 | AB11: 20 | AC11: =+AA11*AB11 -> 15840000 | AD11: =+SUM(AC11:AC14) -> 22176000
B12: Sábado | C12: 33000 | D12: 33000 | E12: 33000 | F12: 33000 | G12: 33000 | H12: 33000 | I12: 33000 | J12: 33000 | K12: 33000 | L12: 33000 | M12: 33000 | N12: 33000 | O12: 33000 | P12: 33000 | Q12: 33000 | R12: 33000 | S12: 33000 | T12: 33000 | U12: 33000 | V12: 33000 | W12: 33000 | X12: 33000 | Y12: 33000 | Z12: 33000 | AA12: =SUM(C12:Z12) -> 792000 | AB12: 4 | AC12: =+AA12*AB12 -> 3168000
B13: Domingo | C13: 33000 | D13: 33000 | E13: 33000 | F13: 33000 | G13: 33000 | H13: 33000 | I13: 33000 | J13: 33000 | K13: 33000 | L13: 33000 | M13: 33000 | N13: 33000 | O13: 33000 | P13: 33000 | Q13: 33000 | R13: 33000 | S13: 33000 | T13: 33000 | U13: 33000 | V13: 33000 | W13: 33000 | X13: 33000 | Y13: 33000 | Z13: 33000 | AA13: =SUM(C13:Z13) -> 792000 | AB13: 4 | AC13: =+AA13*AB13 -> 3168000
B14: Festivo | C14: 0 | D14: 0 | E14: 0 | F14: 0 | G14: 0 | H14: 0 | I14: 0 | J14: 0 | K14: 0 | L14: 0 | M14: 0 | N14: 0 | O14: 0 | P14: 0 | Q14: 0 | R14: 0 | S14: 0 | T14: 0 | U14: 0 | V14: 0 | W14: 0 | X14: 0 | Y14: 0 | Z14: 0 | AA14: =SUM(C14:Z14) -> 0 | AB14: 0 | AC14: =+AA14*AB14 -> 0
A15: 46447 | B15: Hábil | C15: 33000 | D15: 33000 | E15: 33000 | F15: 33000 | G15: 33000 | H15: 33000 | I15: 33000 | J15: 33000 | K15: 33000 | L15: 33000 | M15: 33000 | N15: 33000 | O15: 33000 | P15: 33000 | Q15: 33000 | R15: 33000 | S15: 33000 | T15: 33000 | U15: 33000 | V15: 33000 | W15: 33000 | X15: 33000 | Y15: 33000 | Z15: 33000 | AA15: =SUM(C15:Z15) -> 792000 | AB15: 20 | AC15: =+AA15*AB15 -> 15840000 | AD15: =+SUM(AC15:AC18) -> 24552000
B16: Sábado | C16: 33000 | D16: 33000 | E16: 33000 | F16: 33000 | G16: 33000 | H16: 33000 | I16: 33000 | J16: 33000 | K16: 33000 | L16: 33000 | M16: 33000 | N16: 33000 | O16: 33000 | P16: 33000 | Q16: 33000 | R16: 33000 | S16: 33000 | T16: 33000 | U16: 33000 | V16: 33000 | W16: 33000 | X16: 33000 | Y16: 33000 | Z16: 33000 | AA16: =SUM(C16:Z16) -> 792000 | AB16: 4 | AC16: =+AA16*AB16 -> 3168000
B17: Domingo | C17: 33000 | D17: 33000 | E17: 33000 | F17: 33000 | G17: 33000 | H17: 33000 | I17: 33000 | J17: 33000 | K17: 33000 | L17: 33000 | M17: 33000 | N17: 33000 | O17: 33000 | P17: 33000 | Q17: 33000 | R17: 33000 | S17: 33000 | T17: 33000 | U17: 33000 | V17: 33000 | W17: 33000 | X17: 33000 | Y17: 33000 | Z17: 33000 | AA17: =SUM(C17:Z17) -> 792000 | AB17: 4 | AC17: =+AA17*AB17 -> 3168000
B18: Festivo | C18: 33000 | D18: 33000 | E18: 33000 | F18: 33000 | G18: 33000 | H18: 33000 | I18: 33000 | J18: 33000 | K18: 33000 | L18: 33000 | M18: 33000 | N18: 33000 | O18: 33000 | P18: 33000 | Q18: 33000 | R18: 33000 | S18: 33000 | T18: 33000 | U18: 33000 | V18: 33000 | W18: 33000 | X18: 33000 | Y18: 33000 | Z18: 33000 | AA18: =SUM(C18:Z18) -> 792000 | AB18: 3 | AC18: =+AA18*AB18 -> 2376000
A19: 46478 | B19: Hábil | C19: 33000 | D19: 33000 | E19: 33000 | F19: 33000 | G19: 33000 | H19: 33000 | I19: 33000 | J19: 33000 | K19: 33000 | L19: 33000 | M19: 33000 | N19: 33000 | O19: 33000 | P19: 33000 | Q19: 33000 | R19: 33000 | S19: 33000 | T19: 33000 | U19: 33000 | V19: 33000 | W19: 33000 | X19: 33000 | Y19: 33000 | Z19: 33000 | AA19: =SUM(C19:Z19) -> 792000 | AB19: 22 | AC19: =+AA19*AB19 -> 17424000 | AD19: =+SUM(AC19:AC22) -> 23760000
B20: Sábado | C20: 33000 | D20: 33000 | E20: 33000 | F20: 33000 | G20: 33000 | H20: 33000 | I20: 33000 | J20: 33000 | K20: 33000 | L20: 33000 | M20: 33000 | N20: 33000 | O20: 33000 | P20: 33000 | Q20: 33000 | R20: 33000 | S20: 33000 | T20: 33000 | U20: 33000 | V20: 33000 | W20: 33000 | X20: 33000 | Y20: 33000 | Z20: 33000 | AA20: =SUM(C20:Z20) -> 792000 | AB20: 4 | AC20: =+AA20*AB20 -> 3168000
B21: Domingo | C21: 33000 | D21: 33000 | E21: 33000 | F21: 33000 | G21: 33000 | H21: 33000 | I21: 33000 | J21: 33000 | K21: 33000 | L21: 33000 | M21: 33000 | N21: 33000 | O21: 33000 | P21: 33000 | Q21: 33000 | R21: 33000 | S21: 33000 | T21: 33000 | U21: 33000 | V21: 33000 | W21: 33000 | X21: 33000 | Y21: 33000 | Z21: 33000 | AA21: =SUM(C21:Z21) -> 792000 | AB21: 4 | AC21: =+AA21*AB21 -> 3168000
B22: Festivo | C22: 0 | D22: 0 | E22: 0 | F22: 0 | G22: 0 | H22: 0 | I22: 0 | J22: 0 | K22: 0 | L22: 0 | M22: 0 | N22: 0 | O22: 0 | P22: 0 | Q22: 0 | R22: 0 | S22: 0 | T22: 0 | U22: 0 | V22: 0 | W22: 0 | X22: 0 | Y22: 0 | Z22: 0 | AA22: =SUM(C22:Z22) -> 0 | AB22: 0 | AC22: =+AA22*AB22 -> 0
A23: 46508 | B23: Hábil | C23: 33000 | D23: 33000 | E23: 33000 | F23: 33000 | G23: 33000 | H23: 33000 | I23: 33000 | J23: 33000 | K23: 33000 | L23: 33000 | M23: 33000 | N23: 33000 | O23: 33000 | P23: 33000 | Q23: 33000 | R23: 33000 | S23: 33000 | T23: 33000 | U23: 33000 | V23: 33000 | W23: 33000 | X23: 33000 | Y23: 33000 | Z23: 33000 | AA23: =SUM(C23:Z23) -> 792000 | AB23: 19 | AC23: =+AA23*AB23 -> 15048000 | AD23: =+SUM(AC23:AC26) -> 24552000
B24: Sábado | C24: 33000 | D24: 33000 | E24: 33000 | F24: 33000 | G24: 33000 | H24: 33000 | I24: 33000 | J24: 33000 | K24: 33000 | L24: 33000 | M24: 33000 | N24: 33000 | O24: 33000 | P24: 33000 | Q24: 33000 | R24: 33000 | S24: 33000 | T24: 33000 | U24: 33000 | V24: 33000 | W24: 33000 | X24: 33000 | Y24: 33000 | Z24: 33000 | AA24: =SUM(C24:Z24) -> 792000 | AB24: 4 | AC24: =+AA24*AB24 -> 3168000
B25: Domingo | C25: 33000 | D25: 33000 | E25: 33000 | F25: 33000 | G25: 33000 | H25: 33000 | I25: 33000 | J25: 33000 | K25: 33000 | L25: 33000 | M25: 33000 | N25: 33000 | O25: 33000 | P25: 33000 | Q25: 33000 | R25: 33000 | S25: 33000 | T25: 33000 | U25: 33000 | V25: 33000 | W25: 33000 | X25: 33000 | Y25: 33000 | Z25: 33000 | AA25: =SUM(C25:Z25) -> 792000 | AB25: 5 | AC25: =+AA25*AB25 -> 3960000
B26: Festivo | C26: 33000 | D26: 33000 | E26: 33000 | F26: 33000 | G26: 33000 | H26: 33000 | I26: 33000 | J26: 33000 | K26: 33000 | L26: 33000 | M26: 33000 | N26: 33000 | O26: 33000 | P26: 33000 | Q26: 33000 | R26: 33000 | S26: 33000 | T26: 33000 | U26: 33000 | V26: 33000 | W26: 33000 | X26: 33000 | Y26: 33000 | Z26: 33000 | AA26: =SUM(C26:Z26) -> 792000 | AB26: 3 | AC26: =+AA26*AB26 -> 2376000
A27: 46539 | B27: Hábil | C27: 33000 | D27: 33000 | E27: 33000 | F27: 33000 | G27: 33000 | H27: 33000 | I27: 33000 | J27: 33000 | K27: 33000 | L27: 33000 | M27: 33000 | N27: 33000 | O27: 33000 | P27: 33000 | Q27: 33000 | R27: 33000 | S27: 33000 | T27: 33000 | U27: 33000 | V27: 33000 | W27: 33000 | X27: 33000 | Y27: 33000 | Z27: 33000 | AA27: =SUM(C27:Z27) -> 792000 | AB27: 21 | AC27: =+AA27*AB27 -> 16632000 | AD27: =+SUM(AC27:AC30) -> 23760000
B28: Sábado | C28: 33000 | D28: 33000 | E28: 33000 | F28: 33000 | G28: 33000 | H28: 33000 | I28: 33000 | J28: 33000 | K28: 33000 | L28: 33000 | M28: 33000 | N28: 33000 | O28: 33000 | P28: 33000 | Q28: 33000 | R28: 33000 | S28: 33000 | T28: 33000 | U28: 33000 | V28: 33000 | W28: 33000 | X28: 33000 | Y28: 33000 | Z28: 33000 | AA28: =SUM(C28:Z28) -> 792000 | AB28: 4 | AC28: =+AA28*AB28 -> 3168000
B29: Domingo | C29: 33000 | D29: 33000 | E29: 33000 | F29: 33000 | G29: 33000 | H29: 33000 | I29: 33000 | J29: 33000 | K29: 33000 | L29: 33000 | M29: 33000 | N29: 33000 | O29: 33000 | P29: 33000 | Q29: 33000 | R29: 33000 | S29: 33000 | T29: 33000 | U29: 33000 | V29: 33000 | W29: 33000 | X29: 33000 | Y29: 33000 | Z29: 33000 | AA29: =SUM(C29:Z29) -> 792000 | AB29: 4 | AC29: =+AA29*AB29 -> 3168000
B30: Festivo | C30: 33000 | D30: 33000 | E30: 33000 | F30: 33000 | G30: 33000 | H30: 33000 | I30: 33000 | J30: 33000 | K30: 33000 | L30: 33000 | M30: 33000 | N30: 33000 | O30: 33000 | P30: 33000 | Q30: 33000 | R30: 33000 | S30: 33000 | T30: 33000 | U30: 33000 | V30: 33000 | W30: 33000 | X30: 33000 | Y30: 33000 | Z30: 33000 | AA30: =SUM(C30:Z30) -> 792000 | AB30: 1 | AC30: =+AA30*AB30 -> 792000
A31: 46569 | B31: Hábil | C31: 33000 | D31: 33000 | E31: 33000 | F31: 33000 | G31: 33000 | H31: 33000 | I31: 33000 | J31: 33000 | K31: 33000 | L31: 33000 | M31: 33000 | N31: 33000 | O31: 33000 | P31: 33000 | Q31: 33000 | R31: 33000 | S31: 33000 | T31: 33000 | U31: 33000 | V31: 33000 | W31: 33000 | X31: 33000 | Y31: 33000 | Z31: 33000 | AA31: =SUM(C31:Z31) -> 792000 | AB31: 20 | AC31: =+AA31*AB31 -> 15840000 | AD31: =+SUM(AC31:AC34) -> 24552000
B32: Sábado | C32: 33000 | D32: 33000 | E32: 33000 | F32: 33000 | G32: 33000 | H32: 33000 | I32: 33000 | J32: 33000 | K32: 33000 | L32: 33000 | M32: 33000 | N32: 33000 | O32: 33000 | P32: 33000 | Q32: 33000 | R32: 33000 | S32: 33000 | T32: 33000 | U32: 33000 | V32: 33000 | W32: 33000 | X32: 33000 | Y32: 33000 | Z32: 33000 | AA32: =SUM(C32:Z32) -> 792000 | AB32: 5 | AC32: =+AA32*AB32 -> 3960000
B33: Domingo | C33: 33000 | D33: 33000 | E33: 33000 | F33: 33000 | G33: 33000 | H33: 33000 | I33: 33000 | J33: 33000 | K33: 33000 | L33: 33000 | M33: 33000 | N33: 33000 | O33: 33000 | P33: 33000 | Q33: 33000 | R33: 33000 | S33: 33000 | T33: 33000 | U33: 33000 | V33: 33000 | W33: 33000 | X33: 33000 | Y33: 33000 | Z33: 33000 | AA33: =SUM(C33:Z33) -> 792000 | AB33: 4 | AC33: =+AA33*AB33 -> 3168000
B34: Festivo | C34: 33000 | D34: 33000 | E34: 33000 | F34: 33000 | G34: 33000 | H34: 33000 | I34: 33000 | J34: 33000 | K34: 33000 | L34: 33000 | M34: 33000 | N34: 33000 | O34: 33000 | P34: 33000 | Q34: 33000 | R34: 33000 | S34: 33000 | T34: 33000 | U34: 33000 | V34: 33000 | W34: 33000 | X34: 33000 | Y34: 33000 | Z34: 33000 | AA34: =SUM(C34:Z34) -> 792000 | AB34: 2 | AC34: =+AA34*AB34 -> 1584000
A35: 46600 | B35: Hábil | C35: 33000 | D35: 33000 | E35: 33000 | F35: 33000 | G35: 33000 | H35: 33000 | I35: 33000 | J35: 33000 | K35: 33000 | L35: 33000 | M35: 33000 | N35: 33000 | O35: 33000 | P35: 33000 | Q35: 33000 | R35: 33000 | S35: 33000 | T35: 33000 | U35: 33000 | V35: 33000 | W35: 33000 | X35: 33000 | Y35: 33000 | Z35: 33000 | AA35: =SUM(C35:Z35) -> 792000 | AB35: 21 | AC35: =+AA35*AB35 -> 16632000 | AD35: =+SUM(AC35:AC38) -> 24552000
B36: Sábado | C36: 33000 | D36: 33000 | E36: 33000 | F36: 33000 | G36: 33000 | H36: 33000 | I36: 33000 | J36: 33000 | K36: 33000 | L36: 33000 | M36: 33000 | N36: 33000 | O36: 33000 | P36: 33000 | Q36: 33000 | R36: 33000 | S36: 33000 | T36: 33000 | U36: 33000 | V36: 33000 | W36: 33000 | X36: 33000 | Y36: 33000 | Z36: 33000 | AA36: =SUM(C36:Z36) -> 792000 | AB36: 3 | AC36: =+AA36*AB36 -> 2376000
B37: Domingo | C37: 33000 | D37: 33000 | E37: 33000 | F37: 33000 | G37: 33000 | H37: 33000 | I37: 33000 | J37: 33000 | K37: 33000 | L37: 33000 | M37: 33000 | N37: 33000 | O37: 33000 | P37: 33000 | Q37: 33000 | R37: 33000 | S37: 33000 | T37: 33000 | U37: 33000 | V37: 33000 | W37: 33000 | X37: 33000 | Y37: 33000 | Z37: 33000 | AA37: =SUM(C37:Z37) -> 792000 | AB37: 5 | AC37: =+AA37*AB37 -> 3960000
B38: Festivo | C38: 33000 | D38: 33000 | E38: 33000 | F38: 33000 | G38: 33000 | H38: 33000 | I38: 33000 | J38: 33000 | K38: 33000 | L38: 33000 | M38: 33000 | N38: 33000 | O38: 33000 | P38: 33000 | Q38: 33000 | R38: 33000 | S38: 33000 | T38: 33000 | U38: 33000 | V38: 33000 | W38: 33000 | X38: 33000 | Y38: 33000 | Z38: 33000 | AA38: =SUM(C38:Z38) -> 792000 | AB38: 2 | AC38: =+AA38*AB38 -> 1584000
A39: 46631 | B39: Hábil | C39: 33000 | D39: 33000 | E39: 33000 | F39: 33000 | G39: 33000 | H39: 33000 | I39: 33000 | J39: 33000 | K39: 33000 | L39: 33000 | M39: 33000 | N39: 33000 | O39: 33000 | P39: 33000 | Q39: 33000 | R39: 33000 | S39: 33000 | T39: 33000 | U39: 33000 | V39: 33000 | W39: 33000 | X39: 33000 | Y39: 33000 | Z39: 33000 | AA39: =SUM(C39:Z39) -> 792000 | AB39: 22 | AC39: =+AA39*AB39 -> 17424000 | AD39: =+SUM(AC39:AC42) -> 23760000
B40: Sábado | C40: 33000 | D40: 33000 | E40: 33000 | F40: 33000 | G40: 33000 | H40: 33000 | I40: 33000 | J40: 33000 | K40: 33000 | L40: 33000 | M40: 33000 | N40: 33000 | O40: 33000 | P40: 33000 | Q40: 33000 | R40: 33000 | S40: 33000 | T40: 33000 | U40: 33000 | V40: 33000 | W40: 33000 | X40: 33000 | Y40: 33000 | Z40: 33000 | AA40: =SUM(C40:Z40) -> 792000 | AB40: 4 | AC40: =+AA40*AB40 -> 3168000
B41: Domingo | C41: 33000 | D41: 33000 | E41: 33000 | F41: 33000 | G41: 33000 | H41: 33000 | I41: 33000 | J41: 33000 | K41: 33000 | L41: 33000 | M41: 33000 | N41: 33000 | O41: 33000 | P41: 33000 | Q41: 33000 | R41: 33000 | S41: 33000 | T41: 33000 | U41: 33000 | V41: 33000 | W41: 33000 | X41: 33000 | Y41: 33000 | Z41: 33000 | AA41: =SUM(C41:Z41) -> 792000 | AB41: 4 | AC41: =+AA41*AB41 -> 3168000
B42: Festivo | C42: 0 | D42: 0 | E42: 0 | F42: 0 | G42: 0 | H42: 0 | I42: 0 | J42: 0 | K42: 0 | L42: 0 | M42: 0 | N42: 0 | O42: 0 | P42: 0 | Q42: 0 | R42: 0 | S42: 0 | T42: 0 | U42: 0 | V42: 0 | W42: 0 | X42: 0 | Y42: 0 | Z42: 0 | AA42: =SUM(C42:Z42) -> 0 | AB42: 0 | AC42: =+AA42*AB42 -> 0
...

Sheet OF P3
C1: * La energia a ofertar debe ser expresada únicamente en kilovatio (kWh) redondeado a cero decimales
C4: OFERTA PRODUCTO 3
C5: MES | D5: ENERGIA SOLICITADA (KWh) | E5: % | F5: ENERGIA OFERTADA (KWh) | G5: PRECIO $/kWh
C6: 47119 | D6: =+VLOOKUP(C6,'CURVA P3'!$A$4:$AD$55,30,FALSE) -> 34681994 | E6: % | G6: $/kWh
C7: 47150 | D7: =+VLOOKUP(C7,'CURVA P3'!$A$4:$AD$55,30,FALSE) -> 37564556
C8: 47178 | D8: =+VLOOKUP(C8,'CURVA P3'!$A$4:$AD$55,30,FALSE) -> 34606811
C9: 47209 | D9: =+VLOOKUP(C9,'CURVA P3'!$A$4:$AD$55,30,FALSE) -> 36860395
C10: 47239 | D10: =+VLOOKUP(C10,'CURVA P3'!$A$4:$AD$55,30,FALSE) -> 37145955
C11: 47270 | D11: =+VLOOKUP(C11,'CURVA P3'!$A$4:$AD$55,30,FALSE) -> 38564385
C12: 47300 | D12: =+VLOOKUP(C12,'CURVA P3'!$A$4:$AD$55,30,FALSE) -> 36644330
C13: 47331 | D13: =+VLOOKUP(C13,'CURVA P3'!$A$4:$AD$55,30,FALSE) -> 38267878
C14: 47362 | D14: =+VLOOKUP(C14,'CURVA P3'!$A$4:$AD$55,30,FALSE) -> 40109230
C15: 47392 | D15: =+VLOOKUP(C15,'CURVA P3'!$A$4:$AD$55,30,FALSE) -> 39254580
C16: 47423 | D16: =+VLOOKUP(C16,'CURVA P3'!$A$4:$AD$55,30,FALSE) -> 38870616
C17: 47453 | D17: =+VLOOKUP(C17,'CURVA P3'!$A$4:$AD$55,30,FALSE) -> 37280033
D18: =SUM(D6:D17) -> 449850763

Sheet CURVA P3
A1: Curva de distribucion en kwh
A2: * La energia a ofertar debe ser expresada únicamente en kilovatio (kWh) redondeado a cero decimales
A4: TOTAL | C4: =+AD55 -> 449850763
A5: MES | B5: DÍA | C5: HORA 01 | D5: HORA 02 | E5: HORA 03 | F5: HORA 04 | G5: HORA 05 | H5: HORA 06 | I5: HORA 07 | J5: HORA 08 | K5: HORA 09 | L5: HORA 10 | M5: HORA 11 | N5: HORA 12 | O5: HORA 13 | P5: HORA 14 | Q5: HORA 15 | R5: HORA 16 | S5: HORA 17 | T5: HORA 18 | U5: HORA 19 | V5: HORA 20 | W5: HORA 21 | X5: HORA 22 | Y5: HORA 23 | Z5: HORA 24 | AA5: TOTAL DÍA | AB5: NUMERO DÍAS | AC5: TOTAL DÍA MES | AD5: TOTAL MES
A7: 47119 | B7: Hábil | C7: 50734 | D7: 47502 | E7: 44893 | F7: 42973 | G7: 42369 | H7: 43525 | I7: 43877 | J7: 34803 | K7: 30488 | L7: 28809 | M7: 29156 | N7: 27931 | O7: 25350 | P7: 36515 | Q7: 53473 | R7: 65353 | S7: 70043 | T7: 68850 | U7: 71947 | V7: 70846 | W7: 69418 | X7: 67127 | Y7: 62458 | Z7: 56260 | AA7: =SUM(C7:Z7) -> 1184700 | AB7: 21 | AC7: =+AA7*AB7 -> 24878700 | AD7: =+SUM(AC7:AC10) -> 34681994
B8: Sábado | C8: 52409 | D8: 48832 | E8: 45926 | F8: 43784 | G8: 42911 | H8: 43290 | I8: 42906 | J8: 32987 | K8: 28664 | L8: 26873 | M8: 26568 | N8: 24777 | O8: 24000 | P8: 30955 | Q8: 43585 | R8: 54468 | S8: 59197 | T8: 61835 | U8: 68285 | V8: 67868 | W8: 65544 | X8: 63208 | Y8: 59983 | Z8: 55559 | AA8: =SUM(C8:Z8) -> 1114414 | AB8: 4 | AC8: =+AA8*AB8 -> 4457656
B9: Domingo | C9: 51565 | D9: 48222 | E9: 45398 | F9: 43172 | G9: 41903 | H9: 41277 | I9: 39644 | J9: 25647 | K9: 16706 | L9: 13145 | M9: 10996 | N9: 9065 | O9: 11717 | P9: 18098 | Q9: 29418 | R9: 41038 | S9: 47340 | T9: 52632 | U9: 60366 | V9: 62538 | W9: 62268 | X9: 61150 | Y9: 57537 | Z9: 52408 | AA9: =SUM(C9:Z9) -> 943250 | AB9: 4 | AC9: =+AA9*AB9 -> 3773000
B10: Festivo | C10: 41719 | D10: 40098 | E10: 38671 | F10: 37217 | G10: 36468 | H10: 35829 | I10: 33583 | J10: 18968 | K10: 9365 | L10: 5768 | M10: 4228 | N10: 2293 | O10: 5050 | P10: 11785 | Q10: 22839 | R10: 34112 | S10: 39906 | T10: 47180 | U10: 55548 | V10: 57080 | W10: 56207 | X10: 54390 | Y10: 51102 | Z10: 46913 | AA10: =SUM(C10:Z10) -> 786319 | AB10: 2 | AC10: =+AA10*AB10 -> 1572638
A11: 47150 | B11: Hábil | C11: 58326 | D11: 54371 | E11: 51584 | F11: 49711 | G11: 49640 | H11: 52884 | I11: 54401 | J11: 45983 | K11: 41099 | L11: 39048 | M11: 39454 | N11: 36545 | O11: 31369 | P11: 45498 | Q11: 64686 | R11: 77595 | S11: 82370 | T11: 78349 | U11: 79944 | V11: 79795 | W11: 78550 | X11: 75784 | Y11: 69794 | Z11: 62451 | AA11: =SUM(C11:Z11) -> 1399231 | AB11: 20 | AC11: =+AA11*AB11 -> 27984620 | AD11: =+SUM(AC11:AC14) -> 37564556
B12: Sábado | C12: 56427 | D12: 52634 | E12: 49937 | F12: 48081 | G12: 47460 | H12: 48509 | I12: 49614 | J12: 41370 | K12: 37511 | L12: 35673 | M12: 35308 | N12: 32883 | O12: 30567 | P12: 37301 | Q12: 50934 | R12: 62618 | S12: 67504 | T12: 68213 | U12: 73987 | V12: 74615 | W12: 72208 | X12: 69616 | Y12: 66238 | Z12: 61411 | AA12: =SUM(C12:Z12) -> 1270619 | AB12: 4 | AC12: =+AA12*AB12 -> 5082476
B13: Domingo | C13: 57952 | D13: 53917 | E13: 51108 | F13: 48856 | G13: 47601 | H13: 47219 | I13: 46156 | J13: 32827 | K13: 23322 | L13: 19914 | M13: 18025 | N13: 16245 | O13: 19029 | P13: 25458 | Q13: 37791 | R13: 50518 | S13: 57445 | T13: 60702 | U13: 67855 | V13: 71585 | W13: 72096 | X13: 71420 | Y13: 66850 | Z13: 60474 | AA13: =SUM(C13:Z13) -> 1124365 | AB13: 4 | AC13: =+AA13*AB13 -> 4497460
B14: Festivo | C14: 0 | D14: 0 | E14: 0 | F14: 0 | G14: 0 | H14: 0 | I14: 0 | J14: 0 | K14: 0 | L14: 0 | M14: 0 | N14: 0 | O14: 0 | P14: 0 | Q14: 0 | R14: 0 | S14: 0 | T14: 0 | U14: 0 | V14: 0 | W14: 0 | X14: 0 | Y14: 0 | Z14: 0 | AA14: =SUM(C14:Z14) -> 0 | AB14: 0 | AC14: =+AA14*AB14 -> 0
A15: 47178 | B15: Hábil | C15: 51101 | D15: 47388 | E15: 44817 | F15: 42960 | G15: 42754 | H15: 44893 | I15: 45199 | J15: 36499 | K15: 31631 | L15: 29188 | M15: 29105 | N15: 26682 | O15: 22748 | P15: 35665 | Q15: 53291 | R15: 65130 | S15: 70051 | T15: 67983 | U15: 70086 | V15: 69973 | W15: 69018 | X15: 66862 | Y15: 61977 | Z15: 55582 | AA15: =SUM(C15:Z15) -> 1180583 | AB15: 19 | AC15: =+AA15*AB15 -> 22431077 | AD15: =+SUM(AC15:AC18) -> 34606811
B16: Sábado | C16: 52927 | D16: 49035 | E16: 46276 | F16: 44067 | G16: 43091 | H16: 43283 | I16: 43521 | J16: 35115 | K16: 30678 | L16: 28374 | M16: 27941 | N16: 25208 | O16: 23215 | P16: 29931 | Q16: 42680 | R16: 53744 | S16: 58748 | T16: 60980 | U16: 66518 | V16: 66935 | W16: 65036 | X16: 63129 | Y16: 60487 | Z16: 56461 | AA16: =SUM(C16:Z16) -> 1117380 | AB16: 5 | AC16: =+AA16*AB16 -> 5586900
B17: Domingo | C17: 53216 | D17: 49475 | E17: 46809 | F17: 44647 | G17: 43354 | H17: 42520 | I17: 40722 | J17: 27061 | K17: 17863 | L17: 13739 | M17: 11084 | N17: 9445 | O17: 12203 | P17: 18690 | Q17: 30575 | R17: 42295 | S17: 48773 | T17: 53469 | U17: 60171 | V17: 63602 | W17: 64376 | X17: 64024 | Y17: 60049 | Z17: 54519 | AA17: =SUM(C17:Z17) -> 972681 | AB17: 4 | AC17: =+AA17*AB17 -> 3890724
B18: Festivo | C18: 44825 | D18: 41063 | E18: 38642 | F18: 36996 | G18: 36175 | H18: 35991 | I18: 35521 | J18: 24305 | K18: 16859 | L18: 14320 | M18: 13700 | N18: 12081 | O18: 12598 | P18: 19906 | Q18: 31195 | R18: 41792 | S18: 47075 | T18: 51087 | U18: 58643 | V18: 61941 | W18: 61863 | X18: 59914 | Y18: 54396 | Z18: 48482 | AA18: =SUM(C18:Z18) -> 899370 | AB18: 3 | AC18: =+AA18*AB18 -> 2698110
A19: 47209 | B19: Hábil | C19: 53919 | D19: 50010 | E19: 47334 | F19: 45454 | G19: 45249 | H19: 46225 | I19: 47117 | J19: 39656 | K19: 36010 | L19: 34289 | M19: 34963 | N19: 33009 | O19: 28301 | P19: 41652 | Q19: 60295 | R19: 72089 | S19: 76368 | T19: 73378 | U19: 75014 | V19: 74551 | W19: 73813 | X19: 71465 | Y19: 66237 | Z19: 59347 | AA19: =SUM(C19:Z19) -> 1285745 | AB19: 21 | AC19: =+AA19*AB19 -> 27000645 | AD19: =+SUM(AC19:AC22) -> 36860395
B20: Sábado | C20: 54928 | D20: 51010 | E20: 48150 | F20: 45980 | G20: 45085 | H20: 44011 | I20: 44873 | J20: 36483 | K20: 33043 | L20: 31480 | M20: 31209 | N20: 29212 | O20: 27616 | P20: 34691 | Q20: 47795 | R20: 58719 | S20: 63062 | T20: 64716 | U20: 69798 | V20: 69182 | W20: 67168 | X20: 64969 | Y20: 61993 | Z20: 57897 | AA20: =SUM(C20:Z20) -> 1183070 | AB20: 4 | AC20: =+AA20*AB20 -> 4732280
B21: Domingo | C21: 55133 | D21: 51055 | E21: 48085 | F21: 45716 | G21: 44354 | H21: 42478 | I21: 41547 | J21: 28614 | K21: 19596 | L21: 15951 | M21: 14180 | N21: 13026 | O21: 15711 | P21: 22412 | Q21: 34556 | R21: 46310 | S21: 52377 | T21: 56388 | U21: 63027 | V21: 65752 | W21: 65741 | X21: 65448 | Y21: 61853 | Z21: 56184 | AA21: =SUM(C21:Z21) -> 1025494 | AB21: 5 | AC21: =+AA21*AB21 -> 5127470
B22: Festivo | C22: 0 | D22: 0 | E22: 0 | F22: 0 | G22: 0 | H22: 0 | I22: 0 | J22: 0 | K22: 0 | L22: 0 | M22: 0 | N22: 0 | O22: 0 | P22: 0 | Q22: 0 | R22: 0 | S22: 0 | T22: 0 | U22: 0 | V22: 0 | W22: 0 | X22: 0 | Y22: 0 | Z22: 0 | AA22: =SUM(C22:Z22) -> 0 | AB22: 0 | AC22: =+AA22*AB22 -> 0
A23: 47239 | B23: Hábil | C23: 53931 | D23: 50223 | E23: 47490 | F23: 45577 | G23: 45080 | H23: 44651 | I23: 45911 | J23: 38727 | K23: 35791 | L23: 34376 | M23: 34820 | N23: 32616 | O23: 28094 | P23: 41114 | Q23: 59277 | R23: 70323 | S23: 74257 | T23: 71253 | U23: 72504 | V23: 72600 | W23: 72308 | X23: 70408 | Y23: 65503 | Z23: 59017 | AA23: =SUM(C23:Z23) -> 1265851 | AB23: 21 | AC23: =+AA23*AB23 -> 26582871 | AD23: =+SUM(AC23:AC26) -> 37145955
B24: Sábado | C24: 56647 | D24: 52445 | E24: 49360 | F24: 46971 | G24: 45994 | H24: 44045 | I24: 45072 | J24: 36765 | K24: 33985 | L24: 32856 | M24: 32615 | N24: 29973 | O24: 27867 | P24: 34608 | Q24: 46981 | R24: 57739 | S24: 61839 | T24: 62660 | U24: 67459 | V24: 68151 | W24: 66505 | X24: 64818 | Y24: 62128 | Z24: 58109 | AA24: =SUM(C24:Z24) -> 1185592 | AB24: 4 | AC24: =+AA24*AB24 -> 4742368
B25: Domingo | C25: 54403 | D25: 50795 | E25: 48051 | F25: 45776 | G25: 44321 | H25: 41363 | I25: 41233 | J25: 27966 | K25: 19110 | L25: 15450 | M25: 13870 | N25: 11868 | O25: 13406 | P25: 19475 | Q25: 31663 | R25: 42880 | S25: 48945 | T25: 53321 | U25: 59772 | V25: 62849 | W25: 63479 | X25: 63614 | Y25: 60693 | Z25: 55633 | AA25: =SUM(C25:Z25) -> 989936 | AB25: 4 | AC25: =+AA25*AB25 -> 3959744
B26: Festivo | C26: 46745 | D26: 43195 | E26: 40671 | F26: 38835 | G26: 37992 | H26: 36023 | I26: 36443 | J26: 24621 | K26: 16951 | L26: 14412 | M26: 13866 | N26: 12349 | O26: 13417 | P26: 20524 | Q26: 32598 | R26: 43646 | S26: 48821 | T26: 52175 | U26: 58908 | V26: 62663 | W26: 63094 | X26: 62120 | Y26: 57961 | Z26: 52456 | AA26: =SUM(C26:Z26) -> 930486 | AB26: 2 | AC26: =+AA26*AB26 -> 1860972
A27: 47270 | B27: Hábil | C27: 57627 | D27: 53657 | E27: 50733 | F27: 48727 | G27: 48210 | H27: 47527 | I27: 49629 | J27: 43360 | K27: 40579 | L27: 38947 | M27: 39320 | N27: 37413 | O27: 32168 | P27: 45064 | Q27: 63248 | R27: 74791 | S27: 79186 | T27: 75160 | U27: 75622 | V27: 76379 | W27: 75521 | X27: 73237 | Y27: 68406 | Z27: 61914 | AA27: =SUM(C27:Z27) -> 1356425 | AB27: 19 | AC27: =+AA27*AB27 -> 25772075 | AD27: =+SUM(AC27:AC30) -> 38564385
B28: Sábado | C28: 58866 | D28: 55007 | E28: 52081 | F28: 49913 | G28: 49163 | H28: 47281 | I28: 49120 | J28: 41405 | K28: 38265 | L28: 36716 | M28: 36531 | N28: 34030 | O28: 31543 | P28: 37512 | Q28: 50881 | R28: 62249 | S28: 66699 | T28: 67311 | U28: 71209 | V28: 72332 | W28: 70326 | X28: 68247 | Y28: 65411 | Z28: 61398 | AA28: =SUM(C28:Z28) -> 1273496 | AB28: 5 | AC28: =+AA28*AB28 -> 6367480
B29: Domingo | C29: 58352 | D29: 54648 | E29: 51893 | F29: 49666 | G29: 48341 | H29: 45459 | I29: 45233 | J29: 32508 | K29: 22793 | L29: 19696 | M29: 16867 | N29: 14699 | O29: 16938 | P29: 23118 | Q29: 34986 | R29: 46564 | S29: 53363 | T29: 56570 | U29: 62724 | V29: 67312 | W29: 67687 | X29: 67488 | Y29: 64858 | Z29: 60243 | AA29: =SUM(C29:Z29) -> 1082006 | AB29: 4 | AC29: =+AA29*AB29 -> 4328024
B30: Festivo | C30: 51453 | D30: 47869 | E30: 45395 | F30: 43415 | G30: 42678 | H30: 40566 | I30: 41018 | J30: 30259 | K30: 23353 | L30: 21327 | M30: 21000 | N30: 19253 | O30: 19874 | P30: 26641 | Q30: 38307 | R30: 48845 | S30: 53775 | T30: 56078 | U30: 61954 | V30: 67044 | W30: 66726 | X30: 65241 | Y30: 61020 | Z30: 55312 | AA30: =SUM(C30:Z30) -> 1048403 | AB30: 2 | AC30: =+AA30*AB30 -> 2096806
A31: 47300 | B31: Hábil | C31: 54444 | D31: 50601 | E31: 47844 | F31: 45732 | G31: 45082 | H31: 45041 | I31: 46546 | J31: 39393 | K31: 36321 | L31: 34708 | M31: 35026 | N31: 32351 | O31: 26951 | P31: 39685 | Q31: 57532 | R31: 68930 | S31: 72856 | T31: 69468 | U31: 69380 | V31: 71374 | W31: 71028 | X31: 69310 | Y31: 64853 | Z31: 58722 | AA31: =SUM(C31:Z31) -> 1253178 | AB31: 20 | AC31: =+AA31*AB31 -> 25063560 | AD31: =+SUM(AC31:AC34) -> 36644330
B32: Sábado | C32: 53654 | D32: 49953 | E32: 47380 | F32: 45304 | G32: 44511 | H32: 43114 | I32: 44234 | J32: 36267 | K32: 32704 | L32: 31150 | M32: 30406 | N32: 28493 | O32: 26347 | P32: 32955 | Q32: 46007 | R32: 56416 | S32: 60565 | T32: 61174 | U32: 65207 | V32: 67738 | W32: 65795 | X32: 64037 | Y32: 61809 | Z32: 58273 | AA32: =SUM(C32:Z32) -> 1153493 | AB32: 4 | AC32: =+AA32*AB32 -> 4613972
B33: Domingo | C33: 55494 | D33: 51667 | E33: 48824 | F33: 46705 | G33: 45291 | H33: 42879 | I33: 42325 | J33: 28532 | K33: 19483 | L33: 15639 | M33: 13306 | N33: 10772 | O33: 13361 | P33: 19636 | Q33: 30920 | R33: 42861 | S33: 48867 | T33: 53259 | U33: 58287 | V33: 63123 | W33: 63885 | X33: 63822 | Y33: 60903 | Z33: 56303 | AA33: =SUM(C33:Z33) -> 996144 | AB33: 5 | AC33: =+AA33*AB33 -> 4980720
B34: Festivo | C34: 50971 | D34: 47271 | E34: 44517 | F34: 42723 | G34: 41840 | H34: 40205 | I34: 40317 | J34: 28865 | K34: 21603 | L34: 18747 | M34: 17403 | N34: 15040 | O34: 14981 | P34: 22480 | Q34: 34560 | R34: 45893 | S34: 51134 | T34: 53554 | U34: 58569 | V34: 63958 | W34: 63872 | X34: 62645 | Y34: 58755 | Z34: 53136 | AA34: =SUM(C34:Z34) -> 993039 | AB34: 2 | AC34: =+AA34*AB34 -> 1986078
A35: 47331 | B35: Hábil | C35: 55808 | D35: 51917 | E35: 48969 | F35: 46741 | G35: 45992 | H35: 45975 | I35: 46880 | J35: 39727 | K35: 36413 | L35: 35374 | M35: 35891 | N35: 33745 | O35: 28535 | P35: 42243 | Q35: 60887 | R35: 72186 | S35: 76192 | T35: 72230 | U35: 72786 | V35: 73605 | W35: 73531 | X35: 72085 | Y35: 67391 | Z35: 61229 | AA35: =SUM(C35:Z35) -> 1296332 | AB35: 21 | AC35: =+AA35*AB35 -> 27222972 | AD35: =+SUM(AC35:AC38) -> 38267878
B36: Sábado | C36: 59763 | D36: 55578 | E36: 52350 | F36: 49854 | G36: 48534 | H36: 46951 | I36: 47526 | J36: 39727 | K36: 36224 | L36: 35125 | M36: 34292 | N36: 33064 | O36: 30194 | P36: 37335 | Q36: 50223 | R36: 60867 | S36: 65294 | T36: 65214 | U36: 69952 | V36: 70613 | W36: 68585 | X36: 67573 | Y36: 65564 | Z36: 61773 | AA36: =SUM(C36:Z36) -> 1252175 | AB36: 4 | AC36: =+AA36*AB36 -> 5008700
B37: Domingo | C37: 58045 | D37: 54076 | E37: 50919 | F37: 48489 | G37: 46672 | H37: 43537 | I37: 42284 | J37: 29323 | K37: 19977 | L37: 15558 | M37: 13763 | N37: 10740 | O37: 13432 | P37: 21119 | Q37: 32455 | R37: 44214 | S37: 49109 | T37: 52686 | U37: 59105 | V37: 62671 | W37: 63600 | X37: 63948 | Y37: 61321 | Z37: 56518 | AA37: =SUM(C37:Z37) -> 1013561 | AB37: 4 | AC37: =+AA37*AB37 -> 4054244
B38: Festivo | C38: 48810 | D38: 45549 | E38: 42951 | F38: 41186 | G38: 40339 | H38: 38711 | I38: 38212 | J38: 26612 | K38: 19449 | L38: 17688 | M38: 17136 | N38: 15935 | O38: 16882 | P38: 23894 | Q38: 35904 | R38: 47611 | S38: 52512 | T38: 54157 | U38: 60622 | V38: 64032 | W38: 63852 | X38: 63865 | Y38: 60272 | Z38: 54800 | AA38: =SUM(C38:Z38) -> 990981 | AB38: 2 | AC38: =+AA38*AB38 -> 1981962
A39: 47362 | B39: Hábil | C39: 59558 | D39: 55238 | E39: 52042 | F39: 49580 | G39: 48701 | H39: 48494 | I39: 49742 | J39: 43125 | K39: 40194 | L39: 39373 | M39: 40195 | N39: 38089 | O39: 33109 | P39: 47574 | Q39: 66200 | R39: 77516 | S39: 80809 | T39: 77700 | U39: 79159 | V39: 77582 | W39: 77227 | X39: 75897 | Y39: 71194 | Z39: 64375 | AA39: =SUM(C39:Z39) -> 1392673 | AB39: 20 | AC39: =+AA39*AB39 -> 27853460 | AD39: =+SUM(AC39:AC42) -> 40109230
B40: Sábado | C40: 61096 | D40: 57115 | E40: 53961 | F40: 51296 | G40: 50023 | H40: 48218 | I40: 49229 | J40: 42116 | K40: 39356 | L40: 37996 | M40: 38439 | N40: 36529 | O40: 34165 | P40: 41606 | Q40: 54979 | R40: 65542 | S40: 69236 | T40: 70642 | U40: 76164 | V40: 74703 | W40: 72129 | X40: 70232 | Y40: 68003 | Z40: 64297 | AA40: =SUM(C40:Z40) -> 1327072 | AB40: 5 | AC40: =+AA40*AB40 -> 6635360
B41: Domingo | C41: 60279 | D41: 56417 | E41: 53448 | F41: 51075 | G41: 49460 | H41: 47016 | I41: 46355 | J41: 33066 | K41: 23470 | L41: 19026 | M41: 17504 | N41: 16095 | O41: 17837 | P41: 25392 | Q41: 38220 | R41: 49580 | S41: 55347 | T41: 59434 | U41: 66741 | V41: 68825 | W41: 70017 | X41: 70520 | Y41: 67307 | Z41: 61651 | AA41: =SUM(C41:Z41) -> 1124082 | AB41: 5 | AC41: =+AA41*AB41 -> 5620410
B42: Festivo | C42: 0 | D42: 0 | E42: 0 | F42: 0 | G42: 0 | H42: 0 | I42: 0 | J42: 0 | K42: 0 | L42: 0 | M42: 0 | N42: 0 | O42: 0 | P42: 0 | Q42: 0 | R42: 0 | S42: 0 | T42: 0 | U42: 0 | V42: 0 | W42: 0 | X42: 0 | Y42: 0 | Z42: 0 | AA42: =SUM(C42:Z42) -> 0 | AB42: 0 | AC42: =+AA42*AB42 -> 0
...

Sheet OF P4
C1: * La energia a ofertar debe ser expresada únicamente en kilovatio (kWh) redondeado a cero decimales
C4: OFERTA PRODUCTO 4
C5: MES | D5: ENERGIA SOLICITADA (KWh) | E5: % | F5: ENERGIA OFERTADA (KWh) | G5: PRECIO $/kWh
C6: 47119 | D6: =+VLOOKUP(C6,'PLANA P4'!$A$4:$AD$55,30,FALSE) -> 29760000 | E6: % | G6: $/kWh
C7: 47150 | D7: =+VLOOKUP(C7,'PLANA P4'!$A$4:$AD$55,30,FALSE) -> 26880000
C8: 47178 | D8: =+VLOOKUP(C8,'PLANA P4'!$A$4:$AD$55,30,FALSE) -> 29760000
C9: 47209 | D9: =+VLOOKUP(C9,'PLANA P4'!$A$4:$AD$55,30,FALSE) -> 28800000
C10: 47239 | D10: =+VLOOKUP(C10,'PLANA P4'!$A$4:$AD$55,30,FALSE) -> 29760000
C11: 47270 | D11: =+VLOOKUP(C11,'PLANA P4'!$A$4:$AD$55,30,FALSE) -> 28800000
C12: 47300 | D12: =+VLOOKUP(C12,'PLANA P4'!$A$4:$AD$55,30,FALSE) -> 29760000
C13: 47331 | D13: =+VLOOKUP(C13,'PLANA P4'!$A$4:$AD$55,30,FALSE) -> 29760000
C14: 47362 | D14: =+VLOOKUP(C14,'PLANA P4'!$A$4:$AD$55,30,FALSE) -> 28800000
C15: 47392 | D15: =+VLOOKUP(C15,'PLANA P4'!$A$4:$AD$55,30,FALSE) -> 29760000
C16: 47423 | D16: =+VLOOKUP(C16,'PLANA P4'!$A$4:$AD$55,30,FALSE) -> 28800000
C17: 47453 | D17: =+VLOOKUP(C17,'PLANA P4'!$A$4:$AD$55,30,FALSE) -> 29760000
D18: =SUM(D6:D17) -> 350400000

Sheet PLANA P4
A1: Curva de distribucion en kwh
A2: * La energia a ofertar debe ser expresada únicamente en kilovatio (kWh) redondeado a cero decimales
A4: TOTAL | C4: =+AD55 -> 350400000
A5: MES | B5: DÍA | C5: HORA 01 | D5: HORA 02 | E5: HORA 03 | F5: HORA 04 | G5: HORA 05 | H5: HORA 06 | I5: HORA 07 | J5: HORA 08 | K5: HORA 09 | L5: HORA 10 | M5: HORA 11 | N5: HORA 12 | O5: HORA 13 | P5: HORA 14 | Q5: HORA 15 | R5: HORA 16 | S5: HORA 17 | T5: HORA 18 | U5: HORA 19 | V5: HORA 20 | W5: HORA 21 | X5: HORA 22 | Y5: HORA 23 | Z5: HORA 24 | AA5: TOTAL DÍA | AB5: NUMERO DÍAS | AC5: TOTAL DÍA MES | AD5: TOTAL MES
A7: 47119 | B7: Hábil | C7: 40000 | D7: 40000 | E7: 40000 | F7: 40000 | G7: 40000 | H7: 40000 | I7: 40000 | J7: 40000 | K7: 40000 | L7: 40000 | M7: 40000 | N7: 40000 | O7: 40000 | P7: 40000 | Q7: 40000 | R7: 40000 | S7: 40000 | T7: 40000 | U7: 40000 | V7: 40000 | W7: 40000 | X7: 40000 | Y7: 40000 | Z7: 40000 | AA7: =SUM(C7:Z7) -> 960000 | AB7: 21 | AC7: =+AA7*AB7 -> 20160000 | AD7: =+SUM(AC7:AC10) -> 29760000
B8: Sábado | C8: 40000 | D8: 40000 | E8: 40000 | F8: 40000 | G8: 40000 | H8: 40000 | I8: 40000 | J8: 40000 | K8: 40000 | L8: 40000 | M8: 40000 | N8: 40000 | O8: 40000 | P8: 40000 | Q8: 40000 | R8: 40000 | S8: 40000 | T8: 40000 | U8: 40000 | V8: 40000 | W8: 40000 | X8: 40000 | Y8: 40000 | Z8: 40000 | AA8: =SUM(C8:Z8) -> 960000 | AB8: 4 | AC8: =+AA8*AB8 -> 3840000
B9: Domingo | C9: 40000 | D9: 40000 | E9: 40000 | F9: 40000 | G9: 40000 | H9: 40000 | I9: 40000 | J9: 40000 | K9: 40000 | L9: 40000 | M9: 40000 | N9: 40000 | O9: 40000 | P9: 40000 | Q9: 40000 | R9: 40000 | S9: 40000 | T9: 40000 | U9: 40000 | V9: 40000 | W9: 40000 | X9: 40000 | Y9: 40000 | Z9: 40000 | AA9: =SUM(C9:Z9) -> 960000 | AB9: 4 | AC9: =+AA9*AB9 -> 3840000
B10: Festivo | C10: 40000 | D10: 40000 | E10: 40000 | F10: 40000 | G10: 40000 | H10: 40000 | I10: 40000 | J10: 40000 | K10: 40000 | L10: 40000 | M10: 40000 | N10: 40000 | O10: 40000 | P10: 40000 | Q10: 40000 | R10: 40000 | S10: 40000 | T10: 40000 | U10: 40000 | V10: 40000 | W10: 40000 | X10: 40000 | Y10: 40000 | Z10: 40000 | AA10: =SUM(C10:Z10) -> 960000 | AB10: 2 | AC10: =+AA10*AB10 -> 1920000
A11: 47150 | B11: Hábil | C11: 40000 | D11: 40000 | E11: 40000 | F11: 40000 | G11: 40000 | H11: 40000 | I11: 40000 | J11: 40000 | K11: 40000 | L11: 40000 | M11: 40000 | N11: 40000 | O11: 40000 | P11: 40000 | Q11: 40000 | R11: 40000 | S11: 40000 | T11: 40000 | U11: 40000 | V11: 40000 | W11: 40000 | X11: 40000 | Y11: 40000 | Z11: 40000 | AA11: =SUM(C11:Z11) -> 960000 | AB11: 20 | AC11: =+AA11*AB11 -> 19200000 | AD11: =+SUM(AC11:AC14) -> 26880000
B12: Sábado | C12: 40000 | D12: 40000 | E12: 40000 | F12: 40000 | G12: 40000 | H12: 40000 | I12: 40000 | J12: 40000 | K12: 40000 | L12: 40000 | M12: 40000 | N12: 40000 | O12: 40000 | P12: 40000 | Q12: 40000 | R12: 40000 | S12: 40000 | T12: 40000 | U12: 40000 | V12: 40000 | W12: 40000 | X12: 40000 | Y12: 40000 | Z12: 40000 | AA12: =SUM(C12:Z12) -> 960000 | AB12: 4 | AC12: =+AA12*AB12 -> 3840000
B13: Domingo | C13: 40000 | D13: 40000 | E13: 40000 | F13: 40000 | G13: 40000 | H13: 40000 | I13: 40000 | J13: 40000 | K13: 40000 | L13: 40000 | M13: 40000 | N13: 40000 | O13: 40000 | P13: 40000 | Q13: 40000 | R13: 40000 | S13: 40000 | T13: 40000 | U13: 40000 | V13: 40000 | W13: 40000 | X13: 40000 | Y13: 40000 | Z13: 40000 | AA13: =SUM(C13:Z13) -> 960000 | AB13: 4 | AC13: =+AA13*AB13 -> 3840000
B14: Festivo | AA14: =SUM(C14:Z14) -> 0 | AB14: 0 | AC14: =+AA14*AB14 -> 0
A15: 47178 | B15: Hábil | C15: 40000 | D15: 40000 | E15: 40000 | F15: 40000 | G15: 40000 | H15: 40000 | I15: 40000 | J15: 40000 | K15: 40000 | L15: 40000 | M15: 40000 | N15: 40000 | O15: 40000 | P15: 40000 | Q15: 40000 | R15: 40000 | S15: 40000 | T15: 40000 | U15: 40000 | V15: 40000 | W15: 40000 | X15: 40000 | Y15: 40000 | Z15: 40000 | AA15: =SUM(C15:Z15) -> 960000 | AB15: 19 | AC15: =+AA15*AB15 -> 18240000 | AD15: =+SUM(AC15:AC18) -> 29760000
B16: Sábado | C16: 40000 | D16: 40000 | E16: 40000 | F16: 40000 | G16: 40000 | H16: 40000 | I16: 40000 | J16: 40000 | K16: 40000 | L16: 40000 | M16: 40000 | N16: 40000 | O16: 40000 | P16: 40000 | Q16: 40000 | R16: 40000 | S16: 40000 | T16: 40000 | U16: 40000 | V16: 40000 | W16: 40000 | X16: 40000 | Y16: 40000 | Z16: 40000 | AA16: =SUM(C16:Z16) -> 960000 | AB16: 5 | AC16: =+AA16*AB16 -> 4800000
B17: Domingo | C17: 40000 | D17: 40000 | E17: 40000 | F17: 40000 | G17: 40000 | H17: 40000 | I17: 40000 | J17: 40000 | K17: 40000 | L17: 40000 | M17: 40000 | N17: 40000 | O17: 40000 | P17: 40000 | Q17: 40000 | R17: 40000 | S17: 40000 | T17: 40000 | U17: 40000 | V17: 40000 | W17: 40000 | X17: 40000 | Y17: 40000 | Z17: 40000 | AA17: =SUM(C17:Z17) -> 960000 | AB17: 4 | AC17: =+AA17*AB17 -> 3840000
B18: Festivo | C18: 40000 | D18: 40000 | E18: 40000 | F18: 40000 | G18: 40000 | H18: 40000 | I18: 40000 | J18: 40000 | K18: 40000 | L18: 40000 | M18: 40000 | N18: 40000 | O18: 40000 | P18: 40000 | Q18: 40000 | R18: 40000 | S18: 40000 | T18: 40000 | U18: 40000 | V18: 40000 | W18: 40000 | X18: 40000 | Y18: 40000 | Z18: 40000 | AA18: =SUM(C18:Z18) -> 960000 | AB18: 3 | AC18: =+AA18*AB18 -> 2880000
A19: 47209 | B19: Hábil | C19: 40000 | D19: 40000 | E19: 40000 | F19: 40000 | G19: 40000 | H19: 40000 | I19: 40000 | J19: 40000 | K19: 40000 | L19: 40000 | M19: 40000 | N19: 40000 | O19: 40000 | P19: 40000 | Q19: 40000 | R19: 40000 | S19: 40000 | T19: 40000 | U19: 40000 | V19: 40000 | W19: 40000 | X19: 40000 | Y19: 40000 | Z19: 40000 | AA19: =SUM(C19:Z19) -> 960000 | AB19: 21 | AC19: =+AA19*AB19 -> 20160000 | AD19: =+SUM(AC19:AC22) -> 28800000
B20: Sábado | C20: 40000 | D20: 40000 | E20: 40000 | F20: 40000 | G20: 40000 | H20: 40000 | I20: 40000 | J20: 40000 | K20: 40000 | L20: 40000 | M20: 40000 | N20: 40000 | O20: 40000 | P20: 40000 | Q20: 40000 | R20: 40000 | S20: 40000 | T20: 40000 | U20: 40000 | V20: 40000 | W20: 40000 | X20: 40000 | Y20: 40000 | Z20: 40000 | AA20: =SUM(C20:Z20) -> 960000 | AB20: 4 | AC20: =+AA20*AB20 -> 3840000
B21: Domingo | C21: 40000 | D21: 40000 | E21: 40000 | F21: 40000 | G21: 40000 | H21: 40000 | I21: 40000 | J21: 40000 | K21: 40000 | L21: 40000 | M21: 40000 | N21: 40000 | O21: 40000 | P21: 40000 | Q21: 40000 | R21: 40000 | S21: 40000 | T21: 40000 | U21: 40000 | V21: 40000 | W21: 40000 | X21: 40000 | Y21: 40000 | Z21: 40000 | AA21: =SUM(C21:Z21) -> 960000 | AB21: 5 | AC21: =+AA21*AB21 -> 4800000
B22: Festivo | AA22: =SUM(C22:Z22) -> 0 | AB22: 0 | AC22: =+AA22*AB22 -> 0
A23: 47239 | B23: Hábil | C23: 40000 | D23: 40000 | E23: 40000 | F23: 40000 | G23: 40000 | H23: 40000 | I23: 40000 | J23: 40000 | K23: 40000 | L23: 40000 | M23: 40000 | N23: 40000 | O23: 40000 | P23: 40000 | Q23: 40000 | R23: 40000 | S23: 40000 | T23: 40000 | U23: 40000 | V23: 40000 | W23: 40000 | X23: 40000 | Y23: 40000 | Z23: 40000 | AA23: =SUM(C23:Z23) -> 960000 | AB23: 21 | AC23: =+AA23*AB23 -> 20160000 | AD23: =+SUM(AC23:AC26) -> 29760000
B24: Sábado | C24: 40000 | D24: 40000 | E24: 40000 | F24: 40000 | G24: 40000 | H24: 40000 | I24: 40000 | J24: 40000 | K24: 40000 | L24: 40000 | M24: 40000 | N24: 40000 | O24: 40000 | P24: 40000 | Q24: 40000 | R24: 40000 | S24: 40000 | T24: 40000 | U24: 40000 | V24: 40000 | W24: 40000 | X24: 40000 | Y24: 40000 | Z24: 40000 | AA24: =SUM(C24:Z24) -> 960000 | AB24: 4 | AC24: =+AA24*AB24 -> 3840000
B25: Domingo | C25: 40000 | D25: 40000 | E25: 40000 | F25: 40000 | G25: 40000 | H25: 40000 | I25: 40000 | J25: 40000 | K25: 40000 | L25: 40000 | M25: 40000 | N25: 40000 | O25: 40000 | P25: 40000 | Q25: 40000 | R25: 40000 | S25: 40000 | T25: 40000 | U25: 40000 | V25: 40000 | W25: 40000 | X25: 40000 | Y25: 40000 | Z25: 40000 | AA25: =SUM(C25:Z25) -> 960000 | AB25: 4 | AC25: =+AA25*AB25 -> 3840000
B26: Festivo | C26: 40000 | D26: 40000 | E26: 40000 | F26: 40000 | G26: 40000 | H26: 40000 | I26: 40000 | J26: 40000 | K26: 40000 | L26: 40000 | M26: 40000 | N26: 40000 | O26: 40000 | P26: 40000 | Q26: 40000 | R26: 40000 | S26: 40000 | T26: 40000 | U26: 40000 | V26: 40000 | W26: 40000 | X26: 40000 | Y26: 40000 | Z26: 40000 | AA26: =SUM(C26:Z26) -> 960000 | AB26: 2 | AC26: =+AA26*AB26 -> 1920000
A27: 47270 | B27: Hábil | C27: 40000 | D27: 40000 | E27: 40000 | F27: 40000 | G27: 40000 | H27: 40000 | I27: 40000 | J27: 40000 | K27: 40000 | L27: 40000 | M27: 40000 | N27: 40000 | O27: 40000 | P27: 40000 | Q27: 40000 | R27: 40000 | S27: 40000 | T27: 40000 | U27: 40000 | V27: 40000 | W27: 40000 | X27: 40000 | Y27: 40000 | Z27: 40000 | AA27: =SUM(C27:Z27) -> 960000 | AB27: 19 | AC27: =+AA27*AB27 -> 18240000 | AD27: =+SUM(AC27:AC30) -> 28800000
B28: Sábado | C28: 40000 | D28: 40000 | E28: 40000 | F28: 40000 | G28: 40000 | H28: 40000 | I28: 40000 | J28: 40000 | K28: 40000 | L28: 40000 | M28: 40000 | N28: 40000 | O28: 40000 | P28: 40000 | Q28: 40000 | R28: 40000 | S28: 40000 | T28: 40000 | U28: 40000 | V28: 40000 | W28: 40000 | X28: 40000 | Y28: 40000 | Z28: 40000 | AA28: =SUM(C28:Z28) -> 960000 | AB28: 5 | AC28: =+AA28*AB28 -> 4800000
B29: Domingo | C29: 40000 | D29: 40000 | E29: 40000 | F29: 40000 | G29: 40000 | H29: 40000 | I29: 40000 | J29: 40000 | K29: 40000 | L29: 40000 | M29: 40000 | N29: 40000 | O29: 40000 | P29: 40000 | Q29: 40000 | R29: 40000 | S29: 40000 | T29: 40000 | U29: 40000 | V29: 40000 | W29: 40000 | X29: 40000 | Y29: 40000 | Z29: 40000 | AA29: =SUM(C29:Z29) -> 960000 | AB29: 4 | AC29: =+AA29*AB29 -> 3840000
B30: Festivo | C30: 40000 | D30: 40000 | E30: 40000 | F30: 40000 | G30: 40000 | H30: 40000 | I30: 40000 | J30: 40000 | K30: 40000 | L30: 40000 | M30: 40000 | N30: 40000 | O30: 40000 | P30: 40000 | Q30: 40000 | R30: 40000 | S30: 40000 | T30: 40000 | U30: 40000 | V30: 40000 | W30: 40000 | X30: 40000 | Y30: 40000 | Z30: 40000 | AA30: =SUM(C30:Z30) -> 960000 | AB30: 2 | AC30: =+AA30*AB30 -> 1920000
A31: 47300 | B31: Hábil | C31: 40000 | D31: 40000 | E31: 40000 | F31: 40000 | G31: 40000 | H31: 40000 | I31: 40000 | J31: 40000 | K31: 40000 | L31: 40000 | M31: 40000 | N31: 40000 | O31: 40000 | P31: 40000 | Q31: 40000 | R31: 40000 | S31: 40000 | T31: 40000 | U31: 40000 | V31: 40000 | W31: 40000 | X31: 40000 | Y31: 40000 | Z31: 40000 | AA31: =SUM(C31:Z31) -> 960000 | AB31: 20 | AC31: =+AA31*AB31 -> 19200000 | AD31: =+SUM(AC31:AC34) -> 29760000
