Workbook

Sheet Producto 1 curvo 26
B2: ANEXO 1 - CANTIDADES DE ENERGÍA SOLICITADA EN kWh
B3: PRODUCTO 1
B4: PERIODO 02 DE JULIO DEL 2026 A DICIEMBRE 31 DE 2026
C5: DIA | D5: 1 | E5: 2 | F5: 3 | G5: 4 | H5: 5 | I5: 6 | J5: 7 | K5: 8 | L5: 9 | M5: 10 | N5: 11 | O5: 12 | P5: 13 | Q5: 14 | R5: 15 | S5: 16 | T5: 17 | U5: 18 | V5: 19 | W5: 20 | X5: 21 | Y5: 22 | Z5: 23 | AA5: 24 | AB5: Total | AC5: No. DÍAS | AD5: Total
B6: 46023 | C6: Hábil | D6: 0 | E6: 0 | F6: 0 | G6: 0 | H6: 0 | I6: 0 | J6: 0 | K6: 0 | L6: 0 | M6: 0 | N6: 0 | O6: 0 | P6: 0 | Q6: 0 | R6: 0 | S6: 0 | T6: 0 | U6: 0 | V6: 0 | W6: 0 | X6: 0 | Y6: 0 | Z6: 0 | AA6: 0 | AB6: =(SUM(D6:AA6)) -> 0 | AC6: 20 | AD6: =(AB6*AC6)+(AB7*AC7)+(AB8*AC8)+(AB9*AC9) -> 0 | AE6: =+AD6 -> 0
C7: Sábado | D7: 0 | E7: 0 | F7: 0 | G7: 0 | H7: 0 | I7: 0 | J7: 0 | K7: 0 | L7: 0 | M7: 0 | N7: 0 | O7: 0 | P7: 0 | Q7: 0 | R7: 0 | S7: 0 | T7: 0 | U7: 0 | V7: 0 | W7: 0 | X7: 0 | Y7: 0 | Z7: 0 | AA7: 0 | AB7: =(SUM(D7:AA7)) -> 0 | AC7: 5 | AE7: =+AD10 -> 0
C8: Domingo | D8: 0 | E8: 0 | F8: 0 | G8: 0 | H8: 0 | I8: 0 | J8: 0 | K8: 0 | L8: 0 | M8: 0 | N8: 0 | O8: 0 | P8: 0 | Q8: 0 | R8: 0 | S8: 0 | T8: 0 | U8: 0 | V8: 0 | W8: 0 | X8: 0 | Y8: 0 | Z8: 0 | AA8: 0 | AB8: =(SUM(D8:AA8)) -> 0 | AC8: 4 | AE8: =+AD14 -> 0
C9: Festivo | D9: 0 | E9: 0 | F9: 0 | G9: 0 | H9: 0 | I9: 0 | J9: 0 | K9: 0 | L9: 0 | M9: 0 | N9: 0 | O9: 0 | P9: 0 | Q9: 0 | R9: 0 | S9: 0 | T9: 0 | U9: 0 | V9: 0 | W9: 0 | X9: 0 | Y9: 0 | Z9: 0 | AA9: 0 | AB9: =(SUM(D9:AA9)) -> 0 | AC9: 2 | AE9: =+AD18 -> 0
B10: 46054 | C10: Hábil | D10: 0 | E10: 0 | F10: 0 | G10: 0 | H10: 0 | I10: 0 | J10: 0 | K10: 0 | L10: 0 | M10: 0 | N10: 0 | O10: 0 | P10: 0 | Q10: 0 | R10: 0 | S10: 0 | T10: 0 | U10: 0 | V10: 0 | W10: 0 | X10: 0 | Y10: 0 | Z10: 0 | AA10: 0 | AB10: =(SUM(D10:AA10)) -> 0 | AC10: 20 | AD10: =(AB10*AC10)+(AB11*AC11)+(AB12*AC12)+(AB13*AC13) -> 0 | AE10: =+AD22 -> 0
C11: Sábado | D11: 0 | E11: 0 | F11: 0 | G11: 0 | H11: 0 | I11: 0 | J11: 0 | K11: 0 | L11: 0 | M11: 0 | N11: 0 | O11: 0 | P11: 0 | Q11: 0 | R11: 0 | S11: 0 | T11: 0 | U11: 0 | V11: 0 | W11: 0 | X11: 0 | Y11: 0 | Z11: 0 | AA11: 0 | AB11: =(SUM(D11:AA11)) -> 0 | AC11: 4 | AE11: =+AD26 -> 0
C12: Domingo | D12: 0 | E12: 0 | F12: 0 | G12: 0 | H12: 0 | I12: 0 | J12: 0 | K12: 0 | L12: 0 | M12: 0 | N12: 0 | O12: 0 | P12: 0 | Q12: 0 | R12: 0 | S12: 0 | T12: 0 | U12: 0 | V12: 0 | W12: 0 | X12: 0 | Y12: 0 | Z12: 0 | AA12: 0 | AB12: =(SUM(D12:AA12)) -> 0 | AC12: 4 | AE12: =+AD30 -> 3195152.6
C13: Festivo | D13: 0 | E13: 0 | F13: 0 | G13: 0 | H13: 0 | I13: 0 | J13: 0 | K13: 0 | L13: 0 | M13: 0 | N13: 0 | O13: 0 | P13: 0 | Q13: 0 | R13: 0 | S13: 0 | T13: 0 | U13: 0 | V13: 0 | W13: 0 | X13: 0 | Y13: 0 | Z13: 0 | AA13: 0 | AB13: =(SUM(D13:AA13)) -> 0 | AC13: 0 | AE13: =+AD34 -> 3152670.3
B14: 46082 | C14: Hábil | D14: 0 | E14: 0 | F14: 0 | G14: 0 | H14: 0 | I14: 0 | J14: 0 | K14: 0 | L14: 0 | M14: 0 | N14: 0 | O14: 0 | P14: 0 | Q14: 0 | R14: 0 | S14: 0 | T14: 0 | U14: 0 | V14: 0 | W14: 0 | X14: 0 | Y14: 0 | Z14: 0 | AA14: 0 | AB14: =(SUM(D14:AA14)) -> 0 | AC14: 21 | AD14: =(AB14*AC14)+(AB15*AC15)+(AB16*AC16)+(AB17*AC17) -> 0 | AE14: =+AD38 -> 3863339
C15: Sábado | D15: 0 | E15: 0 | F15: 0 | G15: 0 | H15: 0 | I15: 0 | J15: 0 | K15: 0 | L15: 0 | M15: 0 | N15: 0 | O15: 0 | P15: 0 | Q15: 0 | R15: 0 | S15: 0 | T15: 0 | U15: 0 | V15: 0 | W15: 0 | X15: 0 | Y15: 0 | Z15: 0 | AA15: 0 | AB15: =(SUM(D15:AA15)) -> 0 | AC15: 4 | AE15: =+AD42 -> 4394273.8
C16: Domingo | D16: 0 | E16: 0 | F16: 0 | G16: 0 | H16: 0 | I16: 0 | J16: 0 | K16: 0 | L16: 0 | M16: 0 | N16: 0 | O16: 0 | P16: 0 | Q16: 0 | R16: 0 | S16: 0 | T16: 0 | U16: 0 | V16: 0 | W16: 0 | X16: 0 | Y16: 0 | Z16: 0 | AA16: 0 | AB16: =(SUM(D16:AA16)) -> 0 | AC16: 5 | AE16: =+AD46 -> 3537054.9
C17: Festivo | D17: 0 | E17: 0 | F17: 0 | G17: 0 | H17: 0 | I17: 0 | J17: 0 | K17: 0 | L17: 0 | M17: 0 | N17: 0 | O17: 0 | P17: 0 | Q17: 0 | R17: 0 | S17: 0 | T17: 0 | U17: 0 | V17: 0 | W17: 0 | X17: 0 | Y17: 0 | Z17: 0 | AA17: 0 | AB17: =(SUM(D17:AA17)) -> 0 | AC17: 1 | AE17: =+AD50 -> 4409114.7
B18: 46113 | C18: Hábil | D18: 0 | E18: 0 | F18: 0 | G18: 0 | H18: 0 | I18: 0 | J18: 0 | K18: 0 | L18: 0 | M18: 0 | N18: 0 | O18: 0 | P18: 0 | Q18: 0 | R18: 0 | S18: 0 | T18: 0 | U18: 0 | V18: 0 | W18: 0 | X18: 0 | Y18: 0 | Z18: 0 | AA18: 0 | AB18: =(SUM(D18:AA18)) -> 0 | AC18: 20 | AD18: =(AB18*AC18)+(AB19*AC19)+(AB20*AC20)+(AB21*AC21) -> 0
C19: Sábado | D19: 0 | E19: 0 | F19: 0 | G19: 0 | H19: 0 | I19: 0 | J19: 0 | K19: 0 | L19: 0 | M19: 0 | N19: 0 | O19: 0 | P19: 0 | Q19: 0 | R19: 0 | S19: 0 | T19: 0 | U19: 0 | V19: 0 | W19: 0 | X19: 0 | Y19: 0 | Z19: 0 | AA19: 0 | AB19: =(SUM(D19:AA19)) -> 0 | AC19: 4
C20: Domingo | D20: 0 | E20: 0 | F20: 0 | G20: 0 | H20: 0 | I20: 0 | J20: 0 | K20: 0 | L20: 0 | M20: 0 | N20: 0 | O20: 0 | P20: 0 | Q20: 0 | R20: 0 | S20: 0 | T20: 0 | U20: 0 | V20: 0 | W20: 0 | X20: 0 | Y20: 0 | Z20: 0 | AA20: 0 | AB20: =(SUM(D20:AA20)) -> 0 | AC20: 4
C21: Festivo | D21: 0 | E21: 0 | F21: 0 | G21: 0 | H21: 0 | I21: 0 | J21: 0 | K21: 0 | L21: 0 | M21: 0 | N21: 0 | O21: 0 | P21: 0 | Q21: 0 | R21: 0 | S21: 0 | T21: 0 | U21: 0 | V21: 0 | W21: 0 | X21: 0 | Y21: 0 | Z21: 0 | AA21: 0 | AB21: =(SUM(D21:AA21)) -> 0 | AC21: 2
B22: 46143 | C22: Hábil | D22: 0 | E22: 0 | F22: 0 | G22: 0 | H22: 0 | I22: 0 | J22: 0 | K22: 0 | L22: 0 | M22: 0 | N22: 0 | O22: 0 | P22: 0 | Q22: 0 | R22: 0 | S22: 0 | T22: 0 | U22: 0 | V22: 0 | W22: 0 | X22: 0 | Y22: 0 | Z22: 0 | AA22: 0 | AB22: =(SUM(D22:AA22)) -> 0 | AC22: 19 | AD22: =(AB22*AC22)+(AB23*AC23)+(AB24*AC24)+(AB25*AC25) -> 0
C23: Sábado | D23: 0 | E23: 0 | F23: 0 | G23: 0 | H23: 0 | I23: 0 | J23: 0 | K23: 0 | L23: 0 | M23: 0 | N23: 0 | O23: 0 | P23: 0 | Q23: 0 | R23: 0 | S23: 0 | T23: 0 | U23: 0 | V23: 0 | W23: 0 | X23: 0 | Y23: 0 | Z23: 0 | AA23: 0 | AB23: =(SUM(D23:AA23)) -> 0 | AC23: 5
C24: Domingo | D24: 0 | E24: 0 | F24: 0 | G24: 0 | H24: 0 | I24: 0 | J24: 0 | K24: 0 | L24: 0 | M24: 0 | N24: 0 | O24: 0 | P24: 0 | Q24: 0 | R24: 0 | S24: 0 | T24: 0 | U24: 0 | V24: 0 | W24: 0 | X24: 0 | Y24: 0 | Z24: 0 | AA24: 0 | AB24: =(SUM(D24:AA24)) -> 0 | AC24: 5
C25: Festivo | D25: 0 | E25: 0 | F25: 0 | G25: 0 | H25: 0 | I25: 0 | J25: 0 | K25: 0 | L25: 0 | M25: 0 | N25: 0 | O25: 0 | P25: 0 | Q25: 0 | R25: 0 | S25: 0 | T25: 0 | U25: 0 | V25: 0 | W25: 0 | X25: 0 | Y25: 0 | Z25: 0 | AA25: 0 | AB25: =(SUM(D25:AA25)) -> 0 | AC25: 2
B26: 46174 | C26: Hábil | D26: 0 | E26: 0 | F26: 0 | G26: 0 | H26: 0 | I26: 0 | J26: 0 | K26: 0 | L26: 0 | M26: 0 | N26: 0 | O26: 0 | P26: 0 | Q26: 0 | R26: 0 | S26: 0 | T26: 0 | U26: 0 | V26: 0 | W26: 0 | X26: 0 | Y26: 0 | Z26: 0 | AA26: 0 | AB26: =(SUM(D26:AA26)) -> 0 | AC26: 19 | AD26: =(AB26*AC26)+(AB27*AC27)+(AB28*AC28)+(AB29*AC29) -> 0
C27: Sábado | D27: 0 | E27: 0 | F27: 0 | G27: 0 | H27: 0 | I27: 0 | J27: 0 | K27: 0 | L27: 0 | M27: 0 | N27: 0 | O27: 0 | P27: 0 | Q27: 0 | R27: 0 | S27: 0 | T27: 0 | U27: 0 | V27: 0 | W27: 0 | X27: 0 | Y27: 0 | Z27: 0 | AA27: 0 | AB27: =(SUM(D27:AA27)) -> 0 | AC27: 4
C28: Domingo | D28: 0 | E28: 0 | F28: 0 | G28: 0 | H28: 0 | I28: 0 | J28: 0 | K28: 0 | L28: 0 | M28: 0 | N28: 0 | O28: 0 | P28: 0 | Q28: 0 | R28: 0 | S28: 0 | T28: 0 | U28: 0 | V28: 0 | W28: 0 | X28: 0 | Y28: 0 | Z28: 0 | AA28: 0 | AB28: =(SUM(D28:AA28)) -> 0 | AC28: 4
C29: Festivo | D29: 0 | E29: 0 | F29: 0 | G29: 0 | H29: 0 | I29: 0 | J29: 0 | K29: 0 | L29: 0 | M29: 0 | N29: 0 | O29: 0 | P29: 0 | Q29: 0 | R29: 0 | S29: 0 | T29: 0 | U29: 0 | V29: 0 | W29: 0 | X29: 0 | Y29: 0 | Z29: 0 | AA29: 0 | AB29: =(SUM(D29:AA29)) -> 0 | AC29: 3
B30: 46204 | C30: Hábil | D30: 5576.6516 | E30: 5090.2736 | F30: 5090.2736 | G30: 5090.2736 | H30: 5576.6516 | I30: 7035.7857 | J30: 5670.5167 | K30: 3460.6634 | L30: 2379.9816 | M30: 1896.0099 | N30: 1441.5505 | O30: 1301.0174 | P30: 1889.2876 | Q30: 1301.0174 | R30: 1301.0174 | S30: 1301.0174 | T30: 1301.0174 | U30: 1301.0174 | V30: 1301.0174 | W30: 1620.6412 | X30: 2873.8215 | Y30: 4480.4351 | Z30: 5652.1291 | AA30: 6269.4102 | AB30: =(SUM(D30:AA30)) -> 80201.478 | AC30: 21 | AD30: =(AB30*AC30)+(AB31*AC31)+(AB32*AC32)+(AB33*AC33) -> 3195152.6
C31: Sábado | D31: 7345.1282 | E31: 6891.6014 | F31: 6438.0745 | G31: 5984.5477 | H31: 6438.0745 | I31: 6891.6014 | J31: 6500.9487 | K31: 5442.1869 | L31: 5140.8335 | M31: 4737.7296 | N31: 4061.2102 | O31: 4438.3624 | P31: 5397.8734 | Q31: 5576.2918 | R31: 5854.0497 | S31: 5604.6301 | T31: 5344.1236 | U31: 2443.5126 | V31: 2675.7098 | W31: 3781.588 | X31: 5334.6582 | Y31: 6542.637 | Z31: 7345.1282 | AA31: 6891.6014 | AB31: =(SUM(D31:AA31)) -> 133102.1 | AC31: 4
C32: domingo | D32: 7099.2413 | E32: 6687.9899 | F32: 6276.7386 | G32: 6276.7386 | H32: 6276.7386 | I32: 5865.4872 | J32: 6276.7386 | K32: 7079.081 | L32: 7490.3323 | M32: 8312.8351 | N32: 8293.9321 | O32: 8593.1685 | P32: 9102.6108 | Q32: 9200.1333 | R32: 9487.6724 | S32: 10390.123 | T32: 10480.55 | U32: 8800.8671 | V32: 8946.1054 | W32: 9407.2106 | X32: 10008.88 | Y32: 9155.4981 | Z32: 8332.9954 | AA32: 7510.4927 | AB32: =(SUM(D32:AA32)) -> 195352.16 | AC32: 4
C33: Festivo | D33: 7200.0264 | E33: 6786.1228 | F33: 6372.2192 | G33: 5958.3156 | H33: 5958.3156 | I33: 5958.3156 | J33: 6372.2192 | K33: 6765.9625 | L33: 7593.7697 | M33: 8421.5769 | N33: 9249.3841 | O33: 9663.2877 | P33: 9663.2877 | Q33: 10077.191 | R33: 10077.191 | S33: 10491.095 | T33: 10491.095 | U33: 8533.0629 | V33: 8287.526 | W33: 9096.6115 | X33: 9590.5202 | Y33: 9269.5444 | Z33: 8027.8336 | AA33: 7200.0264 | AB33: =(SUM(D33:AA33)) -> 197104.5 | AC33: 1
B34: 46235 | C34: Hábil | D34: 5211.0247 | E34: 4727.6596 | F34: 4727.6596 | G34: 4727.6596 | H34: 5211.0247 | I34: 6661.12 | J34: 4774.5381 | K34: 2460.5992 | L34: 1336.9466 | M34: 1032.2002 | N34: 1032.2002 | O34: 1032.2002 | P34: 1032.2002 | Q34: 1032.2002 | R34: 1032.2002 | S34: 1032.2002 | T34: 1032.2002 | U34: 1032.2002 | V34: 1032.2002 | W34: 1032.2002 | X34: 1953.0134 | Y34: 3609.5501 | Z34: 4818.1472 | AA34: 5454.0037 | AB34: =(SUM(D34:AA34)) -> 67027.149 | AC34: 19 | AD34: =(AB34*AC34)+(AB35*AC35)+(AB36*AC36)+(AB37*AC37) -> 3152670.3
C35: Sábado | D35: 6961.4784 | E35: 6522.5738 | F35: 6071.7168 | G35: 5620.8599 | H35: 6071.7168 | I35: 6522.5738 | J35: 5635.7624 | K35: 4510.6262 | L35: 4191.6127 | M35: 3769.1462 | N35: 3068.2752 | O35: 3450.0277 | P35: 4433.2397 | Q35: 4625.4693 | R35: 4919.9585 | S35: 4673.5137 | T35: 4413.2975 | U35: 1514.7125 | V35: 1757.1618 | W35: 2897.5787 | X35: 4494.4549 | Y35: 5739.5779 | Z35: 6935.5739 | AA35: 6522.5738 | AB35: =(SUM(D35:AA35)) -> 115323.48 | AC35: 5
C36: Domingo | D36: 6735.8691 | E36: 6326.8578 | F36: 5917.8464 | G36: 5917.8464 | H36: 5917.8464 | I36: 5508.835 | J36: 5917.8464 | K36: 6715.7305 | L36: 7124.7419 | M36: 7942.7647 | N36: 8019.3124 | O36: 8316.4294 | P36: 8760.7874 | Q36: 8920.9435 | R36: 9206.3758 | S36: 10104.26 | T36: 10194.59 | U36: 8078.7509 | V36: 8226.9374 | W36: 8702.0658 | X36: 9321.5523 | Y36: 8780.926 | Z36: 7962.9033 | AA36: 7144.8805 | AB36: =(SUM(D36:AA36)) -> 185766.9 | AC36: 5
C37: Festivo | D37: 6835.8462 | E37: 6424.2039 | F37: 6012.5615 | G37: 5600.9191 | H37: 5600.9191 | I37: 5600.9191 | J37: 6012.5615 | K37: 6404.0652 | L37: 7227.3499 | M37: 8050.6347 | N37: 8873.9194 | O37: 9285.5617 | P37: 9285.5617 | Q37: 9697.2041 | R37: 9697.2041 | S37: 10108.846 | T37: 10108.846 | U37: 7802.8156 | V37: 7551.6929 | W37: 8386.1359 | X37: 8894.4987 | Y37: 8894.058 | Z37: 7659.1309 | AA37: 6835.8462 | AB37: =(SUM(D37:AA37)) -> 186851.3 | AC37: 2
B38: 46266 | C38: Hábil | D38: 6688.1549 | E38: 6206.5787 | F38: 6206.5787 | G38: 6206.5787 | H38: 6688.1549 | I38: 8132.8832 | J38: 6871.2696 | K38: 4577.9213 | L38: 3462.503 | M38: 2961.0833 | N38: 2491.4032 | O38: 2301.983 | P38: 2940.1524 | Q38: 2255.1477 | R38: 2077.4511 | S38: 2077.4511 | T38: 2077.4511 | U38: 2077.4511 | V38: 2077.4511 | W38: 2765.5641 | X38: 4050.8914 | Y38: 5698.4872 | Z38: 6900.4271 | AA38: 7532.986 | AB38: =(SUM(D38:AA38)) -> 105326 | AC38: 22 | AD38: =(AB38*AC38)+(AB39*AC39)+(AB40*AC40)+(AB41*AC41) -> 3863339
C39: Sábado | D39: 8481.2595 | E39: 8031.0078 | F39: 7580.756 | G39: 7130.5042 | H39: 7580.756 | I39: 8031.0078 | J39: 7722.8629 | K39: 6611.1313 | L39: 6295.6478 | M39: 5876.9463 | N39: 5180.5152 | O39: 5561.8722 | P39: 6541.2971 | Q39: 6730.6757 | R39: 7021.8113 | S39: 6774.2531 | T39: 6513.5195 | U39: 3609.5518 | V39: 3849.9263 | W39: 4984.2698 | X39: 6573.8534 | Y39: 7812.5589 | Z39: 8481.2595 | AA39: 8031.0078 | AB39: =(SUM(D39:AA39)) -> 161008.25 | AC39: 4
C40: Domingo | D40: 8296.4109 | E40: 7886.5697 | F40: 7476.7286 | G40: 7476.7286 | H40: 7476.7286 | I40: 7066.8875 | J40: 7476.7286 | K40: 8276.2332 | L40: 8686.0743 | M40: 9505.7566 | N40: 9639.9412 | O40: 9937.6708 | P40: 10325.439 | Q40: 10543.394 | R40: 10829.416 | S40: 11729.115 | T40: 11819.621 | U40: 10125.078 | V40: 10272.839 | W40: 10745.77 | X40: 11362.532 | Y40: 10345.617 | Z40: 9525.9343 | AA40: 8706.252 | AB40: =(SUM(D40:AA40)) -> 225533.47 | AC40: 4
C41: Festivo | D41: 2077.4511 | E41: 2077.4511 | F41: 2077.4511 | G41: 2077.4511 | H41: 2077.4511 | I41: 2077.4511 | J41: 2077.4511 | K41: 2077.4511 | L41: 2077.4511 | M41: 2077.4511 | N41: 2077.4511 | O41: 2077.4511 | P41: 2077.4511 | Q41: 2077.4511 | R41: 2077.4511 | S41: 2077.4511 | T41: 2077.4511 | U41: 2077.4511 | V41: 2077.4511 | W41: 2077.4511 | X41: 2077.4511 | Y41: 2077.4511 | Z41: 2077.4511 | AA41: 2077.4511 | AB41: =(SUM(D41:AA41)) -> 49858.827 | AC41: 0
...

Sheet Anexo 2 Producto 1
B4: ANEXO 2 - OFERTA PRODUCTO 1
B5: NOMBRE DEL OFERENTE
B6: PRECIOS Y CANTIDADES DE ENERGIA OFERTADA
B7: EN PESOS DE MARZO 2026
B8: PRODUCTO 1
B9: AÑO | C9: MES | D9: PERIODO 2026
D10: E. Solicitada [kWh] | E10: % E. Ofertado | F10: E. Ofertada [kWh] | G10: $/kWh
B11: 2026 | C11: Enero | D11: =+'Producto 1 curvo 26'!AE6 -> 0 | F11: =+$E$11*D11 -> 0
B12: 2026 | C12: Febrero | D12: =+'Producto 1 curvo 26'!AE7 -> 0 | F12: =+$E$11*D12 -> 0
B13: 2026 | C13: Marzo | D13: =+'Producto 1 curvo 26'!AE8 -> 0 | F13: =+$E$11*D13 -> 0
B14: 2026 | C14: Abril | D14: =+'Producto 1 curvo 26'!AE9 -> 0 | F14: =+$E$11*D14 -> 0
B15: 2026 | C15: Mayo | D15: =+'Producto 1 curvo 26'!AE10 -> 0 | F15: =+$E$11*D15 -> 0
B16: 2026 | C16: Junio | D16: =+'Producto 1 curvo 26'!AE11 -> 0 | F16: =+$E$11*D16 -> 0
B17: 2026 | C17: Julio | D17: =+'Producto 1 curvo 26'!AE12 -> 3195152.6 | F17: =+$E$11*D17 -> 0
B18: 2026 | C18: Agosto | D18: =+'Producto 1 curvo 26'!AE13 -> 3152670.3 | F18: =+$E$11*D18 -> 0
B19: 2026 | C19: Septiembre | D19: =+'Producto 1 curvo 26'!AE14 -> 3863339 | F19: =+$E$11*D19 -> 0
B20: 2026 | C20: Octubre | D20: =+'Producto 1 curvo 26'!AE15 -> 4394273.8 | F20: =+$E$11*D20 -> 0
B21: 2026 | C21: Noviembre | D21: =+'Producto 1 curvo 26'!AE16 -> 3537054.9 | F21: =+$E$11*D21 -> 0
B22: 2026 | C22: Diciembre | D22: =+'Producto 1 curvo 26'!AE17 -> 4409114.7 | F22: =+$E$11*D22 -> 0 | H22: =SUM(D11:D22) -> 22551605 | I22: =+H22/1000 -> 22551.605
B23: Total Producto 1 | D23: =+SUM(D11:D22) -> 22551605 | I23: =+D23/1000 -> 22551.605
B25: E. Solicitada = Energía solicitada por RUITOQUE para el producto.
B26: % E. Ofertado = Porcentaje de energía ofertado por el agente respecto a la E. Solicitada.
B27: E. Ofertada = Energía ofertada por el agente, producto de la E. Solicitada y el % E. Ofertado.
B28: $/kWh = Tarifa de la oferta para todas las horas del mes.

Sheet Producto 2 Plano 26
B2: ANEXO 1 - CANTIDADES DE ENERGÍA SOLICITADA EN kWh
B3: PRODUCTO 2
B4: PERIODO 01 DE NOVIEMBRE DEL 2026 A DICIEMBRE 31 DE 2026
C5: DIA | D5: 1 | E5: 2 | F5: 3 | G5: 4 | H5: 5 | I5: 6 | J5: 7 | K5: 8 | L5: 9 | M5: 10 | N5: 11 | O5: 12 | P5: 13 | Q5: 14 | R5: 15 | S5: 16 | T5: 17 | U5: 18 | V5: 19 | W5: 20 | X5: 21 | Y5: 22 | Z5: 23 | AA5: 24 | AB5: Total | AC5: No. DÍAS | AD5: Total
B6: 46023 | C6: Hábil | AB6: =(SUM(D6:AA6)) -> 0 | AC6: 20 | AD6: =(AB6*AC6)+(AB7*AC7)+(AB8*AC8)+(AB9*AC9) -> 0 | AE6: =+AD6 -> 0
C7: Sábado | AB7: =(SUM(D7:AA7)) -> 0 | AC7: 5 | AE7: =+AD10 -> 0
C8: Domingo | AB8: =(SUM(D8:AA8)) -> 0 | AC8: 4 | AE8: =+AD14 -> 0
C9: Festivo | AB9: =(SUM(D9:AA9)) -> 0 | AC9: 2 | AE9: =+AD18 -> 0
B10: 46054 | C10: Hábil | AB10: =(SUM(D10:AA10)) -> 0 | AC10: 20 | AD10: =(AB10*AC10)+(AB11*AC11)+(AB12*AC12)+(AB13*AC13) -> 0 | AE10: =+AD22 -> 0
C11: Sábado | AB11: =(SUM(D11:AA11)) -> 0 | AC11: 4 | AE11: =+AD26 -> 0
C12: Domingo | AB12: =(SUM(D12:AA12)) -> 0 | AC12: 4 | AE12: =+AD30 -> 0
C13: Festivo | AB13: =(SUM(D13:AA13)) -> 0 | AC13: 0 | AE13: =+AD34 -> 0
B14: 46082 | C14: Hábil | AB14: =(SUM(D14:AA14)) -> 0 | AC14: 21 | AD14: =(AB14*AC14)+(AB15*AC15)+(AB16*AC16)+(AB17*AC17) -> 0 | AE14: =+AD38 -> 0
C15: Sábado | AB15: =(SUM(D15:AA15)) -> 0 | AC15: 4 | AE15: =+AD42 -> 0
C16: Domingo | AB16: =(SUM(D16:AA16)) -> 0 | AC16: 5 | AE16: =+AD46 -> 3500006.4
C17: Festivo | AB17: =(SUM(D17:AA17)) -> 0 | AC17: 1 | AE17: =+AD50 -> 7000005.8
B18: 46113 | C18: Hábil | AB18: =(SUM(D18:AA18)) -> 0 | AC18: 20 | AD18: =(AB18*AC18)+(AB19*AC19)+(AB20*AC20)+(AB21*AC21) -> 0 | AE18: =+#REF! -> #REF!
C19: Sábado | AB19: =(SUM(D19:AA19)) -> 0 | AC19: 4 | AE19: =+#REF! -> #REF!
C20: Domingo | AB20: =(SUM(D20:AA20)) -> 0 | AC20: 4 | AE20: =+#REF! -> #REF!
C21: Festivo | AB21: =(SUM(D21:AA21)) -> 0 | AC21: 2 | AE21: =+#REF! -> #REF!
B22: 46143 | C22: Hábil | AB22: =(SUM(D22:AA22)) -> 0 | AC22: 19 | AD22: =(AB22*AC22)+(AB23*AC23)+(AB24*AC24)+(AB25*AC25) -> 0 | AE22: =+#REF! -> #REF!
C23: Sábado | AB23: =(SUM(D23:AA23)) -> 0 | AC23: 5 | AE23: =+#REF! -> #REF!
C24: Domingo | AB24: =(SUM(D24:AA24)) -> 0 | AC24: 5 | AE24: =+#REF! -> #REF!
C25: Festivo | AB25: =(SUM(D25:AA25)) -> 0 | AC25: 2 | AE25: =+#REF! -> #REF!
B26: 46174 | C26: Hábil | AB26: =(SUM(D26:AA26)) -> 0 | AC26: 19 | AD26: =(AB26*AC26)+(AB27*AC27)+(AB28*AC28)+(AB29*AC29) -> 0 | AE26: =+#REF! -> #REF!
C27: Sábado | AB27: =(SUM(D27:AA27)) -> 0 | AC27: 4 | AE27: =+#REF! -> #REF!
C28: Domingo | AB28: =(SUM(D28:AA28)) -> 0 | AC28: 4 | AE28: =+#REF! -> #REF!
C29: Festivo | AB29: =(SUM(D29:AA29)) -> 0 | AC29: 3 | AE29: =+#REF! -> #REF!
B30: 46204 | C30: Hábil | AB30: =(SUM(D30:AA30)) -> 0 | AC30: 21 | AD30: =(AB30*AC30)+(AB31*AC31)+(AB32*AC32)+(AB33*AC33) -> 0 | AE30: =+#REF! -> #REF!
C31: Sábado | AB31: =(SUM(D31:AA31)) -> 0 | AC31: 4 | AE31: =+#REF! -> #REF!
C32: domingo | AB32: =(SUM(D32:AA32)) -> 0 | AC32: 4 | AE32: =+#REF! -> #REF!
C33: Festivo | AB33: =(SUM(D33:AA33)) -> 0 | AC33: 1 | AE33: =+#REF! -> #REF!
B34: 46235 | C34: Hábil | AB34: =(SUM(D34:AA34)) -> 0 | AC34: 19 | AD34: =(AB34*AC34)+(AB35*AC35)+(AB36*AC36)+(AB37*AC37) -> 0 | AE34: =+#REF! -> #REF!
C35: Sábado | AB35: =(SUM(D35:AA35)) -> 0 | AC35: 5 | AE35: =+#REF! -> #REF!
C36: Domingo | AB36: =(SUM(D36:AA36)) -> 0 | AC36: 5 | AE36: =+#REF! -> #REF!
C37: Festivo | AB37: =(SUM(D37:AA37)) -> 0 | AC37: 2 | AE37: =+#REF! -> #REF!
B38: 46266 | C38: Hábil | AB38: =(SUM(D38:AA38)) -> 0 | AC38: 22 | AD38: =(AB38*AC38)+(AB39*AC39)+(AB40*AC40)+(AB41*AC41) -> 0 | AE38: =+#REF! -> #REF!
C39: Sábado | AB39: =(SUM(D39:AA39)) -> 0 | AC39: 4 | AE39: =+#REF! -> #REF!
C40: Domingo | AB40: =(SUM(D40:AA40)) -> 0 | AC40: 4 | AE40: =+#REF! -> #REF!
C41: Festivo | AB41: =(SUM(D41:AA41)) -> 0 | AC41: 0 | AE41: =+#REF! -> #REF!
...

Sheet Anexo 2 Producto 2
B4: ANEXO 2 - OFERTA PRODUCTO 2
B5: NOMBRE DEL OFERENTE
B6: PRECIOS Y CANTIDADES DE ENERGIA OFERTADA
B7: EN PESOS DE MARZO 2026
B8: PRODUCTO 2
B9: AÑO | C9: MES | D9: PERIODO 2026
D10: E. Solicitada [kWh] | E10: % E. Ofertado | F10: E. Ofertada [kWh] | G10: $/kWh
B11: 2026 | C11: Enero | D11: =+'Producto 2 Plano 26'!AE6 -> 0 | F11: =+$E$11*D11 -> 0
B12: 2026 | C12: Febrero | D12: =+'Producto 2 Plano 26'!AE7 -> 0 | F12: =+$E$11*D12 -> 0
B13: 2026 | C13: Marzo | D13: =+'Producto 2 Plano 26'!AE8 -> 0 | F13: =+$E$11*D13 -> 0
B14: 2026 | C14: Abril | D14: =+'Producto 2 Plano 26'!AE9 -> 0 | F14: =+$E$11*D14 -> 0
B15: 2026 | C15: Mayo | D15: =+'Producto 2 Plano 26'!AE10 -> 0 | F15: =+$E$11*D15 -> 0
B16: 2026 | C16: Junio | D16: =+'Producto 2 Plano 26'!AE11 -> 0 | F16: =+$E$11*D16 -> 0
B17: 2026 | C17: Julio | D17: =+'Producto 2 Plano 26'!AE12 -> 0 | F17: =+$E$11*D17 -> 0
B18: 2026 | C18: Agosto | D18: =+'Producto 2 Plano 26'!AE13 -> 0 | F18: =+$E$11*D18 -> 0
B19: 2026 | C19: Septiembre | D19: =+'Producto 2 Plano 26'!AE14 -> 0 | F19: =+$E$11*D19 -> 0
B20: 2026 | C20: Octubre | D20: =+'Producto 2 Plano 26'!AE15 -> 0 | F20: =+$E$11*D20 -> 0
B21: 2026 | C21: Noviembre | D21: =+'Producto 2 Plano 26'!AE16 -> 3500006.4 | F21: =+$E$11*D21 -> 0
B22: 2026 | C22: Diciembre | D22: =+'Producto 2 Plano 26'!AE17 -> 7000005.8 | F22: =+$E$11*D22 -> 0 | H22: =SUM(D11:D22) -> 10500012 | I22: =+H22/1000 -> 10500.012
B23: Total Producto 2 | D23: =+SUM(D11:D22) -> 10500012 | I23: =+D23/1000 -> 10500.012
B25: E. Solicitada = Energía solicitada por RUITOQUE para el producto.
B26: % E. Ofertado = Porcentaje de energía ofertado por el agente respecto a la E. Solicitada.
B27: E. Ofertada = Energía ofertada por el agente, producto de la E. Solicitada y el % E. Ofertado.
B28: $/kWh = Tarifa de la oferta para todas las horas del mes.

Sheet Producto 3 Plano 29-36
B2: ANEXO 1 - CANTIDADES DE ENERGÍA SOLICITADA EN kWh
B3: PRODUCTO 3
B4: PERIODO 01 DE ENERO DEL 2029 A DICIEMBRE 31 DE 2036
C5: DIA | D5: 1 | E5: 2 | F5: 3 | G5: 4 | H5: 5 | I5: 6 | J5: 7 | K5: 8 | L5: 9 | M5: 10 | N5: 11 | O5: 12 | P5: 13 | Q5: 14 | R5: 15 | S5: 16 | T5: 17 | U5: 18 | V5: 19 | W5: 20 | X5: 21 | Y5: 22 | Z5: 23 | AA5: 24 | AB5: Total | AC5: No. DÍAS | AD5: Total
B6: 47119 | C6: Hábil | D6: 19551.6 | E6: =+$D$6 -> 19551.6 | F6: =+$D$6 -> 19551.6 | G6: =+$D$6 -> 19551.6 | H6: =+$D$6 -> 19551.6 | I6: =+$D$6 -> 19551.6 | J6: =+$D$6 -> 19551.6 | K6: =+$D$6 -> 19551.6 | L6: =+$D$6 -> 19551.6 | ... AA6: =+$D$6 -> 19551.6 | AB6: =(SUM(D6:AA6)) -> 469238.4 | AC6: 21 | AD6: =(AB6*AC6)+(AB7*AC7)+(AB8*AC8)+(AB9*AC9) -> 14546390 | AE6: =+AD6 -> 14546390
C7: Sábado | D7: =+$D$6 -> 19551.6 | E7: =+$D$6 -> 19551.6 | F7: =+$D$6 -> 19551.6 | G7: =+$D$6 -> 19551.6 | H7: =+$D$6 -> 19551.6 | I7: =+$D$6 -> 19551.6 | J7: =+$D$6 -> 19551.6 | K7: =+$D$6 -> 19551.6 | ... AA7: =+$D$6 -> 19551.6 | AB7: =(SUM(D7:AA7)) -> 469238.4 | AC7: 4 | AE7: =+AD10 -> 13138675
C8: Domingo | D8: =+$D$6 -> 19551.6 | E8: =+$D$6 -> 19551.6 | F8: =+$D$6 -> 19551.6 | G8: =+$D$6 -> 19551.6 | H8: =+$D$6 -> 19551.6 | I8: =+$D$6 -> 19551.6 | J8: =+$D$6 -> 19551.6 | K8: =+$D$6 -> 19551.6 | ... AA8: =+$D$6 -> 19551.6 | AB8: =(SUM(D8:AA8)) -> 469238.4 | AC8: 4 | AE8: =+AD14 -> 14546390
C9: Festivo | D9: =+$D$6 -> 19551.6 | E9: =+$D$6 -> 19551.6 | F9: =+$D$6 -> 19551.6 | G9: =+$D$6 -> 19551.6 | H9: =+$D$6 -> 19551.6 | I9: =+$D$6 -> 19551.6 | J9: =+$D$6 -> 19551.6 | K9: =+$D$6 -> 19551.6 | ... AA9: =+$D$6 -> 19551.6 | AB9: =(SUM(D9:AA9)) -> 469238.4 | AC9: 2 | AE9: =+AD18 -> 14077152
B10: 47150 | C10: Hábil | D10: =+$D$6 -> 19551.6 | E10: =+$D$6 -> 19551.6 | F10: =+$D$6 -> 19551.6 | G10: =+$D$6 -> 19551.6 | H10: =+$D$6 -> 19551.6 | I10: =+$D$6 -> 19551.6 | J10: =+$D$6 -> 19551.6 | K10: =+$D$6 -> 19551.6 | ... AA10: =+$D$6 -> 19551.6 | AB10: =(SUM(D10:AA10)) -> 469238.4 | AC10: 20 | AD10: =(AB10*AC10)+(AB11*AC11)+(AB12*AC12)+(AB13*AC13) -> 13138675 | AE10: =+AD22 -> 14546390
C11: Sábado | D11: =+$D$6 -> 19551.6 | E11: =+$D$6 -> 19551.6 | F11: =+$D$6 -> 19551.6 | G11: =+$D$6 -> 19551.6 | H11: =+$D$6 -> 19551.6 | I11: =+$D$6 -> 19551.6 | J11: =+$D$6 -> 19551.6 | K11: =+$D$6 -> 19551.6 | ... AA11: =+$D$6 -> 19551.6 | AB11: =(SUM(D11:AA11)) -> 469238.4 | AC11: 4 | AE11: =+AD26 -> 14077152
C12: Domingo | D12: =+$D$6 -> 19551.6 | E12: =+$D$6 -> 19551.6 | F12: =+$D$6 -> 19551.6 | G12: =+$D$6 -> 19551.6 | H12: =+$D$6 -> 19551.6 | I12: =+$D$6 -> 19551.6 | J12: =+$D$6 -> 19551.6 | K12: =+$D$6 -> 19551.6 | ... AA12: =+$D$6 -> 19551.6 | AB12: =(SUM(D12:AA12)) -> 469238.4 | AC12: 4 | AE12: =+AD30 -> 14546390
C13: Festivo | D13: =+$D$6 -> 19551.6 | E13: =+$D$6 -> 19551.6 | F13: =+$D$6 -> 19551.6 | G13: =+$D$6 -> 19551.6 | H13: =+$D$6 -> 19551.6 | I13: =+$D$6 -> 19551.6 | J13: =+$D$6 -> 19551.6 | K13: =+$D$6 -> 19551.6 | ... AA13: =+$D$6 -> 19551.6 | AB13: =(SUM(D13:AA13)) -> 469238.4 | AC13: 0 | AE13: =+AD34 -> 14546390
B14: 47178 | C14: Hábil | D14: =+$D$6 -> 19551.6 | E14: =+$D$6 -> 19551.6 | F14: =+$D$6 -> 19551.6 | G14: =+$D$6 -> 19551.6 | H14: =+$D$6 -> 19551.6 | I14: =+$D$6 -> 19551.6 | J14: =+$D$6 -> 19551.6 | K14: =+$D$6 -> 19551.6 | ... AA14: =+$D$6 -> 19551.6 | AB14: =(SUM(D14:AA14)) -> 469238.4 | AC14: 19 | AD14: =(AB14*AC14)+(AB15*AC15)+(AB16*AC16)+(AB17*AC17) -> 14546390 | AE14: =+AD38 -> 14077152
C15: Sábado | D15: =+$D$6 -> 19551.6 | E15: =+$D$6 -> 19551.6 | F15: =+$D$6 -> 19551.6 | G15: =+$D$6 -> 19551.6 | H15: =+$D$6 -> 19551.6 | I15: =+$D$6 -> 19551.6 | J15: =+$D$6 -> 19551.6 | K15: =+$D$6 -> 19551.6 | ... AA15: =+$D$6 -> 19551.6 | AB15: =(SUM(D15:AA15)) -> 469238.4 | AC15: 5 | AE15: =+AD42 -> 14546390
C16: Domingo | D16: =+$D$6 -> 19551.6 | E16: =+$D$6 -> 19551.6 | F16: =+$D$6 -> 19551.6 | G16: =+$D$6 -> 19551.6 | H16: =+$D$6 -> 19551.6 | I16: =+$D$6 -> 19551.6 | J16: =+$D$6 -> 19551.6 | K16: =+$D$6 -> 19551.6 | ... AA16: =+$D$6 -> 19551.6 | AB16: =(SUM(D16:AA16)) -> 469238.4 | AC16: 4 | AE16: =+AD46 -> 14077152
C17: Festivo | D17: =+$D$6 -> 19551.6 | E17: =+$D$6 -> 19551.6 | F17: =+$D$6 -> 19551.6 | G17: =+$D$6 -> 19551.6 | H17: =+$D$6 -> 19551.6 | I17: =+$D$6 -> 19551.6 | J17: =+$D$6 -> 19551.6 | K17: =+$D$6 -> 19551.6 | ... AA17: =+$D$6 -> 19551.6 | AB17: =(SUM(D17:AA17)) -> 469238.4 | AC17: 3 | AE17: =+AD50 -> 14546390
B18: 47209 | C18: Hábil | D18: =+$D$6 -> 19551.6 | E18: =+$D$6 -> 19551.6 | F18: =+$D$6 -> 19551.6 | G18: =+$D$6 -> 19551.6 | H18: =+$D$6 -> 19551.6 | I18: =+$D$6 -> 19551.6 | J18: =+$D$6 -> 19551.6 | K18: =+$D$6 -> 19551.6 | ... AA18: =+$D$6 -> 19551.6 | AB18: =(SUM(D18:AA18)) -> 469238.4 | AC18: 21 | AD18: =(AB18*AC18)+(AB19*AC19)+(AB20*AC20)+(AB21*AC21) -> 14077152 | AE18: 11534887
C19: Sábado | D19: =+$D$6 -> 19551.6 | E19: =+$D$6 -> 19551.6 | F19: =+$D$6 -> 19551.6 | G19: =+$D$6 -> 19551.6 | H19: =+$D$6 -> 19551.6 | I19: =+$D$6 -> 19551.6 | J19: =+$D$6 -> 19551.6 | K19: =+$D$6 -> 19551.6 | ... AA19: =+$D$6 -> 19551.6 | AB19: =(SUM(D19:AA19)) -> 469238.4 | AC19: 4 | AE19: 10418607
C20: Domingo | D20: =+$D$6 -> 19551.6 | E20: =+$D$6 -> 19551.6 | F20: =+$D$6 -> 19551.6 | G20: =+$D$6 -> 19551.6 | H20: =+$D$6 -> 19551.6 | I20: =+$D$6 -> 19551.6 | J20: =+$D$6 -> 19551.6 | K20: =+$D$6 -> 19551.6 | ... AA20: =+$D$6 -> 19551.6 | AB20: =(SUM(D20:AA20)) -> 469238.4 | AC20: 5 | AE20: 11534887
C21: Festivo | D21: =+$D$6 -> 19551.6 | E21: =+$D$6 -> 19551.6 | F21: =+$D$6 -> 19551.6 | G21: =+$D$6 -> 19551.6 | H21: =+$D$6 -> 19551.6 | I21: =+$D$6 -> 19551.6 | J21: =+$D$6 -> 19551.6 | K21: =+$D$6 -> 19551.6 | ... AA21: =+$D$6 -> 19551.6 | AB21: =(SUM(D21:AA21)) -> 469238.4 | AC21: 0 | AE21: 11162794
B22: 47239 | C22: Hábil | D22: =+$D$6 -> 19551.6 | E22: =+$D$6 -> 19551.6 | F22: =+$D$6 -> 19551.6 | G22: =+$D$6 -> 19551.6 | H22: =+$D$6 -> 19551.6 | I22: =+$D$6 -> 19551.6 | J22: =+$D$6 -> 19551.6 | K22: =+$D$6 -> 19551.6 | ... AA22: =+$D$6 -> 19551.6 | AB22: =(SUM(D22:AA22)) -> 469238.4 | AC22: 21 | AD22: =(AB22*AC22)+(AB23*AC23)+(AB24*AC24)+(AB25*AC25) -> 14546390 | AE22: 11534887
C23: Sábado | D23: =+$D$6 -> 19551.6 | E23: =+$D$6 -> 19551.6 | F23: =+$D$6 -> 19551.6 | G23: =+$D$6 -> 19551.6 | H23: =+$D$6 -> 19551.6 | I23: =+$D$6 -> 19551.6 | J23: =+$D$6 -> 19551.6 | K23: =+$D$6 -> 19551.6 | ... AA23: =+$D$6 -> 19551.6 | AB23: =(SUM(D23:AA23)) -> 469238.4 | AC23: 4 | AE23: 11162794
C24: Domingo | D24: =+$D$6 -> 19551.6 | E24: =+$D$6 -> 19551.6 | F24: =+$D$6 -> 19551.6 | G24: =+$D$6 -> 19551.6 | H24: =+$D$6 -> 19551.6 | I24: =+$D$6 -> 19551.6 | J24: =+$D$6 -> 19551.6 | K24: =+$D$6 -> 19551.6 | ... AA24: =+$D$6 -> 19551.6 | AB24: =(SUM(D24:AA24)) -> 469238.4 | AC24: 4 | AE24: 11534887
C25: Festivo | D25: =+$D$6 -> 19551.6 | E25: =+$D$6 -> 19551.6 | F25: =+$D$6 -> 19551.6 | G25: =+$D$6 -> 19551.6 | H25: =+$D$6 -> 19551.6 | I25: =+$D$6 -> 19551.6 | J25: =+$D$6 -> 19551.6 | K25: =+$D$6 -> 19551.6 | ... AA25: =+$D$6 -> 19551.6 | AB25: =(SUM(D25:AA25)) -> 469238.4 | AC25: 2 | AE25: 11534887
B26: 47270 | C26: Hábil | D26: =+$D$6 -> 19551.6 | E26: =+$D$6 -> 19551.6 | F26: =+$D$6 -> 19551.6 | G26: =+$D$6 -> 19551.6 | H26: =+$D$6 -> 19551.6 | I26: =+$D$6 -> 19551.6 | J26: =+$D$6 -> 19551.6 | K26: =+$D$6 -> 19551.6 | ... AA26: =+$D$6 -> 19551.6 | AB26: =(SUM(D26:AA26)) -> 469238.4 | AC26: 19 | AD26: =(AB26*AC26)+(AB27*AC27)+(AB28*AC28)+(AB29*AC29) -> 14077152 | AE26: 11162794
C27: Sábado | D27: =+$D$6 -> 19551.6 | E27: =+$D$6 -> 19551.6 | F27: =+$D$6 -> 19551.6 | G27: =+$D$6 -> 19551.6 | H27: =+$D$6 -> 19551.6 | I27: =+$D$6 -> 19551.6 | J27: =+$D$6 -> 19551.6 | K27: =+$D$6 -> 19551.6 | ... AA27: =+$D$6 -> 19551.6 | AB27: =(SUM(D27:AA27)) -> 469238.4 | AC27: 5 | AE27: 11534887
C28: Domingo | D28: =+$D$6 -> 19551.6 | E28: =+$D$6 -> 19551.6 | F28: =+$D$6 -> 19551.6 | G28: =+$D$6 -> 19551.6 | H28: =+$D$6 -> 19551.6 | I28: =+$D$6 -> 19551.6 | J28: =+$D$6 -> 19551.6 | K28: =+$D$6 -> 19551.6 | ... AA28: =+$D$6 -> 19551.6 | AB28: =(SUM(D28:AA28)) -> 469238.4 | AC28: 4 | AE28: 11162794
C29: Festivo | D29: =+$D$6 -> 19551.6 | E29: =+$D$6 -> 19551.6 | F29: =+$D$6 -> 19551.6 | G29: =+$D$6 -> 19551.6 | H29: =+$D$6 -> 19551.6 | I29: =+$D$6 -> 19551.6 | J29: =+$D$6 -> 19551.6 | K29: =+$D$6 -> 19551.6 | ... AA29: =+$D$6 -> 19551.6 | AB29: =(SUM(D29:AA29)) -> 469238.4 | AC29: 2 | AE29: 11534887
B30: 47300 | C30: Hábil | D30: =+$D$6 -> 19551.6 | E30: =+$D$6 -> 19551.6 | F30: =+$D$6 -> 19551.6 | G30: =+$D$6 -> 19551.6 | H30: =+$D$6 -> 19551.6 | I30: =+$D$6 -> 19551.6 | J30: =+$D$6 -> 19551.6 | K30: =+$D$6 -> 19551.6 | ... AA30: =+$D$6 -> 19551.6 | AB30: =(SUM(D30:AA30)) -> 469238.4 | AC30: 20 | AD30: =(AB30*AC30)+(AB31*AC31)+(AB32*AC32)+(AB33*AC33) -> 14546390 | AE30: 13229220
C31: Sábado | D31: =+$D$6 -> 19551.6 | E31: =+$D$6 -> 19551.6 | F31: =+$D$6 -> 19551.6 | G31: =+$D$6 -> 19551.6 | H31: =+$D$6 -> 19551.6 | I31: =+$D$6 -> 19551.6 | J31: =+$D$6 -> 19551.6 | K31: =+$D$6 -> 19551.6 | ... AA31: =+$D$6 -> 19551.6 | AB31: =(SUM(D31:AA31)) -> 469238.4 | AC31: 4 | AE31: 11948973
C32: domingo | D32: =+$D$6 -> 19551.6 | E32: =+$D$6 -> 19551.6 | F32: =+$D$6 -> 19551.6 | G32: =+$D$6 -> 19551.6 | H32: =+$D$6 -> 19551.6 | I32: =+$D$6 -> 19551.6 | J32: =+$D$6 -> 19551.6 | K32: =+$D$6 -> 19551.6 | ... AA32: =+$D$6 -> 19551.6 | AB32: =(SUM(D32:AA32)) -> 469238.4 | AC32: 5 | AE32: 13229220
C33: Festivo | D33: =+$D$6 -> 19551.6 | E33: =+$D$6 -> 19551.6 | F33: =+$D$6 -> 19551.6 | G33: =+$D$6 -> 19551.6 | H33: =+$D$6 -> 19551.6 | I33: =+$D$6 -> 19551.6 | J33: =+$D$6 -> 19551.6 | K33: =+$D$6 -> 19551.6 | ... AA33: =+$D$6 -> 19551.6 | AB33: =(SUM(D33:AA33)) -> 469238.4 | AC33: 2 | AE33: 12802471
B34: 47331 | C34: Hábil | D34: =+$D$6 -> 19551.6 | E34: =+$D$6 -> 19551.6 | F34: =+$D$6 -> 19551.6 | G34: =+$D$6 -> 19551.6 | H34: =+$D$6 -> 19551.6 | I34: =+$D$6 -> 19551.6 | J34: =+$D$6 -> 19551.6 | K34: =+$D$6 -> 19551.6 | ... AA34: =+$D$6 -> 19551.6 | AB34: =(SUM(D34:AA34)) -> 469238.4 | AC34: 21 | AD34: =(AB34*AC34)+(AB35*AC35)+(AB36*AC36)+(AB37*AC37) -> 14546390 | AE34: 13229220
C35: Sábado | D35: =+$D$6 -> 19551.6 | E35: =+$D$6 -> 19551.6 | F35: =+$D$6 -> 19551.6 | G35: =+$D$6 -> 19551.6 | H35: =+$D$6 -> 19551.6 | I35: =+$D$6 -> 19551.6 | J35: =+$D$6 -> 19551.6 | K35: =+$D$6 -> 19551.6 | ... AA35: =+$D$6 -> 19551.6 | AB35: =(SUM(D35:AA35)) -> 469238.4 | AC35: 4 | AE35: 12802471
C36: Domingo | D36: =+$D$6 -> 19551.6 | E36: =+$D$6 -> 19551.6 | F36: =+$D$6 -> 19551.6 | G36: =+$D$6 -> 19551.6 | H36: =+$D$6 -> 19551.6 | I36: =+$D$6 -> 19551.6 | J36: =+$D$6 -> 19551.6 | K36: =+$D$6 -> 19551.6 | ... AA36: =+$D$6 -> 19551.6 | AB36: =(SUM(D36:AA36)) -> 469238.4 | AC36: 4 | AE36: 13229220
C37: Festivo | D37: =+$D$6 -> 19551.6 | E37: =+$D$6 -> 19551.6 | F37: =+$D$6 -> 19551.6 | G37: =+$D$6 -> 19551.6 | H37: =+$D$6 -> 19551.6 | I37: =+$D$6 -> 19551.6 | J37: =+$D$6 -> 19551.6 | K37: =+$D$6 -> 19551.6 | ... AA37: =+$D$6 -> 19551.6 | AB37: =(SUM(D37:AA37)) -> 469238.4 | AC37: 2 | AE37: 13229220
B38: 47362 | C38: Hábil | D38: =+$D$6 -> 19551.6 | E38: =+$D$6 -> 19551.6 | F38: =+$D$6 -> 19551.6 | G38: =+$D$6 -> 19551.6 | H38: =+$D$6 -> 19551.6 | I38: =+$D$6 -> 19551.6 | J38: =+$D$6 -> 19551.6 | K38: =+$D$6 -> 19551.6 | ... AA38: =+$D$6 -> 19551.6 | AB38: =(SUM(D38:AA38)) -> 469238.4 | AC38: 20 | AD38: =(AB38*AC38)+(AB39*AC39)+(AB40*AC40)+(AB41*AC41) -> 14077152 | AE38: 12802471
C39: Sábado | D39: =+$D$6 -> 19551.6 | E39: =+$D$6 -> 19551.6 | F39: =+$D$6 -> 19551.6 | G39: =+$D$6 -> 19551.6 | H39: =+$D$6 -> 19551.6 | I39: =+$D$6 -> 19551.6 | J39: =+$D$6 -> 19551.6 | K39: =+$D$6 -> 19551.6 | ... AA39: =+$D$6 -> 19551.6 | AB39: =(SUM(D39:AA39)) -> 469238.4 | AC39: 5 | AE39: 13229220
C40: Domingo | D40: =+$D$6 -> 19551.6 | E40: =+$D$6 -> 19551.6 | F40: =+$D$6 -> 19551.6 | G40: =+$D$6 -> 19551.6 | H40: =+$D$6 -> 19551.6 | I40: =+$D$6 -> 19551.6 | J40: =+$D$6 -> 19551.6 | K40: =+$D$6 -> 19551.6 | ... AA40: =+$D$6 -> 19551.6 | AB40: =(SUM(D40:AA40)) -> 469238.4 | AC40: 5 | AE40: 12802471
C41: Festivo | D41: =+$D$6 -> 19551.6 | E41: =+$D$6 -> 19551.6 | F41: =+$D$6 -> 19551.6 | G41: =+$D$6 -> 19551.6 | H41: =+$D$6 -> 19551.6 | I41: =+$D$6 -> 19551.6 | J41: =+$D$6 -> 19551.6 | K41: =+$D$6 -> 19551.6 | ... AA41: =+$D$6 -> 19551.6 | AB41: =(SUM(D41:AA41)) -> 469238.4 | AC41: 0 | AE41: 13229220
...

Sheet Anexo 2 Producto 3
B4: ANEXO 2 - OFERTA PRODUCTO 3
B5: NOMBRE DEL OFERENTE
B6: PRECIOS Y CANTIDADES DE ENERGIA OFERTADA
B7: EN PESOS DE MARZO 2026
B8: PRODUCTO 3
B9: AÑO | C9: MES | D9: PERIODO 2029 - 2036
D10: E. Solicitada [kWh] | E10: % E. Ofertado | F10: E. Ofertada [kWh] | G10: $/kWh
B11: 2029 | C11: Enero | D11: =+'Producto 3 Plano 29-36'!AE6 -> 14546390 | F11: =+E11*D11 -> 0 | I11: =+H11/1000 -> 0
B12: 2029 | C12: Febrero | D12: =+'Producto 3 Plano 29-36'!AE7 -> 13138675 | F12: =+E11*D12 -> 0
B13: 2029 | C13: Marzo | D13: =+'Producto 3 Plano 29-36'!AE8 -> 14546390 | F13: =+E11*D13 -> 0
B14: 2029 | C14: Abril | D14: =+'Producto 3 Plano 29-36'!AE9 -> 14077152 | F14: =+E11*D14 -> 0
B15: 2029 | C15: Mayo | D15: =+'Producto 3 Plano 29-36'!AE10 -> 14546390 | F15: =+E11*D15 -> 0
B16: 2029 | C16: Junio | D16: =+'Producto 3 Plano 29-36'!AE11 -> 14077152 | F16: =+E11*D16 -> 0
B17: 2029 | C17: Julio | D17: =+'Producto 3 Plano 29-36'!AE12 -> 14546390 | F17: =+E11*D17 -> 0
B18: 2029 | C18: Agosto | D18: =+'Producto 3 Plano 29-36'!AE13 -> 14546390 | F18: =+E11*D18 -> 0
B19: 2029 | C19: Septiembre | D19: =+'Producto 3 Plano 29-36'!AE14 -> 14077152 | F19: =+E11*D19 -> 0
B20: 2029 | C20: Octubre | D20: =+'Producto 3 Plano 29-36'!AE15 -> 14546390 | F20: =+E11*D20 -> 0
B21: 2029 | C21: Noviembre | D21: =+'Producto 3 Plano 29-36'!AE16 -> 14077152 | F21: =+E11*D21 -> 0
B22: 2029 | C22: Diciembre | D22: =+'Producto 3 Plano 29-36'!AE17 -> 14546390 | F22: =+E11*D22 -> 0
B23: 2030 | C23: Enero | D23: =+'Producto 3 Plano 29-36'!AE18 -> 11534887 | F23: =+E23*D23 -> 0 | I23: =+H23/1000 -> 0
B24: 2030 | C24: Febrero | D24: =+'Producto 3 Plano 29-36'!AE19 -> 10418607 | F24: =+E23*D24 -> 0
B25: 2030 | C25: Marzo | D25: =+'Producto 3 Plano 29-36'!AE20 -> 11534887 | F25: =+E23*D25 -> 0
B26: 2030 | C26: Abril | D26: =+'Producto 3 Plano 29-36'!AE21 -> 11162794 | F26: =+E23*D26 -> 0
B27: 2030 | C27: Mayo | D27: =+'Producto 3 Plano 29-36'!AE22 -> 11534887 | F27: =+E23*D27 -> 0
B28: 2030 | C28: Junio | D28: =+'Producto 3 Plano 29-36'!AE23 -> 11162794 | F28: =+E23*D28 -> 0
B29: 2030 | C29: Julio | D29: =+'Producto 3 Plano 29-36'!AE24 -> 11534887 | F29: =+E23*D29 -> 0
B30: 2030 | C30: Agosto | D30: =+'Producto 3 Plano 29-36'!AE25 -> 11534887 | F30: =+E23*D30 -> 0
B31: 2030 | C31: Septiembre | D31: =+'Producto 3 Plano 29-36'!AE26 -> 11162794 | F31: =+E23*D31 -> 0
B32: 2030 | C32: Octubre | D32: =+'Producto 3 Plano 29-36'!AE27 -> 11534887 | F32: =+E23*D32 -> 0
B33: 2030 | C33: Noviembre | D33: =+'Producto 3 Plano 29-36'!AE28 -> 11162794 | F33: =+E23*D33 -> 0
B34: 2030 | C34: Diciembre | D34: =+'Producto 3 Plano 29-36'!AE29 -> 11534887 | F34: =+E23*D34 -> 0
B35: 2031 | C35: Enero | D35: =+'Producto 3 Plano 29-36'!AE30 -> 13229220 | F35: =+E35*D35 -> 0 | I35: =+H35/1000 -> 0
B36: 2031 | C36: Febrero | D36: =+'Producto 3 Plano 29-36'!AE31 -> 11948973 | F36: =+E35*D36 -> 0
B37: 2031 | C37: Marzo | D37: =+'Producto 3 Plano 29-36'!AE32 -> 13229220 | F37: =+E35*D37 -> 0
B38: 2031 | C38: Abril | D38: =+'Producto 3 Plano 29-36'!AE33 -> 12802471 | F38: =+E35*D38 -> 0
B39: 2031 | C39: Mayo | D39: =+'Producto 3 Plano 29-36'!AE34 -> 13229220 | F39: =+E35*D39 -> 0
B40: 2031 | C40: Junio | D40: =+'Producto 3 Plano 29-36'!AE35 -> 12802471 | F40: =+E35*D40 -> 0
B41: 2031 | C41: Julio | D41: =+'Producto 3 Plano 29-36'!AE36 -> 13229220 | F41: =+E35*D41 -> 0
B42: 2031 | C42: Agosto | D42: =+'Producto 3 Plano 29-36'!AE37 -> 13229220 | F42: =+E35*D42 -> 0
B43: 2031 | C43: Septiembre | D43: =+'Producto 3 Plano 29-36'!AE38 -> 12802471 | F43: =+E35*D43 -> 0
...

Sheet Producto 4 Plano 27
B2: ANEXO 1 - CANTIDADES DE ENERGÍA SOLICITADA EN kWh
B3: PRODUCTO 4
B4: PERIODO 01 DE ENERO DEL 2027 A DICIEMBRE 31 DE 2027
C5: DIA | D5: 1 | E5: 2 | F5: 3 | G5: 4 | H5: 5 | I5: 6 | J5: 7 | K5: 8 | L5: 9 | M5: 10 | N5: 11 | O5: 12 | P5: 13 | Q5: 14 | R5: 15 | S5: 16 | T5: 17 | U5: 18 | V5: 19 | W5: 20 | X5: 21 | Y5: 22 | Z5: 23 | AA5: 24 | AB5: Total | AC5: No. DÍAS | AD5: Total
B6: 46388 | C6: Hábil | D6: 8675.8 | E6: =+$D$6 -> 8675.8 | F6: =+$D$6 -> 8675.8 | G6: =+$D$6 -> 8675.8 | H6: =+$D$6 -> 8675.8 | I6: =+$D$6 -> 8675.8 | J6: =+$D$6 -> 8675.8 | K6: =+$D$6 -> 8675.8 | L6: =+$D$6 -> 8675.8 | ... AA6: =+$D$6 -> 8675.8 | AB6: =(SUM(D6:AA6)) -> 208219.2 | AC6: 19 | AD6: =(AB6*AC6)+(AB7*AC7)+(AB8*AC8)+(AB9*AC9) -> 6454795.2 | AE6: =+AD6 -> 6454795.2
C7: Sábado | D7: =+$D$6 -> 8675.8 | E7: =+$D$6 -> 8675.8 | F7: =+$D$6 -> 8675.8 | G7: =+$D$6 -> 8675.8 | H7: =+$D$6 -> 8675.8 | I7: =+$D$6 -> 8675.8 | J7: =+$D$6 -> 8675.8 | K7: =+$D$6 -> 8675.8 | ... AA7: =+$D$6 -> 8675.8 | AB7: =(SUM(D7:AA7)) -> 208219.2 | AC7: 5 | AE7: =+AD10 -> 5830137.6
C8: Domingo | D8: =+$D$6 -> 8675.8 | E8: =+$D$6 -> 8675.8 | F8: =+$D$6 -> 8675.8 | G8: =+$D$6 -> 8675.8 | H8: =+$D$6 -> 8675.8 | I8: =+$D$6 -> 8675.8 | J8: =+$D$6 -> 8675.8 | K8: =+$D$6 -> 8675.8 | ... AA8: =+$D$6 -> 8675.8 | AB8: =(SUM(D8:AA8)) -> 208219.2 | AC8: 5 | AE8: =+AD14 -> 6454795.2
C9: Festivo | D9: =+$D$6 -> 8675.8 | E9: =+$D$6 -> 8675.8 | F9: =+$D$6 -> 8675.8 | G9: =+$D$6 -> 8675.8 | H9: =+$D$6 -> 8675.8 | I9: =+$D$6 -> 8675.8 | J9: =+$D$6 -> 8675.8 | K9: =+$D$6 -> 8675.8 | ... AA9: =+$D$6 -> 8675.8 | AB9: =(SUM(D9:AA9)) -> 208219.2 | AC9: 2 | AE9: =+AD18 -> 6246576
B10: 46419 | C10: Hábil | D10: =+$D$6 -> 8675.8 | E10: =+$D$6 -> 8675.8 | F10: =+$D$6 -> 8675.8 | G10: =+$D$6 -> 8675.8 | H10: =+$D$6 -> 8675.8 | I10: =+$D$6 -> 8675.8 | J10: =+$D$6 -> 8675.8 | K10: =+$D$6 -> 8675.8 | ... AA10: =+$D$6 -> 8675.8 | AB10: =(SUM(D10:AA10)) -> 208219.2 | AC10: 20 | AD10: =(AB10*AC10)+(AB11*AC11)+(AB12*AC12)+(AB13*AC13) -> 5830137.6 | AE10: =+AD22 -> 6454795.2
C11: Sábado | D11: =+$D$6 -> 8675.8 | E11: =+$D$6 -> 8675.8 | F11: =+$D$6 -> 8675.8 | G11: =+$D$6 -> 8675.8 | H11: =+$D$6 -> 8675.8 | I11: =+$D$6 -> 8675.8 | J11: =+$D$6 -> 8675.8 | K11: =+$D$6 -> 8675.8 | ... AA11: =+$D$6 -> 8675.8 | AB11: =(SUM(D11:AA11)) -> 208219.2 | AC11: 4 | AE11: =+AD26 -> 6246576
C12: Domingo | D12: =+$D$6 -> 8675.8 | E12: =+$D$6 -> 8675.8 | F12: =+$D$6 -> 8675.8 | G12: =+$D$6 -> 8675.8 | H12: =+$D$6 -> 8675.8 | I12: =+$D$6 -> 8675.8 | J12: =+$D$6 -> 8675.8 | K12: =+$D$6 -> 8675.8 | ... AA12: =+$D$6 -> 8675.8 | AB12: =(SUM(D12:AA12)) -> 208219.2 | AC12: 4 | AE12: =+AD30 -> 6454795.2
C13: Festivo | D13: =+$D$6 -> 8675.8 | E13: =+$D$6 -> 8675.8 | F13: =+$D$6 -> 8675.8 | G13: =+$D$6 -> 8675.8 | H13: =+$D$6 -> 8675.8 | I13: =+$D$6 -> 8675.8 | J13: =+$D$6 -> 8675.8 | K13: =+$D$6 -> 8675.8 | ... AA13: =+$D$6 -> 8675.8 | AB13: =(SUM(D13:AA13)) -> 208219.2 | AC13: 0 | AE13: =+AD34 -> 6454795.2
B14: 46447 | C14: Hábil | D14: =+$D$6 -> 8675.8 | E14: =+$D$6 -> 8675.8 | F14: =+$D$6 -> 8675.8 | G14: =+$D$6 -> 8675.8 | H14: =+$D$6 -> 8675.8 | I14: =+$D$6 -> 8675.8 | J14: =+$D$6 -> 8675.8 | K14: =+$D$6 -> 8675.8 | ... AA14: =+$D$6 -> 8675.8 | AB14: =(SUM(D14:AA14)) -> 208219.2 | AC14: 20 | AD14: =(AB14*AC14)+(AB15*AC15)+(AB16*AC16)+(AB17*AC17) -> 6454795.2 | AE14: =+AD38 -> 6246576
C15: Sábado | D15: =+$D$6 -> 8675.8 | E15: =+$D$6 -> 8675.8 | F15: =+$D$6 -> 8675.8 | G15: =+$D$6 -> 8675.8 | H15: =+$D$6 -> 8675.8 | I15: =+$D$6 -> 8675.8 | J15: =+$D$6 -> 8675.8 | K15: =+$D$6 -> 8675.8 | ... AA15: =+$D$6 -> 8675.8 | AB15: =(SUM(D15:AA15)) -> 208219.2 | AC15: 4 | AE15: =+AD42 -> 6454795.2
C16: Domingo | D16: =+$D$6 -> 8675.8 | E16: =+$D$6 -> 8675.8 | F16: =+$D$6 -> 8675.8 | G16: =+$D$6 -> 8675.8 | H16: =+$D$6 -> 8675.8 | I16: =+$D$6 -> 8675.8 | J16: =+$D$6 -> 8675.8 | K16: =+$D$6 -> 8675.8 | ... AA16: =+$D$6 -> 8675.8 | AB16: =(SUM(D16:AA16)) -> 208219.2 | AC16: 4 | AE16: =+AD46 -> 6246576
C17: Festivo | D17: =+$D$6 -> 8675.8 | E17: =+$D$6 -> 8675.8 | F17: =+$D$6 -> 8675.8 | G17: =+$D$6 -> 8675.8 | H17: =+$D$6 -> 8675.8 | I17: =+$D$6 -> 8675.8 | J17: =+$D$6 -> 8675.8 | K17: =+$D$6 -> 8675.8 | ... AA17: =+$D$6 -> 8675.8 | AB17: =(SUM(D17:AA17)) -> 208219.2 | AC17: 3 | AE17: =+AD50 -> 6454795.2
B18: 46478 | C18: Hábil | D18: =+$D$6 -> 8675.8 | E18: =+$D$6 -> 8675.8 | F18: =+$D$6 -> 8675.8 | G18: =+$D$6 -> 8675.8 | H18: =+$D$6 -> 8675.8 | I18: =+$D$6 -> 8675.8 | J18: =+$D$6 -> 8675.8 | K18: =+$D$6 -> 8675.8 | ... AA18: =+$D$6 -> 8675.8 | AB18: =(SUM(D18:AA18)) -> 208219.2 | AC18: 22 | AD18: =(AB18*AC18)+(AB19*AC19)+(AB20*AC20)+(AB21*AC21) -> 6246576
C19: Sábado | D19: =+$D$6 -> 8675.8 | E19: =+$D$6 -> 8675.8 | F19: =+$D$6 -> 8675.8 | G19: =+$D$6 -> 8675.8 | H19: =+$D$6 -> 8675.8 | I19: =+$D$6 -> 8675.8 | J19: =+$D$6 -> 8675.8 | K19: =+$D$6 -> 8675.8 | ... AA19: =+$D$6 -> 8675.8 | AB19: =(SUM(D19:AA19)) -> 208219.2 | AC19: 4
C20: Domingo | D20: =+$D$6 -> 8675.8 | E20: =+$D$6 -> 8675.8 | F20: =+$D$6 -> 8675.8 | G20: =+$D$6 -> 8675.8 | H20: =+$D$6 -> 8675.8 | I20: =+$D$6 -> 8675.8 | J20: =+$D$6 -> 8675.8 | K20: =+$D$6 -> 8675.8 | ... AA20: =+$D$6 -> 8675.8 | AB20: =(SUM(D20:AA20)) -> 208219.2 | AC20: 4
C21: Festivo | D21: =+$D$6 -> 8675.8 | E21: =+$D$6 -> 8675.8 | F21: =+$D$6 -> 8675.8 | G21: =+$D$6 -> 8675.8 | H21: =+$D$6 -> 8675.8 | I21: =+$D$6 -> 8675.8 | J21: =+$D$6 -> 8675.8 | K21: =+$D$6 -> 8675.8 | ... AA21: =+$D$6 -> 8675.8 | AB21: =(SUM(D21:AA21)) -> 208219.2 | AC21: 0
B22: 46508 | C22: Hábil | D22: =+$D$6 -> 8675.8 | E22: =+$D$6 -> 8675.8 | F22: =+$D$6 -> 8675.8 | G22: =+$D$6 -> 8675.8 | H22: =+$D$6 -> 8675.8 | I22: =+$D$6 -> 8675.8 | J22: =+$D$6 -> 8675.8 | K22: =+$D$6 -> 8675.8 | ... AA22: =+$D$6 -> 8675.8 | AB22: =(SUM(D22:AA22)) -> 208219.2 | AC22: 19 | AD22: =(AB22*AC22)+(AB23*AC23)+(AB24*AC24)+(AB25*AC25) -> 6454795.2
C23: Sábado | D23: =+$D$6 -> 8675.8 | E23: =+$D$6 -> 8675.8 | F23: =+$D$6 -> 8675.8 | G23: =+$D$6 -> 8675.8 | H23: =+$D$6 -> 8675.8 | I23: =+$D$6 -> 8675.8 | J23: =+$D$6 -> 8675.8 | K23: =+$D$6 -> 8675.8 | ... AA23: =+$D$6 -> 8675.8 | AB23: =(SUM(D23:AA23)) -> 208219.2 | AC23: 4
C24: Domingo | D24: =+$D$6 -> 8675.8 | E24: =+$D$6 -> 8675.8 | F24: =+$D$6 -> 8675.8 | G24: =+$D$6 -> 8675.8 | H24: =+$D$6 -> 8675.8 | I24: =+$D$6 -> 8675.8 | J24: =+$D$6 -> 8675.8 | K24: =+$D$6 -> 8675.8 | ... AA24: =+$D$6 -> 8675.8 | AB24: =(SUM(D24:AA24)) -> 208219.2 | AC24: 5
C25: Festivo | D25: =+$D$6 -> 8675.8 | E25: =+$D$6 -> 8675.8 | F25: =+$D$6 -> 8675.8 | G25: =+$D$6 -> 8675.8 | H25: =+$D$6 -> 8675.8 | I25: =+$D$6 -> 8675.8 | J25: =+$D$6 -> 8675.8 | K25: =+$D$6 -> 8675.8 | ... AA25: =+$D$6 -> 8675.8 | AB25: =(SUM(D25:AA25)) -> 208219.2 | AC25: 3
B26: 46539 | C26: Hábil | D26: =+$D$6 -> 8675.8 | E26: =+$D$6 -> 8675.8 | F26: =+$D$6 -> 8675.8 | G26: =+$D$6 -> 8675.8 | H26: =+$D$6 -> 8675.8 | I26: =+$D$6 -> 8675.8 | J26: =+$D$6 -> 8675.8 | K26: =+$D$6 -> 8675.8 | ... AA26: =+$D$6 -> 8675.8 | AB26: =(SUM(D26:AA26)) -> 208219.2 | AC26: 21 | AD26: =(AB26*AC26)+(AB27*AC27)+(AB28*AC28)+(AB29*AC29) -> 6246576
C27: Sábado | D27: =+$D$6 -> 8675.8 | E27: =+$D$6 -> 8675.8 | F27: =+$D$6 -> 8675.8 | G27: =+$D$6 -> 8675.8 | H27: =+$D$6 -> 8675.8 | I27: =+$D$6 -> 8675.8 | J27: =+$D$6 -> 8675.8 | K27: =+$D$6 -> 8675.8 | ... AA27: =+$D$6 -> 8675.8 | AB27: =(SUM(D27:AA27)) -> 208219.2 | AC27: 4
C28: Domingo | D28: =+$D$6 -> 8675.8 | E28: =+$D$6 -> 8675.8 | F28: =+$D$6 -> 8675.8 | G28: =+$D$6 -> 8675.8 | H28: =+$D$6 -> 8675.8 | I28: =+$D$6 -> 8675.8 | J28: =+$D$6 -> 8675.8 | K28: =+$D$6 -> 8675.8 | ... AA28: =+$D$6 -> 8675.8 | AB28: =(SUM(D28:AA28)) -> 208219.2 | AC28: 4
C29: Festivo | D29: =+$D$6 -> 8675.8 | E29: =+$D$6 -> 8675.8 | F29: =+$D$6 -> 8675.8 | G29: =+$D$6 -> 8675.8 | H29: =+$D$6 -> 8675.8 | I29: =+$D$6 -> 8675.8 | J29: =+$D$6 -> 8675.8 | K29: =+$D$6 -> 8675.8 | ... AA29: =+$D$6 -> 8675.8 | AB29: =(SUM(D29:AA29)) -> 208219.2 | AC29: 1
B30: 46569 | C30: Hábil | D30: =+$D$6 -> 8675.8 | E30: =+$D$6 -> 8675.8 | F30: =+$D$6 -> 8675.8 | G30: =+$D$6 -> 8675.8 | H30: =+$D$6 -> 8675.8 | I30: =+$D$6 -> 8675.8 | J30: =+$D$6 -> 8675.8 | K30: =+$D$6 -> 8675.8 | ... AA30: =+$D$6 -> 8675.8 | AB30: =(SUM(D30:AA30)) -> 208219.2 | AC30: 20 | AD30: =(AB30*AC30)+(AB31*AC31)+(AB32*AC32)+(AB33*AC33) -> 6454795.2
C31: Sábado | D31: =+$D$6 -> 8675.8 | E31: =+$D$6 -> 8675.8 | F31: =+$D$6 -> 8675.8 | G31: =+$D$6 -> 8675.8 | H31: =+$D$6 -> 8675.8 | I31: =+$D$6 -> 8675.8 | J31: =+$D$6 -> 8675.8 | K31: =+$D$6 -> 8675.8 | ... AA31: =+$D$6 -> 8675.8 | AB31: =(SUM(D31:AA31)) -> 208219.2 | AC31: 5
C32: domingo | D32: =+$D$6 -> 8675.8 | E32: =+$D$6 -> 8675.8 | F32: =+$D$6 -> 8675.8 | G32: =+$D$6 -> 8675.8 | H32: =+$D$6 -> 8675.8 | I32: =+$D$6 -> 8675.8 | J32: =+$D$6 -> 8675.8 | K32: =+$D$6 -> 8675.8 | ... AA32: =+$D$6 -> 8675.8 | AB32: =(SUM(D32:AA32)) -> 208219.2 | AC32: 4
C33: Festivo | D33: =+$D$6 -> 8675.8 | E33: =+$D$6 -> 8675.8 | F33: =+$D$6 -> 8675.8 | G33: =+$D$6 -> 8675.8 | H33: =+$D$6 -> 8675.8 | I33: =+$D$6 -> 8675.8 | J33: =+$D$6 -> 8675.8 | K33: =+$D$6 -> 8675.8 | ... AA33: =+$D$6 -> 8675.8 | AB33: =(SUM(D33:AA33)) -> 208219.2 | AC33: 2
B34: 46600 | C34: Hábil | D34: =+$D$6 -> 8675.8 | E34: =+$D$6 -> 8675.8 | F34: =+$D$6 -> 8675.8 | G34: =+$D$6 -> 8675.8 | H34: =+$D$6 -> 8675.8 | I34: =+$D$6 -> 8675.8 | J34: =+$D$6 -> 8675.8 | K34: =+$D$6 -> 8675.8 | ... AA34: =+$D$6 -> 8675.8 | AB34: =(SUM(D34:AA34)) -> 208219.2 | AC34: 21 | AD34: =(AB34*AC34)+(AB35*AC35)+(AB36*AC36)+(AB37*AC37) -> 6454795.2
C35: Sábado | D35: =+$D$6 -> 8675.8 | E35: =+$D$6 -> 8675.8 | F35: =+$D$6 -> 8675.8 | G35: =+$D$6 -> 8675.8 | H35: =+$D$6 -> 8675.8 | I35: =+$D$6 -> 8675.8 | J35: =+$D$6 -> 8675.8 | K35: =+$D$6 -> 8675.8 | ... AA35: =+$D$6 -> 8675.8 | AB35: =(SUM(D35:AA35)) -> 208219.2 | AC35: 3
C36: Domingo | D36: =+$D$6 -> 8675.8 | E36: =+$D$6 -> 8675.8 | F36: =+$D$6 -> 8675.8 | G36: =+$D$6 -> 8675.8 | H36: =+$D$6 -> 8675.8 | I36: =+$D$6 -> 8675.8 | J36: =+$D$6 -> 8675.8 | K36: =+$D$6 -> 8675.8 | ... AA36: =+$D$6 -> 8675.8 | AB36: =(SUM(D36:AA36)) -> 208219.2 | AC36: 5
C37: Festivo | D37: =+$D$6 -> 8675.8 | E37: =+$D$6 -> 8675.8 | F37: =+$D$6 -> 8675.8 | G37: =+$D$6 -> 8675.8 | H37: =+$D$6 -> 8675.8 | I37: =+$D$6 -> 8675.8 | J37: =+$D$6 -> 8675.8 | K37: =+$D$6 -> 8675.8 | ... AA37: =+$D$6 -> 8675.8 | AB37: =(SUM(D37:AA37)) -> 208219.2 | AC37: 2
B38: 46631 | C38: Hábil | D38: =+$D$6 -> 8675.8 | E38: =+$D$6 -> 8675.8 | F38: =+$D$6 -> 8675.8 | G38: =+$D$6 -> 8675.8 | H38: =+$D$6 -> 8675.8 | I38: =+$D$6 -> 8675.8 | J38: =+$D$6 -> 8675.8 | K38: =+$D$6 -> 8675.8 | ... AA38: =+$D$6 -> 8675.8 | AB38: =(SUM(D38:AA38)) -> 208219.2 | AC38: 22 | AD38: =(AB38*AC38)+(AB39*AC39)+(AB40*AC40)+(AB41*AC41) -> 6246576
C39: Sábado | D39: =+$D$6 -> 8675.8 | E39: =+$D$6 -> 8675.8 | F39: =+$D$6 -> 8675.8 | G39: =+$D$6 -> 8675.8 | H39: =+$D$6 -> 8675.8 | I39: =+$D$6 -> 8675.8 | J39: =+$D$6 -> 8675.8 | K39: =+$D$6 -> 8675.8 | ... AA39: =+$D$6 -> 8675.8 | AB39: =(SUM(D39:AA39)) -> 208219.2 | AC39: 4
C40: Domingo | D40: =+$D$6 -> 8675.8 | E40: =+$D$6 -> 8675.8 | F40: =+$D$6 -> 8675.8 | G40: =+$D$6 -> 8675.8 | H40: =+$D$6 -> 8675.8 | I40: =+$D$6 -> 8675.8 | J40: =+$D$6 -> 8675.8 | K40: =+$D$6 -> 8675.8 | ... AA40: =+$D$6 -> 8675.8 | AB40: =(SUM(D40:AA40)) -> 208219.2 | AC40: 4
C41: Festivo | D41: =+$D$6 -> 8675.8 | E41: =+$D$6 -> 8675.8 | F41: =+$D$6 -> 8675.8 | G41: =+$D$6 -> 8675.8 | H41: =+$D$6 -> 8675.8 | I41: =+$D$6 -> 8675.8 | J41: =+$D$6 -> 8675.8 | K41: =+$D$6 -> 8675.8 | ... AA41: =+$D$6 -> 8675.8 | AB41: =(SUM(D41:AA41)) -> 208219.2 | AC41: 0
...

Sheet Anexo 2 Producto 4
B4: ANEXO 2 - OFERTA PRODUCTO 4
B5: NOMBRE DEL OFERENTE
B6: PRECIOS Y CANTIDADES DE ENERGIA OFERTADA
B7: EN PESOS DE MARZO 2026
B8: PRODUCTO 4
B9: 2027 | C9: Enero | D9: =+'Producto 4 Plano 27'!AE6 -> 6454795.2 | F9: =+E9*D9 -> 0
B10: =+B9 -> 2027 | C10: Febrero | D10: =+'Producto 4 Plano 27'!AE7 -> 5830137.6 | F10: =+E10*D10 -> 0
B11: =+B10 -> 2027 | C11: Marzo | D11: =+'Producto 4 Plano 27'!AE8 -> 6454795.2 | F11: =+E11*D11 -> 0
B12: =+B11 -> 2027 | C12: Abril | D12: =+'Producto 4 Plano 27'!AE9 -> 6246576 | F12: =+E12*D12 -> 0
B13: =+B12 -> 2027 | C13: Mayo | D13: =+'Producto 4 Plano 27'!AE10 -> 6454795.2 | F13: =+E13*D13 -> 0
B14: =+B13 -> 2027 | C14: Junio | D14: =+'Producto 4 Plano 27'!AE11 -> 6246576 | F14: =+E14*D14 -> 0
B15: =+B14 -> 2027 | C15: Julio | D15: =+'Producto 4 Plano 27'!AE12 -> 6454795.2 | F15: =+E15*D15 -> 0
B16: =+B15 -> 2027 | C16: Agosto | D16: =+'Producto 4 Plano 27'!AE13 -> 6454795.2 | F16: =+E16*D16 -> 0
B17: =+B16 -> 2027 | C17: Septiembre | D17: =+'Producto 4 Plano 27'!AE14 -> 6246576 | F17: =+E17*D17 -> 0
B18: =+B17 -> 2027 | C18: Octubre | D18: =+'Producto 4 Plano 27'!AE15 -> 6454795.2 | F18: =+E18*D18 -> 0
B19: =+B18 -> 2027 | C19: Noviembre | D19: =+'Producto 4 Plano 27'!AE16 -> 6246576 | F19: =+E19*D19 -> 0
B20: =+B19 -> 2027 | C20: Diciembre | D20: =+'Producto 4 Plano 27'!AE17 -> 6454795.2 | F20: =+E20*D20 -> 0
B21: Total Producto 4 | D21: =+SUM(D9:D20) -> 76000008
B23: E. Solicitada = Energía solicitada por RUITOQUE para el producto.
B24: % E. Ofertado = Porcentaje de energía ofertado por el agente respecto a la E. Solicitada.
B25: E. Ofertada = Energía ofertada por el agente, producto de la E. Solicitada y el % E. Ofertado.
B26: $/kWh = Tarifa de la oferta para todas las horas del mes.

Sheet Producto 5 Plano 27
B2: ANEXO 1 - CANTIDADES DE ENERGÍA SOLICITADA EN kWh
B3: PRODUCTO 5
B4: PERIODO 01 DE ENERO DEL 2027 A DICIEMBRE 31 DE 2027
C5: DIA | D5: 1 | E5: 2 | F5: 3 | G5: 4 | H5: 5 | I5: 6 | J5: 7 | K5: 8 | L5: 9 | M5: 10 | N5: 11 | O5: 12 | P5: 13 | Q5: 14 | R5: 15 | S5: 16 | T5: 17 | U5: 18 | V5: 19 | W5: 20 | X5: 21 | Y5: 22 | Z5: 23 | AA5: 24 | AB5: Total | AC5: No. DÍAS | AD5: Total
B6: 46388 | C6: Hábil | D6: 4109.59 | E6: =+D6 -> 4109.59 | F6: =+D6 -> 4109.59 | G6: =+D6 -> 4109.59 | H6: =+D6 -> 4109.59 | I6: =+D6 -> 4109.59 | J6: =+D6 -> 4109.59 | K6: =+D6 -> 4109.59 | L6: =+D6 -> 4109.59 | M6: =+D6 -> 4109.59 | N6: =+D6 -> 4109.59 | O6: =+D6 -> 4109.59 | P6: =+D6 -> 4109.59 | Q6: =+D6 -> 4109.59 | R6: =+D6 -> 4109.59 | S6: =+D6 -> 4109.59 | T6: =+D6 -> 4109.59 | U6: =+D6 -> 4109.59 | V6: =+D6 -> 4109.59 | W6: =+D6 -> 4109.59 | X6: =+D6 -> 4109.59 | Y6: =+D6 -> 4109.59 | Z6: =+D6 -> 4109.59 | AA6: =+D6 -> 4109.59 | AB6: =(SUM(D6:AA6)) -> 98630.16 | AC6: 19 | AD6: =(AB6*AC6)+(AB7*AC7)+(AB8*AC8)+(AB9*AC9) -> 3057535 | AE6: =+AD6 -> 3057535
C7: Sábado | D7: =+D6 -> 4109.59 | E7: =+D6 -> 4109.59 | F7: =+D6 -> 4109.59 | G7: =+D6 -> 4109.59 | H7: =+D6 -> 4109.59 | I7: =+D6 -> 4109.59 | J7: =+D6 -> 4109.59 | K7: =+D6 -> 4109.59 | L7: =+D6 -> 4109.59 | M7: =+D6 -> 4109.59 | N7: =+D6 -> 4109.59 | O7: =+D6 -> 4109.59 | P7: =+D6 -> 4109.59 | Q7: =+D6 -> 4109.59 | R7: =+D6 -> 4109.59 | S7: =+D6 -> 4109.59 | T7: =+D6 -> 4109.59 | U7: =+D6 -> 4109.59 | V7: =+D6 -> 4109.59 | W7: =+D6 -> 4109.59 | X7: =+D6 -> 4109.59 | Y7: =+D6 -> 4109.59 | Z7: =+D6 -> 4109.59 | AA7: =+D6 -> 4109.59 | AB7: =(SUM(D7:AA7)) -> 98630.16 | AC7: 5 | AE7: =+AD10 -> 2761644.5
C8: Domingo | D8: =+D6 -> 4109.59 | E8: =+D6 -> 4109.59 | F8: =+D6 -> 4109.59 | G8: =+D6 -> 4109.59 | H8: =+D6 -> 4109.59 | I8: =+D6 -> 4109.59 | J8: =+D6 -> 4109.59 | K8: =+D6 -> 4109.59 | L8: =+D6 -> 4109.59 | M8: =+D6 -> 4109.59 | N8: =+D6 -> 4109.59 | O8: =+D6 -> 4109.59 | P8: =+D6 -> 4109.59 | Q8: =+D6 -> 4109.59 | R8: =+D6 -> 4109.59 | S8: =+D6 -> 4109.59 | T8: =+D6 -> 4109.59 | U8: =+D6 -> 4109.59 | V8: =+D6 -> 4109.59 | W8: =+D6 -> 4109.59 | X8: =+D6 -> 4109.59 | Y8: =+D6 -> 4109.59 | Z8: =+D6 -> 4109.59 | AA8: =+D6 -> 4109.59 | AB8: =(SUM(D8:AA8)) -> 98630.16 | AC8: 5 | AE8: =+AD14 -> 3057535
C9: Festivo | D9: =+D6 -> 4109.59 | E9: =+D6 -> 4109.59 | F9: =+D6 -> 4109.59 | G9: =+D6 -> 4109.59 | H9: =+D6 -> 4109.59 | I9: =+D6 -> 4109.59 | J9: =+D6 -> 4109.59 | K9: =+D6 -> 4109.59 | L9: =+D6 -> 4109.59 | M9: =+D6 -> 4109.59 | N9: =+D6 -> 4109.59 | O9: =+D6 -> 4109.59 | P9: =+D6 -> 4109.59 | Q9: =+D6 -> 4109.59 | R9: =+D6 -> 4109.59 | S9: =+D6 -> 4109.59 | T9: =+D6 -> 4109.59 | U9: =+D6 -> 4109.59 | V9: =+D6 -> 4109.59 | W9: =+D6 -> 4109.59 | X9: =+D6 -> 4109.59 | Y9: =+D6 -> 4109.59 | Z9: =+D6 -> 4109.59 | AA9: =+D6 -> 4109.59 | AB9: =(SUM(D9:AA9)) -> 98630.16 | AC9: 2 | AE9: =+AD18 -> 2958904.8
B10: 46419 | C10: Hábil | D10: 4109.59 | E10: =+D10 -> 4109.59 | F10: =+D10 -> 4109.59 | G10: =+D10 -> 4109.59 | H10: =+D10 -> 4109.59 | I10: =+D10 -> 4109.59 | J10: =+D10 -> 4109.59 | K10: =+D10 -> 4109.59 | L10: =+D10 -> 4109.59 | M10: =+D10 -> 4109.59 | N10: =+D10 -> 4109.59 | O10: =+D10 -> 4109.59 | P10: =+D10 -> 4109.59 | Q10: =+D10 -> 4109.59 | R10: =+D10 -> 4109.59 | S10: =+D10 -> 4109.59 | T10: =+D10 -> 4109.59 | U10: =+D10 -> 4109.59 | V10: =+D10 -> 4109.59 | W10: =+D10 -> 4109.59 | X10: =+D10 -> 4109.59 | Y10: =+D10 -> 4109.59 | Z10: =+D10 -> 4109.59 | AA10: =+D10 -> 4109.59 | AB10: =(SUM(D10:AA10)) -> 98630.16 | AC10: 20 | AD10: =(AB10*AC10)+(AB11*AC11)+(AB12*AC12)+(AB13*AC13) -> 2761644.5 | AE10: =+AD22 -> 3057535
C11: Sábado | D11: =+D10 -> 4109.59 | E11: =+D10 -> 4109.59 | F11: =+D10 -> 4109.59 | G11: =+D10 -> 4109.59 | H11: =+D10 -> 4109.59 | I11: =+D10 -> 4109.59 | J11: =+D10 -> 4109.59 | K11: =+D10 -> 4109.59 | L11: =+D10 -> 4109.59 | M11: =+D10 -> 4109.59 | N11: =+D10 -> 4109.59 | O11: =+D10 -> 4109.59 | P11: =+D10 -> 4109.59 | Q11: =+D10 -> 4109.59 | R11: =+D10 -> 4109.59 | S11: =+D10 -> 4109.59 | T11: =+D10 -> 4109.59 | U11: =+D10 -> 4109.59 | V11: =+D10 -> 4109.59 | W11: =+D10 -> 4109.59 | X11: =+D10 -> 4109.59 | Y11: =+D10 -> 4109.59 | Z11: =+D10 -> 4109.59 | AA11: =+D10 -> 4109.59 | AB11: =(SUM(D11:AA11)) -> 98630.16 | AC11: 4 | AE11: =+AD26 -> 2958904.8
C12: Domingo | D12: =+D10 -> 4109.59 | E12: =+D10 -> 4109.59 | F12: =+D10 -> 4109.59 | G12: =+D10 -> 4109.59 | H12: =+D10 -> 4109.59 | I12: =+D10 -> 4109.59 | J12: =+D10 -> 4109.59 | K12: =+D10 -> 4109.59 | L12: =+D10 -> 4109.59 | M12: =+D10 -> 4109.59 | N12: =+D10 -> 4109.59 | O12: =+D10 -> 4109.59 | P12: =+D10 -> 4109.59 | Q12: =+D10 -> 4109.59 | R12: =+D10 -> 4109.59 | S12: =+D10 -> 4109.59 | T12: =+D10 -> 4109.59 | U12: =+D10 -> 4109.59 | V12: =+D10 -> 4109.59 | W12: =+D10 -> 4109.59 | X12: =+D10 -> 4109.59 | Y12: =+D10 -> 4109.59 | Z12: =+D10 -> 4109.59 | AA12: =+D10 -> 4109.59 | AB12: =(SUM(D12:AA12)) -> 98630.16 | AC12: 4 | AE12: =+AD30 -> 3057535
C13: Festivo | D13: =+D10 -> 4109.59 | E13: =+D10 -> 4109.59 | F13: =+D10 -> 4109.59 | G13: =+D10 -> 4109.59 | H13: =+D10 -> 4109.59 | I13: =+D10 -> 4109.59 | J13: =+D10 -> 4109.59 | K13: =+D10 -> 4109.59 | L13: =+D10 -> 4109.59 | M13: =+D10 -> 4109.59 | N13: =+D10 -> 4109.59 | O13: =+D10 -> 4109.59 | P13: =+D10 -> 4109.59 | Q13: =+D10 -> 4109.59 | R13: =+D10 -> 4109.59 | S13: =+D10 -> 4109.59 | T13: =+D10 -> 4109.59 | U13: =+D10 -> 4109.59 | V13: =+D10 -> 4109.59 | W13: =+D10 -> 4109.59 | X13: =+D10 -> 4109.59 | Y13: =+D10 -> 4109.59 | Z13: =+D10 -> 4109.59 | AA13: =+D10 -> 4109.59 | AB13: =(SUM(D13:AA13)) -> 98630.16 | AC13: 0 | AE13: =+AD34 -> 3057535
B14: 46447 | C14: Hábil | D14: 4109.59 | E14: =+D14 -> 4109.59 | F14: =+D14 -> 4109.59 | G14: =+D14 -> 4109.59 | H14: =+D14 -> 4109.59 | I14: =+D14 -> 4109.59 | J14: =+D14 -> 4109.59 | K14: =+D14 -> 4109.59 | L14: =+D14 -> 4109.59 | M14: =+D14 -> 4109.59 | N14: =+D14 -> 4109.59 | O14: =+D14 -> 4109.59 | P14: =+D14 -> 4109.59 | Q14: =+D14 -> 4109.59 | R14: =+D14 -> 4109.59 | S14: =+D14 -> 4109.59 | T14: =+D14 -> 4109.59 | U14: =+D14 -> 4109.59 | V14: =+D14 -> 4109.59 | W14: =+D14 -> 4109.59 | X14: =+D14 -> 4109.59 | Y14: =+D14 -> 4109.59 | Z14: =+D14 -> 4109.59 | AA14: =+D14 -> 4109.59 | AB14: =(SUM(D14:AA14)) -> 98630.16 | AC14: 20 | AD14: =(AB14*AC14)+(AB15*AC15)+(AB16*AC16)+(AB17*AC17) -> 3057535 | AE14: =+AD38 -> 2958904.8
C15: Sábado | D15: =+D14 -> 4109.59 | E15: =+D14 -> 4109.59 | F15: =+D14 -> 4109.59 | G15: =+D14 -> 4109.59 | H15: =+D14 -> 4109.59 | I15: =+D14 -> 4109.59 | J15: =+D14 -> 4109.59 | K15: =+D14 -> 4109.59 | L15: =+D14 -> 4109.59 | M15: =+D14 -> 4109.59 | N15: =+D14 -> 4109.59 | O15: =+D14 -> 4109.59 | P15: =+D14 -> 4109.59 | Q15: =+D14 -> 4109.59 | R15: =+D14 -> 4109.59 | S15: =+D14 -> 4109.59 | T15: =+D14 -> 4109.59 | U15: =+D14 -> 4109.59 | V15: =+D14 -> 4109.59 | W15: =+D14 -> 4109.59 | X15: =+D14 -> 4109.59 | Y15: =+D14 -> 4109.59 | Z15: =+D14 -> 4109.59 | AA15: =+D14 -> 4109.59 | AB15: =(SUM(D15:AA15)) -> 98630.16 | AC15: 4 | AE15: =+AD42 -> 3057535
C16: Domingo | D16: =+D14 -> 4109.59 | E16: =+D14 -> 4109.59 | F16: =+D14 -> 4109.59 | G16: =+D14 -> 4109.59 | H16: =+D14 -> 4109.59 | I16: =+D14 -> 4109.59 | J16: =+D14 -> 4109.59 | K16: =+D14 -> 4109.59 | L16: =+D14 -> 4109.59 | M16: =+D14 -> 4109.59 | N16: =+D14 -> 4109.59 | O16: =+D14 -> 4109.59 | P16: =+D14 -> 4109.59 | Q16: =+D14 -> 4109.59 | R16: =+D14 -> 4109.59 | S16: =+D14 -> 4109.59 | T16: =+D14 -> 4109.59 | U16: =+D14 -> 4109.59 | V16: =+D14 -> 4109.59 | W16: =+D14 -> 4109.59 | X16: =+D14 -> 4109.59 | Y16: =+D14 -> 4109.59 | Z16: =+D14 -> 4109.59 | AA16: =+D14 -> 4109.59 | AB16: =(SUM(D16:AA16)) -> 98630.16 | AC16: 4 | AE16: =+AD46 -> 2958904.8
C17: Festivo | D17: =+D14 -> 4109.59 | E17: =+D14 -> 4109.59 | F17: =+D14 -> 4109.59 | G17: =+D14 -> 4109.59 | H17: =+D14 -> 4109.59 | I17: =+D14 -> 4109.59 | J17: =+D14 -> 4109.59 | K17: =+D14 -> 4109.59 | L17: =+D14 -> 4109.59 | M17: =+D14 -> 4109.59 | N17: =+D14 -> 4109.59 | O17: =+D14 -> 4109.59 | P17: =+D14 -> 4109.59 | Q17: =+D14 -> 4109.59 | R17: =+D14 -> 4109.59 | S17: =+D14 -> 4109.59 | T17: =+D14 -> 4109.59 | U17: =+D14 -> 4109.59 | V17: =+D14 -> 4109.59 | W17: =+D14 -> 4109.59 | X17: =+D14 -> 4109.59 | Y17: =+D14 -> 4109.59 | Z17: =+D14 -> 4109.59 | AA17: =+D14 -> 4109.59 | AB17: =(SUM(D17:AA17)) -> 98630.16 | AC17: 3 | AE17: =+AD50 -> 3057535
B18: 46478 | C18: Hábil | D18: 4109.59 | E18: =+D18 -> 4109.59 | F18: =+D18 -> 4109.59 | G18: =+D18 -> 4109.59 | H18: =+D18 -> 4109.59 | I18: =+D18 -> 4109.59 | J18: =+D18 -> 4109.59 | K18: =+D18 -> 4109.59 | L18: =+D18 -> 4109.59 | M18: =+D18 -> 4109.59 | N18: =+D18 -> 4109.59 | O18: =+D18 -> 4109.59 | P18: =+D18 -> 4109.59 | Q18: =+D18 -> 4109.59 | R18: =+D18 -> 4109.59 | S18: =+D18 -> 4109.59 | T18: =+D18 -> 4109.59 | U18: =+D18 -> 4109.59 | V18: =+D18 -> 4109.59 | W18: =+D18 -> 4109.59 | X18: =+D18 -> 4109.59 | Y18: =+D18 -> 4109.59 | Z18: =+D18 -> 4109.59 | AA18: =+D18 -> 4109.59 | AB18: =(SUM(D18:AA18)) -> 98630.16 | AC18: 22 | AD18: =(AB18*AC18)+(AB19*AC19)+(AB20*AC20)+(AB21*AC21) -> 2958904.8
C19: Sábado | D19: =+D18 -> 4109.59 | E19: =+D18 -> 4109.59 | F19: =+D18 -> 4109.59 | G19: =+D18 -> 4109.59 | H19: =+D18 -> 4109.59 | I19: =+D18 -> 4109.59 | J19: =+D18 -> 4109.59 | K19: =+D18 -> 4109.59 | L19: =+D18 -> 4109.59 | M19: =+D18 -> 4109.59 | N19: =+D18 -> 4109.59 | O19: =+D18 -> 4109.59 | P19: =+D18 -> 4109.59 | Q19: =+D18 -> 4109.59 | R19: =+D18 -> 4109.59 | S19: =+D18 -> 4109.59 | T19: =+D18 -> 4109.59 | U19: =+D18 -> 4109.59 | V19: =+D18 -> 4109.59 | W19: =+D18 -> 4109.59 | X19: =+D18 -> 4109.59 | Y19: =+D18 -> 4109.59 | Z19: =+D18 -> 4109.59 | AA19: =+D18 -> 4109.59 | AB19: =(SUM(D19:AA19)) -> 98630.16 | AC19: 4
