Workbook

Sheet Oferta Producto 1
B1: ANEXO. CANTIDADES DE ENERGÍA Y PRECIO
B2: PRODUCTO: | C2: 1
B4: CONVOCATORIA PUBLICA: | C4: CP-CHCC2025-003
B5: OFERENTE:
B6: AÑO: | C6: 2027
B7: CANTIDAD EN: | C7: kWh
B8: EN PESOS DE | C8: 45870
B9: INDICADOR: | C9: IPP- PROVISIONAL
B10: TIPO DE CONTRATO: | C10: PLC
B11: TIPO DE CARGA: | C11: CURVA
B13: Fecha | C13: Energia Solicitada kWh | D13: Porcentaje Ofertado % | E13: Energia Ofertada kWh | F13: Precio $/KWh
B14: 46388 | C14: =+'Cantidad Producto 1-2027'!AE7 -> 14155456 | E14: =+C14*D14 -> 0
B15: 46419 | C15: =+'Cantidad Producto 1-2027'!AE8 -> 13137748 | E15: =+C15*D15 -> 0
B16: 46447 | C16: =+'Cantidad Producto 1-2027'!AE9 -> 13819567 | E16: =+C16*D16 -> 0
B17: 46478 | C17: =+'Cantidad Producto 1-2027'!AE10 -> 13943586 | E17: =+C17*D17 -> 0
B18: 46508 | C18: =+'Cantidad Producto 1-2027'!AE11 -> 13868380 | E18: =+C18*D18 -> 0
B19: 46539 | C19: =+'Cantidad Producto 1-2027'!AE12 -> 13827876 | E19: =+C19*D19 -> 0
B20: 46569 | C20: =+'Cantidad Producto 1-2027'!AE13 -> 12923708 | E20: =+C20*D20 -> 0
B21: 46600 | C21: =+'Cantidad Producto 1-2027'!AE14 -> 13437104 | E21: =+C21*D21 -> 0
B22: 46631 | C22: =+'Cantidad Producto 1-2027'!AE15 -> 12944034 | E22: =+C22*D22 -> 0
B23: 46661 | C23: =+'Cantidad Producto 1-2027'!AE16 -> 13505119 | E23: =+C23*D23 -> 0
B24: 46692 | C24: =+'Cantidad Producto 1-2027'!AE17 -> 13089684 | E24: =+C24*D24 -> 0
B25: 46722 | C25: =+'Cantidad Producto 1-2027'!AE18 -> 13514959 | E25: =+C25*D25 -> 0
B26: Total producto | C26: =SUM(C14:C25) -> 162167221 | D26: %
B28: Notas:
B29: 1) La Energía Ofertada según Anexo 8.1
B30: 2) El porcentaje puede ser diferente para cada mes y el precio debe ser el mismo para todos los meses del año.
B31: 3) Precio ofertado en $kWh en pesos de agosto 2025.
B32: 5) El tope máximo para las ofertas plana es de 5.000 KWh
B36: OFERENTE E.S.P

Sheet Oferta Producto 2
B1: ANEXO. CANTIDADES DE ENERGÍA Y PRECIO
B2: PRODUCTO: | C2: 2
B4: CONVOCATORIA PUBLICA: | C4: =+'Oferta Producto 1'!C4 -> CP-CHCC2025-003
B5: OFERENTE:
B6: AÑO: | C6: 2028
B7: CANTIDAD EN: | C7: kWh
B8: EN PESOS DE | C8: =+'Oferta Producto 1'!C8 -> 45870
B9: INDICADOR: | C9: IPP- PROVISIONAL
B10: TIPO DE CONTRATO: | C10: PLC
B11: TIPO DE CARGA: | C11: CURVA
B13: Fecha | C13: Energia Solicitada kWh | D13: Porcentaje Ofertado % | E13: Energia Ofertada kWh | F13: Precio $/KWh
B14: 46753 | C14: =+'Cantidad Producto 2-2028'!AE7 -> 2766303
B15: 46784 | C15: =+'Cantidad Producto 2-2028'!AE8 -> 2501857
B16: 46813 | C16: =+'Cantidad Producto 2-2028'!AE9 -> 2619980
B17: 46844 | C17: =+'Cantidad Producto 2-2028'!AE10 -> 2723545
B18: 46874 | C18: =+'Cantidad Producto 2-2028'!AE11 -> 2724187
B19: 46905 | C19: =+'Cantidad Producto 2-2028'!AE12 -> 2695390
B20: 46935 | C20: =+'Cantidad Producto 2-2028'!AE13 -> 2897980
B21: 46966 | C21: =+'Cantidad Producto 2-2028'!AE14 -> 2910774
B22: 46997 | C22: =+'Cantidad Producto 2-2028'!AE15 -> 2814865
B23: 47027 | C23: =+'Cantidad Producto 2-2028'!AE16 -> 2910046
B24: 47058 | C24: =+'Cantidad Producto 2-2028'!AE17 -> 2854598
B25: 47088 | C25: =+'Cantidad Producto 2-2028'!AE18 -> 2942882
B26: Total producto | C26: =SUM(C14:C25) -> 33362407 | D26: %
B29: Notas:
B30: 1) La Energía Ofertada según Anexo 8.2
B31: 2) Para las ofertas curvas, el porcentaje y el precio debe ser el mismo para todos los meses del año.
B32: 3) Para la ofertas planas la cantidad de energía ofertada debe ser la misma para todas las horas del año
B33: y el precio debe ser el mismo para todos los meses del año.
B34: 4) Precio ofertado en $kWh en pesos de agosto 2025.
B35: 5) El tope máximo para las ofertas plana es de 2.000 KWh
B39: OFERENTE E.S.P

Sheet Oferta Producto 3
B1: ANEXO. CANTIDADES DE ENERGÍA Y PRECIO
B2: PRODUCTO: | C2: 3
B4: CONVOCATORIA PUBLICA: | C4: =+'Oferta Producto 1'!C4 -> CP-CHCC2025-003
B5: OFERENTE:
B6: AÑO: | C6: 2029
B7: CANTIDAD EN: | C7: kWh
B8: EN PESOS DE | C8: =+'Oferta Producto 1'!C8 -> 45870
B9: INDICADOR: | C9: IPP- PROVISIONAL
B10: TIPO DE CONTRATO: | C10: PLC
B11: TIPO DE CARGA: | C11: CURVA
B13: Fecha | C13: Energia Solicitada kWh | D13: Porcentaje Ofertado % | E13: Energia Ofertada kWh | F13: Precio $/KWh
B14: 47119 | C14: =+'Cantidad Producto3-2029'!AE7 -> 6675330
B15: 47150 | C15: =+'Cantidad Producto3-2029'!AE8 -> 6071720
B16: 47178 | C16: =+'Cantidad Producto3-2029'!AE9 -> 6318856
B17: 47209 | C17: =+'Cantidad Producto3-2029'!AE10 -> 6557158
B18: 47239 | C18: =+'Cantidad Producto3-2029'!AE11 -> 6567612
B19: 47270 | C19: =+'Cantidad Producto3-2029'!AE12 -> 6448400
B20: 47300 | C20: =+'Cantidad Producto3-2029'!AE13 -> 6740976
B21: 47331 | C21: =+'Cantidad Producto3-2029'!AE14 -> 7014730
B22: 47362 | C22: =+'Cantidad Producto3-2029'!AE15 -> 6783280
B23: 47392 | C23: =+'Cantidad Producto3-2029'!AE16 -> 7034886
B24: 47423 | C24: =+'Cantidad Producto3-2029'!AE17 -> 6905710
B25: 47453 | C25: =+'Cantidad Producto3-2029'!AE18 -> 7078222
B26: Total producto | C26: =SUM(C14:C25) -> 80196880 | D26: %
B27: Notas:
B28: 1) La Energía Ofertada según Anexo 8.3
B29: 2) Para las ofertas curvas, el porcentaje y el precio debe ser el mismo para todos los meses del año.
B30: 3) Para la ofertas planas la cantidad de energía ofertada debe ser la misma para todas las horas del año
B31: y el precio debe ser el mismo para todos los meses del año.
B32: 4) Precio ofertado en $kWh en pesos de agosto 2025.
B33: 5) El tope máximo para las ofertas plana es de 2.500 KWh
B36: OFERENTE E.S.P

Sheet Oferta Producto 4
B1: ANEXO. CANTIDADES DE ENERGÍA Y PRECIO
B2: PRODUCTO: | C2: 4
B4: CONVOCATORIA PUBLICA: | C4: =+'Oferta Producto 1'!C4 -> CP-CHCC2025-003
B5: OFERENTE:
B6: AÑO: | C6: 2030
B7: CANTIDAD EN: | C7: kWh
B8: EN PESOS DE | C8: =+'Oferta Producto 1'!C8 -> 45870
B9: INDICADOR: | C9: IPP- PROVISIONAL
B10: TIPO DE CONTRATO: | C10: PLC
B11: TIPO DE CARGA: | C11: CURVA
B13: Fecha | C13: Energia Solicitada kWh | D13: Porcentaje Ofertado % | E13: Energia Ofertada kWh | F13: Precio $/KWh
B14: 47484 | C14: =+'Cantidad Producto 1-2030'!AE7 -> 17721564
B15: 47515 | C15: =+'Cantidad Producto 1-2030'!AE8 -> 16439400
B16: 47543 | C16: =+'Cantidad Producto 1-2030'!AE9 -> 17111754
B17: 47574 | C17: =+'Cantidad Producto 1-2030'!AE10 -> 17481176
B18: 47604 | C18: =+'Cantidad Producto 1-2030'!AE11 -> 17473832
B19: 47635 | C19: =+'Cantidad Producto 1-2030'!AE12 -> 17225127
B20: 47665 | C20: =+'Cantidad Producto 1-2030'!AE13 -> 17733863
B21: 47696 | C21: =+'Cantidad Producto 1-2030'!AE14 -> 18358026
B22: 47727 | C22: =+'Cantidad Producto 1-2030'!AE15 -> 17784623
B23: 47757 | C23: =+'Cantidad Producto 1-2030'!AE16 -> 18398248
B24: 47788 | C24: =+'Cantidad Producto 1-2030'!AE17 -> 18072840
B25: 47818 | C25: =+'Cantidad Producto 1-2030'!AE18 -> 18469208
B26: Total producto | C26: =SUM(C14:C25) -> 212269661 | D26: %
B27: Notas:
B28: 1) La Energía Ofertada según Anexo 8.4
B29: 2) Para las ofertas curvas, el porcentaje y el precio debe ser el mismo para todos los meses del año.
B30: 3) Para la ofertas planas la cantidad de energía ofertada debe ser la misma para todas las horas del año
B31: y el precio debe ser el mismo para todos los meses del año.
B32: 4) Precio ofertado en $kWh en pesos de agosto 2025.
B33: 5) El tope máximo para las ofertas plana es de 3.500 KWh
B36: OFERENTE E.S.P

Sheet Cantidad Producto 1-2027
B2: CANTIDADES DE ENERGÍA SOLICITADAS (kWh)
B3: CENTRAL HIDROELECTRICA DE CALDAS S.A. E.S.P. -BENEFICIO E INTERÉS COLECTIVO
B4: 2027
B6: Mes | C6: Tipo Día | D6: Días | E6: H1 | F6: H2 | G6: H3 | H6: H4 | I6: H5 | J6: H6 | K6: H7 | L6: H8 | M6: H9 | N6: H10 | O6: H11 | P6: H12 | Q6: H13 | R6: H14 | S6: H15 | T6: H16 | U6: H17 | V6: H18 | W6: H19 | X6: H20 | Y6: H21 | Z6: H22 | AA6: H23 | AB6: H24 | AC6: TOTAL MES
B7: Ene | C7: Ordinario | D7: 19 | E7: 13796 | F7: 12943 | G7: 12563 | H7: 12276 | I7: 12326 | J7: 12789 | K7: 11767 | L7: 19683 | M7: 20643 | N7: 21442 | O7: 22028 | P7: 22778 | Q7: 23516 | R7: 23331 | S7: 23244 | T7: 23145 | U7: 22647 | V7: 17257 | W7: 19408 | X7: 21054 | Y7: 20602 | Z7: 19353 | AA7: 17197 | AB7: 15578 | AC7: 14155456 | AE7: =((+AC7)*1000)/1000 -> 14155456
B8: Ene | C8: Sábado | D8: 5 | E8: 12659 | F8: 12166 | G8: 12029 | H8: 11962 | I8: 12587 | J8: 15021 | K8: 15429 | L8: 22563 | M8: 22325 | N8: 22915 | O8: 23751 | P8: 25239 | Q8: 25020 | R8: 25220 | S8: 25956 | T8: 26222 | U8: 25796 | V8: 20071 | W8: 22190 | X8: 23559 | Y8: 22732 | Z8: 20937 | AA8: 17716 | AB8: 14852 | AE8: =((+AC11)*1000)/1000 -> 13137748
B9: Ene | C9: Domingo | D9: 5 | E9: 12501 | F9: 12103 | G9: 11937 | H9: 12064 | I9: 13037 | J9: 16014 | K9: 17913 | L9: 25427 | M9: 25277 | N9: 25554 | O9: 26323 | P9: 28001 | Q9: 27082 | R9: 26518 | S9: 27237 | T9: 27396 | U9: 26880 | V9: 21809 | W9: 24258 | X9: 24458 | Y9: 23155 | Z9: 21502 | AA9: 18804 | AB9: 16979 | AE9: =((+AC15)*1000)/1000 -> 13819567
B10: Ene | C10: Festivo | D10: 2 | E10: 13201 | F10: 12740 | G10: 12153 | H10: 11696 | I10: 11586 | J10: 11556 | K10: 10885 | L10: 17526 | M10: 18629 | N10: 19372 | O10: 20127 | P10: 20492 | Q10: 21296 | R10: 21052 | S10: 20980 | T10: 20747 | U10: 20427 | V10: 15712 | W10: 18621 | X10: 19559 | Y10: 18892 | Z10: 17914 | AA10: 16693 | AB10: 15030 | AE10: =((+AC19)*1000)/1000 -> 13943586
B11: Feb | C11: Ordinario | D11: 20 | E11: 11601 | F11: 11458 | G11: 11042 | H11: 11349 | I11: 11614 | J11: 15585 | K11: 17397 | L11: 24609 | M11: 24218 | N11: 24180 | O11: 24851 | P11: 25558 | Q11: 24988 | R11: 24992 | S11: 25585 | T11: 25943 | U11: 25705 | V11: 20130 | W11: 22334 | X11: 22746 | Y11: 21749 | Z11: 19786 | AA11: 16784 | AB11: 14244 | AC11: 13137748 | AE11: =((+AC23)*1000)/1000 -> 13868380
B12: Feb | C12: Sábado | D12: 4 | E12: 12594 | F12: 11905 | G12: 11497 | H12: 11232 | I12: 11466 | J12: 12069 | K12: 13440 | L12: 22752 | M12: 23880 | N12: 24294 | O12: 24918 | P12: 25539 | Q12: 25186 | R12: 24653 | S12: 24578 | T12: 24460 | U12: 24693 | V12: 19878 | W12: 21711 | X12: 22381 | Y12: 21396 | Z12: 19222 | AA12: 16831 | AB12: 14609 | AE12: =((+AC27)*1000)/1000 -> 13827876
B13: Feb | C13: Domingo | D13: 4 | E13: 12828 | F13: 11994 | G13: 11344 | H13: 11022 | I13: 10889 | J13: 10827 | K13: 10881 | L13: 18704 | M13: 20289 | N13: 21476 | O13: 21630 | P13: 22642 | Q13: 23638 | R13: 23778 | S13: 23228 | T13: 24176 | U13: 22052 | V13: 17892 | W13: 21360 | X13: 20229 | Y13: 19855 | Z13: 18022 | AA13: 15250 | AB13: 13007 | AE13: =((+AC31)*1000)/1000 -> 12923708
B14: Feb | C14: Festivo | D14: 0 | E14: 0 | F14: 0 | G14: 0 | H14: 0 | I14: 0 | J14: 0 | K14: 0 | L14: 0 | M14: 0 | N14: 0 | O14: 0 | P14: 0 | Q14: 0 | R14: 0 | S14: 0 | T14: 0 | U14: 0 | V14: 0 | W14: 0 | X14: 0 | Y14: 0 | Z14: 0 | AA14: 0 | AB14: 0 | AE14: =((+AC35)*1000)/1000 -> 13437104
B15: Mar | C15: Ordinario | D15: 20 | E15: 11183 | F15: 10683 | G15: 10530 | H15: 10492 | I15: 11524 | J15: 14678 | K15: 16138 | L15: 22646 | M15: 22296 | N15: 22411 | O15: 22661 | P15: 23997 | Q15: 23682 | R15: 23563 | S15: 24216 | T15: 24417 | U15: 23838 | V15: 19390 | W15: 21413 | X15: 22232 | Y15: 21417 | Z15: 18805 | AA15: 16186 | AB15: 13725 | AC15: 13819567 | AE15: =((+AC39)*1000)/1000 -> 12944034
B16: Mar | C16: Sábado | D16: 4 | E16: 10903 | F16: 11181 | G16: 10893 | H16: 10732 | I16: 11062 | J16: 11977 | K16: 13344 | L16: 21982 | M16: 23003 | N16: 23698 | O16: 23909 | P16: 23908 | Q16: 24060 | R16: 23690 | S16: 23730 | T16: 23844 | U16: 23546 | V16: 19144 | W16: 20448 | X16: 21796 | Y16: 20937 | Z16: 19281 | AA16: 17055 | AB16: 14923 | AE16: =((+AC43)*1000)/1000 -> 13505119
B17: Mar | C17: Domingo | D17: 4 | E17: 12444 | F17: 11828 | G17: 11059 | H17: 11186 | I17: 11139 | J17: 9616 | K17: 10584 | L17: 17958 | M17: 19404 | N17: 19938 | O17: 20784 | P17: 21829 | Q17: 21748 | R17: 22205 | S17: 21924 | T17: 21840 | U17: 21497 | V17: 17583 | W17: 19368 | X17: 20668 | Y17: 20890 | Z17: 18827 | AA17: 16304 | AB17: 13671 | AE17: =((+AC47)*1000)/1000 -> 13089684
B18: Mar | C18: Festivo | D18: 3 | E18: 12878 | F18: 12483 | G18: 11817 | H18: 11763 | I18: 11822 | J18: 11505 | K18: 11703 | L18: 18987 | M18: 20090 | N18: 20799 | O18: 22039 | P18: 22775 | Q18: 23457 | R18: 23129 | S18: 23380 | T18: 23268 | U18: 23010 | V18: 19144 | W18: 21905 | X18: 22570 | Y18: 21780 | Z18: 20169 | AA18: 16591 | AB18: 14185 | AE18: =((+AC51)*1000)/1000 -> 13514959
B19: Abr | C19: Ordinario | D19: 22 | E19: 11610 | F19: 11156 | G19: 11140 | H19: 10933 | I19: 11818 | J19: 14590 | K19: 16383 | L19: 23323 | M19: 23039 | N19: 22927 | O19: 23994 | P19: 24776 | Q19: 24646 | R19: 24676 | S19: 25576 | T19: 25548 | U19: 25400 | V19: 20334 | W19: 22311 | X19: 22820 | Y19: 22105 | Z19: 20068 | AA19: 17011 | AB19: 14439 | AC19: 13943586 | AE19: =SUM(AE7:AE18) -> 162167221
B20: Abr | C20: Sábado | D20: 4 | E20: 12538 | F20: 11904 | G20: 11531 | H20: 11436 | I20: 11783 | J20: 12277 | K20: 12661 | L20: 22043 | M20: 22646 | N20: 23120 | O20: 24096 | P20: 24186 | Q20: 25026 | R20: 24405 | S20: 24779 | T20: 24980 | U20: 25142 | V20: 19668 | W20: 23014 | X20: 21911 | Y20: 20919 | Z20: 19695 | AA20: 17674 | AB20: 17034
B21: Abr | C21: Domingo | D21: 4 | E21: 13298 | F21: 12362 | G21: 11691 | H21: 11540 | I21: 11014 | J21: 10975 | K21: 11318 | L21: 18462 | M21: 20258 | N21: 20783 | O21: 21634 | P21: 21950 | Q21: 22889 | R21: 22904 | S21: 22799 | T21: 22540 | U21: 23073 | V21: 18845 | W21: 21024 | X21: 21434 | Y21: 21132 | Z21: 19638 | AA21: 17490 | AB21: 13949
B22: Abr | C22: Festivo | D22: 0
B23: May | C23: Ordinario | D23: 19 | E23: 11361 | F23: 10925 | G23: 10618 | H23: 10716 | I23: 11610 | J23: 14461 | K23: 16046 | L23: 22784 | M23: 22452 | N23: 21987 | O23: 22640 | P23: 24055 | Q23: 23687 | R23: 23953 | S23: 24799 | T23: 24868 | U23: 24567 | V23: 19818 | W23: 21642 | X23: 22173 | Y23: 21235 | Z23: 19303 | AA23: 16582 | AB23: 14078 | AC23: 13868380
B24: May | C24: Sábado | D24: 4 | E24: 12319 | F24: 11270 | G24: 11107 | H24: 10981 | I24: 11262 | J24: 11588 | K24: 12871 | L24: 21464 | M24: 22705 | N24: 23306 | O24: 23504 | P24: 23666 | Q24: 23894 | R24: 23246 | S24: 23164 | T24: 23192 | U24: 23114 | V24: 18779 | W24: 20708 | X24: 21694 | Y24: 20696 | Z24: 19311 | AA24: 17071 | AB24: 14831
B25: May | C25: Domingo | D25: 5 | E25: 12443 | F25: 11791 | G25: 10888 | H25: 10686 | I25: 10317 | J25: 10344 | K25: 10693 | L25: 18329 | M25: 19834 | N25: 20648 | O25: 21270 | P25: 21532 | Q25: 21878 | R25: 21399 | S25: 21088 | T25: 21410 | U25: 22338 | V25: 16266 | W25: 19888 | X25: 20560 | Y25: 19977 | Z25: 18229 | AA25: 15464 | AB25: 12800
B26: May | C26: Festivo | D26: 3 | E26: 11012 | F26: 11787 | G26: 11747 | H26: 11133 | I26: 11894 | J26: 12212 | K26: 12851 | L26: 20829 | M26: 21513 | N26: 22928 | O26: 24038 | P26: 25132 | Q26: 25937 | R26: 25757 | S26: 24611 | T26: 24452 | U26: 23579 | V26: 19261 | W26: 21752 | X26: 21486 | Y26: 20530 | Z26: 19250 | AA26: 16749 | AB26: 14296
B27: Jun | C27: Ordinario | D27: 21 | E27: 11786 | F27: 11231 | G27: 11065 | H27: 10970 | I27: 11885 | J27: 14205 | K27: 15840 | L27: 23432 | M27: 23233 | N27: 23563 | O27: 24305 | P27: 25035 | Q27: 24886 | R27: 24852 | S27: 25549 | T27: 25541 | U27: 25522 | V27: 20334 | W27: 22535 | X27: 22829 | Y27: 21561 | Z27: 19446 | AA27: 16666 | AB27: 14359 | AC27: 13827876
B28: Jun | C28: Sábado | D28: 4 | E28: 12284 | F28: 11569 | G28: 11234 | H28: 11002 | I28: 11350 | J28: 11994 | K28: 13006 | L28: 22189 | M28: 23042 | N28: 23541 | O28: 24117 | P28: 24391 | Q28: 24460 | R28: 24002 | S28: 23585 | T28: 23577 | U28: 23472 | V28: 19009 | W28: 20987 | X28: 21962 | Y28: 20973 | Z28: 19362 | AA28: 17508 | AB28: 15368
B29: Jun | C29: Domingo | D29: 4 | E29: 13416 | F29: 12433 | G29: 11881 | H29: 11644 | I29: 11400 | J29: 11187 | K29: 11151 | L29: 18948 | M29: 20199 | N29: 21199 | O29: 21663 | P29: 22037 | Q29: 22219 | R29: 22170 | S29: 21766 | T29: 21924 | U29: 22106 | V29: 17955 | W29: 19801 | X29: 20815 | Y29: 20114 | Z29: 18746 | AA29: 16745 | AB29: 14480
B30: Jun | C30: Festivo | D30: 1 | E30: 12240 | F30: 11636 | G30: 11183 | H30: 10996 | I30: 11054 | J30: 11061 | K30: 10810 | L30: 18452 | M30: 19024 | N30: 19501 | O30: 21406 | P30: 22259 | Q30: 23322 | R30: 23141 | S30: 22999 | T30: 22980 | U30: 22567 | V30: 18239 | W30: 20547 | X30: 21196 | Y30: 20484 | Z30: 18984 | AA30: 16466 | AB30: 14167
B31: Jul | C31: Ordinario | D31: 20 | E31: 10288 | F31: 9738 | G31: 9449 | H31: 9465 | I31: 10356 | J31: 13041 | K31: 14647 | L31: 20583 | M31: 20405 | N31: 20663 | O31: 21053 | P31: 22496 | Q31: 21984 | R31: 22072 | S31: 22733 | T31: 22806 | U31: 22449 | V31: 20119 | W31: 21788 | X31: 23096 | Y31: 22047 | Z31: 19847 | AA31: 16738 | AB31: 14517 | AC31: 12923708
B32: Jul | C32: Sábado | D32: 5 | E32: 11100 | F32: 10415 | G32: 9894 | H32: 9765 | I32: 9962 | J32: 10348 | K32: 11342 | L32: 19345 | M32: 20278 | N32: 20809 | O32: 21010 | P32: 21803 | Q32: 22067 | R32: 21744 | S32: 21415 | T32: 21069 | U32: 20678 | V32: 18973 | W32: 20217 | X32: 21564 | Y32: 20397 | Z32: 18684 | AA32: 16572 | AB32: 14589
B33: Jul | C33: Domingo | D33: 4 | E33: 10334 | F33: 9601 | G33: 9167 | H33: 8943 | I33: 8763 | J33: 8427 | K33: 8725 | L33: 15144 | M33: 16502 | N33: 17076 | O33: 17551 | P33: 18766 | Q33: 19032 | R33: 19189 | S33: 19060 | T33: 18944 | U33: 18846 | V33: 17292 | W33: 19315 | X33: 21096 | Y33: 20453 | Z33: 18348 | AA33: 15455 | AB33: 13212
B34: Jul | C34: Festivo | D34: 2 | E34: 12270 | F34: 11369 | G34: 10472 | H34: 9683 | I34: 9488 | J34: 8564 | K34: 8768 | L34: 15164 | M34: 17021 | N34: 16889 | O34: 16338 | P34: 17622 | Q34: 18237 | R34: 18678 | S34: 17517 | T34: 17599 | U34: 17734 | V34: 16084 | W34: 17553 | X34: 19741 | Y34: 19868 | Z34: 18101 | AA34: 15755 | AB34: 13957
B35: Ago | C35: Ordinario | D35: 21 | E35: 11692 | F35: 11163 | G35: 10775 | H35: 10644 | I35: 11134 | J35: 12915 | K35: 11879 | L35: 18582 | M35: 19136 | N35: 19601 | O35: 20590 | P35: 21486 | Q35: 21185 | R35: 21491 | S35: 21624 | T35: 21540 | U35: 21287 | V35: 17726 | W35: 21273 | X35: 22407 | Y35: 21655 | Z35: 19915 | AA35: 16706 | AB35: 14584 | AC35: 13437104
B36: Ago | C36: Sábado | D36: 3 | E36: 11753 | F36: 11220 | G36: 11022 | H36: 11143 | I36: 12512 | J36: 16932 | K36: 17321 | L36: 22340 | M36: 21526 | N36: 21665 | O36: 22835 | P36: 23857 | Q36: 22403 | R36: 22916 | S36: 24610 | T36: 24517 | U36: 24118 | V36: 20582 | W36: 23653 | X36: 24854 | Y36: 23769 | Z36: 22022 | AA36: 18275 | AB36: 15831
B37: Ago | C37: Domingo | D37: 5 | E37: 12112 | F37: 11460 | G37: 11290 | H37: 11335 | I37: 11969 | J37: 13385 | K37: 14197 | L37: 22369 | M37: 23361 | N37: 24214 | O37: 24969 | P37: 25984 | Q37: 24788 | R37: 23870 | S37: 23403 | T37: 23309 | U37: 23547 | V37: 20798 | W37: 24357 | X37: 24331 | Y37: 22740 | Z37: 21315 | AA37: 19014 | AB37: 17477
B38: Ago | C38: Festivo | D38: 2 | E38: 12104 | F38: 11538 | G38: 10954 | H38: 10517 | I38: 10644 | J38: 10792 | K38: 9509 | L38: 16783 | M38: 17727 | N38: 18841 | O38: 19424 | P38: 20630 | Q38: 20343 | R38: 20497 | S38: 20536 | T38: 20133 | U38: 19878 | V38: 16921 | W38: 19686 | X38: 21270 | Y38: 20806 | Z38: 19525 | AA38: 17243 | AB38: 15357
B39: Sep | C39: Ordinario | D39: 22 | E39: 11650 | F39: 11178 | G39: 11011 | H39: 10895 | I39: 11699 | J39: 14188 | K39: 13952 | L39: 20584 | M39: 20339 | N39: 20708 | O39: 21321 | P39: 22155 | Q39: 21834 | R39: 22133 | S39: 22841 | T39: 23083 | U39: 22723 | V39: 18922 | W39: 22364 | X39: 22630 | Y39: 21723 | Z39: 19812 | AA39: 17123 | AB39: 14995 | AC39: 12944034
B40: Sep | C40: Sábado | D40: 4 | E40: 12793 | F40: 11797 | G40: 11480 | H40: 11266 | I40: 11595 | J40: 12048 | K40: 11766 | L40: 19469 | M40: 20806 | N40: 21452 | O40: 21735 | P40: 22079 | Q40: 21888 | R40: 21535 | S40: 21355 | T40: 21442 | U40: 21708 | V40: 18058 | W40: 21208 | X40: 21070 | Y40: 20434 | Z40: 18569 | AA40: 16739 | AB40: 15181
B41: Sep | C41: Domingo | D41: 4 | E41: 12372 | F41: 11765 | G41: 11383 | H41: 11032 | I41: 10789 | J41: 10317 | K41: 9029 | L41: 15799 | M41: 17346 | N41: 18009 | O41: 18615 | P41: 19070 | Q41: 19407 | R41: 19310 | S41: 19491 | T41: 19738 | U41: 19626 | V41: 16918 | W41: 20425 | X41: 20591 | Y41: 20165 | Z41: 18093 | AA41: 15903 | AB41: 14096
B42: Sep | C42: Festivo | D42: 0 | E42: 0 | F42: 0 | G42: 0 | H42: 0 | I42: 0 | J42: 0 | K42: 0 | L42: 0 | M42: 0 | N42: 0 | O42: 0 | P42: 0 | Q42: 0 | R42: 0 | S42: 0 | T42: 0 | U42: 0 | V42: 0 | W42: 0 | X42: 0 | Y42: 0 | Z42: 0 | AA42: 0 | AB42: 0
...

Sheet Cantidad Producto 2-2028
B2: CANTIDADES DE ENERGÍA SOLICITADAS (kWh)
B3: CENTRAL HIDROELECTRICA DE CALDAS S.A. E.S.P. -BENEFICIO E INTERÉS COLECTIVO
B4: 2028
B6: Mes | C6: Tipo Día | D6: Días | E6: H1 | F6: H2 | G6: H3 | H6: H4 | I6: H5 | J6: H6 | K6: H7 | L6: H8 | M6: H9 | N6: H10 | O6: H11 | P6: H12 | Q6: H13 | R6: H14 | S6: H15 | T6: H16 | U6: H17 | V6: H18 | W6: H19 | X6: H20 | Y6: H21 | Z6: H22 | AA6: H23 | AB6: H24 | AC6: TOTAL MES
B7: Ene | C7: Ordinario | D7: 20 | E7: 2924 | F7: 2709 | G7: 2611 | H7: 2533 | I7: 2466 | J7: 2330 | K7: 2040 | L7: 4095 | M7: 4459 | N7: 4692 | O7: 4800 | P7: 4883 | Q7: 5108 | R7: 5061 | S7: 4928 | T7: 4850 | U7: 4808 | V7: 1688 | W7: 2003 | X7: 2312 | Y7: 2331 | Z7: 2243 | AA7: 2059 | AB7: 1927 | AC7: =+SUM(E7:AB7)*D7+SUM(E8:AB8)*D8+SUM(E9:AB9)*D9+SUM(E10:AB10)*D10 -> 2766303 | AE7: =((+AC7)*1000)/1000 -> 2766303
B8: Ene | C8: Sábado | D8: 4 | E8: 2467 | F8: 2406 | G8: 2423 | H8: 2418 | I8: 2687 | J8: 3689 | K8: 4087 | L8: 5705 | M8: 5295 | N8: 5425 | O8: 5741 | P8: 6263 | Q8: 6062 | R8: 6229 | S8: 6567 | T8: 6723 | U8: 6654 | V8: 3281 | W8: 3481 | X8: 3686 | Y8: 3601 | Z8: 3237 | AA8: 2351 | AB8: 1538 | AE8: =((+AC11)*1000)/1000 -> 2501857
B9: Ene | C9: Domingo | D9: 5 | E9: 2218 | F9: 2263 | G9: 2257 | H9: 2365 | I9: 2858 | J9: 4230 | K9: 5412 | L9: 7501 | M9: 7136 | N9: 7056 | O9: 7284 | P9: 7910 | Q9: 7280 | R9: 7025 | S9: 7413 | T9: 7522 | U9: 7451 | V9: 4291 | W9: 4686 | X9: 4275 | Y9: 3821 | Z9: 3438 | AA9: 2986 | AB9: 2671 | AE9: =((+AC15)*1000)/1000 -> 2619980
B10: Ene | C10: Festivo | D10: 2 | E10: 2356 | F10: 2276 | G10: 2125 | H10: 2101 | I10: 2140 | J10: 2206 | K10: 2392 | L10: 4297 | M10: 4564 | N10: 4634 | O10: 4815 | P10: 4805 | Q10: 4930 | R10: 4827 | S10: 4818 | T10: 4778 | U10: 4783 | V10: 1866 | W10: 2207 | X10: 2249 | Y10: 2056 | Z10: 1964 | AA10: 2080 | AB10: 1878 | AE10: =((+AC19)*1000)/1000 -> 2723545
B11: Feb | C11: Ordinario | D11: 21 | E11: 1782 | F11: 1854 | G11: 1710 | H11: 1858 | I11: 1796 | J11: 2871 | K11: 3806 | L11: 5645 | M11: 5519 | N11: 5463 | O11: 5575 | P11: 5698 | Q11: 5508 | R11: 5457 | S11: 5580 | T11: 5684 | U11: 5729 | V11: 2708 | W11: 2995 | X11: 2697 | Y11: 2482 | Z11: 2240 | AA11: 1738 | AB11: 1250 | AC11: =+SUM(E11:AB11)*D11+SUM(E12:AB12)*D12+SUM(E13:AB13)*D13+SUM(E14:AB14)*D14 -> 2501857 | AE11: =((+AC23)*1000)/1000 -> 2724187
B12: Feb | C12: Sábado | D12: 4 | E12: 2192 | F12: 2088 | G12: 2044 | H12: 1946 | I12: 1998 | J12: 2158 | K12: 2949 | L12: 5260 | M12: 5489 | N12: 5595 | O12: 5632 | P12: 5744 | Q12: 5501 | R12: 5412 | S12: 5438 | T12: 5429 | U12: 5628 | V12: 2837 | W12: 2921 | X12: 2748 | Y12: 2609 | Z12: 2137 | AA12: 1689 | AB12: 1243 | AE12: =((+AC27)*1000)/1000 -> 2695390
B13: Feb | C13: Domingo | D13: 4 | E13: 2106 | F13: 1991 | G13: 1847 | H13: 1792 | I13: 1853 | J13: 1858 | K13: 2204 | L13: 4296 | M13: 4694 | N13: 4914 | O13: 4846 | P13: 5176 | Q13: 5401 | R13: 5485 | S13: 5319 | T13: 5773 | U13: 5078 | V13: 2349 | W13: 3163 | X13: 2188 | Y13: 2141 | Z13: 1821 | AA13: 1311 | AB13: 1035 | AE13: =((+AC31)*1000)/1000 -> 2897980
B14: Feb | C14: Festivo | D14: 0 | E14: 0 | F14: 0 | G14: 0 | H14: 0 | I14: 0 | J14: 0 | K14: 0 | L14: 0 | M14: 0 | N14: 0 | O14: 0 | P14: 0 | Q14: 0 | R14: 0 | S14: 0 | T14: 0 | U14: 0 | V14: 0 | W14: 0 | X14: 0 | Y14: 0 | Z14: 0 | AA14: 0 | AB14: 0 | AE14: =((+AC35)*1000)/1000 -> 2910774
B15: Mar | C15: Ordinario | D15: 22 | E15: 2014 | F15: 1914 | G15: 1890 | H15: 1891 | I15: 2173 | J15: 2929 | K15: 3492 | L15: 5084 | M15: 4950 | N15: 4928 | O15: 4886 | P15: 5329 | Q15: 5280 | R15: 5208 | S15: 5362 | T15: 5421 | U15: 5280 | V15: 2499 | W15: 2858 | X15: 2842 | Y15: 2775 | Z15: 2226 | AA15: 1876 | AB15: 1356 | AC15: =+SUM(E15:AB15)*D15+SUM(E16:AB16)*D16+SUM(E17:AB17)*D17+SUM(E18:AB18)*D18 -> 2619980 | AE15: =((+AC39)*1000)/1000 -> 2814865
B16: Mar | C16: Sábado | D16: 4 | E16: 1762 | F16: 2068 | G16: 2015 | H16: 1981 | I16: 2090 | J16: 2355 | K16: 2964 | L16: 5173 | M16: 5354 | N16: 5507 | O16: 5510 | P16: 5394 | Q16: 5457 | R16: 5387 | S16: 5472 | T16: 5569 | U16: 5569 | V16: 2700 | W16: 2663 | X16: 2922 | Y16: 2848 | Z16: 2540 | AA16: 2181 | AB16: 1729 | AE16: =((+AC43)*1000)/1000 -> 2910046
B17: Mar | C17: Domingo | D17: 4 | E17: 2379 | F17: 2306 | G17: 2068 | H17: 2209 | I17: 2233 | J17: 1610 | K17: 2267 | L17: 4224 | M17: 4480 | N17: 4428 | O17: 4702 | P17: 5066 | Q17: 4915 | R17: 5072 | S17: 5037 | T17: 5033 | U17: 5024 | V17: 2455 | W17: 2619 | X17: 2684 | Y17: 2950 | Z17: 2482 | AA17: 2095 | AB17: 1512 | AE17: =((+AC47)*1000)/1000 -> 2854598
B18: Mar | C18: Festivo | D18: 1 | E18: 2737 | F18: 2748 | G18: 2537 | H18: 2562 | I18: 2603 | J18: 2443 | K18: 2710 | L18: 4552 | M18: 4716 | N18: 4887 | O18: 5322 | P18: 5465 | Q18: 5609 | R18: 5514 | S18: 5785 | T18: 5781 | U18: 5801 | V18: 3318 | W18: 3902 | X18: 3689 | Y18: 3618 | Z18: 3380 | AA18: 2217 | AB18: 1658 | AE18: =((+AC51)*1000)/1000 -> 2942882
B19: Abr | C19: Ordinario | D19: 18 | E19: 2257 | F19: 2193 | G19: 2232 | H19: 2140 | I19: 2312 | J19: 2784 | K19: 3400 | L19: 5281 | M19: 5305 | N19: 5216 | O19: 5530 | P19: 5853 | Q19: 5819 | R19: 5774 | S19: 6023 | T19: 5939 | U19: 5944 | V19: 2751 | W19: 2932 | X19: 2909 | Y19: 2900 | Z19: 2580 | AA19: 2139 | AB19: 1683 | AC19: =+SUM(E19:AB19)*D19+SUM(E20:AB20)*D20+SUM(E21:AB21)*D21+SUM(E22:AB22)*D22 -> 2723545
B20: Abr | C20: Sábado | D20: 5 | E20: 2493 | F20: 2362 | G20: 2327 | H20: 2307 | I20: 2385 | J20: 2439 | K20: 2722 | L20: 5010 | M20: 4928 | N20: 4986 | O20: 5335 | P20: 5297 | Q20: 5524 | R20: 5540 | S20: 5794 | T20: 5895 | U20: 6087 | V20: 3302 | W20: 3579 | X20: 2845 | Y20: 2721 | Z20: 2601 | AA20: 2365 | AB20: 2118
B21: Abr | C21: Domingo | D21: 5 | E21: 2704 | F21: 2479 | G21: 2305 | H21: 2336 | I21: 2178 | J21: 2198 | K21: 2508 | L21: 4333 | M21: 4746 | N21: 4743 | O21: 4973 | P21: 4999 | Q21: 5218 | R21: 5170 | S21: 5288 | T21: 5255 | U21: 5630 | V21: 2709 | W21: 3017 | X21: 2899 | Y21: 2941 | Z21: 2816 | AA21: 2608 | AB21: 1684
B22: Abr | C22: Festivo | D22: 2 | E22: 3098 | F22: 2817 | G22: 2795 | H22: 2689 | I22: 2759 | J22: 2770 | K22: 3027 | L22: 5187 | M22: 5245 | N22: 5057 | O22: 4861 | P22: 5362 | Q22: 5398 | R22: 5211 | S22: 5447 | T22: 5497 | U22: 5646 | V22: 2902 | W22: 3023 | X22: 2878 | Y22: 2786 | Z22: 2992 | AA22: 2989 | AB22: 2525
B23: May | C23: Ordinario | D23: 21 | E23: 2308 | F23: 2221 | G23: 2130 | H23: 2167 | I23: 2345 | J23: 2884 | K23: 3402 | L23: 5191 | M23: 5122 | N23: 4883 | O23: 4986 | P23: 5437 | Q23: 5392 | R23: 5519 | S23: 5787 | T23: 5783 | U23: 5769 | V23: 2725 | W23: 2857 | X23: 2880 | Y23: 2775 | Z23: 2483 | AA23: 2130 | AB23: 1695 | AC23: =+SUM(E23:AB23)*D23+SUM(E24:AB24)*D24+SUM(E25:AB25)*D25+SUM(E26:AB26)*D26 -> 2724187
B24: May | C24: Sábado | D24: 4 | E24: 2533 | F24: 2209 | G24: 2222 | H24: 2203 | I24: 2258 | J24: 2288 | K24: 2720 | L24: 4871 | M24: 5153 | N24: 5264 | O24: 5235 | P24: 5212 | Q24: 5325 | R24: 5186 | S24: 5244 | T24: 5298 | U24: 5370 | V24: 2524 | W24: 2734 | X24: 2898 | Y24: 2753 | Z24: 2567 | AA24: 2199 | AB24: 1798
B25: May | C25: Domingo | D25: 4 | E25: 2503 | F25: 2384 | G25: 2102 | H25: 2102 | I25: 1977 | J25: 2093 | K25: 2350 | L25: 4391 | M25: 4684 | N25: 4771 | O25: 4870 | P25: 4865 | Q25: 5004 | R25: 4878 | S25: 4865 | T25: 5040 | U25: 5531 | V25: 1933 | W25: 2815 | X25: 2774 | Y25: 2638 | Z25: 2313 | AA25: 1778 | AB25: 1226
B26: May | C26: Festivo | D26: 2 | E26: 2098 | F26: 2583 | G26: 2627 | H26: 2414 | I26: 2725 | J26: 2900 | K26: 3281 | L26: 5453 | M26: 5433 | N26: 5779 | O26: 5988 | P26: 6214 | Q26: 6437 | R26: 6451 | S26: 6085 | T26: 6079 | U26: 5823 | V26: 3007 | W26: 3341 | X26: 2820 | Y26: 2633 | Z26: 2614 | AA26: 2330 | AB26: 1931
B27: Jun | C27: Ordinario | D27: 20 | E27: 2364 | F27: 2247 | G27: 2220 | H27: 2174 | I27: 2407 | J27: 2949 | K27: 3459 | L27: 5392 | M27: 5288 | N27: 5341 | O27: 5472 | P27: 5564 | Q27: 5616 | R27: 5644 | S27: 5857 | T27: 5859 | U27: 5982 | V27: 2911 | W27: 3231 | X27: 3077 | Y27: 2851 | Z27: 2467 | AA27: 2088 | AB27: 1737 | AC27: =+SUM(E27:AB27)*D27+SUM(E28:AB28)*D28+SUM(E29:AB29)*D29+SUM(E30:AB30)*D30 -> 2695390
B28: Jun | C28: Sábado | D28: 4 | E28: 2395 | F28: 2244 | G28: 2171 | H28: 2120 | I28: 2191 | J28: 2382 | K28: 2688 | L28: 5067 | M28: 5178 | N28: 5258 | O28: 5402 | P28: 5380 | Q28: 5417 | R28: 5325 | S28: 5200 | T28: 5233 | U28: 5332 | V28: 2552 | W28: 2751 | X28: 2907 | Y28: 2795 | Z28: 2572 | AA28: 2353 | AB28: 1996
B29: Jun | C29: Domingo | D29: 4 | E29: 2816 | F29: 2520 | G29: 2416 | H29: 2382 | I29: 2315 | J29: 2333 | K29: 2457 | L29: 4528 | M29: 4709 | N29: 4930 | O29: 5007 | P29: 5019 | Q29: 4983 | R29: 5036 | S29: 4964 | T29: 5082 | U29: 5300 | V29: 2674 | W29: 2833 | X29: 2901 | Y29: 2764 | Z29: 2601 | AA29: 2336 | AB29: 1912
B30: Jun | C30: Festivo | D30: 2 | E30: 2380 | F30: 2271 | G30: 2167 | H30: 2157 | I30: 2161 | J30: 2234 | K30: 2276 | L30: 4346 | M30: 4268 | N30: 4276 | O30: 4814 | P30: 4920 | Q30: 5287 | R30: 5375 | S30: 5400 | T30: 5481 | U30: 5459 | V30: 2485 | W30: 2737 | X30: 2633 | Y30: 2615 | Z30: 2524 | AA30: 2182 | AB30: 1823
B31: Jul | C31: Ordinario | D31: 19 | E31: 2637 | F31: 2528 | G31: 2445 | H31: 2469 | I31: 2683 | J31: 3268 | K31: 3894 | L31: 5520 | M31: 5481 | N31: 5517 | O31: 5488 | P31: 5881 | Q31: 5804 | R31: 5859 | S31: 6001 | T31: 6021 | U31: 6018 | V31: 3191 | W31: 3329 | X31: 3496 | Y31: 3345 | Z31: 2924 | AA31: 2421 | AB31: 2160 | AC31: =+SUM(E31:AB31)*D31+SUM(E32:AB32)*D32+SUM(E33:AB33)*D33+SUM(E34:AB34)*D34 -> 2897980
B32: Jul | C32: Sábado | D32: 5 | E32: 3028 | F32: 2849 | G32: 2704 | H32: 2646 | I32: 2693 | J32: 2755 | K32: 3086 | L32: 5279 | M32: 5402 | N32: 5465 | O32: 5452 | P32: 5672 | Q32: 5811 | R32: 5776 | S32: 5712 | T32: 5611 | U32: 5550 | V32: 2936 | W32: 2871 | X32: 3085 | Y32: 2868 | Z32: 2536 | AA32: 2245 | AB32: 1959
B33: Jul | C33: Domingo | D33: 5 | E33: 2463 | F33: 2281 | G33: 2250 | H33: 2207 | I33: 2167 | J33: 2091 | K33: 2405 | L33: 4218 | M33: 4470 | N33: 4458 | O33: 4490 | P33: 4821 | Q33: 4852 | R33: 4959 | S33: 5005 | T33: 4994 | U33: 5074 | V33: 2545 | W33: 2779 | X33: 3113 | Y33: 3038 | Z33: 2565 | AA33: 1930 | AB33: 1522
B34: Jul | C34: Festivo | D34: 2 | E34: 3448 | F34: 3208 | G34: 2903 | H34: 2554 | I34: 2519 | J34: 2106 | K34: 2311 | L34: 4026 | M34: 4557 | N34: 4310 | O34: 3821 | P34: 4203 | Q34: 4374 | R34: 4634 | S34: 4187 | T34: 4263 | U34: 4535 | V34: 1971 | W34: 1959 | X34: 2503 | Y34: 2781 | Z34: 2488 | AA34: 2112 | AB34: 1887
B35: Ago | C35: Ordinario | D35: 21 | E35: 3005 | F35: 2894 | G35: 2765 | H35: 2706 | I35: 2702 | J35: 2795 | K35: 2249 | L35: 4261 | M35: 4548 | N35: 4702 | O35: 4933 | P35: 5137 | Q35: 5151 | R35: 5255 | S35: 5156 | T35: 5110 | U35: 5135 | V35: 1922 | W35: 2791 | X35: 2924 | Y35: 2880 | Z35: 2651 | AA35: 2199 | AB35: 1939 | AC35: =+SUM(E35:AB35)*D35+SUM(E36:AB36)*D36+SUM(E37:AB37)*D37+SUM(E38:AB38)*D38 -> 2910774
B36: Ago | C36: Sábado | D36: 4 | E36: 2826 | F36: 2753 | G36: 2748 | H36: 2836 | I36: 3370 | J36: 5149 | K36: 5267 | L36: 6143 | M36: 5542 | N36: 5446 | O36: 5807 | P36: 6102 | Q36: 5561 | R36: 5912 | S36: 6742 | T36: 6764 | U36: 6672 | V36: 3432 | W36: 4056 | X36: 4270 | Y36: 4105 | Z36: 3792 | AA36: 2874 | AB36: 2341
B37: Ago | C37: Domingo | D37: 4 | E37: 2998 | F37: 2843 | G37: 2877 | H37: 2986 | I37: 3307 | J37: 3926 | K37: 4519 | L37: 7109 | M37: 7173 | N37: 7363 | O37: 7515 | P37: 7805 | Q37: 7220 | R37: 6762 | S37: 6653 | T37: 6688 | U37: 6885 | V37: 3969 | W37: 4840 | X37: 4475 | Y37: 3957 | Z37: 3788 | AA37: 3606 | AB37: 3456
B38: Ago | C38: Festivo | D38: 2 | E38: 3200 | F38: 3047 | G38: 2894 | H38: 2733 | I38: 2775 | J38: 2820 | K38: 2456 | L38: 4570 | M38: 4730 | N38: 4911 | O38: 4857 | P38: 5076 | Q38: 4899 | R38: 5050 | S38: 5194 | T38: 5088 | U38: 5095 | V38: 1982 | W38: 2552 | X38: 2828 | Y38: 2895 | Z38: 2920 | AA38: 2777 | AB38: 2573
B39: Sep | C39: Ordinario | D39: 21 | E39: 2982 | F39: 2873 | G39: 2834 | H39: 2795 | I39: 2944 | J39: 3420 | K39: 3224 | L39: 5143 | M39: 5118 | N39: 5230 | O39: 5329 | P39: 5535 | Q39: 5480 | R39: 5554 | S39: 5702 | T39: 5759 | U39: 5730 | V39: 2502 | W39: 3226 | X39: 3197 | Y39: 3114 | Z39: 2849 | AA39: 2521 | AB39: 2216 | AC39: =+SUM(E39:AB39)*D39+SUM(E40:AB40)*D40+SUM(E41:AB41)*D41+SUM(E42:AB42)*D42 -> 2814865
B40: Sep | C40: Sábado | D40: 5 | E40: 3251 | F40: 3015 | G40: 2952 | H40: 2903 | I40: 2981 | J40: 3090 | K40: 2881 | L40: 4939 | M40: 5255 | N40: 5416 | O40: 5457 | P40: 5571 | Q40: 5503 | R40: 5426 | S40: 5397 | T40: 5443 | U40: 5614 | V40: 2357 | W40: 3017 | X40: 2956 | Y40: 2939 | Z40: 2612 | AA40: 2429 | AB40: 2224
B41: Sep | C41: Domingo | D41: 4 | E41: 3118 | F41: 2992 | G41: 2911 | H41: 2842 | I41: 2812 | J41: 2685 | K41: 2311 | L41: 4237 | M41: 4564 | N41: 4691 | O41: 4829 | P41: 4926 | Q41: 4972 | R41: 4965 | S41: 5044 | T41: 5136 | U41: 5186 | V41: 2303 | W41: 3013 | X41: 2920 | Y41: 2925 | Z41: 2588 | AA41: 2386 | AB41: 2121
B42: Sep | C42: Festivo | D42: 0 | E42: 0 | F42: 0 | G42: 0 | H42: 0 | I42: 0 | J42: 0 | K42: 0 | L42: 0 | M42: 0 | N42: 0 | O42: 0 | P42: 0 | Q42: 0 | R42: 0 | S42: 0 | T42: 0 | U42: 0 | V42: 0 | W42: 0 | X42: 0 | Y42: 0 | Z42: 0 | AA42: 0 | AB42: 0
...

Sheet Cantidad Producto3-2029
B2: CANTIDADES DE ENERGÍA SOLICITADAS (kWh)
B3: CENTRAL HIDROELECTRICA DE CALDAS S.A. E.S.P. -BENEFICIO E INTERÉS COLECTIVO
B4: 2029
B6: Mes | C6: Tipo Día | D6: Días | E6: H1 | F6: H2 | G6: H3 | H6: H4 | I6: H5 | J6: H6 | K6: H7 | L6: H8 | M6: H9 | N6: H10 | O6: H11 | P6: H12 | Q6: H13 | R6: H14 | S6: H15 | T6: H16 | U6: H17 | V6: H18 | W6: H19 | X6: H20 | Y6: H21 | Z6: H22 | AA6: H23 | AB6: H24 | AC6: TOTAL MES
B7: Ene | C7: Ordinario | D7: 21 | E7: 5650 | F7: 5151 | G7: 4925 | H7: 4749 | I7: 4655 | J7: 4527 | K7: 3862 | L7: 8744 | M7: 9494 | N7: 10009 | O7: 10287 | P7: 10560 | Q7: 11054 | R7: 10950 | S7: 10726 | T7: 10583 | U7: 10473 | V7: 8385 | W7: 9472 | X7: 10394 | Y7: 10191 | Z7: 9565 | AA7: 8509 | AB7: 7651 | AC7: =+SUM(E7:AB7)*D7+SUM(E8:AB8)*D8+SUM(E9:AB9)*D9+SUM(E10:AB10)*D10 -> 6675330 | AE7: =((+AC7)*1000)/1000 -> 6675330
B8: Ene | C8: Sábado | D8: 4 | E8: 4716 | F8: 4525 | G8: 4530 | H8: 4508 | I8: 5059 | J8: 7130 | K8: 7841 | L8: 11869 | M8: 11155 | N8: 11468 | O8: 12125 | P8: 13243 | Q8: 12877 | R8: 13187 | S8: 13871 | T8: 14174 | U8: 14031 | V8: 11377 | W8: 12282 | X8: 13010 | Y8: 12568 | Z8: 11460 | AA8: 9145 | AB8: 6956 | AE8: =((+AC11)*1000)/1000 -> 6071720
B9: Ene | C9: Domingo | D9: 4 | E9: 4280 | F9: 4282 | G9: 4242 | H9: 4440 | I9: 5412 | J9: 8178 | K9: 10436 | L9: 15264 | M9: 14648 | N9: 14569 | O9: 15074 | P9: 16395 | Q9: 15208 | R9: 14695 | S9: 15458 | T9: 15668 | U9: 15498 | V9: 13163 | W9: 14406 | X9: 13959 | Y9: 12899 | Z9: 11726 | AA9: 10193 | AB9: 8988 | AE9: =((+AC15)*1000)/1000 -> 6318856
B10: Ene | C10: Festivo | D10: 2 | E10: 4635 | F10: 4427 | G10: 4074 | H10: 3953 | I10: 3983 | J10: 4070 | K10: 4223 | L10: 8583 | M10: 9212 | N10: 9459 | O10: 9887 | P10: 9942 | Q10: 10303 | R10: 10102 | S10: 10073 | T10: 9968 | U10: 9958 | V10: 8007 | W10: 9351 | X10: 9764 | Y10: 9178 | Z10: 8600 | AA10: 8267 | AB10: 7327 | AE10: =((+AC19)*1000)/1000 -> 6557158
B11: Feb | C11: Ordinario | D11: 20 | E11: 3388 | F11: 3499 | G11: 3189 | H11: 3499 | I11: 3445 | J11: 5991 | K11: 7869 | L11: 12322 | M11: 12001 | N11: 11875 | O11: 12164 | P11: 12482 | Q11: 12058 | R11: 11980 | S11: 12313 | T11: 12565 | U11: 12652 | V11: 10565 | W11: 11571 | X11: 11348 | Y11: 10643 | Z11: 9609 | AA11: 7821 | AB11: 6247 | AC11: =+SUM(E11:AB11)*D11+SUM(E12:AB12)*D12+SUM(E13:AB13)*D13+SUM(E14:AB14)*D14 -> 6071720 | AE11: =((+AC23)*1000)/1000 -> 6567612
B12: Feb | C12: Sábado | D12: 4 | E12: 4278 | F12: 3996 | G12: 3857 | H12: 3647 | I12: 3773 | J12: 4143 | K12: 5705 | L12: 11328 | M12: 11897 | N12: 12128 | O12: 12277 | P12: 12557 | Q12: 12085 | R12: 11845 | S12: 11879 | T12: 11855 | U12: 12283 | V12: 10657 | W12: 11227 | X12: 11246 | Y12: 10683 | Z12: 9321 | AA12: 7875 | AB12: 6427 | AE12: =((+AC27)*1000)/1000 -> 6448400
B13: Feb | C13: Domingo | D13: 4 | E13: 4169 | F13: 3841 | G13: 3493 | H13: 3345 | I13: 3417 | J13: 3398 | K13: 3967 | L13: 8921 | M13: 9872 | N13: 10437 | O13: 10330 | P13: 11063 | Q13: 11625 | R13: 11803 | S13: 11430 | T13: 12374 | U13: 10862 | V13: 9326 | W13: 11452 | X13: 9829 | Y13: 9585 | Z13: 8499 | AA13: 6808 | AB13: 5635 | AE13: =((+AC31)*1000)/1000 -> 6740976
B14: Feb | C14: Festivo | D14: 0 | E14: 0 | F14: 0 | G14: 0 | H14: 0 | I14: 0 | J14: 0 | K14: 0 | L14: 0 | M14: 0 | N14: 0 | O14: 0 | P14: 0 | Q14: 0 | R14: 0 | S14: 0 | T14: 0 | U14: 0 | V14: 0 | W14: 0 | X14: 0 | Y14: 0 | Z14: 0 | AA14: 0 | AB14: 0 | AE14: =((+AC35)*1000)/1000 -> 7014730
B15: Mar | C15: Ordinario | D15: 19 | E15: 3121 | F15: 2908 | G15: 2858 | H15: 2897 | I15: 3638 | J15: 5697 | K15: 7249 | L15: 11033 | M15: 10640 | N15: 10583 | O15: 10557 | P15: 11488 | Q15: 11234 | R15: 11047 | S15: 11407 | T15: 11569 | U15: 11320 | V15: 9895 | W15: 10951 | X15: 11026 | Y15: 10502 | Z15: 8829 | AA15: 7398 | AB15: 5697 | AC15: =+SUM(E15:AB15)*D15+SUM(E16:AB16)*D16+SUM(E17:AB17)*D17+SUM(E18:AB18)*D18 -> 6318856 | AE15: =((+AC39)*1000)/1000 -> 6783280
B16: Mar | C16: Sábado | D16: 5 | E16: 2739 | F16: 3345 | G16: 3239 | H16: 3163 | I16: 3472 | J16: 4123 | K16: 5799 | L16: 11084 | M16: 11541 | N16: 11872 | O16: 11914 | P16: 11749 | Q16: 11845 | R16: 11530 | S16: 11618 | T16: 11779 | U16: 11791 | V16: 10156 | W16: 10345 | X16: 11168 | Y16: 10716 | Z16: 9605 | AA16: 8210 | AB16: 6741 | AE16: =((+AC43)*1000)/1000 -> 7034886
B17: Mar | C17: Domingo | D17: 4 | E17: 4031 | F17: 3837 | G17: 3330 | H17: 3597 | I17: 3646 | J17: 2325 | K17: 3843 | L17: 8479 | M17: 9212 | N17: 9221 | O17: 9898 | P17: 10755 | Q17: 10538 | R17: 10746 | S17: 10588 | T17: 10497 | U17: 10453 | V17: 9287 | W17: 10005 | X17: 10348 | Y17: 10616 | Z17: 9209 | AA17: 7736 | AB17: 6030 | AE17: =((+AC47)*1000)/1000 -> 6905710
B18: Mar | C18: Festivo | D18: 3 | E18: 4720 | F18: 4716 | G18: 4298 | H18: 4318 | I18: 4455 | J18: 4074 | K18: 4775 | L18: 9124 | M18: 9561 | N18: 10194 | O18: 11405 | P18: 11816 | Q18: 12127 | R18: 11791 | S18: 12262 | T18: 12206 | U18: 12169 | V18: 10967 | W18: 12406 | X18: 12693 | Y18: 12163 | Z18: 10696 | AA18: 7880 | AB18: 6148 | AE18: =((+AC51)*1000)/1000 -> 7078222
B19: Abr | C19: Ordinario | D19: 21 | E19: 3782 | F19: 3640 | G19: 3720 | H19: 3551 | I19: 4012 | J19: 5339 | K19: 6972 | L19: 11444 | M19: 11510 | N19: 11363 | O19: 12059 | P19: 12889 | Q19: 12635 | R19: 12487 | S19: 12990 | T19: 12835 | U19: 12786 | V19: 10534 | W19: 11250 | X19: 11455 | Y19: 11095 | Z19: 9931 | AA19: 8276 | AB19: 6663 | AC19: =+SUM(E19:AB19)*D19+SUM(E20:AB20)*D20+SUM(E21:AB21)*D21+SUM(E22:AB22)*D22 -> 6557158
B20: Abr | C20: Sábado | D20: 4 | E20: 4328 | F20: 4007 | G20: 3972 | H20: 3897 | I20: 4082 | J20: 4270 | K20: 4997 | L20: 10527 | M20: 10474 | N20: 10740 | O20: 11543 | P20: 11603 | Q20: 12114 | R20: 11946 | S20: 12363 | T20: 12500 | U20: 12771 | V20: 10877 | W20: 12062 | X20: 10715 | Y20: 10183 | Z20: 9559 | AA20: 8541 | AB20: 7979
B21: Abr | C21: Domingo | D21: 5 | E21: 4778 | F21: 4231 | G21: 3833 | H21: 3855 | I21: 3544 | J21: 3557 | K21: 4361 | L21: 8776 | M21: 9909 | N21: 10101 | O21: 10612 | P21: 10628 | Q21: 10989 | R21: 10821 | S21: 11018 | T21: 10870 | U21: 11650 | V21: 9886 | W21: 10770 | X21: 10855 | Y21: 10691 | Z21: 9979 | AA21: 8892 | AB21: 6470
B22: Abr | C22: Festivo | D22: 0 | E22: 14253 | F22: 12523 | G22: 11797 | H22: 11190 | I22: 11312 | J22: 11695 | K22: 12756 | L22: 17065 | M22: 19006 | N22: 20080 | O22: 20846 | P22: 22902 | Q22: 23550 | R22: 22880 | S22: 22564 | T22: 22177 | U22: 22223 | V22: 26483 | W22: 29381 | X22: 30346 | Y22: 29247 | Z22: 27681 | AA22: 24923 | AB22: 21220
B23: May | C23: Ordinario | D23: 21 | E23: 3881 | F23: 3668 | G23: 3480 | H23: 3582 | I23: 4112 | J23: 5676 | K23: 7115 | L23: 11277 | M23: 11094 | N23: 10635 | O23: 10892 | P23: 11889 | Q23: 11703 | R23: 11884 | S23: 12466 | T23: 12444 | U23: 12402 | V23: 10478 | W23: 11040 | X23: 11318 | Y23: 10803 | Z23: 9646 | AA23: 8120 | AB23: 6571 | AC23: =+SUM(E23:AB23)*D23+SUM(E24:AB24)*D24+SUM(E25:AB25)*D25+SUM(E26:AB26)*D26 -> 6567612
B24: May | C24: Sábado | D24: 4 | E24: 4409 | F24: 3728 | G24: 3715 | H24: 3690 | I24: 3842 | J24: 4009 | K24: 5226 | L24: 10397 | M24: 11072 | N24: 11343 | O24: 11371 | P24: 11352 | Q24: 11572 | R24: 11211 | S24: 11226 | T24: 11290 | U24: 11391 | V24: 9769 | W24: 10392 | X24: 11021 | Y24: 10468 | Z24: 9683 | AA24: 8360 | AB24: 7062
B25: May | C25: Domingo | D25: 4 | E25: 4433 | F25: 4141 | G25: 3510 | H25: 3492 | I25: 3206 | J25: 3381 | K25: 4104 | L25: 8921 | M25: 9718 | N25: 9996 | O25: 10241 | P25: 10218 | Q25: 10505 | R25: 10243 | S25: 10221 | T25: 10506 | U25: 11429 | V25: 8143 | W25: 10213 | X25: 10447 | Y25: 10033 | Z25: 8932 | AA25: 7169 | AB25: 5551
B26: May | C26: Festivo | D26: 2 | E26: 3415 | F26: 4372 | G26: 4427 | H26: 3991 | I26: 4630 | J26: 4930 | K26: 5860 | L26: 10942 | M26: 11028 | N26: 11906 | O26: 12407 | P26: 12910 | Q26: 13372 | R26: 13351 | S26: 12564 | T26: 12497 | U26: 11965 | V26: 10217 | W26: 11215 | X26: 10623 | Y26: 10125 | Z26: 9534 | AA26: 8144 | AB26: 6829
B27: Jun | C27: Ordinario | D27: 19 | E27: 4097 | F27: 3831 | G27: 3749 | H27: 3675 | I27: 4258 | J27: 5681 | K27: 7070 | L27: 11650 | M27: 11351 | N27: 11480 | O27: 11831 | P27: 12093 | Q27: 12111 | R27: 12145 | S27: 12607 | T27: 12648 | U27: 12875 | V27: 10807 | W27: 11665 | X27: 11697 | Y27: 10939 | Z27: 9619 | AA27: 8080 | AB27: 6755 | AC27: =+SUM(E27:AB27)*D27+SUM(E28:AB28)*D28+SUM(E29:AB29)*D29+SUM(E30:AB30)*D30 -> 6448400
B28: Jun | C28: Sábado | D28: 5 | E28: 4109 | F28: 3788 | G28: 3572 | H28: 3471 | I28: 3663 | J28: 4102 | K28: 5062 | L28: 10667 | M28: 11032 | N28: 11222 | O28: 11599 | P28: 11586 | Q28: 11663 | R28: 11425 | S28: 11071 | T28: 11102 | U28: 11244 | V28: 9736 | W28: 10380 | X28: 10892 | Y28: 10365 | Z28: 9481 | AA28: 8522 | AB28: 7294
B29: Jun | C29: Domingo | D29: 4 | E29: 5051 | F29: 4360 | G29: 4115 | H29: 3992 | I29: 3830 | J29: 3790 | K29: 4313 | L29: 9151 | M29: 9733 | N29: 10338 | O29: 10533 | P29: 10565 | Q29: 10509 | R29: 10583 | S29: 10289 | T29: 10478 | U29: 10912 | V29: 9481 | W29: 10070 | X29: 10661 | Y29: 10252 | Z29: 9474 | AA29: 8315 | AB29: 6943
B30: Jun | C30: Festivo | D30: 2 | E30: 4102 | F30: 3815 | G30: 3602 | H30: 3549 | I30: 3534 | J30: 3623 | K30: 3891 | L30: 8837 | M30: 8760 | N30: 9096 | O30: 10249 | P30: 10540 | Q30: 11337 | R30: 11571 | S30: 11440 | T30: 11503 | U30: 11517 | V30: 9337 | W30: 9986 | X30: 10369 | Y30: 10136 | Z30: 9514 | AA30: 8170 | AB30: 6843
B31: Jul | C31: Ordinario | D31: 20 | E31: 4411 | F31: 4169 | G31: 3993 | H31: 4057 | I31: 4589 | J31: 6125 | K31: 7745 | L31: 11621 | M31: 11466 | N31: 11534 | O31: 11527 | P31: 12327 | Q31: 12133 | R31: 12223 | S31: 12537 | T31: 12630 | U31: 12638 | V31: 11108 | W31: 11489 | X31: 12240 | Y31: 11666 | Z31: 10336 | AA31: 8509 | AB31: 7415 | AC31: =+SUM(E31:AB31)*D31+SUM(E32:AB32)*D32+SUM(E33:AB33)*D33+SUM(E34:AB34)*D34 -> 6740976
B32: Jul | C32: Sábado | D32: 4 | E32: 5388 | F32: 4948 | G32: 4654 | H32: 4509 | I32: 4623 | J32: 4811 | K32: 5719 | L32: 10953 | M32: 11306 | N32: 11449 | O32: 11495 | P32: 11918 | Q32: 12262 | R32: 12093 | S32: 11923 | T32: 11658 | U32: 11456 | V32: 10345 | W32: 10393 | X32: 11115 | Y32: 10436 | Z32: 9370 | AA32: 8256 | AB32: 7239
B33: Jul | C33: Domingo | D33: 5 | E33: 4265 | F33: 3823 | G33: 3733 | H33: 3616 | I33: 3509 | J33: 3345 | K33: 4138 | L33: 8405 | M33: 9134 | N33: 9186 | O33: 9261 | P33: 9866 | Q33: 9973 | R33: 10171 | S33: 10185 | T33: 10127 | U33: 10217 | V33: 9106 | W33: 9832 | X33: 10981 | Y33: 10796 | Z33: 9422 | AA33: 7353 | AB33: 6036
B34: Jul | C34: Festivo | D34: 2 | E34: 6159 | F34: 5607 | G34: 5004 | H34: 4244 | I34: 4221 | J34: 3372 | K34: 3963 | L34: 8156 | M34: 9293 | N34: 9016 | O34: 8004 | P34: 8844 | Q34: 9301 | R34: 9761 | S34: 8726 | T34: 8809 | U34: 9327 | V34: 8234 | W34: 8459 | X34: 9949 | Y34: 10333 | Z34: 9349 | AA34: 7814 | AB34: 6825
B35: Ago | C35: Ordinario | D35: 21 | E35: 5473 | F35: 5185 | G35: 4949 | H35: 4846 | I35: 4943 | J35: 5447 | K35: 4660 | L35: 9345 | M35: 9862 | N35: 10202 | O35: 10730 | P35: 11210 | Q35: 11221 | R35: 11385 | S35: 11258 | T35: 11203 | U35: 11222 | V35: 8953 | W35: 10819 | X35: 11465 | Y35: 11134 | Z35: 10217 | AA35: 8506 | AB35: 7317 | AC35: =+SUM(E35:AB35)*D35+SUM(E36:AB36)*D36+SUM(E37:AB37)*D37+SUM(E38:AB38)*D38 -> 7014730
B36: Ago | C36: Sábado | D36: 4 | E36: 5104 | F36: 4925 | G36: 4884 | H36: 5043 | I36: 6164 | J36: 9945 | K36: 10534 | L36: 13028 | M36: 11888 | N36: 11663 | O36: 12513 | P36: 13107 | Q36: 12102 | R36: 12710 | S36: 14393 | T36: 14377 | U36: 14088 | V36: 11683 | W36: 13065 | X36: 13910 | Y36: 13374 | Z36: 12318 | AA36: 9968 | AB36: 8276
B37: Ago | C37: Domingo | D37: 4 | E37: 5730 | F37: 5329 | G37: 5330 | H37: 5485 | I37: 6148 | J37: 7415 | K37: 8948 | L37: 14820 | M37: 15129 | N37: 15577 | O37: 15855 | P37: 16401 | Q37: 15292 | R37: 14327 | S37: 14045 | T37: 14037 | U37: 14356 | V37: 12514 | W37: 14427 | X37: 14021 | Y37: 12754 | Z37: 11954 | AA37: 11040 | AB37: 10185
B38: Ago | C38: Festivo | D38: 2 | E38: 5931 | F38: 5563 | G38: 5248 | H38: 4865 | I38: 4948 | J38: 5040 | K38: 4375 | L38: 9236 | M38: 9654 | N38: 10088 | O38: 10105 | P38: 10565 | Q38: 10435 | R38: 10641 | S38: 10823 | T38: 10577 | U38: 10678 | V38: 8446 | W38: 9782 | X38: 10648 | Y38: 10588 | Z38: 10124 | AA38: 9166 | AB38: 8181
B39: Sep | C39: Ordinario | D39: 20 | E39: 5456 | F39: 5200 | G39: 5106 | H39: 5043 | I39: 5463 | J39: 6758 | K39: 6677 | L39: 11204 | M39: 11110 | N39: 11323 | O39: 11662 | P39: 12107 | Q39: 11940 | R39: 12083 | S39: 12437 | T39: 12551 | U39: 12497 | V39: 10076 | W39: 11869 | X39: 12021 | Y39: 11534 | Z39: 10519 | AA39: 9084 | AB39: 7858 | AC39: =+SUM(E39:AB39)*D39+SUM(E40:AB40)*D40+SUM(E41:AB41)*D41+SUM(E42:AB42)*D42 -> 6783280
B40: Sep | C40: Sábado | D40: 5 | E40: 6043 | F40: 5518 | G40: 5345 | H40: 5231 | I40: 5404 | J40: 5649 | K40: 5542 | L40: 10634 | M40: 11349 | N40: 11704 | O40: 11871 | P40: 12062 | Q40: 11965 | R40: 11773 | S40: 11672 | T40: 11705 | U40: 11957 | V40: 9615 | W40: 11260 | X40: 11200 | Y40: 10854 | Z40: 9870 | AA40: 8885 | AB40: 7959
B41: Sep | C41: Domingo | D41: 5 | E41: 5829 | F41: 5501 | G41: 5296 | H41: 5111 | I41: 4990 | J41: 4762 | K41: 4130 | L41: 8757 | M41: 9574 | N41: 9936 | O41: 10263 | P41: 10513 | Q41: 10688 | R41: 10628 | S41: 10712 | T41: 10827 | U41: 10875 | V41: 9000 | W41: 10829 | X41: 10934 | Y41: 10699 | Z41: 9608 | AA41: 8432 | AB41: 7383
B42: Sep | C42: Festivo | D42: 0 | E42: 0 | F42: 0 | G42: 0 | H42: 0 | I42: 0 | J42: 0 | K42: 0 | L42: 0 | M42: 0 | N42: 0 | O42: 0 | P42: 0 | Q42: 0 | R42: 0 | S42: 0 | T42: 0 | U42: 0 | V42: 0 | W42: 0 | X42: 0 | Y42: 0 | Z42: 0 | AA42: 0 | AB42: 0
...

Sheet Cantidad Producto 1-2030
B2: CANTIDADES DE ENERGÍA SOLICITADAS (kWh)
B3: CENTRAL HIDROELECTRICA DE CALDAS S.A. E.S.P. -BENEFICIO E INTERÉS COLECTIVO
B4: 2030
B6: Mes | C6: Tipo Día | D6: Días | E6: H1 | F6: H2 | G6: H3 | H6: H4 | I6: H5 | J6: H6 | K6: H7 | L6: H8 | M6: H9 | N6: H10 | O6: H11 | P6: H12 | Q6: H13 | R6: H14 | S6: H15 | T6: H16 | U6: H17 | V6: H18 | W6: H19 | X6: H20 | Y6: H21 | Z6: H22 | AA6: H23 | AB6: H24 | AC6: TOTAL MES | AE6: 1000
B7: Ene | C7: Ordinario | D7: 21 | E7: 15518 | F7: 14256 | G7: 13668 | H7: 13297 | I7: 13406 | J7: 14035 | K7: 13508 | L7: 23275 | M7: 24977 | N7: 26367 | O7: 27378 | P7: 28487 | Q7: 29281 | R7: 28922 | S7: 28559 | T7: 28230 | U7: 27910 | V7: 24482 | W7: 27313 | X7: 29487 | Y7: 28640 | Z7: 26648 | AA7: 23445 | AB7: 20715 | AC7: =+SUM(E7:AB7)*D7+SUM(E8:AB8)*D8+SUM(E9:AB9)*D9+SUM(E10:AB10)*D10 -> 17721564 | AE7: =((+AC7)*1000)/1000 -> 17721564
B8: Ene | C8: Sábado | D8: 4 | E8: 14153 | F8: 13325 | G8: 13057 | H8: 12904 | I8: 13949 | J8: 17814 | K8: 19383 | L8: 27991 | M8: 27627 | N8: 28727 | O8: 30247 | P8: 32643 | Q8: 32120 | R8: 32338 | S8: 33252 | T8: 33575 | U8: 33239 | V8: 29043 | W8: 31650 | X8: 33496 | Y8: 32210 | Z8: 29535 | AA8: 24544 | AB8: 19719 | AE8: =((+AC11)*1000)/1000 -> 16439400
B9: Ene | C9: Domingo | D9: 4 | E9: 13586 | F9: 13060 | G9: 12712 | H9: 12877 | I9: 14453 | J9: 19218 | K9: 23057 | L9: 32552 | M9: 32396 | N9: 32961 | O9: 34263 | P9: 36938 | Q9: 35232 | R9: 34232 | S9: 35249 | T9: 35435 | U9: 34996 | V9: 31490 | W9: 34601 | X9: 34642 | Y9: 32547 | Z9: 29776 | AA9: 25907 | AB9: 22707 | AE9: =((+AC15)*1000)/1000 -> 17111754
B10: Ene | C10: Festivo | D10: 2 | E10: 14556 | F10: 13756 | G10: 12801 | H10: 12314 | I10: 12210 | J10: 12344 | K10: 12312 | L10: 20698 | M10: 22360 | N10: 23458 | O10: 24713 | P10: 25415 | Q10: 26424 | R10: 26030 | S10: 25730 | T10: 25373 | U10: 25257 | V10: 22429 | W10: 26040 | X10: 27368 | Y10: 25967 | Z10: 24199 | AA10: 22455 | AB10: 19775 | AE10: =((+AC19)*1000)/1000 -> 17481176
B11: Feb | C11: Ordinario | D11: 20 | E11: 11872 | F11: 11690 | G11: 11004 | H11: 11481 | I11: 11824 | J11: 17713 | K11: 21567 | L11: 30108 | M11: 29805 | N11: 29975 | O11: 30998 | P11: 32064 | Q11: 31162 | R11: 30929 | S11: 31662 | T11: 32128 | U11: 32160 | V11: 28631 | W11: 31297 | X11: 31770 | Y11: 30032 | Z11: 27144 | AA11: 22511 | AB11: 18526 | AC11: =+SUM(E11:AB11)*D11+SUM(E12:AB12)*D12+SUM(E13:AB13)*D13+SUM(E14:AB14)*D14 -> 16439400 | AE11: =((+AC23)*1000)/1000 -> 17473832
B12: Feb | C12: Sábado | D12: 4 | E12: 13738 | F12: 12829 | G12: 12305 | H12: 11876 | I12: 12255 | J12: 13331 | K12: 16512 | L12: 27910 | M12: 29659 | N12: 30538 | O12: 31287 | P12: 32181 | Q12: 31468 | R12: 30640 | S12: 30393 | T12: 30255 | U12: 30895 | V12: 28365 | W12: 30284 | X12: 31123 | Y12: 29600 | Z12: 26449 | AA12: 22847 | AB12: 19245 | AE12: =((+AC27)*1000)/1000 -> 17225127
B13: Feb | C13: Domingo | D13: 4 | E13: 13772 | F13: 12696 | G13: 11821 | H13: 11394 | I13: 11410 | J13: 11453 | K13: 12497 | L13: 22287 | M13: 24849 | N13: 26492 | O13: 26745 | P13: 28484 | Q13: 29707 | R13: 29820 | S13: 28926 | T13: 30329 | U13: 27578 | V13: 25431 | W13: 30006 | X13: 28203 | Y13: 27466 | Z13: 24685 | AA13: 20435 | AB13: 17114 | AE13: =((+AC31)*1000)/1000 -> 17733863
B14: Feb | C14: Festivo | D14: 0 | E14: 0 | F14: 0 | G14: 0 | H14: 0 | I14: 0 | J14: 0 | K14: 0 | L14: 0 | M14: 0 | N14: 0 | O14: 0 | P14: 0 | Q14: 0 | R14: 0 | S14: 0 | T14: 0 | U14: 0 | V14: 0 | W14: 0 | X14: 0 | Y14: 0 | Z14: 0 | AA14: 0 | AB14: 0 | AE14: =((+AC35)*1000)/1000 -> 18358026
B15: Mar | C15: Ordinario | D15: 20 | E15: 11461 | F15: 10719 | G15: 10465 | H15: 10456 | I15: 12053 | J15: 16835 | K15: 19875 | L15: 27350 | M15: 26965 | N15: 27248 | O15: 27682 | P15: 29720 | Q15: 29139 | R15: 28772 | S15: 29549 | T15: 29810 | U15: 29335 | V15: 27125 | W15: 29896 | X15: 30800 | Y15: 29440 | Z15: 25577 | AA15: 21726 | AB15: 17669 | AC15: =+SUM(E15:AB15)*D15+SUM(E16:AB16)*D16+SUM(E17:AB17)*D17+SUM(E18:AB18)*D18 -> 17111754 | AE15: =((+AC39)*1000)/1000 -> 17784623
B16: Mar | C16: Sábado | D16: 5 | E16: 11046 | F16: 11561 | G16: 11146 | H16: 10912 | I16: 11532 | J16: 13019 | K16: 16031 | L16: 26758 | M16: 28294 | N16: 29382 | O16: 29823 | P16: 29932 | Q16: 30104 | R16: 29328 | S16: 29278 | T16: 29403 | U16: 29328 | V16: 27015 | W16: 28477 | X16: 30433 | Y16: 29150 | Z16: 26542 | AA16: 23132 | AB16: 19621 | AE16: =((+AC43)*1000)/1000 -> 18398248
B17: Mar | C17: Domingo | D17: 5 | E17: 13362 | F17: 12493 | G17: 11350 | H17: 11604 | I17: 11637 | J17: 9447 | K17: 11774 | L17: 20986 | M17: 23129 | N17: 23877 | O17: 25367 | P17: 27134 | Q17: 26968 | R17: 27341 | S17: 26835 | T17: 26576 | U17: 26393 | V17: 24792 | W17: 27124 | X17: 28663 | Y17: 28840 | Z17: 25660 | AA17: 21911 | AB17: 17839 | AE17: =((+AC47)*1000)/1000 -> 18072840
B18: Mar | C18: Festivo | D18: 1 | E18: 14200 | F18: 13681 | G18: 12722 | H18: 12625 | I18: 12858 | J18: 12397 | K18: 13429 | L18: 22324 | M18: 23883 | N18: 25365 | O18: 27725 | P18: 28919 | Q18: 29741 | R18: 29017 | S18: 29435 | T18: 29209 | U18: 29067 | V18: 27418 | W18: 31074 | X18: 32288 | Y18: 30950 | Z18: 27854 | AA18: 22224 | AB18: 18264 | AE18: =((+AC51)*1000)/1000 -> 18469208
B19: Abr | C19: Ordinario | D19: 20 | E19: 12515 | F19: 11867 | G19: 11831 | H19: 11506 | I19: 12726 | J19: 16456 | K19: 19789 | L19: 28362 | M19: 28464 | N19: 28519 | O19: 30194 | P19: 31791 | Q19: 31346 | R19: 31121 | S19: 32176 | T19: 31977 | U19: 31955 | V19: 28438 | W19: 30920 | X19: 31693 | Y19: 30576 | Z19: 27569 | AA19: 23200 | AB19: 19148 | AC19: =+SUM(E19:AB19)*D19+SUM(E20:AB20)*D20+SUM(E21:AB21)*D21+SUM(E22:AB22)*D22 -> 17481176
B20: Abr | C20: Sábado | D20: 4 | E20: 13752 | F20: 12785 | G20: 12385 | H20: 12189 | I20: 12683 | J20: 13426 | K20: 14827 | L20: 26361 | M20: 27140 | N20: 28069 | O20: 29761 | P20: 30155 | Q20: 31201 | R20: 30413 | S20: 30893 | T20: 31053 | U20: 31510 | V20: 28132 | W20: 31919 | X20: 30091 | Y20: 28638 | Z20: 26829 | AA20: 23928 | AB20: 22215
B21: Abr | C21: Domingo | D21: 4 | E21: 14783 | F21: 13363 | G21: 12379 | H21: 12210 | I21: 11571 | J21: 11641 | K21: 12879 | L21: 21818 | M21: 24577 | N21: 25500 | O21: 26819 | P21: 27247 | Q21: 28274 | R21: 28013 | S21: 27963 | T21: 27509 | U21: 28726 | V21: 26255 | W21: 29058 | X21: 29723 | Y21: 29132 | Z21: 26993 | AA21: 23880 | AB21: 18469
B22: Abr | C22: Festivo | D22: 2 | E22: 15883 | F22: 14342 | G22: 13928 | H22: 13402 | I22: 13554 | J22: 13658 | K22: 14759 | L22: 24881 | M22: 26255 | N22: 26310 | O22: 25842 | P22: 28135 | Q22: 28846 | R22: 28052 | S22: 28330 | T22: 28141 | U22: 28494 | V22: 26586 | W22: 29015 | X22: 29337 | Y22: 28153 | Z22: 27400 | AA22: 25619 | AB22: 22002
B23: May | C23: Ordinario | D23: 22 | E23: 12345 | F23: 11641 | G23: 11155 | H23: 11295 | I23: 12608 | J23: 16627 | K23: 19640 | L23: 27699 | M23: 27537 | N23: 27058 | O23: 28039 | P23: 30225 | Q23: 29710 | R23: 29912 | S23: 30996 | T23: 30954 | U23: 30833 | V23: 27884 | W23: 30091 | X23: 30962 | Y23: 29545 | Z23: 26637 | AA23: 22611 | AB23: 18699 | AC23: =+SUM(E23:AB23)*D23+SUM(E24:AB24)*D24+SUM(E25:AB25)*D25+SUM(E26:AB26)*D26 -> 17473832
B24: May | C24: Sábado | D24: 4 | E24: 13636 | F24: 12048 | G24: 11788 | H24: 11629 | I24: 12050 | J24: 12658 | K24: 15169 | L24: 25781 | M24: 27662 | N24: 28636 | O24: 29087 | P24: 29415 | Q24: 29759 | R24: 28791 | S24: 28567 | T24: 28547 | U24: 28698 | V24: 26332 | W24: 28655 | X24: 30071 | Y24: 28624 | Z24: 26551 | AA24: 23233 | AB24: 19846
B25: May | C25: Domingo | D25: 4 | E25: 13802 | F25: 12830 | G25: 11469 | H25: 11234 | I25: 10721 | J25: 10950 | K25: 12153 | L25: 21744 | M25: 23956 | N25: 25133 | O25: 26053 | P25: 26423 | Q25: 26955 | R25: 26267 | S25: 25896 | T25: 26267 | U25: 27826 | V25: 22689 | W25: 27511 | X25: 28462 | Y25: 27496 | Z25: 24865 | AA25: 20746 | AB25: 16749
B26: May | C26: Festivo | D26: 1 | E26: 11666 | F26: 12866 | G26: 12759 | H26: 11874 | I26: 13045 | J26: 13621 | K26: 15214 | L26: 25268 | M26: 26214 | N26: 28387 | O26: 29939 | P26: 31446 | Q26: 32487 | R26: 32201 | S26: 30527 | T26: 30242 | U26: 29252 | V26: 26748 | W26: 29881 | X26: 29447 | Y26: 28085 | Z26: 26146 | AA26: 22449 | AB26: 18882
B27: Jun | C27: Ordinario | D27: 18 | E27: 12925 | F27: 12077 | G27: 11764 | H27: 11607 | I27: 12946 | J27: 16351 | K27: 19370 | L27: 28545 | M27: 28378 | N27: 29011 | O27: 30182 | P27: 31248 | Q27: 31061 | R27: 30942 | S27: 31814 | T27: 31798 | U27: 32122 | V27: 28849 | W27: 31511 | X27: 32085 | Y27: 30222 | Z27: 27029 | AA27: 22923 | AB27: 19301 | AC27: =+SUM(E27:AB27)*D27+SUM(E28:AB28)*D28+SUM(E29:AB29)*D29+SUM(E30:AB30)*D30 -> 17225127
B28: Jun | C28: Sábado | D28: 5 | E28: 13352 | F28: 12329 | G28: 11737 | H28: 11426 | I28: 11944 | J28: 12998 | K28: 15115 | L28: 26549 | M28: 27912 | N28: 28736 | O28: 29781 | P28: 30212 | Q28: 30324 | R28: 29612 | S28: 28823 | T28: 28752 | U28: 28897 | V28: 26690 | W28: 28996 | X28: 30455 | Y28: 29021 | Z28: 26670 | AA28: 23933 | AB28: 20617
B29: Jun | C29: Domingo | D29: 5 | E29: 15101 | F29: 13505 | G29: 12730 | H29: 12357 | I29: 12043 | J29: 11901 | K29: 12692 | L29: 22410 | M29: 24278 | N29: 25902 | O29: 26657 | P29: 27179 | Q29: 27308 | R29: 27206 | S29: 26448 | T29: 26627 | U29: 27251 | V29: 25281 | W29: 27500 | X29: 29135 | Y29: 28114 | Z29: 26024 | AA29: 22953 | AB29: 19436
B30: Jun | C30: Festivo | D30: 2 | E30: 13305 | F30: 12363 | G30: 11726 | H30: 11467 | I30: 11525 | J30: 11692 | K30: 12048 | L30: 21790 | M30: 22493 | N30: 23582 | O30: 26306 | P30: 27485 | Q30: 29036 | R30: 28984 | S30: 28549 | T30: 28453 | U30: 28319 | V30: 25516 | W30: 28080 | X30: 29388 | Y30: 28458 | Z30: 26365 | AA30: 22682 | AB30: 19105
B31: Jul | C31: Ordinario | D31: 22 | E31: 13224 | F31: 12412 | G31: 11948 | H31: 11989 | I31: 13253 | J31: 17040 | K31: 20178 | L31: 27945 | M31: 27900 | N31: 28399 | O31: 28953 | P31: 30950 | Q31: 30335 | R31: 30369 | S31: 31099 | T31: 31200 | U31: 31086 | V31: 28743 | W31: 30511 | X31: 32491 | Y31: 30990 | Z31: 27818 | AA31: 23275 | AB31: 20007 | AC31: =+SUM(E31:AB31)*D31+SUM(E32:AB32)*D32+SUM(E33:AB33)*D33+SUM(E34:AB34)*D34 -> 17733863
B32: Jul | C32: Sábado | D32: 3 | E32: 14791 | F32: 13669 | G32: 12920 | H32: 12645 | I32: 12957 | J32: 13604 | K32: 15562 | L32: 26296 | M32: 27672 | N32: 28462 | O32: 28906 | P32: 30052 | Q32: 30566 | R32: 30002 | S32: 29488 | T32: 28894 | U32: 28518 | V32: 27030 | W32: 28237 | X32: 30153 | Y32: 28500 | Z32: 25952 | AA32: 22938 | AB32: 20045
B33: Jul | C33: Domingo | D33: 4 | E33: 13317 | F33: 12151 | G33: 11611 | H33: 11270 | I33: 11052 | J33: 10753 | K33: 11936 | L33: 20643 | M33: 22679 | N33: 23449 | O33: 24085 | P33: 25677 | Q33: 26008 | R33: 26204 | S33: 25961 | T33: 25738 | U33: 25814 | V33: 24358 | W33: 26752 | X33: 29460 | Y33: 28725 | Z33: 25662 | AA33: 21122 | AB33: 17724
B34: Jul | C34: Festivo | D34: 2 | E34: 16281 | F34: 14908 | G34: 13620 | H34: 12312 | I34: 12205 | J34: 10901 | K34: 11869 | L34: 20538 | M34: 23210 | N34: 23255 | O34: 22192 | P34: 24123 | Q34: 25048 | R34: 25643 | S34: 23722 | T34: 23735 | U34: 24375 | V34: 22926 | W34: 24505 | X34: 27793 | Y34: 28057 | Z34: 25526 | AA34: 21814 | AB34: 19018
B35: Ago | C35: Ordinario | D35: 20 | E35: 15087 | F35: 14261 | G35: 13677 | H35: 13463 | I35: 14067 | J35: 16365 | K35: 15506 | L35: 24490 | M35: 25585 | N35: 26474 | O35: 27946 | P35: 29284 | Q35: 28968 | R35: 29201 | S35: 29158 | T35: 28982 | U35: 28962 | V35: 25231 | W35: 29797 | X35: 31487 | Y35: 30363 | Z35: 27791 | AA35: 23248 | AB35: 19934 | AC35: =+SUM(E35:AB35)*D35+SUM(E36:AB36)*D36+SUM(E37:AB37)*D37+SUM(E38:AB38)*D38 -> 18358026
B36: Ago | C36: Sábado | D36: 5 | E36: 14870 | F36: 14114 | G36: 13823 | H36: 14006 | I36: 16073 | J36: 22850 | K36: 24129 | L36: 30274 | M36: 29106 | N36: 29305 | O36: 31158 | P36: 32642 | Q36: 30723 | R36: 31449 | S36: 34022 | T36: 33832 | U36: 33390 | V36: 29537 | W36: 33303 | X36: 35180 | Y36: 33681 | Z36: 31079 | AA36: 25787 | AB36: 21861
B37: Ago | C37: Domingo | D37: 4 | E37: 15791 | F37: 14720 | G37: 14466 | H37: 14560 | I37: 15652 | J37: 17862 | K37: 20071 | L37: 31481 | M37: 32922 | N37: 34316 | O37: 35349 | P37: 36797 | Q37: 35027 | R37: 33322 | S37: 32576 | T37: 32374 | U37: 32888 | V37: 30104 | W37: 34746 | X37: 34693 | Y37: 32208 | Z37: 30035 | AA37: 27019 | AB37: 24502
B38: Ago | C38: Festivo | D38: 2 | E38: 15908 | F38: 14950 | G38: 14102 | H38: 13383 | I38: 13582 | J38: 13860 | K38: 12596 | L38: 22422 | M38: 23963 | N38: 25529 | O38: 26229 | P38: 27780 | Q38: 27537 | R38: 27678 | S38: 27676 | T38: 27067 | U38: 27059 | V38: 23730 | W38: 27226 | X38: 29561 | Y38: 28979 | Z38: 27201 | AA38: 24093 | AB38: 21185
