Workbook

Sheet OF P1 
B1: * La energia a ofertar debe ser expresada únicamente en kilovatio (kWh) redondeado a cero decimales
B4: OFERTA PRODUCTO 1
B5: MES | C5: ENERGIA SOLICITADA (kWh) | D5: % | E5: ENERGIA OFERTADA (kWh) | F5: PRECIO $/kWh
B6: 46023 | C6: =+VLOOKUP(B6,'CURVA P1'!$A$7:$AD$56,30,FALSE) -> 31489590 | D6: % | F6: $/kWh
B7: 46054 | C7: =+VLOOKUP(B7,'CURVA P1'!$A$7:$AD$56,30,FALSE) -> 32887916
B8: 46082 | C8: =+VLOOKUP(B8,'CURVA P1'!$A$7:$AD$56,30,FALSE) -> 31497080
B9: 46113 | C9: =+VLOOKUP(B9,'CURVA P1'!$A$7:$AD$56,30,FALSE) -> 33072292
B10: 46143 | C10: =+VLOOKUP(B10,'CURVA P1'!$A$7:$AD$56,30,FALSE) -> 16640411
B11: 46174 | C11: =+VLOOKUP(B11,'CURVA P1'!$A$7:$AD$56,30,FALSE) -> 17037915
B12: 46204 | C12: =+VLOOKUP(B12,'CURVA P1'!$A$7:$AD$56,30,FALSE) -> 16335944
B13: 46235 | C13: =+VLOOKUP(B13,'CURVA P1'!$A$7:$AD$56,30,FALSE) -> 17146466
B14: 46266 | C14: =+VLOOKUP(B14,'CURVA P1'!$A$7:$AD$56,30,FALSE) -> 26119312
B15: 46296 | C15: =+VLOOKUP(B15,'CURVA P1'!$A$7:$AD$56,30,FALSE) -> 26450360
B16: 46327 | C16: =+VLOOKUP(B16,'CURVA P1'!$A$7:$AD$56,30,FALSE) -> 26048507
B17: 46357 | C17: =+VLOOKUP(B17,'CURVA P1'!$A$7:$AD$56,30,FALSE) -> 33274072
C18: =+SUM(C6:C17) -> 307999865

Sheet CURVA P1
A1: Curva de distribucion en kWh
A2: * La energia a ofertar debe ser expresada únicamente en kilovatio (kWh) redondeado a cero decimales
A4: TOTAL | C4: =+AD55 -> 307999865
A5: MES | B5: DÍA | C5: HORA 01 | D5: HORA 02 | E5: HORA 03 | F5: HORA 04 | G5: HORA 05 | H5: HORA 06 | I5: HORA 07 | J5: HORA 08 | K5: HORA 09 | L5: HORA 10 | M5: HORA 11 | N5: HORA 12 | O5: HORA 13 | P5: HORA 14 | Q5: HORA 15 | R5: HORA 16 | S5: HORA 17 | T5: HORA 18 | U5: HORA 19 | V5: HORA 20 | W5: HORA 21 | X5: HORA 22 | Y5: HORA 23 | Z5: HORA 24 | AA5: TOTAL DÍA | AB5: NUMERO DÍAS | AC5: TOTAL DÍA MES | AD5: TOTAL MES
A7: 46023 | B7: Hábil | C7: 50359 | D7: 49257 | E7: 47138 | F7: 45557 | G7: 45046 | H7: 45878 | I7: 46181 | J7: 43708 | K7: 44338 | L7: 44046 | M7: 44177 | N7: 44147 | O7: 41142 | P7: 49488 | Q7: 60425 | R7: 65754 | S7: 67413 | T7: 41305 | U7: 41832 | V7: 40086 | W7: 38615 | X7: 37650 | Y7: 36028 | Z7: 33740 | AA7: 1062299 | AB7: 20 | AC7: =+AA7*AB7 -> 21245980 | AD7: =+SUM(AC7:AC10) -> 31489590
A8: 46024 | B8: Sábado | C8: 51639 | D8: 50006 | E8: 47519 | F8: 45761 | G8: 44924 | H8: 45146 | I8: 45044 | J8: 42861 | K8: 44330 | L8: 44412 | M8: 44354 | N8: 43634 | O8: 41565 | P8: 46453 | Q8: 54131 | R8: 58851 | S8: 60276 | T8: 38700 | U8: 40333 | V8: 38860 | W8: 37362 | X8: 36080 | Y8: 34779 | Z8: 32838 | AA8: 1030084 | AB8: 5 | AC8: =+AA8*AB8 -> 5150420
A9: 46025 | B9: Domingo | C9: 50635 | D9: 49278 | E9: 47010 | F9: 45252 | G9: 44213 | H9: 43643 | I9: 42608 | J9: 36482 | K9: 34016 | L9: 32285 | M9: 30781 | N9: 30063 | O9: 31038 | P9: 35546 | Q9: 41773 | R9: 46724 | S9: 49339 | T9: 31196 | U9: 33329 | V9: 33601 | W9: 33555 | X9: 33336 | Y9: 32194 | Z9: 29741 | AA9: 891802 | AB9: 4 | AC9: =+AA9*AB9 -> 3567208
A10: 46026 | B10: Festivo | C10: 41940 | D10: 40382 | E10: 39694 | F10: 38633 | G10: 38176 | H10: 37713 | I10: 36084 | J10: 29779 | K10: 27232 | L10: 25425 | M10: 24773 | N10: 24007 | O10: 24531 | P10: 29359 | Q10: 35614 | R10: 40433 | S10: 42659 | T10: 27053 | U10: 29324 | V10: 29377 | W10: 29326 | X10: 29088 | Y10: 28024 | Z10: 26386 | AA10: 762991 | AB10: 2 | AC10: =+AA10*AB10 -> 1525982
A11: 46054 | B11: Hábil | C11: 56491 | D11: 53516 | E11: 51338 | F11: 50001 | G11: 50159 | H11: 53594 | I11: 55210 | J11: 53862 | K11: 54701 | L11: 54401 | M11: 54865 | N11: 52964 | O11: 47294 | P11: 58250 | Q11: 70378 | R11: 75877 | S11: 77090 | T11: 46208 | U11: 46232 | V11: 45329 | W11: 44436 | X11: 42300 | Y11: 38247 | Z11: 34729 | AA11: 1214368 | AB11: 20 | AC11: =+AA11*AB11 -> 24287360 | AD11: =+SUM(AC11:AC14) -> 32887916
A12: 46055 | B12: Sábado | C12: 53819 | D12: 51036 | E12: 48921 | F12: 47705 | G12: 47048 | H12: 48066 | I12: 49511 | J12: 49419 | K12: 50941 | L12: 51248 | M12: 51070 | N12: 50112 | O12: 47723 | P12: 51978 | Q12: 58887 | R12: 63702 | S12: 64870 | T12: 39745 | U12: 42002 | V12: 41964 | W12: 40466 | X12: 38848 | Y12: 36695 | Z12: 34328 | AA12: 1116466 | AB12: 4 | AC12: =+AA12*AB12 -> 4465864
A13: 46056 | B13: Domingo | C13: 55760 | D13: 52806 | E13: 50608 | F13: 48719 | G13: 47883 | H13: 47666 | I13: 47225 | J13: 42322 | K13: 40336 | L13: 39357 | M13: 38166 | N13: 37905 | O13: 38611 | P13: 42831 | Q13: 49581 | R13: 55346 | S13: 58247 | T13: 37442 | U13: 40447 | V13: 41737 | W13: 41867 | X13: 41526 | Y13: 39542 | Z13: 36273 | AA13: 1033673 | AB13: 4 | AC13: =+AA13*AB13 -> 4134692
A14: 46057 | B14: Festivo | C14: 0 | D14: 0 | E14: 0 | F14: 0 | G14: 0 | H14: 0 | I14: 0 | J14: 0 | K14: 0 | L14: 0 | M14: 0 | N14: 0 | O14: 0 | P14: 0 | Q14: 0 | R14: 0 | S14: 0 | T14: 0 | U14: 0 | V14: 0 | W14: 0 | X14: 0 | Y14: 0 | Z14: 0 | AA14: 0 | AB14: 0 | AC14: =+AA14*AB14 -> 0
A15: 46082 | B15: Hábil | C15: 51368 | D15: 48475 | E15: 46429 | F15: 44928 | G15: 44758 | H15: 46965 | I15: 46625 | J15: 44209 | K15: 44236 | L15: 43423 | M15: 43334 | N15: 41949 | O15: 37784 | P15: 48291 | Q15: 59929 | R15: 65148 | S15: 66621 | T15: 38917 | U15: 38899 | V15: 38786 | W15: 39093 | X15: 38522 | Y15: 35617 | Z15: 32690 | AA15: 1047634 | AB15: 21 | AC15: =+AA15*AB15 -> 22000314 | AD15: =+SUM(AC15:AC18) -> 31497080
B16: Sábado | C16: 53036 | D16: 50146 | E16: 47859 | F16: 45954 | G16: 44918 | H16: 44884 | I16: 44832 | J16: 43347 | K16: 44218 | L16: 44065 | M16: 43889 | N16: 42674 | O16: 40063 | P16: 45012 | Q16: 52878 | R16: 57708 | S16: 59237 | T16: 37206 | U16: 38596 | V16: 38362 | W16: 38045 | X16: 37918 | Y16: 37309 | Z16: 35447 | AA16: 1027397 | AB16: 4 | AC16: =+AA16*AB16 -> 4109588
B17: Domingo | C17: 54307 | D17: 51304 | E17: 49166 | F17: 47423 | G17: 46228 | H17: 45273 | I17: 43741 | J17: 37516 | K17: 34391 | L17: 31852 | M17: 29688 | N17: 28741 | O17: 30088 | P17: 35021 | Q17: 41806 | R17: 47367 | S17: 50238 | T17: 31423 | U17: 33657 | V17: 35599 | W17: 36548 | X17: 36993 | Y17: 34610 | Z17: 31854 | AA17: 915452 | AB17: 5 | AC17: =+AA17*AB17 -> 4577260
B18: Festivo | C18: 42361 | D18: 39395 | E18: 37594 | F18: 36348 | G18: 36025 | H18: 35604 | I18: 35443 | J18: 31786 | K18: 30422 | L18: 29569 | M18: 29717 | N18: 30038 | O18: 29873 | P18: 35332 | Q18: 41169 | R18: 44994 | S18: 47007 | T18: 27498 | U18: 30392 | V18: 32257 | W18: 32754 | X18: 32291 | Y18: 29247 | Z18: 26060 | AA18: 809918 | AB18: 1 | AC18: =+AA18*AB18 -> 809918
A19: 46113 | B19: Hábil | C19: 54112 | D19: 51100 | E19: 49042 | F19: 47561 | G19: 47598 | H19: 49302 | I19: 49891 | J19: 49194 | K19: 50572 | L19: 50204 | M19: 50970 | N19: 50042 | O19: 44855 | P19: 55383 | Q19: 68022 | R19: 73037 | S19: 73863 | T19: 43956 | U19: 44438 | V19: 43664 | W19: 43105 | X19: 42029 | Y19: 39045 | Z19: 35647 | AA19: 1157506 | AB19: 20 | AC19: =+AA19*AB19 -> 23150120 | AD19: =+SUM(AC19:AC22) -> 33072292
B20: Sábado | C20: 55623 | D20: 52812 | E20: 50701 | F20: 48709 | G20: 48019 | H20: 47476 | I20: 48345 | J20: 47163 | K20: 48995 | L20: 48726 | M20: 49194 | N20: 48527 | O20: 45874 | P20: 50440 | Q20: 57766 | R20: 62385 | S20: 63268 | T20: 40158 | U20: 41684 | V20: 40333 | W20: 39051 | X20: 37622 | Y20: 35985 | Z20: 34045 | AA20: 1097714 | AB20: 4 | AC20: =+AA20*AB20 -> 4390856
B21: Domingo | C21: 55418 | D21: 52131 | E21: 49727 | F21: 47878 | G21: 46671 | H21: 45329 | I21: 44377 | J21: 39543 | K21: 37391 | L21: 35265 | M21: 33797 | N21: 34024 | O21: 34895 | P21: 39546 | Q21: 46346 | R21: 51534 | S21: 54115 | T21: 33689 | U21: 36377 | V21: 37463 | W21: 36460 | X21: 36295 | Y21: 34263 | Z21: 31107 | AA21: 962733 | AB21: 4 | AC21: =+AA21*AB21 -> 3850932
B22: Festivo | C22: 52070 | D22: 49048 | E22: 46782 | F22: 45079 | G22: 43800 | H22: 42492 | I22: 41695 | J22: 35310 | K22: 31207 | L22: 27734 | M22: 25457 | N22: 25386 | O22: 26491 | P22: 31087 | Q22: 37855 | R22: 42510 | S22: 44890 | T22: 28285 | U22: 30975 | V22: 32104 | W22: 31476 | X22: 31425 | Y22: 30945 | Z22: 29421 | AA22: 840192 | AB22: 2 | AC22: =+AA22*AB22 -> 1680384
A23: 46143 | B23: Hábil | C23: 28720 | D23: 25771 | E23: 23445 | F23: 21787 | G23: 21279 | H23: 21378 | I23: 21748 | J23: 21050 | K23: 22666 | L23: 22622 | M23: 23165 | N23: 21980 | O23: 16957 | P23: 28078 | Q23: 40558 | R23: 45072 | S23: 45643 | T23: 17328 | U23: 15875 | V23: 15385 | W23: 15950 | X23: 15542 | Y23: 13042 | Z23: 9838 | AA23: 599078 | AB23: 19 | AC23: =+AA23*AB23 -> 11382482 | AD23: =+SUM(AC23:AC26) -> 16640411
B24: Sábado | C24: 29570 | D24: 26110 | E24: 23369 | F24: 21542 | G24: 20578 | H24: 19040 | I24: 20487 | J24: 19346 | K24: 21411 | L24: 21970 | M24: 22511 | N24: 21338 | O24: 18714 | P24: 23675 | Q24: 30947 | R24: 34302 | S24: 35033 | T24: 11024 | U24: 11981 | V24: 12005 | W24: 10833 | X24: 10146 | Y24: 9157 | Z24: 6813 | AA24: 533022 | AB24: 5 | AC24: =+AA24*AB24 -> 2665110
B25: Domingo | C25: 27539 | D25: 24850 | E25: 22586 | F25: 20745 | G25: 19484 | H25: 17142 | I25: 16948 | J25: 12209 | K25: 9695 | L25: 7589 | M25: 6486 | N25: 5675 | O25: 5385 | P25: 9405 | Q25: 16518 | R25: 21482 | S25: 24193 | T25: 5506 | U25: 7589 | V25: 8555 | W25: 9223 | X25: 10180 | Y25: 9056 | Z25: 6550 | AA25: 388959 | AB25: 5 | AC25: =+AA25*AB25 -> 1944795
B26: Festivo | C26: 20534 | D26: 17854 | E26: 15862 | F26: 14292 | G26: 13510 | H26: 11645 | I26: 12038 | J26: 7764 | K26: 6132 | L26: 4947 | M26: 4392 | N26: 4229 | O26: 4289 | P26: 9360 | Q26: 15871 | R26: 20681 | S26: 22536 | T26: 2557 | U26: 5406 | V26: 8205 | W26: 9294 | X26: 9601 | Y26: 7041 | Z26: 3392 | AA26: 324012 | AB26: 2 | AC26: =+AA26*AB26 -> 648024
A27: 46174 | B27: Hábil | C27: 30155 | D27: 27061 | E27: 24567 | F27: 22941 | G27: 22393 | H27: 22191 | I27: 23605 | J27: 23697 | K27: 25542 | L27: 25248 | M27: 25736 | N27: 25060 | O27: 19385 | P27: 29837 | Q27: 41545 | R27: 46380 | S27: 47344 | T27: 16434 | U27: 15740 | V27: 15457 | W27: 15522 | X27: 15062 | Y27: 12790 | Z27: 9634 | AA27: 628342 | AB27: 19 | AC27: =+AA27*AB27 -> 11938498 | AD27: =+SUM(AC27:AC30) -> 17037915
B28: Sábado | C28: 29736 | D28: 26725 | E28: 24348 | F28: 22491 | G28: 21847 | H28: 20448 | I28: 22012 | J28: 22070 | K28: 23696 | L28: 23491 | M28: 23355 | N28: 21985 | O28: 18635 | P28: 22978 | Q28: 31726 | R28: 36841 | S28: 37750 | T28: 12934 | U28: 14070 | V28: 13019 | W28: 12050 | X28: 11016 | Y28: 9724 | Z28: 7745 | AA28: 562162 | AB28: 4 | AC28: =+AA28*AB28 -> 2248648
B29: Domingo | C29: 29560 | D29: 26961 | E29: 24720 | F29: 22727 | G29: 21641 | H29: 19230 | I29: 18875 | J29: 14302 | K29: 11168 | L29: 9753 | M29: 7425 | N29: 6667 | O29: 7437 | P29: 11925 | Q29: 18766 | R29: 24046 | S29: 27018 | T29: 5713 | U29: 8089 | V29: 9955 | W29: 10716 | X29: 12134 | Y29: 11415 | Z29: 9479 | AA29: 432004 | AB29: 4 | AC29: =+AA29*AB29 -> 1728016
B30: Festivo | C30: 22959 | D30: 20371 | E30: 18424 | F30: 16785 | G30: 16041 | H30: 14313 | I30: 14679 | J30: 11793 | K30: 11295 | L30: 10920 | M30: 10244 | N30: 9377 | O30: 8513 | P30: 12798 | Q30: 19130 | R30: 23297 | S30: 24775 | T30: 2240 | U30: 4188 | V30: 7301 | W30: 7382 | X30: 7508 | Y30: 5741 | Z30: 2876 | AA30: 374251 | AB30: 3 | AC30: =+AA30*AB30 -> 1122753
A31: 46204 | B31: Hábil | C31: 28040 | D31: 25019 | E31: 22819 | F31: 21002 | G31: 20412 | H31: 20782 | I31: 21469 | J31: 20654 | K31: 22342 | L31: 22057 | M31: 22560 | N31: 20911 | O31: 15301 | P31: 25324 | Q31: 36832 | R31: 41523 | S31: 42090 | T31: 13706 | U31: 12877 | V31: 13167 | W31: 13758 | X31: 13354 | Y31: 11015 | Z31: 7884 | AA31: 562796 | AB31: 22 | AC31: =+AA31*AB31 -> 12381512 | AD31: =+SUM(AC31:AC34) -> 16335944
B32: Sábado | C32: 25967 | D32: 23374 | E32: 21323 | F32: 19697 | G32: 19233 | H32: 18113 | I32: 18852 | J32: 17597 | K32: 18728 | L32: 18570 | M32: 18118 | N32: 17482 | O32: 14778 | P32: 19819 | Q32: 27879 | R32: 31971 | S32: 32459 | T32: 7657 | U32: 9758 | V32: 11109 | W32: 10029 | X32: 9875 | Y32: 9479 | Z32: 8141 | AA32: 485743 | AB32: 4 | AC32: =+AA32*AB32 -> 1942972
B33: Domingo | C33: 29638 | D33: 26914 | E33: 24398 | F33: 22532 | G33: 21237 | H33: 19202 | I33: 18729 | J33: 12340 | K33: 9613 | L33: 8146 | M33: 6210 | N33: 5022 | O33: 5817 | P33: 10588 | Q33: 16751 | R33: 22100 | S33: 24839 | T33: 7246 | U33: 9473 | V33: 11318 | W33: 11732 | X33: 12415 | Y33: 11356 | Z33: 9275 | AA33: 414825 | AB33: 4 | AC33: =+AA33*AB33 -> 1659300
B34: Festivo | C34: 24697 | D34: 21848 | E34: 19529 | F34: 18132 | G34: 17280 | H34: 15884 | I34: 15510 | J34: 11197 | K34: 9466 | L34: 8099 | M34: 6954 | N34: 5741 | O34: 4842 | P34: 9967 | Q34: 16313 | R34: 21048 | S34: 22896 | T34: 1949 | U34: 4719 | V34: 6943 | W34: 7030 | X34: 6398 | Y34: 4241 | Z34: 1818 | AA34: 352160 | AB34: 1 | AC34: =+AA34*AB34 -> 352160
A35: 46235 | B35: Hábil | C35: 29623 | D35: 26363 | E35: 23978 | F35: 22087 | G35: 21394 | H35: 21423 | I35: 21851 | J35: 21455 | K35: 22655 | L35: 22959 | M35: 23358 | N35: 22277 | O35: 16599 | P35: 27701 | Q35: 40241 | R35: 45046 | S35: 45897 | T35: 15588 | U35: 14785 | V35: 15518 | W35: 16312 | X35: 16637 | Y35: 14135 | Z35: 11241 | AA35: 604568 | AB35: 19 | AC35: =+AA35*AB35 -> 11486792 | AD35: =+SUM(AC35:AC38) -> 17146466
B36: Sábado | C36: 34602 | D36: 31087 | E36: 28290 | F36: 26053 | G36: 24934 | H36: 23159 | I36: 23586 | J36: 23057 | K36: 23978 | L36: 24541 | M36: 23743 | N36: 23594 | O36: 19750 | P36: 24890 | Q36: 32604 | R36: 36656 | S36: 38011 | T36: 13100 | U36: 15058 | V36: 15151 | W36: 14189 | X36: 15006 | Y36: 14522 | Z36: 13069 | AA36: 604801 | AB36: 5 | AC36: =+AA36*AB36 -> 3024005
B37: Domingo | C37: 31435 | D37: 28351 | E37: 25837 | F37: 23765 | G37: 22098 | H37: 19280 | I37: 18137 | J37: 12985 | K37: 9699 | L37: 6600 | M37: 5291 | N37: 3249 | O37: 4348 | P37: 10681 | Q37: 16774 | R37: 22095 | S37: 23223 | T37: 3399 | U37: 6469 | V37: 7505 | W37: 8002 | X37: 9292 | Y37: 8114 | Z37: 6036 | AA37: 397007 | AB37: 5 | AC37: =+AA37*AB37 -> 1985035
B38: Festivo | C38: 19642 | D38: 17516 | E38: 15599 | F38: 14430 | G38: 13776 | H38: 12730 | I38: 11922 | J38: 7545 | K38: 5805 | L38: 5452 | M38: 4802 | N38: 4615 | O38: 4648 | P38: 9637 | Q38: 16130 | R38: 21128 | S38: 22898 | T38: 5 | U38: 3663 | V38: 6927 | W38: 7768 | X38: 9817 | Y38: 8328 | Z38: 3921 | AA38: 325317 | AB38: 2 | AC38: =+AA38*AB38 -> 650634
A39: 46266 | B39: Hábil | C39: 44214 | D39: 40633 | E39: 37941 | F39: 35826 | G39: 35002 | H39: 35112 | I39: 35828 | J39: 35722 | K39: 37056 | L39: 37470 | M39: 38196 | N39: 37109 | O39: 31802 | P39: 43449 | Q39: 55201 | R39: 59801 | S39: 59928 | T39: 29787 | U39: 29907 | V39: 29379 | W39: 30049 | X39: 30144 | Y39: 27761 | Z39: 23989 | AA39: 900874 | AB39: 22 | AC39: =+AA39*AB39 -> 19819228 | AD39: =+SUM(AC39:AC42) -> 26119312
B40: Sábado | C40: 44379 | D40: 41166 | E40: 38636 | F40: 36712 | G40: 35715 | H40: 33976 | I40: 35239 | J40: 35350 | K40: 37440 | L40: 37304 | M40: 37575 | N40: 37023 | O40: 33385 | P40: 39014 | Q40: 47217 | R40: 51532 | S40: 52231 | T40: 28209 | U40: 30145 | V40: 28678 | W40: 27332 | X40: 26955 | Y40: 25658 | Z40: 23942 | AA40: 866453 | AB40: 4 | AC40: =+AA40*AB40 -> 3465812
B41: Domingo | C41: 43899 | D41: 40971 | E41: 38751 | F41: 36908 | G41: 35424 | H41: 33575 | I41: 33042 | J41: 27680 | K41: 24456 | L41: 21383 | M41: 20535 | N41: 20102 | O41: 19667 | P41: 25117 | Q41: 32964 | R41: 37863 | S41: 40063 | T41: 19684 | U41: 22427 | V41: 23761 | W41: 24386 | X41: 24933 | Y41: 23283 | Z41: 20723 | AA41: 708568 | AB41: 4 | AC41: =+AA41*AB41 -> 2834272
B42: Festivo | C42: 0 | D42: 0 | E42: 0 | F42: 0 | G42: 0 | H42: 0 | I42: 0 | J42: 0 | K42: 0 | L42: 0 | M42: 0 | N42: 0 | O42: 0 | P42: 0 | Q42: 0 | R42: 0 | S42: 0 | T42: 0 | U42: 0 | V42: 0 | W42: 0 | X42: 0 | Y42: 0 | Z42: 0 | AA42: 0 | AB42: 0 | AC42: =+AA42*AB42 -> 0
...

Sheet OF P2
C1: * La energia a ofertar debe ser expresada únicamente en kilovatio (kWh) redondeado a cero decimales
C4: OFERTA PRODUCTO 2
C5: MES | D5: ENERGIA SOLICITADA (KWh) | E5: % | F5: ENERGIA OFERTADA (kWh) | G5: PRECIO $/kWh
C6: 46388 | D6: =+VLOOKUP(C6,'CURVA P2'!$A$4:$AD$55,30,FALSE) -> 59963979 | E6: % | G6: $/kWh
C7: 46419 | D7: =+VLOOKUP(C7,'CURVA P2'!$A$4:$AD$55,30,FALSE) -> 61532312
C8: 46447 | D8: =+VLOOKUP(C8,'CURVA P2'!$A$4:$AD$55,30,FALSE) -> 59946328
C9: 46478 | D9: =+VLOOKUP(C9,'CURVA P2'!$A$4:$AD$55,30,FALSE) -> 62364066
C10: 46508 | D10: =+VLOOKUP(C10,'CURVA P2'!$A$4:$AD$55,30,FALSE) -> 42259367
C11: 46539 | D11: =+VLOOKUP(C11,'CURVA P2'!$A$4:$AD$55,30,FALSE) -> 47145425
C12: 46569 | D12: =+VLOOKUP(C12,'CURVA P2'!$A$4:$AD$55,30,FALSE) -> 41796550
C13: 46600 | D13: =+VLOOKUP(C13,'CURVA P2'!$A$4:$AD$55,30,FALSE) -> 40054834
C14: 46631 | D14: =+VLOOKUP(C14,'CURVA P2'!$A$4:$AD$55,30,FALSE) -> 44476632
C15: 46661 | D15: =+VLOOKUP(C15,'CURVA P2'!$A$4:$AD$55,30,FALSE) -> 40797963
C16: 46692 | D16: =+VLOOKUP(C16,'CURVA P2'!$A$4:$AD$55,30,FALSE) -> 41250458
C17: 46722 | D17: =+VLOOKUP(C17,'CURVA P2'!$A$4:$AD$55,30,FALSE) -> 58412086
D18: =SUM(D6:D17) -> 600000000
D20: =D18/1000000 -> 600

Sheet CURVA P2
A1: Curva de distribucion en kWh
A2: * La energia a ofertar debe ser expresada únicamente en kilovatio (kWh) redondeado a cero decimales
A4: TOTAL | C4: =+AD55 -> 600000000
A5: MES | B5: DÍA | C5: HORA 01 | D5: HORA 02 | E5: HORA 03 | F5: HORA 04 | G5: HORA 05 | H5: HORA 06 | I5: HORA 07 | J5: HORA 08 | K5: HORA 09 | L5: HORA 10 | M5: HORA 11 | N5: HORA 12 | O5: HORA 13 | P5: HORA 14 | Q5: HORA 15 | R5: HORA 16 | S5: HORA 17 | T5: HORA 18 | U5: HORA 19 | V5: HORA 20 | W5: HORA 21 | X5: HORA 22 | Y5: HORA 23 | Z5: HORA 24 | AA5: TOTAL DÍA | AB5: NUMERO DÍAS | AC5: TOTAL DÍA MES | AD5: TOTAL MES
A7: 46388 | B7: Hábil | C7: 85475 | D7: 82464 | E7: 79295 | F7: 76963 | G7: 76233 | H7: 77616 | I7: 78575 | J7: 72426 | K7: 75399 | L7: 76442 | M7: 77860 | N7: 78462 | O7: 73684 | P7: 84405 | Q7: 98326 | R7: 104491 | S7: 105523 | T7: 91398 | U7: 93879 | V7: 91988 | W7: 90009 | X7: 87762 | Y7: 83491 | Z7: 77755 | AA7: =SUM(C7:Z7) -> 2019921 | AB7: 19 | AC7: =+AA7*AB7 -> 38378499 | AD7: =+SUM(AC7:AC10) -> 59963979
B8: Sábado | C8: 87557 | D8: 83976 | E8: 80369 | F8: 77752 | G8: 76635 | H8: 77073 | I8: 77239 | J8: 70681 | K8: 74205 | L8: 75424 | M8: 76295 | N8: 76098 | O8: 73115 | P8: 78888 | Q8: 87888 | R8: 93001 | S8: 93900 | T8: 84915 | U8: 90415 | V8: 89198 | W8: 86629 | X8: 84171 | Y8: 81080 | Z8: 76787 | AA8: =SUM(C8:Z8) -> 1953291 | AB8: 5 | AC8: =+AA8*AB8 -> 9766455
B9: Domingo | C9: 86354 | D9: 83106 | E9: 79690 | F9: 77013 | G9: 75468 | H9: 74690 | I9: 73367 | J9: 61597 | K9: 59814 | L9: 58732 | M9: 57474 | N9: 57184 | O9: 58374 | P9: 63527 | Q9: 70740 | R9: 76473 | S9: 79162 | T9: 73792 | U9: 80498 | V9: 82146 | W9: 81890 | X9: 80936 | Y9: 77698 | Z9: 72616 | AA9: =SUM(C9:Z9) -> 1742341 | AB9: 5 | AC9: =+AA9*AB9 -> 8711705
B10: Festivo | C10: 74349 | D10: 72212 | E10: 70753 | F10: 69045 | G10: 68220 | H10: 67471 | I10: 65300 | J10: 53049 | K10: 50893 | L10: 49748 | M10: 49454 | N10: 49131 | O10: 50105 | P10: 55720 | Q10: 62801 | R10: 68239 | S10: 70332 | T10: 67824 | U10: 75022 | V10: 76102 | W10: 75471 | X10: 74076 | Y10: 71137 | Z10: 67206 | AA10: =SUM(C10:Z10) -> 1553660 | AB10: 2 | AC10: =+AA10*AB10 -> 3107320
A11: 46419 | B11: Hábil | C11: 94094 | D11: 89437 | E11: 86116 | F11: 83963 | G11: 84020 | H11: 88475 | I11: 91088 | J11: 86080 | K11: 89226 | L11: 90248 | M11: 92009 | N11: 90489 | O11: 82218 | P11: 96330 | Q11: 112003 | R11: 118440 | S11: 118934 | T11: 100410 | U11: 101555 | V11: 100881 | W11: 99388 | X11: 96097 | Y11: 89394 | Z11: 82105 | AA11: =SUM(C11:Z11) -> 2263000 | AB11: 20 | AC11: =+AA11*AB11 -> 45260000 | AD11: =+SUM(AC11:AC14) -> 61532312
B12: Sábado | C12: 91298 | D12: 86843 | E12: 83613 | F12: 81518 | G12: 80670 | H12: 82050 | I12: 84273 | J12: 80213 | K12: 84554 | L12: 86110 | M12: 86961 | N12: 86326 | O12: 82041 | P12: 87100 | Q12: 95839 | R12: 101027 | S12: 101548 | T12: 89405 | U12: 94811 | V12: 95227 | W12: 92586 | X12: 89735 | Y12: 86012 | Z12: 81185 | AA12: =SUM(C12:Z12) -> 2110945 | AB12: 4 | AC12: =+AA12*AB12 -> 8443780
B13: Domingo | C13: 93495 | D13: 88784 | E13: 85426 | F13: 82665 | G13: 81252 | H13: 80868 | I13: 80374 | J13: 69906 | K13: 68588 | L13: 68274 | M13: 67464 | N13: 67665 | O13: 68637 | P13: 73478 | Q13: 81278 | R13: 87744 | S13: 90702 | T13: 82684 | U13: 89503 | V13: 92867 | W13: 93238 | X13: 92504 | Y13: 88087 | Z13: 81650 | AA13: =SUM(C13:Z13) -> 1957133 | AB13: 4 | AC13: =+AA13*AB13 -> 7828532
B14: Festivo | C14: 0 | D14: 0 | E14: 0 | F14: 0 | G14: 0 | H14: 0 | I14: 0 | J14: 0 | K14: 0 | L14: 0 | M14: 0 | N14: 0 | O14: 0 | P14: 0 | Q14: 0 | R14: 0 | S14: 0 | T14: 0 | U14: 0 | V14: 0 | W14: 0 | X14: 0 | Y14: 0 | Z14: 0 | AA14: =SUM(C14:Z14) -> 0 | AB14: 0 | AC14: =+AA14*AB14 -> 0
A15: 46447 | B15: Hábil | C15: 86183 | D15: 81752 | E15: 78670 | F15: 76436 | G15: 76217 | H15: 79183 | I15: 79682 | J15: 73703 | K15: 75886 | L15: 76108 | M15: 77105 | N15: 76071 | O15: 69649 | P15: 82898 | Q15: 97713 | R15: 103799 | S15: 104865 | T15: 89301 | U15: 90763 | V15: 90596 | W15: 90042 | X15: 88105 | Y15: 82827 | Z15: 76528 | AA15: =SUM(C15:Z15) -> 2004082 | AB15: 20 | AC15: =+AA15*AB15 -> 40081640 | AD15: =+SUM(AC15:AC18) -> 59946328
B16: Sábado | C16: 88452 | D16: 83892 | E16: 80531 | F16: 77798 | G16: 76493 | H16: 76654 | I16: 77297 | J16: 72177 | K16: 75219 | L16: 75958 | M16: 76663 | N16: 75545 | O16: 71413 | P16: 77043 | Q16: 86220 | R16: 91537 | S16: 92699 | T16: 83221 | U16: 87965 | V16: 88110 | W16: 86555 | X16: 85076 | Y16: 82802 | Z16: 78831 | AA16: =SUM(C16:Z16) -> 1948151 | AB16: 4 | AC16: =+AA16*AB16 -> 7792604
B17: Domingo | C17: 89429 | D17: 84891 | E17: 81675 | F17: 79062 | G17: 77415 | H17: 76280 | I17: 74542 | J17: 62955 | K17: 60589 | L17: 58616 | M17: 56595 | N17: 56339 | O17: 57837 | P17: 63325 | Q17: 71241 | R17: 77442 | S17: 80428 | T17: 74326 | U17: 80421 | V17: 83984 | W17: 85011 | X17: 84937 | Y17: 80647 | Z17: 75100 | AA17: =SUM(C17:Z17) -> 1773087 | AB17: 4 | AC17: =+AA17*AB17 -> 7092348
B18: Festivo | C18: 76883 | D18: 72327 | E18: 69459 | F18: 67497 | G18: 66700 | H18: 66308 | I18: 66328 | J18: 57882 | K18: 57712 | L18: 57869 | M18: 58682 | N18: 59274 | O18: 58365 | P18: 64762 | Q18: 71718 | R18: 76072 | S18: 77697 | T18: 70875 | U18: 77938 | V18: 81408 | W18: 81677 | X18: 80040 | Y18: 74281 | Z18: 68158 | AA18: =SUM(C18:Z18) -> 1659912 | AB18: 3 | AC18: =+AA18*AB18 -> 4979736
A19: 46478 | B19: Hábil | C19: 89307 | D19: 84677 | E19: 81513 | F19: 79277 | G19: 79158 | H19: 80883 | I19: 82380 | J19: 78147 | K19: 82029 | L19: 83045 | M19: 85065 | N19: 84666 | O19: 77170 | P19: 90582 | Q19: 106463 | R19: 112212 | S19: 112377 | T19: 95543 | U19: 96991 | V19: 96176 | W19: 95245 | X19: 92898 | Y19: 87412 | Z19: 80523 | AA19: =SUM(C19:Z19) -> 2133739 | AB19: 22 | AC19: =+AA19*AB19 -> 46942258 | AD19: =+SUM(AC19:AC22) -> 62364066
B20: Sábado | C20: 90985 | D20: 86460 | E20: 83112 | F20: 80362 | G20: 79320 | H20: 78224 | I20: 79864 | J20: 74786 | K20: 79161 | L20: 80338 | M20: 81568 | N20: 81260 | O20: 77382 | P20: 82961 | Q20: 91901 | R20: 96827 | S20: 97077 | T20: 87217 | U20: 91720 | V20: 90449 | W20: 88216 | X20: 85770 | Y20: 82670 | Z20: 78635 | AA20: =SUM(C20:Z20) -> 2026265 | AB20: 4 | AC20: =+AA20*AB20 -> 8105060
B21: Domingo | C21: 91065 | D21: 86133 | E21: 82535 | F21: 79714 | G21: 78018 | H21: 75873 | I21: 75123 | J21: 64713 | K21: 63150 | L21: 61790 | M21: 60818 | N21: 61657 | O21: 62753 | P21: 68146 | Q21: 76129 | R21: 81965 | S21: 84402 | T21: 77434 | U21: 83697 | V21: 86236 | W21: 85568 | X21: 85215 | Y21: 81453 | Z21: 75600 | AA21: =SUM(C21:Z21) -> 1829187 | AB21: 4 | AC21: =+AA21*AB21 -> 7316748
B22: Festivo | C22: 0 | D22: 0 | E22: 0 | F22: 0 | G22: 0 | H22: 0 | I22: 0 | J22: 0 | K22: 0 | L22: 0 | M22: 0 | N22: 0 | O22: 0 | P22: 0 | Q22: 0 | R22: 0 | S22: 0 | T22: 0 | U22: 0 | V22: 0 | W22: 0 | X22: 0 | Y22: 0 | Z22: 0 | AA22: =SUM(C22:Z22) -> 0 | AB22: 0 | AC22: =+AA22*AB22 -> 0
A23: 46508 | B23: Hábil | C23: 63217 | D23: 58717 | E23: 55316 | F23: 52913 | G23: 52252 | H23: 52012 | I23: 53652 | J23: 49895 | K23: 54325 | L23: 55745 | M23: 57516 | N23: 56758 | O23: 49410 | P23: 63179 | Q23: 78883 | R23: 83976 | S23: 83798 | T23: 67159 | U23: 67070 | V23: 66805 | W23: 66932 | X23: 65317 | Y23: 60299 | Z23: 53762 | AA23: =SUM(C23:Z23) -> 1468908 | AB23: 19 | AC23: =+AA23*AB23 -> 27909252 | AD23: =+SUM(AC23:AC26) -> 42259367
B24: Sábado | C24: 65704 | D24: 60556 | E24: 56668 | F24: 53819 | G24: 52531 | H24: 50168 | I24: 52293 | J24: 47515 | K24: 52367 | L24: 54350 | M24: 55685 | N24: 54664 | O24: 50472 | P24: 56177 | Q24: 64772 | R24: 68922 | S24: 68933 | T24: 57269 | U24: 61140 | V24: 61628 | W24: 59728 | X24: 58099 | Y24: 55583 | Z24: 51299 | AA24: =SUM(C24:Z24) -> 1370342 | AB24: 4 | AC24: =+AA24*AB24 -> 5481368
B25: Domingo | C25: 62922 | D25: 58642 | E25: 55259 | F25: 52484 | G25: 50664 | H25: 47072 | I25: 47359 | J25: 36939 | K25: 35127 | L25: 33780 | M25: 33158 | N25: 32774 | O25: 32428 | P25: 37111 | Q25: 45482 | R25: 50987 | S25: 53578 | T25: 47354 | U25: 53100 | V25: 55827 | W25: 56663 | X25: 57333 | Y25: 54578 | Z25: 49484 | AA25: =SUM(C25:Z25) -> 1140105 | AB25: 5 | AC25: =+AA25*AB25 -> 5700525
B26: Festivo | C26: 53357 | D26: 49121 | E26: 46056 | F26: 43752 | G26: 42657 | H26: 40076 | I26: 41089 | J26: 31986 | K26: 31548 | L26: 31500 | M26: 31913 | N26: 32259 | O26: 31850 | P26: 37862 | Q26: 45765 | R26: 51051 | S26: 52500 | T26: 44783 | U26: 51254 | V26: 55656 | W26: 56659 | X26: 56190 | Y26: 51671 | Z26: 45519 | AA26: =SUM(C26:Z26) -> 1056074 | AB26: 3 | AC26: =+AA26*AB26 -> 3168222
A27: 46539 | B27: Hábil | C27: 70543 | D27: 65819 | E27: 62215 | F27: 59792 | G27: 59104 | H27: 58503 | I27: 61361 | J27: 58465 | K27: 63121 | L27: 64242 | M27: 65917 | N27: 65697 | O27: 57538 | P27: 70651 | Q27: 85674 | R27: 91156 | S27: 91467 | T27: 73143 | U27: 72971 | V27: 73306 | W27: 72722 | X27: 70823 | Y27: 66064 | Z27: 59626 | AA27: =SUM(C27:Z27) -> 1639920 | AB27: 21 | AC27: =+AA27*AB27 -> 34438320 | AD27: =+SUM(AC27:AC30) -> 47145425
B28: Sábado | C28: 71150 | D28: 66548 | E28: 63020 | F28: 60343 | G28: 59424 | H28: 57230 | I28: 59963 | J28: 56028 | K28: 60404 | L28: 61660 | M28: 62552 | N28: 61504 | O28: 56610 | P28: 61386 | Q28: 71379 | R28: 76897 | S28: 77228 | T28: 65422 | U28: 68804 | V28: 68925 | W28: 66934 | X28: 64820 | Y28: 62038 | Z28: 58030 | AA28: =SUM(C28:Z28) -> 1538299 | AB28: 4 | AC28: =+AA28*AB28 -> 6153196
B29: Domingo | C29: 70717 | D29: 66473 | E29: 63140 | F29: 60340 | G29: 58731 | H29: 55210 | I29: 55325 | J29: 45170 | K29: 42526 | L29: 41947 | M29: 39785 | N29: 39313 | O29: 40050 | P29: 45001 | Q29: 52816 | R29: 58586 | S29: 61724 | T29: 53453 | U29: 59115 | V29: 63448 | W29: 64165 | X29: 64868 | Y29: 62571 | Z29: 58177 | AA29: =SUM(C29:Z29) -> 1322651 | AB29: 4 | AC29: =+AA29*AB29 -> 5290604
B30: Festivo | C30: 62099 | D30: 57944 | E30: 54980 | F30: 52555 | G30: 51571 | H30: 49001 | I30: 50006 | J30: 42311 | K30: 43125 | L30: 43936 | M30: 44390 | N30: 44138 | O30: 42815 | P30: 48036 | Q30: 55424 | R30: 59819 | S30: 60802 | T30: 51261 | U30: 56493 | V30: 61944 | W30: 61782 | X30: 60859 | Y30: 56862 | Z30: 51152 | AA30: =SUM(C30:Z30) -> 1263305 | AB30: 1 | AC30: =+AA30*AB30 -> 1263305
A31: 46569 | B31: Hábil | C31: 61438 | D31: 56819 | E31: 53492 | F31: 50865 | G31: 50051 | H31: 50259 | I31: 52230 | J31: 46407 | K31: 50780 | L31: 51901 | M31: 53535 | N31: 52172 | O31: 43928 | P31: 56743 | Q31: 71558 | R31: 77001 | S31: 76870 | T31: 68831 | U31: 68212 | V31: 69744 | W31: 69852 | X31: 68376 | Y31: 63811 | Z31: 57616 | AA31: =SUM(C31:Z31) -> 1422491 | AB31: 20 | AC31: =+AA31*AB31 -> 28449820 | AD31: =+SUM(AC31:AC34) -> 41796550
B32: Sábado | C32: 59819 | D32: 55542 | E32: 52427 | F32: 49930 | G32: 49075 | H32: 47369 | I32: 49102 | J32: 42467 | K32: 46222 | L32: 47462 | M32: 47812 | N32: 47562 | O32: 43293 | P32: 48954 | Q32: 58451 | R32: 62897 | S32: 62841 | T32: 59418 | U32: 63487 | V32: 66085 | W32: 64047 | X32: 62726 | Y32: 60939 | Z32: 57671 | AA32: =SUM(C32:Z32) -> 1305598 | AB32: 5 | AC32: =+AA32*AB32 -> 6527990
B33: Domingo | C33: 63367 | D33: 58915 | E33: 55318 | F33: 52648 | G33: 50839 | H33: 47839 | I33: 47598 | J33: 33821 | K33: 31750 | L33: 30646 | M33: 28995 | N33: 28025 | O33: 29049 | P33: 34326 | Q33: 41511 | R33: 47714 | S33: 50340 | T33: 53698 | U33: 58540 | V33: 63038 | W33: 63835 | X33: 64213 | Y33: 61521 | Z33: 57011 | AA33: =SUM(C33:Z33) -> 1154557 | AB33: 4 | AC33: =+AA33*AB33 -> 4618228
B34: Festivo | C34: 57089 | D34: 52696 | E34: 49295 | F34: 47131 | G34: 45973 | H34: 43894 | I34: 44100 | J34: 33192 | K34: 32741 | L34: 32332 | M34: 31799 | N34: 30900 | O34: 29289 | P34: 35465 | Q34: 43086 | R34: 48489 | S34: 50010 | T34: 49755 | U34: 55360 | V34: 60823 | W34: 60906 | X34: 59777 | Y34: 55802 | Z34: 50352 | AA34: =SUM(C34:Z34) -> 1100256 | AB34: 2 | AC34: =+AA34*AB34 -> 2200512
A35: 46600 | B35: Hábil | C35: 59270 | D35: 54463 | E35: 50879 | F35: 48120 | G35: 47167 | H35: 47194 | I35: 48542 | J35: 43396 | K35: 47289 | L35: 49150 | M35: 50864 | N35: 50195 | O35: 42035 | P35: 56196 | Q35: 72232 | R35: 77697 | S35: 77763 | T35: 66291 | U35: 66138 | V35: 67151 | W35: 67564 | X35: 66737 | Y35: 61873 | Z35: 55776 | AA35: =SUM(C35:Z35) -> 1373982 | AB35: 21 | AC35: =+AA35*AB35 -> 28853622 | AD35: =+SUM(AC35:AC38) -> 40054834
B36: Sábado | C36: 65140 | D36: 59951 | E36: 55919 | F36: 52751 | G36: 51121 | H36: 48914 | I36: 50037 | J36: 44395 | K36: 47997 | L36: 49977 | M36: 50086 | N36: 50555 | O36: 45143 | P36: 51199 | Q36: 60391 | R36: 64921 | S36: 65533 | T36: 59789 | U36: 64285 | V36: 64793 | W36: 62743 | X36: 62548 | Y36: 60837 | Z36: 57281 | AA36: =SUM(C36:Z36) -> 1346306 | AB36: 3 | AC36: =+AA36*AB36 -> 4038918
B37: Domingo | C37: 61981 | D37: 57209 | E37: 53379 | F37: 50358 | G37: 48055 | H37: 44073 | I37: 42900 | J37: 30889 | K37: 28263 | L37: 25797 | M37: 24871 | N37: 23052 | O37: 24365 | P37: 31543 | Q37: 38729 | R37: 44769 | S37: 45606 | T37: 45042 | U37: 51385 | V37: 54472 | W37: 55432 | X37: 56436 | Y37: 53855 | Z37: 49225 | AA37: =SUM(C37:Z37) -> 1041686 | AB37: 5 | AC37: =+AA37*AB37 -> 5208430
B38: Festivo | C38: 48457 | D38: 44780 | E38: 41713 | F38: 39712 | G38: 38696 | H38: 36870 | I38: 36475 | J38: 25827 | K38: 25565 | L38: 26542 | M38: 26872 | N38: 27394 | O38: 26888 | P38: 32786 | Q38: 40636 | R38: 46466 | S38: 47692 | T38: 44044 | U38: 50845 | V38: 55292 | W38: 55712 | X38: 57042 | Y38: 53615 | Z38: 47011 | AA38: =SUM(C38:Z38) -> 976932 | AB38: 2 | AC38: =+AA38*AB38 -> 1953864
A39: 46631 | B39: Hábil | C39: 66044 | D39: 60758 | E39: 56830 | F39: 53782 | G39: 52654 | H39: 52564 | I39: 54366 | J39: 49925 | K39: 54223 | L39: 56339 | M39: 58468 | N39: 57880 | O39: 50100 | P39: 64997 | Q39: 80349 | R39: 85498 | S39: 84587 | T39: 73233 | U39: 74253 | V39: 72825 | W39: 72960 | X39: 72080 | Y39: 67342 | Z39: 60273 | AA39: =SUM(C39:Z39) -> 1532330 | AB39: 22 | AC39: =+AA39*AB39 -> 33711260 | AD39: =+SUM(AC39:AC42) -> 44476632
B40: Sábado | C40: 67427 | D40: 62594 | E40: 58780 | F40: 55684 | G40: 54151 | H40: 51785 | I40: 53725 | J40: 49068 | K40: 53981 | L40: 55440 | M40: 57016 | N40: 56858 | O40: 51848 | P40: 58341 | Q40: 68018 | R40: 72532 | S40: 72209 | T40: 67411 | U40: 72387 | V40: 70467 | W40: 67815 | X40: 66267 | Y40: 63909 | Z40: 60293 | AA40: =SUM(C40:Z40) -> 1468006 | AB40: 4 | AC40: =+AA40*AB40 -> 5872024
B41: Domingo | C41: 66425 | D41: 61855 | E41: 58368 | F41: 55543 | G41: 53471 | H41: 50590 | I41: 50249 | J41: 38056 | K41: 35389 | L41: 32990 | M41: 32560 | N41: 32833 | O41: 32541 | P41: 38987 | Q41: 48073 | R41: 53465 | S41: 55432 | T41: 54287 | U41: 61007 | V41: 63279 | W41: 64467 | X41: 65154 | Y41: 61904 | Z41: 56412 | AA41: =SUM(C41:Z41) -> 1223337 | AB41: 4 | AC41: =+AA41*AB41 -> 4893348
B42: Festivo | C42: 0 | D42: 0 | E42: 0 | F42: 0 | G42: 0 | H42: 0 | I42: 0 | J42: 0 | K42: 0 | L42: 0 | M42: 0 | N42: 0 | O42: 0 | P42: 0 | Q42: 0 | R42: 0 | S42: 0 | T42: 0 | U42: 0 | V42: 0 | W42: 0 | X42: 0 | Y42: 0 | Z42: 0 | AA42: =SUM(C42:Z42) -> 0 | AB42: 0 | AC42: =+AA42*AB42 -> 0
...

Sheet OF P3
C1: * La energia a ofertar debe ser expresada únicamente en kilovatio (kWh) redondeado a cero decimales
C4: OFERTA PRODUCTO 3
C5: MES | D5: ENERGIA SOLICITADA (KWh) | E5: % | F5: ENERGIA OFERTADA (kWh) | G5: PRECIO $/kWh
C6: 47119 | D6: =+VLOOKUP(C6,'CURVA P3'!$A$4:$AD$55,30,FALSE) -> 35518721 | E6: % | G6: $/kWh
C7: 47150 | D7: =+VLOOKUP(C7,'CURVA P3'!$A$4:$AD$55,30,FALSE) -> 36348972
C8: 47178 | D8: =+VLOOKUP(C8,'CURVA P3'!$A$4:$AD$55,30,FALSE) -> 35276623
C9: 47209 | D9: =+VLOOKUP(C9,'CURVA P3'!$A$4:$AD$55,30,FALSE) -> 36873376
C10: 47239 | D10: =+VLOOKUP(C10,'CURVA P3'!$A$4:$AD$55,30,FALSE) -> 37561812
C11: 47270 | D11: =+VLOOKUP(C11,'CURVA P3'!$A$4:$AD$55,30,FALSE) -> 37699759
C12: 47300 | D12: =+VLOOKUP(C12,'CURVA P3'!$A$4:$AD$55,30,FALSE) -> 36474141
C13: 47331 | D13: =+VLOOKUP(C13,'CURVA P3'!$A$4:$AD$55,30,FALSE) -> 38473209
C14: 47362 | D14: =+VLOOKUP(C14,'CURVA P3'!$A$4:$AD$55,30,FALSE) -> 39738570
C15: 47392 | D15: =+VLOOKUP(C15,'CURVA P3'!$A$4:$AD$55,30,FALSE) -> 39458444
C16: 47423 | D16: =+VLOOKUP(C16,'CURVA P3'!$A$4:$AD$55,30,FALSE) -> 38831644
C17: 47453 | D17: =+VLOOKUP(C17,'CURVA P3'!$A$4:$AD$55,30,FALSE) -> 37744620
D18: =SUM(D6:D17) -> 449999891
D20: =D18/1000000 -> 449.99989

Sheet CURVA P3
A1: Curva de distribucion en kWh
A2: * La energia a ofertar debe ser expresada únicamente en kilovatio (kWh) redondeado a cero decimales
A4: TOTAL | C4: =+AD55 -> 449999891
A5: MES | B5: DÍA | C5: HORA 01 | D5: HORA 02 | E5: HORA 03 | F5: HORA 04 | G5: HORA 05 | H5: HORA 06 | I5: HORA 07 | J5: HORA 08 | K5: HORA 09 | L5: HORA 10 | M5: HORA 11 | N5: HORA 12 | O5: HORA 13 | P5: HORA 14 | Q5: HORA 15 | R5: HORA 16 | S5: HORA 17 | T5: HORA 18 | U5: HORA 19 | V5: HORA 20 | W5: HORA 21 | X5: HORA 22 | Y5: HORA 23 | Z5: HORA 24 | AA5: TOTAL DÍA | AB5: NUMERO DÍAS | AC5: TOTAL DÍA MES | AD5: TOTAL MES
A7: 47119 | B7: Hábil | C7: 50154 | D7: 47788 | E7: 45877 | F7: 44471 | G7: 44029 | H7: 44876 | I7: 45134 | J7: 37592 | K7: 34432 | L7: 33203 | M7: 33457 | N7: 32560 | O7: 30670 | P7: 38846 | Q7: 51262 | R7: 59962 | S7: 63396 | T7: 66763 | U7: 69031 | V7: 68225 | W7: 67179 | X7: 65502 | Y7: 62083 | Z7: 57545 | AA7: =SUM(C7:Z7) -> 1194037 | AB7: 21 | AC7: =+AA7*AB7 -> 25074777 | AD7: =+SUM(AC7:AC10) -> 35518721
B8: Sábado | C8: 51381 | D8: 48762 | E8: 46634 | F8: 45065 | G8: 44426 | H8: 44704 | I8: 44423 | J8: 36262 | K8: 33097 | L8: 31785 | M8: 31562 | N8: 30251 | O8: 29682 | P8: 34775 | Q8: 44022 | R8: 51991 | S8: 55454 | T8: 61627 | U8: 66350 | V8: 66044 | W8: 64343 | X8: 62632 | Y8: 60271 | Z8: 57031 | AA8: =SUM(C8:Z8) -> 1142574 | AB8: 4 | AC8: =+AA8*AB8 -> 4570296
B9: Domingo | C9: 50763 | D9: 48315 | E9: 46247 | F9: 44617 | G9: 43688 | H9: 43230 | I9: 42034 | J9: 30888 | K9: 24341 | L9: 21734 | M9: 20160 | N9: 18746 | O9: 20688 | P9: 25360 | Q9: 33649 | R9: 42158 | S9: 46772 | T9: 54889 | U9: 60551 | V9: 62142 | W9: 61944 | X9: 61125 | Y9: 58480 | Z9: 54724 | AA9: =SUM(C9:Z9) -> 1017245 | AB9: 4 | AC9: =+AA9*AB9 -> 4068980
B10: Festivo | C10: 43553 | D10: 42366 | E10: 41321 | F10: 40257 | G10: 39708 | H10: 39240 | I10: 37596 | J10: 25997 | K10: 18966 | L10: 16332 | M10: 15204 | N10: 13788 | O10: 15806 | P10: 20738 | Q10: 28832 | R10: 37086 | S10: 41329 | T10: 50896 | U10: 57023 | V10: 58145 | W10: 57506 | X10: 56176 | Y10: 53768 | Z10: 50701 | AA10: =SUM(C10:Z10) -> 902334 | AB10: 2 | AC10: =+AA10*AB10 -> 1804668
A11: 47150 | B11: Hábil | C11: 55198 | D11: 52302 | E11: 50261 | F11: 48890 | G11: 48838 | H11: 51213 | I11: 52324 | J11: 45162 | K11: 41585 | L11: 40084 | M11: 40381 | N11: 38251 | O11: 34461 | P11: 44806 | Q11: 58856 | R11: 68309 | S11: 71805 | T11: 73581 | U11: 74749 | V11: 74640 | W11: 73728 | X11: 71702 | Y11: 67316 | Z11: 61940 | AA11: =SUM(C11:Z11) -> 1340382 | AB11: 20 | AC11: =+AA11*AB11 -> 26807640 | AD11: =+SUM(AC11:AC14) -> 36348972
B12: Sábado | C12: 53808 | D12: 51030 | E12: 49055 | F12: 47696 | G12: 47241 | H12: 48010 | I12: 48819 | J12: 41784 | K12: 38959 | L12: 37613 | M12: 37346 | N12: 35570 | O12: 33874 | P12: 38804 | Q12: 48787 | R12: 57342 | S12: 60920 | T12: 66159 | U12: 70387 | V12: 70846 | W12: 69084 | X12: 67187 | Y12: 64713 | Z12: 61178 | AA12: =SUM(C12:Z12) -> 1246212 | AB12: 4 | AC12: =+AA12*AB12 -> 4984848
B13: Domingo | C13: 54924 | D13: 51970 | E13: 49913 | F13: 48264 | G13: 47345 | H13: 47065 | I13: 46287 | J13: 35528 | K13: 28569 | L13: 26074 | M13: 24690 | N13: 23387 | O13: 25425 | P13: 30133 | Q13: 39164 | R13: 48482 | S13: 53554 | T13: 60659 | U13: 65897 | V13: 68628 | W13: 69003 | X13: 68507 | Y13: 65161 | Z13: 60492 | AA13: =SUM(C13:Z13) -> 1139121 | AB13: 4 | AC13: =+AA13*AB13 -> 4556484
B14: Festivo | C14: 0 | D14: 0 | E14: 0 | F14: 0 | G14: 0 | H14: 0 | I14: 0 | J14: 0 | K14: 0 | L14: 0 | M14: 0 | N14: 0 | O14: 0 | P14: 0 | Q14: 0 | R14: 0 | S14: 0 | T14: 0 | U14: 0 | V14: 0 | W14: 0 | X14: 0 | Y14: 0 | Z14: 0 | AA14: =SUM(C14:Z14) -> 0 | AB14: 0 | AC14: =+AA14*AB14 -> 0
A15: 47178 | B15: Hábil | C15: 50134 | D15: 47415 | E15: 45532 | F15: 44172 | G15: 44022 | H15: 45588 | I15: 45812 | J15: 38487 | K15: 34923 | L15: 33134 | M15: 33074 | N15: 31299 | O15: 28418 | P15: 37877 | Q15: 50783 | R15: 59452 | S15: 63055 | T15: 66051 | U15: 67591 | V15: 67508 | W15: 66809 | X15: 65230 | Y15: 61653 | Z15: 56971 | AA15: =SUM(C15:Z15) -> 1184990 | AB15: 19 | AC15: =+AA15*AB15 -> 22514810 | AD15: =+SUM(AC15:AC18) -> 35276623
B16: Sábado | C16: 51471 | D16: 48621 | E16: 46600 | F16: 44983 | G16: 44268 | H16: 44409 | I16: 44583 | J16: 37474 | K16: 34225 | L16: 32538 | M16: 32221 | N16: 30220 | O16: 28760 | P16: 33678 | Q16: 43013 | R16: 51114 | S16: 54779 | T16: 60923 | U16: 64978 | V16: 65284 | W16: 63893 | X16: 62497 | Y16: 60562 | Z16: 57615 | AA16: =SUM(C16:Z16) -> 1138709 | AB16: 5 | AC16: =+AA16*AB16 -> 5693545
B17: Domingo | C17: 51682 | D17: 48943 | E17: 46991 | F17: 45408 | G17: 44461 | H17: 43851 | I17: 42533 | J17: 31576 | K17: 24842 | L17: 21822 | M17: 19878 | N17: 18678 | O17: 20697 | P17: 25447 | Q17: 34150 | R17: 42731 | S17: 47475 | T17: 55424 | U17: 60331 | V17: 62844 | W17: 63410 | X17: 63152 | Y17: 60241 | Z17: 56193 | AA17: =SUM(C17:Z17) -> 1032760 | AB17: 4 | AC17: =+AA17*AB17 -> 4131040
B18: Festivo | C18: 45538 | D18: 42783 | E18: 41011 | F18: 39805 | G18: 39204 | H18: 39069 | I18: 38726 | J18: 29558 | K18: 24107 | L18: 22248 | M18: 21793 | N18: 20608 | O18: 20986 | P18: 26338 | Q18: 34603 | R18: 42363 | S18: 46231 | T18: 53679 | U18: 59212 | V18: 61627 | W18: 61570 | X18: 60142 | Y18: 56103 | Z18: 51772 | AA18: =SUM(C18:Z18) -> 979076 | AB18: 3 | AC18: =+AA18*AB18 -> 2937228
A19: 47209 | B19: Hábil | C19: 52624 | D19: 49762 | E19: 47803 | F19: 46426 | G19: 46276 | H19: 46990 | I19: 47643 | J19: 41310 | K19: 38641 | L19: 37380 | M19: 37874 | N19: 36444 | O19: 32996 | P19: 42772 | Q19: 56423 | R19: 65058 | S19: 68191 | T19: 70116 | U19: 71314 | V19: 70975 | W19: 70435 | X19: 68715 | Y19: 64887 | Z19: 59842 | AA19: =SUM(C19:Z19) -> 1270897 | AB19: 21 | AC19: =+AA19*AB19 -> 26688837 | AD19: =+SUM(AC19:AC22) -> 36873376
B20: Sábado | C20: 53363 | D20: 50494 | E20: 48400 | F20: 46811 | G20: 46156 | H20: 45369 | I20: 46001 | J20: 38987 | K20: 36468 | L20: 35324 | M20: 35125 | N20: 33663 | O20: 32494 | P20: 37675 | Q20: 47270 | R20: 55268 | S20: 58449 | T20: 63774 | U20: 67494 | V20: 67043 | W20: 65569 | X20: 63959 | Y20: 61780 | Z20: 58780 | AA20: =SUM(C20:Z20) -> 1195716 | AB20: 4 | AC20: =+AA20*AB20 -> 4782864
B21: Domingo | C21: 53513 | D21: 50527 | E21: 48353 | F21: 46618 | G21: 45620 | H21: 44247 | I21: 43565 | J21: 33225 | K21: 26622 | L21: 23953 | M21: 22657 | N21: 21811 | O21: 23777 | P21: 28684 | Q21: 37576 | R21: 46183 | S21: 50625 | T21: 57675 | U21: 62536 | V21: 64532 | W21: 64524 | X21: 64309 | Y21: 61677 | Z21: 57526 | AA21: =SUM(C21:Z21) -> 1080335 | AB21: 5 | AC21: =+AA21*AB21 -> 5401675
B22: Festivo | C22: 0 | D22: 0 | E22: 0 | F22: 0 | G22: 0 | H22: 0 | I22: 0 | J22: 0 | K22: 0 | L22: 0 | M22: 0 | N22: 0 | O22: 0 | P22: 0 | Q22: 0 | R22: 0 | S22: 0 | T22: 0 | U22: 0 | V22: 0 | W22: 0 | X22: 0 | Y22: 0 | Z22: 0 | AA22: =SUM(C22:Z22) -> 0 | AB22: 0 | AC22: =+AA22*AB22 -> 0
A23: 47239 | B23: Hábil | C23: 52865 | D23: 50150 | E23: 48149 | F23: 46748 | G23: 46384 | H23: 46070 | I23: 46993 | J23: 40907 | K23: 38758 | L23: 37722 | M23: 38047 | N23: 36433 | O23: 33122 | P23: 42656 | Q23: 55955 | R23: 64043 | S23: 66924 | T23: 68622 | U23: 69538 | V23: 69608 | W23: 69395 | X23: 68003 | Y23: 64412 | Z23: 59662 | AA23: =SUM(C23:Z23) -> 1261166 | AB23: 21 | AC23: =+AA23*AB23 -> 26484486 | AD23: =+SUM(AC23:AC26) -> 37561812
B24: Sábado | C24: 54854 | D24: 51777 | E24: 49518 | F24: 47769 | G24: 47054 | H24: 45626 | I24: 46378 | J24: 39471 | K24: 37435 | L24: 36609 | M24: 36433 | N24: 34498 | O24: 32956 | P24: 37891 | Q24: 46951 | R24: 54829 | S24: 57831 | T24: 62330 | U24: 65844 | V24: 66351 | W24: 65145 | X24: 63910 | Y24: 61941 | Z24: 58998 | AA24: =SUM(C24:Z24) -> 1202399 | AB24: 4 | AC24: =+AA24*AB24 -> 4809596
B25: Domingo | C25: 53211 | D25: 50568 | E25: 48560 | F25: 46894 | G25: 45828 | H25: 43662 | I25: 43567 | J25: 33028 | K25: 26544 | L25: 23863 | M25: 22707 | N25: 21241 | O25: 22367 | P25: 26811 | Q25: 35735 | R25: 43948 | S25: 48390 | T25: 55492 | U25: 60216 | V25: 62468 | W25: 62929 | X25: 63028 | Y25: 60890 | Z25: 57184 | AA25: =SUM(C25:Z25) -> 1059131 | AB25: 4 | AC25: =+AA25*AB25 -> 4236524
B26: Festivo | C26: 47603 | D26: 45004 | E26: 43156 | F26: 41811 | G26: 41194 | H26: 39752 | I26: 40060 | J26: 30579 | K26: 24963 | L26: 23103 | M26: 22704 | N26: 21593 | O26: 22375 | P26: 27579 | Q26: 36420 | R26: 44509 | S26: 48299 | T26: 54653 | U26: 59583 | V26: 62332 | W26: 62648 | X26: 61935 | Y26: 58889 | Z26: 54859 | AA26: =SUM(C26:Z26) -> 1015603 | AB26: 2 | AC26: =+AA26*AB26 -> 2031206
A27: 47270 | B27: Hábil | C27: 54665 | D27: 51758 | E27: 49617 | F27: 48149 | G27: 47770 | H27: 47270 | I27: 48809 | J27: 43216 | K27: 41180 | L27: 39985 | M27: 40258 | N27: 38862 | O27: 35021 | P27: 44464 | Q27: 57779 | R27: 66230 | S27: 69449 | T27: 71240 | U27: 71578 | V27: 72133 | W27: 71505 | X27: 69832 | Y27: 66295 | Z27: 61541 | AA27: =SUM(C27:Z27) -> 1308606 | AB27: 19 | AC27: =+AA27*AB27 -> 24863514 | AD27: =+SUM(AC27:AC30) -> 37699759
B28: Sábado | C28: 55573 | D28: 52747 | E28: 50604 | F28: 49017 | G28: 48468 | H28: 47090 | I28: 48437 | J28: 41785 | K28: 39485 | L28: 38351 | M28: 38216 | N28: 36385 | O28: 34563 | P28: 38934 | Q28: 48723 | R28: 57047 | S28: 60306 | T28: 65493 | U28: 68347 | V28: 69169 | W28: 67701 | X28: 66179 | Y28: 64102 | Z28: 61163 | AA28: =SUM(C28:Z28) -> 1247885 | AB28: 5 | AC28: =+AA28*AB28 -> 6239425
B29: Domingo | C29: 55196 | D29: 52484 | E29: 50467 | F29: 48836 | G29: 47866 | H29: 45755 | I29: 45590 | J29: 35270 | K29: 28156 | L29: 25889 | M29: 23818 | N29: 22230 | O29: 23870 | P29: 28395 | Q29: 37085 | R29: 45563 | S29: 50541 | T29: 57628 | U29: 62134 | V29: 65493 | W29: 65768 | X29: 65623 | Y29: 63697 | Z29: 60318 | AA29: =SUM(C29:Z29) -> 1107672 | AB29: 4 | AC29: =+AA29*AB29 -> 4430688
B30: Festivo | C30: 50144 | D30: 47520 | E30: 45709 | F30: 44259 | G30: 43719 | H30: 42173 | I30: 42504 | J30: 33624 | K30: 28567 | L30: 27083 | M30: 26844 | N30: 25565 | O30: 26019 | P30: 30974 | Q30: 39516 | R30: 47232 | S30: 50843 | T30: 57268 | U30: 61570 | V30: 65297 | W30: 65065 | X30: 63977 | Y30: 60887 | Z30: 56707 | AA30: =SUM(C30:Z30) -> 1083066 | AB30: 2 | AC30: =+AA30*AB30 -> 2166132
A31: 47300 | B31: Hábil | C31: 52126 | D31: 49312 | E31: 47293 | F31: 45746 | G31: 45271 | H31: 45240 | I31: 46342 | J31: 40061 | K31: 37812 | L31: 36630 | M31: 36864 | N31: 34905 | O31: 30951 | P31: 40275 | Q31: 53343 | R31: 61689 | S31: 64564 | T31: 67016 | U31: 66952 | V31: 68412 | W31: 68159 | X31: 66901 | Y31: 63637 | Z31: 59148 | AA31: =SUM(C31:Z31) -> 1228649 | AB31: 20 | AC31: =+AA31*AB31 -> 24572980 | AD31: =+SUM(AC31:AC34) -> 36474141
B32: Sábado | C32: 51547 | D32: 48837 | E32: 46953 | F32: 45433 | G32: 44852 | H32: 43830 | I32: 44650 | J32: 37772 | K32: 35163 | L32: 34025 | M32: 33481 | N32: 32080 | O32: 30509 | P32: 35347 | Q32: 44904 | R32: 52526 | S32: 55564 | T32: 60944 | U32: 63896 | V32: 65750 | W32: 64327 | X32: 63039 | Y32: 61408 | Z32: 58819 | AA32: =SUM(C32:Z32) -> 1155656 | AB32: 4 | AC32: =+AA32*AB32 -> 4622624
B33: Domingo | C33: 52894 | D33: 50092 | E33: 48011 | F33: 46459 | G33: 45424 | H33: 43657 | I33: 43252 | J33: 32108 | K33: 25482 | L33: 22668 | M33: 20960 | N33: 19104 | O33: 21000 | P33: 25595 | Q33: 33857 | R33: 42600 | S33: 46998 | T33: 55148 | U33: 58829 | V33: 62370 | W33: 62929 | X33: 62882 | Y33: 60745 | Z33: 57377 | AA33: =SUM(C33:Z33) -> 1040441 | AB33: 5 | AC33: =+AA33*AB33 -> 5202205
B34: Festivo | C34: 49582 | D34: 46874 | E34: 44857 | F34: 43543 | G34: 42897 | H34: 41699 | I34: 41781 | J34: 32352 | K34: 27035 | L34: 24944 | M34: 23960 | N34: 22229 | O34: 22186 | P34: 27677 | Q34: 36522 | R34: 44820 | S34: 48658 | T34: 55364 | U34: 59036 | V34: 62982 | W34: 62919 | X34: 62020 | Y34: 59172 | Z34: 55057 | AA34: =SUM(C34:Z34) -> 1038166 | AB34: 2 | AC34: =+AA34*AB34 -> 2076332
A35: 47331 | B35: Hábil | C35: 54379 | D35: 51530 | E35: 49371 | F35: 47740 | G35: 47191 | H35: 47178 | I35: 47841 | J35: 41806 | K35: 39380 | L35: 38619 | M35: 38998 | N35: 37426 | O35: 33611 | P35: 43649 | Q35: 57300 | R35: 65574 | S35: 68507 | T35: 69374 | U35: 69782 | V35: 70382 | W35: 70327 | X35: 69269 | Y35: 65831 | Z35: 61320 | AA35: =SUM(C35:Z35) -> 1286385 | AB35: 21 | AC35: =+AA35*AB35 -> 27014085 | AD35: =+SUM(AC35:AC38) -> 38473209
B36: Sábado | C36: 57274 | D36: 54210 | E36: 51847 | F36: 50019 | G36: 49052 | H36: 47893 | I36: 48314 | J36: 41806 | K36: 39241 | L36: 38436 | M36: 37827 | N36: 36928 | O36: 34826 | P36: 40055 | Q36: 49492 | R36: 57285 | S36: 60527 | T36: 64237 | U36: 67706 | V36: 68191 | W36: 66706 | X36: 65965 | Y36: 64494 | Z36: 61718 | AA36: =SUM(C36:Z36) -> 1254049 | AB36: 4 | AC36: =+AA36*AB36 -> 5016196
B37: Domingo | C37: 56017 | D37: 53110 | E37: 50799 | F37: 49019 | G37: 47689 | H37: 45394 | I37: 44476 | J37: 34189 | K37: 27345 | L37: 24109 | M37: 22795 | N37: 20582 | O37: 22553 | P37: 28181 | Q37: 36481 | R37: 45092 | S37: 48676 | T37: 55064 | U37: 59764 | V37: 62375 | W37: 63056 | X37: 63311 | Y37: 61387 | Z37: 57870 | AA37: =SUM(C37:Z37) -> 1079334 | AB37: 4 | AC37: =+AA37*AB37 -> 4317336
B38: Festivo | C38: 49254 | D38: 46867 | E38: 44964 | F38: 43672 | G38: 43052 | H38: 41860 | I38: 41494 | J38: 32203 | K38: 26958 | L38: 25669 | M38: 25265 | N38: 24385 | O38: 25079 | P38: 30213 | Q38: 39007 | R38: 47579 | S38: 51168 | T38: 56141 | U38: 60875 | V38: 63372 | W38: 63240 | X38: 63249 | Y38: 60618 | Z38: 56612 | AA38: =SUM(C38:Z38) -> 1062796 | AB38: 2 | AC38: =+AA38*AB38 -> 2125592
A39: 47362 | B39: Hábil | C39: 57531 | D39: 54368 | E39: 52027 | F39: 50225 | G39: 49581 | H39: 49430 | I39: 50344 | J39: 44781 | K39: 42635 | L39: 42034 | M39: 42636 | N39: 41093 | O39: 37447 | P39: 48039 | Q39: 61677 | R39: 69963 | S39: 72375 | T39: 73489 | U39: 74557 | V39: 73402 | W39: 73142 | X39: 72169 | Y39: 68725 | Z39: 63732 | AA39: =SUM(C39:Z39) -> 1365402 | AB39: 20 | AC39: =+AA39*AB39 -> 27308040 | AD39: =+SUM(AC39:AC42) -> 39738570
B40: Sábado | C40: 58657 | D40: 55742 | E40: 53433 | F40: 51482 | G40: 50549 | H40: 49227 | I40: 49968 | J40: 44042 | K40: 42022 | L40: 41026 | M40: 41350 | N40: 39951 | O40: 38221 | P40: 43669 | Q40: 53461 | R40: 61195 | S40: 63901 | T40: 68321 | U40: 72364 | V40: 71294 | W40: 69410 | X40: 68021 | Y40: 66388 | Z40: 63675 | AA40: =SUM(C40:Z40) -> 1317369 | AB40: 5 | AC40: =+AA40*AB40 -> 6586845
B41: Domingo | C41: 58059 | D41: 55231 | E41: 53057 | F41: 51320 | G41: 50137 | H41: 48348 | I41: 47864 | J41: 37416 | K41: 30390 | L41: 27135 | M41: 26021 | N41: 24989 | O41: 26265 | P41: 31796 | Q41: 41189 | R41: 49508 | S41: 53730 | T41: 60114 | U41: 65465 | V41: 66990 | W41: 67864 | X41: 68232 | Y41: 65879 | Z41: 61738 | AA41: =SUM(C41:Z41) -> 1168737 | AB41: 5 | AC41: =+AA41*AB41 -> 5843685
B42: Festivo | C42: 0 | D42: 0 | E42: 0 | F42: 0 | G42: 0 | H42: 0 | I42: 0 | J42: 0 | K42: 0 | L42: 0 | M42: 0 | N42: 0 | O42: 0 | P42: 0 | Q42: 0 | R42: 0 | S42: 0 | T42: 0 | U42: 0 | V42: 0 | W42: 0 | X42: 0 | Y42: 0 | Z42: 0 | AA42: =SUM(C42:Z42) -> 0 | AB42: 0 | AC42: =+AA42*AB42 -> 0
...

Sheet Producto 4
A1: * La energia a ofertar debe ser expresada únicamente en kilovatio (kWh) redondeado a cero decimales
A3: OFERTA PRODUCTO 4
A4: AÑO | B4: DIAS DE SUMINISTRO | C4: ENERGIA DIARIA SOLICITADA (kWh-DIA) | D4: % | E4: ENERGIA OFERTADA (kWh) | F4: PRECIO $/kWh
A5: 2026 | B5: 365 | C5: =C27 -> 49999890 | D5: % | F5: $/kWh | I5: =C5/1000000 -> 49.99989
A6: 2027 | B6: 365 | C6: =C39 -> 49999890 | F6: $/kWh | I6: =C6/1000000 -> 49.99989
A7: 2028 | B7: 366 | C7: =C51 -> 49999626 | F7: $/kWh | I7: =C7/1000000 -> 49.999626
A8: 2029 | B8: 365 | C8: =C63 -> 49999890 | F8: $/kWh | I8: =C8/1000000 -> 49.99989
A9: 2030 | B9: 365 | C9: =C75 -> 49999890 | F9: $/kWh | I9: =C9/1000000 -> 49.99989
A10: 2031 | B10: 365 | C10: =C87 -> 49999890 | F10: $/kWh | I10: =C10/1000000 -> 49.99989
A11: 2032 | B11: 366 | C11: =C99 -> 49999626 | F11: $/kWh | I11: =C11/1000000 -> 49.999626
A12: 2033 | B12: 365 | C12: =C111 -> 49999890 | F12: $/kWh | I12: =C12/1000000 -> 49.99989
A13: 2034 | B13: 365 | C13: =C123 -> 49999890 | F13: $/kWh | I13: =C13/1000000 -> 49.99989
A14: 2035 | B14: 365 | C14: =C135 -> 49999890 | F14: $/kWh | I14: =C14/1000000 -> 49.99989
A15: 2036 | B15: 366 | C15: =C147 -> 49999626 | F15: $/kWh | I15: =C15/1000000 -> 49.999626
A16: 2037 | B16: 365 | C16: =C159 -> 49999890 | F16: $/kWh | I16: =C15/1000000 -> 49.999626
A17: 2038 | B17: 365 | C17: =C171 -> 49999890 | F17: $/kWh | I17: =C17/1000000 -> 49.99989
A18: 2039 | B18: 365 | C18: =C183 -> 49999890 | F18: $/kWh | I18: =C18/1000000 -> 49.99989
A19: 2040 | B19: 366 | C19: =C195 -> 49999626 | F19: $/kWh
C20: =SUM(C5:C19) -> 749997294
A22: * La energia a ofertar debe ser expresada únicamente en kilovatio (kWh) redondeado a cero decimales
A25: OFERTA PRODUCTO 4
A26: MES | B26: ENERGIA SOLICITADA (kWh) | C26: TOTAL ENERGIA | D26: % | E26: ENERGIA OFERTADA (KWh) | F26: PRECIO $/kWh
A27: 46023 | B27: =+VLOOKUP(A27,'CURVA P4'!$A$4:$QX$55,30,FALSE) -> 4246566 | C27: =SUM(B27:B38) -> 49999890 | D27: % | F27: $/kWh
A28: 46054 | B28: =+VLOOKUP(A28,'CURVA P4'!$A$4:$QX$55,30,FALSE) -> 3835608
A29: 46082 | B29: =+VLOOKUP(A29,'CURVA P4'!$A$4:$QX$55,30,FALSE) -> 4246566
A30: 46113 | B30: =+VLOOKUP(A30,'CURVA P4'!$A$4:$QX$55,30,FALSE) -> 4109580
A31: 46143 | B31: =+VLOOKUP(A31,'CURVA P4'!$A$4:$QX$55,30,FALSE) -> 4246566
A32: 46174 | B32: =+VLOOKUP(A32,'CURVA P4'!$A$4:$QX$55,30,FALSE) -> 4109580
A33: 46204 | B33: =+VLOOKUP(A33,'CURVA P4'!$A$4:$QX$55,30,FALSE) -> 4246566
A34: 46235 | B34: =+VLOOKUP(A34,'CURVA P4'!$A$4:$QX$55,30,FALSE) -> 4246566
A35: 46266 | B35: =+VLOOKUP(A35,'CURVA P4'!$A$4:$QX$55,30,FALSE) -> 4109580
A36: 46296 | B36: =+VLOOKUP(A36,'CURVA P4'!$A$4:$QX$55,30,FALSE) -> 4246566
A37: 46327 | B37: =+VLOOKUP(A37,'CURVA P4'!$A$4:$QX$55,30,FALSE) -> 4109580
A38: 46357 | B38: =+VLOOKUP(A38,'CURVA P4'!$A$4:$QX$55,30,FALSE) -> 4246566
A39: 46388 | B39: =+VLOOKUP(A39,'CURVA P4'!$AF$4:$QX$55,30,FALSE) -> 4246566 | C39: =SUM(B39:B50) -> 49999890 | F39: $/kWh
A40: 46419 | B40: =+VLOOKUP(A40,'CURVA P4'!$AF$4:$QX$55,30,FALSE) -> 3835608
A41: 46447 | B41: =+VLOOKUP(A41,'CURVA P4'!$AF$4:$QX$55,30,FALSE) -> 4246566
A42: 46478 | B42: =+VLOOKUP(A42,'CURVA P4'!$AF$4:$QX$55,30,FALSE) -> 4109580
A43: 46508 | B43: =+VLOOKUP(A43,'CURVA P4'!$AF$4:$QX$55,30,FALSE) -> 4246566
A44: 46539 | B44: =+VLOOKUP(A44,'CURVA P4'!$AF$4:$QX$55,30,FALSE) -> 4109580
...

Sheet CURVA P4
A1: Curva de distribucion en kWh | AF1: Curva de distribucion en kWh | BK1: Curva de distribucion en kWh | CP1: Curva de distribucion en kWh | DV1: Curva de distribucion en kWh | FB1: Curva de distribucion en kWh | GG1: Curva de distribucion en kWh | HL1: Curva de distribucion en kWh | IQ1: Curva de distribucion en kWh | JV1: Curva de distribucion en kWh | LA1: Curva de distribucion en kWh | MF1: Curva de distribucion en kWh | NK1: Curva de distribucion en kWh | OP1: Curva de distribucion en kWh | PU1: Curva de distribucion en kWh
A2: * La energia a ofertar debe ser expresada únicamente en kilovatio (kWh) redondeado a cero decimales | AF2: * La energia a ofertar debe ser expresada únicamente en kilovatio (kWh) redondeado a cero decimales | BK2: * La energia a ofertar debe ser expresada únicamente en kilovatio (kWh) redondeado a cero decimales | CP2: * La energia a ofertar debe ser expresada únicamente en kilovatio (kWh) redondeado a cero decimales | DV2: * La energia a ofertar debe ser expresada únicamente en kilovatio (kWh) redondeado a cero decimales | FB2: * La energia a ofertar debe ser expresada únicamente en kilovatio (kWh) redondeado a cero decimales | GG2: * La energia a ofertar debe ser expresada únicamente en kilovatio (kWh) redondeado a cero decimales | HL2: * La energia a ofertar debe ser expresada únicamente en kilovatio (kWh) redondeado a cero decimales | IQ2: * La energia a ofertar debe ser expresada únicamente en kilovatio (kWh) redondeado a cero decimales | JV2: * La energia a ofertar debe ser expresada únicamente en kilovatio (kWh) redondeado a cero decimales | LA2: * La energia a ofertar debe ser expresada únicamente en kilovatio (kWh) redondeado a cero decimales | MF2: * La energia a ofertar debe ser expresada únicamente en kilovatio (kWh) redondeado a cero decimales | NK2: * La energia a ofertar debe ser expresada únicamente en kilovatio (kWh) redondeado a cero decimales | OP2: * La energia a ofertar debe ser expresada únicamente en kilovatio (kWh) redondeado a cero decimales | PU2: * La energia a ofertar debe ser expresada únicamente en kilovatio (kWh) redondeado a cero decimales
A4: TOTAL | C4: =+AD55 -> 49999890 | AF4: TOTAL | AH4: =+BI55 -> 49999890 | BI4: 100000000 | BK4: TOTAL | BM4: =+CN55 -> 49999626 | CN4: 100000000 | CP4: TOTAL | CR4: =+DS55 -> 49999890 | DS4: 100000000 | DV4: TOTAL | DX4: =+EY55 -> 49999890 | EY4: 100000000 | FB4: TOTAL | FD4: =+GE55 -> 49999890 | GE4: 100000000 | GG4: TOTAL | GI4: =+HJ55 -> 49999626 | HJ4: 100000000 | HL4: TOTAL | HN4: =+IO55 -> 49999890 | IO4: 100000000 | IQ4: TOTAL | IS4: =+JT55 -> 49999890 | JT4: 100000000 | JV4: TOTAL | JX4: =+KY55 -> 49999890 | KY4: 100000000 | LA4: TOTAL | LC4: =+MD55 -> 49999626 | MD4: 100000000 | MF4: TOTAL | MH4: =+NI55 -> 49999890 | NK4: TOTAL | NM4: =+ON55 -> 49999890 | OP4: TOTAL | OR4: =+PS55 -> 49999890 | PS4: 100000000 | PU4: TOTAL | PW4: =+QX55 -> 49999626 | QX4: 100000000
