Workbook

Sheet Producto 1 2026
A1: ANEXO 1 - OFERTAS PRODUCTO 1 - CURVA PLC
A2: EMPRESA SIGLO XXI EICE ESP
A3: NOMBRE DEL OFERENTE
A4: PRODUCTO 1 - CURVA PLC
A5: AÑO | B5: MES | C5: PERIODO ENERO 2026 - DICIEMBRE 2026
C6: E. Solicitada [kWh] | D6: % E. Ofertado | E6: E. Ofertada [kWh] | F6: $/kWh
A7: 2026 | B7: 1 | C7: =SUMIFS('2026 Curvas'!AH:AH,'2026 Curvas'!A:A,A7,'2026 Curvas'!B:B,B7) -> 345097.67
A8: 2026 | B8: 2 | C8: =SUMIFS('2026 Curvas'!AH:AH,'2026 Curvas'!A:A,A8,'2026 Curvas'!B:B,B8) -> 345635.07
A9: 2026 | B9: 3 | C9: =SUMIFS('2026 Curvas'!AH:AH,'2026 Curvas'!A:A,A9,'2026 Curvas'!B:B,B9) -> 440635.06
A10: 2026 | B10: 4 | C10: =SUMIFS('2026 Curvas'!AH:AH,'2026 Curvas'!A:A,A10,'2026 Curvas'!B:B,B10) -> 392442.19
A11: 2026 | B11: 5 | C11: =SUMIFS('2026 Curvas'!AH:AH,'2026 Curvas'!A:A,A11,'2026 Curvas'!B:B,B11) -> 350729.26
A12: 2026 | B12: 6 | C12: =SUMIFS('2026 Curvas'!AH:AH,'2026 Curvas'!A:A,A12,'2026 Curvas'!B:B,B12) -> 310457.91
A13: 2026 | B13: 7 | C13: =SUMIFS('2026 Curvas'!AH:AH,'2026 Curvas'!A:A,A13,'2026 Curvas'!B:B,B13) -> 333760.19
A14: 2026 | B14: 8 | C14: =SUMIFS('2026 Curvas'!AH:AH,'2026 Curvas'!A:A,A14,'2026 Curvas'!B:B,B14) -> 359914.53
A15: 2026 | B15: 9 | C15: =SUMIFS('2026 Curvas'!AH:AH,'2026 Curvas'!A:A,A15,'2026 Curvas'!B:B,B15) -> 351876.54
A16: 2026 | B16: 10 | C16: =SUMIFS('2026 Curvas'!AH:AH,'2026 Curvas'!A:A,A16,'2026 Curvas'!B:B,B16) -> 373230.01
A17: 2026 | B17: 11 | C17: =SUMIFS('2026 Curvas'!AH:AH,'2026 Curvas'!A:A,A17,'2026 Curvas'!B:B,B17) -> 340262.43
A18: 2026 | B18: 12 | C18: =SUMIFS('2026 Curvas'!AH:AH,'2026 Curvas'!A:A,A18,'2026 Curvas'!B:B,B18) -> 367242.56
A19: Total | C19: =SUM(C7:C18) -> 4311283.4

Sheet Producto 2 2027
A2: ANEXO 1 - OFERTAS PRODUCTO2 - CURVA PLC
A3: EMPRESA SIGLO XXI EICE ESP
A4: NOMBRE DEL OFERENTE
A5: PRODUCTO 2 - CURVA PLC
A6: AÑO | B6: MES | C6: PERIODO ENERO 2027 - DICIEMBRE 2027
C7: E. Solicitada [kWh] | D7: % E. Ofertado | E7: E. Ofertada [kWh] | F7: $/kWh
A8: 2027 | B8: 1 | C8: =SUMIFS('2027 Curvas'!AH:AH,'2027 Curvas'!A:A,A8,'2027 Curvas'!B:B,B8) -> 342652.67
A9: 2027 | B9: 2 | C9: =SUMIFS('2027 Curvas'!AH:AH,'2027 Curvas'!A:A,A9,'2027 Curvas'!B:B,B9) -> 347611.77
A10: 2027 | B10: 3 | C10: =SUMIFS('2027 Curvas'!AH:AH,'2027 Curvas'!A:A,A10,'2027 Curvas'!B:B,B10) -> 447413.48
A11: 2027 | B11: 4 | C11: =SUMIFS('2027 Curvas'!AH:AH,'2027 Curvas'!A:A,A11,'2027 Curvas'!B:B,B11) -> 409689.57
A12: 2027 | B12: 5 | C12: =SUMIFS('2027 Curvas'!AH:AH,'2027 Curvas'!A:A,A12,'2027 Curvas'!B:B,B12) -> 354470.57
A13: 2027 | B13: 6 | C13: =SUMIFS('2027 Curvas'!AH:AH,'2027 Curvas'!A:A,A13,'2027 Curvas'!B:B,B13) -> 312959
A14: 2027 | B14: 7 | C14: =SUMIFS('2027 Curvas'!AH:AH,'2027 Curvas'!A:A,A14,'2027 Curvas'!B:B,B14) -> 337449.61
A15: 2027 | B15: 8 | C15: =SUMIFS('2027 Curvas'!AH:AH,'2027 Curvas'!A:A,A15,'2027 Curvas'!B:B,B15) -> 367011.66
A16: 2027 | B16: 9 | C16: =SUMIFS('2027 Curvas'!AH:AH,'2027 Curvas'!A:A,A16,'2027 Curvas'!B:B,B16) -> 355580.69
A17: 2027 | B17: 10 | C17: =SUMIFS('2027 Curvas'!AH:AH,'2027 Curvas'!A:A,A17,'2027 Curvas'!B:B,B17) -> 375703.24
A18: 2027 | B18: 11 | C18: =SUMIFS('2027 Curvas'!AH:AH,'2027 Curvas'!A:A,A18,'2027 Curvas'!B:B,B18) -> 342740.14
A19: 2027 | B19: 12 | C19: =SUMIFS('2027 Curvas'!AH:AH,'2027 Curvas'!A:A,A19,'2027 Curvas'!B:B,B19) -> 371134.83
A20: Total | C20: =SUM(C8:C19) -> 4364417.2

Sheet Producto 3 2028
A3: ANEXO 1 - OFERTAS PRODUCTO 3 - CURVA PLC
A4: EMPRESA SIGLO XXI EICE ESP
A5: NOMBRE DEL OFERENTE
A6: PRODUCTO 3 - CURVA PLC
A7: AÑO | B7: MES | C7: PERIODO ENERO 2028 - DICIEMBRE 2028
C8: E. Solicitada [kWh] | D8: % E. Ofertado | E8: E. Ofertada [kWh] | F8: $/kWh
A9: 2028 | B9: 1 | C9: =SUMIFS('2028 Curvas'!AH:AH,'2028 Curvas'!A:A,A9,'2028 Curvas'!B:B,B9) -> 347383.32
A10: 2028 | B10: 2 | C10: =SUMIFS('2028 Curvas'!AH:AH,'2028 Curvas'!A:A,A10,'2028 Curvas'!B:B,B10) -> 360614.2
A11: 2028 | B11: 3 | C11: =SUMIFS('2028 Curvas'!AH:AH,'2028 Curvas'!A:A,A11,'2028 Curvas'!B:B,B11) -> 445383.98
A12: 2028 | B12: 4 | C12: =SUMIFS('2028 Curvas'!AH:AH,'2028 Curvas'!A:A,A12,'2028 Curvas'!B:B,B12) -> 393926.38
A13: 2028 | B13: 5 | C13: =SUMIFS('2028 Curvas'!AH:AH,'2028 Curvas'!A:A,A13,'2028 Curvas'!B:B,B13) -> 354742.94
A14: 2028 | B14: 6 | C14: =SUMIFS('2028 Curvas'!AH:AH,'2028 Curvas'!A:A,A14,'2028 Curvas'!B:B,B14) -> 313177.48
A15: 2028 | B15: 7 | C15: =SUMIFS('2028 Curvas'!AH:AH,'2028 Curvas'!A:A,A15,'2028 Curvas'!B:B,B15) -> 334770.99
A16: 2028 | B16: 8 | C16: =SUMIFS('2028 Curvas'!AH:AH,'2028 Curvas'!A:A,A16,'2028 Curvas'!B:B,B16) -> 363537.94
A17: 2028 | B17: 9 | C17: =SUMIFS('2028 Curvas'!AH:AH,'2028 Curvas'!A:A,A17,'2028 Curvas'!B:B,B17) -> 353128.76
A18: 2028 | B18: 10 | C18: =SUMIFS('2028 Curvas'!AH:AH,'2028 Curvas'!A:A,A18,'2028 Curvas'!B:B,B18) -> 374326.76
A19: 2028 | B19: 11 | C19: =SUMIFS('2028 Curvas'!AH:AH,'2028 Curvas'!A:A,A19,'2028 Curvas'!B:B,B19) -> 344988.65
A20: 2028 | B20: 12 | C20: =SUMIFS('2028 Curvas'!AH:AH,'2028 Curvas'!A:A,A20,'2028 Curvas'!B:B,B20) -> 367506.13
A21: Total | C21: =SUM(C9:C20) -> 4353487.5

Sheet 2026 Curvas
A1: ANEXO 1A - CANTIDADES DE ENERGÍA SOLICITADA EN kWh
A2: CURVA HORARIA POR TIPO DE DÍA
A3: OFERTA BASICA MODALIDAD PAGUE LO CONTRATADO
A4: kWh.
A5: PERIODO 01 DE ENERO 2026 A DICIEMBRE 31 DE 20256
A6: año | B6: mes | C6: tipo_dia | D6: Laborales | E6: Sabados | F6: Domingos | G6: Festivos | H6: Total Dias | I6: hora_0 | J6: hora_1 | K6: hora_2 | L6: hora_3 | M6: hora_4 | N6: hora_5 | O6: hora_6 | P6: hora_7 | Q6: hora_8 | R6: hora_9 | S6: hora_10 | T6: hora_11 | U6: hora_12 | V6: hora_13 | W6: hora_14 | X6: hora_15 | Y6: hora_16 | Z6: hora_17 | AA6: hora_18 | AB6: hora_19 | AC6: hora_20 | AD6: hora_21 | AE6: hora_22 | AF6: hora_23 | AG6: consumo_diario | AH6: consumo_mensual_tipo | AI6: TOTAL
A7: 2026 | B7: 1 | C7: 1 | D7: 20 | E7: 5 | F7: 4 | G7: 2 | H7: 31 | I7: 416.13776 | J7: 397.5473 | K7: 382.01815 | L7: 372.11408 | M7: 362.15103 | N7: 332.41267 | O7: 370.80874 | P7: 409.83922 | Q7: 467.33686 | R7: 484.07898 | S7: 524.29112 | T7: 534.66942 | U7: 525.57268 | V7: 535.05348 | W7: 573.34995 | X7: 558.93288 | Y7: 552.49395 | Z7: 557.41507 | AA7: 594.42856 | AB7: 593.09292 | AC7: 563.65565 | AD7: 515.4329 | AE7: 473.08495 | AF7: 438.41025 | AG7: =SUM(I7:AF7) -> 11534.329 | AH7: =AG7*D7 -> 230686.57 | AI7: =AH7+AH8+AH9+AH10 -> 345097.67
A8: 2026 | B8: 1 | C8: 2 | D8: 20 | E8: 5 | F8: 4 | G8: 2 | H8: 31 | I8: 390.91234 | J8: 374.14058 | K8: 364.17105 | L8: 355.3175 | M8: 344.67492 | N8: 327.41321 | O8: 354.92406 | P8: 394.70072 | Q8: 421.09559 | R8: 433.26984 | S8: 456.42567 | T8: 468.2634 | U8: 470.47555 | V8: 483.07046 | W8: 476.80517 | X8: 443.01914 | Y8: 487.08153 | Z8: 518.48715 | AA8: 566.89961 | AB8: 557.43734 | AC8: 530.42881 | AD8: 471.64349 | AE8: 440.03744 | AF8: 414.14983 | AG8: =SUM(I8:AF8) -> 10544.844 | AH8: =E8*AG8 -> 52724.222
A9: 2026 | B9: 1 | C9: 3 | D9: 20 | E9: 5 | F9: 4 | G9: 2 | H9: 31 | I9: 390.95235 | J9: 374.96255 | K9: 363.43601 | L9: 354.05797 | M9: 346.171 | N9: 320.25736 | O9: 343.05739 | P9: 377.82062 | Q9: 362.98447 | R9: 377.14084 | S9: 420.41128 | T9: 434.91498 | U9: 443.02276 | V9: 455.12737 | W9: 469.68813 | X9: 466.31155 | Y9: 454.79244 | Z9: 485.26857 | AA9: 547.93765 | AB9: 555.15725 | AC9: 532.85341 | AD9: 486.21382 | AE9: 455.49207 | AF9: 418.7019 | AG9: =SUM(I9:AF9) -> 10236.734 | AH9: =AG9*F9 -> 40946.935
A10: 2026 | B10: 1 | C10: 4 | D10: 20 | E10: 5 | F10: 4 | G10: 2 | H10: 31 | I10: 396.24027 | J10: 386.7273 | K10: 375.12648 | L10: 367.68634 | M10: 359.15471 | N10: 337.97082 | O10: 364.78238 | P10: 395.93486 | Q10: 413.60395 | R10: 416.52793 | S10: 435.24846 | T10: 444.96671 | U10: 451.17017 | V10: 455.91163 | W10: 410.34951 | X10: 397.61715 | Y10: 453.28806 | Z10: 484.63079 | AA10: 542.84016 | AB10: 554.19564 | AC10: 542.55978 | AD10: 495.62578 | AE10: 459.67677 | AF10: 428.13376 | AG10: =SUM(I10:AF10) -> 10369.969 | AH10: =AG10*G10 -> 20739.939
A11: 2026 | B11: 2 | C11: 1 | D11: 20 | E11: 4 | F11: 4 | G11: 0 | H11: 28 | I11: 463.33738 | J11: 428.94217 | K11: 414.72357 | L11: 401.12937 | M11: 373.23894 | N11: 355.17709 | O11: 371.47826 | P11: 471.30703 | Q11: 506.63353 | R11: 515.64379 | S11: 575.5179 | T11: 584.87081 | U11: 567.97691 | V11: 592.00776 | W11: 633.86037 | X11: 597.4747 | Y11: 601.39841 | Z11: 562.04049 | AA11: 603.43455 | AB11: 627.95614 | AC11: 617.13465 | AD11: 576.46803 | AE11: 533.78538 | AF11: 492.57487 | AG11: =SUM(I11:AF11) -> 12468.112 | AH11: =AG11*D11 -> 249362.24 | AI11: =AH11+AH12+AH13+AH14 -> 345635.07
A12: 2026 | B12: 2 | C12: 2 | D12: 20 | E12: 4 | F12: 4 | G12: 0 | H12: 28 | I12: 469.47638 | J12: 446.4227 | K12: 431.38535 | L12: 416.01025 | M12: 403.22198 | N12: 385.06561 | O12: 396.42614 | P12: 434.69883 | Q12: 463.04131 | R12: 479.54222 | S12: 499.44873 | T12: 515.65795 | U12: 518.19872 | V12: 544.83199 | W12: 566.12019 | X12: 566.17392 | Y12: 548.20689 | Z12: 545.4691 | AA12: 620.08014 | AB12: 630.52722 | AC12: 612.69835 | AD12: 581.15753 | AE12: 546.02689 | AF12: 505.48209 | AG12: =SUM(I12:AF12) -> 12125.37 | AH12: =AG12*E12 -> 48501.482
A13: 2026 | B13: 2 | C13: 3 | D13: 20 | E13: 4 | F13: 4 | G13: 0 | H13: 28 | I13: 476.03921 | J13: 434.23179 | K13: 435.14254 | L13: 418.54374 | M13: 404.25902 | N13: 383.45793 | O13: 380.12021 | P13: 417.3123 | Q13: 439.67835 | R13: 458.1474 | S13: 475.93146 | T13: 501.06569 | U13: 514.77573 | V13: 545.23594 | W13: 559.67715 | X13: 554.55898 | Y13: 531.45919 | Z13: 526.18452 | AA13: 602.37737 | AB13: 632.4425 | AC13: 623.13229 | AD13: 587.25887 | AE13: 541.73403 | AF13: 500.07027 | AG13: =SUM(I13:AF13) -> 11942.837 | AH13: =AG13*F13 -> 47771.346
A14: 2026 | B14: 2 | C14: 4 | D14: 20 | E14: 4 | F14: 4 | G14: 0 | H14: 28 | AG14: =SUM(I14:AF14) -> 0 | AH14: =AG14*G14 -> 0
A15: 2026 | B15: 3 | C15: 1 | D15: 21 | E15: 4 | F15: 5 | G15: 1 | H15: 31 | I15: 567.38217 | J15: 542.23976 | K15: 524.68663 | L15: 505.03613 | M15: 486.61704 | N15: 466.09644 | O15: 483.70702 | P15: 544.91819 | Q15: 591.66987 | R15: 620.36081 | S15: 652.87393 | T15: 666.69491 | U15: 645.61161 | V15: 670.62015 | W15: 694.76274 | X15: 717.23856 | Y15: 680.4614 | Z15: 664.93279 | AA15: 714.20238 | AB15: 722.64162 | AC15: 709.37386 | AD15: 684.14616 | AE15: 645.99602 | AF15: 604.28254 | AG15: =SUM(I15:AF15) -> 14806.553 | AH15: =AG15*D15 -> 310937.61 | AI15: =AH15+AH16+AH17+AH18 -> 440635.06
A16: 2026 | B16: 3 | C16: 2 | D16: 21 | E16: 4 | F16: 5 | G16: 1 | H16: 31 | I16: 524.70873 | J16: 510.52574 | K16: 493.03227 | L16: 476.51722 | M16: 459.43212 | N16: 438.97021 | O16: 447.13134 | P16: 441.79147 | Q16: 485.9615 | R16: 526.40439 | S16: 547.53171 | T16: 560.73421 | U16: 567.13128 | V16: 591.9111 | W16: 603.51952 | X16: 603.54025 | Y16: 576.43667 | Z16: 580.85201 | AA16: 649.20693 | AB16: 628.93159 | AC16: 638.14577 | AD16: 611.24326 | AE16: 581.619 | AF16: 551.36042 | AG16: =SUM(I16:AF16) -> 13096.639 | AH16: =AG16*E16 -> 52386.555
A17: 2026 | B17: 3 | C17: 3 | D17: 21 | E17: 4 | F17: 5 | G17: 1 | H17: 31 | I17: 535.49147 | J17: 514.85293 | K17: 496.18324 | L17: 478.98446 | M17: 466.54217 | N17: 441.19298 | O17: 445.30986 | P17: 476.06973 | Q17: 499.45216 | R17: 512.28822 | S17: 529.62451 | T17: 556.71753 | U17: 565.60965 | V17: 589.78378 | W17: 606.29085 | X17: 604.87828 | Y17: 573.56838 | Z17: 568.12019 | AA17: 633.53597 | AB17: 656.81631 | AC17: 651.22644 | AD17: 621.21035 | AE17: 585.82524 | AF17: 549.34425 | AG17: =SUM(I17:AF17) -> 13158.919 | AH17: =AG17*F17 -> 65794.595
A18: 2026 | B18: 3 | C18: 4 | D18: 21 | E18: 4 | F18: 5 | G18: 1 | H18: 31 | I18: 489.82477 | J18: 476.50482 | K18: 464.78179 | L18: 453.2091 | M18: 443.06963 | N18: 420.77283 | O18: 425.95782 | P18: 455.69803 | Q18: 422.3898 | R18: 323.11991 | S18: 436.86902 | T18: 478.20531 | U18: 505.16259 | V18: 522.66194 | W18: 532.0898 | X18: 534.13774 | Y18: 499.25263 | Z18: 500.18807 | AA18: 480.0862 | AB18: 581.2303 | AC18: 573.81029 | AD18: 557.82768 | AE18: 501.97208 | AF18: 437.47706 | AG18: =SUM(I18:AF18) -> 11516.299 | AH18: =AG18*G18 -> 11516.299
A19: 2026 | B19: 4 | C19: 1 | D19: 20 | E19: 4 | F19: 4 | G19: 2 | H19: 30 | I19: 478.38667 | J19: 473.93053 | K19: 456.98696 | L19: 437.79324 | M19: 417.42482 | N19: 397.5342 | O19: 446.27367 | P19: 507.02879 | Q19: 542.67109 | R19: 574.15044 | S19: 602.02293 | T19: 620.11767 | U19: 590.54768 | V19: 609.23372 | W19: 658.65501 | X19: 664.80089 | Y19: 635.32446 | Z19: 617.67271 | AA19: 662.68736 | AB19: 662.21875 | AC19: 644.98113 | AD19: 616.21442 | AE19: 543.68455 | AF19: 517.51302 | AG19: =SUM(I19:AF19) -> 13377.855 | AH19: =AG19*D19 -> 267557.09 | AI19: =AH19+AH20+AH21+AH22 -> 392442.19
A20: 2026 | B20: 4 | C20: 2 | D20: 20 | E20: 4 | F20: 4 | G20: 2 | H20: 30 | I20: 498.88339 | J20: 479.89369 | K20: 465.53721 | L20: 453.64841 | M20: 436.79546 | N20: 409.25158 | O20: 432.44642 | P20: 476.5303 | Q20: 507.07425 | R20: 513.04203 | S20: 548.0861 | T20: 572.30256 | U20: 564.42106 | V20: 566.26643 | W20: 578.54372 | X20: 574.58319 | Y20: 543.96729 | Z20: 533.74401 | AA20: 614.44393 | AB20: 624.99816 | AC20: 607.46893 | AD20: 573.62273 | AE20: 536.25846 | AF20: 497.91214 | AG20: =SUM(I20:AF20) -> 12609.721 | AH20: =AG20*E20 -> 50438.886
A21: 2026 | B21: 4 | C21: 3 | D21: 20 | E21: 4 | F21: 4 | G21: 2 | H21: 30 | I21: 486.14544 | J21: 470.60585 | K21: 457.07687 | L21: 441.8526 | M21: 432.55259 | N21: 403.85128 | O21: 419.46135 | P21: 456.71333 | Q21: 478.43315 | R21: 500.27909 | S21: 517.05027 | T21: 538.22106 | U21: 482.70292 | V21: 600.79861 | W21: 600.59087 | X21: 601.05828 | Y21: 575.29127 | Z21: 577.05334 | AA21: 666.27707 | AB21: 691.76957 | AC21: 685.41128 | AD21: 649.41315 | AE21: 597.7122 | AF21: 556.88044 | AG21: =SUM(I21:AF21) -> 12887.202 | AH21: =AG21*F21 -> 51548.807
A22: 2026 | B22: 4 | C22: 4 | D22: 20 | E22: 4 | F22: 4 | G22: 2 | H22: 30 | I22: 435.82127 | J22: 434.2715 | K22: 412.97219 | L22: 395.82156 | M22: 383.34293 | N22: 368.97402 | O22: 398.3744 | P22: 418.02685 | Q22: 439.92991 | R22: 441.91195 | S22: 473.85135 | T22: 501.65093 | U22: 524.0355 | V22: 523.9657 | W22: 508.77975 | X22: 517.98203 | Y22: 490.93679 | Z22: 513.2381 | AA22: 583.32769 | AB22: 604.53877 | AC22: 574.59134 | AD22: 544.26443 | AE22: 497.94018 | AF22: 460.15281 | AG22: =SUM(I22:AF22) -> 11448.702 | AH22: =AG22*G22 -> 22897.404
A23: 2026 | B23: 5 | C23: 1 | D23: 19 | E23: 5 | F23: 5 | G23: 2 | H23: 31 | I23: 389.42603 | J23: 365.34497 | K23: 358.58584 | L23: 354.69135 | M23: 341.83813 | N23: 328.31163 | O23: 396.54195 | P23: 439.68659 | Q23: 477.85501 | R23: 506.19849 | S23: 531.67232 | T23: 567.36282 | U23: 518.95785 | V23: 549.09269 | W23: 587.11828 | X23: 589.22742 | Y23: 559.54195 | Z23: 539.19277 | AA23: 595.88126 | AB23: 588.14352 | AC23: 569.93153 | AD23: 530.47978 | AE23: 464.34329 | AF23: 429.88869 | AG23: =SUM(I23:AF23) -> 11579.314 | AH23: =AG23*D23 -> 220006.97 | AI23: =AH23+AH24+AH25+AH26 -> 350729.26
A24: 2026 | B24: 5 | C24: 2 | D24: 19 | E24: 5 | F24: 5 | G24: 2 | H24: 31 | I24: 466.0265 | J24: 450.53867 | K24: 434.78538 | L24: 418.18925 | M24: 411.45441 | N24: 381.12312 | O24: 365.27446 | P24: 346.83032 | Q24: 482.00489 | R24: 509.9615 | S24: 429.60215 | T24: 517.62164 | U24: 510.84298 | V24: 451.34799 | W24: 512.09304 | X24: 528.90824 | Y24: 509.76304 | Z24: 522.51362 | AA24: 569.48742 | AB24: 573.49791 | AC24: 547.81117 | AD24: 506.6366 | AE24: 474.73308 | AF24: 443.37855 | AG24: =SUM(I24:AF24) -> 11364.426 | AH24: =AG24*E24 -> 56822.13
A25: 2026 | B25: 5 | C25: 3 | D25: 19 | E25: 5 | F25: 5 | G25: 2 | H25: 31 | I25: 406.63661 | J25: 391.92888 | K25: 383.0074 | L25: 376.69695 | M25: 374.33054 | N25: 348.78423 | O25: 357.36374 | P25: 372.41594 | Q25: 421.40674 | R25: 420.35583 | S25: 434.24729 | T25: 452.82914 | U25: 372.66057 | V25: 472.82053 | W25: 464.05714 | X25: 422.73639 | Y25: 431.0671 | Z25: 467.52688 | AA25: 536.03312 | AB25: 511.91964 | AC25: 511.77237 | AD25: 471.94769 | AE25: 437.75448 | AF25: 410.35597 | AG25: =SUM(I25:AF25) -> 10250.655 | AH25: =AG25*F25 -> 51253.276
A26: 2026 | B26: 5 | C26: 4 | D26: 19 | E26: 5 | F26: 5 | G26: 2 | H26: 31 | I26: 454.35932 | J26: 440.3938 | K26: 423.55395 | L26: 412.44166 | M26: 402.02554 | N26: 371.75812 | O26: 353.71053 | P26: 444.20689 | Q26: 492.53771 | R26: 420.83785 | S26: 545.75752 | T26: 559.73886 | U26: 558.59968 | V26: 375.43936 | W26: 305.43772 | X26: 355.64609 | Y26: 532.70968 | Z26: 532.27194 | AA26: 590.85539 | AB26: 602.147 | AC26: 584.85359 | AD26: 562.41805 | AE26: 517.06176 | AF26: 484.67947 | AG26: =SUM(I26:AF26) -> 11323.441 | AH26: =AG26*G26 -> 22646.883
A27: 2026 | B27: 6 | C27: 1 | D27: 19 | E27: 4 | F27: 4 | G27: 3 | H27: 30 | I27: 368.40277 | J27: 358.14731 | K27: 348.75778 | L27: 340.85269 | M27: 321.97448 | N27: 311.24437 | O27: 355.72236 | P27: 392.52111 | Q27: 432.28875 | R27: 445.86334 | S27: 468.09843 | T27: 492.64488 | U27: 479.83504 | V27: 461.21903 | W27: 502.52888 | X27: 520.0348 | Y27: 506.42054 | Z27: 486.34263 | AA27: 528.11855 | AB27: 523.37358 | AC27: 532.0433 | AD27: 485.16881 | AE27: 420.00171 | AF27: 388.63976 | AG27: =SUM(I27:AF27) -> 10470.245 | AH27: =AG27*D27 -> 198934.65 | AI27: =AH27+AH28+AH29+AH30 -> 310457.91
A28: 2026 | B28: 6 | C28: 2 | D28: 19 | E28: 4 | F28: 4 | G28: 3 | H28: 30 | I28: 388.42377 | J28: 375.63062 | K28: 365.12675 | L28: 354.06224 | M28: 334.70798 | N28: 329.77801 | O28: 359.35379 | P28: 398.51325 | Q28: 431.61333 | R28: 447.79876 | S28: 456.18804 | T28: 460.26487 | U28: 450.9615 | V28: 462.85275 | W28: 464.74795 | X28: 466.7955 | Y28: 448.53612 | Z28: 470.82358 | AA28: 500.74874 | AB28: 527.65741 | AC28: 497.47428 | AD28: 460.49643 | AE28: 425.37723 | AF28: 395.01941 | AG28: =SUM(I28:AF28) -> 10272.952 | AH28: =AG28*E28 -> 41091.809
A29: 2026 | B29: 6 | C29: 3 | D29: 19 | E29: 4 | F29: 4 | G29: 3 | H29: 30 | I29: 373.4559 | J29: 349.16982 | K29: 334.95924 | L29: 346.85862 | M29: 320.29834 | N29: 292.74491 | O29: 346.43915 | P29: 374.17352 | Q29: 396.69537 | R29: 402.85171 | S29: 417.0335 | T29: 433.36405 | U29: 449.79124 | V29: 470.28153 | W29: 470.84494 | X29: 467.65573 | Y29: 448.14626 | Z29: 456.79886 | AA29: 533.78191 | AB29: 548.43663 | AC29: 535.64691 | AD29: 502.99815 | AE29: 463.35205 | AF29: 423.54146 | AG29: =SUM(I29:AF29) -> 10159.32 | AH29: =AG29*F29 -> 40637.279
A30: 2026 | B30: 6 | C30: 4 | D30: 19 | E30: 4 | F30: 4 | G30: 3 | H30: 30 | I30: 395.51865 | J30: 381.35713 | K30: 369.94658 | L30: 359.98181 | M30: 354.69571 | N30: 333.91276 | O30: 358.58624 | P30: 308.48627 | Q30: 388.75164 | R30: 433.52033 | S30: 453.29425 | T30: 473.00292 | U30: 458.98195 | V30: 466.73289 | W30: 449.18284 | X30: 443.89172 | Y30: 386.91933 | Z30: 390.60404 | AA30: 510.68331 | AB30: 507.31989 | AC30: 477.54605 | AD30: 444.64473 | AE30: 406.75851 | AF30: 377.07002 | AG30: =SUM(I30:AF30) -> 9931.3896 | AH30: =AG30*G30 -> 29794.169
A31: 2026 | B31: 7 | C31: 1 | D31: 22 | E31: 4 | F31: 4 | G31: 1 | H31: 31 | I31: 377.41997 | J31: 353.91778 | K31: 345.45179 | L31: 341.52661 | M31: 345.01732 | N31: 337.99074 | O31: 382.30537 | P31: 417.92491 | Q31: 457.11293 | R31: 480.98487 | S31: 499.15879 | T31: 500.36815 | U31: 493.8021 | V31: 492.20113 | W31: 532.51981 | X31: 524.07012 | Y31: 509.4018 | Z31: 516.90104 | AA31: 566.516 | AB31: 558.93899 | AC31: 544.40665 | AD31: 490.27417 | AE31: 440.30762 | AF31: 403.99655 | AG31: =SUM(I31:AF31) -> 10912.515 | AH31: =AG31*D31 -> 240075.33 | AI31: =AH31+AH32+AH33+AH34 -> 333760.19
A32: 2026 | B32: 7 | C32: 2 | D32: 22 | E32: 4 | F32: 4 | G32: 1 | H32: 31 | I32: 375.90657 | J32: 361.81033 | K32: 353.85306 | L32: 348.27093 | M32: 349.98957 | N32: 332.16389 | O32: 353.27903 | P32: 377.05118 | Q32: 399.98464 | R32: 412.48599 | S32: 444.03324 | T32: 454.27286 | U32: 457.11205 | V32: 435.08259 | W32: 501.94434 | X32: 497.90211 | Y32: 364.43727 | Z32: 520.39818 | AA32: 568.53111 | AB32: 590.14208 | AC32: 573.41117 | AD32: 523.15143 | AE32: 476.9829 | AF32: 440.25998 | AG32: =SUM(I32:AF32) -> 10512.456 | AH32: =AG32*E32 -> 42049.826
A33: 2026 | B33: 7 | C33: 3 | D33: 22 | E33: 4 | F33: 4 | G33: 1 | H33: 31 | I33: 412.25373 | J33: 397.26869 | K33: 383.47026 | L33: 368.84916 | M33: 370.74823 | N33: 355.87853 | O33: 381.14319 | P33: 404.73174 | Q33: 406.86916 | R33: 349.29967 | S33: 405.13325 | T33: 440.96201 | U33: 442.86195 | V33: 409.36795 | W33: 469.62844 | X33: 461.03517 | Y33: 444.02036 | Z33: 449.20246 | AA33: 523.91747 | AB33: 537.60826 | AC33: 512.24621 | AD33: 472.86533 | AE33: 437.69266 | AF33: 406.34634 | AG33: =SUM(I33:AF33) -> 10243.4 | AH33: =AG33*F33 -> 40973.601
A34: 2026 | B34: 7 | C34: 4 | D34: 22 | E34: 4 | F34: 4 | G34: 1 | H34: 31 | I34: 403.67651 | J34: 380.90767 | K34: 370.31943 | L34: 365.08735 | M34: 362.01635 | N34: 328.18363 | O34: 371.63262 | P34: 400.95707 | Q34: 430.21948 | R34: 438.99821 | S34: 444.73695 | T34: 469.27394 | U34: 492.08415 | V34: 476.52234 | W34: 470.46305 | X34: 480.90653 | Y34: 476.15009 | Z34: 492.04279 | AA34: 559.99776 | AB34: 562.21053 | AC34: 533.47547 | AD34: 482.9125 | AE34: 450.94099 | AF34: 417.70799 | AG34: =SUM(I34:AF34) -> 10661.423 | AH34: =AG34*G34 -> 10661.423
A35: 2026 | B35: 8 | C35: 1 | D35: 19 | E35: 5 | F35: 5 | G35: 2 | H35: 31 | I35: 415.33364 | J35: 388.81548 | K35: 378.11783 | L35: 366.93665 | M35: 364.69636 | N35: 356.10411 | O35: 408.75495 | P35: 452.64544 | Q35: 489.48925 | R35: 491.61539 | S35: 537.72749 | T35: 565.83481 | U35: 550.58085 | V35: 575.88081 | W35: 599.30782 | X35: 574.2076 | Y35: 535.43688 | Z35: 548.93618 | AA35: 600.48088 | AB35: 606.65126 | AC35: 581.72745 | AD35: 536.04286 | AE35: 477.5926 | AF35: 444.17044 | AG35: =SUM(I35:AF35) -> 11847.087 | AH35: =AG35*D35 -> 225094.65 | AI35: =AH35+AH36+AH37+AH38 -> 359914.53
A36: 2026 | B36: 8 | C36: 2 | D36: 19 | E36: 5 | F36: 5 | G36: 2 | H36: 31 | I36: 404.7963 | J36: 404.12357 | K36: 391.04337 | L36: 380.47852 | M36: 378.75438 | N36: 353.74484 | O36: 383.24561 | P36: 427.49571 | Q36: 461.05826 | R36: 478.33139 | S36: 477.47038 | T36: 533.32405 | U36: 539.85885 | V36: 561.75014 | W36: 568.79267 | X36: 549.93502 | Y36: 524.23582 | Z36: 538.3505 | AA36: 619.26237 | AB36: 627.64825 | AC36: 598.22575 | AD36: 559.09941 | AE36: 521.80087 | AF36: 486.73842 | AG36: =SUM(I36:AF36) -> 11769.564 | AH36: =AG36*E36 -> 58847.822
A37: 2026 | B37: 8 | C37: 3 | D37: 19 | E37: 5 | F37: 5 | G37: 2 | H37: 31 | I37: 449.31213 | J37: 339.19037 | K37: 311.95548 | L37: 408.24592 | M37: 396.849 | N37: 364.88009 | O37: 382.26324 | P37: 410.96552 | Q37: 429.84198 | R37: 438.49077 | S37: 446.76364 | T37: 470.78375 | U37: 471.81559 | V37: 474.69852 | W37: 475.06148 | X37: 478.9607 | Y37: 469.25932 | Z37: 479.45588 | AA37: 552.92915 | AB37: 575.99001 | AC37: 559.41575 | AD37: 526.22833 | AE37: 483.18139 | AF37: 436.04339 | AG37: =SUM(I37:AF37) -> 10832.581 | AH37: =AG37*F37 -> 54162.907
A38: 2026 | B38: 8 | C38: 4 | D38: 19 | E38: 5 | F38: 5 | G38: 2 | H38: 31 | I38: 390.4606 | J38: 375.55992 | K38: 362.60213 | L38: 354.08526 | M38: 353.91564 | N38: 333.10916 | O38: 377.5388 | P38: 415.65658 | Q38: 440.59043 | R38: 444.90798 | S38: 481.44266 | T38: 510.35996 | U38: 511.61924 | V38: 535.08307 | W38: 536.71243 | X38: 524.55133 | Y38: 213.50278 | Z38: 448.39286 | AA38: 600.85372 | AB38: 622.48259 | AC38: 595.19979 | AD38: 543.69246 | AE38: 487.17369 | AF38: 445.08273 | AG38: =SUM(I38:AF38) -> 10904.576 | AH38: =AG38*G38 -> 21809.152
A39: 2026 | B39: 9 | C39: 1 | D39: 22 | E39: 4 | F39: 4 | G39: 0 | H39: 30 | I39: 414.53128 | J39: 396.97385 | K39: 383.08784 | L39: 373.06546 | M39: 372.4967 | N39: 365.53825 | O39: 409.73215 | P39: 467.95964 | Q39: 501.73891 | R39: 541.80393 | S39: 572.52466 | T39: 590.38216 | U39: 556.48375 | V39: 563.54614 | W39: 599.65291 | X39: 617.45157 | Y39: 585.65069 | Z39: 581.19674 | AA39: 616.95195 | AB39: 616.64551 | AC39: 594.82877 | AD39: 548.94723 | AE39: 490.34857 | AF39: 451.3132 | AG39: =SUM(I39:AF39) -> 12212.852 | AH39: =AG39*D39 -> 268682.74 | AI39: =AH39+AH40+AH41+AH42 -> 351876.54
A40: 2026 | B40: 9 | C40: 2 | D40: 22 | E40: 4 | F40: 4 | G40: 0 | H40: 30 | I40: 405.32705 | J40: 392.18944 | K40: 379.52012 | L40: 369.53148 | M40: 364.42072 | N40: 341.05906 | O40: 370.94144 | P40: 416.108 | Q40: 445.64612 | R40: 458.08002 | S40: 457.55603 | T40: 487.50423 | U40: 486.436 | V40: 508.72439 | W40: 518.56621 | X40: 516.974 | Y40: 490.80002 | Z40: 471.15688 | AA40: 574.08845 | AB40: 580.48259 | AC40: 550.01548 | AD40: 508.78514 | AE40: 473.92616 | AF40: 438.3331 | AG40: =SUM(I40:AF40) -> 11006.172 | AH40: =AG40*E40 -> 44024.689
...

Sheet 2027 Curvas
A1: ANEXO 1A - CANTIDADES DE ENERGÍA SOLICITADA EN kWh
A2: CURVA HORARIA POR TIPO DE DÍA
A3: OFERTA BASICA MODALIDAD PAGUE LO CONTRATADO
A4: kWh.
A5: PERIODO 01 DE ENERO 2027 A DICIEMBRE 31 DE 2027
A6: año | B6: mes | C6: tipo_dia | D6: Laborales | E6: Sabados | F6: Domingos | G6: Festivos | H6: Total Dias | I6: hora_0 | J6: hora_1 | K6: hora_2 | L6: hora_3 | M6: hora_4 | N6: hora_5 | O6: hora_6 | P6: hora_7 | Q6: hora_8 | R6: hora_9 | S6: hora_10 | T6: hora_11 | U6: hora_12 | V6: hora_13 | W6: hora_14 | X6: hora_15 | Y6: hora_16 | Z6: hora_17 | AA6: hora_18 | AB6: hora_19 | AC6: hora_20 | AD6: hora_21 | AE6: hora_22 | AF6: hora_23 | AG6: consumo_diario | AH6: consumo_mensual_tipo | AI6: TOTAL
A7: 2027 | B7: 1 | C7: 1 | D7: 19 | E7: 5 | F7: 5 | G7: 2 | H7: 31 | I7: 415.6689 | J7: 397.09939 | K7: 381.58773 | L7: 371.69483 | M7: 361.743 | N7: 332.03815 | O7: 370.39096 | P7: 409.37746 | Q7: 466.81032 | R7: 483.53357 | S7: 523.70041 | T7: 534.06701 | U7: 524.98052 | V7: 534.45065 | W7: 572.70397 | X7: 558.30314 | Y7: 551.87147 | Z7: 556.78704 | AA7: 593.75882 | AB7: 592.42469 | AC7: 563.02059 | AD7: 514.85217 | AE7: 472.55193 | AF7: 437.9163 | AG7: =SUM(I7:AF7) -> 11521.333 | AH7: =AG7*D7 -> 218905.33 | AI7: =AH7+AH8+AH9+AH10 -> 342652.67
A8: 2027 | B8: 1 | C8: 2 | D8: 19 | E8: 5 | F8: 5 | G8: 2 | H8: 31 | I8: 386.91597 | J8: 370.31566 | K8: 360.44805 | L8: 351.68501 | M8: 341.15124 | N8: 324.066 | O8: 351.2956 | P8: 390.66561 | Q8: 416.79064 | R8: 428.84044 | S8: 451.75954 | T8: 463.47625 | U8: 465.66578 | V8: 478.13193 | W8: 471.9307 | X8: 438.49007 | Y8: 482.102 | Z8: 513.18655 | AA8: 561.10408 | AB8: 551.73854 | AC8: 525.00612 | AD8: 466.82178 | AE8: 435.53885 | AF8: 409.91589 | AG8: =SUM(I8:AF8) -> 10437.042 | AH8: =AG8*E8 -> 52185.211
A9: 2027 | B9: 1 | C9: 3 | D9: 19 | E9: 5 | F9: 5 | G9: 2 | H9: 31 | I9: 387.97505 | J9: 372.10702 | K9: 360.66826 | L9: 351.36164 | M9: 343.53473 | N9: 317.81843 | O9: 340.44483 | P9: 374.94332 | Q9: 360.22016 | R9: 374.26872 | S9: 417.20963 | T9: 431.60288 | U9: 439.64892 | V9: 451.66134 | W9: 466.11122 | X9: 462.76034 | Y9: 451.32896 | Z9: 481.573 | AA9: 543.76482 | AB9: 550.92944 | AC9: 528.79545 | AD9: 482.51105 | AE9: 452.02327 | AF9: 415.51327 | AG9: =SUM(I9:AF9) -> 10158.776 | AH9: =AG9*F9 -> 50793.879
A10: 2027 | B10: 1 | C10: 4 | D10: 19 | E10: 5 | F10: 5 | G10: 2 | H10: 31 | I10: 396.78128 | J10: 387.25532 | K10: 375.63866 | L10: 368.18836 | M10: 359.64508 | N10: 338.43227 | O10: 365.28044 | P10: 396.47545 | Q10: 414.16866 | R10: 417.09664 | S10: 435.84273 | T10: 445.57425 | U10: 451.78618 | V10: 456.53411 | W10: 410.90978 | X10: 398.16004 | Y10: 453.90696 | Z10: 485.29249 | AA10: 543.58133 | AB10: 554.95232 | AC10: 543.30056 | AD10: 496.30249 | AE10: 460.30439 | AF10: 428.71831 | AG10: =SUM(I10:AF10) -> 10384.128 | AH10: =AG10*G10 -> 20768.256
A11: 2027 | B11: 2 | C11: 1 | D11: 20 | E11: 4 | F11: 4 | G11: 0 | H11: 28 | I11: 464.80348 | J11: 430.29943 | K11: 416.03584 | L11: 402.39863 | M11: 374.41995 | N11: 356.30094 | O11: 372.65369 | P11: 472.79834 | Q11: 508.23663 | R11: 517.27539 | S11: 577.33896 | T11: 586.72147 | U11: 569.7741 | V11: 593.881 | W11: 635.86604 | X11: 599.36523 | Y11: 603.30136 | Z11: 563.81891 | AA11: 605.34394 | AB11: 629.94312 | AC11: 619.08739 | AD11: 578.2921 | AE11: 535.47439 | AF11: 494.13348 | AG11: =SUM(I11:AF11) -> 12507.564 | AH11: =AG11*D11 -> 250151.28 | AI11: =AH11+AH12+AH13+AH14 -> 347611.77
A12: 2027 | B12: 2 | C12: 2 | D12: 20 | E12: 4 | F12: 4 | G12: 0 | H12: 28 | I12: 474.95396 | J12: 451.6313 | K12: 436.41851 | L12: 420.86403 | M12: 407.92655 | N12: 389.55834 | O12: 401.05141 | P12: 439.77065 | Q12: 468.44381 | R12: 485.13724 | S12: 505.27601 | T12: 521.67435 | U12: 524.24476 | V12: 551.18878 | W12: 572.72536 | X12: 572.77971 | Y12: 554.60305 | Z12: 551.83332 | AA12: 627.31488 | AB12: 637.88385 | AC12: 619.84697 | AD12: 587.93815 | AE12: 552.39762 | AF12: 511.37977 | AG12: =SUM(I12:AF12) -> 12266.842 | AH12: =AG12*E12 -> 49067.37
A13: 2027 | B13: 2 | C13: 3 | D13: 20 | E13: 4 | F13: 4 | G13: 0 | H13: 28 | I13: 482.23522 | J13: 439.88364 | K13: 440.80625 | L13: 423.9914 | M13: 409.52076 | N13: 388.44893 | O13: 385.06777 | P13: 422.74393 | Q13: 445.40109 | R13: 464.11053 | S13: 482.12607 | T13: 507.58744 | U13: 521.47593 | V13: 552.3326 | W13: 566.96177 | X13: 561.77698 | Y13: 538.37654 | Z13: 533.03321 | AA13: 610.21777 | AB13: 640.67421 | AC13: 631.24282 | AD13: 594.90249 | AE13: 548.78511 | AF13: 506.57907 | AG13: =SUM(I13:AF13) -> 12098.282 | AH13: =AG13*F13 -> 48393.126
A14: 2027 | B14: 2 | C14: 4 | D14: 20 | E14: 4 | F14: 4 | G14: 0 | H14: 28 | AG14: =SUM(I14:AF14) -> 0 | AH14: =AG14*G14 -> 0
A15: 2027 | B15: 3 | C15: 1 | D15: 20 | E15: 4 | F15: 4 | G15: 3 | H15: 31 | I15: 585.85042 | J15: 559.88963 | K15: 541.76514 | L15: 521.47502 | M15: 502.45639 | N15: 481.26784 | O15: 499.45165 | P15: 562.65524 | Q15: 610.92868 | R15: 640.55351 | S15: 674.12493 | T15: 688.39578 | U15: 666.62622 | V15: 692.44879 | W15: 717.37722 | X15: 740.58463 | Y15: 702.61037 | Z15: 686.5763 | AA15: 737.44962 | AB15: 746.16356 | AC15: 732.46393 | AD15: 706.41507 | AE15: 667.02314 | AF15: 623.95189 | AG15: =SUM(I15:AF15) -> 15288.505 | AH15: =AG15*D15 -> 305770.1 | AI15: =AH15+AH16+AH17+AH18 -> 447413.48
A16: 2027 | B16: 3 | C16: 2 | D16: 20 | E16: 4 | F16: 4 | G16: 3 | H16: 31 | I16: 534.19003 | J16: 519.75075 | K16: 501.94118 | L16: 485.12772 | M16: 467.73389 | N16: 446.90224 | O16: 455.21084 | P16: 449.77448 | Q16: 494.74265 | R16: 535.91633 | S16: 557.42541 | T16: 570.86648 | U16: 577.37914 | V16: 602.60672 | W16: 614.4249 | X16: 614.446 | Y16: 586.85267 | Z16: 591.3478 | AA16: 660.93787 | AB16: 640.29616 | AC16: 649.67683 | AD16: 622.28821 | AE16: 592.12864 | AF16: 561.3233 | AG16: =SUM(I16:AF16) -> 13333.29 | AH16: =AG16*E16 -> 53333.161
A17: 2027 | B17: 3 | C17: 3 | D17: 20 | E17: 4 | F17: 4 | G17: 3 | H17: 31 | I17: 546.54741 | J17: 525.48276 | K17: 506.42761 | L17: 488.87374 | M17: 476.17456 | N17: 450.30201 | O17: 454.50388 | P17: 485.89883 | Q17: 509.76402 | R17: 522.8651 | S17: 540.55932 | T17: 568.21172 | U17: 577.28742 | V17: 601.96066 | W17: 618.80855 | X17: 617.36681 | Y17: 585.41047 | Z17: 579.84979 | AA17: 646.61618 | AB17: 670.37717 | AC17: 664.67189 | AD17: 634.03608 | AE17: 597.9204 | AF17: 560.6862 | AG17: =SUM(I17:AF17) -> 13430.603 | AH17: =AG17*F17 -> 53722.41
A18: 2027 | B18: 3 | C18: 4 | D18: 20 | E18: 4 | F18: 4 | G18: 3 | H18: 31 | I18: 490.37641 | J18: 477.04146 | K18: 465.30523 | L18: 453.71951 | M18: 443.56862 | N18: 421.24671 | O18: 426.43754 | P18: 456.21124 | Q18: 422.8655 | R18: 323.48381 | S18: 437.36103 | T18: 478.74387 | U18: 505.73151 | V18: 523.25057 | W18: 532.68905 | X18: 534.7393 | Y18: 499.8149 | Z18: 500.75139 | AA18: 480.62688 | AB18: 581.88489 | AC18: 574.45652 | AD18: 558.45591 | AE18: 502.53741 | AF18: 437.96975 | AG18: =SUM(I18:AF18) -> 11529.269 | AH18: =AG18*G18 -> 34587.807
A19: 2027 | B19: 4 | C19: 1 | D19: 22 | E19: 4 | F19: 4 | G19: 0 | H19: 30 | I19: 492.36352 | J19: 487.77719 | K19: 470.33858 | L19: 450.58409 | M19: 429.62057 | N19: 409.14882 | O19: 459.31228 | P19: 521.84246 | Q19: 558.52611 | R19: 590.92519 | S19: 619.61202 | T19: 638.23543 | U19: 607.8015 | V19: 627.03349 | W19: 677.89869 | X19: 684.22414 | Y19: 653.88651 | Z19: 635.71903 | AA19: 682.04886 | AB19: 681.56656 | AC19: 663.82531 | AD19: 634.21814 | AE19: 559.56918 | AF19: 532.63301 | AG19: =SUM(I19:AF19) -> 13768.711 | AH19: =AG19*D19 -> 302911.63 | AI19: =AH19+AH20+AH21+AH22 -> 409689.57
A20: 2027 | B20: 4 | C20: 2 | D20: 22 | E20: 4 | F20: 4 | G20: 0 | H20: 30 | I20: 518.25427 | J20: 498.52723 | K20: 483.6133 | L20: 471.26288 | M20: 453.75555 | N20: 425.14219 | O20: 449.23765 | P20: 495.03324 | Q20: 526.76317 | R20: 532.96266 | S20: 569.36744 | T20: 594.52418 | U20: 586.33666 | V20: 588.25368 | W20: 601.00769 | X20: 596.89337 | Y20: 565.0887 | Z20: 554.46846 | AA20: 638.30185 | AB20: 649.26588 | AC20: 631.05602 | AD20: 595.89562 | AE20: 557.08055 | AF20: 517.24531 | AG20: =SUM(I20:AF20) -> 13099.338 | AH20: =AG20*E20 -> 52397.35
A21: 2027 | B21: 4 | C21: 3 | D21: 22 | E21: 4 | F21: 4 | G21: 0 | H21: 30 | I21: 512.85128 | J21: 496.45804 | K21: 482.18586 | L21: 466.12526 | M21: 456.31436 | N21: 426.03638 | O21: 442.50397 | P21: 481.80235 | Q21: 504.71532 | R21: 527.76134 | S21: 545.45383 | T21: 567.78761 | U21: 509.21964 | V21: 633.80278 | W21: 633.58363 | X21: 634.07672 | Y21: 606.89423 | Z21: 608.7531 | AA21: 702.87823 | AB21: 729.77113 | AC21: 723.06356 | AD21: 685.08791 | AE21: 630.54683 | AF21: 587.47202 | AG21: =SUM(I21:AF21) -> 13595.145 | AH21: =AG21*F21 -> 54380.581
A22: 2027 | B22: 4 | C22: 4 | D22: 22 | E22: 4 | F22: 4 | G22: 0 | H22: 30 | I22: 442.34631 | J22: 440.77333 | K22: 419.15513 | L22: 401.74773 | M22: 389.08227 | N22: 374.49824 | O22: 404.33879 | P22: 424.28547 | Q22: 446.51647 | R22: 448.52818 | S22: 480.94577 | T22: 509.16156 | U22: 531.88127 | V22: 531.81043 | W22: 516.39711 | X22: 525.73716 | Y22: 498.28701 | Z22: 520.92221 | AA22: 592.06117 | AB22: 613.58982 | AC22: 583.19402 | AD22: 552.41306 | AE22: 505.39526 | AF22: 467.04214 | AG22: =SUM(I22:AF22) -> 11620.11 | AH22: =AG22*G22 -> 0
A23: 2027 | B23: 5 | C23: 1 | D23: 19 | E23: 4 | F23: 5 | G23: 3 | H23: 31 | I23: 393.32738 | J23: 369.00507 | K23: 362.17822 | L23: 358.24471 | M23: 345.26273 | N23: 331.60072 | O23: 400.51458 | P23: 444.09145 | Q23: 482.64225 | R23: 511.26968 | S23: 536.99872 | T23: 573.04677 | U23: 524.15687 | V23: 554.5936 | W23: 593.00015 | X23: 595.13041 | Y23: 565.14755 | Z23: 544.59451 | AA23: 601.85091 | AB23: 594.03566 | AC23: 575.64121 | AD23: 535.79423 | AE23: 468.99518 | AF23: 434.19539 | AG23: =SUM(I23:AF23) -> 11695.318 | AH23: =AG23*D23 -> 222211.04 | AI23: =AH23+AH24+AH25+AH26 -> 354470.57
A24: 2027 | B24: 5 | C24: 2 | D24: 19 | E24: 4 | F24: 5 | G24: 3 | H24: 31 | I24: 473.18905 | J24: 457.46319 | K24: 441.46777 | L24: 424.61658 | M24: 417.77822 | N24: 386.98076 | O24: 370.88851 | P24: 352.1609 | Q24: 489.41302 | R24: 517.79931 | S24: 436.20488 | T24: 525.57718 | U24: 518.69434 | V24: 458.28494 | W24: 519.96361 | X24: 537.03725 | Y24: 517.5978 | Z24: 530.54435 | AA24: 578.24011 | AB24: 582.31224 | AC24: 556.23071 | AD24: 514.42331 | AE24: 482.02945 | AF24: 450.19302 | AG24: =SUM(I24:AF24) -> 11539.091 | AH24: =AG24*E24 -> 46156.362
A25: 2027 | B25: 5 | C25: 3 | D25: 19 | E25: 4 | F25: 5 | G25: 3 | H25: 31 | I25: 406.32901 | J25: 391.63241 | K25: 382.71767 | L25: 376.412 | M25: 374.04738 | N25: 348.52039 | O25: 357.09341 | P25: 372.13423 | Q25: 421.08797 | R25: 420.03785 | S25: 433.9188 | T25: 452.4866 | U25: 372.37867 | V25: 472.46287 | W25: 463.7061 | X25: 422.41661 | Y25: 430.74103 | Z25: 467.17322 | AA25: 535.62764 | AB25: 511.53241 | AC25: 511.38524 | AD25: 471.59068 | AE25: 437.42334 | AF25: 410.04556 | AG25: =SUM(I25:AF25) -> 10242.901 | AH25: =AG25*F25 -> 51214.506
A26: 2027 | B26: 5 | C26: 4 | D26: 19 | E26: 4 | F26: 5 | G26: 3 | H26: 31 | I26: 466.64218 | J26: 452.29912 | K26: 435.00404 | L26: 423.59135 | M26: 412.89364 | N26: 381.80799 | O26: 363.27252 | P26: 456.2153 | Q26: 505.85267 | R26: 432.21451 | S26: 560.51119 | T26: 574.87049 | U26: 573.70051 | V26: 385.58875 | W26: 313.69474 | X26: 365.2604 | Y26: 547.11061 | Z26: 546.66104 | AA26: 606.8282 | AB26: 618.42506 | AC26: 600.66416 | AD26: 577.6221 | AE26: 531.03968 | AF26: 497.78199 | AG26: =SUM(I26:AF26) -> 11629.552 | AH26: =AG26*G26 -> 34888.657
A27: 2027 | B27: 6 | C27: 1 | D27: 21 | E27: 4 | F27: 4 | G27: 1 | H27: 30 | I27: 369.26719 | J27: 358.98767 | K27: 349.57611 | L27: 341.65247 | M27: 322.72996 | N27: 311.97467 | O27: 356.55703 | P27: 393.44212 | Q27: 433.30307 | R27: 446.90951 | S27: 469.19677 | T27: 493.80082 | U27: 480.96093 | V27: 462.30124 | W27: 503.70801 | X27: 521.255 | Y27: 507.60881 | Z27: 487.48378 | AA27: 529.35772 | AB27: 524.60162 | AC27: 533.29169 | AD27: 486.30721 | AE27: 420.9872 | AF27: 389.55166 | AG27: =SUM(I27:AF27) -> 10494.812 | AH27: =AG27*D27 -> 220391.06 | AI27: =AH27+AH28+AH29+AH30 -> 312959
A28: 2027 | B28: 6 | C28: 2 | D28: 21 | E28: 4 | F28: 4 | G28: 1 | H28: 30 | I28: 391.45169 | J28: 378.55881 | K28: 367.97306 | L28: 356.8223 | M28: 337.31717 | N28: 332.34877 | O28: 362.1551 | P28: 401.61982 | Q28: 434.97794 | R28: 451.28953 | S28: 459.74421 | T28: 463.85282 | U28: 454.47693 | V28: 466.46087 | W28: 468.37085 | X28: 470.43437 | Y28: 452.03265 | Z28: 474.49384 | AA28: 504.65228 | AB28: 531.77072 | AC28: 501.35229 | AD28: 464.08619 | AE28: 428.69322 | AF28: 398.09875 | AG28: =SUM(I28:AF28) -> 10353.034 | AH28: =AG28*E28 -> 41412.137
A29: 2027 | B29: 6 | C29: 3 | D29: 21 | E29: 4 | F29: 4 | G29: 1 | H29: 30 | I29: 378.66901 | J29: 354.04391 | K29: 339.63497 | L29: 351.70045 | M29: 324.76942 | N29: 296.83137 | O29: 351.27513 | P29: 379.39665 | Q29: 402.23288 | R29: 408.47516 | S29: 422.85492 | T29: 439.41342 | U29: 456.06992 | V29: 476.84624 | W29: 477.41751 | X29: 474.18379 | Y29: 454.40198 | Z29: 463.17536 | AA29: 541.23303 | AB29: 556.09232 | AC29: 543.12406 | AD29: 510.01955 | AE29: 469.82003 | AF29: 429.45372 | AG29: =SUM(I29:AF29) -> 10301.135 | AH29: =AG29*F29 -> 41204.539
A30: 2027 | B30: 6 | C30: 4 | D30: 21 | E30: 4 | F30: 4 | G30: 1 | H30: 30 | I30: 396.31035 | J30: 382.12048 | K30: 370.68709 | L30: 360.70237 | M30: 355.40569 | N30: 334.58114 | O30: 359.30401 | P30: 309.10376 | Q30: 389.52979 | R30: 434.38809 | S30: 454.2016 | T30: 473.94971 | U30: 459.90068 | V30: 467.66713 | W30: 450.08196 | X30: 444.78025 | Y30: 387.69381 | Z30: 391.38589 | AA30: 511.70553 | AB30: 508.33537 | AC30: 478.50194 | AD30: 445.53476 | AE30: 407.57271 | AF30: 377.82478 | AG30: =SUM(I30:AF30) -> 9951.2689 | AH30: =AG30*G30 -> 9951.2689
A31: 2027 | B31: 7 | C31: 1 | D31: 20 | E31: 5 | F31: 4 | G31: 2 | H31: 31 | I31: 382.01291 | J31: 358.22471 | K31: 349.6557 | L31: 345.68275 | M31: 349.21594 | N31: 342.10385 | O31: 386.95777 | P31: 423.01077 | Q31: 462.67568 | R31: 486.83812 | S31: 505.23321 | T31: 506.45729 | U31: 499.81133 | V31: 498.19088 | W31: 539.0002 | X31: 530.44769 | Y31: 515.60086 | Z31: 523.19137 | AA31: 573.41011 | AB31: 565.74089 | AC31: 551.0317 | AD31: 496.24046 | AE31: 445.66586 | AF31: 408.91291 | AG31: =SUM(I31:AF31) -> 11045.313 | AH31: =AG31*D31 -> 220906.26 | AI31: =AH31+AH32+AH33+AH34 -> 337449.61
A32: 2027 | B32: 7 | C32: 2 | D32: 20 | E32: 5 | F32: 4 | G32: 2 | H32: 31 | I32: 381.72208 | J32: 367.40777 | K32: 359.32739 | L32: 353.6589 | M32: 355.40413 | N32: 337.30268 | O32: 358.74448 | P32: 382.8844 | Q32: 406.17265 | R32: 418.8674 | S32: 450.90271 | T32: 461.30075 | U32: 464.18385 | V32: 441.81359 | W32: 509.70973 | X32: 505.60497 | Y32: 370.07534 | Z32: 528.44906 | AA32: 577.32664 | AB32: 599.27194 | AC32: 582.2822 | AD32: 531.24491 | AE32: 484.36212 | AF32: 447.07107 | AG32: =SUM(I32:AF32) -> 10675.091 | AH32: =AG32*E32 -> 53375.454
A33: 2027 | B33: 7 | C33: 3 | D33: 20 | E33: 5 | F33: 4 | G33: 2 | H33: 31 | I33: 417.40428 | J33: 402.23203 | K33: 388.26121 | L33: 373.45743 | M33: 375.38023 | N33: 360.32475 | O33: 385.90506 | P33: 409.78831 | Q33: 411.95244 | R33: 353.6637 | S33: 410.19484 | T33: 446.47124 | U33: 448.39491 | V33: 414.48245 | W33: 475.49581 | X33: 466.79519 | Y33: 449.56779 | Z33: 454.81464 | AA33: 530.46311 | AB33: 544.32495 | AC33: 518.64604 | AD33: 478.77314 | AE33: 443.16104 | AF33: 411.42309 | AG33: =SUM(I33:AF33) -> 10371.378 | AH33: =AG33*F33 -> 41485.511
A34: 2027 | B34: 7 | C34: 4 | D34: 20 | E34: 5 | F34: 4 | G34: 2 | H34: 31 | I34: 410.48313 | J34: 387.33037 | K34: 376.5636 | L34: 371.2433 | M34: 368.12052 | N34: 333.71732 | O34: 377.89893 | P34: 407.71784 | Q34: 437.47366 | R34: 446.40041 | S34: 452.23591 | T34: 477.18664 | U34: 500.38146 | V34: 484.55725 | W34: 478.3958 | X34: 489.01537 | Y34: 484.17873 | Z34: 500.3394 | AA34: 569.4402 | AB34: 571.69029 | AC34: 542.4707 | AD34: 491.05517 | AE34: 458.54457 | AF34: 424.75121 | AG34: =SUM(I34:AF34) -> 10841.192 | AH34: =AG34*G34 -> 21682.384
A35: 2027 | B35: 8 | C35: 1 | D35: 21 | E35: 3 | F35: 5 | G35: 2 | H35: 31 | I35: 423.07991 | J35: 396.06716 | K35: 385.17 | L35: 373.78027 | M35: 371.49821 | N35: 362.7457 | O35: 416.37852 | P35: 461.08759 | Q35: 498.61857 | R35: 500.78437 | S35: 547.75649 | T35: 576.38803 | U35: 560.84957 | V35: 586.6214 | W35: 610.48534 | X35: 584.91698 | Y35: 545.42315 | Z35: 559.17422 | AA35: 611.68028 | AB35: 617.96574 | AC35: 592.57708 | AD35: 546.04044 | AE35: 486.50004 | AF35: 452.45453 | AG35: =SUM(I35:AF35) -> 12068.044 | AH35: =AG35*D35 -> 253428.92 | AI35: =AH35+AH36+AH37+AH38 -> 367011.66
A36: 2027 | B36: 8 | C36: 2 | D36: 21 | E36: 3 | F36: 5 | G36: 2 | H36: 31 | I36: 416.32163 | J36: 415.62974 | K36: 402.17713 | L36: 391.31148 | M36: 389.53825 | N36: 363.81663 | O36: 394.15735 | P36: 439.66733 | Q36: 474.18547 | R36: 491.95041 | S36: 491.06488 | T36: 548.50881 | U36: 555.22967 | V36: 577.74425 | W36: 584.98729 | X36: 565.59273 | Y36: 539.16182 | Z36: 553.67837 | AA36: 636.89396 | AB36: 645.5186 | AC36: 615.25838 | AD36: 575.01804 | AE36: 536.65754 | AF36: 500.5968 | AG36: =SUM(I36:AF36) -> 12104.667 | AH36: =AG36*E36 -> 36314
A37: 2027 | B37: 8 | C37: 3 | D37: 21 | E37: 3 | F37: 5 | G37: 2 | H37: 31 | I37: 457.55458 | J37: 345.41268 | K37: 317.67818 | L37: 415.73502 | M37: 404.12904 | N37: 371.57367 | O37: 389.2757 | P37: 418.50451 | Q37: 437.72725 | R37: 446.53471 | S37: 454.95934 | T37: 479.42009 | U37: 480.47086 | V37: 483.40668 | W37: 483.77629 | X37: 487.74704 | Y37: 477.8677 | Z37: 488.2513 | AA37: 563.07241 | AB37: 586.55632 | AC37: 569.678 | AD37: 535.88178 | AE37: 492.04516 | AF37: 444.04243 | AG37: =SUM(I37:AF37) -> 11031.301 | AH37: =AG37*F37 -> 55156.504
A38: 2027 | B38: 8 | C38: 4 | D38: 21 | E38: 3 | F38: 5 | G38: 2 | H38: 31 | I38: 395.88696 | J38: 380.7792 | K38: 367.64133 | L38: 359.00609 | M38: 358.83412 | N38: 337.73849 | O38: 382.78558 | P38: 421.4331 | Q38: 446.71346 | R38: 451.09101 | S38: 488.13343 | T38: 517.4526 | U38: 518.72938 | V38: 542.51929 | W38: 544.1713 | X38: 531.84119 | Y38: 216.4699 | Z38: 454.62432 | AA38: 609.20399 | AB38: 631.13343 | AC38: 603.47148 | AD38: 551.24834 | AE38: 493.94411 | AF38: 451.2682 | AG38: =SUM(I38:AF38) -> 11056.12 | AH38: =AG38*G38 -> 22112.241
A39: 2027 | B39: 9 | C39: 1 | D39: 22 | E39: 4 | F39: 4 | G39: 0 | H39: 30 | I39: 420.63111 | J39: 402.81532 | K39: 388.72498 | L39: 378.55512 | M39: 377.97799 | N39: 370.91715 | O39: 415.76136 | P39: 474.84567 | Q39: 509.122 | R39: 549.77658 | S39: 580.94936 | T39: 599.06964 | U39: 564.67241 | V39: 571.83873 | W39: 608.4768 | X39: 626.53737 | Y39: 594.26855 | Z39: 589.74905 | AA39: 626.0304 | AB39: 625.71945 | AC39: 603.58167 | AD39: 557.02499 | AE39: 497.56405 | AF39: 457.95428 | AG39: =SUM(I39:AF39) -> 12392.564 | AH39: =AG39*D39 -> 272636.41 | AI39: =AH39+AH40+AH41+AH42 -> 355580.69
A40: 2027 | B40: 9 | C40: 2 | D40: 22 | E40: 4 | F40: 4 | G40: 0 | H40: 30 | I40: 407.85911 | J40: 394.63943 | K40: 381.89097 | L40: 371.83993 | M40: 366.69724 | N40: 343.18964 | O40: 373.25869 | P40: 418.7074 | Q40: 448.43004 | R40: 460.94162 | S40: 460.41436 | T40: 490.54964 | U40: 489.47475 | V40: 511.90236 | W40: 521.80566 | X40: 520.20351 | Y40: 493.86602 | Z40: 474.10018 | AA40: 577.67475 | AB40: 584.10884 | AC40: 553.4514 | AD40: 511.96349 | AE40: 476.88675 | AF40: 441.07134 | AG40: =SUM(I40:AF40) -> 11074.927 | AH40: =AG40*E40 -> 44299.709
...

Sheet 2028 Curvas
A1: CURVA HORARIA POR TIPO DE DÍA
A3: OFERTA BASICA MODALIDAD PAGUE LO CONTRATADO
A4: kwh
A5: PERIODO 01 DE ENERO 2028 A DICIEMBRE 31 DE 2028
A6: año | B6: mes | C6: tipo_dia | D6: Laborales | E6: Sabados | F6: Domingos | G6: Festivos | H6: Total Dias | I6: hora_0 | J6: hora_1 | K6: hora_2 | L6: hora_3 | M6: hora_4 | N6: hora_5 | O6: hora_6 | P6: hora_7 | Q6: hora_8 | R6: hora_9 | S6: hora_10 | T6: hora_11 | U6: hora_12 | V6: hora_13 | W6: hora_14 | X6: hora_15 | Y6: hora_16 | Z6: hora_17 | AA6: hora_18 | AB6: hora_19 | AC6: hora_20 | AD6: hora_21 | AE6: hora_22 | AF6: hora_23 | AG6: consumo_diario | AH6: consumo_mensual_tipo | AI6: TOTAL
A7: 2028 | B7: 1 | C7: 1 | D7: 20 | E7: 5 | F7: 5 | G7: 1 | H7: 31 | I7: 419.05572 | J7: 400.3349 | K7: 384.69686 | L7: 374.72334 | M7: 364.69044 | N7: 334.74355 | O7: 373.40885 | P7: 412.71301 | Q7: 470.61383 | R7: 487.47334 | S7: 527.96745 | T7: 538.41852 | U7: 529.25799 | V7: 538.80528 | W7: 577.37028 | X7: 562.85212 | Y7: 556.36804 | Z7: 561.32366 | AA7: 598.59669 | AB7: 597.25169 | AC7: 567.608 | AD7: 519.04712 | AE7: 476.40222 | AF7: 441.48439 | AG7: =SUM(I7:AF7) -> 11615.207 | AH7: =AG7*D7 -> 232304.15 | AI7: =AH7+AH8+AH9+AH10 -> 347383.32
A8: 2028 | B8: 1 | C8: 2 | D8: 20 | E8: 5 | F8: 5 | G8: 1 | H8: 31 | I8: 393.65342 | J8: 376.76405 | K8: 366.72462 | L8: 357.80898 | M8: 347.09178 | N8: 329.70904 | O8: 357.41279 | P8: 397.46836 | Q8: 424.04831 | R8: 436.30793 | S8: 459.62613 | T8: 471.54686 | U8: 473.77453 | V8: 486.45775 | W8: 480.14853 | X8: 446.12559 | Y8: 490.49695 | Z8: 522.12278 | AA8: 570.87471 | AB8: 561.34609 | AC8: 534.14817 | AD8: 474.95065 | AE8: 443.12298 | AF8: 417.05385 | AG8: =SUM(I8:AF8) -> 10618.785 | AH8: =AG8*E8 -> 53093.924
A9: 2028 | B9: 1 | C9: 3 | D9: 20 | E9: 5 | F9: 5 | G9: 1 | H9: 31 | I9: 393.69371 | J9: 377.59179 | K9: 365.98442 | L9: 356.54063 | M9: 348.59835 | N9: 322.503 | O9: 345.46291 | P9: 380.4699 | Q9: 365.52972 | R9: 379.78535 | S9: 423.35921 | T9: 437.96461 | U9: 446.12924 | V9: 458.31873 | W9: 472.98159 | X9: 469.58132 | Y9: 457.98145 | Z9: 488.67127 | AA9: 551.77979 | AB9: 559.05001 | AC9: 536.58977 | AD9: 489.62315 | AE9: 458.68598 | AF9: 421.63784 | AG9: =SUM(I9:AF9) -> 10308.514 | AH9: =F9*AG9 -> 51542.569
A10: 2028 | B10: 1 | C10: 4 | D10: 20 | E10: 5 | F10: 5 | G10: 1 | H10: 31 | I10: 399.01871 | J10: 389.43903 | K10: 377.75687 | L10: 370.26455 | M10: 361.6731 | N10: 340.34067 | O10: 367.34023 | P10: 398.71115 | Q10: 416.50414 | R10: 419.44863 | S10: 438.30042 | T10: 448.08682 | U10: 454.33377 | V10: 459.10849 | W10: 413.22688 | X10: 400.40524 | Y10: 456.46651 | Z10: 488.02902 | AA10: 546.64655 | AB10: 558.08166 | AC10: 546.36421 | AD10: 499.10111 | AE10: 462.90002 | AF10: 431.13583 | AG10: =SUM(I10:AF10) -> 10442.684 | AH10: =AG10*G10 -> 10442.684
A11: 2028 | B11: 2 | C11: 1 | D11: 21 | E11: 4 | F11: 4 | G11: 0 | H11: 29 | I11: 466.5863 | J11: 431.94991 | K11: 417.63161 | L11: 403.94209 | M11: 375.85609 | N11: 357.66759 | O11: 374.08306 | P11: 474.61184 | Q11: 510.18605 | R11: 519.25948 | S11: 579.55343 | T11: 588.97193 | U11: 571.95956 | V11: 596.15892 | W11: 638.305 | X11: 601.66419 | Y11: 605.61542 | Z11: 565.98152 | AA11: 607.66583 | AB11: 632.35937 | AC11: 621.46199 | AD11: 580.51022 | AE11: 537.52829 | AF11: 496.0288 | AG11: =SUM(I11:AF11) -> 12555.539 | AH11: =AG11*D11 -> 263666.31 | AI11: =AH11+AH12+AH13+AH14 -> 360614.2
A12: 2028 | B12: 2 | C12: 2 | D12: 21 | E12: 4 | F12: 4 | G12: 0 | H12: 29 | I12: 472.76835 | J12: 449.55301 | K12: 434.41022 | L12: 418.92732 | M12: 406.04938 | N12: 387.76569 | O12: 399.20588 | P12: 437.74694 | Q12: 466.28815 | R12: 482.90477 | S12: 502.95086 | T12: 519.27374 | U12: 521.83233 | V12: 548.65235 | W12: 570.08982 | X12: 570.14393 | Y12: 552.05091 | Z12: 549.29393 | AA12: 624.42814 | AB12: 634.94847 | AC12: 616.99459 | AD12: 585.23261 | AE12: 549.85563 | AF12: 509.02653 | AG12: =SUM(I12:AF12) -> 12210.394 | AH12: =AG12*E12 -> 48841.574
A13: 2028 | B13: 2 | C13: 3 | D13: 21 | E13: 4 | F13: 4 | G13: 0 | H13: 29 | I13: 479.3772 | J13: 437.27662 | K13: 438.19376 | L13: 421.47857 | M13: 407.09369 | N13: 386.14674 | O13: 382.78562 | P13: 420.23849 | Q13: 442.76137 | R13: 461.35993 | S13: 479.26869 | T13: 504.57916 | U13: 518.38534 | V13: 549.05914 | W13: 563.60161 | X13: 558.44754 | Y13: 535.18579 | Z13: 529.87413 | AA13: 606.60124 | AB13: 636.87718 | AC13: 627.50169 | AD13: 591.37673 | AE13: 545.53267 | AF13: 503.57677 | AG13: =SUM(I13:AF13) -> 12026.58 | AH13: =F13*AG13 -> 48106.319
A14: 2028 | B14: 2 | C14: 4 | D14: 21 | E14: 4 | F14: 4 | G14: 0 | H14: 29 | AG14: =SUM(I14:AF14) -> 0 | AH14: =AG14*G14 -> 0
A15: 2028 | B15: 3 | C15: 1 | D15: 22 | E15: 4 | F15: 4 | G15: 1 | H15: 31 | I15: 571.36065 | J15: 546.04195 | K15: 528.36573 | L15: 508.57744 | M15: 490.0292 | N15: 469.36471 | O15: 487.09877 | P15: 548.73916 | Q15: 595.81866 | R15: 624.71078 | S15: 657.45188 | T15: 671.36978 | U15: 650.13864 | V15: 675.32254 | W15: 699.63442 | X15: 722.26784 | Y15: 685.23279 | Z15: 669.5953 | AA15: 719.21037 | AB15: 727.70879 | AC15: 714.34799 | AD15: 688.9434 | AE15: 650.52574 | AF15: 608.51976 | AG15: =SUM(I15:AF15) -> 14910.376 | AH15: =AG15*D15 -> 328028.28 | AI15: =AH15+AH16+AH17+AH18 -> 445383.98
A16: 2028 | B16: 3 | C16: 2 | D16: 22 | E16: 4 | F16: 4 | G16: 1 | H16: 31 | I16: 528.38799 | J16: 514.10554 | K16: 496.48941 | L16: 479.85856 | M16: 462.65366 | N16: 442.04827 | O16: 450.26663 | P16: 444.88931 | Q16: 489.36906 | R16: 530.09554 | S16: 551.371 | T16: 564.66608 | U16: 571.108 | V16: 596.06158 | W16: 607.7514 | X16: 607.77227 | Y16: 580.47864 | Z16: 584.92495 | AA16: 653.75917 | AB16: 633.34166 | AC16: 642.62045 | AD16: 615.5293 | AE16: 585.69731 | AF16: 555.22655 | AG16: =SUM(I16:AF16) -> 13188.472 | AH16: =AG16*E16 -> 52753.889
A17: 2028 | B17: 3 | C17: 3 | D17: 22 | E17: 4 | F17: 4 | G17: 1 | H17: 31 | I17: 539.24633 | J17: 518.46308 | K17: 499.66248 | L17: 482.3431 | M17: 469.81357 | N17: 444.28663 | O17: 448.43237 | P17: 479.40793 | Q17: 502.95432 | R17: 515.88038 | S17: 533.33823 | T17: 560.62124 | U17: 569.5757 | V17: 593.91934 | W17: 610.54217 | X17: 609.11969 | Y17: 577.59024 | Z17: 572.10385 | AA17: 637.97833 | AB17: 661.4219 | AC17: 655.79284 | AD17: 625.56628 | AE17: 589.93305 | AF17: 553.19625 | AG17: =SUM(I17:AF17) -> 13251.189 | AH17: =F17*AG17 -> 53004.757
A18: 2028 | B18: 3 | C18: 4 | D18: 22 | E18: 4 | F18: 4 | G18: 1 | H18: 31 | I18: 493.25942 | J18: 479.84607 | K18: 468.04084 | L18: 456.387 | M18: 446.17644 | N18: 423.72329 | O18: 428.94464 | P18: 458.89338 | Q18: 425.35159 | R18: 325.38563 | S18: 439.93235 | T18: 481.55848 | U18: 508.70479 | V18: 526.32684 | W18: 535.82082 | X18: 537.88312 | Y18: 502.75339 | Z18: 503.69539 | AA18: 483.45257 | AB18: 585.30589 | AC18: 577.83384 | AD18: 561.73917 | AE18: 505.49191 | AF18: 440.54465 | AG18: =SUM(I18:AF18) -> 11597.051 | AH18: =AG18*G18 -> 11597.051
A19: 2028 | B19: 4 | C19: 1 | D19: 18 | E19: 5 | F19: 5 | G19: 2 | H19: 30 | I19: 481.74112 | J19: 477.25373 | K19: 460.19135 | L19: 440.86304 | M19: 420.35181 | N19: 400.32171 | O19: 449.40294 | P19: 510.58407 | Q19: 546.4763 | R19: 578.17639 | S19: 606.24432 | T19: 624.46593 | U19: 594.6886 | V19: 613.50567 | W19: 663.2735 | X19: 669.46247 | Y19: 639.77936 | Z19: 622.00383 | AA19: 667.33412 | AB19: 666.86223 | AC19: 649.50373 | AD19: 620.53532 | AE19: 547.49686 | AF19: 521.14182 | AG19: =SUM(I19:AF19) -> 13471.66 | AH19: =AG19*D19 -> 242489.88 | AI19: =AH19+AH20+AH21+AH22 -> 393926.38
A20: 2028 | B20: 4 | C20: 2 | D20: 18 | E20: 5 | F20: 5 | G20: 2 | H20: 30 | I20: 502.38156 | J20: 483.25871 | K20: 468.80155 | L20: 456.82939 | M20: 439.85827 | N20: 412.12125 | O20: 435.47874 | P20: 479.87173 | Q20: 510.62986 | R20: 516.63948 | S20: 551.92928 | T20: 576.31554 | U20: 568.37878 | V20: 570.23709 | W20: 582.60047 | X20: 578.61217 | Y20: 547.78159 | Z20: 537.48662 | AA20: 618.75241 | AB20: 629.38065 | AC20: 611.7285 | AD20: 577.64498 | AE20: 540.0187 | AF20: 501.4035 | AG20: =SUM(I20:AF20) -> 12698.141 | AH20: =AG20*E20 -> 63490.704
A21: 2028 | B21: 4 | C21: 3 | D21: 18 | E21: 5 | F21: 5 | G21: 2 | H21: 30 | I21: 489.55429 | J21: 473.90574 | K21: 460.2819 | L21: 444.95087 | M21: 435.58565 | N21: 406.68308 | O21: 422.40261 | P21: 459.91581 | Q21: 481.78792 | R21: 503.78704 | S21: 520.67583 | T21: 541.99507 | U21: 486.08763 | V21: 605.01141 | W21: 604.80221 | X21: 605.2729 | Y21: 579.32521 | Z21: 581.09964 | AA21: 670.94901 | AB21: 696.62026 | AC21: 690.21739 | AD21: 653.96683 | AE21: 601.90336 | AF21: 560.78528 | AG21: =SUM(I21:AF21) -> 12977.567 | AH21: =F21*AG21 -> 64887.835
A22: 2028 | B22: 4 | C22: 4 | D22: 18 | E22: 5 | F22: 5 | G22: 2 | H22: 30 | I22: 438.87725 | J22: 437.31661 | K22: 415.86795 | L22: 398.59706 | M22: 386.03093 | N22: 371.56127 | O22: 401.1678 | P22: 420.95805 | Q22: 443.0147 | R22: 445.01064 | S22: 477.17399 | T22: 505.1685 | U22: 527.71004 | V22: 527.63975 | W22: 512.34731 | X22: 521.61412 | Y22: 494.37924 | Z22: 516.83693 | AA22: 587.41798 | AB22: 608.7778 | AC22: 578.62037 | AD22: 548.08081 | AE22: 501.43174 | AF22: 463.3794 | AG22: =SUM(I22:AF22) -> 11528.98 | AH22: =AG22*G22 -> 23057.96
A23: 2028 | B23: 5 | C23: 1 | D23: 21 | E23: 4 | F23: 4 | G23: 2 | H23: 31 | I23: 392.15669 | J23: 367.90677 | K23: 361.10024 | L23: 357.17844 | M23: 344.2351 | N23: 330.61375 | O23: 399.3225 | P23: 442.76967 | Q23: 481.20573 | R23: 509.74795 | S23: 535.40041 | T23: 571.34117 | U23: 522.59678 | V23: 552.94292 | W23: 591.23516 | X23: 593.35908 | Y23: 563.46545 | Z23: 542.97359 | AA23: 600.05958 | AB23: 592.26758 | AC23: 573.92789 | AD23: 534.1995 | AE23: 467.59927 | AF23: 432.90307 | AG23: =SUM(I23:AF23) -> 11660.508 | AH23: =AG23*D23 -> 244870.67 | AI23: =AH23+AH24+AH25+AH26 -> 354742.94
A24: 2028 | B24: 5 | C24: 2 | D24: 21 | E24: 4 | F24: 4 | G24: 2 | H24: 31 | I24: 469.29427 | J24: 453.69785 | K24: 437.83409 | L24: 421.1216 | M24: 414.33953 | N24: 383.79556 | O24: 367.83576 | P24: 349.26229 | Q24: 485.38471 | R24: 513.53735 | S24: 432.61452 | T24: 521.25121 | U24: 514.42501 | V24: 454.51284 | W24: 515.68384 | X24: 532.61695 | Y24: 513.33749 | Z24: 526.17748 | AA24: 573.48067 | AB24: 577.51928 | AC24: 551.65242 | AD24: 510.18914 | AE24: 478.06191 | AF24: 446.48752 | AG24: =SUM(I24:AF24) -> 11444.113 | AH24: =AG24*E24 -> 45776.453
A25: 2028 | B25: 5 | C25: 3 | D25: 21 | E25: 4 | F25: 4 | G25: 2 | H25: 31 | I25: 409.48794 | J25: 394.67709 | K25: 385.69304 | L25: 379.33835 | M25: 376.95534 | N25: 351.2299 | O25: 359.86957 | P25: 375.02732 | Q25: 424.36164 | R25: 423.30336 | S25: 437.29223 | T25: 456.00438 | U25: 375.27366 | V25: 476.13595 | W25: 467.31111 | X25: 425.70062 | Y25: 434.08975 | Z25: 470.80518 | AA25: 539.79179 | AB25: 515.50922 | AC25: 515.36092 | AD25: 475.25698 | AE25: 440.82401 | AF25: 413.23339 | AG25: =SUM(I25:AF25) -> 10322.533 | AH25: =F25*AG25 -> 41290.131
A26: 2028 | B26: 5 | C26: 4 | D26: 21 | E26: 4 | F26: 4 | G26: 2 | H26: 31 | I26: 457.54528 | J26: 443.48184 | K26: 426.52391 | L26: 415.3337 | M26: 404.84454 | N26: 374.36489 | O26: 356.19075 | P26: 447.32167 | Q26: 495.99139 | R26: 423.78876 | S26: 549.58437 | T26: 563.66375 | U26: 562.51658 | V26: 378.07194 | W26: 307.57945 | X26: 358.13988 | Y26: 536.44504 | Z26: 536.00423 | AA26: 594.99847 | AB26: 606.36925 | AC26: 588.95459 | AD26: 566.36173 | AE26: 520.68739 | AF26: 488.07804 | AG26: =SUM(I26:AF26) -> 11402.841 | AH26: =AG26*G26 -> 22805.683
A27: 2028 | B27: 6 | C27: 1 | D27: 20 | E27: 4 | F27: 4 | G27: 2 | H27: 30 | I27: 370.98601 | J27: 360.65864 | K27: 351.20327 | L27: 343.24275 | M27: 324.23217 | N27: 313.42682 | O27: 358.21669 | P27: 395.27347 | Q27: 435.31996 | R27: 448.98973 | S27: 471.38073 | T27: 496.09931 | U27: 483.19965 | V27: 464.4531 | W27: 506.05261 | X27: 523.68128 | Y27: 509.97156 | Z27: 489.75287 | AA27: 531.82171 | AB27: 527.04347 | AC27: 535.77399 | AD27: 488.57081 | AE27: 422.94677 | AF27: 391.3649 | AG27: =SUM(I27:AF27) -> 10543.662 | AH27: =AG27*D27 -> 210873.25 | AI27: =AH27+AH28+AH29+AH30 -> 313177.48
A28: 2028 | B28: 6 | C28: 2 | D28: 20 | E28: 4 | F28: 4 | G28: 2 | H28: 30 | I28: 391.14739 | J28: 378.26454 | K28: 367.68702 | L28: 356.54492 | M28: 337.05496 | N28: 332.09041 | O28: 361.87357 | P28: 401.30762 | Q28: 434.63981 | R28: 450.93872 | S28: 459.38683 | T28: 463.49224 | U28: 454.12364 | V28: 466.09827 | W28: 468.00676 | X28: 470.06867 | Y28: 451.68126 | Z28: 474.12499 | AA28: 504.25999 | AB28: 531.35734 | AC28: 500.96257 | AD28: 463.72543 | AE28: 428.35998 | AF28: 397.78928 | AG28: =SUM(I28:AF28) -> 10344.986 | AH28: =AG28*E28 -> 41379.945
A29: 2028 | B29: 6 | C29: 3 | D29: 20 | E29: 4 | F29: 4 | G29: 2 | H29: 30 | I29: 376.07457 | J29: 351.61819 | K29: 337.30797 | L29: 349.29079 | M29: 322.54428 | N29: 294.79764 | O29: 348.86838 | P29: 376.79723 | Q29: 399.477 | R29: 405.67651 | S29: 419.95774 | T29: 436.4028 | U29: 452.94518 | V29: 473.57915 | W29: 474.1465 | X29: 470.93494 | Y29: 451.28866 | Z29: 460.00193 | AA29: 537.52479 | AB29: 552.28227 | AC29: 539.40286 | AD29: 506.52517 | AE29: 466.60108 | AF29: 426.51133 | AG29: =SUM(I29:AF29) -> 10230.557 | AH29: =F29*AG29 -> 40922.228
A30: 2028 | B30: 6 | C30: 4 | D30: 20 | E30: 4 | F30: 4 | G30: 2 | H30: 30 | I30: 398.29203 | J30: 384.0312 | K30: 372.54065 | L30: 362.506 | M30: 357.18284 | N30: 336.25416 | O30: 361.10065 | P30: 310.64938 | Q30: 391.47757 | R30: 436.56017 | S30: 456.47275 | T30: 476.31961 | U30: 462.20034 | V30: 470.00562 | W30: 452.33251 | X30: 447.00429 | Y30: 389.63241 | Z30: 393.34295 | AA30: 514.26422 | AB30: 510.87722 | AC30: 480.8946 | AD30: 447.76258 | AE30: 409.6107 | AF30: 379.71403 | AG30: =SUM(I30:AF30) -> 10001.028 | AH30: =AG30*G30 -> 20002.057
A31: 2028 | B31: 7 | C31: 1 | D31: 19 | E31: 5 | F31: 5 | G31: 2 | H31: 31 | I31: 380.06644 | J31: 356.39945 | K31: 347.8741 | L31: 343.9214 | M31: 347.43658 | N31: 340.36073 | O31: 384.9861 | P31: 420.8554 | Q31: 460.3182 | R31: 484.35753 | S31: 502.6589 | T31: 503.87674 | U31: 497.26464 | V31: 495.65245 | W31: 536.25384 | X31: 527.7449 | Y31: 512.97372 | Z31: 520.52555 | AA31: 570.48841 | AB31: 562.85827 | AC31: 548.22403 | AD31: 493.71197 | AE31: 443.39506 | AF31: 406.82938 | AG31: =SUM(I31:AF31) -> 10989.034 | AH31: =AG31*D31 -> 208791.64 | AI31: =AH31+AH32+AH33+AH34 -> 334770.99
A32: 2028 | B32: 7 | C32: 2 | D32: 19 | E32: 5 | F32: 5 | G32: 2 | H32: 31 | I32: 378.54243 | J32: 364.34735 | K32: 356.33428 | L32: 350.71301 | M32: 352.44369 | N32: 334.49303 | O32: 355.75623 | P32: 379.69507 | Q32: 402.78933 | R32: 415.37834 | S32: 447.1468 | T32: 457.45822 | U32: 460.31731 | V32: 438.13339 | W32: 505.46397 | X32: 501.3934 | Y32: 366.9927 | Z32: 524.04721 | AA32: 572.51765 | AB32: 594.28015 | AC32: 577.43193 | AD32: 526.81977 | AE32: 480.3275 | AF32: 443.34708 | AG32: =SUM(I32:AF32) -> 10586.17 | AH32: =AG32*E32 -> 52930.849
A33: 2028 | B33: 7 | C33: 3 | D33: 19 | E33: 5 | F33: 5 | G33: 2 | H33: 31 | I33: 415.14445 | J33: 400.05434 | K33: 386.15916 | L33: 371.43553 | M33: 373.34792 | N33: 358.37395 | O33: 383.81576 | P33: 407.56972 | Q33: 409.72213 | R33: 351.74896 | S33: 407.97405 | T33: 444.05404 | U33: 445.96729 | V33: 412.23844 | W33: 472.92147 | X33: 464.26795 | Y33: 447.13383 | Z33: 452.35226 | AA33: 527.59118 | AB33: 541.37797 | AC33: 515.83808 | AD33: 476.18106 | AE33: 440.76176 | AF33: 409.19564 | AG33: =SUM(I33:AF33) -> 10315.227 | AH33: =F33*AG33 -> 51576.135
A34: 2028 | B34: 7 | C34: 4 | D34: 19 | E34: 5 | F34: 5 | G34: 2 | H34: 31 | I34: 406.50709 | J34: 383.57859 | K34: 372.91611 | L34: 367.64735 | M34: 364.55481 | N34: 330.48485 | O34: 374.23851 | P34: 403.76858 | Q34: 433.23618 | R34: 442.07646 | S34: 447.85544 | T34: 472.56449 | U34: 495.53464 | V34: 479.86371 | W34: 473.76194 | X34: 484.27864 | Y34: 479.48886 | Z34: 495.49299 | AA34: 563.92446 | AB34: 566.15275 | AC34: 537.2162 | AD34: 486.29869 | AE34: 454.10299 | AF34: 420.63696 | AG34: =SUM(I34:AF34) -> 10736.181 | AH34: =AG34*G34 -> 21472.363
