Workbook

Sheet A2P1 
B1: CENTRALES ELECTRICAS DE NARIÑO S.A. E.S.P.
B2: CURVA DE ENERGIA DE REFERENCIA PARA OFERTAR MENSUAL
B3: ANEXO 2 PRODUCTO 1 - CUADRO DE CANTIDADES DE ENERGÍA
B4: AÑO 2027 MWh
B7: Franja | C7: Hora | D7: AÑO 2027 MWh
D8: 46388 | E8: 46419 | F8: 46447 | G8: 46478 | H8: 46508 | I8: 46539 | J8: 46569 | K8: 46600 | L8: 46631 | M8: 46661 | N8: 46692 | O8: 46722
B9: Baja | C9: 1 | D9: 41.5 | E9: 41.5 | F9: 41.5 | G9: 41.5 | H9: 41.5 | I9: 41.5 | J9: 41.5 | K9: 41.5 | L9: 41.5 | M9: 41.5 | N9: 41.5 | O9: 41.5
C10: 2 | D10: 41.5 | E10: 41.5 | F10: 41.5 | G10: 41.5 | H10: 41.5 | I10: 41.5 | J10: 41.5 | K10: 41.5 | L10: 41.5 | M10: 41.5 | N10: 41.5 | O10: 41.5
C11: 3 | D11: 41.5 | E11: 41.5 | F11: 41.5 | G11: 41.5 | H11: 41.5 | I11: 41.5 | J11: 41.5 | K11: 41.5 | L11: 41.5 | M11: 41.5 | N11: 41.5 | O11: 41.5
C12: 4 | D12: 41.5 | E12: 41.5 | F12: 41.5 | G12: 41.5 | H12: 41.5 | I12: 41.5 | J12: 41.5 | K12: 41.5 | L12: 41.5 | M12: 41.5 | N12: 41.5 | O12: 41.5
B13: Media | C13: 5 | D13: 41.5 | E13: 41.5 | F13: 41.5 | G13: 41.5 | H13: 41.5 | I13: 41.5 | J13: 41.5 | K13: 41.5 | L13: 41.5 | M13: 41.5 | N13: 41.5 | O13: 41.5
C14: 6 | D14: 41.5 | E14: 41.5 | F14: 41.5 | G14: 41.5 | H14: 41.5 | I14: 41.5 | J14: 41.5 | K14: 41.5 | L14: 41.5 | M14: 41.5 | N14: 41.5 | O14: 41.5
C15: 7 | D15: 41.5 | E15: 41.5 | F15: 41.5 | G15: 41.5 | H15: 41.5 | I15: 41.5 | J15: 41.5 | K15: 41.5 | L15: 41.5 | M15: 41.5 | N15: 41.5 | O15: 41.5
C16: 8 | D16: 41.5 | E16: 41.5 | F16: 41.5 | G16: 41.5 | H16: 41.5 | I16: 41.5 | J16: 41.5 | K16: 41.5 | L16: 41.5 | M16: 41.5 | N16: 41.5 | O16: 41.5
C17: 9 | D17: 41.5 | E17: 41.5 | F17: 41.5 | G17: 41.5 | H17: 41.5 | I17: 41.5 | J17: 41.5 | K17: 41.5 | L17: 41.5 | M17: 41.5 | N17: 41.5 | O17: 41.5
B18: Alta | C18: 10 | D18: 41.5 | E18: 41.5 | F18: 41.5 | G18: 41.5 | H18: 41.5 | I18: 41.5 | J18: 41.5 | K18: 41.5 | L18: 41.5 | M18: 41.5 | N18: 41.5 | O18: 41.5
C19: 11 | D19: 41.5 | E19: 41.5 | F19: 41.5 | G19: 41.5 | H19: 41.5 | I19: 41.5 | J19: 41.5 | K19: 41.5 | L19: 41.5 | M19: 41.5 | N19: 41.5 | O19: 41.5
C20: 12 | D20: 41.5 | E20: 41.5 | F20: 41.5 | G20: 41.5 | H20: 41.5 | I20: 41.5 | J20: 41.5 | K20: 41.5 | L20: 41.5 | M20: 41.5 | N20: 41.5 | O20: 41.5
B21: Media | C21: 13 | D21: 41.5 | E21: 41.5 | F21: 41.5 | G21: 41.5 | H21: 41.5 | I21: 41.5 | J21: 41.5 | K21: 41.5 | L21: 41.5 | M21: 41.5 | N21: 41.5 | O21: 41.5
C22: 14 | D22: 41.5 | E22: 41.5 | F22: 41.5 | G22: 41.5 | H22: 41.5 | I22: 41.5 | J22: 41.5 | K22: 41.5 | L22: 41.5 | M22: 41.5 | N22: 41.5 | O22: 41.5
C23: 15 | D23: 41.5 | E23: 41.5 | F23: 41.5 | G23: 41.5 | H23: 41.5 | I23: 41.5 | J23: 41.5 | K23: 41.5 | L23: 41.5 | M23: 41.5 | N23: 41.5 | O23: 41.5
C24: 16 | D24: 41.5 | E24: 41.5 | F24: 41.5 | G24: 41.5 | H24: 41.5 | I24: 41.5 | J24: 41.5 | K24: 41.5 | L24: 41.5 | M24: 41.5 | N24: 41.5 | O24: 41.5
C25: 17 | D25: 41.5 | E25: 41.5 | F25: 41.5 | G25: 41.5 | H25: 41.5 | I25: 41.5 | J25: 41.5 | K25: 41.5 | L25: 41.5 | M25: 41.5 | N25: 41.5 | O25: 41.5
C26: 18 | D26: 41.5 | E26: 41.5 | F26: 41.5 | G26: 41.5 | H26: 41.5 | I26: 41.5 | J26: 41.5 | K26: 41.5 | L26: 41.5 | M26: 41.5 | N26: 41.5 | O26: 41.5
B27: Alta | C27: 19 | D27: 41.5 | E27: 41.5 | F27: 41.5 | G27: 41.5 | H27: 41.5 | I27: 41.5 | J27: 41.5 | K27: 41.5 | L27: 41.5 | M27: 41.5 | N27: 41.5 | O27: 41.5
C28: 20 | D28: 41.5 | E28: 41.5 | F28: 41.5 | G28: 41.5 | H28: 41.5 | I28: 41.5 | J28: 41.5 | K28: 41.5 | L28: 41.5 | M28: 41.5 | N28: 41.5 | O28: 41.5
C29: 21 | D29: 41.5 | E29: 41.5 | F29: 41.5 | G29: 41.5 | H29: 41.5 | I29: 41.5 | J29: 41.5 | K29: 41.5 | L29: 41.5 | M29: 41.5 | N29: 41.5 | O29: 41.5
B30: Media | C30: 22 | D30: 41.5 | E30: 41.5 | F30: 41.5 | G30: 41.5 | H30: 41.5 | I30: 41.5 | J30: 41.5 | K30: 41.5 | L30: 41.5 | M30: 41.5 | N30: 41.5 | O30: 41.5
C31: 23 | D31: 41.5 | E31: 41.5 | F31: 41.5 | G31: 41.5 | H31: 41.5 | I31: 41.5 | J31: 41.5 | K31: 41.5 | L31: 41.5 | M31: 41.5 | N31: 41.5 | O31: 41.5
B32: Baja | C32: 24 | D32: 41.5 | E32: 41.5 | F32: 41.5 | G32: 41.5 | H32: 41.5 | I32: 41.5 | J32: 41.5 | K32: 41.5 | L32: 41.5 | M32: 41.5 | N32: 41.5 | O32: 41.5
B33: Días | D33: 31 | E33: 28 | F33: 31 | G33: 30 | H33: 31 | I33: 30 | J33: 31 | K33: 31 | L33: 30 | M33: 31 | N33: 30 | O33: 31
B34: Resúmen Año 2027 MWh
B35: Baja | D35: =(SUM(D9:D12)+D32) -> 207.5 | E35: =(SUM(E9:E12)+E32) -> 207.5 | F35: =(SUM(F9:F12)+F32) -> 207.5 | G35: =(SUM(G9:G12)+G32) -> 207.5 | H35: =(SUM(H9:H12)+H32) -> 207.5 | I35: =(SUM(I9:I12)+I32) -> 207.5 | J35: =(SUM(J9:J12)+J32) -> 207.5 | K35: =(SUM(K9:K12)+K32) -> 207.5 | ... O35: =(SUM(O9:O12)+O32) -> 207.5
B36: Media | D36: =(SUM(D13:D17)+SUM(D21:D26)+D30+D31) -> 539.5 | E36: =(SUM(E13:E17)+SUM(E21:E26)+E30+E31) -> 539.5 | F36: =(SUM(F13:F17)+SUM(F21:F26)+F30+F31) -> 539.5 | G36: =(SUM(G13:G17)+SUM(G21:G26)+G30+G31) -> 539.5 | H36: =(SUM(H13:H17)+SUM(H21:H26)+H30+H31) -> 539.5 | I36: =(SUM(I13:I17)+SUM(I21:I26)+I30+I31) -> 539.5 | J36: =(SUM(J13:J17)+SUM(J21:J26)+J30+J31) -> 539.5 | K36: =(SUM(K13:K17)+SUM(K21:K26)+K30+K31) -> 539.5 | ... O36: =(SUM(O13:O17)+SUM(O21:O26)+O30+O31) -> 539.5
B37: Alta | D37: =(SUM(D18:D20)+SUM(D27:D29)) -> 249 | E37: =(SUM(E18:E20)+SUM(E27:E29)) -> 249 | F37: =(SUM(F18:F20)+SUM(F27:F29)) -> 249 | G37: =(SUM(G18:G20)+SUM(G27:G29)) -> 249 | H37: =(SUM(H18:H20)+SUM(H27:H29)) -> 249 | I37: =(SUM(I18:I20)+SUM(I27:I29)) -> 249 | J37: =(SUM(J18:J20)+SUM(J27:J29)) -> 249 | K37: =(SUM(K18:K20)+SUM(K27:K29)) -> 249 | ... O37: =(SUM(O18:O20)+SUM(O27:O29)) -> 249
B38: Subtotal Baja | D38: =D35*D33 -> 6432.5 | E38: =E35*E33 -> 5810 | F38: =F35*F33 -> 6432.5 | G38: =G35*G33 -> 6225 | H38: =H35*H33 -> 6432.5 | I38: =I35*I33 -> 6225 | J38: =J35*J33 -> 6432.5 | K38: =K35*K33 -> 6432.5 | ... O38: =O35*O33 -> 6432.5
B39: Subtotal Media | D39: =D33*D36 -> 16724.5 | E39: =E33*E36 -> 15106 | F39: =F33*F36 -> 16724.5 | G39: =G33*G36 -> 16185 | H39: =H33*H36 -> 16724.5 | I39: =I33*I36 -> 16185 | J39: =J33*J36 -> 16724.5 | K39: =K33*K36 -> 16724.5 | ... O39: =O33*O36 -> 16724.5
B40: Subtotal Alta | D40: =D33*D37 -> 7719 | E40: =E33*E37 -> 6972 | F40: =F33*F37 -> 7719 | G40: =G33*G37 -> 7470 | H40: =H33*H37 -> 7719 | I40: =I33*I37 -> 7470 | J40: =J33*J37 -> 7719 | K40: =K33*K37 -> 7719 | ... O40: =O33*O37 -> 7719
B41: Total | D41: =D40+D39+D38 -> 30876 | E41: =E40+E39+E38 -> 27888 | F41: =F40+F39+F38 -> 30876 | G41: =G40+G39+G38 -> 29880 | H41: =H40+H39+H38 -> 30876 | I41: =I40+I39+I38 -> 29880 | J41: =J40+J39+J38 -> 30876 | K41: =K40+K39+K38 -> 30876 | ... O41: =O40+O39+O38 -> 30876 | P41: =SUM(D41:O41) -> 363540
D42: 46388 | E42: 46419 | F42: 46447 | G42: 46478 | H42: 46508 | I42: 46539 | J42: 46569 | K42: 46600 | L42: 46631 | M42: 46661 | N42: 46692 | O42: 46722

Sheet A3P2
B1: CENTRALES ELECTRICAS DE NARIÑO S.A. E.S.P.
B2: CURVA DE ENERGIA DE REFERENCIA PARA OFERTAR MENSUAL
B3: ANEXO 3 PRODUCTO 2 - CUADRO DE CANTIDADES DE ENERGÍA
B4: AÑO 2028 MWh
B7: Franja | C7: Hora | D7: AÑO 2028 MWh
D8: 46753 | E8: 46784 | F8: 46813 | G8: 46844 | H8: 46874 | I8: 46905 | J8: 46935 | K8: 46966 | L8: 46997 | M8: 47027 | N8: 47058 | O8: 47088
B9: Baja | C9: 1 | D9: 43.5 | E9: 43.5 | F9: 43.5 | G9: 43.5 | H9: 43.5 | I9: 43.5 | J9: 43.5 | K9: 43.5 | L9: 43.5 | M9: 43.5 | N9: 43.5 | O9: 43.5
C10: 2 | D10: 43.5 | E10: 43.5 | F10: 43.5 | G10: 43.5 | H10: 43.5 | I10: 43.5 | J10: 43.5 | K10: 43.5 | L10: 43.5 | M10: 43.5 | N10: 43.5 | O10: 43.5
C11: 3 | D11: 43.5 | E11: 43.5 | F11: 43.5 | G11: 43.5 | H11: 43.5 | I11: 43.5 | J11: 43.5 | K11: 43.5 | L11: 43.5 | M11: 43.5 | N11: 43.5 | O11: 43.5
C12: 4 | D12: 43.5 | E12: 43.5 | F12: 43.5 | G12: 43.5 | H12: 43.5 | I12: 43.5 | J12: 43.5 | K12: 43.5 | L12: 43.5 | M12: 43.5 | N12: 43.5 | O12: 43.5
B13: Media | C13: 5 | D13: 43.5 | E13: 43.5 | F13: 43.5 | G13: 43.5 | H13: 43.5 | I13: 43.5 | J13: 43.5 | K13: 43.5 | L13: 43.5 | M13: 43.5 | N13: 43.5 | O13: 43.5
C14: 6 | D14: 43.5 | E14: 43.5 | F14: 43.5 | G14: 43.5 | H14: 43.5 | I14: 43.5 | J14: 43.5 | K14: 43.5 | L14: 43.5 | M14: 43.5 | N14: 43.5 | O14: 43.5
C15: 7 | D15: 43.5 | E15: 43.5 | F15: 43.5 | G15: 43.5 | H15: 43.5 | I15: 43.5 | J15: 43.5 | K15: 43.5 | L15: 43.5 | M15: 43.5 | N15: 43.5 | O15: 43.5
C16: 8 | D16: 43.5 | E16: 43.5 | F16: 43.5 | G16: 43.5 | H16: 43.5 | I16: 43.5 | J16: 43.5 | K16: 43.5 | L16: 43.5 | M16: 43.5 | N16: 43.5 | O16: 43.5
C17: 9 | D17: 43.5 | E17: 43.5 | F17: 43.5 | G17: 43.5 | H17: 43.5 | I17: 43.5 | J17: 43.5 | K17: 43.5 | L17: 43.5 | M17: 43.5 | N17: 43.5 | O17: 43.5
B18: Alta | C18: 10 | D18: 43.5 | E18: 43.5 | F18: 43.5 | G18: 43.5 | H18: 43.5 | I18: 43.5 | J18: 43.5 | K18: 43.5 | L18: 43.5 | M18: 43.5 | N18: 43.5 | O18: 43.5
C19: 11 | D19: 43.5 | E19: 43.5 | F19: 43.5 | G19: 43.5 | H19: 43.5 | I19: 43.5 | J19: 43.5 | K19: 43.5 | L19: 43.5 | M19: 43.5 | N19: 43.5 | O19: 43.5
C20: 12 | D20: 43.5 | E20: 43.5 | F20: 43.5 | G20: 43.5 | H20: 43.5 | I20: 43.5 | J20: 43.5 | K20: 43.5 | L20: 43.5 | M20: 43.5 | N20: 43.5 | O20: 43.5
B21: Media | C21: 13 | D21: 43.5 | E21: 43.5 | F21: 43.5 | G21: 43.5 | H21: 43.5 | I21: 43.5 | J21: 43.5 | K21: 43.5 | L21: 43.5 | M21: 43.5 | N21: 43.5 | O21: 43.5
C22: 14 | D22: 43.5 | E22: 43.5 | F22: 43.5 | G22: 43.5 | H22: 43.5 | I22: 43.5 | J22: 43.5 | K22: 43.5 | L22: 43.5 | M22: 43.5 | N22: 43.5 | O22: 43.5
C23: 15 | D23: 43.5 | E23: 43.5 | F23: 43.5 | G23: 43.5 | H23: 43.5 | I23: 43.5 | J23: 43.5 | K23: 43.5 | L23: 43.5 | M23: 43.5 | N23: 43.5 | O23: 43.5
C24: 16 | D24: 43.5 | E24: 43.5 | F24: 43.5 | G24: 43.5 | H24: 43.5 | I24: 43.5 | J24: 43.5 | K24: 43.5 | L24: 43.5 | M24: 43.5 | N24: 43.5 | O24: 43.5
C25: 17 | D25: 43.5 | E25: 43.5 | F25: 43.5 | G25: 43.5 | H25: 43.5 | I25: 43.5 | J25: 43.5 | K25: 43.5 | L25: 43.5 | M25: 43.5 | N25: 43.5 | O25: 43.5
C26: 18 | D26: 43.5 | E26: 43.5 | F26: 43.5 | G26: 43.5 | H26: 43.5 | I26: 43.5 | J26: 43.5 | K26: 43.5 | L26: 43.5 | M26: 43.5 | N26: 43.5 | O26: 43.5
B27: Alta | C27: 19 | D27: 43.5 | E27: 43.5 | F27: 43.5 | G27: 43.5 | H27: 43.5 | I27: 43.5 | J27: 43.5 | K27: 43.5 | L27: 43.5 | M27: 43.5 | N27: 43.5 | O27: 43.5
C28: 20 | D28: 43.5 | E28: 43.5 | F28: 43.5 | G28: 43.5 | H28: 43.5 | I28: 43.5 | J28: 43.5 | K28: 43.5 | L28: 43.5 | M28: 43.5 | N28: 43.5 | O28: 43.5
C29: 21 | D29: 43.5 | E29: 43.5 | F29: 43.5 | G29: 43.5 | H29: 43.5 | I29: 43.5 | J29: 43.5 | K29: 43.5 | L29: 43.5 | M29: 43.5 | N29: 43.5 | O29: 43.5
B30: Media | C30: 22 | D30: 43.5 | E30: 43.5 | F30: 43.5 | G30: 43.5 | H30: 43.5 | I30: 43.5 | J30: 43.5 | K30: 43.5 | L30: 43.5 | M30: 43.5 | N30: 43.5 | O30: 43.5
C31: 23 | D31: 43.5 | E31: 43.5 | F31: 43.5 | G31: 43.5 | H31: 43.5 | I31: 43.5 | J31: 43.5 | K31: 43.5 | L31: 43.5 | M31: 43.5 | N31: 43.5 | O31: 43.5
B32: Baja | C32: 24 | D32: 43.5 | E32: 43.5 | F32: 43.5 | G32: 43.5 | H32: 43.5 | I32: 43.5 | J32: 43.5 | K32: 43.5 | L32: 43.5 | M32: 43.5 | N32: 43.5 | O32: 43.5
B33: Días | D33: 31 | E33: 29 | F33: 31 | G33: 30 | H33: 31 | I33: 30 | J33: 31 | K33: 31 | L33: 30 | M33: 31 | N33: 30 | O33: 31
B34: Resúmen Año 2028 MWh
B35: Baja | D35: =(SUM(D9:D12)+D32) -> 217.5 | E35: =(SUM(E9:E12)+E32) -> 217.5 | F35: =(SUM(F9:F12)+F32) -> 217.5 | G35: =(SUM(G9:G12)+G32) -> 217.5 | H35: =(SUM(H9:H12)+H32) -> 217.5 | I35: =(SUM(I9:I12)+I32) -> 217.5 | J35: =(SUM(J9:J12)+J32) -> 217.5 | K35: =(SUM(K9:K12)+K32) -> 217.5 | ... O35: =(SUM(O9:O12)+O32) -> 217.5
B36: Media | D36: =(SUM(D13:D17)+SUM(D21:D26)+D30+D31) -> 565.5 | E36: =(SUM(E13:E17)+SUM(E21:E26)+E30+E31) -> 565.5 | F36: =(SUM(F13:F17)+SUM(F21:F26)+F30+F31) -> 565.5 | G36: =(SUM(G13:G17)+SUM(G21:G26)+G30+G31) -> 565.5 | H36: =(SUM(H13:H17)+SUM(H21:H26)+H30+H31) -> 565.5 | I36: =(SUM(I13:I17)+SUM(I21:I26)+I30+I31) -> 565.5 | J36: =(SUM(J13:J17)+SUM(J21:J26)+J30+J31) -> 565.5 | K36: =(SUM(K13:K17)+SUM(K21:K26)+K30+K31) -> 565.5 | ... O36: =(SUM(O13:O17)+SUM(O21:O26)+O30+O31) -> 565.5
B37: Alta | D37: =(SUM(D18:D20)+SUM(D27:D29)) -> 261 | E37: =(SUM(E18:E20)+SUM(E27:E29)) -> 261 | F37: =(SUM(F18:F20)+SUM(F27:F29)) -> 261 | G37: =(SUM(G18:G20)+SUM(G27:G29)) -> 261 | H37: =(SUM(H18:H20)+SUM(H27:H29)) -> 261 | I37: =(SUM(I18:I20)+SUM(I27:I29)) -> 261 | J37: =(SUM(J18:J20)+SUM(J27:J29)) -> 261 | K37: =(SUM(K18:K20)+SUM(K27:K29)) -> 261 | ... O37: =(SUM(O18:O20)+SUM(O27:O29)) -> 261
B38: Subtotal Baja | D38: =D35*D33 -> 6742.5 | E38: =E35*E33 -> 6307.5 | F38: =F35*F33 -> 6742.5 | G38: =G35*G33 -> 6525 | H38: =H35*H33 -> 6742.5 | I38: =I35*I33 -> 6525 | J38: =J35*J33 -> 6742.5 | K38: =K35*K33 -> 6742.5 | ... O38: =O35*O33 -> 6742.5
B39: Subtotal Media | D39: =D33*D36 -> 17530.5 | E39: =E33*E36 -> 16399.5 | F39: =F33*F36 -> 17530.5 | G39: =G33*G36 -> 16965 | H39: =H33*H36 -> 17530.5 | I39: =I33*I36 -> 16965 | J39: =J33*J36 -> 17530.5 | K39: =K33*K36 -> 17530.5 | ... O39: =O33*O36 -> 17530.5
B40: Subtotal Alta | D40: =D33*D37 -> 8091 | E40: =E33*E37 -> 7569 | F40: =F33*F37 -> 8091 | G40: =G33*G37 -> 7830 | H40: =H33*H37 -> 8091 | I40: =I33*I37 -> 7830 | J40: =J33*J37 -> 8091 | K40: =K33*K37 -> 8091 | ... O40: =O33*O37 -> 8091
B41: Total | D41: =D40+D39+D38 -> 32364 | E41: =E40+E39+E38 -> 30276 | F41: =F40+F39+F38 -> 32364 | G41: =G40+G39+G38 -> 31320 | H41: =H40+H39+H38 -> 32364 | I41: =I40+I39+I38 -> 31320 | J41: =J40+J39+J38 -> 32364 | K41: =K40+K39+K38 -> 32364 | ... O41: =O40+O39+O38 -> 32364 | P41: =SUM(D41:O41) -> 382104
D42: 46753 | E42: 46784 | F42: 46813 | G42: 46844 | H42: 46874 | I42: 46905 | J42: 46935 | K42: 46966 | L42: 46997 | M42: 47027 | N42: 47058 | O42: 47088

Sheet A4P3
B1: CENTRALES ELECTRICAS DE NARIÑO S.A. E.S.P.
B2: CURVA DE ENERGIA DE REFERENCIA PARA OFERTAR MENSUAL
B3: ANEXO 4 PRODUCTO 3 - CUADRO DE CANTIDADES DE ENERGÍA
B4: AÑO 2029 MWh
B7: Franja | C7: Hora | D7: AÑO 2029 MWh
D8: 47119 | E8: 47150 | F8: 47178 | G8: 47209 | H8: 47239 | I8: 47270 | J8: 47300 | K8: 47331 | L8: 47362 | M8: 47392 | N8: 47423 | O8: 47453
B9: Baja | C9: 1 | D9: 35.9 | E9: 35.9 | F9: 35.9 | G9: 35.9 | H9: 35.9 | I9: 35.9 | J9: 35.9 | K9: 35.9 | L9: 35.9 | M9: 35.9 | N9: 35.9 | O9: 35.9
C10: 2 | D10: 35.9 | E10: 35.9 | F10: 35.9 | G10: 35.9 | H10: 35.9 | I10: 35.9 | J10: 35.9 | K10: 35.9 | L10: 35.9 | M10: 35.9 | N10: 35.9 | O10: 35.9
C11: 3 | D11: 35.9 | E11: 35.9 | F11: 35.9 | G11: 35.9 | H11: 35.9 | I11: 35.9 | J11: 35.9 | K11: 35.9 | L11: 35.9 | M11: 35.9 | N11: 35.9 | O11: 35.9
C12: 4 | D12: 35.9 | E12: 35.9 | F12: 35.9 | G12: 35.9 | H12: 35.9 | I12: 35.9 | J12: 35.9 | K12: 35.9 | L12: 35.9 | M12: 35.9 | N12: 35.9 | O12: 35.9
B13: Media | C13: 5 | D13: 35.9 | E13: 35.9 | F13: 35.9 | G13: 35.9 | H13: 35.9 | I13: 35.9 | J13: 35.9 | K13: 35.9 | L13: 35.9 | M13: 35.9 | N13: 35.9 | O13: 35.9
C14: 6 | D14: 35.9 | E14: 35.9 | F14: 35.9 | G14: 35.9 | H14: 35.9 | I14: 35.9 | J14: 35.9 | K14: 35.9 | L14: 35.9 | M14: 35.9 | N14: 35.9 | O14: 35.9
C15: 7 | D15: 35.9 | E15: 35.9 | F15: 35.9 | G15: 35.9 | H15: 35.9 | I15: 35.9 | J15: 35.9 | K15: 35.9 | L15: 35.9 | M15: 35.9 | N15: 35.9 | O15: 35.9
C16: 8 | D16: 35.9 | E16: 35.9 | F16: 35.9 | G16: 35.9 | H16: 35.9 | I16: 35.9 | J16: 35.9 | K16: 35.9 | L16: 35.9 | M16: 35.9 | N16: 35.9 | O16: 35.9
C17: 9 | D17: 35.9 | E17: 35.9 | F17: 35.9 | G17: 35.9 | H17: 35.9 | I17: 35.9 | J17: 35.9 | K17: 35.9 | L17: 35.9 | M17: 35.9 | N17: 35.9 | O17: 35.9
B18: Alta | C18: 10 | D18: 35.9 | E18: 35.9 | F18: 35.9 | G18: 35.9 | H18: 35.9 | I18: 35.9 | J18: 35.9 | K18: 35.9 | L18: 35.9 | M18: 35.9 | N18: 35.9 | O18: 35.9
C19: 11 | D19: 35.9 | E19: 35.9 | F19: 35.9 | G19: 35.9 | H19: 35.9 | I19: 35.9 | J19: 35.9 | K19: 35.9 | L19: 35.9 | M19: 35.9 | N19: 35.9 | O19: 35.9
C20: 12 | D20: 35.9 | E20: 35.9 | F20: 35.9 | G20: 35.9 | H20: 35.9 | I20: 35.9 | J20: 35.9 | K20: 35.9 | L20: 35.9 | M20: 35.9 | N20: 35.9 | O20: 35.9
B21: Media | C21: 13 | D21: 35.9 | E21: 35.9 | F21: 35.9 | G21: 35.9 | H21: 35.9 | I21: 35.9 | J21: 35.9 | K21: 35.9 | L21: 35.9 | M21: 35.9 | N21: 35.9 | O21: 35.9
C22: 14 | D22: 35.9 | E22: 35.9 | F22: 35.9 | G22: 35.9 | H22: 35.9 | I22: 35.9 | J22: 35.9 | K22: 35.9 | L22: 35.9 | M22: 35.9 | N22: 35.9 | O22: 35.9
C23: 15 | D23: 35.9 | E23: 35.9 | F23: 35.9 | G23: 35.9 | H23: 35.9 | I23: 35.9 | J23: 35.9 | K23: 35.9 | L23: 35.9 | M23: 35.9 | N23: 35.9 | O23: 35.9
C24: 16 | D24: 35.9 | E24: 35.9 | F24: 35.9 | G24: 35.9 | H24: 35.9 | I24: 35.9 | J24: 35.9 | K24: 35.9 | L24: 35.9 | M24: 35.9 | N24: 35.9 | O24: 35.9
C25: 17 | D25: 35.9 | E25: 35.9 | F25: 35.9 | G25: 35.9 | H25: 35.9 | I25: 35.9 | J25: 35.9 | K25: 35.9 | L25: 35.9 | M25: 35.9 | N25: 35.9 | O25: 35.9
C26: 18 | D26: 35.9 | E26: 35.9 | F26: 35.9 | G26: 35.9 | H26: 35.9 | I26: 35.9 | J26: 35.9 | K26: 35.9 | L26: 35.9 | M26: 35.9 | N26: 35.9 | O26: 35.9
B27: Alta | C27: 19 | D27: 35.9 | E27: 35.9 | F27: 35.9 | G27: 35.9 | H27: 35.9 | I27: 35.9 | J27: 35.9 | K27: 35.9 | L27: 35.9 | M27: 35.9 | N27: 35.9 | O27: 35.9
C28: 20 | D28: 35.9 | E28: 35.9 | F28: 35.9 | G28: 35.9 | H28: 35.9 | I28: 35.9 | J28: 35.9 | K28: 35.9 | L28: 35.9 | M28: 35.9 | N28: 35.9 | O28: 35.9
C29: 21 | D29: 35.9 | E29: 35.9 | F29: 35.9 | G29: 35.9 | H29: 35.9 | I29: 35.9 | J29: 35.9 | K29: 35.9 | L29: 35.9 | M29: 35.9 | N29: 35.9 | O29: 35.9
B30: Media | C30: 22 | D30: 35.9 | E30: 35.9 | F30: 35.9 | G30: 35.9 | H30: 35.9 | I30: 35.9 | J30: 35.9 | K30: 35.9 | L30: 35.9 | M30: 35.9 | N30: 35.9 | O30: 35.9
C31: 23 | D31: 35.9 | E31: 35.9 | F31: 35.9 | G31: 35.9 | H31: 35.9 | I31: 35.9 | J31: 35.9 | K31: 35.9 | L31: 35.9 | M31: 35.9 | N31: 35.9 | O31: 35.9
B32: Baja | C32: 24 | D32: 35.9 | E32: 35.9 | F32: 35.9 | G32: 35.9 | H32: 35.9 | I32: 35.9 | J32: 35.9 | K32: 35.9 | L32: 35.9 | M32: 35.9 | N32: 35.9 | O32: 35.9
B33: Días | D33: 31 | E33: 28 | F33: 31 | G33: 30 | H33: 31 | I33: 30 | J33: 31 | K33: 31 | L33: 30 | M33: 31 | N33: 30 | O33: 31
B34: Resúmen Periodo Año 2029 MWh
B35: Baja | D35: =(SUM(D9:D12)+D32) -> 179.5 | E35: =(SUM(E9:E12)+E32) -> 179.5 | F35: =(SUM(F9:F12)+F32) -> 179.5 | G35: =(SUM(G9:G12)+G32) -> 179.5 | H35: =(SUM(H9:H12)+H32) -> 179.5 | I35: =(SUM(I9:I12)+I32) -> 179.5 | J35: =(SUM(J9:J12)+J32) -> 179.5 | K35: =(SUM(K9:K12)+K32) -> 179.5 | ... O35: =(SUM(O9:O12)+O32) -> 179.5
B36: Media | D36: =(SUM(D13:D17)+SUM(D21:D26)+D30+D31) -> 466.7 | E36: =(SUM(E13:E17)+SUM(E21:E26)+E30+E31) -> 466.7 | F36: =(SUM(F13:F17)+SUM(F21:F26)+F30+F31) -> 466.7 | G36: =(SUM(G13:G17)+SUM(G21:G26)+G30+G31) -> 466.7 | H36: =(SUM(H13:H17)+SUM(H21:H26)+H30+H31) -> 466.7 | I36: =(SUM(I13:I17)+SUM(I21:I26)+I30+I31) -> 466.7 | J36: =(SUM(J13:J17)+SUM(J21:J26)+J30+J31) -> 466.7 | K36: =(SUM(K13:K17)+SUM(K21:K26)+K30+K31) -> 466.7 | ... O36: =(SUM(O13:O17)+SUM(O21:O26)+O30+O31) -> 466.7
B37: Alta | D37: =(SUM(D18:D20)+SUM(D27:D29)) -> 215.4 | E37: =(SUM(E18:E20)+SUM(E27:E29)) -> 215.4 | F37: =(SUM(F18:F20)+SUM(F27:F29)) -> 215.4 | G37: =(SUM(G18:G20)+SUM(G27:G29)) -> 215.4 | H37: =(SUM(H18:H20)+SUM(H27:H29)) -> 215.4 | I37: =(SUM(I18:I20)+SUM(I27:I29)) -> 215.4 | J37: =(SUM(J18:J20)+SUM(J27:J29)) -> 215.4 | K37: =(SUM(K18:K20)+SUM(K27:K29)) -> 215.4 | ... O37: =(SUM(O18:O20)+SUM(O27:O29)) -> 215.4
B38: Subtotal Baja | D38: =D35*D33 -> 5564.5 | E38: =E35*E33 -> 5026 | F38: =F35*F33 -> 5564.5 | G38: =G35*G33 -> 5385 | H38: =H35*H33 -> 5564.5 | I38: =I35*I33 -> 5385 | J38: =J35*J33 -> 5564.5 | K38: =K35*K33 -> 5564.5 | ... O38: =O35*O33 -> 5564.5
B39: Subtotal Media | D39: =D33*D36 -> 14467.7 | E39: =E33*E36 -> 13067.6 | F39: =F33*F36 -> 14467.7 | G39: =G33*G36 -> 14001 | H39: =H33*H36 -> 14467.7 | I39: =I33*I36 -> 14001 | J39: =J33*J36 -> 14467.7 | K39: =K33*K36 -> 14467.7 | ... O39: =O33*O36 -> 14467.7
B40: Subtotal Alta | D40: =D33*D37 -> 6677.4 | E40: =E33*E37 -> 6031.2 | F40: =F33*F37 -> 6677.4 | G40: =G33*G37 -> 6462 | H40: =H33*H37 -> 6677.4 | I40: =I33*I37 -> 6462 | J40: =J33*J37 -> 6677.4 | K40: =K33*K37 -> 6677.4 | ... O40: =O33*O37 -> 6677.4
B41: Total | D41: =D40+D39+D38 -> 26709.6 | E41: =E40+E39+E38 -> 24124.8 | F41: =F40+F39+F38 -> 26709.6 | G41: =G40+G39+G38 -> 25848 | H41: =H40+H39+H38 -> 26709.6 | I41: =I40+I39+I38 -> 25848 | J41: =J40+J39+J38 -> 26709.6 | K41: =K40+K39+K38 -> 26709.6 | ... O41: =O40+O39+O38 -> 26709.6 | P41: =SUM(D41:O41) -> 314484
D42: 47119 | E42: 47150 | F42: 47178 | G42: 47209 | H42: 47239 | I42: 47270 | J42: 47300 | K42: 47331 | L42: 47362 | M42: 47392 | N42: 47423 | O42: 47453

Sheet A5P4
B1: CENTRALES ELECTRICAS DE NARIÑO S.A. E.S.P.
B2: CURVA DE ENERGIA DE REFERENCIA PARA OFERTAR MENSUAL
B3: ANEXO 5 PRODUCTO 4 - CUADRO DE CANTIDADES DE ENERGÍA
B4: AÑO 2030 MWh
B7: Franja | C7: Hora | D7: AÑO 2030 MWh
D8: 47484 | E8: 47515 | F8: 47543 | G8: 47574 | H8: 47604 | I8: 47635 | J8: 47665 | K8: 47696 | L8: 47727 | M8: 47757 | N8: 47788 | O8: 47818
B9: Baja | C9: 1 | D9: 32.7 | E9: 32.7 | F9: 32.7 | G9: 32.7 | H9: 32.7 | I9: 32.7 | J9: 32.7 | K9: 32.7 | L9: 32.7 | M9: 32.7 | N9: 32.7 | O9: 32.7
C10: 2 | D10: 32.7 | E10: 32.7 | F10: 32.7 | G10: 32.7 | H10: 32.7 | I10: 32.7 | J10: 32.7 | K10: 32.7 | L10: 32.7 | M10: 32.7 | N10: 32.7 | O10: 32.7
C11: 3 | D11: 32.7 | E11: 32.7 | F11: 32.7 | G11: 32.7 | H11: 32.7 | I11: 32.7 | J11: 32.7 | K11: 32.7 | L11: 32.7 | M11: 32.7 | N11: 32.7 | O11: 32.7
C12: 4 | D12: 32.7 | E12: 32.7 | F12: 32.7 | G12: 32.7 | H12: 32.7 | I12: 32.7 | J12: 32.7 | K12: 32.7 | L12: 32.7 | M12: 32.7 | N12: 32.7 | O12: 32.7
B13: Media | C13: 5 | D13: 32.7 | E13: 32.7 | F13: 32.7 | G13: 32.7 | H13: 32.7 | I13: 32.7 | J13: 32.7 | K13: 32.7 | L13: 32.7 | M13: 32.7 | N13: 32.7 | O13: 32.7
C14: 6 | D14: 32.7 | E14: 32.7 | F14: 32.7 | G14: 32.7 | H14: 32.7 | I14: 32.7 | J14: 32.7 | K14: 32.7 | L14: 32.7 | M14: 32.7 | N14: 32.7 | O14: 32.7
C15: 7 | D15: 32.7 | E15: 32.7 | F15: 32.7 | G15: 32.7 | H15: 32.7 | I15: 32.7 | J15: 32.7 | K15: 32.7 | L15: 32.7 | M15: 32.7 | N15: 32.7 | O15: 32.7
C16: 8 | D16: 32.7 | E16: 32.7 | F16: 32.7 | G16: 32.7 | H16: 32.7 | I16: 32.7 | J16: 32.7 | K16: 32.7 | L16: 32.7 | M16: 32.7 | N16: 32.7 | O16: 32.7
C17: 9 | D17: 32.7 | E17: 32.7 | F17: 32.7 | G17: 32.7 | H17: 32.7 | I17: 32.7 | J17: 32.7 | K17: 32.7 | L17: 32.7 | M17: 32.7 | N17: 32.7 | O17: 32.7
B18: Alta | C18: 10 | D18: 32.7 | E18: 32.7 | F18: 32.7 | G18: 32.7 | H18: 32.7 | I18: 32.7 | J18: 32.7 | K18: 32.7 | L18: 32.7 | M18: 32.7 | N18: 32.7 | O18: 32.7
C19: 11 | D19: 32.7 | E19: 32.7 | F19: 32.7 | G19: 32.7 | H19: 32.7 | I19: 32.7 | J19: 32.7 | K19: 32.7 | L19: 32.7 | M19: 32.7 | N19: 32.7 | O19: 32.7
C20: 12 | D20: 32.7 | E20: 32.7 | F20: 32.7 | G20: 32.7 | H20: 32.7 | I20: 32.7 | J20: 32.7 | K20: 32.7 | L20: 32.7 | M20: 32.7 | N20: 32.7 | O20: 32.7
B21: Media | C21: 13 | D21: 32.7 | E21: 32.7 | F21: 32.7 | G21: 32.7 | H21: 32.7 | I21: 32.7 | J21: 32.7 | K21: 32.7 | L21: 32.7 | M21: 32.7 | N21: 32.7 | O21: 32.7
C22: 14 | D22: 32.7 | E22: 32.7 | F22: 32.7 | G22: 32.7 | H22: 32.7 | I22: 32.7 | J22: 32.7 | K22: 32.7 | L22: 32.7 | M22: 32.7 | N22: 32.7 | O22: 32.7
C23: 15 | D23: 32.7 | E23: 32.7 | F23: 32.7 | G23: 32.7 | H23: 32.7 | I23: 32.7 | J23: 32.7 | K23: 32.7 | L23: 32.7 | M23: 32.7 | N23: 32.7 | O23: 32.7
C24: 16 | D24: 32.7 | E24: 32.7 | F24: 32.7 | G24: 32.7 | H24: 32.7 | I24: 32.7 | J24: 32.7 | K24: 32.7 | L24: 32.7 | M24: 32.7 | N24: 32.7 | O24: 32.7
C25: 17 | D25: 32.7 | E25: 32.7 | F25: 32.7 | G25: 32.7 | H25: 32.7 | I25: 32.7 | J25: 32.7 | K25: 32.7 | L25: 32.7 | M25: 32.7 | N25: 32.7 | O25: 32.7
C26: 18 | D26: 32.7 | E26: 32.7 | F26: 32.7 | G26: 32.7 | H26: 32.7 | I26: 32.7 | J26: 32.7 | K26: 32.7 | L26: 32.7 | M26: 32.7 | N26: 32.7 | O26: 32.7
B27: Alta | C27: 19 | D27: 32.7 | E27: 32.7 | F27: 32.7 | G27: 32.7 | H27: 32.7 | I27: 32.7 | J27: 32.7 | K27: 32.7 | L27: 32.7 | M27: 32.7 | N27: 32.7 | O27: 32.7
C28: 20 | D28: 32.7 | E28: 32.7 | F28: 32.7 | G28: 32.7 | H28: 32.7 | I28: 32.7 | J28: 32.7 | K28: 32.7 | L28: 32.7 | M28: 32.7 | N28: 32.7 | O28: 32.7
C29: 21 | D29: 32.7 | E29: 32.7 | F29: 32.7 | G29: 32.7 | H29: 32.7 | I29: 32.7 | J29: 32.7 | K29: 32.7 | L29: 32.7 | M29: 32.7 | N29: 32.7 | O29: 32.7
B30: Media | C30: 22 | D30: 32.7 | E30: 32.7 | F30: 32.7 | G30: 32.7 | H30: 32.7 | I30: 32.7 | J30: 32.7 | K30: 32.7 | L30: 32.7 | M30: 32.7 | N30: 32.7 | O30: 32.7
C31: 23 | D31: 32.7 | E31: 32.7 | F31: 32.7 | G31: 32.7 | H31: 32.7 | I31: 32.7 | J31: 32.7 | K31: 32.7 | L31: 32.7 | M31: 32.7 | N31: 32.7 | O31: 32.7
B32: Baja | C32: 24 | D32: 32.7 | E32: 32.7 | F32: 32.7 | G32: 32.7 | H32: 32.7 | I32: 32.7 | J32: 32.7 | K32: 32.7 | L32: 32.7 | M32: 32.7 | N32: 32.7 | O32: 32.7
B33: Días | D33: 31 | E33: 28 | F33: 31 | G33: 30 | H33: 31 | I33: 30 | J33: 31 | K33: 31 | L33: 30 | M33: 31 | N33: 30 | O33: 31
B34: Resúmen Periodo Año 2030 MWh
B35: Baja | D35: =(SUM(D9:D12)+D32) -> 163.5 | E35: =(SUM(E9:E12)+E32) -> 163.5 | F35: =(SUM(F9:F12)+F32) -> 163.5 | G35: =(SUM(G9:G12)+G32) -> 163.5 | H35: =(SUM(H9:H12)+H32) -> 163.5 | I35: =(SUM(I9:I12)+I32) -> 163.5 | J35: =(SUM(J9:J12)+J32) -> 163.5 | K35: =(SUM(K9:K12)+K32) -> 163.5 | ... O35: =(SUM(O9:O12)+O32) -> 163.5
B36: Media | D36: =(SUM(D13:D17)+SUM(D21:D26)+D30+D31) -> 425.1 | E36: =(SUM(E13:E17)+SUM(E21:E26)+E30+E31) -> 425.1 | F36: =(SUM(F13:F17)+SUM(F21:F26)+F30+F31) -> 425.1 | G36: =(SUM(G13:G17)+SUM(G21:G26)+G30+G31) -> 425.1 | H36: =(SUM(H13:H17)+SUM(H21:H26)+H30+H31) -> 425.1 | I36: =(SUM(I13:I17)+SUM(I21:I26)+I30+I31) -> 425.1 | J36: =(SUM(J13:J17)+SUM(J21:J26)+J30+J31) -> 425.1 | K36: =(SUM(K13:K17)+SUM(K21:K26)+K30+K31) -> 425.1 | ... O36: =(SUM(O13:O17)+SUM(O21:O26)+O30+O31) -> 425.1
B37: Alta | D37: =(SUM(D18:D20)+SUM(D27:D29)) -> 196.2 | E37: =(SUM(E18:E20)+SUM(E27:E29)) -> 196.2 | F37: =(SUM(F18:F20)+SUM(F27:F29)) -> 196.2 | G37: =(SUM(G18:G20)+SUM(G27:G29)) -> 196.2 | H37: =(SUM(H18:H20)+SUM(H27:H29)) -> 196.2 | I37: =(SUM(I18:I20)+SUM(I27:I29)) -> 196.2 | J37: =(SUM(J18:J20)+SUM(J27:J29)) -> 196.2 | K37: =(SUM(K18:K20)+SUM(K27:K29)) -> 196.2 | ... O37: =(SUM(O18:O20)+SUM(O27:O29)) -> 196.2
B38: Subtotal Baja | D38: =D35*D33 -> 5068.5 | E38: =E35*E33 -> 4578 | F38: =F35*F33 -> 5068.5 | G38: =G35*G33 -> 4905 | H38: =H35*H33 -> 5068.5 | I38: =I35*I33 -> 4905 | J38: =J35*J33 -> 5068.5 | K38: =K35*K33 -> 5068.5 | ... O38: =O35*O33 -> 5068.5
B39: Subtotal Media | D39: =D33*D36 -> 13178.1 | E39: =E33*E36 -> 11902.8 | F39: =F33*F36 -> 13178.1 | G39: =G33*G36 -> 12753 | H39: =H33*H36 -> 13178.1 | I39: =I33*I36 -> 12753 | J39: =J33*J36 -> 13178.1 | K39: =K33*K36 -> 13178.1 | ... O39: =O33*O36 -> 13178.1
B40: Subtotal Alta | D40: =D33*D37 -> 6082.2 | E40: =E33*E37 -> 5493.6 | F40: =F33*F37 -> 6082.2 | G40: =G33*G37 -> 5886 | H40: =H33*H37 -> 6082.2 | I40: =I33*I37 -> 5886 | J40: =J33*J37 -> 6082.2 | K40: =K33*K37 -> 6082.2 | ... O40: =O33*O37 -> 6082.2
B41: Total | D41: =D40+D39+D38 -> 24328.8 | E41: =E40+E39+E38 -> 21974.4 | F41: =F40+F39+F38 -> 24328.8 | G41: =G40+G39+G38 -> 23544 | H41: =H40+H39+H38 -> 24328.8 | I41: =I40+I39+I38 -> 23544 | J41: =J40+J39+J38 -> 24328.8 | K41: =K40+K39+K38 -> 24328.8 | ... O41: =O40+O39+O38 -> 24328.8 | P41: =SUM(D41:O41) -> 286452
D42: 47484 | E42: 47515 | F42: 47543 | G42: 47574 | H42: 47604 | I42: 47635 | J42: 47665 | K42: 47696 | L42: 47727 | M42: 47757 | N42: 47788 | O42: 47818

Sheet A6P5
B1: CENTRALES ELECTRICAS DE NARIÑO S.A. E.S.P.
B2: CURVA DE ENERGIA DE REFERENCIA PARA OFERTAR MENSUAL
B3: ANEXO 6 PRODUCTO 5 - CUADRO DE CANTIDADES DE ENERGÍA
B4: AÑO 2031 MWh
B7: Franja | C7: Hora | D7: AÑO 2031 MWh
D8: 47849 | E8: 47880 | F8: 47908 | G8: 47939 | H8: 47969 | I8: 48000 | J8: 48030 | K8: 48061 | L8: 48092 | M8: 48122 | N8: 48153 | O8: 48183
B9: Baja | C9: 1 | D9: 50.7 | E9: 50.7 | F9: 50.7 | G9: 50.7 | H9: 50.7 | I9: 50.7 | J9: 50.7 | K9: 50.7 | L9: 50.7 | M9: 50.7 | N9: 50.7 | O9: 50.7
C10: 2 | D10: 50.7 | E10: 50.7 | F10: 50.7 | G10: 50.7 | H10: 50.7 | I10: 50.7 | J10: 50.7 | K10: 50.7 | L10: 50.7 | M10: 50.7 | N10: 50.7 | O10: 50.7
C11: 3 | D11: 50.7 | E11: 50.7 | F11: 50.7 | G11: 50.7 | H11: 50.7 | I11: 50.7 | J11: 50.7 | K11: 50.7 | L11: 50.7 | M11: 50.7 | N11: 50.7 | O11: 50.7
C12: 4 | D12: 50.7 | E12: 50.7 | F12: 50.7 | G12: 50.7 | H12: 50.7 | I12: 50.7 | J12: 50.7 | K12: 50.7 | L12: 50.7 | M12: 50.7 | N12: 50.7 | O12: 50.7
B13: Media | C13: 5 | D13: 50.7 | E13: 50.7 | F13: 50.7 | G13: 50.7 | H13: 50.7 | I13: 50.7 | J13: 50.7 | K13: 50.7 | L13: 50.7 | M13: 50.7 | N13: 50.7 | O13: 50.7
C14: 6 | D14: 50.7 | E14: 50.7 | F14: 50.7 | G14: 50.7 | H14: 50.7 | I14: 50.7 | J14: 50.7 | K14: 50.7 | L14: 50.7 | M14: 50.7 | N14: 50.7 | O14: 50.7
C15: 7 | D15: 50.7 | E15: 50.7 | F15: 50.7 | G15: 50.7 | H15: 50.7 | I15: 50.7 | J15: 50.7 | K15: 50.7 | L15: 50.7 | M15: 50.7 | N15: 50.7 | O15: 50.7
C16: 8 | D16: 50.7 | E16: 50.7 | F16: 50.7 | G16: 50.7 | H16: 50.7 | I16: 50.7 | J16: 50.7 | K16: 50.7 | L16: 50.7 | M16: 50.7 | N16: 50.7 | O16: 50.7
C17: 9 | D17: 50.7 | E17: 50.7 | F17: 50.7 | G17: 50.7 | H17: 50.7 | I17: 50.7 | J17: 50.7 | K17: 50.7 | L17: 50.7 | M17: 50.7 | N17: 50.7 | O17: 50.7
B18: Alta | C18: 10 | D18: 50.7 | E18: 50.7 | F18: 50.7 | G18: 50.7 | H18: 50.7 | I18: 50.7 | J18: 50.7 | K18: 50.7 | L18: 50.7 | M18: 50.7 | N18: 50.7 | O18: 50.7
C19: 11 | D19: 50.7 | E19: 50.7 | F19: 50.7 | G19: 50.7 | H19: 50.7 | I19: 50.7 | J19: 50.7 | K19: 50.7 | L19: 50.7 | M19: 50.7 | N19: 50.7 | O19: 50.7
C20: 12 | D20: 50.7 | E20: 50.7 | F20: 50.7 | G20: 50.7 | H20: 50.7 | I20: 50.7 | J20: 50.7 | K20: 50.7 | L20: 50.7 | M20: 50.7 | N20: 50.7 | O20: 50.7
B21: Media | C21: 13 | D21: 50.7 | E21: 50.7 | F21: 50.7 | G21: 50.7 | H21: 50.7 | I21: 50.7 | J21: 50.7 | K21: 50.7 | L21: 50.7 | M21: 50.7 | N21: 50.7 | O21: 50.7
C22: 14 | D22: 50.7 | E22: 50.7 | F22: 50.7 | G22: 50.7 | H22: 50.7 | I22: 50.7 | J22: 50.7 | K22: 50.7 | L22: 50.7 | M22: 50.7 | N22: 50.7 | O22: 50.7
C23: 15 | D23: 50.7 | E23: 50.7 | F23: 50.7 | G23: 50.7 | H23: 50.7 | I23: 50.7 | J23: 50.7 | K23: 50.7 | L23: 50.7 | M23: 50.7 | N23: 50.7 | O23: 50.7
C24: 16 | D24: 50.7 | E24: 50.7 | F24: 50.7 | G24: 50.7 | H24: 50.7 | I24: 50.7 | J24: 50.7 | K24: 50.7 | L24: 50.7 | M24: 50.7 | N24: 50.7 | O24: 50.7
C25: 17 | D25: 50.7 | E25: 50.7 | F25: 50.7 | G25: 50.7 | H25: 50.7 | I25: 50.7 | J25: 50.7 | K25: 50.7 | L25: 50.7 | M25: 50.7 | N25: 50.7 | O25: 50.7
C26: 18 | D26: 50.7 | E26: 50.7 | F26: 50.7 | G26: 50.7 | H26: 50.7 | I26: 50.7 | J26: 50.7 | K26: 50.7 | L26: 50.7 | M26: 50.7 | N26: 50.7 | O26: 50.7
B27: Alta | C27: 19 | D27: 50.7 | E27: 50.7 | F27: 50.7 | G27: 50.7 | H27: 50.7 | I27: 50.7 | J27: 50.7 | K27: 50.7 | L27: 50.7 | M27: 50.7 | N27: 50.7 | O27: 50.7
C28: 20 | D28: 50.7 | E28: 50.7 | F28: 50.7 | G28: 50.7 | H28: 50.7 | I28: 50.7 | J28: 50.7 | K28: 50.7 | L28: 50.7 | M28: 50.7 | N28: 50.7 | O28: 50.7
C29: 21 | D29: 50.7 | E29: 50.7 | F29: 50.7 | G29: 50.7 | H29: 50.7 | I29: 50.7 | J29: 50.7 | K29: 50.7 | L29: 50.7 | M29: 50.7 | N29: 50.7 | O29: 50.7
B30: Media | C30: 22 | D30: 50.7 | E30: 50.7 | F30: 50.7 | G30: 50.7 | H30: 50.7 | I30: 50.7 | J30: 50.7 | K30: 50.7 | L30: 50.7 | M30: 50.7 | N30: 50.7 | O30: 50.7
C31: 23 | D31: 50.7 | E31: 50.7 | F31: 50.7 | G31: 50.7 | H31: 50.7 | I31: 50.7 | J31: 50.7 | K31: 50.7 | L31: 50.7 | M31: 50.7 | N31: 50.7 | O31: 50.7
B32: Baja | C32: 24 | D32: 50.7 | E32: 50.7 | F32: 50.7 | G32: 50.7 | H32: 50.7 | I32: 50.7 | J32: 50.7 | K32: 50.7 | L32: 50.7 | M32: 50.7 | N32: 50.7 | O32: 50.7
B33: Días | D33: 31 | E33: 28 | F33: 31 | G33: 30 | H33: 31 | I33: 30 | J33: 31 | K33: 31 | L33: 30 | M33: 31 | N33: 30 | O33: 31
B34: Resúmen Periodo Año 2031 MWh
B35: Baja | D35: =(SUM(D9:D12)+D32) -> 253.5 | E35: =(SUM(E9:E12)+E32) -> 253.5 | F35: =(SUM(F9:F12)+F32) -> 253.5 | G35: =(SUM(G9:G12)+G32) -> 253.5 | H35: =(SUM(H9:H12)+H32) -> 253.5 | I35: =(SUM(I9:I12)+I32) -> 253.5 | J35: =(SUM(J9:J12)+J32) -> 253.5 | K35: =(SUM(K9:K12)+K32) -> 253.5 | ... O35: =(SUM(O9:O12)+O32) -> 253.5
B36: Media | D36: =(SUM(D13:D17)+SUM(D21:D26)+D30+D31) -> 659.1 | E36: =(SUM(E13:E17)+SUM(E21:E26)+E30+E31) -> 659.1 | F36: =(SUM(F13:F17)+SUM(F21:F26)+F30+F31) -> 659.1 | G36: =(SUM(G13:G17)+SUM(G21:G26)+G30+G31) -> 659.1 | H36: =(SUM(H13:H17)+SUM(H21:H26)+H30+H31) -> 659.1 | I36: =(SUM(I13:I17)+SUM(I21:I26)+I30+I31) -> 659.1 | J36: =(SUM(J13:J17)+SUM(J21:J26)+J30+J31) -> 659.1 | K36: =(SUM(K13:K17)+SUM(K21:K26)+K30+K31) -> 659.1 | ... O36: =(SUM(O13:O17)+SUM(O21:O26)+O30+O31) -> 659.1
B37: Alta | D37: =(SUM(D18:D20)+SUM(D27:D29)) -> 304.2 | E37: =(SUM(E18:E20)+SUM(E27:E29)) -> 304.2 | F37: =(SUM(F18:F20)+SUM(F27:F29)) -> 304.2 | G37: =(SUM(G18:G20)+SUM(G27:G29)) -> 304.2 | H37: =(SUM(H18:H20)+SUM(H27:H29)) -> 304.2 | I37: =(SUM(I18:I20)+SUM(I27:I29)) -> 304.2 | J37: =(SUM(J18:J20)+SUM(J27:J29)) -> 304.2 | K37: =(SUM(K18:K20)+SUM(K27:K29)) -> 304.2 | ... O37: =(SUM(O18:O20)+SUM(O27:O29)) -> 304.2
B38: Subtotal Baja | D38: =D35*D33 -> 7858.5 | E38: =E35*E33 -> 7098 | F38: =F35*F33 -> 7858.5 | G38: =G35*G33 -> 7605 | H38: =H35*H33 -> 7858.5 | I38: =I35*I33 -> 7605 | J38: =J35*J33 -> 7858.5 | K38: =K35*K33 -> 7858.5 | ... O38: =O35*O33 -> 7858.5
B39: Subtotal Media | D39: =D33*D36 -> 20432.1 | E39: =E33*E36 -> 18454.8 | F39: =F33*F36 -> 20432.1 | G39: =G33*G36 -> 19773 | H39: =H33*H36 -> 20432.1 | I39: =I33*I36 -> 19773 | J39: =J33*J36 -> 20432.1 | K39: =K33*K36 -> 20432.1 | ... O39: =O33*O36 -> 20432.1
B40: Subtotal Alta | D40: =D33*D37 -> 9430.2 | E40: =E33*E37 -> 8517.6 | F40: =F33*F37 -> 9430.2 | G40: =G33*G37 -> 9126 | H40: =H33*H37 -> 9430.2 | I40: =I33*I37 -> 9126 | J40: =J33*J37 -> 9430.2 | K40: =K33*K37 -> 9430.2 | ... O40: =O33*O37 -> 9430.2
B41: Total | D41: =D40+D39+D38 -> 37720.8 | E41: =E40+E39+E38 -> 34070.4 | F41: =F40+F39+F38 -> 37720.8 | G41: =G40+G39+G38 -> 36504 | H41: =H40+H39+H38 -> 37720.8 | I41: =I40+I39+I38 -> 36504 | J41: =J40+J39+J38 -> 37720.8 | K41: =K40+K39+K38 -> 37720.8 | ... O41: =O40+O39+O38 -> 37720.8 | P41: =SUM(D41:O41) -> 444132
D42: 47849 | E42: 47880 | F42: 47908 | G42: 47939 | H42: 47969 | I42: 48000 | J42: 48030 | K42: 48061 | L42: 48092 | M42: 48122 | N42: 48153 | O42: 48183

Sheet A7P6
B1: CENTRALES ELECTRICAS DE NARIÑO S.A. E.S.P.
B2: CURVA DE ENERGIA DE REFERENCIA PARA OFERTAR MENSUAL
B3: ANEXO 7 PRODUCTO 6 - CUADRO DE CANTIDADES DE ENERGÍA
B4: AÑO 2032 MWh
B7: Franja | C7: Hora | D7: AÑO 2032 MWh
D8: 48214 | E8: 48245 | F8: 48274 | G8: 48305 | H8: 48335 | I8: 48366 | J8: 48396 | K8: 48427 | L8: 48458 | M8: 48488 | N8: 48519 | O8: 48549
B9: Baja | C9: 1 | D9: 83.7 | E9: 83.7 | F9: 83.7 | G9: 83.7 | H9: 83.7 | I9: 83.7 | J9: 83.7 | K9: 83.7 | L9: 83.7 | M9: 83.7 | N9: 83.7 | O9: 83.7
C10: 2 | D10: 83.7 | E10: 83.7 | F10: 83.7 | G10: 83.7 | H10: 83.7 | I10: 83.7 | J10: 83.7 | K10: 83.7 | L10: 83.7 | M10: 83.7 | N10: 83.7 | O10: 83.7
C11: 3 | D11: 83.7 | E11: 83.7 | F11: 83.7 | G11: 83.7 | H11: 83.7 | I11: 83.7 | J11: 83.7 | K11: 83.7 | L11: 83.7 | M11: 83.7 | N11: 83.7 | O11: 83.7
C12: 4 | D12: 83.7 | E12: 83.7 | F12: 83.7 | G12: 83.7 | H12: 83.7 | I12: 83.7 | J12: 83.7 | K12: 83.7 | L12: 83.7 | M12: 83.7 | N12: 83.7 | O12: 83.7
B13: Media | C13: 5 | D13: 83.7 | E13: 83.7 | F13: 83.7 | G13: 83.7 | H13: 83.7 | I13: 83.7 | J13: 83.7 | K13: 83.7 | L13: 83.7 | M13: 83.7 | N13: 83.7 | O13: 83.7
C14: 6 | D14: 83.7 | E14: 83.7 | F14: 83.7 | G14: 83.7 | H14: 83.7 | I14: 83.7 | J14: 83.7 | K14: 83.7 | L14: 83.7 | M14: 83.7 | N14: 83.7 | O14: 83.7
C15: 7 | D15: 83.7 | E15: 83.7 | F15: 83.7 | G15: 83.7 | H15: 83.7 | I15: 83.7 | J15: 83.7 | K15: 83.7 | L15: 83.7 | M15: 83.7 | N15: 83.7 | O15: 83.7
C16: 8 | D16: 83.7 | E16: 83.7 | F16: 83.7 | G16: 83.7 | H16: 83.7 | I16: 83.7 | J16: 83.7 | K16: 83.7 | L16: 83.7 | M16: 83.7 | N16: 83.7 | O16: 83.7
C17: 9 | D17: 83.7 | E17: 83.7 | F17: 83.7 | G17: 83.7 | H17: 83.7 | I17: 83.7 | J17: 83.7 | K17: 83.7 | L17: 83.7 | M17: 83.7 | N17: 83.7 | O17: 83.7
B18: Alta | C18: 10 | D18: 83.7 | E18: 83.7 | F18: 83.7 | G18: 83.7 | H18: 83.7 | I18: 83.7 | J18: 83.7 | K18: 83.7 | L18: 83.7 | M18: 83.7 | N18: 83.7 | O18: 83.7
C19: 11 | D19: 83.7 | E19: 83.7 | F19: 83.7 | G19: 83.7 | H19: 83.7 | I19: 83.7 | J19: 83.7 | K19: 83.7 | L19: 83.7 | M19: 83.7 | N19: 83.7 | O19: 83.7
C20: 12 | D20: 83.7 | E20: 83.7 | F20: 83.7 | G20: 83.7 | H20: 83.7 | I20: 83.7 | J20: 83.7 | K20: 83.7 | L20: 83.7 | M20: 83.7 | N20: 83.7 | O20: 83.7
B21: Media | C21: 13 | D21: 83.7 | E21: 83.7 | F21: 83.7 | G21: 83.7 | H21: 83.7 | I21: 83.7 | J21: 83.7 | K21: 83.7 | L21: 83.7 | M21: 83.7 | N21: 83.7 | O21: 83.7
C22: 14 | D22: 83.7 | E22: 83.7 | F22: 83.7 | G22: 83.7 | H22: 83.7 | I22: 83.7 | J22: 83.7 | K22: 83.7 | L22: 83.7 | M22: 83.7 | N22: 83.7 | O22: 83.7
C23: 15 | D23: 83.7 | E23: 83.7 | F23: 83.7 | G23: 83.7 | H23: 83.7 | I23: 83.7 | J23: 83.7 | K23: 83.7 | L23: 83.7 | M23: 83.7 | N23: 83.7 | O23: 83.7
C24: 16 | D24: 83.7 | E24: 83.7 | F24: 83.7 | G24: 83.7 | H24: 83.7 | I24: 83.7 | J24: 83.7 | K24: 83.7 | L24: 83.7 | M24: 83.7 | N24: 83.7 | O24: 83.7
C25: 17 | D25: 83.7 | E25: 83.7 | F25: 83.7 | G25: 83.7 | H25: 83.7 | I25: 83.7 | J25: 83.7 | K25: 83.7 | L25: 83.7 | M25: 83.7 | N25: 83.7 | O25: 83.7
C26: 18 | D26: 83.7 | E26: 83.7 | F26: 83.7 | G26: 83.7 | H26: 83.7 | I26: 83.7 | J26: 83.7 | K26: 83.7 | L26: 83.7 | M26: 83.7 | N26: 83.7 | O26: 83.7
B27: Alta | C27: 19 | D27: 83.7 | E27: 83.7 | F27: 83.7 | G27: 83.7 | H27: 83.7 | I27: 83.7 | J27: 83.7 | K27: 83.7 | L27: 83.7 | M27: 83.7 | N27: 83.7 | O27: 83.7
C28: 20 | D28: 83.7 | E28: 83.7 | F28: 83.7 | G28: 83.7 | H28: 83.7 | I28: 83.7 | J28: 83.7 | K28: 83.7 | L28: 83.7 | M28: 83.7 | N28: 83.7 | O28: 83.7
C29: 21 | D29: 83.7 | E29: 83.7 | F29: 83.7 | G29: 83.7 | H29: 83.7 | I29: 83.7 | J29: 83.7 | K29: 83.7 | L29: 83.7 | M29: 83.7 | N29: 83.7 | O29: 83.7
B30: Media | C30: 22 | D30: 83.7 | E30: 83.7 | F30: 83.7 | G30: 83.7 | H30: 83.7 | I30: 83.7 | J30: 83.7 | K30: 83.7 | L30: 83.7 | M30: 83.7 | N30: 83.7 | O30: 83.7
C31: 23 | D31: 83.7 | E31: 83.7 | F31: 83.7 | G31: 83.7 | H31: 83.7 | I31: 83.7 | J31: 83.7 | K31: 83.7 | L31: 83.7 | M31: 83.7 | N31: 83.7 | O31: 83.7
B32: Baja | C32: 24 | D32: 83.7 | E32: 83.7 | F32: 83.7 | G32: 83.7 | H32: 83.7 | I32: 83.7 | J32: 83.7 | K32: 83.7 | L32: 83.7 | M32: 83.7 | N32: 83.7 | O32: 83.7
B33: Días | D33: 31 | E33: 29 | F33: 31 | G33: 30 | H33: 31 | I33: 30 | J33: 31 | K33: 31 | L33: 30 | M33: 31 | N33: 30 | O33: 31
B34: Resúmen Periodo Año 2032 MWh
B35: Baja | D35: =(SUM(D9:D12)+D32) -> 418.5 | E35: =(SUM(E9:E12)+E32) -> 418.5 | F35: =(SUM(F9:F12)+F32) -> 418.5 | G35: =(SUM(G9:G12)+G32) -> 418.5 | H35: =(SUM(H9:H12)+H32) -> 418.5 | I35: =(SUM(I9:I12)+I32) -> 418.5 | J35: =(SUM(J9:J12)+J32) -> 418.5 | K35: =(SUM(K9:K12)+K32) -> 418.5 | ... O35: =(SUM(O9:O12)+O32) -> 418.5
B36: Media | D36: =(SUM(D13:D17)+SUM(D21:D26)+D30+D31) -> 1088.1 | E36: =(SUM(E13:E17)+SUM(E21:E26)+E30+E31) -> 1088.1 | F36: =(SUM(F13:F17)+SUM(F21:F26)+F30+F31) -> 1088.1 | G36: =(SUM(G13:G17)+SUM(G21:G26)+G30+G31) -> 1088.1 | H36: =(SUM(H13:H17)+SUM(H21:H26)+H30+H31) -> 1088.1 | I36: =(SUM(I13:I17)+SUM(I21:I26)+I30+I31) -> 1088.1 | J36: =(SUM(J13:J17)+SUM(J21:J26)+J30+J31) -> 1088.1 | K36: =(SUM(K13:K17)+SUM(K21:K26)+K30+K31) -> 1088.1 | ... O36: =(SUM(O13:O17)+SUM(O21:O26)+O30+O31) -> 1088.1
B37: Alta | D37: =(SUM(D18:D20)+SUM(D27:D29)) -> 502.2 | E37: =(SUM(E18:E20)+SUM(E27:E29)) -> 502.2 | F37: =(SUM(F18:F20)+SUM(F27:F29)) -> 502.2 | G37: =(SUM(G18:G20)+SUM(G27:G29)) -> 502.2 | H37: =(SUM(H18:H20)+SUM(H27:H29)) -> 502.2 | I37: =(SUM(I18:I20)+SUM(I27:I29)) -> 502.2 | J37: =(SUM(J18:J20)+SUM(J27:J29)) -> 502.2 | K37: =(SUM(K18:K20)+SUM(K27:K29)) -> 502.2 | ... O37: =(SUM(O18:O20)+SUM(O27:O29)) -> 502.2
B38: Subtotal Baja | D38: =D35*D33 -> 12973.5 | E38: =E35*E33 -> 12136.5 | F38: =F35*F33 -> 12973.5 | G38: =G35*G33 -> 12555 | H38: =H35*H33 -> 12973.5 | I38: =I35*I33 -> 12555 | J38: =J35*J33 -> 12973.5 | K38: =K35*K33 -> 12973.5 | ... O38: =O35*O33 -> 12973.5
B39: Subtotal Media | D39: =D33*D36 -> 33731.1 | E39: =E33*E36 -> 31554.9 | F39: =F33*F36 -> 33731.1 | G39: =G33*G36 -> 32643 | H39: =H33*H36 -> 33731.1 | I39: =I33*I36 -> 32643 | J39: =J33*J36 -> 33731.1 | K39: =K33*K36 -> 33731.1 | ... O39: =O33*O36 -> 33731.1
B40: Subtotal Alta | D40: =D33*D37 -> 15568.2 | E40: =E33*E37 -> 14563.8 | F40: =F33*F37 -> 15568.2 | G40: =G33*G37 -> 15066 | H40: =H33*H37 -> 15568.2 | I40: =I33*I37 -> 15066 | J40: =J33*J37 -> 15568.2 | K40: =K33*K37 -> 15568.2 | ... O40: =O33*O37 -> 15568.2
B41: Total | D41: =D40+D39+D38 -> 62272.8 | E41: =E40+E39+E38 -> 58255.2 | F41: =F40+F39+F38 -> 62272.8 | G41: =G40+G39+G38 -> 60264 | H41: =H40+H39+H38 -> 62272.8 | I41: =I40+I39+I38 -> 60264 | J41: =J40+J39+J38 -> 62272.8 | K41: =K40+K39+K38 -> 62272.8 | ... O41: =O40+O39+O38 -> 62272.8 | P41: =SUM(D41:O41) -> 735220.8
D42: 48214 | E42: 48245 | F42: 48274 | G42: 48305 | H42: 48335 | I42: 48366 | J42: 48396 | K42: 48427 | L42: 48458 | M42: 48488 | N42: 48519 | O42: 48549

Sheet A8P7
B1: CENTRALES ELECTRICAS DE NARIÑO S.A. E.S.P.
B2: CURVA DE ENERGIA DE REFERENCIA PARA OFERTAR MENSUAL
B3: ANEXO 8 PRODUCTO 7 - CUADRO DE CANTIDADES DE ENERGÍA
B4: AÑO 2033 MWh
B7: Franja | C7: Hora | D7: AÑO 2033 MWh
D8: 48580 | E8: 48611 | F8: 48639 | G8: 48670 | H8: 48700 | I8: 48731 | J8: 48761 | K8: 48792 | L8: 48823 | M8: 48853 | N8: 48884 | O8: 48914
B9: Baja | C9: 1 | D9: 89 | E9: 89 | F9: 89 | G9: 89 | H9: 89 | I9: 89 | J9: 89 | K9: 89 | L9: 89 | M9: 89 | N9: 89 | O9: 89
C10: 2 | D10: 89 | E10: 89 | F10: 89 | G10: 89 | H10: 89 | I10: 89 | J10: 89 | K10: 89 | L10: 89 | M10: 89 | N10: 89 | O10: 89
C11: 3 | D11: 89 | E11: 89 | F11: 89 | G11: 89 | H11: 89 | I11: 89 | J11: 89 | K11: 89 | L11: 89 | M11: 89 | N11: 89 | O11: 89
C12: 4 | D12: 89 | E12: 89 | F12: 89 | G12: 89 | H12: 89 | I12: 89 | J12: 89 | K12: 89 | L12: 89 | M12: 89 | N12: 89 | O12: 89
B13: Media | C13: 5 | D13: 89 | E13: 89 | F13: 89 | G13: 89 | H13: 89 | I13: 89 | J13: 89 | K13: 89 | L13: 89 | M13: 89 | N13: 89 | O13: 89
C14: 6 | D14: 89 | E14: 89 | F14: 89 | G14: 89 | H14: 89 | I14: 89 | J14: 89 | K14: 89 | L14: 89 | M14: 89 | N14: 89 | O14: 89
C15: 7 | D15: 89 | E15: 89 | F15: 89 | G15: 89 | H15: 89 | I15: 89 | J15: 89 | K15: 89 | L15: 89 | M15: 89 | N15: 89 | O15: 89
C16: 8 | D16: 89 | E16: 89 | F16: 89 | G16: 89 | H16: 89 | I16: 89 | J16: 89 | K16: 89 | L16: 89 | M16: 89 | N16: 89 | O16: 89
C17: 9 | D17: 89 | E17: 89 | F17: 89 | G17: 89 | H17: 89 | I17: 89 | J17: 89 | K17: 89 | L17: 89 | M17: 89 | N17: 89 | O17: 89
B18: Alta | C18: 10 | D18: 89 | E18: 89 | F18: 89 | G18: 89 | H18: 89 | I18: 89 | J18: 89 | K18: 89 | L18: 89 | M18: 89 | N18: 89 | O18: 89
C19: 11 | D19: 89 | E19: 89 | F19: 89 | G19: 89 | H19: 89 | I19: 89 | J19: 89 | K19: 89 | L19: 89 | M19: 89 | N19: 89 | O19: 89
C20: 12 | D20: 89 | E20: 89 | F20: 89 | G20: 89 | H20: 89 | I20: 89 | J20: 89 | K20: 89 | L20: 89 | M20: 89 | N20: 89 | O20: 89
B21: Media | C21: 13 | D21: 89 | E21: 89 | F21: 89 | G21: 89 | H21: 89 | I21: 89 | J21: 89 | K21: 89 | L21: 89 | M21: 89 | N21: 89 | O21: 89
C22: 14 | D22: 89 | E22: 89 | F22: 89 | G22: 89 | H22: 89 | I22: 89 | J22: 89 | K22: 89 | L22: 89 | M22: 89 | N22: 89 | O22: 89
C23: 15 | D23: 89 | E23: 89 | F23: 89 | G23: 89 | H23: 89 | I23: 89 | J23: 89 | K23: 89 | L23: 89 | M23: 89 | N23: 89 | O23: 89
C24: 16 | D24: 89 | E24: 89 | F24: 89 | G24: 89 | H24: 89 | I24: 89 | J24: 89 | K24: 89 | L24: 89 | M24: 89 | N24: 89 | O24: 89
C25: 17 | D25: 89 | E25: 89 | F25: 89 | G25: 89 | H25: 89 | I25: 89 | J25: 89 | K25: 89 | L25: 89 | M25: 89 | N25: 89 | O25: 89
C26: 18 | D26: 89 | E26: 89 | F26: 89 | G26: 89 | H26: 89 | I26: 89 | J26: 89 | K26: 89 | L26: 89 | M26: 89 | N26: 89 | O26: 89
B27: Alta | C27: 19 | D27: 89 | E27: 89 | F27: 89 | G27: 89 | H27: 89 | I27: 89 | J27: 89 | K27: 89 | L27: 89 | M27: 89 | N27: 89 | O27: 89
C28: 20 | D28: 89 | E28: 89 | F28: 89 | G28: 89 | H28: 89 | I28: 89 | J28: 89 | K28: 89 | L28: 89 | M28: 89 | N28: 89 | O28: 89
C29: 21 | D29: 89 | E29: 89 | F29: 89 | G29: 89 | H29: 89 | I29: 89 | J29: 89 | K29: 89 | L29: 89 | M29: 89 | N29: 89 | O29: 89
B30: Media | C30: 22 | D30: 89 | E30: 89 | F30: 89 | G30: 89 | H30: 89 | I30: 89 | J30: 89 | K30: 89 | L30: 89 | M30: 89 | N30: 89 | O30: 89
C31: 23 | D31: 89 | E31: 89 | F31: 89 | G31: 89 | H31: 89 | I31: 89 | J31: 89 | K31: 89 | L31: 89 | M31: 89 | N31: 89 | O31: 89
B32: Baja | C32: 24 | D32: 89 | E32: 89 | F32: 89 | G32: 89 | H32: 89 | I32: 89 | J32: 89 | K32: 89 | L32: 89 | M32: 89 | N32: 89 | O32: 89
B33: Días | D33: 31 | E33: 28 | F33: 31 | G33: 30 | H33: 31 | I33: 30 | J33: 31 | K33: 31 | L33: 30 | M33: 31 | N33: 30 | O33: 31
B34: Resúmen Periodo Año 2033 MWh
B35: Baja | D35: =(SUM(D9:D12)+D32) -> 445 | E35: =(SUM(E9:E12)+E32) -> 445 | F35: =(SUM(F9:F12)+F32) -> 445 | G35: =(SUM(G9:G12)+G32) -> 445 | H35: =(SUM(H9:H12)+H32) -> 445 | I35: =(SUM(I9:I12)+I32) -> 445 | J35: =(SUM(J9:J12)+J32) -> 445 | K35: =(SUM(K9:K12)+K32) -> 445 | ... O35: =(SUM(O9:O12)+O32) -> 445
B36: Media | D36: =(SUM(D13:D17)+SUM(D21:D26)+D30+D31) -> 1157 | E36: =(SUM(E13:E17)+SUM(E21:E26)+E30+E31) -> 1157 | F36: =(SUM(F13:F17)+SUM(F21:F26)+F30+F31) -> 1157 | G36: =(SUM(G13:G17)+SUM(G21:G26)+G30+G31) -> 1157 | H36: =(SUM(H13:H17)+SUM(H21:H26)+H30+H31) -> 1157 | I36: =(SUM(I13:I17)+SUM(I21:I26)+I30+I31) -> 1157 | J36: =(SUM(J13:J17)+SUM(J21:J26)+J30+J31) -> 1157 | K36: =(SUM(K13:K17)+SUM(K21:K26)+K30+K31) -> 1157 | ... O36: =(SUM(O13:O17)+SUM(O21:O26)+O30+O31) -> 1157
B37: Alta | D37: =(SUM(D18:D20)+SUM(D27:D29)) -> 534 | E37: =(SUM(E18:E20)+SUM(E27:E29)) -> 534 | F37: =(SUM(F18:F20)+SUM(F27:F29)) -> 534 | G37: =(SUM(G18:G20)+SUM(G27:G29)) -> 534 | H37: =(SUM(H18:H20)+SUM(H27:H29)) -> 534 | I37: =(SUM(I18:I20)+SUM(I27:I29)) -> 534 | J37: =(SUM(J18:J20)+SUM(J27:J29)) -> 534 | K37: =(SUM(K18:K20)+SUM(K27:K29)) -> 534 | ... O37: =(SUM(O18:O20)+SUM(O27:O29)) -> 534
B38: Subtotal Baja | D38: =D35*D33 -> 13795 | E38: =E35*E33 -> 12460 | F38: =F35*F33 -> 13795 | G38: =G35*G33 -> 13350 | H38: =H35*H33 -> 13795 | I38: =I35*I33 -> 13350 | J38: =J35*J33 -> 13795 | K38: =K35*K33 -> 13795 | ... O38: =O35*O33 -> 13795
B39: Subtotal Media | D39: =D33*D36 -> 35867 | E39: =E33*E36 -> 32396 | F39: =F33*F36 -> 35867 | G39: =G33*G36 -> 34710 | H39: =H33*H36 -> 35867 | I39: =I33*I36 -> 34710 | J39: =J33*J36 -> 35867 | K39: =K33*K36 -> 35867 | ... O39: =O33*O36 -> 35867
B40: Subtotal Alta | D40: =D33*D37 -> 16554 | E40: =E33*E37 -> 14952 | F40: =F33*F37 -> 16554 | G40: =G33*G37 -> 16020 | H40: =H33*H37 -> 16554 | I40: =I33*I37 -> 16020 | J40: =J33*J37 -> 16554 | K40: =K33*K37 -> 16554 | ... O40: =O33*O37 -> 16554
B41: Total | D41: =D40+D39+D38 -> 66216 | E41: =E40+E39+E38 -> 59808 | F41: =F40+F39+F38 -> 66216 | G41: =G40+G39+G38 -> 64080 | H41: =H40+H39+H38 -> 66216 | I41: =I40+I39+I38 -> 64080 | J41: =J40+J39+J38 -> 66216 | K41: =K40+K39+K38 -> 66216 | ... O41: =O40+O39+O38 -> 66216 | P41: =SUM(D41:O41) -> 779640
D42: 48580 | E42: 48611 | F42: 48639 | G42: 48670 | H42: 48700 | I42: 48731 | J42: 48761 | K42: 48792 | L42: 48823 | M42: 48853 | N42: 48884 | O42: 48914

Sheet A9P8
B1: CENTRALES ELECTRICAS DE NARIÑO S.A. E.S.P.
B2: CURVA DE ENERGIA DE REFERENCIA PARA OFERTAR MENSUAL
B3: ANEXO 9 PRODUCTO 8 - CUADRO DE CANTIDADES DE ENERGÍA
B4: AÑO 2034 MWh
B7: Franja | C7: Hora | D7: AÑO 2034 MWh
D8: 48945 | E8: 48976 | F8: 49004 | G8: 49035 | H8: 49065 | I8: 49096 | J8: 49126 | K8: 49157 | L8: 49188 | M8: 49218 | N8: 49249 | O8: 49279
B9: Baja | C9: 1 | D9: 90.1 | E9: 90.1 | F9: 90.1 | G9: 90.1 | H9: 90.1 | I9: 90.1 | J9: 90.1 | K9: 90.1 | L9: 90.1 | M9: 90.1 | N9: 90.1 | O9: 90.1
C10: 2 | D10: 90.1 | E10: 90.1 | F10: 90.1 | G10: 90.1 | H10: 90.1 | I10: 90.1 | J10: 90.1 | K10: 90.1 | L10: 90.1 | M10: 90.1 | N10: 90.1 | O10: 90.1
C11: 3 | D11: 90.1 | E11: 90.1 | F11: 90.1 | G11: 90.1 | H11: 90.1 | I11: 90.1 | J11: 90.1 | K11: 90.1 | L11: 90.1 | M11: 90.1 | N11: 90.1 | O11: 90.1
C12: 4 | D12: 90.1 | E12: 90.1 | F12: 90.1 | G12: 90.1 | H12: 90.1 | I12: 90.1 | J12: 90.1 | K12: 90.1 | L12: 90.1 | M12: 90.1 | N12: 90.1 | O12: 90.1
B13: Media | C13: 5 | D13: 90.1 | E13: 90.1 | F13: 90.1 | G13: 90.1 | H13: 90.1 | I13: 90.1 | J13: 90.1 | K13: 90.1 | L13: 90.1 | M13: 90.1 | N13: 90.1 | O13: 90.1
C14: 6 | D14: 90.1 | E14: 90.1 | F14: 90.1 | G14: 90.1 | H14: 90.1 | I14: 90.1 | J14: 90.1 | K14: 90.1 | L14: 90.1 | M14: 90.1 | N14: 90.1 | O14: 90.1
C15: 7 | D15: 90.1 | E15: 90.1 | F15: 90.1 | G15: 90.1 | H15: 90.1 | I15: 90.1 | J15: 90.1 | K15: 90.1 | L15: 90.1 | M15: 90.1 | N15: 90.1 | O15: 90.1
C16: 8 | D16: 90.1 | E16: 90.1 | F16: 90.1 | G16: 90.1 | H16: 90.1 | I16: 90.1 | J16: 90.1 | K16: 90.1 | L16: 90.1 | M16: 90.1 | N16: 90.1 | O16: 90.1
C17: 9 | D17: 90.1 | E17: 90.1 | F17: 90.1 | G17: 90.1 | H17: 90.1 | I17: 90.1 | J17: 90.1 | K17: 90.1 | L17: 90.1 | M17: 90.1 | N17: 90.1 | O17: 90.1
B18: Alta | C18: 10 | D18: 90.1 | E18: 90.1 | F18: 90.1 | G18: 90.1 | H18: 90.1 | I18: 90.1 | J18: 90.1 | K18: 90.1 | L18: 90.1 | M18: 90.1 | N18: 90.1 | O18: 90.1
C19: 11 | D19: 90.1 | E19: 90.1 | F19: 90.1 | G19: 90.1 | H19: 90.1 | I19: 90.1 | J19: 90.1 | K19: 90.1 | L19: 90.1 | M19: 90.1 | N19: 90.1 | O19: 90.1
C20: 12 | D20: 90.1 | E20: 90.1 | F20: 90.1 | G20: 90.1 | H20: 90.1 | I20: 90.1 | J20: 90.1 | K20: 90.1 | L20: 90.1 | M20: 90.1 | N20: 90.1 | O20: 90.1
B21: Media | C21: 13 | D21: 90.1 | E21: 90.1 | F21: 90.1 | G21: 90.1 | H21: 90.1 | I21: 90.1 | J21: 90.1 | K21: 90.1 | L21: 90.1 | M21: 90.1 | N21: 90.1 | O21: 90.1
C22: 14 | D22: 90.1 | E22: 90.1 | F22: 90.1 | G22: 90.1 | H22: 90.1 | I22: 90.1 | J22: 90.1 | K22: 90.1 | L22: 90.1 | M22: 90.1 | N22: 90.1 | O22: 90.1
C23: 15 | D23: 90.1 | E23: 90.1 | F23: 90.1 | G23: 90.1 | H23: 90.1 | I23: 90.1 | J23: 90.1 | K23: 90.1 | L23: 90.1 | M23: 90.1 | N23: 90.1 | O23: 90.1
C24: 16 | D24: 90.1 | E24: 90.1 | F24: 90.1 | G24: 90.1 | H24: 90.1 | I24: 90.1 | J24: 90.1 | K24: 90.1 | L24: 90.1 | M24: 90.1 | N24: 90.1 | O24: 90.1
C25: 17 | D25: 90.1 | E25: 90.1 | F25: 90.1 | G25: 90.1 | H25: 90.1 | I25: 90.1 | J25: 90.1 | K25: 90.1 | L25: 90.1 | M25: 90.1 | N25: 90.1 | O25: 90.1
C26: 18 | D26: 90.1 | E26: 90.1 | F26: 90.1 | G26: 90.1 | H26: 90.1 | I26: 90.1 | J26: 90.1 | K26: 90.1 | L26: 90.1 | M26: 90.1 | N26: 90.1 | O26: 90.1
B27: Alta | C27: 19 | D27: 90.1 | E27: 90.1 | F27: 90.1 | G27: 90.1 | H27: 90.1 | I27: 90.1 | J27: 90.1 | K27: 90.1 | L27: 90.1 | M27: 90.1 | N27: 90.1 | O27: 90.1
C28: 20 | D28: 90.1 | E28: 90.1 | F28: 90.1 | G28: 90.1 | H28: 90.1 | I28: 90.1 | J28: 90.1 | K28: 90.1 | L28: 90.1 | M28: 90.1 | N28: 90.1 | O28: 90.1
C29: 21 | D29: 90.1 | E29: 90.1 | F29: 90.1 | G29: 90.1 | H29: 90.1 | I29: 90.1 | J29: 90.1 | K29: 90.1 | L29: 90.1 | M29: 90.1 | N29: 90.1 | O29: 90.1
B30: Media | C30: 22 | D30: 90.1 | E30: 90.1 | F30: 90.1 | G30: 90.1 | H30: 90.1 | I30: 90.1 | J30: 90.1 | K30: 90.1 | L30: 90.1 | M30: 90.1 | N30: 90.1 | O30: 90.1
C31: 23 | D31: 90.1 | E31: 90.1 | F31: 90.1 | G31: 90.1 | H31: 90.1 | I31: 90.1 | J31: 90.1 | K31: 90.1 | L31: 90.1 | M31: 90.1 | N31: 90.1 | O31: 90.1
B32: Baja | C32: 24 | D32: 90.1 | E32: 90.1 | F32: 90.1 | G32: 90.1 | H32: 90.1 | I32: 90.1 | J32: 90.1 | K32: 90.1 | L32: 90.1 | M32: 90.1 | N32: 90.1 | O32: 90.1
B33: Días | D33: 31 | E33: 28 | F33: 31 | G33: 30 | H33: 31 | I33: 30 | J33: 31 | K33: 31 | L33: 30 | M33: 31 | N33: 30 | O33: 31
B34: Resúmen Periodo Año 2034 MWh
B35: Baja | D35: =(SUM(D9:D12)+D32) -> 450.5 | E35: =(SUM(E9:E12)+E32) -> 450.5 | F35: =(SUM(F9:F12)+F32) -> 450.5 | G35: =(SUM(G9:G12)+G32) -> 450.5 | H35: =(SUM(H9:H12)+H32) -> 450.5 | I35: =(SUM(I9:I12)+I32) -> 450.5 | J35: =(SUM(J9:J12)+J32) -> 450.5 | K35: =(SUM(K9:K12)+K32) -> 450.5 | ... O35: =(SUM(O9:O12)+O32) -> 450.5
B36: Media | D36: =(SUM(D13:D17)+SUM(D21:D26)+D30+D31) -> 1171.3 | E36: =(SUM(E13:E17)+SUM(E21:E26)+E30+E31) -> 1171.3 | F36: =(SUM(F13:F17)+SUM(F21:F26)+F30+F31) -> 1171.3 | G36: =(SUM(G13:G17)+SUM(G21:G26)+G30+G31) -> 1171.3 | H36: =(SUM(H13:H17)+SUM(H21:H26)+H30+H31) -> 1171.3 | I36: =(SUM(I13:I17)+SUM(I21:I26)+I30+I31) -> 1171.3 | J36: =(SUM(J13:J17)+SUM(J21:J26)+J30+J31) -> 1171.3 | K36: =(SUM(K13:K17)+SUM(K21:K26)+K30+K31) -> 1171.3 | ... O36: =(SUM(O13:O17)+SUM(O21:O26)+O30+O31) -> 1171.3
B37: Alta | D37: =(SUM(D18:D20)+SUM(D27:D29)) -> 540.6 | E37: =(SUM(E18:E20)+SUM(E27:E29)) -> 540.6 | F37: =(SUM(F18:F20)+SUM(F27:F29)) -> 540.6 | G37: =(SUM(G18:G20)+SUM(G27:G29)) -> 540.6 | H37: =(SUM(H18:H20)+SUM(H27:H29)) -> 540.6 | I37: =(SUM(I18:I20)+SUM(I27:I29)) -> 540.6 | J37: =(SUM(J18:J20)+SUM(J27:J29)) -> 540.6 | K37: =(SUM(K18:K20)+SUM(K27:K29)) -> 540.6 | ... O37: =(SUM(O18:O20)+SUM(O27:O29)) -> 540.6
B38: Subtotal Baja | D38: =D35*D33 -> 13965.5 | E38: =E35*E33 -> 12614 | F38: =F35*F33 -> 13965.5 | G38: =G35*G33 -> 13515 | H38: =H35*H33 -> 13965.5 | I38: =I35*I33 -> 13515 | J38: =J35*J33 -> 13965.5 | K38: =K35*K33 -> 13965.5 | ... O38: =O35*O33 -> 13965.5
B39: Subtotal Media | D39: =D33*D36 -> 36310.3 | E39: =E33*E36 -> 32796.4 | F39: =F33*F36 -> 36310.3 | G39: =G33*G36 -> 35139 | H39: =H33*H36 -> 36310.3 | I39: =I33*I36 -> 35139 | J39: =J33*J36 -> 36310.3 | K39: =K33*K36 -> 36310.3 | ... O39: =O33*O36 -> 36310.3
B40: Subtotal Alta | D40: =D33*D37 -> 16758.6 | E40: =E33*E37 -> 15136.8 | F40: =F33*F37 -> 16758.6 | G40: =G33*G37 -> 16218 | H40: =H33*H37 -> 16758.6 | I40: =I33*I37 -> 16218 | J40: =J33*J37 -> 16758.6 | K40: =K33*K37 -> 16758.6 | ... O40: =O33*O37 -> 16758.6
B41: Total | D41: =D40+D39+D38 -> 67034.4 | E41: =E40+E39+E38 -> 60547.2 | F41: =F40+F39+F38 -> 67034.4 | G41: =G40+G39+G38 -> 64872 | H41: =H40+H39+H38 -> 67034.4 | I41: =I40+I39+I38 -> 64872 | J41: =J40+J39+J38 -> 67034.4 | K41: =K40+K39+K38 -> 67034.4 | ... O41: =O40+O39+O38 -> 67034.4 | P41: =SUM(D41:O41) -> 789276
D42: 48945 | E42: 48976 | F42: 49004 | G42: 49035 | H42: 49065 | I42: 49096 | J42: 49126 | K42: 49157 | L42: 49188 | M42: 49218 | N42: 49249 | O42: 49279

Sheet A10P9
B1: CENTRALES ELECTRICAS DE NARIÑO S.A. E.S.P.
B2: CURVA DE ENERGIA DE REFERENCIA PARA OFERTAR MENSUAL
B3: ANEXO 10 PRODUCTO 9 - CUADRO DE CANTIDADES DE ENERGÍA
B4: AÑO 2035 MWh
B7: Franja | C7: Hora | D7: AÑO 2035 MWh
D8: 49310 | E8: 49341 | F8: 49369 | G8: 49400 | H8: 49430 | I8: 49461 | J8: 49491 | K8: 49522 | L8: 49553 | M8: 49583 | N8: 49614 | O8: 49644
B9: Baja | C9: 1 | D9: 93.4 | E9: 93.4 | F9: 93.4 | G9: 93.4 | H9: 93.4 | I9: 93.4 | J9: 93.4 | K9: 93.4 | L9: 93.4 | M9: 93.4 | N9: 93.4 | O9: 93.4
C10: 2 | D10: 93.4 | E10: 93.4 | F10: 93.4 | G10: 93.4 | H10: 93.4 | I10: 93.4 | J10: 93.4 | K10: 93.4 | L10: 93.4 | M10: 93.4 | N10: 93.4 | O10: 93.4
C11: 3 | D11: 93.4 | E11: 93.4 | F11: 93.4 | G11: 93.4 | H11: 93.4 | I11: 93.4 | J11: 93.4 | K11: 93.4 | L11: 93.4 | M11: 93.4 | N11: 93.4 | O11: 93.4
C12: 4 | D12: 93.4 | E12: 93.4 | F12: 93.4 | G12: 93.4 | H12: 93.4 | I12: 93.4 | J12: 93.4 | K12: 93.4 | L12: 93.4 | M12: 93.4 | N12: 93.4 | O12: 93.4
B13: Media | C13: 5 | D13: 93.4 | E13: 93.4 | F13: 93.4 | G13: 93.4 | H13: 93.4 | I13: 93.4 | J13: 93.4 | K13: 93.4 | L13: 93.4 | M13: 93.4 | N13: 93.4 | O13: 93.4
C14: 6 | D14: 93.4 | E14: 93.4 | F14: 93.4 | G14: 93.4 | H14: 93.4 | I14: 93.4 | J14: 93.4 | K14: 93.4 | L14: 93.4 | M14: 93.4 | N14: 93.4 | O14: 93.4
C15: 7 | D15: 93.4 | E15: 93.4 | F15: 93.4 | G15: 93.4 | H15: 93.4 | I15: 93.4 | J15: 93.4 | K15: 93.4 | L15: 93.4 | M15: 93.4 | N15: 93.4 | O15: 93.4
C16: 8 | D16: 93.4 | E16: 93.4 | F16: 93.4 | G16: 93.4 | H16: 93.4 | I16: 93.4 | J16: 93.4 | K16: 93.4 | L16: 93.4 | M16: 93.4 | N16: 93.4 | O16: 93.4
C17: 9 | D17: 93.4 | E17: 93.4 | F17: 93.4 | G17: 93.4 | H17: 93.4 | I17: 93.4 | J17: 93.4 | K17: 93.4 | L17: 93.4 | M17: 93.4 | N17: 93.4 | O17: 93.4
B18: Alta | C18: 10 | D18: 93.4 | E18: 93.4 | F18: 93.4 | G18: 93.4 | H18: 93.4 | I18: 93.4 | J18: 93.4 | K18: 93.4 | L18: 93.4 | M18: 93.4 | N18: 93.4 | O18: 93.4
C19: 11 | D19: 93.4 | E19: 93.4 | F19: 93.4 | G19: 93.4 | H19: 93.4 | I19: 93.4 | J19: 93.4 | K19: 93.4 | L19: 93.4 | M19: 93.4 | N19: 93.4 | O19: 93.4
C20: 12 | D20: 93.4 | E20: 93.4 | F20: 93.4 | G20: 93.4 | H20: 93.4 | I20: 93.4 | J20: 93.4 | K20: 93.4 | L20: 93.4 | M20: 93.4 | N20: 93.4 | O20: 93.4
B21: Media | C21: 13 | D21: 93.4 | E21: 93.4 | F21: 93.4 | G21: 93.4 | H21: 93.4 | I21: 93.4 | J21: 93.4 | K21: 93.4 | L21: 93.4 | M21: 93.4 | N21: 93.4 | O21: 93.4
C22: 14 | D22: 93.4 | E22: 93.4 | F22: 93.4 | G22: 93.4 | H22: 93.4 | I22: 93.4 | J22: 93.4 | K22: 93.4 | L22: 93.4 | M22: 93.4 | N22: 93.4 | O22: 93.4
C23: 15 | D23: 93.4 | E23: 93.4 | F23: 93.4 | G23: 93.4 | H23: 93.4 | I23: 93.4 | J23: 93.4 | K23: 93.4 | L23: 93.4 | M23: 93.4 | N23: 93.4 | O23: 93.4
C24: 16 | D24: 93.4 | E24: 93.4 | F24: 93.4 | G24: 93.4 | H24: 93.4 | I24: 93.4 | J24: 93.4 | K24: 93.4 | L24: 93.4 | M24: 93.4 | N24: 93.4 | O24: 93.4
C25: 17 | D25: 93.4 | E25: 93.4 | F25: 93.4 | G25: 93.4 | H25: 93.4 | I25: 93.4 | J25: 93.4 | K25: 93.4 | L25: 93.4 | M25: 93.4 | N25: 93.4 | O25: 93.4
C26: 18 | D26: 93.4 | E26: 93.4 | F26: 93.4 | G26: 93.4 | H26: 93.4 | I26: 93.4 | J26: 93.4 | K26: 93.4 | L26: 93.4 | M26: 93.4 | N26: 93.4 | O26: 93.4
B27: Alta | C27: 19 | D27: 93.4 | E27: 93.4 | F27: 93.4 | G27: 93.4 | H27: 93.4 | I27: 93.4 | J27: 93.4 | K27: 93.4 | L27: 93.4 | M27: 93.4 | N27: 93.4 | O27: 93.4
C28: 20 | D28: 93.4 | E28: 93.4 | F28: 93.4 | G28: 93.4 | H28: 93.4 | I28: 93.4 | J28: 93.4 | K28: 93.4 | L28: 93.4 | M28: 93.4 | N28: 93.4 | O28: 93.4
C29: 21 | D29: 93.4 | E29: 93.4 | F29: 93.4 | G29: 93.4 | H29: 93.4 | I29: 93.4 | J29: 93.4 | K29: 93.4 | L29: 93.4 | M29: 93.4 | N29: 93.4 | O29: 93.4
B30: Media | C30: 22 | D30: 93.4 | E30: 93.4 | F30: 93.4 | G30: 93.4 | H30: 93.4 | I30: 93.4 | J30: 93.4 | K30: 93.4 | L30: 93.4 | M30: 93.4 | N30: 93.4 | O30: 93.4
C31: 23 | D31: 93.4 | E31: 93.4 | F31: 93.4 | G31: 93.4 | H31: 93.4 | I31: 93.4 | J31: 93.4 | K31: 93.4 | L31: 93.4 | M31: 93.4 | N31: 93.4 | O31: 93.4
B32: Baja | C32: 24 | D32: 93.4 | E32: 93.4 | F32: 93.4 | G32: 93.4 | H32: 93.4 | I32: 93.4 | J32: 93.4 | K32: 93.4 | L32: 93.4 | M32: 93.4 | N32: 93.4 | O32: 93.4
B33: Días | D33: 31 | E33: 28 | F33: 31 | G33: 30 | H33: 31 | I33: 30 | J33: 31 | K33: 31 | L33: 30 | M33: 31 | N33: 30 | O33: 31
B34: Resúmen Periodo Año 2035 MWh
B35: Baja | D35: =(SUM(D9:D12)+D32) -> 467 | E35: =(SUM(E9:E12)+E32) -> 467 | F35: =(SUM(F9:F12)+F32) -> 467 | G35: =(SUM(G9:G12)+G32) -> 467 | H35: =(SUM(H9:H12)+H32) -> 467 | I35: =(SUM(I9:I12)+I32) -> 467 | J35: =(SUM(J9:J12)+J32) -> 467 | K35: =(SUM(K9:K12)+K32) -> 467 | ... O35: =(SUM(O9:O12)+O32) -> 467
B36: Media | D36: =(SUM(D13:D17)+SUM(D21:D26)+D30+D31) -> 1214.2 | E36: =(SUM(E13:E17)+SUM(E21:E26)+E30+E31) -> 1214.2 | F36: =(SUM(F13:F17)+SUM(F21:F26)+F30+F31) -> 1214.2 | G36: =(SUM(G13:G17)+SUM(G21:G26)+G30+G31) -> 1214.2 | H36: =(SUM(H13:H17)+SUM(H21:H26)+H30+H31) -> 1214.2 | I36: =(SUM(I13:I17)+SUM(I21:I26)+I30+I31) -> 1214.2 | J36: =(SUM(J13:J17)+SUM(J21:J26)+J30+J31) -> 1214.2 | K36: =(SUM(K13:K17)+SUM(K21:K26)+K30+K31) -> 1214.2 | ... O36: =(SUM(O13:O17)+SUM(O21:O26)+O30+O31) -> 1214.2
B37: Alta | D37: =(SUM(D18:D20)+SUM(D27:D29)) -> 560.4 | E37: =(SUM(E18:E20)+SUM(E27:E29)) -> 560.4 | F37: =(SUM(F18:F20)+SUM(F27:F29)) -> 560.4 | G37: =(SUM(G18:G20)+SUM(G27:G29)) -> 560.4 | H37: =(SUM(H18:H20)+SUM(H27:H29)) -> 560.4 | I37: =(SUM(I18:I20)+SUM(I27:I29)) -> 560.4 | J37: =(SUM(J18:J20)+SUM(J27:J29)) -> 560.4 | K37: =(SUM(K18:K20)+SUM(K27:K29)) -> 560.4 | ... O37: =(SUM(O18:O20)+SUM(O27:O29)) -> 560.4
B38: Subtotal Baja | D38: =D35*D33 -> 14477 | E38: =E35*E33 -> 13076 | F38: =F35*F33 -> 14477 | G38: =G35*G33 -> 14010 | H38: =H35*H33 -> 14477 | I38: =I35*I33 -> 14010 | J38: =J35*J33 -> 14477 | K38: =K35*K33 -> 14477 | ... O38: =O35*O33 -> 14477
B39: Subtotal Media | D39: =D33*D36 -> 37640.2 | E39: =E33*E36 -> 33997.6 | F39: =F33*F36 -> 37640.2 | G39: =G33*G36 -> 36426 | H39: =H33*H36 -> 37640.2 | I39: =I33*I36 -> 36426 | J39: =J33*J36 -> 37640.2 | K39: =K33*K36 -> 37640.2 | ... O39: =O33*O36 -> 37640.2
B40: Subtotal Alta | D40: =D33*D37 -> 17372.4 | E40: =E33*E37 -> 15691.2 | F40: =F33*F37 -> 17372.4 | G40: =G33*G37 -> 16812 | H40: =H33*H37 -> 17372.4 | I40: =I33*I37 -> 16812 | J40: =J33*J37 -> 17372.4 | K40: =K33*K37 -> 17372.4 | ... O40: =O33*O37 -> 17372.4
B41: Total | D41: =D40+D39+D38 -> 69489.6 | E41: =E40+E39+E38 -> 62764.8 | F41: =F40+F39+F38 -> 69489.6 | G41: =G40+G39+G38 -> 67248 | H41: =H40+H39+H38 -> 69489.6 | I41: =I40+I39+I38 -> 67248 | J41: =J40+J39+J38 -> 69489.6 | K41: =K40+K39+K38 -> 69489.6 | ... O41: =O40+O39+O38 -> 69489.6 | P41: =SUM(D41:O41) -> 818184
D42: 49310 | E42: 49341 | F42: 49369 | G42: 49400 | H42: 49430 | I42: 49461 | J42: 49491 | K42: 49522 | L42: 49553 | M42: 49583 | N42: 49614 | O42: 49644

Sheet A11P10
B1: CENTRALES ELECTRICAS DE NARIÑO S.A. E.S.P.
B2: CURVA DE ENERGIA DE REFERENCIA PARA OFERTAR MENSUAL
