Workbook

Sheet OF P1 
C1: * La energia a ofertar debe ser expresada únicamente en kilovatio (kWh) redondeado a cero decimales - PLANA
C4: OFERTA PRODUCTO 1
C5: MES | D5: ENERGIA SOLICITADA (KWh) | E5: % | F5: ENERGIA OFERTADA (KWh) | G5: PRECIO $/kWh
C6: 46388 | D6: =+VLOOKUP(C6,'PLANA P1'!$A$4:$AD$55,30,FALSE) -> 29760000 | E6: % | G6: $/kWh
C7: 46419 | D7: =+VLOOKUP(C7,'PLANA P1'!$A$4:$AD$55,30,FALSE) -> 26880000 | E7: % | G7: $/kWh
C8: 46447 | D8: =+VLOOKUP(C8,'PLANA P1'!$A$4:$AD$55,30,FALSE) -> 29760000 | E8: % | G8: $/kWh
C9: 46478 | D9: =+VLOOKUP(C9,'PLANA P1'!$A$4:$AD$55,30,FALSE) -> 28800000 | E9: % | G9: $/kWh
C10: 46508 | D10: =+VLOOKUP(C10,'PLANA P1'!$A$4:$AD$55,30,FALSE) -> 29760000 | E10: % | G10: $/kWh
C11: 46539 | D11: =+VLOOKUP(C11,'PLANA P1'!$A$4:$AD$55,30,FALSE) -> 28800000 | E11: % | G11: $/kWh
C12: 46569 | D12: =+VLOOKUP(C12,'PLANA P1'!$A$4:$AD$55,30,FALSE) -> 29760000 | E12: % | G12: $/kWh
C13: 46600 | D13: =+VLOOKUP(C13,'PLANA P1'!$A$4:$AD$55,30,FALSE) -> 0 | E13: =+VLOOKUP(D13,'PLANA P1'!$A$4:$AD$55,30,FALSE) -> #N/A | F13: =+VLOOKUP(E13,'PLANA P1'!$A$4:$AD$55,30,FALSE) -> #N/A | G13: =+VLOOKUP(F13,'PLANA P1'!$A$4:$AD$55,30,FALSE) -> #N/A
C14: 46631 | D14: =+VLOOKUP(C14,'PLANA P1'!$A$4:$AD$55,30,FALSE) -> 0 | E14: =+VLOOKUP(D14,'PLANA P1'!$A$4:$AD$55,30,FALSE) -> #N/A | F14: =+VLOOKUP(E14,'PLANA P1'!$A$4:$AD$55,30,FALSE) -> #N/A | G14: =+VLOOKUP(F14,'PLANA P1'!$A$4:$AD$55,30,FALSE) -> #N/A
C15: 46661 | D15: =+VLOOKUP(C15,'PLANA P1'!$A$4:$AD$55,30,FALSE) -> 0 | E15: =+VLOOKUP(D15,'PLANA P1'!$A$4:$AD$55,30,FALSE) -> #N/A | F15: =+VLOOKUP(E15,'PLANA P1'!$A$4:$AD$55,30,FALSE) -> #N/A | G15: =+VLOOKUP(F15,'PLANA P1'!$A$4:$AD$55,30,FALSE) -> #N/A
C16: 46692 | D16: =+VLOOKUP(C16,'PLANA P1'!$A$4:$AD$55,30,FALSE) -> 0 | E16: =+VLOOKUP(D16,'PLANA P1'!$A$4:$AD$55,30,FALSE) -> #N/A | F16: =+VLOOKUP(E16,'PLANA P1'!$A$4:$AD$55,30,FALSE) -> #N/A | G16: =+VLOOKUP(F16,'PLANA P1'!$A$4:$AD$55,30,FALSE) -> #N/A
C17: 46722 | D17: =+VLOOKUP(C17,'PLANA P1'!$A$4:$AD$55,30,FALSE) -> 0 | E17: =+VLOOKUP(D17,'PLANA P1'!$A$4:$AD$55,30,FALSE) -> #N/A | F17: =+VLOOKUP(E17,'PLANA P1'!$A$4:$AD$55,30,FALSE) -> #N/A | G17: =+VLOOKUP(F17,'PLANA P1'!$A$4:$AD$55,30,FALSE) -> #N/A
D18: =SUM(D6:D17) -> 203520000

Sheet PLANA P1
A1: Curva de distribucion en kwh
A2: * La energia a ofertar debe ser expresada únicamente en kilovatio (kWh) redondeado a cero decimales
A4: TOTAL | C4: =+AD55 -> 203520000
A5: MES | B5: DÍA | C5: HORA 01 | D5: HORA 02 | E5: HORA 03 | F5: HORA 04 | G5: HORA 05 | H5: HORA 06 | I5: HORA 07 | J5: HORA 08 | K5: HORA 09 | L5: HORA 10 | M5: HORA 11 | N5: HORA 12 | O5: HORA 13 | P5: HORA 14 | Q5: HORA 15 | R5: HORA 16 | S5: HORA 17 | T5: HORA 18 | U5: HORA 19 | V5: HORA 20 | W5: HORA 21 | X5: HORA 22 | Y5: HORA 23 | Z5: HORA 24 | AA5: TOTAL DÍA | AB5: NUMERO DÍAS | AC5: TOTAL DÍA MES | AD5: TOTAL MES
A7: 46388 | B7: Hábil | C7: 40000 | D7: 40000 | E7: 40000 | F7: 40000 | G7: 40000 | H7: 40000 | I7: 40000 | J7: 40000 | K7: 40000 | L7: 40000 | M7: 40000 | N7: 40000 | O7: 40000 | P7: 40000 | Q7: 40000 | R7: 40000 | S7: 40000 | T7: 40000 | U7: 40000 | V7: 40000 | W7: 40000 | X7: 40000 | Y7: 40000 | Z7: 40000 | AA7: =SUM(C7:Z7) -> 960000 | AB7: 19 | AC7: =+AA7*AB7 -> 18240000 | AD7: =+SUM(AC7:AC10) -> 29760000
B8: Sábado | C8: 40000 | D8: 40000 | E8: 40000 | F8: 40000 | G8: 40000 | H8: 40000 | I8: 40000 | J8: 40000 | K8: 40000 | L8: 40000 | M8: 40000 | N8: 40000 | O8: 40000 | P8: 40000 | Q8: 40000 | R8: 40000 | S8: 40000 | T8: 40000 | U8: 40000 | V8: 40000 | W8: 40000 | X8: 40000 | Y8: 40000 | Z8: 40000 | AA8: =SUM(C8:Z8) -> 960000 | AB8: 5 | AC8: =+AA8*AB8 -> 4800000
B9: Domingo | C9: 40000 | D9: 40000 | E9: 40000 | F9: 40000 | G9: 40000 | H9: 40000 | I9: 40000 | J9: 40000 | K9: 40000 | L9: 40000 | M9: 40000 | N9: 40000 | O9: 40000 | P9: 40000 | Q9: 40000 | R9: 40000 | S9: 40000 | T9: 40000 | U9: 40000 | V9: 40000 | W9: 40000 | X9: 40000 | Y9: 40000 | Z9: 40000 | AA9: =SUM(C9:Z9) -> 960000 | AB9: 5 | AC9: =+AA9*AB9 -> 4800000
B10: Festivo | C10: 40000 | D10: 40000 | E10: 40000 | F10: 40000 | G10: 40000 | H10: 40000 | I10: 40000 | J10: 40000 | K10: 40000 | L10: 40000 | M10: 40000 | N10: 40000 | O10: 40000 | P10: 40000 | Q10: 40000 | R10: 40000 | S10: 40000 | T10: 40000 | U10: 40000 | V10: 40000 | W10: 40000 | X10: 40000 | Y10: 40000 | Z10: 40000 | AA10: =SUM(C10:Z10) -> 960000 | AB10: 2 | AC10: =+AA10*AB10 -> 1920000
A11: 46419 | B11: Hábil | C11: 40000 | D11: 40000 | E11: 40000 | F11: 40000 | G11: 40000 | H11: 40000 | I11: 40000 | J11: 40000 | K11: 40000 | L11: 40000 | M11: 40000 | N11: 40000 | O11: 40000 | P11: 40000 | Q11: 40000 | R11: 40000 | S11: 40000 | T11: 40000 | U11: 40000 | V11: 40000 | W11: 40000 | X11: 40000 | Y11: 40000 | Z11: 40000 | AA11: =SUM(C11:Z11) -> 960000 | AB11: 20 | AC11: =+AA11*AB11 -> 19200000 | AD11: =+SUM(AC11:AC14) -> 26880000
B12: Sábado | C12: 40000 | D12: 40000 | E12: 40000 | F12: 40000 | G12: 40000 | H12: 40000 | I12: 40000 | J12: 40000 | K12: 40000 | L12: 40000 | M12: 40000 | N12: 40000 | O12: 40000 | P12: 40000 | Q12: 40000 | R12: 40000 | S12: 40000 | T12: 40000 | U12: 40000 | V12: 40000 | W12: 40000 | X12: 40000 | Y12: 40000 | Z12: 40000 | AA12: =SUM(C12:Z12) -> 960000 | AB12: 4 | AC12: =+AA12*AB12 -> 3840000
B13: Domingo | C13: 40000 | D13: 40000 | E13: 40000 | F13: 40000 | G13: 40000 | H13: 40000 | I13: 40000 | J13: 40000 | K13: 40000 | L13: 40000 | M13: 40000 | N13: 40000 | O13: 40000 | P13: 40000 | Q13: 40000 | R13: 40000 | S13: 40000 | T13: 40000 | U13: 40000 | V13: 40000 | W13: 40000 | X13: 40000 | Y13: 40000 | Z13: 40000 | AA13: =SUM(C13:Z13) -> 960000 | AB13: 4 | AC13: =+AA13*AB13 -> 3840000
B14: Festivo | AA14: =SUM(C14:Z14) -> 0 | AB14: 0 | AC14: =+AA14*AB14 -> 0
A15: 46447 | B15: Hábil | C15: 40000 | D15: 40000 | E15: 40000 | F15: 40000 | G15: 40000 | H15: 40000 | I15: 40000 | J15: 40000 | K15: 40000 | L15: 40000 | M15: 40000 | N15: 40000 | O15: 40000 | P15: 40000 | Q15: 40000 | R15: 40000 | S15: 40000 | T15: 40000 | U15: 40000 | V15: 40000 | W15: 40000 | X15: 40000 | Y15: 40000 | Z15: 40000 | AA15: =SUM(C15:Z15) -> 960000 | AB15: 20 | AC15: =+AA15*AB15 -> 19200000 | AD15: =+SUM(AC15:AC18) -> 29760000
B16: Sábado | C16: 40000 | D16: 40000 | E16: 40000 | F16: 40000 | G16: 40000 | H16: 40000 | I16: 40000 | J16: 40000 | K16: 40000 | L16: 40000 | M16: 40000 | N16: 40000 | O16: 40000 | P16: 40000 | Q16: 40000 | R16: 40000 | S16: 40000 | T16: 40000 | U16: 40000 | V16: 40000 | W16: 40000 | X16: 40000 | Y16: 40000 | Z16: 40000 | AA16: =SUM(C16:Z16) -> 960000 | AB16: 4 | AC16: =+AA16*AB16 -> 3840000
B17: Domingo | C17: 40000 | D17: 40000 | E17: 40000 | F17: 40000 | G17: 40000 | H17: 40000 | I17: 40000 | J17: 40000 | K17: 40000 | L17: 40000 | M17: 40000 | N17: 40000 | O17: 40000 | P17: 40000 | Q17: 40000 | R17: 40000 | S17: 40000 | T17: 40000 | U17: 40000 | V17: 40000 | W17: 40000 | X17: 40000 | Y17: 40000 | Z17: 40000 | AA17: =SUM(C17:Z17) -> 960000 | AB17: 4 | AC17: =+AA17*AB17 -> 3840000
B18: Festivo | C18: 40000 | D18: 40000 | E18: 40000 | F18: 40000 | G18: 40000 | H18: 40000 | I18: 40000 | J18: 40000 | K18: 40000 | L18: 40000 | M18: 40000 | N18: 40000 | O18: 40000 | P18: 40000 | Q18: 40000 | R18: 40000 | S18: 40000 | T18: 40000 | U18: 40000 | V18: 40000 | W18: 40000 | X18: 40000 | Y18: 40000 | Z18: 40000 | AA18: =SUM(C18:Z18) -> 960000 | AB18: 3 | AC18: =+AA18*AB18 -> 2880000
A19: 46478 | B19: Hábil | C19: 40000 | D19: 40000 | E19: 40000 | F19: 40000 | G19: 40000 | H19: 40000 | I19: 40000 | J19: 40000 | K19: 40000 | L19: 40000 | M19: 40000 | N19: 40000 | O19: 40000 | P19: 40000 | Q19: 40000 | R19: 40000 | S19: 40000 | T19: 40000 | U19: 40000 | V19: 40000 | W19: 40000 | X19: 40000 | Y19: 40000 | Z19: 40000 | AA19: =SUM(C19:Z19) -> 960000 | AB19: 22 | AC19: =+AA19*AB19 -> 21120000 | AD19: =+SUM(AC19:AC22) -> 28800000
B20: Sábado | C20: 40000 | D20: 40000 | E20: 40000 | F20: 40000 | G20: 40000 | H20: 40000 | I20: 40000 | J20: 40000 | K20: 40000 | L20: 40000 | M20: 40000 | N20: 40000 | O20: 40000 | P20: 40000 | Q20: 40000 | R20: 40000 | S20: 40000 | T20: 40000 | U20: 40000 | V20: 40000 | W20: 40000 | X20: 40000 | Y20: 40000 | Z20: 40000 | AA20: =SUM(C20:Z20) -> 960000 | AB20: 4 | AC20: =+AA20*AB20 -> 3840000
B21: Domingo | C21: 40000 | D21: 40000 | E21: 40000 | F21: 40000 | G21: 40000 | H21: 40000 | I21: 40000 | J21: 40000 | K21: 40000 | L21: 40000 | M21: 40000 | N21: 40000 | O21: 40000 | P21: 40000 | Q21: 40000 | R21: 40000 | S21: 40000 | T21: 40000 | U21: 40000 | V21: 40000 | W21: 40000 | X21: 40000 | Y21: 40000 | Z21: 40000 | AA21: =SUM(C21:Z21) -> 960000 | AB21: 4 | AC21: =+AA21*AB21 -> 3840000
B22: Festivo | AA22: =SUM(C22:Z22) -> 0 | AB22: 0 | AC22: =+AA22*AB22 -> 0
A23: 46508 | B23: Hábil | C23: 40000 | D23: 40000 | E23: 40000 | F23: 40000 | G23: 40000 | H23: 40000 | I23: 40000 | J23: 40000 | K23: 40000 | L23: 40000 | M23: 40000 | N23: 40000 | O23: 40000 | P23: 40000 | Q23: 40000 | R23: 40000 | S23: 40000 | T23: 40000 | U23: 40000 | V23: 40000 | W23: 40000 | X23: 40000 | Y23: 40000 | Z23: 40000 | AA23: =SUM(C23:Z23) -> 960000 | AB23: 19 | AC23: =+AA23*AB23 -> 18240000 | AD23: =+SUM(AC23:AC26) -> 29760000
B24: Sábado | C24: 40000 | D24: 40000 | E24: 40000 | F24: 40000 | G24: 40000 | H24: 40000 | I24: 40000 | J24: 40000 | K24: 40000 | L24: 40000 | M24: 40000 | N24: 40000 | O24: 40000 | P24: 40000 | Q24: 40000 | R24: 40000 | S24: 40000 | T24: 40000 | U24: 40000 | V24: 40000 | W24: 40000 | X24: 40000 | Y24: 40000 | Z24: 40000 | AA24: =SUM(C24:Z24) -> 960000 | AB24: 4 | AC24: =+AA24*AB24 -> 3840000
B25: Domingo | C25: 40000 | D25: 40000 | E25: 40000 | F25: 40000 | G25: 40000 | H25: 40000 | I25: 40000 | J25: 40000 | K25: 40000 | L25: 40000 | M25: 40000 | N25: 40000 | O25: 40000 | P25: 40000 | Q25: 40000 | R25: 40000 | S25: 40000 | T25: 40000 | U25: 40000 | V25: 40000 | W25: 40000 | X25: 40000 | Y25: 40000 | Z25: 40000 | AA25: =SUM(C25:Z25) -> 960000 | AB25: 5 | AC25: =+AA25*AB25 -> 4800000
B26: Festivo | C26: 40000 | D26: 40000 | E26: 40000 | F26: 40000 | G26: 40000 | H26: 40000 | I26: 40000 | J26: 40000 | K26: 40000 | L26: 40000 | M26: 40000 | N26: 40000 | O26: 40000 | P26: 40000 | Q26: 40000 | R26: 40000 | S26: 40000 | T26: 40000 | U26: 40000 | V26: 40000 | W26: 40000 | X26: 40000 | Y26: 40000 | Z26: 40000 | AA26: =SUM(C26:Z26) -> 960000 | AB26: 3 | AC26: =+AA26*AB26 -> 2880000
A27: 46539 | B27: Hábil | C27: 40000 | D27: 40000 | E27: 40000 | F27: 40000 | G27: 40000 | H27: 40000 | I27: 40000 | J27: 40000 | K27: 40000 | L27: 40000 | M27: 40000 | N27: 40000 | O27: 40000 | P27: 40000 | Q27: 40000 | R27: 40000 | S27: 40000 | T27: 40000 | U27: 40000 | V27: 40000 | W27: 40000 | X27: 40000 | Y27: 40000 | Z27: 40000 | AA27: =SUM(C27:Z27) -> 960000 | AB27: 21 | AC27: =+AA27*AB27 -> 20160000 | AD27: =+SUM(AC27:AC30) -> 28800000
B28: Sábado | C28: 40000 | D28: 40000 | E28: 40000 | F28: 40000 | G28: 40000 | H28: 40000 | I28: 40000 | J28: 40000 | K28: 40000 | L28: 40000 | M28: 40000 | N28: 40000 | O28: 40000 | P28: 40000 | Q28: 40000 | R28: 40000 | S28: 40000 | T28: 40000 | U28: 40000 | V28: 40000 | W28: 40000 | X28: 40000 | Y28: 40000 | Z28: 40000 | AA28: =SUM(C28:Z28) -> 960000 | AB28: 4 | AC28: =+AA28*AB28 -> 3840000
B29: Domingo | C29: 40000 | D29: 40000 | E29: 40000 | F29: 40000 | G29: 40000 | H29: 40000 | I29: 40000 | J29: 40000 | K29: 40000 | L29: 40000 | M29: 40000 | N29: 40000 | O29: 40000 | P29: 40000 | Q29: 40000 | R29: 40000 | S29: 40000 | T29: 40000 | U29: 40000 | V29: 40000 | W29: 40000 | X29: 40000 | Y29: 40000 | Z29: 40000 | AA29: =SUM(C29:Z29) -> 960000 | AB29: 4 | AC29: =+AA29*AB29 -> 3840000
B30: Festivo | C30: 40000 | D30: 40000 | E30: 40000 | F30: 40000 | G30: 40000 | H30: 40000 | I30: 40000 | J30: 40000 | K30: 40000 | L30: 40000 | M30: 40000 | N30: 40000 | O30: 40000 | P30: 40000 | Q30: 40000 | R30: 40000 | S30: 40000 | T30: 40000 | U30: 40000 | V30: 40000 | W30: 40000 | X30: 40000 | Y30: 40000 | Z30: 40000 | AA30: =SUM(C30:Z30) -> 960000 | AB30: 1 | AC30: =+AA30*AB30 -> 960000
A31: 46569 | B31: Hábil | C31: 40000 | D31: 40000 | E31: 40000 | F31: 40000 | G31: 40000 | H31: 40000 | I31: 40000 | J31: 40000 | K31: 40000 | L31: 40000 | M31: 40000 | N31: 40000 | O31: 40000 | P31: 40000 | Q31: 40000 | R31: 40000 | S31: 40000 | T31: 40000 | U31: 40000 | V31: 40000 | W31: 40000 | X31: 40000 | Y31: 40000 | Z31: 40000 | AA31: =SUM(C31:Z31) -> 960000 | AB31: 20 | AC31: =+AA31*AB31 -> 19200000 | AD31: =+SUM(AC31:AC34) -> 29760000
B32: Sábado | C32: 40000 | D32: 40000 | E32: 40000 | F32: 40000 | G32: 40000 | H32: 40000 | I32: 40000 | J32: 40000 | K32: 40000 | L32: 40000 | M32: 40000 | N32: 40000 | O32: 40000 | P32: 40000 | Q32: 40000 | R32: 40000 | S32: 40000 | T32: 40000 | U32: 40000 | V32: 40000 | W32: 40000 | X32: 40000 | Y32: 40000 | Z32: 40000 | AA32: =SUM(C32:Z32) -> 960000 | AB32: 5 | AC32: =+AA32*AB32 -> 4800000
B33: Domingo | C33: 40000 | D33: 40000 | E33: 40000 | F33: 40000 | G33: 40000 | H33: 40000 | I33: 40000 | J33: 40000 | K33: 40000 | L33: 40000 | M33: 40000 | N33: 40000 | O33: 40000 | P33: 40000 | Q33: 40000 | R33: 40000 | S33: 40000 | T33: 40000 | U33: 40000 | V33: 40000 | W33: 40000 | X33: 40000 | Y33: 40000 | Z33: 40000 | AA33: =SUM(C33:Z33) -> 960000 | AB33: 4 | AC33: =+AA33*AB33 -> 3840000
B34: Festivo | C34: 40000 | D34: 40000 | E34: 40000 | F34: 40000 | G34: 40000 | H34: 40000 | I34: 40000 | J34: 40000 | K34: 40000 | L34: 40000 | M34: 40000 | N34: 40000 | O34: 40000 | P34: 40000 | Q34: 40000 | R34: 40000 | S34: 40000 | T34: 40000 | U34: 40000 | V34: 40000 | W34: 40000 | X34: 40000 | Y34: 40000 | Z34: 40000 | AA34: =SUM(C34:Z34) -> 960000 | AB34: 2 | AC34: =+AA34*AB34 -> 1920000
A35: 46600 | B35: Hábil | C35: 0 | D35: 0 | E35: 0 | F35: 0 | G35: 0 | H35: 0 | I35: 0 | J35: 0 | K35: 0 | L35: 0 | M35: 0 | N35: 0 | O35: 0 | P35: 0 | Q35: 0 | R35: 0 | S35: 0 | T35: 0 | U35: 0 | V35: 0 | W35: 0 | X35: 0 | Y35: 0 | Z35: 0 | AA35: =SUM(C35:Z35) -> 0 | AB35: 21 | AC35: =+AA35*AB35 -> 0 | AD35: =+SUM(AC35:AC38) -> 0
B36: Sábado | C36: 0 | D36: 0 | E36: 0 | F36: 0 | G36: 0 | H36: 0 | I36: 0 | J36: 0 | K36: 0 | L36: 0 | M36: 0 | N36: 0 | O36: 0 | P36: 0 | Q36: 0 | R36: 0 | S36: 0 | T36: 0 | U36: 0 | V36: 0 | W36: 0 | X36: 0 | Y36: 0 | Z36: 0 | AA36: =SUM(C36:Z36) -> 0 | AB36: 3 | AC36: =+AA36*AB36 -> 0
B37: Domingo | C37: 0 | D37: 0 | E37: 0 | F37: 0 | G37: 0 | H37: 0 | I37: 0 | J37: 0 | K37: 0 | L37: 0 | M37: 0 | N37: 0 | O37: 0 | P37: 0 | Q37: 0 | R37: 0 | S37: 0 | T37: 0 | U37: 0 | V37: 0 | W37: 0 | X37: 0 | Y37: 0 | Z37: 0 | AA37: =SUM(C37:Z37) -> 0 | AB37: 5 | AC37: =+AA37*AB37 -> 0
B38: Festivo | C38: 0 | D38: 0 | E38: 0 | F38: 0 | G38: 0 | H38: 0 | I38: 0 | J38: 0 | K38: 0 | L38: 0 | M38: 0 | N38: 0 | O38: 0 | P38: 0 | Q38: 0 | R38: 0 | S38: 0 | T38: 0 | U38: 0 | V38: 0 | W38: 0 | X38: 0 | Y38: 0 | Z38: 0 | AA38: =SUM(C38:Z38) -> 0 | AB38: 2 | AC38: =+AA38*AB38 -> 0
A39: 46631 | B39: Hábil | C39: 0 | D39: 0 | E39: 0 | F39: 0 | G39: 0 | H39: 0 | I39: 0 | J39: 0 | K39: 0 | L39: 0 | M39: 0 | N39: 0 | O39: 0 | P39: 0 | Q39: 0 | R39: 0 | S39: 0 | T39: 0 | U39: 0 | V39: 0 | W39: 0 | X39: 0 | Y39: 0 | Z39: 0 | AA39: =SUM(C39:Z39) -> 0 | AB39: 22 | AC39: =+AA39*AB39 -> 0 | AD39: =+SUM(AC39:AC42) -> 0
B40: Sábado | C40: 0 | D40: 0 | E40: 0 | F40: 0 | G40: 0 | H40: 0 | I40: 0 | J40: 0 | K40: 0 | L40: 0 | M40: 0 | N40: 0 | O40: 0 | P40: 0 | Q40: 0 | R40: 0 | S40: 0 | T40: 0 | U40: 0 | V40: 0 | W40: 0 | X40: 0 | Y40: 0 | Z40: 0 | AA40: =SUM(C40:Z40) -> 0 | AB40: 4 | AC40: =+AA40*AB40 -> 0
B41: Domingo | C41: 0 | D41: 0 | E41: 0 | F41: 0 | G41: 0 | H41: 0 | I41: 0 | J41: 0 | K41: 0 | L41: 0 | M41: 0 | N41: 0 | O41: 0 | P41: 0 | Q41: 0 | R41: 0 | S41: 0 | T41: 0 | U41: 0 | V41: 0 | W41: 0 | X41: 0 | Y41: 0 | Z41: 0 | AA41: =SUM(C41:Z41) -> 0 | AB41: 4 | AC41: =+AA41*AB41 -> 0
B42: Festivo | C42: 0 | D42: 0 | E42: 0 | F42: 0 | G42: 0 | H42: 0 | I42: 0 | J42: 0 | K42: 0 | L42: 0 | M42: 0 | N42: 0 | O42: 0 | P42: 0 | Q42: 0 | R42: 0 | S42: 0 | T42: 0 | U42: 0 | V42: 0 | W42: 0 | X42: 0 | Y42: 0 | Z42: 0 | AA42: =SUM(C42:Z42) -> 0 | AB42: 0 | AC42: =+AA42*AB42 -> 0
...
