Workbook

Sheet Cant. Requeridas Producto 1
A1: ANEXO 3 - CANTIDADES DE ENERGÍA SOLICITADA EN kWh
A2: PRODUCTO 1 - PAGUE LO CONTRATADO
A3: Periodo: 1 de enero 2027 a 31 diciembre de 2027
A4: CONVOCATORIA PÚBLICA N° CP-BIAC2026-003 - BIA ENERGY S.A.S. E.S.P.
A9: Mes | B9: Tipo de día | C9: H1 | D9: H2 | E9: H3 | F9: H4 | G9: H5 | H9: H6 | I9: H7 | J9: H8 | K9: H9 | L9: H10 | M9: H11 | N9: H12 | O9: H13 | P9: H14 | Q9: H15 | R9: H16 | S9: H17 | T9: H18 | U9: H19 | V9: H20 | W9: H21 | X9: H22 | Y9: H23 | Z9: H24 | AA9: TOTAL DÍA | AB9: DÍAS | AC9: TOTAL | AD9: TOTAL MES
A10: 46388 | B10: Ordinario | C10: 8016.624 | D10: 7688.576 | E10: 7505.092 | F10: 7430.08 | G10: 7544.656 | H10: 8028.832 | I10: 9714.964 | J10: 12190.22 | K10: 14261.072 | L10: 15659.56 | M10: 16797.34 | N10: 17482.08 | O10: 17252.144 | P10: 17311.084 | Q10: 17769.752 | R10: 17777.256 | S10: 17276.168 | T10: 16122.96 | U10: 15273.468 | V10: 14308.336 | W10: 13032.376 | X10: 11581.836 | Y10: 10037.104 | Z10: 8982.736 | AA10: =SUM(C10:Z10) -> 309044.32 | AB10: 19 | AC10: =AA10*AB10 -> 5871842 | AD10: =SUM(AC10:AC12) -> 8878036
A11: 46388 | B11: Sábado | C11: 8710.996 | D11: 8256.248 | E11: 8002.68 | F11: 7806.12 | G11: 7843.78 | H11: 7875.784 | I11: 9022.16 | J11: 11077.416 | K11: 13029.856 | L11: 14554.708 | M11: 15506.26 | N11: 15942.948 | O11: 15495.676 | P11: 15004.556 | Q11: 14667.492 | R11: 14585.732 | S11: 14410.536 | T11: 14138.236 | U11: 13810.272 | V11: 13087.284 | W11: 11973.276 | X11: 10720.668 | Y11: 9382.464 | Z11: 8421.896 | AA11: =SUM(C11:Z11) -> 283327.04 | AB11: 5 | AC11: =AA11*AB11 -> 1416635.2
A12: 46388 | B12: Festivo | C12: 7799.428 | D12: 7412.076 | E12: 7054.18 | F12: 6872.32 | G12: 6719.02 | H12: 6587.196 | I12: 6800.108 | J12: 7601.356 | K12: 8655.192 | L12: 10120.656 | M12: 11304.496 | N12: 11974.648 | O12: 12205.508 | P12: 12261.2 | Q12: 12176.5 | R12: 12117.532 | S12: 11830.868 | T12: 11543.812 | U12: 11383.12 | V12: 10815.952 | W12: 9897.832 | X12: 8843.492 | Y12: 7894.908 | Z12: 7208.432 | AA12: =SUM(C12:Z12) -> 227079.83 | AB12: 7 | AC12: =AA12*AB12 -> 1589558.8
A13: 46419 | B13: Ordinario | C13: 7587.162 | D13: 7276.688 | E13: 7103.0335 | F13: 7032.04 | G13: 7140.478 | H13: 7598.716 | I13: 9194.5195 | J13: 11537.173 | K13: 13497.086 | L13: 14820.655 | M13: 15897.483 | N13: 16545.54 | O13: 16327.922 | P13: 16383.704 | Q13: 16817.801 | R13: 16824.903 | S13: 16350.659 | T13: 15259.23 | U13: 14455.246 | V13: 13541.818 | W13: 12334.213 | X13: 10961.38 | Y13: 9499.402 | Z13: 8501.518 | AA13: =SUM(C13:Z13) -> 292488.37 | AB13: 20 | AC13: =AA13*AB13 -> 5849767.4 | AD13: =SUM(AC13:AC15) -> 7782022
A14: 46419 | B14: Sábado | C14: 8244.3355 | D14: 7813.949 | E14: 7573.965 | F14: 7387.935 | G14: 7423.5775 | H14: 7453.867 | I14: 8538.83 | J14: 10483.983 | K14: 12331.828 | L14: 13774.992 | M14: 14675.567 | N14: 15088.862 | O14: 14665.55 | P14: 14200.74 | Q14: 13881.734 | R14: 13804.353 | S14: 13638.543 | T14: 13380.831 | U14: 13070.436 | V14: 12386.18 | W14: 11331.851 | X14: 10146.346 | Y14: 8879.832 | Z14: 7970.723 | AA14: =SUM(C14:Z14) -> 268148.81 | AB14: 4 | AC14: =AA14*AB14 -> 1072595.2
A15: 46419 | B15: Festivo | C15: 7381.6015 | D15: 7015.0005 | E15: 6676.2775 | F15: 6504.16 | G15: 6359.0725 | H15: 6234.3105 | I15: 6435.8165 | J15: 7194.1405 | K15: 8191.521 | L15: 9578.478 | M15: 10698.898 | N15: 11333.149 | O15: 11551.641 | P15: 11604.35 | Q15: 11524.188 | R15: 11468.379 | S15: 11197.072 | T15: 10925.394 | U15: 10773.31 | V15: 10236.526 | W15: 9367.591 | X15: 8369.7335 | Y15: 7471.9665 | Z15: 6822.266 | AA15: =SUM(C15:Z15) -> 214914.84 | AB15: 4 | AC15: =AA15*AB15 -> 859659.36
A16: 46447 | B16: Ordinario | C16: 8016.624 | D16: 7688.576 | E16: 7505.092 | F16: 7430.08 | G16: 7544.656 | H16: 8028.832 | I16: 9714.964 | J16: 12190.22 | K16: 14261.072 | L16: 15659.56 | M16: 16797.34 | N16: 17482.08 | O16: 17252.144 | P16: 17311.084 | Q16: 17769.752 | R16: 17777.256 | S16: 17276.168 | T16: 16122.96 | U16: 15273.468 | V16: 14308.336 | W16: 13032.376 | X16: 11581.836 | Y16: 10037.104 | Z16: 8982.736 | AA16: =SUM(C16:Z16) -> 309044.32 | AB16: 20 | AC16: =AA16*AB16 -> 6180886.3 | AD16: =SUM(AC16:AC18) -> 8903753.3
A17: 46447 | B17: Sábado | C17: 8710.996 | D17: 8256.248 | E17: 8002.68 | F17: 7806.12 | G17: 7843.78 | H17: 7875.784 | I17: 9022.16 | J17: 11077.416 | K17: 13029.856 | L17: 14554.708 | M17: 15506.26 | N17: 15942.948 | O17: 15495.676 | P17: 15004.556 | Q17: 14667.492 | R17: 14585.732 | S17: 14410.536 | T17: 14138.236 | U17: 13810.272 | V17: 13087.284 | W17: 11973.276 | X17: 10720.668 | Y17: 9382.464 | Z17: 8421.896 | AA17: =SUM(C17:Z17) -> 283327.04 | AB17: 4 | AC17: =AA17*AB17 -> 1133308.2
A18: 46447 | B18: Festivo | C18: 7799.428 | D18: 7412.076 | E18: 7054.18 | F18: 6872.32 | G18: 6719.02 | H18: 6587.196 | I18: 6800.108 | J18: 7601.356 | K18: 8655.192 | L18: 10120.656 | M18: 11304.496 | N18: 11974.648 | O18: 12205.508 | P18: 12261.2 | Q18: 12176.5 | R18: 12117.532 | S18: 11830.868 | T18: 11543.812 | U18: 11383.12 | V18: 10815.952 | W18: 9897.832 | X18: 8843.492 | Y18: 7894.908 | Z18: 7208.432 | AA18: =SUM(C18:Z18) -> 227079.83 | AB18: 7 | AC18: =AA18*AB18 -> 1589558.8
A19: 46478 | B19: Ordinario | C19: 8589.24 | D19: 8237.76 | E19: 8041.17 | F19: 7960.8 | G19: 8083.56 | H19: 8602.32 | I19: 10408.89 | J19: 13060.95 | K19: 15279.72 | L19: 16778.1 | M19: 17997.15 | N19: 18730.8 | O19: 18484.44 | P19: 18547.59 | Q19: 19039.02 | R19: 19047.06 | S19: 18510.18 | T19: 17274.6 | U19: 16364.43 | V19: 15330.36 | W19: 13963.26 | X19: 12409.11 | Y19: 10754.04 | Z19: 9624.36 | AA19: =SUM(C19:Z19) -> 331118.91 | AB19: 22 | AC19: =AA19*AB19 -> 7284616 | AD19: =SUM(AC19:AC21) -> 9472074.1
A20: 46478 | B20: Sábado | C20: 9333.21 | D20: 8845.98 | E20: 8574.3 | F20: 8363.7 | G20: 8404.05 | H20: 8438.34 | I20: 9666.6 | J20: 11868.66 | K20: 13960.56 | L20: 15594.33 | M20: 16613.85 | N20: 17081.73 | O20: 16602.51 | P20: 16076.31 | Q20: 15715.17 | R20: 15627.57 | S20: 15439.86 | T20: 15148.11 | U20: 14796.72 | V20: 14022.09 | W20: 12828.51 | X20: 11486.43 | Y20: 10052.64 | Z20: 9023.46 | AA20: =SUM(C20:Z20) -> 303564.69 | AB20: 4 | AC20: =AA20*AB20 -> 1214258.8
A21: 46478 | B21: Festivo | C21: 8356.53 | D21: 7941.51 | E21: 7558.05 | F21: 7363.2 | G21: 7198.95 | H21: 7057.71 | I21: 7285.83 | J21: 8144.31 | K21: 9273.42 | L21: 10843.56 | M21: 12111.96 | N21: 12829.98 | O21: 13077.33 | P21: 13137 | Q21: 13046.25 | R21: 12983.07 | S21: 12675.93 | T21: 12368.37 | U21: 12196.2 | V21: 11588.52 | W21: 10604.82 | X21: 9475.17 | Y21: 8458.83 | Z21: 7723.32 | AA21: =SUM(C21:Z21) -> 243299.82 | AB21: 4 | AC21: =AA21*AB21 -> 973199.28
A22: 46508 | B22: Ordinario | C22: 5153.544 | D22: 4942.656 | E22: 4824.702 | F22: 4776.48 | G22: 4850.136 | H22: 5161.392 | I22: 6245.334 | J22: 7836.57 | K22: 9167.832 | L22: 10066.86 | M22: 10798.29 | N22: 11238.48 | O22: 11090.664 | P22: 11128.554 | Q22: 11423.412 | R22: 11428.236 | S22: 11106.108 | T22: 10364.76 | U22: 9818.658 | V22: 9198.216 | W22: 8377.956 | X22: 7445.466 | Y22: 6452.424 | Z22: 5774.616 | AA22: =SUM(C22:Z22) -> 198671.35 | AB22: 19 | AC22: =AA22*AB22 -> 3774755.6 | AD22: =SUM(AC22:AC24) -> 5671150
A23: 46508 | B23: Sábado | C23: 5599.926 | D23: 5307.588 | E23: 5144.58 | F23: 5018.22 | G23: 5042.43 | H23: 5063.004 | I23: 5799.96 | J23: 7121.196 | K23: 8376.336 | L23: 9356.598 | M23: 9968.31 | N23: 10249.038 | O23: 9961.506 | P23: 9645.786 | Q23: 9429.102 | R23: 9376.542 | S23: 9263.916 | T23: 9088.866 | U23: 8878.032 | V23: 8413.254 | W23: 7697.106 | X23: 6891.858 | Y23: 6031.584 | Z23: 5414.076 | AA23: =SUM(C23:Z23) -> 182138.81 | AB23: 4 | AC23: =AA23*AB23 -> 728555.26
A24: 46508 | B24: Festivo | C24: 5013.918 | D24: 4764.906 | E24: 4534.83 | F24: 4417.92 | G24: 4319.37 | H24: 4234.626 | I24: 4371.498 | J24: 4886.586 | K24: 5564.052 | L24: 6506.136 | M24: 7267.176 | N24: 7697.988 | O24: 7846.398 | P24: 7882.2 | Q24: 7827.75 | R24: 7789.842 | S24: 7605.558 | T24: 7421.022 | U24: 7317.72 | V24: 6953.112 | W24: 6362.892 | X24: 5685.102 | Y24: 5075.298 | Z24: 4633.992 | AA24: =SUM(C24:Z24) -> 145979.89 | AB24: 8 | AC24: =AA24*AB24 -> 1167839.1
A25: 46539 | B25: Ordinario | C25: 5439.852 | D25: 5217.248 | E25: 5092.741 | F25: 5041.84 | G25: 5119.588 | H25: 5448.136 | I25: 6592.297 | J25: 8271.935 | K25: 9677.156 | L25: 10626.13 | M25: 11398.195 | N25: 11862.84 | O25: 11706.812 | P25: 11746.807 | Q25: 12058.046 | R25: 12063.138 | S25: 11723.114 | T25: 10940.58 | U25: 10364.139 | V25: 9709.228 | W25: 8843.398 | X25: 7859.103 | Y25: 6810.892 | Z25: 6095.428 | AA25: =SUM(C25:Z25) -> 209708.64 | AB25: 21 | AC25: =AA25*AB25 -> 4403881.5 | AD25: =SUM(AC25:AC27) -> 5943361.5
A26: 46539 | B26: Sábado | C26: 5911.033 | D26: 5602.454 | E26: 5430.39 | F26: 5297.01 | G26: 5322.565 | H26: 5344.282 | I26: 6122.18 | J26: 7516.818 | K26: 8841.688 | L26: 9876.409 | M26: 10522.105 | N26: 10818.429 | O26: 10514.923 | P26: 10181.663 | Q26: 9952.941 | R26: 9897.461 | S26: 9778.578 | T26: 9593.803 | U26: 9371.256 | V26: 8880.657 | W26: 8124.723 | X26: 7274.739 | Y26: 6366.672 | Z26: 5714.858 | AA26: =SUM(C26:Z26) -> 192257.64 | AB26: 4 | AC26: =AA26*AB26 -> 769030.55
A27: 46539 | B27: Festivo | C27: 5292.469 | D27: 5029.623 | E27: 4786.765 | F27: 4663.36 | G27: 4559.335 | H27: 4469.883 | I27: 4614.359 | J27: 5158.063 | K27: 5873.166 | L27: 6867.588 | M27: 7670.908 | N27: 8125.654 | O27: 8282.309 | P27: 8320.1 | Q27: 8262.625 | R27: 8222.611 | S27: 8028.089 | T27: 7833.301 | U27: 7724.26 | V27: 7339.396 | W27: 6716.386 | X27: 6000.941 | Y27: 5357.259 | Z27: 4891.436 | AA27: =SUM(C27:Z27) -> 154089.89 | AB27: 5 | AC27: =AA27*AB27 -> 770449.43
A28: 46569 | B28: Ordinario | C28: 5153.544 | D28: 4942.656 | E28: 4824.702 | F28: 4776.48 | G28: 4850.136 | H28: 5161.392 | I28: 6245.334 | J28: 7836.57 | K28: 9167.832 | L28: 10066.86 | M28: 10798.29 | N28: 11238.48 | O28: 11090.664 | P28: 11128.554 | Q28: 11423.412 | R28: 11428.236 | S28: 11106.108 | T28: 10364.76 | U28: 9818.658 | V28: 9198.216 | W28: 8377.956 | X28: 7445.466 | Y28: 6452.424 | Z28: 5774.616 | AA28: =SUM(C28:Z28) -> 198671.35 | AB28: 20 | AC28: =AA28*AB28 -> 3973426.9 | AD28: =SUM(AC28:AC30) -> 5760000.3
A29: 46569 | B29: Sábado | C29: 5599.926 | D29: 5307.588 | E29: 5144.58 | F29: 5018.22 | G29: 5042.43 | H29: 5063.004 | I29: 5799.96 | J29: 7121.196 | K29: 8376.336 | L29: 9356.598 | M29: 9968.31 | N29: 10249.038 | O29: 9961.506 | P29: 9645.786 | Q29: 9429.102 | R29: 9376.542 | S29: 9263.916 | T29: 9088.866 | U29: 8878.032 | V29: 8413.254 | W29: 7697.106 | X29: 6891.858 | Y29: 6031.584 | Z29: 5414.076 | AA29: =SUM(C29:Z29) -> 182138.81 | AB29: 5 | AC29: =AA29*AB29 -> 910694.07
A30: 46569 | B30: Festivo | C30: 5013.918 | D30: 4764.906 | E30: 4534.83 | F30: 4417.92 | G30: 4319.37 | H30: 4234.626 | I30: 4371.498 | J30: 4886.586 | K30: 5564.052 | L30: 6506.136 | M30: 7267.176 | N30: 7697.988 | O30: 7846.398 | P30: 7882.2 | Q30: 7827.75 | R30: 7789.842 | S30: 7605.558 | T30: 7421.022 | U30: 7317.72 | V30: 6953.112 | W30: 6362.892 | X30: 5685.102 | Y30: 5075.298 | Z30: 4633.992 | AA30: =SUM(C30:Z30) -> 145979.89 | AB30: 6 | AC30: =AA30*AB30 -> 875879.35
A31: 46600 | B31: Ordinario | C31: 5153.544 | D31: 4942.656 | E31: 4824.702 | F31: 4776.48 | G31: 4850.136 | H31: 5161.392 | I31: 6245.334 | J31: 7836.57 | K31: 9167.832 | L31: 10066.86 | M31: 10798.29 | N31: 11238.48 | O31: 11090.664 | P31: 11128.554 | Q31: 11423.412 | R31: 11428.236 | S31: 11106.108 | T31: 10364.76 | U31: 9818.658 | V31: 9198.216 | W31: 8377.956 | X31: 7445.466 | Y31: 6452.424 | Z31: 5774.616 | AA31: =SUM(C31:Z31) -> 198671.35 | AB31: 21 | AC31: =AA31*AB31 -> 4172098.3 | AD31: =SUM(AC31:AC33) -> 5740374
A32: 46600 | B32: Sábado | C32: 5599.926 | D32: 5307.588 | E32: 5144.58 | F32: 5018.22 | G32: 5042.43 | H32: 5063.004 | I32: 5799.96 | J32: 7121.196 | K32: 8376.336 | L32: 9356.598 | M32: 9968.31 | N32: 10249.038 | O32: 9961.506 | P32: 9645.786 | Q32: 9429.102 | R32: 9376.542 | S32: 9263.916 | T32: 9088.866 | U32: 8878.032 | V32: 8413.254 | W32: 7697.106 | X32: 6891.858 | Y32: 6031.584 | Z32: 5414.076 | AA32: =SUM(C32:Z32) -> 182138.81 | AB32: 3 | AC32: =AA32*AB32 -> 546416.44
A33: 46600 | B33: Festivo | C33: 5013.918 | D33: 4764.906 | E33: 4534.83 | F33: 4417.92 | G33: 4319.37 | H33: 4234.626 | I33: 4371.498 | J33: 4886.586 | K33: 5564.052 | L33: 6506.136 | M33: 7267.176 | N33: 7697.988 | O33: 7846.398 | P33: 7882.2 | Q33: 7827.75 | R33: 7789.842 | S33: 7605.558 | T33: 7421.022 | U33: 7317.72 | V33: 6953.112 | W33: 6362.892 | X33: 5685.102 | Y33: 5075.298 | Z33: 4633.992 | AA33: =SUM(C33:Z33) -> 145979.89 | AB33: 7 | AC33: =AA33*AB33 -> 1021859.2
A34: 46631 | B34: Ordinario | C34: 5439.852 | D34: 5217.248 | E34: 5092.741 | F34: 5041.84 | G34: 5119.588 | H34: 5448.136 | I34: 6592.297 | J34: 8271.935 | K34: 9677.156 | L34: 10626.13 | M34: 11398.195 | N34: 11862.84 | O34: 11706.812 | P34: 11746.807 | Q34: 12058.046 | R34: 12063.138 | S34: 11723.114 | T34: 10940.58 | U34: 10364.139 | V34: 9709.228 | W34: 8843.398 | X34: 7859.103 | Y34: 6810.892 | Z34: 6095.428 | AA34: =SUM(C34:Z34) -> 209708.64 | AB34: 22 | AC34: =AA34*AB34 -> 4613590.1 | AD34: =SUM(AC34:AC36) -> 5998980.2
A35: 46631 | B35: Sábado | C35: 5911.033 | D35: 5602.454 | E35: 5430.39 | F35: 5297.01 | G35: 5322.565 | H35: 5344.282 | I35: 6122.18 | J35: 7516.818 | K35: 8841.688 | L35: 9876.409 | M35: 10522.105 | N35: 10818.429 | O35: 10514.923 | P35: 10181.663 | Q35: 9952.941 | R35: 9897.461 | S35: 9778.578 | T35: 9593.803 | U35: 9371.256 | V35: 8880.657 | W35: 8124.723 | X35: 7274.739 | Y35: 6366.672 | Z35: 5714.858 | AA35: =SUM(C35:Z35) -> 192257.64 | AB35: 4 | AC35: =AA35*AB35 -> 769030.55
A36: 46631 | B36: Festivo | C36: 5292.469 | D36: 5029.623 | E36: 4786.765 | F36: 4663.36 | G36: 4559.335 | H36: 4469.883 | I36: 4614.359 | J36: 5158.063 | K36: 5873.166 | L36: 6867.588 | M36: 7670.908 | N36: 8125.654 | O36: 8282.309 | P36: 8320.1 | Q36: 8262.625 | R36: 8222.611 | S36: 8028.089 | T36: 7833.301 | U36: 7724.26 | V36: 7339.396 | W36: 6716.386 | X36: 6000.941 | Y36: 5357.259 | Z36: 4891.436 | AA36: =SUM(C36:Z36) -> 154089.89 | AB36: 4 | AC36: =AA36*AB36 -> 616359.54
A37: 46661 | B37: Ordinario | C37: 4008.312 | D37: 3844.288 | E37: 3752.546 | F37: 3715.04 | G37: 3772.328 | H37: 4014.416 | I37: 4857.482 | J37: 6095.11 | K37: 7130.536 | L37: 7829.78 | M37: 8398.67 | N37: 8741.04 | O37: 8626.072 | P37: 8655.542 | Q37: 8884.876 | R37: 8888.628 | S37: 8638.084 | T37: 8061.48 | U37: 7636.734 | V37: 7154.168 | W37: 6516.188 | X37: 5790.918 | Y37: 5018.552 | Z37: 4491.368 | AA37: =SUM(C37:Z37) -> 154522.16 | AB37: 20 | AC37: =AA37*AB37 -> 3090443.2 | AD37: =SUM(AC37:AC39) -> 4480000.3
A38: 46661 | B38: Sábado | C38: 4355.498 | D38: 4128.124 | E38: 4001.34 | F38: 3903.06 | G38: 3921.89 | H38: 3937.892 | I38: 4511.08 | J38: 5538.708 | K38: 6514.928 | L38: 7277.354 | M38: 7753.13 | N38: 7971.474 | O38: 7747.838 | P38: 7502.278 | Q38: 7333.746 | R38: 7292.866 | S38: 7205.268 | T38: 7069.118 | U38: 6905.136 | V38: 6543.642 | W38: 5986.638 | X38: 5360.334 | Y38: 4691.232 | Z38: 4210.948 | AA38: =SUM(C38:Z38) -> 141663.52 | AB38: 5 | AC38: =AA38*AB38 -> 708317.61
A39: 46661 | B39: Festivo | C39: 3899.714 | D39: 3706.038 | E39: 3527.09 | F39: 3436.16 | G39: 3359.51 | H39: 3293.598 | I39: 3400.054 | J39: 3800.678 | K39: 4327.596 | L39: 5060.328 | M39: 5652.248 | N39: 5987.324 | O39: 6102.754 | P39: 6130.6 | Q39: 6088.25 | R39: 6058.766 | S39: 5915.434 | T39: 5771.906 | U39: 5691.56 | V39: 5407.976 | W39: 4948.916 | X39: 4421.746 | Y39: 3947.454 | Z39: 3604.216 | AA39: =SUM(C39:Z39) -> 113539.92 | AB39: 6 | AC39: =AA39*AB39 -> 681239.5
A40: 46692 | B40: Ordinario | C40: 4294.62 | D40: 4118.88 | E40: 4020.585 | F40: 3980.4 | G40: 4041.78 | H40: 4301.16 | I40: 5204.445 | J40: 6530.475 | K40: 7639.86 | L40: 8389.05 | M40: 8998.575 | N40: 9365.4 | O40: 9242.22 | P40: 9273.795 | Q40: 9519.51 | R40: 9523.53 | S40: 9255.09 | T40: 8637.3 | U40: 8182.215 | V40: 7665.18 | W40: 6981.63 | X40: 6204.555 | Y40: 5377.02 | Z40: 4812.18 | AA40: =SUM(C40:Z40) -> 165559.45 | AB40: 20 | AC40: =AA40*AB40 -> 3311189.1 | AD40: =SUM(AC40:AC42) -> 4648217.9
A41: 46692 | B41: Sábado | C41: 4666.605 | D41: 4422.99 | E41: 4287.15 | F41: 4181.85 | G41: 4202.025 | H41: 4219.17 | I41: 4833.3 | J41: 5934.33 | K41: 6980.28 | L41: 7797.165 | M41: 8306.925 | N41: 8540.865 | O41: 8301.255 | P41: 8038.155 | Q41: 7857.585 | R41: 7813.785 | S41: 7719.93 | T41: 7574.055 | U41: 7398.36 | V41: 7011.045 | W41: 6414.255 | X41: 5743.215 | Y41: 5026.32 | Z41: 4511.73 | AA41: =SUM(C41:Z41) -> 151782.35 | AB41: 4 | AC41: =AA41*AB41 -> 607129.38
A42: 46692 | B42: Festivo | C42: 4178.265 | D42: 3970.755 | E42: 3779.025 | F42: 3681.6 | G42: 3599.475 | H42: 3528.855 | I42: 3642.915 | J42: 4072.155 | K42: 4636.71 | L42: 5421.78 | M42: 6055.98 | N42: 6414.99 | O42: 6538.665 | P42: 6568.5 | Q42: 6523.125 | R42: 6491.535 | S42: 6337.965 | T42: 6184.185 | U42: 6098.1 | V42: 5794.26 | W42: 5302.41 | X42: 4737.585 | Y42: 4229.415 | Z42: 3861.66 | AA42: =SUM(C42:Z42) -> 121649.91 | AB42: 6 | AC42: =AA42*AB42 -> 729899.46
A43: 46722 | B43: Ordinario | C43: 4008.312 | D43: 3844.288 | E43: 3752.546 | F43: 3715.04 | G43: 3772.328 | H43: 4014.416 | I43: 4857.482 | J43: 6095.11 | K43: 7130.536 | L43: 7829.78 | M43: 8398.67 | N43: 8741.04 | O43: 8626.072 | P43: 8655.542 | Q43: 8884.876 | R43: 8888.628 | S43: 8638.084 | T43: 8061.48 | U43: 7636.734 | V43: 7154.168 | W43: 6516.188 | X43: 5790.918 | Y43: 5018.552 | Z43: 4491.368 | AA43: =SUM(C43:Z43) -> 154522.16 | AB43: 22 | AC43: =AA43*AB43 -> 3399487.5 | AD43: =SUM(AC43:AC45) -> 4505717.5
A44: 46722 | B44: Sábado | C44: 4355.498 | D44: 4128.124 | E44: 4001.34 | F44: 3903.06 | G44: 3921.89 | H44: 3937.892 | I44: 4511.08 | J44: 5538.708 | K44: 6514.928 | L44: 7277.354 | M44: 7753.13 | N44: 7971.474 | O44: 7747.838 | P44: 7502.278 | Q44: 7333.746 | R44: 7292.866 | S44: 7205.268 | T44: 7069.118 | U44: 6905.136 | V44: 6543.642 | W44: 5986.638 | X44: 5360.334 | Y44: 4691.232 | Z44: 4210.948 | AA44: =SUM(C44:Z44) -> 141663.52 | AB44: 3 | AC44: =AA44*AB44 -> 424990.57
...

Sheet Oferta Producto 1
A4: CONVOCATORIA PÚBLICA N° CP-BIAC2026-003 - BIA ENERGY S.A.S. E.S.P.
B5: ANEXO 4. FORMATO DE OFERTA - PRODUCTO 1
B6: NOMBRE DEL OFERENTE
B7: Precios y cantidades de la energía ofertada
B8: En pesos de marzo de 2026
B10: OPCIÓN 24 HORAS
B11: Mes | C11: E. Solicitada [kWh-mes] | D11: % E. Ofertada | E11: E. Ofertada [kWh-mes] | F11: $/kWh
B12: 46418 | C12: ='Cant. Requeridas Producto 1'!AD10 -> 8878036 | E12: =C12*$D$12 -> 0
B13: 46419 | C13: ='Cant. Requeridas Producto 1'!AD13 -> 7782022 | E13: =C13*$D$13 -> 0
B14: 46447 | C14: ='Cant. Requeridas Producto 1'!AD16 -> 8903753.3 | E14: =C14*$D$13 -> 0
B15: 46478 | C15: ='Cant. Requeridas Producto 1'!AD19 -> 9472074.1 | E15: =C15*$D$13 -> 0
B16: 46508 | C16: ='Cant. Requeridas Producto 1'!AD22 -> 5671150 | E16: =C16*$D$13 -> 0
B17: 46539 | C17: ='Cant. Requeridas Producto 1'!AD25 -> 5943361.5 | E17: =C17*$D$13 -> 0
B18: 46569 | C18: ='Cant. Requeridas Producto 1'!AD28 -> 5760000.3 | E18: =C18*$D$13 -> 0
B19: 46600 | C19: ='Cant. Requeridas Producto 1'!AD31 -> 5740374 | E19: =C19*$D$13 -> 0
B20: 46631 | C20: ='Cant. Requeridas Producto 1'!AD34 -> 5998980.2 | E20: =C20*$D$13 -> 0
B21: 46661 | C21: ='Cant. Requeridas Producto 1'!AD37 -> 4480000.3 | E21: =C21*$D$13 -> 0
B22: 46692 | C22: ='Cant. Requeridas Producto 1'!AD40 -> 4648217.9 | E22: =C22*$D$13 -> 0
B23: 46722 | C23: ='Cant. Requeridas Producto 1'!AD43 -> 4505717.5 | E23: =C23*$D$13 -> 0
B24: TOTAL | C24: =SUM(C12:C23) -> 77783687 | E24: =SUM(E12:E23) -> 0
B27: El oferente debe indicar si acepta adjudicaciones parciales o no
B28: • Para el periodo de 2027, se puede presentar oferta con diferente porcentaje cada mes, incluyendo el 0%
B29: • El precio ofertado podrá ser diferente para cada mes del producto, expresado en $/kWh, con hasta dos (2) decimales
B34: XXXXX
B35: XXXXXXXX S.A.S. E.S.P.

Sheet Cant. Requeridas Producto 2
A1: ANEXO 3 - CANTIDADES DE ENERGÍA SOLICITADA EN kWh
A2: PRODUCTO 2 - PAGUE LO CONTRATADO
A3: Periodo: 1 de enero 2028 a 31 diciembre de 2028
A4: CONVOCATORIA PÚBLICA N° CP-BIAC2026-003 - BIA ENERGY S.A.S. E.S.P.
A9: Mes | B9: Tipo de día | C9: H1 | D9: H2 | E9: H3 | F9: H4 | G9: H5 | H9: H6 | I9: H7 | J9: H8 | K9: H9 | L9: H10 | M9: H11 | N9: H12 | O9: H13 | P9: H14 | Q9: H15 | R9: H16 | S9: H17 | T9: H18 | U9: H19 | V9: H20 | W9: H21 | X9: H22 | Y9: H23 | Z9: H24 | AA9: TOTAL DÍA | AB9: DÍAS | AC9: TOTAL | AD9: TOTAL MES
A10: 46753 | B10: Ordinario | C10: 4294.6139 | D10: 4118.8781 | E10: 4020.5814 | F10: 3980.3998 | G10: 4041.7789 | H10: 4301.1665 | I10: 5204.4497 | J10: 6530.4709 | K10: 7639.8546 | L10: 8389.0499 | M10: 8998.5729 | N10: 9365.4064 | O10: 9242.2145 | P10: 9273.7944 | Q10: 9519.5138 | R10: 9523.532 | S10: 9255.0903 | T10: 8637.2951 | U10: 8182.2169 | V10: 7665.1747 | W10: 6981.6332 | X10: 6204.5489 | Y10: 5377.0265 | Z10: 4812.1751 | AA10: =SUM(C10:Z10) -> 165559.44 | AB10: 20 | AC10: =AA10*AB10 -> 3311188.8 | AD10: =SUM(AC10:AC12) -> 4769867.6
A11: 46753 | B11: Sábado | C11: 4666.6109 | D11: 4422.991 | E11: 4287.1504 | F11: 4181.8457 | G11: 4202.023 | H11: 4219.167 | I11: 4833.2947 | J11: 5934.3276 | K11: 6980.2785 | L11: 7797.1657 | M11: 8306.9248 | N11: 8540.8633 | O11: 8301.2533 | P11: 8038.1617 | Q11: 7857.579 | R11: 7813.7873 | S11: 7719.9321 | T11: 7574.0566 | U11: 7398.3652 | V11: 7011.0427 | W11: 6414.2499 | X11: 5743.2107 | Y11: 5026.3233 | Z11: 4511.7344 | AA11: =SUM(C11:Z11) -> 151782.34 | AB11: 4 | AC11: =AA11*AB11 -> 607129.35
A12: 46753 | B12: Festivo | C12: 4178.2703 | D12: 3970.748 | E12: 3779.0198 | F12: 3681.6067 | G12: 3599.472 | H12: 3528.8526 | I12: 3642.9214 | J12: 4072.1535 | K12: 4636.7028 | L12: 5421.7799 | M12: 6055.984 | N12: 6414.9962 | O12: 6538.6619 | P12: 6568.502 | Q12: 6523.13 | R12: 6491.5417 | S12: 6337.9656 | T12: 6184.1865 | U12: 6098.0999 | V12: 5794.2586 | W12: 5302.415 | X12: 4737.5793 | Y12: 4229.4224 | Z12: 3861.6528 | AA12: =SUM(C12:Z12) -> 121649.92 | AB12: 7 | AC12: =AA12*AB12 -> 851549.46
A13: 46784 | B13: Ordinario | C13: 4294.6139 | D13: 4118.8781 | E13: 4020.5814 | F13: 3980.3998 | G13: 4041.7789 | H13: 4301.1665 | I13: 5204.4497 | J13: 6530.4709 | K13: 7639.8546 | L13: 8389.0499 | M13: 8998.5729 | N13: 9365.4064 | O13: 9242.2145 | P13: 9273.7944 | Q13: 9519.5138 | R13: 9523.532 | S13: 9255.0903 | T13: 8637.2951 | U13: 8182.2169 | V13: 7665.1747 | W13: 6981.6332 | X13: 6204.5489 | Y13: 5377.0265 | Z13: 4812.1751 | AA13: =SUM(C13:Z13) -> 165559.44 | AB13: 21 | AC13: =AA13*AB13 -> 3476748.2 | AD13: =SUM(AC13:AC15) -> 4570477.3
A14: 46784 | B14: Sábado | C14: 4666.6109 | D14: 4422.991 | E14: 4287.1504 | F14: 4181.8457 | G14: 4202.023 | H14: 4219.167 | I14: 4833.2947 | J14: 5934.3276 | K14: 6980.2785 | L14: 7797.1657 | M14: 8306.9248 | N14: 8540.8633 | O14: 8301.2533 | P14: 8038.1617 | Q14: 7857.579 | R14: 7813.7873 | S14: 7719.9321 | T14: 7574.0566 | U14: 7398.3652 | V14: 7011.0427 | W14: 6414.2499 | X14: 5743.2107 | Y14: 5026.3233 | Z14: 4511.7344 | AA14: =SUM(C14:Z14) -> 151782.34 | AB14: 4 | AC14: =AA14*AB14 -> 607129.35
A15: 46784 | B15: Festivo | C15: 4178.2703 | D15: 3970.748 | E15: 3779.0198 | F15: 3681.6067 | G15: 3599.472 | H15: 3528.8526 | I15: 3642.9214 | J15: 4072.1535 | K15: 4636.7028 | L15: 5421.7799 | M15: 6055.984 | N15: 6414.9962 | O15: 6538.6619 | P15: 6568.502 | Q15: 6523.13 | R15: 6491.5417 | S15: 6337.9656 | T15: 6184.1865 | U15: 6098.0999 | V15: 5794.2586 | W15: 5302.415 | X15: 4737.5793 | Y15: 4229.4224 | Z15: 3861.6528 | AA15: =SUM(C15:Z15) -> 121649.92 | AB15: 4 | AC15: =AA15*AB15 -> 486599.69
A16: 46813 | B16: Ordinario | C16: 4473.5561 | D16: 4290.4981 | E16: 4188.1057 | F16: 4146.2498 | G16: 4210.1864 | H16: 4480.3818 | I16: 5421.3018 | J16: 6802.5738 | K16: 7958.1819 | L16: 8738.5937 | M16: 9373.5135 | N16: 9755.6317 | O16: 9627.3067 | P16: 9660.2025 | Q16: 9916.1603 | R16: 9920.3459 | S16: 9640.719 | T16: 8997.1823 | U16: 8523.1426 | V16: 7984.5569 | W16: 7272.5346 | X16: 6463.0718 | Y16: 5601.0692 | Z16: 5012.6824 | AA16: =SUM(C16:Z16) -> 172457.75 | AB16: 22 | AC16: =AA16*AB16 -> 3794070.5 | AD16: =SUM(AC16:AC18) -> 5060090.2
A17: 46813 | B17: Sábado | C17: 4861.0531 | D17: 4607.2823 | E17: 4465.7816 | F17: 4356.0893 | G17: 4377.1073 | H17: 4394.9656 | I17: 5034.682 | J17: 6181.5913 | K17: 7271.1234 | L17: 8122.0476 | M17: 8653.0467 | N17: 8896.7326 | O17: 8647.1388 | P17: 8373.0851 | Q17: 8184.9781 | R17: 8139.3618 | S17: 8041.5959 | T17: 7889.6423 | U17: 7706.6304 | V17: 7303.1694 | W17: 6681.5103 | X17: 5982.5112 | Y17: 5235.7534 | Z17: 4699.7233 | AA17: =SUM(C17:Z17) -> 158106.6 | AB17: 4 | AC17: =AA17*AB17 -> 632426.41
A18: 46813 | B18: Festivo | C18: 4352.3649 | D18: 4136.1958 | E18: 3936.479 | F18: 3835.007 | G18: 3749.45 | H18: 3675.8881 | I18: 3794.7097 | J18: 4241.8266 | K18: 4829.8987 | L18: 5647.6874 | M18: 6308.3166 | N18: 6682.2877 | O18: 6811.1061 | P18: 6842.1896 | Q18: 6794.9271 | R18: 6762.0226 | S18: 6602.0475 | T18: 6441.8609 | U18: 6352.1874 | V18: 6035.6861 | W18: 5523.349 | X18: 4934.9785 | Y18: 4405.6484 | Z18: 4022.555 | AA18: =SUM(C18:Z18) -> 126718.67 | AB18: 5 | AC18: =AA18*AB18 -> 633593.35
A19: 46844 | B19: Ordinario | C19: 4473.5561 | D19: 4290.4981 | E19: 4188.1057 | F19: 4146.2498 | G19: 4210.1864 | H19: 4480.3818 | I19: 5421.3018 | J19: 6802.5738 | K19: 7958.1819 | L19: 8738.5937 | M19: 9373.5135 | N19: 9755.6317 | O19: 9627.3067 | P19: 9660.2025 | Q19: 9916.1603 | R19: 9920.3459 | S19: 9640.719 | T19: 8997.1823 | U19: 8523.1426 | V19: 7984.5569 | W19: 7272.5346 | X19: 6463.0718 | Y19: 5601.0692 | Z19: 5012.6824 | AA19: =SUM(C19:Z19) -> 172457.75 | AB19: 18 | AC19: =AA19*AB19 -> 3104239.5 | AD19: =SUM(AC19:AC21) -> 4781803.2
A20: 46844 | B20: Sábado | C20: 4861.0531 | D20: 4607.2823 | E20: 4465.7816 | F20: 4356.0893 | G20: 4377.1073 | H20: 4394.9656 | I20: 5034.682 | J20: 6181.5913 | K20: 7271.1234 | L20: 8122.0476 | M20: 8653.0467 | N20: 8896.7326 | O20: 8647.1388 | P20: 8373.0851 | Q20: 8184.9781 | R20: 8139.3618 | S20: 8041.5959 | T20: 7889.6423 | U20: 7706.6304 | V20: 7303.1694 | W20: 6681.5103 | X20: 5982.5112 | Y20: 5235.7534 | Z20: 4699.7233 | AA20: =SUM(C20:Z20) -> 158106.6 | AB20: 5 | AC20: =AA20*AB20 -> 790533.01
A21: 46844 | B21: Festivo | C21: 4352.3649 | D21: 4136.1958 | E21: 3936.479 | F21: 3835.007 | G21: 3749.45 | H21: 3675.8881 | I21: 3794.7097 | J21: 4241.8266 | K21: 4829.8987 | L21: 5647.6874 | M21: 6308.3166 | N21: 6682.2877 | O21: 6811.1061 | P21: 6842.1896 | Q21: 6794.9271 | R21: 6762.0226 | S21: 6602.0475 | T21: 6441.8609 | U21: 6352.1874 | V21: 6035.6861 | W21: 5523.349 | X21: 4934.9785 | Y21: 4405.6484 | Z21: 4022.555 | AA21: =SUM(C21:Z21) -> 126718.67 | AB21: 7 | AC21: =AA21*AB21 -> 887030.69
A22: 46874 | B22: Ordinario | C22: 2863.0759 | D22: 2745.9188 | E22: 2680.3876 | F22: 2653.5999 | G22: 2694.5193 | H22: 2867.4443 | I22: 3469.6331 | J22: 4353.6473 | K22: 5093.2364 | L22: 5592.7 | M22: 5999.0486 | N22: 6243.6043 | O22: 6161.4763 | P22: 6182.5296 | Q22: 6346.3426 | R22: 6349.0213 | S22: 6170.0602 | T22: 5758.1967 | U22: 5454.8113 | V22: 5110.1164 | W22: 4654.4221 | X22: 4136.3659 | Y22: 3584.6843 | Z22: 3208.1167 | AA22: =SUM(C22:Z22) -> 110372.96 | AB22: 21 | AC22: =AA22*AB22 -> 2317832.1 | AD22: =SUM(AC22:AC24) -> 3209184.7
A23: 46874 | B23: Sábado | C23: 3111.074 | D23: 2948.6606 | E23: 2858.1003 | F23: 2787.8971 | G23: 2801.3487 | H23: 2812.778 | I23: 3222.1965 | J23: 3956.2184 | K23: 4653.519 | L23: 5198.1104 | M23: 5537.9499 | N23: 5693.9088 | O23: 5534.1689 | P23: 5358.7745 | Q23: 5238.386 | R23: 5209.1915 | S23: 5146.6214 | T23: 5049.3711 | U23: 4932.2434 | V23: 4674.0284 | W23: 4276.1666 | X23: 3828.8072 | Y23: 3350.8822 | Z23: 3007.8229 | AA23: =SUM(C23:Z23) -> 101188.23 | AB23: 4 | AC23: =AA23*AB23 -> 404752.9
A24: 46874 | B24: Festivo | C24: 2785.5135 | D24: 2647.1653 | E24: 2519.3466 | F24: 2454.4045 | G24: 2399.648 | H24: 2352.5684 | I24: 2428.6142 | J24: 2714.769 | K24: 3091.1352 | L24: 3614.5199 | M24: 4037.3226 | N24: 4276.6641 | O24: 4359.1079 | P24: 4379.0013 | Q24: 4348.7533 | R24: 4327.6944 | S24: 4225.3104 | T24: 4122.791 | U24: 4065.3999 | V24: 3862.8391 | W24: 3534.9433 | X24: 3158.3862 | Y24: 2819.615 | Z24: 2574.4352 | AA24: =SUM(C24:Z24) -> 81099.949 | AB24: 6 | AC24: =AA24*AB24 -> 486599.69
A25: 46905 | B25: Ordinario | C25: 3042.0182 | D25: 2917.5387 | E25: 2847.9118 | F25: 2819.4499 | G25: 2862.9267 | H25: 3046.6596 | I25: 3686.4852 | J25: 4625.7502 | K25: 5411.5637 | L25: 5942.2437 | M25: 6373.9892 | N25: 6633.8295 | O25: 6546.5686 | P25: 6568.9377 | Q25: 6742.989 | R25: 6745.8352 | S25: 6555.6889 | T25: 6118.084 | U25: 5795.737 | V25: 5429.4987 | W25: 4945.3235 | X25: 4394.8888 | Y25: 3808.7271 | Z25: 3408.624 | AA25: =SUM(C25:Z25) -> 117271.27 | AB25: 20 | AC25: =AA25*AB25 -> 2345425.4 | AD25: =SUM(AC25:AC27) -> 3292487.5
A26: 46905 | B26: Sábado | C26: 3305.5161 | D26: 3132.9519 | E26: 3036.7315 | F26: 2962.1407 | G26: 2976.4329 | H26: 2988.5766 | I26: 3423.5837 | J26: 4203.4821 | K26: 4944.3639 | L26: 5522.9923 | M26: 5884.0717 | N26: 6049.7781 | O26: 5880.0544 | P26: 5693.6979 | Q26: 5565.7851 | R26: 5534.766 | S26: 5468.2852 | T26: 5364.9568 | U26: 5240.5087 | V26: 4966.1552 | W26: 4543.427 | X26: 4068.1076 | Y26: 3560.3123 | Z26: 3195.8119 | AA26: =SUM(C26:Z26) -> 107512.49 | AB26: 4 | AC26: =AA26*AB26 -> 430049.96
A27: 46905 | B27: Festivo | C27: 2959.6081 | D27: 2812.6131 | E27: 2676.8057 | F27: 2607.8048 | G27: 2549.626 | H27: 2499.6039 | I27: 2580.4026 | J27: 2884.4421 | K27: 3284.3311 | L27: 3840.4274 | M27: 4289.6553 | N27: 4543.9556 | O27: 4631.5522 | P27: 4652.6889 | Q27: 4620.5504 | R27: 4598.1753 | S27: 4489.3923 | T27: 4380.4654 | U27: 4319.4874 | V27: 4104.2665 | W27: 3755.8773 | X27: 3355.7854 | Y27: 2995.8409 | Z27: 2735.3374 | AA27: =SUM(C27:Z27) -> 86168.695 | AB27: 6 | AC27: =AA27*AB27 -> 517012.17
A28: 46935 | B28: Ordinario | C28: 3042.0182 | D28: 2917.5387 | E28: 2847.9118 | F28: 2819.4499 | G28: 2862.9267 | H28: 3046.6596 | I28: 3686.4852 | J28: 4625.7502 | K28: 5411.5637 | L28: 5942.2437 | M28: 6373.9892 | N28: 6633.8295 | O28: 6546.5686 | P28: 6568.9377 | Q28: 6742.989 | R28: 6745.8352 | S28: 6555.6889 | T28: 6118.084 | U28: 5795.737 | V28: 5429.4987 | W28: 4945.3235 | X28: 4394.8888 | Y28: 3808.7271 | Z28: 3408.624 | AA28: =SUM(C28:Z28) -> 117271.27 | AB28: 19 | AC28: =AA28*AB28 -> 2228154.1 | AD28: =SUM(AC28:AC30) -> 3368897.4
A29: 46935 | B29: Sábado | C29: 3305.5161 | D29: 3132.9519 | E29: 3036.7315 | F29: 2962.1407 | G29: 2976.4329 | H29: 2988.5766 | I29: 3423.5837 | J29: 4203.4821 | K29: 4944.3639 | L29: 5522.9923 | M29: 5884.0717 | N29: 6049.7781 | O29: 5880.0544 | P29: 5693.6979 | Q29: 5565.7851 | R29: 5534.766 | S29: 5468.2852 | T29: 5364.9568 | U29: 5240.5087 | V29: 4966.1552 | W29: 4543.427 | X29: 4068.1076 | Y29: 3560.3123 | Z29: 3195.8119 | AA29: =SUM(C29:Z29) -> 107512.49 | AB29: 5 | AC29: =AA29*AB29 -> 537562.45
A30: 46935 | B30: Festivo | C30: 2959.6081 | D30: 2812.6131 | E30: 2676.8057 | F30: 2607.8048 | G30: 2549.626 | H30: 2499.6039 | I30: 2580.4026 | J30: 2884.4421 | K30: 3284.3311 | L30: 3840.4274 | M30: 4289.6553 | N30: 4543.9556 | O30: 4631.5522 | P30: 4652.6889 | Q30: 4620.5504 | R30: 4598.1753 | S30: 4489.3923 | T30: 4380.4654 | U30: 4319.4874 | V30: 4104.2665 | W30: 3755.8773 | X30: 3355.7854 | Y30: 2995.8409 | Z30: 2735.3374 | AA30: =SUM(C30:Z30) -> 86168.695 | AB30: 7 | AC30: =AA30*AB30 -> 603180.87
A31: 46966 | B31: Ordinario | C31: 3042.0182 | D31: 2917.5387 | E31: 2847.9118 | F31: 2819.4499 | G31: 2862.9267 | H31: 3046.6596 | I31: 3686.4852 | J31: 4625.7502 | K31: 5411.5637 | L31: 5942.2437 | M31: 6373.9892 | N31: 6633.8295 | O31: 6546.5686 | P31: 6568.9377 | Q31: 6742.989 | R31: 6745.8352 | S31: 6555.6889 | T31: 6118.084 | U31: 5795.737 | V31: 5429.4987 | W31: 4945.3235 | X31: 4394.8888 | Y31: 3808.7271 | Z31: 3408.624 | AA31: =SUM(C31:Z31) -> 117271.27 | AB31: 21 | AC31: =AA31*AB31 -> 2462696.6 | AD31: =SUM(AC31:AC33) -> 3409758.8
A32: 46966 | B32: Sábado | C32: 3305.5161 | D32: 3132.9519 | E32: 3036.7315 | F32: 2962.1407 | G32: 2976.4329 | H32: 2988.5766 | I32: 3423.5837 | J32: 4203.4821 | K32: 4944.3639 | L32: 5522.9923 | M32: 5884.0717 | N32: 6049.7781 | O32: 5880.0544 | P32: 5693.6979 | Q32: 5565.7851 | R32: 5534.766 | S32: 5468.2852 | T32: 5364.9568 | U32: 5240.5087 | V32: 4966.1552 | W32: 4543.427 | X32: 4068.1076 | Y32: 3560.3123 | Z32: 3195.8119 | AA32: =SUM(C32:Z32) -> 107512.49 | AB32: 4 | AC32: =AA32*AB32 -> 430049.96
A33: 46966 | B33: Festivo | C33: 2959.6081 | D33: 2812.6131 | E33: 2676.8057 | F33: 2607.8048 | G33: 2549.626 | H33: 2499.6039 | I33: 2580.4026 | J33: 2884.4421 | K33: 3284.3311 | L33: 3840.4274 | M33: 4289.6553 | N33: 4543.9556 | O33: 4631.5522 | P33: 4652.6889 | Q33: 4620.5504 | R33: 4598.1753 | S33: 4489.3923 | T33: 4380.4654 | U33: 4319.4874 | V33: 4104.2665 | W33: 3755.8773 | X33: 3355.7854 | Y33: 2995.8409 | Z33: 2735.3374 | AA33: =SUM(C33:Z33) -> 86168.695 | AB33: 6 | AC33: =AA33*AB33 -> 517012.17
A34: 46997 | B34: Ordinario | C34: 3220.9604 | D34: 3089.1586 | E34: 3015.4361 | F34: 2985.2999 | G34: 3031.3342 | H34: 3225.8749 | I34: 3903.3373 | J34: 4897.8532 | K34: 5729.891 | L34: 6291.7874 | M34: 6748.9297 | N34: 7024.0548 | O34: 6931.6608 | P34: 6955.3458 | Q34: 7139.6354 | R34: 7142.649 | S34: 6941.3177 | T34: 6477.9713 | U34: 6136.6627 | V34: 5748.881 | W34: 5236.2249 | X34: 4653.4117 | Y34: 4032.7698 | Z34: 3609.1313 | AA34: =SUM(C34:Z34) -> 124169.58 | AB34: 21 | AC34: =AA34*AB34 -> 2607561.2 | AD34: =SUM(AC34:AC36) -> 3541694.7
A35: 46997 | B35: Sábado | C35: 3499.9582 | D35: 3317.2432 | E35: 3215.3628 | F35: 3136.3843 | G35: 3151.5172 | H35: 3164.3752 | I35: 3624.971 | J35: 4450.7457 | K35: 5235.2089 | L35: 5847.8743 | M35: 6230.1936 | N35: 6405.6474 | O35: 6225.94 | P35: 6028.6213 | Q35: 5893.1843 | R35: 5860.3405 | S35: 5789.9491 | T35: 5680.5425 | U35: 5548.7739 | V35: 5258.282 | W35: 4810.6874 | X35: 4307.4081 | Y35: 3769.7425 | Z35: 3383.8008 | AA35: =SUM(C35:Z35) -> 113836.75 | AB35: 5 | AC35: =AA35*AB35 -> 569183.77
A36: 46997 | B36: Festivo | C36: 3133.7027 | D36: 2978.061 | E36: 2834.2649 | F36: 2761.2051 | G36: 2699.604 | H36: 2646.6395 | I36: 2732.191 | J36: 3054.1151 | K36: 3477.5271 | L36: 4066.3349 | M36: 4541.988 | N36: 4811.2471 | O36: 4903.9964 | P36: 4926.3765 | Q36: 4892.3475 | R36: 4868.6563 | S36: 4753.4742 | T36: 4638.1398 | U36: 4573.5749 | V36: 4345.694 | W36: 3976.8113 | X36: 3553.1845 | Y36: 3172.0668 | Z36: 2896.2396 | AA36: =SUM(C36:Z36) -> 91237.442 | AB36: 4 | AC36: =AA36*AB36 -> 364949.77
A37: 47027 | B37: Ordinario | C37: 3042.0182 | D37: 2917.5387 | E37: 2847.9118 | F37: 2819.4499 | G37: 2862.9267 | H37: 3046.6596 | I37: 3686.4852 | J37: 4625.7502 | K37: 5411.5637 | L37: 5942.2437 | M37: 6373.9892 | N37: 6633.8295 | O37: 6546.5686 | P37: 6568.9377 | Q37: 6742.989 | R37: 6745.8352 | S37: 6555.6889 | T37: 6118.084 | U37: 5795.737 | V37: 5429.4987 | W37: 4945.3235 | X37: 4394.8888 | Y37: 3808.7271 | Z37: 3408.624 | AA37: =SUM(C37:Z37) -> 117271.27 | AB37: 21 | AC37: =AA37*AB37 -> 2462696.6 | AD37: =SUM(AC37:AC39) -> 3409758.8
A38: 47027 | B38: Sábado | C38: 3305.5161 | D38: 3132.9519 | E38: 3036.7315 | F38: 2962.1407 | G38: 2976.4329 | H38: 2988.5766 | I38: 3423.5837 | J38: 4203.4821 | K38: 4944.3639 | L38: 5522.9923 | M38: 5884.0717 | N38: 6049.7781 | O38: 5880.0544 | P38: 5693.6979 | Q38: 5565.7851 | R38: 5534.766 | S38: 5468.2852 | T38: 5364.9568 | U38: 5240.5087 | V38: 4966.1552 | W38: 4543.427 | X38: 4068.1076 | Y38: 3560.3123 | Z38: 3195.8119 | AA38: =SUM(C38:Z38) -> 107512.49 | AB38: 4 | AC38: =AA38*AB38 -> 430049.96
A39: 47027 | B39: Festivo | C39: 2959.6081 | D39: 2812.6131 | E39: 2676.8057 | F39: 2607.8048 | G39: 2549.626 | H39: 2499.6039 | I39: 2580.4026 | J39: 2884.4421 | K39: 3284.3311 | L39: 3840.4274 | M39: 4289.6553 | N39: 4543.9556 | O39: 4631.5522 | P39: 4652.6889 | Q39: 4620.5504 | R39: 4598.1753 | S39: 4489.3923 | T39: 4380.4654 | U39: 4319.4874 | V39: 4104.2665 | W39: 3755.8773 | X39: 3355.7854 | Y39: 2995.8409 | Z39: 2735.3374 | AA39: =SUM(C39:Z39) -> 86168.695 | AB39: 6 | AC39: =AA39*AB39 -> 517012.17
A40: 47058 | B40: Ordinario | C40: 3131.4893 | D40: 3003.3486 | E40: 2931.674 | F40: 2902.3749 | G40: 2947.1305 | H40: 3136.2673 | I40: 3794.9113 | J40: 4761.8017 | K40: 5570.7273 | L40: 6117.0156 | M40: 6561.4594 | N40: 6828.9422 | O40: 6739.1147 | P40: 6762.1418 | Q40: 6941.3122 | R40: 6944.2421 | S40: 6748.5033 | T40: 6298.0276 | U40: 5966.1998 | V40: 5589.1899 | W40: 5090.7742 | X40: 4524.1502 | Y40: 3920.7485 | Z40: 3508.8777 | AA40: =SUM(C40:Z40) -> 120720.42 | AB40: 20 | AC40: =AA40*AB40 -> 2414408.5 | AD40: =SUM(AC40:AC42) -> 3389325.4
A41: 47058 | B41: Sábado | C41: 3402.7371 | D41: 3225.0976 | E41: 3126.0472 | F41: 3049.2625 | G41: 3063.9751 | H41: 3076.4759 | I41: 3524.2774 | J41: 4327.1139 | K41: 5089.7864 | L41: 5685.4333 | M41: 6057.1327 | N41: 6227.7128 | O41: 6052.9972 | P41: 5861.1596 | Q41: 5729.4847 | R41: 5697.5532 | S41: 5629.1171 | T41: 5522.7496 | U41: 5394.6413 | V41: 5112.2186 | W41: 4677.0572 | X41: 4187.7578 | Y41: 3665.0274 | Z41: 3289.8063 | AA41: =SUM(C41:Z41) -> 110674.62 | AB41: 4 | AC41: =AA41*AB41 -> 442698.49
A42: 47058 | B42: Festivo | C42: 3046.6554 | D42: 2895.3371 | E42: 2755.5353 | F42: 2684.5049 | G42: 2624.615 | H42: 2573.1217 | I42: 2656.2968 | J42: 2969.2786 | K42: 3380.9291 | L42: 3953.3812 | M42: 4415.8216 | N42: 4677.6014 | O42: 4767.7743 | P42: 4789.5327 | Q42: 4756.449 | R42: 4733.4158 | S42: 4621.4332 | T42: 4509.3026 | U42: 4446.5312 | V42: 4224.9803 | W42: 3866.3443 | X42: 3454.4849 | Y42: 3083.9539 | Z42: 2815.7885 | AA42: =SUM(C42:Z42) -> 88703.069 | AB42: 6 | AC42: =AA42*AB42 -> 532218.41
A43: 47088 | B43: Ordinario | C43: 2505.1914 | D43: 2402.6789 | E43: 2345.3392 | F43: 2321.8999 | G43: 2357.7044 | H43: 2509.0138 | I43: 3035.929 | J43: 3809.4414 | K43: 4456.5819 | L43: 4893.6125 | M43: 5249.1675 | N43: 5463.1537 | O43: 5391.2918 | P43: 5409.7134 | Q43: 5553.0497 | R43: 5555.3937 | S43: 5398.8027 | T43: 5038.4221 | U43: 4772.9599 | V43: 4471.3519 | W43: 4072.6194 | X43: 3619.3202 | Y43: 3136.5988 | Z43: 2807.1022 | AA43: =SUM(C43:Z43) -> 96576.339 | AB43: 19 | AC43: =AA43*AB43 -> 1834950.4 | AD43: =SUM(AC43:AC45) -> 2774386.1
A44: 47088 | B44: Sábado | C44: 2722.1897 | D44: 2580.0781 | E44: 2500.8377 | F44: 2439.41 | G44: 2451.1801 | H44: 2461.1807 | I44: 2819.4219 | J44: 3461.6911 | K44: 4071.8291 | L44: 4548.3466 | M44: 4845.7061 | N44: 4982.1702 | O44: 4842.3978 | P44: 4688.9277 | Q44: 4583.5878 | R44: 4558.0426 | S44: 4503.2937 | T44: 4418.1997 | U44: 4315.713 | V44: 4089.7749 | W44: 3741.6458 | X44: 3350.2063 | Y44: 2932.0219 | Z44: 2631.8451 | AA44: =SUM(C44:Z44) -> 88539.697 | AB44: 5 | AC44: =AA44*AB44 -> 442698.49
...

Sheet Oferta Producto 2
A4: CONVOCATORIA PÚBLICA N° CP-BIAC2026-003 - BIA ENERGY S.A.S. E.S.P.
B5: ANEXO 4. FORMATO DE OFERTA - PRODUCTO 2
B6: NOMBRE DEL OFERENTE
B7: Precios y cantidades de la energía ofertada
B8: En pesos de marzo de 2026
B10: OPCIÓN 24 HORAS
B11: Mes | C11: E. Solicitada [kWh-mes] | D11: % E. Ofertada | E11: E. Ofertada [kWh-mes] | F11: $/kWh
B12: 46783 | C12: ='Cant. Requeridas Producto 2'!AD10 -> 4769867.6 | E12: =C12*$D$12 -> 0
B13: 46784 | C13: ='Cant. Requeridas Producto 2'!AD13 -> 4570477.3 | E13: =C13*$D$13 -> 0
B14: 46813 | C14: ='Cant. Requeridas Producto 2'!AD16 -> 5060090.2 | E14: =C14*$D$13 -> 0
B15: 46844 | C15: ='Cant. Requeridas Producto 2'!AD19 -> 4781803.2 | E15: =C15*$D$13 -> 0
B16: 46874 | C16: ='Cant. Requeridas Producto 2'!AD22 -> 3209184.7 | E16: =C16*$D$13 -> 0
B17: 46905 | C17: ='Cant. Requeridas Producto 2'!AD25 -> 3292487.5 | E17: =C17*$D$13 -> 0
B18: 46935 | C18: ='Cant. Requeridas Producto 2'!AD28 -> 3368897.4 | E18: =C18*$D$13 -> 0
B19: 46966 | C19: ='Cant. Requeridas Producto 2'!AD31 -> 3409758.8 | E19: =C19*$D$13 -> 0
B20: 46997 | C20: ='Cant. Requeridas Producto 2'!AD34 -> 3541694.7 | E20: =C20*$D$13 -> 0
B21: 47027 | C21: ='Cant. Requeridas Producto 2'!AD37 -> 3409758.8 | E21: =C21*$D$13 -> 0
B22: 47058 | C22: ='Cant. Requeridas Producto 2'!AD40 -> 3389325.4 | E22: =C22*$D$13 -> 0
B23: 47088 | C23: ='Cant. Requeridas Producto 2'!AD43 -> 2774386.1 | E23: =C23*$D$13 -> 0
B24: TOTAL | C24: =SUM(C12:C23) -> 45577732 | E24: =SUM(E12:E23) -> 0
B27: El oferente debe indicar si acepta adjudicaciones parciales o no
B28: • Para el periodo de 2028, se puede presentar oferta con diferente porcentaje cada mes, incluyendo el 0%
B29: • El precio ofertado podrá ser diferente para cada mes del producto, expresado en $/kWh, con hasta dos (2) decimales
B34: XXXXX
B35: XXXXXXXX S.A.S. E.S.P.

Sheet Cant. Requeridas Producto 3
A1: ANEXO 3 - CANTIDADES DE ENERGÍA SOLICITADA EN kWh
A2: PRODUCTO 3 - PAGUE LO CONTRATADO
A3: Periodo: 1 de enero 2029 a 31 diciembre de 2029
A4: CONVOCATORIA PÚBLICA N° CP-BIAC2026-003 - BIA ENERGY S.A.S. E.S.P.
A9: Mes | B9: Tipo de día | C9: H1 | D9: H2 | E9: H3 | F9: H4 | G9: H5 | H9: H6 | I9: H7 | J9: H8 | K9: H9 | L9: H10 | M9: H11 | N9: H12 | O9: H13 | P9: H14 | Q9: H15 | R9: H16 | S9: H17 | T9: H18 | U9: H19 | V9: H20 | W9: H21 | X9: H22 | Y9: H23 | Z9: H24 | AA9: TOTAL DÍA | AB9: DÍAS | AC9: TOTAL | AD9: TOTAL MES
A10: 47119 | B10: Ordinario | C10: 5314.59 | D10: 5097.114 | E10: 4975.47 | F10: 4925.736 | G10: 5001.696 | H10: 5322.69 | I10: 6440.508 | J10: 8081.46 | K10: 9454.32 | L10: 10381.446 | M10: 11135.736 | N10: 11589.696 | O10: 11437.236 | P10: 11476.314 | Q10: 11780.406 | R10: 11785.374 | S10: 11453.166 | T10: 10688.652 | U10: 10125.486 | V10: 9485.658 | W10: 8639.766 | X10: 7678.134 | Y10: 6654.078 | Z10: 5955.066 | AA10: =SUM(C10:Z10) -> 204879.8 | AB10: 21 | AC10: =AA10*AB10 -> 4302475.8 | AD10: =SUM(AC10:AC12) -> 5957049.3
A11: 47119 | B11: Sábado | C11: 5774.94 | D11: 5473.458 | E11: 5305.356 | F11: 5175.036 | G11: 5200.002 | H11: 5221.224 | I11: 5981.202 | J11: 7343.73 | K11: 8638.092 | L11: 9648.99 | M11: 10279.818 | N11: 10569.312 | O11: 10272.798 | P11: 9947.232 | Q11: 9723.762 | R11: 9669.564 | S11: 9553.41 | T11: 9372.888 | U11: 9155.484 | V11: 8676.162 | W11: 7937.64 | X11: 7107.228 | Y11: 6220.08 | Z11: 5583.276 | AA11: =SUM(C11:Z11) -> 187830.68 | AB11: 4 | AC11: =AA11*AB11 -> 751322.74
A12: 47119 | B12: Festivo | C12: 5170.608 | D12: 4913.802 | E12: 4676.544 | F12: 4555.98 | G12: 4454.352 | H12: 4366.962 | I12: 4508.118 | J12: 5039.298 | K12: 5737.914 | L12: 6709.446 | M12: 7494.282 | N12: 7938.558 | O12: 8091.594 | P12: 8128.53 | Q12: 8072.37 | R12: 8033.274 | S12: 7843.23 | T12: 7652.934 | U12: 7546.392 | V12: 7170.39 | W12: 6561.738 | X12: 5862.762 | Y12: 5233.914 | Z12: 4778.802 | AA12: =SUM(C12:Z12) -> 150541.79 | AB12: 6 | AC12: =AA12*AB12 -> 903250.76
A13: 47150 | B13: Ordinario | C13: 5314.59 | D13: 5097.114 | E13: 4975.47 | F13: 4925.736 | G13: 5001.696 | H13: 5322.69 | I13: 6440.508 | J13: 8081.46 | K13: 9454.32 | L13: 10381.446 | M13: 11135.736 | N13: 11589.696 | O13: 11437.236 | P13: 11476.314 | Q13: 11780.406 | R13: 11785.374 | S13: 11453.166 | T13: 10688.652 | U13: 10125.486 | V13: 9485.658 | W13: 8639.766 | X13: 7678.134 | Y13: 6654.078 | Z13: 5955.066 | AA13: =SUM(C13:Z13) -> 204879.8 | AB13: 20 | AC13: =AA13*AB13 -> 4097596 | AD13: =SUM(AC13:AC15) -> 5451085.9
A14: 47150 | B14: Sábado | C14: 5774.94 | D14: 5473.458 | E14: 5305.356 | F14: 5175.036 | G14: 5200.002 | H14: 5221.224 | I14: 5981.202 | J14: 7343.73 | K14: 8638.092 | L14: 9648.99 | M14: 10279.818 | N14: 10569.312 | O14: 10272.798 | P14: 9947.232 | Q14: 9723.762 | R14: 9669.564 | S14: 9553.41 | T14: 9372.888 | U14: 9155.484 | V14: 8676.162 | W14: 7937.64 | X14: 7107.228 | Y14: 6220.08 | Z14: 5583.276 | AA14: =SUM(C14:Z14) -> 187830.68 | AB14: 4 | AC14: =AA14*AB14 -> 751322.74
A15: 47150 | B15: Festivo | C15: 5170.608 | D15: 4913.802 | E15: 4676.544 | F15: 4555.98 | G15: 4454.352 | H15: 4366.962 | I15: 4508.118 | J15: 5039.298 | K15: 5737.914 | L15: 6709.446 | M15: 7494.282 | N15: 7938.558 | O15: 8091.594 | P15: 8128.53 | Q15: 8072.37 | R15: 8033.274 | S15: 7843.23 | T15: 7652.934 | U15: 7546.392 | V15: 7170.39 | W15: 6561.738 | X15: 5862.762 | Y15: 5233.914 | Z15: 4778.802 | AA15: =SUM(C15:Z15) -> 150541.79 | AB15: 4 | AC15: =AA15*AB15 -> 602167.18
A16: 47178 | B16: Ordinario | C16: 5314.59 | D16: 5097.114 | E16: 4975.47 | F16: 4925.736 | G16: 5001.696 | H16: 5322.69 | I16: 6440.508 | J16: 8081.46 | K16: 9454.32 | L16: 10381.446 | M16: 11135.736 | N16: 11589.696 | O16: 11437.236 | P16: 11476.314 | Q16: 11780.406 | R16: 11785.374 | S16: 11453.166 | T16: 10688.652 | U16: 10125.486 | V16: 9485.658 | W16: 8639.766 | X16: 7678.134 | Y16: 6654.078 | Z16: 5955.066 | AA16: =SUM(C16:Z16) -> 204879.8 | AB16: 19 | AC16: =AA16*AB16 -> 3892716.2 | AD16: =SUM(AC16:AC18) -> 5885662.1
A17: 47178 | B17: Sábado | C17: 5774.94 | D17: 5473.458 | E17: 5305.356 | F17: 5175.036 | G17: 5200.002 | H17: 5221.224 | I17: 5981.202 | J17: 7343.73 | K17: 8638.092 | L17: 9648.99 | M17: 10279.818 | N17: 10569.312 | O17: 10272.798 | P17: 9947.232 | Q17: 9723.762 | R17: 9669.564 | S17: 9553.41 | T17: 9372.888 | U17: 9155.484 | V17: 8676.162 | W17: 7937.64 | X17: 7107.228 | Y17: 6220.08 | Z17: 5583.276 | AA17: =SUM(C17:Z17) -> 187830.68 | AB17: 5 | AC17: =AA17*AB17 -> 939153.42
A18: 47178 | B18: Festivo | C18: 5170.608 | D18: 4913.802 | E18: 4676.544 | F18: 4555.98 | G18: 4454.352 | H18: 4366.962 | I18: 4508.118 | J18: 5039.298 | K18: 5737.914 | L18: 6709.446 | M18: 7494.282 | N18: 7938.558 | O18: 8091.594 | P18: 8128.53 | Q18: 8072.37 | R18: 8033.274 | S18: 7843.23 | T18: 7652.934 | U18: 7546.392 | V18: 7170.39 | W18: 6561.738 | X18: 5862.762 | Y18: 5233.914 | Z18: 4778.802 | AA18: =SUM(C18:Z18) -> 150541.79 | AB18: 7 | AC18: =AA18*AB18 -> 1053792.6
A19: 47209 | B19: Ordinario | C19: 5314.59 | D19: 5097.114 | E19: 4975.47 | F19: 4925.736 | G19: 5001.696 | H19: 5322.69 | I19: 6440.508 | J19: 8081.46 | K19: 9454.32 | L19: 10381.446 | M19: 11135.736 | N19: 11589.696 | O19: 11437.236 | P19: 11476.314 | Q19: 11780.406 | R19: 11785.374 | S19: 11453.166 | T19: 10688.652 | U19: 10125.486 | V19: 9485.658 | W19: 8639.766 | X19: 7678.134 | Y19: 6654.078 | Z19: 5955.066 | AA19: =SUM(C19:Z19) -> 204879.8 | AB19: 21 | AC19: =AA19*AB19 -> 4302475.8 | AD19: =SUM(AC19:AC21) -> 5806507.5
A20: 47209 | B20: Sábado | C20: 5774.94 | D20: 5473.458 | E20: 5305.356 | F20: 5175.036 | G20: 5200.002 | H20: 5221.224 | I20: 5981.202 | J20: 7343.73 | K20: 8638.092 | L20: 9648.99 | M20: 10279.818 | N20: 10569.312 | O20: 10272.798 | P20: 9947.232 | Q20: 9723.762 | R20: 9669.564 | S20: 9553.41 | T20: 9372.888 | U20: 9155.484 | V20: 8676.162 | W20: 7937.64 | X20: 7107.228 | Y20: 6220.08 | Z20: 5583.276 | AA20: =SUM(C20:Z20) -> 187830.68 | AB20: 4 | AC20: =AA20*AB20 -> 751322.74
A21: 47209 | B21: Festivo | C21: 5170.608 | D21: 4913.802 | E21: 4676.544 | F21: 4555.98 | G21: 4454.352 | H21: 4366.962 | I21: 4508.118 | J21: 5039.298 | K21: 5737.914 | L21: 6709.446 | M21: 7494.282 | N21: 7938.558 | O21: 8091.594 | P21: 8128.53 | Q21: 8072.37 | R21: 8033.274 | S21: 7843.23 | T21: 7652.934 | U21: 7546.392 | V21: 7170.39 | W21: 6561.738 | X21: 5862.762 | Y21: 5233.914 | Z21: 4778.802 | AA21: =SUM(C21:Z21) -> 150541.79 | AB21: 5 | AC21: =AA21*AB21 -> 752708.97
A22: 47239 | B22: Ordinario | C22: 5314.59 | D22: 5097.114 | E22: 4975.47 | F22: 4925.736 | G22: 5001.696 | H22: 5322.69 | I22: 6440.508 | J22: 8081.46 | K22: 9454.32 | L22: 10381.446 | M22: 11135.736 | N22: 11589.696 | O22: 11437.236 | P22: 11476.314 | Q22: 11780.406 | R22: 11785.374 | S22: 11453.166 | T22: 10688.652 | U22: 10125.486 | V22: 9485.658 | W22: 8639.766 | X22: 7678.134 | Y22: 6654.078 | Z22: 5955.066 | AA22: =SUM(C22:Z22) -> 204879.8 | AB22: 21 | AC22: =AA22*AB22 -> 4302475.8 | AD22: =SUM(AC22:AC24) -> 5957049.3
A23: 47239 | B23: Sábado | C23: 5774.94 | D23: 5473.458 | E23: 5305.356 | F23: 5175.036 | G23: 5200.002 | H23: 5221.224 | I23: 5981.202 | J23: 7343.73 | K23: 8638.092 | L23: 9648.99 | M23: 10279.818 | N23: 10569.312 | O23: 10272.798 | P23: 9947.232 | Q23: 9723.762 | R23: 9669.564 | S23: 9553.41 | T23: 9372.888 | U23: 9155.484 | V23: 8676.162 | W23: 7937.64 | X23: 7107.228 | Y23: 6220.08 | Z23: 5583.276 | AA23: =SUM(C23:Z23) -> 187830.68 | AB23: 4 | AC23: =AA23*AB23 -> 751322.74
A24: 47239 | B24: Festivo | C24: 5170.608 | D24: 4913.802 | E24: 4676.544 | F24: 4555.98 | G24: 4454.352 | H24: 4366.962 | I24: 4508.118 | J24: 5039.298 | K24: 5737.914 | L24: 6709.446 | M24: 7494.282 | N24: 7938.558 | O24: 8091.594 | P24: 8128.53 | Q24: 8072.37 | R24: 8033.274 | S24: 7843.23 | T24: 7652.934 | U24: 7546.392 | V24: 7170.39 | W24: 6561.738 | X24: 5862.762 | Y24: 5233.914 | Z24: 4778.802 | AA24: =SUM(C24:Z24) -> 150541.79 | AB24: 6 | AC24: =AA24*AB24 -> 903250.76
A25: 47270 | B25: Ordinario | C25: 5314.59 | D25: 5097.114 | E25: 4975.47 | F25: 4925.736 | G25: 5001.696 | H25: 5322.69 | I25: 6440.508 | J25: 8081.46 | K25: 9454.32 | L25: 10381.446 | M25: 11135.736 | N25: 11589.696 | O25: 11437.236 | P25: 11476.314 | Q25: 11780.406 | R25: 11785.374 | S25: 11453.166 | T25: 10688.652 | U25: 10125.486 | V25: 9485.658 | W25: 8639.766 | X25: 7678.134 | Y25: 6654.078 | Z25: 5955.066 | AA25: =SUM(C25:Z25) -> 204879.8 | AB25: 19 | AC25: =AA25*AB25 -> 3892716.2 | AD25: =SUM(AC25:AC27) -> 5735120.3
A26: 47270 | B26: Sábado | C26: 5774.94 | D26: 5473.458 | E26: 5305.356 | F26: 5175.036 | G26: 5200.002 | H26: 5221.224 | I26: 5981.202 | J26: 7343.73 | K26: 8638.092 | L26: 9648.99 | M26: 10279.818 | N26: 10569.312 | O26: 10272.798 | P26: 9947.232 | Q26: 9723.762 | R26: 9669.564 | S26: 9553.41 | T26: 9372.888 | U26: 9155.484 | V26: 8676.162 | W26: 7937.64 | X26: 7107.228 | Y26: 6220.08 | Z26: 5583.276 | AA26: =SUM(C26:Z26) -> 187830.68 | AB26: 5 | AC26: =AA26*AB26 -> 939153.42
A27: 47270 | B27: Festivo | C27: 5170.608 | D27: 4913.802 | E27: 4676.544 | F27: 4555.98 | G27: 4454.352 | H27: 4366.962 | I27: 4508.118 | J27: 5039.298 | K27: 5737.914 | L27: 6709.446 | M27: 7494.282 | N27: 7938.558 | O27: 8091.594 | P27: 8128.53 | Q27: 8072.37 | R27: 8033.274 | S27: 7843.23 | T27: 7652.934 | U27: 7546.392 | V27: 7170.39 | W27: 6561.738 | X27: 5862.762 | Y27: 5233.914 | Z27: 4778.802 | AA27: =SUM(C27:Z27) -> 150541.79 | AB27: 6 | AC27: =AA27*AB27 -> 903250.76
A28: 47300 | B28: Ordinario | C28: 5314.59 | D28: 5097.114 | E28: 4975.47 | F28: 4925.736 | G28: 5001.696 | H28: 5322.69 | I28: 6440.508 | J28: 8081.46 | K28: 9454.32 | L28: 10381.446 | M28: 11135.736 | N28: 11589.696 | O28: 11437.236 | P28: 11476.314 | Q28: 11780.406 | R28: 11785.374 | S28: 11453.166 | T28: 10688.652 | U28: 10125.486 | V28: 9485.658 | W28: 8639.766 | X28: 7678.134 | Y28: 6654.078 | Z28: 5955.066 | AA28: =SUM(C28:Z28) -> 204879.8 | AB28: 20 | AC28: =AA28*AB28 -> 4097596 | AD28: =SUM(AC28:AC30) -> 5902711.3
A29: 47300 | B29: Sábado | C29: 5774.94 | D29: 5473.458 | E29: 5305.356 | F29: 5175.036 | G29: 5200.002 | H29: 5221.224 | I29: 5981.202 | J29: 7343.73 | K29: 8638.092 | L29: 9648.99 | M29: 10279.818 | N29: 10569.312 | O29: 10272.798 | P29: 9947.232 | Q29: 9723.762 | R29: 9669.564 | S29: 9553.41 | T29: 9372.888 | U29: 9155.484 | V29: 8676.162 | W29: 7937.64 | X29: 7107.228 | Y29: 6220.08 | Z29: 5583.276 | AA29: =SUM(C29:Z29) -> 187830.68 | AB29: 4 | AC29: =AA29*AB29 -> 751322.74
A30: 47300 | B30: Festivo | C30: 5170.608 | D30: 4913.802 | E30: 4676.544 | F30: 4555.98 | G30: 4454.352 | H30: 4366.962 | I30: 4508.118 | J30: 5039.298 | K30: 5737.914 | L30: 6709.446 | M30: 7494.282 | N30: 7938.558 | O30: 8091.594 | P30: 8128.53 | Q30: 8072.37 | R30: 8033.274 | S30: 7843.23 | T30: 7652.934 | U30: 7546.392 | V30: 7170.39 | W30: 6561.738 | X30: 5862.762 | Y30: 5233.914 | Z30: 4778.802 | AA30: =SUM(C30:Z30) -> 150541.79 | AB30: 7 | AC30: =AA30*AB30 -> 1053792.6
A31: 47331 | B31: Ordinario | C31: 5314.59 | D31: 5097.114 | E31: 4975.47 | F31: 4925.736 | G31: 5001.696 | H31: 5322.69 | I31: 6440.508 | J31: 8081.46 | K31: 9454.32 | L31: 10381.446 | M31: 11135.736 | N31: 11589.696 | O31: 11437.236 | P31: 11476.314 | Q31: 11780.406 | R31: 11785.374 | S31: 11453.166 | T31: 10688.652 | U31: 10125.486 | V31: 9485.658 | W31: 8639.766 | X31: 7678.134 | Y31: 6654.078 | Z31: 5955.066 | AA31: =SUM(C31:Z31) -> 204879.8 | AB31: 21 | AC31: =AA31*AB31 -> 4302475.8 | AD31: =SUM(AC31:AC33) -> 5957049.3
A32: 47331 | B32: Sábado | C32: 5774.94 | D32: 5473.458 | E32: 5305.356 | F32: 5175.036 | G32: 5200.002 | H32: 5221.224 | I32: 5981.202 | J32: 7343.73 | K32: 8638.092 | L32: 9648.99 | M32: 10279.818 | N32: 10569.312 | O32: 10272.798 | P32: 9947.232 | Q32: 9723.762 | R32: 9669.564 | S32: 9553.41 | T32: 9372.888 | U32: 9155.484 | V32: 8676.162 | W32: 7937.64 | X32: 7107.228 | Y32: 6220.08 | Z32: 5583.276 | AA32: =SUM(C32:Z32) -> 187830.68 | AB32: 4 | AC32: =AA32*AB32 -> 751322.74
A33: 47331 | B33: Festivo | C33: 5170.608 | D33: 4913.802 | E33: 4676.544 | F33: 4555.98 | G33: 4454.352 | H33: 4366.962 | I33: 4508.118 | J33: 5039.298 | K33: 5737.914 | L33: 6709.446 | M33: 7494.282 | N33: 7938.558 | O33: 8091.594 | P33: 8128.53 | Q33: 8072.37 | R33: 8033.274 | S33: 7843.23 | T33: 7652.934 | U33: 7546.392 | V33: 7170.39 | W33: 6561.738 | X33: 5862.762 | Y33: 5233.914 | Z33: 4778.802 | AA33: =SUM(C33:Z33) -> 150541.79 | AB33: 6 | AC33: =AA33*AB33 -> 903250.76
A34: 47362 | B34: Ordinario | C34: 5314.59 | D34: 5097.114 | E34: 4975.47 | F34: 4925.736 | G34: 5001.696 | H34: 5322.69 | I34: 6440.508 | J34: 8081.46 | K34: 9454.32 | L34: 10381.446 | M34: 11135.736 | N34: 11589.696 | O34: 11437.236 | P34: 11476.314 | Q34: 11780.406 | R34: 11785.374 | S34: 11453.166 | T34: 10688.652 | U34: 10125.486 | V34: 9485.658 | W34: 8639.766 | X34: 7678.134 | Y34: 6654.078 | Z34: 5955.066 | AA34: =SUM(C34:Z34) -> 204879.8 | AB34: 20 | AC34: =AA34*AB34 -> 4097596 | AD34: =SUM(AC34:AC36) -> 5789458.3
A35: 47362 | B35: Sábado | C35: 5774.94 | D35: 5473.458 | E35: 5305.356 | F35: 5175.036 | G35: 5200.002 | H35: 5221.224 | I35: 5981.202 | J35: 7343.73 | K35: 8638.092 | L35: 9648.99 | M35: 10279.818 | N35: 10569.312 | O35: 10272.798 | P35: 9947.232 | Q35: 9723.762 | R35: 9669.564 | S35: 9553.41 | T35: 9372.888 | U35: 9155.484 | V35: 8676.162 | W35: 7937.64 | X35: 7107.228 | Y35: 6220.08 | Z35: 5583.276 | AA35: =SUM(C35:Z35) -> 187830.68 | AB35: 5 | AC35: =AA35*AB35 -> 939153.42
A36: 47362 | B36: Festivo | C36: 5170.608 | D36: 4913.802 | E36: 4676.544 | F36: 4555.98 | G36: 4454.352 | H36: 4366.962 | I36: 4508.118 | J36: 5039.298 | K36: 5737.914 | L36: 6709.446 | M36: 7494.282 | N36: 7938.558 | O36: 8091.594 | P36: 8128.53 | Q36: 8072.37 | R36: 8033.274 | S36: 7843.23 | T36: 7652.934 | U36: 7546.392 | V36: 7170.39 | W36: 6561.738 | X36: 5862.762 | Y36: 5233.914 | Z36: 4778.802 | AA36: =SUM(C36:Z36) -> 150541.79 | AB36: 5 | AC36: =AA36*AB36 -> 752708.97
A37: 47392 | B37: Ordinario | C37: 5314.59 | D37: 5097.114 | E37: 4975.47 | F37: 4925.736 | G37: 5001.696 | H37: 5322.69 | I37: 6440.508 | J37: 8081.46 | K37: 9454.32 | L37: 10381.446 | M37: 11135.736 | N37: 11589.696 | O37: 11437.236 | P37: 11476.314 | Q37: 11780.406 | R37: 11785.374 | S37: 11453.166 | T37: 10688.652 | U37: 10125.486 | V37: 9485.658 | W37: 8639.766 | X37: 7678.134 | Y37: 6654.078 | Z37: 5955.066 | AA37: =SUM(C37:Z37) -> 204879.8 | AB37: 22 | AC37: =AA37*AB37 -> 4507355.6 | AD37: =SUM(AC37:AC39) -> 6011387.3
A38: 47392 | B38: Sábado | C38: 5774.94 | D38: 5473.458 | E38: 5305.356 | F38: 5175.036 | G38: 5200.002 | H38: 5221.224 | I38: 5981.202 | J38: 7343.73 | K38: 8638.092 | L38: 9648.99 | M38: 10279.818 | N38: 10569.312 | O38: 10272.798 | P38: 9947.232 | Q38: 9723.762 | R38: 9669.564 | S38: 9553.41 | T38: 9372.888 | U38: 9155.484 | V38: 8676.162 | W38: 7937.64 | X38: 7107.228 | Y38: 6220.08 | Z38: 5583.276 | AA38: =SUM(C38:Z38) -> 187830.68 | AB38: 4 | AC38: =AA38*AB38 -> 751322.74
A39: 47392 | B39: Festivo | C39: 5170.608 | D39: 4913.802 | E39: 4676.544 | F39: 4555.98 | G39: 4454.352 | H39: 4366.962 | I39: 4508.118 | J39: 5039.298 | K39: 5737.914 | L39: 6709.446 | M39: 7494.282 | N39: 7938.558 | O39: 8091.594 | P39: 8128.53 | Q39: 8072.37 | R39: 8033.274 | S39: 7843.23 | T39: 7652.934 | U39: 7546.392 | V39: 7170.39 | W39: 6561.738 | X39: 5862.762 | Y39: 5233.914 | Z39: 4778.802 | AA39: =SUM(C39:Z39) -> 150541.79 | AB39: 5 | AC39: =AA39*AB39 -> 752708.97
A40: 47423 | B40: Ordinario | C40: 5314.59 | D40: 5097.114 | E40: 4975.47 | F40: 4925.736 | G40: 5001.696 | H40: 5322.69 | I40: 6440.508 | J40: 8081.46 | K40: 9454.32 | L40: 10381.446 | M40: 11135.736 | N40: 11589.696 | O40: 11437.236 | P40: 11476.314 | Q40: 11780.406 | R40: 11785.374 | S40: 11453.166 | T40: 10688.652 | U40: 10125.486 | V40: 9485.658 | W40: 8639.766 | X40: 7678.134 | Y40: 6654.078 | Z40: 5955.066 | AA40: =SUM(C40:Z40) -> 204879.8 | AB40: 20 | AC40: =AA40*AB40 -> 4097596 | AD40: =SUM(AC40:AC42) -> 5752169.5
A41: 47423 | B41: Sábado | C41: 5774.94 | D41: 5473.458 | E41: 5305.356 | F41: 5175.036 | G41: 5200.002 | H41: 5221.224 | I41: 5981.202 | J41: 7343.73 | K41: 8638.092 | L41: 9648.99 | M41: 10279.818 | N41: 10569.312 | O41: 10272.798 | P41: 9947.232 | Q41: 9723.762 | R41: 9669.564 | S41: 9553.41 | T41: 9372.888 | U41: 9155.484 | V41: 8676.162 | W41: 7937.64 | X41: 7107.228 | Y41: 6220.08 | Z41: 5583.276 | AA41: =SUM(C41:Z41) -> 187830.68 | AB41: 4 | AC41: =AA41*AB41 -> 751322.74
A42: 47423 | B42: Festivo | C42: 5170.608 | D42: 4913.802 | E42: 4676.544 | F42: 4555.98 | G42: 4454.352 | H42: 4366.962 | I42: 4508.118 | J42: 5039.298 | K42: 5737.914 | L42: 6709.446 | M42: 7494.282 | N42: 7938.558 | O42: 8091.594 | P42: 8128.53 | Q42: 8072.37 | R42: 8033.274 | S42: 7843.23 | T42: 7652.934 | U42: 7546.392 | V42: 7170.39 | W42: 6561.738 | X42: 5862.762 | Y42: 5233.914 | Z42: 4778.802 | AA42: =SUM(C42:Z42) -> 150541.79 | AB42: 6 | AC42: =AA42*AB42 -> 903250.76
A43: 47453 | B43: Ordinario | C43: 5314.59 | D43: 5097.114 | E43: 4975.47 | F43: 4925.736 | G43: 5001.696 | H43: 5322.69 | I43: 6440.508 | J43: 8081.46 | K43: 9454.32 | L43: 10381.446 | M43: 11135.736 | N43: 11589.696 | O43: 11437.236 | P43: 11476.314 | Q43: 11780.406 | R43: 11785.374 | S43: 11453.166 | T43: 10688.652 | U43: 10125.486 | V43: 9485.658 | W43: 8639.766 | X43: 7678.134 | Y43: 6654.078 | Z43: 5955.066 | AA43: =SUM(C43:Z43) -> 204879.8 | AB43: 20 | AC43: =AA43*AB43 -> 4097596 | AD43: =SUM(AC43:AC45) -> 5902711.3
A44: 47453 | B44: Sábado | C44: 5774.94 | D44: 5473.458 | E44: 5305.356 | F44: 5175.036 | G44: 5200.002 | H44: 5221.224 | I44: 5981.202 | J44: 7343.73 | K44: 8638.092 | L44: 9648.99 | M44: 10279.818 | N44: 10569.312 | O44: 10272.798 | P44: 9947.232 | Q44: 9723.762 | R44: 9669.564 | S44: 9553.41 | T44: 9372.888 | U44: 9155.484 | V44: 8676.162 | W44: 7937.64 | X44: 7107.228 | Y44: 6220.08 | Z44: 5583.276 | AA44: =SUM(C44:Z44) -> 187830.68 | AB44: 4 | AC44: =AA44*AB44 -> 751322.74
...

Sheet Oferta Producto 3
A4: CONVOCATORIA PÚBLICA N° CP-BIAC2026-003 - BIA ENERGY S.A.S. E.S.P.
B5: ANEXO 4. FORMATO DE OFERTA - PRODUCTO 3
B6: NOMBRE DEL OFERENTE
B7: Precios y cantidades de la energía ofertada
B8: En pesos de marzo de 2026
B10: OPCIÓN 24 HORAS
B11: Mes | C11: E. Solicitada [kWh-mes] | D11: % E. Ofertada | E11: E. Ofertada [kWh-mes] | F11: $/kWh
B12: 47149 | C12: ='Cant. Requeridas Producto 3'!AD10 -> 5957049.3
B13: 47150 | C13: ='Cant. Requeridas Producto 3'!AD13 -> 5451085.9 | E13: =C13*$D$13 -> 0
B14: 47178 | C14: ='Cant. Requeridas Producto 3'!AD16 -> 5885662.1 | E14: =C14*$D$13 -> 0
B15: 47209 | C15: ='Cant. Requeridas Producto 3'!AD19 -> 5806507.5 | E15: =C15*$D$13 -> 0
B16: 47239 | C16: ='Cant. Requeridas Producto 3'!AD22 -> 5957049.3 | E16: =C16*$D$13 -> 0
B17: 47270 | C17: ='Cant. Requeridas Producto 3'!AD25 -> 5735120.3 | E17: =C17*$D$13 -> 0
B18: 47300 | C18: ='Cant. Requeridas Producto 3'!AD28 -> 5902711.3 | E18: =C18*$D$13 -> 0
B19: 47331 | C19: ='Cant. Requeridas Producto 3'!AD31 -> 5957049.3 | E19: =C19*$D$13 -> 0
B20: 47362 | C20: ='Cant. Requeridas Producto 3'!AD34 -> 5789458.3 | E20: =C20*$D$13 -> 0
B21: 47392 | C21: ='Cant. Requeridas Producto 3'!AD37 -> 6011387.3 | E21: =C21*$D$13 -> 0
B22: 47423 | C22: ='Cant. Requeridas Producto 3'!AD40 -> 5752169.5 | E22: =C22*$D$13 -> 0
