Workbook

Sheet Anexo 1
B3: ANEXO No 1 - PRODUCTO No. 1 - CURVA
B4: PAGUE LO CONTRATADO AÑO 2026
B5: PRECIO OFERTADO EN $ / kWh DE ABRIL DE 2025
B8: MES | C8: ENERGIA SOLICITADA kWh/MES | D8: % OFERTADO ANUAL | E8: ENERGIA OFERTADA kWh/MES | F8: PRECIO OFERTADO ANUAL $/kWh
B10: 46023 | C10: =+'Anexo 11'!AC6 -> 3391082 | E10: =+'Cantidades Ofertadas Prod 1'!AC6 -> 0
B11: 46054 | C11: =+'Anexo 11'!AC9 -> 2821556 | E11: =+'Cantidades Ofertadas Prod 1'!AC9 -> 0
B12: 46082 | C12: =+'Anexo 11'!AC12 -> 3106413 | E12: =+'Cantidades Ofertadas Prod 1'!AC12 -> 0
B13: 46113 | C13: =+'Anexo 11'!AC15 -> 2813914 | E13: =+'Cantidades Ofertadas Prod 1'!AC15 -> 0
B14: 46143 | C14: =+'Anexo 11'!AC18 -> 2929799 | E14: =+'Cantidades Ofertadas Prod 1'!AC18 -> 0
B15: 46174 | C15: =+'Anexo 11'!AC21 -> 3370208 | E15: =+'Cantidades Ofertadas Prod 1'!AC21 -> 0
B16: 46204 | C16: =+'Anexo 11'!AC24 -> 3239178 | E16: =+'Cantidades Ofertadas Prod 1'!AC24 -> 0
B17: 46235 | C17: =+'Anexo 11'!AC27 -> 3279184 | E17: =+'Cantidades Ofertadas Prod 1'!AC27 -> 0
B18: 46266 | C18: =+'Anexo 11'!AC30 -> 3385268 | E18: =+'Cantidades Ofertadas Prod 1'!AC30 -> 0
B19: 46296 | C19: =+'Anexo 11'!AC33 -> 3124074 | E19: =+'Cantidades Ofertadas Prod 1'!AC33 -> 0
B20: 46327 | C20: =+'Anexo 11'!AC36 -> 2579989 | E20: =+'Cantidades Ofertadas Prod 1'!AC36 -> 0
B21: 46357 | C21: =+'Anexo 11'!AC39 -> 3523726 | E21: =+'Cantidades Ofertadas Prod 1'!AC39 -> 0
B22: TOTAL | C22: =+SUM(C10:C21) -> 37564391 | E22: =SUM(E10:E21) -> 0 | F22: =+F10 -> 0
B23: *Solo se debe ingresar valores en las celdas en color Naranja
B24: * Se debe ofertar un unico % para todos los meses del año.
B25: * Los % ofertados se aplicaran a las curvas de carga de la hoja "Anexo 11".
B26: * La energia ofertada se calcula de manera automatica en la hoja "Cantidades Ofertadas Prod 1"
B27: * Se debe ofertar un unico precio por producto.
B28: * Para ofertas planas se debe diligenciar el anexo 1A, con un tope horario de 500 kWh
B31: ____________________________________________
B32: Firma del Representante Legal
B33: o Apoderado General (Responsable del negocio)

Sheet Anexo 1A
B3: ANEXO No 1A - PRODUCTO No. 1 - OFERTA PLANA
B4: PAGUE LO CONTRATADO AÑO 2026
B5: PRECIO OFERTADO EN $ / kWh DE ABRIL DE 2025
B8: MES | C8: ENERGIA MAXIMA A OFERTAR kWh/MES | D8: kWh OFERTADO | E8: ENERGIA OFERTADA kWh/MES | F8: PRECIO OFERTADO ANUAL $/kWh
A9: 500
A10: 31 | B10: 46023 | C10: =+$A$9*A10*24 -> 372000 | E10: =+$D$10*A10*24 -> 0
A11: 28 | B11: 46054 | C11: =+$A$9*A11*24 -> 336000 | E11: =+$D$10*A11*24 -> 0
A12: 31 | B12: 46082 | C12: =+$A$9*A12*24 -> 372000 | E12: =+$D$10*A12*24 -> 0
A13: 30 | B13: 46113 | C13: =+$A$9*A13*24 -> 360000 | E13: =+$D$10*A13*24 -> 0
A14: 31 | B14: 46143 | C14: =+$A$9*A14*24 -> 372000 | E14: =+$D$10*A14*24 -> 0
A15: 30 | B15: 46174 | C15: =+$A$9*A15*24 -> 360000 | E15: =+$D$10*A15*24 -> 0
A16: 31 | B16: 46204 | C16: =+$A$9*A16*24 -> 372000 | E16: =+$D$10*A16*24 -> 0
A17: 31 | B17: 46235 | C17: =+$A$9*A17*24 -> 372000 | E17: =+$D$10*A17*24 -> 0
A18: 30 | B18: 46266 | C18: =+$A$9*A18*24 -> 360000 | E18: =+$D$10*A18*24 -> 0
A19: 31 | B19: 46296 | C19: =+$A$9*A19*24 -> 372000 | E19: =+$D$10*A19*24 -> 0
A20: 30 | B20: 46327 | C20: =+$A$9*A20*24 -> 360000 | E20: =+$D$10*A20*24 -> 0
A21: 31 | B21: 46357 | C21: =+$A$9*A21*24 -> 372000 | E21: =+$D$10*A21*24 -> 0
B22: TOTAL | C22: =+SUM(C10:C21) -> 4380000 | E22: =SUM(E10:E21) -> 0 | F22: =+F10 -> 0
B23: *Solo se debe ingresar valores en las celdas en color Naranja
B24: * Se debe oferta un valor de kWh el cual se aplica para todas las horas del año, con un tope horario de 500 kWh
B25: * Se debe ofertar un unico precio por producto.
B26: * A las ofertas planas al momento de la evaluación se le adicionarán 5 $/kWh al precio ofertado; con el fin de hacerlas comparables con las Ofertas que siguen la curva
B29: ____________________________________________
B30: Firma del Representante Legal
B31: o Apoderado General (Responsable del negocio)

Sheet Anexo 11
A1: CURVAS REQUERIDAS PRODUCTO 1 AÑO 2026 MODALIDAD PAGUE LO CONTRATADO - kWh
A4: Periodo | B4: Tipo de día | C4: H01 | D4: H02 | E4: H03 | F4: H04 | G4: H05 | H4: H06 | I4: H07 | J4: H08 | K4: H09 | L4: H10 | M4: H11 | N4: H12 | O4: H13 | P4: H14 | Q4: H15 | R4: H16 | S4: H17 | T4: H18 | U4: H19 | V4: H20 | W4: H21 | X4: H22 | Y4: H23 | Z4: H24 | AA4: TOTAL DÍA | AB4: Días/ | AC4: TOTAL MES
AB5: mes
A6: 46023 | B6: O | C6: 4279 | D6: 4158 | E6: 4042 | F6: 3963 | G6: 3909 | H6: 3826 | I6: 3634 | J6: 5008 | K6: 5418 | L6: 5669 | M6: 5942 | N6: 6215 | O6: 6337 | P6: 6362 | Q6: 6590 | R6: 6664 | S6: 6547 | T6: 4478 | U6: 4099 | V6: 4003 | W6: 3960 | X6: 3890 | Y6: 3830 | Z6: 3729 | AA6: =SUM(C6:Z6) -> 116552 | AB6: 20 | AC6: =+AA6*AB6+AA7*AB7+AA8*AB8 -> 3391082
B7: S | C7: 4164 | D7: 4060 | E7: 3971 | F7: 3900 | G7: 3839 | H7: 3822 | I7: 3539 | J7: 4691 | K7: 4991 | L7: 5229 | M7: 5447 | N7: 5626 | O7: 5813 | P7: 5773 | Q7: 5796 | R7: 5806 | S7: 5873 | T7: 3932 | U7: 3794 | V7: 3736 | W7: 3688 | X7: 3557 | Y7: 3462 | Z7: 3385 | AA7: =SUM(C7:Z7) -> 107894 | AB7: 5
B8: F | C8: 3085 | D8: 3065 | E8: 2998 | F8: 3010 | G8: 3036 | H8: 3135 | I8: 2916 | J8: 3963 | K8: 4187 | L8: 4378 | M8: 4513 | N8: 4739 | O8: 4914 | P8: 4824 | Q8: 4704 | R8: 4735 | S8: 4712 | T8: 2897 | U8: 2688 | V8: 2741 | W8: 2789 | X8: 2828 | Y8: 2932 | Z8: 2973 | AA8: =SUM(C8:Z8) -> 86762 | AB8: 6
A9: 46054 | B9: O | C9: 4043 | D9: 3967 | E9: 3890 | F9: 3814 | G9: 3772 | H9: 3644 | I9: 3036 | J9: 4372 | K9: 4673 | L9: 4876 | M9: 5027 | N9: 5252 | O9: 5329 | P9: 5428 | Q9: 5649 | R9: 5675 | S9: 5590 | T9: 3510 | U9: 3485 | V9: 3390 | W9: 3372 | X9: 3347 | Y9: 3357 | Z9: 3358 | AA9: =SUM(C9:Z9) -> 101856 | AB9: 20 | AC9: =+AA9*AB9+AA10*AB10+AA11*AB11 -> 2821556
B10: S | C10: 3884 | D10: 3869 | E10: 3787 | F10: 3715 | G10: 3699 | H10: 3667 | I10: 3100 | J10: 4165 | K10: 4278 | L10: 4386 | M10: 4626 | N10: 4716 | O10: 4848 | P10: 4838 | Q10: 4884 | R10: 4878 | S10: 4857 | T10: 3084 | U10: 3309 | V10: 3127 | W10: 3071 | X10: 3048 | Y10: 3025 | Z10: 3067 | AA10: =SUM(C10:Z10) -> 93928 | AB10: 4
B11: F | C11: 4184 | D11: 4143 | E11: 4083 | F11: 3934 | G11: 3949 | H11: 3953 | I11: 3364 | J11: 4360 | K11: 4541 | L11: 4696 | M11: 4828 | N11: 5044 | O11: 5122 | P11: 5153 | Q11: 5110 | R11: 5174 | S11: 5115 | T11: 3289 | U11: 3604 | V11: 3686 | W11: 3639 | X11: 3741 | Y11: 3776 | Z11: 3693 | AA11: =SUM(C11:Z11) -> 102181 | AB11: 4
A12: 46082 | B12: O | C12: 4474 | D12: 4370 | E12: 4251 | F12: 4184 | G12: 4109 | H12: 3912 | I12: 3147 | J12: 4469 | K12: 4724 | L12: 4928 | M12: 5141 | N12: 5358 | O12: 5522 | P12: 5567 | Q12: 5678 | R12: 5696 | S12: 5568 | T12: 3523 | U12: 3785 | V12: 3796 | W12: 3758 | X12: 3788 | Y12: 3812 | Z12: 3833 | AA12: =SUM(C12:Z12) -> 107393 | AB12: 21 | AC12: =+AA12*AB12+AA13*AB13+AA14*AB14 -> 3106413
B13: S | C13: 4022 | D13: 3942 | E13: 3819 | F13: 3821 | G13: 3730 | H13: 3623 | I13: 2946 | J13: 3905 | K13: 3984 | L13: 4028 | M13: 4131 | N13: 4242 | O13: 4445 | P13: 4524 | Q13: 4466 | R13: 4472 | S13: 4490 | T13: 2615 | U13: 2822 | V13: 2756 | W13: 2885 | X13: 2824 | Y13: 2884 | Z13: 3055 | AA13: =SUM(C13:Z13) -> 88431 | AB13: 4
B14: F | C14: 3717 | D14: 3711 | E14: 3647 | F14: 3619 | G14: 3545 | H14: 3562 | I14: 2722 | J14: 3557 | K14: 3586 | L14: 3607 | M14: 3692 | N14: 3741 | O14: 3936 | P14: 4049 | Q14: 4050 | R14: 4046 | S14: 4146 | T14: 2369 | U14: 2783 | V14: 2766 | W14: 2869 | X14: 2937 | Y14: 3102 | Z14: 3147 | AA14: =SUM(C14:Z14) -> 82906 | AB14: 6
A15: 46113 | B15: O | C15: 4244 | D15: 4148 | E15: 4032 | F15: 3967 | G15: 3888 | H15: 3574 | I15: 3006 | J15: 4287 | K15: 4401 | L15: 4545 | M15: 4684 | N15: 4951 | O15: 5310 | P15: 5288 | Q15: 5097 | R15: 5076 | S15: 4944 | T15: 3051 | U15: 3306 | V15: 3480 | W15: 3565 | X15: 3489 | Y15: 3502 | Z15: 3554 | AA15: =SUM(C15:Z15) -> 99389 | AB15: 20 | AC15: =+AA15*AB15+AA16*AB16+AA17*AB17 -> 2813914
B16: S | C16: 3835 | D16: 3787 | E16: 3698 | F16: 3639 | G16: 3607 | H16: 3557 | I16: 2901 | J16: 3982 | K16: 3939 | L16: 3974 | M16: 4105 | N16: 4252 | O16: 4548 | P16: 4514 | Q16: 4586 | R16: 4583 | S16: 4696 | T16: 2826 | U16: 3089 | V16: 3013 | W16: 3042 | X16: 2898 | Y16: 2979 | Z16: 3062 | AA16: =SUM(C16:Z16) -> 89112 | AB16: 4
B17: F | C17: 3323 | D17: 3380 | E17: 3309 | F17: 3271 | G17: 3173 | H17: 3141 | I17: 2461 | J17: 3370 | K17: 3457 | L17: 3514 | M17: 3624 | N17: 3680 | O17: 3885 | P17: 4077 | Q17: 4098 | R17: 4145 | S17: 4179 | T17: 2350 | U17: 2771 | V17: 2670 | W17: 2615 | X17: 2497 | Y17: 2610 | Z17: 2681 | AA17: =SUM(C17:Z17) -> 78281 | AB17: 6
A18: 46143 | B18: O | C18: 4237 | D18: 4131 | E18: 4060 | F18: 3964 | G18: 3897 | H18: 3580 | I18: 3020 | J18: 4315 | K18: 4521 | L18: 4709 | M18: 4815 | N18: 5019 | O18: 5293 | P18: 5227 | Q18: 5153 | R18: 5162 | S18: 5141 | T18: 3079 | U18: 3300 | V18: 3362 | W18: 3491 | X18: 3388 | Y18: 3426 | Z18: 3470 | AA18: =SUM(C18:Z18) -> 99760 | AB18: 19 | AC18: =+AA18*AB18+AA19*AB19+AA20*AB20 -> 2929799
B19: S | C19: 4077 | D19: 3964 | E19: 3985 | F19: 3894 | G19: 3847 | H19: 3661 | I19: 2949 | J19: 4027 | K19: 4055 | L19: 4275 | M19: 4437 | N19: 4551 | O19: 4688 | P19: 4596 | Q19: 4560 | R19: 4570 | S19: 4623 | T19: 2812 | U19: 3211 | V19: 3140 | W19: 3068 | X19: 3072 | Y19: 3021 | Z19: 3203 | AA19: =SUM(C19:Z19) -> 92286 | AB19: 5
B20: F | C20: 3644 | D20: 3645 | E20: 3585 | F20: 3523 | G20: 3500 | H20: 3407 | I20: 2596 | J20: 3560 | K20: 3554 | L20: 3621 | M20: 3654 | N20: 3698 | O20: 3908 | P20: 4041 | Q20: 4131 | R20: 4246 | S20: 4198 | T20: 2257 | U20: 2631 | V20: 2743 | W20: 2740 | X20: 2846 | Y20: 2975 | Z20: 3144 | AA20: =SUM(C20:Z20) -> 81847 | AB20: 7
A21: 46174 | B21: O | C21: 4228 | D21: 4224 | E21: 4116 | F21: 4073 | G21: 4072 | H21: 3932 | I21: 3527 | J21: 4864 | K21: 5069 | L21: 5320 | M21: 5482 | N21: 5803 | O21: 5966 | P21: 5792 | Q21: 5818 | R21: 5860 | S21: 5689 | T21: 3793 | U21: 4078 | V21: 4237 | W21: 4266 | X21: 4030 | Y21: 3808 | Z21: 3639 | AA21: =SUM(C21:Z21) -> 111686 | AB21: 19 | AC21: =+AA21*AB21+AA22*AB22+AA23*AB23 -> 3370208
B22: S | C22: 4157 | D22: 4150 | E22: 4016 | F22: 4016 | G22: 4072 | H22: 4018 | I22: 3447 | J22: 4689 | K22: 4831 | L22: 5093 | M22: 5189 | N22: 5414 | O22: 5514 | P22: 5496 | Q22: 5405 | R22: 5469 | S22: 5497 | T22: 3657 | U22: 4025 | V22: 3958 | W22: 3836 | X22: 3736 | Y22: 3570 | Z22: 3482 | AA22: =SUM(C22:Z22) -> 106737 | AB22: 4
B23: F | C23: 4451 | D23: 4367 | E23: 4312 | F23: 4244 | G23: 4284 | H23: 4322 | I23: 4012 | J23: 5189 | K23: 5427 | L23: 5609 | M23: 5700 | N23: 5846 | O23: 5829 | P23: 5917 | Q23: 6108 | R23: 6171 | S23: 6123 | T23: 4223 | U23: 4249 | V23: 4433 | W23: 4359 | X23: 4173 | Y23: 4031 | Z23: 3939 | AA23: =SUM(C23:Z23) -> 117318 | AB23: 7
A24: 46204 | B24: O | C24: 4257 | D24: 4236 | E24: 4128 | F24: 4044 | G24: 4010 | H24: 3836 | I24: 3352 | J24: 4772 | K24: 4981 | L24: 5230 | M24: 5400 | N24: 5697 | O24: 5813 | P24: 5719 | Q24: 5866 | R24: 5929 | S24: 5770 | T24: 3803 | U24: 3977 | V24: 4003 | W24: 4030 | X24: 3879 | Y24: 3665 | Z24: 3581 | AA24: =SUM(C24:Z24) -> 109978 | AB24: 22 | AC24: =+AA24*AB24+AA25*AB25+AA26*AB26 -> 3239178
B25: S | C25: 3628 | D25: 3651 | E25: 3536 | F25: 3501 | G25: 3565 | H25: 3529 | I25: 2885 | J25: 4101 | K25: 4198 | L25: 4398 | M25: 4522 | N25: 4720 | O25: 4840 | P25: 4752 | Q25: 4690 | R25: 4687 | S25: 4754 | T25: 2928 | U25: 3367 | V25: 3210 | W25: 3191 | X25: 3059 | Y25: 2941 | Z25: 2895 | AA25: =SUM(C25:Z25) -> 91548 | AB25: 4
B26: F | C26: 3698 | D26: 3708 | E26: 3652 | F26: 3533 | G26: 3529 | H26: 3422 | I26: 2859 | J26: 3898 | K26: 4001 | L26: 4189 | M26: 4311 | N26: 4416 | O26: 4647 | P26: 4686 | Q26: 4608 | R26: 4562 | S26: 4628 | T26: 2851 | U26: 3182 | V26: 3260 | W26: 3339 | X26: 3251 | Y26: 3261 | Z26: 3203 | AA26: =SUM(C26:Z26) -> 90694 | AB26: 5
A27: 46235 | B27: O | C27: 4174 | D27: 4094 | E27: 4001 | F27: 3905 | G27: 3882 | H27: 3650 | I27: 3155 | J27: 4606 | K27: 4910 | L27: 5139 | M27: 5346 | N27: 5677 | O27: 5806 | P27: 5737 | Q27: 5902 | R27: 5981 | S27: 5919 | T27: 3782 | U27: 3918 | V27: 3832 | W27: 3819 | X27: 3713 | Y27: 3613 | Z27: 3531 | AA27: =SUM(C27:Z27) -> 108092 | AB27: 19 | AC27: =+AA27*AB27+AA28*AB28+AA29*AB29 -> 3279184
B28: S | C28: 4284 | D28: 4230 | E28: 4188 | F28: 4066 | G28: 4071 | H28: 3987 | I28: 3529 | J28: 4668 | K28: 4943 | L28: 5140 | M28: 5225 | N28: 5519 | O28: 5740 | P28: 5491 | Q28: 5691 | R28: 5547 | S28: 5511 | T28: 3690 | U28: 3810 | V28: 3776 | W28: 3667 | X28: 3473 | Y28: 3458 | Z28: 3381 | AA28: =SUM(C28:Z28) -> 107085 | AB28: 5
B29: F | C29: 4197 | D29: 4123 | E29: 3972 | F29: 3900 | G29: 3913 | H29: 3850 | I29: 2964 | J29: 4142 | K29: 4236 | L29: 4399 | M29: 4556 | N29: 4692 | O29: 4860 | P29: 4969 | Q29: 4867 | R29: 4914 | S29: 4990 | T29: 3077 | U29: 3567 | V29: 3744 | W29: 3738 | X29: 3705 | Y29: 3681 | Z29: 3517 | AA29: =SUM(C29:Z29) -> 98573 | AB29: 7
A30: 46266 | B30: O | C30: 4548 | D30: 4402 | E30: 4313 | F30: 4237 | G30: 4184 | H30: 3956 | I30: 3500 | J30: 4968 | K30: 5332 | L30: 5650 | M30: 5842 | N30: 6198 | O30: 6285 | P30: 6225 | Q30: 6399 | R30: 6436 | S30: 6318 | T30: 4203 | U30: 4333 | V30: 4278 | W30: 4280 | X30: 4141 | Y30: 4015 | Z30: 3955 | AA30: =SUM(C30:Z30) -> 117998 | AB30: 22 | AC30: =+AA30*AB30+AA31*AB31+AA32*AB32 -> 3385268
B31: S | C31: 4050 | D31: 3966 | E31: 3895 | F31: 3841 | G31: 3807 | H31: 3655 | I31: 3180 | J31: 4345 | K31: 4702 | L31: 4895 | M31: 5039 | N31: 5172 | O31: 5318 | P31: 5188 | Q31: 5152 | R31: 5208 | S31: 5222 | T31: 3329 | U31: 3558 | V31: 3410 | W31: 3349 | X31: 3267 | Y31: 3213 | Z31: 3247 | AA31: =SUM(C31:Z31) -> 100008 | AB31: 4
B32: F | C32: 4014 | D32: 3972 | E32: 3850 | F32: 3823 | G32: 3843 | H32: 3723 | I32: 3129 | J32: 4226 | K32: 4407 | L32: 4541 | M32: 4665 | N32: 4781 | O32: 4938 | P32: 4960 | Q32: 4934 | R32: 4876 | S32: 4876 | T32: 3125 | U32: 3667 | V32: 3450 | W32: 3424 | X32: 3311 | Y32: 3348 | Z32: 3437 | AA32: =SUM(C32:Z32) -> 97320 | AB32: 4
A33: 46296 | B33: O | C33: 3977 | D33: 3866 | E33: 3778 | F33: 3737 | G33: 3677 | H33: 3475 | I33: 3162 | J33: 4526 | K33: 4837 | L33: 5049 | M33: 5259 | N33: 5513 | O33: 5642 | P33: 5593 | Q33: 5757 | R33: 5785 | S33: 5640 | T33: 3527 | U33: 3581 | V33: 3398 | W33: 3387 | X33: 3264 | Y33: 3224 | Z33: 3240 | AA33: =SUM(C33:Z33) -> 102894 | AB33: 21 | AC33: =+AA33*AB33+AA34*AB34+AA35*AB35 -> 3124074
B34: S | C34: 4138 | D34: 4045 | E34: 3947 | F34: 3870 | G34: 3901 | H34: 3745 | I34: 3377 | J34: 4649 | K34: 4950 | L34: 5204 | M34: 5331 | N34: 5500 | O34: 5617 | P34: 5443 | Q34: 5447 | R34: 5413 | S34: 5351 | T34: 3657 | U34: 3886 | V34: 3736 | W34: 3598 | X34: 3430 | Y34: 3388 | Z34: 3393 | AA34: =SUM(C34:Z34) -> 105016 | AB34: 5
B35: F | C35: 3709 | D35: 3577 | E35: 3553 | F35: 3469 | G35: 3454 | H35: 3359 | I35: 2895 | J35: 3946 | K35: 4019 | L35: 4219 | M35: 4331 | N35: 4401 | O35: 4507 | P35: 4610 | Q35: 4572 | R35: 4485 | S35: 4502 | T35: 2683 | U35: 2858 | V35: 2831 | W35: 2846 | X35: 2852 | Y35: 2970 | Z35: 2996 | AA35: =SUM(C35:Z35) -> 87644 | AB35: 5
A36: 46327 | B36: O | C36: 3452 | D36: 3457 | E36: 3392 | F36: 3325 | G36: 3290 | H36: 3080 | I36: 2877 | J36: 4165 | K36: 4395 | L36: 4535 | M36: 4624 | N36: 4860 | O36: 4976 | P36: 4924 | Q36: 4998 | R36: 5031 | S36: 4884 | T36: 2860 | U36: 2714 | V36: 2534 | W36: 2585 | X36: 2518 | Y36: 2563 | Z36: 2633 | AA36: =SUM(C36:Z36) -> 88672 | AB36: 19 | AC36: =+AA36*AB36+AA37*AB37+AA38*AB38 -> 2579989
B37: S | C37: 3274 | D37: 3244 | E37: 3188 | F37: 3165 | G37: 3156 | H37: 3112 | I37: 2924 | J37: 4063 | K37: 4211 | L37: 4316 | M37: 4330 | N37: 4435 | O37: 4615 | P37: 4615 | Q37: 4605 | R37: 4674 | S37: 4642 | T37: 2646 | U37: 2721 | V37: 2631 | W37: 2523 | X37: 2421 | Y37: 2531 | Z37: 2612 | AA37: =SUM(C37:Z37) -> 84654 | AB37: 4
B38: F | C38: 3184 | D38: 3258 | E38: 3152 | F38: 3062 | G38: 3079 | H38: 3058 | I38: 2686 | J38: 3712 | K38: 3816 | L38: 3990 | M38: 4063 | N38: 4070 | O38: 4249 | P38: 4360 | Q38: 4245 | R38: 4251 | S38: 4251 | T38: 2214 | U38: 2396 | V38: 2276 | W38: 2376 | X38: 2378 | Y38: 2612 | Z38: 2777 | AA38: =SUM(C38:Z38) -> 79515 | AB38: 7
A39: 46357 | B39: O | C39: 4014 | D39: 3992 | E39: 3875 | F39: 3793 | G39: 3798 | H39: 3871 | I39: 3897 | J39: 5233 | K39: 5655 | L39: 5959 | M39: 6239 | N39: 6550 | O39: 6619 | P39: 6528 | Q39: 6717 | R39: 6703 | S39: 6535 | T39: 4478 | U39: 4208 | V39: 4039 | W39: 3860 | X39: 3696 | Y39: 3553 | Z39: 3452 | AA39: =SUM(C39:Z39) -> 117264 | AB39: 21 | AC39: =+AA39*AB39+AA40*AB40+AA41*AB41 -> 3523726
B40: S | C40: 4421 | D40: 4238 | E40: 4155 | F40: 4091 | G40: 4147 | H40: 4161 | I40: 4171 | J40: 5476 | K40: 5918 | L40: 6199 | M40: 6505 | N40: 6728 | O40: 6611 | P40: 6439 | Q40: 6437 | R40: 6366 | S40: 6360 | T40: 4639 | U40: 4587 | V40: 4327 | W40: 4065 | X40: 3752 | Y40: 3545 | Z40: 3479 | AA40: =SUM(C40:Z40) -> 120817 | AB40: 4
B41: F | C41: 3308 | D41: 3294 | E41: 3271 | F41: 3282 | G41: 3329 | H41: 3422 | I41: 3397 | J41: 4521 | K41: 4739 | L41: 4983 | M41: 5185 | N41: 5361 | O41: 5417 | P41: 5379 | Q41: 5246 | R41: 5172 | S41: 5175 | T41: 3381 | U41: 3279 | V41: 3185 | W41: 3144 | X41: 3024 | Y41: 2947 | Z41: 2878 | AA41: =SUM(C41:Z41) -> 96319 | AB41: 6
A42: TOTAL AÑO | C42: =+SUM(C6:C41) -> 142375 | D42: =+SUM(D6:D41) -> 140434 | E42: =+SUM(E6:E41) -> 137447 | F42: =+SUM(F6:F41) -> 135195 | G42: =+SUM(G6:G41) -> 134563 | H42: =+SUM(H6:H41) -> 131227 | I42: =+SUM(I6:I41) -> 114262 | J42: =+SUM(J6:J41) -> 156790 | ... AC42: =+SUM(AC6:AC41) -> 37564391

Sheet Cantidades Ofertadas Prod 1
A1: CANTIDADES OFERTADAS PRODUCTO 1 AÑO 2026 MODALIDAD PAGUE LO CONTRATADO - kWh
A4: Periodo | B4: Tipo de día | C4: H01 | D4: H02 | E4: H03 | F4: H04 | G4: H05 | H4: H06 | I4: H07 | J4: H08 | K4: H09 | L4: H10 | M4: H11 | N4: H12 | O4: H13 | P4: H14 | Q4: H15 | R4: H16 | S4: H17 | T4: H18 | U4: H19 | V4: H20 | W4: H21 | X4: H22 | Y4: H23 | Z4: H24 | AA4: TOTAL DÍA | AB4: Días/ | AC4: TOTAL MES
AB5: mes
A6: 46023 | B6: O | C6: =ROUND('Anexo 11'!C6*'Anexo 1'!$D$10,0) -> 0 | D6: =ROUND('Anexo 11'!D6*'Anexo 1'!$D$10,0) -> 0 | E6: =ROUND('Anexo 11'!E6*'Anexo 1'!$D$10,0) -> 0 | F6: =ROUND('Anexo 11'!F6*'Anexo 1'!$D$10,0) -> 0 | G6: =ROUND('Anexo 11'!G6*'Anexo 1'!$D$10,0) -> 0 | H6: =ROUND('Anexo 11'!H6*'Anexo 1'!$D$10,0) -> 0 | I6: =ROUND('Anexo 11'!I6*'Anexo 1'!$D$10,0) -> 0 | J6: =ROUND('Anexo 11'!J6*'Anexo 1'!$D$10,0) -> 0 | ... Z6: =ROUND('Anexo 11'!Z6*'Anexo 1'!$D$10,0) -> 0 | AA6: =SUM(C6:Z6) -> 0 | AB6: 20 | AC6: =+AA6*AB6+AA7*AB7+AA8*AB8 -> 0
B7: S | C7: =ROUND('Anexo 11'!C7*'Anexo 1'!$D$10,0) -> 0 | D7: =ROUND('Anexo 11'!D7*'Anexo 1'!$D$10,0) -> 0 | E7: =ROUND('Anexo 11'!E7*'Anexo 1'!$D$10,0) -> 0 | F7: =ROUND('Anexo 11'!F7*'Anexo 1'!$D$10,0) -> 0 | G7: =ROUND('Anexo 11'!G7*'Anexo 1'!$D$10,0) -> 0 | H7: =ROUND('Anexo 11'!H7*'Anexo 1'!$D$10,0) -> 0 | I7: =ROUND('Anexo 11'!I7*'Anexo 1'!$D$10,0) -> 0 | J7: =ROUND('Anexo 11'!J7*'Anexo 1'!$D$10,0) -> 0 | ... Z7: =ROUND('Anexo 11'!Z7*'Anexo 1'!$D$10,0) -> 0 | AA7: =SUM(C7:Z7) -> 0 | AB7: 5
B8: F | C8: =ROUND('Anexo 11'!C8*'Anexo 1'!$D$10,0) -> 0 | D8: =ROUND('Anexo 11'!D8*'Anexo 1'!$D$10,0) -> 0 | E8: =ROUND('Anexo 11'!E8*'Anexo 1'!$D$10,0) -> 0 | F8: =ROUND('Anexo 11'!F8*'Anexo 1'!$D$10,0) -> 0 | G8: =ROUND('Anexo 11'!G8*'Anexo 1'!$D$10,0) -> 0 | H8: =ROUND('Anexo 11'!H8*'Anexo 1'!$D$10,0) -> 0 | I8: =ROUND('Anexo 11'!I8*'Anexo 1'!$D$10,0) -> 0 | J8: =ROUND('Anexo 11'!J8*'Anexo 1'!$D$10,0) -> 0 | ... Z8: =ROUND('Anexo 11'!Z8*'Anexo 1'!$D$10,0) -> 0 | AA8: =SUM(C8:Z8) -> 0 | AB8: 6
A9: 46054 | B9: O | C9: =ROUND('Anexo 11'!C9*'Anexo 1'!$D$10,0) -> 0 | D9: =ROUND('Anexo 11'!D9*'Anexo 1'!$D$10,0) -> 0 | E9: =ROUND('Anexo 11'!E9*'Anexo 1'!$D$10,0) -> 0 | F9: =ROUND('Anexo 11'!F9*'Anexo 1'!$D$10,0) -> 0 | G9: =ROUND('Anexo 11'!G9*'Anexo 1'!$D$10,0) -> 0 | H9: =ROUND('Anexo 11'!H9*'Anexo 1'!$D$10,0) -> 0 | I9: =ROUND('Anexo 11'!I9*'Anexo 1'!$D$10,0) -> 0 | J9: =ROUND('Anexo 11'!J9*'Anexo 1'!$D$10,0) -> 0 | ... Z9: =ROUND('Anexo 11'!Z9*'Anexo 1'!$D$10,0) -> 0 | AA9: =SUM(C9:Z9) -> 0 | AB9: 20 | AC9: =+AA9*AB9+AA10*AB10+AA11*AB11 -> 0
B10: S | C10: =ROUND('Anexo 11'!C10*'Anexo 1'!$D$10,0) -> 0 | D10: =ROUND('Anexo 11'!D10*'Anexo 1'!$D$10,0) -> 0 | E10: =ROUND('Anexo 11'!E10*'Anexo 1'!$D$10,0) -> 0 | F10: =ROUND('Anexo 11'!F10*'Anexo 1'!$D$10,0) -> 0 | G10: =ROUND('Anexo 11'!G10*'Anexo 1'!$D$10,0) -> 0 | H10: =ROUND('Anexo 11'!H10*'Anexo 1'!$D$10,0) -> 0 | I10: =ROUND('Anexo 11'!I10*'Anexo 1'!$D$10,0) -> 0 | J10: =ROUND('Anexo 11'!J10*'Anexo 1'!$D$10,0) -> 0 | ... Z10: =ROUND('Anexo 11'!Z10*'Anexo 1'!$D$10,0) -> 0 | AA10: =SUM(C10:Z10) -> 0 | AB10: 4
B11: F | C11: =ROUND('Anexo 11'!C11*'Anexo 1'!$D$10,0) -> 0 | D11: =ROUND('Anexo 11'!D11*'Anexo 1'!$D$10,0) -> 0 | E11: =ROUND('Anexo 11'!E11*'Anexo 1'!$D$10,0) -> 0 | F11: =ROUND('Anexo 11'!F11*'Anexo 1'!$D$10,0) -> 0 | G11: =ROUND('Anexo 11'!G11*'Anexo 1'!$D$10,0) -> 0 | H11: =ROUND('Anexo 11'!H11*'Anexo 1'!$D$10,0) -> 0 | I11: =ROUND('Anexo 11'!I11*'Anexo 1'!$D$10,0) -> 0 | J11: =ROUND('Anexo 11'!J11*'Anexo 1'!$D$10,0) -> 0 | ... Z11: =ROUND('Anexo 11'!Z11*'Anexo 1'!$D$10,0) -> 0 | AA11: =SUM(C11:Z11) -> 0 | AB11: 4
A12: 46082 | B12: O | C12: =ROUND('Anexo 11'!C12*'Anexo 1'!$D$10,0) -> 0 | D12: =ROUND('Anexo 11'!D12*'Anexo 1'!$D$10,0) -> 0 | E12: =ROUND('Anexo 11'!E12*'Anexo 1'!$D$10,0) -> 0 | F12: =ROUND('Anexo 11'!F12*'Anexo 1'!$D$10,0) -> 0 | G12: =ROUND('Anexo 11'!G12*'Anexo 1'!$D$10,0) -> 0 | H12: =ROUND('Anexo 11'!H12*'Anexo 1'!$D$10,0) -> 0 | I12: =ROUND('Anexo 11'!I12*'Anexo 1'!$D$10,0) -> 0 | J12: =ROUND('Anexo 11'!J12*'Anexo 1'!$D$10,0) -> 0 | ... Z12: =ROUND('Anexo 11'!Z12*'Anexo 1'!$D$10,0) -> 0 | AA12: =SUM(C12:Z12) -> 0 | AB12: 21 | AC12: =+AA12*AB12+AA13*AB13+AA14*AB14 -> 0
B13: S | C13: =ROUND('Anexo 11'!C13*'Anexo 1'!$D$10,0) -> 0 | D13: =ROUND('Anexo 11'!D13*'Anexo 1'!$D$10,0) -> 0 | E13: =ROUND('Anexo 11'!E13*'Anexo 1'!$D$10,0) -> 0 | F13: =ROUND('Anexo 11'!F13*'Anexo 1'!$D$10,0) -> 0 | G13: =ROUND('Anexo 11'!G13*'Anexo 1'!$D$10,0) -> 0 | H13: =ROUND('Anexo 11'!H13*'Anexo 1'!$D$10,0) -> 0 | I13: =ROUND('Anexo 11'!I13*'Anexo 1'!$D$10,0) -> 0 | J13: =ROUND('Anexo 11'!J13*'Anexo 1'!$D$10,0) -> 0 | ... Z13: =ROUND('Anexo 11'!Z13*'Anexo 1'!$D$10,0) -> 0 | AA13: =SUM(C13:Z13) -> 0 | AB13: 4
B14: F | C14: =ROUND('Anexo 11'!C14*'Anexo 1'!$D$10,0) -> 0 | D14: =ROUND('Anexo 11'!D14*'Anexo 1'!$D$10,0) -> 0 | E14: =ROUND('Anexo 11'!E14*'Anexo 1'!$D$10,0) -> 0 | F14: =ROUND('Anexo 11'!F14*'Anexo 1'!$D$10,0) -> 0 | G14: =ROUND('Anexo 11'!G14*'Anexo 1'!$D$10,0) -> 0 | H14: =ROUND('Anexo 11'!H14*'Anexo 1'!$D$10,0) -> 0 | I14: =ROUND('Anexo 11'!I14*'Anexo 1'!$D$10,0) -> 0 | J14: =ROUND('Anexo 11'!J14*'Anexo 1'!$D$10,0) -> 0 | ... Z14: =ROUND('Anexo 11'!Z14*'Anexo 1'!$D$10,0) -> 0 | AA14: =SUM(C14:Z14) -> 0 | AB14: 6
A15: 46113 | B15: O | C15: =ROUND('Anexo 11'!C15*'Anexo 1'!$D$10,0) -> 0 | D15: =ROUND('Anexo 11'!D15*'Anexo 1'!$D$10,0) -> 0 | E15: =ROUND('Anexo 11'!E15*'Anexo 1'!$D$10,0) -> 0 | F15: =ROUND('Anexo 11'!F15*'Anexo 1'!$D$10,0) -> 0 | G15: =ROUND('Anexo 11'!G15*'Anexo 1'!$D$10,0) -> 0 | H15: =ROUND('Anexo 11'!H15*'Anexo 1'!$D$10,0) -> 0 | I15: =ROUND('Anexo 11'!I15*'Anexo 1'!$D$10,0) -> 0 | J15: =ROUND('Anexo 11'!J15*'Anexo 1'!$D$10,0) -> 0 | ... Z15: =ROUND('Anexo 11'!Z15*'Anexo 1'!$D$10,0) -> 0 | AA15: =SUM(C15:Z15) -> 0 | AB15: 20 | AC15: =+AA15*AB15+AA16*AB16+AA17*AB17 -> 0
B16: S | C16: =ROUND('Anexo 11'!C16*'Anexo 1'!$D$10,0) -> 0 | D16: =ROUND('Anexo 11'!D16*'Anexo 1'!$D$10,0) -> 0 | E16: =ROUND('Anexo 11'!E16*'Anexo 1'!$D$10,0) -> 0 | F16: =ROUND('Anexo 11'!F16*'Anexo 1'!$D$10,0) -> 0 | G16: =ROUND('Anexo 11'!G16*'Anexo 1'!$D$10,0) -> 0 | H16: =ROUND('Anexo 11'!H16*'Anexo 1'!$D$10,0) -> 0 | I16: =ROUND('Anexo 11'!I16*'Anexo 1'!$D$10,0) -> 0 | J16: =ROUND('Anexo 11'!J16*'Anexo 1'!$D$10,0) -> 0 | ... Z16: =ROUND('Anexo 11'!Z16*'Anexo 1'!$D$10,0) -> 0 | AA16: =SUM(C16:Z16) -> 0 | AB16: 4
B17: F | C17: =ROUND('Anexo 11'!C17*'Anexo 1'!$D$10,0) -> 0 | D17: =ROUND('Anexo 11'!D17*'Anexo 1'!$D$10,0) -> 0 | E17: =ROUND('Anexo 11'!E17*'Anexo 1'!$D$10,0) -> 0 | F17: =ROUND('Anexo 11'!F17*'Anexo 1'!$D$10,0) -> 0 | G17: =ROUND('Anexo 11'!G17*'Anexo 1'!$D$10,0) -> 0 | H17: =ROUND('Anexo 11'!H17*'Anexo 1'!$D$10,0) -> 0 | I17: =ROUND('Anexo 11'!I17*'Anexo 1'!$D$10,0) -> 0 | J17: =ROUND('Anexo 11'!J17*'Anexo 1'!$D$10,0) -> 0 | ... Z17: =ROUND('Anexo 11'!Z17*'Anexo 1'!$D$10,0) -> 0 | AA17: =SUM(C17:Z17) -> 0 | AB17: 6
A18: 46143 | B18: O | C18: =ROUND('Anexo 11'!C18*'Anexo 1'!$D$10,0) -> 0 | D18: =ROUND('Anexo 11'!D18*'Anexo 1'!$D$10,0) -> 0 | E18: =ROUND('Anexo 11'!E18*'Anexo 1'!$D$10,0) -> 0 | F18: =ROUND('Anexo 11'!F18*'Anexo 1'!$D$10,0) -> 0 | G18: =ROUND('Anexo 11'!G18*'Anexo 1'!$D$10,0) -> 0 | H18: =ROUND('Anexo 11'!H18*'Anexo 1'!$D$10,0) -> 0 | I18: =ROUND('Anexo 11'!I18*'Anexo 1'!$D$10,0) -> 0 | J18: =ROUND('Anexo 11'!J18*'Anexo 1'!$D$10,0) -> 0 | ... Z18: =ROUND('Anexo 11'!Z18*'Anexo 1'!$D$10,0) -> 0 | AA18: =SUM(C18:Z18) -> 0 | AB18: 19 | AC18: =+AA18*AB18+AA19*AB19+AA20*AB20 -> 0
B19: S | C19: =ROUND('Anexo 11'!C19*'Anexo 1'!$D$10,0) -> 0 | D19: =ROUND('Anexo 11'!D19*'Anexo 1'!$D$10,0) -> 0 | E19: =ROUND('Anexo 11'!E19*'Anexo 1'!$D$10,0) -> 0 | F19: =ROUND('Anexo 11'!F19*'Anexo 1'!$D$10,0) -> 0 | G19: =ROUND('Anexo 11'!G19*'Anexo 1'!$D$10,0) -> 0 | H19: =ROUND('Anexo 11'!H19*'Anexo 1'!$D$10,0) -> 0 | I19: =ROUND('Anexo 11'!I19*'Anexo 1'!$D$10,0) -> 0 | J19: =ROUND('Anexo 11'!J19*'Anexo 1'!$D$10,0) -> 0 | ... Z19: =ROUND('Anexo 11'!Z19*'Anexo 1'!$D$10,0) -> 0 | AA19: =SUM(C19:Z19) -> 0 | AB19: 5
B20: F | C20: =ROUND('Anexo 11'!C20*'Anexo 1'!$D$10,0) -> 0 | D20: =ROUND('Anexo 11'!D20*'Anexo 1'!$D$10,0) -> 0 | E20: =ROUND('Anexo 11'!E20*'Anexo 1'!$D$10,0) -> 0 | F20: =ROUND('Anexo 11'!F20*'Anexo 1'!$D$10,0) -> 0 | G20: =ROUND('Anexo 11'!G20*'Anexo 1'!$D$10,0) -> 0 | H20: =ROUND('Anexo 11'!H20*'Anexo 1'!$D$10,0) -> 0 | I20: =ROUND('Anexo 11'!I20*'Anexo 1'!$D$10,0) -> 0 | J20: =ROUND('Anexo 11'!J20*'Anexo 1'!$D$10,0) -> 0 | ... Z20: =ROUND('Anexo 11'!Z20*'Anexo 1'!$D$10,0) -> 0 | AA20: =SUM(C20:Z20) -> 0 | AB20: 7
A21: 46174 | B21: O | C21: =ROUND('Anexo 11'!C21*'Anexo 1'!$D$10,0) -> 0 | D21: =ROUND('Anexo 11'!D21*'Anexo 1'!$D$10,0) -> 0 | E21: =ROUND('Anexo 11'!E21*'Anexo 1'!$D$10,0) -> 0 | F21: =ROUND('Anexo 11'!F21*'Anexo 1'!$D$10,0) -> 0 | G21: =ROUND('Anexo 11'!G21*'Anexo 1'!$D$10,0) -> 0 | H21: =ROUND('Anexo 11'!H21*'Anexo 1'!$D$10,0) -> 0 | I21: =ROUND('Anexo 11'!I21*'Anexo 1'!$D$10,0) -> 0 | J21: =ROUND('Anexo 11'!J21*'Anexo 1'!$D$10,0) -> 0 | ... Z21: =ROUND('Anexo 11'!Z21*'Anexo 1'!$D$10,0) -> 0 | AA21: =SUM(C21:Z21) -> 0 | AB21: 19 | AC21: =+AA21*AB21+AA22*AB22+AA23*AB23 -> 0
B22: S | C22: =ROUND('Anexo 11'!C22*'Anexo 1'!$D$10,0) -> 0 | D22: =ROUND('Anexo 11'!D22*'Anexo 1'!$D$10,0) -> 0 | E22: =ROUND('Anexo 11'!E22*'Anexo 1'!$D$10,0) -> 0 | F22: =ROUND('Anexo 11'!F22*'Anexo 1'!$D$10,0) -> 0 | G22: =ROUND('Anexo 11'!G22*'Anexo 1'!$D$10,0) -> 0 | H22: =ROUND('Anexo 11'!H22*'Anexo 1'!$D$10,0) -> 0 | I22: =ROUND('Anexo 11'!I22*'Anexo 1'!$D$10,0) -> 0 | J22: =ROUND('Anexo 11'!J22*'Anexo 1'!$D$10,0) -> 0 | ... Z22: =ROUND('Anexo 11'!Z22*'Anexo 1'!$D$10,0) -> 0 | AA22: =SUM(C22:Z22) -> 0 | AB22: 4
B23: F | C23: =ROUND('Anexo 11'!C23*'Anexo 1'!$D$10,0) -> 0 | D23: =ROUND('Anexo 11'!D23*'Anexo 1'!$D$10,0) -> 0 | E23: =ROUND('Anexo 11'!E23*'Anexo 1'!$D$10,0) -> 0 | F23: =ROUND('Anexo 11'!F23*'Anexo 1'!$D$10,0) -> 0 | G23: =ROUND('Anexo 11'!G23*'Anexo 1'!$D$10,0) -> 0 | H23: =ROUND('Anexo 11'!H23*'Anexo 1'!$D$10,0) -> 0 | I23: =ROUND('Anexo 11'!I23*'Anexo 1'!$D$10,0) -> 0 | J23: =ROUND('Anexo 11'!J23*'Anexo 1'!$D$10,0) -> 0 | ... Z23: =ROUND('Anexo 11'!Z23*'Anexo 1'!$D$10,0) -> 0 | AA23: =SUM(C23:Z23) -> 0 | AB23: 7
A24: 46204 | B24: O | C24: =ROUND('Anexo 11'!C24*'Anexo 1'!$D$10,0) -> 0 | D24: =ROUND('Anexo 11'!D24*'Anexo 1'!$D$10,0) -> 0 | E24: =ROUND('Anexo 11'!E24*'Anexo 1'!$D$10,0) -> 0 | F24: =ROUND('Anexo 11'!F24*'Anexo 1'!$D$10,0) -> 0 | G24: =ROUND('Anexo 11'!G24*'Anexo 1'!$D$10,0) -> 0 | H24: =ROUND('Anexo 11'!H24*'Anexo 1'!$D$10,0) -> 0 | I24: =ROUND('Anexo 11'!I24*'Anexo 1'!$D$10,0) -> 0 | J24: =ROUND('Anexo 11'!J24*'Anexo 1'!$D$10,0) -> 0 | ... Z24: =ROUND('Anexo 11'!Z24*'Anexo 1'!$D$10,0) -> 0 | AA24: =SUM(C24:Z24) -> 0 | AB24: 22 | AC24: =+AA24*AB24+AA25*AB25+AA26*AB26 -> 0
B25: S | C25: =ROUND('Anexo 11'!C25*'Anexo 1'!$D$10,0) -> 0 | D25: =ROUND('Anexo 11'!D25*'Anexo 1'!$D$10,0) -> 0 | E25: =ROUND('Anexo 11'!E25*'Anexo 1'!$D$10,0) -> 0 | F25: =ROUND('Anexo 11'!F25*'Anexo 1'!$D$10,0) -> 0 | G25: =ROUND('Anexo 11'!G25*'Anexo 1'!$D$10,0) -> 0 | H25: =ROUND('Anexo 11'!H25*'Anexo 1'!$D$10,0) -> 0 | I25: =ROUND('Anexo 11'!I25*'Anexo 1'!$D$10,0) -> 0 | J25: =ROUND('Anexo 11'!J25*'Anexo 1'!$D$10,0) -> 0 | ... Z25: =ROUND('Anexo 11'!Z25*'Anexo 1'!$D$10,0) -> 0 | AA25: =SUM(C25:Z25) -> 0 | AB25: 4
B26: F | C26: =ROUND('Anexo 11'!C26*'Anexo 1'!$D$10,0) -> 0 | D26: =ROUND('Anexo 11'!D26*'Anexo 1'!$D$10,0) -> 0 | E26: =ROUND('Anexo 11'!E26*'Anexo 1'!$D$10,0) -> 0 | F26: =ROUND('Anexo 11'!F26*'Anexo 1'!$D$10,0) -> 0 | G26: =ROUND('Anexo 11'!G26*'Anexo 1'!$D$10,0) -> 0 | H26: =ROUND('Anexo 11'!H26*'Anexo 1'!$D$10,0) -> 0 | I26: =ROUND('Anexo 11'!I26*'Anexo 1'!$D$10,0) -> 0 | J26: =ROUND('Anexo 11'!J26*'Anexo 1'!$D$10,0) -> 0 | ... Z26: =ROUND('Anexo 11'!Z26*'Anexo 1'!$D$10,0) -> 0 | AA26: =SUM(C26:Z26) -> 0 | AB26: 5
A27: 46235 | B27: O | C27: =ROUND('Anexo 11'!C27*'Anexo 1'!$D$10,0) -> 0 | D27: =ROUND('Anexo 11'!D27*'Anexo 1'!$D$10,0) -> 0 | E27: =ROUND('Anexo 11'!E27*'Anexo 1'!$D$10,0) -> 0 | F27: =ROUND('Anexo 11'!F27*'Anexo 1'!$D$10,0) -> 0 | G27: =ROUND('Anexo 11'!G27*'Anexo 1'!$D$10,0) -> 0 | H27: =ROUND('Anexo 11'!H27*'Anexo 1'!$D$10,0) -> 0 | I27: =ROUND('Anexo 11'!I27*'Anexo 1'!$D$10,0) -> 0 | J27: =ROUND('Anexo 11'!J27*'Anexo 1'!$D$10,0) -> 0 | ... Z27: =ROUND('Anexo 11'!Z27*'Anexo 1'!$D$10,0) -> 0 | AA27: =SUM(C27:Z27) -> 0 | AB27: 19 | AC27: =+AA27*AB27+AA28*AB28+AA29*AB29 -> 0
B28: S | C28: =ROUND('Anexo 11'!C28*'Anexo 1'!$D$10,0) -> 0 | D28: =ROUND('Anexo 11'!D28*'Anexo 1'!$D$10,0) -> 0 | E28: =ROUND('Anexo 11'!E28*'Anexo 1'!$D$10,0) -> 0 | F28: =ROUND('Anexo 11'!F28*'Anexo 1'!$D$10,0) -> 0 | G28: =ROUND('Anexo 11'!G28*'Anexo 1'!$D$10,0) -> 0 | H28: =ROUND('Anexo 11'!H28*'Anexo 1'!$D$10,0) -> 0 | I28: =ROUND('Anexo 11'!I28*'Anexo 1'!$D$10,0) -> 0 | J28: =ROUND('Anexo 11'!J28*'Anexo 1'!$D$10,0) -> 0 | ... Z28: =ROUND('Anexo 11'!Z28*'Anexo 1'!$D$10,0) -> 0 | AA28: =SUM(C28:Z28) -> 0 | AB28: 5
B29: F | C29: =ROUND('Anexo 11'!C29*'Anexo 1'!$D$10,0) -> 0 | D29: =ROUND('Anexo 11'!D29*'Anexo 1'!$D$10,0) -> 0 | E29: =ROUND('Anexo 11'!E29*'Anexo 1'!$D$10,0) -> 0 | F29: =ROUND('Anexo 11'!F29*'Anexo 1'!$D$10,0) -> 0 | G29: =ROUND('Anexo 11'!G29*'Anexo 1'!$D$10,0) -> 0 | H29: =ROUND('Anexo 11'!H29*'Anexo 1'!$D$10,0) -> 0 | I29: =ROUND('Anexo 11'!I29*'Anexo 1'!$D$10,0) -> 0 | J29: =ROUND('Anexo 11'!J29*'Anexo 1'!$D$10,0) -> 0 | ... Z29: =ROUND('Anexo 11'!Z29*'Anexo 1'!$D$10,0) -> 0 | AA29: =SUM(C29:Z29) -> 0 | AB29: 7
A30: 46266 | B30: O | C30: =ROUND('Anexo 11'!C30*'Anexo 1'!$D$10,0) -> 0 | D30: =ROUND('Anexo 11'!D30*'Anexo 1'!$D$10,0) -> 0 | E30: =ROUND('Anexo 11'!E30*'Anexo 1'!$D$10,0) -> 0 | F30: =ROUND('Anexo 11'!F30*'Anexo 1'!$D$10,0) -> 0 | G30: =ROUND('Anexo 11'!G30*'Anexo 1'!$D$10,0) -> 0 | H30: =ROUND('Anexo 11'!H30*'Anexo 1'!$D$10,0) -> 0 | I30: =ROUND('Anexo 11'!I30*'Anexo 1'!$D$10,0) -> 0 | J30: =ROUND('Anexo 11'!J30*'Anexo 1'!$D$10,0) -> 0 | ... Z30: =ROUND('Anexo 11'!Z30*'Anexo 1'!$D$10,0) -> 0 | AA30: =SUM(C30:Z30) -> 0 | AB30: 22 | AC30: =+AA30*AB30+AA31*AB31+AA32*AB32 -> 0
B31: S | C31: =ROUND('Anexo 11'!C31*'Anexo 1'!$D$10,0) -> 0 | D31: =ROUND('Anexo 11'!D31*'Anexo 1'!$D$10,0) -> 0 | E31: =ROUND('Anexo 11'!E31*'Anexo 1'!$D$10,0) -> 0 | F31: =ROUND('Anexo 11'!F31*'Anexo 1'!$D$10,0) -> 0 | G31: =ROUND('Anexo 11'!G31*'Anexo 1'!$D$10,0) -> 0 | H31: =ROUND('Anexo 11'!H31*'Anexo 1'!$D$10,0) -> 0 | I31: =ROUND('Anexo 11'!I31*'Anexo 1'!$D$10,0) -> 0 | J31: =ROUND('Anexo 11'!J31*'Anexo 1'!$D$10,0) -> 0 | ... Z31: =ROUND('Anexo 11'!Z31*'Anexo 1'!$D$10,0) -> 0 | AA31: =SUM(C31:Z31) -> 0 | AB31: 4
B32: F | C32: =ROUND('Anexo 11'!C32*'Anexo 1'!$D$10,0) -> 0 | D32: =ROUND('Anexo 11'!D32*'Anexo 1'!$D$10,0) -> 0 | E32: =ROUND('Anexo 11'!E32*'Anexo 1'!$D$10,0) -> 0 | F32: =ROUND('Anexo 11'!F32*'Anexo 1'!$D$10,0) -> 0 | G32: =ROUND('Anexo 11'!G32*'Anexo 1'!$D$10,0) -> 0 | H32: =ROUND('Anexo 11'!H32*'Anexo 1'!$D$10,0) -> 0 | I32: =ROUND('Anexo 11'!I32*'Anexo 1'!$D$10,0) -> 0 | J32: =ROUND('Anexo 11'!J32*'Anexo 1'!$D$10,0) -> 0 | ... Z32: =ROUND('Anexo 11'!Z32*'Anexo 1'!$D$10,0) -> 0 | AA32: =SUM(C32:Z32) -> 0 | AB32: 4
A33: 46296 | B33: O | C33: =ROUND('Anexo 11'!C33*'Anexo 1'!$D$10,0) -> 0 | D33: =ROUND('Anexo 11'!D33*'Anexo 1'!$D$10,0) -> 0 | E33: =ROUND('Anexo 11'!E33*'Anexo 1'!$D$10,0) -> 0 | F33: =ROUND('Anexo 11'!F33*'Anexo 1'!$D$10,0) -> 0 | G33: =ROUND('Anexo 11'!G33*'Anexo 1'!$D$10,0) -> 0 | H33: =ROUND('Anexo 11'!H33*'Anexo 1'!$D$10,0) -> 0 | I33: =ROUND('Anexo 11'!I33*'Anexo 1'!$D$10,0) -> 0 | J33: =ROUND('Anexo 11'!J33*'Anexo 1'!$D$10,0) -> 0 | ... Z33: =ROUND('Anexo 11'!Z33*'Anexo 1'!$D$10,0) -> 0 | AA33: =SUM(C33:Z33) -> 0 | AB33: 21 | AC33: =+AA33*AB33+AA34*AB34+AA35*AB35 -> 0
B34: S | C34: =ROUND('Anexo 11'!C34*'Anexo 1'!$D$10,0) -> 0 | D34: =ROUND('Anexo 11'!D34*'Anexo 1'!$D$10,0) -> 0 | E34: =ROUND('Anexo 11'!E34*'Anexo 1'!$D$10,0) -> 0 | F34: =ROUND('Anexo 11'!F34*'Anexo 1'!$D$10,0) -> 0 | G34: =ROUND('Anexo 11'!G34*'Anexo 1'!$D$10,0) -> 0 | H34: =ROUND('Anexo 11'!H34*'Anexo 1'!$D$10,0) -> 0 | I34: =ROUND('Anexo 11'!I34*'Anexo 1'!$D$10,0) -> 0 | J34: =ROUND('Anexo 11'!J34*'Anexo 1'!$D$10,0) -> 0 | ... Z34: =ROUND('Anexo 11'!Z34*'Anexo 1'!$D$10,0) -> 0 | AA34: =SUM(C34:Z34) -> 0 | AB34: 5
B35: F | C35: =ROUND('Anexo 11'!C35*'Anexo 1'!$D$10,0) -> 0 | D35: =ROUND('Anexo 11'!D35*'Anexo 1'!$D$10,0) -> 0 | E35: =ROUND('Anexo 11'!E35*'Anexo 1'!$D$10,0) -> 0 | F35: =ROUND('Anexo 11'!F35*'Anexo 1'!$D$10,0) -> 0 | G35: =ROUND('Anexo 11'!G35*'Anexo 1'!$D$10,0) -> 0 | H35: =ROUND('Anexo 11'!H35*'Anexo 1'!$D$10,0) -> 0 | I35: =ROUND('Anexo 11'!I35*'Anexo 1'!$D$10,0) -> 0 | J35: =ROUND('Anexo 11'!J35*'Anexo 1'!$D$10,0) -> 0 | ... Z35: =ROUND('Anexo 11'!Z35*'Anexo 1'!$D$10,0) -> 0 | AA35: =SUM(C35:Z35) -> 0 | AB35: 5
A36: 46327 | B36: O | C36: =ROUND('Anexo 11'!C36*'Anexo 1'!$D$10,0) -> 0 | D36: =ROUND('Anexo 11'!D36*'Anexo 1'!$D$10,0) -> 0 | E36: =ROUND('Anexo 11'!E36*'Anexo 1'!$D$10,0) -> 0 | F36: =ROUND('Anexo 11'!F36*'Anexo 1'!$D$10,0) -> 0 | G36: =ROUND('Anexo 11'!G36*'Anexo 1'!$D$10,0) -> 0 | H36: =ROUND('Anexo 11'!H36*'Anexo 1'!$D$10,0) -> 0 | I36: =ROUND('Anexo 11'!I36*'Anexo 1'!$D$10,0) -> 0 | J36: =ROUND('Anexo 11'!J36*'Anexo 1'!$D$10,0) -> 0 | ... Z36: =ROUND('Anexo 11'!Z36*'Anexo 1'!$D$10,0) -> 0 | AA36: =SUM(C36:Z36) -> 0 | AB36: 19 | AC36: =+AA36*AB36+AA37*AB37+AA38*AB38 -> 0
B37: S | C37: =ROUND('Anexo 11'!C37*'Anexo 1'!$D$10,0) -> 0 | D37: =ROUND('Anexo 11'!D37*'Anexo 1'!$D$10,0) -> 0 | E37: =ROUND('Anexo 11'!E37*'Anexo 1'!$D$10,0) -> 0 | F37: =ROUND('Anexo 11'!F37*'Anexo 1'!$D$10,0) -> 0 | G37: =ROUND('Anexo 11'!G37*'Anexo 1'!$D$10,0) -> 0 | H37: =ROUND('Anexo 11'!H37*'Anexo 1'!$D$10,0) -> 0 | I37: =ROUND('Anexo 11'!I37*'Anexo 1'!$D$10,0) -> 0 | J37: =ROUND('Anexo 11'!J37*'Anexo 1'!$D$10,0) -> 0 | ... Z37: =ROUND('Anexo 11'!Z37*'Anexo 1'!$D$10,0) -> 0 | AA37: =SUM(C37:Z37) -> 0 | AB37: 4
B38: F | C38: =ROUND('Anexo 11'!C38*'Anexo 1'!$D$10,0) -> 0 | D38: =ROUND('Anexo 11'!D38*'Anexo 1'!$D$10,0) -> 0 | E38: =ROUND('Anexo 11'!E38*'Anexo 1'!$D$10,0) -> 0 | F38: =ROUND('Anexo 11'!F38*'Anexo 1'!$D$10,0) -> 0 | G38: =ROUND('Anexo 11'!G38*'Anexo 1'!$D$10,0) -> 0 | H38: =ROUND('Anexo 11'!H38*'Anexo 1'!$D$10,0) -> 0 | I38: =ROUND('Anexo 11'!I38*'Anexo 1'!$D$10,0) -> 0 | J38: =ROUND('Anexo 11'!J38*'Anexo 1'!$D$10,0) -> 0 | ... Z38: =ROUND('Anexo 11'!Z38*'Anexo 1'!$D$10,0) -> 0 | AA38: =SUM(C38:Z38) -> 0 | AB38: 7
A39: 46357 | B39: O | C39: =ROUND('Anexo 11'!C39*'Anexo 1'!$D$10,0) -> 0 | D39: =ROUND('Anexo 11'!D39*'Anexo 1'!$D$10,0) -> 0 | E39: =ROUND('Anexo 11'!E39*'Anexo 1'!$D$10,0) -> 0 | F39: =ROUND('Anexo 11'!F39*'Anexo 1'!$D$10,0) -> 0 | G39: =ROUND('Anexo 11'!G39*'Anexo 1'!$D$10,0) -> 0 | H39: =ROUND('Anexo 11'!H39*'Anexo 1'!$D$10,0) -> 0 | I39: =ROUND('Anexo 11'!I39*'Anexo 1'!$D$10,0) -> 0 | J39: =ROUND('Anexo 11'!J39*'Anexo 1'!$D$10,0) -> 0 | ... Z39: =ROUND('Anexo 11'!Z39*'Anexo 1'!$D$10,0) -> 0 | AA39: =SUM(C39:Z39) -> 0 | AB39: 21 | AC39: =+AA39*AB39+AA40*AB40+AA41*AB41 -> 0
B40: S | C40: =ROUND('Anexo 11'!C40*'Anexo 1'!$D$10,0) -> 0 | D40: =ROUND('Anexo 11'!D40*'Anexo 1'!$D$10,0) -> 0 | E40: =ROUND('Anexo 11'!E40*'Anexo 1'!$D$10,0) -> 0 | F40: =ROUND('Anexo 11'!F40*'Anexo 1'!$D$10,0) -> 0 | G40: =ROUND('Anexo 11'!G40*'Anexo 1'!$D$10,0) -> 0 | H40: =ROUND('Anexo 11'!H40*'Anexo 1'!$D$10,0) -> 0 | I40: =ROUND('Anexo 11'!I40*'Anexo 1'!$D$10,0) -> 0 | J40: =ROUND('Anexo 11'!J40*'Anexo 1'!$D$10,0) -> 0 | ... Z40: =ROUND('Anexo 11'!Z40*'Anexo 1'!$D$10,0) -> 0 | AA40: =SUM(C40:Z40) -> 0 | AB40: 4
B41: F | C41: =ROUND('Anexo 11'!C41*'Anexo 1'!$D$10,0) -> 0 | D41: =ROUND('Anexo 11'!D41*'Anexo 1'!$D$10,0) -> 0 | E41: =ROUND('Anexo 11'!E41*'Anexo 1'!$D$10,0) -> 0 | F41: =ROUND('Anexo 11'!F41*'Anexo 1'!$D$10,0) -> 0 | G41: =ROUND('Anexo 11'!G41*'Anexo 1'!$D$10,0) -> 0 | H41: =ROUND('Anexo 11'!H41*'Anexo 1'!$D$10,0) -> 0 | I41: =ROUND('Anexo 11'!I41*'Anexo 1'!$D$10,0) -> 0 | J41: =ROUND('Anexo 11'!J41*'Anexo 1'!$D$10,0) -> 0 | ... Z41: =ROUND('Anexo 11'!Z41*'Anexo 1'!$D$10,0) -> 0 | AA41: =SUM(C41:Z41) -> 0 | AB41: 6
A42: TOTAL AÑO | C42: =+SUM(C6:C41) -> 0 | D42: =+SUM(D6:D41) -> 0 | E42: =+SUM(E6:E41) -> 0 | F42: =+SUM(F6:F41) -> 0 | G42: =+SUM(G6:G41) -> 0 | H42: =+SUM(H6:H41) -> 0 | I42: =+SUM(I6:I41) -> 0 | J42: =+SUM(J6:J41) -> 0 | ... AC42: =+SUM(AC6:AC41) -> 0

Sheet Anexo 2
B3: ANEXO No 2 - PRODUCTO No. 2 - CURVA
B4: PAGUE LO CONTRATADO AÑO 2027
B5: PRECIO OFERTADO EN $ / kWh DE ABRIL DE 2025
B8: MES | C8: ENERGIA SOLICITADA kWh/MES | D8: % OFERTADO ANUAL | E8: ENERGIA OFERTADA kWh/MES | F8: PRECIO OFERTADO ANUAL $/kWh
B10: 46388 | C10: =+'Anexo 12'!AC6 -> 1459048 | E10: =+'Cantidades Ofertadas Prod 2'!AC6 -> 0
B11: 46419 | C11: =+'Anexo 12'!AC9 -> 642156 | E11: =+'Cantidades Ofertadas Prod 2'!AC9 -> 0
B12: 46447 | C12: =+'Anexo 12'!AC12 -> 1318259 | E12: =+'Cantidades Ofertadas Prod 2'!AC12 -> 0
B13: 46478 | C13: =+'Anexo 12'!AC15 -> 1230452 | E13: =+'Cantidades Ofertadas Prod 2'!AC15 -> 0
B14: 46508 | C14: =+'Anexo 12'!AC18 -> 1138076 | E14: =+'Cantidades Ofertadas Prod 2'!AC18 -> 0
B15: 46539 | C15: =+'Anexo 12'!AC21 -> 1078720 | E15: =+'Cantidades Ofertadas Prod 2'!AC21 -> 0
B16: 46569 | C16: =+'Anexo 12'!AC24 -> 903223 | E16: =+'Cantidades Ofertadas Prod 2'!AC24 -> 0
B17: 46600 | C17: =+'Anexo 12'!AC27 -> 1105017 | E17: =+'Cantidades Ofertadas Prod 2'!AC27 -> 0
B18: 46631 | C18: =+'Anexo 12'!AC30 -> 1204912 | E18: =+'Cantidades Ofertadas Prod 2'!AC30 -> 0
B19: 46661 | C19: =+'Anexo 12'!AC33 -> 838498 | E19: =+'Cantidades Ofertadas Prod 2'!AC33 -> 0
B20: 46692 | C20: =+'Anexo 12'!AC36 -> 599804 | E20: =+'Cantidades Ofertadas Prod 2'!AC36 -> 0
B21: 46722 | C21: =+'Anexo 12'!AC39 -> 1271732 | E21: =+'Cantidades Ofertadas Prod 2'!AC39 -> 0
B22: TOTAL | C22: =+SUM(C10:C21) -> 12789897 | E22: =SUM(E10:E21) -> 0 | F22: =+F10 -> 0
B23: *Solo se debe ingresar valores en las celdas en color Naranja
B24: * Se debe ofertar un unico % para todos los meses del año.
B25: * Los % ofertados se aplicaran a las curvas de carga de la hoja "Anexo 12".
B26: * La energia ofertada se calcula de manera automatica en la hoja "Cantidades Ofertadas Prod2"
B27: * Se debe ofertar un unico precio por producto.
B28: * Para este producto solo se reciben ofertas siguiendo la curva.
B31: ____________________________________________
B32: Firma del Representante Legal
B33: o Apoderado General (Responsable del negocio)

Sheet Anexo 12
A1: CURVAS REQUERIDAS PRODUCTO 2 AÑO 2027 MODALIDAD PAGUE LO CONTRATADO - kWh
A4: Periodo | B4: Tipo de día | C4: H01 | D4: H02 | E4: H03 | F4: H04 | G4: H05 | H4: H06 | I4: H07 | J4: H08 | K4: H09 | L4: H10 | M4: H11 | N4: H12 | O4: H13 | P4: H14 | Q4: H15 | R4: H16 | S4: H17 | T4: H18 | U4: H19 | V4: H20 | W4: H21 | X4: H22 | Y4: H23 | Z4: H24 | AA4: TOTAL DÍA | AB4: Días/ | AC4: TOTAL MES
AB5: mes
A6: 46388 | B6: O | C6: 1446 | D6: 1300 | E6: 1195 | F6: 1101 | G6: 1132 | H6: 1185 | I6: 931 | J6: 1659 | K6: 2134 | L6: 2494 | M6: 2850 | N6: 3061 | O6: 2897 | P6: 2942 | Q6: 3264 | R6: 3344 | S6: 3313 | T6: 2511 | U6: 2620 | V6: 2710 | W6: 2553 | X6: 2430 | Y6: 2130 | Z6: 1643 | AA6: =SUM(C6:Z6) -> 52845 | AB6: 19 | AC6: =+AA6*AB6+AA7*AB7+AA8*AB8 -> 1459048
B7: S | C7: 1397 | D7: 1244 | E7: 1127 | F7: 1053 | G7: 1056 | H7: 1075 | I7: 713 | J7: 1303 | K7: 1834 | L7: 2155 | M7: 2458 | N7: 2654 | O7: 2678 | P7: 2649 | Q7: 2677 | R7: 2671 | S7: 2728 | T7: 1879 | U7: 2192 | V7: 2370 | W7: 2226 | X7: 2062 | Y7: 1854 | Z7: 1557 | AA7: =SUM(C7:Z7) -> 45612 | AB7: 5
B8: F | C8: 979 | D8: 844 | E8: 704 | F8: 670 | G8: 647 | H8: 733 | I8: 471 | J8: 894 | K8: 1195 | L8: 1533 | M8: 1759 | N8: 1986 | O8: 2121 | P8: 1952 | Q8: 1842 | R8: 1850 | S8: 1802 | T8: 1222 | U8: 1417 | V8: 1694 | W8: 1724 | X8: 1694 | Y8: 1492 | Z8: 1194 | AA8: =SUM(C8:Z8) -> 32419 | AB8: 7
A9: 46419 | B9: O | C9: 785 | D9: 750 | E9: 710 | F9: 630 | G9: 635 | H9: 746 | I9: 25 | J9: 567 | K9: 821 | L9: 1043 | M9: 1225 | N9: 1364 | O9: 1217 | P9: 1356 | Q9: 1540 | R9: 1546 | S9: 1555 | T9: 758 | U9: 1322 | V9: 1407 | W9: 1300 | X9: 1217 | Y9: 1040 | Z9: 728 | AA9: =SUM(C9:Z9) -> 24287 | AB9: 20 | AC9: =+AA9*AB9+AA10*AB10+AA11*AB11 -> 642156
B10: S | C10: 772 | D10: 782 | E10: 718 | F10: 676 | G10: 681 | H10: 610 | I10: 0 | J10: 352 | K10: 603 | L10: 825 | M10: 905 | N10: 1029 | O10: 1073 | P10: 1047 | Q10: 1052 | R10: 996 | S10: 962 | T10: 350 | U10: 1224 | V10: 1295 | W10: 1116 | X10: 1172 | Y10: 1010 | Z10: 794 | AA10: =SUM(C10:Z10) -> 20044 | AB10: 4
B11: F | C11: 803 | D11: 824 | E11: 702 | F11: 623 | G11: 616 | H11: 629 | I11: 0 | J11: 290 | K11: 489 | L11: 679 | M11: 847 | N11: 983 | O11: 1014 | P11: 1011 | Q11: 912 | R11: 977 | S11: 952 | T11: 276 | U11: 1104 | V11: 1217 | W11: 1086 | X11: 1176 | Y11: 1075 | Z11: 775 | AA11: =SUM(C11:Z11) -> 19060 | AB11: 4
A12: 46447 | B12: O | C12: 1743 | D12: 1647 | E12: 1564 | F12: 1495 | G12: 1471 | H12: 1555 | I12: 817 | J12: 1350 | K12: 1650 | L12: 1933 | M12: 2175 | N12: 2344 | O12: 2277 | P12: 2371 | Q12: 2588 | R12: 2595 | S12: 2561 | T12: 1704 | U12: 2325 | V12: 2601 | W12: 2528 | X12: 2511 | Y12: 2261 | Z12: 1887 | AA12: =SUM(C12:Z12) -> 47953 | AB12: 20 | AC12: =+AA12*AB12+AA13*AB13+AA14*AB14 -> 1318259
B13: S | C13: 1650 | D13: 1536 | E13: 1342 | F13: 1370 | G13: 1325 | H13: 1275 | I13: 515 | J13: 958 | K13: 1269 | L13: 1486 | M13: 1711 | N13: 1803 | O13: 1885 | P13: 1833 | Q13: 1846 | R13: 1910 | S13: 1831 | T13: 1024 | U13: 1677 | V13: 1934 | W13: 2008 | X13: 1928 | Y13: 1741 | Z13: 1609 | AA13: =SUM(C13:Z13) -> 37466 | AB13: 4
B14: F | C14: 1534 | D14: 1476 | E14: 1339 | F14: 1202 | G14: 1067 | H14: 1092 | I14: 265 | J14: 592 | K14: 868 | L14: 972 | M14: 1118 | N14: 1202 | O14: 1434 | P14: 1293 | Q14: 1293 | R14: 1355 | S14: 1349 | T14: 711 | U14: 1496 | V14: 1811 | W14: 1881 | X14: 1805 | Y14: 1478 | Z14: 1272 | AA14: =SUM(C14:Z14) -> 29905 | AB14: 7
A15: 46478 | B15: O | C15: 1531 | D15: 1393 | E15: 1293 | F15: 1236 | G15: 1190 | H15: 1130 | I15: 765 | J15: 1338 | K15: 1538 | L15: 1787 | M15: 2030 | N15: 2349 | O15: 2465 | P15: 2437 | Q15: 2365 | R15: 2315 | S15: 2208 | T15: 1609 | U15: 2145 | V15: 2435 | W15: 2410 | X15: 2271 | Y15: 2001 | Z15: 1617 | AA15: =SUM(C15:Z15) -> 43858 | AB15: 22 | AC15: =+AA15*AB15+AA16*AB16+AA17*AB17 -> 1230452
B16: S | C16: 1372 | D16: 1239 | E16: 1118 | F16: 1091 | G16: 1064 | H16: 1065 | I16: 693 | J16: 1209 | K16: 1298 | L16: 1488 | M16: 1743 | N16: 1905 | O16: 2045 | P16: 1946 | Q16: 1990 | R16: 1975 | S16: 2054 | T16: 1512 | U16: 1993 | V16: 2027 | W16: 1939 | X16: 1780 | Y16: 1568 | Z16: 1304 | AA16: =SUM(C16:Z16) -> 37418 | AB16: 4
B17: F | C17: 972 | D17: 1025 | E17: 819 | F17: 743 | G17: 709 | H17: 750 | I17: 457 | J17: 841 | K17: 1009 | L17: 1201 | M17: 1320 | N17: 1353 | O17: 1520 | P17: 1650 | Q17: 1639 | R17: 1686 | S17: 1737 | T17: 1146 | U17: 1554 | V17: 1714 | W17: 1674 | X17: 1403 | Y17: 1140 | Z17: 914 | AA17: =SUM(C17:Z17) -> 28976 | AB17: 4
A18: 46508 | B18: O | C18: 1477 | D18: 1352 | E18: 1285 | F18: 1190 | G18: 1156 | H18: 1047 | I18: 661 | J18: 1293 | K18: 1526 | L18: 1750 | M18: 1944 | N18: 2163 | O18: 2153 | P18: 2167 | Q18: 2132 | R18: 2092 | S18: 2069 | T18: 1389 | U18: 2062 | V18: 2264 | W18: 2242 | X18: 2080 | Y18: 1812 | Z18: 1450 | AA18: =SUM(C18:Z18) -> 40756 | AB18: 19 | AC18: =+AA18*AB18+AA19*AB19+AA20*AB20 -> 1138076
B19: S | C19: 1439 | D19: 1250 | E19: 1255 | F19: 1201 | G19: 1172 | H19: 1063 | I19: 554 | J19: 998 | K19: 1090 | L19: 1282 | M19: 1597 | N19: 1790 | O19: 1812 | P19: 1773 | Q19: 1788 | R19: 1813 | S19: 1765 | T19: 1173 | U19: 1917 | V19: 2215 | W19: 2068 | X19: 1843 | Y19: 1634 | Z19: 1482 | AA19: =SUM(C19:Z19) -> 35974 | AB19: 4
B20: F | C20: 1259 | D20: 1162 | E20: 1018 | F20: 967 | G20: 924 | H20: 868 | I20: 276 | J20: 704 | K20: 903 | L20: 1049 | M20: 1129 | N20: 1168 | O20: 1317 | P20: 1326 | Q20: 1414 | R20: 1459 | S20: 1402 | T20: 651 | U20: 1198 | V20: 1589 | W20: 1590 | X20: 1591 | Y20: 1368 | Z20: 1145 | AA20: =SUM(C20:Z20) -> 27477 | AB20: 8
A21: 46539 | B21: O | C21: 701 | D21: 666 | E21: 572 | F21: 564 | G21: 607 | H21: 642 | I21: 492 | J21: 1184 | K21: 1442 | L21: 1722 | M21: 1926 | N21: 2132 | O21: 2105 | P21: 2018 | Q21: 2119 | R21: 2172 | S21: 2046 | T21: 1400 | U21: 1769 | V21: 2034 | W21: 1946 | X21: 1695 | Y21: 1310 | Z21: 834 | AA21: =SUM(C21:Z21) -> 34098 | AB21: 21 | AC21: =+AA21*AB21+AA22*AB22+AA23*AB23 -> 1078720
B22: S | C22: 934 | D22: 856 | E22: 629 | F22: 674 | G22: 720 | H22: 740 | I22: 413 | J22: 1066 | K22: 1285 | L22: 1643 | M22: 1820 | N22: 2024 | O22: 2002 | P22: 2036 | Q22: 2002 | R22: 2078 | S22: 2126 | T22: 1434 | U22: 1882 | V22: 2124 | W22: 1955 | X22: 1862 | Y22: 1514 | Z22: 1174 | AA22: =SUM(C22:Z22) -> 34993 | AB22: 4
B23: F | C23: 1183 | D23: 1019 | E23: 912 | F23: 858 | G23: 912 | H23: 1039 | I23: 959 | J23: 1612 | K23: 1961 | L23: 2236 | M23: 2408 | N23: 2591 | O23: 2457 | P23: 2522 | Q23: 2769 | R23: 2819 | S23: 2755 | T23: 2053 | U23: 2132 | V23: 2408 | W23: 2251 | X23: 1994 | Y23: 1520 | Z23: 1168 | AA23: =SUM(C23:Z23) -> 44538 | AB23: 5
A24: 46569 | B24: O | C24: 733 | D24: 706 | E24: 604 | F24: 558 | G24: 581 | H24: 581 | I24: 385 | J24: 1143 | K24: 1406 | L24: 1740 | M24: 1982 | N24: 2225 | O24: 2147 | P24: 2094 | Q24: 2315 | R24: 2350 | S24: 2253 | T24: 1521 | U24: 1746 | V24: 1944 | W24: 1866 | X24: 1689 | Y24: 1295 | Z24: 827 | AA24: =SUM(C24:Z24) -> 34691 | AB24: 20 | AC24: =+AA24*AB24+AA25*AB25+AA26*AB26 -> 903223
B25: S | C25: 306 | D25: 285 | E25: 147 | F25: 123 | G25: 185 | H25: 231 | I25: 0 | J25: 448 | K25: 714 | L25: 1024 | M25: 1159 | N25: 1338 | O25: 1342 | P25: 1328 | Q25: 1221 | R25: 1274 | S25: 1306 | T25: 684 | U25: 1160 | V25: 1340 | W25: 1262 | X25: 1148 | Y25: 803 | Z25: 489 | AA25: =SUM(C25:Z25) -> 19317 | AB25: 5
B26: F | C26: 562 | D26: 520 | E26: 387 | F26: 257 | G26: 253 | H26: 170 | I26: 0 | J26: 335 | K26: 564 | L26: 814 | M26: 928 | N26: 1084 | O26: 1259 | P26: 1272 | Q26: 1235 | R26: 1174 | S26: 1279 | T26: 609 | U26: 957 | V26: 1294 | W26: 1298 | X26: 1131 | Y26: 894 | Z26: 527 | AA26: =SUM(C26:Z26) -> 18803 | AB26: 6
A27: 46600 | B27: O | C27: 901 | D27: 765 | E27: 644 | F27: 551 | G27: 578 | H27: 568 | I27: 364 | J27: 1203 | K27: 1645 | L27: 2011 | M27: 2318 | N27: 2591 | O27: 2477 | P27: 2493 | Q27: 2755 | R27: 2840 | S27: 2779 | T27: 1863 | U27: 2079 | V27: 2097 | W27: 2001 | X27: 1861 | Y27: 1501 | Z27: 1026 | AA27: =SUM(C27:Z27) -> 39911 | AB27: 21 | AC27: =+AA27*AB27+AA28*AB28+AA29*AB29 -> 1105017
B28: S | C28: 833 | D28: 730 | E28: 636 | F28: 527 | G28: 588 | H28: 503 | I28: 232 | J28: 871 | K28: 1291 | L28: 1617 | M28: 1780 | N28: 2044 | O28: 2159 | P28: 1939 | Q28: 2479 | R28: 2209 | S28: 2010 | T28: 1279 | U28: 1666 | V28: 1831 | W28: 1671 | X28: 1441 | Y28: 1214 | Z28: 887 | AA28: =SUM(C28:Z28) -> 32437 | AB28: 3
B29: F | C29: 875 | D29: 698 | E29: 511 | F29: 448 | G29: 459 | H29: 409 | I29: 0 | J29: 509 | K29: 700 | L29: 958 | M29: 1190 | N29: 1338 | O29: 1431 | P29: 1542 | Q29: 1461 | R29: 1462 | S29: 1543 | T29: 798 | U29: 1252 | V29: 1621 | W29: 1564 | X29: 1511 | Y29: 1185 | Z29: 760 | AA29: =SUM(C29:Z29) -> 24225 | AB29: 7
A30: 46631 | B30: O | C30: 1130 | D30: 976 | E30: 879 | F30: 821 | G30: 837 | H30: 802 | I30: 608 | J30: 1376 | K30: 1826 | L30: 2176 | M30: 2467 | N30: 2744 | O30: 2619 | P30: 2605 | Q30: 2818 | R30: 2819 | S30: 2783 | T30: 1970 | U30: 2272 | V30: 2286 | W30: 2215 | X30: 2033 | Y30: 1650 | Z30: 1226 | AA30: =SUM(C30:Z30) -> 43938 | AB30: 22 | AC30: =+AA30*AB30+AA31*AB31+AA32*AB32 -> 1204912
B31: S | C31: 931 | D31: 785 | E31: 702 | F31: 649 | G31: 651 | H31: 566 | I31: 293 | J31: 896 | K31: 1380 | L31: 1678 | M31: 1896 | N31: 2021 | O31: 2094 | P31: 1969 | Q31: 1911 | R31: 2015 | S31: 1971 | T31: 1216 | U31: 1809 | V31: 1887 | W31: 1724 | X31: 1570 | Y31: 1317 | Z31: 1050 | AA31: =SUM(C31:Z31) -> 32981 | AB31: 4
B32: F | C32: 829 | D32: 720 | E32: 544 | F32: 527 | G32: 562 | H32: 515 | I32: 188 | J32: 749 | K32: 1018 | L32: 1220 | M32: 1459 | N32: 1589 | O32: 1690 | P32: 1724 | Q32: 1709 | R32: 1631 | S32: 1625 | T32: 903 | U32: 1423 | V32: 1505 | W32: 1403 | X32: 1286 | Y32: 1003 | Z32: 766 | AA32: =SUM(C32:Z32) -> 26588 | AB32: 4
A33: 46661 | B33: O | C33: 589 | D33: 455 | E33: 376 | F33: 336 | G33: 333 | H33: 258 | I33: 103 | J33: 856 | K33: 1240 | L33: 1513 | M33: 1786 | N33: 2004 | O33: 1888 | P33: 1878 | Q33: 2052 | R33: 2136 | S33: 2142 | T33: 1331 | U33: 1682 | V33: 1532 | W33: 1453 | X33: 1280 | Y33: 995 | Z33: 615 | AA33: =SUM(C33:Z33) -> 28833 | AB33: 20 | AC33: =+AA33*AB33+AA34*AB34+AA35*AB35 -> 838498
B34: S | C34: 969 | D34: 833 | E34: 695 | F34: 586 | G34: 654 | H34: 435 | I34: 250 | J34: 994 | K34: 1462 | L34: 1782 | M34: 1994 | N34: 2072 | O34: 2050 | P34: 1931 | Q34: 1996 | R34: 2016 | S34: 2000 | T34: 1403 | U34: 1915 | V34: 1848 | W34: 1670 | X34: 1493 | Y34: 1296 | Z34: 1054 | AA34: =SUM(C34:Z34) -> 33398 | AB34: 5
B35: F | C35: 689 | D35: 510 | E35: 428 | F35: 299 | G35: 259 | H35: 166 | I35: 0 | J35: 327 | K35: 433 | L35: 690 | M35: 881 | N35: 984 | O35: 1035 | P35: 1093 | Q35: 1019 | R35: 923 | S35: 953 | T35: 278 | U35: 867 | V35: 960 | W35: 948 | X35: 892 | Y35: 713 | Z35: 461 | AA35: =SUM(C35:Z35) -> 15808 | AB35: 6
A36: 46692 | B36: O | C36: 385 | D36: 361 | E36: 289 | F36: 209 | G36: 219 | H36: 200 | I36: 0 | J36: 665 | K36: 976 | L36: 1191 | M36: 1364 | N36: 1541 | O36: 1504 | P36: 1460 | Q36: 1616 | R36: 1656 | S36: 1571 | T36: 917 | U36: 1374 | V36: 1234 | W36: 1151 | X36: 968 | Y36: 724 | Z36: 362 | AA36: =SUM(C36:Z36) -> 21937 | AB36: 20 | AC36: =+AA36*AB36+AA37*AB37+AA38*AB38 -> 599804
B37: S | C37: 171 | D37: 99 | E37: 0 | F37: 0 | G37: 24 | H37: 18 | I37: 0 | J37: 468 | K37: 725 | L37: 984 | M37: 1113 | N37: 1258 | O37: 1358 | P37: 1401 | Q37: 1347 | R37: 1402 | S37: 1364 | T37: 683 | U37: 1302 | V37: 1329 | W37: 1110 | X37: 930 | Y37: 793 | Z37: 571 | AA37: =SUM(C37:Z37) -> 18450 | AB37: 4
B38: F | C38: 438 | D38: 428 | E38: 252 | F38: 112 | G38: 124 | H38: 137 | I38: 0 | J38: 254 | K38: 436 | L38: 718 | M38: 916 | N38: 947 | O38: 1091 | P38: 1136 | Q38: 993 | R38: 935 | S38: 939 | T38: 211 | U38: 872 | V38: 798 | W38: 855 | X38: 789 | Y38: 674 | Z38: 489 | AA38: =SUM(C38:Z38) -> 14544 | AB38: 6
A39: 46722 | B39: O | C39: 1056 | D39: 1045 | E39: 920 | F39: 891 | G39: 932 | H39: 1020 | I39: 768 | J39: 1465 | K39: 1914 | L39: 2226 | M39: 2518 | N39: 2754 | O39: 2680 | P39: 2666 | Q39: 2817 | R39: 2792 | S39: 2696 | T39: 1934 | U39: 2436 | V39: 2396 | W39: 2194 | X39: 1997 | Y39: 1628 | Z39: 1197 | AA39: =SUM(C39:Z39) -> 44942 | AB39: 22 | AC39: =+AA39*AB39+AA40*AB40+AA41*AB41 -> 1271732
B40: S | C40: 1270 | D40: 1048 | E40: 962 | F40: 920 | G40: 994 | H40: 1083 | I40: 823 | J40: 1601 | K40: 2065 | L40: 2462 | M40: 2782 | N40: 3008 | O40: 2802 | P40: 2700 | Q40: 2712 | R40: 2680 | S40: 2635 | T40: 1935 | U40: 2572 | V40: 2528 | W40: 2270 | X40: 1974 | Y40: 1638 | Z40: 1246 | AA40: =SUM(C40:Z40) -> 46710 | AB40: 3
B41: F | C41: 494 | D41: 391 | E41: 305 | F41: 282 | G41: 333 | H41: 441 | I41: 143 | J41: 671 | K41: 899 | L41: 1194 | M41: 1428 | N41: 1593 | O41: 1626 | P41: 1641 | Q41: 1468 | R41: 1402 | S41: 1406 | T41: 801 | U41: 1346 | V41: 1473 | W41: 1466 | X41: 1357 | Y41: 1016 | Z41: 637 | AA41: =SUM(C41:Z41) -> 23813 | AB41: 6
A42: TOTAL AÑO | C42: =+SUM(C6:C41) -> 35138 | D42: =+SUM(D6:D41) -> 31720 | E42: =+SUM(E6:E41) -> 27583 | F42: =+SUM(F6:F41) -> 25440 | G42: =+SUM(G6:G41) -> 25650 | H42: =+SUM(H6:H41) -> 25347 | I42: =+SUM(I6:I41) -> 13164 | J42: =+SUM(J6:J41) -> 33041 | ... AC42: =+SUM(AC6:AC41) -> 12789897

Sheet Cantidades Ofertadas Prod 2
A1: CANTIDADES OFERTADAS PRODUCTO 2 AÑO 2027 MODALIDAD PAGUE LO CONTRATADO - kWh
A4: Periodo | B4: Tipo de día | C4: H01 | D4: H02 | E4: H03 | F4: H04 | G4: H05 | H4: H06 | I4: H07 | J4: H08 | K4: H09 | L4: H10 | M4: H11 | N4: H12 | O4: H13 | P4: H14 | Q4: H15 | R4: H16 | S4: H17 | T4: H18 | U4: H19 | V4: H20 | W4: H21 | X4: H22 | Y4: H23 | Z4: H24 | AA4: TOTAL DÍA | AB4: Días/ | AC4: TOTAL MES
AB5: mes
A6: 46388 | B6: O | C6: =ROUND('Anexo 12'!C6*'Anexo 2'!$D$10,0) -> 0 | D6: =ROUND('Anexo 12'!D6*'Anexo 2'!$D$10,0) -> 0 | E6: =ROUND('Anexo 12'!E6*'Anexo 2'!$D$10,0) -> 0 | F6: =ROUND('Anexo 12'!F6*'Anexo 2'!$D$10,0) -> 0 | G6: =ROUND('Anexo 12'!G6*'Anexo 2'!$D$10,0) -> 0 | H6: =ROUND('Anexo 12'!H6*'Anexo 2'!$D$10,0) -> 0 | I6: =ROUND('Anexo 12'!I6*'Anexo 2'!$D$10,0) -> 0 | J6: =ROUND('Anexo 12'!J6*'Anexo 2'!$D$10,0) -> 0 | ... Z6: =ROUND('Anexo 12'!Z6*'Anexo 2'!$D$10,0) -> 0 | AA6: =SUM(C6:Z6) -> 0 | AB6: 19 | AC6: =+AA6*AB6+AA7*AB7+AA8*AB8 -> 0
B7: S | C7: =ROUND('Anexo 12'!C7*'Anexo 2'!$D$10,0) -> 0 | D7: =ROUND('Anexo 12'!D7*'Anexo 2'!$D$10,0) -> 0 | E7: =ROUND('Anexo 12'!E7*'Anexo 2'!$D$10,0) -> 0 | F7: =ROUND('Anexo 12'!F7*'Anexo 2'!$D$10,0) -> 0 | G7: =ROUND('Anexo 12'!G7*'Anexo 2'!$D$10,0) -> 0 | H7: =ROUND('Anexo 12'!H7*'Anexo 2'!$D$10,0) -> 0 | I7: =ROUND('Anexo 12'!I7*'Anexo 2'!$D$10,0) -> 0 | J7: =ROUND('Anexo 12'!J7*'Anexo 2'!$D$10,0) -> 0 | ... Z7: =ROUND('Anexo 12'!Z7*'Anexo 2'!$D$10,0) -> 0 | AA7: =SUM(C7:Z7) -> 0 | AB7: 5
B8: F | C8: =ROUND('Anexo 12'!C8*'Anexo 2'!$D$10,0) -> 0 | D8: =ROUND('Anexo 12'!D8*'Anexo 2'!$D$10,0) -> 0 | E8: =ROUND('Anexo 12'!E8*'Anexo 2'!$D$10,0) -> 0 | F8: =ROUND('Anexo 12'!F8*'Anexo 2'!$D$10,0) -> 0 | G8: =ROUND('Anexo 12'!G8*'Anexo 2'!$D$10,0) -> 0 | H8: =ROUND('Anexo 12'!H8*'Anexo 2'!$D$10,0) -> 0 | I8: =ROUND('Anexo 12'!I8*'Anexo 2'!$D$10,0) -> 0 | J8: =ROUND('Anexo 12'!J8*'Anexo 2'!$D$10,0) -> 0 | ... Z8: =ROUND('Anexo 12'!Z8*'Anexo 2'!$D$10,0) -> 0 | AA8: =SUM(C8:Z8) -> 0 | AB8: 7
A9: 46419 | B9: O | C9: =ROUND('Anexo 12'!C9*'Anexo 2'!$D$10,0) -> 0 | D9: =ROUND('Anexo 12'!D9*'Anexo 2'!$D$10,0) -> 0 | E9: =ROUND('Anexo 12'!E9*'Anexo 2'!$D$10,0) -> 0 | F9: =ROUND('Anexo 12'!F9*'Anexo 2'!$D$10,0) -> 0 | G9: =ROUND('Anexo 12'!G9*'Anexo 2'!$D$10,0) -> 0 | H9: =ROUND('Anexo 12'!H9*'Anexo 2'!$D$10,0) -> 0 | I9: =ROUND('Anexo 12'!I9*'Anexo 2'!$D$10,0) -> 0 | J9: =ROUND('Anexo 12'!J9*'Anexo 2'!$D$10,0) -> 0 | ... Z9: =ROUND('Anexo 12'!Z9*'Anexo 2'!$D$10,0) -> 0 | AA9: =SUM(C9:Z9) -> 0 | AB9: 20 | AC9: =+AA9*AB9+AA10*AB10+AA11*AB11 -> 0
B10: S | C10: =ROUND('Anexo 12'!C10*'Anexo 2'!$D$10,0) -> 0 | D10: =ROUND('Anexo 12'!D10*'Anexo 2'!$D$10,0) -> 0 | E10: =ROUND('Anexo 12'!E10*'Anexo 2'!$D$10,0) -> 0 | F10: =ROUND('Anexo 12'!F10*'Anexo 2'!$D$10,0) -> 0 | G10: =ROUND('Anexo 12'!G10*'Anexo 2'!$D$10,0) -> 0 | H10: =ROUND('Anexo 12'!H10*'Anexo 2'!$D$10,0) -> 0 | I10: =ROUND('Anexo 12'!I10*'Anexo 2'!$D$10,0) -> 0 | J10: =ROUND('Anexo 12'!J10*'Anexo 2'!$D$10,0) -> 0 | ... Z10: =ROUND('Anexo 12'!Z10*'Anexo 2'!$D$10,0) -> 0 | AA10: =SUM(C10:Z10) -> 0 | AB10: 4
B11: F | C11: =ROUND('Anexo 12'!C11*'Anexo 2'!$D$10,0) -> 0 | D11: =ROUND('Anexo 12'!D11*'Anexo 2'!$D$10,0) -> 0 | E11: =ROUND('Anexo 12'!E11*'Anexo 2'!$D$10,0) -> 0 | F11: =ROUND('Anexo 12'!F11*'Anexo 2'!$D$10,0) -> 0 | G11: =ROUND('Anexo 12'!G11*'Anexo 2'!$D$10,0) -> 0 | H11: =ROUND('Anexo 12'!H11*'Anexo 2'!$D$10,0) -> 0 | I11: =ROUND('Anexo 12'!I11*'Anexo 2'!$D$10,0) -> 0 | J11: =ROUND('Anexo 12'!J11*'Anexo 2'!$D$10,0) -> 0 | ... Z11: =ROUND('Anexo 12'!Z11*'Anexo 2'!$D$10,0) -> 0 | AA11: =SUM(C11:Z11) -> 0 | AB11: 4
A12: 46447 | B12: O | C12: =ROUND('Anexo 12'!C12*'Anexo 2'!$D$10,0) -> 0 | D12: =ROUND('Anexo 12'!D12*'Anexo 2'!$D$10,0) -> 0 | E12: =ROUND('Anexo 12'!E12*'Anexo 2'!$D$10,0) -> 0 | F12: =ROUND('Anexo 12'!F12*'Anexo 2'!$D$10,0) -> 0 | G12: =ROUND('Anexo 12'!G12*'Anexo 2'!$D$10,0) -> 0 | H12: =ROUND('Anexo 12'!H12*'Anexo 2'!$D$10,0) -> 0 | I12: =ROUND('Anexo 12'!I12*'Anexo 2'!$D$10,0) -> 0 | J12: =ROUND('Anexo 12'!J12*'Anexo 2'!$D$10,0) -> 0 | ... Z12: =ROUND('Anexo 12'!Z12*'Anexo 2'!$D$10,0) -> 0 | AA12: =SUM(C12:Z12) -> 0 | AB12: 20 | AC12: =+AA12*AB12+AA13*AB13+AA14*AB14 -> 0
B13: S | C13: =ROUND('Anexo 12'!C13*'Anexo 2'!$D$10,0) -> 0 | D13: =ROUND('Anexo 12'!D13*'Anexo 2'!$D$10,0) -> 0 | E13: =ROUND('Anexo 12'!E13*'Anexo 2'!$D$10,0) -> 0 | F13: =ROUND('Anexo 12'!F13*'Anexo 2'!$D$10,0) -> 0 | G13: =ROUND('Anexo 12'!G13*'Anexo 2'!$D$10,0) -> 0 | H13: =ROUND('Anexo 12'!H13*'Anexo 2'!$D$10,0) -> 0 | I13: =ROUND('Anexo 12'!I13*'Anexo 2'!$D$10,0) -> 0 | J13: =ROUND('Anexo 12'!J13*'Anexo 2'!$D$10,0) -> 0 | ... Z13: =ROUND('Anexo 12'!Z13*'Anexo 2'!$D$10,0) -> 0 | AA13: =SUM(C13:Z13) -> 0 | AB13: 4
B14: F | C14: =ROUND('Anexo 12'!C14*'Anexo 2'!$D$10,0) -> 0 | D14: =ROUND('Anexo 12'!D14*'Anexo 2'!$D$10,0) -> 0 | E14: =ROUND('Anexo 12'!E14*'Anexo 2'!$D$10,0) -> 0 | F14: =ROUND('Anexo 12'!F14*'Anexo 2'!$D$10,0) -> 0 | G14: =ROUND('Anexo 12'!G14*'Anexo 2'!$D$10,0) -> 0 | H14: =ROUND('Anexo 12'!H14*'Anexo 2'!$D$10,0) -> 0 | I14: =ROUND('Anexo 12'!I14*'Anexo 2'!$D$10,0) -> 0 | J14: =ROUND('Anexo 12'!J14*'Anexo 2'!$D$10,0) -> 0 | ... Z14: =ROUND('Anexo 12'!Z14*'Anexo 2'!$D$10,0) -> 0 | AA14: =SUM(C14:Z14) -> 0 | AB14: 7
A15: 46478 | B15: O | C15: =ROUND('Anexo 12'!C15*'Anexo 2'!$D$10,0) -> 0 | D15: =ROUND('Anexo 12'!D15*'Anexo 2'!$D$10,0) -> 0 | E15: =ROUND('Anexo 12'!E15*'Anexo 2'!$D$10,0) -> 0 | F15: =ROUND('Anexo 12'!F15*'Anexo 2'!$D$10,0) -> 0 | G15: =ROUND('Anexo 12'!G15*'Anexo 2'!$D$10,0) -> 0 | H15: =ROUND('Anexo 12'!H15*'Anexo 2'!$D$10,0) -> 0 | I15: =ROUND('Anexo 12'!I15*'Anexo 2'!$D$10,0) -> 0 | J15: =ROUND('Anexo 12'!J15*'Anexo 2'!$D$10,0) -> 0 | ... Z15: =ROUND('Anexo 12'!Z15*'Anexo 2'!$D$10,0) -> 0 | AA15: =SUM(C15:Z15) -> 0 | AB15: 22 | AC15: =+AA15*AB15+AA16*AB16+AA17*AB17 -> 0
B16: S | C16: =ROUND('Anexo 12'!C16*'Anexo 2'!$D$10,0) -> 0 | D16: =ROUND('Anexo 12'!D16*'Anexo 2'!$D$10,0) -> 0 | E16: =ROUND('Anexo 12'!E16*'Anexo 2'!$D$10,0) -> 0 | F16: =ROUND('Anexo 12'!F16*'Anexo 2'!$D$10,0) -> 0 | G16: =ROUND('Anexo 12'!G16*'Anexo 2'!$D$10,0) -> 0 | H16: =ROUND('Anexo 12'!H16*'Anexo 2'!$D$10,0) -> 0 | I16: =ROUND('Anexo 12'!I16*'Anexo 2'!$D$10,0) -> 0 | J16: =ROUND('Anexo 12'!J16*'Anexo 2'!$D$10,0) -> 0 | ... Z16: =ROUND('Anexo 12'!Z16*'Anexo 2'!$D$10,0) -> 0 | AA16: =SUM(C16:Z16) -> 0 | AB16: 4
B17: F | C17: =ROUND('Anexo 12'!C17*'Anexo 2'!$D$10,0) -> 0 | D17: =ROUND('Anexo 12'!D17*'Anexo 2'!$D$10,0) -> 0 | E17: =ROUND('Anexo 12'!E17*'Anexo 2'!$D$10,0) -> 0 | F17: =ROUND('Anexo 12'!F17*'Anexo 2'!$D$10,0) -> 0 | G17: =ROUND('Anexo 12'!G17*'Anexo 2'!$D$10,0) -> 0 | H17: =ROUND('Anexo 12'!H17*'Anexo 2'!$D$10,0) -> 0 | I17: =ROUND('Anexo 12'!I17*'Anexo 2'!$D$10,0) -> 0 | J17: =ROUND('Anexo 12'!J17*'Anexo 2'!$D$10,0) -> 0 | ... Z17: =ROUND('Anexo 12'!Z17*'Anexo 2'!$D$10,0) -> 0 | AA17: =SUM(C17:Z17) -> 0 | AB17: 4
