Workbook

Sheet Formato Resumen 23
A1: ANEXO 3. CUADRO DE CANTIDADES DE ENERGÍA Y PRECIO
B2: ="El precio del suministro para cada período (mes) se debe expresar en pesos por Kilovatio-hora (COP/KWh) con dos cifras decimales, en forma de precio monomio fijo, en pesos constantes de "&C11 -> El precio del suministro para cada período (mes) se debe expresar en pesos por Kilovatio-hora (COP/KWh) con dos cifras decimales, en forma de precio monomio fijo, en pesos constantes de noviembre de 2024
B5: OFERTA MERCANTIL N°:
B6: INVITACIÓN: | C6: CP-EXEC2025-001
B7: OFERENTE:
B8: OFERTA:
B9: FNCER (SI/NO):
B10: CANTIDAD EN: | C10: KWh
B11: PRECIOS $/kWh de: | C11: noviembre de 2024
B12: MODALIDAD: | C12: PC (1)
B14: AÑO 2024 | C14: ENERGÍA SOLICITADA (KWh) | D14: NIVEL DE COBERTURA ESPERADO (%) | E14: ENERGÍA OFRECIDA (KWh) (2) (3) | F14: PRECIO OFERTADO (COP/KWh) (4)
B16: ENE | E16: 0
B17: FEB | D17: 1 | E17: 0
B18: MAR | D18: 1 | E18: 0
B19: ABR | D19: 1 | E19: 0
B20: MAY | D20: 1 | E20: 0
B21: JUN | D21: 1 | E21: 0
B22: JUL | D22: 1 | E22: 0
B23: AGO | D23: 1 | E23: 0
B24: SEP | D24: 1 | E24: 0
B25: OCT | D25: 1 | E25: 0
B26: NOV | D26: 1 | E26: 0
B27: DIC | D27: 1 | E27: 2000000
B28: TOTAL | C28: =SUM(C16:C27) -> 0 | E28: 2000000
B30: NOTAS:
B31: _PC: Pague lo contratado
B32: _La energía ofrecida se despachará de acuerdo con las curvas descritas los terminos de referencia.
B33: _Ingresar con dos cifras decimales la energía ofrecida hasta las cantidades solicitadas.
B34: _Ingresar un precio monomio fijo en COP/KWh con dos cifras decimales.
B35: _No serán tenidas en cuenta ofertas con condiciones y/o modificaciones adicionales a los Pliegos definitivos.
B42: OFERENTE E.S.P.

Sheet P1_AÑO 2024
A1: ANEXO 3. CUADRO DE CANTIDADES DE ENERGÍA Y PRECIO
B2: ="El precio del suministro para cada período (mes) se debe expresar en pesos por Kilovatio-hora (COP/KWh) con dos cifras decimales, en forma de precio monomio fijo, en pesos constantes de "&C11 -> El precio del suministro para cada período (mes) se debe expresar en pesos por Kilovatio-hora (COP/KWh) con dos cifras decimales, en forma de precio monomio fijo, en pesos constantes de noviembre de 2024
B5: OFERTA MERCANTIL N°:
B6: INVITACIÓN: | C6: ='Formato Resumen 23'!C6 -> CP-EXEC2025-001
B7: OFERENTE:
B8: OFERTA: | C8: CP-EXEC2024-002-PROD01
B9: FNCER (SI/NO):
B10: CANTIDAD EN: | C10: KWh
B11: PRECIOS $/kWh de: | C11: ='Formato Resumen 23'!C11 -> noviembre de 2024
B12: MODALIDAD: | C12: PC (1)
B14: AÑO 2024 | C14: ENERGÍA SOLICITADA (KWh) | D14: NIVEL DE COBERTURA ESPERADO (%) | E14: ENERGÍA OFRECIDA (KWh) (2) (3) | F14: PRECIO OFERTADO (COP/KWh) (4)
B16: ENE | E16: 0
B17: FEB | E17: 0
B18: MAR | E18: 0
B19: ABR | E19: 0
B20: MAY | E20: 0
B21: JUN | E21: 0
B22: JUL | E22: 0
B23: AGO | E23: 0
B24: SEP | E24: 0
B25: OCT | E25: 0
B26: NOV | C26: 4000000 | D26: 1 | E26: 0
B27: DIC | C27: 4000000 | D27: 1 | E27: 2000000
B28: TOTAL | C28: =SUM(C16:C27) -> 8000000 | E28: 2000000
B30: NOTAS:
B31: =IF('Formato Resumen 23'!B31=0,"",'Formato Resumen 23'!B31) -> _PC: Pague lo contratado
B32: =IF('Formato Resumen 23'!B32=0,"",'Formato Resumen 23'!B32) -> _La energía ofrecida se despachará de acuerdo con las curvas descritas los terminos de referencia.
B33: =IF('Formato Resumen 23'!B33=0,"",'Formato Resumen 23'!B33) -> _Ingresar con dos cifras decimales la energía ofrecida hasta las cantidades solicitadas.
B34: =IF('Formato Resumen 23'!B34=0,"",'Formato Resumen 23'!B34) -> _Ingresar un precio monomio fijo en COP/KWh con dos cifras decimales.
B35: =IF('Formato Resumen 23'!B35=0,"",'Formato Resumen 23'!B35) -> _No serán tenidas en cuenta ofertas con condiciones y/o modificaciones adicionales a los Pliegos definitivos.
B36: =IF('Formato Resumen 23'!B36=0,"",'Formato Resumen 23'!B36)
B38: =IF('Formato Resumen 23'!B38=0,"",'Formato Resumen 23'!B38)
B39: =IF('Formato Resumen 23'!B39=0,"",'Formato Resumen 23'!B39)
B40: =IF('Formato Resumen 23'!B40=0,"",'Formato Resumen 23'!B40)
B41: =IF('Formato Resumen 23'!B41=0,"",'Formato Resumen 23'!B41)
B48: OFERENTE E.S.P.

Sheet P1 DETALLE AÑO 2024
A1: ANEXO 4. CANTIDADES HORARIAS SOLICITADAS
A2: OFERTA MERCANTIL N°:
A3: INVITACIÓN: | D3: ='Formato Resumen 23'!C6 -> CP-EXEC2025-001
A4: OFERENTE:
A5: OFERTA: | D5: ='P1_AÑO 2024'!C8 -> CP-EXEC2024-002-PROD01
A6: AÑO: | D6: 2024 | E6: 0.031692962 | F6: 0.030769317 | G6: 0.029908399 | H6: 0.029629673 | I6: 0.030054654 | J6: 0.031743509 | K6: 0.037034552 | L6: 0.043161528 | M6: 0.046031335 | N6: 0.047955986 | O6: 0.04960977 | P6: 0.05112634 | Q6: 0.050804516 | R6: 0.05066491 | S6: 0.050973242 | T6: 0.050831094 | U6: 0.048893801 | V6: 0.046964572 | W6: 0.046697005 | X6: 0.046103444 | Y6: 0.043155278 | Z6: 0.038573955 | AA6: 0.03473795 | AB6: 0.032882208
A7: CANTIDAD EN: | D7: KWh* | AC7: L-V
A8: MODALIDAD: | D8: ='P1_AÑO 2025'!C12 -> PC (1) | AC8: SAB
A9: CURVA HORARIA: | AC9: DOM
A10: ="AÑO: "&D6 -> AÑO: 2024 | B10: Cantidad Ofrecida | C10: Tipo de día | D10: N° días mes | E10: H1 | F10: H2 | G10: H3 | H10: H4 | I10: H5 | J10: H6 | K10: H7 | L10: H8 | M10: H9 | N10: H10 | O10: H11 | P10: H12 | Q10: H13 | R10: H14 | S10: H15 | T10: H16 | U10: H17 | V10: H18 | W10: H19 | X10: H20 | Y10: H21 | Z10: H22 | AA10: H23 | AB10: H24 | AC10: TOTAL
A11: =1&"-"&$D$6 -> 1-2024 | B11: ='P1_AÑO 2024'!C16 -> 0 | C11: L-V | D11: =VLOOKUP(A11&C11,calendario!I:L,4,0) -> 23 | E11: =$B11/24/$D14 -> 0 | F11: =$B11/24/$D14 -> 0 | G11: =((78%*$B11)/$D11)*G$7 -> 0 | H11: =((78%*$B11)/$D11)*H$7 -> 0 | I11: =((78%*$B11)/$D11)*I$7 -> 0 | J11: =((78%*$B11)/$D11)*J$7 -> 0 | K11: =((78%*$B11)/$D11)*K$7 -> 0 | L11: =((78%*$B11)/$D11)*L$7 -> 0 | M11: =((78%*$B11)/$D11)*M$7 -> 0 | N11: =((78%*$B11)/$D11)*N$7 -> 0 | ... AB11: =((78%*$B11)/$D11)*AB$7 -> 0 | AC11: =+SUM(E11:AB11)*D11 -> 0 | AF11: ORD | AG11: 1
C12: SAB | D12: =VLOOKUP(A11&C12,calendario!I:L,4,0) -> 4 | E12: =$B11/24/$D14 -> 0 | F12: =$B11/24/$D14 -> 0 | G12: =((13%*$B11)/$D12)*G$8 -> 0 | H12: =((13%*$B11)/$D12)*H$8 -> 0 | I12: =((13%*$B11)/$D12)*I$8 -> 0 | J12: =((13%*$B11)/$D12)*J$8 -> 0 | K12: =((13%*$B11)/$D12)*K$8 -> 0 | L12: =((13%*$B11)/$D12)*L$8 -> 0 | M12: =((13%*$B11)/$D12)*M$8 -> 0 | N12: =((13%*$B11)/$D12)*N$8 -> 0 | ... AB12: =((13%*$B11)/$D12)*AB$8 -> 0 | AC12: =+SUM(E12:AB12)*D12 -> 0 | AF12: SÁB | AG12: 1
C13: DOM | D13: =VLOOKUP(A11&C13,calendario!I:L,4,0) -> 4 | E13: =$B11/24/$D14 -> 0 | F13: =$B11/24/$D14 -> 0 | G13: =((9%*$B11)/$D13)*G$9 -> 0 | H13: =((9%*$B11)/$D13)*H$9 -> 0 | I13: =((9%*$B11)/$D13)*I$9 -> 0 | J13: =((9%*$B11)/$D13)*J$9 -> 0 | K13: =((9%*$B11)/$D13)*K$9 -> 0 | L13: =((9%*$B11)/$D13)*L$9 -> 0 | M13: =((9%*$B11)/$D13)*M$9 -> 0 | N13: =((9%*$B11)/$D13)*N$9 -> 0 | ... AB13: =((9%*$B11)/$D13)*AB$9 -> 0 | AC13: =+SUM(E13:AB13)*D13 -> 0 | AF13: FES | AG13: 1
C14: TOTAL | D14: =SUM(D11:D13) -> 31 | AC14: =+SUM(AC11:AC13) -> 0
A15: =2&"-"&$D$6 -> 2-2024 | B15: ='P1_AÑO 2024'!C17 -> 0 | C15: L-V | D15: =VLOOKUP(A15&C15,calendario!I:L,4,0) -> 21 | E15: =$B15/24/$D18 -> 0 | F15: =$B15/24/$D18 -> 0 | G15: =$B15/24/$D18 -> 0 | H15: =$B15/24/$D18 -> 0 | I15: =$B15/24/$D18 -> 0 | J15: =$B15/24/$D18 -> 0 | K15: =$B15/24/$D18 -> 0 | L15: =$B15/24/$D18 -> 0 | ... AB15: =$B15/24/$D18 -> 0 | AC15: =+SUM(E15:AB15)*D15 -> 0 | AF15: ORD | AG15: 2
C16: SAB | D16: =VLOOKUP(A15&C16,calendario!I:L,4,0) -> 4 | E16: =$B15/24/$D18 -> 0 | F16: =$B15/24/$D18 -> 0 | G16: =$B15/24/$D18 -> 0 | H16: =$B15/24/$D18 -> 0 | I16: =$B15/24/$D18 -> 0 | J16: =$B15/24/$D18 -> 0 | K16: =$B15/24/$D18 -> 0 | L16: =$B15/24/$D18 -> 0 | ... AB16: =$B15/24/$D18 -> 0 | AC16: =+SUM(E16:AB16)*D16 -> 0 | AF16: SÁB | AG16: 2
C17: DOM | D17: =VLOOKUP(A15&C17,calendario!I:L,4,0) -> 4 | E17: =$B15/24/$D18 -> 0 | F17: =$B15/24/$D18 -> 0 | G17: =$B15/24/$D18 -> 0 | H17: =$B15/24/$D18 -> 0 | I17: =$B15/24/$D18 -> 0 | J17: =$B15/24/$D18 -> 0 | K17: =$B15/24/$D18 -> 0 | L17: =$B15/24/$D18 -> 0 | ... AB17: =$B15/24/$D18 -> 0 | AC17: =+SUM(E17:AB17)*D17 -> 0 | AF17: FES | AG17: 2
C18: TOTAL | D18: =SUM(D15:D17) -> 29 | AC18: =+SUM(AC15:AC17) -> 0
A19: =3&"-"&$D$6 -> 3-2024 | B19: ='P1_AÑO 2024'!C18 -> 0 | C19: L-V | D19: =VLOOKUP(A19&C19,calendario!I:L,4,0) -> 21 | E19: =$B19/24/$D22 -> 0 | F19: =$B19/24/$D22 -> 0 | G19: =$B19/24/$D22 -> 0 | H19: =$B19/24/$D22 -> 0 | I19: =$B19/24/$D22 -> 0 | J19: =$B19/24/$D22 -> 0 | K19: =$B19/24/$D22 -> 0 | L19: =$B19/24/$D22 -> 0 | ... AB19: =$B19/24/$D22 -> 0 | AC19: =+SUM(E19:AB19)*D19 -> 0 | AF19: ORD | AG19: 3
C20: SAB | D20: =VLOOKUP(A19&C20,calendario!I:L,4,0) -> 5 | E20: =$B19/24/$D22 -> 0 | F20: =$B19/24/$D22 -> 0 | G20: =$B19/24/$D22 -> 0 | H20: =$B19/24/$D22 -> 0 | I20: =$B19/24/$D22 -> 0 | J20: =$B19/24/$D22 -> 0 | K20: =$B19/24/$D22 -> 0 | L20: =$B19/24/$D22 -> 0 | ... AB20: =$B19/24/$D22 -> 0 | AC20: =+SUM(E20:AB20)*D20 -> 0 | AF20: SÁB | AG20: 3
C21: DOM | D21: =VLOOKUP(A19&C21,calendario!I:L,4,0) -> 5 | E21: =$B19/24/$D22 -> 0 | F21: =$B19/24/$D22 -> 0 | G21: =$B19/24/$D22 -> 0 | H21: =$B19/24/$D22 -> 0 | I21: =$B19/24/$D22 -> 0 | J21: =$B19/24/$D22 -> 0 | K21: =$B19/24/$D22 -> 0 | L21: =$B19/24/$D22 -> 0 | ... AB21: =$B19/24/$D22 -> 0 | AC21: =+SUM(E21:AB21)*D21 -> 0 | AF21: FES | AG21: 3
C22: TOTAL | D22: =SUM(D19:D21) -> 31 | AC22: =+SUM(AC19:AC21) -> 0
A23: =4&"-"&$D$6 -> 4-2024 | B23: ='P1_AÑO 2024'!C19 -> 0 | C23: L-V | D23: =VLOOKUP(A23&C23,calendario!I:L,4,0) -> 22 | E23: =$B23/24/$D26 -> 0 | F23: =$B23/24/$D26 -> 0 | G23: =$B23/24/$D26 -> 0 | H23: =$B23/24/$D26 -> 0 | I23: =$B23/24/$D26 -> 0 | J23: =$B23/24/$D26 -> 0 | K23: =$B23/24/$D26 -> 0 | L23: =$B23/24/$D26 -> 0 | ... AB23: =$B23/24/$D26 -> 0 | AC23: =+SUM(E23:AB23)*D23 -> 0 | AF23: ORD | AG23: 4
C24: SAB | D24: =VLOOKUP(A23&C24,calendario!I:L,4,0) -> 4 | E24: =$B23/24/$D26 -> 0 | F24: =$B23/24/$D26 -> 0 | G24: =$B23/24/$D26 -> 0 | H24: =$B23/24/$D26 -> 0 | I24: =$B23/24/$D26 -> 0 | J24: =$B23/24/$D26 -> 0 | K24: =$B23/24/$D26 -> 0 | L24: =$B23/24/$D26 -> 0 | ... AB24: =$B23/24/$D26 -> 0 | AC24: =+SUM(E24:AB24)*D24 -> 0 | AF24: SÁB | AG24: 4
C25: DOM | D25: =VLOOKUP(A23&C25,calendario!I:L,4,0) -> 4 | E25: =$B23/24/$D26 -> 0 | F25: =$B23/24/$D26 -> 0 | G25: =$B23/24/$D26 -> 0 | H25: =$B23/24/$D26 -> 0 | I25: =$B23/24/$D26 -> 0 | J25: =$B23/24/$D26 -> 0 | K25: =$B23/24/$D26 -> 0 | L25: =$B23/24/$D26 -> 0 | ... AB25: =$B23/24/$D26 -> 0 | AC25: =+SUM(E25:AB25)*D25 -> 0 | AF25: FES | AG25: 4
C26: TOTAL | D26: =SUM(D23:D25) -> 30 | AC26: =+SUM(AC23:AC25) -> 0
A27: =5&"-"&$D$6 -> 5-2024 | B27: ='P1_AÑO 2024'!C20 -> 0 | C27: L-V | D27: =VLOOKUP(A27&C27,calendario!I:L,4,0) -> 23 | E27: =$B27/24/$D30 -> 0 | F27: =$B27/24/$D30 -> 0 | G27: =$B27/24/$D30 -> 0 | H27: =$B27/24/$D30 -> 0 | I27: =$B27/24/$D30 -> 0 | J27: =$B27/24/$D30 -> 0 | K27: =$B27/24/$D30 -> 0 | L27: =$B27/24/$D30 -> 0 | ... AB27: =$B27/24/$D30 -> 0 | AC27: =+SUM(E27:AB27)*D27 -> 0 | AF27: ORD | AG27: 5
C28: SAB | D28: =VLOOKUP(A27&C28,calendario!I:L,4,0) -> 4 | E28: =$B27/24/$D30 -> 0 | F28: =$B27/24/$D30 -> 0 | G28: =$B27/24/$D30 -> 0 | H28: =$B27/24/$D30 -> 0 | I28: =$B27/24/$D30 -> 0 | J28: =$B27/24/$D30 -> 0 | K28: =$B27/24/$D30 -> 0 | L28: =$B27/24/$D30 -> 0 | ... AB28: =$B27/24/$D30 -> 0 | AC28: =+SUM(E28:AB28)*D28 -> 0 | AF28: SÁB | AG28: 5
C29: DOM | D29: =VLOOKUP(A27&C29,calendario!I:L,4,0) -> 4 | E29: =$B27/24/$D30 -> 0 | F29: =$B27/24/$D30 -> 0 | G29: =$B27/24/$D30 -> 0 | H29: =$B27/24/$D30 -> 0 | I29: =$B27/24/$D30 -> 0 | J29: =$B27/24/$D30 -> 0 | K29: =$B27/24/$D30 -> 0 | L29: =$B27/24/$D30 -> 0 | ... AB29: =$B27/24/$D30 -> 0 | AC29: =+SUM(E29:AB29)*D29 -> 0 | AF29: FES | AG29: 5
C30: TOTAL | D30: =SUM(D27:D29) -> 31 | AC30: =+SUM(AC27:AC29) -> 0
A31: =6&"-"&$D$6 -> 6-2024 | B31: ='P1_AÑO 2024'!C21 -> 0 | C31: L-V | D31: =VLOOKUP(A31&C31,calendario!I:L,4,0) -> 20 | E31: =$B31/24/$D34 -> 0 | F31: =$B31/24/$D34 -> 0 | G31: =$B31/24/$D34 -> 0 | H31: =$B31/24/$D34 -> 0 | I31: =$B31/24/$D34 -> 0 | J31: =$B31/24/$D34 -> 0 | K31: =$B31/24/$D34 -> 0 | L31: =$B31/24/$D34 -> 0 | ... AB31: =$B31/24/$D34 -> 0 | AC31: =+SUM(E31:AB31)*D31 -> 0 | AF31: ORD | AG31: 6
C32: SAB | D32: =VLOOKUP(A31&C32,calendario!I:L,4,0) -> 5 | E32: =$B31/24/$D34 -> 0 | F32: =$B31/24/$D34 -> 0 | G32: =$B31/24/$D34 -> 0 | H32: =$B31/24/$D34 -> 0 | I32: =$B31/24/$D34 -> 0 | J32: =$B31/24/$D34 -> 0 | K32: =$B31/24/$D34 -> 0 | L32: =$B31/24/$D34 -> 0 | ... AB32: =$B31/24/$D34 -> 0 | AC32: =+SUM(E32:AB32)*D32 -> 0 | AF32: SÁB | AG32: 6
C33: DOM | D33: =VLOOKUP(A31&C33,calendario!I:L,4,0) -> 5 | E33: =$B31/24/$D34 -> 0 | F33: =$B31/24/$D34 -> 0 | G33: =$B31/24/$D34 -> 0 | H33: =$B31/24/$D34 -> 0 | I33: =$B31/24/$D34 -> 0 | J33: =$B31/24/$D34 -> 0 | K33: =$B31/24/$D34 -> 0 | L33: =$B31/24/$D34 -> 0 | ... AB33: =$B31/24/$D34 -> 0 | AC33: =+SUM(E33:AB33)*D33 -> 0 | AF33: FES | AG33: 6
C34: TOTAL | D34: =SUM(D31:D33) -> 30 | AC34: =+SUM(AC31:AC33) -> 0
A35: =7&"-"&$D$6 -> 7-2024 | B35: ='P1_AÑO 2024'!C22 -> 0 | C35: L-V | D35: =VLOOKUP(A35&C35,calendario!I:L,4,0) -> 23 | E35: =$B35/24/$D38 -> 0 | F35: =$B35/24/$D38 -> 0 | G35: =$B35/24/$D38 -> 0 | H35: =$B35/24/$D38 -> 0 | I35: =$B35/24/$D38 -> 0 | J35: =$B35/24/$D38 -> 0 | K35: =$B35/24/$D38 -> 0 | L35: =$B35/24/$D38 -> 0 | ... AB35: =$B35/24/$D38 -> 0 | AC35: =+SUM(E35:AB35)*D35 -> 0 | AF35: ORD | AG35: 7
C36: SAB | D36: =VLOOKUP(A35&C36,calendario!I:L,4,0) -> 4 | E36: =$B35/24/$D38 -> 0 | F36: =$B35/24/$D38 -> 0 | G36: =$B35/24/$D38 -> 0 | H36: =$B35/24/$D38 -> 0 | I36: =$B35/24/$D38 -> 0 | J36: =$B35/24/$D38 -> 0 | K36: =$B35/24/$D38 -> 0 | L36: =$B35/24/$D38 -> 0 | ... AB36: =$B35/24/$D38 -> 0 | AC36: =+SUM(E36:AB36)*D36 -> 0 | AF36: SÁB | AG36: 7
C37: DOM | D37: =VLOOKUP(A35&C37,calendario!I:L,4,0) -> 4 | E37: =$B35/24/$D38 -> 0 | F37: =$B35/24/$D38 -> 0 | G37: =$B35/24/$D38 -> 0 | H37: =$B35/24/$D38 -> 0 | I37: =$B35/24/$D38 -> 0 | J37: =$B35/24/$D38 -> 0 | K37: =$B35/24/$D38 -> 0 | L37: =$B35/24/$D38 -> 0 | ... AB37: =$B35/24/$D38 -> 0 | AC37: =+SUM(E37:AB37)*D37 -> 0 | AF37: FES | AG37: 7
C38: TOTAL | D38: =SUM(D35:D37) -> 31 | AC38: =+SUM(AC35:AC37) -> 0
A39: =8&"-"&$D$6 -> 8-2024 | B39: ='P1_AÑO 2024'!C23 -> 0 | C39: L-V | D39: =VLOOKUP(A39&C39,calendario!I:L,4,0) -> 22 | E39: =$B39/24/$D42 -> 0 | F39: =$B39/24/$D42 -> 0 | G39: =$B39/24/$D42 -> 0 | H39: =$B39/24/$D42 -> 0 | I39: =$B39/24/$D42 -> 0 | J39: =$B39/24/$D42 -> 0 | K39: =$B39/24/$D42 -> 0 | L39: =$B39/24/$D42 -> 0 | ... AB39: =$B39/24/$D42 -> 0 | AC39: =+SUM(E39:AB39)*D39 -> 0 | AF39: ORD | AG39: 8
C40: SAB | D40: =VLOOKUP(A39&C40,calendario!I:L,4,0) -> 5 | E40: =$B39/24/$D42 -> 0 | F40: =$B39/24/$D42 -> 0 | G40: =$B39/24/$D42 -> 0 | H40: =$B39/24/$D42 -> 0 | I40: =$B39/24/$D42 -> 0 | J40: =$B39/24/$D42 -> 0 | K40: =$B39/24/$D42 -> 0 | L40: =$B39/24/$D42 -> 0 | ... AB40: =$B39/24/$D42 -> 0 | AC40: =+SUM(E40:AB40)*D40 -> 0 | AF40: SÁB | AG40: 8
...

Sheet P1_AÑO 2025
A1: ANEXO 3. CUADRO DE CANTIDADES DE ENERGÍA Y PRECIO
B2: ="El precio del suministro para cada período (mes) se debe expresar en pesos por Kilovatio-hora (COP/KWh) con dos cifras decimales, en forma de precio monomio fijo, en pesos constantes de "&C11 -> El precio del suministro para cada período (mes) se debe expresar en pesos por Kilovatio-hora (COP/KWh) con dos cifras decimales, en forma de precio monomio fijo, en pesos constantes de noviembre de 2024
B5: OFERTA MERCANTIL N°:
B6: INVITACIÓN: | C6: ='Formato Resumen 23'!C6 -> CP-EXEC2025-001
B7: OFERENTE:
B8: OFERTA: | C8: =C6&" -PROD01" -> CP-EXEC2025-001 -PROD01
B9: FNCER (SI/NO):
B10: CANTIDAD EN: | C10: KWh
B11: PRECIOS $/kWh de: | C11: ='P1_AÑO 2024'!C11 -> noviembre de 2024
B12: MODALIDAD: | C12: PC (1)
B14: AÑO 2025 | C14: ENERGÍA SOLICITADA (KWh) | D14: NIVEL DE COBERTURA ESPERADO (%) | E14: ENERGÍA OFRECIDA (KWh) (2) (3) | F14: PRECIO OFERTADO (COP/KWh) (4)
B16: ENE | C16: 4000000 | D16: 1 | E16: =C16 -> 4000000 | F16: 450
B17: FEB | C17: 4000000 | D17: 1 | E17: =C17 -> 4000000 | F17: 450
B18: MAR | C18: 4000000 | D18: 1 | E18: =C18 -> 4000000 | F18: 450
B19: ABR | C19: 4000000 | D19: 1 | E19: =C19 -> 4000000 | F19: 430
B20: MAY | C20: 4000000 | D20: 1 | E20: =C20 -> 4000000 | F20: 430
B21: JUN | C21: 5000000 | D21: 1 | E21: =C21 -> 5000000 | F21: 450
B22: JUL | C22: 5000000 | D22: 1 | E22: =C22 -> 5000000 | F22: 450
B23: AGO | C23: 6000000 | D23: 1 | E23: =C23 -> 6000000 | F23: 430
B24: SEP | C24: 6000000 | D24: 1 | E24: =C24 -> 6000000 | F24: 430
B25: OCT | C25: 6000000 | D25: 1 | E25: =C25 -> 6000000 | F25: 430
B26: NOV | C26: 6000000 | D26: 1 | E26: =C26 -> 6000000 | F26: 430
B27: DIC | C27: 6000000 | D27: 1 | E27: =C27 -> 6000000 | F27: 450 | G27: =SUMPRODUCT(E16:E27,F16:F27)/SUM(E16:E27) -> 439.33333
B28: TOTAL | C28: =SUM(C16:C27) -> 60000000 | E28: 2000000
B30: NOTAS:
B31: =IF('Formato Resumen 23'!B31=0,"",'Formato Resumen 23'!B31) -> _PC: Pague lo contratado
B32: =IF('Formato Resumen 23'!B32=0,"",'Formato Resumen 23'!B32) -> _La energía ofrecida se despachará de acuerdo con las curvas descritas los terminos de referencia.
B33: =IF('Formato Resumen 23'!B33=0,"",'Formato Resumen 23'!B33) -> _Ingresar con dos cifras decimales la energía ofrecida hasta las cantidades solicitadas.
B34: =IF('Formato Resumen 23'!B34=0,"",'Formato Resumen 23'!B34) -> _Ingresar un precio monomio fijo en COP/KWh con dos cifras decimales.
B35: =IF('Formato Resumen 23'!B35=0,"",'Formato Resumen 23'!B35) -> _No serán tenidas en cuenta ofertas con condiciones y/o modificaciones adicionales a los Pliegos definitivos.
B36: =IF('Formato Resumen 23'!B36=0,"",'Formato Resumen 23'!B36)
B37: =IF('Formato Resumen 23'!B37=0,"",'Formato Resumen 23'!B37)
B38: =IF('Formato Resumen 23'!B38=0,"",'Formato Resumen 23'!B38)
B39: =IF('Formato Resumen 23'!B39=0,"",'Formato Resumen 23'!B39)
B40: =IF('Formato Resumen 23'!B40=0,"",'Formato Resumen 23'!B40)
B41: =IF('Formato Resumen 23'!B41=0,"",'Formato Resumen 23'!B41)
B48: OFERENTE E.S.P.

Sheet P1 DETALLE AÑO 2025
A1: ANEXO 4. CANTIDADES HORARIAS SOLICITADAS
A2: OFERTA MERCANTIL N°:
A3: INVITACIÓN: | D3: ='Formato Resumen 23'!C6 -> CP-EXEC2025-001
A4: OFERENTE:
A5: OFERTA: | D5: ='P1_AÑO 2025'!C8 -> CP-EXEC2025-001 -PROD01
A6: AÑO: | D6: 2025 | E6: 0.031692962 | F6: 0.030769317 | G6: 0.029908399 | H6: 0.029629673 | I6: 0.030054654 | J6: 0.031743509 | K6: 0.037034552 | L6: 0.043161528 | M6: 0.046031335 | N6: 0.047955986 | O6: 0.04960977 | P6: 0.05112634 | Q6: 0.050804516 | R6: 0.05066491 | S6: 0.050973242 | T6: 0.050831094 | U6: 0.048893801 | V6: 0.046964572 | W6: 0.046697005 | X6: 0.046103444 | Y6: 0.043155278 | Z6: 0.038573955 | AA6: 0.03473795 | AB6: 0.032882208
A7: CANTIDAD EN: | D7: KWh* | AC7: L-V
A8: MODALIDAD: | D8: ='P1_AÑO 2025'!C12 -> PC (1) | AC8: SAB
A9: CURVA HORARIA: | AC9: DOM
A10: ="AÑO: "&D6 -> AÑO: 2025 | B10: Cantidad Ofrecida | C10: Tipo de día | D10: N° días mes | E10: H1 | F10: H2 | G10: H3 | H10: H4 | I10: H5 | J10: H6 | K10: H7 | L10: H8 | M10: H9 | N10: H10 | O10: H11 | P10: H12 | Q10: H13 | R10: H14 | S10: H15 | T10: H16 | U10: H17 | V10: H18 | W10: H19 | X10: H20 | Y10: H21 | Z10: H22 | AA10: H23 | AB10: H24 | AC10: TOTAL
A11: =1&"-"&$D$6 -> 1-2025 | B11: ='P1_AÑO 2025'!C16 -> 4000000 | C11: L-V | D11: =VLOOKUP(A11&C11,calendario!I:L,4,0) -> 23 | E11: =(($B11)/$D14)*E$6 -> 4089.4144 | F11: =(($B11)/$D14)*F$6 -> 3970.2344 | G11: =(($B11)/$D14)*G$6 -> 3859.1483 | H11: =(($B11)/$D14)*H$6 -> 3823.1837 | I11: =(($B11)/$D14)*I$6 -> 3878.0199 | J11: =(($B11)/$D14)*J$6 -> 4095.9366 | K11: =(($B11)/$D14)*K$6 -> 4778.6518 | L11: =(($B11)/$D14)*L$6 -> 5569.2294 | ... AB11: =(($B11)/$D14)*AB$6 -> 4242.8656 | AC11: =+SUM(E11:AB11)*D11 -> 2967741.9 | AF11: ORD | AG11: 1
C12: SAB | D12: =VLOOKUP(A11&C12,calendario!I:L,4,0) -> 4 | E12: =(($B11)/$D14)*E$6 -> 4089.4144 | F12: =(($B11)/$D14)*F$6 -> 3970.2344 | G12: =(($B11)/$D14)*G$6 -> 3859.1483 | H12: =(($B11)/$D14)*H$6 -> 3823.1837 | I12: =(($B11)/$D14)*I$6 -> 3878.0199 | J12: =(($B11)/$D14)*J$6 -> 4095.9366 | K12: =(($B11)/$D14)*K$6 -> 4778.6518 | L12: =(($B11)/$D14)*L$6 -> 5569.2294 | ... AB12: =(($B11)/$D14)*AB$6 -> 4242.8656 | AC12: =+SUM(E12:AB12)*D12 -> 516129.03 | AF12: SÁB | AG12: 1
C13: DOM | D13: =VLOOKUP(A11&C13,calendario!I:L,4,0) -> 4 | E13: =(($B11)/$D14)*E$6 -> 4089.4144 | F13: =(($B11)/$D14)*F$6 -> 3970.2344 | G13: =(($B11)/$D14)*G$6 -> 3859.1483 | H13: =(($B11)/$D14)*H$6 -> 3823.1837 | I13: =(($B11)/$D14)*I$6 -> 3878.0199 | J13: =(($B11)/$D14)*J$6 -> 4095.9366 | K13: =(($B11)/$D14)*K$6 -> 4778.6518 | L13: =(($B11)/$D14)*L$6 -> 5569.2294 | ... AB13: =(($B11)/$D14)*AB$6 -> 4242.8656 | AC13: =+SUM(E13:AB13)*D13 -> 516129.03 | AF13: FES | AG13: 1
C14: TOTAL | D14: =SUM(D11:D13) -> 31 | AC14: =+SUM(AC11:AC13) -> 4000000
A15: =2&"-"&$D$6 -> 2-2025 | B15: ='P1_AÑO 2025'!C17 -> 4000000 | C15: L-V | D15: =VLOOKUP(A15&C15,calendario!I:L,4,0) -> 20 | E15: =(($B15)/$D18)*E$6 -> 4527.566 | F15: =(($B15)/$D18)*F$6 -> 4395.6167 | G15: =(($B15)/$D18)*G$6 -> 4272.6285 | H15: =(($B15)/$D18)*H$6 -> 4232.8105 | I15: =(($B15)/$D18)*I$6 -> 4293.522 | J15: =(($B15)/$D18)*J$6 -> 4534.787 | K15: =(($B15)/$D18)*K$6 -> 5290.6502 | L15: =(($B15)/$D18)*L$6 -> 6165.9326 | ... AB15: =(($B15)/$D18)*AB$6 -> 4697.4583 | AC15: =+SUM(E15:AB15)*D15 -> 2857142.9 | AF15: ORD | AG15: 2
C16: SAB | D16: =VLOOKUP(A15&C16,calendario!I:L,4,0) -> 4 | E16: =(($B15)/$D18)*E$6 -> 4527.566 | F16: =(($B15)/$D18)*F$6 -> 4395.6167 | G16: =(($B15)/$D18)*G$6 -> 4272.6285 | H16: =(($B15)/$D18)*H$6 -> 4232.8105 | I16: =(($B15)/$D18)*I$6 -> 4293.522 | J16: =(($B15)/$D18)*J$6 -> 4534.787 | K16: =(($B15)/$D18)*K$6 -> 5290.6502 | L16: =(($B15)/$D18)*L$6 -> 6165.9326 | ... AB16: =(($B15)/$D18)*AB$6 -> 4697.4583 | AC16: =+SUM(E16:AB16)*D16 -> 571428.57 | AF16: SÁB | AG16: 2
C17: DOM | D17: =VLOOKUP(A15&C17,calendario!I:L,4,0) -> 4 | E17: =(($B15)/$D18)*E$6 -> 4527.566 | F17: =(($B15)/$D18)*F$6 -> 4395.6167 | G17: =(($B15)/$D18)*G$6 -> 4272.6285 | H17: =(($B15)/$D18)*H$6 -> 4232.8105 | I17: =(($B15)/$D18)*I$6 -> 4293.522 | J17: =(($B15)/$D18)*J$6 -> 4534.787 | K17: =(($B15)/$D18)*K$6 -> 5290.6502 | L17: =(($B15)/$D18)*L$6 -> 6165.9326 | ... AB17: =(($B15)/$D18)*AB$6 -> 4697.4583 | AC17: =+SUM(E17:AB17)*D17 -> 571428.57 | AF17: FES | AG17: 2
C18: TOTAL | D18: =SUM(D15:D17) -> 28 | AC18: =+SUM(AC15:AC17) -> 4000000
A19: =3&"-"&$D$6 -> 3-2025 | B19: ='P1_AÑO 2025'!C18 -> 4000000 | C19: L-V | D19: =VLOOKUP(A19&C19,calendario!I:L,4,0) -> 21 | E19: =(($B19)/$D22)*E$6 -> 4089.4144 | F19: =(($B19)/$D22)*F$6 -> 3970.2344 | G19: =(($B19)/$D22)*G$6 -> 3859.1483 | H19: =(($B19)/$D22)*H$6 -> 3823.1837 | I19: =(($B19)/$D22)*I$6 -> 3878.0199 | J19: =(($B19)/$D22)*J$6 -> 4095.9366 | K19: =(($B19)/$D22)*K$6 -> 4778.6518 | L19: =(($B19)/$D22)*L$6 -> 5569.2294 | ... AB19: =(($B19)/$D22)*AB$6 -> 4242.8656 | AC19: =+SUM(E19:AB19)*D19 -> 2709677.4 | AF19: ORD | AG19: 3
C20: SAB | D20: =VLOOKUP(A19&C20,calendario!I:L,4,0) -> 5 | E20: =(($B19)/$D22)*E$6 -> 4089.4144 | F20: =(($B19)/$D22)*F$6 -> 3970.2344 | G20: =(($B19)/$D22)*G$6 -> 3859.1483 | H20: =(($B19)/$D22)*H$6 -> 3823.1837 | I20: =(($B19)/$D22)*I$6 -> 3878.0199 | J20: =(($B19)/$D22)*J$6 -> 4095.9366 | K20: =(($B19)/$D22)*K$6 -> 4778.6518 | L20: =(($B19)/$D22)*L$6 -> 5569.2294 | ... AB20: =(($B19)/$D22)*AB$6 -> 4242.8656 | AC20: =+SUM(E20:AB20)*D20 -> 645161.29 | AF20: SÁB | AG20: 3
C21: DOM | D21: =VLOOKUP(A19&C21,calendario!I:L,4,0) -> 5 | E21: =(($B19)/$D22)*E$6 -> 4089.4144 | F21: =(($B19)/$D22)*F$6 -> 3970.2344 | G21: =(($B19)/$D22)*G$6 -> 3859.1483 | H21: =(($B19)/$D22)*H$6 -> 3823.1837 | I21: =(($B19)/$D22)*I$6 -> 3878.0199 | J21: =(($B19)/$D22)*J$6 -> 4095.9366 | K21: =(($B19)/$D22)*K$6 -> 4778.6518 | L21: =(($B19)/$D22)*L$6 -> 5569.2294 | ... AB21: =(($B19)/$D22)*AB$6 -> 4242.8656 | AC21: =+SUM(E21:AB21)*D21 -> 645161.29 | AF21: FES | AG21: 3
C22: TOTAL | D22: =SUM(D19:D21) -> 31 | AC22: =+SUM(AC19:AC21) -> 4000000
A23: =4&"-"&$D$6 -> 4-2025 | B23: ='P1_AÑO 2025'!C19 -> 4000000 | C23: L-V | D23: =VLOOKUP(A23&C23,calendario!I:L,4,0) -> 22 | E23: =(($B23)/$D26)*E$6 -> 4225.7282 | F23: =(($B23)/$D26)*F$6 -> 4102.5756 | G23: =(($B23)/$D26)*G$6 -> 3987.7866 | H23: =(($B23)/$D26)*H$6 -> 3950.6231 | I23: =(($B23)/$D26)*I$6 -> 4007.2872 | J23: =(($B23)/$D26)*J$6 -> 4232.4678 | K23: =(($B23)/$D26)*K$6 -> 4937.9402 | L23: =(($B23)/$D26)*L$6 -> 5754.8704 | ... AB23: =(($B23)/$D26)*AB$6 -> 4384.2944 | AC23: =+SUM(E23:AB23)*D23 -> 2933333.3 | AF23: ORD | AG23: 4
C24: SAB | D24: =VLOOKUP(A23&C24,calendario!I:L,4,0) -> 4 | E24: =(($B23)/$D26)*E$6 -> 4225.7282 | F24: =(($B23)/$D26)*F$6 -> 4102.5756 | G24: =(($B23)/$D26)*G$6 -> 3987.7866 | H24: =(($B23)/$D26)*H$6 -> 3950.6231 | I24: =(($B23)/$D26)*I$6 -> 4007.2872 | J24: =(($B23)/$D26)*J$6 -> 4232.4678 | K24: =(($B23)/$D26)*K$6 -> 4937.9402 | L24: =(($B23)/$D26)*L$6 -> 5754.8704 | ... AB24: =(($B23)/$D26)*AB$6 -> 4384.2944 | AC24: =+SUM(E24:AB24)*D24 -> 533333.33 | AF24: SÁB | AG24: 4
C25: DOM | D25: =VLOOKUP(A23&C25,calendario!I:L,4,0) -> 4 | E25: =(($B23)/$D26)*E$6 -> 4225.7282 | F25: =(($B23)/$D26)*F$6 -> 4102.5756 | G25: =(($B23)/$D26)*G$6 -> 3987.7866 | H25: =(($B23)/$D26)*H$6 -> 3950.6231 | I25: =(($B23)/$D26)*I$6 -> 4007.2872 | J25: =(($B23)/$D26)*J$6 -> 4232.4678 | K25: =(($B23)/$D26)*K$6 -> 4937.9402 | L25: =(($B23)/$D26)*L$6 -> 5754.8704 | ... AB25: =(($B23)/$D26)*AB$6 -> 4384.2944 | AC25: =+SUM(E25:AB25)*D25 -> 533333.33 | AF25: FES | AG25: 4
C26: TOTAL | D26: =SUM(D23:D25) -> 30 | AC26: =+SUM(AC23:AC25) -> 4000000
A27: =5&"-"&$D$6 -> 5-2025 | B27: ='P1_AÑO 2025'!C20 -> 4000000 | C27: L-V | D27: =VLOOKUP(A27&C27,calendario!I:L,4,0) -> 22 | E27: =(($B27)/$D30)*E$6 -> 4089.4144 | F27: =(($B27)/$D30)*F$6 -> 3970.2344 | G27: =(($B27)/$D30)*G$6 -> 3859.1483 | H27: =(($B27)/$D30)*H$6 -> 3823.1837 | I27: =(($B27)/$D30)*I$6 -> 3878.0199 | J27: =(($B27)/$D30)*J$6 -> 4095.9366 | K27: =(($B27)/$D30)*K$6 -> 4778.6518 | L27: =(($B27)/$D30)*L$6 -> 5569.2294 | ... AB27: =(($B27)/$D30)*AB$6 -> 4242.8656 | AC27: =+SUM(E27:AB27)*D27 -> 2838709.7 | AF27: ORD | AG27: 5
C28: SAB | D28: =VLOOKUP(A27&C28,calendario!I:L,4,0) -> 5 | E28: =(($B27)/$D30)*E$6 -> 4089.4144 | F28: =(($B27)/$D30)*F$6 -> 3970.2344 | G28: =(($B27)/$D30)*G$6 -> 3859.1483 | H28: =(($B27)/$D30)*H$6 -> 3823.1837 | I28: =(($B27)/$D30)*I$6 -> 3878.0199 | J28: =(($B27)/$D30)*J$6 -> 4095.9366 | K28: =(($B27)/$D30)*K$6 -> 4778.6518 | L28: =(($B27)/$D30)*L$6 -> 5569.2294 | ... AB28: =(($B27)/$D30)*AB$6 -> 4242.8656 | AC28: =+SUM(E28:AB28)*D28 -> 645161.29 | AF28: SÁB | AG28: 5
C29: DOM | D29: =VLOOKUP(A27&C29,calendario!I:L,4,0) -> 4 | E29: =(($B27)/$D30)*E$6 -> 4089.4144 | F29: =(($B27)/$D30)*F$6 -> 3970.2344 | G29: =(($B27)/$D30)*G$6 -> 3859.1483 | H29: =(($B27)/$D30)*H$6 -> 3823.1837 | I29: =(($B27)/$D30)*I$6 -> 3878.0199 | J29: =(($B27)/$D30)*J$6 -> 4095.9366 | K29: =(($B27)/$D30)*K$6 -> 4778.6518 | L29: =(($B27)/$D30)*L$6 -> 5569.2294 | ... AB29: =(($B27)/$D30)*AB$6 -> 4242.8656 | AC29: =+SUM(E29:AB29)*D29 -> 516129.03 | AF29: FES | AG29: 5
C30: TOTAL | D30: =SUM(D27:D29) -> 31 | AC30: =+SUM(AC27:AC29) -> 4000000
A31: =6&"-"&$D$6 -> 6-2025 | B31: ='P1_AÑO 2025'!C21 -> 5000000 | C31: L-V | D31: =VLOOKUP(A31&C31,calendario!I:L,4,0) -> 21 | E31: =(($B31)/$D34)*E$6 -> 5282.1603 | F31: =(($B31)/$D34)*F$6 -> 5128.2195 | G31: =(($B31)/$D34)*G$6 -> 4984.7332 | H31: =(($B31)/$D34)*H$6 -> 4938.2789 | I31: =(($B31)/$D34)*I$6 -> 5009.109 | J31: =(($B31)/$D34)*J$6 -> 5290.5848 | K31: =(($B31)/$D34)*K$6 -> 6172.4253 | L31: =(($B31)/$D34)*L$6 -> 7193.588 | ... AB31: =(($B31)/$D34)*AB$6 -> 5480.368 | AC31: =+SUM(E31:AB31)*D31 -> 3500000 | AF31: ORD | AG31: 6
C32: SAB | D32: =VLOOKUP(A31&C32,calendario!I:L,4,0) -> 4 | E32: =(($B31)/$D34)*E$6 -> 5282.1603 | F32: =(($B31)/$D34)*F$6 -> 5128.2195 | G32: =(($B31)/$D34)*G$6 -> 4984.7332 | H32: =(($B31)/$D34)*H$6 -> 4938.2789 | I32: =(($B31)/$D34)*I$6 -> 5009.109 | J32: =(($B31)/$D34)*J$6 -> 5290.5848 | K32: =(($B31)/$D34)*K$6 -> 6172.4253 | L32: =(($B31)/$D34)*L$6 -> 7193.588 | ... AB32: =(($B31)/$D34)*AB$6 -> 5480.368 | AC32: =+SUM(E32:AB32)*D32 -> 666666.67 | AF32: SÁB | AG32: 6
C33: DOM | D33: =VLOOKUP(A31&C33,calendario!I:L,4,0) -> 5 | E33: =(($B31)/$D34)*E$6 -> 5282.1603 | F33: =(($B31)/$D34)*F$6 -> 5128.2195 | G33: =(($B31)/$D34)*G$6 -> 4984.7332 | H33: =(($B31)/$D34)*H$6 -> 4938.2789 | I33: =(($B31)/$D34)*I$6 -> 5009.109 | J33: =(($B31)/$D34)*J$6 -> 5290.5848 | K33: =(($B31)/$D34)*K$6 -> 6172.4253 | L33: =(($B31)/$D34)*L$6 -> 7193.588 | ... AB33: =(($B31)/$D34)*AB$6 -> 5480.368 | AC33: =+SUM(E33:AB33)*D33 -> 833333.33 | AF33: FES | AG33: 6
C34: TOTAL | D34: =SUM(D31:D33) -> 30 | AC34: =+SUM(AC31:AC33) -> 5000000
A35: =7&"-"&$D$6 -> 7-2025 | B35: ='P1_AÑO 2025'!C22 -> 5000000 | C35: L-V | D35: =VLOOKUP(A35&C35,calendario!I:L,4,0) -> 23 | E35: =(($B35)/$D38)*E$6 -> 5111.768 | F35: =(($B35)/$D38)*F$6 -> 4962.7931 | G35: =(($B35)/$D38)*G$6 -> 4823.9354 | H35: =(($B35)/$D38)*H$6 -> 4778.9796 | I35: =(($B35)/$D38)*I$6 -> 4847.5249 | J35: =(($B35)/$D38)*J$6 -> 5119.9208 | K35: =(($B35)/$D38)*K$6 -> 5973.3148 | L35: =(($B35)/$D38)*L$6 -> 6961.5368 | ... AB35: =(($B35)/$D38)*AB$6 -> 5303.582 | AC35: =+SUM(E35:AB35)*D35 -> 3709677.4 | AF35: ORD | AG35: 7
C36: SAB | D36: =VLOOKUP(A35&C36,calendario!I:L,4,0) -> 4 | E36: =(($B35)/$D38)*E$6 -> 5111.768 | F36: =(($B35)/$D38)*F$6 -> 4962.7931 | G36: =(($B35)/$D38)*G$6 -> 4823.9354 | H36: =(($B35)/$D38)*H$6 -> 4778.9796 | I36: =(($B35)/$D38)*I$6 -> 4847.5249 | J36: =(($B35)/$D38)*J$6 -> 5119.9208 | K36: =(($B35)/$D38)*K$6 -> 5973.3148 | L36: =(($B35)/$D38)*L$6 -> 6961.5368 | ... AB36: =(($B35)/$D38)*AB$6 -> 5303.582 | AC36: =+SUM(E36:AB36)*D36 -> 645161.29 | AF36: SÁB | AG36: 7
C37: DOM | D37: =VLOOKUP(A35&C37,calendario!I:L,4,0) -> 4 | E37: =(($B35)/$D38)*E$6 -> 5111.768 | F37: =(($B35)/$D38)*F$6 -> 4962.7931 | G37: =(($B35)/$D38)*G$6 -> 4823.9354 | H37: =(($B35)/$D38)*H$6 -> 4778.9796 | I37: =(($B35)/$D38)*I$6 -> 4847.5249 | J37: =(($B35)/$D38)*J$6 -> 5119.9208 | K37: =(($B35)/$D38)*K$6 -> 5973.3148 | L37: =(($B35)/$D38)*L$6 -> 6961.5368 | ... AB37: =(($B35)/$D38)*AB$6 -> 5303.582 | AC37: =+SUM(E37:AB37)*D37 -> 645161.29 | AF37: FES | AG37: 7
C38: TOTAL | D38: =SUM(D35:D37) -> 31 | AC38: =+SUM(AC35:AC37) -> 5000000
A39: =8&"-"&$D$6 -> 8-2025 | B39: ='P1_AÑO 2025'!C23 -> 6000000 | C39: L-V | D39: =VLOOKUP(A39&C39,calendario!I:L,4,0) -> 21 | E39: =(($B39)/$D42)*E$6 -> 6134.1216 | F39: =(($B39)/$D42)*F$6 -> 5955.3517 | G39: =(($B39)/$D42)*G$6 -> 5788.7225 | H39: =(($B39)/$D42)*H$6 -> 5734.7755 | I39: =(($B39)/$D42)*I$6 -> 5817.0298 | J39: =(($B39)/$D42)*J$6 -> 6143.9049 | K39: =(($B39)/$D42)*K$6 -> 7167.9777 | L39: =(($B39)/$D42)*L$6 -> 8353.8441 | ... AB39: =(($B39)/$D42)*AB$6 -> 6364.2984 | AC39: =+SUM(E39:AB39)*D39 -> 4064516.1 | AF39: ORD | AG39: 8
C40: SAB | D40: =VLOOKUP(A39&C40,calendario!I:L,4,0) -> 5 | E40: =(($B39)/$D42)*E$6 -> 6134.1216 | F40: =(($B39)/$D42)*F$6 -> 5955.3517 | G40: =(($B39)/$D42)*G$6 -> 5788.7225 | H40: =(($B39)/$D42)*H$6 -> 5734.7755 | I40: =(($B39)/$D42)*I$6 -> 5817.0298 | J40: =(($B39)/$D42)*J$6 -> 6143.9049 | K40: =(($B39)/$D42)*K$6 -> 7167.9777 | L40: =(($B39)/$D42)*L$6 -> 8353.8441 | ... AB40: =(($B39)/$D42)*AB$6 -> 6364.2984 | AC40: =+SUM(E40:AB40)*D40 -> 967741.94 | AF40: SÁB | AG40: 8
...

Sheet AÑO 2026
A1: ANEXO 3. CUADRO DE CANTIDADES DE ENERGÍA Y PRECIO
B2: ="El precio del suministro para cada período (mes) se debe expresar en pesos por Kilovatio-hora (COP/KWh) con dos cifras decimales, en forma de precio monomio fijo, en pesos constantes de "&C11 -> El precio del suministro para cada período (mes) se debe expresar en pesos por Kilovatio-hora (COP/KWh) con dos cifras decimales, en forma de precio monomio fijo, en pesos constantes de noviembre de 2024
B5: OFERTA MERCANTIL N°:
B6: INVITACIÓN: | C6: ='Formato Resumen 23'!C6 -> CP-EXEC2025-001
B7: OFERENTE:
B8: OFERTA: | C8: =C6&" -PROD01" -> CP-EXEC2025-001 -PROD01
B9: FNCER (SI/NO):
B10: CANTIDAD EN: | C10: KWh
B11: PRECIOS $/kWh de: | C11: ='P1_AÑO 2024'!C11 -> noviembre de 2024
B12: MODALIDAD: | C12: PC (1)
B14: AÑO 2026 | C14: ENERGÍA SOLICITADA (KWh) | D14: NIVEL DE COBERTURA ESPERADO (%) | E14: ENERGÍA OFRECIDA (KWh) (2) (3) | F14: PRECIO OFERTADO (COP/KWh) (4)
B16: ENE | C16: 6000000 | D16: 1
B17: FEB | C17: 6000000 | D17: 1
B18: MAR | C18: 6000000 | D18: 1
B19: ABR | C19: 6000000 | D19: 1
B20: MAY | C20: 6000000 | D20: 1
B21: JUN | C21: 6000000 | D21: 1
B22: JUL | C22: 6000000 | D22: 1
B23: AGO | C23: 6000000 | D23: 1
B24: SEP | C24: 6000000 | D24: 1
B25: OCT | C25: 6000000 | D25: 1
B26: NOV | C26: 6000000 | D26: 1
B27: DIC | C27: 6000000 | D27: 1
B28: TOTAL | C28: =SUM(C16:C27) -> 72000000
B30: NOTAS:
B31: =IF('Formato Resumen 23'!B31=0,"",'Formato Resumen 23'!B31) -> _PC: Pague lo contratado
B32: =IF('Formato Resumen 23'!B32=0,"",'Formato Resumen 23'!B32) -> _La energía ofrecida se despachará de acuerdo con las curvas descritas los terminos de referencia.
B33: =IF('Formato Resumen 23'!B33=0,"",'Formato Resumen 23'!B33) -> _Ingresar con dos cifras decimales la energía ofrecida hasta las cantidades solicitadas.
B34: =IF('Formato Resumen 23'!B34=0,"",'Formato Resumen 23'!B34) -> _Ingresar un precio monomio fijo en COP/KWh con dos cifras decimales.
B35: =IF('Formato Resumen 23'!B35=0,"",'Formato Resumen 23'!B35) -> _No serán tenidas en cuenta ofertas con condiciones y/o modificaciones adicionales a los Pliegos definitivos.
B36: =IF('Formato Resumen 23'!B36=0,"",'Formato Resumen 23'!B36)
B37: =IF('Formato Resumen 23'!B37=0,"",'Formato Resumen 23'!B37)
B38: =IF('Formato Resumen 23'!B38=0,"",'Formato Resumen 23'!B38)
B39: =IF('Formato Resumen 23'!B39=0,"",'Formato Resumen 23'!B39)
B40: =IF('Formato Resumen 23'!B40=0,"",'Formato Resumen 23'!B40)
B41: =IF('Formato Resumen 23'!B41=0,"",'Formato Resumen 23'!B41)
B48: OFERENTE E.S.P.

Sheet DETALLE AÑO 2026
A1: ANEXO 4. CANTIDADES HORARIAS SOLICITADAS
A2: OFERTA MERCANTIL N°:
A3: INVITACIÓN: | D3: ='Formato Resumen 23'!C6 -> CP-EXEC2025-001
A4: OFERENTE:
A5: OFERTA: | D5: ='AÑO 2026'!C8 -> CP-EXEC2025-001 -PROD01
A6: AÑO: | D6: 2026 | E6: 0.031692962 | F6: 0.030769317 | G6: 0.029908399 | H6: 0.029629673 | I6: 0.030054654 | J6: 0.031743509 | K6: 0.037034552 | L6: 0.043161528 | M6: 0.046031335 | N6: 0.047955986 | O6: 0.04960977 | P6: 0.05112634 | Q6: 0.050804516 | R6: 0.05066491 | S6: 0.050973242 | T6: 0.050831094 | U6: 0.048893801 | V6: 0.046964572 | W6: 0.046697005 | X6: 0.046103444 | Y6: 0.043155278 | Z6: 0.038573955 | AA6: 0.03473795 | AB6: 0.032882208
A7: CANTIDAD EN: | D7: KWh* | E7: 0.030195225 | F7: 0.029611293 | G7: 0.028832821 | H7: 0.028478695 | I7: 0.028563322 | J7: 0.030749703 | K7: 0.036409241 | L7: 0.042493628 | M7: 0.045730747 | N7: 0.047701346 | O7: 0.049721527 | P7: 0.051064572 | Q7: 0.050757726 | R7: 0.051097168 | S7: 0.051615707 | T7: 0.052079942 | U7: 0.050805101 | V7: 0.048481356 | W7: 0.048303686 | X7: 0.04768075 | Y7: 0.04408306 | Z7: 0.038689068 | AA7: 0.034525596 | AB7: 0.03232872 | AC7: L-V
A8: MODALIDAD: | D8: ='P1_AÑO 2025'!C12 -> PC (1) | AC8: SAB
A9: CURVA HORARIA: | AC9: DOM
A10: ="AÑO: "&D6 -> AÑO: 2026 | B10: Cantidad Ofrecida | C10: Tipo de día | D10: N° días mes | E10: H1 | F10: H2 | G10: H3 | H10: H4 | I10: H5 | J10: H6 | K10: H7 | L10: H8 | M10: H9 | N10: H10 | O10: H11 | P10: H12 | Q10: H13 | R10: H14 | S10: H15 | T10: H16 | U10: H17 | V10: H18 | W10: H19 | X10: H20 | Y10: H21 | Z10: H22 | AA10: H23 | AB10: H24 | AC10: TOTAL
A11: =1&"-"&$D$6 -> 1-2026 | B11: ='AÑO 2026'!C16 -> 6000000 | C11: L-V | D11: =VLOOKUP(A11&C11,calendario!I:L,4,0) -> 22 | E11: =(($B11)/$D14)*E$7 -> 5844.237 | F11: =(($B11)/$D14)*F$7 -> 5731.218 | G11: =(($B11)/$D14)*G$7 -> 5580.546 | H11: =(($B11)/$D14)*H$7 -> 5512.0055 | I11: =(($B11)/$D14)*I$7 -> 5528.3849 | J11: =(($B11)/$D14)*J$7 -> 5951.5554 | K11: =(($B11)/$D14)*K$7 -> 7046.9499 | L11: =(($B11)/$D14)*L$7 -> 8224.5732 | ... AB11: =(($B11)/$D14)*AB$7 -> 6257.1717 | AC11: =+SUM(E11:AB11)*D11 -> 4258064.5
C12: SAB | D12: =VLOOKUP(A11&C12,calendario!I:L,4,0) -> 5 | E12: =(($B11)/$D14)*E$7 -> 5844.237 | F12: =(($B11)/$D14)*F$7 -> 5731.218 | G12: =(($B11)/$D14)*G$7 -> 5580.546 | H12: =(($B11)/$D14)*H$7 -> 5512.0055 | I12: =(($B11)/$D14)*I$7 -> 5528.3849 | J12: =(($B11)/$D14)*J$7 -> 5951.5554 | K12: =(($B11)/$D14)*K$7 -> 7046.9499 | L12: =(($B11)/$D14)*L$7 -> 8224.5732 | ... AB12: =(($B11)/$D14)*AB$7 -> 6257.1717 | AC12: =+SUM(E12:AB12)*D12 -> 967741.94 | AF12: SÁB | AG12: 1
C13: DOM | D13: =VLOOKUP(A11&C13,calendario!I:L,4,0) -> 4 | E13: =(($B11)/$D14)*E$7 -> 5844.237 | F13: =(($B11)/$D14)*F$7 -> 5731.218 | G13: =(($B11)/$D14)*G$7 -> 5580.546 | H13: =(($B11)/$D14)*H$7 -> 5512.0055 | I13: =(($B11)/$D14)*I$7 -> 5528.3849 | J13: =(($B11)/$D14)*J$7 -> 5951.5554 | K13: =(($B11)/$D14)*K$7 -> 7046.9499 | L13: =(($B11)/$D14)*L$7 -> 8224.5732 | ... AB13: =(($B11)/$D14)*AB$7 -> 6257.1717 | AC13: =+SUM(E13:AB13)*D13 -> 774193.55 | AF13: FES | AG13: 1
C14: TOTAL | D14: =SUM(D11:D13) -> 31 | AC14: =+SUM(AC11:AC13) -> 6000000
A15: =2&"-"&$D$6 -> 2-2026 | B15: ='AÑO 2026'!C17 -> 6000000 | C15: L-V | D15: =VLOOKUP(A15&C15,calendario!I:L,4,0) -> 20 | E15: =(($B15)/$D18)*E$7 -> 6470.4053 | F15: =(($B15)/$D18)*F$7 -> 6345.2771 | G15: =(($B15)/$D18)*G$7 -> 6178.4616 | H15: =(($B15)/$D18)*H$7 -> 6102.5775 | I15: =(($B15)/$D18)*I$7 -> 6120.7118 | J15: =(($B15)/$D18)*J$7 -> 6589.2221 | K15: =(($B15)/$D18)*K$7 -> 7801.9803 | L15: =(($B15)/$D18)*L$7 -> 9105.7774 | ... AB15: =(($B15)/$D18)*AB$7 -> 6927.5829 | AC15: =+SUM(E15:AB15)*D15 -> 4285714.3 | AF15: ORD | AG15: 2
C16: SAB | D16: =VLOOKUP(A15&C16,calendario!I:L,4,0) -> 4 | E16: =(($B15)/$D18)*E$7 -> 6470.4053 | F16: =(($B15)/$D18)*F$7 -> 6345.2771 | G16: =(($B15)/$D18)*G$7 -> 6178.4616 | H16: =(($B15)/$D18)*H$7 -> 6102.5775 | I16: =(($B15)/$D18)*I$7 -> 6120.7118 | J16: =(($B15)/$D18)*J$7 -> 6589.2221 | K16: =(($B15)/$D18)*K$7 -> 7801.9803 | L16: =(($B15)/$D18)*L$7 -> 9105.7774 | ... AB16: =(($B15)/$D18)*AB$7 -> 6927.5829 | AC16: =+SUM(E16:AB16)*D16 -> 857142.86 | AF16: SÁB | AG16: 2
C17: DOM | D17: =VLOOKUP(A15&C17,calendario!I:L,4,0) -> 4 | E17: =(($B15)/$D18)*E$7 -> 6470.4053 | F17: =(($B15)/$D18)*F$7 -> 6345.2771 | G17: =(($B15)/$D18)*G$7 -> 6178.4616 | H17: =(($B15)/$D18)*H$7 -> 6102.5775 | I17: =(($B15)/$D18)*I$7 -> 6120.7118 | J17: =(($B15)/$D18)*J$7 -> 6589.2221 | K17: =(($B15)/$D18)*K$7 -> 7801.9803 | L17: =(($B15)/$D18)*L$7 -> 9105.7774 | ... AB17: =(($B15)/$D18)*AB$7 -> 6927.5829 | AC17: =+SUM(E17:AB17)*D17 -> 857142.86 | AF17: FES | AG17: 2
C18: TOTAL | D18: =SUM(D15:D17) -> 28 | AC18: =+SUM(AC15:AC17) -> 6000000
A19: =3&"-"&$D$6 -> 3-2026 | B19: ='AÑO 2026'!C18 -> 6000000 | C19: L-V | D19: =VLOOKUP(A19&C19,calendario!I:L,4,0) -> 22 | E19: =(($B19)/$D22)*E$7 -> 5844.237 | F19: =(($B19)/$D22)*F$7 -> 5731.218 | G19: =(($B19)/$D22)*G$7 -> 5580.546 | H19: =(($B19)/$D22)*H$7 -> 5512.0055 | I19: =(($B19)/$D22)*I$7 -> 5528.3849 | J19: =(($B19)/$D22)*J$7 -> 5951.5554 | K19: =(($B19)/$D22)*K$7 -> 7046.9499 | L19: =(($B19)/$D22)*L$7 -> 8224.5732 | ... AB19: =(($B19)/$D22)*AB$7 -> 6257.1717 | AC19: =+SUM(E19:AB19)*D19 -> 4258064.5 | AF19: ORD | AG19: 3
C20: SAB | D20: =VLOOKUP(A19&C20,calendario!I:L,4,0) -> 4 | E20: =(($B19)/$D22)*E$7 -> 5844.237 | F20: =(($B19)/$D22)*F$7 -> 5731.218 | G20: =(($B19)/$D22)*G$7 -> 5580.546 | H20: =(($B19)/$D22)*H$7 -> 5512.0055 | I20: =(($B19)/$D22)*I$7 -> 5528.3849 | J20: =(($B19)/$D22)*J$7 -> 5951.5554 | K20: =(($B19)/$D22)*K$7 -> 7046.9499 | L20: =(($B19)/$D22)*L$7 -> 8224.5732 | ... AB20: =(($B19)/$D22)*AB$7 -> 6257.1717 | AC20: =+SUM(E20:AB20)*D20 -> 774193.55 | AF20: SÁB | AG20: 3
C21: DOM | D21: =VLOOKUP(A19&C21,calendario!I:L,4,0) -> 5 | E21: =(($B19)/$D22)*E$7 -> 5844.237 | F21: =(($B19)/$D22)*F$7 -> 5731.218 | G21: =(($B19)/$D22)*G$7 -> 5580.546 | H21: =(($B19)/$D22)*H$7 -> 5512.0055 | I21: =(($B19)/$D22)*I$7 -> 5528.3849 | J21: =(($B19)/$D22)*J$7 -> 5951.5554 | K21: =(($B19)/$D22)*K$7 -> 7046.9499 | L21: =(($B19)/$D22)*L$7 -> 8224.5732 | ... AB21: =(($B19)/$D22)*AB$7 -> 6257.1717 | AC21: =+SUM(E21:AB21)*D21 -> 967741.94 | AF21: FES | AG21: 3
C22: TOTAL | D22: =SUM(D19:D21) -> 31 | AC22: =+SUM(AC19:AC21) -> 6000000
A23: =4&"-"&$D$6 -> 4-2026 | B23: ='AÑO 2026'!C19 -> 6000000 | C23: L-V | D23: =VLOOKUP(A23&C23,calendario!I:L,4,0) -> 22 | E23: =(($B23)/$D26)*E$7 -> 6039.0449 | F23: =(($B23)/$D26)*F$7 -> 5922.2586 | G23: =(($B23)/$D26)*G$7 -> 5766.5642 | H23: =(($B23)/$D26)*H$7 -> 5695.739 | I23: =(($B23)/$D26)*I$7 -> 5712.6644 | J23: =(($B23)/$D26)*J$7 -> 6149.9406 | K23: =(($B23)/$D26)*K$7 -> 7281.8483 | L23: =(($B23)/$D26)*L$7 -> 8498.7256 | ... AB23: =(($B23)/$D26)*AB$7 -> 6465.7441 | AC23: =+SUM(E23:AB23)*D23 -> 4400000 | AF23: ORD | AG23: 4
C24: SAB | D24: =VLOOKUP(A23&C24,calendario!I:L,4,0) -> 4 | E24: =(($B23)/$D26)*E$7 -> 6039.0449 | F24: =(($B23)/$D26)*F$7 -> 5922.2586 | G24: =(($B23)/$D26)*G$7 -> 5766.5642 | H24: =(($B23)/$D26)*H$7 -> 5695.739 | I24: =(($B23)/$D26)*I$7 -> 5712.6644 | J24: =(($B23)/$D26)*J$7 -> 6149.9406 | K24: =(($B23)/$D26)*K$7 -> 7281.8483 | L24: =(($B23)/$D26)*L$7 -> 8498.7256 | ... AB24: =(($B23)/$D26)*AB$7 -> 6465.7441 | AC24: =+SUM(E24:AB24)*D24 -> 800000 | AF24: SÁB | AG24: 4
C25: DOM | D25: =VLOOKUP(A23&C25,calendario!I:L,4,0) -> 4 | E25: =(($B23)/$D26)*E$7 -> 6039.0449 | F25: =(($B23)/$D26)*F$7 -> 5922.2586 | G25: =(($B23)/$D26)*G$7 -> 5766.5642 | H25: =(($B23)/$D26)*H$7 -> 5695.739 | I25: =(($B23)/$D26)*I$7 -> 5712.6644 | J25: =(($B23)/$D26)*J$7 -> 6149.9406 | K25: =(($B23)/$D26)*K$7 -> 7281.8483 | L25: =(($B23)/$D26)*L$7 -> 8498.7256 | ... AB25: =(($B23)/$D26)*AB$7 -> 6465.7441 | AC25: =+SUM(E25:AB25)*D25 -> 800000 | AF25: FES | AG25: 4
C26: TOTAL | D26: =SUM(D23:D25) -> 30 | AC26: =+SUM(AC23:AC25) -> 6000000
A27: =5&"-"&$D$6 -> 5-2026 | B27: ='AÑO 2026'!C20 -> 6000000 | C27: L-V | D27: =VLOOKUP(A27&C27,calendario!I:L,4,0) -> 21 | E27: =(($B27)/$D30)*E$7 -> 5844.237 | F27: =(($B27)/$D30)*F$7 -> 5731.218 | G27: =(($B27)/$D30)*G$7 -> 5580.546 | H27: =(($B27)/$D30)*H$7 -> 5512.0055 | I27: =(($B27)/$D30)*I$7 -> 5528.3849 | J27: =(($B27)/$D30)*J$7 -> 5951.5554 | K27: =(($B27)/$D30)*K$7 -> 7046.9499 | L27: =(($B27)/$D30)*L$7 -> 8224.5732 | ... AB27: =(($B27)/$D30)*AB$7 -> 6257.1717 | AC27: =+SUM(E27:AB27)*D27 -> 4064516.1 | AF27: ORD | AG27: 5
C28: SAB | D28: =VLOOKUP(A27&C28,calendario!I:L,4,0) -> 5 | E28: =(($B27)/$D30)*E$7 -> 5844.237 | F28: =(($B27)/$D30)*F$7 -> 5731.218 | G28: =(($B27)/$D30)*G$7 -> 5580.546 | H28: =(($B27)/$D30)*H$7 -> 5512.0055 | I28: =(($B27)/$D30)*I$7 -> 5528.3849 | J28: =(($B27)/$D30)*J$7 -> 5951.5554 | K28: =(($B27)/$D30)*K$7 -> 7046.9499 | L28: =(($B27)/$D30)*L$7 -> 8224.5732 | ... AB28: =(($B27)/$D30)*AB$7 -> 6257.1717 | AC28: =+SUM(E28:AB28)*D28 -> 967741.94 | AF28: SÁB | AG28: 5
C29: DOM | D29: =VLOOKUP(A27&C29,calendario!I:L,4,0) -> 5 | E29: =(($B27)/$D30)*E$7 -> 5844.237 | F29: =(($B27)/$D30)*F$7 -> 5731.218 | G29: =(($B27)/$D30)*G$7 -> 5580.546 | H29: =(($B27)/$D30)*H$7 -> 5512.0055 | I29: =(($B27)/$D30)*I$7 -> 5528.3849 | J29: =(($B27)/$D30)*J$7 -> 5951.5554 | K29: =(($B27)/$D30)*K$7 -> 7046.9499 | L29: =(($B27)/$D30)*L$7 -> 8224.5732 | ... AB29: =(($B27)/$D30)*AB$7 -> 6257.1717 | AC29: =+SUM(E29:AB29)*D29 -> 967741.94 | AF29: FES | AG29: 5
C30: TOTAL | D30: =SUM(D27:D29) -> 31 | AC30: =+SUM(AC27:AC29) -> 6000000
A31: =6&"-"&$D$6 -> 6-2026 | B31: ='AÑO 2026'!C21 -> 6000000 | C31: L-V | D31: =VLOOKUP(A31&C31,calendario!I:L,4,0) -> 22 | E31: =(($B31)/$D34)*E$7 -> 6039.0449 | F31: =(($B31)/$D34)*F$7 -> 5922.2586 | G31: =(($B31)/$D34)*G$7 -> 5766.5642 | H31: =(($B31)/$D34)*H$7 -> 5695.739 | I31: =(($B31)/$D34)*I$7 -> 5712.6644 | J31: =(($B31)/$D34)*J$7 -> 6149.9406 | K31: =(($B31)/$D34)*K$7 -> 7281.8483 | L31: =(($B31)/$D34)*L$7 -> 8498.7256 | ... AB31: =(($B31)/$D34)*AB$7 -> 6465.7441 | AC31: =+SUM(E31:AB31)*D31 -> 4400000 | AF31: ORD | AG31: 6
C32: SAB | D32: =VLOOKUP(A31&C32,calendario!I:L,4,0) -> 4 | E32: =(($B31)/$D34)*E$7 -> 6039.0449 | F32: =(($B31)/$D34)*F$7 -> 5922.2586 | G32: =(($B31)/$D34)*G$7 -> 5766.5642 | H32: =(($B31)/$D34)*H$7 -> 5695.739 | I32: =(($B31)/$D34)*I$7 -> 5712.6644 | J32: =(($B31)/$D34)*J$7 -> 6149.9406 | K32: =(($B31)/$D34)*K$7 -> 7281.8483 | L32: =(($B31)/$D34)*L$7 -> 8498.7256 | ... AB32: =(($B31)/$D34)*AB$7 -> 6465.7441 | AC32: =+SUM(E32:AB32)*D32 -> 800000 | AF32: SÁB | AG32: 6
C33: DOM | D33: =VLOOKUP(A31&C33,calendario!I:L,4,0) -> 4 | E33: =(($B31)/$D34)*E$7 -> 6039.0449 | F33: =(($B31)/$D34)*F$7 -> 5922.2586 | G33: =(($B31)/$D34)*G$7 -> 5766.5642 | H33: =(($B31)/$D34)*H$7 -> 5695.739 | I33: =(($B31)/$D34)*I$7 -> 5712.6644 | J33: =(($B31)/$D34)*J$7 -> 6149.9406 | K33: =(($B31)/$D34)*K$7 -> 7281.8483 | L33: =(($B31)/$D34)*L$7 -> 8498.7256 | ... AB33: =(($B31)/$D34)*AB$7 -> 6465.7441 | AC33: =+SUM(E33:AB33)*D33 -> 800000 | AF33: FES | AG33: 6
C34: TOTAL | D34: =SUM(D31:D33) -> 30 | AC34: =+SUM(AC31:AC33) -> 6000000
A35: =7&"-"&$D$6 -> 7-2026 | B35: ='AÑO 2026'!C22 -> 6000000 | C35: L-V | D35: =VLOOKUP(A35&C35,calendario!I:L,4,0) -> 23 | E35: =(($B35)/$D38)*E$7 -> 5844.237 | F35: =(($B35)/$D38)*F$7 -> 5731.218 | G35: =(($B35)/$D38)*G$7 -> 5580.546 | H35: =(($B35)/$D38)*H$7 -> 5512.0055 | I35: =(($B35)/$D38)*I$7 -> 5528.3849 | J35: =(($B35)/$D38)*J$7 -> 5951.5554 | K35: =(($B35)/$D38)*K$7 -> 7046.9499 | L35: =(($B35)/$D38)*L$7 -> 8224.5732 | ... AB35: =(($B35)/$D38)*AB$7 -> 6257.1717 | AC35: =+SUM(E35:AB35)*D35 -> 4451612.9 | AF35: ORD | AG35: 7
C36: SAB | D36: =VLOOKUP(A35&C36,calendario!I:L,4,0) -> 4 | E36: =(($B35)/$D38)*E$7 -> 5844.237 | F36: =(($B35)/$D38)*F$7 -> 5731.218 | G36: =(($B35)/$D38)*G$7 -> 5580.546 | H36: =(($B35)/$D38)*H$7 -> 5512.0055 | I36: =(($B35)/$D38)*I$7 -> 5528.3849 | J36: =(($B35)/$D38)*J$7 -> 5951.5554 | K36: =(($B35)/$D38)*K$7 -> 7046.9499 | L36: =(($B35)/$D38)*L$7 -> 8224.5732 | ... AB36: =(($B35)/$D38)*AB$7 -> 6257.1717 | AC36: =+SUM(E36:AB36)*D36 -> 774193.55 | AF36: SÁB | AG36: 7
C37: DOM | D37: =VLOOKUP(A35&C37,calendario!I:L,4,0) -> 4 | E37: =(($B35)/$D38)*E$7 -> 5844.237 | F37: =(($B35)/$D38)*F$7 -> 5731.218 | G37: =(($B35)/$D38)*G$7 -> 5580.546 | H37: =(($B35)/$D38)*H$7 -> 5512.0055 | I37: =(($B35)/$D38)*I$7 -> 5528.3849 | J37: =(($B35)/$D38)*J$7 -> 5951.5554 | K37: =(($B35)/$D38)*K$7 -> 7046.9499 | L37: =(($B35)/$D38)*L$7 -> 8224.5732 | ... AB37: =(($B35)/$D38)*AB$7 -> 6257.1717 | AC37: =+SUM(E37:AB37)*D37 -> 774193.55 | AF37: FES | AG37: 7
C38: TOTAL | D38: =SUM(D35:D37) -> 31 | AC38: =+SUM(AC35:AC37) -> 6000000
A39: =8&"-"&$D$6 -> 8-2026 | B39: ='AÑO 2026'!C23 -> 6000000 | C39: L-V | D39: =VLOOKUP(A39&C39,calendario!I:L,4,0) -> 21 | E39: =(($B39)/$D42)*E$7 -> 5844.237 | F39: =(($B39)/$D42)*F$7 -> 5731.218 | G39: =(($B39)/$D42)*G$7 -> 5580.546 | H39: =(($B39)/$D42)*H$7 -> 5512.0055 | I39: =(($B39)/$D42)*I$7 -> 5528.3849 | J39: =(($B39)/$D42)*J$7 -> 5951.5554 | K39: =(($B39)/$D42)*K$7 -> 7046.9499 | L39: =(($B39)/$D42)*L$7 -> 8224.5732 | ... AB39: =(($B39)/$D42)*AB$7 -> 6257.1717 | AC39: =+SUM(E39:AB39)*D39 -> 4064516.1 | AF39: ORD | AG39: 8
C40: SAB | D40: =VLOOKUP(A39&C40,calendario!I:L,4,0) -> 5 | E40: =(($B39)/$D42)*E$7 -> 5844.237 | F40: =(($B39)/$D42)*F$7 -> 5731.218 | G40: =(($B39)/$D42)*G$7 -> 5580.546 | H40: =(($B39)/$D42)*H$7 -> 5512.0055 | I40: =(($B39)/$D42)*I$7 -> 5528.3849 | J40: =(($B39)/$D42)*J$7 -> 5951.5554 | K40: =(($B39)/$D42)*K$7 -> 7046.9499 | L40: =(($B39)/$D42)*L$7 -> 8224.5732 | ... AB40: =(($B39)/$D42)*AB$7 -> 6257.1717 | AC40: =+SUM(E40:AB40)*D40 -> 967741.94 | AF40: SÁB | AG40: 8
...

Sheet AÑO 2027
A1: ANEXO 3. CUADRO DE CANTIDADES DE ENERGÍA Y PRECIO
B2: ="El precio del suministro para cada período (mes) se debe expresar en pesos por Kilovatio-hora (COP/KWh) con dos cifras decimales, en forma de precio monomio fijo, en pesos constantes de "&C11 -> El precio del suministro para cada período (mes) se debe expresar en pesos por Kilovatio-hora (COP/KWh) con dos cifras decimales, en forma de precio monomio fijo, en pesos constantes de noviembre de 2024
B5: OFERTA MERCANTIL N°:
B6: INVITACIÓN: | C6: ='Formato Resumen 23'!C6 -> CP-EXEC2025-001
B7: OFERENTE:
B8: OFERTA: | C8: =C6&" -PROD01" -> CP-EXEC2025-001 -PROD01
B9: FNCER (SI/NO):
B10: CANTIDAD EN: | C10: KWh
B11: PRECIOS $/kWh de: | C11: ='P1_AÑO 2024'!C11 -> noviembre de 2024
B12: MODALIDAD: | C12: PC (1)
B14: AÑO 2027 | C14: ENERGÍA SOLICITADA (KWh) | D14: NIVEL DE COBERTURA ESPERADO (%) | E14: ENERGÍA OFRECIDA (KWh) (2) (3) | F14: PRECIO OFERTADO (COP/KWh) (4)
B16: ENE | C16: 6000000 | D16: 1 | E16: 0
B17: FEB | C17: 6000000 | D17: 1 | E17: 0
B18: MAR | C18: 6000000 | D18: 1 | E18: 0
B19: ABR | C19: 6000000 | D19: 1 | E19: 0
B20: MAY | C20: 6000000 | D20: 1 | E20: 0
B21: JUN | C21: 6000000 | D21: 1 | E21: 0
B22: JUL | C22: 6000000 | D22: 1 | E22: 0
B23: AGO | C23: 6000000 | D23: 1 | E23: 0
B24: SEP | C24: 6000000 | D24: 1 | E24: 0
B25: OCT | C25: 6000000 | D25: 1 | E25: 0
B26: NOV | C26: 6000000 | D26: 1 | E26: 0
B27: DIC | C27: 6000000 | D27: 1 | E27: 2000000
B28: TOTAL | C28: =SUM(C16:C27) -> 72000000 | E28: 2000000
B30: NOTAS:
B31: =IF('Formato Resumen 23'!B31=0,"",'Formato Resumen 23'!B31) -> _PC: Pague lo contratado
B32: =IF('Formato Resumen 23'!B32=0,"",'Formato Resumen 23'!B32) -> _La energía ofrecida se despachará de acuerdo con las curvas descritas los terminos de referencia.
B33: =IF('Formato Resumen 23'!B33=0,"",'Formato Resumen 23'!B33) -> _Ingresar con dos cifras decimales la energía ofrecida hasta las cantidades solicitadas.
B34: =IF('Formato Resumen 23'!B34=0,"",'Formato Resumen 23'!B34) -> _Ingresar un precio monomio fijo en COP/KWh con dos cifras decimales.
B35: =IF('Formato Resumen 23'!B35=0,"",'Formato Resumen 23'!B35) -> _No serán tenidas en cuenta ofertas con condiciones y/o modificaciones adicionales a los Pliegos definitivos.
B36: =IF('Formato Resumen 23'!B36=0,"",'Formato Resumen 23'!B36)
B37: =IF('Formato Resumen 23'!B37=0,"",'Formato Resumen 23'!B37)
B38: =IF('Formato Resumen 23'!B38=0,"",'Formato Resumen 23'!B38)
B39: =IF('Formato Resumen 23'!B39=0,"",'Formato Resumen 23'!B39)
B40: =IF('Formato Resumen 23'!B40=0,"",'Formato Resumen 23'!B40)
B41: =IF('Formato Resumen 23'!B41=0,"",'Formato Resumen 23'!B41)
B48: OFERENTE E.S.P.

Sheet DETALLE AÑO 2027
A1: ANEXO 4. CANTIDADES HORARIAS SOLICITADAS
A2: OFERTA MERCANTIL N°:
A3: INVITACIÓN: | D3: ='Formato Resumen 23'!C6 -> CP-EXEC2025-001
A4: OFERENTE:
A5: OFERTA: | D5: ='AÑO 2027'!C8 -> CP-EXEC2025-001 -PROD01
A6: AÑO: | D6: 2027 | E6: 0.031692962 | F6: 0.030769317 | G6: 0.029908399 | H6: 0.029629673 | I6: 0.030054654 | J6: 0.031743509 | K6: 0.037034552 | L6: 0.043161528 | M6: 0.046031335 | N6: 0.047955986 | O6: 0.04960977 | P6: 0.05112634 | Q6: 0.050804516 | R6: 0.05066491 | S6: 0.050973242 | T6: 0.050831094 | U6: 0.048893801 | V6: 0.046964572 | W6: 0.046697005 | X6: 0.046103444 | Y6: 0.043155278 | Z6: 0.038573955 | AA6: 0.03473795 | AB6: 0.032882208
A7: CANTIDAD EN: | D7: KWh* | E7: ='DETALLE AÑO 2026'!E7 -> 0.030195225 | F7: ='DETALLE AÑO 2026'!F7 -> 0.029611293 | G7: ='DETALLE AÑO 2026'!G7 -> 0.028832821 | H7: ='DETALLE AÑO 2026'!H7 -> 0.028478695 | I7: ='DETALLE AÑO 2026'!I7 -> 0.028563322 | J7: ='DETALLE AÑO 2026'!J7 -> 0.030749703 | K7: ='DETALLE AÑO 2026'!K7 -> 0.036409241 | L7: ='DETALLE AÑO 2026'!L7 -> 0.042493628 | ... AB7: ='DETALLE AÑO 2026'!AB7 -> 0.03232872 | AC7: L-V
A8: MODALIDAD: | D8: ='P1_AÑO 2025'!C12 -> PC (1) | AC8: SAB
A9: CURVA HORARIA: | AC9: DOM
A10: ="AÑO: "&D6 -> AÑO: 2027 | B10: Cantidad Ofrecida | C10: Tipo de día | D10: N° días mes | E10: H1 | F10: H2 | G10: H3 | H10: H4 | I10: H5 | J10: H6 | K10: H7 | L10: H8 | M10: H9 | N10: H10 | O10: H11 | P10: H12 | Q10: H13 | R10: H14 | S10: H15 | T10: H16 | U10: H17 | V10: H18 | W10: H19 | X10: H20 | Y10: H21 | Z10: H22 | AA10: H23 | AB10: H24 | AC10: TOTAL
A11: =1&"-"&$D$6 -> 1-2027 | B11: ='AÑO 2027'!C16 -> 6000000 | C11: L-V | D11: =VLOOKUP(A11&C11,calendario!I:L,4,0) -> 21 | E11: =(($B11)/$D14)*E$7 -> 5844.237 | F11: =(($B11)/$D14)*F$7 -> 5731.218 | G11: =(($B11)/$D14)*G$7 -> 5580.546 | H11: =(($B11)/$D14)*H$7 -> 5512.0055 | I11: =(($B11)/$D14)*I$7 -> 5528.3849 | J11: =(($B11)/$D14)*J$7 -> 5951.5554 | K11: =(($B11)/$D14)*K$7 -> 7046.9499 | L11: =(($B11)/$D14)*L$7 -> 8224.5732 | ... AB11: =(($B11)/$D14)*AB$7 -> 6257.1717 | AC11: =+SUM(E11:AB11)*D11 -> 4064516.1 | AF11: ORD | AG11: 1
C12: SAB | D12: =VLOOKUP(A11&C12,calendario!I:L,4,0) -> 5 | E12: =(($B11)/$D14)*E$7 -> 5844.237 | F12: =(($B11)/$D14)*F$7 -> 5731.218 | G12: =(($B11)/$D14)*G$7 -> 5580.546 | H12: =(($B11)/$D14)*H$7 -> 5512.0055 | I12: =(($B11)/$D14)*I$7 -> 5528.3849 | J12: =(($B11)/$D14)*J$7 -> 5951.5554 | K12: =(($B11)/$D14)*K$7 -> 7046.9499 | L12: =(($B11)/$D14)*L$7 -> 8224.5732 | ... AB12: =(($B11)/$D14)*AB$7 -> 6257.1717 | AC12: =+SUM(E12:AB12)*D12 -> 967741.94 | AF12: SÁB | AG12: 1
C13: DOM | D13: =VLOOKUP(A11&C13,calendario!I:L,4,0) -> 5 | E13: =(($B11)/$D14)*E$7 -> 5844.237 | F13: =(($B11)/$D14)*F$7 -> 5731.218 | G13: =(($B11)/$D14)*G$7 -> 5580.546 | H13: =(($B11)/$D14)*H$7 -> 5512.0055 | I13: =(($B11)/$D14)*I$7 -> 5528.3849 | J13: =(($B11)/$D14)*J$7 -> 5951.5554 | K13: =(($B11)/$D14)*K$7 -> 7046.9499 | L13: =(($B11)/$D14)*L$7 -> 8224.5732 | ... AB13: =(($B11)/$D14)*AB$7 -> 6257.1717 | AC13: =+SUM(E13:AB13)*D13 -> 967741.94 | AF13: FES | AG13: 1
C14: TOTAL | D14: =SUM(D11:D13) -> 31 | AC14: =+SUM(AC11:AC13) -> 6000000
A15: =2&"-"&$D$6 -> 2-2027 | B15: ='AÑO 2027'!C17 -> 6000000 | C15: L-V | D15: =VLOOKUP(A15&C15,calendario!I:L,4,0) -> 20 | E15: =(($B15)/$D18)*E$7 -> 6470.4053 | F15: =(($B15)/$D18)*F$7 -> 6345.2771 | G15: =(($B15)/$D18)*G$7 -> 6178.4616 | H15: =(($B15)/$D18)*H$7 -> 6102.5775 | I15: =(($B15)/$D18)*I$7 -> 6120.7118 | J15: =(($B15)/$D18)*J$7 -> 6589.2221 | K15: =(($B15)/$D18)*K$7 -> 7801.9803 | L15: =(($B15)/$D18)*L$7 -> 9105.7774 | ... AB15: =(($B15)/$D18)*AB$7 -> 6927.5829 | AC15: =+SUM(E15:AB15)*D15 -> 4285714.3 | AF15: ORD | AG15: 2
C16: SAB | D16: =VLOOKUP(A15&C16,calendario!I:L,4,0) -> 4 | E16: =(($B15)/$D18)*E$7 -> 6470.4053 | F16: =(($B15)/$D18)*F$7 -> 6345.2771 | G16: =(($B15)/$D18)*G$7 -> 6178.4616 | H16: =(($B15)/$D18)*H$7 -> 6102.5775 | I16: =(($B15)/$D18)*I$7 -> 6120.7118 | J16: =(($B15)/$D18)*J$7 -> 6589.2221 | K16: =(($B15)/$D18)*K$7 -> 7801.9803 | L16: =(($B15)/$D18)*L$7 -> 9105.7774 | ... AB16: =(($B15)/$D18)*AB$7 -> 6927.5829 | AC16: =+SUM(E16:AB16)*D16 -> 857142.86 | AF16: SÁB | AG16: 2
C17: DOM | D17: =VLOOKUP(A15&C17,calendario!I:L,4,0) -> 4 | E17: =(($B15)/$D18)*E$7 -> 6470.4053 | F17: =(($B15)/$D18)*F$7 -> 6345.2771 | G17: =(($B15)/$D18)*G$7 -> 6178.4616 | H17: =(($B15)/$D18)*H$7 -> 6102.5775 | I17: =(($B15)/$D18)*I$7 -> 6120.7118 | J17: =(($B15)/$D18)*J$7 -> 6589.2221 | K17: =(($B15)/$D18)*K$7 -> 7801.9803 | L17: =(($B15)/$D18)*L$7 -> 9105.7774 | ... AB17: =(($B15)/$D18)*AB$7 -> 6927.5829 | AC17: =+SUM(E17:AB17)*D17 -> 857142.86 | AF17: FES | AG17: 2
C18: TOTAL | D18: =SUM(D15:D17) -> 28 | AC18: =+SUM(AC15:AC17) -> 6000000
A19: =3&"-"&$D$6 -> 3-2027 | B19: ='AÑO 2027'!C18 -> 6000000 | C19: L-V | D19: =VLOOKUP(A19&C19,calendario!I:L,4,0) -> 23 | E19: =(($B19)/$D22)*E$7 -> 5844.237 | F19: =(($B19)/$D22)*F$7 -> 5731.218 | G19: =(($B19)/$D22)*G$7 -> 5580.546 | H19: =(($B19)/$D22)*H$7 -> 5512.0055 | I19: =(($B19)/$D22)*I$7 -> 5528.3849 | J19: =(($B19)/$D22)*J$7 -> 5951.5554 | K19: =(($B19)/$D22)*K$7 -> 7046.9499 | L19: =(($B19)/$D22)*L$7 -> 8224.5732 | ... AB19: =(($B19)/$D22)*AB$7 -> 6257.1717 | AC19: =+SUM(E19:AB19)*D19 -> 4451612.9 | AF19: ORD | AG19: 3
C20: SAB | D20: =VLOOKUP(A19&C20,calendario!I:L,4,0) -> 4 | E20: =(($B19)/$D22)*E$7 -> 5844.237 | F20: =(($B19)/$D22)*F$7 -> 5731.218 | G20: =(($B19)/$D22)*G$7 -> 5580.546 | H20: =(($B19)/$D22)*H$7 -> 5512.0055 | I20: =(($B19)/$D22)*I$7 -> 5528.3849 | J20: =(($B19)/$D22)*J$7 -> 5951.5554 | K20: =(($B19)/$D22)*K$7 -> 7046.9499 | L20: =(($B19)/$D22)*L$7 -> 8224.5732 | ... AB20: =(($B19)/$D22)*AB$7 -> 6257.1717 | AC20: =+SUM(E20:AB20)*D20 -> 774193.55 | AF20: SÁB | AG20: 3
C21: DOM | D21: =VLOOKUP(A19&C21,calendario!I:L,4,0) -> 4 | E21: =(($B19)/$D22)*E$7 -> 5844.237 | F21: =(($B19)/$D22)*F$7 -> 5731.218 | G21: =(($B19)/$D22)*G$7 -> 5580.546 | H21: =(($B19)/$D22)*H$7 -> 5512.0055 | I21: =(($B19)/$D22)*I$7 -> 5528.3849 | J21: =(($B19)/$D22)*J$7 -> 5951.5554 | K21: =(($B19)/$D22)*K$7 -> 7046.9499 | L21: =(($B19)/$D22)*L$7 -> 8224.5732 | ... AB21: =(($B19)/$D22)*AB$7 -> 6257.1717 | AC21: =+SUM(E21:AB21)*D21 -> 774193.55 | AF21: FES | AG21: 3
C22: TOTAL | D22: =SUM(D19:D21) -> 31 | AC22: =+SUM(AC19:AC21) -> 6000000
A23: =4&"-"&$D$6 -> 4-2027 | B23: ='AÑO 2027'!C19 -> 6000000 | C23: L-V | D23: =VLOOKUP(A23&C23,calendario!I:L,4,0) -> 22 | E23: =(($B23)/$D26)*E$7 -> 6039.0449 | F23: =(($B23)/$D26)*F$7 -> 5922.2586 | G23: =(($B23)/$D26)*G$7 -> 5766.5642 | H23: =(($B23)/$D26)*H$7 -> 5695.739 | I23: =(($B23)/$D26)*I$7 -> 5712.6644 | J23: =(($B23)/$D26)*J$7 -> 6149.9406 | K23: =(($B23)/$D26)*K$7 -> 7281.8483 | L23: =(($B23)/$D26)*L$7 -> 8498.7256 | ... AB23: =(($B23)/$D26)*AB$7 -> 6465.7441 | AC23: =+SUM(E23:AB23)*D23 -> 4400000 | AF23: ORD | AG23: 4
C24: SAB | D24: =VLOOKUP(A23&C24,calendario!I:L,4,0) -> 4 | E24: =(($B23)/$D26)*E$7 -> 6039.0449 | F24: =(($B23)/$D26)*F$7 -> 5922.2586 | G24: =(($B23)/$D26)*G$7 -> 5766.5642 | H24: =(($B23)/$D26)*H$7 -> 5695.739 | I24: =(($B23)/$D26)*I$7 -> 5712.6644 | J24: =(($B23)/$D26)*J$7 -> 6149.9406 | K24: =(($B23)/$D26)*K$7 -> 7281.8483 | L24: =(($B23)/$D26)*L$7 -> 8498.7256 | ... AB24: =(($B23)/$D26)*AB$7 -> 6465.7441 | AC24: =+SUM(E24:AB24)*D24 -> 800000 | AF24: SÁB | AG24: 4
C25: DOM | D25: =VLOOKUP(A23&C25,calendario!I:L,4,0) -> 4 | E25: =(($B23)/$D26)*E$7 -> 6039.0449 | F25: =(($B23)/$D26)*F$7 -> 5922.2586 | G25: =(($B23)/$D26)*G$7 -> 5766.5642 | H25: =(($B23)/$D26)*H$7 -> 5695.739 | I25: =(($B23)/$D26)*I$7 -> 5712.6644 | J25: =(($B23)/$D26)*J$7 -> 6149.9406 | K25: =(($B23)/$D26)*K$7 -> 7281.8483 | L25: =(($B23)/$D26)*L$7 -> 8498.7256 | ... AB25: =(($B23)/$D26)*AB$7 -> 6465.7441 | AC25: =+SUM(E25:AB25)*D25 -> 800000 | AF25: FES | AG25: 4
C26: TOTAL | D26: =SUM(D23:D25) -> 30 | AC26: =+SUM(AC23:AC25) -> 6000000
A27: =5&"-"&$D$6 -> 5-2027 | B27: ='AÑO 2027'!C20 -> 6000000 | C27: L-V | D27: =VLOOKUP(A27&C27,calendario!I:L,4,0) -> 21 | E27: =(($B27)/$D30)*E$7 -> 5844.237 | F27: =(($B27)/$D30)*F$7 -> 5731.218 | G27: =(($B27)/$D30)*G$7 -> 5580.546 | H27: =(($B27)/$D30)*H$7 -> 5512.0055 | I27: =(($B27)/$D30)*I$7 -> 5528.3849 | J27: =(($B27)/$D30)*J$7 -> 5951.5554 | K27: =(($B27)/$D30)*K$7 -> 7046.9499 | L27: =(($B27)/$D30)*L$7 -> 8224.5732 | ... AB27: =(($B27)/$D30)*AB$7 -> 6257.1717 | AC27: =+SUM(E27:AB27)*D27 -> 4064516.1 | AF27: ORD | AG27: 5
C28: SAB | D28: =VLOOKUP(A27&C28,calendario!I:L,4,0) -> 5 | E28: =(($B27)/$D30)*E$7 -> 5844.237 | F28: =(($B27)/$D30)*F$7 -> 5731.218 | G28: =(($B27)/$D30)*G$7 -> 5580.546 | H28: =(($B27)/$D30)*H$7 -> 5512.0055 | I28: =(($B27)/$D30)*I$7 -> 5528.3849 | J28: =(($B27)/$D30)*J$7 -> 5951.5554 | K28: =(($B27)/$D30)*K$7 -> 7046.9499 | L28: =(($B27)/$D30)*L$7 -> 8224.5732 | ... AB28: =(($B27)/$D30)*AB$7 -> 6257.1717 | AC28: =+SUM(E28:AB28)*D28 -> 967741.94 | AF28: SÁB | AG28: 5
C29: DOM | D29: =VLOOKUP(A27&C29,calendario!I:L,4,0) -> 5 | E29: =(($B27)/$D30)*E$7 -> 5844.237 | F29: =(($B27)/$D30)*F$7 -> 5731.218 | G29: =(($B27)/$D30)*G$7 -> 5580.546 | H29: =(($B27)/$D30)*H$7 -> 5512.0055 | I29: =(($B27)/$D30)*I$7 -> 5528.3849 | J29: =(($B27)/$D30)*J$7 -> 5951.5554 | K29: =(($B27)/$D30)*K$7 -> 7046.9499 | L29: =(($B27)/$D30)*L$7 -> 8224.5732 | ... AB29: =(($B27)/$D30)*AB$7 -> 6257.1717 | AC29: =+SUM(E29:AB29)*D29 -> 967741.94 | AF29: FES | AG29: 5
C30: TOTAL | D30: =SUM(D27:D29) -> 31 | AC30: =+SUM(AC27:AC29) -> 6000000
A31: =6&"-"&$D$6 -> 6-2027 | B31: ='AÑO 2027'!C21 -> 6000000 | C31: L-V | D31: =VLOOKUP(A31&C31,calendario!I:L,4,0) -> 22 | E31: =(($B31)/$D34)*E$7 -> 6039.0449 | F31: =(($B31)/$D34)*F$7 -> 5922.2586 | G31: =(($B31)/$D34)*G$7 -> 5766.5642 | H31: =(($B31)/$D34)*H$7 -> 5695.739 | I31: =(($B31)/$D34)*I$7 -> 5712.6644 | J31: =(($B31)/$D34)*J$7 -> 6149.9406 | K31: =(($B31)/$D34)*K$7 -> 7281.8483 | L31: =(($B31)/$D34)*L$7 -> 8498.7256 | ... AB31: =(($B31)/$D34)*AB$7 -> 6465.7441 | AC31: =+SUM(E31:AB31)*D31 -> 4400000 | AF31: ORD | AG31: 6
