Workbook

Sheet PRODUCTO 01
C1: CP-GNCC2025-004
C2: CP-GNCC2025-004-PROD01
C3: CANTIDAD EN: | D3: KWh
C4: MODALIDAD: | D4: PAGUE LO CONTRATADO
C5: OFERENTE:
C9: MES DE SUMINISTRO | D9: ENERGÍA SOLICITADA (KWh) | E9: % ENERGÍA OFRECIDA | F9: ENERGÍA OFRECIDA (KWh) | G9: PRECIO OFERTADO ($/KWh)
C10: 46054 | D10: =+_xlfn.XLOOKUP(_xlfn.CONCAT(C10,"TOTAL"),'Cantidades horarias PROD 01'!D:D,'Cantidades horarias PROD 01'!AG:AG) -> 4396573.2 | E10: 1 | F10: =ROUND(D10*$E10,2) -> 4396573.2
C11: 46082 | D11: =+_xlfn.XLOOKUP(_xlfn.CONCAT(C11,"TOTAL"),'Cantidades horarias PROD 01'!D:D,'Cantidades horarias PROD 01'!AG:AG) -> 9669031.7 | E11: 1 | F11: =ROUND(D11*$E11,2) -> 9669031.7
C12: 46113 | D12: =+_xlfn.XLOOKUP(_xlfn.CONCAT(C12,"TOTAL"),'Cantidades horarias PROD 01'!D:D,'Cantidades horarias PROD 01'!AG:AG) -> 10071257 | E12: 1 | F12: =ROUND(D12*$E12,2) -> 10071257
C13: 46143 | D13: =+_xlfn.XLOOKUP(_xlfn.CONCAT(C13,"TOTAL"),'Cantidades horarias PROD 01'!D:D,'Cantidades horarias PROD 01'!AG:AG) -> 9866307.1 | E13: 1 | F13: =ROUND(D13*$E13,2) -> 9866307.1
C14: 46174 | D14: =+_xlfn.XLOOKUP(_xlfn.CONCAT(C14,"TOTAL"),'Cantidades horarias PROD 01'!D:D,'Cantidades horarias PROD 01'!AG:AG) -> 12364564 | E14: 1 | F14: =ROUND(D14*$E14,2) -> 12364564
C15: 46204 | D15: =+_xlfn.XLOOKUP(_xlfn.CONCAT(C15,"TOTAL"),'Cantidades horarias PROD 01'!D:D,'Cantidades horarias PROD 01'!AG:AG) -> 12776719 | E15: 1 | F15: =ROUND(D15*$E15,2) -> 12776719
C16: 46235 | D16: =+_xlfn.XLOOKUP(_xlfn.CONCAT(C16,"TOTAL"),'Cantidades horarias PROD 01'!D:D,'Cantidades horarias PROD 01'!AG:AG) -> 12207909 | E16: 1 | F16: =ROUND(D16*$E16,2) -> 12207909
C17: 46266 | D17: =+_xlfn.XLOOKUP(_xlfn.CONCAT(C17,"TOTAL"),'Cantidades horarias PROD 01'!D:D,'Cantidades horarias PROD 01'!AG:AG) -> 11954829 | E17: 1 | F17: =ROUND(D17*$E17,2) -> 11954829
C18: 46296 | D18: =+_xlfn.XLOOKUP(_xlfn.CONCAT(C18,"TOTAL"),'Cantidades horarias PROD 01'!D:D,'Cantidades horarias PROD 01'!AG:AG) -> 13185122 | E18: 1 | F18: =ROUND(D18*$E18,2) -> 13185122
C19: 46327 | D19: =+_xlfn.XLOOKUP(_xlfn.CONCAT(C19,"TOTAL"),'Cantidades horarias PROD 01'!D:D,'Cantidades horarias PROD 01'!AG:AG) -> 11780439 | E19: 1 | F19: =ROUND(D19*$E19,2) -> 11780439
C20: 46357 | D20: =+_xlfn.XLOOKUP(_xlfn.CONCAT(C20,"TOTAL"),'Cantidades horarias PROD 01'!D:D,'Cantidades horarias PROD 01'!AG:AG) -> 13169894 | E20: 1 | F20: =ROUND(D20*$E20,2) -> 13169894
C21: 46388 | D21: =+_xlfn.XLOOKUP(_xlfn.CONCAT(C21,"TOTAL"),'Cantidades horarias PROD 01'!D:D,'Cantidades horarias PROD 01'!AG:AG) -> 14876875 | E21: 1 | F21: =ROUND(D21*$E21,2) -> 14876875
... C32: 46722 | D32: =+_xlfn.XLOOKUP(_xlfn.CONCAT(C32,"TOTAL"),'Cantidades horarias PROD 01'!D:D,'Cantidades horarias PROD 01'!AG:AG) -> 14420455 | E32: 1 | F32: =ROUND(D32*$E32,2) -> 14420455
C33: TOTAL | D33: =SUM(D10:D32) -> 2.9225497e+08 | E33: =IFERROR(F33/D33,0) -> 1 | F33: =SUM(F10:F32) -> 2.9225497e+08 | G33: =+(SUM(F10:F20)*G10+SUM(F21:F32)*G21)/F33 -> 0
C35: Nota
C36: 1. $/kWh expresados en pesos de octubre de 2025.
C37: 2. La energia ofertada se despachara conforme a las cantidades horarias de este anexo
C38: XXXXXXXXXXXXXXXXXXXXXXXX
C39: REPRESENTANTE LEGAL
C40: XXXXXXXXXXXXXXXXXX.SA.E.S.P
C46: XXXXXXXXXXXXXXXXXXXXXX S.A E.S.P
C48: Nota
C49: 1. $/kWh expresados en pesos de octubre 2025.
C50: 2. La energia ofertada se despachara conforme a las cantidades horarias de este anexo
C54: XXXXXXXXXXXXXXXXXXXXXXXX
C55: REPRESENTANTE LEGAL
C56: XXXXXXXXXXXXXXXXXXXXXX S.A E.S.P

Sheet Cantidades horarias PROD 01
E1: CUADRO DE CANTIDADES HORARIAS OFRECIDAS
E2: CANTIDADES DE ENERGIA (KWh) - PRODUCTO 1
E3: PAGUE LO CONTRATADO
E5: OFERENTE:
B8: MES | C8: AÑO | D8: LLAVE | F8: Cantidad Ofrecida | G8: Tipo de día | H8: N° días mes | I8: H1 | J8: H2 | K8: H3 | L8: H4 | M8: H5 | N8: H6 | O8: H7 | P8: H8 | Q8: H9 | R8: H10 | S8: H11 | T8: H12 | U8: H13 | V8: H14 | W8: H15 | X8: H16 | Y8: H17 | Z8: H18 | AA8: H19 | AB8: H20 | AC8: H21 | AD8: H22 | AE8: H23 | AF8: H24 | AG8: TOTAL
B9: =+MONTH(E9) -> 2 | C9: =+YEAR(E9) -> 2026 | D9: =+_xlfn.CONCAT(B9:C9,G9) -> 22026OR | E9: 46054 | F9: =+'PRODUCTO 01'!F10 -> 4396573.2 | G9: OR | H9: 10 | I9: 12212.703 | J9: 12212.703 | K9: 12212.703 | L9: 12212.703 | M9: 12212.703 | N9: 12212.703 | O9: 12212.703 | P9: 12212.703 | Q9: 12212.703 | R9: 12212.703 | S9: 12212.703 | T9: 12212.703 | U9: 12212.703 | V9: 12212.703 | W9: 12212.703 | X9: 12212.703 | Y9: 12212.703 | Z9: 12212.703 | AA9: 12212.703 | AB9: 12212.703 | AC9: 12212.703 | AD9: 12212.703 | AE9: 12212.703 | AF9: 12212.703 | AG9: =+SUM(I9:AF9)*H9 -> 2931048.8
B10: =+B9 -> 2 | C10: =+C9 -> 2026 | D10: =+_xlfn.CONCAT(B10:C10,G10) -> 22026SA | G10: SA | H10: 3 | I10: 12212.703 | J10: 12212.703 | K10: 12212.703 | L10: 12212.703 | M10: 12212.703 | N10: 12212.703 | O10: 12212.703 | P10: 12212.703 | Q10: 12212.703 | R10: 12212.703 | S10: 12212.703 | T10: 12212.703 | U10: 12212.703 | V10: 12212.703 | W10: 12212.703 | X10: 12212.703 | Y10: 12212.703 | Z10: 12212.703 | AA10: 12212.703 | AB10: 12212.703 | AC10: 12212.703 | AD10: 12212.703 | AE10: 12212.703 | AF10: 12212.703 | AG10: =+SUM(I10:AF10)*H10 -> 879314.64
B11: =+B10 -> 2 | C11: =+C10 -> 2026 | D11: =+_xlfn.CONCAT(B11:C11,G11) -> 22026DO | G11: DO | H11: 2 | I11: 12212.703 | J11: 12212.703 | K11: 12212.703 | L11: 12212.703 | M11: 12212.703 | N11: 12212.703 | O11: 12212.703 | P11: 12212.703 | Q11: 12212.703 | R11: 12212.703 | S11: 12212.703 | T11: 12212.703 | U11: 12212.703 | V11: 12212.703 | W11: 12212.703 | X11: 12212.703 | Y11: 12212.703 | Z11: 12212.703 | AA11: 12212.703 | AB11: 12212.703 | AC11: 12212.703 | AD11: 12212.703 | AE11: 12212.703 | AF11: 12212.703 | AG11: =+SUM(I11:AF11)*H11 -> 586209.76
B12: =+B11 -> 2 | C12: =+C11 -> 2026 | D12: =+_xlfn.CONCAT(B12:C12,G12) -> 22026FE | G12: FE | H12: 0 | I12: 0 | J12: 0 | K12: 0 | L12: 0 | M12: 0 | N12: 0 | O12: 0 | P12: 0 | Q12: 0 | R12: 0 | S12: 0 | T12: 0 | U12: 0 | V12: 0 | W12: 0 | X12: 0 | Y12: 0 | Z12: 0 | AA12: 0 | AB12: 0 | AC12: 0 | AD12: 0 | AE12: 0 | AF12: 0 | AG12: =+SUM(I12:AF12)*H12 -> 0
B13: =+B12 -> 2 | C13: =+C12 -> 2026 | D13: =+_xlfn.CONCAT(E9,G13) -> 46054TOTAL | G13: TOTAL | H13: =+SUM(H9:H12) -> 15 | I13: =+SUMPRODUCT(I9:I12,$H9:$H12) -> 183190.55 | J13: =+SUMPRODUCT(J9:J12,$H9:$H12) -> 183190.55 | K13: =+SUMPRODUCT(K9:K12,$H9:$H12) -> 183190.55 | L13: =+SUMPRODUCT(L9:L12,$H9:$H12) -> 183190.55 | M13: =+SUMPRODUCT(M9:M12,$H9:$H12) -> 183190.55 | N13: =+SUMPRODUCT(N9:N12,$H9:$H12) -> 183190.55 | O13: =+SUMPRODUCT(O9:O12,$H9:$H12) -> 183190.55 | P13: =+SUMPRODUCT(P9:P12,$H9:$H12) -> 183190.55 | ... AF13: =+SUMPRODUCT(AF9:AF12,$H9:$H12) -> 183190.55 | AG13: =SUM(I13:AF13) -> 4396573.2
B14: =+MONTH(E14) -> 3 | C14: =+YEAR(E14) -> 2026 | D14: =+_xlfn.CONCAT(B14:C14,G14) -> 32026OR | E14: 46082 | F14: =+'PRODUCTO 01'!F11 -> 9669031.7 | G14: OR | H14: 21 | I14: 13236.775 | J14: 13195.262 | K14: 13054.01 | L14: 12784.7 | M14: 13117.747 | N14: 13236.775 | O14: 12726.206 | P14: 12726.206 | Q14: 12726.206 | R14: 12726.206 | S14: 12726.206 | T14: 12726.206 | U14: 12726.206 | V14: 12726.206 | W14: 12726.206 | X14: 12726.206 | Y14: 12726.206 | Z14: 12726.206 | AA14: 12726.206 | AB14: 13214.199 | AC14: 13214.199 | AD14: 13214.199 | AE14: 13214.199 | AF14: 13214.199 | AG14: =+SUM(I14:AF14)*H14 -> 6512875.8
B15: =+MONTH(E15) -> 3 | C15: =+YEAR(E15) -> 2026 | D15: =+_xlfn.CONCAT(B15:C15,G15) -> 32026SA | E15: 46082 | G15: SA | H15: 4 | I15: 13185.98 | J15: 13185.98 | K15: 13185.98 | L15: 13185.98 | M15: 13185.98 | N15: 13185.98 | O15: 12673.587 | P15: 12673.587 | Q15: 12673.587 | R15: 12673.587 | S15: 12673.587 | T15: 12673.587 | U15: 12792.108 | V15: 12264.917 | W15: 12171.594 | X15: 12792.108 | Y15: 12792.108 | Z15: 12792.108 | AA15: 12792.108 | AB15: 13304.501 | AC15: 13304.501 | AD15: 13304.501 | AE15: 13304.501 | AF15: 13304.501 | AG15: =+SUM(I15:AF15)*H15 -> 1240307.8
B16: =+MONTH(E16) -> 3 | C16: =+YEAR(E16) -> 2026 | D16: =+_xlfn.CONCAT(B16:C16,G16) -> 32026DO | E16: 46082 | G16: DO | H16: 5 | I16: 13304.501 | J16: 13304.501 | K16: 13304.501 | L16: 13304.501 | M16: 13304.501 | N16: 13304.501 | O16: 13304.501 | P16: 13304.501 | Q16: 13304.501 | R16: 13304.501 | S16: 13304.501 | T16: 13304.501 | U16: 13304.501 | V16: 13304.501 | W16: 13304.501 | X16: 13304.501 | Y16: 13304.501 | Z16: 13304.501 | AA16: 13304.501 | AB16: 13304.501 | AC16: 13304.501 | AD16: 13304.501 | AE16: 13304.501 | AF16: 13304.501 | AG16: =+SUM(I16:AF16)*H16 -> 1596540.1
B17: =+MONTH(E17) -> 3 | C17: =+YEAR(E17) -> 2026 | D17: =+_xlfn.CONCAT(B17:C17,G17) -> 32026FE | E17: 46082 | G17: FE | H17: 1 | I17: 13304.501 | J17: 13304.501 | K17: 13304.501 | L17: 13304.501 | M17: 13304.501 | N17: 13304.501 | O17: 13304.501 | P17: 13304.501 | Q17: 13304.501 | R17: 13304.501 | S17: 13304.501 | T17: 13304.501 | U17: 13304.501 | V17: 13304.501 | W17: 13304.501 | X17: 13304.501 | Y17: 13304.501 | Z17: 13304.501 | AA17: 13304.501 | AB17: 13304.501 | AC17: 13304.501 | AD17: 13304.501 | AE17: 13304.501 | AF17: 13304.501 | AG17: =+SUM(I17:AF17)*H17 -> 319308.02
D18: =+_xlfn.CONCAT(E18,G18) -> 46082TOTAL | E18: 46082 | G18: TOTAL | H18: =+SUM(H14:H17) -> 31 | I18: =+SUMPRODUCT(I14:I17,$H14:$H17) -> 410543.19 | J18: =+SUMPRODUCT(J14:J17,$H14:$H17) -> 409671.43 | K18: =+SUMPRODUCT(K14:K17,$H14:$H17) -> 406705.14 | L18: =+SUMPRODUCT(L14:L17,$H14:$H17) -> 401049.63 | M18: =+SUMPRODUCT(M14:M17,$H14:$H17) -> 408043.62 | N18: =+SUMPRODUCT(N14:N17,$H14:$H17) -> 410543.19 | O18: =+SUMPRODUCT(O14:O17,$H14:$H17) -> 397771.68 | P18: =+SUMPRODUCT(P14:P17,$H14:$H17) -> 397771.68 | ... AF18: =+SUMPRODUCT(AF14:AF17,$H14:$H17) -> 410543.19 | AG18: =SUM(I18:AF18) -> 9669031.7
B19: =+MONTH(E19) -> 4 | C19: =+YEAR(E19) -> 2026 | D19: =+_xlfn.CONCAT(B19:C19,G19) -> 42026OR | E19: 46113 | F19: =+'PRODUCTO 01'!F12 -> 10071257 | G19: OR | H19: 20 | I19: 13689.237 | J19: 13689.237 | K19: 13632.408 | L19: 13390.353 | M19: 13655.235 | N19: 13693.884 | O19: 13748.317 | P19: 13975.705 | Q19: 14268.408 | R19: 14682.856 | S19: 14799.452 | T19: 14795.299 | U19: 14815.768 | V19: 14954.406 | W19: 14824.466 | X19: 14977.205 | Y19: 14334.274 | Z19: 13814.859 | AA19: 13791.43 | AB19: 13689.248 | AC19: 13689.237 | AD19: 13689.237 | AE19: 13689.237 | AF19: 13689.237 | AG19: =+SUM(I19:AF19)*H19 -> 6759579.9
B20: =+MONTH(E20) -> 4 | C20: =+YEAR(E20) -> 2026 | D20: =+_xlfn.CONCAT(B20:C20,G20) -> 42026SA | E20: 46113 | G20: SA | H20: 4 | I20: 13689.237 | J20: 13599.618 | K20: 12955.503 | L20: 12736.643 | M20: 12907.014 | N20: 13457.016 | O20: 13748.317 | P20: 13975.705 | Q20: 14268.408 | R20: 14682.856 | S20: 14799.452 | T20: 14795.299 | U20: 14815.768 | V20: 14954.406 | W20: 14824.466 | X20: 14977.205 | Y20: 14334.274 | Z20: 13814.859 | AA20: 13791.43 | AB20: 13689.248 | AC20: 13689.237 | AD20: 13689.237 | AE20: 13510.269 | AF20: 12295.058 | AG20: =+SUM(I20:AF20)*H20 -> 1336002.1
B21: =+MONTH(E21) -> 4 | C21: =+YEAR(E21) -> 2026 | D21: =+_xlfn.CONCAT(B21:C21,G21) -> 42026DO | E21: 46113 | G21: DO | H21: 4 | I21: 13689.237 | J21: 13542.341 | K21: 12903.472 | L21: 12557.912 | M21: 12218.456 | N21: 12410.955 | O21: 13448.394 | P21: 13975.705 | Q21: 14268.408 | R21: 14682.856 | S21: 14799.452 | T21: 14795.299 | U21: 14815.768 | V21: 14954.406 | W21: 14824.466 | X21: 14977.205 | Y21: 14334.274 | Z21: 13814.859 | AA21: 13791.43 | AB21: 13689.248 | AC21: 13689.237 | AD21: 13689.237 | AE21: 13689.237 | AF21: 13689.237 | AG21: =+SUM(I21:AF21)*H21 -> 1333004.4
B22: =+MONTH(E22) -> 4 | C22: =+YEAR(E22) -> 2026 | D22: =+_xlfn.CONCAT(B22:C22,G22) -> 42026FE | E22: 46113 | G22: FE | H22: 2 | I22: 13689.237 | J22: 12209.505 | K22: 9684.3716 | L22: 8553.3497 | M22: 8400.083 | N22: 12570.225 | O22: 13748.317 | P22: 13975.705 | Q22: 14268.408 | R22: 14682.856 | S22: 14799.452 | T22: 14795.299 | U22: 14815.768 | V22: 14954.406 | W22: 14824.466 | X22: 14977.205 | Y22: 14334.274 | Z22: 13814.859 | AA22: 13791.43 | AB22: 13689.248 | AC22: 13689.237 | AD22: 13689.237 | AE22: 13689.237 | AF22: 13689.237 | AG22: =+SUM(I22:AF22)*H22 -> 642670.83
D23: =+_xlfn.CONCAT(E23,G23) -> 46113TOTAL | E23: 46113 | G23: TOTAL | H23: =+SUM(H19:H22) -> 30 | I23: =+SUMPRODUCT(I19:I22,$H19:$H22) -> 410677.11 | J23: =+SUMPRODUCT(J19:J22,$H19:$H22) -> 406771.59 | K23: =+SUMPRODUCT(K19:K22,$H19:$H22) -> 395452.79 | L23: =+SUMPRODUCT(L19:L22,$H19:$H22) -> 386091.99 | M23: =+SUMPRODUCT(M19:M22,$H19:$H22) -> 390406.74 | N23: =+SUMPRODUCT(N19:N22,$H19:$H22) -> 402490.02 | O23: =+SUMPRODUCT(O19:O22,$H19:$H22) -> 411249.82 | P23: =+SUMPRODUCT(P19:P22,$H19:$H22) -> 419271.14 | ... AF23: =+SUMPRODUCT(AF19:AF22,$H19:$H22) -> 405100.4 | AG23: =SUM(I23:AF23) -> 10071257
B24: =+MONTH(E24) -> 5 | C24: =+YEAR(E24) -> 2026 | D24: =+_xlfn.CONCAT(B24:C24,G24) -> 52026OR | E24: 46143 | F24: =+'PRODUCTO 01'!F13 -> 9866307.1 | G24: OR | H24: 19 | I24: 12814.677 | J24: 12814.677 | K24: 12814.677 | L24: 12750.638 | M24: 12814.677 | N24: 12827.218 | O24: 12909.32 | P24: 13341.394 | Q24: 14105.488 | R24: 14234.654 | S24: 13928.992 | T24: 13772.449 | U24: 13748.425 | V24: 13664.719 | W24: 13938.223 | X24: 14078.804 | Y24: 13691.549 | Z24: 12973.863 | AA24: 12945.198 | AB24: 12814.832 | AC24: 12814.677 | AD24: 12814.677 | AE24: 12814.677 | AF24: 12814.677 | AG24: =+SUM(I24:AF24)*H24 -> 6046620.4
B25: =+MONTH(E25) -> 5 | C25: =+YEAR(E25) -> 2026 | D25: =+_xlfn.CONCAT(B25:C25,G25) -> 52026SA | E25: 46143 | G25: SA | H25: 5 | I25: 12814.677 | J25: 12814.677 | K25: 12814.677 | L25: 12814.677 | M25: 12814.677 | N25: 12827.218 | O25: 12909.32 | P25: 13341.394 | Q25: 14105.488 | R25: 14234.654 | S25: 13928.992 | T25: 13772.449 | U25: 13748.425 | V25: 13664.719 | W25: 13938.223 | X25: 14078.804 | Y25: 13691.549 | Z25: 12973.863 | AA25: 12945.198 | AB25: 12814.832 | AC25: 12814.677 | AD25: 12814.677 | AE25: 12814.677 | AF25: 12814.677 | AG25: =+SUM(I25:AF25)*H25 -> 1591536.1
B26: =+MONTH(E26) -> 5 | C26: =+YEAR(E26) -> 2026 | D26: =+_xlfn.CONCAT(B26:C26,G26) -> 52026DO | E26: 46143 | G26: DO | H26: 5 | I26: 12814.677 | J26: 12814.677 | K26: 12814.677 | L26: 12814.677 | M26: 12814.677 | N26: 12827.218 | O26: 12909.32 | P26: 13341.394 | Q26: 14105.488 | R26: 14234.654 | S26: 13928.992 | T26: 13772.449 | U26: 13748.425 | V26: 13664.719 | W26: 13938.223 | X26: 14078.804 | Y26: 13691.549 | Z26: 12973.863 | AA26: 12945.198 | AB26: 12814.832 | AC26: 12814.677 | AD26: 12814.677 | AE26: 12814.677 | AF26: 12814.677 | AG26: =+SUM(I26:AF26)*H26 -> 1591536.1
B27: =+MONTH(E27) -> 5 | C27: =+YEAR(E27) -> 2026 | D27: =+_xlfn.CONCAT(B27:C27,G27) -> 52026FE | E27: 46143 | G27: FE | H27: 2 | I27: 12814.677 | J27: 12814.677 | K27: 12814.677 | L27: 12814.677 | M27: 12814.677 | N27: 12827.218 | O27: 12909.32 | P27: 13341.394 | Q27: 14105.488 | R27: 14234.654 | S27: 13928.992 | T27: 13772.449 | U27: 13748.425 | V27: 13664.719 | W27: 13938.223 | X27: 14078.804 | Y27: 13691.549 | Z27: 12973.863 | AA27: 12945.198 | AB27: 12814.832 | AC27: 12814.677 | AD27: 12814.677 | AE27: 12814.677 | AF27: 12814.677 | AG27: =+SUM(I27:AF27)*H27 -> 636614.44
D28: =+_xlfn.CONCAT(E28,G28) -> 46143TOTAL | E28: 46143 | G28: TOTAL | H28: =+SUM(H24:H27) -> 31 | I28: =+SUMPRODUCT(I24:I27,$H24:$H27) -> 397254.98 | J28: =+SUMPRODUCT(J24:J27,$H24:$H27) -> 397254.97 | K28: =+SUMPRODUCT(K24:K27,$H24:$H27) -> 397254.98 | L28: =+SUMPRODUCT(L24:L27,$H24:$H27) -> 396038.24 | M28: =+SUMPRODUCT(M24:M27,$H24:$H27) -> 397254.97 | N28: =+SUMPRODUCT(N24:N27,$H24:$H27) -> 397643.75 | O28: =+SUMPRODUCT(O24:O27,$H24:$H27) -> 400188.92 | P28: =+SUMPRODUCT(P24:P27,$H24:$H27) -> 413583.21 | ... AF28: =+SUMPRODUCT(AF24:AF27,$H24:$H27) -> 397254.98 | AG28: =SUM(I28:AF28) -> 9866307.1
B29: =+MONTH(E29) -> 6 | C29: =+YEAR(E29) -> 2026 | D29: =+_xlfn.CONCAT(B29:C29,G29) -> 62026OR | E29: 46174 | F29: =+'PRODUCTO 01'!F14 -> 12364564 | G29: OR | H29: 19 | I29: 16815.555 | J29: 16672.681 | K29: 16400.2 | L29: 15610.825 | M29: 16543.098 | N29: 16826.733 | O29: 16905.702 | P29: 17143.379 | Q29: 17606.508 | R29: 18192.895 | S29: 18270.096 | T29: 18181.525 | U29: 18342.889 | V29: 17973.157 | W29: 17696.643 | X29: 17405.128 | Y29: 17226.02 | Z29: 16976.084 | AA29: 16986.471 | AB29: 16815.838 | AC29: 16815.555 | AD29: 16815.555 | AE29: 16815.555 | AF29: 16815.555 | AG29: =+SUM(I29:AF29)*H29 -> 7825219.3
B30: =+MONTH(E30) -> 6 | C30: =+YEAR(E30) -> 2026 | D30: =+_xlfn.CONCAT(B30:C30,G30) -> 62026SA | E30: 46174 | G30: SA | H30: 4 | I30: 16813.236 | J30: 16813.236 | K30: 16813.236 | L30: 16813.239 | M30: 16813.239 | N30: 16824.413 | O30: 16903.382 | P30: 17141.06 | Q30: 17604.188 | R30: 18190.576 | S30: 18267.776 | T30: 18179.206 | U30: 18340.569 | V30: 17970.838 | W30: 17694.323 | X30: 17402.809 | Y30: 17223.701 | Z30: 16973.765 | AA30: 16984.152 | AB30: 16813.519 | AC30: 16813.236 | AD30: 16813.236 | AE30: 16813.236 | AF30: 16238.831 | AG30: =+SUM(I30:AF30)*H30 -> 1653036
B31: =+MONTH(E31) -> 6 | C31: =+YEAR(E31) -> 2026 | D31: =+_xlfn.CONCAT(B31:C31,G31) -> 62026DO | E31: 46174 | G31: DO | H31: 4 | I31: 16813.236 | J31: 16813.236 | K31: 16813.236 | L31: 16740.236 | M31: 15285.594 | N31: 16058.159 | O31: 16903.382 | P31: 17141.06 | Q31: 17604.188 | R31: 18190.576 | S31: 18267.776 | T31: 18179.206 | U31: 18340.569 | V31: 17970.838 | W31: 17694.323 | X31: 17402.809 | Y31: 17223.701 | Z31: 16973.765 | AA31: 16984.152 | AB31: 16813.519 | AC31: 16813.236 | AD31: 16813.236 | AE31: 16813.236 | AF31: 16813.236 | AG31: =+SUM(I31:AF31)*H31 -> 1645866
B32: =+MONTH(E32) -> 6 | C32: =+YEAR(E32) -> 2026 | D32: =+_xlfn.CONCAT(B32:C32,G32) -> 62026FE | E32: 46174 | G32: FE | H32: 3 | I32: 16798.546 | J32: 16798.546 | K32: 16798.546 | L32: 16798.55 | M32: 16798.55 | N32: 16809.724 | O32: 16888.693 | P32: 17126.371 | Q32: 17589.499 | R32: 18175.886 | S32: 18253.087 | T32: 18164.517 | U32: 18325.88 | V32: 17956.149 | W32: 17679.634 | X32: 17388.119 | Y32: 17209.012 | Z32: 16959.076 | AA32: 16969.462 | AB32: 16798.829 | AC32: 16798.546 | AD32: 16798.546 | AE32: 16798.546 | AF32: 16798.546 | AG32: =+SUM(I32:AF32)*H32 -> 1240442.6
D33: =+_xlfn.CONCAT(E33,G33) -> 46174TOTAL | E33: 46174 | G33: TOTAL | H33: =+SUM(H29:H32) -> 30 | I33: =+SUMPRODUCT(I29:I32,$H29:$H32) -> 504397.08 | J33: =+SUMPRODUCT(J29:J32,$H29:$H32) -> 501682.47 | K33: =+SUMPRODUCT(K29:K32,$H29:$H32) -> 496505.33 | L33: =+SUMPRODUCT(L29:L32,$H29:$H32) -> 481215.23 | M33: =+SUMPRODUCT(M29:M32,$H29:$H32) -> 493109.85 | N33: =+SUMPRODUCT(N29:N32,$H29:$H32) -> 501667.38 | O33: =+SUMPRODUCT(O29:O32,$H29:$H32) -> 507101.47 | P33: =+SUMPRODUCT(P29:P32,$H29:$H32) -> 514231.8 | ... AF33: =+SUMPRODUCT(AF29:AF32,$H29:$H32) -> 502099.46 | AG33: =SUM(I33:AF33) -> 12364564
B34: =+MONTH(E34) -> 7 | C34: =+YEAR(E34) -> 2026 | D34: =+_xlfn.CONCAT(B34:C34,G34) -> 72026OR | E34: 46204 | F34: =+'PRODUCTO 01'!F15 -> 12776719 | G34: OR | H34: 22 | I34: 16786.805 | J34: 16549.897 | K34: 16071.953 | L34: 15107.769 | M34: 16321.803 | N34: 16789.861 | O34: 16878.71 | P34: 17175.322 | Q34: 17690.368 | R34: 18359.218 | S34: 18240.253 | T34: 18232.326 | U34: 18361.907 | V34: 17817.578 | W34: 17826.053 | X34: 17956.184 | Y34: 17418.423 | Z34: 16995.897 | AA34: 17009.377 | AB34: 16787.341 | AC34: 16786.805 | AD34: 16786.805 | AE34: 16786.805 | AF34: 16786.805 | AG34: =+SUM(I34:AF34)*H34 -> 9053533.8
B35: =+MONTH(E35) -> 7 | C35: =+YEAR(E35) -> 2026 | D35: =+_xlfn.CONCAT(B35:C35,G35) -> 72026SA | E35: 46204 | G35: SA | H35: 4 | I35: 16791.638 | J35: 16791.637 | K35: 16791.637 | L35: 16791.637 | M35: 16791.637 | N35: 16794.693 | O35: 16883.542 | P35: 17180.154 | Q35: 17695.2 | R35: 18364.051 | S35: 18245.086 | T35: 18237.159 | U35: 18366.74 | V35: 17822.41 | W35: 17830.885 | X35: 17961.016 | Y35: 17423.255 | Z35: 17000.729 | AA35: 17014.209 | AB35: 16792.174 | AC35: 16791.638 | AD35: 16791.637 | AE35: 16791.637 | AF35: 16203.244 | AG35: =+SUM(I35:AF35)*H35 -> 1656590.6
B36: =+MONTH(E36) -> 7 | C36: =+YEAR(E36) -> 2026 | D36: =+_xlfn.CONCAT(B36:C36,G36) -> 72026DO | E36: 46204 | G36: DO | H36: 4 | I36: 16791.638 | J36: 16791.637 | K36: 16791.637 | L36: 16791.637 | M36: 15921.958 | N36: 16617.606 | O36: 16883.542 | P36: 17180.154 | Q36: 17695.2 | R36: 18364.051 | S36: 18245.086 | T36: 18237.159 | U36: 18366.74 | V36: 17822.41 | W36: 17830.885 | X36: 17961.016 | Y36: 17423.255 | Z36: 17000.729 | AA36: 17014.209 | AB36: 16792.174 | AC36: 16791.638 | AD36: 16791.637 | AE36: 16791.637 | AF36: 16791.637 | AG36: =+SUM(I36:AF36)*H36 -> 1654757.1
B37: =+MONTH(E37) -> 7 | C37: =+YEAR(E37) -> 2026 | D37: =+_xlfn.CONCAT(B37:C37,G37) -> 72026FE | E37: 46204 | G37: FE | H37: 1 | I37: 16768.857 | J37: 16768.856 | K37: 16408.487 | L37: 15918.537 | M37: 15628.028 | N37: 16771.912 | O37: 16860.761 | P37: 17157.373 | Q37: 17672.419 | R37: 18341.27 | S37: 18222.305 | T37: 18214.378 | U37: 18343.959 | V37: 17799.63 | W37: 17808.104 | X37: 17938.235 | Y37: 17400.474 | Z37: 16977.948 | AA37: 16991.428 | AB37: 16769.393 | AC37: 16768.857 | AD37: 16768.856 | AE37: 16768.856 | AF37: 16768.856 | AG37: =+SUM(I37:AF37)*H37 -> 411837.78
D38: =+_xlfn.CONCAT(E38,G38) -> 46204TOTAL | E38: 46204 | G38: TOTAL | H38: =+SUM(H34:H37) -> 31 | I38: =+SUMPRODUCT(I34:I37,$H34:$H37) -> 520411.67 | J38: =+SUMPRODUCT(J34:J37,$H34:$H37) -> 515199.69 | K38: =+SUMPRODUCT(K34:K37,$H34:$H37) -> 504324.55 | L38: =+SUMPRODUCT(L34:L37,$H34:$H37) -> 482622.55 | M38: =+SUMPRODUCT(M34:M37,$H34:$H37) -> 505562.07 | N38: =+SUMPRODUCT(N34:N37,$H34:$H37) -> 519798.05 | O38: =+SUMPRODUCT(O34:O37,$H34:$H37) -> 523260.71 | P38: =+SUMPRODUCT(P34:P37,$H34:$H37) -> 532455.69 | ... AF38: =+SUMPRODUCT(AF34:AF37,$H34:$H37) -> 518058.09 | AG38: =SUM(I38:AF38) -> 12776719
B39: =+MONTH(E39) -> 8 | C39: =+YEAR(E39) -> 2026 | D39: =+_xlfn.CONCAT(B39:C39,G39) -> 82026OR | E39: 46235 | F39: =+'PRODUCTO 01'!F16 -> 12207909 | G39: OR | H39: 19 | I39: 15924.633 | J39: 15924.633 | K39: 15924.633 | L39: 15701.423 | M39: 15924.633 | N39: 15928.276 | O39: 15984.68 | P39: 16217.972 | Q39: 17177.467 | R39: 17441.43 | S39: 17567.331 | T39: 17085.809 | U39: 17101.122 | V39: 17231.696 | W39: 16844.683 | X39: 16990.849 | Y39: 16345.705 | Z39: 16095.397 | AA39: 16103.043 | AB39: 15924.732 | AC39: 15924.633 | AD39: 15924.633 | AE39: 15924.633 | AF39: 15924.633 | AG39: =+SUM(I39:AF39)*H39 -> 7469634.9
B40: =+MONTH(E40) -> 8 | C40: =+YEAR(E40) -> 2026 | D40: =+_xlfn.CONCAT(B40:C40,G40) -> 82026SA | E40: 46235 | G40: SA | H40: 5 | I40: 15965.047 | J40: 15965.047 | K40: 15965.047 | L40: 15965.047 | M40: 15965.047 | N40: 15968.69 | O40: 16025.093 | P40: 16281.488 | Q40: 17240.982 | R40: 17504.945 | S40: 17630.846 | T40: 17149.324 | U40: 17164.638 | V40: 17295.212 | W40: 16908.199 | X40: 17054.364 | Y40: 16409.221 | Z40: 16135.81 | AA40: 16143.456 | AB40: 15965.145 | AC40: 15965.047 | AD40: 15965.047 | AE40: 15965.047 | AF40: 15965.047 | AG40: =+SUM(I40:AF40)*H40 -> 1972814.2
B41: =+MONTH(E41) -> 8 | C41: =+YEAR(E41) -> 2026 | D41: =+_xlfn.CONCAT(B41:C41,G41) -> 82026DO | E41: 46235 | G41: DO | H41: 5 | I41: 15965.047 | J41: 15965.047 | K41: 15965.047 | L41: 15965.047 | M41: 15965.047 | N41: 15968.69 | O41: 16025.093 | P41: 16281.488 | Q41: 17240.982 | R41: 17504.945 | S41: 17630.846 | T41: 17149.324 | U41: 17164.638 | V41: 17295.212 | W41: 16908.199 | X41: 17054.364 | Y41: 16409.221 | Z41: 16135.81 | AA41: 16143.456 | AB41: 15965.145 | AC41: 15965.047 | AD41: 15965.047 | AE41: 15965.047 | AF41: 15965.047 | AG41: =+SUM(I41:AF41)*H41 -> 1972814.2
B42: =+MONTH(E42) -> 8 | C42: =+YEAR(E42) -> 2026 | D42: =+_xlfn.CONCAT(B42:C42,G42) -> 82026FE | E42: 46235 | G42: FE | H42: 2 | I42: 16038.382 | J42: 16038.382 | K42: 16038.382 | L42: 16038.382 | M42: 16038.382 | N42: 16042.026 | O42: 16098.429 | P42: 16354.823 | Q42: 17314.318 | R42: 17578.281 | S42: 17704.181 | T42: 17222.66 | U42: 17237.973 | V42: 17368.547 | W42: 16981.534 | X42: 17127.7 | Y42: 16482.556 | Z42: 16209.146 | AA42: 16216.792 | AB42: 16038.481 | AC42: 16038.382 | AD42: 16038.382 | AE42: 16038.382 | AF42: 16038.382 | AG42: =+SUM(I42:AF42)*H42 -> 792645.78
D43: =+_xlfn.CONCAT(E43,G43) -> 46235TOTAL | E43: 46235 | G43: TOTAL | H43: =+SUM(H39:H42) -> 31 | I43: =+SUMPRODUCT(I39:I42,$H39:$H42) -> 494295.26 | J43: =+SUMPRODUCT(J39:J42,$H39:$H42) -> 494295.26 | K43: =+SUMPRODUCT(K39:K42,$H39:$H42) -> 494295.26 | L43: =+SUMPRODUCT(L39:L42,$H39:$H42) -> 490054.27 | M43: =+SUMPRODUCT(M39:M42,$H39:$H42) -> 494295.26 | N43: =+SUMPRODUCT(N39:N42,$H39:$H42) -> 494408.2 | O43: =+SUMPRODUCT(O39:O42,$H39:$H42) -> 496156.7 | P43: =+SUMPRODUCT(P39:P42,$H39:$H42) -> 503666 | ... AF43: =+SUMPRODUCT(AF39:AF42,$H39:$H42) -> 494295.26 | AG43: =SUM(I43:AF43) -> 12207909
...

Sheet calendario
A1: Cuenta de TIPO
A2: MES | B2: TIPO | C2: 2014 | D2: 2015 | E2: 2016 | F2: 2017 | G2: 2018
A3: 1 | B3: 1ORD | C3: =31-C4-C5 -> 21 | D3: =31-D4-D5 -> 20 | E3: 19 | F3: 21 | G3: 21
A4: 1 | B4: 2SÁB | C4: 4 | D4: 5 | E4: 5 | F4: 4 | G4: 4
A5: 1 | B5: 3FES | C5: 6 | D5: 6 | E5: 7 | F5: 6 | G5: 6
A6: 2 | B6: 1ORD | C6: =28-C7-C8 -> 20 | D6: =28-D7-D8 -> 20 | E6: 21 | F6: 20 | G6: 20
A7: 2 | B7: 2SÁB | C7: 4 | D7: 4 | E7: 4 | F7: 4 | G7: 4
A8: 2 | B8: 3FES | C8: 4 | D8: 4 | E8: 4 | F8: 4 | G8: 4
A9: 3 | B9: 1ORD | C9: =31-C10-C11 -> 20 | D9: =31-D10-D11 -> 21 | E9: 20 | F9: 22 | G9: 19
A10: 3 | B10: 2SÁB | C10: 5 | D10: 4 | E10: 4 | F10: 4 | G10: 5
A11: 3 | B11: 3FES | C11: 6 | D11: 6 | E11: 7 | F11: 5 | G11: 7
A12: 4 | B12: 1ORD | C12: =30-C13-C14 -> 20 | D12: =30-D13-D14 -> 20 | E12: 21 | F12: 18 | G12: 21
A13: 4 | B13: 2SÁB | C13: 4 | D13: 4 | E13: 5 | F13: 5 | G13: 4
A14: 4 | B14: 3FES | C14: 6 | D14: 6 | E14: 4 | F14: 7 | G14: 5
A15: 5 | B15: 1ORD | C15: =31-C16-C17 -> 21 | D15: =31-D16-D17 -> 19 | E15: 20 | F15: 21 | G15: 21
A16: 5 | B16: 2SÁB | C16: 5 | D16: 5 | E16: 4 | F16: 4 | G16: 4
A17: 5 | B17: 3FES | C17: 5 | D17: 7 | E17: 7 | F17: 6 | G17: 6
A18: 6 | B18: 1ORD | C18: =30-C19-C20 -> 18 | D18: =30-D19-D20 -> 19 | E18: 21 | F18: 20 | G18: 19
A19: 6 | B19: 2SÁB | C19: 4 | D19: 4 | E19: 4 | F19: 4 | G19: 5
A20: 6 | B20: 3FES | C20: 8 | D20: 7 | E20: 5 | F20: 6 | G20: 6
A21: 7 | B21: 1ORD | C21: =31-C22-C23 -> 23 | D21: =31-D22-D23 -> 22 | E21: 19 | F21: 19 | G21: 20
A22: 7 | B22: 2SÁB | C22: 4 | D22: 4 | E22: 5 | F22: 5 | G22: 4
A23: 7 | B23: 3FES | C23: 4 | D23: 5 | E23: 7 | F23: 7 | G23: 7
A24: 8 | B24: 1ORD | C24: =31-C25-C26 -> 19 | D24: =31-D25-D26 -> 19 | E24: 22 | F24: 21 | G24: 21
A25: 8 | B25: 2SÁB | C25: 5 | D25: 5 | E25: 4 | F25: 4 | G25: 4
A26: 8 | B26: 3FES | C26: 7 | D26: 7 | E26: 5 | F26: 6 | G26: 6
A27: 9 | B27: 1ORD | C27: =30-C28-C29 -> 22 | D27: =30-D28-D29 -> 22 | E27: 22 | F27: 21 | G27: 20
A28: 9 | B28: 2SÁB | C28: 4 | D28: 4 | E28: 4 | F28: 5 | G28: 5
A29: 9 | B29: 3FES | C29: 4 | D29: 4 | E29: 4 | F29: 4 | G29: 5
A30: 10 | B30: 1ORD | C30: =31-C31-C32 -> 22 | D30: =31-D31-D32 -> 21 | E30: 20 | F30: 21 | G30: 22
A31: 10 | B31: 2SÁB | C31: 4 | D31: 5 | E31: 5 | F31: 4 | G31: 4
A32: 10 | B32: 3FES | C32: 5 | D32: 5 | E32: 6 | F32: 6 | G32: 5
A33: 11 | B33: 1ORD | C33: =30-C34-C35 -> 18 | D33: =30-D34-D35 -> 19 | E33: 20 | F33: 20 | G33: 20
A34: 11 | B34: 2SÁB | C34: 5 | D34: 4 | E34: 4 | F34: 4 | G34: 4
A35: 11 | B35: 3FES | C35: 7 | D35: 7 | E35: 6 | F35: 6 | G35: 6
A36: 12 | B36: 1ORD | C36: =31-C37-C38 -> 21 | D36: =31-D37-D38 -> 21 | E36: 21 | F36: 19 | G36: 20
A37: 12 | B37: 2SÁB | C37: 4 | D37: 4 | E37: 5 | F37: 5 | G37: 5
A38: 12 | B38: 3FES | C38: 6 | D38: 6 | E38: 5 | F38: 7 | G38: 6

Sheet curvas típicas de referencia
A2: tipo día | B2: H1 | C2: H2 | D2: H3 | E2: H4 | F2: H5 | G2: H6 | H2: H7 | I2: H8 | J2: H9 | K2: H10 | L2: H11 | M2: H12 | N2: H13 | O2: H14 | P2: H15 | Q2: H16 | R2: H17 | S2: H18 | T2: H19 | U2: H20 | V2: H21 | W2: H22 | X2: H23 | Y2: H24
A3: Habil | B3: 0.027834527 | C3: 0.026682521 | D3: 0.025923893 | E3: 0.025439158 | F3: 0.025556097 | G3: 0.027259445 | H3: 0.032350135 | I3: 0.040455761 | J3: 0.047464293 | K3: 0.051692777 | L3: 0.054607079 | M3: 0.05493643 | N3: 0.052911056 | O3: 0.054485015 | P3: 0.056958239 | Q3: 0.057105703 | R3: 0.054820804 | S3: 0.051080543 | T3: 0.047845564 | U3: 0.044575088 | V3: 0.040435268 | W3: 0.036298963 | X3: 0.032954022 | Y3: 0.030327619
A4: Sabado | B4: 0.031933621 | C4: 0.030285079 | D4: 0.02935318 | E4: 0.028733579 | F4: 0.028654972 | G4: 0.029977253 | H4: 0.034030119 | I4: 0.040020468 | J4: 0.046345254 | K4: 0.051632171 | L4: 0.055400723 | M4: 0.055432951 | N4: 0.052958111 | O4: 0.051848023 | P4: 0.050438564 | Q4: 0.049277928 | R4: 0.047857004 | S4: 0.0471393 | T4: 0.046673457 | U4: 0.044979657 | V4: 0.042158325 | W4: 0.038032949 | X4: 0.03456292 | Y4: 0.032274391
A5: Festivo | B5: 0.0369262 | C5: 0.035565247 | D5: 0.034193693 | E5: 0.033394425 | F5: 0.032854151 | G5: 0.032653619 | H5: 0.033632199 | I5: 0.036341608 | J5: 0.040377423 | K5: 0.043732241 | L5: 0.047238598 | M5: 0.049884901 | N5: 0.050097655 | O5: 0.049054338 | P5: 0.047949351 | Q5: 0.047121269 | R5: 0.046744813 | S5: 0.046327025 | T5: 0.047122858 | U5: 0.046196154 | V5: 0.044346624 | W5: 0.041928399 | X5: 0.039253217 | Y5: 0.037063992
A8: CURVA ACTUALIZADA CON DEMANDAS PROYECCION DEMANDA REGULADA MATRICIAL 2014 (Enero 2014)
