Workbook

Sheet Oferta Producto No. 1
D2: ANEXO No. 1 OFERTAS Y CANTIDADES
C3: OFERTA MERCANTIL IRREVOCABLE A LA EMPRESA DE ENERGIA DE PEREIRA S.A. ESP. INVITACIÓN PARA EL SUMINISTRO DE ENERGÍA ELÉCTRICA CON DESTINO AL MERCADO REGULADO CONVOCATORIA PÚBLICA No. 007-2025 - CP-EEPC2025-007
D4: PRODUCTO No. 1
C6: EMPRESA: XXXXXXXXXXXXXXXXXXXXXXXXXXXXXX
C7: REPRESENTANTE LEGAL: XXXXXXXXXXXXXXXXXXXXXXXXXXXXXX
C8: TIPO DE AGENTE: (COMERCIALIZADOR/GENERADOR)
C9: ="PRODUCTO OFERTADO: "&D4 -> PRODUCTO OFERTADO: PRODUCTO No. 1
C11: Las tarifas ofertadas están referidas en pesos constantes de septiembre de 2025 provisional
F13: ="Oferta " & PROPER(D4) -> Oferta Producto No. 1
F14: Periodo | G14: Energía requerida (MWh-mes) | H14: Energía ofertada (%) | I14: Energía ofertada (MWh-mes) | J14: Tarifa monomia ($/kWh)
A15: 22.85 | B15: 31 | F15: =+'Cantidades Producto No. 1'!A18 -> 46023 | G15: =+SUMIFS('Cantidades Producto No. 1'!$Z$18:$Z$22,'Cantidades Producto No. 1'!$A$18:$A$22,'Oferta Producto No. 1'!$F15) -> 5282.3288
B16: 28 | F16: =+'Cantidades Producto No. 1'!A19 -> 46054 | G16: =+SUMIFS('Cantidades Producto No. 1'!$Z$18:$Z$22,'Cantidades Producto No. 1'!$A$18:$A$22,'Oferta Producto No. 1'!$F16) -> 4771.1357
B17: 31 | F17: =+'Cantidades Producto No. 1'!A20 -> 46082 | G17: =+SUMIFS('Cantidades Producto No. 1'!$Z$18:$Z$22,'Cantidades Producto No. 1'!$A$18:$A$22,'Oferta Producto No. 1'!$F17) -> 5282.3288
B18: 30 | F18: =+'Cantidades Producto No. 1'!A21 -> 46113 | G18: =+SUMIFS('Cantidades Producto No. 1'!$Z$18:$Z$22,'Cantidades Producto No. 1'!$A$18:$A$22,'Oferta Producto No. 1'!$F18) -> 5111.9311
B19: 31 | F19: =+'Cantidades Producto No. 1'!#REF! -> #REF! | G19: =+SUMIFS('Cantidades Producto No. 1'!$Z$18:$Z$22,'Cantidades Producto No. 1'!$A$18:$A$22,'Oferta Producto No. 1'!$F19) -> 0
B20: 30 | F20: =+'Cantidades Producto No. 1'!#REF! -> #REF! | G20: =+SUMIFS('Cantidades Producto No. 1'!$Z$18:$Z$22,'Cantidades Producto No. 1'!$A$18:$A$22,'Oferta Producto No. 1'!$F20) -> 0
B21: 31 | F21: =+'Cantidades Producto No. 1'!#REF! -> #REF! | G21: =+SUMIFS('Cantidades Producto No. 1'!$Z$18:$Z$22,'Cantidades Producto No. 1'!$A$18:$A$22,'Oferta Producto No. 1'!$F21) -> 0
B22: 31 | F22: =+'Cantidades Producto No. 1'!#REF! -> #REF! | G22: =+SUMIFS('Cantidades Producto No. 1'!$Z$18:$Z$22,'Cantidades Producto No. 1'!$A$18:$A$22,'Oferta Producto No. 1'!$F22) -> 0
B23: 30 | F23: =+'Cantidades Producto No. 1'!#REF! -> #REF! | G23: =+SUMIFS('Cantidades Producto No. 1'!$Z$18:$Z$22,'Cantidades Producto No. 1'!$A$18:$A$22,'Oferta Producto No. 1'!$F23) -> 0
B24: 31 | F24: =+'Cantidades Producto No. 1'!#REF! -> #REF! | G24: =+SUMIFS('Cantidades Producto No. 1'!$Z$18:$Z$22,'Cantidades Producto No. 1'!$A$18:$A$22,'Oferta Producto No. 1'!$F24) -> 0
B25: 31 | F25: =+'Cantidades Producto No. 1'!A22 -> 46357 | G25: =+SUMIFS('Cantidades Producto No. 1'!$Z$18:$Z$22,'Cantidades Producto No. 1'!$A$18:$A$22,'Oferta Producto No. 1'!$F25) -> 5282.3288
F26: TOTAL | G26: =SUM(G15:G25) -> 25730.053
B28: Notas
B30: (1) Oferta válida para la modalidad Pague lo Contratado.
B31: ="(2) Las cantidades se distribuyen de acuerdo a la curva del Anexo 1. Ofertas y Cantidades "& D4 &" de los Pliegos de Condiciones Definitivos." -> (2) Las cantidades se distribuyen de acuerdo a la curva del Anexo 1. Ofertas y Cantidades PRODUCTO No. 1 de los Pliegos de Condiciones Definitivos.
B32: (3) La cantidad de energía es equivalente a un porcentaje de las cantidades de energía requerida por la Empresa de Energía de Pereira S.A. ESP. (para todo el año/para cada mes), de acuerdo con el Anexo No.1 Ofertas y Cantidades PRODUCTO No. 1 de los Pliegos Definitivos, que se aplicarán para todas las 24 horas del día de la curva establecida en dicho Anexo, presentando una tarifa para cada año sin ningún tipo de discriminación por mes, ni tipo de carga ni tipo de día.
B33: (4) Esta oferta NO presenta restricciones tales como adjudicación mínima o total u otras que no permitan la evaluación objetiva e integral del producto ofertado.
B34: (5) Los precios ofertados incluyen todos los pagos, cargos, impuestos, estampillas, etc., que el Proponente deba realizar ante cualquier entidad gubernamental, o empresa pública, privada o mixta para entregar la energía en la frontera con el Sistema de Transmisión Nacional – STN.
B35: (6) Las cantidades ofertadas están sujetas a la adjudicación en la misma proporción respecto a las cantidades ofertadas para todos y cada uno de los meses del año. Es decir, si la Empresa de Energía de Pereira decide adjudicar, por ejemplo, el 50% de lo ofertado en cualesquiera de los meses de alguno de los años, ese mismo porcentaje debe ser adjudicado en el resto de cada uno de los meses de ese año.

Sheet Cantidades Producto No. 1
AJ1: …..
A2: EMPRESA DE ENERGÍA DE PEREIRA S.A. E.S.P.
A3: PRODUCTO No. 1
A5: DEMANDA DIARIA ESTIMADA TO [MWh]
A7: MES | B7: H1 | C7: H2 | D7: H3 | E7: H4 | F7: H5 | G7: H6 | H7: H7 | I7: H8 | J7: H9 | K7: H10 | L7: H11 | M7: H12 | N7: H13 | O7: H14 | P7: H15 | Q7: H16 | R7: H17 | S7: H18 | T7: H19 | U7: H20 | V7: H21 | W7: H22 | X7: H23 | Y7: H24 | Z7: TOTAL | AA7: Días
A8: 46023 | B8: 7.0999043 | C8: 7.0999043 | D8: 7.0999043 | E8: 7.0999043 | F8: 7.0999043 | G8: 7.0999043 | H8: 7.0999043 | I8: 7.0999043 | J8: 7.0999043 | K8: 7.0999043 | L8: 7.0999043 | M8: 7.0999043 | N8: 7.0999043 | O8: 7.0999043 | P8: 7.0999043 | Q8: 7.0999043 | R8: 7.0999043 | S8: 7.0999043 | T8: 7.0999043 | U8: 7.0999043 | V8: 7.0999043 | W8: 7.0999043 | X8: 7.0999043 | Y8: 7.0999043 | Z8: =SUM(B8:Y8) -> 170.3977 | AA8: 31 | AB8: =+Z8*AA8 -> 5282.3288 | AD8: HABIL
A9: 46054 | B9: 7.0999043 | C9: 7.0999043 | D9: 7.0999043 | E9: 7.0999043 | F9: 7.0999043 | G9: 7.0999043 | H9: 7.0999043 | I9: 7.0999043 | J9: 7.0999043 | K9: 7.0999043 | L9: 7.0999043 | M9: 7.0999043 | N9: 7.0999043 | O9: 7.0999043 | P9: 7.0999043 | Q9: 7.0999043 | R9: 7.0999043 | S9: 7.0999043 | T9: 7.0999043 | U9: 7.0999043 | V9: 7.0999043 | W9: 7.0999043 | X9: 7.0999043 | Y9: 7.0999043 | Z9: =SUM(B9:Y9) -> 170.3977 | AA9: 28 | AB9: =+Z9*AA9 -> 4771.1357 | AD9: HABIL
A10: 46082 | B10: 7.0999043 | C10: 7.0999043 | D10: 7.0999043 | E10: 7.0999043 | F10: 7.0999043 | G10: 7.0999043 | H10: 7.0999043 | I10: 7.0999043 | J10: 7.0999043 | K10: 7.0999043 | L10: 7.0999043 | M10: 7.0999043 | N10: 7.0999043 | O10: 7.0999043 | P10: 7.0999043 | Q10: 7.0999043 | R10: 7.0999043 | S10: 7.0999043 | T10: 7.0999043 | U10: 7.0999043 | V10: 7.0999043 | W10: 7.0999043 | X10: 7.0999043 | Y10: 7.0999043 | Z10: =SUM(B10:Y10) -> 170.3977 | AA10: 31 | AB10: =+Z10*AA10 -> 5282.3288 | AD10: HABIL
A11: 46113 | B11: 7.0999043 | C11: 7.0999043 | D11: 7.0999043 | E11: 7.0999043 | F11: 7.0999043 | G11: 7.0999043 | H11: 7.0999043 | I11: 7.0999043 | J11: 7.0999043 | K11: 7.0999043 | L11: 7.0999043 | M11: 7.0999043 | N11: 7.0999043 | O11: 7.0999043 | P11: 7.0999043 | Q11: 7.0999043 | R11: 7.0999043 | S11: 7.0999043 | T11: 7.0999043 | U11: 7.0999043 | V11: 7.0999043 | W11: 7.0999043 | X11: 7.0999043 | Y11: 7.0999043 | Z11: =SUM(B11:Y11) -> 170.3977 | AA11: 30 | AB11: =+Z11*AA11 -> 5111.9311 | AD11: HABIL
A12: 46357 | B12: 7.0999043 | C12: 7.0999043 | D12: 7.0999043 | E12: 7.0999043 | F12: 7.0999043 | G12: 7.0999043 | H12: 7.0999043 | I12: 7.0999043 | J12: 7.0999043 | K12: 7.0999043 | L12: 7.0999043 | M12: 7.0999043 | N12: 7.0999043 | O12: 7.0999043 | P12: 7.0999043 | Q12: 7.0999043 | R12: 7.0999043 | S12: 7.0999043 | T12: 7.0999043 | U12: 7.0999043 | V12: 7.0999043 | W12: 7.0999043 | X12: 7.0999043 | Y12: 7.0999043 | Z12: =SUM(B12:Y12) -> 170.3977 | AA12: 31 | AB12: =+Z12*AA12 -> 5282.3288 | AD12: HABIL
A15: DEMANDA DIARIA ESTIMADA TOTAL [MWh]
A17: MES | B17: H1 | C17: H2 | D17: H3 | E17: H4 | F17: H5 | G17: H6 | H17: H7 | I17: H8 | J17: H9 | K17: H10 | L17: H11 | M17: H12 | N17: H13 | O17: H14 | P17: H15 | Q17: H16 | R17: H17 | S17: H18 | T17: H19 | U17: H20 | V17: H21 | W17: H22 | X17: H23 | Y17: H24 | Z17: TOTAL | AA17: Días
A18: =+A8 -> 46023 | B18: =+B8*$AA18 -> 220.09703 | C18: =+C8*$AA18 -> 220.09703 | D18: =+D8*$AA18 -> 220.09703 | E18: =+E8*$AA18 -> 220.09703 | F18: =+F8*$AA18 -> 220.09703 | G18: =+G8*$AA18 -> 220.09703 | H18: =+H8*$AA18 -> 220.09703 | I18: =+I8*$AA18 -> 220.09703 | ... Y18: =+Y8*$AA18 -> 220.09703 | Z18: =SUM(B18:Y18) -> 5282.3288 | AA18: =+AA8 -> 31
A19: =+A9 -> 46054 | B19: =+B9*$AA19 -> 198.79732 | C19: =+C9*$AA19 -> 198.79732 | D19: =+D9*$AA19 -> 198.79732 | E19: =+E9*$AA19 -> 198.79732 | F19: =+F9*$AA19 -> 198.79732 | G19: =+G9*$AA19 -> 198.79732 | H19: =+H9*$AA19 -> 198.79732 | I19: =+I9*$AA19 -> 198.79732 | ... Y19: =+Y9*$AA19 -> 198.79732 | Z19: =SUM(B19:Y19) -> 4771.1357 | AA19: =+AA9 -> 28
A20: =+A10 -> 46082 | B20: =+B10*$AA20 -> 220.09703 | C20: =+C10*$AA20 -> 220.09703 | D20: =+D10*$AA20 -> 220.09703 | E20: =+E10*$AA20 -> 220.09703 | F20: =+F10*$AA20 -> 220.09703 | G20: =+G10*$AA20 -> 220.09703 | H20: =+H10*$AA20 -> 220.09703 | I20: =+I10*$AA20 -> 220.09703 | ... Y20: =+Y10*$AA20 -> 220.09703 | Z20: =SUM(B20:Y20) -> 5282.3288 | AA20: =+AA10 -> 31
A21: =+A11 -> 46113 | B21: =+B11*$AA21 -> 212.99713 | C21: =+C11*$AA21 -> 212.99713 | D21: =+D11*$AA21 -> 212.99713 | E21: =+E11*$AA21 -> 212.99713 | F21: =+F11*$AA21 -> 212.99713 | G21: =+G11*$AA21 -> 212.99713 | H21: =+H11*$AA21 -> 212.99713 | I21: =+I11*$AA21 -> 212.99713 | ... Y21: =+Y11*$AA21 -> 212.99713 | Z21: =SUM(B21:Y21) -> 5111.9311 | AA21: =+AA11 -> 30
A22: =+A12 -> 46357 | B22: =+B12*$AA22 -> 220.09703 | C22: =+C12*$AA22 -> 220.09703 | D22: =+D12*$AA22 -> 220.09703 | E22: =+E12*$AA22 -> 220.09703 | F22: =+F12*$AA22 -> 220.09703 | G22: =+G12*$AA22 -> 220.09703 | H22: =+H12*$AA22 -> 220.09703 | I22: =+I12*$AA22 -> 220.09703 | ... Y22: =+Y12*$AA22 -> 220.09703 | Z22: =SUM(B22:Y22) -> 5282.3288 | AA22: =+AA12 -> 31

Sheet Oferta Producto No. 2 
D2: ANEXO No. 1 OFERTAS Y CANTIDADES
C3: OFERTA MERCANTIL IRREVOCABLE A LA EMPRESA DE ENERGIA DE PEREIRA S.A. ESP. INVITACIÓN PARA EL SUMINISTRO DE ENERGÍA ELÉCTRICA CON DESTINO AL MERCADO REGULADO CONVOCATORIA PÚBLICA No. 007-2025 - CP-EEPC2025-007
D4: PRODUCTO No. 2
C6: EMPRESA: XXXXXXXXXXXXXXXXXXXXXXXXXXXXXX
C7: REPRESENTANTE LEGAL: XXXXXXXXXXXXXXXXXXXXXXXXXXXXXX
C8: TIPO DE AGENTE: (COMERCIALIZADOR/GENERADOR)
C9: ="PRODUCTO OFERTADO: "&D4 -> PRODUCTO OFERTADO: PRODUCTO No. 2
C11: Las tarifas ofertadas están referidas en pesos constantes de septiembre de 2025 provisional
F13: ="Oferta " & PROPER(D4) -> Oferta Producto No. 2
F14: Periodo | G14: Energía requerida (MWh-mes) | H14: Energía ofertada (%) | I14: Energía ofertada (MWh-mes) | J14: Tarifa monomia ($/kWh)
A15: 22.85 | B15: 31 | F15: =+'Cantidades Producto No. 2'!A16 -> 46023 | G15: 9948.5347
F16: TOTAL | G16: =SUM(G15:G15) -> 9948.5347
B18: Notas
B20: (1) Oferta válida para la modalidad Pague lo Contratado.
B21: ="(2) Las cantidades se distribuyen de acuerdo a la curva del Anexo 1. Ofertas y Cantidades "& D4 &" de los Pliegos de Condiciones Definitivos" -> (2) Las cantidades se distribuyen de acuerdo a la curva del Anexo 1. Ofertas y Cantidades PRODUCTO No. 2 de los Pliegos de Condiciones Definitivos
B22: (3) La cantidad de energía es equivalente a un porcentaje de las cantidades de energía requerida por la Empresa de Energía de Pereira S.A. ESP. (para todo el año/para cada mes), de acuerdo con el Anexo No.1 Ofertas y Cantidades PRODUCTO No. 2 de los Pliegos Definitivos, que se aplicarán para todas las 24 horas del día de la curva establecida en dicho Anexo, presentando una tarifa para cada año sin ningún tipo de discriminación por mes, ni tipo de carga ni tipo de día.
B23: (4) Esta oferta NO presenta restricciones tales como adjudicación mínima o total u otras que no permitan la evaluación objetiva e integral del producto ofertado.
B24: (5) Los precios ofertados incluyen todos los pagos, cargos, impuestos, estampillas, etc., que el Proponente deba realizar ante cualquier entidad gubernamental, o empresa pública, privada o mixta para entregar la energía en la frontera con el Sistema de Transmisión Nacional – STN.
B25: (6) Las cantidades ofertadas están sujetas a la adjudicación en la misma proporción respecto a las cantidades ofertadas para todos y cada uno de los meses del año. Es decir, si la Empresa de Energía de Pereira decide adjudicar, por ejemplo, el 50% de lo ofertado en cualesquiera de los meses de alguno de los años, ese mismo porcentaje debe ser adjudicado en el resto de cada uno de los meses de ese año.

Sheet Cantidades Producto No. 2
A2: EMPRESA DE ENERGÍA DE PEREIRA S.A. E.S.P.
A3: PRODUCTO No. 2
A7: MES | B7: H1 | C7: H2 | D7: H3 | E7: H4 | F7: H5 | G7: H6 | H7: H7 | I7: H8 | J7: H9 | K7: H10 | L7: H11 | M7: H12 | N7: H13 | O7: H14 | P7: H15 | Q7: H16 | R7: H17 | S7: H18 | T7: H19 | U7: H20 | V7: H21 | W7: H22 | X7: H23 | Y7: H24 | Z7: TOTAL | AA7: Días | AD7: TIPO DE DÍA
A8: =+$A$16 -> 46023 | B8: 8.2120991 | C8: 6.8609861 | D8: 6.1350681 | E8: 5.8702146 | F8: 6.3302422 | G8: 7.9371759 | H8: 10.647549 | I8: 9.547444 | J8: 12.399414 | K8: 14.562553 | L8: 16.645062 | M8: 18.567155 | N8: 18.542821 | O8: 18.154042 | P8: 18.555004 | Q8: 18.451893 | R8: 17.825475 | S8: 21.092014 | T8: 21.748118 | U8: 22.493739 | V8: 21.093278 | W8: 18.880424 | X8: 15.426273 | Y8: 11.566794 | Z8: =SUM(B8:Y8) -> 347.54484 | AA8: =+SUMIFS('Cantidades Producto Base Curva'!$AA:$AA,'Cantidades Producto Base Curva'!$A:$A,'Cantidades Producto No. 2'!$A8,'Cantidades Producto Base Curva'!$AD:$AD,'Cantidades Producto No. 2'!AD8) -> 20 | AB8: =+Z8*AA8 -> 6950.8968 | AD8: HABIL
A9: =+$A$16 -> 46023 | B9: 8.475977 | C9: 7.0358861 | D9: 6.1877782 | E9: 5.7280093 | F9: 5.8918184 | G9: 6.7461214 | H9: 8.7855796 | I9: 7.7759924 | J9: 10.795828 | K9: 13.407887 | L9: 15.171179 | M9: 16.659926 | N9: 16.853198 | O9: 15.949727 | P9: 15.186154 | Q9: 14.86808 | R9: 14.329756 | S9: 18.580369 | T9: 19.858117 | U9: 20.427412 | V9: 18.972315 | W9: 16.959274 | X9: 14.293956 | Y9: 11.550473 | Z9: =SUM(B9:Y9) -> 310.49081 | AA9: =+SUMIFS('Cantidades Producto Base Curva'!$AA:$AA,'Cantidades Producto Base Curva'!$A:$A,'Cantidades Producto No. 2'!$A9,'Cantidades Producto Base Curva'!$AD:$AD,'Cantidades Producto No. 2'!AD9) -> 5 | AB9: =+Z9*AA9 -> 1552.4541 | AD9: SABADOS
A10: =+$A$16 -> 46023 | B10: 8.8293917 | C10: 7.400304 | D10: 6.2221306 | E10: 5.7546322 | F10: 5.4760726 | G10: 5.5752463 | H10: 6.2974088 | I10: 3.5879439 | J10: 5.3169644 | K10: 7.180656 | L10: 8.7680969 | M10: 10.217103 | N10: 11.21073 | O10: 11.310574 | P10: 10.863769 | Q10: 10.627386 | R10: 10.528423 | S10: 14.784947 | T10: 16.309043 | U10: 17.999909 | V10: 17.502928 | W10: 15.772977 | X10: 13.202472 | Y10: 10.613623 | Z10: =SUM(B10:Y10) -> 241.35273 | AA10: =+SUMIFS('Cantidades Producto Base Curva'!$AA:$AA,'Cantidades Producto Base Curva'!$A:$A,'Cantidades Producto No. 2'!$A10,'Cantidades Producto Base Curva'!$AD:$AD,'Cantidades Producto No. 2'!AD10) -> 5 | AB10: =+Z10*AA10 -> 1206.7637 | AD10: DOMINGOS Y FESTIVOS
A11: =+$A$16 -> 46023 | B11: 7.5948838 | C11: 6.1893175 | D11: 5.3045291 | E11: 4.7937996 | F11: 4.7817484 | G11: 5.2260155 | H11: 6.5238773 | I11: 4.0788137 | J11: 5.9558049 | K11: 8.1343676 | L11: 10.165882 | M11: 11.759661 | N11: 12.571548 | O11: 12.039335 | P11: 10.749574 | Q11: 10.193681 | R11: 10.350495 | S11: 15.354838 | T11: 17.068149 | U11: 17.923292 | V11: 16.747628 | W11: 14.575404 | X11: 11.607505 | Y11: 8.7301009 | Z11: =SUM(B11:Y11) -> 238.42025 | AA11: =+SUMIFS('Cantidades Producto Base Curva'!$AA:$AA,'Cantidades Producto Base Curva'!$A:$A,'Cantidades Producto No. 2'!$A11,'Cantidades Producto Base Curva'!$AD:$AD,'Cantidades Producto No. 2'!AD11) -> 1 | AB11: =+Z11*AA11 -> 238.42025 | AD11: LUNES FESTIVOS
A13: DEMANDA DIARIA ESTIMADA TOTAL [MWh]
A15: MES | B15: H1 | C15: H2 | D15: H3 | E15: H4 | F15: H5 | G15: H6 | H15: H7 | I15: H8 | J15: H9 | K15: H10 | L15: H11 | M15: H12 | N15: H13 | O15: H14 | P15: H15 | Q15: H16 | R15: H17 | S15: H18 | T15: H19 | U15: H20 | V15: H21 | W15: H22 | X15: H23 | Y15: H24 | Z15: TOTAL | AA15: Días
A16: 46023 | B16: =+B8*$AA$8+B9*$AA$9+B10*$AA$10+B11*$AA$11 -> 258.36371 | C16: =+C8*$AA$8+C9*$AA$9+C10*$AA$10+C11*$AA$11 -> 215.58999 | D16: =+D8*$AA$8+D9*$AA$9+D10*$AA$10+D11*$AA$11 -> 190.05544 | E16: =+E8*$AA$8+E9*$AA$9+E10*$AA$10+E11*$AA$11 -> 179.6113 | F16: =+F8*$AA$8+F9*$AA$9+F10*$AA$10+F11*$AA$11 -> 188.22605 | G16: =+G8*$AA$8+G9*$AA$9+G10*$AA$10+G11*$AA$11 -> 225.57637 | H16: =+H8*$AA$8+H9*$AA$9+H10*$AA$10+H11*$AA$11 -> 294.8898 | I16: =+I8*$AA$8+I9*$AA$9+I10*$AA$10+I11*$AA$11 -> 251.84737 | ... Y16: =+Y8*$AA$8+Y9*$AA$9+Y10*$AA$10+Y11*$AA$11 -> 350.88646 | Z16: =SUM(B16:Y16) -> 9948.5347 | AA16: =+AA8+AA9+AA10+AA11 -> 31 | AB16: =+AB8+AB9+AB10+AB11 -> 9948.5347

Sheet Cantidades Producto Base Curva
A2: EMPRESA DE ENERGÍA DE PEREIRA S.A. E.S.P.
A3: PRODUCTO No. 1
A5: DEMANDA DIARIA ESTIMADA DÍA HABIL [MWh]
A7: MES | B7: H1 | C7: H2 | D7: H3 | E7: H4 | F7: H5 | G7: H6 | H7: H7 | I7: H8 | J7: H9 | K7: H10 | L7: H11 | M7: H12 | N7: H13 | O7: H14 | P7: H15 | Q7: H16 | R7: H17 | S7: H18 | T7: H19 | U7: H20 | V7: H21 | W7: H22 | X7: H23 | Y7: H24 | Z7: TOTAL | AA7: Días
A8: 46023 | B8: 8.2120991 | C8: 6.8609861 | D8: 6.1350681 | E8: 5.8702146 | F8: 6.3302422 | G8: 7.9371759 | H8: 10.647549 | I8: 9.547444 | J8: 12.399414 | K8: 14.562553 | L8: 16.645062 | M8: 18.567155 | N8: 18.542821 | O8: 18.154042 | P8: 18.555004 | Q8: 18.451893 | R8: 17.825475 | S8: 21.092014 | T8: 21.748118 | U8: 22.493739 | V8: 21.093278 | W8: 18.880424 | X8: 15.426273 | Y8: 11.566794 | Z8: =SUM(B8:Y8) -> 347.54484 | AA8: 20 | AB8: =+Z8*AA8 -> 6950.8968 | AD8: HABIL
A9: 46054 | B9: 7.8819608 | C9: 6.6656545 | D9: 6.0035848 | E9: 5.8143698 | F9: 6.4917955 | G9: 9.1222298 | H9: 12.129901 | I9: 10.603465 | J9: 12.999574 | K9: 14.902383 | L9: 16.852415 | M9: 18.580539 | N9: 17.95087 | O9: 17.852802 | P9: 18.533781 | Q9: 18.595785 | R9: 18.02337 | S9: 20.485833 | T9: 20.406402 | U9: 21.60014 | V9: 20.579431 | W9: 18.367841 | X9: 14.783064 | Y9: 11.009176 | Z9: =SUM(B9:Y9) -> 346.23636 | AA9: 20 | AB9: =+Z9*AA9 -> 6924.7273 | AD9: HABIL
A10: 46082 | B10: 6.8492601 | C10: 5.7185345 | D10: 5.1587112 | E10: 4.9416408 | F10: 5.6033159 | G10: 8.0588741 | H10: 10.73943 | I10: 9.6931674 | J10: 11.96957 | K10: 13.634157 | L10: 15.496149 | M10: 17.045511 | N10: 16.651376 | O10: 16.34996 | P10: 16.87027 | Q10: 16.755643 | R10: 16.304559 | S10: 18.964393 | T10: 19.094227 | U10: 20.279073 | V10: 18.955173 | W10: 16.818566 | X10: 13.465822 | Y10: 9.9096936 | Z10: =SUM(B10:Y10) -> 315.32708 | AA10: 21 | AB10: =+Z10*AA10 -> 6621.8686 | AD10: HABIL
A11: 46113 | B11: 3.0620683 | C11: 1.9016416 | D11: 1.3434502 | E11: 1.1296269 | F11: 1.7837343 | G11: 3.9381656 | H11: 6.6457034 | I11: 5.8766448 | J11: 7.9431723 | K11: 10.146429 | L11: 11.816793 | M11: 13.329256 | N11: 12.965655 | O11: 12.424488 | P11: 12.403541 | Q11: 12.483407 | R11: 12.103502 | S11: 15.15748 | T11: 15.716177 | U11: 16.377227 | V11: 14.989731 | W11: 12.826714 | X11: 9.5266404 | Y11: 6.1472089 | Z11: =SUM(B11:Y11) -> 222.03846 | AA11: 20 | AB11: =+Z11*AA11 -> 4440.7691 | AD11: HABIL
A12: 46143 | B12: 0 | C12: 0 | D12: 0 | E12: 0 | F12: 0 | G12: 0 | H12: 0 | I12: 0 | J12: 0 | K12: 0 | L12: 0 | M12: 0 | N12: 0 | O12: 0 | P12: 0 | Q12: 0 | R12: 0 | S12: 0 | T12: 0 | U12: 0 | V12: 0 | W12: 0 | X12: 0 | Y12: 0 | Z12: =SUM(B12:Y12) -> 0 | AA12: 19 | AB12: =+Z12*AA12 -> 0 | AD12: HABIL
A13: 46174 | B13: 0 | C13: 0 | D13: 0 | E13: 0 | F13: 0 | G13: 0 | H13: 0 | I13: 0 | J13: 0 | K13: 0 | L13: 0 | M13: 0 | N13: 0 | O13: 0 | P13: 0 | Q13: 0 | R13: 0 | S13: 0 | T13: 0 | U13: 0 | V13: 0 | W13: 0 | X13: 0 | Y13: 0 | Z13: =SUM(B13:Y13) -> 0 | AA13: 19 | AB13: =+Z13*AA13 -> 0 | AD13: HABIL
A14: 46204 | B14: 0 | C14: 0 | D14: 0 | E14: 0 | F14: 0 | G14: 0 | H14: 0 | I14: 0 | J14: 0 | K14: 0 | L14: 0 | M14: 0 | N14: 0 | O14: 0 | P14: 0 | Q14: 0 | R14: 0 | S14: 0 | T14: 0 | U14: 0 | V14: 0 | W14: 0 | X14: 0 | Y14: 0 | Z14: =SUM(B14:Y14) -> 0 | AA14: 22 | AB14: =+Z14*AA14 -> 0 | AD14: HABIL
A15: 46235 | B15: 0 | C15: 0 | D15: 0 | E15: 0 | F15: 0 | G15: 0 | H15: 0 | I15: 0 | J15: 0 | K15: 0 | L15: 0 | M15: 0 | N15: 0 | O15: 0 | P15: 0 | Q15: 0 | R15: 0 | S15: 0 | T15: 0 | U15: 0 | V15: 0 | W15: 0 | X15: 0 | Y15: 0 | Z15: =SUM(B15:Y15) -> 0 | AA15: 19 | AB15: =+Z15*AA15 -> 0 | AD15: HABIL
A16: 46266 | B16: 0 | C16: 0 | D16: 0 | E16: 0 | F16: 0 | G16: 0 | H16: 0 | I16: 0 | J16: 0 | K16: 0 | L16: 0 | M16: 0 | N16: 0 | O16: 0 | P16: 0 | Q16: 0 | R16: 0 | S16: 0 | T16: 0 | U16: 0 | V16: 0 | W16: 0 | X16: 0 | Y16: 0 | Z16: =SUM(B16:Y16) -> 0 | AA16: 22 | AB16: =+Z16*AA16 -> 0 | AD16: HABIL
A17: 46296 | B17: 0 | C17: 0 | D17: 0 | E17: 0 | F17: 0 | G17: 0 | H17: 0 | I17: 0 | J17: 0 | K17: 0 | L17: 0 | M17: 0 | N17: 0 | O17: 0 | P17: 0 | Q17: 0 | R17: 0 | S17: 0 | T17: 0 | U17: 0 | V17: 0 | W17: 0 | X17: 0 | Y17: 0 | Z17: =SUM(B17:Y17) -> 0 | AA17: 21 | AB17: =+Z17*AA17 -> 0 | AD17: HABIL
A18: 46327 | B18: 6.656321 | C18: 5.5276423 | D18: 4.9181695 | E18: 4.7244654 | F18: 5.2422234 | G18: 6.670582 | H18: 9.5123457 | I18: 9.288104 | J18: 11.728907 | K18: 13.487989 | L18: 15.207692 | M18: 16.774779 | N18: 16.544387 | O18: 16.138986 | P18: 16.645021 | Q18: 16.457032 | R18: 16.034066 | S18: 19.493213 | T18: 20.131366 | U18: 19.458553 | V18: 18.058239 | W18: 15.826936 | X18: 12.591048 | Y18: 9.5298669 | Z18: =SUM(B18:Y18) -> 306.64794 | AA18: 19 | AB18: =+Z18*AA18 -> 5826.3108 | AD18: HABIL
A19: 46357 | B19: 3.521098 | C19: 2.1634146 | D19: 1.4475567 | E19: 1.1460153 | F19: 1.5179083 | G19: 2.6884096 | H19: 5.2906807 | I19: 5.0999321 | J19: 7.7929272 | K19: 9.5739619 | L19: 11.283668 | M19: 12.786984 | N19: 12.803268 | O19: 12.51054 | P19: 12.746428 | Q19: 12.55091 | R19: 11.957822 | S19: 14.759883 | T19: 15.89393 | U19: 15.810453 | V19: 14.460384 | W19: 12.581803 | X19: 9.7719612 | Y19: 6.8032136 | Z19: =SUM(B19:Y19) -> 216.96315 | AA19: 21 | AB19: =+Z19*AA19 -> 4556.2262 | AD19: HABIL
A21: DEMANDA DIARIA ESTIMADA DÍA SABADO [MWh]
A23: MES | B23: H1 | C23: H2 | D23: H3 | E23: H4 | F23: H5 | G23: H6 | H23: H7 | I23: H8 | J23: H9 | K23: H10 | L23: H11 | M23: H12 | N23: H13 | O23: H14 | P23: H15 | Q23: H16 | R23: H17 | S23: H18 | T23: H19 | U23: H20 | V23: H21 | W23: H22 | X23: H23 | Y23: H24 | Z23: TOTAL | AA23: Días
A24: =+A8 -> 46023 | B24: 8.475977 | C24: 7.0358861 | D24: 6.1877782 | E24: 5.7280093 | F24: 5.8918184 | G24: 6.7461214 | H24: 8.7855796 | I24: 7.7759924 | J24: 10.795828 | K24: 13.407887 | L24: 15.171179 | M24: 16.659926 | N24: 16.853198 | O24: 15.949727 | P24: 15.186154 | Q24: 14.86808 | R24: 14.329756 | S24: 18.580369 | T24: 19.858117 | U24: 20.427412 | V24: 18.972315 | W24: 16.959274 | X24: 14.293956 | Y24: 11.550473 | Z24: =SUM(B24:Y24) -> 310.49081 | AA24: 5 | AB24: =+Z24*AA24 -> 1552.4541 | AD24: SABADOS
A25: =+A9 -> 46054 | B25: 8.0465204 | C25: 6.7429663 | D25: 5.9969459 | E25: 5.6140093 | F25: 5.8270032 | G25: 6.9848018 | H25: 9.3844352 | I25: 8.4603243 | J25: 11.391435 | K25: 13.555425 | L25: 15.292843 | M25: 16.38599 | N25: 16.356434 | O25: 15.74434 | P25: 15.225466 | Q25: 14.912483 | R25: 14.566039 | S25: 18.218272 | T25: 18.832329 | U25: 20.213919 | V25: 18.902375 | W25: 17.059283 | X25: 14.384217 | Y25: 11.712919 | Z25: =SUM(B25:Y25) -> 309.81078 | AA25: 4 | AB25: =+Z25*AA25 -> 1239.2431 | AD25: SABADOS
A26: =+A10 -> 46082 | B26: 7.0453248 | C26: 5.7755825 | D26: 5.0765128 | E26: 4.7101857 | F26: 5.024182 | G26: 6.0689409 | H26: 8.0447722 | I26: 7.5558531 | J26: 10.426645 | K26: 12.33136 | L26: 13.916869 | M26: 15.365009 | N26: 15.307879 | O26: 14.337152 | P26: 13.672472 | Q26: 13.336652 | R26: 12.988591 | S26: 16.751607 | T26: 17.238044 | U26: 17.8937 | V26: 16.642162 | W26: 14.954642 | X26: 12.463236 | Y26: 9.9768152 | Z26: =SUM(B26:Y26) -> 276.90419 | AA26: 4 | AB26: =+Z26*AA26 -> 1107.6168 | AD26: SABADOS
A27: =+A11 -> 46113 | B27: 3.4154496 | C27: 2.0858245 | D27: 1.3193903 | E27: 0.93086334 | F27: 1.1386039 | G27: 1.6907592 | H27: 3.9716941 | I27: 3.6443195 | J27: 6.3673935 | K27: 8.4901969 | L27: 10.08446 | M27: 11.351628 | N27: 11.433228 | O27: 10.420118 | P27: 9.852769 | Q27: 9.5411052 | R27: 8.9815916 | S27: 12.656551 | T27: 13.651824 | U27: 14.375812 | V27: 13.129209 | W27: 11.345284 | X27: 8.9681614 | Y27: 6.5086894 | Z27: =SUM(B27:Y27) -> 185.35492 | AA27: 4 | AB27: =+Z27*AA27 -> 741.41969 | AD27: SABADOS
A28: =+A12 -> 46143 | B28: 0 | C28: 0 | D28: 0 | E28: 0 | F28: 0 | G28: 0 | H28: 0 | I28: 0 | J28: 0 | K28: 0 | L28: 0 | M28: 0 | N28: 0 | O28: 0 | P28: 0 | Q28: 0 | R28: 0 | S28: 0 | T28: 0 | U28: 0 | V28: 0 | W28: 0 | X28: 0 | Y28: 0 | Z28: =SUM(B28:Y28) -> 0 | AA28: 5 | AB28: =+Z28*AA28 -> 0 | AD28: SABADOS
A29: =+A13 -> 46174 | B29: 0 | C29: 0 | D29: 0 | E29: 0 | F29: 0 | G29: 0 | H29: 0 | I29: 0 | J29: 0 | K29: 0 | L29: 0 | M29: 0 | N29: 0 | O29: 0 | P29: 0 | Q29: 0 | R29: 0 | S29: 0 | T29: 0 | U29: 0 | V29: 0 | W29: 0 | X29: 0 | Y29: 0 | Z29: =SUM(B29:Y29) -> 0 | AA29: 4 | AB29: =+Z29*AA29 -> 0 | AD29: SABADOS
A30: =+A14 -> 46204 | B30: 0 | C30: 0 | D30: 0 | E30: 0 | F30: 0 | G30: 0 | H30: 0 | I30: 0 | J30: 0 | K30: 0 | L30: 0 | M30: 0 | N30: 0 | O30: 0 | P30: 0 | Q30: 0 | R30: 0 | S30: 0 | T30: 0 | U30: 0 | V30: 0 | W30: 0 | X30: 0 | Y30: 0 | Z30: =SUM(B30:Y30) -> 0 | AA30: 4 | AB30: =+Z30*AA30 -> 0 | AD30: SABADOS
A31: =+A15 -> 46235 | B31: 0 | C31: 0 | D31: 0 | E31: 0 | F31: 0 | G31: 0 | H31: 0 | I31: 0 | J31: 0 | K31: 0 | L31: 0 | M31: 0 | N31: 0 | O31: 0 | P31: 0 | Q31: 0 | R31: 0 | S31: 0 | T31: 0 | U31: 0 | V31: 0 | W31: 0 | X31: 0 | Y31: 0 | Z31: =SUM(B31:Y31) -> 0 | AA31: 5 | AB31: =+Z31*AA31 -> 0 | AD31: SABADOS
A32: =+A16 -> 46266 | B32: 0 | C32: 0 | D32: 0 | E32: 0 | F32: 0 | G32: 0 | H32: 0 | I32: 0 | J32: 0 | K32: 0 | L32: 0 | M32: 0 | N32: 0 | O32: 0 | P32: 0 | Q32: 0 | R32: 0 | S32: 0 | T32: 0 | U32: 0 | V32: 0 | W32: 0 | X32: 0 | Y32: 0 | Z32: =SUM(B32:Y32) -> 0 | AA32: 4 | AB32: =+Z32*AA32 -> 0 | AD32: SABADOS
A33: =+A17 -> 46296 | B33: 0 | C33: 0 | D33: 0 | E33: 0 | F33: 0 | G33: 0 | H33: 0 | I33: 0 | J33: 0 | K33: 0 | L33: 0 | M33: 0 | N33: 0 | O33: 0 | P33: 0 | Q33: 0 | R33: 0 | S33: 0 | T33: 0 | U33: 0 | V33: 0 | W33: 0 | X33: 0 | Y33: 0 | Z33: =SUM(B33:Y33) -> 0 | AA33: 5 | AB33: =+Z33*AA33 -> 0 | AD33: SABADOS
A34: =+A18 -> 46327 | B34: 6.8861274 | C34: 5.6527504 | D34: 4.9515701 | E34: 4.5823023 | F34: 4.8359813 | G34: 5.2799778 | H34: 7.7059397 | I34: 7.7293719 | J34: 10.458561 | K34: 12.43682 | L34: 14.062473 | M34: 15.454096 | N34: 15.371238 | O34: 14.375118 | P34: 13.622993 | Q34: 13.296748 | R34: 12.879151 | S34: 16.463739 | T34: 18.195592 | U34: 17.822356 | V34: 16.367902 | W34: 14.774094 | X34: 12.321436 | Y34: 9.8388508 | Z34: =SUM(B34:Y34) -> 275.36519 | AA34: 4 | AB34: =+Z34*AA34 -> 1101.4608 | AD34: SABADOS
A35: =+A19 -> 46357 | B35: 3.7104186 | C35: 2.3242857 | D35: 1.5189039 | E35: 1.0971686 | F35: 1.3399807 | G35: 1.9514161 | H35: 4.2504221 | I35: 4.0537467 | J35: 6.9184179 | K35: 8.94129 | L35: 10.508285 | M35: 11.891288 | N35: 11.841084 | O35: 10.767385 | P35: 9.8178458 | Q35: 9.3315749 | R35: 9.1122558 | S35: 12.943989 | T35: 14.411392 | U35: 14.225399 | V35: 12.827705 | W35: 11.063516 | X35: 8.6909331 | Y35: 6.2750118 | Z35: =SUM(B35:Y35) -> 189.81371 | AA35: 4 | AB35: =+Z35*AA35 -> 759.25486 | AD35: SABADOS
A37: DEMANDA DIARIA ESTIMADA DÍA DOMINGO Y FESTIVO DIFERENTE A LUNES [MWh]
A39: MES | B39: H1 | C39: H2 | D39: H3 | E39: H4 | F39: H5 | G39: H6 | H39: H7 | I39: H8 | J39: H9 | K39: H10 | L39: H11 | M39: H12 | N39: H13 | O39: H14 | P39: H15 | Q39: H16 | R39: H17 | S39: H18 | T39: H19 | U39: H20 | V39: H21 | W39: H22 | X39: H23 | Y39: H24 | Z39: TOTAL | AA39: Días
A40: =+A24 -> 46023 | B40: 8.8293917 | C40: 7.400304 | D40: 6.2221306 | E40: 5.7546322 | F40: 5.4760726 | G40: 5.5752463 | H40: 6.2974088 | I40: 3.5879439 | J40: 5.3169644 | K40: 7.180656 | L40: 8.7680969 | M40: 10.217103 | N40: 11.21073 | O40: 11.310574 | P40: 10.863769 | Q40: 10.627386 | R40: 10.528423 | S40: 14.784947 | T40: 16.309043 | U40: 17.999909 | V40: 17.502928 | W40: 15.772977 | X40: 13.202472 | Y40: 10.613623 | Z40: =SUM(B40:Y40) -> 241.35273 | AA40: 5 | AB40: =+Z40*AA40 -> 1206.7637 | AD40: DOMINGOS Y FESTIVOS
A41: =+A25 -> 46054 | B41: 8.5332034 | C41: 7.0864587 | D41: 6.0523803 | E41: 5.4960993 | F41: 5.4160439 | G41: 5.8054285 | H41: 6.8752684 | I41: 4.6864019 | J41: 6.7971584 | K41: 8.8020321 | L41: 10.027397 | M41: 11.33405 | N41: 11.964207 | O41: 11.649541 | P41: 10.901718 | Q41: 10.413532 | R41: 10.10973 | S41: 14.252079 | T41: 15.071942 | U41: 17.650553 | V41: 17.058154 | W41: 15.112302 | X41: 12.046179 | Y41: 9.0412017 | Z41: =SUM(B41:Y41) -> 242.18306 | AA41: 4 | AB41: =+Z41*AA41 -> 968.73224 | AD41: DOMINGOS Y FESTIVOS
A42: =+A26 -> 46082 | B42: 7.2541479 | C42: 5.927801 | D42: 5.1126019 | E42: 4.635743 | F42: 4.4870739 | G42: 4.8933762 | H42: 5.8131446 | I42: 3.9967857 | J42: 5.7989874 | K42: 7.5111777 | L42: 8.6112475 | M42: 9.6519031 | N42: 10.45229 | O42: 10.398816 | P42: 9.6909101 | Q42: 9.3642685 | R42: 9.3579536 | S42: 13.492546 | T42: 14.754205 | U42: 16.249564 | V42: 15.414969 | W42: 13.570441 | X42: 10.98617 | Y42: 8.3069233 | Z42: =SUM(B42:Y42) -> 215.73305 | AA42: 5 | AB42: =+Z42*AA42 -> 1078.6652 | AD42: DOMINGOS Y FESTIVOS
A43: =+A27 -> 46113 | B43: 3.197673 | C43: 1.8274181 | D43: 0.96975749 | E43: 0.51601693 | F43: 0.5057388 | G43: 0.51957181 | H43: 1.5666141 | I43: 0.14175091 | J43: 2.0317642 | K43: 3.844614 | L43: 5.2361422 | M43: 6.6371058 | N43: 7.3115273 | O43: 6.9587416 | P43: 6.5833363 | Q43: 5.7367802 | R43: 5.5318808 | S43: 9.7230442 | T43: 10.91146 | U43: 11.976699 | V43: 11.271205 | W43: 9.5885092 | X43: 7.0850991 | Y43: 4.6929222 | Z43: =SUM(B43:Y43) -> 124.36537 | AA43: 6 | AB43: =+Z43*AA43 -> 746.19223 | AD43: DOMINGOS Y FESTIVOS
A44: =+A28 -> 46143 | B44: 0 | C44: 0 | D44: 0 | E44: 0 | F44: 0 | G44: 0 | H44: 0 | I44: 0 | J44: 0 | K44: 0 | L44: 0 | M44: 0 | N44: 0 | O44: 0 | P44: 0 | Q44: 0 | R44: 0 | S44: 0 | T44: 0 | U44: 0 | V44: 0 | W44: 0 | X44: 0 | Y44: 0 | Z44: =SUM(B44:Y44) -> 0 | AA44: 6 | AB44: =+Z44*AA44 -> 0 | AD44: DOMINGOS Y FESTIVOS
A45: =+A29 -> 46174 | B45: 0 | C45: 0 | D45: 0 | E45: 0 | F45: 0 | G45: 0 | H45: 0 | I45: 0 | J45: 0 | K45: 0 | L45: 0 | M45: 0 | N45: 0 | O45: 0 | P45: 0 | Q45: 0 | R45: 0 | S45: 0 | T45: 0 | U45: 0 | V45: 0 | W45: 0 | X45: 0 | Y45: 0 | Z45: =SUM(B45:Y45) -> 0 | AA45: 4 | AB45: =+Z45*AA45 -> 0 | AD45: DOMINGOS Y FESTIVOS
A46: =+A30 -> 46204 | B46: 0 | C46: 0 | D46: 0 | E46: 0 | F46: 0 | G46: 0 | H46: 0 | I46: 0 | J46: 0 | K46: 0 | L46: 0 | M46: 0 | N46: 0 | O46: 0 | P46: 0 | Q46: 0 | R46: 0 | S46: 0 | T46: 0 | U46: 0 | V46: 0 | W46: 0 | X46: 0 | Y46: 0 | Z46: =SUM(B46:Y46) -> 0 | AA46: 4 | AB46: =+Z46*AA46 -> 0 | AD46: DOMINGOS Y FESTIVOS
A47: =+A31 -> 46235 | B47: 0 | C47: 0 | D47: 0 | E47: 0 | F47: 0 | G47: 0 | H47: 0 | I47: 0 | J47: 0 | K47: 0 | L47: 0 | M47: 0 | N47: 0 | O47: 0 | P47: 0 | Q47: 0 | R47: 0 | S47: 0 | T47: 0 | U47: 0 | V47: 0 | W47: 0 | X47: 0 | Y47: 0 | Z47: =SUM(B47:Y47) -> 0 | AA47: 6 | AB47: =+Z47*AA47 -> 0 | AD47: DOMINGOS Y FESTIVOS
...

Sheet Oferta Producto No. 3
D2: ANEXO No. 1 OFERTAS Y CANTIDADES
C3: OFERTA MERCANTIL IRREVOCABLE A LA EMPRESA DE ENERGIA DE PEREIRA S.A. ESP. INVITACIÓN PARA EL SUMINISTRO DE ENERGÍA ELÉCTRICA CON DESTINO AL MERCADO REGULADO CONVOCATORIA PÚBLICA No. 007-2025 - CP-EEPC2025-007
D4: PRODUCTO No. 3
C6: EMPRESA: XXXXXXXXXXXXXXXXXXXXXXXXXXXXXX
C7: REPRESENTANTE LEGAL: XXXXXXXXXXXXXXXXXXXXXXXXXXXXXX
C8: TIPO DE AGENTE: (COMERCIALIZADOR/GENERADOR)
C9: ="PRODUCTO OFERTADO: "&D4 -> PRODUCTO OFERTADO: PRODUCTO No. 3
C11: Las tarifas ofertadas están referidas en pesos constantes de septiembre de 2025 provisional
F13: ="Oferta " & PROPER(D4) -> Oferta Producto No. 3
F14: Periodo | G14: Energía requerida (MWh-mes) | H14: Energía ofertada (%) | I14: Energía ofertada (MWh-mes) | J14: Tarifa monomia ($/kWh)
A15: 22.85 | B15: 31 | F15: =+'Cantidades Producto No. 3'!A16 -> 46054 | G15: 9132.7027
F16: TOTAL | G16: 9132.7027
B18: Notas
B20: (1) Oferta válida para la modalidad Pague lo Contratado.
B21: ="(2) Las cantidades se distribuyen de acuerdo a la curva del Anexo 1. Ofertas y Cantidades "& D4 &" de los Pliegos de Condiciones Definitivos" -> (2) Las cantidades se distribuyen de acuerdo a la curva del Anexo 1. Ofertas y Cantidades PRODUCTO No. 3 de los Pliegos de Condiciones Definitivos
B22: (3) La cantidad de energía es equivalente a un porcentaje de las cantidades de energía requerida por la Empresa de Energía de Pereira S.A. ESP. (para todo el año/para cada mes), de acuerdo con el Anexo No.1 Ofertas y Cantidades PRODUCTO No. 3 de los Pliegos Definitivos, que se aplicarán para todas las 24 horas del día de la curva establecida en dicho Anexo, presentando una tarifa para cada año sin ningún tipo de discriminación por mes, ni tipo de carga ni tipo de día.
B23: (4) Esta oferta NO presenta restricciones tales como adjudicación mínima o total u otras que no permitan la evaluación objetiva e integral del producto ofertado.
B24: (5) Los precios ofertados incluyen todos los pagos, cargos, impuestos, estampillas, etc., que el Proponente deba realizar ante cualquier entidad gubernamental, o empresa pública, privada o mixta para entregar la energía en la frontera con el Sistema de Transmisión Nacional – STN.
B25: (6) Las cantidades ofertadas están sujetas a la adjudicación en la misma proporción respecto a las cantidades ofertadas para todos y cada uno de los meses del año. Es decir, si la Empresa de Energía de Pereira decide adjudicar, por ejemplo, el 50% de lo ofertado en cualesquiera de los meses de alguno de los años, ese mismo porcentaje debe ser adjudicado en el resto de cada uno de los meses de ese año.

Sheet Cantidades Producto No. 3
A2: EMPRESA DE ENERGÍA DE PEREIRA S.A. E.S.P.
A3: PRODUCTO No. 3
A7: MES | B7: H1 | C7: H2 | D7: H3 | E7: H4 | F7: H5 | G7: H6 | H7: H7 | I7: H8 | J7: H9 | K7: H10 | L7: H11 | M7: H12 | N7: H13 | O7: H14 | P7: H15 | Q7: H16 | R7: H17 | S7: H18 | T7: H19 | U7: H20 | V7: H21 | W7: H22 | X7: H23 | Y7: H24 | Z7: TOTAL | AA7: Días | AD7: TIPO DE DÍA
A8: =+$A$16 -> 46054 | B8: 7.8819608 | C8: 6.6656545 | D8: 6.0035848 | E8: 5.8143698 | F8: 6.4917955 | G8: 9.1222298 | H8: 12.129901 | I8: 10.603465 | J8: 12.999574 | K8: 14.902383 | L8: 16.852415 | M8: 18.580539 | N8: 17.95087 | O8: 17.852802 | P8: 18.533781 | Q8: 18.595785 | R8: 18.02337 | S8: 20.485833 | T8: 20.406402 | U8: 21.60014 | V8: 20.579431 | W8: 18.367841 | X8: 14.783064 | Y8: 11.009176 | Z8: =SUM(B8:Y8) -> 346.23636 | AA8: =+SUMIFS('Cantidades Producto Base Curva'!$AA:$AA,'Cantidades Producto Base Curva'!$A:$A,'Cantidades Producto No. 3'!$A8,'Cantidades Producto Base Curva'!$AD:$AD,'Cantidades Producto No. 3'!AD8) -> 20 | AB8: =+Z8*AA8 -> 6924.7273 | AD8: HABIL
A9: =+$A$16 -> 46054 | B9: 8.0465204 | C9: 6.7429663 | D9: 5.9969459 | E9: 5.6140093 | F9: 5.8270032 | G9: 6.9848018 | H9: 9.3844352 | I9: 8.4603243 | J9: 11.391435 | K9: 13.555425 | L9: 15.292843 | M9: 16.38599 | N9: 16.356434 | O9: 15.74434 | P9: 15.225466 | Q9: 14.912483 | R9: 14.566039 | S9: 18.218272 | T9: 18.832329 | U9: 20.213919 | V9: 18.902375 | W9: 17.059283 | X9: 14.384217 | Y9: 11.712919 | Z9: =SUM(B9:Y9) -> 309.81078 | AA9: =+SUMIFS('Cantidades Producto Base Curva'!$AA:$AA,'Cantidades Producto Base Curva'!$A:$A,'Cantidades Producto No. 3'!$A9,'Cantidades Producto Base Curva'!$AD:$AD,'Cantidades Producto No. 3'!AD9) -> 4 | AB9: =+Z9*AA9 -> 1239.2431 | AD9: SABADOS
A10: =+$A$16 -> 46054 | B10: 8.5332034 | C10: 7.0864587 | D10: 6.0523803 | E10: 5.4960993 | F10: 5.4160439 | G10: 5.8054285 | H10: 6.8752684 | I10: 4.6864019 | J10: 6.7971584 | K10: 8.8020321 | L10: 10.027397 | M10: 11.33405 | N10: 11.964207 | O10: 11.649541 | P10: 10.901718 | Q10: 10.413532 | R10: 10.10973 | S10: 14.252079 | T10: 15.071942 | U10: 17.650553 | V10: 17.058154 | W10: 15.112302 | X10: 12.046179 | Y10: 9.0412017 | Z10: =SUM(B10:Y10) -> 242.18306 | AA10: =+SUMIFS('Cantidades Producto Base Curva'!$AA:$AA,'Cantidades Producto Base Curva'!$A:$A,'Cantidades Producto No. 3'!$A10,'Cantidades Producto Base Curva'!$AD:$AD,'Cantidades Producto No. 3'!AD10) -> 4 | AB10: =+Z10*AA10 -> 968.73224 | AD10: DOMINGOS Y FESTIVOS
A11: =+$A$16 -> 46054 | B11: 13.268852 | C11: 11.284127 | D11: 9.9147185 | E11: 9.1499909 | F11: 9.0136581 | G11: 9.3670779 | H11: 10.197551 | I11: 8.2702414 | J11: 11.162809 | K11: 13.87005 | L11: 15.663989 | M11: 17.397619 | N11: 18.198763 | O11: 17.732594 | P11: 16.663752 | Q11: 15.961859 | R11: 15.531386 | S11: 20.476952 | T11: 22.798401 | U11: 26.085582 | V11: 25.315442 | W11: 22.744852 | X11: 18.524888 | Y11: 14.35517 | Z11: =SUM(B11:Y11) -> 372.95032 | AA11: =+SUMIFS('Cantidades Producto Base Curva'!$AA:$AA,'Cantidades Producto Base Curva'!$A:$A,'Cantidades Producto No. 3'!$A11,'Cantidades Producto Base Curva'!$AD:$AD,'Cantidades Producto No. 3'!AD11) -> 0 | AB11: =+Z11*AA11 -> 0 | AD11: LUNES FESTIVOS
A13: DEMANDA DIARIA ESTIMADA TOTAL [MWh]
A15: MES | B15: H1 | C15: H2 | D15: H3 | E15: H4 | F15: H5 | G15: H6 | H15: H7 | I15: H8 | J15: H9 | K15: H10 | L15: H11 | M15: H12 | N15: H13 | O15: H14 | P15: H15 | Q15: H16 | R15: H17 | S15: H18 | T15: H19 | U15: H20 | V15: H21 | W15: H22 | X15: H23 | Y15: H24 | Z15: TOTAL | AA15: Días
A16: 46054 | B16: =+B8*$AA$8+B9*$AA$9+B10*$AA$10+B11*$AA$11 -> 223.95811 | C16: =+C8*$AA$8+C9*$AA$9+C10*$AA$10+C11*$AA$11 -> 188.63079 | D16: =+D8*$AA$8+D9*$AA$9+D10*$AA$10+D11*$AA$11 -> 168.269 | E16: =+E8*$AA$8+E9*$AA$9+E10*$AA$10+E11*$AA$11 -> 160.72783 | F16: =+F8*$AA$8+F9*$AA$9+F10*$AA$10+F11*$AA$11 -> 174.8081 | G16: =+G8*$AA$8+G9*$AA$9+G10*$AA$10+G11*$AA$11 -> 233.60552 | H16: =+H8*$AA$8+H9*$AA$9+H10*$AA$10+H11*$AA$11 -> 307.63683 | I16: =+I8*$AA$8+I9*$AA$9+I10*$AA$10+I11*$AA$11 -> 264.65621 | ... Y16: =+Y8*$AA$8+Y9*$AA$9+Y10*$AA$10+Y11*$AA$11 -> 303.20001 | Z16: =SUM(B16:Y16) -> 9132.7027 | AA16: =+AA8+AA9+AA10+AA11 -> 28 | AB16: =+AB8+AB9+AB10+AB11 -> 9132.7027 | AC16: =+AB16-'Oferta Producto No. 3'!G15 -> 0

Sheet Oferta Producto No. 4
D2: ANEXO No. 1 OFERTAS Y CANTIDADES
C3: OFERTA MERCANTIL IRREVOCABLE A LA EMPRESA DE ENERGIA DE PEREIRA S.A. ESP. INVITACIÓN PARA EL SUMINISTRO DE ENERGÍA ELÉCTRICA CON DESTINO AL MERCADO REGULADO CONVOCATORIA PÚBLICA No. 007-2025 - CP-EEPC2025-007
D4: PRODUCTO No. 4
C6: EMPRESA: XXXXXXXXXXXXXXXXXXXXXXXXXXXXXX
C7: REPRESENTANTE LEGAL: XXXXXXXXXXXXXXXXXXXXXXXXXXXXXX
C8: TIPO DE AGENTE: (COMERCIALIZADOR/GENERADOR)
C9: ="PRODUCTO OFERTADO: "&D4 -> PRODUCTO OFERTADO: PRODUCTO No. 4
C11: Las tarifas ofertadas están referidas en pesos constantes de septiembre de 2025 provisional
F13: ="Oferta " & PROPER(D4) -> Oferta Producto No. 4
F14: Periodo | G14: Energía requerida (MWh-mes) | H14: Energía ofertada (%) | I14: Energía ofertada (MWh-mes) | J14: Tarifa monomia ($/kWh)
A15: 22.85 | B15: 31 | F15: =+'Cantidades Producto No. 4'!A16 -> 46082 | G15: 9027.5021
F16: TOTAL | G16: 9027.5021
B18: Notas
B20: (1) Oferta válida para la modalidad Pague lo Contratado.
B21: ="(2) Las cantidades se distribuyen de acuerdo a la curva del Anexo 1. Ofertas y Cantidades "& D4 &" de los Pliegos de Condiciones Definitivos" -> (2) Las cantidades se distribuyen de acuerdo a la curva del Anexo 1. Ofertas y Cantidades PRODUCTO No. 4 de los Pliegos de Condiciones Definitivos
B22: (3) La cantidad de energía es equivalente a un porcentaje de las cantidades de energía requerida por la Empresa de Energía de Pereira S.A. ESP. (para todo el año/para cada mes), de acuerdo con el Anexo No.1 Ofertas y Cantidades PRODUCTO No. 4 de los Pliegos Definitivos, que se aplicarán para todas las 24 horas del día de la curva establecida en dicho Anexo, presentando una tarifa para cada año sin ningún tipo de discriminación por mes, ni tipo de carga ni tipo de día.
B23: (4) Esta oferta NO presenta restricciones tales como adjudicación mínima o total u otras que no permitan la evaluación objetiva e integral del producto ofertado.
B24: (5) Los precios ofertados incluyen todos los pagos, cargos, impuestos, estampillas, etc., que el Proponente deba realizar ante cualquier entidad gubernamental, o empresa pública, privada o mixta para entregar la energía en la frontera con el Sistema de Transmisión Nacional – STN.
B25: (6) Las cantidades ofertadas están sujetas a la adjudicación en la misma proporción respecto a las cantidades ofertadas para todos y cada uno de los meses del año. Es decir, si la Empresa de Energía de Pereira decide adjudicar, por ejemplo, el 50% de lo ofertado en cualesquiera de los meses de alguno de los años, ese mismo porcentaje debe ser adjudicado en el resto de cada uno de los meses de ese año.

Sheet Cantidades Producto No. 4
A2: EMPRESA DE ENERGÍA DE PEREIRA S.A. E.S.P.
A3: PRODUCTO No. 4
A7: MES | B7: H1 | C7: H2 | D7: H3 | E7: H4 | F7: H5 | G7: H6 | H7: H7 | I7: H8 | J7: H9 | K7: H10 | L7: H11 | M7: H12 | N7: H13 | O7: H14 | P7: H15 | Q7: H16 | R7: H17 | S7: H18 | T7: H19 | U7: H20 | V7: H21 | W7: H22 | X7: H23 | Y7: H24 | Z7: TOTAL | AA7: Días | AD7: TIPO DE DÍA
A8: =+$A$16 -> 46082 | B8: 6.8492601 | C8: 5.7185345 | D8: 5.1587112 | E8: 4.9416408 | F8: 5.6033159 | G8: 8.0588741 | H8: 10.73943 | I8: 9.6931674 | J8: 11.96957 | K8: 13.634157 | L8: 15.496149 | M8: 17.045511 | N8: 16.651376 | O8: 16.34996 | P8: 16.87027 | Q8: 16.755643 | R8: 16.304559 | S8: 18.964393 | T8: 19.094227 | U8: 20.279073 | V8: 18.955173 | W8: 16.818566 | X8: 13.465822 | Y8: 9.9096936 | Z8: =SUM(B8:Y8) -> 315.32708 | AA8: =+SUMIFS('Cantidades Producto Base Curva'!$AA:$AA,'Cantidades Producto Base Curva'!$A:$A,'Cantidades Producto No. 4'!$A8,'Cantidades Producto Base Curva'!$AD:$AD,'Cantidades Producto No. 4'!AD8) -> 21 | AB8: =+Z8*AA8 -> 6621.8686 | AD8: HABIL
A9: =+$A$16 -> 46082 | B9: 7.0453248 | C9: 5.7755825 | D9: 5.0765128 | E9: 4.7101857 | F9: 5.024182 | G9: 6.0689409 | H9: 8.0447722 | I9: 7.5558531 | J9: 10.426645 | K9: 12.33136 | L9: 13.916869 | M9: 15.365009 | N9: 15.307879 | O9: 14.337152 | P9: 13.672472 | Q9: 13.336652 | R9: 12.988591 | S9: 16.751607 | T9: 17.238044 | U9: 17.8937 | V9: 16.642162 | W9: 14.954642 | X9: 12.463236 | Y9: 9.9768152 | Z9: =SUM(B9:Y9) -> 276.90419 | AA9: =+SUMIFS('Cantidades Producto Base Curva'!$AA:$AA,'Cantidades Producto Base Curva'!$A:$A,'Cantidades Producto No. 4'!$A9,'Cantidades Producto Base Curva'!$AD:$AD,'Cantidades Producto No. 4'!AD9) -> 4 | AB9: =+Z9*AA9 -> 1107.6168 | AD9: SABADOS
A10: =+$A$16 -> 46082 | B10: 7.2541479 | C10: 5.927801 | D10: 5.1126019 | E10: 4.635743 | F10: 4.4870739 | G10: 4.8933762 | H10: 5.8131446 | I10: 3.9967857 | J10: 5.7989874 | K10: 7.5111777 | L10: 8.6112475 | M10: 9.6519031 | N10: 10.45229 | O10: 10.398816 | P10: 9.6909101 | Q10: 9.3642685 | R10: 9.3579536 | S10: 13.492546 | T10: 14.754205 | U10: 16.249564 | V10: 15.414969 | W10: 13.570441 | X10: 10.98617 | Y10: 8.3069233 | Z10: =SUM(B10:Y10) -> 215.73305 | AA10: =+SUMIFS('Cantidades Producto Base Curva'!$AA:$AA,'Cantidades Producto Base Curva'!$A:$A,'Cantidades Producto No. 4'!$A10,'Cantidades Producto Base Curva'!$AD:$AD,'Cantidades Producto No. 4'!AD10) -> 5 | AB10: =+Z10*AA10 -> 1078.6652 | AD10: DOMINGOS Y FESTIVOS
A11: =+$A$16 -> 46082 | B11: 6.5485993 | C11: 5.3393524 | D11: 4.5980779 | E11: 4.1610448 | F11: 4.0357364 | G11: 4.4640037 | H11: 5.3244845 | I11: 3.9326505 | J11: 6.0791133 | K11: 7.8315753 | L11: 9.3229926 | M11: 10.68383 | N11: 11.141456 | O11: 10.883165 | P11: 10.421277 | Q11: 10.008038 | R11: 9.9906835 | S11: 14.08266 | T11: 15.158246 | U11: 16.552511 | V11: 15.888926 | W11: 13.989318 | X11: 10.790599 | Y11: 8.1231602 | Z11: =SUM(B11:Y11) -> 219.3515 | AA11: =+SUMIFS('Cantidades Producto Base Curva'!$AA:$AA,'Cantidades Producto Base Curva'!$A:$A,'Cantidades Producto No. 4'!$A11,'Cantidades Producto Base Curva'!$AD:$AD,'Cantidades Producto No. 4'!AD11) -> 1 | AB11: =+Z11*AA11 -> 219.3515 | AD11: LUNES FESTIVOS
A13: DEMANDA DIARIA ESTIMADA TOTAL [MWh]
A15: MES | B15: H1 | C15: H2 | D15: H3 | E15: H4 | F15: H5 | G15: H6 | H15: H7 | I15: H8 | J15: H9 | K15: H10 | L15: H11 | M15: H12 | N15: H13 | O15: H14 | P15: H15 | Q15: H16 | R15: H17 | S15: H18 | T15: H19 | U15: H20 | V15: H21 | W15: H22 | X15: H23 | Y15: H24 | Z15: TOTAL | AA15: Días
A16: 46082 | B16: =+B8*$AA$8+B9*$AA$9+B10*$AA$10+B11*$AA$11 -> 214.8351 | C16: =+C8*$AA$8+C9*$AA$9+C10*$AA$10+C11*$AA$11 -> 178.16991 | D16: =+D8*$AA$8+D9*$AA$9+D10*$AA$10+D11*$AA$11 -> 158.80007 | E16: =+E8*$AA$8+E9*$AA$9+E10*$AA$10+E11*$AA$11 -> 149.95496 | F16: =+F8*$AA$8+F9*$AA$9+F10*$AA$10+F11*$AA$11 -> 164.23747 | G16: =+G8*$AA$8+G9*$AA$9+G10*$AA$10+G11*$AA$11 -> 222.443 | H16: =+H8*$AA$8+H9*$AA$9+H10*$AA$10+H11*$AA$11 -> 292.09734 | I16: =+I8*$AA$8+I9*$AA$9+I10*$AA$10+I11*$AA$11 -> 257.69651 | ... Y16: =+Y8*$AA$8+Y9*$AA$9+Y10*$AA$10+Y11*$AA$11 -> 297.6686 | Z16: =SUM(B16:Y16) -> 9027.5021 | AA16: =+AA8+AA9+AA10+AA11 -> 31 | AB16: =+AB8+AB9+AB10+AB11 -> 9027.5021 | AC16: =+AB16-'Oferta Producto No. 4'!G15 -> 0

Sheet Oferta Producto No. 5
D2: ANEXO No. 1 OFERTAS Y CANTIDADES
C3: OFERTA MERCANTIL IRREVOCABLE A LA EMPRESA DE ENERGIA DE PEREIRA S.A. ESP. INVITACIÓN PARA EL SUMINISTRO DE ENERGÍA ELÉCTRICA CON DESTINO AL MERCADO REGULADO CONVOCATORIA PÚBLICA No. 007-2025 - CP-EEPC2025-007
D4: PRODUCTO No. 5
C6: EMPRESA: XXXXXXXXXXXXXXXXXXXXXXXXXXXXXX
C7: REPRESENTANTE LEGAL: XXXXXXXXXXXXXXXXXXXXXXXXXXXXXX
C8: TIPO DE AGENTE: (COMERCIALIZADOR/GENERADOR)
C9: ="PRODUCTO OFERTADO: "&D4 -> PRODUCTO OFERTADO: PRODUCTO No. 5
C11: Las tarifas ofertadas están referidas en pesos constantes de septiembre de 2025 provisional
F13: ="Oferta " & PROPER(D4) -> Oferta Producto No. 5
F14: Periodo | G14: Energía requerida (MWh-mes) | H14: Energía ofertada (%) | I14: Energía ofertada (MWh-mes) | J14: Tarifa monomia ($/kWh)
A15: 22.85 | B15: 31 | F15: =+'Cantidades Producto No. 5'!A16 -> 46113 | G15: 5928.3811
F16: TOTAL | G16: 5928.3811
B18: Notas
B20: (1) Oferta válida para la modalidad Pague lo Contratado.
B21: ="(2) Las cantidades se distribuyen de acuerdo a la curva del Anexo 1. Ofertas y Cantidades "& D4 &" de los Pliegos de Condiciones Definitivos" -> (2) Las cantidades se distribuyen de acuerdo a la curva del Anexo 1. Ofertas y Cantidades PRODUCTO No. 5 de los Pliegos de Condiciones Definitivos
B22: (3) La cantidad de energía es equivalente a un porcentaje de las cantidades de energía requerida por la Empresa de Energía de Pereira S.A. ESP. (para todo el año/para cada mes), de acuerdo con el Anexo No.1 Ofertas y Cantidades PRODUCTO No. 5 de los Pliegos Definitivos, que se aplicarán para todas las 24 horas del día de la curva establecida en dicho Anexo, presentando una tarifa para cada año sin ningún tipo de discriminación por mes, ni tipo de carga ni tipo de día.
B23: (4) Esta oferta NO presenta restricciones tales como adjudicación mínima o total u otras que no permitan la evaluación objetiva e integral del producto ofertado.
B24: (5) Los precios ofertados incluyen todos los pagos, cargos, impuestos, estampillas, etc., que el Proponente deba realizar ante cualquier entidad gubernamental, o empresa pública, privada o mixta para entregar la energía en la frontera con el Sistema de Transmisión Nacional – STN.
B25: (6) Las cantidades ofertadas están sujetas a la adjudicación en la misma proporción respecto a las cantidades ofertadas para todos y cada uno de los meses del año. Es decir, si la Empresa de Energía de Pereira decide adjudicar, por ejemplo, el 50% de lo ofertado en cualesquiera de los meses de alguno de los años, ese mismo porcentaje debe ser adjudicado en el resto de cada uno de los meses de ese año.

Sheet Cantidades Producto No. 5
A2: EMPRESA DE ENERGÍA DE PEREIRA S.A. E.S.P.
A3: PRODUCTO No. 5
A7: MES | B7: H1 | C7: H2 | D7: H3 | E7: H4 | F7: H5 | G7: H6 | H7: H7 | I7: H8 | J7: H9 | K7: H10 | L7: H11 | M7: H12 | N7: H13 | O7: H14 | P7: H15 | Q7: H16 | R7: H17 | S7: H18 | T7: H19 | U7: H20 | V7: H21 | W7: H22 | X7: H23 | Y7: H24 | Z7: TOTAL | AA7: Días | AD7: TIPO DE DÍA
A8: =+$A$16 -> 46113 | B8: 3.0620683 | C8: 1.9016416 | D8: 1.3434502 | E8: 1.1296269 | F8: 1.7837343 | G8: 3.9381656 | H8: 6.6457034 | I8: 5.8766448 | J8: 7.9431723 | K8: 10.146429 | L8: 11.816793 | M8: 13.329256 | N8: 12.965655 | O8: 12.424488 | P8: 12.403541 | Q8: 12.483407 | R8: 12.103502 | S8: 15.15748 | T8: 15.716177 | U8: 16.377227 | V8: 14.989731 | W8: 12.826714 | X8: 9.5266404 | Y8: 6.1472089 | Z8: =SUM(B8:Y8) -> 222.03846 | AA8: =+SUMIFS('Cantidades Producto Base Curva'!$AA:$AA,'Cantidades Producto Base Curva'!$A:$A,'Cantidades Producto No. 5'!$A8,'Cantidades Producto Base Curva'!$AD:$AD,'Cantidades Producto No. 5'!AD8) -> 20 | AB8: =+Z8*AA8 -> 4440.7691 | AD8: HABIL
A9: =+$A$16 -> 46113 | B9: 3.4154496 | C9: 2.0858245 | D9: 1.3193903 | E9: 0.93086334 | F9: 1.1386039 | G9: 1.6907592 | H9: 3.9716941 | I9: 3.6443195 | J9: 6.3673935 | K9: 8.4901969 | L9: 10.08446 | M9: 11.351628 | N9: 11.433228 | O9: 10.420118 | P9: 9.852769 | Q9: 9.5411052 | R9: 8.9815916 | S9: 12.656551 | T9: 13.651824 | U9: 14.375812 | V9: 13.129209 | W9: 11.345284 | X9: 8.9681614 | Y9: 6.5086894 | Z9: =SUM(B9:Y9) -> 185.35492 | AA9: =+SUMIFS('Cantidades Producto Base Curva'!$AA:$AA,'Cantidades Producto Base Curva'!$A:$A,'Cantidades Producto No. 5'!$A9,'Cantidades Producto Base Curva'!$AD:$AD,'Cantidades Producto No. 5'!AD9) -> 4 | AB9: =+Z9*AA9 -> 741.41969 | AD9: SABADOS
A10: =+$A$16 -> 46113 | B10: 3.197673 | C10: 1.8274181 | D10: 0.96975749 | E10: 0.51601693 | F10: 0.5057388 | G10: 0.51957181 | H10: 1.5666141 | I10: 0.14175091 | J10: 2.0317642 | K10: 3.844614 | L10: 5.2361422 | M10: 6.6371058 | N10: 7.3115273 | O10: 6.9587416 | P10: 6.5833363 | Q10: 5.7367802 | R10: 5.5318808 | S10: 9.7230442 | T10: 10.91146 | U10: 11.976699 | V10: 11.271205 | W10: 9.5885092 | X10: 7.0850991 | Y10: 4.6929222 | Z10: =SUM(B10:Y10) -> 124.36537 | AA10: =+SUMIFS('Cantidades Producto Base Curva'!$AA:$AA,'Cantidades Producto Base Curva'!$A:$A,'Cantidades Producto No. 5'!$A10,'Cantidades Producto Base Curva'!$AD:$AD,'Cantidades Producto No. 5'!AD10) -> 6 | AB10: =+Z10*AA10 -> 746.19223 | AD10: DOMINGOS Y FESTIVOS
A11: =+$A$16 -> 46113 | B11: 11.87046 | C11: 9.9340514 | D11: 8.7248953 | E11: 8.0512589 | F11: 7.9805859 | G11: 7.9556202 | H11: 8.7459927 | I11: 7.5975837 | J11: 10.310164 | K11: 12.860371 | L11: 14.846678 | M11: 16.697416 | N11: 17.553775 | O11: 17.039601 | P11: 16.324875 | Q11: 15.257233 | R11: 14.927501 | S11: 19.961513 | T11: 22.726856 | U11: 24.536228 | V11: 23.644223 | W11: 21.303066 | X11: 17.58955 | Y11: 13.972602 | Z11: =SUM(B11:Y11) -> 350.4121 | AA11: =+SUMIFS('Cantidades Producto Base Curva'!$AA:$AA,'Cantidades Producto Base Curva'!$A:$A,'Cantidades Producto No. 5'!$A11,'Cantidades Producto Base Curva'!$AD:$AD,'Cantidades Producto No. 5'!AD11) -> 0 | AB11: =+Z11*AA11 -> 0 | AD11: LUNES FESTIVOS
A13: DEMANDA DIARIA ESTIMADA TOTAL [MWh]
A15: MES | B15: H1 | C15: H2 | D15: H3 | E15: H4 | F15: H5 | G15: H6 | H15: H7 | I15: H8 | J15: H9 | K15: H10 | L15: H11 | M15: H12 | N15: H13 | O15: H14 | P15: H15 | Q15: H16 | R15: H17 | S15: H18 | T15: H19 | U15: H20 | V15: H21 | W15: H22 | X15: H23 | Y15: H24 | Z15: TOTAL | AA15: Días
A16: 46113 | B16: =+B8*$AA$8+B9*$AA$9+B10*$AA$10+B11*$AA$11 -> 94.089202 | C16: =+C8*$AA$8+C9*$AA$9+C10*$AA$10+C11*$AA$11 -> 57.340639 | D16: =+D8*$AA$8+D9*$AA$9+D10*$AA$10+D11*$AA$11 -> 37.96511 | E16: =+E8*$AA$8+E9*$AA$9+E10*$AA$10+E11*$AA$11 -> 29.412094 | F16: =+F8*$AA$8+F9*$AA$9+F10*$AA$10+F11*$AA$11 -> 43.263534 | G16: =+G8*$AA$8+G9*$AA$9+G10*$AA$10+G11*$AA$11 -> 88.643779 | H16: =+H8*$AA$8+H9*$AA$9+H10*$AA$10+H11*$AA$11 -> 158.20053 | I16: =+I8*$AA$8+I9*$AA$9+I10*$AA$10+I11*$AA$11 -> 132.96068 | ... Y16: =+Y8*$AA$8+Y9*$AA$9+Y10*$AA$10+Y11*$AA$11 -> 177.13647 | Z16: =SUM(B16:Y16) -> 5928.3811 | AA16: =+AA8+AA9+AA10+AA11 -> 30 | AB16: =+AB8+AB9+AB10+AB11 -> 5928.3811 | AC16: =+AB16-'Oferta Producto No. 5'!G15 -> 0

Sheet Oferta Producto No. 6
D2: ANEXO No. 1 OFERTAS Y CANTIDADES
C3: OFERTA MERCANTIL IRREVOCABLE A LA EMPRESA DE ENERGIA DE PEREIRA S.A. ESP. INVITACIÓN PARA EL SUMINISTRO DE ENERGÍA ELÉCTRICA CON DESTINO AL MERCADO REGULADO CONVOCATORIA PÚBLICA No. 007-2025 - CP-EEPC2025-007
D4: PRODUCTO No. 6
C6: EMPRESA: XXXXXXXXXXXXXXXXXXXXXXXXXXXXXX
C7: REPRESENTANTE LEGAL: XXXXXXXXXXXXXXXXXXXXXXXXXXXXXX
C8: TIPO DE AGENTE: (COMERCIALIZADOR/GENERADOR)
C9: ="PRODUCTO OFERTADO: "&D4 -> PRODUCTO OFERTADO: PRODUCTO No. 6
C11: Las tarifas ofertadas están referidas en pesos constantes de septiembre de 2025 provisional
F13: ="Oferta " & PROPER(D4) -> Oferta Producto No. 6
F14: Periodo | G14: Energía requerida (MWh-mes) | H14: Energía ofertada (%) | I14: Energía ofertada (MWh-mes) | J14: Tarifa monomia ($/kWh)
A15: 22.85 | B15: 31 | F15: =+'Cantidades Producto No. 6'!A16 -> 46327 | G15: =+_xlfn.XLOOKUP(F15,'[1]Oferta Producto Base Curva'!$F$15:$F$26,'[1]Oferta Producto Base Curva'!$G$15:$G$26) -> 8435.6107
F16: TOTAL | G16: =SUM(G15:G15) -> 8435.6107
B18: Notas
B20: (1) Oferta válida para la modalidad Pague lo Contratado.
B21: ="(2) Las cantidades se distribuyen de acuerdo a la curva del Anexo 1. Ofertas y Cantidades "& D4 &" de los Pliegos de Condiciones Definitivos" -> (2) Las cantidades se distribuyen de acuerdo a la curva del Anexo 1. Ofertas y Cantidades PRODUCTO No. 6 de los Pliegos de Condiciones Definitivos
B22: (3) La cantidad de energía es equivalente a un porcentaje de las cantidades de energía requerida por la Empresa de Energía de Pereira S.A. ESP. (para todo el año/para cada mes), de acuerdo con el Anexo No.1 Ofertas y Cantidades PRODUCTO No. 6 de los Pliegos Definitivos, que se aplicarán para todas las 24 horas del día de la curva establecida en dicho Anexo, presentando una tarifa para cada año sin ningún tipo de discriminación por mes, ni tipo de carga ni tipo de día.
B23: (4) Esta oferta NO presenta restricciones tales como adjudicación mínima o total u otras que no permitan la evaluación objetiva e integral del producto ofertado.
B24: (5) Los precios ofertados incluyen todos los pagos, cargos, impuestos, estampillas, etc., que el Proponente deba realizar ante cualquier entidad gubernamental, o empresa pública, privada o mixta para entregar la energía en la frontera con el Sistema de Transmisión Nacional – STN.
B25: (6) Las cantidades ofertadas están sujetas a la adjudicación en la misma proporción respecto a las cantidades ofertadas para todos y cada uno de los meses del año. Es decir, si la Empresa de Energía de Pereira decide adjudicar, por ejemplo, el 50% de lo ofertado en cualesquiera de los meses de alguno de los años, ese mismo porcentaje debe ser adjudicado en el resto de cada uno de los meses de ese año.

Sheet Cantidades Producto No. 6
A2: EMPRESA DE ENERGÍA DE PEREIRA S.A. E.S.P.
A3: PRODUCTO No. 6
A7: MES | B7: H1 | C7: H2 | D7: H3 | E7: H4 | F7: H5 | G7: H6 | H7: H7 | I7: H8 | J7: H9 | K7: H10 | L7: H11 | M7: H12 | N7: H13 | O7: H14 | P7: H15 | Q7: H16 | R7: H17 | S7: H18 | T7: H19 | U7: H20 | V7: H21 | W7: H22 | X7: H23 | Y7: H24 | Z7: TOTAL | AA7: Días | AD7: TIPO DE DÍA
A8: =+$A$16 -> 46327 | B8: 6.656321 | C8: 5.5276423 | D8: 4.9181695 | E8: 4.7244654 | F8: 5.2422234 | G8: 6.670582 | H8: 9.5123457 | I8: 9.288104 | J8: 11.728907 | K8: 13.487989 | L8: 15.207692 | M8: 16.774779 | N8: 16.544387 | O8: 16.138986 | P8: 16.645021 | Q8: 16.457032 | R8: 16.034066 | S8: 19.493213 | T8: 20.131366 | U8: 19.458553 | V8: 18.058239 | W8: 15.826936 | X8: 12.591048 | Y8: 9.5298669 | Z8: =SUM(B8:Y8) -> 306.64794 | AA8: =+SUMIFS('Cantidades Producto Base Curva'!$AA:$AA,'Cantidades Producto Base Curva'!$A:$A,'Cantidades Producto No. 6'!$A8,'Cantidades Producto Base Curva'!$AD:$AD,'Cantidades Producto No. 6'!AD8) -> 19 | AB8: =+Z8*AA8 -> 5826.3108 | AD8: HABIL
A9: =+$A$16 -> 46327 | B9: 6.8861274 | C9: 5.6527504 | D9: 4.9515701 | E9: 4.5823023 | F9: 4.8359813 | G9: 5.2799778 | H9: 7.7059397 | I9: 7.7293719 | J9: 10.458561 | K9: 12.43682 | L9: 14.062473 | M9: 15.454096 | N9: 15.371238 | O9: 14.375118 | P9: 13.622993 | Q9: 13.296748 | R9: 12.879151 | S9: 16.463739 | T9: 18.195592 | U9: 17.822356 | V9: 16.367902 | W9: 14.774094 | X9: 12.321436 | Y9: 9.8388508 | Z9: =SUM(B9:Y9) -> 275.36519 | AA9: =+SUMIFS('Cantidades Producto Base Curva'!$AA:$AA,'Cantidades Producto Base Curva'!$A:$A,'Cantidades Producto No. 6'!$A9,'Cantidades Producto Base Curva'!$AD:$AD,'Cantidades Producto No. 6'!AD9) -> 4 | AB9: =+Z9*AA9 -> 1101.4608 | AD9: SABADOS
A10: =+$A$16 -> 46327 | B10: 6.9708002 | C10: 5.7389947 | D10: 4.8859051 | E10: 4.3502494 | F10: 4.2674819 | G10: 3.967629 | H10: 5.0478361 | I10: 3.7304049 | J10: 5.737817 | K10: 7.43058 | L10: 8.7643608 | M10: 10.218905 | N10: 11.022882 | O10: 10.804904 | P10: 10.19505 | Q10: 9.9351758 | R10: 9.7149863 | S10: 13.603726 | T10: 15.514432 | U10: 15.579 | V10: 14.847055 | W10: 13.22481 | X10: 10.79999 | Y10: 8.3025141 | Z10: =SUM(B10:Y10) -> 214.65549 | AA10: =+SUMIFS('Cantidades Producto Base Curva'!$AA:$AA,'Cantidades Producto Base Curva'!$A:$A,'Cantidades Producto No. 6'!$A10,'Cantidades Producto Base Curva'!$AD:$AD,'Cantidades Producto No. 6'!AD10) -> 5 | AB10: =+Z10*AA10 -> 1073.2774 | AD10: DOMINGOS Y FESTIVOS
A11: =+$A$16 -> 46327 | B11: 6.0266463 | C11: 4.8139212 | D11: 4.1943097 | E11: 3.8293251 | F11: 3.8851287 | G11: 3.9855006 | H11: 5.0794118 | I11: 4.0021799 | J11: 6.012689 | K11: 7.9432993 | L11: 9.6273708 | M11: 10.717787 | N11: 11.568276 | O11: 11.289389 | P11: 10.529381 | Q11: 10.103611 | R11: 10.063371 | S11: 14.162043 | T11: 15.921302 | U11: 15.966579 | V11: 15.222718 | W11: 13.560916 | X11: 10.819289 | Y11: 7.9564447 | Z11: =SUM(B11:Y11) -> 217.28089 | AA11: =+SUMIFS('Cantidades Producto Base Curva'!$AA:$AA,'Cantidades Producto Base Curva'!$A:$A,'Cantidades Producto No. 6'!$A11,'Cantidades Producto Base Curva'!$AD:$AD,'Cantidades Producto No. 6'!AD11) -> 2 | AB11: =+Z11*AA11 -> 434.56178 | AD11: LUNES FESTIVOS
A13: DEMANDA DIARIA ESTIMADA TOTAL [MWh]
A15: MES | B15: H1 | C15: H2 | D15: H3 | E15: H4 | F15: H5 | G15: H6 | H15: H7 | I15: H8 | J15: H9 | K15: H10 | L15: H11 | M15: H12 | N15: H13 | O15: H14 | P15: H15 | Q15: H16 | R15: H17 | S15: H18 | T15: H19 | U15: H20 | V15: H21 | W15: H22 | X15: H23 | Y15: H24 | Z15: TOTAL | AA15: Días
A16: 46327 | B16: =+B8*$AA$8+B9*$AA$9+B10*$AA$10+B11*$AA$11 -> 200.9219 | C16: =+C8*$AA$8+C9*$AA$9+C10*$AA$10+C11*$AA$11 -> 165.95902 | D16: =+D8*$AA$8+D9*$AA$9+D10*$AA$10+D11*$AA$11 -> 146.06965 | E16: =+E8*$AA$8+E9*$AA$9+E10*$AA$10+E11*$AA$11 -> 137.50395 | F16: =+F8*$AA$8+F9*$AA$9+F10*$AA$10+F11*$AA$11 -> 148.05384 | G16: =+G8*$AA$8+G9*$AA$9+G10*$AA$10+G11*$AA$11 -> 175.67012 | H16: =+H8*$AA$8+H9*$AA$9+H10*$AA$10+H11*$AA$11 -> 246.95633 | I16: =+I8*$AA$8+I9*$AA$9+I10*$AA$10+I11*$AA$11 -> 234.04785 | ... Y16: =+Y8*$AA$8+Y9*$AA$9+Y10*$AA$10+Y11*$AA$11 -> 277.84833 | Z16: =SUM(B16:Y16) -> 8435.6107 | AA16: =+AA8+AA9+AA10+AA11 -> 30 | AB16: =+AB8+AB9+AB10+AB11 -> 8435.6107 | AC16: =+AB16-'Oferta Producto No. 6'!G15 -> 0

Sheet Oferta Producto No. 7
D2: ANEXO No. 1 OFERTAS Y CANTIDADES
C3: OFERTA MERCANTIL IRREVOCABLE A LA EMPRESA DE ENERGIA DE PEREIRA S.A. ESP. INVITACIÓN PARA EL SUMINISTRO DE ENERGÍA ELÉCTRICA CON DESTINO AL MERCADO REGULADO CONVOCATORIA PÚBLICA No. 007-2025 - CP-EEPC2025-007
D4: PRODUCTO No. 7
C6: EMPRESA: XXXXXXXXXXXXXXXXXXXXXXXXXXXXXX
C7: REPRESENTANTE LEGAL: XXXXXXXXXXXXXXXXXXXXXXXXXXXXXX
C8: TIPO DE AGENTE: (COMERCIALIZADOR/GENERADOR)
C9: ="PRODUCTO OFERTADO: "&D4 -> PRODUCTO OFERTADO: PRODUCTO No. 7
C11: Las tarifas ofertadas están referidas en pesos constantes de septiembre de 2025 provisional
F13: ="Oferta " & PROPER(D4) -> Oferta Producto No. 7
F14: Periodo | G14: Energía requerida (MWh-mes) | H14: Energía ofertada (%) | I14: Energía ofertada (MWh-mes) | J14: Tarifa monomia ($/kWh)
A15: 22.85 | B15: 31 | F15: =+'Cantidades Producto No. 7'!A16 -> 46357 | G15: =+_xlfn.XLOOKUP(F15,'[1]Oferta Producto Base Curva'!$F$15:$F$26,'[1]Oferta Producto Base Curva'!$G$15:$G$26) -> 6091.3722
F16: TOTAL | G16: =SUM(G15:G15) -> 6091.3722
B18: Notas
B20: (1) Oferta válida para la modalidad Pague lo Contratado.
