Workbook

Sheet Oferta Producto No. 1
D2: ANEXO No. 1 OFERTAS Y CANTIDADES
C3: OFERTA MERCANTIL IRREVOCABLE A LA EMPRESA DE ENERGIA DE PEREIRA S.A. ESP. INVITACIÓN PARA EL SUMINISTRO DE ENERGÍA ELÉCTRICA CON DESTINO AL MERCADO REGULADO CONVOCATORIA PÚBLICA No. 002-2025 - CP-EEPC2025-002
D4: PRODUCTO No. 1
C6: EMPRESA: XXXXXXXXXXXXXXXXXXXXXXXXXXXXXX
C7: REPRESENTANTE LEGAL: XXXXXXXXXXXXXXXXXXXXXXXXXXXXXX
C8: TIPO DE AGENTE: (COMERCIALIZADOR/GENERADOR)
C9: ="PRODUCTO OFERTADO: "&D4 -> PRODUCTO OFERTADO: PRODUCTO No. 1
C11: Las tarifas ofertadas están referidas en pesos constantes de febrero de 2025 provisional
F13: ="Oferta " & PROPER(D4) -> Oferta Producto No. 1
F14: Periodo | G14: Energía requerida (MWh-año) | H14: Energía ofertada (%) | I14: Energía ofertada (MWh-año) | J14: Tarifa monomia ($/kWh)
B15: 30 | E15: 46023 | F15: año 2026 | G15: =+SUMIFS('Cantidades Producto No. 1'!$Z$360:$Z$443,'Cantidades Producto No. 1'!$A$360:$A$443,">="&'Oferta Producto No. 1'!E15,'Cantidades Producto No. 1'!$A$360:$A$443,"<="&DATE(YEAR('Oferta Producto No. 1'!E15)+1,MONTH('Oferta Producto No. 1'!E15),1-1)) -> 113868.15
B16: 31 | E16: =+DATE(YEAR(E15)+1,MONTH(E15),1) -> 46388 | F16: año 2027 | G16: =+SUMIFS('Cantidades Producto No. 1'!$Z$360:$Z$443,'Cantidades Producto No. 1'!$A$360:$A$443,">="&'Oferta Producto No. 1'!E16,'Cantidades Producto No. 1'!$A$360:$A$443,"<="&DATE(YEAR('Oferta Producto No. 1'!E16)+1,MONTH('Oferta Producto No. 1'!E16),1-1)) -> 68574.891
B17: 31 | E17: =+DATE(YEAR(E16)+1,MONTH(E16),1) -> 46753 | F17: año 2028 | G17: =+SUMIFS('Cantidades Producto No. 1'!$Z$360:$Z$443,'Cantidades Producto No. 1'!$A$360:$A$443,">="&'Oferta Producto No. 1'!E17,'Cantidades Producto No. 1'!$A$360:$A$443,"<="&DATE(YEAR('Oferta Producto No. 1'!E17)+1,MONTH('Oferta Producto No. 1'!E17),1-1)) -> 69880.214
E18: =+DATE(YEAR(E17)+1,MONTH(E17),1) -> 47119 | F18: año 2029 | G18: =+SUMIFS('Cantidades Producto No. 1'!$Z$360:$Z$443,'Cantidades Producto No. 1'!$A$360:$A$443,">="&'Oferta Producto No. 1'!E18,'Cantidades Producto No. 1'!$A$360:$A$443,"<="&DATE(YEAR('Oferta Producto No. 1'!E18)+1,MONTH('Oferta Producto No. 1'!E18),1-1)) -> 66964.333
E19: =+DATE(YEAR(E18)+1,MONTH(E18),1) -> 47484 | F19: año 2030 | G19: =+SUMIFS('Cantidades Producto No. 1'!$Z$360:$Z$443,'Cantidades Producto No. 1'!$A$360:$A$443,">="&'Oferta Producto No. 1'!E19,'Cantidades Producto No. 1'!$A$360:$A$443,"<="&DATE(YEAR('Oferta Producto No. 1'!E19)+1,MONTH('Oferta Producto No. 1'!E19),1-1)) -> 68238.623
E20: =+DATE(YEAR(E19)+1,MONTH(E19),1) -> 47849 | F20: año 2031 | G20: =+SUMIFS('Cantidades Producto No. 1'!$Z$360:$Z$443,'Cantidades Producto No. 1'!$A$360:$A$443,">="&'Oferta Producto No. 1'!E20,'Cantidades Producto No. 1'!$A$360:$A$443,"<="&DATE(YEAR('Oferta Producto No. 1'!E20)+1,MONTH('Oferta Producto No. 1'!E20),1-1)) -> 69434.194
E21: =+DATE(YEAR(E20)+1,MONTH(E20),1) -> 48214 | F21: año 2032 | G21: =+SUMIFS('Cantidades Producto No. 1'!$Z$360:$Z$443,'Cantidades Producto No. 1'!$A$360:$A$443,">="&'Oferta Producto No. 1'!E21,'Cantidades Producto No. 1'!$A$360:$A$443,"<="&DATE(YEAR('Oferta Producto No. 1'!E21)+1,MONTH('Oferta Producto No. 1'!E21),1-1)) -> 70899.731
F22: TOTAL | G22: =SUM(G15:G21) -> 527860.13
B24: Notas
B26: (1) Oferta válida para la modalidad Pague lo Contratado.
B27: ="(2) Las cantidades se distribuyen de acuerdo a la curva del Anexo 1. Ofertas y Cantidades "& D4 &" de los Pliegos de Condiciones definitivos" -> (2) Las cantidades se distribuyen de acuerdo a la curva del Anexo 1. Ofertas y Cantidades PRODUCTO No. 1 de los Pliegos de Condiciones definitivos
B28: (3) La cantidad de energía es equivalente a un porcentaje de las cantidades de energía requerida por la Empresa de Energía de Pereira S.A. ESP. (para todo el año/para cada mes), de acuerdo con el Anexo No.1 Ofertas y Cantidades PRODUCTO No. 1 de los Pliegos definitivos, que se aplicarán para todas las 24 horas del día de la curva establecida en dicho Anexo, presentando una tarifa para cada año sin ningún tipo de discriminación por mes, ni tipo de carga ni tipo de día.
B29: (4) Esta oferta NO presenta restricciones tales como adjudicación mínima o total u otras que no permitan la evaluación objetiva e integral del producto ofertado.
B30: (5) Los precios ofertados incluyen todos los pagos, cargos, impuestos, estampillas, etc., que el Proponente deba realizar ante cualquier entidad gubernamental, o empresa pública, privada o mixta para entregar la energía en la frontera con el Sistema de Transmisión Nacional – STN.
B31: (6) Las cantidades ofertadas están sujetas a la adjudicación en la misma proporción respecto a las cantidades ofertadas para todos y cada uno de los meses del año. Es decir, si la Empresa de Energía de Pereira decide adjudicar, por ejemplo, el 50% de lo ofertado en cualesquiera de los meses de alguno de los años, ese mismo porcentaje debe ser adjudicado en el resto de cada uno de los meses de ese año

Sheet Cantidades Producto No. 1
A2: EMPRESA DE ENERGÍA DE PEREIRA S.A. E.S.P.
A3: PRODUCTO No. 1
A5: DEMANDA DIARIA ESTIMADA DÍA HABIL [MWh]
A7: MES | B7: H1 | C7: H2 | D7: H3 | E7: H4 | F7: H5 | G7: H6 | H7: H7 | I7: H8 | J7: H9 | K7: H10 | L7: H11 | M7: H12 | N7: H13 | O7: H14 | P7: H15 | Q7: H16 | R7: H17 | S7: H18 | T7: H19 | U7: H20 | V7: H21 | W7: H22 | X7: H23 | Y7: H24 | Z7: TOTAL | AA7: Días
A8: 46023 | B8: 8.249076 | C8: 6.973318 | D8: 6.285895 | E8: 6.038175 | F8: 6.477878 | G8: 7.982777 | H8: 10.565258 | I8: 9.332851 | J8: 12.020613 | K8: 14.05811 | L8: 16.021291 | M8: 17.842033 | N8: 17.823454 | O8: 17.458067 | P8: 17.83584 | Q8: 17.736752 | R8: 17.142224 | S8: 20.455479 | T8: 21.050007 | U8: 21.756009 | V8: 20.4369 | W8: 18.343666 | X8: 15.092341 | Y8: 11.450857 | Z8: =SUM(B8:Y8) -> 338.42887 | AA8: 20 | AB8: =+Z8*AA8 -> 6768.5774 | AD8: HABIL
A9: 46054 | B9: 7.908461 | C9: 6.768949 | D9: 6.143456 | E9: 5.957666 | F9: 6.601738 | G9: 9.072745 | H9: 11.921525 | I9: 10.292766 | J9: 12.547018 | K9: 14.330602 | L9: 16.16373 | M9: 17.798682 | N9: 17.21654 | O9: 17.123645 | P9: 17.761524 | Q9: 17.817261 | R9: 17.272277 | S9: 19.811407 | T9: 19.712319 | U9: 20.839445 | V9: 19.885723 | W9: 17.798682 | X9: 14.435883 | Y9: 10.887294 | Z9: =SUM(B9:Y9) -> 336.06934 | AA9: 20 | AB9: =+Z9*AA9 -> 6721.3868 | AD9: HABIL
A10: 46082 | B10: 7.871303 | C10: 6.725598 | D10: 6.155842 | E10: 5.926701 | F10: 6.601738 | G10: 9.097517 | H10: 11.859595 | I10: 10.478556 | J10: 12.788545 | K10: 14.479234 | L10: 16.368099 | M10: 17.947314 | N10: 17.557155 | O10: 17.253698 | P10: 17.77391 | Q10: 17.656243 | R10: 17.204154 | S10: 20.275882 | T10: 20.37497 | U10: 21.576412 | V10: 20.232531 | W10: 18.064981 | X10: 14.652638 | Y10: 11.035926 | Z10: =SUM(B10:Y10) -> 339.95854 | AA10: 21 | AB10: =+Z10*AA10 -> 7139.1294 | AD10: HABIL
A11: 46113 | B11: 7.827952 | C11: 6.638896 | D11: 6.06914 | E11: 5.852385 | F11: 6.521229 | G11: 8.713551 | H11: 11.512787 | I11: 10.40424 | J11: 12.503667 | K11: 14.757919 | L11: 16.460994 | M11: 18.009244 | N11: 17.656243 | O11: 17.09268 | P11: 17.067908 | Q11: 17.142224 | R11: 16.758258 | S11: 20.25111 | T11: 20.789901 | U11: 21.464938 | V11: 20.052934 | W11: 17.848226 | X11: 14.479234 | Y11: 11.029733 | Z11: =SUM(B11:Y11) -> 336.90539 | AA11: 20 | AB11: =+Z11*AA11 -> 6738.1079 | AD11: HABIL
A12: 46143 | B12: 7.821759 | C12: 6.657475 | D12: 6.056754 | E12: 5.809034 | F12: 6.50265 | G12: 8.533954 | H12: 11.556138 | I12: 10.317538 | J12: 12.769966 | K12: 14.658831 | L12: 16.584854 | M12: 18.306508 | N12: 17.848226 | O12: 17.3404 | P12: 17.637664 | Q12: 17.458067 | R12: 16.702521 | S12: 20.344005 | T12: 20.833252 | U12: 21.384429 | V12: 19.978618 | W12: 17.600506 | X12: 14.151005 | Y12: 10.763434 | Z12: =SUM(B12:Y12) -> 337.61759 | AA12: 19 | AB12: =+Z12*AA12 -> 6414.7342 | AD12: HABIL
A13: 46174 | B13: 7.710285 | C13: 6.515036 | D13: 5.827613 | E13: 5.586086 | F13: 6.261123 | G13: 8.081865 | H13: 11.289839 | I13: 10.360889 | J13: 12.838089 | K13: 14.733147 | L13: 16.460994 | M13: 18.182648 | N13: 17.89777 | O13: 17.247505 | P13: 17.309435 | Q13: 17.160803 | R13: 16.7211 | S13: 20.238724 | T13: 20.653655 | U13: 21.786974 | V13: 20.337812 | W13: 17.860612 | X13: 14.206742 | Y13: 10.788206 | Z13: =SUM(B13:Y13) -> 336.05695 | AA13: 19 | AB13: =+Z13*AA13 -> 6385.0821 | AD13: HABIL
A14: 46204 | B14: 7.481144 | C14: 6.44072 | D14: 5.765683 | E14: 5.542735 | F14: 6.205386 | G14: 8.168567 | H14: 11.060698 | I14: 10.088397 | J14: 12.646106 | K14: 14.627866 | L14: 16.355713 | M14: 18.170262 | N14: 17.736752 | O14: 17.191768 | P14: 17.458067 | Q14: 17.544769 | R14: 17.160803 | S14: 20.288268 | T14: 20.170601 | U14: 21.61357 | V14: 20.170601 | W14: 17.742945 | X14: 14.045724 | Y14: 10.918259 | Z14: =SUM(B14:Y14) -> 334.5954 | AA14: 22 | AB14: =+Z14*AA14 -> 7361.0989 | AD14: HABIL
A15: 46235 | B15: 7.778408 | C15: 6.614124 | D15: 5.994824 | E15: 5.778069 | F15: 6.465492 | G15: 8.719744 | H15: 11.58091 | I15: 10.459977 | J15: 12.918598 | K15: 14.733147 | L15: 16.739679 | M15: 18.51707 | N15: 18.08356 | O15: 17.643857 | P15: 17.903963 | Q15: 17.77391 | R15: 17.352786 | S15: 20.505023 | T15: 20.635076 | U15: 21.725044 | V15: 20.195373 | W15: 17.767717 | X15: 14.002373 | Y15: 10.862522 | Z15: =SUM(B15:Y15) -> 340.75125 | AA15: 19 | AB15: =+Z15*AA15 -> 6474.2737 | AD15: HABIL
A16: 46266 | B16: 7.61739 | C16: 6.446913 | D16: 5.846192 | E16: 5.648016 | F16: 6.37879 | G16: 8.577305 | H16: 11.531366 | I16: 10.298959 | J16: 12.07635 | K16: 14.107654 | L16: 16.368099 | M16: 18.040209 | N16: 17.563348 | O16: 17.111259 | P16: 17.507611 | Q16: 17.445681 | R16: 16.944048 | S16: 20.294461 | T16: 21.155288 | U16: 21.149095 | V16: 19.582266 | W16: 17.228926 | X16: 13.6246 | Y16: 10.484749 | Z16: =SUM(B16:Y16) -> 333.02857 | AA16: 22 | AB16: =+Z16*AA16 -> 7326.6286 | AD16: HABIL
A17: 46296 | B17: 7.443986 | C17: 6.261123 | D17: 5.703753 | E17: 5.530349 | F17: 6.056754 | G17: 7.276775 | H17: 10.453784 | I17: 9.803519 | J17: 12.565597 | K17: 14.708375 | L17: 16.7211 | M17: 18.343666 | N17: 17.984472 | O17: 17.544769 | P17: 17.804875 | Q17: 17.489032 | R17: 17.03075 | S17: 20.851831 | T17: 21.706465 | U17: 20.888989 | V17: 19.371704 | W17: 17.03075 | X17: 13.742267 | Y17: 10.620995 | Z17: =SUM(B17:Y17) -> 332.93568 | AA17: 21 | AB17: =+Z17*AA17 -> 6991.6493 | AD17: HABIL
A18: 46327 | B18: 7.772215 | C18: 6.576966 | D18: 5.939087 | E18: 5.728525 | F18: 6.267316 | G18: 7.772215 | H18: 10.806785 | I18: 10.199871 | J18: 12.769966 | K18: 14.621673 | L18: 16.436222 | M18: 18.102139 | N18: 17.872998 | O18: 17.451874 | P18: 17.984472 | Q18: 17.77391 | R18: 17.321821 | S18: 21.403008 | T18: 22.028501 | U18: 21.322499 | V18: 19.848565 | W18: 17.495225 | X18: 14.089075 | Y18: 10.862522 | Z18: =SUM(B18:Y18) -> 338.44745 | AA18: 19 | AB18: =+Z18*AA18 -> 6430.5015 | AD18: HABIL
A19: 46357 | B19: 8.633042 | C19: 7.214845 | D19: 6.465492 | E19: 6.143456 | F19: 6.533615 | G19: 7.759829 | H19: 10.521907 | I19: 9.952151 | J19: 12.769966 | K19: 14.627866 | L19: 16.417643 | M19: 17.996858 | N19: 18.034016 | O19: 17.730559 | P19: 17.972086 | Q19: 17.761524 | R19: 17.142224 | S19: 20.492637 | T19: 21.638342 | U19: 21.545447 | V19: 20.12725 | W19: 18.170262 | X19: 15.228587 | Y19: 12.13828 | Z19: =SUM(B19:Y19) -> 343.01788 | AA19: 21 | AB19: =+Z19*AA19 -> 7203.3756 | AD19: HABIL
... A91: 48549 | B91: 6.174421 | C91: 5.685174 | D91: 5.431261 | E91: 5.32598 | F91: 5.462226 | G91: 5.889543 | H91: 6.731791 | I91: 7.691706 | J91: 8.682586 | K91: 9.345237 | L91: 9.97073 | M91: 10.497135 | N91: 10.459977 | O91: 10.34231 | P91: 10.441398 | Q91: 10.373275 | R91: 10.162713 | S91: 9.995502 | T91: 10.546679 | U91: 10.5281 | V91: 10.038853 | W91: 9.345237 | X91: 8.29862 | Y91: 7.196266 | Z91: =SUM(B91:Y91) -> 204.61672 | AA91: 22 | AB91: =+Z91*AA91 -> 4501.5678 | AD91: HABIL
A93: DEMANDA DIARIA ESTIMADA DÍA SABADO [MWh]
A95: MES | B95: H1 | C95: H2 | D95: H3 | E95: H4 | F95: H5 | G95: H6 | H95: H7 | I95: H8 | J95: H9 | K95: H10 | L95: H11 | M95: H12 | N95: H13 | O95: H14 | P95: H15 | Q95: H16 | R95: H17 | S95: H18 | T95: H19 | U95: H20 | V95: H21 | W95: H22 | X95: H23 | Y95: H24 | Z95: TOTAL | AA95: Días
A96: =+A8 -> 46023 | B96: 8.434866 | C96: 7.084792 | D96: 6.285895 | E96: 5.852385 | F96: 6.001017 | G96: 6.8123 | H96: 8.756902 | I96: 7.598811 | J96: 10.435205 | K96: 12.893826 | L96: 14.547357 | M96: 15.946975 | N96: 16.138958 | O96: 15.284324 | P96: 14.565936 | Q96: 14.268672 | R96: 13.760846 | S96: 18.009244 | T96: 19.185914 | U96: 19.712319 | V96: 18.343666 | W96: 16.442415 | X96: 13.940443 | Y96: 11.364155 | Z96: =SUM(B96:Y96) -> 301.66722 | AA96: 5 | AB96: =+Z96*AA96 -> 1508.3361 | AD96: SABADOS
A97: =+A9 -> 46054 | B97: 8.001356 | C97: 6.775142 | D97: 6.081526 | E97: 5.722332 | F97: 5.914315 | G97: 7.004283 | H97: 9.283307 | I97: 8.211918 | J97: 10.96161 | K97: 12.992914 | L97: 14.61548 | M97: 15.637325 | N97: 15.612553 | O97: 15.04899 | P97: 14.559743 | Q97: 14.268672 | R97: 13.946636 | S97: 17.612892 | T97: 18.157876 | U97: 19.44602 | V97: 18.219806 | W97: 16.491959 | X97: 13.977601 | Y97: 11.475629 | Z97: =SUM(B97:Y97) -> 300.01988 | AA97: 4 | AB97: =+Z97*AA97 -> 1200.0795 | AD97: SABADOS
A98: =+A10 -> 46082 | B98: 8.007549 | C98: 6.719405 | D98: 6.00721 | E98: 5.63563 | F98: 5.957666 | G98: 7.022862 | H98: 9.060359 | I98: 8.242883 | J98: 11.153593 | K98: 13.06723 | L98: 14.67741 | M98: 16.151344 | N98: 16.095607 | O98: 15.11092 | P98: 14.442076 | Q98: 14.101461 | R98: 13.74846 | S98: 17.9597 | T98: 18.405596 | U98: 19.043475 | V98: 17.77391 | W98: 16.064642 | X98: 13.537898 | Y98: 11.02354 | Z98: =SUM(B98:Y98) -> 299.01043 | AA98: 4 | AB98: =+Z98*AA98 -> 1196.0417 | AD98: SABADOS
A99: =+A11 -> 46113 | B99: 8.119023 | C99: 6.762756 | D99: 5.982438 | E99: 5.592279 | F99: 5.796648 | G99: 6.360211 | H99: 8.725937 | I99: 8.057093 | J99: 10.831557 | K99: 12.980528 | L99: 14.596901 | M99: 15.885045 | N99: 15.984133 | O99: 14.949902 | P99: 14.386339 | Q99: 14.064303 | R99: 13.494547 | S99: 17.631471 | T99: 18.585193 | U99: 19.315967 | V99: 18.046402 | W99: 16.231853 | X99: 13.822776 | Y99: 11.320804 | Z99: =SUM(B99:Y99) -> 297.52411 | AA99: 4 | AB99: =+Z99*AA99 -> 1190.0964 | AD99: SABADOS
A100: =+A12 -> 46143 | B100: 7.815566 | C100: 6.614124 | D100: 5.901929 | E100: 5.548928 | F100: 5.827613 | G100: 6.44072 | H100: 9.122289 | I100: 8.521568 | J100: 11.39512 | K100: 13.742267 | L100: 15.23478 | M100: 16.442415 | N100: 16.169923 | O100: 14.98706 | P100: 14.479234 | Q100: 14.113847 | R100: 13.593635 | S100: 17.842033 | T100: 18.876264 | U100: 19.650389 | V100: 18.219806 | W100: 16.386678 | X100: 13.847548 | Y100: 11.258874 | Z100: =SUM(B100:Y100) -> 302.03261 | AA100: 5 | AB100: =+Z100*AA100 -> 1510.163 | AD100: SABADOS
A101: =+A13 -> 46174 | B101: 7.809373 | C101: 6.521229 | D101: 5.796648 | E101: 5.462226 | F101: 5.728525 | G101: 6.570773 | H101: 8.812639 | I101: 8.162374 | J101: 11.060698 | K101: 13.352108 | L101: 14.795077 | M101: 16.169923 | N101: 16.306169 | O101: 15.432956 | P101: 14.609287 | Q101: 13.989987 | R101: 13.457389 | S101: 17.637664 | T101: 18.665702 | U101: 19.433634 | V101: 18.003051 | W101: 16.064642 | X101: 13.401652 | Y101: 10.695311 | Z101: =SUM(B101:Y101) -> 297.93904 | AA101: 4 | AB101: =+Z101*AA101 -> 1191.7561 | AD101: SABADOS
A102: =+A14 -> 46204 | B102: 8.026128 | C102: 6.651282 | D102: 5.75949 | E102: 5.431261 | F102: 5.660402 | G102: 6.223965 | H102: 8.595884 | I102: 7.846531 | J102: 10.918259 | K102: 13.265406 | L102: 14.795077 | M102: 16.200888 | N102: 16.361906 | O102: 15.377219 | P102: 14.448269 | Q102: 13.711302 | R102: 13.25302 | S102: 17.433295 | T102: 18.009244 | U102: 19.433634 | V102: 17.996858 | W102: 16.219467 | X102: 13.742267 | Y102: 11.128821 | Z102: =SUM(B102:Y102) -> 296.48987 | AA102: 4 | AB102: =+Z102*AA102 -> 1185.9595 | AD102: SABADOS
A103: =+A15 -> 46235 | B103: 8.255269 | C103: 6.960932 | D103: 6.168228 | E103: 5.75949 | F103: 6.038175 | G103: 6.8123 | H103: 9.252342 | I103: 8.403901 | J103: 11.265067 | K103: 13.494547 | L103: 15.061376 | M103: 16.392871 | N103: 16.405257 | O103: 15.377219 | P103: 14.55355 | Q103: 13.804197 | R103: 13.25302 | S103: 17.235119 | T103: 18.095946 | U103: 19.148756 | V103: 17.792489 | W103: 16.052256 | X103: 13.606021 | Y103: 10.986382 | Z103: =SUM(B103:Y103) -> 300.17471 | AA103: 5 | AB103: =+Z103*AA103 -> 1500.8735 | AD103: SABADOS
A104: =+A16 -> 46266 | B104: 7.67932 | C104: 6.453106 | D104: 5.734718 | E104: 5.319787 | F104: 5.604665 | G104: 6.329246 | H104: 8.775481 | I104: 8.354357 | J104: 11.20933 | K104: 13.25302 | L104: 14.98706 | M104: 16.361906 | N104: 15.761185 | O104: 15.278131 | P104: 14.330602 | Q104: 13.853741 | R104: 13.222055 | S104: 18.009244 | T104: 19.204493 | U104: 18.938194 | V104: 17.458067 | W104: 15.563009 | X104: 12.980528 | Y104: 10.472363 | Z104: =SUM(B104:Y104) -> 295.13361 | AA104: 4 | AB104: =+Z104*AA104 -> 1180.5344 | AD104: SABADOS
A105: =+A17 -> 46296 | B105: 7.821759 | C105: 6.533615 | D105: 5.809034 | E105: 5.51177 | F105: 5.784262 | G105: 6.155842 | H105: 8.73213 | I105: 8.193339 | J105: 11.172172 | K105: 13.259213 | L105: 14.881779 | M105: 16.238046 | N105: 16.213274 | O105: 15.35864 | P105: 14.683603 | Q105: 14.05811 | R105: 13.426424 | S105: 18.064981 | T105: 19.495564 | U105: 18.870071 | V105: 17.15461 | W105: 15.408184 | X105: 13.160125 | Y105: 10.670539 | Z105: =SUM(B105:Y105) -> 296.65709 | AA105: 5 | AB105: =+Z105*AA105 -> 1483.2854 | AD105: SABADOS
A106: =+A18 -> 46327 | B106: 7.945619 | C106: 6.645089 | D106: 5.914315 | E106: 5.517963 | F106: 5.790455 | G106: 6.25493 | H106: 8.843604 | I106: 8.490603 | J106: 11.357962 | K106: 13.432617 | L106: 15.141885 | M106: 16.615819 | N106: 16.53531 | O106: 15.488693 | P106: 14.702182 | Q106: 14.361567 | R106: 13.921864 | S106: 18.126911 | T106: 19.898109 | U106: 19.501757 | V106: 17.953507 | W106: 16.28759 | X106: 13.717495 | Y106: 11.110242 | Z106: =SUM(B106:Y106) -> 303.55609 | AA106: 4 | AB106: =+Z106*AA106 -> 1214.2244 | AD106: SABADOS
A107: =+A19 -> 46357 | B107: 8.756902 | C107: 7.30774 | D107: 6.471685 | E107: 6.025789 | F107: 6.285895 | G107: 6.923774 | H107: 9.376202 | I107: 8.800253 | J107: 11.791472 | K107: 13.897092 | L107: 15.538237 | M107: 16.981206 | N107: 16.937855 | O107: 15.816922 | P107: 14.819849 | Q107: 14.312023 | R107: 14.089075 | S107: 18.529456 | T107: 19.984811 | U107: 19.774249 | V107: 18.312701 | W107: 16.467187 | X107: 13.99618 | Y107: 11.481822 | Z107: =SUM(B107:Y107) -> 312.67838 | AA107: 4 | AB107: =+Z107*AA107 -> 1250.7135 | AD107: SABADOS
... A179: =+A91 -> 48549 | B179: 6.279702 | C179: 5.778069 | D179: 5.486998 | E179: 5.338366 | F179: 5.418875 | G179: 5.648016 | H179: 6.360211 | I179: 7.301547 | J179: 8.335778 | K179: 9.085131 | L179: 9.654887 | M179: 10.131748 | N179: 10.09459 | O179: 9.710624 | P179: 9.370009 | Q179: 9.196605 | R179: 9.097517 | S179: 9.277114 | T179: 10.001695 | U179: 9.989309 | V179: 9.506255 | W179: 8.874569 | X179: 7.98897 | Y179: 7.078599 | Z179: =SUM(B179:Y179) -> 195.00518 | AA179: 3 | AB179: =+Z179*AA179 -> 585.01555 | AD179: SABADOS
A181: DEMANDA DIARIA ESTIMADA DÍA DOMINGO Y FESTIVO DIFERENTE A LUNES [MWh]
A183: MES | B183: H1 | C183: H2 | D183: H3 | E183: H4 | F183: H5 | G183: H6 | H183: H7 | I183: H8 | J183: H9 | K183: H10 | L183: H11 | M183: H12 | N183: H13 | O183: H14 | P183: H15 | Q183: H16 | R183: H17 | S183: H18 | T183: H19 | U183: H20 | V183: H21 | W183: H22 | X183: H23 | Y183: H24 | Z183: TOTAL | AA183: Días
A184: =+A96 -> 46023 | B184: 8.577305 | C184: 7.252003 | D184: 6.149649 | E184: 5.716139 | F184: 5.44984 | G184: 5.548928 | H184: 6.25493 | I184: 3.480466 | J184: 5.084453 | K184: 6.818493 | L184: 8.292427 | M184: 9.642501 | N184: 10.571451 | O184: 10.670539 | P184: 10.255608 | Q184: 10.038853 | R184: 9.958344 | S184: 14.200549 | T184: 15.575395 | U184: 17.15461 | V184: 16.696328 | W184: 15.079955 | X184: 12.689457 | Y184: 10.286573 | Z184: =SUM(B184:Y184) -> 231.4448 | AA184: 5 | AB184: =+Z184*AA184 -> 1157.224 | AD184: DOMINGOS Y FESTIVOS
A185: =+A97 -> 46054 | B185: 8.261462 | C185: 6.917581 | D185: 5.957666 | E185: 5.437454 | F185: 5.369331 | G185: 5.734718 | H185: 6.768949 | I185: 4.502311 | J185: 6.459299 | K185: 8.317199 | L185: 9.450518 | M185: 10.664346 | N185: 11.246488 | O185: 10.96161 | P185: 10.267994 | Q185: 9.815905 | R185: 9.53722 | S185: 13.649372 | T185: 14.355374 | U185: 16.770644 | V185: 16.219467 | W185: 14.404918 | X185: 11.549945 | Y185: 8.756902 | Z185: =SUM(B185:Y185) -> 231.37667 | AA185: 4 | AB185: =+Z185*AA185 -> 925.50669 | AD185: DOMINGOS Y FESTIVOS
A186: =+A98 -> 46082 | B186: 8.019935 | C186: 6.68844 | D186: 5.870964 | E186: 5.394103 | F186: 5.245471 | G186: 5.666595 | H186: 6.638896 | I186: 4.452767 | J186: 6.261123 | K186: 7.976584 | L186: 9.072745 | M186: 10.113169 | N186: 10.918259 | O186: 10.868715 | P186: 10.15652 | Q186: 9.834484 | R186: 9.834484 | S186: 14.417304 | T186: 15.612553 | U186: 17.111259 | V186: 16.262818 | W186: 14.404918 | X186: 11.816244 | Y186: 9.134675 | Z186: =SUM(B186:Y186) -> 231.77302 | AA186: 5 | AB186: =+Z186*AA186 -> 1158.8651 | AD186: DOMINGOS Y FESTIVOS
A187: =+A99 -> 46113 | B187: 7.704092 | C187: 6.31686 | D187: 5.462226 | E187: 5.003944 | F187: 4.991558 | G187: 5.010137 | H187: 6.118684 | I187: 4.322714 | J187: 6.223965 | K187: 8.044707 | L187: 9.444325 | M187: 10.856329 | N187: 11.537559 | O187: 11.184558 | P187: 10.812978 | Q187: 9.958344 | R187: 9.766361 | S187: 14.411111 | T187: 15.532044 | U187: 16.59724 | V187: 15.885045 | W187: 14.188163 | X187: 11.673805 | Y187: 9.270921 | Z187: =SUM(B187:Y187) -> 230.31767 | AA187: 6 | AB187: =+Z187*AA187 -> 1381.906 | AD187: DOMINGOS Y FESTIVOS
A188: =+A100 -> 46143 | B188: 7.834145 | C188: 6.446913 | D188: 5.654209 | E188: 5.103032 | F188: 4.960593 | G188: 4.626171 | H188: 6.354018 | I188: 4.576627 | J188: 6.583159 | K188: 8.639235 | L188: 9.989309 | M188: 11.02354 | N188: 11.203137 | O188: 11.073084 | P188: 10.020274 | Q188: 10.15652 | R188: 10.09459 | S188: 14.534971 | T188: 15.569202 | U188: 17.15461 | V188: 16.547696 | W188: 14.764112 | X188: 11.983455 | Y188: 9.326658 | Z188: =SUM(B188:Y188) -> 234.21926 | AA188: 6 | AB188: =+Z188*AA188 -> 1405.3156 | AD188: DOMINGOS Y FESTIVOS
A189: =+A101 -> 46174 | B189: 7.443986 | C189: 6.056754 | D189: 5.288822 | E189: 4.787189 | F189: 4.750031 | G189: 4.83054 | H189: 6.168228 | I189: 4.421802 | J189: 6.409755 | K189: 8.348164 | L189: 9.444325 | M189: 10.410433 | N189: 11.011154 | O189: 10.980189 | P189: 10.348503 | Q189: 9.853063 | R189: 9.574378 | S189: 13.841355 | T189: 14.788884 | U189: 16.826381 | V189: 16.169923 | W189: 14.373953 | X189: 11.884367 | Y189: 9.22757 | Z189: =SUM(B189:Y189) -> 227.23975 | AA189: 4 | AB189: =+Z189*AA189 -> 908.959 | AD189: DOMINGOS Y FESTIVOS
...

Sheet Oferta Producto No. 2
D2: ANEXO No. 1 OFERTAS Y CANTIDADES
C3: OFERTA MERCANTIL IRREVOCABLE A LA EMPRESA DE ENERGIA DE PEREIRA S.A. ESP. INVITACIÓN PARA EL SUMINISTRO DE ENERGÍA ELÉCTRICA CON DESTINO AL MERCADO REGULADO CONVOCATORIA PÚBLICA No. 002-2025 - CP-EEPC2025-002
D4: PRODUCTO No. 2
C6: EMPRESA: XXXXXXXXXXXXXXXXXXXXXXXXXXXXXX
C7: REPRESENTANTE LEGAL: XXXXXXXXXXXXXXXXXXXXXXXXXXXXXX
C8: TIPO DE AGENTE: (COMERCIALIZADOR/GENERADOR)
C9: ="PRODUCTO OFERTADO: "&D4 -> PRODUCTO OFERTADO: PRODUCTO No. 2
C11: Las tarifas ofertadas están referidas en pesos constantes de febrero de 2025 provisional
F13: ="Oferta " & PROPER(D4) -> Oferta Producto No. 2
F14: Periodo | G14: Energía requerida (MWh-mes) | H14: Energía ofertada (%) | I14: Energía ofertada (MWh-mes) | J14: Tarifa monomia ($/kWh)
A15: 22.85 | B15: 31 | F15: =+'Cantidades Producto No. 2'!A8 -> 46023 | G15: =+'Cantidades Producto No. 2'!AB24 -> 4464
B16: 28 | F16: =+'Cantidades Producto No. 2'!A9 -> 46054 | G16: =+'Cantidades Producto No. 2'!AB25 -> 4032
B17: 31 | F17: =+'Cantidades Producto No. 2'!A10 -> 46082 | G17: =+'Cantidades Producto No. 2'!AB26 -> 4464
B18: 30 | F18: =+'Cantidades Producto No. 2'!A11 -> 46113 | G18: =+'Cantidades Producto No. 2'!AB27 -> 4320
B19: 31 | F19: =+'Cantidades Producto No. 2'!A12 -> 46143 | G19: =+'Cantidades Producto No. 2'!AB28 -> 4464
B20: 30 | F20: =+'Cantidades Producto No. 2'!A13 -> 46174 | G20: =+'Cantidades Producto No. 2'!AB29 -> 4320
B21: 31 | F21: =+'Cantidades Producto No. 2'!A14 -> 46204 | G21: =+'Cantidades Producto No. 2'!AB30 -> 4464
B22: 31 | F22: =+'Cantidades Producto No. 2'!A15 -> 46235 | G22: =+'Cantidades Producto No. 2'!AB31 -> 4464
B23: 30 | F23: =+'Cantidades Producto No. 2'!A16 -> 46266 | G23: =+'Cantidades Producto No. 2'!AB32 -> 4320
B24: 31 | F24: =+'Cantidades Producto No. 2'!A17 -> 46296 | G24: =+'Cantidades Producto No. 2'!AB33 -> 4464
B25: 30 | F25: =+'Cantidades Producto No. 2'!A18 -> 46327 | G25: =+'Cantidades Producto No. 2'!AB34 -> 4320
B26: 31 | F26: =+'Cantidades Producto No. 2'!A19 -> 46357 | G26: =+'Cantidades Producto No. 2'!AB35 -> 4464
F27: TOTAL | G27: =SUM(G15:G26) -> 52560
B29: Notas
B31: (1) Oferta válida para la modalidad Pague lo Contratado.
B32: ="(2) Las cantidades se distribuyen de acuerdo a la curva del Anexo 1. Ofertas y Cantidades "& D4 &" de los Pliegos de Condiciones definitivos" -> (2) Las cantidades se distribuyen de acuerdo a la curva del Anexo 1. Ofertas y Cantidades PRODUCTO No. 2 de los Pliegos de Condiciones definitivos
B33: (3) La cantidad de energía es equivalente a un porcentaje de las cantidades de energía requerida por la Empresa de Energía de Pereira S.A. ESP. (para todo el año/para cada mes), de acuerdo con el Anexo No.1 Ofertas y Cantidades PRODUCTO No. 2 de los Pliegos definitivos, que se aplicarán para todas las 24 horas del día de la curva establecida en dicho Anexo, presentando una tarifa para cada año sin ningún tipo de discriminación por mes, ni tipo de carga ni tipo de día.
B34: (4) Esta oferta NO presenta restricciones tales como adjudicación mínima o total u otras que no permitan la evaluación objetiva e integral del producto ofertado.
B35: (5) Los precios ofertados incluyen todos los pagos, cargos, impuestos, estampillas, etc., que el Proponente deba realizar ante cualquier entidad gubernamental, o empresa pública, privada o mixta para entregar la energía en la frontera con el Sistema de Transmisión Nacional – STN.
B36: (6) Las cantidades ofertadas están sujetas a la adjudicación en la misma proporción respecto a las cantidades ofertadas para todos y cada uno de los meses del año. Es decir, si la Empresa de Energía de Pereira decide adjudicar, por ejemplo, el 50% de lo ofertado en cualesquiera de los meses de alguno de los años, ese mismo porcentaje debe ser adjudicado en el resto de cada uno de los meses de ese año

Sheet Cantidades Producto No. 2
A2: EMPRESA DE ENERGÍA DE PEREIRA S.A. E.S.P.
A3: ='Oferta Producto No. 2'!D4 -> PRODUCTO No. 2
A5: DEMANDA DIARIA ESTIMADA TO [MWh]
A7: MES | B7: H1 | C7: H2 | D7: H3 | E7: H4 | F7: H5 | G7: H6 | H7: H7 | I7: H8 | J7: H9 | K7: H10 | L7: H11 | M7: H12 | N7: H13 | O7: H14 | P7: H15 | Q7: H16 | R7: H17 | S7: H18 | T7: H19 | U7: H20 | V7: H21 | W7: H22 | X7: H23 | Y7: H24 | Z7: TOTAL | AA7: Días
A8: 46023 | B8: 6 | C8: 6 | D8: 6 | E8: 6 | F8: 6 | G8: 6 | H8: 6 | I8: 6 | J8: 6 | K8: 6 | L8: 6 | M8: 6 | N8: 6 | O8: 6 | P8: 6 | Q8: 6 | R8: 6 | S8: 6 | T8: 6 | U8: 6 | V8: 6 | W8: 6 | X8: 6 | Y8: 6 | Z8: =SUM(B8:Y8) -> 144 | AA8: 31 | AB8: =+Z8*AA8 -> 4464
A9: 46054 | B9: 6 | C9: 6 | D9: 6 | E9: 6 | F9: 6 | G9: 6 | H9: 6 | I9: 6 | J9: 6 | K9: 6 | L9: 6 | M9: 6 | N9: 6 | O9: 6 | P9: 6 | Q9: 6 | R9: 6 | S9: 6 | T9: 6 | U9: 6 | V9: 6 | W9: 6 | X9: 6 | Y9: 6 | Z9: =SUM(B9:Y9) -> 144 | AA9: 28 | AB9: =+Z9*AA9 -> 4032
A10: 46082 | B10: 6 | C10: 6 | D10: 6 | E10: 6 | F10: 6 | G10: 6 | H10: 6 | I10: 6 | J10: 6 | K10: 6 | L10: 6 | M10: 6 | N10: 6 | O10: 6 | P10: 6 | Q10: 6 | R10: 6 | S10: 6 | T10: 6 | U10: 6 | V10: 6 | W10: 6 | X10: 6 | Y10: 6 | Z10: =SUM(B10:Y10) -> 144 | AA10: 31 | AB10: =+Z10*AA10 -> 4464
A11: 46113 | B11: 6 | C11: 6 | D11: 6 | E11: 6 | F11: 6 | G11: 6 | H11: 6 | I11: 6 | J11: 6 | K11: 6 | L11: 6 | M11: 6 | N11: 6 | O11: 6 | P11: 6 | Q11: 6 | R11: 6 | S11: 6 | T11: 6 | U11: 6 | V11: 6 | W11: 6 | X11: 6 | Y11: 6 | Z11: =SUM(B11:Y11) -> 144 | AA11: 30 | AB11: =+Z11*AA11 -> 4320
A12: 46143 | B12: 6 | C12: 6 | D12: 6 | E12: 6 | F12: 6 | G12: 6 | H12: 6 | I12: 6 | J12: 6 | K12: 6 | L12: 6 | M12: 6 | N12: 6 | O12: 6 | P12: 6 | Q12: 6 | R12: 6 | S12: 6 | T12: 6 | U12: 6 | V12: 6 | W12: 6 | X12: 6 | Y12: 6 | Z12: =SUM(B12:Y12) -> 144 | AA12: 31 | AB12: =+Z12*AA12 -> 4464
A13: 46174 | B13: 6 | C13: 6 | D13: 6 | E13: 6 | F13: 6 | G13: 6 | H13: 6 | I13: 6 | J13: 6 | K13: 6 | L13: 6 | M13: 6 | N13: 6 | O13: 6 | P13: 6 | Q13: 6 | R13: 6 | S13: 6 | T13: 6 | U13: 6 | V13: 6 | W13: 6 | X13: 6 | Y13: 6 | Z13: =SUM(B13:Y13) -> 144 | AA13: 30 | AB13: =+Z13*AA13 -> 4320
A14: 46204 | B14: 6 | C14: 6 | D14: 6 | E14: 6 | F14: 6 | G14: 6 | H14: 6 | I14: 6 | J14: 6 | K14: 6 | L14: 6 | M14: 6 | N14: 6 | O14: 6 | P14: 6 | Q14: 6 | R14: 6 | S14: 6 | T14: 6 | U14: 6 | V14: 6 | W14: 6 | X14: 6 | Y14: 6 | Z14: =SUM(B14:Y14) -> 144 | AA14: 31 | AB14: =+Z14*AA14 -> 4464
A15: 46235 | B15: 6 | C15: 6 | D15: 6 | E15: 6 | F15: 6 | G15: 6 | H15: 6 | I15: 6 | J15: 6 | K15: 6 | L15: 6 | M15: 6 | N15: 6 | O15: 6 | P15: 6 | Q15: 6 | R15: 6 | S15: 6 | T15: 6 | U15: 6 | V15: 6 | W15: 6 | X15: 6 | Y15: 6 | Z15: =SUM(B15:Y15) -> 144 | AA15: 31 | AB15: =+Z15*AA15 -> 4464
A16: 46266 | B16: 6 | C16: 6 | D16: 6 | E16: 6 | F16: 6 | G16: 6 | H16: 6 | I16: 6 | J16: 6 | K16: 6 | L16: 6 | M16: 6 | N16: 6 | O16: 6 | P16: 6 | Q16: 6 | R16: 6 | S16: 6 | T16: 6 | U16: 6 | V16: 6 | W16: 6 | X16: 6 | Y16: 6 | Z16: =SUM(B16:Y16) -> 144 | AA16: 30 | AB16: =+Z16*AA16 -> 4320
A17: 46296 | B17: 6 | C17: 6 | D17: 6 | E17: 6 | F17: 6 | G17: 6 | H17: 6 | I17: 6 | J17: 6 | K17: 6 | L17: 6 | M17: 6 | N17: 6 | O17: 6 | P17: 6 | Q17: 6 | R17: 6 | S17: 6 | T17: 6 | U17: 6 | V17: 6 | W17: 6 | X17: 6 | Y17: 6 | Z17: =SUM(B17:Y17) -> 144 | AA17: 31 | AB17: =+Z17*AA17 -> 4464
A18: 46327 | B18: 6 | C18: 6 | D18: 6 | E18: 6 | F18: 6 | G18: 6 | H18: 6 | I18: 6 | J18: 6 | K18: 6 | L18: 6 | M18: 6 | N18: 6 | O18: 6 | P18: 6 | Q18: 6 | R18: 6 | S18: 6 | T18: 6 | U18: 6 | V18: 6 | W18: 6 | X18: 6 | Y18: 6 | Z18: =SUM(B18:Y18) -> 144 | AA18: 30 | AB18: =+Z18*AA18 -> 4320
A19: 46357 | B19: 6 | C19: 6 | D19: 6 | E19: 6 | F19: 6 | G19: 6 | H19: 6 | I19: 6 | J19: 6 | K19: 6 | L19: 6 | M19: 6 | N19: 6 | O19: 6 | P19: 6 | Q19: 6 | R19: 6 | S19: 6 | T19: 6 | U19: 6 | V19: 6 | W19: 6 | X19: 6 | Y19: 6 | Z19: =SUM(B19:Y19) -> 144 | AA19: 31 | AB19: =+Z19*AA19 -> 4464
A21: DEMANDA DIARIA ESTIMADA TOTAL [MWh]
A23: MES | B23: H1 | C23: H2 | D23: H3 | E23: H4 | F23: H5 | G23: H6 | H23: H7 | I23: H8 | J23: H9 | K23: H10 | L23: H11 | M23: H12 | N23: H13 | O23: H14 | P23: H15 | Q23: H16 | R23: H17 | S23: H18 | T23: H19 | U23: H20 | V23: H21 | W23: H22 | X23: H23 | Y23: H24 | Z23: TOTAL | AA23: Días
A24: =+A8 -> 46023 | B24: =+B8*$AA8 -> 186 | C24: =+C8*$AA8 -> 186 | D24: =+D8*$AA8 -> 186 | E24: =+E8*$AA8 -> 186 | F24: =+F8*$AA8 -> 186 | G24: =+G8*$AA8 -> 186 | H24: =+H8*$AA8 -> 186 | I24: =+I8*$AA8 -> 186 | ... Y24: =+Y8*$AA8 -> 186 | Z24: =SUM(B24:Y24) -> 4464 | AA24: =+AA8 -> 31 | AB24: =+AB8 -> 4464 | AC24: =+Z24-AB24 -> 0
A25: =+A9 -> 46054 | B25: =+B9*$AA9 -> 168 | C25: =+C9*$AA9 -> 168 | D25: =+D9*$AA9 -> 168 | E25: =+E9*$AA9 -> 168 | F25: =+F9*$AA9 -> 168 | G25: =+G9*$AA9 -> 168 | H25: =+H9*$AA9 -> 168 | I25: =+I9*$AA9 -> 168 | ... Y25: =+Y9*$AA9 -> 168 | Z25: =SUM(B25:Y25) -> 4032 | AA25: =+AA9 -> 28 | AB25: =+AB9 -> 4032 | AC25: =+Z25-AB25 -> 0
A26: =+A10 -> 46082 | B26: =+B10*$AA10 -> 186 | C26: =+C10*$AA10 -> 186 | D26: =+D10*$AA10 -> 186 | E26: =+E10*$AA10 -> 186 | F26: =+F10*$AA10 -> 186 | G26: =+G10*$AA10 -> 186 | H26: =+H10*$AA10 -> 186 | I26: =+I10*$AA10 -> 186 | ... Y26: =+Y10*$AA10 -> 186 | Z26: =SUM(B26:Y26) -> 4464 | AA26: =+AA10 -> 31 | AB26: =+AB10 -> 4464 | AC26: =+Z26-AB26 -> 0
A27: =+A11 -> 46113 | B27: =+B11*$AA11 -> 180 | C27: =+C11*$AA11 -> 180 | D27: =+D11*$AA11 -> 180 | E27: =+E11*$AA11 -> 180 | F27: =+F11*$AA11 -> 180 | G27: =+G11*$AA11 -> 180 | H27: =+H11*$AA11 -> 180 | I27: =+I11*$AA11 -> 180 | ... Y27: =+Y11*$AA11 -> 180 | Z27: =SUM(B27:Y27) -> 4320 | AA27: =+AA11 -> 30 | AB27: =+AB11 -> 4320 | AC27: =+Z27-AB27 -> 0
A28: =+A12 -> 46143 | B28: =+B12*$AA12 -> 186 | C28: =+C12*$AA12 -> 186 | D28: =+D12*$AA12 -> 186 | E28: =+E12*$AA12 -> 186 | F28: =+F12*$AA12 -> 186 | G28: =+G12*$AA12 -> 186 | H28: =+H12*$AA12 -> 186 | I28: =+I12*$AA12 -> 186 | ... Y28: =+Y12*$AA12 -> 186 | Z28: =SUM(B28:Y28) -> 4464 | AA28: =+AA12 -> 31 | AB28: =+AB12 -> 4464 | AC28: =+Z28-AB28 -> 0
A29: =+A13 -> 46174 | B29: =+B13*$AA13 -> 180 | C29: =+C13*$AA13 -> 180 | D29: =+D13*$AA13 -> 180 | E29: =+E13*$AA13 -> 180 | F29: =+F13*$AA13 -> 180 | G29: =+G13*$AA13 -> 180 | H29: =+H13*$AA13 -> 180 | I29: =+I13*$AA13 -> 180 | ... Y29: =+Y13*$AA13 -> 180 | Z29: =SUM(B29:Y29) -> 4320 | AA29: =+AA13 -> 30 | AB29: =+AB13 -> 4320 | AC29: =+Z29-AB29 -> 0
A30: =+A14 -> 46204 | B30: =+B14*$AA14 -> 186 | C30: =+C14*$AA14 -> 186 | D30: =+D14*$AA14 -> 186 | E30: =+E14*$AA14 -> 186 | F30: =+F14*$AA14 -> 186 | G30: =+G14*$AA14 -> 186 | H30: =+H14*$AA14 -> 186 | I30: =+I14*$AA14 -> 186 | ... Y30: =+Y14*$AA14 -> 186 | Z30: =SUM(B30:Y30) -> 4464 | AA30: =+AA14 -> 31 | AB30: =+AB14 -> 4464 | AC30: =+Z30-AB30 -> 0
A31: =+A15 -> 46235 | B31: =+B15*$AA15 -> 186 | C31: =+C15*$AA15 -> 186 | D31: =+D15*$AA15 -> 186 | E31: =+E15*$AA15 -> 186 | F31: =+F15*$AA15 -> 186 | G31: =+G15*$AA15 -> 186 | H31: =+H15*$AA15 -> 186 | I31: =+I15*$AA15 -> 186 | ... Y31: =+Y15*$AA15 -> 186 | Z31: =SUM(B31:Y31) -> 4464 | AA31: =+AA15 -> 31 | AB31: =+AB15 -> 4464 | AC31: =+Z31-AB31 -> 0
A32: =+A16 -> 46266 | B32: =+B16*$AA16 -> 180 | C32: =+C16*$AA16 -> 180 | D32: =+D16*$AA16 -> 180 | E32: =+E16*$AA16 -> 180 | F32: =+F16*$AA16 -> 180 | G32: =+G16*$AA16 -> 180 | H32: =+H16*$AA16 -> 180 | I32: =+I16*$AA16 -> 180 | ... Y32: =+Y16*$AA16 -> 180 | Z32: =SUM(B32:Y32) -> 4320 | AA32: =+AA16 -> 30 | AB32: =+AB16 -> 4320 | AC32: =+Z32-AB32 -> 0
A33: =+A17 -> 46296 | B33: =+B17*$AA17 -> 186 | C33: =+C17*$AA17 -> 186 | D33: =+D17*$AA17 -> 186 | E33: =+E17*$AA17 -> 186 | F33: =+F17*$AA17 -> 186 | G33: =+G17*$AA17 -> 186 | H33: =+H17*$AA17 -> 186 | I33: =+I17*$AA17 -> 186 | ... Y33: =+Y17*$AA17 -> 186 | Z33: =SUM(B33:Y33) -> 4464 | AA33: =+AA17 -> 31 | AB33: =+AB17 -> 4464 | AC33: =+Z33-AB33 -> 0
A34: =+A18 -> 46327 | B34: =+B18*$AA18 -> 180 | C34: =+C18*$AA18 -> 180 | D34: =+D18*$AA18 -> 180 | E34: =+E18*$AA18 -> 180 | F34: =+F18*$AA18 -> 180 | G34: =+G18*$AA18 -> 180 | H34: =+H18*$AA18 -> 180 | I34: =+I18*$AA18 -> 180 | ... Y34: =+Y18*$AA18 -> 180 | Z34: =SUM(B34:Y34) -> 4320 | AA34: =+AA18 -> 30 | AB34: =+AB18 -> 4320 | AC34: =+Z34-AB34 -> 0
A35: =+A19 -> 46357 | B35: =+B19*$AA19 -> 186 | C35: =+C19*$AA19 -> 186 | D35: =+D19*$AA19 -> 186 | E35: =+E19*$AA19 -> 186 | F35: =+F19*$AA19 -> 186 | G35: =+G19*$AA19 -> 186 | H35: =+H19*$AA19 -> 186 | I35: =+I19*$AA19 -> 186 | ... Y35: =+Y19*$AA19 -> 186 | Z35: =SUM(B35:Y35) -> 4464 | AA35: =+AA19 -> 31 | AB35: =+AB19 -> 4464 | AC35: =+Z35-AB35 -> 0

Sheet Oferta Producto No. 3
D2: ANEXO No. 1 OFERTAS Y CANTIDADES
C3: OFERTA MERCANTIL IRREVOCABLE A LA EMPRESA DE ENERGIA DE PEREIRA S.A. ESP. INVITACIÓN PARA EL SUMINISTRO DE ENERGÍA ELÉCTRICA CON DESTINO AL MERCADO REGULADO CONVOCATORIA PÚBLICA No. 002-2025 - CP-EEPC2025-002
D4: PRODUCTO No. 3
C6: EMPRESA: XXXXXXXXXXXXXXXXXXXXXXXXXXXXXX
C7: REPRESENTANTE LEGAL: XXXXXXXXXXXXXXXXXXXXXXXXXXXXXX
C8: TIPO DE AGENTE: (COMERCIALIZADOR/GENERADOR)
C9: ="PRODUCTO OFERTADO: "&D4 -> PRODUCTO OFERTADO: PRODUCTO No. 3
C11: Las tarifas ofertadas están referidas en pesos constantes de febrero de 2025 provisional
F13: ="Oferta " & PROPER(D4) -> Oferta Producto No. 3
F14: Periodo | G14: Energía requerida (MWh-mes) | H14: Energía ofertada (%) | I14: Energía ofertada (MWh-mes) | J14: Tarifa monomia ($/kWh)
A15: 22.85 | B15: 31 | F15: =+'Cantidades Producto No. 3'!A8 -> 46388 | G15: =+'Cantidades Producto No. 3'!AB24 -> 4464
B16: 28 | F16: =+'Cantidades Producto No. 3'!A9 -> 46419 | G16: =+'Cantidades Producto No. 3'!AB25 -> 4032
B17: 31 | F17: =+'Cantidades Producto No. 3'!A10 -> 46447 | G17: =+'Cantidades Producto No. 3'!AB26 -> 4464
B18: 30 | F18: =+'Cantidades Producto No. 3'!A11 -> 46478 | G18: =+'Cantidades Producto No. 3'!AB27 -> 4320
B19: 31 | F19: =+'Cantidades Producto No. 3'!A12 -> 46508 | G19: =+'Cantidades Producto No. 3'!AB28 -> 4464
B20: 30 | F20: =+'Cantidades Producto No. 3'!A13 -> 46539 | G20: =+'Cantidades Producto No. 3'!AB29 -> 4320
B21: 31 | F21: =+'Cantidades Producto No. 3'!A14 -> 46569 | G21: =+'Cantidades Producto No. 3'!AB30 -> 4464
B22: 31 | F22: =+'Cantidades Producto No. 3'!A15 -> 46600 | G22: =+'Cantidades Producto No. 3'!AB31 -> 4464
B23: 30 | F23: =+'Cantidades Producto No. 3'!A16 -> 46631 | G23: =+'Cantidades Producto No. 3'!AB32 -> 4320
B24: 31 | F24: =+'Cantidades Producto No. 3'!A17 -> 46661 | G24: =+'Cantidades Producto No. 3'!AB33 -> 4464
B25: 30 | F25: =+'Cantidades Producto No. 3'!A18 -> 46692 | G25: =+'Cantidades Producto No. 3'!AB34 -> 4320
B26: 31 | F26: =+'Cantidades Producto No. 3'!A19 -> 46722 | G26: =+'Cantidades Producto No. 3'!AB35 -> 4464
F27: TOTAL | G27: =SUM(G15:G26) -> 52560
B29: Notas
B31: (1) Oferta válida para la modalidad Pague lo Contratado.
B32: ="(2) Las cantidades se distribuyen de acuerdo a la curva del Anexo 1. Ofertas y Cantidades "& D4 &" de los Pliegos de Condiciones definitivos" -> (2) Las cantidades se distribuyen de acuerdo a la curva del Anexo 1. Ofertas y Cantidades PRODUCTO No. 3 de los Pliegos de Condiciones definitivos
B33: (3) La cantidad de energía es equivalente a un porcentaje de las cantidades de energía requerida por la Empresa de Energía de Pereira S.A. ESP. (para todo el año/para cada mes), de acuerdo con el Anexo No.1 Ofertas y Cantidades PRODUCTO No. 3 de los Pliegos definitivos, que se aplicarán para todas las 24 horas del día de la curva establecida en dicho Anexo, presentando una tarifa para cada año sin ningún tipo de discriminación por mes, ni tipo de carga ni tipo de día.
B34: (4) Esta oferta NO presenta restricciones tales como adjudicación mínima o total u otras que no permitan la evaluación objetiva e integral del producto ofertado.
B35: (5) Los precios ofertados incluyen todos los pagos, cargos, impuestos, estampillas, etc., que el Proponente deba realizar ante cualquier entidad gubernamental, o empresa pública, privada o mixta para entregar la energía en la frontera con el Sistema de Transmisión Nacional – STN.
B36: (6) Las cantidades ofertadas están sujetas a la adjudicación en la misma proporción respecto a las cantidades ofertadas para todos y cada uno de los meses del año. Es decir, si la Empresa de Energía de Pereira decide adjudicar, por ejemplo, el 50% de lo ofertado en cualesquiera de los meses de alguno de los años, ese mismo porcentaje debe ser adjudicado en el resto de cada uno de los meses de ese año

Sheet Cantidades Producto No. 3
A2: EMPRESA DE ENERGÍA DE PEREIRA S.A. E.S.P.
A3: ='Oferta Producto No. 3'!D4 -> PRODUCTO No. 3
A5: DEMANDA DIARIA ESTIMADA TO [MWh]
A7: MES | B7: H1 | C7: H2 | D7: H3 | E7: H4 | F7: H5 | G7: H6 | H7: H7 | I7: H8 | J7: H9 | K7: H10 | L7: H11 | M7: H12 | N7: H13 | O7: H14 | P7: H15 | Q7: H16 | R7: H17 | S7: H18 | T7: H19 | U7: H20 | V7: H21 | W7: H22 | X7: H23 | Y7: H24 | Z7: TOTAL | AA7: Días
A8: 46388 | B8: 6 | C8: 6 | D8: 6 | E8: 6 | F8: 6 | G8: 6 | H8: 6 | I8: 6 | J8: 6 | K8: 6 | L8: 6 | M8: 6 | N8: 6 | O8: 6 | P8: 6 | Q8: 6 | R8: 6 | S8: 6 | T8: 6 | U8: 6 | V8: 6 | W8: 6 | X8: 6 | Y8: 6 | Z8: =SUM(B8:Y8) -> 144 | AA8: 31 | AB8: =+Z8*AA8 -> 4464
A9: 46419 | B9: 6 | C9: 6 | D9: 6 | E9: 6 | F9: 6 | G9: 6 | H9: 6 | I9: 6 | J9: 6 | K9: 6 | L9: 6 | M9: 6 | N9: 6 | O9: 6 | P9: 6 | Q9: 6 | R9: 6 | S9: 6 | T9: 6 | U9: 6 | V9: 6 | W9: 6 | X9: 6 | Y9: 6 | Z9: =SUM(B9:Y9) -> 144 | AA9: 28 | AB9: =+Z9*AA9 -> 4032
A10: 46447 | B10: 6 | C10: 6 | D10: 6 | E10: 6 | F10: 6 | G10: 6 | H10: 6 | I10: 6 | J10: 6 | K10: 6 | L10: 6 | M10: 6 | N10: 6 | O10: 6 | P10: 6 | Q10: 6 | R10: 6 | S10: 6 | T10: 6 | U10: 6 | V10: 6 | W10: 6 | X10: 6 | Y10: 6 | Z10: =SUM(B10:Y10) -> 144 | AA10: 31 | AB10: =+Z10*AA10 -> 4464
A11: 46478 | B11: 6 | C11: 6 | D11: 6 | E11: 6 | F11: 6 | G11: 6 | H11: 6 | I11: 6 | J11: 6 | K11: 6 | L11: 6 | M11: 6 | N11: 6 | O11: 6 | P11: 6 | Q11: 6 | R11: 6 | S11: 6 | T11: 6 | U11: 6 | V11: 6 | W11: 6 | X11: 6 | Y11: 6 | Z11: =SUM(B11:Y11) -> 144 | AA11: 30 | AB11: =+Z11*AA11 -> 4320
A12: 46508 | B12: 6 | C12: 6 | D12: 6 | E12: 6 | F12: 6 | G12: 6 | H12: 6 | I12: 6 | J12: 6 | K12: 6 | L12: 6 | M12: 6 | N12: 6 | O12: 6 | P12: 6 | Q12: 6 | R12: 6 | S12: 6 | T12: 6 | U12: 6 | V12: 6 | W12: 6 | X12: 6 | Y12: 6 | Z12: =SUM(B12:Y12) -> 144 | AA12: 31 | AB12: =+Z12*AA12 -> 4464
A13: 46539 | B13: 6 | C13: 6 | D13: 6 | E13: 6 | F13: 6 | G13: 6 | H13: 6 | I13: 6 | J13: 6 | K13: 6 | L13: 6 | M13: 6 | N13: 6 | O13: 6 | P13: 6 | Q13: 6 | R13: 6 | S13: 6 | T13: 6 | U13: 6 | V13: 6 | W13: 6 | X13: 6 | Y13: 6 | Z13: =SUM(B13:Y13) -> 144 | AA13: 30 | AB13: =+Z13*AA13 -> 4320
A14: 46569 | B14: 6 | C14: 6 | D14: 6 | E14: 6 | F14: 6 | G14: 6 | H14: 6 | I14: 6 | J14: 6 | K14: 6 | L14: 6 | M14: 6 | N14: 6 | O14: 6 | P14: 6 | Q14: 6 | R14: 6 | S14: 6 | T14: 6 | U14: 6 | V14: 6 | W14: 6 | X14: 6 | Y14: 6 | Z14: =SUM(B14:Y14) -> 144 | AA14: 31 | AB14: =+Z14*AA14 -> 4464
A15: 46600 | B15: 6 | C15: 6 | D15: 6 | E15: 6 | F15: 6 | G15: 6 | H15: 6 | I15: 6 | J15: 6 | K15: 6 | L15: 6 | M15: 6 | N15: 6 | O15: 6 | P15: 6 | Q15: 6 | R15: 6 | S15: 6 | T15: 6 | U15: 6 | V15: 6 | W15: 6 | X15: 6 | Y15: 6 | Z15: =SUM(B15:Y15) -> 144 | AA15: 31 | AB15: =+Z15*AA15 -> 4464
A16: 46631 | B16: 6 | C16: 6 | D16: 6 | E16: 6 | F16: 6 | G16: 6 | H16: 6 | I16: 6 | J16: 6 | K16: 6 | L16: 6 | M16: 6 | N16: 6 | O16: 6 | P16: 6 | Q16: 6 | R16: 6 | S16: 6 | T16: 6 | U16: 6 | V16: 6 | W16: 6 | X16: 6 | Y16: 6 | Z16: =SUM(B16:Y16) -> 144 | AA16: 30 | AB16: =+Z16*AA16 -> 4320
A17: 46661 | B17: 6 | C17: 6 | D17: 6 | E17: 6 | F17: 6 | G17: 6 | H17: 6 | I17: 6 | J17: 6 | K17: 6 | L17: 6 | M17: 6 | N17: 6 | O17: 6 | P17: 6 | Q17: 6 | R17: 6 | S17: 6 | T17: 6 | U17: 6 | V17: 6 | W17: 6 | X17: 6 | Y17: 6 | Z17: =SUM(B17:Y17) -> 144 | AA17: 31 | AB17: =+Z17*AA17 -> 4464
A18: 46692 | B18: 6 | C18: 6 | D18: 6 | E18: 6 | F18: 6 | G18: 6 | H18: 6 | I18: 6 | J18: 6 | K18: 6 | L18: 6 | M18: 6 | N18: 6 | O18: 6 | P18: 6 | Q18: 6 | R18: 6 | S18: 6 | T18: 6 | U18: 6 | V18: 6 | W18: 6 | X18: 6 | Y18: 6 | Z18: =SUM(B18:Y18) -> 144 | AA18: 30 | AB18: =+Z18*AA18 -> 4320
A19: 46722 | B19: 6 | C19: 6 | D19: 6 | E19: 6 | F19: 6 | G19: 6 | H19: 6 | I19: 6 | J19: 6 | K19: 6 | L19: 6 | M19: 6 | N19: 6 | O19: 6 | P19: 6 | Q19: 6 | R19: 6 | S19: 6 | T19: 6 | U19: 6 | V19: 6 | W19: 6 | X19: 6 | Y19: 6 | Z19: =SUM(B19:Y19) -> 144 | AA19: 31 | AB19: =+Z19*AA19 -> 4464
A21: DEMANDA DIARIA ESTIMADA TOTAL [MWh]
A23: MES | B23: H1 | C23: H2 | D23: H3 | E23: H4 | F23: H5 | G23: H6 | H23: H7 | I23: H8 | J23: H9 | K23: H10 | L23: H11 | M23: H12 | N23: H13 | O23: H14 | P23: H15 | Q23: H16 | R23: H17 | S23: H18 | T23: H19 | U23: H20 | V23: H21 | W23: H22 | X23: H23 | Y23: H24 | Z23: TOTAL | AA23: Días
A24: =+A8 -> 46388 | B24: =+B8*$AA8 -> 186 | C24: =+C8*$AA8 -> 186 | D24: =+D8*$AA8 -> 186 | E24: =+E8*$AA8 -> 186 | F24: =+F8*$AA8 -> 186 | G24: =+G8*$AA8 -> 186 | H24: =+H8*$AA8 -> 186 | I24: =+I8*$AA8 -> 186 | ... Y24: =+Y8*$AA8 -> 186 | Z24: =SUM(B24:Y24) -> 4464 | AA24: =+AA8 -> 31 | AB24: =+AB8 -> 4464 | AC24: =+Z24-AB24 -> 0
A25: =+A9 -> 46419 | B25: =+B9*$AA9 -> 168 | C25: =+C9*$AA9 -> 168 | D25: =+D9*$AA9 -> 168 | E25: =+E9*$AA9 -> 168 | F25: =+F9*$AA9 -> 168 | G25: =+G9*$AA9 -> 168 | H25: =+H9*$AA9 -> 168 | I25: =+I9*$AA9 -> 168 | ... Y25: =+Y9*$AA9 -> 168 | Z25: =SUM(B25:Y25) -> 4032 | AA25: =+AA9 -> 28 | AB25: =+AB9 -> 4032 | AC25: =+Z25-AB25 -> 0
A26: =+A10 -> 46447 | B26: =+B10*$AA10 -> 186 | C26: =+C10*$AA10 -> 186 | D26: =+D10*$AA10 -> 186 | E26: =+E10*$AA10 -> 186 | F26: =+F10*$AA10 -> 186 | G26: =+G10*$AA10 -> 186 | H26: =+H10*$AA10 -> 186 | I26: =+I10*$AA10 -> 186 | ... Y26: =+Y10*$AA10 -> 186 | Z26: =SUM(B26:Y26) -> 4464 | AA26: =+AA10 -> 31 | AB26: =+AB10 -> 4464 | AC26: =+Z26-AB26 -> 0
A27: =+A11 -> 46478 | B27: =+B11*$AA11 -> 180 | C27: =+C11*$AA11 -> 180 | D27: =+D11*$AA11 -> 180 | E27: =+E11*$AA11 -> 180 | F27: =+F11*$AA11 -> 180 | G27: =+G11*$AA11 -> 180 | H27: =+H11*$AA11 -> 180 | I27: =+I11*$AA11 -> 180 | ... Y27: =+Y11*$AA11 -> 180 | Z27: =SUM(B27:Y27) -> 4320 | AA27: =+AA11 -> 30 | AB27: =+AB11 -> 4320 | AC27: =+Z27-AB27 -> 0
A28: =+A12 -> 46508 | B28: =+B12*$AA12 -> 186 | C28: =+C12*$AA12 -> 186 | D28: =+D12*$AA12 -> 186 | E28: =+E12*$AA12 -> 186 | F28: =+F12*$AA12 -> 186 | G28: =+G12*$AA12 -> 186 | H28: =+H12*$AA12 -> 186 | I28: =+I12*$AA12 -> 186 | ... Y28: =+Y12*$AA12 -> 186 | Z28: =SUM(B28:Y28) -> 4464 | AA28: =+AA12 -> 31 | AB28: =+AB12 -> 4464 | AC28: =+Z28-AB28 -> 0
A29: =+A13 -> 46539 | B29: =+B13*$AA13 -> 180 | C29: =+C13*$AA13 -> 180 | D29: =+D13*$AA13 -> 180 | E29: =+E13*$AA13 -> 180 | F29: =+F13*$AA13 -> 180 | G29: =+G13*$AA13 -> 180 | H29: =+H13*$AA13 -> 180 | I29: =+I13*$AA13 -> 180 | ... Y29: =+Y13*$AA13 -> 180 | Z29: =SUM(B29:Y29) -> 4320 | AA29: =+AA13 -> 30 | AB29: =+AB13 -> 4320 | AC29: =+Z29-AB29 -> 0
A30: =+A14 -> 46569 | B30: =+B14*$AA14 -> 186 | C30: =+C14*$AA14 -> 186 | D30: =+D14*$AA14 -> 186 | E30: =+E14*$AA14 -> 186 | F30: =+F14*$AA14 -> 186 | G30: =+G14*$AA14 -> 186 | H30: =+H14*$AA14 -> 186 | I30: =+I14*$AA14 -> 186 | ... Y30: =+Y14*$AA14 -> 186 | Z30: =SUM(B30:Y30) -> 4464 | AA30: =+AA14 -> 31 | AB30: =+AB14 -> 4464 | AC30: =+Z30-AB30 -> 0
A31: =+A15 -> 46600 | B31: =+B15*$AA15 -> 186 | C31: =+C15*$AA15 -> 186 | D31: =+D15*$AA15 -> 186 | E31: =+E15*$AA15 -> 186 | F31: =+F15*$AA15 -> 186 | G31: =+G15*$AA15 -> 186 | H31: =+H15*$AA15 -> 186 | I31: =+I15*$AA15 -> 186 | ... Y31: =+Y15*$AA15 -> 186 | Z31: =SUM(B31:Y31) -> 4464 | AA31: =+AA15 -> 31 | AB31: =+AB15 -> 4464 | AC31: =+Z31-AB31 -> 0
A32: =+A16 -> 46631 | B32: =+B16*$AA16 -> 180 | C32: =+C16*$AA16 -> 180 | D32: =+D16*$AA16 -> 180 | E32: =+E16*$AA16 -> 180 | F32: =+F16*$AA16 -> 180 | G32: =+G16*$AA16 -> 180 | H32: =+H16*$AA16 -> 180 | I32: =+I16*$AA16 -> 180 | ... Y32: =+Y16*$AA16 -> 180 | Z32: =SUM(B32:Y32) -> 4320 | AA32: =+AA16 -> 30 | AB32: =+AB16 -> 4320 | AC32: =+Z32-AB32 -> 0
A33: =+A17 -> 46661 | B33: =+B17*$AA17 -> 186 | C33: =+C17*$AA17 -> 186 | D33: =+D17*$AA17 -> 186 | E33: =+E17*$AA17 -> 186 | F33: =+F17*$AA17 -> 186 | G33: =+G17*$AA17 -> 186 | H33: =+H17*$AA17 -> 186 | I33: =+I17*$AA17 -> 186 | ... Y33: =+Y17*$AA17 -> 186 | Z33: =SUM(B33:Y33) -> 4464 | AA33: =+AA17 -> 31 | AB33: =+AB17 -> 4464 | AC33: =+Z33-AB33 -> 0
A34: =+A18 -> 46692 | B34: =+B18*$AA18 -> 180 | C34: =+C18*$AA18 -> 180 | D34: =+D18*$AA18 -> 180 | E34: =+E18*$AA18 -> 180 | F34: =+F18*$AA18 -> 180 | G34: =+G18*$AA18 -> 180 | H34: =+H18*$AA18 -> 180 | I34: =+I18*$AA18 -> 180 | ... Y34: =+Y18*$AA18 -> 180 | Z34: =SUM(B34:Y34) -> 4320 | AA34: =+AA18 -> 30 | AB34: =+AB18 -> 4320 | AC34: =+Z34-AB34 -> 0
A35: =+A19 -> 46722 | B35: =+B19*$AA19 -> 186 | C35: =+C19*$AA19 -> 186 | D35: =+D19*$AA19 -> 186 | E35: =+E19*$AA19 -> 186 | F35: =+F19*$AA19 -> 186 | G35: =+G19*$AA19 -> 186 | H35: =+H19*$AA19 -> 186 | I35: =+I19*$AA19 -> 186 | ... Y35: =+Y19*$AA19 -> 186 | Z35: =SUM(B35:Y35) -> 4464 | AA35: =+AA19 -> 31 | AB35: =+AB19 -> 4464 | AC35: =+Z35-AB35 -> 0
