Workbook

Sheet Oferta Producto 1
B2: ANEXO. CANTIDADES DE ENERGÍA Y PRECIO
B3: PRODUCTO: | C3: 1
B4: OFERTA MERCANTIL No.
B5: INVITACIÓN | C5: CP-CHCC2026-001
B6: OFERENTE:
B7: AÑO: | C7: 2027
B8: CANTIDAD EN: | C8: kWh
B9: EN PESOS DE | C9: 46023
B10: INDICADOR: | C10: IPP- PROVISIONAL
B11: TIPO DE CONTRATO: | C11: PLC
B12: TIPO DE CARGA: | C12: CURVA
B14: Fecha | C14: Energia Solicitada kWh | D14: Porcentaje Ofertado % | E14: Energia Ofertada kWh | F14: Precio $/KWh
B15: 46388 | C15: =+'Cantidad Producto 1-2027'!AE7 -> 21160717 | E15: =+C15*D15 -> 0
B16: 46419 | C16: =+'Cantidad Producto 1-2027'!AE8 -> 19666280 | E16: =+C16*D16 -> 0
B17: 46447 | C17: =+'Cantidad Producto 1-2027'!AE9 -> 20632850 | E17: =+C17*D17 -> 0
B18: 46478 | C18: =+'Cantidad Producto 1-2027'!AE10 -> 20862710 | E18: =+C18*D18 -> 0
B19: 46508 | C19: =+'Cantidad Producto 1-2027'!AE11 -> 13081884 | E19: =+C19*D19 -> 0
B20: 46539 | C20: =+'Cantidad Producto 1-2027'!AE12 -> 13075450 | E20: =+C20*D20 -> 0
B21: 46569 | C21: =+'Cantidad Producto 1-2027'!AE13 -> 15106714 | E21: =+C21*D21 -> 0
B22: 46600 | C22: =+'Cantidad Producto 1-2027'!AE14 -> 14925358 | E22: =+C22*D22 -> 0
B23: 46631 | C23: =+'Cantidad Producto 1-2027'!AE15 -> 16716840 | E23: =+C23*D23 -> 0
B24: 46661 | C24: =+'Cantidad Producto 1-2027'!AE16 -> 22181361 | E24: =+C24*D24 -> 0
B25: 46692 | C25: =+'Cantidad Producto 1-2027'!AE17 -> 21509490 | E25: =+C25*D25 -> 0
B26: 46722 | C26: =+'Cantidad Producto 1-2027'!AE18 -> 22442595 | E26: =+C26*D26 -> 0
B27: Total producto | C27: =SUM(C15:C26) -> 221362249 | D27: %
B29: Notas:
B30: 1) La energía ofertada debe corresponder a lo establecido en el Anexo 8.1.
B31: 2) El porcentaje y el precio ofertado deben permanecer iguales para todos los meses del año
B32: 3) El precio debe ser presentado en $/kWh, expresado en pesos de enero de 2026.
B33: 4) Solo se evaluarán las ofertas que sigan la curva de carga.
B34: 5)No se tendrán en cuenta ofertas que incluyan condiciones y/o modificaciones adicionales a los Pliegos definitivos.
B39: OFERENTE E.S.P

Sheet Oferta Producto 2
B2: ANEXO. CANTIDADES DE ENERGÍA Y PRECIO
B3: PRODUCTO: | C3: 2
B4: OFERTA MERCANTIL No.
B5: INVITACIÓN | C5: CP-CHCC2026-001
B6: OFERENTE:
B7: AÑO: | C7: 2028
B8: CANTIDAD EN: | C8: kWh
B9: EN PESOS DE | C9: 46023
B10: INDICADOR: | C10: IPP- PROVISIONAL
B11: TIPO DE CONTRATO: | C11: PLC
B12: TIPO DE CARGA: | C12: CURVA
B14: Fecha | C14: Energia Solicitada kWh | D14: Porcentaje Ofertado % | E14: Energia Ofertada kWh | F14: Precio $/KWh
B15: 46753 | C15: =+'Cantidad Producto 2-2028'!AE7 -> 6104641
B16: 46784 | C16: =+'Cantidad Producto 2-2028'!AE8 -> 5712690
B17: 46813 | C17: =+'Cantidad Producto 2-2028'!AE9 -> 5944863
B18: 46844 | C18: =+'Cantidad Producto 2-2028'!AE10 -> 5945886
B19: 46874 | C19: =+'Cantidad Producto 2-2028'!AE11 -> 5919594
B20: 46905 | C20: =+'Cantidad Producto 2-2028'!AE12 -> 6098112
B21: 46935 | C21: =+'Cantidad Producto 2-2028'!AE13 -> 6557268
B22: 46966 | C22: =+'Cantidad Producto 2-2028'!AE14 -> 6194133
B23: 46997 | C23: =+'Cantidad Producto 2-2028'!AE15 -> 5869856
B24: 47027 | C24: =+'Cantidad Producto 2-2028'!AE16 -> 6068014
B25: 47058 | C25: =+'Cantidad Producto 2-2028'!AE17 -> 5937618
B26: 47088 | C26: =+'Cantidad Producto 2-2028'!AE18 -> 6251095
B27: Total producto | C27: =SUM(C15:C26) -> 72603770 | D27: %
B29: Notas:
B30: Notas:
B31: 1) La energía ofertada debe corresponder a lo establecido en el Anexo 8.2
B32: 2) El porcentaje y el precio ofertado deben permanecer iguales para todos los meses del año
B33: 3) El precio debe ser presentado en $/kWh, expresado en pesos de enero de 2026.
B34: 4) Solo se evaluarán las ofertas que sigan la curva de carga.
B35: 5)No se tendrán en cuenta ofertas que incluyan condiciones y/o modificaciones adicionales a los Pliegos definitivos.
B40: OFERENTE E.S.P

Sheet Oferta Producto 3
B2: ANEXO. CANTIDADES DE ENERGÍA Y PRECIO
B3: PRODUCTO: | C3: 3
B4: OFERTA MERCANTIL No.
B5: INVITACIÓN | C5: =+'Oferta Producto 1'!C5 -> CP-CHCC2026-001
B6: OFERENTE:
B7: AÑO: | C7: 2029
B8: CANTIDAD EN: | C8: kWh
B9: EN PESOS DE | C9: =+'Oferta Producto 1'!C9 -> 46023
B10: INDICADOR: | C10: IPP- PROVISIONAL
B11: TIPO DE CONTRATO: | C11: PLC
B12: TIPO DE CARGA: | C12: CURVA
B14: Fecha | C14: Energia Solicitada kWh | D14: Porcentaje Ofertado % | E14: Energia Ofertada kWh | F14: Precio $/KWh
B15: 47119 | C15: =+'Cantidad Producto3-2029'!AE7 -> 10369193
B16: 47150 | C16: =+'Cantidad Producto3-2029'!AE8 -> 9610152
B17: 47178 | C17: =+'Cantidad Producto3-2029'!AE9 -> 10033768
B18: 47209 | C18: =+'Cantidad Producto3-2029'!AE10 -> 10103775
B19: 47239 | C19: =+'Cantidad Producto3-2029'!AE11 -> 10080661
B20: 47270 | C20: =+'Cantidad Producto3-2029'!AE12 -> 10232240
B21: 47300 | C21: =+'Cantidad Producto3-2029'!AE13 -> 10757818
B22: 47331 | C22: =+'Cantidad Producto3-2029'!AE14 -> 10593018
B23: 47362 | C23: =+'Cantidad Producto3-2029'!AE15 -> 10083685
B24: 47392 | C24: =+'Cantidad Producto3-2029'!AE16 -> 10452286
B25: 47423 | C25: =+'Cantidad Producto3-2029'!AE17 -> 10239540
B26: 47453 | C26: =+'Cantidad Producto3-2029'!AE18 -> 10677244
B27: Total producto | C27: =SUM(C15:C26) -> 123233380 | D27: %
B29: Notas:
B30: 1) La energía ofertada debe corresponder a lo establecido en el Anexo 8.3
B31: 2) El porcentaje y el precio ofertado deben permanecer iguales para todos los meses del año
B32: 3) El precio debe ser presentado en $/kWh, expresado en pesos de enero de 2026.
B33: 4) Solo se evaluarán las ofertas que sigan la curva de carga.
B34: 5) No se tendrán en cuenta ofertas que incluyan condiciones y/o modificaciones adicionales a los Pliegos definitivos.
B38: OFERENTE E.S.P

Sheet Oferta Producto 4
B2: ANEXO. CANTIDADES DE ENERGÍA Y PRECIO
B3: PRODUCTO: | C3: 4
B4: OFERTA MERCANTIL No.
B5: INVITACIÓN | C5: =+'Oferta Producto 1'!C5 -> CP-CHCC2026-001
B6: OFERENTE:
B7: AÑO: | C7: 2030
B8: CANTIDAD EN: | C8: kWh
B9: EN PESOS DE | C9: =+'Oferta Producto 1'!C9 -> 46023
B10: INDICADOR: | C10: IPP- PROVISIONAL
B11: TIPO DE CONTRATO: | C11: PLC
B12: TIPO DE CARGA: | C12: CURVA
B14: Fecha | C14: Energia Solicitada kWh | D14: Porcentaje Ofertado % | E14: Energia Ofertada kWh | F14: Precio $/KWh
B15: 47484 | C15: =+'Cantidad Producto 4-2030'!AE7 -> 23463619
B16: 47515 | C16: =+'Cantidad Producto 4-2030'!AE8 -> 21983264
B17: 47543 | C17: =+'Cantidad Producto 4-2030'!AE9 -> 22930560
B18: 47574 | C18: =+'Cantidad Producto 4-2030'!AE10 -> 23011184
B19: 47604 | C19: =+'Cantidad Producto 4-2030'!AE11 -> 22947941
B20: 47635 | C20: =+'Cantidad Producto 4-2030'!AE12 -> 23112949
B21: 47665 | C21: =+'Cantidad Producto 4-2030'!AE13 -> 23935549
B22: 47696 | C22: =+'Cantidad Producto 4-2030'!AE14 -> 23893234
B23: 47727 | C23: =+'Cantidad Producto 4-2030'!AE15 -> 22902751
B24: 47757 | C24: =+'Cantidad Producto 4-2030'!AE16 -> 23690538
B25: 47788 | C25: =+'Cantidad Producto 4-2030'!AE17 -> 23238819
B26: 47818 | C26: =+'Cantidad Producto 4-2030'!AE18 -> 24027837
B27: Total producto | C27: =SUM(C15:C26) -> 279138245 | D27: %
B29: Notas:
B30: 1) La energía ofertada debe corresponder a lo establecido en el Anexo 8.4
B31: 2) El porcentaje y el precio ofertado deben permanecer iguales para todos los meses del año
B32: 3) El precio debe ser presentado en $/kWh, expresado en pesos de enero de 2026.
B33: 4) Solo se evaluarán las ofertas que sigan la curva de carga.
B34: 5) No se tendrán en cuenta ofertas que incluyan condiciones y/o modificaciones adicionales a los Pliegos definitivos.
B39: OFERENTE E.S.P

Sheet Oferta Producto 5
B2: ANEXO. CANTIDADES DE ENERGÍA Y PRECIO
B3: PRODUCTO: | C3: 5
B4: OFERTA MERCANTIL No.
B5: INVITACIÓN | C5: =+'Oferta Producto 1'!C5 -> CP-CHCC2026-001
B6: OFERENTE:
B7: AÑO: | C7: 2031
B8: CANTIDAD EN: | C8: kWh
B9: EN PESOS DE | C9: =+'Oferta Producto 1'!C9 -> 46023
B10: INDICADOR: | C10: IPP- PROVISIONAL
B11: TIPO DE CONTRATO: | C11: PLC
B12: TIPO DE CARGA: | C12: CURVA
B14: Fecha | C14: Energia Solicitada kWh | D14: Porcentaje Ofertado % | E14: Energia Ofertada kWh | F14: Precio $/KWh
B15: 47484 | C15: =+'Cantidad Producto 5-2031'!AE7 -> 25540072
B16: 47515 | C16: =+'Cantidad Producto 5-2031'!AE8 -> 23863988
B17: 47543 | C17: =+'Cantidad Producto 5-2031'!AE9 -> 25133146
B18: 47574 | C18: =+'Cantidad Producto 5-2031'!AE10 -> 25175078
B19: 47604 | C19: =+'Cantidad Producto 5-2031'!AE11 -> 25029031
B20: 47635 | C20: =+'Cantidad Producto 5-2031'!AE12 -> 25005430
B21: 47665 | C21: =+'Cantidad Producto 5-2031'!AE13 -> 25526198
B22: 47696 | C22: =+'Cantidad Producto 5-2031'!AE14 -> 26065129
B23: 47727 | C23: =+'Cantidad Producto 5-2031'!AE15 -> 24899520
B24: 47757 | C24: =+'Cantidad Producto 5-2031'!AE16 -> 25960421
B25: 47788 | C25: =+'Cantidad Producto 5-2031'!AE17 -> 25357228
B26: 47818 | C26: =+'Cantidad Producto 5-2031'!AE18 -> 26212931
B27: Total producto | C27: =SUM(C15:C26) -> 303768172 | D27: %
B29: Notas:
B30: 1) La energía ofertada debe corresponder a lo establecido en el Anexo 8.5
B31: 2) El porcentaje y el precio ofertado deben permanecer iguales para todos los meses del año
B32: 3) El precio debe ser presentado en $/kWh, expresado en pesos de enero de 2026.
B33: 4) Solo se evaluarán las ofertas que sigan la curva de carga.
B34: 5) No se tendrán en cuenta ofertas que incluyan condiciones y/o modificaciones adicionales a los Pliegos definitivos.
B39: OFERENTE E.S.P

Sheet Oferta Producto 6 
B2: ANEXO. CANTIDADES DE ENERGÍA Y PRECIO
B3: PRODUCTO: | C3: 6
B4: OFERTA MERCANTIL No.
B5: INVITACIÓN | C5: =+'Oferta Producto 1'!C5 -> CP-CHCC2026-001
B6: OFERENTE:
B7: AÑO: | C7: 2027-2031
B8: CANTIDAD EN: | C8: kWh
B9: EN PESOS DE | C9: =+'Oferta Producto 1'!C9 -> 46023
B10: INDICADOR: | C10: IPP- PROVISIONAL
B11: TIPO DE CONTRATO: | C11: PLC
B12: TIPO DE CARGA: | C12: CURVA
B14: Fecha | C14: Energia Solicitada kWh | D14: Porcentaje Ofertado % | E14: Energia Ofertada kWh | F14: Precio $/KWh
B15: 46388 | C15: 3720000
B16: 46419 | C16: 3360000
B17: 46447 | C17: 3720000
B18: 46478 | C18: 3600000
B19: 46508 | C19: 3720000
B20: 46539 | C20: 3600000
B21: 46569 | C21: 3720000
B22: 46600 | C22: 3720000
B23: 46631 | C23: 3600000
B24: 46661 | C24: 3720000
B25: 46692 | C25: 3600000
B26: 46722 | C26: 3720000
B27: Total año | C27: =SUM(C15:C26) -> 43800000
B28: 46753 | C28: 3720000
B29: 46784 | C29: 3480000
B30: 46813 | C30: 3720000
B31: 46844 | C31: 3600000
B32: 46874 | C32: 3720000
B33: 46905 | C33: 3600000
B34: 46935 | C34: 3720000
B35: 46966 | C35: 3720000
B36: 46997 | C36: 3600000
B37: 47027 | C37: 3720000
B38: 47058 | C38: 3600000
B39: 47088 | C39: 3720000
B40: Total año | C40: =SUM(C28:C39) -> 43920000
B41: 47119 | C41: 3720000
B42: 47150 | C42: 3360000
...

Sheet Cantidad Producto 1-2027
B2: CANTIDADES DE ENERGÍA SOLICITADAS (kWh)
B3: CENTRAL HIDROELECTRICA DE CALDAS S.A. E.S.P. -BENEFICIO E INTERÉS COLECTIVO
B4: 2027
B6: Mes | C6: Tipo Día | D6: Días | E6: H1 | F6: H2 | G6: H3 | H6: H4 | I6: H5 | J6: H6 | K6: H7 | L6: H8 | M6: H9 | N6: H10 | O6: H11 | P6: H12 | Q6: H13 | R6: H14 | S6: H15 | T6: H16 | U6: H17 | V6: H18 | W6: H19 | X6: H20 | Y6: H21 | Z6: H22 | AA6: H23 | AB6: H24 | AC6: TOTAL MES
B7: Ene | C7: Ordinario | D7: 19 | E7: 16613 | F7: 15788 | G7: 15218 | H7: 15006 | I7: 16235 | J7: 19814 | K7: 22646 | L7: 34328 | M7: 34359 | N7: 34611 | O7: 35680 | P7: 37670 | Q7: 35855 | R7: 35042 | S7: 36101 | T7: 37129 | U7: 37319 | V7: 32112 | W7: 35239 | X7: 35827 | Y7: 34099 | Z7: 31078 | AA7: 25657 | AB7: 22570 | AC7: =+SUM(E7:AB7)*D7+SUM(E8:AB8)*D8+SUM(E9:AB9)*D9+SUM(E10:AB10)*D10 -> 21160717 | AE7: =+AC7 -> 21160717
B8: Ene | C8: Sábado | D8: 5 | E8: 17810 | F8: 16343 | G8: 15740 | H8: 15403 | I8: 15731 | J8: 16786 | K8: 18311 | L8: 31812 | M8: 34034 | N8: 35200 | O8: 35858 | P8: 37090 | Q8: 37728 | R8: 37069 | S8: 36942 | T8: 36823 | U8: 37115 | V8: 32003 | W8: 35782 | X8: 36129 | Y8: 34448 | Z8: 32224 | AA8: 28459 | AB8: 25645 | AE8: =+AC11 -> 19666280
B9: Ene | C9: Domingo | D9: 5 | E9: 19399 | F9: 17931 | G9: 16978 | H9: 16258 | I9: 15955 | J9: 15556 | K9: 15455 | L9: 26478 | M9: 28564 | N9: 29670 | O9: 31225 | P9: 32965 | Q9: 33600 | R9: 32941 | S9: 33689 | T9: 34608 | U9: 34706 | V9: 30557 | W9: 34005 | X9: 34138 | Y9: 32343 | Z9: 29643 | AA9: 25223 | AB9: 22003 | AE9: =+AC15 -> 20632850
B10: Ene | C10: Festivo | D10: 2 | E10: 18999 | F10: 18005 | G10: 16742 | H10: 16402 | I10: 15773 | J10: 15517 | K10: 13995 | L10: 23782 | M10: 24903 | N10: 26389 | O10: 28449 | P10: 29265 | Q10: 30766 | R10: 31396 | S10: 32072 | T10: 31986 | U10: 32154 | V10: 28901 | W10: 32255 | X10: 32918 | Y10: 32046 | Z10: 28752 | AA10: 24507 | AB10: 21485 | AE10: =+AC19 -> 20862710
B11: Feb | C11: Ordinario | D11: 20 | E11: 16036 | F11: 15811 | G11: 15158 | H11: 15641 | I11: 16056 | J11: 22297 | K11: 25144 | L11: 36712 | M11: 36098 | N11: 36038 | O11: 37091 | P11: 38203 | Q11: 37307 | R11: 37314 | S11: 38245 | T11: 38808 | U11: 38434 | V11: 31633 | W11: 35096 | X11: 35744 | Y11: 34176 | Z11: 31092 | AA11: 26374 | AB11: 22384 | AC11: =+SUM(E11:AB11)*D11+SUM(E12:AB12)*D12+SUM(E13:AB13)*D13+SUM(E14:AB14)*D14 -> 19666280 | AE11: =+AC23 -> 13081884
B12: Feb | C12: Sábado | D12: 4 | E12: 17596 | F12: 16513 | G12: 15873 | H12: 15457 | I12: 15824 | J12: 16772 | K12: 18925 | L12: 33793 | M12: 35567 | N12: 36217 | O12: 37196 | P12: 38173 | Q12: 37619 | R12: 36780 | S12: 36663 | T12: 36477 | U12: 36843 | V12: 31236 | W12: 34118 | X12: 35169 | Y12: 33623 | Z12: 30207 | AA12: 26449 | AB12: 22956 | AE12: =+AC27 -> 13075450
B13: Feb | C13: Domingo | D13: 4 | E13: 17964 | F13: 16654 | G13: 15633 | H13: 15126 | I13: 14917 | J13: 14820 | K13: 14905 | L13: 27432 | M13: 29922 | N13: 31788 | O13: 32030 | P13: 33620 | Q13: 35185 | R13: 35406 | S13: 34541 | T13: 36031 | U13: 32694 | V13: 28116 | W13: 33566 | X13: 31788 | Y13: 31201 | Z13: 28321 | AA13: 23965 | AB13: 20439 | AE13: =+AC31 -> 15106714
B14: Feb | C14: Festivo | D14: 0 | E14: 0 | F14: 0 | G14: 0 | H14: 0 | I14: 0 | J14: 0 | K14: 0 | L14: 0 | M14: 0 | N14: 0 | O14: 0 | P14: 0 | Q14: 0 | R14: 0 | S14: 0 | T14: 0 | U14: 0 | V14: 0 | W14: 0 | X14: 0 | Y14: 0 | Z14: 0 | AA14: 0 | AB14: 0 | AE14: =+AC35 -> 14925358
B15: Mar | C15: Ordinario | D15: 20 | E15: 15379 | F15: 14594 | G15: 14352 | H15: 14293 | I15: 15915 | J15: 20872 | K15: 23166 | L15: 33627 | M15: 33077 | N15: 33258 | O15: 33651 | P15: 35750 | Q15: 35255 | R15: 35068 | S15: 36093 | T15: 36409 | U15: 35500 | V15: 30470 | W15: 33649 | X15: 34937 | Y15: 33655 | Z15: 29551 | AA15: 25435 | AB15: 21568 | AC15: =+SUM(E15:AB15)*D15+SUM(E16:AB16)*D16+SUM(E17:AB17)*D17+SUM(E18:AB18)*D18 -> 20632850 | AE15: =+AC39 -> 16716840
B16: Mar | C16: Sábado | D16: 4 | E16: 14939 | F16: 15376 | G16: 14923 | H16: 14670 | I16: 15189 | J16: 16627 | K16: 18775 | L16: 32583 | M16: 34187 | N16: 35280 | O16: 35612 | P16: 35611 | Q16: 35850 | R16: 35268 | S16: 35330 | T16: 35510 | U16: 35041 | V16: 30083 | W16: 32133 | X16: 34251 | Y16: 32901 | Z16: 30299 | AA16: 26800 | AB16: 23451 | AE16: =+AC43 -> 22181361
B17: Mar | C17: Domingo | D17: 4 | E17: 17360 | F17: 16392 | G17: 15184 | H17: 15384 | I17: 15311 | J17: 12918 | K17: 14438 | L17: 26259 | M17: 28532 | N17: 29371 | O17: 30700 | P17: 32343 | Q17: 32216 | R17: 32934 | S17: 32493 | T17: 32361 | U17: 31821 | V17: 27630 | W17: 30436 | X17: 32479 | Y17: 32827 | Z17: 29586 | AA17: 25620 | AB17: 21483 | AE17: =+AC47 -> 21509490
B18: Mar | C18: Festivo | D18: 3 | E18: 18043 | F18: 17422 | G18: 16376 | H18: 16290 | I18: 16383 | J18: 15885 | K18: 16197 | L18: 27876 | M18: 29610 | N18: 30725 | O18: 32673 | P18: 33830 | Q18: 34901 | R18: 34386 | S18: 34780 | T18: 34604 | U18: 34199 | V18: 30083 | W18: 34422 | X18: 35467 | Y18: 34225 | Z18: 31695 | AA18: 26071 | AB18: 22291 | AE18: =+AC51 -> 22442595
B19: Abr | C19: Ordinario | D19: 22 | E19: 16050 | F19: 15337 | G19: 15312 | H19: 14986 | I19: 16377 | J19: 20734 | K19: 23551 | L19: 34691 | M19: 34244 | N19: 34068 | O19: 35745 | P19: 36974 | Q19: 36770 | R19: 36817 | S19: 38231 | T19: 38187 | U19: 37955 | V19: 31953 | W19: 35060 | X19: 35860 | Y19: 34736 | Z19: 31536 | AA19: 26732 | AB19: 22689 | AC19: =+SUM(E19:AB19)*D19+SUM(E20:AB20)*D20+SUM(E21:AB21)*D21+SUM(E22:AB22)*D22 -> 20862710 | AE19: =SUM(AE7:AE18) -> 221362249
B20: Abr | C20: Sábado | D20: 4 | E20: 17509 | F20: 16513 | G20: 15927 | H20: 15777 | I20: 16322 | J20: 17099 | K20: 17702 | L20: 32680 | M20: 33626 | N20: 34372 | O20: 35906 | P20: 36047 | Q20: 37367 | R20: 36392 | S20: 36979 | T20: 37295 | U20: 37549 | V20: 30907 | W20: 36164 | X20: 34431 | Y20: 32873 | Z20: 30949 | AA20: 27774 | AB20: 26768
B21: Abr | C21: Domingo | D21: 4 | E21: 18704 | F21: 17231 | G21: 16177 | H21: 15940 | I21: 15113 | J21: 15052 | K21: 15591 | L21: 27052 | M21: 29875 | N21: 30699 | O21: 32037 | P21: 32533 | Q21: 34009 | R21: 34033 | S21: 33867 | T21: 33460 | U21: 34298 | V21: 29613 | W21: 33038 | X21: 33682 | Y21: 33208 | Z21: 30860 | AA21: 27485 | AB21: 21920
B22: Abr | C22: Festivo | D22: 0 | E22: 27608 | F22: 24521 | G22: 23220 | H22: 22148 | I22: 22363 | J22: 23052 | K22: 24962 | L22: 33253 | M22: 36755 | N22: 38703 | O22: 40076 | P22: 43733 | Q22: 44907 | R22: 43706 | S22: 43103 | T22: 42394 | U22: 42032 | V22: 47439 | W22: 52553 | X22: 54267 | Y22: 52319 | Z22: 49543 | AA22: 44673 | AB22: 38580
B23: May | C23: Ordinario | D23: 19 | E23: 9410 | F23: 8966 | G23: 8652 | H23: 8751 | I23: 9664 | J23: 12577 | K23: 14195 | L23: 21312 | M23: 20973 | N23: 20498 | O23: 21165 | P23: 22611 | Q23: 22234 | R23: 22506 | S23: 23371 | T23: 23442 | U23: 23134 | V23: 20243 | W23: 22106 | X23: 22648 | Y23: 21690 | Z23: 19717 | AA23: 16937 | AB23: 14379 | AC23: =+SUM(E23:AB23)*D23+SUM(E24:AB24)*D24+SUM(E25:AB25)*D25+SUM(E26:AB26)*D26 -> 13081884
B24: May | C24: Sábado | D24: 4 | E24: 10389 | F24: 9317 | G24: 9151 | H24: 9022 | I24: 9310 | J24: 9643 | K24: 10953 | L24: 19965 | M24: 21232 | N24: 21846 | O24: 22048 | P24: 22213 | Q24: 22446 | R24: 21785 | S24: 21700 | T24: 21729 | U24: 21649 | V24: 19181 | W24: 21152 | X24: 22158 | Y24: 21139 | Z24: 19726 | AA24: 17437 | AB24: 15149
B25: May | C25: Domingo | D25: 5 | E25: 10516 | F25: 9849 | G25: 8928 | H25: 8722 | I25: 8343 | J25: 8371 | K25: 8728 | L25: 16761 | M25: 18300 | N25: 19131 | O25: 19765 | P25: 20034 | Q25: 20386 | R25: 19898 | S25: 19580 | T25: 19909 | U25: 20856 | V25: 16615 | W25: 20314 | X25: 21001 | Y25: 20406 | Z25: 18620 | AA25: 15795 | AB25: 13074
B26: May | C26: Festivo | D26: 3 | E26: 9053 | F26: 9846 | G26: 9805 | H26: 9178 | I26: 9955 | J26: 10279 | K26: 10932 | L26: 19315 | M26: 20014 | N26: 21460 | O26: 22593 | P26: 23712 | Q26: 24533 | R26: 24350 | S26: 23179 | T26: 23016 | U26: 22124 | V26: 19674 | W26: 22218 | X26: 21946 | Y26: 20970 | Z26: 19662 | AA26: 17108 | AB26: 14603
B27: Jun | C27: Ordinario | D27: 21 | E27: 9029 | F27: 8400 | G27: 8212 | H27: 8105 | I27: 9141 | J27: 11764 | K27: 13616 | L27: 22440 | M27: 22214 | N27: 22588 | O27: 23428 | P27: 24253 | Q27: 24084 | R27: 24046 | S27: 24835 | T27: 24825 | U27: 24804 | V27: 20893 | W27: 23384 | X27: 23716 | Y27: 22282 | Z27: 19889 | AA27: 16743 | AB27: 14134 | AC27: =+SUM(E27:AB27)*D27+SUM(E28:AB28)*D28+SUM(E29:AB29)*D29+SUM(E30:AB30)*D30 -> 13075450
B28: Jun | C28: Sábado | D28: 4 | E28: 9591 | F28: 8782 | G28: 8404 | H28: 8141 | I28: 8535 | J28: 9263 | K28: 10409 | L28: 21032 | M28: 21997 | N28: 22563 | O28: 23214 | P28: 23524 | Q28: 23602 | R28: 23084 | S28: 22613 | T28: 22603 | U28: 22484 | V28: 19394 | W28: 21632 | X28: 22735 | Y28: 21617 | Z28: 19794 | AA28: 17697 | AB28: 15274
B29: Jun | C29: Domingo | D29: 4 | E29: 10872 | F29: 9760 | G29: 9135 | H29: 8868 | I29: 8591 | J29: 8351 | K29: 8310 | L29: 17366 | M29: 18782 | N29: 19913 | O29: 20438 | P29: 20861 | Q29: 21067 | R29: 21012 | S29: 20555 | T29: 20734 | U29: 20939 | V29: 18202 | W29: 20291 | X29: 21437 | Y29: 20645 | Z29: 19097 | AA29: 16834 | AB29: 14270
B30: Jun | C30: Festivo | D30: 1 | E30: 9542 | F30: 8859 | G30: 8346 | H30: 8135 | I30: 8200 | J30: 8208 | K30: 7924 | L30: 16805 | M30: 17451 | N30: 17991 | O30: 20147 | P30: 21111 | Q30: 22314 | R30: 22110 | S30: 21949 | T30: 21927 | U30: 21460 | V30: 18523 | W30: 21134 | X30: 21869 | Y30: 21064 | Z30: 19366 | AA30: 16518 | AB30: 13916
B31: Jul | C31: Ordinario | D31: 20 | E31: 12378 | F31: 11772 | G31: 11453 | H31: 11472 | I31: 12453 | J31: 15409 | K31: 17178 | L31: 24858 | M31: 24662 | N31: 24945 | O31: 25376 | P31: 26964 | Q31: 26401 | R31: 26498 | S31: 27225 | T31: 27305 | U31: 26913 | V31: 22009 | W31: 23846 | X31: 25286 | Y31: 24131 | Z31: 21709 | AA31: 18286 | AB31: 15839 | AC31: =+SUM(E31:AB31)*D31+SUM(E32:AB32)*D32+SUM(E33:AB33)*D33+SUM(E34:AB34)*D34 -> 15106714
B32: Jul | C32: Sábado | D32: 5 | E32: 13271 | F32: 12518 | G32: 11942 | H32: 11801 | I32: 12018 | J32: 12443 | K32: 13538 | L32: 23494 | M32: 24522 | N32: 25106 | O32: 25327 | P32: 26200 | Q32: 26490 | R32: 26135 | S32: 25772 | T32: 25392 | U32: 24961 | V32: 20746 | W32: 22122 | X32: 23605 | Y32: 22316 | Z32: 20430 | AA32: 18108 | AB32: 15923
B33: Jul | C33: Domingo | D33: 4 | E33: 12427 | F33: 11620 | G33: 11142 | H33: 10896 | I33: 10697 | J33: 10328 | K33: 10655 | L33: 18868 | M33: 20363 | N33: 20995 | O33: 21519 | P33: 22855 | Q33: 23149 | R33: 23322 | S33: 23180 | T33: 23051 | U33: 22944 | V33: 18895 | W33: 21124 | X33: 23084 | Y33: 22376 | Z33: 20059 | AA33: 16873 | AB33: 14402
B34: Jul | C34: Festivo | D34: 2 | E34: 14560 | F34: 13567 | G34: 12580 | H34: 11710 | I34: 11496 | J34: 10479 | K34: 10704 | L34: 18890 | M34: 20935 | N34: 20789 | O34: 20183 | P34: 21597 | Q34: 22273 | R34: 22759 | S34: 21480 | T34: 21571 | U34: 21720 | V34: 17565 | W34: 19183 | X34: 21592 | Y34: 21732 | Z34: 19787 | AA34: 17204 | AB34: 15223
B35: Ago | C35: Ordinario | D35: 21 | E35: 11687 | F35: 10833 | G35: 10515 | H35: 10457 | I35: 11843 | J35: 15894 | K35: 19235 | L35: 26240 | M35: 25034 | N35: 24756 | O35: 25163 | P35: 26103 | Q35: 25792 | R35: 25975 | S35: 27133 | T35: 27552 | U35: 27492 | V35: 23478 | W35: 25092 | X35: 26466 | Y35: 24954 | Z35: 22044 | AA35: 18357 | AB35: 15872 | AC35: =+SUM(E35:AB35)*D35+SUM(E36:AB36)*D36+SUM(E37:AB37)*D37+SUM(E38:AB38)*D38 -> 14925358
B36: Ago | C36: Sábado | D36: 3 | E36: 12925 | F36: 11953 | G36: 11237 | H36: 10799 | I36: 10435 | J36: 8937 | K36: 10655 | L36: 22031 | M36: 24437 | N36: 24537 | O36: 24114 | P36: 24275 | Q36: 25183 | R36: 25775 | S36: 24166 | T36: 24081 | U36: 23881 | V36: 21227 | W36: 22375 | X36: 23123 | Y36: 21406 | Z36: 19500 | AA36: 16991 | AB36: 15545
B37: Ago | C37: Domingo | D37: 5 | E37: 12022 | F37: 11168 | G37: 10316 | H37: 9852 | I37: 9157 | J37: 8456 | K37: 7753 | L37: 15645 | M37: 16992 | N37: 17944 | O37: 18511 | P37: 19684 | Q37: 21021 | R37: 21259 | S37: 20781 | T37: 21142 | U37: 21592 | V37: 18686 | W37: 20760 | X37: 22438 | Y37: 21680 | Z37: 18802 | AA37: 15600 | AB37: 13400
B38: Ago | C38: Festivo | D38: 2 | E38: 11698 | F38: 10553 | G38: 10462 | H38: 10535 | I38: 10865 | J38: 11070 | K38: 11858 | L38: 20200 | M38: 21032 | N38: 21304 | O38: 22788 | P38: 22861 | Q38: 23126 | R38: 24909 | S38: 25004 | T38: 24333 | U38: 25202 | V38: 22883 | W38: 24530 | X38: 24620 | Y38: 22742 | Z38: 19835 | AA38: 16632 | AB38: 13949
B39: Sep | C39: Ordinario | D39: 22 | E39: 13275 | F39: 12472 | G39: 12175 | H39: 11936 | I39: 13278 | J39: 17030 | K39: 19905 | L39: 28817 | M39: 27851 | N39: 27929 | O39: 28651 | P39: 30232 | Q39: 29700 | R39: 29437 | S39: 30588 | T39: 31151 | U39: 30822 | V39: 25965 | W39: 28677 | X39: 29326 | Y39: 27759 | Z39: 25124 | AA39: 20757 | AB39: 17435 | AC39: =+SUM(E39:AB39)*D39+SUM(E40:AB40)*D40+SUM(E41:AB41)*D41+SUM(E42:AB42)*D42 -> 16716840
B40: Sep | C40: Sábado | D40: 4 | E40: 13554 | F40: 12518 | G40: 12150 | H40: 11926 | I40: 12199 | J40: 13488 | K40: 14947 | L40: 26752 | M40: 27711 | N40: 28177 | O40: 29076 | P40: 29484 | Q40: 29470 | R40: 29532 | S40: 29072 | T40: 29142 | U40: 29906 | V40: 24782 | W40: 27282 | X40: 27672 | Y40: 26033 | Z40: 23290 | AA40: 20877 | AB40: 17927
B41: Sep | C41: Domingo | D41: 4 | E41: 14205 | F41: 13074 | G41: 12142 | H41: 11926 | I41: 11452 | J41: 11012 | K41: 11760 | L41: 21616 | M41: 22357 | N41: 23162 | O41: 24355 | P41: 25774 | Q41: 27020 | R41: 27361 | S41: 26741 | T41: 26517 | U41: 26660 | V41: 23469 | W41: 25483 | X41: 26805 | Y41: 24830 | Z41: 22765 | AA41: 18925 | AB41: 16226
B42: Sep | C42: Festivo | D42: 0 | E42: 0 | F42: 0 | G42: 0 | H42: 0 | I42: 0 | J42: 0 | K42: 0 | L42: 0 | M42: 0 | N42: 0 | O42: 0 | P42: 0 | Q42: 0 | R42: 0 | S42: 0 | T42: 0 | U42: 0 | V42: 0 | W42: 0 | X42: 0 | Y42: 0 | Z42: 0 | AA42: 0 | AB42: 0
...

Sheet Cantidad Producto 2-2028
B2: CANTIDADES DE ENERGÍA SOLICITADAS (kWh)
B3: CENTRAL HIDROELECTRICA DE CALDAS S.A. E.S.P. -BENEFICIO E INTERÉS COLECTIVO
B4: 2028
B6: Mes | C6: Tipo Día | D6: Días | E6: H1 | F6: H2 | G6: H3 | H6: H4 | I6: H5 | J6: H6 | K6: H7 | L6: H8 | M6: H9 | N6: H10 | O6: H11 | P6: H12 | Q6: H13 | R6: H14 | S6: H15 | T6: H16 | U6: H17 | V6: H18 | W6: H19 | X6: H20 | Y6: H21 | Z6: H22 | AA6: H23 | AB6: H24 | AC6: TOTAL MES
B7: Ene | C7: Ordinario | D7: 20 | E7: 5509 | F7: 5433 | G7: 5282 | H7: 5282 | I7: 5809 | J7: 7163 | K7: 9143 | L7: 12506 | M7: 12299 | N7: 12131 | O7: 12396 | P7: 13004 | Q7: 11712 | R7: 11341 | S7: 11782 | T7: 12310 | U7: 12781 | V7: 6187 | W7: 6576 | X7: 5985 | Y7: 5452 | Z7: 4717 | AA7: 3279 | AB7: 2758 | AC7: =+SUM(E7:AB7)*D7+SUM(E8:AB8)*D8+SUM(E9:AB9)*D9+SUM(E10:AB10)*D10 -> 6104641 | AE7: =+AC7 -> 6104641
B8: Ene | C8: Sábado | D8: 4 | E8: 6395 | F8: 5907 | G8: 5721 | H8: 5584 | I8: 5677 | J8: 5832 | K8: 6999 | L8: 11319 | M8: 12064 | N8: 12416 | O8: 12585 | P8: 12852 | Q8: 13057 | R8: 12800 | S8: 12660 | T8: 12626 | U8: 13045 | V8: 6369 | W8: 6954 | X8: 6295 | Y8: 5942 | Z8: 5659 | AA8: 4881 | AB8: 4445 | AE8: =+AC11 -> 5712690
B9: Ene | C9: Domingo | D9: 5 | E9: 6996 | F9: 6603 | G9: 6209 | H9: 5881 | I9: 5697 | J9: 5197 | K9: 5485 | L9: 8890 | M9: 9561 | N9: 9795 | O9: 10375 | P9: 10936 | Q9: 11024 | R9: 10716 | S9: 11164 | T9: 11724 | U9: 12110 | V9: 5760 | W9: 6203 | X9: 5401 | Y9: 4772 | Z9: 4068 | AA9: 3206 | AB9: 2478 | AE9: =+AC15 -> 5944863
B10: Ene | C10: Festivo | D10: 2 | E10: 6391 | F10: 6108 | G10: 5663 | H10: 5835 | I10: 5648 | J10: 5642 | K10: 5698 | L10: 8868 | M10: 8978 | N10: 9271 | O10: 10062 | P10: 10178 | Q10: 10521 | R10: 10912 | S10: 11339 | T10: 11426 | U10: 11809 | V10: 6058 | W10: 5953 | X10: 5572 | Y10: 5343 | Z10: 4213 | AA10: 3117 | AB10: 2550 | AE10: =+AC19 -> 5945886
B11: Feb | C11: Ordinario | D11: 21 | E11: 5445 | F11: 5567 | G11: 5321 | H11: 5573 | I11: 5468 | J11: 7296 | K11: 8885 | L11: 12486 | M11: 12273 | N11: 12177 | O11: 12368 | P11: 12576 | Q11: 12253 | R11: 12166 | S11: 12375 | T11: 12551 | U11: 12629 | V11: 5250 | W11: 5739 | X11: 5232 | Y11: 4866 | Z11: 4456 | AA11: 3601 | AB11: 2773 | AC11: =+SUM(E11:AB11)*D11+SUM(E12:AB12)*D12+SUM(E13:AB13)*D13+SUM(E14:AB14)*D14 -> 5712690 | AE11: =+AC23 -> 5919594
B12: Feb | C12: Sábado | D12: 4 | E12: 6141 | F12: 5964 | G12: 5889 | H12: 5723 | I12: 5811 | J12: 6084 | K12: 7428 | L12: 11831 | M12: 12221 | N12: 12401 | O12: 12464 | P12: 12655 | Q12: 12241 | R12: 12090 | S12: 12135 | T12: 12119 | U12: 12457 | V12: 5470 | W12: 5613 | X12: 5319 | Y12: 5082 | Z12: 4280 | AA12: 3518 | AB12: 2760 | AE12: =+AC27 -> 6098112
B13: Feb | C13: Domingo | D13: 4 | E13: 5995 | F13: 5799 | G13: 5555 | H13: 5461 | I13: 5564 | J13: 5574 | K13: 6161 | L13: 10193 | M13: 10868 | N13: 11243 | O13: 11128 | P13: 11689 | Q13: 12070 | R13: 12214 | S13: 11932 | T13: 12703 | U13: 11523 | V13: 4641 | W13: 6024 | X13: 4366 | Y13: 4287 | Z13: 3743 | AA13: 2876 | AB13: 2406 | AE13: =+AC31 -> 6557268
B14: Feb | C14: Festivo | D14: 0 | E14: 0 | F14: 0 | G14: 0 | H14: 0 | I14: 0 | J14: 0 | K14: 0 | L14: 0 | M14: 0 | N14: 0 | O14: 0 | P14: 0 | Q14: 0 | R14: 0 | S14: 0 | T14: 0 | U14: 0 | V14: 0 | W14: 0 | X14: 0 | Y14: 0 | Z14: 0 | AA14: 0 | AB14: 0 | AE14: =+AC35 -> 6194133
B15: Mar | C15: Ordinario | D15: 22 | E15: 5732 | F15: 5561 | G15: 5521 | H15: 5522 | I15: 6002 | J15: 7288 | K15: 8243 | L15: 11404 | M15: 11176 | N15: 11140 | O15: 11067 | P15: 11820 | Q15: 11737 | R15: 11615 | S15: 11876 | T15: 11977 | U15: 11737 | V15: 4867 | W15: 5477 | X15: 5450 | Y15: 5337 | Z15: 4402 | AA15: 3807 | AB15: 2923 | AC15: =+SUM(E15:AB15)*D15+SUM(E16:AB16)*D16+SUM(E17:AB17)*D17+SUM(E18:AB18)*D18 -> 5944863 | AE15: =+AC39 -> 5869856
B16: Mar | C16: Sábado | D16: 4 | E16: 5302 | F16: 5823 | G16: 5733 | H16: 5675 | I16: 5860 | J16: 6312 | K16: 7347 | L16: 11556 | M16: 11862 | N16: 12124 | O16: 12128 | P16: 11931 | Q16: 12037 | R16: 11919 | S16: 12063 | T16: 12229 | U16: 12229 | V16: 5208 | W16: 5146 | X16: 5585 | Y16: 5460 | Z16: 4935 | AA16: 4326 | AB16: 3557 | AE16: =+AC43 -> 6068014
B17: Mar | C17: Domingo | D17: 4 | E17: 6351 | F17: 6228 | G17: 5823 | H17: 6063 | I17: 6105 | J17: 5045 | K17: 6163 | L17: 9943 | M17: 10377 | N17: 10289 | O17: 10755 | P17: 11373 | Q17: 11117 | R17: 11383 | S17: 11324 | T17: 11318 | U17: 11302 | V17: 4791 | W17: 5071 | X17: 5180 | Y17: 5634 | Z17: 4837 | AA17: 4179 | AB17: 3189 | AE17: =+AC47 -> 5937618
B18: Mar | C18: Festivo | D18: 1 | E18: 6961 | F18: 6980 | G18: 6621 | H18: 6664 | I18: 6733 | J18: 6460 | K18: 6915 | L18: 10499 | M18: 10778 | N18: 11069 | O18: 11808 | P18: 12052 | Q18: 12295 | R18: 12136 | S18: 12595 | T18: 12588 | U18: 12622 | V18: 6258 | W18: 7251 | X18: 6890 | Y18: 6769 | Z18: 6365 | AA18: 4388 | AB18: 3436 | AE18: =+AC51 -> 6251095
B19: Abr | C19: Ordinario | D19: 18 | E19: 5943 | F19: 5833 | G19: 5900 | H19: 5743 | I19: 6035 | J19: 6838 | K19: 7884 | L19: 11496 | M19: 11537 | N19: 11386 | O19: 11919 | P19: 12468 | Q19: 12411 | R19: 12333 | S19: 12756 | T19: 12615 | U19: 12624 | V19: 5240 | W19: 5548 | X19: 5510 | Y19: 5494 | Z19: 4951 | AA19: 4199 | AB19: 3425 | AC19: =+SUM(E19:AB19)*D19+SUM(E20:AB20)*D20+SUM(E21:AB21)*D21+SUM(E22:AB22)*D22 -> 5945886 | AE19: =SUM(AE7:AE18) -> 72603770
B20: Abr | C20: Sábado | D20: 5 | E20: 6344 | F20: 6119 | G20: 6061 | H20: 6028 | I20: 6159 | J20: 6252 | K20: 6733 | L20: 11035 | M20: 10896 | N20: 10994 | O20: 11587 | P20: 11524 | Q20: 11908 | R20: 11935 | S20: 12367 | T20: 12540 | U20: 12866 | V20: 6178 | W20: 6648 | X20: 5401 | Y20: 5189 | Z20: 4986 | AA20: 4584 | AB20: 4164
B21: Abr | C21: Domingo | D21: 5 | E21: 6701 | F21: 6319 | G21: 6024 | H21: 6075 | I21: 5807 | J21: 5841 | K21: 6368 | L21: 9883 | M21: 10586 | N21: 10580 | O21: 10973 | P21: 11016 | Q21: 11389 | R21: 11307 | S21: 11507 | T21: 11451 | U21: 12088 | V21: 5168 | W21: 5694 | X21: 5491 | Y21: 5563 | Z21: 5351 | AA21: 4997 | AB21: 3427
B22: Abr | C22: Festivo | D22: 2 | E22: 7370 | F22: 6894 | G22: 6856 | H22: 6676 | I22: 6795 | J22: 6814 | K22: 7251 | L22: 11337 | M22: 11434 | N22: 11115 | O22: 10781 | P22: 11633 | Q22: 11695 | R22: 11376 | S22: 11778 | T22: 11862 | U22: 12116 | V22: 5496 | W22: 5703 | X22: 5457 | Y22: 5300 | Z22: 5651 | AA22: 5645 | AB22: 4856
B23: May | C23: Ordinario | D23: 21 | E23: 5918 | F23: 5770 | G23: 5616 | H23: 5677 | I23: 5980 | J23: 6898 | K23: 7778 | L23: 11211 | M23: 11094 | N23: 10688 | O23: 10862 | P23: 11629 | Q23: 11553 | R23: 11769 | S23: 12224 | T23: 12218 | U23: 12194 | V23: 5167 | W23: 5391 | X23: 5430 | Y23: 5252 | Z23: 4756 | AA23: 4156 | AB23: 3415 | AC23: =+SUM(E23:AB23)*D23+SUM(E24:AB24)*D24+SUM(E25:AB25)*D25+SUM(E26:AB26)*D26 -> 5919594
B24: May | C24: Sábado | D24: 4 | E24: 6301 | F24: 5749 | G24: 5772 | H24: 5739 | I24: 5832 | J24: 5884 | K24: 6618 | L24: 10666 | M24: 11146 | N24: 11335 | O24: 11287 | P24: 11246 | Q24: 11438 | R24: 11203 | S24: 11300 | T24: 11392 | U24: 11515 | V24: 4825 | W24: 5181 | X24: 5460 | Y24: 5214 | Z24: 4898 | AA24: 4272 | AB24: 3590
B25: May | C25: Domingo | D25: 4 | E25: 6250 | F25: 6048 | G25: 5568 | H25: 5568 | I25: 5356 | J25: 5552 | K25: 5990 | L25: 9851 | M25: 10349 | N25: 10497 | O25: 10665 | P25: 10656 | Q25: 10892 | R25: 10680 | S25: 10657 | T25: 10955 | U25: 11789 | V25: 3821 | W25: 5320 | X25: 5251 | Y25: 5018 | Z25: 4467 | AA25: 3556 | AB25: 2619
B26: May | C26: Festivo | D26: 2 | E26: 5561 | F26: 6386 | G26: 6460 | H26: 6099 | I26: 6627 | J26: 6924 | K26: 7572 | L26: 11656 | M26: 11623 | N26: 12210 | O26: 12566 | P26: 12949 | Q26: 13328 | R26: 13352 | S26: 12732 | T26: 12720 | U26: 12285 | V26: 5645 | W26: 6215 | X26: 5328 | Y26: 5010 | Z26: 4977 | AA26: 4495 | AB26: 3818
B27: Jun | C27: Ordinario | D27: 20 | E27: 6444 | F27: 6244 | G27: 6199 | H27: 6120 | I27: 6518 | J27: 7438 | K27: 8304 | L27: 12067 | M27: 11890 | N27: 11981 | O27: 12203 | P27: 12359 | Q27: 12449 | R27: 12496 | S27: 12858 | T27: 12862 | U27: 13071 | V27: 5598 | W27: 6142 | X27: 5881 | Y27: 5496 | Z27: 4843 | AA27: 4199 | AB27: 3602 | AC27: =+SUM(E27:AB27)*D27+SUM(E28:AB28)*D28+SUM(E29:AB29)*D29+SUM(E30:AB30)*D30 -> 6098112
B28: Jun | C28: Sábado | D28: 4 | E28: 6496 | F28: 6241 | G28: 6115 | H28: 6028 | I28: 6149 | J28: 6475 | K28: 6995 | L28: 11516 | M28: 11704 | N28: 11840 | O28: 12085 | P28: 12047 | Q28: 12109 | R28: 11954 | S28: 11741 | T28: 11797 | U28: 11966 | V28: 4988 | W28: 5327 | X28: 5592 | Y28: 5400 | Z28: 5021 | AA28: 4651 | AB28: 4043
B29: Jun | C29: Domingo | D29: 4 | E29: 7213 | F29: 6709 | G29: 6532 | H29: 6474 | I29: 6361 | J29: 6392 | K29: 6602 | L29: 10599 | M29: 10907 | N29: 11282 | O29: 11414 | P29: 11433 | Q29: 11372 | R29: 11463 | S29: 11341 | T29: 11541 | U29: 11911 | V29: 5196 | W29: 5465 | X29: 5581 | Y29: 5349 | Z29: 5072 | AA29: 4621 | AB29: 3900
B30: Jun | C30: Festivo | D30: 2 | E30: 6471 | F30: 6285 | G30: 6110 | H30: 6092 | I30: 6099 | J30: 6222 | K30: 6295 | L30: 10289 | M30: 10156 | N30: 10169 | O30: 11086 | P30: 11265 | Q30: 11889 | R30: 12040 | S30: 12081 | T30: 12218 | U30: 12181 | V30: 4875 | W30: 5303 | X30: 5126 | Y30: 5096 | Z30: 4941 | AA30: 4359 | AB30: 3748
B31: Jul | C31: Ordinario | D31: 19 | E31: 7007 | F31: 6821 | G31: 6681 | H31: 6721 | I31: 7086 | J31: 8080 | K31: 9143 | L31: 12403 | M31: 12338 | N31: 12400 | O31: 12350 | P31: 13018 | Q31: 12887 | R31: 12981 | S31: 13222 | T31: 13257 | U31: 13251 | V31: 6101 | W31: 6336 | X31: 6618 | Y31: 6361 | Z31: 5647 | AA31: 4791 | AB31: 4349 | AC31: =+SUM(E31:AB31)*D31+SUM(E32:AB32)*D32+SUM(E33:AB33)*D33+SUM(E34:AB34)*D34 -> 6557268
B32: Jul | C32: Sábado | D32: 5 | E32: 7672 | F32: 7366 | G32: 7122 | H32: 7022 | I32: 7101 | J32: 7208 | K32: 7771 | L32: 11995 | M32: 12203 | N32: 12311 | O32: 12289 | P32: 12661 | Q32: 12898 | R32: 12839 | S32: 12731 | T32: 12559 | U32: 12456 | V32: 5667 | W32: 5560 | X32: 5924 | Y32: 5552 | Z32: 4988 | AA32: 4496 | AB32: 4008
B33: Jul | C33: Domingo | D33: 5 | E33: 6711 | F33: 6402 | G33: 6348 | H33: 6276 | I33: 6209 | J33: 6078 | K33: 6612 | L33: 10190 | M33: 10619 | N33: 10598 | O33: 10653 | P33: 11216 | Q33: 11267 | R33: 11450 | S33: 11528 | T33: 11510 | U33: 11646 | V33: 5002 | W33: 5400 | X33: 5968 | Y33: 5840 | Z33: 5037 | AA33: 3957 | AB33: 3263
B34: Jul | C34: Festivo | D34: 2 | E34: 8386 | F34: 7977 | G34: 7460 | H34: 6865 | I34: 6807 | J34: 6104 | K34: 6454 | L34: 9865 | M34: 10766 | N34: 10346 | O34: 9516 | P34: 10165 | Q34: 10456 | R34: 10898 | S34: 10137 | T34: 10268 | U34: 10729 | V34: 4027 | W34: 4006 | X34: 4931 | Y34: 5403 | Z34: 4905 | AA34: 4266 | AB34: 3884
B35: Ago | C35: Ordinario | D35: 21 | E35: 6421 | F35: 6086 | G35: 5932 | H35: 5882 | I35: 6341 | J35: 7647 | K35: 9213 | L35: 12253 | M35: 11725 | N35: 11544 | O35: 11547 | P35: 11860 | Q35: 11898 | R35: 11988 | S35: 12383 | T35: 12589 | U35: 12755 | V35: 6205 | W35: 6384 | X35: 6670 | Y35: 6221 | Z35: 5293 | AA35: 4463 | AB35: 3957 | AC35: =+SUM(E35:AB35)*D35+SUM(E36:AB36)*D36+SUM(E37:AB37)*D37+SUM(E38:AB38)*D38 -> 6194133
B36: Ago | C36: Sábado | D36: 4 | E36: 6768 | F36: 6434 | G36: 6151 | H36: 5982 | I36: 5843 | J36: 5298 | K36: 6210 | L36: 10788 | M36: 11605 | N36: 11409 | O36: 11061 | P36: 11019 | Q36: 11502 | R36: 12112 | S36: 11584 | T36: 11632 | U36: 11611 | V36: 5756 | W36: 5553 | X36: 5587 | Y36: 5025 | Z36: 4517 | AA36: 3880 | AB36: 3685
B37: Ago | C37: Domingo | D37: 4 | E37: 6335 | F37: 6002 | G37: 5692 | H37: 5592 | I37: 5360 | J37: 5146 | K37: 5258 | L37: 8864 | M37: 9106 | N37: 9428 | O37: 9533 | P37: 10048 | Q37: 10538 | R37: 10460 | S37: 10298 | T37: 10618 | U37: 11055 | V37: 5123 | W37: 5554 | X37: 5880 | Y37: 5564 | Z37: 4560 | AA37: 3897 | AB37: 3373
B38: Ago | C38: Festivo | D38: 2 | E38: 6505 | F38: 5959 | G38: 6011 | H38: 6048 | I38: 6225 | J38: 6321 | K38: 6933 | L38: 10535 | M38: 10682 | N38: 10451 | O38: 10821 | P38: 10485 | Q38: 10509 | R38: 11665 | S38: 11939 | T38: 11636 | U38: 12288 | V38: 6476 | W38: 6649 | X38: 6186 | Y38: 5544 | Z38: 4765 | AA38: 4156 | AB38: 3487
B39: Sep | C39: Ordinario | D39: 21 | E39: 6131 | F39: 5847 | G39: 5741 | H39: 5627 | I39: 6032 | J39: 7089 | K39: 8537 | L39: 11714 | M39: 11313 | N39: 11274 | O39: 11391 | P39: 12004 | Q39: 11854 | R39: 11610 | S39: 11979 | T39: 12210 | U39: 12244 | V39: 5810 | W39: 6001 | X39: 6117 | Y39: 5775 | Z39: 5270 | AA39: 4270 | AB39: 3474 | AC39: =+SUM(E39:AB39)*D39+SUM(E40:AB40)*D40+SUM(E41:AB41)*D41+SUM(E42:AB42)*D42 -> 5869856
B40: Sep | C40: Sábado | D40: 5 | E40: 5896 | F40: 5657 | G40: 5579 | H40: 5530 | I40: 5570 | J40: 6140 | K40: 6807 | L40: 11041 | M40: 11122 | N40: 11177 | O40: 11539 | P40: 11705 | Q40: 11723 | R40: 11889 | S40: 11716 | T40: 11769 | U40: 12288 | V40: 5544 | W40: 5726 | X40: 5941 | Y40: 5469 | Z40: 4766 | AA40: 4466 | AB40: 3626
B41: Sep | C41: Domingo | D41: 4 | E41: 6346 | F41: 5952 | G41: 5577 | H41: 5598 | I41: 5465 | J41: 5353 | K41: 6090 | L41: 9702 | M41: 9527 | N41: 9701 | O41: 10151 | P41: 10770 | Q41: 11293 | R41: 11545 | S41: 11198 | T41: 11047 | U41: 11294 | V41: 5565 | W41: 5295 | X41: 5751 | Y41: 4973 | Z41: 4785 | AA41: 3923 | AB41: 3307
B42: Sep | C42: Festivo | D42: 0 | E42: 0 | F42: 0 | G42: 0 | H42: 0 | I42: 0 | J42: 0 | K42: 0 | L42: 0 | M42: 0 | N42: 0 | O42: 0 | P42: 0 | Q42: 0 | R42: 0 | S42: 0 | T42: 0 | U42: 0 | V42: 0 | W42: 0 | X42: 0 | Y42: 0 | Z42: 0 | AA42: 0 | AB42: 0
...

Sheet Cantidad Producto3-2029
B2: CANTIDADES DE ENERGÍA SOLICITADAS (kWh)
B3: CENTRAL HIDROELECTRICA DE CALDAS S.A. E.S.P. -BENEFICIO E INTERÉS COLECTIVO
B4: 2029
B6: Mes | C6: Tipo Día | D6: Días | E6: H1 | F6: H2 | G6: H3 | H6: H4 | I6: H5 | J6: H6 | K6: H7 | L6: H8 | M6: H9 | N6: H10 | O6: H11 | P6: H12 | Q6: H13 | R6: H14 | S6: H15 | T6: H16 | U6: H17 | V6: H18 | W6: H19 | X6: H20 | Y6: H21 | Z6: H22 | AA6: H23 | AB6: H24 | AC6: TOTAL MES
B7: Ene | C7: Ordinario | D7: 21 | E7: 7540 | F7: 7278 | G7: 7004 | H7: 6953 | I7: 7694 | J7: 9668 | K7: 12131 | L7: 18441 | M7: 18304 | N7: 18215 | O7: 18684 | P7: 19669 | Q7: 18051 | R7: 17521 | S7: 18132 | T7: 18842 | U7: 19435 | V7: 14951 | W7: 16182 | X7: 15882 | Y7: 14851 | Z7: 13237 | AA7: 10323 | AB7: 8799 | AC7: =+SUM(E7:AB7)*D7+SUM(E8:AB8)*D8+SUM(E9:AB9)*D9+SUM(E10:AB10)*D10 -> 10369193 | AE7: =+AC7 -> 10369193
B8: Ene | C8: Sábado | D8: 4 | E8: 8558 | F8: 7791 | G8: 7509 | H8: 7308 | I8: 7542 | J8: 8185 | K8: 9786 | L8: 17266 | M8: 18265 | N8: 18847 | O8: 19213 | P8: 19847 | Q8: 20102 | R8: 19784 | S8: 19726 | T8: 19726 | U8: 20267 | V8: 15502 | W8: 17022 | X8: 16612 | Y8: 15747 | Z8: 14743 | AA8: 12672 | AB8: 11064 | AE8: =+AC11 -> 9610152
B9: Ene | C9: Domingo | D9: 4 | E9: 9367 | F9: 8744 | G9: 8172 | H9: 7743 | I9: 7645 | J9: 7469 | K9: 8126 | L9: 14339 | M9: 15263 | N9: 15650 | O9: 16573 | P9: 17637 | Q9: 17630 | R9: 17124 | S9: 17855 | T9: 18645 | U9: 19111 | V9: 14722 | W9: 16048 | X9: 15302 | Y9: 14092 | Z9: 12472 | AA9: 10325 | AB9: 8479 | AE9: =+AC15 -> 10033768
B10: Ene | C10: Festivo | D10: 2 | E10: 8696 | F10: 8226 | G10: 7507 | H10: 7639 | I10: 7335 | J10: 7290 | K10: 7137 | L10: 12838 | M10: 13195 | N10: 13751 | O10: 14967 | P10: 15212 | Q10: 15865 | R10: 16369 | S10: 16933 | T10: 17010 | U10: 17508 | V10: 13882 | W10: 14719 | X10: 14643 | Y10: 14007 | Z10: 11924 | AA10: 9741 | AB10: 8205 | AE10: =+AC19 -> 10103775
B11: Feb | C11: Ordinario | D11: 20 | E11: 7195 | F11: 7344 | G11: 6929 | H11: 7343 | I11: 7272 | J11: 10666 | K11: 13169 | L11: 19740 | M11: 19312 | N11: 19143 | O11: 19529 | P11: 19953 | Q11: 19388 | R11: 19283 | S11: 19728 | T11: 20063 | U11: 20180 | V11: 14407 | W11: 15748 | X11: 15450 | Y11: 14511 | Z11: 13133 | AA11: 10748 | AB11: 8650 | AC11: =+SUM(E11:AB11)*D11+SUM(E12:AB12)*D12+SUM(E13:AB13)*D13+SUM(E14:AB14)*D14 -> 9610152 | AE11: =+AC23 -> 10080661
B12: Feb | C12: Sábado | D12: 4 | E12: 8382 | F12: 8005 | G12: 7820 | H12: 7541 | I12: 7709 | J12: 8202 | K12: 10285 | L12: 18415 | M12: 19173 | N12: 19480 | O12: 19679 | P12: 20053 | Q12: 19424 | R12: 19103 | S12: 19149 | T12: 19117 | U12: 19688 | V12: 14530 | W12: 15290 | X12: 15315 | Y12: 14564 | Z12: 12748 | AA12: 10820 | AB12: 8889 | AE12: =+AC27 -> 10232240
B13: Feb | C13: Domingo | D13: 4 | E13: 8236 | F13: 7799 | G13: 7336 | H13: 7138 | I13: 7233 | J13: 7208 | K13: 7967 | L13: 15206 | M13: 16474 | N13: 17227 | O13: 17084 | P13: 18061 | Q13: 18811 | R13: 19048 | S13: 18551 | T13: 19808 | U13: 17794 | V13: 12755 | W13: 15590 | X13: 13426 | Y13: 13101 | Z13: 11653 | AA13: 9398 | AB13: 7833 | AE13: =+AC31 -> 10757818
B14: Feb | C14: Festivo | D14: 0 | E14: 0 | F14: 0 | G14: 0 | H14: 0 | I14: 0 | J14: 0 | K14: 0 | L14: 0 | M14: 0 | N14: 0 | O14: 0 | P14: 0 | Q14: 0 | R14: 0 | S14: 0 | T14: 0 | U14: 0 | V14: 0 | W14: 0 | X14: 0 | Y14: 0 | Z14: 0 | AA14: 0 | AB14: 0 | AE14: =+AC35 -> 10593018
B15: Mar | C15: Ordinario | D15: 19 | E15: 6729 | F15: 6445 | G15: 6378 | H15: 6430 | I15: 7418 | J15: 10164 | K15: 12233 | L15: 17882 | M15: 17358 | N15: 17282 | O15: 17248 | P15: 18490 | Q15: 18151 | R15: 17901 | S15: 18381 | T15: 18597 | U15: 18265 | V15: 13507 | W15: 14916 | X15: 15016 | Y15: 14317 | Z15: 12087 | AA15: 10179 | AB15: 7910 | AC15: =+SUM(E15:AB15)*D15+SUM(E16:AB16)*D16+SUM(E17:AB17)*D17+SUM(E18:AB18)*D18 -> 10033768 | AE15: =+AC39 -> 10083685
B16: Mar | C16: Sábado | D16: 5 | E16: 6220 | F16: 7027 | G16: 6885 | H16: 6785 | I16: 7197 | J16: 8064 | K16: 10299 | L16: 17951 | M16: 18560 | N16: 19001 | O16: 19056 | P16: 18838 | Q16: 18965 | R16: 18545 | S16: 18663 | T16: 18877 | U16: 18893 | V16: 13856 | W16: 14108 | X16: 15205 | Y16: 14603 | Z16: 13121 | AA16: 11261 | AB16: 9302 | AE16: =+AC43 -> 10452286
B17: Mar | C17: Domingo | D17: 4 | E17: 7943 | F17: 7683 | G17: 7007 | H17: 7364 | I17: 7429 | J17: 5667 | K17: 7691 | L17: 14476 | M17: 15455 | N17: 15466 | O17: 16370 | P17: 17512 | Q17: 17223 | R17: 17499 | S17: 17289 | T17: 17167 | U17: 17109 | V17: 12697 | W17: 13655 | X17: 14112 | Y17: 14469 | Z17: 12594 | AA17: 10629 | AB17: 8354 | AE17: =+AC47 -> 10239540
B18: Mar | C18: Festivo | D18: 3 | E18: 8860 | F18: 8856 | G18: 8298 | H18: 8324 | I18: 8507 | J18: 7999 | K18: 8934 | L18: 15337 | M18: 15920 | N18: 16763 | O18: 18378 | P18: 18927 | Q18: 19341 | R18: 18894 | S18: 19521 | T18: 19447 | U18: 19397 | V18: 14937 | W18: 16855 | X18: 17239 | Y18: 16532 | Z18: 14575 | AA18: 10821 | AB18: 8512 | AE18: =+AC51 -> 10677244
B19: Abr | C19: Ordinario | D19: 21 | E19: 7303 | F19: 7113 | G19: 7219 | H19: 6994 | I19: 7609 | J19: 9379 | K19: 11555 | L19: 18070 | M19: 18158 | N19: 17962 | O19: 18889 | P19: 19997 | Q19: 19657 | R19: 19461 | S19: 20131 | T19: 19924 | U19: 19859 | V19: 14250 | W19: 15205 | X19: 15478 | Y19: 14999 | Z19: 13446 | AA19: 11240 | AB19: 9089 | AC19: =+SUM(E19:AB19)*D19+SUM(E20:AB20)*D20+SUM(E21:AB21)*D21+SUM(E22:AB22)*D22 -> 10103775 | AE19: =SUM(AE7:AE18) -> 123233380
B20: Abr | C20: Sábado | D20: 4 | E20: 8030 | F20: 7603 | G20: 7556 | H20: 7456 | I20: 7703 | J20: 7953 | K20: 8922 | L20: 16846 | M20: 16777 | N20: 17132 | O20: 18201 | P20: 18281 | Q20: 18963 | R20: 18740 | S20: 19294 | T20: 19478 | U20: 19839 | V20: 14708 | W20: 16288 | X20: 14492 | Y20: 13782 | Z20: 12951 | AA20: 11593 | AB20: 10844
B21: Abr | C21: Domingo | D21: 5 | E21: 8630 | F21: 7901 | G21: 7371 | H21: 7400 | I21: 6985 | J21: 7002 | K21: 8074 | L21: 14513 | M21: 16023 | N21: 16280 | O21: 16961 | P21: 16982 | Q21: 17462 | R21: 17238 | S21: 17501 | T21: 17305 | U21: 18344 | V21: 13386 | W21: 14565 | X21: 14678 | Y21: 14460 | Z21: 13510 | AA21: 12061 | AB21: 8832
B22: Abr | C22: Festivo | D22: 0 | E22: 21264 | F22: 18957 | G22: 17989 | H22: 17180 | I22: 17343 | J22: 17853 | K22: 19267 | L22: 25564 | M22: 28153 | N22: 29585 | O22: 30605 | P22: 33347 | Q22: 34211 | R22: 33318 | S22: 32896 | T22: 32380 | U22: 32442 | V22: 35516 | W22: 39380 | X22: 40666 | Y22: 39202 | Z22: 37114 | AA22: 33437 | AB22: 28499
B23: May | C23: Ordinario | D23: 21 | E23: 7304 | F23: 7021 | G23: 6770 | H23: 6906 | I23: 7612 | J23: 9697 | K23: 11616 | L23: 17688 | M23: 17444 | N23: 16832 | O23: 17174 | P23: 18504 | Q23: 18256 | R23: 18497 | S23: 19273 | T23: 19244 | U23: 19188 | V23: 14153 | W23: 14903 | X23: 15273 | Y23: 14587 | Z23: 13044 | AA23: 11009 | AB23: 8944 | AC23: =+SUM(E23:AB23)*D23+SUM(E24:AB24)*D24+SUM(E25:AB25)*D25+SUM(E26:AB26)*D26 -> 10080661
B24: May | C24: Sábado | D24: 4 | E24: 8009 | F24: 7101 | G24: 7082 | H24: 7049 | I24: 7253 | J24: 7475 | K24: 9098 | L24: 16515 | M24: 17414 | N24: 17776 | O24: 17813 | P24: 17788 | Q24: 18081 | R24: 17600 | S24: 17620 | T24: 17705 | U24: 17840 | V24: 13208 | W24: 14038 | X24: 14877 | Y24: 14140 | Z24: 13093 | AA24: 11329 | AB24: 9598
B25: May | C25: Domingo | D25: 4 | E25: 8040 | F25: 7650 | G25: 6809 | H25: 6786 | I25: 6405 | J25: 6637 | K25: 7601 | L25: 14547 | M25: 15610 | N25: 15980 | O25: 16307 | P25: 16276 | Q25: 16658 | R25: 16310 | S25: 16281 | T25: 16660 | U25: 17890 | V25: 11040 | W25: 13800 | X25: 14112 | Y25: 13560 | Z25: 12092 | AA25: 9742 | AB25: 7585
B26: May | C26: Festivo | D26: 2 | E26: 6683 | F26: 7958 | G26: 8033 | H26: 7451 | I26: 8303 | J26: 8703 | K26: 9943 | L26: 17241 | M26: 17356 | N26: 18527 | O26: 19194 | P26: 19866 | Q26: 20481 | R26: 20453 | S26: 19403 | T26: 19314 | U26: 18605 | V26: 13806 | W26: 15136 | X26: 14347 | Y26: 13683 | Z26: 12894 | AA26: 11042 | AB26: 9289
B27: Jun | C27: Ordinario | D27: 19 | E27: 8159 | F27: 7803 | G27: 7694 | H27: 7596 | I27: 8373 | J27: 10270 | K27: 12122 | L27: 18864 | M27: 18466 | N27: 18637 | O27: 19105 | P27: 19455 | Q27: 19479 | R27: 19524 | S27: 20141 | T27: 20195 | U27: 20498 | V27: 14738 | W27: 15882 | X27: 15925 | Y27: 14914 | Z27: 13154 | AA27: 11102 | AB27: 9335 | AC27: =+SUM(E27:AB27)*D27+SUM(E28:AB28)*D28+SUM(E29:AB29)*D29+SUM(E30:AB30)*D30 -> 10232240
B28: Jun | C28: Sábado | D28: 5 | E28: 8175 | F28: 7747 | G28: 7459 | H28: 7324 | I28: 7579 | J28: 8165 | K28: 9445 | L28: 17553 | M28: 18040 | N28: 18293 | O28: 18796 | P28: 18779 | Q28: 18881 | R28: 18565 | S28: 18092 | T28: 18133 | U28: 18322 | V28: 13310 | W28: 14169 | X28: 14851 | Y28: 14149 | Z28: 12971 | AA28: 11691 | AB28: 10054
B29: Jun | C29: Domingo | D29: 4 | E29: 9430 | F29: 8509 | G29: 8183 | H29: 8019 | I29: 7802 | J29: 7749 | K29: 8447 | L29: 15533 | M29: 16308 | N29: 17115 | O29: 17374 | P29: 17417 | Q29: 17343 | R29: 17441 | S29: 17049 | T29: 17302 | U29: 17880 | V29: 12970 | W29: 13755 | X29: 14544 | Y29: 13998 | Z29: 12960 | AA29: 11415 | AB29: 9586
B30: Jun | C30: Festivo | D30: 2 | E30: 8165 | F30: 7783 | G30: 7498 | H30: 7428 | I30: 7407 | J30: 7527 | K30: 7884 | L30: 15114 | M30: 15010 | N30: 15459 | O30: 16996 | P30: 17385 | Q30: 18447 | R30: 18759 | S30: 18584 | T30: 18669 | U30: 18687 | V30: 12778 | W30: 13643 | X30: 14153 | Y30: 13844 | Z30: 13014 | AA30: 11223 | AB30: 9453
B31: Jul | C31: Ordinario | D31: 20 | E31: 8704 | F31: 8381 | G31: 8146 | H31: 8232 | I31: 8941 | J31: 10989 | K31: 13149 | L31: 18978 | M31: 18771 | N31: 18862 | O31: 18853 | P31: 19919 | Q31: 19661 | R31: 19781 | S31: 20199 | T31: 20324 | U31: 20333 | V31: 15168 | W31: 15676 | X31: 16678 | Y31: 15912 | Z31: 14139 | AA31: 11702 | AB31: 10245 | AC31: =+SUM(E31:AB31)*D31+SUM(E32:AB32)*D32+SUM(E33:AB33)*D33+SUM(E34:AB34)*D34 -> 10757818
B32: Jul | C32: Sábado | D32: 4 | E32: 10006 | F32: 9419 | G32: 9028 | H32: 8834 | I32: 8986 | J32: 9236 | K32: 10448 | L32: 18087 | M32: 18558 | N32: 18748 | O32: 18809 | P32: 19373 | Q32: 19832 | R32: 19607 | S32: 19380 | T32: 19027 | U32: 18758 | V32: 14151 | W32: 14219 | X32: 15182 | Y32: 14273 | Z32: 12851 | AA32: 11370 | AB32: 10013
B33: Jul | C33: Domingo | D33: 5 | E33: 8509 | F33: 7919 | G33: 7799 | H33: 7643 | I33: 7500 | J33: 7282 | K33: 8338 | L33: 14690 | M33: 15661 | N33: 15731 | O33: 15831 | P33: 16638 | Q33: 16781 | R33: 17044 | S33: 17063 | T33: 16986 | U33: 17105 | V33: 12499 | W33: 13467 | X33: 14999 | Y33: 14752 | Z33: 12920 | AA33: 10162 | AB33: 8405
B34: Jul | C34: Festivo | D34: 2 | E34: 11034 | F34: 10298 | G34: 9493 | H34: 8481 | I34: 8450 | J34: 7318 | K34: 8106 | L34: 14358 | M34: 15874 | N34: 15504 | O34: 14155 | P34: 15274 | Q34: 15885 | R34: 16497 | S34: 15117 | T34: 15228 | U34: 15918 | V34: 11337 | W34: 11636 | X34: 13623 | Y34: 14135 | Z34: 12823 | AA34: 10777 | AB34: 9458
B35: Ago | C35: Ordinario | D35: 21 | E35: 8465 | F35: 7883 | G35: 7654 | H35: 7584 | I35: 8349 | J35: 10586 | K35: 12933 | L35: 18652 | M35: 17957 | N35: 17805 | O35: 17981 | P35: 18575 | Q35: 18609 | R35: 18708 | S35: 19306 | T35: 19621 | U35: 19813 | V35: 15357 | W35: 16076 | X35: 17020 | Y35: 16069 | Z35: 14112 | AA35: 11747 | AB35: 10074 | AC35: =+SUM(E35:AB35)*D35+SUM(E36:AB36)*D36+SUM(E37:AB37)*D37+SUM(E38:AB38)*D38 -> 10593018
B36: Ago | C36: Sábado | D36: 4 | E36: 8859 | F36: 8335 | G36: 7906 | H36: 7685 | I36: 7751 | J36: 7932 | K36: 9687 | L36: 17209 | M36: 18192 | N36: 17848 | O36: 17672 | P36: 17723 | Q36: 18296 | R36: 19125 | S36: 18726 | T36: 18719 | U36: 18519 | V36: 14889 | W36: 15010 | X36: 15690 | Y36: 14590 | Z36: 13213 | AA36: 11340 | AB36: 10054
B37: Ago | C37: Domingo | D37: 4 | E37: 8706 | F37: 8077 | G37: 7576 | H37: 7396 | I37: 7219 | J37: 7183 | K37: 8007 | L37: 14741 | M37: 15332 | N37: 15929 | O37: 16092 | P37: 16850 | Q37: 17391 | R37: 17059 | S37: 16715 | T37: 17059 | U37: 17625 | V37: 13893 | W37: 15014 | X37: 15762 | Y37: 14839 | Z37: 12797 | AA37: 11096 | AB37: 9590
B38: Ago | C38: Festivo | D38: 2 | E38: 8737 | F38: 7858 | G38: 7862 | H38: 7775 | I38: 8028 | J38: 8180 | K38: 8968 | L38: 15450 | M38: 15838 | N38: 15681 | O38: 16334 | P38: 15984 | Q38: 16251 | R38: 17749 | S38: 18033 | T38: 17537 | U38: 18545 | V38: 14911 | W38: 15608 | X38: 15494 | Y38: 14384 | Z38: 12647 | AA38: 10872 | AB38: 9119
B39: Sep | C39: Ordinario | D39: 20 | E39: 8109 | F39: 7634 | G39: 7452 | H39: 7302 | I39: 8070 | J39: 10138 | K39: 12464 | L39: 18372 | M39: 17759 | N39: 17729 | O39: 18111 | P39: 19064 | Q39: 18762 | R39: 18449 | S39: 19082 | T39: 19416 | U39: 19458 | V39: 14991 | W39: 15961 | X39: 16390 | Y39: 15465 | Z39: 14038 | AA39: 11517 | AB39: 9505 | AC39: =+SUM(E39:AB39)*D39+SUM(E40:AB40)*D40+SUM(E41:AB41)*D41+SUM(E42:AB42)*D42 -> 10083685
B40: Sep | C40: Sábado | D40: 5 | E40: 7946 | F40: 7465 | G40: 7275 | H40: 7170 | I40: 7275 | J40: 8126 | K40: 9382 | L40: 17167 | M40: 17496 | N40: 17671 | O40: 18293 | P40: 18511 | Q40: 18565 | R40: 18715 | S40: 18410 | T40: 18419 | U40: 19068 | V40: 14348 | W40: 15257 | X40: 15614 | Y40: 14547 | Z40: 13032 | AA40: 11734 | AB40: 9825
B41: Sep | C41: Domingo | D41: 5 | E41: 8585 | F41: 7899 | G41: 7302 | H41: 7246 | I41: 6969 | J41: 6809 | K41: 7843 | L41: 14465 | M41: 14554 | N41: 14979 | O41: 15712 | P41: 16666 | Q41: 17508 | R41: 17787 | S41: 17241 | T41: 16973 | U41: 17260 | V41: 13682 | W41: 14103 | X41: 15083 | Y41: 13696 | Z41: 12765 | AA41: 10486 | AB41: 8861
B42: Sep | C42: Festivo | D42: 0 | E42: 0 | F42: 0 | G42: 0 | H42: 0 | I42: 0 | J42: 0 | K42: 0 | L42: 0 | M42: 0 | N42: 0 | O42: 0 | P42: 0 | Q42: 0 | R42: 0 | S42: 0 | T42: 0 | U42: 0 | V42: 0 | W42: 0 | X42: 0 | Y42: 0 | Z42: 0 | AA42: 0 | AB42: 0
...

Sheet Cantidad Producto 4-2030
B2: CANTIDADES DE ENERGÍA SOLICITADAS (kWh)
B3: CENTRAL HIDROELECTRICA DE CALDAS S.A. E.S.P. -BENEFICIO E INTERÉS COLECTIVO
B4: 2030
B6: Mes | C6: Tipo Día | D6: Días | E6: H1 | F6: H2 | G6: H3 | H6: H4 | I6: H5 | J6: H6 | K6: H7 | L6: H8 | M6: H9 | N6: H10 | O6: H11 | P6: H12 | Q6: H13 | R6: H14 | S6: H15 | T6: H16 | U6: H17 | V6: H18 | W6: H19 | X6: H20 | Y6: H21 | Z6: H22 | AA6: H23 | AB6: H24 | AC6: TOTAL MES
B7: Ene | C7: Ordinario | D7: 21 | E7: 18548 | F7: 17653 | G7: 16988 | H7: 16825 | I7: 18284 | J7: 22323 | K7: 26823 | L7: 38220 | M7: 38521 | N7: 39000 | O7: 40363 | P7: 42648 | Q7: 40111 | R7: 39082 | S7: 40038 | T7: 41023 | U7: 41772 | V7: 35142 | W7: 38204 | X7: 38470 | Y7: 36288 | Z7: 32704 | AA7: 26553 | AB7: 22694 | AC7: =+SUM(E7:AB7)*D7+SUM(E8:AB8)*D8+SUM(E9:AB9)*D9+SUM(E10:AB10)*D10 -> 23463619 | AE7: =+AC7 -> 23463619
B8: Ene | C8: Sábado | D8: 4 | E8: 20378 | F8: 18601 | G8: 17837 | H8: 17389 | I8: 17876 | J8: 19268 | K8: 22153 | L8: 35694 | M8: 38247 | N8: 39820 | O8: 40862 | P8: 42425 | Q8: 42937 | R8: 42078 | S8: 41687 | T8: 41457 | U8: 42173 | V8: 35347 | W8: 38956 | X8: 39055 | Y8: 37089 | Z8: 34605 | AA8: 30171 | AB8: 26392 | AE8: =+AC11 -> 21983264
B9: Ene | C9: Domingo | D9: 4 | E9: 21828 | F9: 20238 | G9: 19027 | H9: 18162 | I9: 17918 | J9: 17714 | K9: 18717 | L9: 29748 | M9: 32235 | N9: 33668 | O9: 35611 | P9: 37753 | Q9: 38123 | R9: 37195 | S9: 37977 | T9: 38981 | U9: 39516 | V9: 33439 | W9: 36666 | X9: 36485 | Y9: 34282 | Z9: 30869 | AA9: 26070 | AB9: 21864 | AE9: =+AC15 -> 22930560
B10: Ene | C10: Festivo | D10: 2 | E10: 21239 | F10: 19984 | G10: 18459 | H10: 18322 | I10: 17670 | J10: 17584 | K10: 17000 | L10: 26873 | M10: 28131 | N10: 29794 | O10: 32289 | P10: 33395 | Q10: 34868 | R10: 35577 | S10: 36142 | T10: 36045 | U10: 36689 | V10: 31811 | W10: 34682 | X10: 35315 | Y10: 33856 | Z10: 29724 | AA10: 24968 | AB10: 21318 | AE10: =+AC19 -> 23011184
B11: Feb | C11: Ordinario | D11: 20 | E11: 18240 | F11: 18021 | G11: 17197 | H11: 17770 | I11: 18182 | J11: 25249 | K11: 29874 | L11: 41071 | M11: 40708 | N11: 40912 | O11: 42140 | P11: 43419 | Q11: 42336 | R11: 42056 | S11: 42937 | T11: 43496 | U11: 43534 | V11: 34814 | W11: 38013 | X11: 38581 | Y11: 36495 | Z11: 33030 | AA11: 27470 | AB11: 22689 | AC11: =+SUM(E11:AB11)*D11+SUM(E12:AB12)*D12+SUM(E13:AB13)*D13+SUM(E14:AB14)*D14 -> 21983264 | AE11: =+AC23 -> 22947941
B12: Feb | C12: Sábado | D12: 4 | E12: 20479 | F12: 19389 | G12: 18759 | H12: 18244 | I12: 18699 | J12: 19991 | K12: 23807 | L12: 38434 | M12: 40533 | N12: 41587 | O12: 42487 | P12: 43560 | Q12: 42704 | R12: 41711 | S12: 41414 | T12: 41248 | U12: 42016 | V12: 34495 | W12: 36797 | X12: 37805 | Y12: 35977 | Z12: 32196 | AA12: 27873 | AB12: 23552 | AE12: =+AC27 -> 23112949
B13: Feb | C13: Domingo | D13: 4 | E13: 20519 | F13: 19228 | G13: 18178 | H13: 17666 | I13: 17685 | J13: 17737 | K13: 18990 | L13: 31686 | M13: 34760 | N13: 36732 | O13: 37036 | P13: 39123 | Q13: 40590 | R13: 40726 | S13: 39653 | T13: 41336 | U13: 38036 | V13: 30975 | W13: 36464 | X13: 34301 | Y13: 33416 | Z13: 30079 | AA13: 24979 | AB13: 20994 | AE13: =+AC31 -> 23935549
B14: Feb | C14: Festivo | D14: 0 | E14: 0 | F14: 0 | G14: 0 | H14: 0 | I14: 0 | J14: 0 | K14: 0 | L14: 0 | M14: 0 | N14: 0 | O14: 0 | P14: 0 | Q14: 0 | R14: 0 | S14: 0 | T14: 0 | U14: 0 | V14: 0 | W14: 0 | X14: 0 | Y14: 0 | Z14: 0 | AA14: 0 | AB14: 0 | AE14: =+AC35 -> 23893234
B15: Mar | C15: Ordinario | D15: 20 | E15: 17582 | F15: 16692 | G15: 16387 | H15: 16376 | I15: 18292 | J15: 24031 | K15: 27679 | L15: 37555 | M15: 37094 | N15: 37433 | O15: 37953 | P15: 40399 | Q15: 39702 | R15: 39262 | S15: 40194 | T15: 40508 | U15: 39937 | V15: 32999 | W15: 36325 | X15: 37410 | Y15: 35778 | Z15: 31143 | AA15: 26521 | AB15: 21653 | AC15: =+SUM(E15:AB15)*D15+SUM(E16:AB16)*D16+SUM(E17:AB17)*D17+SUM(E18:AB18)*D18 -> 22930560 | AE15: =+AC39 -> 22902751
B16: Mar | C16: Sábado | D16: 5 | E16: 17084 | F16: 17702 | G16: 17205 | H16: 16924 | I16: 17667 | J16: 19452 | K16: 23066 | L16: 36845 | M16: 38689 | N16: 39994 | O16: 40523 | P16: 40654 | Q16: 40860 | R16: 39929 | S16: 39869 | T16: 40019 | U16: 39929 | V16: 32868 | W16: 34623 | X16: 36969 | Y16: 35430 | Z16: 32300 | AA16: 28208 | AB16: 23995 | AE16: =+AC43 -> 23690538
B17: Mar | C17: Domingo | D17: 5 | E17: 19863 | F17: 18821 | G17: 17449 | H17: 17754 | I17: 17794 | J17: 15165 | K17: 17958 | L17: 29919 | M17: 32491 | N17: 33387 | O17: 35176 | P17: 37296 | Q17: 37097 | R17: 37544 | S17: 36937 | T17: 36627 | U17: 36407 | V17: 30200 | W17: 32998 | X17: 34845 | Y17: 35057 | Z17: 31242 | AA17: 26743 | AB17: 21856 | AE17: =+AC47 -> 23238819
B18: Mar | C18: Festivo | D18: 1 | E18: 20869 | F18: 20247 | G18: 19095 | H18: 18979 | I18: 19259 | J18: 18705 | K18: 19944 | L18: 31524 | M18: 33395 | N18: 35173 | O18: 38006 | P18: 39438 | Q18: 40424 | R18: 39556 | S18: 40057 | T18: 39786 | U18: 39616 | V18: 33352 | W18: 37739 | X18: 39196 | Y18: 37590 | Z18: 33875 | AA18: 27119 | AB18: 22366 | AE18: =+AC51 -> 24027837
B19: Abr | C19: Ordinario | D19: 20 | E19: 18397 | F19: 17619 | G19: 17576 | H19: 17186 | I19: 18651 | J19: 23126 | K19: 27125 | L19: 38241 | M19: 38363 | N19: 38429 | O19: 40439 | P19: 42356 | Q19: 41821 | R19: 41551 | S19: 42817 | T19: 42578 | U19: 42551 | V19: 34423 | W19: 37402 | X19: 38328 | Y19: 36989 | Z19: 33380 | AA19: 28138 | AB19: 23275 | AC19: =+SUM(E19:AB19)*D19+SUM(E20:AB20)*D20+SUM(E21:AB21)*D21+SUM(E22:AB22)*D22 -> 23011184 | AE19: =SUM(AE7:AE18) -> 279138245
B20: Abr | C20: Sábado | D20: 4 | E20: 19881 | F20: 18721 | G20: 18241 | H20: 18005 | I20: 18598 | J20: 19490 | K20: 21171 | L20: 35839 | M20: 36773 | N20: 37889 | O20: 39919 | P20: 40392 | Q20: 41647 | R20: 40701 | S20: 41277 | T20: 41469 | U20: 42018 | V20: 34055 | W20: 38600 | X20: 36406 | Y20: 34663 | Z20: 32491 | AA20: 29011 | AB20: 26955
B21: Abr | C21: Domingo | D21: 4 | E21: 21118 | F21: 19414 | G21: 18233 | H21: 18031 | I21: 17264 | J21: 17348 | K21: 18834 | L21: 30388 | M21: 33698 | N21: 34806 | O21: 36389 | P21: 36902 | Q21: 38135 | R21: 37821 | S21: 37761 | T21: 37217 | U21: 38677 | V21: 31804 | W21: 35167 | X21: 35965 | Y21: 35255 | Z21: 32689 | AA21: 28953 | AB21: 22460
B22: Abr | C22: Festivo | D22: 2 | E22: 22438 | F22: 20590 | G22: 20092 | H22: 19462 | I22: 19644 | J22: 19769 | K22: 21090 | L22: 34063 | M22: 35712 | N22: 35777 | O22: 35216 | P22: 37968 | Q22: 38821 | R22: 37868 | S22: 38202 | T22: 37975 | U22: 38399 | V22: 32201 | W22: 35115 | X22: 35502 | Y22: 34081 | Z22: 33177 | AA22: 31039 | AB22: 26699
B23: May | C23: Ordinario | D23: 22 | E23: 18000 | F23: 17155 | G23: 16571 | H23: 16740 | I23: 18316 | J23: 23138 | K23: 26753 | L23: 37208 | M23: 37013 | N23: 36439 | O23: 37616 | P23: 40239 | Q23: 39622 | R23: 39863 | S23: 41165 | T23: 41114 | U23: 40969 | V23: 33726 | W23: 36375 | X23: 37420 | Y23: 35720 | Z23: 32230 | AA23: 27398 | AB23: 22704 | AC23: =+SUM(E23:AB23)*D23+SUM(E24:AB24)*D24+SUM(E25:AB25)*D25+SUM(E26:AB26)*D26 -> 22947941
B24: May | C24: Sábado | D24: 4 | E24: 19549 | F24: 17643 | G24: 17331 | H24: 17140 | I24: 17645 | J24: 18375 | K24: 21389 | L24: 34906 | M24: 37164 | N24: 38332 | O24: 38873 | P24: 39268 | Q24: 39680 | R24: 38518 | S24: 38250 | T24: 38226 | U24: 38407 | V24: 31864 | W24: 34651 | X24: 36350 | Y24: 34615 | Z24: 32127 | AA24: 28145 | AB24: 24080
B25: May | C25: Domingo | D25: 4 | E25: 19748 | F25: 18582 | G25: 16948 | H25: 16667 | I25: 16051 | J25: 16325 | K25: 17769 | L25: 30062 | M25: 32716 | N25: 34129 | O25: 35233 | P25: 35676 | Q25: 36315 | R25: 35490 | S25: 35044 | T25: 35490 | U25: 37360 | V25: 27492 | W25: 33278 | X25: 34419 | Y25: 33261 | Z25: 30103 | AA25: 25161 | AB25: 20365
B26: May | C26: Festivo | D26: 1 | E26: 17185 | F26: 18624 | G26: 18497 | H26: 17435 | I26: 18840 | J26: 19531 | K26: 21442 | L26: 34290 | M26: 35426 | N26: 38034 | O26: 39895 | P26: 41705 | Q26: 42954 | R26: 42611 | S26: 40602 | T26: 40260 | U26: 39072 | V26: 32363 | W26: 36122 | X26: 35602 | Y26: 33967 | Z26: 31640 | AA26: 27204 | AB26: 22924
B27: Jun | C27: Ordinario | D27: 18 | E27: 19542 | F27: 18524 | G27: 18149 | H27: 17960 | I27: 19567 | J27: 23652 | K27: 27275 | L27: 39238 | M27: 39037 | N27: 39797 | O27: 41203 | P27: 42482 | Q27: 42257 | R27: 42115 | S27: 43161 | T27: 43142 | U27: 43530 | V27: 35099 | W27: 38294 | X27: 38983 | Y27: 36748 | Z27: 32915 | AA27: 27988 | AB27: 23642 | AC27: =+SUM(E27:AB27)*D27+SUM(E28:AB28)*D28+SUM(E29:AB29)*D29+SUM(E30:AB30)*D30 -> 23112949
