Workbook

Sheet Producto 1 Plano Ene 26
B2: ANEXO 1 - CANTIDADES DE ENERGÍA SOLICITADA EN kWh
B3: PRODUCTO 1
B4: PERIODO 01 DE FEBRERO DEL 2026 A JUNIO 30 DE 2026
C5: DIA | D5: 1 | E5: 2 | F5: 3 | G5: 4 | H5: 5 | I5: 6 | J5: 7 | K5: 8 | L5: 9 | M5: 10 | N5: 11 | O5: 12 | P5: 13 | Q5: 14 | R5: 15 | S5: 16 | T5: 17 | U5: 18 | V5: 19 | W5: 20 | X5: 21 | Y5: 22 | Z5: 23 | AA5: 24 | AB5: Total | AC5: No. DÍAS | AD5: Total
B6: 46023 | C6: Hábil | AB6: =(SUM(D6:AA6)) -> 0 | AC6: 20 | AD6: =(AB6*AC6)+(AB7*AC7)+(AB8*AC8)+(AB9*AC9) -> 0 | AE6: =+AD6 -> 0
C7: Sábado | AB7: =(SUM(D7:AA7)) -> 0 | AC7: 5
C8: Domingo | AB8: =(SUM(D8:AA8)) -> 0 | AC8: 4
C9: Festivo | AB9: =(SUM(D9:AA9)) -> 0 | AC9: 2
B10: 46054 | C10: Hábil | D10: 5311.76 | E10: 5795.32 | F10: 6101.99 | G10: 6456.12 | H10: 6076.18 | I10: 4547.59 | J10: 3394.91 | K10: 3394.91 | L10: 3394.91 | M10: 3394.91 | N10: 3394.91 | O10: 3394.91 | P10: 3394.91 | Q10: 3394.91 | R10: 3394.91 | S10: 3394.91 | T10: 3394.91 | U10: 3394.91 | V10: 3394.91 | W10: 3394.91 | X10: 3394.91 | Y10: 3394.91 | Z10: 3394.91 | AA10: 3394.91 | AB10: =(SUM(D10:AA10)) -> 95397.34 | AC10: 20 | AD10: =(AB10*AC10)+(AB11*AC11)+(AB12*AC12)+(AB13*AC13) -> 2975103.1 | AE10: =+AD10 -> 2975103.1 | AF10: =+AE10/1000000 -> 2.9751031
C11: Sábado | D11: 6912.8 | E11: 7377.1 | F11: 7671.54 | G11: 8006.95 | H11: 7671.47 | I11: 6252.89 | J11: 3394.91 | K11: 3394.91 | L11: 3394.91 | M11: 3394.91 | N11: 3394.91 | O11: 3394.91 | P11: 3394.91 | Q11: 3394.91 | R11: 3394.91 | S11: 3394.91 | T11: 3394.91 | U11: 3394.91 | V11: 3394.91 | W11: 3394.91 | X11: 3394.91 | Y11: 3394.91 | Z11: 3394.91 | AA11: 3624.16 | AB11: =(SUM(D11:AA11)) -> 105230.38 | AC11: 4
C12: Domingo | D12: 9604.04 | E12: 9331.81 | F12: 9059.59 | G12: 9059.59 | H12: 9059.59 | I12: 8787.37 | J12: 8585 | K12: 7099.61 | L12: 6374.05 | M12: 6005.76 | N12: 5651.57 | O12: 5552.28 | P12: 6078.59 | Q12: 5499.38 | R12: 4862.67 | S12: 4347.71 | T12: 4158.53 | U12: 3394.91 | V12: 4025.67 | W12: 5042.07 | X12: 6025.16 | Y12: 7266.91 | Z12: 8125.35 | AA12: 8561.48 | AB12: =(SUM(D12:AA12)) -> 161558.69 | AC12: 4
C13: Festivo | D13: 0 | E13: 0 | F13: 0 | G13: 0 | H13: 0 | I13: 0 | J13: 0 | K13: 0 | L13: 0 | M13: 0 | N13: 0 | O13: 0 | P13: 0 | Q13: 0 | R13: 0 | S13: 0 | T13: 0 | U13: 0 | V13: 0 | W13: 0 | X13: 0 | Y13: 0 | Z13: 0 | AA13: 0 | AB13: =(SUM(D13:AA13)) -> 0 | AC13: 0
B14: 46082 | C14: Hábil | D14: 1882.1078 | E14: 2355.5871 | F14: 2655.7899 | G14: 3002.9724 | H14: 2631.3413 | I14: 1134.2669 | J14: 0 | K14: 0 | L14: 0 | M14: 0 | N14: 0 | O14: 0 | P14: 0 | Q14: 0 | R14: 0 | S14: 0 | T14: 0 | U14: 0 | V14: 0 | W14: 0 | X14: 0 | Y14: 0 | Z14: 0 | AA14: 0 | AB14: =(SUM(D14:AA14)) -> 13662.065 | AC14: 21 | AD14: =(AB14*AC14)+(AB15*AC15)+(AB16*AC16)+(AB17*AC17) -> 870004.85 | AE14: =+AD14 -> 870004.85 | AF14: =+AE14/1000000 -> 0.87000485
C15: Sábado | D15: 3464.07 | E15: 3918.166 | F15: 4205.9967 | G15: 4534.4541 | H15: 4205.9967 | I15: 2817.2857 | J15: 0 | K15: 0 | L15: 0 | M15: 0 | N15: 0 | O15: 0 | P15: 0 | Q15: 0 | R15: 0 | S15: 0 | T15: 0 | U15: 0 | V15: 0 | W15: 0 | X15: 0 | Y15: 0 | Z15: 0 | AA15: 291.53183 | AB15: =(SUM(D15:AA15)) -> 23437.501 | AC15: 4
C16: Domingo | D16: 6462.3588 | E16: 6188.3311 | F16: 5914.3034 | G16: 5914.3034 | H16: 5914.3034 | I16: 5640.2852 | J16: 5140.2588 | K16: 3664.0462 | L16: 2947.2454 | M16: 2583.6653 | N16: 2234.842 | O16: 2132.3929 | P16: 2642.3589 | Q16: 2082.5705 | R16: 1466.0726 | S16: 973.25766 | T16: 792.87461 | U16: 0 | V16: 729.31606 | W16: 1722.5675 | X16: 2682.7949 | Y16: 3895.9973 | Z16: 4736.4526 | AA16: 5163.0762 | AB16: =(SUM(D16:AA16)) -> 81623.674 | AC16: 5
C17: Festivo | D17: 6546.3881 | E17: 6270.1569 | F17: 5993.9161 | G17: 5717.6849 | H17: 5717.6849 | I17: 5717.6849 | J17: 5119.5019 | K17: 3659.458 | L17: 2903.7856 | M17: 2635.0997 | N17: 2345.2372 | O17: 2145.9764 | P17: 2664.995 | Q17: 2106.5802 | R17: 1497.4083 | S17: 979.36264 | T17: 812.67764 | U17: 0 | V17: 624.18641 | W17: 1596.3662 | X17: 2559.2549 | Y17: 3778.1521 | Z17: 4680.3059 | AA17: 5161.2351 | AB17: =(SUM(D17:AA17)) -> 81233.099 | AC17: 1
B18: 46113 | C18: Hábil | D18: 5641.38 | E18: 6143.21 | F18: 6461.37 | G18: 6829.5 | H18: 6435.76 | I18: 4848.84 | J18: 4174.67 | K18: 4174.67 | L18: 4174.67 | M18: 4174.67 | N18: 4174.67 | O18: 4174.67 | P18: 4174.67 | Q18: 4174.67 | R18: 4174.67 | S18: 4174.67 | T18: 4174.67 | U18: 4174.67 | V18: 4174.67 | W18: 4174.67 | X18: 4174.67 | Y18: 4174.67 | Z18: 4174.67 | AA18: 4174.67 | AB18: =(SUM(D18:AA18)) -> 111504.12 | AC18: 20 | AD18: =(AB18*AC18)+(AB19*AC19)+(AB20*AC20)+(AB21*AC21) -> 3637637.6 | AE18: =+AD18 -> 3637637.6 | AF18: =+AE18/1000000 -> 3.6376376
C19: Sábado | D19: 7317.07 | E19: 7798.24 | F19: 7734.54 | G19: 7414.61 | H19: 7734.54 | I19: 6631 | J19: 4174.67 | K19: 4174.67 | L19: 4174.67 | M19: 4174.67 | N19: 4174.67 | O19: 4174.67 | P19: 4174.67 | Q19: 4174.67 | R19: 4174.67 | S19: 4174.67 | T19: 4174.67 | U19: 4174.67 | V19: 4174.67 | W19: 4174.67 | X19: 4174.67 | Y19: 4174.67 | Z19: 4174.67 | AA19: 4174.67 | AB19: =(SUM(D19:AA19)) -> 119774.06 | AC19: 4
C20: Domingo | D20: 7783.36 | E20: 7504.24 | F20: 7225.12 | G20: 7225.12 | H20: 7225.12 | I20: 6946.01 | J20: 7225.12 | K20: 7506.88 | L20: 6742.79 | M20: 6355.25 | N20: 5984.04 | O20: 5872.74 | P20: 6411.53 | Q20: 5820.86 | R20: 5169.83 | S20: 4652.38 | T20: 4463.26 | U20: 4174.67 | V20: 4429.07 | W20: 5482.54 | X20: 6500.82 | Y20: 7787.5 | Z20: 8620.71 | AA20: 7847.25 | AB20: =(SUM(D20:AA20)) -> 154956.21 | AC20: 4
C21: Festivo | D21: 7867.49 | E21: 7586.16 | F21: 7304.83 | G21: 7023.5 | H21: 7023.5 | I21: 7023.5 | J21: 7304.83 | K21: 7502.07 | L21: 6697.22 | M21: 6409.19 | N21: 6099.76 | O21: 5886.94 | P21: 6435.24 | Q21: 5846 | R21: 5202.66 | S21: 4658.76 | T21: 4484.02 | U21: 4174.67 | V21: 4318.86 | W21: 5350.22 | X21: 6371.28 | Y21: 7663.92 | Z21: 8430.15 | AA21: 7652.27 | AB21: =(SUM(D21:AA21)) -> 154317.04 | AC21: 2
B22: 46143 | C22: Hábil | D22: 9308.02 | E22: 8816.38 | F22: 8816.38 | G22: 8816.38 | H22: 9308.02 | I22: 10782.93 | J22: 8602.83 | K22: 6290.82 | L22: 5167.83 | M22: 4795.64 | N22: 4795.64 | O22: 4795.64 | P22: 4795.64 | Q22: 4795.64 | R22: 4795.64 | S22: 4795.64 | T22: 4795.64 | U22: 4795.64 | V22: 4795.64 | W22: 4795.64 | X22: 5780.11 | Y22: 7436.13 | Z22: 8644.33 | AA22: 9280 | AB22: =(SUM(D22:AA22)) -> 159802.2 | AC22: 19 | AD22: =(AB22*AC22)+(AB23*AC23)+(AB24*AC24)+(AB25*AC25) -> 6060646.8 | AE22: =+AD22 -> 6060646.8 | AF22: =+AE22/1000000 -> 6.0606468
C23: Sábado | D23: 10788.81 | E23: 10626.87 | F23: 10168.75 | G23: 9710.62 | H23: 10168.75 | I23: 10626.87 | J23: 9463.62 | K23: 8339.96 | L23: 8021.33 | M23: 7599.23 | N23: 6898.69 | O23: 7280.56 | P23: 8263.67 | Q23: 8455.56 | R23: 8749.68 | S23: 8502.95 | T23: 8242.54 | U23: 5341.77 | V23: 5584.04 | W23: 6724.09 | X23: 8320.61 | Y23: 9565.36 | Z23: 10760.9 | AA23: 10626.87 | AB23: =(SUM(D23:AA23)) -> 208832.1 | AC23: 5
C24: Domingo | D24: 10821.67 | E24: 10406.64 | F24: 9991.61 | G24: 9991.61 | H24: 9991.61 | I24: 9576.58 | J24: 9991.61 | K24: 10801.52 | L24: 11216.54 | M24: 12046.6 | N24: 12023.03 | O24: 12326.08 | P24: 12835.36 | Q24: 12936.76 | R24: 13228.11 | S24: 14138.09 | T24: 14228.49 | U24: 11903.43 | V24: 12051.62 | W24: 12526.61 | X24: 13145.93 | Y24: 12896.82 | Z24: 12066.76 | AA24: 11236.7 | AB24: =(SUM(D24:AA24)) -> 282379.78 | AC24: 5
C25: Festivo | D25: 10923.94 | E25: 10506.22 | F25: 10088.5 | G25: 9670.78 | H25: 9670.78 | I25: 9670.78 | J25: 10088.5 | K25: 10486.07 | L25: 11321.51 | M25: 12156.95 | N25: 12992.39 | O25: 13410.11 | P25: 13410.11 | Q25: 13827.83 | R25: 13827.83 | S25: 14245.55 | T25: 14245.55 | U25: 11627.57 | V25: 11376.46 | W25: 12210.64 | X25: 12718.87 | Y25: 13012.55 | Z25: 11759.38 | AA25: 10923.94 | AB25: =(SUM(D25:AA25)) -> 284172.81 | AC25: 2
B26: 46174 | C26: Hábil | D26: 7024.58 | E26: 6549.99 | F26: 6549.99 | G26: 6549.99 | H26: 7024.58 | I26: 8448.34 | J26: 6891.27 | K26: 4543.6 | L26: 3406.11 | M26: 3026.54 | N26: 3026.54 | O26: 3026.54 | P26: 3026.54 | Q26: 3026.54 | R26: 3026.54 | S26: 3026.54 | T26: 3026.54 | U26: 3026.54 | V26: 3026.54 | W26: 3026.54 | X26: 4062.65 | Y26: 5735.16 | Z26: 6955.56 | AA26: 7597.35 | AB26: =(SUM(D26:AA26)) -> 114631.11 | AC26: 19 | AD26: =(AB26*AC26)+(AB27*AC27)+(AB28*AC28)+(AB29*AC29) -> 4456602 | AE26: =+AD26 -> 4456602 | AF26: =+AE26/1000000 -> 4.456602
C27: Sábado | D27: 8803.34 | E27: 8359.28 | F27: 7915.23 | G27: 7471.18 | H27: 7915.23 | I27: 8359.28 | J27: 7758.58 | K27: 6611.48 | L27: 6286.63 | M27: 5857.8 | N27: 5149 | O27: 5532.17 | P27: 6523.02 | Q27: 6719.84 | R27: 7019.87 | S27: 6774.51 | T27: 6514.49 | U27: 3617.7 | V27: 3863.39 | W27: 5014.99 | X27: 6626.13 | Y27: 7883.35 | Z27: 8803.34 | AA27: 8359.28 | AB27: =(SUM(D27:AA27)) -> 163739.11 | AC27: 4
C28: Domingo | D28: 8637.42 | E28: 8232.79 | F28: 7828.16 | G28: 7828.16 | H28: 7828.16 | I28: 7423.53 | J28: 7828.16 | K28: 8617.3 | L28: 9021.93 | M28: 9831.19 | N28: 9721.79 | O28: 10014.61 | P28: 10523.12 | Q28: 10614.6 | R28: 10895.74 | S28: 11784.8 | T28: 11875.06 | U28: 10237.02 | V28: 10386.15 | W28: 10866.06 | X28: 11491.66 | Y28: 10591.1 | Z28: 9851.31 | AA28: 9042.05 | AB28: =(SUM(D28:AA28)) -> 230971.87 | AC28: 4
C29: Festivo | D29: 8733.76 | E29: 8326.6 | F29: 7919.43 | G29: 7512.27 | H29: 7512.27 | I29: 7512.27 | J29: 7919.43 | K29: 8306.47 | L29: 9120.8 | M29: 9935.13 | N29: 10749.46 | O29: 11156.63 | P29: 11156.63 | Q29: 11563.79 | R29: 11563.79 | S29: 11970.96 | T29: 11970.96 | U29: 9958.33 | V29: 9705.25 | W29: 10548.34 | X29: 11061.65 | Y29: 10769.59 | Z29: 9548.09 | AA29: 8733.76 | AB29: =(SUM(D29:AA29)) -> 233255.66 | AC29: 3
B30: 46204 | C30: Hábil | AB30: =(SUM(D30:AA30)) -> 0 | AC30: 22 | AD30: =(AB30*AC30)+(AB31*AC31)+(AB32*AC32)+(AB33*AC33) -> 0
C31: Sábado | AB31: =(SUM(D31:AA31)) -> 0 | AC31: 4
C32: domingo | AB32: =(SUM(D32:AA32)) -> 0 | AC32: 4
C33: Festivo | AB33: =(SUM(D33:AA33)) -> 0 | AC33: 1
B34: 46235 | C34: Hábil | AB34: =(SUM(D34:AA34)) -> 0 | AC34: 19 | AD34: =(AB34*AC34)+(AB35*AC35)+(AB36*AC36)+(AB37*AC37) -> 0
C35: Sábado | AB35: =(SUM(D35:AA35)) -> 0 | AC35: 5
C36: Domingo | AB36: =(SUM(D36:AA36)) -> 0 | AC36: 5
C37: Festivo | AB37: =(SUM(D37:AA37)) -> 0 | AC37: 2
B38: 46266 | C38: Hábil | AB38: =(SUM(D38:AA38)) -> 0 | AC38: 22 | AD38: =(AB38*AC38)+(AB39*AC39)+(AB40*AC40)+(AB41*AC41) -> 0
C39: Sábado | AB39: =(SUM(D39:AA39)) -> 0 | AC39: 4
C40: Domingo | AB40: =(SUM(D40:AA40)) -> 0 | AC40: 4
C41: Festivo | AB41: =(SUM(D41:AA41)) -> 0 | AC41: 0
...

Sheet Anexo 2 Producto 1
B4: ANEXO 2 - OFERTA PRODUCTO 1
B5: NOMBRE DEL OFERENTE
B6: PRECIOS Y CANTIDADES DE ENERGIA OFERTADA
B7: EN PESOS DE NOVIEMBRE 2025
B8: PRODUCTO 1
B9: AÑO | C9: MES | D9: PERIODO 2026
D10: E. Solicitada [kWh] | E10: % E. Ofertado | F10: E. Ofertada [kWh] | G10: $/kWh
B11: 2026 | C11: Enero | D11: =+'Producto 1 Plano Ene 26'!AE6 -> 0 | F11: =+E11*D11 -> 0
B12: 2026 | C12: Febrero | D12: =+'Producto 1 Plano Ene 26'!AE10 -> 2975103.1 | F12: =+E12*D12 -> 0
B13: 2026 | C13: Marzo | D13: =+'Producto 1 Plano Ene 26'!AE14 -> 870004.85 | F13: =+E13*D13 -> 0
B14: 2026 | C14: Abril | D14: =+'Producto 1 Plano Ene 26'!AE18 -> 3637637.6 | F14: =+E14*D14 -> 0
B15: 2026 | C15: Mayo | D15: =+'Producto 1 Plano Ene 26'!AE22 -> 6060646.8 | F15: =+E15*D15 -> 0
B16: 2026 | C16: Junio | D16: =+'Producto 1 Plano Ene 26'!AE26 -> 4456602 | F16: =+E16*D16 -> 0
B17: 2026 | C17: Julio | D17: =+'Producto 1 Plano Ene 26'!AE12 -> 0 | F17: =+E17*D17 -> 0
B18: 2026 | C18: Agosto | D18: =+'Producto 1 Plano Ene 26'!AE13 -> 0 | F18: =+E18*D18 -> 0
B19: 2026 | C19: Septiembre | D19: 0 | F19: =+E19*D19 -> 0
B20: 2026 | C20: Octubre | D20: =+'Producto 1 Plano Ene 26'!AE15 -> 0 | F20: =+E20*D20 -> 0
B21: 2026 | C21: Noviembre | D21: =+'Producto 1 Plano Ene 26'!AE16 -> 0 | F21: =+E21*D21 -> 0
B22: 2026 | C22: Diciembre | D22: =+'Producto 1 Plano Ene 26'!AE17 -> 0 | F22: =+E22*D22 -> 0 | H22: =SUM(D11:D22) -> 17999994 | I22: =+H22/1000 -> 17999.994
B23: Total Producto 1 | D23: =+SUM(D11:D22) -> 17999994 | I23: =+D23/1000 -> 17999.994
B25: E. Solicitada = Energía solicitada por RUITOQUE para el producto.
B26: % E. Ofertado = Porcentaje de energía ofertado por el agente respecto a la E. Solicitada.
B27: E. Ofertada = Energía ofertada por el agente, producto de la E. Solicitada y el % E. Ofertado.
B28: $/kWh = Tarifa de la oferta para todas las horas del mes.
