Workbook

Sheet OF P1 
B1: * La energia a ofertar debe ser expresada únicamente en kilovatio (kWh) redondeado a cero decimales
B4: OFERTA PRODUCTO 1
B5: MES | C5: ENERGIA SOLICITADA (kWh) | D5: % | E5: ENERGIA OFERTADA (kWh) | F5: PRECIO $/kWh
B6: 45658 | C6: =+VLOOKUP(B6,'CURVA P1'!$A$7:$AD$56,30,FALSE) -> 0 | D6: % | F6: $/kWh
B7: 45689 | C7: =+VLOOKUP(B7,'CURVA P1'!$A$7:$AD$56,30,FALSE) -> 0
B8: 45717 | C8: =+VLOOKUP(B8,'CURVA P1'!$A$7:$AD$56,30,FALSE) -> 0
B9: 45748 | C9: =+VLOOKUP(B9,'CURVA P1'!$A$7:$AD$56,30,FALSE) -> 0
B10: 45778 | C10: =+VLOOKUP(B10,'CURVA P1'!$A$7:$AD$56,30,FALSE) -> 0
B11: 45809 | C11: =+VLOOKUP(B11,'CURVA P1'!$A$7:$AD$56,30,FALSE) -> 12840833
B12: 45839 | C12: =+VLOOKUP(B12,'CURVA P1'!$A$7:$AD$56,30,FALSE) -> 10406781
B13: 45870 | C13: =+VLOOKUP(B13,'CURVA P1'!$A$7:$AD$56,30,FALSE) -> 19335230
B14: 45901 | C14: =+VLOOKUP(B14,'CURVA P1'!$A$7:$AD$56,30,FALSE) -> 20046668
B15: 45931 | C15: =+VLOOKUP(B15,'CURVA P1'!$A$7:$AD$56,30,FALSE) -> 19031170
B16: 45962 | C16: =+VLOOKUP(B16,'CURVA P1'!$A$7:$AD$56,30,FALSE) -> 19158612
B17: 45992 | C17: =+VLOOKUP(B17,'CURVA P1'!$A$7:$AD$56,30,FALSE) -> 14734391
C18: =+SUM(C6:C17) -> 115553685

Sheet CURVA P1
A1: Curva de distribucion en kwh
A2: * La energia a ofertar debe ser expresada únicamente en kilovatio (kWh) redondeado a cero decimales
A4: TOTAL | C4: =+AD55 -> 115553685
A5: MES | B5: DÍA | C5: HORA 01 | D5: HORA 02 | E5: HORA 03 | F5: HORA 04 | G5: HORA 05 | H5: HORA 06 | I5: HORA 07 | J5: HORA 08 | K5: HORA 09 | L5: HORA 10 | M5: HORA 11 | N5: HORA 12 | O5: HORA 13 | P5: HORA 14 | Q5: HORA 15 | R5: HORA 16 | S5: HORA 17 | T5: HORA 18 | U5: HORA 19 | V5: HORA 20 | W5: HORA 21 | X5: HORA 22 | Y5: HORA 23 | Z5: HORA 24 | AA5: TOTAL DÍA | AB5: NUMERO DÍAS | AC5: TOTAL DÍA MES | AD5: TOTAL MES
A7: 45658 | B7: Hábil | C7: 0 | D7: 0 | E7: 0 | F7: 0 | G7: 0 | H7: 0 | I7: 0 | J7: 0 | K7: 0 | L7: 0 | M7: 0 | N7: 0 | O7: 0 | P7: 0 | Q7: 0 | R7: 0 | S7: 0 | T7: 0 | U7: 0 | V7: 0 | W7: 0 | X7: 0 | Y7: 0 | Z7: 0 | AA7: =+SUM(C7:Z7) -> 0 | AB7: 21 | AC7: =+AA7*AB7 -> 0 | AD7: =+SUM(AC7:AC10) -> 0
B8: Sábado | C8: 0 | D8: 0 | E8: 0 | F8: 0 | G8: 0 | H8: 0 | I8: 0 | J8: 0 | K8: 0 | L8: 0 | M8: 0 | N8: 0 | O8: 0 | P8: 0 | Q8: 0 | R8: 0 | S8: 0 | T8: 0 | U8: 0 | V8: 0 | W8: 0 | X8: 0 | Y8: 0 | Z8: 0 | AA8: =+SUM(C8:Z8) -> 0 | AB8: 4 | AC8: =+AA8*AB8 -> 0
B9: Domingo | C9: 0 | D9: 0 | E9: 0 | F9: 0 | G9: 0 | H9: 0 | I9: 0 | J9: 0 | K9: 0 | L9: 0 | M9: 0 | N9: 0 | O9: 0 | P9: 0 | Q9: 0 | R9: 0 | S9: 0 | T9: 0 | U9: 0 | V9: 0 | W9: 0 | X9: 0 | Y9: 0 | Z9: 0 | AA9: =+SUM(C9:Z9) -> 0 | AB9: 4 | AC9: =+AA9*AB9 -> 0
B10: Festivo | C10: 0 | D10: 0 | E10: 0 | F10: 0 | G10: 0 | H10: 0 | I10: 0 | J10: 0 | K10: 0 | L10: 0 | M10: 0 | N10: 0 | O10: 0 | P10: 0 | Q10: 0 | R10: 0 | S10: 0 | T10: 0 | U10: 0 | V10: 0 | W10: 0 | X10: 0 | Y10: 0 | Z10: 0 | AA10: =+SUM(C10:Z10) -> 0 | AB10: 2 | AC10: =+AA10*AB10 -> 0
A11: 45689 | B11: Hábil | C11: 0 | D11: 0 | E11: 0 | F11: 0 | G11: 0 | H11: 0 | I11: 0 | J11: 0 | K11: 0 | L11: 0 | M11: 0 | N11: 0 | O11: 0 | P11: 0 | Q11: 0 | R11: 0 | S11: 0 | T11: 0 | U11: 0 | V11: 0 | W11: 0 | X11: 0 | Y11: 0 | Z11: 0 | AA11: =+SUM(C11:Z11) -> 0 | AB11: 20 | AC11: =+AA11*AB11 -> 0 | AD11: =+SUM(AC11:AC14) -> 0
B12: Sábado | C12: 0 | D12: 0 | E12: 0 | F12: 0 | G12: 0 | H12: 0 | I12: 0 | J12: 0 | K12: 0 | L12: 0 | M12: 0 | N12: 0 | O12: 0 | P12: 0 | Q12: 0 | R12: 0 | S12: 0 | T12: 0 | U12: 0 | V12: 0 | W12: 0 | X12: 0 | Y12: 0 | Z12: 0 | AA12: =+SUM(C12:Z12) -> 0 | AB12: 4 | AC12: =+AA12*AB12 -> 0
B13: Domingo | C13: 0 | D13: 0 | E13: 0 | F13: 0 | G13: 0 | H13: 0 | I13: 0 | J13: 0 | K13: 0 | L13: 0 | M13: 0 | N13: 0 | O13: 0 | P13: 0 | Q13: 0 | R13: 0 | S13: 0 | T13: 0 | U13: 0 | V13: 0 | W13: 0 | X13: 0 | Y13: 0 | Z13: 0 | AA13: =+SUM(C13:Z13) -> 0 | AB13: 4 | AC13: =+AA13*AB13 -> 0
B14: Festivo | C14: 0 | D14: 0 | E14: 0 | F14: 0 | G14: 0 | H14: 0 | I14: 0 | J14: 0 | K14: 0 | L14: 0 | M14: 0 | N14: 0 | O14: 0 | P14: 0 | Q14: 0 | R14: 0 | S14: 0 | T14: 0 | U14: 0 | V14: 0 | W14: 0 | X14: 0 | Y14: 0 | Z14: 0 | AA14: =+SUM(C14:Z14) -> 0 | AB14: 0 | AC14: =+AA14*AB14 -> 0
A15: 45717 | B15: Hábil | C15: 0 | D15: 0 | E15: 0 | F15: 0 | G15: 0 | H15: 0 | I15: 0 | J15: 0 | K15: 0 | L15: 0 | M15: 0 | N15: 0 | O15: 0 | P15: 0 | Q15: 0 | R15: 0 | S15: 0 | T15: 0 | U15: 0 | V15: 0 | W15: 0 | X15: 0 | Y15: 0 | Z15: 0 | AA15: =+SUM(C15:Z15) -> 0 | AB15: 20 | AC15: =+AA15*AB15 -> 0 | AD15: =+SUM(AC15:AC18) -> 0
B16: Sábado | C16: 0 | D16: 0 | E16: 0 | F16: 0 | G16: 0 | H16: 0 | I16: 0 | J16: 0 | K16: 0 | L16: 0 | M16: 0 | N16: 0 | O16: 0 | P16: 0 | Q16: 0 | R16: 0 | S16: 0 | T16: 0 | U16: 0 | V16: 0 | W16: 0 | X16: 0 | Y16: 0 | Z16: 0 | AA16: =+SUM(C16:Z16) -> 0 | AB16: 5 | AC16: =+AA16*AB16 -> 0
B17: Domingo | C17: 0 | D17: 0 | E17: 0 | F17: 0 | G17: 0 | H17: 0 | I17: 0 | J17: 0 | K17: 0 | L17: 0 | M17: 0 | N17: 0 | O17: 0 | P17: 0 | Q17: 0 | R17: 0 | S17: 0 | T17: 0 | U17: 0 | V17: 0 | W17: 0 | X17: 0 | Y17: 0 | Z17: 0 | AA17: =+SUM(C17:Z17) -> 0 | AB17: 5 | AC17: =+AA17*AB17 -> 0
B18: Festivo | C18: 0 | D18: 0 | E18: 0 | F18: 0 | G18: 0 | H18: 0 | I18: 0 | J18: 0 | K18: 0 | L18: 0 | M18: 0 | N18: 0 | O18: 0 | P18: 0 | Q18: 0 | R18: 0 | S18: 0 | T18: 0 | U18: 0 | V18: 0 | W18: 0 | X18: 0 | Y18: 0 | Z18: 0 | AA18: =+SUM(C18:Z18) -> 0 | AB18: 1 | AC18: =+AA18*AB18 -> 0
A19: 45748 | B19: Hábil | C19: 0 | D19: 0 | E19: 0 | F19: 0 | G19: 0 | H19: 0 | I19: 0 | J19: 0 | K19: 0 | L19: 0 | M19: 0 | N19: 0 | O19: 0 | P19: 0 | Q19: 0 | R19: 0 | S19: 0 | T19: 0 | U19: 0 | V19: 0 | W19: 0 | X19: 0 | Y19: 0 | Z19: 0 | AA19: =+SUM(C19:Z19) -> 0 | AB19: 20 | AC19: =+AA19*AB19 -> 0 | AD19: =+SUM(AC19:AC22) -> 0
B20: Sábado | C20: 0 | D20: 0 | E20: 0 | F20: 0 | G20: 0 | H20: 0 | I20: 0 | J20: 0 | K20: 0 | L20: 0 | M20: 0 | N20: 0 | O20: 0 | P20: 0 | Q20: 0 | R20: 0 | S20: 0 | T20: 0 | U20: 0 | V20: 0 | W20: 0 | X20: 0 | Y20: 0 | Z20: 0 | AA20: =+SUM(C20:Z20) -> 0 | AB20: 4 | AC20: =+AA20*AB20 -> 0
B21: Domingo | C21: 0 | D21: 0 | E21: 0 | F21: 0 | G21: 0 | H21: 0 | I21: 0 | J21: 0 | K21: 0 | L21: 0 | M21: 0 | N21: 0 | O21: 0 | P21: 0 | Q21: 0 | R21: 0 | S21: 0 | T21: 0 | U21: 0 | V21: 0 | W21: 0 | X21: 0 | Y21: 0 | Z21: 0 | AA21: =+SUM(C21:Z21) -> 0 | AB21: 4 | AC21: =+AA21*AB21 -> 0
B22: Festivo | C22: 0 | D22: 0 | E22: 0 | F22: 0 | G22: 0 | H22: 0 | I22: 0 | J22: 0 | K22: 0 | L22: 0 | M22: 0 | N22: 0 | O22: 0 | P22: 0 | Q22: 0 | R22: 0 | S22: 0 | T22: 0 | U22: 0 | V22: 0 | W22: 0 | X22: 0 | Y22: 0 | Z22: 0 | AA22: =+SUM(C22:Z22) -> 0 | AB22: 2 | AC22: =+AA22*AB22 -> 0
A23: 45778 | B23: Hábil | C23: 0 | D23: 0 | E23: 0 | F23: 0 | G23: 0 | H23: 0 | I23: 0 | J23: 0 | K23: 0 | L23: 0 | M23: 0 | N23: 0 | O23: 0 | P23: 0 | Q23: 0 | R23: 0 | S23: 0 | T23: 0 | U23: 0 | V23: 0 | W23: 0 | X23: 0 | Y23: 0 | Z23: 0 | AA23: =+SUM(C23:Z23) -> 0 | AB23: 21 | AC23: =+AA23*AB23 -> 0 | AD23: =+SUM(AC23:AC26) -> 0
B24: Sábado | C24: 0 | D24: 0 | E24: 0 | F24: 0 | G24: 0 | H24: 0 | I24: 0 | J24: 0 | K24: 0 | L24: 0 | M24: 0 | N24: 0 | O24: 0 | P24: 0 | Q24: 0 | R24: 0 | S24: 0 | T24: 0 | U24: 0 | V24: 0 | W24: 0 | X24: 0 | Y24: 0 | Z24: 0 | AA24: =+SUM(C24:Z24) -> 0 | AB24: 5 | AC24: =+AA24*AB24 -> 0
B25: Domingo | C25: 0 | D25: 0 | E25: 0 | F25: 0 | G25: 0 | H25: 0 | I25: 0 | J25: 0 | K25: 0 | L25: 0 | M25: 0 | N25: 0 | O25: 0 | P25: 0 | Q25: 0 | R25: 0 | S25: 0 | T25: 0 | U25: 0 | V25: 0 | W25: 0 | X25: 0 | Y25: 0 | Z25: 0 | AA25: =+SUM(C25:Z25) -> 0 | AB25: 4 | AC25: =+AA25*AB25 -> 0
B26: Festivo | C26: 0 | D26: 0 | E26: 0 | F26: 0 | G26: 0 | H26: 0 | I26: 0 | J26: 0 | K26: 0 | L26: 0 | M26: 0 | N26: 0 | O26: 0 | P26: 0 | Q26: 0 | R26: 0 | S26: 0 | T26: 0 | U26: 0 | V26: 0 | W26: 0 | X26: 0 | Y26: 0 | Z26: 0 | AA26: =+SUM(C26:Z26) -> 0 | AB26: 1 | AC26: =+AA26*AB26 -> 0
A27: 45809 | B27: Hábil | C27: 21320 | D27: 19388 | E27: 17862 | F27: 16855 | G27: 16536 | H27: 16366 | I27: 17810 | J27: 12665 | K27: 13820 | L27: 15239 | M27: 16914 | N27: 17240 | O27: 14363 | P27: 18590 | Q27: 23693 | R27: 25725 | S27: 25520 | T27: 24697 | U27: 24525 | V27: 24599 | W27: 24400 | X27: 23650 | Y27: 21598 | Z27: 18811 | AA27: =+SUM(C27:Z27) -> 472186 | AB27: 18 | AC27: =+AA27*AB27 -> 8499348 | AD27: =+SUM(AC27:AC30) -> 12840833
B28: Sábado | C28: 21247 | D28: 19365 | E28: 17897 | F28: 16761 | G28: 16369 | H28: 15487 | I28: 16968 | J28: 11728 | K28: 12759 | L28: 14230 | M28: 15550 | N28: 15484 | O28: 13936 | P28: 14680 | Q28: 18065 | R28: 20244 | S28: 20011 | T28: 21393 | U28: 22775 | V28: 22653 | W28: 21792 | X28: 20875 | Y28: 19681 | Z28: 17943 | AA28: =+SUM(C28:Z28) -> 427893 | AB28: 4 | AC28: =+AA28*AB28 -> 1711572
B29: Domingo | C29: 21115 | D29: 19448 | E29: 18062 | F29: 16856 | G29: 16184 | H29: 14703 | I29: 15035 | J29: 7294 | K29: 5596 | L29: 6369 | M29: 6440 | N29: 6713 | O29: 7513 | P29: 8337 | Q29: 10647 | R29: 12923 | S29: 13864 | T29: 15995 | U29: 18382 | V29: 20218 | W29: 20592 | X29: 21063 | Y29: 20129 | Z29: 18262 | AA29: =+SUM(C29:Z29) -> 341740 | AB29: 5 | AC29: =+AA29*AB29 -> 1708700
B30: Festivo | C30: 17233 | D30: 15585 | E30: 14370 | F30: 13358 | G30: 12915 | H30: 11846 | I30: 12595 | J30: 5887 | K30: 5688 | L30: 7056 | M30: 8075 | N30: 8299 | O30: 8172 | P30: 8897 | Q30: 10925 | R30: 12568 | S30: 12656 | T30: 14682 | U30: 16851 | V30: 19280 | W30: 19235 | X30: 18927 | Y30: 17227 | Z30: 14744 | AA30: =+SUM(C30:Z30) -> 307071 | AB30: 3 | AC30: =+AA30*AB30 -> 921213
A31: 45839 | B31: Hábil | C31: 17009 | D31: 15144 | E31: 13792 | F31: 12694 | G31: 12344 | H31: 12519 | I31: 13525 | J31: 7935 | K31: 8958 | L31: 10358 | M31: 12020 | N31: 11793 | O31: 8977 | P31: 12941 | Q31: 17905 | R31: 19863 | S31: 19454 | T31: 19272 | U31: 18925 | V31: 19501 | W31: 19630 | X31: 19052 | Y31: 17098 | Z31: 14454 | AA31: =+SUM(C31:Z31) -> 355163 | AB31: 23 | AC31: =+AA31*AB31 -> 8168749 | AD31: =+SUM(AC31:AC34) -> 10406781
B32: Sábado | C32: 15975 | D32: 14325 | E32: 13062 | F32: 12056 | G32: 11749 | H32: 11057 | I32: 12048 | J32: 6218 | K32: 6930 | L32: 8400 | M32: 9524 | N32: 9860 | O32: 8688 | P32: 9826 | Q32: 12824 | R32: 14440 | S32: 13991 | T32: 15053 | U32: 16796 | V32: 17912 | W32: 17033 | X32: 16550 | Y32: 15867 | Z32: 14522 | AA32: =+SUM(C32:Z32) -> 304706 | AB32: 4 | AC32: =+AA32*AB32 -> 1218824
B33: Domingo | C33: 17929 | D33: 16204 | E33: 14688 | F33: 13563 | G33: 12789 | H33: 11548 | I33: 11772 | J33: 3204 | K33: 1719 | L33: 2435 | M33: 2718 | N33: 2744 | O33: 3565 | P33: 4550 | Q33: 6484 | R33: 8810 | S33: 9626 | T33: 13002 | U33: 15033 | V33: 16887 | W33: 17229 | X33: 17468 | Y33: 16365 | Z33: 14470 | AA33: =+SUM(C33:Z33) -> 254802 | AB33: 4 | AC33: =+AA33*AB33 -> 1019208
B34: Festivo | C34: 0 | D34: 0 | E34: 0 | F34: 0 | G34: 0 | H34: 0 | I34: 0 | J34: 0 | K34: 0 | L34: 0 | M34: 0 | N34: 0 | O34: 0 | P34: 0 | Q34: 0 | R34: 0 | S34: 0 | T34: 0 | U34: 0 | V34: 0 | W34: 0 | X34: 0 | Y34: 0 | Z34: 0 | AA34: =+SUM(C34:Z34) -> 0 | AB34: 0 | AC34: =+AA34*AB34 -> 0
A35: 45870 | B35: Hábil | C35: 29395 | D35: 27394 | E35: 25921 | F35: 24766 | G35: 24351 | H35: 24369 | I35: 25186 | J35: 19821 | K35: 20600 | L35: 22347 | M35: 23970 | N35: 24065 | O35: 21198 | P35: 25790 | Q35: 31355 | R35: 33374 | S35: 33109 | T35: 32309 | U35: 32128 | V35: 32600 | W35: 32867 | X35: 32625 | Y35: 30516 | Z35: 27913 | AA35: =+SUM(C35:Z35) -> 657969 | AB35: 19 | AC35: =+AA35*AB35 -> 12501411 | AD35: =+SUM(AC35:AC38) -> 19335230
B36: Sábado | C36: 32223 | D36: 30064 | E36: 28363 | F36: 27011 | G36: 26328 | H36: 25303 | I36: 26086 | J36: 20696 | K36: 21317 | L36: 23206 | M36: 24150 | N36: 24769 | O36: 22953 | P36: 24156 | Q36: 26968 | R36: 28562 | S36: 28576 | T36: 29623 | U36: 31514 | V36: 31708 | W36: 30832 | X36: 30891 | Y36: 30210 | Z36: 28729 | AA36: =+SUM(C36:Z36) -> 654238 | AB36: 5 | AC36: =+AA36*AB36 -> 3271190
B37: Domingo | C37: 30512 | D37: 28584 | E37: 27023 | F37: 25757 | G37: 24759 | H37: 23057 | I37: 22880 | J37: 14976 | K37: 13190 | L37: 13016 | M37: 13656 | N37: 13212 | O37: 14203 | P37: 16069 | Q37: 17969 | R37: 20275 | S37: 20180 | T37: 22906 | U37: 25623 | V37: 26872 | W37: 27288 | X37: 27842 | Y37: 26747 | Z37: 24789 | AA37: =+SUM(C37:Z37) -> 521385 | AB37: 5 | AC37: =+AA37*AB37 -> 2606925
B38: Festivo | C38: 23887 | D38: 22499 | E38: 21284 | F38: 20524 | G38: 20114 | H38: 19429 | I38: 19503 | J38: 11963 | K38: 11062 | L38: 12438 | M38: 13464 | N38: 14069 | O38: 14442 | P38: 15560 | Q38: 17691 | R38: 19821 | S38: 20075 | T38: 22030 | U38: 25001 | V38: 27081 | W38: 27362 | X38: 28152 | Y38: 26710 | Z38: 23691 | AA38: =+SUM(C38:Z38) -> 477852 | AB38: 2 | AC38: =+AA38*AB38 -> 955704
A39: 45901 | B39: Hábil | C39: 30527 | D39: 28341 | E39: 26777 | F39: 25487 | G39: 25033 | H39: 25177 | I39: 26307 | J39: 21029 | K39: 22145 | L39: 24031 | M39: 25782 | N39: 25775 | O39: 22928 | P39: 27909 | Q39: 33396 | R39: 35396 | S39: 34850 | T39: 34809 | U39: 34533 | V39: 33472 | W39: 33127 | X39: 32622 | Y39: 30874 | Z39: 28093 | AA39: =+SUM(C39:Z39) -> 688420 | AB39: 22 | AC39: =+AA39*AB39 -> 15145240 | AD39: =+SUM(AC39:AC42) -> 20046668
B40: Sábado | C40: 31451 | D40: 29532 | E40: 27854 | F40: 26428 | G40: 25697 | H40: 24841 | I40: 25886 | J40: 20766 | K40: 22089 | L40: 23613 | M40: 25300 | N40: 25726 | O40: 24058 | P40: 25284 | Q40: 28050 | R40: 29798 | S40: 29474 | T40: 31459 | U40: 33269 | V40: 32222 | W40: 30706 | X40: 29688 | Y40: 29023 | Z40: 27712 | AA40: =+SUM(C40:Z40) -> 659926 | AB40: 4 | AC40: =+AA40*AB40 -> 2639704
B41: Domingo | C41: 30306 | D41: 28527 | E41: 27130 | F41: 25989 | G41: 25217 | H41: 24044 | I41: 24401 | J41: 16315 | K41: 14629 | L41: 14579 | M41: 15528 | N41: 16221 | O41: 16611 | P41: 18055 | Q41: 20843 | R41: 22794 | S41: 23290 | T41: 26523 | U41: 29103 | V41: 29716 | W41: 29761 | X41: 30092 | Y41: 29053 | Z41: 26704 | AA41: =+SUM(C41:Z41) -> 565431 | AB41: 4 | AC41: =+AA41*AB41 -> 2261724
B42: Festivo | C42: 0 | D42: 0 | E42: 0 | F42: 0 | G42: 0 | H42: 0 | I42: 0 | J42: 0 | K42: 0 | L42: 0 | M42: 0 | N42: 0 | O42: 0 | P42: 0 | Q42: 0 | R42: 0 | S42: 0 | T42: 0 | U42: 0 | V42: 0 | W42: 0 | X42: 0 | Y42: 0 | Z42: 0 | AA42: =+SUM(C42:Z42) -> 0 | AB42: 0 | AC42: =+AA42*AB42 -> 0
...

Sheet OF P2
C1: * La energia a ofertar debe ser expresada únicamente en kilovatio (kWh) redondeado a cero decimales
C4: OFERTA PRODUCTO 2
C5: MES | D5: ENERGIA SOLICITADA (KWh) | E5: % | F5: ENERGIA OFERTADA (KWh) | G5: PRECIO $/kWh
C6: 46023 | D6: =+VLOOKUP(C6,'CURVA P2'!$A$4:$AD$55,30,FALSE) -> 25867601 | E6: % | G6: $/kWh
C7: 46054 | D7: =+VLOOKUP(C7,'CURVA P2'!$A$4:$AD$55,30,FALSE) -> 26647756
C8: 46082 | D8: =+VLOOKUP(C8,'CURVA P2'!$A$4:$AD$55,30,FALSE) -> 25872672
C9: 46113 | D9: =+VLOOKUP(C9,'CURVA P2'!$A$4:$AD$55,30,FALSE) -> 26939490
C10: 46143 | D10: =+VLOOKUP(C10,'CURVA P2'!$A$4:$AD$55,30,FALSE) -> 27532170
C11: 46174 | D11: =+VLOOKUP(C11,'CURVA P2'!$A$4:$AD$55,30,FALSE) -> 27933263
C12: 46204 | D12: =+VLOOKUP(C12,'CURVA P2'!$A$4:$AD$55,30,FALSE) -> 27138331
C13: 46235 | D13: =+VLOOKUP(C13,'CURVA P2'!$A$4:$AD$55,30,FALSE) -> 28204070
C14: 46266 | D14: =+VLOOKUP(C14,'CURVA P2'!$A$4:$AD$55,30,FALSE) -> 28841092
C15: 46296 | D15: =+VLOOKUP(C15,'CURVA P2'!$A$4:$AD$55,30,FALSE) -> 28440193
C16: 46327 | D16: =+VLOOKUP(C16,'CURVA P2'!$A$4:$AD$55,30,FALSE) -> 27960148
C17: 46357 | D17: =+VLOOKUP(C17,'CURVA P2'!$A$4:$AD$55,30,FALSE) -> 27195988
D18: =SUM(D6:D17) -> 328572774

Sheet CURVA P2
A1: Curva de distribucion en kwh
A2: * La energia a ofertar debe ser expresada únicamente en kilovatio (kWh) redondeado a cero decimales
A4: TOTAL | C4: =+AD55 -> 328572774
A5: MES | B5: DÍA | C5: HORA 01 | D5: HORA 02 | E5: HORA 03 | F5: HORA 04 | G5: HORA 05 | H5: HORA 06 | I5: HORA 07 | J5: HORA 08 | K5: HORA 09 | L5: HORA 10 | M5: HORA 11 | N5: HORA 12 | O5: HORA 13 | P5: HORA 14 | Q5: HORA 15 | R5: HORA 16 | S5: HORA 17 | T5: HORA 18 | U5: HORA 19 | V5: HORA 20 | W5: HORA 21 | X5: HORA 22 | Y5: HORA 23 | Z5: HORA 24 | AA5: TOTAL DÍA | AB5: NUMERO DÍAS | AC5: TOTAL DÍA MES | AD5: TOTAL MES
A7: 46023 | B7: Hábil | C7: 36323 | D7: 35390 | E7: 33981 | F7: 32935 | G7: 32600 | H7: 33173 | I7: 33978 | J7: 34114 | K7: 35656 | L7: 37603 | M7: 39465 | N7: 40444 | O7: 38683 | P7: 41920 | Q7: 46689 | R7: 48652 | S7: 48413 | T7: 32914 | U7: 33512 | V7: 32457 | W7: 31511 | X7: 30752 | Y7: 29404 | Z7: 27545 | AA7: =SUM(C7:Z7) -> 868114 | AB7: 20 | AC7: =+AA7*AB7 -> 17362280 | AD7: =+SUM(AC7:AC10) -> 25867601
B8: Sábado | C8: 37198 | D8: 35946 | E8: 34309 | F8: 33141 | G8: 32604 | H8: 32768 | I8: 33275 | J8: 33486 | K8: 35486 | L8: 37627 | M8: 39327 | N8: 39881 | O8: 38795 | P8: 39771 | Q8: 42374 | R8: 43914 | S8: 43550 | T8: 30804 | U8: 32337 | V8: 31501 | W8: 30458 | X8: 29527 | Y8: 28495 | Z8: 27001 | AA8: =SUM(C8:Z8) -> 843575 | AB8: 5 | AC8: =+AA8*AB8 -> 4217875
B9: Domingo | C9: 36575 | D9: 35494 | E9: 33982 | F9: 32806 | G9: 32116 | H9: 31748 | I9: 31622 | J9: 29322 | K9: 28794 | L9: 29792 | M9: 30537 | N9: 31080 | O9: 31958 | P9: 32675 | Q9: 34369 | R9: 36101 | S9: 36527 | T9: 25830 | U9: 27763 | V9: 28125 | W9: 28067 | X9: 27830 | Y9: 26847 | Z9: 25010 | AA9: =SUM(C9:Z9) -> 744970 | AB9: 4 | AC9: =+AA9*AB9 -> 2979880
B10: Festivo | C10: 30938 | D10: 29931 | E10: 29410 | F10: 28687 | G10: 28363 | H10: 28046 | I10: 27531 | J10: 25085 | K10: 24469 | L10: 25423 | M10: 26690 | N10: 27206 | O10: 27849 | P10: 28776 | Q10: 30465 | R10: 32096 | S10: 32261 | T10: 23109 | U10: 25174 | V10: 25356 | W10: 25241 | X10: 24930 | Y10: 24026 | Z10: 22721 | AA10: =SUM(C10:Z10) -> 653783 | AB10: 2 | AC10: =+AA10*AB10 -> 1307566
A11: 46054 | B11: Hábil | C11: 40464 | D11: 38453 | E11: 36994 | F11: 36081 | G11: 36160 | H11: 38346 | I11: 39981 | J11: 40784 | K11: 42459 | L11: 44406 | M11: 46471 | N11: 46307 | O11: 42842 | P11: 47739 | Q11: 53292 | R11: 55364 | S11: 54841 | T11: 36569 | U11: 36748 | V11: 36246 | W11: 35629 | X11: 34194 | Y11: 31402 | Z11: 28763 | AA11: =SUM(C11:Z11) -> 980535 | AB11: 20 | AC11: =+AA11*AB11 -> 19610700 | AD11: =+SUM(AC11:AC14) -> 26647756
B12: Sábado | C12: 38861 | D12: 36966 | E12: 35548 | F12: 34698 | G12: 34280 | H12: 34937 | I12: 36438 | J12: 37945 | K12: 40098 | L12: 42395 | M12: 44040 | N12: 44429 | O12: 43012 | P12: 43599 | Q12: 45811 | R12: 47397 | S12: 46858 | T12: 32071 | U12: 33872 | V12: 33916 | W12: 32860 | X12: 31720 | Y12: 30213 | Z12: 28449 | AA12: =SUM(C12:Z12) -> 910413 | AB12: 4 | AC12: =+AA12*AB12 -> 3641652
B13: Domingo | C13: 40050 | D13: 38040 | E13: 36567 | F13: 35319 | G13: 34738 | H13: 34585 | I13: 34846 | J13: 33279 | K13: 33047 | L13: 34499 | M13: 35451 | N13: 36273 | O13: 36998 | P13: 37538 | Q13: 39546 | R13: 41743 | S13: 42331 | T13: 30058 | U13: 32399 | V13: 33469 | W13: 33581 | X13: 33321 | Y13: 31788 | Z13: 29385 | AA13: =SUM(C13:Z13) -> 848851 | AB13: 4 | AC13: =+AA13*AB13 -> 3395404
B14: Festivo | C14: 0 | D14: 0 | E14: 0 | F14: 0 | G14: 0 | H14: 0 | I14: 0 | J14: 0 | K14: 0 | L14: 0 | M14: 0 | N14: 0 | O14: 0 | P14: 0 | Q14: 0 | R14: 0 | S14: 0 | T14: 0 | U14: 0 | V14: 0 | W14: 0 | X14: 0 | Y14: 0 | Z14: 0 | AA14: =SUM(C14:Z14) -> 0 | AB14: 0 | AC14: =+AA14*AB14 -> 0
A15: 46082 | B15: Hábil | C15: 36850 | D15: 34912 | E15: 33549 | F15: 32553 | G15: 32445 | H15: 33863 | I15: 34312 | J15: 34496 | K15: 35652 | L15: 37247 | M15: 38949 | N15: 39084 | O15: 36568 | P15: 41137 | Q15: 46348 | R15: 48250 | S15: 47932 | T15: 31504 | U15: 31708 | V15: 31634 | W15: 31691 | X15: 31154 | Y15: 29089 | Z15: 26865 | AA15: =SUM(C15:Z15) -> 857792 | AB15: 21 | AC15: =+AA15*AB15 -> 18013632 | AD15: =+SUM(AC15:AC18) -> 25872672
B16: Sábado | C16: 37925 | D16: 35970 | E16: 34459 | F16: 33210 | G16: 32557 | H16: 32565 | I16: 33164 | J16: 33892 | K16: 35551 | L16: 37518 | M16: 39140 | N16: 39341 | O16: 37849 | P16: 38833 | Q16: 41546 | R16: 43165 | S16: 42885 | T16: 29856 | U16: 31166 | V16: 31083 | W16: 30716 | X16: 30444 | Y16: 29842 | Z16: 28432 | AA16: =SUM(C16:Z16) -> 841109 | AB16: 4 | AC16: =+AA16*AB16 -> 3364436
B17: Domingo | C17: 38635 | D17: 36632 | E17: 35210 | F17: 34050 | G17: 33276 | H17: 32685 | I17: 32276 | J17: 29960 | K17: 29051 | L17: 29556 | M17: 29895 | N17: 30337 | O17: 31428 | P17: 32385 | Q17: 34430 | R17: 36504 | S17: 37088 | T17: 25978 | U17: 27863 | V17: 29249 | W17: 29822 | X17: 30011 | Y17: 28322 | Z17: 26284 | AA17: =SUM(C17:Z17) -> 760927 | AB17: 5 | AC17: =+AA17*AB17 -> 3804635
B18: Festivo | C18: 31470 | D18: 29481 | E18: 28259 | F18: 27417 | G18: 27156 | H18: 26911 | I18: 27371 | J18: 26650 | K18: 26846 | L18: 28414 | M18: 30198 | N18: 31335 | O18: 31403 | P18: 32725 | Q18: 34206 | R18: 35235 | S18: 35240 | T18: 23720 | U18: 26040 | V18: 27378 | W18: 27640 | X18: 27195 | Y18: 24997 | Z18: 22682 | AA18: =SUM(C18:Z18) -> 689969 | AB18: 1 | AC18: =+AA18*AB18 -> 689969
A19: 46113 | B19: Hábil | C19: 38823 | D19: 36792 | E19: 35405 | F19: 34412 | G19: 34411 | H19: 35428 | I19: 36444 | J19: 37702 | K19: 39736 | L19: 41660 | M19: 43906 | N19: 44344 | O19: 41194 | P19: 45815 | Q19: 51649 | R19: 53409 | S19: 52660 | T19: 34968 | U19: 35397 | V19: 34931 | W19: 34544 | X19: 33716 | Y19: 31572 | Z19: 29036 | AA19: =SUM(C19:Z19) -> 937954 | AB19: 20 | AC19: =+AA19*AB19 -> 18759080 | AD19: =+SUM(AC19:AC22) -> 26939490
B20: Sábado | C20: 39746 | D20: 37821 | E20: 36383 | F20: 35086 | G20: 34623 | H20: 34219 | I20: 35382 | J20: 36304 | K20: 38614 | L20: 40605 | M20: 42605 | N20: 43174 | O20: 41688 | P20: 42491 | Q20: 44928 | R20: 46392 | S20: 45680 | T20: 32041 | U20: 33388 | V20: 32596 | W20: 31693 | X20: 30693 | Y20: 29503 | Z20: 28040 | AA20: =SUM(C20:Z20) -> 893695 | AB20: 4 | AC20: =+AA20*AB20 -> 3574780
B21: Domingo | C21: 39666 | D21: 37468 | E21: 35862 | F21: 34619 | G21: 33828 | H21: 32911 | I21: 32907 | J21: 31415 | K21: 31075 | L21: 31863 | M21: 32672 | N21: 33809 | O21: 34629 | P21: 35444 | Q21: 37506 | R21: 39358 | S21: 39728 | T21: 27703 | U21: 29830 | V21: 30690 | W21: 30142 | X21: 30017 | Y21: 28553 | Z21: 26278 | AA21: =SUM(C21:Z21) -> 797973 | AB21: 4 | AC21: =+AA21*AB21 -> 3191892
B22: Festivo | C22: 37199 | D22: 35178 | E22: 33678 | F22: 32560 | G22: 31741 | H22: 30838 | I22: 30928 | J22: 28481 | K22: 26920 | L22: 26801 | M22: 27079 | N22: 27996 | O22: 28986 | P22: 29776 | Q22: 31825 | R22: 33324 | S22: 33627 | T22: 23798 | U22: 25998 | V22: 26836 | W22: 26453 | X22: 26348 | Y22: 25856 | Z22: 24643 | AA22: =SUM(C22:Z22) -> 706869 | AB22: 2 | AC22: =+AA22*AB22 -> 1413738
A23: 46143 | B23: Hábil | C23: 39653 | D23: 37678 | E23: 36142 | F23: 35050 | G23: 34727 | H23: 34736 | I23: 35671 | J23: 36946 | K23: 39141 | L23: 41255 | M23: 43354 | N23: 43620 | O23: 40581 | P23: 45505 | Q23: 51225 | R23: 52669 | S23: 51766 | T23: 34915 | U23: 34254 | V23: 33997 | W23: 34267 | X23: 33849 | Y23: 31999 | Z23: 29612 | AA23: =SUM(C23:Z23) -> 932612 | AB23: 19 | AC23: =+AA23*AB23 -> 17719628 | AD23: =+SUM(AC23:AC26) -> 27532170
B24: Sábado | C24: 40397 | D24: 38099 | E24: 36307 | F24: 35074 | G24: 34456 | H24: 33423 | I24: 34909 | J24: 35840 | K24: 38297 | L24: 40764 | M24: 42801 | N24: 43035 | O24: 41527 | P24: 42527 | Q24: 44889 | R24: 45675 | S24: 44871 | T24: 30654 | U24: 31648 | V24: 31730 | W24: 30929 | X24: 30384 | Y24: 29575 | Z24: 27902 | AA24: =SUM(C24:Z24) -> 885713 | AB24: 5 | AC24: =+AA24*AB24 -> 4428565
B25: Domingo | C25: 39083 | D25: 37257 | E25: 35751 | F25: 34523 | G25: 33694 | H25: 32123 | I25: 32608 | J25: 31120 | K25: 30569 | L25: 31359 | M25: 32376 | N25: 32864 | O25: 32954 | P25: 33383 | Q25: 35642 | R25: 37347 | S25: 37803 | T25: 26741 | U25: 28511 | V25: 29341 | W25: 29762 | X25: 30287 | Y25: 29382 | Z25: 27519 | AA25: =SUM(C25:Z25) -> 781999 | AB25: 5 | AC25: =+AA25*AB25 -> 3909995
B26: Festivo | C26: 34556 | D26: 32740 | E26: 31403 | F26: 30365 | G26: 29856 | H26: 28645 | I26: 29499 | J26: 28411 | K26: 28451 | L26: 29841 | M26: 31251 | N26: 32135 | O26: 32375 | P26: 33468 | Q26: 35388 | R26: 36993 | S26: 36900 | T26: 25048 | U26: 27267 | V26: 29160 | W26: 29793 | X26: 29861 | Y26: 28057 | Z26: 25528 | AA26: =SUM(C26:Z26) -> 736991 | AB26: 2 | AC26: =+AA26*AB26 -> 1473982
A27: 46174 | B27: Hábil | C27: 41516 | D27: 39436 | E27: 37790 | F27: 36706 | G27: 36359 | H27: 36180 | I27: 37766 | J27: 39552 | K27: 41903 | L27: 43874 | M27: 45942 | N27: 46519 | O27: 43058 | P27: 47598 | Q27: 52884 | R27: 54525 | S27: 53861 | T27: 35546 | U27: 35212 | V27: 35135 | W27: 35078 | X27: 34592 | Y27: 32873 | Z27: 30512 | AA27: =SUM(C27:Z27) -> 974417 | AB27: 19 | AC27: =+AA27*AB27 -> 18513923 | AD27: =+SUM(AC27:AC30) -> 27933263
B28: Sábado | C28: 41420 | D28: 39395 | E28: 37812 | F28: 36587 | G28: 36163 | H28: 35214 | I28: 36849 | J28: 38469 | K28: 40681 | L28: 42711 | M28: 44386 | N28: 44530 | O28: 42586 | P28: 43174 | Q28: 46405 | R28: 48178 | S28: 47492 | T28: 32842 | U28: 33850 | V28: 33399 | W28: 32672 | X28: 31898 | Y28: 30910 | Z28: 29434 | AA28: =SUM(C28:Z28) -> 927057 | AB28: 4 | AC28: =+AA28*AB28 -> 3708228
B29: Domingo | C29: 41277 | D29: 39489 | E29: 37995 | F29: 36692 | G29: 35969 | H29: 34372 | I29: 34762 | J29: 33406 | K29: 32466 | L29: 33686 | M29: 33935 | N29: 34438 | O29: 35160 | P29: 35839 | Q29: 37896 | R29: 39780 | S29: 40427 | T29: 27849 | U29: 29747 | V29: 31221 | W29: 31667 | X29: 32404 | Y29: 31743 | Z29: 30229 | AA29: =SUM(C29:Z29) -> 832449 | AB29: 4 | AC29: =+AA29*AB29 -> 3329796
B30: Festivo | C30: 37055 | D30: 35285 | E30: 33977 | F30: 32887 | G30: 32410 | H30: 31258 | I30: 32102 | J30: 31863 | K30: 32608 | L30: 34497 | M30: 35865 | N30: 36351 | O30: 36040 | P30: 36665 | Q30: 38431 | R30: 39614 | S30: 39279 | T30: 25974 | U30: 27618 | V30: 29814 | W30: 29826 | X30: 29746 | Y30: 28365 | Z30: 26242 | AA30: =SUM(C30:Z30) -> 793772 | AB30: 3 | AC30: =+AA30*AB30 -> 2381316
A31: 46204 | B31: Hábil | C31: 39001 | D31: 36978 | E31: 35511 | F31: 34316 | G31: 33934 | H31: 34129 | I31: 35253 | J31: 36449 | K31: 38665 | L31: 40627 | M31: 42686 | N31: 42656 | O31: 39229 | P31: 43519 | Q31: 48671 | R31: 50245 | S31: 49348 | T31: 32431 | U31: 31971 | V31: 32324 | W31: 32604 | X31: 32208 | Y31: 30498 | Z31: 28197 | AA31: =SUM(C31:Z31) -> 901450 | AB31: 22 | AC31: =+AA31*AB31 -> 19831900 | AD31: =+SUM(AC31:AC34) -> 27138331
B32: Sábado | C32: 37840 | D32: 36057 | E32: 34687 | F32: 33597 | G32: 33265 | H32: 32516 | I32: 33628 | J32: 34511 | K32: 36389 | L32: 38424 | M32: 39871 | N32: 40456 | O32: 38903 | P32: 39933 | Q32: 42778 | R32: 43940 | S32: 43018 | T32: 28357 | U32: 29889 | V32: 30871 | W32: 30091 | X32: 29830 | Y32: 29393 | Z32: 28319 | AA32: =SUM(C32:Z32) -> 846563 | AB32: 4 | AC32: =+AA32*AB32 -> 3386252
B33: Domingo | C33: 39996 | D33: 38130 | E33: 36482 | F33: 35259 | G33: 34417 | H33: 33070 | I33: 33353 | J33: 30918 | K33: 30232 | L33: 31345 | M33: 31840 | N33: 32074 | O33: 32847 | P33: 33702 | Q33: 35362 | R33: 37340 | S33: 37814 | T33: 27340 | U33: 29040 | V33: 30520 | W33: 30821 | X33: 31181 | Y33: 30316 | Z33: 28729 | AA33: =SUM(C33:Z33) -> 792128 | AB33: 4 | AC33: =+AA33*AB33 -> 3168512
B34: Festivo | C34: 36890 | D34: 34974 | E34: 33441 | F34: 32502 | G34: 31953 | H34: 31031 | I34: 31435 | J34: 30345 | K34: 30349 | L34: 31607 | M34: 32620 | N34: 32853 | O34: 32473 | P34: 33627 | Q34: 35451 | R34: 37040 | S34: 36953 | T34: 24507 | U34: 26513 | V34: 28260 | W34: 28300 | X34: 27839 | Y34: 26287 | Z34: 24417 | AA34: =SUM(C34:Z34) -> 751667 | AB34: 1 | AC34: =+AA34*AB34 -> 751667
A35: 46235 | B35: Hábil | C35: 40713 | D35: 38552 | E35: 36961 | F35: 35711 | G35: 35262 | H35: 35279 | I35: 36198 | J35: 37635 | K35: 39572 | L35: 41909 | M35: 43938 | N35: 44264 | O35: 40810 | P35: 45786 | Q35: 51585 | R35: 53213 | S35: 52469 | T35: 34453 | U35: 34072 | V35: 34548 | W35: 34964 | X35: 34988 | Y35: 33158 | Z35: 30973 | AA35: =SUM(C35:Z35) -> 947013 | AB35: 19 | AC35: =+AA35*AB35 -> 17993247 | AD35: =+SUM(AC35:AC38) -> 28204070
B36: Sábado | C36: 43797 | D36: 41466 | E36: 39626 | F36: 38162 | G36: 37423 | H36: 36307 | I36: 37193 | J36: 38503 | K36: 40272 | L36: 42744 | M36: 44004 | N36: 44913 | O36: 42678 | P36: 43808 | Q36: 46456 | R36: 47611 | S36: 47172 | T36: 32391 | U36: 33923 | V36: 34039 | W36: 33310 | X36: 33646 | Y36: 33180 | Z36: 32010 | AA36: =SUM(C36:Z36) -> 944634 | AB36: 5 | AC36: =+AA36*AB36 -> 4723170
B37: Domingo | C37: 41920 | D37: 39842 | E37: 38158 | F37: 36789 | G37: 35707 | H37: 33864 | I37: 33712 | J37: 32034 | K37: 31019 | L37: 31204 | M37: 32086 | N37: 31815 | O37: 32768 | P37: 34598 | Q37: 36228 | R37: 38170 | S37: 37660 | T37: 25895 | U37: 28197 | V37: 29111 | W37: 29473 | X37: 30198 | Y37: 29294 | Z37: 27687 | AA37: =SUM(C37:Z37) -> 797429 | AB37: 5 | AC37: =+AA37*AB37 -> 3987145
B38: Festivo | C38: 34667 | D38: 33178 | E38: 31873 | F38: 31057 | G38: 30616 | H38: 29881 | I38: 29993 | J38: 28852 | K38: 28871 | L38: 30786 | M38: 32144 | N38: 33043 | O38: 33257 | P38: 34297 | Q38: 36202 | R38: 37968 | S38: 37804 | T38: 24232 | U38: 26862 | V38: 28972 | W38: 29409 | X38: 30520 | Y38: 29353 | Z38: 26417 | AA38: =SUM(C38:Z38) -> 750254 | AB38: 2 | AC38: =+AA38*AB38 -> 1500508
A39: 46266 | B39: Hábil | C39: 42386 | D39: 40011 | E39: 38232 | F39: 36841 | G39: 36307 | H39: 36343 | I39: 37458 | J39: 39098 | K39: 41155 | L39: 43580 | M39: 45815 | N39: 46150 | O39: 42919 | P39: 48244 | Q39: 53587 | R39: 55075 | S39: 53863 | T39: 36063 | U39: 36267 | V39: 35821 | W39: 36141 | X39: 36054 | Y39: 34295 | Z39: 31573 | AA39: =SUM(C39:Z39) -> 983278 | AB39: 22 | AC39: =+AA39*AB39 -> 21632116 | AD39: =+SUM(AC39:AC42) -> 28841092
B40: Sábado | C40: 42663 | D40: 40518 | E40: 38829 | F40: 37515 | G40: 36845 | H40: 35721 | I40: 37100 | J40: 38809 | K40: 41296 | L40: 43378 | M40: 45330 | N40: 45968 | O40: 43882 | P40: 45295 | Q40: 48232 | R40: 49501 | S40: 48632 | T40: 34505 | U40: 36099 | V40: 35162 | W40: 34173 | X40: 33777 | Y40: 32852 | Z40: 31555 | AA40: =SUM(C40:Z40) -> 957637 | AB40: 4 | AC40: =+AA40*AB40 -> 3830548
B41: Domingo | C41: 42301 | D41: 40323 | E41: 38820 | F41: 37582 | G41: 36616 | H41: 35367 | I41: 35610 | J41: 33781 | K41: 32792 | L41: 32999 | M41: 34161 | N41: 34914 | O41: 34945 | P41: 36270 | Q41: 38961 | R41: 40619 | S41: 40753 | T41: 28773 | U41: 30984 | V41: 31912 | W41: 32366 | X41: 32711 | Y41: 31498 | Z41: 29549 | AA41: =SUM(C41:Z41) -> 844607 | AB41: 4 | AC41: =+AA41*AB41 -> 3378428
B42: Festivo | C42: 0 | D42: 0 | E42: 0 | F42: 0 | G42: 0 | H42: 0 | I42: 0 | J42: 0 | K42: 0 | L42: 0 | M42: 0 | N42: 0 | O42: 0 | P42: 0 | Q42: 0 | R42: 0 | S42: 0 | T42: 0 | U42: 0 | V42: 0 | W42: 0 | X42: 0 | Y42: 0 | Z42: 0 | AA42: =SUM(C42:Z42) -> 0 | AB42: 0 | AC42: =+AA42*AB42 -> 0
...

Sheet OF P3
C1: * La energia a ofertar debe ser expresada únicamente en kilovatio (kWh) redondeado a cero decimales
C4: OFERTA PRODUCTO 3
C5: MES | D5: ENERGIA SOLICITADA (KWh) | E5: % | F5: ENERGIA OFERTADA (KWh) | G5: PRECIO $/kWh
C6: 46388 | D6: =+VLOOKUP(C6,'CURVA P3'!$A$4:$AD$55,30,FALSE) -> 26759066 | E6: % | G6: $/kWh
C7: 46419 | D7: =+VLOOKUP(C7,'CURVA P3'!$A$4:$AD$55,30,FALSE) -> 27672188
C8: 46447 | D8: =+VLOOKUP(C8,'CURVA P3'!$A$4:$AD$55,30,FALSE) -> 26750823
C9: 46478 | D9: =+VLOOKUP(C9,'CURVA P3'!$A$4:$AD$55,30,FALSE) -> 27930538
C10: 46508 | D10: =+VLOOKUP(C10,'CURVA P3'!$A$4:$AD$55,30,FALSE) -> 28291287
C11: 46539 | D11: =+VLOOKUP(C11,'CURVA P3'!$A$4:$AD$55,30,FALSE) -> 28860123
C12: 46569 | D12: =+VLOOKUP(C12,'CURVA P3'!$A$4:$AD$55,30,FALSE) -> 25495169
C13: 46600 | D13: =+VLOOKUP(C13,'CURVA P3'!$A$4:$AD$55,30,FALSE) -> 27128008
C14: 46631 | D14: =+VLOOKUP(C14,'CURVA P3'!$A$4:$AD$55,30,FALSE) -> 28086126
C15: 46661 | D15: =+VLOOKUP(C15,'CURVA P3'!$A$4:$AD$55,30,FALSE) -> 27667080
C16: 46692 | D16: =+VLOOKUP(C16,'CURVA P3'!$A$4:$AD$55,30,FALSE) -> 27316858
C17: 46722 | D17: =+VLOOKUP(C17,'CURVA P3'!$A$4:$AD$55,30,FALSE) -> 26335359
D18: =SUM(D6:D17) -> 328292625

Sheet CURVA P3
A1: Curva de distribucion en kwh
A2: * La energia a ofertar debe ser expresada únicamente en kilovatio (kWh) redondeado a cero decimales
A4: TOTAL | C4: =+AD55 -> 328292625
A5: MES | B5: DÍA | C5: HORA 01 | D5: HORA 02 | E5: HORA 03 | F5: HORA 04 | G5: HORA 05 | H5: HORA 06 | I5: HORA 07 | J5: HORA 08 | K5: HORA 09 | L5: HORA 10 | M5: HORA 11 | N5: HORA 12 | O5: HORA 13 | P5: HORA 14 | Q5: HORA 15 | R5: HORA 16 | S5: HORA 17 | T5: HORA 18 | U5: HORA 19 | V5: HORA 20 | W5: HORA 21 | X5: HORA 22 | Y5: HORA 23 | Z5: HORA 24 | AA5: TOTAL DÍA | AB5: NUMERO DÍAS | AC5: TOTAL DÍA MES | AD5: TOTAL MES
A7: 46388 | B7: Hábil | C7: 41112 | D7: 39632 | E7: 38174 | F7: 37103 | G7: 36769 | H7: 37415 | I7: 38397 | J7: 24160 | K7: 27742 | L7: 30348 | M7: 32594 | N7: 33930 | O7: 31706 | P7: 34486 | Q7: 38163 | R7: 38813 | S7: 37654 | T7: 44966 | U7: 46224 | V7: 45403 | W7: 44508 | X7: 43419 | Y7: 41328 | Z7: 38530 | AA7: =SUM(C7:Z7) -> 902576 | AB7: 19 | AC7: =+AA7*AB7 -> 17148944 | AD7: =+SUM(AC7:AC10) -> 26759066
B8: Sábado | C8: 42081 | D8: 40355 | E8: 38703 | F8: 37499 | G8: 36994 | H8: 37203 | I8: 37807 | J8: 23329 | K8: 27119 | L8: 29780 | M8: 31758 | N8: 32743 | O8: 31367 | P8: 31892 | Q8: 33308 | R8: 33465 | S8: 32259 | T8: 41805 | U8: 44546 | V8: 44054 | W8: 42849 | X8: 41682 | Y8: 40181 | Z8: 38111 | AA8: =SUM(C8:Z8) -> 870890 | AB8: 5 | AC8: =+AA8*AB8 -> 4354450
B9: Domingo | C9: 41548 | D9: 39969 | E9: 38396 | F9: 37161 | G9: 36451 | H9: 36098 | I9: 36009 | J9: 19189 | K9: 20582 | L9: 22213 | M9: 23216 | N9: 24153 | O9: 24668 | P9: 24904 | Q9: 25525 | R9: 25985 | S9: 25600 | T9: 36695 | U9: 40022 | V9: 40866 | W9: 40735 | X9: 40253 | Y9: 38659 | Z9: 36223 | AA9: =SUM(C9:Z9) -> 775120 | AB9: 5 | AC9: =+AA9*AB9 -> 3875600
B10: Festivo | C10: 36092 | D10: 35122 | E10: 34421 | F10: 33627 | G10: 33237 | H10: 32889 | I10: 32414 | J10: 15362 | K10: 16567 | L10: 18173 | M10: 19598 | N10: 20522 | O10: 20967 | P10: 21414 | Q10: 21964 | R10: 22282 | S10: 21623 | T10: 33964 | U10: 37537 | V10: 38103 | W10: 37775 | X10: 37061 | Y10: 35616 | Z10: 33706 | AA10: =SUM(C10:Z10) -> 690036 | AB10: 2 | AC10: =+AA10*AB10 -> 1380072
A11: 46419 | B11: Hábil | C11: 45210 | D11: 43052 | E11: 41519 | F11: 40517 | G11: 40530 | H11: 42535 | I11: 44256 | J11: 30504 | K11: 34168 | L11: 36768 | M11: 39163 | N11: 39572 | O11: 35772 | P11: 40076 | Q11: 44552 | R11: 45321 | S11: 43919 | T11: 49397 | U11: 50001 | V11: 49737 | W11: 49039 | X11: 47517 | Y11: 44388 | Z11: 40894 | AA11: =SUM(C11:Z11) -> 1018407 | AB11: 20 | AC11: =+AA11*AB11 -> 20368140 | AD11: =+SUM(AC11:AC14) -> 27672188
B12: Sábado | C12: 44005 | D12: 41934 | E12: 40442 | F12: 39459 | G12: 39077 | H12: 39703 | I12: 41237 | J12: 27861 | K12: 32084 | L12: 34905 | M12: 36885 | N12: 37667 | O12: 35639 | P12: 35848 | Q12: 37197 | R12: 37378 | S12: 35994 | T12: 44240 | U12: 46868 | V12: 47091 | W12: 45848 | X12: 44506 | Y12: 42758 | Z12: 40448 | AA12: =SUM(C12:Z12) -> 949074 | AB12: 4 | AC12: =+AA12*AB12 -> 3796296
B13: Domingo | C13: 44968 | D13: 42779 | E13: 41228 | F13: 39962 | G13: 39299 | H13: 39119 | I13: 39409 | J13: 23149 | K13: 24747 | L13: 26713 | M13: 27922 | N13: 29074 | O13: 29500 | P13: 29598 | Q13: 30471 | R13: 31230 | S13: 30955 | T13: 40922 | U13: 44220 | V13: 45867 | W13: 46050 | X13: 45697 | Y13: 43564 | Z13: 40495 | AA13: =SUM(C13:Z13) -> 876938 | AB13: 4 | AC13: =+AA13*AB13 -> 3507752
B14: Festivo | C14: 0 | D14: 0 | E14: 0 | F14: 0 | G14: 0 | H14: 0 | I14: 0 | J14: 0 | K14: 0 | L14: 0 | M14: 0 | N14: 0 | O14: 0 | P14: 0 | Q14: 0 | R14: 0 | S14: 0 | T14: 0 | U14: 0 | V14: 0 | W14: 0 | X14: 0 | Y14: 0 | Z14: 0 | AB14: 0 | AC14: =+AA14*AB14 -> 0
A15: 46447 | B15: Hábil | C15: 41360 | D15: 39315 | E15: 37895 | F15: 36869 | G15: 36771 | H15: 38112 | I15: 38916 | J15: 24761 | K15: 27986 | L15: 30211 | M15: 32257 | N15: 32868 | O15: 29896 | P15: 33790 | Q15: 37867 | R15: 38485 | S15: 37362 | T15: 44071 | U15: 44845 | V15: 44769 | W15: 44445 | X15: 43480 | Y15: 40989 | Z15: 37962 | AA15: =SUM(C15:Z15) -> 895282 | AB15: 20 | AC15: =+AA15*AB15 -> 17905640 | AD15: =+SUM(AC15:AC18) -> 26750823
B16: Sábado | C16: 42388 | D16: 40275 | E16: 38733 | F16: 37484 | G16: 36900 | H16: 36989 | I16: 37839 | J16: 24046 | K16: 27640 | L16: 30072 | M16: 31973 | N16: 32524 | O16: 30600 | P16: 31044 | Q16: 32534 | R16: 32788 | S16: 31710 | T16: 41035 | U16: 43398 | V16: 43499 | W16: 42711 | X16: 41942 | Y16: 40804 | Z16: 38897 | AA16: =SUM(C16:Z16) -> 867825 | AB16: 4 | AC16: =+AA16*AB16 -> 3471300
B17: Domingo | C17: 42775 | D17: 40684 | E17: 39204 | F17: 38002 | G17: 37254 | H17: 36752 | I17: 36495 | J17: 19784 | K17: 20934 | L17: 22177 | M17: 22843 | N17: 23818 | O17: 24459 | P17: 24830 | Q17: 25764 | R17: 26410 | S17: 26157 | T17: 36928 | U17: 39919 | V17: 41602 | W17: 42048 | X17: 41964 | Y17: 39942 | Z17: 37293 | AA17: =SUM(C17:Z17) -> 788038 | AB17: 4 | AC17: =+AA17*AB17 -> 3152152
B18: Festivo | C18: 37367 | D18: 35263 | E18: 33932 | F18: 33023 | G18: 32635 | H18: 32471 | I18: 33004 | J18: 17680 | K18: 19808 | L18: 22003 | M18: 23930 | N18: 25228 | O18: 24755 | P18: 25550 | Q18: 26074 | R18: 25920 | S18: 25038 | T18: 35505 | U18: 38939 | V18: 40582 | W18: 40673 | X18: 39856 | Y18: 37125 | Z18: 34216 | AA18: =SUM(C18:Z18) -> 740577 | AB18: 3 | AC18: =+AA18*AB18 -> 2221731
A19: 46478 | B19: Hábil | C19: 42913 | D19: 40771 | E19: 39307 | F19: 38274 | G19: 38208 | H19: 38948 | I19: 40186 | J19: 26813 | K19: 30811 | L19: 33416 | M19: 35921 | N19: 36823 | O19: 33378 | P19: 37364 | Q19: 41912 | R19: 42371 | S19: 40833 | T19: 47018 | U19: 47734 | V19: 47381 | W19: 46946 | X19: 45815 | Y19: 43218 | Z19: 39922 | AA19: =SUM(C19:Z19) -> 956283 | AB19: 22 | AC19: =+AA19*AB19 -> 21038226 | AD19: =+SUM(AC19:AC22) -> 27930538
B20: Sábado | C20: 43647 | D20: 41540 | E20: 39984 | F20: 38732 | G20: 38251 | H20: 37727 | I20: 39013 | J20: 25248 | K20: 29461 | L20: 32141 | M20: 34261 | N20: 35186 | O20: 33394 | P20: 33847 | Q20: 35265 | R20: 35332 | S20: 33833 | T20: 43004 | U20: 45227 | V20: 44692 | W20: 43641 | X20: 42493 | Y20: 41021 | Z20: 39086 | AA20: =SUM(C20:Z20) -> 906026 | AB20: 4 | AC20: =+AA20*AB20 -> 3624104
B21: Domingo | C21: 43710 | D21: 41435 | E21: 39777 | F21: 38473 | G21: 37698 | H21: 36700 | I21: 36907 | J21: 20699 | K21: 22184 | L21: 23712 | M21: 24863 | N21: 26304 | O21: 26781 | P21: 27128 | Q21: 28096 | R21: 28585 | S21: 28070 | T21: 38487 | U21: 41524 | V21: 42755 | W21: 42503 | X21: 42333 | Y21: 40551 | Z21: 37777 | AA21: =SUM(C21:Z21) -> 817052 | AB21: 4 | AC21: =+AA21*AB21 -> 3268208
B22: Festivo | C22: 63321 | D22: 60330 | E22: 58232 | F22: 56747 | G22: 55815 | H22: 54264 | I22: 54860 | J22: 56451 | K22: 58312 | L22: 59544 | M22: 60667 | N22: 62232 | O22: 63013 | P22: 63264 | Q22: 63966 | R22: 63315 | S22: 62463 | T22: 62887 | U22: 69236 | V22: 71122 | W22: 70841 | X22: 70142 | Y22: 68086 | Z22: 64794 | AA22: =SUM(C22:Z22) -> 1493904 | AB22: 0 | AC22: =+AA22*AB22 -> 0
A23: 46508 | B23: Hábil | C23: 43778 | D23: 41701 | E23: 40141 | F23: 39041 | G23: 38743 | H23: 38606 | I23: 39941 | J23: 26784 | K23: 31034 | L23: 33814 | M23: 36205 | N23: 36942 | O23: 33566 | P23: 37674 | Q23: 42137 | R23: 42304 | S23: 40616 | T23: 46827 | U23: 46929 | V23: 46839 | W23: 46848 | X23: 46036 | Y23: 43639 | Z23: 40511 | AA23: =SUM(C23:Z23) -> 960656 | AB23: 19 | AC23: =+AA23*AB23 -> 18252464 | AD23: =+SUM(AC23:AC26) -> 28291287
B24: Sábado | C24: 45007 | D24: 42640 | E24: 40865 | F24: 39545 | G24: 38964 | H24: 37872 | I24: 39353 | J24: 25702 | K24: 30131 | L24: 33147 | M24: 35310 | N24: 35908 | O24: 33953 | P24: 34434 | Q24: 35678 | R24: 35463 | S24: 33858 | T24: 42243 | U24: 44192 | V24: 44448 | W24: 43564 | X24: 42773 | Y24: 41544 | Z24: 39519 | AA24: =SUM(C24:Z24) -> 916113 | AB24: 4 | AC24: =+AA24*AB24 -> 3664452
B25: Domingo | C25: 43744 | D25: 41757 | E25: 40199 | F25: 38921 | G25: 38088 | H25: 36428 | I25: 37107 | J25: 20854 | K25: 22236 | L25: 23766 | M25: 25063 | N25: 25959 | O25: 25792 | P25: 25830 | Q25: 26971 | R25: 27310 | S25: 26866 | T25: 37566 | U25: 40392 | V25: 41735 | W25: 42108 | X25: 42364 | Y25: 41023 | Z25: 38586 | AA25: =SUM(C25:Z25) -> 810665 | AB25: 5 | AC25: =+AA25*AB25 -> 4053325
B26: Festivo | C26: 39404 | D26: 37439 | E26: 36022 | F26: 34965 | G26: 34466 | H26: 33293 | I26: 34294 | J26: 18690 | K26: 20706 | L26: 22827 | M26: 24612 | N26: 25829 | O26: 25595 | P26: 26227 | Q26: 27182 | R26: 27421 | S26: 26460 | T26: 36509 | U26: 39640 | V26: 41679 | W26: 42098 | X26: 41819 | Y26: 39692 | Z26: 36813 | AA26: =SUM(C26:Z26) -> 773682 | AB26: 3 | AC26: =+AA26*AB26 -> 2321046
A27: 46539 | B27: Hábil | C27: 45211 | D27: 43027 | E27: 41374 | F27: 40258 | G27: 39949 | H27: 39653 | I27: 41528 | J27: 28765 | K27: 33123 | L27: 35776 | M27: 38126 | N27: 39098 | O27: 35354 | P27: 39189 | Q27: 43375 | R27: 43712 | S27: 42238 | T27: 47775 | U27: 47755 | V27: 47961 | W27: 47646 | X27: 46688 | Y27: 44402 | Z27: 41318 | AA27: =SUM(C27:Z27) -> 993301 | AB27: 21 | AC27: =+AA27*AB27 -> 20859321 | AD27: =+SUM(AC27:AC30) -> 28860123
B28: Sábado | C28: 45576 | D28: 43447 | E28: 41823 | F28: 40596 | G28: 40175 | H28: 39156 | I28: 40950 | J28: 27645 | K28: 31877 | L28: 34592 | M28: 36592 | N28: 37196 | O28: 34939 | P28: 34993 | Q28: 36828 | R28: 37158 | S28: 35700 | T28: 44048 | U28: 45721 | V28: 45892 | W28: 44937 | X28: 43925 | Y28: 42584 | Z28: 40666 | AA28: =SUM(C28:Z28) -> 947016 | AB28: 4 | AC28: =+AA28*AB28 -> 3788064
B29: Domingo | C29: 45364 | D29: 43384 | E29: 41848 | F29: 40570 | G29: 39830 | H29: 38212 | I29: 38816 | J29: 22702 | K29: 23713 | L29: 25583 | M29: 26194 | N29: 27041 | O29: 27339 | P29: 27471 | Q29: 28347 | R29: 28793 | S29: 28607 | T29: 38452 | U29: 41205 | V29: 43307 | W29: 43609 | X29: 43837 | Y29: 42695 | Z29: 40568 | AA29: =SUM(C29:Z29) -> 847487 | AB29: 4 | AC29: =+AA29*AB29 -> 3389948
B30: Festivo | C30: 41476 | D30: 39541 | E30: 38171 | F30: 37056 | G30: 36611 | H30: 35427 | I30: 36429 | J30: 21444 | K30: 24014 | L30: 26513 | M30: 28335 | N30: 29308 | O30: 28683 | P30: 28975 | Q30: 29676 | R30: 29509 | S30: 28337 | T30: 37644 | U30: 40214 | V30: 42781 | W30: 42687 | X30: 42186 | Y30: 40251 | Z30: 37522 | AA30: =SUM(C30:Z30) -> 822790 | AB30: 1 | AC30: =+AA30*AB30 -> 822790
A31: 46569 | B31: Hábil | C31: 39583 | D31: 37451 | E31: 35918 | F31: 34716 | G31: 34346 | H31: 34418 | I31: 35895 | J31: 21903 | K31: 26115 | L31: 28761 | M31: 31083 | N31: 31547 | O31: 27760 | P31: 31475 | Q31: 35565 | R31: 35898 | S31: 34235 | T31: 43847 | U31: 43605 | V31: 44385 | W31: 44382 | X31: 43643 | Y31: 41470 | Z31: 38517 | AA31: =SUM(C31:Z31) -> 856518 | AB31: 20 | AC31: =+AA31*AB31 -> 17130360 | AD31: =+SUM(AC31:AC34) -> 25495169
B32: Sábado | C32: 38940 | D32: 36945 | E32: 35508 | F32: 34355 | G32: 33950 | H32: 33164 | I32: 34510 | J32: 20136 | K32: 24079 | L32: 26773 | M32: 28516 | N32: 29465 | O32: 27478 | P32: 27929 | Q32: 29568 | R32: 29438 | S32: 27822 | T32: 39492 | U32: 41427 | V32: 42662 | W32: 41695 | X32: 41013 | Y32: 40110 | Z32: 38520 | AA32: =SUM(C32:Z32) -> 803495 | AB32: 5 | AC32: =+AA32*AB32 -> 4017475
B33: Domingo | C33: 40438 | D33: 38364 | E33: 36721 | F33: 35501 | G33: 34677 | H33: 33300 | I33: 33726 | J33: 16119 | K33: 17385 | L33: 18980 | M33: 19819 | N33: 20444 | O33: 20890 | P33: 21166 | Q33: 21778 | R33: 22445 | S33: 22016 | T33: 36511 | U33: 38842 | V33: 41030 | W33: 41409 | X33: 41539 | Y33: 40224 | Z33: 38054 | AA33: =SUM(C33:Z33) -> 731378 | AB33: 4 | AC33: =+AA33*AB33 -> 2925512
B34: Festivo | C34: 37641 | D34: 35608 | E34: 34048 | F34: 33048 | G34: 32523 | H34: 31571 | I34: 32234 | J34: 15930 | K34: 17958 | L34: 19909 | M34: 21259 | N34: 21925 | O34: 21140 | P34: 21864 | Q34: 22704 | R34: 23013 | S34: 22090 | T34: 35066 | U34: 37701 | V34: 40323 | W34: 40348 | X34: 39803 | Y34: 37916 | Z34: 35289 | AA34: =SUM(C34:Z34) -> 710911 | AB34: 2 | AC34: =+AA34*AB34 -> 1421822
A35: 46600 | B35: Hábil | C35: 41829 | D35: 39621 | E35: 37970 | F35: 36705 | G35: 36271 | H35: 36282 | I35: 37457 | J35: 23736 | K35: 27748 | L35: 30726 | M35: 33102 | N35: 33875 | O35: 30136 | P35: 34454 | Q35: 39087 | R35: 39420 | S35: 37832 | T35: 46063 | U35: 46064 | V35: 46525 | W35: 46662 | X35: 46193 | Y35: 43878 | Z35: 40952 | AA35: =SUM(C35:Z35) -> 912588 | AB35: 21 | AC35: =+AA35*AB35 -> 19164348 | AD35: =+SUM(AC35:AC38) -> 27128008
B36: Sábado | C36: 44425 | D36: 42040 | E36: 40194 | F36: 38748 | G36: 38000 | H36: 37015 | I36: 38071 | J36: 24106 | K36: 27992 | L36: 31008 | M36: 32659 | N36: 33939 | O36: 31461 | P36: 32109 | Q36: 33624 | R36: 33539 | S36: 32189 | T36: 42883 | U36: 45058 | V36: 45317 | W36: 44332 | X36: 44146 | Y36: 43292 | Z36: 41561 | AA36: =SUM(C36:Z36) -> 897708 | AB36: 3 | AC36: =+AA36*AB36 -> 2693124
B37: Domingo | C37: 43077 | D37: 40870 | E37: 39102 | F37: 37716 | G37: 36669 | H37: 34852 | I37: 34855 | J37: 18003 | K37: 19035 | L37: 20074 | M37: 21233 | N37: 21496 | O37: 22064 | P37: 23186 | Q37: 23805 | R37: 24390 | S37: 23179 | T37: 36078 | U37: 39117 | V37: 40642 | W37: 41098 | X37: 41498 | Y37: 40255 | Z37: 38020 | AA37: =SUM(C37:Z37) -> 760314 | AB37: 5 | AC37: =+AA37*AB37 -> 3801570
B38: Festivo | C38: 37130 | D38: 35403 | E38: 33978 | F38: 33040 | G38: 32570 | H38: 31711 | I38: 32091 | J38: 15874 | K38: 17993 | L38: 20572 | M38: 22324 | N38: 23635 | O38: 23354 | P38: 23934 | Q38: 24862 | R38: 25368 | S38: 24299 | T38: 35894 | U38: 39115 | V38: 41133 | W38: 41269 | X38: 41764 | Y38: 40105 | Z38: 37065 | AA38: =SUM(C38:Z38) -> 734483 | AB38: 2 | AC38: =+AA38*AB38 -> 1468966
A39: 46631 | B39: Hábil | C39: 43815 | D39: 41386 | E39: 39584 | F39: 38188 | G39: 37676 | H39: 37617 | I39: 39003 | J39: 25599 | K39: 29813 | L39: 32916 | M39: 35479 | N39: 36295 | O39: 32719 | P39: 37369 | Q39: 41718 | R39: 41904 | S39: 39872 | T39: 48256 | U39: 48784 | V39: 48083 | W39: 48086 | X39: 47611 | Y39: 45350 | Z39: 41998 | AA39: =SUM(C39:Z39) -> 959121 | AB39: 22 | AC39: =+AA39*AB39 -> 21100662 | AD39: =+SUM(AC39:AC42) -> 28086126
B40: Sábado | C40: 44530 | D40: 42302 | E40: 40544 | F40: 39103 | G40: 38395 | H40: 37321 | I40: 38724 | J40: 25187 | K40: 29650 | L40: 32461 | M40: 34778 | N40: 35769 | O40: 33481 | P40: 34311 | Q40: 36031 | R40: 35911 | S40: 34133 | T40: 45340 | U40: 47773 | V40: 46907 | W40: 45644 | X40: 44864 | Y40: 43750 | Z40: 42013 | AA40: =SUM(C40:Z40) -> 928922 | AB40: 4 | AC40: =+AA40*AB40 -> 3715688
B41: Domingo | C41: 44049 | D41: 41932 | E41: 40314 | F41: 39009 | G41: 38065 | H41: 36730 | I41: 37111 | J41: 20159 | K41: 21166 | L41: 22239 | M41: 23613 | N41: 24819 | O41: 24693 | P41: 25515 | Q41: 26960 | R41: 27244 | S41: 26519 | T41: 39273 | U41: 42545 | V41: 43610 | W41: 44175 | X41: 44482 | Y41: 42932 | Z41: 40290 | AA41: =SUM(C41:Z41) -> 817444 | AB41: 4 | AC41: =+AA41*AB41 -> 3269776
B42: Festivo | C42: 0 | D42: 0 | E42: 0 | F42: 0 | G42: 0 | H42: 0 | I42: 0 | J42: 0 | K42: 0 | L42: 0 | M42: 0 | N42: 0 | O42: 0 | P42: 0 | Q42: 0 | R42: 0 | S42: 0 | T42: 0 | U42: 0 | V42: 0 | W42: 0 | X42: 0 | Y42: 0 | Z42: 0 | AB42: 0 | AC42: =+AA42*AB42 -> 0
...

Sheet OF P4
C1: * La energia a ofertar debe ser expresada únicamente en kilovatio (kWh) redondeado a cero decimales
C4: OFERTA PRODUCTO 5
C5: MES | D5: ENERGIA SOLICITADA (KWh) | E5: % | F5: ENERGIA OFERTADA (KWh) | G5: PRECIO $/kWh
C6: 46753 | D6: =+VLOOKUP(C6,'CURVA P4'!$A$4:$AD$55,30,FALSE) -> 5794097 | E6: % | G6: $/kWh
C7: 46784 | D7: =+VLOOKUP(C7,'CURVA P4'!$A$4:$AD$55,30,FALSE) -> 5931416
C8: 46813 | D8: =+VLOOKUP(C8,'CURVA P4'!$A$4:$AD$55,30,FALSE) -> 5682804
C9: 46844 | D9: =+VLOOKUP(C9,'CURVA P4'!$A$4:$AD$55,30,FALSE) -> 6148462
C10: 46874 | D10: =+VLOOKUP(C10,'CURVA P4'!$A$4:$AD$55,30,FALSE) -> 6166980
C11: 46905 | D11: =+VLOOKUP(C11,'CURVA P4'!$A$4:$AD$55,30,FALSE) -> 6227362
C12: 46935 | D12: =+VLOOKUP(C12,'CURVA P4'!$A$4:$AD$55,30,FALSE) -> 5905820
C13: 46966 | D13: =+VLOOKUP(C13,'CURVA P4'!$A$4:$AD$55,30,FALSE) -> 6338427
C14: 46997 | D14: =+VLOOKUP(C14,'CURVA P4'!$A$4:$AD$55,30,FALSE) -> 6725972
C15: 47027 | D15: =+VLOOKUP(C15,'CURVA P4'!$A$4:$AD$55,30,FALSE) -> 6598849
C16: 47058 | D16: =+VLOOKUP(C16,'CURVA P4'!$A$4:$AD$55,30,FALSE) -> 6537352
C17: 47088 | D17: =+VLOOKUP(C17,'CURVA P4'!$A$4:$AD$55,30,FALSE) -> 6255105
D18: =SUM(D6:D17) -> 74312646

Sheet CURVA P4
A1: Curva de distribucion en kwh
A2: * La energia a ofertar debe ser expresada únicamente en kilovatio (kWh) redondeado a cero decimales
A4: TOTAL | C4: =+AD55 -> 74312646
A5: MES | B5: DÍA | C5: HORA 01 | D5: HORA 02 | E5: HORA 03 | F5: HORA 04 | G5: HORA 05 | H5: HORA 06 | I5: HORA 07 | J5: HORA 08 | K5: HORA 09 | L5: HORA 10 | M5: HORA 11 | N5: HORA 12 | O5: HORA 13 | P5: HORA 14 | Q5: HORA 15 | R5: HORA 16 | S5: HORA 17 | T5: HORA 18 | U5: HORA 19 | V5: HORA 20 | W5: HORA 21 | X5: HORA 22 | Y5: HORA 23 | Z5: HORA 24 | AA5: TOTAL DÍA | AB5: NUMERO DÍAS | AC5: TOTAL DÍA MES | AD5: TOTAL MES
A7: 46753 | B7: Hábil | C7: 9740 | D7: 9284 | E7: 8882 | F7: 8571 | G7: 8456 | H7: 8574 | I7: 2275 | J7: 3168 | K7: 2531 | L7: 2765 | M7: 3212 | N7: 3247 | O7: 2889 | P7: 4396 | Q7: 6826 | R7: 8522 | S7: 15387 | T7: 12795 | U7: 13186 | V7: 13025 | W7: 12880 | X7: 12636 | Y7: 12023 | Z7: 11182 | AA7: =SUM(C7:Z7) -> 196452 | AB7: 20 | AC7: =+AA7*AB7 -> 3929040 | AD7: =+SUM(AC7:AC10) -> 5794097
B8: Sábado | C8: 9869 | D8: 9350 | E8: 8900 | F8: 8577 | G8: 8415 | H8: 8430 | I8: 2047 | J8: 2832 | K8: 2271 | L8: 2493 | M8: 2843 | N8: 2751 | O8: 2659 | P8: 3401 | Q8: 5102 | R8: 6651 | S8: 13529 | T8: 11821 | U8: 12662 | V8: 12556 | W8: 12238 | X8: 11948 | Y8: 11555 | Z8: 10949 | AA8: =SUM(C8:Z8) -> 183849 | AB8: 4 | AC8: =+AA8*AB8 -> 735396
B9: Domingo | C9: 9713 | D9: 9236 | E9: 8805 | F9: 8469 | G9: 8272 | H9: 8149 | I9: 1600 | J9: 1525 | K9: 127 | L9: 3 | M9: 32 | N9: 491 | O9: 461 | P9: 1113 | Q9: 2572 | R9: 4251 | S9: 11394 | T9: 10444 | U9: 11458 | V9: 11771 | W9: 11790 | X9: 11702 | Y9: 11238 | Z9: 10501 | AA9: =SUM(C9:Z9) -> 155117 | AB9: 5 | AC9: =+AA9*AB9 -> 775585
B10: Festivo | C10: 7676 | D10: 7449 | E10: 7255 | F10: 7054 | G10: 6952 | H10: 6863 | I10: 282 | J10: 63 | K10: 9822 | L10: 10808 | M10: 10024 | N10: 10744 | O10: 7354 | P10: 2996 | Q10: 919 | R10: 2520 | S10: 9601 | T10: 9061 | U10: 10209 | V10: 10417 | W10: 10299 | X10: 10051 | Y10: 9599 | Z10: 9020 | AA10: =SUM(C10:Z10) -> 177038 | AB10: 2 | AC10: =+AA10*AB10 -> 354076
A11: 46784 | B11: Hábil | C11: 10223 | D11: 9657 | E11: 9246 | F11: 8970 | G11: 8947 | H11: 9376 | I11: 3272 | J11: 4460 | K11: 3712 | L11: 3850 | M11: 4289 | N11: 3952 | O11: 3161 | P11: 5125 | Q11: 7870 | R11: 9682 | S11: 16553 | T11: 13533 | U11: 13682 | V11: 13641 | W11: 13558 | X11: 13209 | Y11: 12391 | Z11: 11417 | AA11: =SUM(C11:Z11) -> 213776 | AB11: 21 | AC11: =+AA11*AB11 -> 4489296 | AD11: =+SUM(AC11:AC14) -> 5931416
B12: Sábado | C12: 9684 | D12: 9183 | E12: 8801 | F12: 8560 | G12: 8476 | H12: 8619 | I12: 2439 | J12: 3553 | K12: 2985 | L12: 3163 | M12: 3471 | N12: 3286 | O12: 2964 | P12: 3612 | Q12: 5381 | R12: 7024 | S12: 13931 | T12: 12048 | U12: 12805 | V12: 12868 | W12: 12584 | X12: 12281 | Y12: 11860 | Z12: 11216 | AA12: =SUM(C12:Z12) -> 190794 | AB12: 4 | AC12: =+AA12*AB12 -> 763176
B13: Domingo | C13: 10015 | D13: 9455 | E13: 9050 | F13: 8715 | G13: 8539 | H13: 8454 | I13: 1971 | J13: 2081 | K13: 601 | L13: 553 | M13: 651 | N13: 625 | O13: 1166 | P13: 1769 | Q13: 3347 | R13: 5179 | S13: 12426 | T13: 11200 | U13: 12154 | V13: 12665 | W13: 12812 | X13: 12788 | Y13: 12204 | Z13: 11316 | AA13: =SUM(C13:Z13) -> 169736 | AB13: 4 | AC13: =+AA13*AB13 -> 678944
B14: Festivo | C14: 0 | D14: 0 | E14: 0 | F14: 0 | G14: 0 | H14: 0 | I14: 0 | J14: 0 | K14: 0 | L14: 0 | M14: 0 | N14: 0 | O14: 0 | P14: 0 | Q14: 0 | R14: 0 | S14: 0 | T14: 0 | U14: 0 | V14: 0 | W14: 0 | X14: 0 | Y14: 0 | Z14: 0 | AA14: =SUM(C14:Z14) -> 0 | AB14: 0 | AC14: =+AA14*AB14 -> 0
A15: 46813 | B15: Hábil | C15: 9653 | D15: 9091 | E15: 8689 | F15: 8384 | G15: 8309 | H15: 8524 | I15: 2258 | J15: 3199 | K15: 2440 | L15: 2506 | M15: 2868 | N15: 2649 | O15: 2102 | P15: 3913 | Q15: 6419 | R15: 8082 | S15: 14977 | T15: 12326 | U15: 12560 | V15: 12567 | W15: 12573 | X15: 12404 | Y15: 11795 | Z15: 10952 | AA15: =SUM(C15:Z15) -> 189240 | AB15: 22 | AC15: =+AA15*AB15 -> 4163280 | AD15: =+SUM(AC15:AC18) -> 5682804
B16: Sábado | C16: 10013 | D16: 9426 | E16: 8986 | F16: 8632 | G16: 8446 | H16: 8411 | I16: 2115 | J16: 3000 | K16: 2357 | L16: 2463 | M16: 2783 | N16: 2515 | O16: 2257 | P16: 3008 | Q16: 4752 | R16: 6313 | S16: 13216 | T16: 11612 | U16: 12294 | V16: 12331 | W16: 12142 | X16: 12009 | Y16: 11742 | Z16: 11203 | AA16: =SUM(C16:Z16) -> 182026 | AB16: 4 | AC16: =+AA16*AB16 -> 728104
B17: Domingo | C17: 10070 | D17: 9530 | E17: 9119 | F17: 8792 | G17: 8581 | H17: 8388 | I17: 1803 | J17: 1636 | K17: 154 | L17: 577 | M17: 953 | N17: 1384 | O17: 346 | P17: 1039 | Q17: 2631 | R17: 4327 | S17: 11483 | T17: 10572 | U17: 11402 | V17: 11938 | W17: 12206 | X17: 12318 | Y17: 11804 | Z17: 11013 | AA17: =SUM(C17:Z17) -> 162066 | AB17: 4 | AC17: =+AA17*AB17 -> 648264
B18: Festivo | C18: 7738 | D18: 7231 | E18: 6906 | F18: 6685 | G18: 6577 | H18: 6550 | I18: 211 | J18: 555 | K18: 4053 | L18: 3939 | M18: 2194 | N18: 2543 | O18: 1551 | P18: 533 | Q18: 1949 | R18: 3431 | S18: 10433 | T18: 9266 | U18: 10279 | V18: 10726 | W18: 10720 | X18: 10460 | Y18: 9713 | Z18: 8913 | AA18: =SUM(C18:Z18) -> 143156 | AB18: 1 | AC18: =+AA18*AB18 -> 143156
A19: 46844 | B19: Hábil | C19: 10337 | D19: 9746 | E19: 9337 | F19: 9039 | G19: 8998 | H19: 9151 | I19: 2970 | J19: 4373 | K19: 3891 | L19: 4078 | M19: 4607 | N19: 4464 | O19: 3653 | P19: 5567 | Q19: 8347 | R19: 10036 | S19: 16814 | T19: 13602 | U19: 13806 | V19: 13744 | W19: 13733 | X19: 13469 | Y19: 12729 | Z19: 11756 | AA19: =SUM(C19:Z19) -> 218247 | AB19: 18 | AC19: =+AA19*AB19 -> 3928446 | AD19: =+SUM(AC19:AC22) -> 6148462
B20: Sábado | C20: 10436 | D20: 9855 | E20: 9442 | F20: 9098 | G20: 8937 | H20: 8764 | I20: 2584 | J20: 3743 | K20: 3312 | L20: 3527 | M20: 3886 | N20: 3820 | O20: 3561 | P20: 4327 | Q20: 6087 | R20: 7643 | S20: 14424 | T20: 12338 | U20: 12989 | V20: 12879 | W20: 12639 | X20: 12369 | Y20: 11967 | Z20: 11377 | AA20: =SUM(C20:Z20) -> 200004 | AB20: 5 | AC20: =+AA20*AB20 -> 1000020
B21: Domingo | C21: 10394 | D21: 9795 | E21: 9358 | F21: 8999 | G21: 8779 | H21: 8476 | I21: 2024 | J21: 2232 | K21: 834 | L21: 703 | M21: 785 | N21: 815 | O21: 1361 | P21: 2072 | Q21: 3671 | R21: 5352 | S21: 12454 | T21: 11084 | U21: 12020 | V21: 12434 | W21: 12457 | X21: 12478 | Y21: 11970 | Z21: 11109 | AA21: =SUM(C21:Z21) -> 171656 | AB21: 5 | AC21: =+AA21*AB21 -> 858280
B22: Festivo | C22: 8876 | D22: 8349 | E22: 7972 | F22: 7702 | G22: 7524 | H22: 7261 | I22: 881 | J22: 737 | K22: 6611 | L22: 9826 | M22: 10435 | N22: 10936 | O22: 7065 | P22: 2720 | Q22: 1161 | R22: 2737 | S22: 9950 | T22: 9152 | U22: 10187 | V22: 10506 | W22: 10443 | X22: 10337 | Y22: 10016 | Z22: 9474 | AA22: =SUM(C22:Z22) -> 180858 | AB22: 2 | AC22: =+AA22*AB22 -> 361716
A23: 46874 | B23: Hábil | C23: 10233 | D23: 9690 | E23: 9275 | F23: 8988 | G23: 8900 | H23: 8827 | I23: 2697 | J23: 4043 | K23: 3640 | L23: 3882 | M23: 4341 | N23: 4171 | O23: 3441 | P23: 5260 | Q23: 7945 | R23: 9498 | S23: 16222 | T23: 13153 | U23: 13322 | V23: 13347 | W23: 13365 | X23: 13157 | Y23: 12498 | Z23: 11579 | AA23: =SUM(C23:Z23) -> 211474 | AB23: 21 | AC23: =+AA23*AB23 -> 4440954 | AD23: =+SUM(AC23:AC26) -> 6166980
B24: Sábado | C24: 10633 | D24: 9984 | E24: 9489 | F24: 9132 | G24: 8968 | H24: 8688 | I24: 2536 | J24: 3637 | K24: 3285 | L24: 3607 | M24: 3951 | N24: 3691 | O24: 3345 | P24: 4029 | Q24: 5646 | R24: 7131 | S24: 13920 | T24: 11786 | U24: 12511 | V24: 12611 | W24: 12386 | X24: 12181 | Y24: 11837 | Z24: 11264 | AA24: =SUM(C24:Z24) -> 196248 | AB24: 4 | AC24: =+AA24*AB24 -> 784992
B25: Domingo | C25: 10180 | D25: 9664 | E25: 9269 | F25: 8927 | G25: 8698 | H25: 8278 | I25: 1938 | J25: 2071 | K25: 675 | L25: 472 | M25: 601 | N25: 472 | O25: 794 | P25: 1309 | Q25: 2895 | R25: 4476 | S25: 11587 | T25: 10344 | U25: 11296 | V25: 11747 | W25: 11879 | X25: 11964 | Y25: 11577 | Z25: 10850 | AA25: =SUM(C25:Z25) -> 161963 | AB25: 4 | AC25: =+AA25*AB25 -> 647852
B26: Festivo | C26: 8665 | D26: 8165 | E26: 7809 | F26: 7549 | G26: 7430 | H26: 7150 | I26: 941 | J26: 1232 | K26: 41 | L26: 76 | M26: 367 | N26: 335 | O26: 576 | P26: 1317 | Q26: 2873 | R26: 4435 | S26: 11406 | T26: 9992 | U26: 10941 | V26: 11478 | W26: 11545 | X26: 11412 | Y26: 10820 | Z26: 10036 | AA26: =SUM(C26:Z26) -> 146591 | AB26: 2 | AC26: =+AA26*AB26 -> 293182
A27: 46905 | B27: Hábil | C27: 10526 | D27: 9945 | E27: 9506 | F27: 9209 | G27: 9114 | H27: 8996 | I27: 2989 | J27: 4530 | K27: 4156 | L27: 4334 | M27: 4763 | N27: 4644 | O27: 3759 | P27: 5526 | Q27: 8147 | R27: 9777 | S27: 16612 | T27: 13474 | U27: 13580 | V27: 13679 | W27: 13620 | X27: 13374 | Y27: 12724 | Z27: 11815 | AA27: =SUM(C27:Z27) -> 218799 | AB27: 20 | AC27: =+AA27*AB27 -> 4375980 | AD27: =+SUM(AC27:AC30) -> 6227362
B28: Sábado | C28: 10738 | D28: 10185 | E28: 9737 | F28: 9413 | G28: 9290 | H28: 9011 | I28: 3002 | J28: 4277 | K28: 3828 | L28: 3988 | M28: 4349 | N28: 4126 | O28: 3717 | P28: 4227 | Q28: 6103 | R28: 7764 | S28: 14575 | T28: 12565 | U28: 13095 | V28: 13197 | W28: 12924 | X28: 12683 | Y28: 12322 | Z28: 11772 | AA28: =SUM(C28:Z28) -> 206888 | AB28: 4 | AC28: =+AA28*AB28 -> 827552
B29: Domingo | C29: 10606 | D29: 10080 | E29: 9675 | F29: 9336 | G29: 9141 | H29: 8707 | I29: 2359 | J29: 2616 | K29: 1014 | L29: 1009 | M29: 833 | N29: 728 | O29: 1213 | P29: 1843 | Q29: 3427 | R29: 5107 | S29: 12365 | T29: 11090 | U29: 12004 | V29: 12620 | W29: 12712 | X29: 12795 | Y29: 12499 | Z29: 11872 | AA29: =SUM(C29:Z29) -> 175651 | AB29: 4 | AC29: =+AA29*AB29 -> 702604
B30: Festivo | C30: 9142 | D30: 8637 | E30: 8288 | F30: 8008 | G30: 7903 | H30: 7604 | I30: 1400 | J30: 1931 | K30: 861 | L30: 986 | M30: 1310 | N30: 1230 | O30: 1388 | P30: 2067 | Q30: 3560 | R30: 5040 | S30: 11971 | T30: 10499 | U30: 11326 | V30: 12050 | W30: 12007 | X30: 11802 | Y30: 11206 | Z30: 10397 | AA30: =SUM(C30:Z30) -> 160613 | AB30: 2 | AC30: =+AA30*AB30 -> 321226
A31: 46935 | B31: Hábil | C31: 10126 | D31: 9562 | E31: 9149 | F31: 8830 | G31: 8712 | H31: 8693 | I31: 2631 | J31: 3886 | K31: 3467 | L31: 3642 | M31: 4097 | N31: 3825 | O31: 2919 | P31: 4697 | Q31: 7331 | R31: 8935 | S31: 15609 | T31: 12819 | U31: 12826 | V31: 13123 | W31: 13136 | X31: 12955 | Y31: 12340 | Z31: 11451 | AA31: =SUM(C31:Z31) -> 204761 | AB31: 19 | AC31: =+AA31*AB31 -> 3890459 | AD31: =+SUM(AC31:AC34) -> 5905820
B32: Sábado | C32: 9706 | D32: 9196 | E32: 8825 | F32: 8527 | G32: 8414 | H32: 8224 | I32: 2098 | J32: 3169 | K32: 2636 | L32: 2829 | M32: 3063 | N32: 2991 | O32: 2668 | P32: 3345 | Q32: 5148 | R32: 6540 | S32: 13271 | T32: 11416 | U32: 12042 | V32: 12402 | W32: 12146 | X32: 11933 | Y32: 11641 | Z32: 11133 | AA32: =SUM(C32:Z32) -> 183363 | AB32: 5 | AC32: =+AA32*AB32 -> 916815
B33: Domingo | C33: 10024 | D33: 9498 | E33: 9093 | F33: 8781 | G33: 8569 | H33: 8236 | I33: 1900 | J33: 1867 | K33: 452 | L33: 292 | M33: 265 | N33: 27 | O33: 561 | P33: 1168 | Q33: 2563 | R33: 4294 | S33: 11328 | T33: 10407 | U33: 11157 | V33: 11825 | W33: 11923 | X33: 11947 | Y33: 11562 | Z33: 10947 | AA33: =SUM(C33:Z33) -> 158686 | AB33: 5 | AC33: =+AA33*AB33 -> 793430
B34: Festivo | C34: 9105 | D34: 8579 | E34: 8187 | F34: 7933 | G34: 7806 | H34: 7573 | I34: 1320 | J34: 1696 | K34: 575 | L34: 559 | M34: 714 | N34: 531 | O34: 570 | P34: 1380 | Q34: 2939 | R34: 4548 | S34: 11528 | T34: 10201 | U34: 10915 | V34: 11677 | W34: 11665 | X34: 11489 | Y34: 10933 | Z34: 10135 | AA34: =SUM(C34:Z34) -> 152558 | AB34: 2 | AC34: =+AA34*AB34 -> 305116
A35: 46966 | B35: Hábil | C35: 10478 | D35: 9900 | E35: 9460 | F35: 9117 | G35: 8990 | H35: 8959 | I35: 2865 | J35: 4276 | K35: 3746 | L35: 4057 | M35: 4516 | N35: 4372 | O35: 3474 | P35: 5408 | Q35: 8143 | R35: 9718 | S35: 16461 | T35: 13164 | U35: 13261 | V35: 13406 | W35: 13467 | X35: 13326 | Y35: 12692 | Z35: 11817 | AA35: =SUM(C35:Z35) -> 215073 | AB35: 21 | AC35: =+AA35*AB35 -> 4516533 | AD35: =+SUM(AC35:AC38) -> 6338427
B36: Sábado | C36: 11102 | D36: 10505 | E36: 10012 | F36: 9637 | G36: 9429 | H36: 9165 | I36: 2999 | J36: 4344 | K36: 3783 | L36: 4106 | M36: 4264 | N36: 4374 | O36: 3804 | P36: 4588 | Q36: 6317 | R36: 7810 | S36: 14714 | T36: 12281 | U36: 12978 | V36: 13077 | W36: 12840 | X36: 12739 | Y36: 12482 | Z36: 11968 | AA36: =SUM(C36:Z36) -> 209318 | AB36: 4 | AC36: =+AA36*AB36 -> 837272
