Workbook
Name _Toc148954622: 'Banco de Preguntas'!#REF!
Name _Toc148954623: 'Banco de Preguntas'!#REF!
Name _Toc148954624: 'Banco de Preguntas'!#REF!
Name _Toc148954625: 'Banco de Preguntas'!#REF!
Name aaa: [1]Hoja9!$A$1,[1]Hoja9!$A$3,[1]Hoja9!$A$5,[1]Hoja9!$B$6,[1]Hoja9!$C$7
Name aaa: [1]Hoja9!$A$1,[1]Hoja9!$A$3,[1]Hoja9!$A$5,[1]Hoja9!$B$6,[1]Hoja9!$C$7
Name aaa: [1]Hoja9!$A$1,[1]Hoja9!$A$3,[1]Hoja9!$A$5,[1]Hoja9!$B$6,[1]Hoja9!$C$7
Name aaa: [1]Hoja9!$A$1,[1]Hoja9!$A$3,[1]Hoja9!$A$5,[1]Hoja9!$B$6,[1]Hoja9!$C$7
Name aaa: [1]Hoja9!$A$1,[1]Hoja9!$A$3,[1]Hoja9!$A$5,[1]Hoja9!$B$6,[1]Hoja9!$C$7
Name aaa: [1]Hoja9!$A$1,[1]Hoja9!$A$3,[1]Hoja9!$A$5,[1]Hoja9!$B$6,[1]Hoja9!$C$7
Name aaa: #REF!,#REF!,#REF!,#REF!,#REF!
Name AAAA: #REF!
Name Criterio_Extraer_Dem_Reg: #REF!
Name Criterio_Extraer_Dem_Reg: #REF!
Name Criterio_Extraer_Dem_Reg: #REF!
Name Criterio_Extraer_Dem_Reg: #REF!
Name Criterio_Extraer_Dem_Reg: #REF!
Name Criterio_Extraer_Dem_Reg: #REF!
Name Criterio_Extraer_Dem_Reg: #REF!
Name Criterio_Extraer_Dem_Reg: #REF!
Name Criterio_Extraer_Dem_Reg: #REF!
Name Cuadro: #REF!
Name Cuadro: #REF!
Name Cuadro: #REF!
Name Cuadro: #REF!
Name Cuadro: #REF!
Name Cuadro: #REF!
Name Cuadro: #REF!
Name Cuadro: #REF!
Name Cuadro: #REF!
Name eeee: #REF!
Name eeee: [2]Comparación!#REF!
Name eeee: [2]Comparación!#REF!
Name eeee: [2]Comparación!#REF!
Name eeee: #REF!
Name eeee: [2]Comparación!#REF!
Name eeee: [2]Comparación!#REF!
Name eeee: [2]Comparación!#REF!
Name eeee: #REF!
Name Meses: [3]Evaluación_Mensual!$S$2:$S$25
Name Meses: [3]Evaluación_Mensual!$S$2:$S$25
Name Meses: [3]Evaluación_Mensual!$S$2:$S$25
Name Meses: [3]Evaluación_Mensual!$S$2:$S$25
Name Meses: [3]Evaluación_Mensual!$S$2:$S$25
Name Meses: [3]Evaluación_Mensual!$S$2:$S$25
Name Meses: [4]Evaluación_Mensual!$S$2:$S$25
Name Meses: #REF!
Name Precio_Estación: #REF!
Name Precio_Estación: #REF!
Name Precio_Estación: #REF!
Name Precio_Estación: #REF!
Name Precio_Estación: #REF!
Name Precio_Estación: #REF!
Name Precio_Estación: #REF!
Name Precio_Estación: #REF!
Name Precio_Estación: #N/A
Name Precio_Estación: #REF!
Name Precio_Global: #REF!
Name Precio_Global: #REF!
Name Precio_Global: #REF!

Sheet Listas desplegables
A2: Tipo de agente: | B2: Tipo de oferta:
A3: Comercializador | B3: CURVA
A4: Generador | B4: CURVA SOLAR
B5: CURVA FNCER
B6: PLANA SOLAR
B7: MIXTA
B8: PLANA

Sheet Banco de Preguntas
A2: Consolidado banco de preguntas y respuestas agentes convocatorias ESSA
A3: N° Convocatoria
A4: Nombre remitente correo:
A5: Correo electrónico
A6: Teléfono de contacto:
A9: AGENTE | B9: N° pregunta | C9: PREGUNTA | D9: RESPUESTA

Sheet Factor garantia
A2: 12. TABLA Factores de Indexación IPP serie oferta interna
A4: Mes | B4: Factor | D4: Mes | E4: Factor | G4: Mes | H4: Factor
A5: 46023 | B5: =+'[6]IPC - IPP COL'!P144 -> 1.02 | D5: 47849 | E5: =+'[6]IPC - IPP COL'!P204 -> 1.17 | G5: 49675 | H5: =+'[6]IPC - IPP COL'!P264 -> 1.35
A6: 46054 | B6: =+'[6]IPC - IPP COL'!P145 -> 1.02 | D6: 47880 | E6: =+'[6]IPC - IPP COL'!P205 -> 1.17 | G6: 49706 | H6: =+'[6]IPC - IPP COL'!P265 -> 1.36
A7: 46082 | B7: =+'[6]IPC - IPP COL'!P146 -> 1.03 | D7: 47908 | E7: =+'[6]IPC - IPP COL'!P206 -> 1.17 | G7: 49735 | H7: =+'[6]IPC - IPP COL'!P266 -> 1.36
A8: 46113 | B8: =+'[6]IPC - IPP COL'!P147 -> 1.03 | D8: 47939 | E8: =+'[6]IPC - IPP COL'!P207 -> 1.17 | G8: 49766 | H8: =+'[6]IPC - IPP COL'!P267 -> 1.36
A9: 46143 | B9: =+'[6]IPC - IPP COL'!P148 -> 1.03 | D9: 47969 | E9: =+'[6]IPC - IPP COL'!P208 -> 1.18 | G9: 49796 | H9: =+'[6]IPC - IPP COL'!P268 -> 1.36
A10: 46174 | B10: =+'[6]IPC - IPP COL'!P149 -> 1.03 | D10: 48000 | E10: =+'[6]IPC - IPP COL'!P209 -> 1.18 | G10: 49827 | H10: =+'[6]IPC - IPP COL'!P269 -> 1.37
A11: 46204 | B11: =+'[6]IPC - IPP COL'!P150 -> 1.03 | D11: 48030 | E11: =+'[6]IPC - IPP COL'!P210 -> 1.18 | G11: 49857 | H11: =+'[6]IPC - IPP COL'!P270 -> 1.37
A12: 46235 | B12: =+'[6]IPC - IPP COL'!P151 -> 1.03 | D12: 48061 | E12: =+'[6]IPC - IPP COL'!P211 -> 1.18 | G12: 49888 | H12: =+'[6]IPC - IPP COL'!P271 -> 1.37
A13: 46266 | B13: =+'[6]IPC - IPP COL'!P152 -> 1.04 | D13: 48092 | E13: =+'[6]IPC - IPP COL'!P212 -> 1.18 | G13: 49919 | H13: =+'[6]IPC - IPP COL'!P272 -> 1.37
A14: 46296 | B14: =+'[6]IPC - IPP COL'!P153 -> 1.04 | D14: 48122 | E14: =+'[6]IPC - IPP COL'!P213 -> 1.19 | G14: 49949 | H14: =+'[6]IPC - IPP COL'!P273 -> 1.38
A15: 46327 | B15: =+'[6]IPC - IPP COL'!P154 -> 1.04 | D15: 48153 | E15: =+'[6]IPC - IPP COL'!P214 -> 1.2 | G15: 49980 | H15: =+'[6]IPC - IPP COL'!P274 -> 1.39
A16: 46357 | B16: =+'[6]IPC - IPP COL'!P155 -> 1.04 | D16: 48183 | E16: =+'[6]IPC - IPP COL'!P215 -> 1.2 | G16: 50010 | H16: =+'[6]IPC - IPP COL'!P275 -> 1.39
... A64: 47818 | B64: =+'[6]IPC - IPP COL'!P203 -> 1.16 | D64: 49644 | E64: =+'[6]IPC - IPP COL'!P263 -> 1.35 | G64: 51471 | H64: =+'[6]IPC - IPP COL'!P323 -> 1.56

Sheet Cantidades suministrar P1_2026
B2: ANEXO 10.1 CANTIDADES DE ENERGÍA REQUERIDA PRODUCTO 1
B3: AÑO 2026
B6: Oferta Básica, para la Solicitud Pública de Ofertas No. CP-ESSC2025-002, del 1 de enero de 2026 a 31 de diciembre de 2026.
B8: OFERENTE: | E8: Diligenciar
B9: Tipo de agente: | E9: Elegir de la lista desplegable
B10: Oferta No.: | E10: Diligenciar
B11: Tipo de oferta: | C11: CURVA | E11: Fijo
B12: % de su oferta con FNCER: | E12: Diligenciar
B14: Mes-año | C14: Energia Solicitada (kWh) | D14: % a ofertar | E14: Energia Oferta kWh | F14: Precio $ / kWh
A16: 31 | B16: 46023 | C16: =+'Cantidades 1_(2026)'!AE11 -> 6885008.4 | E16: =+C16*D16 -> 0
A17: 28 | B17: 46054 | C17: =+'Cantidades 1_(2026)'!AE12 -> 6445364.2 | E17: =+C17*D17 -> 0
A18: 31 | B18: 46082 | C18: =+'Cantidades 1_(2026)'!AE13 -> 7112245.3 | E18: =+C18*D18 -> 0
A19: 30 | B19: 46113 | C19: =+'Cantidades 1_(2026)'!AE14 -> 6718171.7 | E19: =+C19*D19 -> 0
A20: 31 | B20: 46143 | C20: =+'Cantidades 1_(2026)'!AE15 -> 6807710.8 | E20: =+C20*D20 -> 0
A21: 30 | B21: 46174 | C21: =+'Cantidades 1_(2026)'!AE16 -> 6344130.5 | E21: =+C21*D21 -> 0
A22: 31 | B22: 46204 | C22: =+'Cantidades 1_(2026)'!AE17 -> 6880357.4 | E22: =+C22*D22 -> 0
A23: 31 | B23: 46235 | C23: =+'Cantidades 1_(2026)'!AE18 -> 6818865.1 | E23: =+C23*D23 -> 0
A24: 30 | B24: 46266 | C24: =+'Cantidades 1_(2026)'!AE19 -> 6736312.6 | E24: =+C24*D24 -> 0
A25: 31 | B25: 46296 | C25: =+'Cantidades 1_(2026)'!AE20 -> 6712169.9 | E25: =+C25*D25 -> 0
A26: 30 | B26: 46327 | C26: =+'Cantidades 1_(2026)'!AE21 -> 6655295.1 | E26: =+C26*D26 -> 0
A27: 31 | B27: 46357 | C27: =+'Cantidades 1_(2026)'!AE22 -> 6831338.7 | E27: =+C27*D27 -> 0
A28: =SUM(A16:A27) -> 365 | B28: TOTAL | C28: =SUM(C16:C27) -> 80946970 | D28: =+E28/C28 -> 0 | E28: =SUM(E16:E27) -> 0
B31: Notas:
B32: (1) La Energía Ofertada se distribuye en forma horaria de acuerdo con la curva de carga presentada en la tabla 9.1. TABLAS CANTIDADES DE ENERGÍA REQUERIDA PRODUCTO 1 AÑO 2026 del pliego de condiciones.
B34: (2) Tipo de Contrato: pague lo contratado.
B35: (3) Precio ofertado en $kWh, en pesos de Abril 2025 (IPP Provisional)
B36: (4) El precio debe ser el mismo para todos los meses del año, con dos cifras decimales
B37: (5) El % igual o diferente para cada uno de los meses del año, con dos cifras decimales.
B38: (6) El precio incluye todos los cargos, impuestos y contribuciones que según la reglamentación vigente en la fecha de apertura de propuestas son responsabilidad de EL OFERENTE.
B39: (7) No serán tenidas en cuenta ofertas con condiciones y/o modificaciones adicionales a los Pliegos definitivos.
B40: (8) La oferta se acoge a todas las condiciones del pliego CP-ESSC2025-002.
B41: (9) Tipo de oferta curva
B42: EL OFERENTE deberá tener en cuenta lo siguiente al completar cada una de las Tablas de las cantidades a ofertar: Debe definir el porcentaje ofertado, hasta máximo el 100% de lo solicitado; EL CONTRATANTE aceptará la oferta de acuerdo a la metodología de evaluación hasta el máximo ofertado.
B48: FIRMA OFERENTE E.S.P.

Sheet Cantidades suministrar P2_2027
B2: ANEXO 10.2 CANTIDADES DE ENERGÍA REQUERIDA PRODUCTO 2
B3: AÑO 2027
B6: Oferta Básica, para la Solicitud Pública de Ofertas No. CP-ESSC2025-002, del 1 de enero de 2027 a 31 de diciembre de 2027.
B8: OFERENTE: | E8: Diligenciar
B9: Tipo de agente: | E9: Elegir de la lista desplegable
B10: Oferta No.: | E10: Diligenciar
B11: Tipo de oferta: | C11: CURVA | E11: Fijo
B12: % de su oferta con FNCER: | E12: Diligenciar
B14: Mes-año | C14: Energia Solicitada (kWh) | D14: % a ofertar | E14: Energia Oferta kWh | F14: Precio $ / kWh
A16: 31 | B16: 46388 | C16: =+'Cantidades 2_(2027)'!AE11 -> 30208541 | E16: =+C16*D16 -> 0
A17: 28 | B17: 46419 | C17: =+'Cantidades 2_(2027)'!AE12 -> 24071174 | E17: =+C17*D17 -> 0
A18: 31 | B18: 46447 | C18: =+'Cantidades 2_(2027)'!AE13 -> 32942148 | E18: =+C18*D18 -> 0
A19: 30 | B19: 46478 | C19: =+'Cantidades 2_(2027)'!AE14 -> 27847437 | E19: =+C19*D19 -> 0
A20: 31 | B20: 46508 | C20: =+'Cantidades 2_(2027)'!AE15 -> 25146241 | E20: =+C20*D20 -> 0
A21: 30 | B21: 46539 | C21: =+'Cantidades 2_(2027)'!AE16 -> 6652499.5 | E21: =+C21*D21 -> 0
A22: 31 | B22: 46569 | C22: =+'Cantidades 2_(2027)'!AE17 -> 7378392.1 | E22: =+C22*D22 -> 0
A23: 31 | B23: 46600 | C23: =+'Cantidades 2_(2027)'!AE18 -> 9177870.5 | E23: =+C23*D23 -> 0
A24: 30 | B24: 46631 | C24: =+'Cantidades 2_(2027)'!AE19 -> 10029118 | E24: =+C24*D24 -> 0
A25: 31 | B25: 46661 | C25: =+'Cantidades 2_(2027)'!AE20 -> 11917265 | E25: =+C25*D25 -> 0
A26: 30 | B26: 46692 | C26: =+'Cantidades 2_(2027)'!AE21 -> 23033067 | E26: =+C26*D26 -> 0
A27: 31 | B27: 46722 | C27: =+'Cantidades 2_(2027)'!AE22 -> 18451290 | E27: =+C27*D27 -> 0
A28: =SUM(A16:A27) -> 365 | B28: TOTAL | C28: =SUM(C16:C27) -> 2.2685504e+08 | D28: =+E28/C28 -> 0 | E28: =SUM(E16:E27) -> 0
B31: Notas:
B32: (1) La Energía Ofertada se distribuye en forma horaria de acuerdo con la curva de carga presentada en la tabla 9.2. TABLAS CANTIDADES DE ENERGÍA REQUERIDA PRODUCTO 2 AÑO 2027 del pliego de condiciones.
B34: (2) Tipo de Contrato: pague lo contratado.
B35: (3) Precio ofertado en $kWh, en pesos de Abril 2025 (IPP Provisional)
B36: (4) El precio debe ser el mismo para todos los meses del año, con dos cifras decimales
B37: (5) El % igual o diferente para cada uno de los meses del año, con dos cifras decimales.
B38: (6) El precio incluye todos los cargos, impuestos y contribuciones que según la reglamentación vigente en la fecha de apertura de propuestas son responsabilidad de EL OFERENTE.
B39: (7) No serán tenidas en cuenta ofertas con condiciones y/o modificaciones adicionales a los Pliegos definitivos.
B40: (8) La oferta se acoge a todas las condiciones del pliego CP-ESSC2025-002.
B41: (9) Tipo de oferta curva
B42: EL OFERENTE deberá tener en cuenta lo siguiente al completar cada una de las Tablas de las cantidades a ofertar: Debe definir el porcentaje ofertado, hasta máximo el 100% de lo solicitado; EL CONTRATANTE aceptará la oferta de acuerdo a la metodología de evaluación hasta el máximo ofertado.
B48: FIRMA OFERENTE E.S.P.

Sheet Cantidades suministrar P3_2028
B2: ANEXO 10.3 CANTIDADES DE ENERGÍA REQUERIDA PRODUCTO 3
B3: AÑO 2028
B6: Oferta Básica, para la Solicitud Pública de Ofertas No. CP-ESSC2025-002, del 1 de enero de 2028 a 31 de diciembre de 2028.
B8: OFERENTE: | E8: Diligenciar
B9: Tipo de agente: | E9: Elegir de la lista desplegable
B10: Oferta No.: | E10: Diligenciar
B11: Tipo de oferta: | C11: CURVA | E11: Fijo
B12: % de su oferta con FNCER: | E12: Diligenciar
B14: Mes-año | C14: Energia Solicitada (kWh) | D14: % a ofertar | E14: Energia Oferta kWh | F14: Precio $ / kWh
A16: 31 | B16: 46753 | C16: =+'Cantidades P3_(2028)'!AE11 -> 11889624 | E16: =+C16*$D$16 -> 0
A17: 28 | B17: 46784 | C17: =+'Cantidades P3_(2028)'!AE12 -> 11132864 | E17: =+C17*$D$16 -> 0
A18: 31 | B18: 46813 | C18: =+'Cantidades P3_(2028)'!AE13 -> 12232068 | E18: =+C18*$D$16 -> 0
A19: 30 | B19: 46844 | C19: =+'Cantidades P3_(2028)'!AE14 -> 11558910 | E19: =+C19*$D$16 -> 0
A20: 31 | B20: 46874 | C20: =+'Cantidades P3_(2028)'!AE15 -> 11676151 | E20: =+C20*$D$16 -> 0
A21: 30 | B21: 46905 | C21: =+'Cantidades P3_(2028)'!AE16 -> 10874815 | E21: =+C21*$D$16 -> 0
A22: 31 | B22: 46935 | C22: =+'Cantidades P3_(2028)'!AE17 -> 11743794 | E22: =+C22*$D$16 -> 0
A23: 31 | B23: 46966 | C23: =+'Cantidades P3_(2028)'!AE18 -> 11620126 | E23: =+C23*$D$16 -> 0
A24: 30 | B24: 46997 | C24: =+'Cantidades P3_(2028)'!AE19 -> 11452943 | E24: =+C24*$D$16 -> 0
A25: 31 | B25: 47027 | C25: =+'Cantidades P3_(2028)'!AE20 -> 11390912 | E25: =+C25*$D$16 -> 0
A26: 30 | B26: 47058 | C26: =+'Cantidades P3_(2028)'!AE21 -> 11265844 | E26: =+C26*$D$16 -> 0
A27: 31 | B27: 47088 | C27: =+'Cantidades P3_(2028)'!AE22 -> 11538543 | E27: =+C27*$D$16 -> 0
A28: =SUM(A16:A27) -> 365 | B28: TOTAL | C28: =SUM(C16:C27) -> 1.3837659e+08 | D28: =+E28/C28 -> 0 | E28: =SUM(E16:E27) -> 0
B31: Notas:
B32: (1) La Energía Ofertada se distribuye en forma horaria de acuerdo con la curva de carga presentada en la tabla 9.3. TABLAS CANTIDADES DE ENERGÍA REQUERIDA PRODUCTO 3 AÑO 2028 del pliego de condiciones.
B34: (2) Tipo de Contrato: pague lo contratado.
B35: (3) Precio ofertado en $kWh, en pesos de Abril 2025 (IPP Provisional)
B36: (4) El precio debe ser el mismo para todos los meses del año, con dos cifras decimales
B37: (5) El % igual o diferente para cada uno de los meses del año, con dos cifras decimales.
B38: (6) El precio incluye todos los cargos, impuestos y contribuciones que según la reglamentación vigente en la fecha de apertura de propuestas son responsabilidad de EL OFERENTE.
B39: (7) No serán tenidas en cuenta ofertas con condiciones y/o modificaciones adicionales a los Pliegos definitivos.
B40: (8) La oferta se acoge a todas las condiciones del pliego CP-ESSC2025-002.
B41: (9) Tipo de oferta curva
B42: EL OFERENTE deberá tener en cuenta lo siguiente al completar cada una de las Tablas de las cantidades a ofertar: Debe definir el porcentaje ofertado, hasta máximo el 100% de lo solicitado; EL CONTRATANTE aceptará la oferta de acuerdo a la metodología de evaluación hasta el máximo ofertado.
B48: FIRMA OFERENTE E.S.P.

Sheet Cant suministrar P4_29-40
B2: ANEXO 10.4 CANTIDADES DE ENERGÍA REQUERIDA PRODUCTO 4
B3: AÑO 2029 al 2040
B6: Oferta Básica, para la Solicitud Pública de Ofertas No. CP-ESSC2025-002, del 1 de enero de 2029 a 31 de diciembre de 2040.
B7: OFERENTE: | K7: Diligenciar
B8: Tipo de agente: | K8: Elegir de la lista desplegable
B9: Oferta No: | K9: Diligenciar
B10: Tipo de oferta: | C10: CURVA | K10: Elegir de la lista desplegable
B11: % de su oferta con FNCER: | K11: Diligenciar
B13: Mes-año | C13: Energia Solicitada (kWh) | D13: % a ofertar | E13: Energia Oferta kWh | F13: Precio $ / kWh | H13: Mes-año | I13: Energia Solicitada (kWh) | J13: % a ofertar | K13: Energia Oferta kWh | L13: Precio $ / kWh
A15: 31 | B15: 47119 | C15: =+'Cantidades P4_(2029-2040)'!AC11 -> 9459407.6 | E15: =+C15*$D$15 -> 0 | H15: 49310 | I15: =+'Cantidades P4_(2029-2040)'!$AC$305 -> 24703007 | J15: =+$D$15 -> 0 | K15: =+I15*$J$15 -> 0
A16: 29 | B16: 47150 | C16: =+'Cantidades P4_(2029-2040)'!AC15 -> 8868777.4 | E16: =+C16*$D$15 -> 0 | H16: 49341 | I16: =+'Cantidades P4_(2029-2040)'!$AC$309 -> 23290602 | K16: =+I16*$J$15 -> 0
A17: 31 | B17: 47178 | C17: =+'Cantidades P4_(2029-2040)'!AC19 -> 9732794.5 | E17: =+C17*$D$15 -> 0 | H17: 49369 | I17: =+'Cantidades P4_(2029-2040)'!$AC$313 -> 25376135 | K17: =+I17*$J$15 -> 0
A18: 30 | B18: 47209 | C18: =+'Cantidades P4_(2029-2040)'!AC23 -> 9210470.7 | E18: =+C18*$D$15 -> 0 | H18: 49400 | I18: =+'Cantidades P4_(2029-2040)'!$AC$317 -> 24167110 | K18: =+I18*$J$15 -> 0
A19: 31 | B19: 47239 | C19: =+'Cantidades P4_(2029-2040)'!AC27 -> 9299682.1 | E19: =+C19*$D$15 -> 0 | H19: 49430 | I19: =+'Cantidades P4_(2029-2040)'!$AC$321 -> 24316489 | K19: =+I19*$J$15 -> 0
A20: 30 | B20: 47270 | C20: =+'Cantidades P4_(2029-2040)'!AC31 -> 8672481.3 | E20: =+C20*$D$15 -> 0 | H20: 49461 | I20: =+'Cantidades P4_(2029-2040)'!$AC$325 -> 22792959 | K20: =+I20*$J$15 -> 0
A21: 31 | B21: 47300 | C21: =+'Cantidades P4_(2029-2040)'!AC35 -> 9351870.8 | E21: =+C21*$D$15 -> 0 | H21: 49491 | I21: =+'Cantidades P4_(2029-2040)'!$AC$329 -> 24375379 | K21: =+I21*$J$15 -> 0
A22: 31 | B22: 47331 | C22: =+'Cantidades P4_(2029-2040)'!AC39 -> 9257080.3 | E22: =+C22*$D$15 -> 0 | H22: 49522 | I22: =+'Cantidades P4_(2029-2040)'!$AC$333 -> 24150029 | K22: =+I22*$J$15 -> 0
A23: 30 | B23: 47362 | C23: =+'Cantidades P4_(2029-2040)'!AC43 -> 9125052.7 | E23: =+C23*$D$15 -> 0 | H23: 49553 | I23: =+'Cantidades P4_(2029-2040)'!$AC$337 -> 23790959 | K23: =+I23*$J$15 -> 0
A24: 31 | B24: 47392 | C24: =+'Cantidades P4_(2029-2040)'!AC47 -> 9078218.3 | E24: =+C24*$D$15 -> 0 | H24: 49583 | I24: =+'Cantidades P4_(2029-2040)'!$AC$341 -> 23675864 | K24: =+I24*$J$15 -> 0
A25: 30 | B25: 47423 | C25: =+'Cantidades P4_(2029-2040)'!AC51 -> 8978859.9 | E25: =+C25*$D$15 -> 0 | H25: 49614 | I25: =+'Cantidades P4_(2029-2040)'!$AC$345 -> 23390514 | K25: =+I25*$J$15 -> 0
A26: 31 | B26: 47453 | C26: =+'Cantidades P4_(2029-2040)'!AC55 -> 9194008.1 | E26: =+C26*$D$15 -> 0 | H26: 49644 | I26: =+'Cantidades P4_(2029-2040)'!$AC$349 -> 23900139 | K26: =+I26*$J$15 -> 0
A27: 31 | B27: 47484 | C27: =+'Cantidades P4_(2029-2040)'!$AC$60 -> 19148897 | D27: =+$D$15 -> 0 | E27: =+C27*$D$27 -> 0 | H27: 49675 | I27: =+'Cantidades P4_(2029-2040)'!$AC$354 -> 29074292 | J27: =+$D$15 -> 0 | K27: =+I27*$J$27 -> 0
A28: 28 | B28: 47515 | C28: =+'Cantidades P4_(2029-2040)'!$AC$64 -> 17975619 | E28: =+C28*$D$27 -> 0 | H28: 49706 | I28: =+'Cantidades P4_(2029-2040)'!$AC$358 -> 27440139 | K28: =+I28*$J$27 -> 0
A29: 31 | B29: 47543 | C29: =+'Cantidades P4_(2029-2040)'!$AC$68 -> 19704151 | E29: =+C29*$D$27 -> 0 | H29: 49735 | I29: =+'Cantidades P4_(2029-2040)'!$AC$362 -> 29869754 | K29: =+I29*$J$27 -> 0
A30: 30 | B30: 47574 | C30: =+'Cantidades P4_(2029-2040)'!$AC$72 -> 18672645 | E30: =+C30*$D$27 -> 0 | H30: 49766 | I30: =+'Cantidades P4_(2029-2040)'!$AC$366 -> 28479297 | K30: =+I30*$J$27 -> 0
A31: 31 | B31: 47604 | C31: =+'Cantidades P4_(2029-2040)'!$AC$76 -> 18845305 | E31: =+C31*$D$27 -> 0 | H31: 49796 | I31: =+'Cantidades P4_(2029-2040)'!$AC$370 -> 28645769 | K31: =+I31*$J$27 -> 0
A32: 30 | B32: 47635 | C32: =+'Cantidades P4_(2029-2040)'!$AC$80 -> 17595837 | E32: =+C32*$D$27 -> 0 | H32: 49827 | I32: =+'Cantidades P4_(2029-2040)'!$AC$374 -> 26878159 | K32: =+I32*$J$27 -> 0
A33: 31 | B33: 47665 | C33: =+'Cantidades P4_(2029-2040)'!$AC$84 -> 18947772 | E33: =+C33*$D$27 -> 0 | H33: 49857 | I33: =+'Cantidades P4_(2029-2040)'!$AC$378 -> 28712117 | K33: =+I33*$J$27 -> 0
A34: 31 | B34: 47696 | C34: =+'Cantidades P4_(2029-2040)'!$AC$88 -> 18762913 | E34: =+C34*$D$27 -> 0 | H34: 49888 | I34: =+'Cantidades P4_(2029-2040)'!$AC$382 -> 28456085 | K34: =+I34*$J$27 -> 0
A35: 30 | B35: 47727 | C35: =+'Cantidades P4_(2029-2040)'!$AC$92 -> 18497564 | E35: =+C35*$D$27 -> 0 | H35: 49919 | I35: =+'Cantidades P4_(2029-2040)'!$AC$386 -> 28036347 | K35: =+I35*$J$27 -> 0
A36: 31 | B36: 47757 | C36: =+'Cantidades P4_(2029-2040)'!$AC$96 -> 18407672 | E36: =+C36*$D$27 -> 0 | H36: 49949 | I36: =+'Cantidades P4_(2029-2040)'!$AC$390 -> 27907462 | K36: =+I36*$J$27 -> 0
A37: 30 | B37: 47788 | C37: =+'Cantidades P4_(2029-2040)'!$AC$100 -> 18206824 | E37: =+C37*$D$27 -> 0 | H37: 49980 | I37: =+'Cantidades P4_(2029-2040)'!$AC$394 -> 27572467 | K37: =+I37*$J$27 -> 0
A38: 31 | B38: 47818 | C38: =+'Cantidades P4_(2029-2040)'!$AC$104 -> 18638821 | E38: =+C38*$D$27 -> 0 | H38: 50010 | I38: =+'Cantidades P4_(2029-2040)'!$AC$398 -> 28168380 | K38: =+I38*$J$27 -> 0
A39: 31 | B39: 47849 | C39: =+'Cantidades P4_(2029-2040)'!$AC$109 -> 21503344 | D39: =+$D$15 -> 0 | E39: =+C39*$D$39 -> 0 | H39: 50041 | I39: =+'Cantidades P4_(2029-2040)'!$AC$403 -> 29779530 | J39: =+$D$15 -> 0 | K39: =+I39*$J$39 -> 0
A40: 28 | B40: 47880 | C40: =+'Cantidades P4_(2029-2040)'!$AC$113 -> 20204289 | E40: =+C40*$D$39 -> 0 | H40: 50072 | I40: =+'Cantidades P4_(2029-2040)'!$AC$407 -> 28133740 | K40: =+I40*$J$39 -> 0
A41: 31 | B41: 47908 | C41: =+'Cantidades P4_(2029-2040)'!$AC$117 -> 22118161 | E41: =+C41*$D$39 -> 0 | H41: 50100 | I41: =+'Cantidades P4_(2029-2040)'!$AC$411 -> 30597487 | K41: =+I41*$J$39 -> 0
A42: 30 | B42: 47939 | C42: =+'Cantidades P4_(2029-2040)'!$AC$121 -> 20982126 | E42: =+C42*$D$39 -> 0 | H42: 50131 | I42: =+'Cantidades P4_(2029-2040)'!$AC$415 -> 29205604 | K42: =+I42*$J$39 -> 0
A43: 31 | B43: 47969 | C43: =+'Cantidades P4_(2029-2040)'!$AC$125 -> 21162017 | E43: =+C43*$D$39 -> 0 | H43: 50161 | I43: =+'Cantidades P4_(2029-2040)'!$AC$419 -> 29366833 | K43: =+I43*$J$39 -> 0
A44: 30 | B44: 48000 | C44: =+'Cantidades P4_(2029-2040)'!$AC$129 -> 19775011 | E44: =+C44*$D$39 -> 0 | H44: 50192 | I44: =+'Cantidades P4_(2029-2040)'!$AC$423 -> 27581697 | K44: =+I44*$J$39 -> 0
A45: 31 | B45: 48030 | C45: =+'Cantidades P4_(2029-2040)'!$AC$133 -> 21262753 | E45: =+C45*$D$39 -> 0 | H45: 50222 | I45: =+'Cantidades P4_(2029-2040)'!$AC$427 -> 29431846 | K45: =+I45*$J$39 -> 0
...

Sheet Hoja9
B2: Mes | C2: AÑO 2026 Energia Solicitada (kWh) | D2: AÑO 2027 Energia Solicitada (kWh) | E2: AÑO 2028 Energia Solicitada (kWh) | F2: AÑO 2029 Energia Solicitada (kWh) | G2: AÑO 2030 Energia Solicitada (kWh) | H2: AÑO 2031 Energia Solicitada (kWh) | I2: AÑO 2032 Energia Solicitada (kWh) | J2: AÑO 2033 Energia Solicitada (kWh) | K2: AÑO 2034 Energia Solicitada (kWh) | L2: AÑO 2035 Energia Solicitada (kWh) | M2: TOTAL PRODUCTO 2 Energia Solicitada (kWh)
B3: CURVA | C3: La misma curva de la tabla 9.1.2 del producto 1 | D3: La misma curva de la tabla 9.1.3 del producto 1 | E3: La misma curva de la tabla 9.1.4 del producto 1 | F3: La misma curva de la tabla 9.1.5 del producto 1 | G3: La misma curva de la tabla 9.1.6 del producto 1 | H3: La misma curva de la tabla 9.1.7 del producto 1 | I3: La misma curva de la tabla 9.1.8 del producto 1 | J3: La misma curva de la tabla 9.1.9 del producto 1 | K3: La misma curva de la tabla 9.1.10 del producto 1 | L3: La misma curva de la tabla 9.1.11 del producto 1
B4: ene | C4: =+#REF! -> #REF! | D4: =+#REF! -> #REF! | E4: =+#REF! -> #REF! | F4: =+#REF! -> #REF! | G4: =+#REF! -> #REF! | H4: =+#REF! -> #REF! | I4: =+#REF! -> #REF! | J4: =+#REF! -> #REF! | ... L4: =+#REF! -> #REF! | M4: =SUM(C4:L4) -> #REF!
B5: feb | C5: =+#REF! -> #REF! | D5: =+#REF! -> #REF! | E5: =+#REF! -> #REF! | F5: =+#REF! -> #REF! | G5: =+#REF! -> #REF! | H5: =+#REF! -> #REF! | I5: =+#REF! -> #REF! | J5: =+#REF! -> #REF! | ... L5: =+#REF! -> #REF! | M5: =SUM(C5:L5) -> #REF!
B6: mar | C6: =+#REF! -> #REF! | D6: =+#REF! -> #REF! | E6: =+#REF! -> #REF! | F6: =+#REF! -> #REF! | G6: =+#REF! -> #REF! | H6: =+#REF! -> #REF! | I6: =+#REF! -> #REF! | J6: =+#REF! -> #REF! | ... L6: =+#REF! -> #REF! | M6: =SUM(C6:L6) -> #REF!
B7: abr | C7: =+#REF! -> #REF! | D7: =+#REF! -> #REF! | E7: =+#REF! -> #REF! | F7: =+#REF! -> #REF! | G7: =+#REF! -> #REF! | H7: =+#REF! -> #REF! | I7: =+#REF! -> #REF! | J7: =+#REF! -> #REF! | ... L7: =+#REF! -> #REF! | M7: =SUM(C7:L7) -> #REF!
B8: may | C8: =+#REF! -> #REF! | D8: =+#REF! -> #REF! | E8: =+#REF! -> #REF! | F8: =+#REF! -> #REF! | G8: =+#REF! -> #REF! | H8: =+#REF! -> #REF! | I8: =+#REF! -> #REF! | J8: =+#REF! -> #REF! | ... L8: =+#REF! -> #REF! | M8: =SUM(C8:L8) -> #REF!
B9: jun | C9: =+#REF! -> #REF! | D9: =+#REF! -> #REF! | E9: =+#REF! -> #REF! | F9: =+#REF! -> #REF! | G9: =+#REF! -> #REF! | H9: =+#REF! -> #REF! | I9: =+#REF! -> #REF! | J9: =+#REF! -> #REF! | ... L9: =+#REF! -> #REF! | M9: =SUM(C9:L9) -> #REF!
B10: jul | C10: =+#REF! -> #REF! | D10: =+#REF! -> #REF! | E10: =+#REF! -> #REF! | F10: =+#REF! -> #REF! | G10: =+#REF! -> #REF! | H10: =+#REF! -> #REF! | I10: =+#REF! -> #REF! | J10: =+#REF! -> #REF! | ... L10: =+#REF! -> #REF! | M10: =SUM(C10:L10) -> #REF!
B11: ago | C11: =+#REF! -> #REF! | D11: =+#REF! -> #REF! | E11: =+#REF! -> #REF! | F11: =+#REF! -> #REF! | G11: =+#REF! -> #REF! | H11: =+#REF! -> #REF! | I11: =+#REF! -> #REF! | J11: =+#REF! -> #REF! | ... L11: =+#REF! -> #REF! | M11: =SUM(C11:L11) -> #REF!
B12: sep | C12: =+#REF! -> #REF! | D12: =+#REF! -> #REF! | E12: =+#REF! -> #REF! | F12: =+#REF! -> #REF! | G12: =+#REF! -> #REF! | H12: =+#REF! -> #REF! | I12: =+#REF! -> #REF! | J12: =+#REF! -> #REF! | ... L12: =+#REF! -> #REF! | M12: =SUM(C12:L12) -> #REF!
B13: oct | C13: =+#REF! -> #REF! | D13: =+#REF! -> #REF! | E13: =+#REF! -> #REF! | F13: =+#REF! -> #REF! | G13: =+#REF! -> #REF! | H13: =+#REF! -> #REF! | I13: =+#REF! -> #REF! | J13: =+#REF! -> #REF! | ... L13: =+#REF! -> #REF! | M13: =SUM(C13:L13) -> #REF!
B14: nov | C14: =+#REF! -> #REF! | D14: =+#REF! -> #REF! | E14: =+#REF! -> #REF! | F14: =+#REF! -> #REF! | G14: =+#REF! -> #REF! | H14: =+#REF! -> #REF! | I14: =+#REF! -> #REF! | J14: =+#REF! -> #REF! | ... L14: =+#REF! -> #REF! | M14: =SUM(C14:L14) -> #REF!
B15: dic | C15: =+#REF! -> #REF! | D15: =+#REF! -> #REF! | E15: =+#REF! -> #REF! | F15: =+#REF! -> #REF! | G15: =+#REF! -> #REF! | H15: =+#REF! -> #REF! | I15: =+#REF! -> #REF! | J15: =+#REF! -> #REF! | ... L15: =+#REF! -> #REF! | M15: =SUM(C15:L15) -> #REF!
B16: TOTAL | C16: =SUM(C4:C15) -> #REF! | D16: =SUM(D4:D15) -> #REF! | E16: =SUM(E4:E15) -> #REF! | F16: =SUM(F4:F15) -> #REF! | G16: =SUM(G4:G15) -> #REF! | H16: =SUM(H4:H15) -> #REF! | I16: =SUM(I4:I15) -> #REF! | J16: =SUM(J4:J15) -> #REF! | ... M16: =SUM(M4:M15) -> #REF!
M17: =+M16-#REF! -> #REF!

Sheet Hoja9 (2)
B2: Mes | C2: AÑO 2027 Energia Solicitada (kWh) | D2: AÑO 2028 Energia Solicitada (kWh) | E2: AÑO 2029 Energia Solicitada (kWh) | F2: AÑO 2030 Energia Solicitada (kWh) | G2: AÑO 2031 Energia Solicitada (kWh) | H2: AÑO 2032 Energia Solicitada (kWh) | I2: AÑO 2033 Energia Solicitada (kWh) | J2: AÑO 2034 Energia Solicitada (kWh) | K2: AÑO 2035 Energia Solicitada (kWh) | L2: AÑO 2036 Energia Solicitada (kWh) | M2: TOTAL PRODUCTO 3 Energia Solicitada (kWh)
B3: CURVA | C3: La misma curva de la tabla 9.1.3 del producto 1 | D3: La misma curva de la tabla 9.1.4 del producto 1 | E3: La misma curva de la tabla 9.1.5 del producto 1 | F3: La misma curva de la tabla 9.1.6 del producto 1 | G3: La misma curva de la tabla 9.1.7 del producto 1 | H3: La misma curva de la tabla 9.1.8 del producto 1 | I3: La misma curva de la tabla 9.1.9 del producto 1 | J3: La misma curva de la tabla 9.1.10 del producto 1 | K3: La misma curva de la tabla 9.1.11 del producto 1 | L3: La misma curva de la tabla 9.1.12 del producto 1
B4: ene | C4: =+#REF! -> #REF! | D4: =+#REF! -> #REF! | E4: =+#REF! -> #REF! | F4: =+#REF! -> #REF! | G4: =+#REF! -> #REF! | H4: =+#REF! -> #REF! | I4: =+#REF! -> #REF! | J4: =+#REF! -> #REF! | ... L4: =+#REF! -> #REF! | M4: =SUM(C4:L4) -> #REF!
B5: feb | C5: =+#REF! -> #REF! | D5: =+#REF! -> #REF! | E5: =+#REF! -> #REF! | F5: =+#REF! -> #REF! | G5: =+#REF! -> #REF! | H5: =+#REF! -> #REF! | I5: =+#REF! -> #REF! | J5: =+#REF! -> #REF! | ... L5: =+#REF! -> #REF! | M5: =SUM(C5:L5) -> #REF!
B6: mar | C6: =+#REF! -> #REF! | D6: =+#REF! -> #REF! | E6: =+#REF! -> #REF! | F6: =+#REF! -> #REF! | G6: =+#REF! -> #REF! | H6: =+#REF! -> #REF! | I6: =+#REF! -> #REF! | J6: =+#REF! -> #REF! | ... L6: =+#REF! -> #REF! | M6: =SUM(C6:L6) -> #REF!
B7: abr | C7: =+#REF! -> #REF! | D7: =+#REF! -> #REF! | E7: =+#REF! -> #REF! | F7: =+#REF! -> #REF! | G7: =+#REF! -> #REF! | H7: =+#REF! -> #REF! | I7: =+#REF! -> #REF! | J7: =+#REF! -> #REF! | ... L7: =+#REF! -> #REF! | M7: =SUM(C7:L7) -> #REF!
B8: may | C8: =+#REF! -> #REF! | D8: =+#REF! -> #REF! | E8: =+#REF! -> #REF! | F8: =+#REF! -> #REF! | G8: =+#REF! -> #REF! | H8: =+#REF! -> #REF! | I8: =+#REF! -> #REF! | J8: =+#REF! -> #REF! | ... L8: =+#REF! -> #REF! | M8: =SUM(C8:L8) -> #REF!
B9: jun | C9: =+#REF! -> #REF! | D9: =+#REF! -> #REF! | E9: =+#REF! -> #REF! | F9: =+#REF! -> #REF! | G9: =+#REF! -> #REF! | H9: =+#REF! -> #REF! | I9: =+#REF! -> #REF! | J9: =+#REF! -> #REF! | ... L9: =+#REF! -> #REF! | M9: =SUM(C9:L9) -> #REF!
B10: jul | C10: =+#REF! -> #REF! | D10: =+#REF! -> #REF! | E10: =+#REF! -> #REF! | F10: =+#REF! -> #REF! | G10: =+#REF! -> #REF! | H10: =+#REF! -> #REF! | I10: =+#REF! -> #REF! | J10: =+#REF! -> #REF! | ... L10: =+#REF! -> #REF! | M10: =SUM(C10:L10) -> #REF!
B11: ago | C11: =+#REF! -> #REF! | D11: =+#REF! -> #REF! | E11: =+#REF! -> #REF! | F11: =+#REF! -> #REF! | G11: =+#REF! -> #REF! | H11: =+#REF! -> #REF! | I11: =+#REF! -> #REF! | J11: =+#REF! -> #REF! | ... L11: =+#REF! -> #REF! | M11: =SUM(C11:L11) -> #REF!
B12: sep | C12: =+#REF! -> #REF! | D12: =+#REF! -> #REF! | E12: =+#REF! -> #REF! | F12: =+#REF! -> #REF! | G12: =+#REF! -> #REF! | H12: =+#REF! -> #REF! | I12: =+#REF! -> #REF! | J12: =+#REF! -> #REF! | ... L12: =+#REF! -> #REF! | M12: =SUM(C12:L12) -> #REF!
B13: oct | C13: =+#REF! -> #REF! | D13: =+#REF! -> #REF! | E13: =+#REF! -> #REF! | F13: =+#REF! -> #REF! | G13: =+#REF! -> #REF! | H13: =+#REF! -> #REF! | I13: =+#REF! -> #REF! | J13: =+#REF! -> #REF! | ... L13: =+#REF! -> #REF! | M13: =SUM(C13:L13) -> #REF!
B14: nov | C14: =+#REF! -> #REF! | D14: =+#REF! -> #REF! | E14: =+#REF! -> #REF! | F14: =+#REF! -> #REF! | G14: =+#REF! -> #REF! | H14: =+#REF! -> #REF! | I14: =+#REF! -> #REF! | J14: =+#REF! -> #REF! | ... L14: =+#REF! -> #REF! | M14: =SUM(C14:L14) -> #REF!
B15: dic | C15: =+#REF! -> #REF! | D15: =+#REF! -> #REF! | E15: =+#REF! -> #REF! | F15: =+#REF! -> #REF! | G15: =+#REF! -> #REF! | H15: =+#REF! -> #REF! | I15: =+#REF! -> #REF! | J15: =+#REF! -> #REF! | ... L15: =+#REF! -> #REF! | M15: =SUM(C15:L15) -> #REF!
B16: TOTAL | C16: =SUM(C4:C15) -> #REF! | D16: =SUM(D4:D15) -> #REF! | E16: =SUM(E4:E15) -> #REF! | F16: =SUM(F4:F15) -> #REF! | G16: =SUM(G4:G15) -> #REF! | H16: =SUM(H4:H15) -> #REF! | I16: =SUM(I4:I15) -> #REF! | J16: =SUM(J4:J15) -> #REF! | ... M16: =SUM(M4:M15) -> #REF!
M17: =+M16-#REF! -> #REF!

Sheet Cantidades 1_(2026)
B4: 9.1 TABLAS CANTIDADES DE ENERGÍA REQUERIDA PRODUCTO 1 AÑO 2026 (kWh)
B5: ELETRIFICADORA DE SANTANDER S.A E.S.P.
B6: SOLICITUD PÚBLICA DE OFERTAS CP-ESSC2025-002
B7: PAGUELO CONTRATADO
B10: Mes | C10: Tipo Día | D10: Días | E10: H1 | F10: H2 | G10: H3 | H10: H4 | I10: H5 | J10: H6 | K10: H7 | L10: H8 | M10: H9 | N10: H10 | O10: H11 | P10: H12 | Q10: H13 | R10: H14 | S10: H15 | T10: H16 | U10: H17 | V10: H18 | W10: H19 | X10: H20 | Y10: H21 | Z10: H22 | AA10: H23 | AB10: H24 | AC10: TOTAL MES kWh | AE10: =+AC10 -> TOTAL MES kWh
B11: 46023 | C11: Ordinario | D11: =+'[7]2026'!D15 -> 20 | E11: =ROUND('[7]2026'!E15,2) -> 8287.17 | F11: =ROUND('[7]2026'!F15,2) -> 7838.02 | G11: =ROUND('[7]2026'!G15,2) -> 7513.37 | H11: =ROUND('[7]2026'!H15,2) -> 7286.39 | I11: =ROUND('[7]2026'!I15,2) -> 7232.59 | J11: =ROUND('[7]2026'!J15,2) -> 7409.15 | K11: =ROUND('[7]2026'!K15,2) -> 7353.98 | L11: =ROUND('[7]2026'!L15,2) -> 8223.58 | ... AB11: =ROUND('[7]2026'!AB15,2) -> 9009.71 | AC11: =SUM(E11:AB11)*D11+SUM(E12:AB12)*D12+SUM(E13:AB13)*D13+SUM(E14:AB14)*D14 -> 6885008.4 | AE11: =+AC11 -> 6885008.4
C12: Sábado | D12: =+'[7]2026'!D16 -> 5 | E12: =ROUND('[7]2026'!E16,2) -> 8349.62 | F12: =ROUND('[7]2026'!F16,2) -> 7906.29 | G12: =ROUND('[7]2026'!G16,2) -> 7577.83 | H12: =ROUND('[7]2026'!H16,2) -> 7318.69 | I12: =ROUND('[7]2026'!I16,2) -> 7250.75 | J12: =ROUND('[7]2026'!J16,2) -> 7282.55 | K12: =ROUND('[7]2026'!K16,2) -> 7094.36 | L12: =ROUND('[7]2026'!L16,2) -> 7769.62 | ... AB12: =ROUND('[7]2026'!AB16,2) -> 8976.36 | AE12: =+AC15 -> 6445364.2
C13: Domingo | D13: =+'[7]2026'!D17 -> 4 | E13: =ROUND('[7]2026'!E17,2) -> 8442.66 | F13: =ROUND('[7]2026'!F17,2) -> 8015.14 | G13: =ROUND('[7]2026'!G17,2) -> 7668.43 | H13: =ROUND('[7]2026'!H17,2) -> 7391.33 | I13: =ROUND('[7]2026'!I17,2) -> 7250.46 | J13: =ROUND('[7]2026'!J17,2) -> 7180.99 | K13: =ROUND('[7]2026'!K17,2) -> 6810.69 | L13: =ROUND('[7]2026'!L17,2) -> 7115.07 | ... AB13: =ROUND('[7]2026'!AB17,2) -> 8836.09 | AE13: =+AC19 -> 7112245.3
C14: Festivo | D14: =+'[7]2026'!D18 -> 2 | E14: =ROUND('[7]2026'!E18,2) -> 8442.66 | F14: =ROUND('[7]2026'!F18,2) -> 8015.14 | G14: =ROUND('[7]2026'!G18,2) -> 7668.43 | H14: =ROUND('[7]2026'!H18,2) -> 7391.33 | I14: =ROUND('[7]2026'!I18,2) -> 7250.46 | J14: =ROUND('[7]2026'!J18,2) -> 7180.99 | K14: =ROUND('[7]2026'!K18,2) -> 6810.69 | L14: =ROUND('[7]2026'!L18,2) -> 7115.07 | ... AB14: =ROUND('[7]2026'!AB18,2) -> 8836.09 | AE14: =+AC23 -> 6718171.7
B15: 46054 | C15: Ordinario | D15: =+'[7]2026'!D19 -> 20 | E15: =ROUND('[7]2026'!E19,2) -> 8510.66 | F15: =ROUND('[7]2026'!F19,2) -> 8061.56 | G15: =ROUND('[7]2026'!G19,2) -> 7740.78 | H15: =ROUND('[7]2026'!H19,2) -> 7530.79 | I15: =ROUND('[7]2026'!I19,2) -> 7546.21 | J15: =ROUND('[7]2026'!J19,2) -> 7965.35 | K15: =ROUND('[7]2026'!K19,2) -> 7944.07 | L15: =ROUND('[7]2026'!L19,2) -> 8764.18 | ... AB15: =ROUND('[7]2026'!AB19,2) -> 9147.53 | AC15: =SUM(E15:AB15)*D15+SUM(E16:AB16)*D16+SUM(E17:AB17)*D17+SUM(E18:AB18)*D18 -> 6445364.2 | AE15: =+AC27 -> 6807710.8
B16: Feb | C16: Sábado | D16: =+'[7]2026'!D20 -> 4 | E16: =ROUND('[7]2026'!E20,2) -> 8537.81 | F16: =ROUND('[7]2026'!F20,2) -> 8122.09 | G16: =ROUND('[7]2026'!G20,2) -> 7760.77 | H16: =ROUND('[7]2026'!H20,2) -> 7515.68 | I16: =ROUND('[7]2026'!I20,2) -> 7422.1 | J16: =ROUND('[7]2026'!J20,2) -> 7496.37 | K16: =ROUND('[7]2026'!K20,2) -> 7420.79 | L16: =ROUND('[7]2026'!L20,2) -> 8158.27 | ... AB16: =ROUND('[7]2026'!AB20,2) -> 9228.99 | AE16: =+AC31 -> 6344130.5
B17: Feb | C17: Domingo | D17: =+'[7]2026'!D21 -> 4 | E17: =ROUND('[7]2026'!E21,2) -> 8670.52 | F17: =ROUND('[7]2026'!F21,2) -> 8226.59 | G17: =ROUND('[7]2026'!G21,2) -> 7883.16 | H17: =ROUND('[7]2026'!H21,2) -> 7631.24 | I17: =ROUND('[7]2026'!I21,2) -> 7471.68 | J17: =ROUND('[7]2026'!J21,2) -> 7438.16 | K17: =ROUND('[7]2026'!K21,2) -> 7110.37 | L17: =ROUND('[7]2026'!L21,2) -> 7428.07 | ... AB17: =ROUND('[7]2026'!AB21,2) -> 9252.17 | AE17: =+AC35 -> 6880357.4
B18: Feb | C18: Festivo | D18: =+'[7]2026'!D22 -> 0 | E18: =ROUND('[7]2026'!E22,2) -> 0 | F18: =ROUND('[7]2026'!F22,2) -> 0 | G18: =ROUND('[7]2026'!G22,2) -> 0 | H18: =ROUND('[7]2026'!H22,2) -> 0 | I18: =ROUND('[7]2026'!I22,2) -> 0 | J18: =ROUND('[7]2026'!J22,2) -> 0 | K18: =ROUND('[7]2026'!K22,2) -> 0 | L18: =ROUND('[7]2026'!L22,2) -> 0 | ... AB18: =ROUND('[7]2026'!AB22,2) -> 0 | AE18: =+AC39 -> 6818865.1
B19: 46082 | C19: Ordinario | D19: =+'[7]2026'!D23 -> 21 | E19: =ROUND('[7]2026'!E23,2) -> 8678.23 | F19: =ROUND('[7]2026'!F23,2) -> 8219.61 | G19: =ROUND('[7]2026'!G23,2) -> 7873.99 | H19: =ROUND('[7]2026'!H23,2) -> 7618.92 | I19: =ROUND('[7]2026'!I23,2) -> 7580.58 | J19: =ROUND('[7]2026'!J23,2) -> 7858.15 | K19: =ROUND('[7]2026'!K23,2) -> 7804.18 | L19: =ROUND('[7]2026'!L23,2) -> 8698.76 | ... AB19: =ROUND('[7]2026'!AB23,2) -> 9392.46 | AC19: =SUM(E19:AB19)*D19+SUM(E20:AB20)*D20+SUM(E21:AB21)*D21+SUM(E22:AB22)*D22 -> 7112245.3 | AE19: =+AC43 -> 6736312.6
C20: Sábado | D20: =+'[7]2026'!D24 -> 4 | E20: =ROUND('[7]2026'!E24,2) -> 8703.44 | F20: =ROUND('[7]2026'!F24,2) -> 8230.26 | G20: =ROUND('[7]2026'!G24,2) -> 7896.95 | H20: =ROUND('[7]2026'!H24,2) -> 7633.18 | I20: =ROUND('[7]2026'!I24,2) -> 7475.72 | J20: =ROUND('[7]2026'!J24,2) -> 7451.64 | K20: =ROUND('[7]2026'!K24,2) -> 7342.5 | L20: =ROUND('[7]2026'!L24,2) -> 8044.92 | ... AB20: =ROUND('[7]2026'!AB24,2) -> 9181.35 | AE20: =+AC47 -> 6712169.9
C21: Domingo | D21: =+'[7]2026'!D25 -> 5 | E21: =ROUND('[7]2026'!E25,2) -> 8633.73 | F21: =ROUND('[7]2026'!F25,2) -> 8191.74 | G21: =ROUND('[7]2026'!G25,2) -> 7797.22 | H21: =ROUND('[7]2026'!H25,2) -> 7520.43 | I21: =ROUND('[7]2026'!I25,2) -> 7392.08 | J21: =ROUND('[7]2026'!J25,2) -> 7308.46 | K21: =ROUND('[7]2026'!K25,2) -> 6951.42 | L21: =ROUND('[7]2026'!L25,2) -> 7285.72 | ... AB21: =ROUND('[7]2026'!AB25,2) -> 8951.75 | AE21: =+AC51 -> 6655295.1
C22: Festivo | D22: =+'[7]2026'!D26 -> 1 | E22: =ROUND('[7]2026'!E26,2) -> 8633.73 | F22: =ROUND('[7]2026'!F26,2) -> 8191.74 | G22: =ROUND('[7]2026'!G26,2) -> 7797.22 | H22: =ROUND('[7]2026'!H26,2) -> 7520.43 | I22: =ROUND('[7]2026'!I26,2) -> 7392.08 | J22: =ROUND('[7]2026'!J26,2) -> 7308.46 | K22: =ROUND('[7]2026'!K26,2) -> 6951.42 | L22: =ROUND('[7]2026'!L26,2) -> 7285.72 | ... AB22: =ROUND('[7]2026'!AB26,2) -> 8951.75 | AE22: =+AC55 -> 6831338.7
B23: 46113 | C23: Ordinario | D23: =+'[7]2026'!D27 -> 20 | E23: =ROUND('[7]2026'!E27,2) -> 8466 | F23: =ROUND('[7]2026'!F27,2) -> 8100.99 | G23: =ROUND('[7]2026'!G27,2) -> 7743.23 | H23: =ROUND('[7]2026'!H27,2) -> 7543.26 | I23: =ROUND('[7]2026'!I27,2) -> 7495.48 | J23: =ROUND('[7]2026'!J27,2) -> 7417.67 | K23: =ROUND('[7]2026'!K27,2) -> 7443.42 | L23: =ROUND('[7]2026'!L27,2) -> 8280.11 | ... AB23: =ROUND('[7]2026'!AB27,2) -> 9391.46 | AC23: =SUM(E23:AB23)*D23+SUM(E24:AB24)*D24+SUM(E25:AB25)*D25+SUM(E26:AB26)*D26 -> 6718171.7 | AE23: =SUM(AE11:AE22) -> 80946970
B24: Feb | C24: Sábado | D24: =+'[7]2026'!D28 -> 4 | E24: =ROUND('[7]2026'!E28,2) -> 8173.8 | F24: =ROUND('[7]2026'!F28,2) -> 7770.95 | G24: =ROUND('[7]2026'!G28,2) -> 7464.95 | H24: =ROUND('[7]2026'!H28,2) -> 7239.31 | I24: =ROUND('[7]2026'!I28,2) -> 7246.07 | J24: =ROUND('[7]2026'!J28,2) -> 7335.44 | K24: =ROUND('[7]2026'!K28,2) -> 7500.25 | L24: =ROUND('[7]2026'!L28,2) -> 8316.38 | ... AB24: =ROUND('[7]2026'!AB28,2) -> 8747.04
B25: Feb | C25: Domingo | D25: =+'[7]2026'!D29 -> 4 | E25: =ROUND('[7]2026'!E29,2) -> 8808.92 | F25: =ROUND('[7]2026'!F29,2) -> 8362.86 | G25: =ROUND('[7]2026'!G29,2) -> 7993.35 | H25: =ROUND('[7]2026'!H29,2) -> 7741.29 | I25: =ROUND('[7]2026'!I29,2) -> 7593.61 | J25: =ROUND('[7]2026'!J29,2) -> 7368.41 | K25: =ROUND('[7]2026'!K29,2) -> 7142.78 | L25: =ROUND('[7]2026'!L29,2) -> 7542.91 | ... AB25: =ROUND('[7]2026'!AB29,2) -> 8927.08
B26: Feb | C26: Festivo | D26: =+'[7]2026'!D30 -> 2 | E26: =ROUND('[7]2026'!E30,2) -> 8808.92 | F26: =ROUND('[7]2026'!F30,2) -> 8362.86 | G26: =ROUND('[7]2026'!G30,2) -> 7993.35 | H26: =ROUND('[7]2026'!H30,2) -> 7741.29 | I26: =ROUND('[7]2026'!I30,2) -> 7593.61 | J26: =ROUND('[7]2026'!J30,2) -> 7368.41 | K26: =ROUND('[7]2026'!K30,2) -> 7142.78 | L26: =ROUND('[7]2026'!L30,2) -> 7542.91 | ... AB26: =ROUND('[7]2026'!AB30,2) -> 8927.08
B27: 46143 | C27: Ordinario | D27: =+'[7]2026'!D31 -> 19 | E27: =ROUND('[7]2026'!E31,2) -> 8662.21 | F27: =ROUND('[7]2026'!F31,2) -> 8211.47 | G27: =ROUND('[7]2026'!G31,2) -> 7847.76 | H27: =ROUND('[7]2026'!H31,2) -> 7536.7 | I27: =ROUND('[7]2026'!I31,2) -> 7452.86 | J27: =ROUND('[7]2026'!J31,2) -> 7334.82 | K27: =ROUND('[7]2026'!K31,2) -> 7443.22 | L27: =ROUND('[7]2026'!L31,2) -> 8243.82 | ... AB27: =ROUND('[7]2026'!AB31,2) -> 8920.12 | AC27: =SUM(E27:AB27)*D27+SUM(E28:AB28)*D28+SUM(E29:AB29)*D29+SUM(E30:AB30)*D30 -> 6807710.8
C28: Sábado | D28: =+'[7]2026'!D32 -> 5 | E28: =ROUND('[7]2026'!E32,2) -> 7985.64 | F28: =ROUND('[7]2026'!F32,2) -> 7590.61 | G28: =ROUND('[7]2026'!G32,2) -> 7301.49 | H28: =ROUND('[7]2026'!H32,2) -> 7102.34 | I28: =ROUND('[7]2026'!I32,2) -> 7076.79 | J28: =ROUND('[7]2026'!J32,2) -> 7067.89 | K28: =ROUND('[7]2026'!K32,2) -> 7175.55 | L28: =ROUND('[7]2026'!L32,2) -> 8016.46 | ... AB28: =ROUND('[7]2026'!AB32,2) -> 8558.97
C29: Domingo | D29: =+'[7]2026'!D33 -> 5 | E29: =ROUND('[7]2026'!E33,2) -> 7979.76 | F29: =ROUND('[7]2026'!F33,2) -> 7667.27 | G29: =ROUND('[7]2026'!G33,2) -> 7346.8 | H29: =ROUND('[7]2026'!H33,2) -> 7176.4 | I29: =ROUND('[7]2026'!I33,2) -> 7121.74 | J29: =ROUND('[7]2026'!J33,2) -> 6945 | K29: =ROUND('[7]2026'!K33,2) -> 6916.12 | L29: =ROUND('[7]2026'!L33,2) -> 7452.04 | ... AB29: =ROUND('[7]2026'!AB33,2) -> 9230.05
C30: Festivo | D30: =+'[7]2026'!D34 -> 2 | E30: =ROUND('[7]2026'!E34,2) -> 7979.76 | F30: =ROUND('[7]2026'!F34,2) -> 7667.27 | G30: =ROUND('[7]2026'!G34,2) -> 7346.8 | H30: =ROUND('[7]2026'!H34,2) -> 7176.4 | I30: =ROUND('[7]2026'!I34,2) -> 7121.74 | J30: =ROUND('[7]2026'!J34,2) -> 6945 | K30: =ROUND('[7]2026'!K34,2) -> 6916.12 | L30: =ROUND('[7]2026'!L34,2) -> 7452.04 | ... AB30: =ROUND('[7]2026'!AB34,2) -> 9230.05
B31: 46174 | C31: Ordinario | D31: =+'[7]2026'!D35 -> 19 | E31: =ROUND('[7]2026'!E35,2) -> 7825.8 | F31: =ROUND('[7]2026'!F35,2) -> 7437.29 | G31: =ROUND('[7]2026'!G35,2) -> 7150.24 | H31: =ROUND('[7]2026'!H35,2) -> 6958.69 | I31: =ROUND('[7]2026'!I35,2) -> 6907.52 | J31: =ROUND('[7]2026'!J35,2) -> 6834.14 | K31: =ROUND('[7]2026'!K35,2) -> 6948.17 | L31: =ROUND('[7]2026'!L35,2) -> 7785.11 | ... AB31: =ROUND('[7]2026'!AB35,2) -> 8688.49 | AC31: =SUM(E31:AB31)*D31+SUM(E32:AB32)*D32+SUM(E33:AB33)*D33+SUM(E34:AB34)*D34 -> 6344130.5
B32: Feb | C32: Sábado | D32: =+'[7]2026'!D36 -> 4 | E32: =ROUND('[7]2026'!E36,2) -> 8059.09 | F32: =ROUND('[7]2026'!F36,2) -> 7662.49 | G32: =ROUND('[7]2026'!G36,2) -> 7361.13 | H32: =ROUND('[7]2026'!H36,2) -> 7152.02 | I32: =ROUND('[7]2026'!I36,2) -> 7127.41 | J32: =ROUND('[7]2026'!J36,2) -> 7207.4 | K32: =ROUND('[7]2026'!K36,2) -> 7256.32 | L32: =ROUND('[7]2026'!L36,2) -> 8072.64 | ... AB32: =ROUND('[7]2026'!AB36,2) -> 8704.85
B33: Feb | C33: Domingo | D33: =+'[7]2026'!D37 -> 4 | E33: =ROUND('[7]2026'!E37,2) -> 7671.12 | F33: =ROUND('[7]2026'!F37,2) -> 7361.08 | G33: =ROUND('[7]2026'!G37,2) -> 7107.73 | H33: =ROUND('[7]2026'!H37,2) -> 6943.58 | I33: =ROUND('[7]2026'!I37,2) -> 6878.1 | J33: =ROUND('[7]2026'!J37,2) -> 6685.5 | K33: =ROUND('[7]2026'!K37,2) -> 6597.53 | L33: =ROUND('[7]2026'!L37,2) -> 7134.99 | ... AB33: =ROUND('[7]2026'!AB37,2) -> 8525.57
B34: Feb | C34: Festivo | D34: =+'[7]2026'!D38 -> 3 | E34: =ROUND('[7]2026'!E38,2) -> 7671.12 | F34: =ROUND('[7]2026'!F38,2) -> 7361.08 | G34: =ROUND('[7]2026'!G38,2) -> 7107.73 | H34: =ROUND('[7]2026'!H38,2) -> 6943.58 | I34: =ROUND('[7]2026'!I38,2) -> 6878.1 | J34: =ROUND('[7]2026'!J38,2) -> 6685.5 | K34: =ROUND('[7]2026'!K38,2) -> 6597.53 | L34: =ROUND('[7]2026'!L38,2) -> 7134.99 | ... AB34: =ROUND('[7]2026'!AB38,2) -> 8525.57
B35: 46204 | C35: Ordinario | D35: =+'[7]2026'!D39 -> 22 | E35: =ROUND('[7]2026'!E39,2) -> 8078.9 | F35: =ROUND('[7]2026'!F39,2) -> 7690.1 | G35: =ROUND('[7]2026'!G39,2) -> 7433.8 | H35: =ROUND('[7]2026'!H39,2) -> 7244.06 | I35: =ROUND('[7]2026'!I39,2) -> 7214.64 | J35: =ROUND('[7]2026'!J39,2) -> 7181.01 | K35: =ROUND('[7]2026'!K39,2) -> 7247.11 | L35: =ROUND('[7]2026'!L39,2) -> 8092.51 | ... AB35: =ROUND('[7]2026'!AB39,2) -> 9015.49 | AC35: =SUM(E35:AB35)*D35+SUM(E36:AB36)*D36+SUM(E37:AB37)*D37+SUM(E38:AB38)*D38 -> 6880357.4
C36: Sábado | D36: =+'[7]2026'!D40 -> 4 | E36: =ROUND('[7]2026'!E40,2) -> 8593.08 | F36: =ROUND('[7]2026'!F40,2) -> 8143.02 | G36: =ROUND('[7]2026'!G40,2) -> 7813.16 | H36: =ROUND('[7]2026'!H40,2) -> 7580.43 | I36: =ROUND('[7]2026'!I40,2) -> 7564.38 | J36: =ROUND('[7]2026'!J40,2) -> 7702.94 | K36: =ROUND('[7]2026'!K40,2) -> 7748.12 | L36: =ROUND('[7]2026'!L40,2) -> 8592.96 | ... AB36: =ROUND('[7]2026'!AB40,2) -> 9258.85
C37: Domingo | D37: =+'[7]2026'!D41 -> 4 | E37: =ROUND('[7]2026'!E41,2) -> 8105.12 | F37: =ROUND('[7]2026'!F41,2) -> 7779.55 | G37: =ROUND('[7]2026'!G41,2) -> 7503.96 | H37: =ROUND('[7]2026'!H41,2) -> 7251.67 | I37: =ROUND('[7]2026'!I41,2) -> 7166.97 | J37: =ROUND('[7]2026'!J41,2) -> 7055.29 | K37: =ROUND('[7]2026'!K41,2) -> 6920.82 | L37: =ROUND('[7]2026'!L41,2) -> 7436.88 | ... AB37: =ROUND('[7]2026'!AB41,2) -> 9168.79
C38: Festivo | D38: =+'[7]2026'!D42 -> 1 | E38: =ROUND('[7]2026'!E42,2) -> 8105.12 | F38: =ROUND('[7]2026'!F42,2) -> 7779.55 | G38: =ROUND('[7]2026'!G42,2) -> 7503.96 | H38: =ROUND('[7]2026'!H42,2) -> 7251.67 | I38: =ROUND('[7]2026'!I42,2) -> 7166.97 | J38: =ROUND('[7]2026'!J42,2) -> 7055.29 | K38: =ROUND('[7]2026'!K42,2) -> 6920.82 | L38: =ROUND('[7]2026'!L42,2) -> 7436.88 | ... AB38: =ROUND('[7]2026'!AB42,2) -> 9168.79
B39: 46235 | C39: Ordinario | D39: =+'[7]2026'!D43 -> 19 | E39: =ROUND('[7]2026'!E43,2) -> 8376.33 | F39: =ROUND('[7]2026'!F43,2) -> 7924.97 | G39: =ROUND('[7]2026'!G43,2) -> 7588.19 | H39: =ROUND('[7]2026'!H43,2) -> 7362.66 | I39: =ROUND('[7]2026'!I43,2) -> 7279.82 | J39: =ROUND('[7]2026'!J43,2) -> 7258.95 | K39: =ROUND('[7]2026'!K43,2) -> 7282.79 | L39: =ROUND('[7]2026'!L43,2) -> 8123.14 | ... AB39: =ROUND('[7]2026'!AB43,2) -> 8806.39 | AC39: =SUM(E39:AB39)*D39+SUM(E40:AB40)*D40+SUM(E41:AB41)*D41+SUM(E42:AB42)*D42 -> 6818865.1
B40: Feb | C40: Sábado | D40: =+'[7]2026'!D44 -> 5 | E40: =ROUND('[7]2026'!E44,2) -> 8265.67 | F40: =ROUND('[7]2026'!F44,2) -> 7855.39 | G40: =ROUND('[7]2026'!G44,2) -> 7541.6 | H40: =ROUND('[7]2026'!H44,2) -> 7320.31 | I40: =ROUND('[7]2026'!I44,2) -> 7299.18 | J40: =ROUND('[7]2026'!J44,2) -> 7418.6 | K40: =ROUND('[7]2026'!K44,2) -> 7497.76 | L40: =ROUND('[7]2026'!L44,2) -> 8353.12 | ... AB40: =ROUND('[7]2026'!AB44,2) -> 8862.47
B41: Feb | C41: Domingo | D41: =+'[7]2026'!D45 -> 5 | E41: =ROUND('[7]2026'!E45,2) -> 8261.55 | F41: =ROUND('[7]2026'!F45,2) -> 7830.99 | G41: =ROUND('[7]2026'!G45,2) -> 7496.59 | H41: =ROUND('[7]2026'!H45,2) -> 7254.73 | I41: =ROUND('[7]2026'!I45,2) -> 7153.23 | J41: =ROUND('[7]2026'!J45,2) -> 7016.47 | K41: =ROUND('[7]2026'!K45,2) -> 6866.84 | L41: =ROUND('[7]2026'!L45,2) -> 7366.39 | ... AB41: =ROUND('[7]2026'!AB45,2) -> 8982.75
B42: Feb | C42: Festivo | D42: =+'[7]2026'!D46 -> 2 | E42: =ROUND('[7]2026'!E46,2) -> 8261.55 | F42: =ROUND('[7]2026'!F46,2) -> 7830.99 | G42: =ROUND('[7]2026'!G46,2) -> 7496.59 | H42: =ROUND('[7]2026'!H46,2) -> 7254.73 | I42: =ROUND('[7]2026'!I46,2) -> 7153.23 | J42: =ROUND('[7]2026'!J46,2) -> 7016.47 | K42: =ROUND('[7]2026'!K46,2) -> 6866.84 | L42: =ROUND('[7]2026'!L46,2) -> 7366.39 | ... AB42: =ROUND('[7]2026'!AB46,2) -> 8982.75
B43: 46266 | C43: Ordinario | D43: =+'[7]2026'!D47 -> 22 | E43: =ROUND('[7]2026'!E47,2) -> 8505.46 | F43: =ROUND('[7]2026'!F47,2) -> 8071.34 | G43: =ROUND('[7]2026'!G47,2) -> 7735.47 | H43: =ROUND('[7]2026'!H47,2) -> 7497.52 | I43: =ROUND('[7]2026'!I47,2) -> 7427.7 | J43: =ROUND('[7]2026'!J47,2) -> 7331.81 | K43: =ROUND('[7]2026'!K47,2) -> 7379.24 | L43: =ROUND('[7]2026'!L47,2) -> 8256.82 | ... AB43: =ROUND('[7]2026'!AB47,2) -> 8903.13 | AC43: =SUM(E43:AB43)*D43+SUM(E44:AB44)*D44+SUM(E45:AB45)*D45+SUM(E46:AB46)*D46 -> 6736312.6
C44: Sábado | D44: =+'[7]2026'!D48 -> 4 | E44: =ROUND('[7]2026'!E48,2) -> 7951.28 | F44: =ROUND('[7]2026'!F48,2) -> 7551.11 | G44: =ROUND('[7]2026'!G48,2) -> 7271.87 | H44: =ROUND('[7]2026'!H48,2) -> 7066.04 | I44: =ROUND('[7]2026'!I48,2) -> 7069.41 | J44: =ROUND('[7]2026'!J48,2) -> 7186.57 | K44: =ROUND('[7]2026'!K48,2) -> 7332.86 | L44: =ROUND('[7]2026'!L48,2) -> 8227.47 | ... AB44: =ROUND('[7]2026'!AB48,2) -> 8616.45
C45: Domingo | D45: =+'[7]2026'!D49 -> 4 | E45: =ROUND('[7]2026'!E49,2) -> 8193.67 | F45: =ROUND('[7]2026'!F49,2) -> 7795.04 | G45: =ROUND('[7]2026'!G49,2) -> 7499.95 | H45: =ROUND('[7]2026'!H49,2) -> 7277.05 | I45: =ROUND('[7]2026'!I49,2) -> 7288.71 | J45: =ROUND('[7]2026'!J49,2) -> 7518.42 | K45: =ROUND('[7]2026'!K49,2) -> 7663.16 | L45: =ROUND('[7]2026'!L49,2) -> 8612.26 | ... AB45: =ROUND('[7]2026'!AB49,2) -> 8919.24
...

Sheet Cantidades 2_(2027)
B4: 9.2 TABLAS CANTIDADES DE ENERGÍA REQUERIDA PRODUCTO 2 AÑO 2027 (kWh)
B5: ELETRIFICADORA DE SANTANDER S.A E.S.P.
B6: SOLICITUD PÚBLICA DE OFERTAS CP-ESSC2025-002
B7: PAGUELO CONTRATADO
B10: Mes | C10: Tipo Día | D10: Días | E10: H1 | F10: H2 | G10: H3 | H10: H4 | I10: H5 | J10: H6 | K10: H7 | L10: H8 | M10: H9 | N10: H10 | O10: H11 | P10: H12 | Q10: H13 | R10: H14 | S10: H15 | T10: H16 | U10: H17 | V10: H18 | W10: H19 | X10: H20 | Y10: H21 | Z10: H22 | AA10: H23 | AB10: H24 | AC10: TOTAL MES kWh | AE10: =+AC10 -> TOTAL MES kWh
B11: 46388 | C11: Ordinario | D11: =+'[7]2027'!D15 -> 19 | E11: =ROUND('[7]2027'!E15,2) -> 43171.1 | F11: =ROUND('[7]2027'!F15,2) -> 39285.02 | G11: =ROUND('[7]2027'!G15,2) -> 36255.57 | H11: =ROUND('[7]2027'!H15,2) -> 34072.35 | I11: =ROUND('[7]2027'!I15,2) -> 32359.27 | J11: =ROUND('[7]2027'!J15,2) -> 29013.65 | K11: =ROUND('[7]2027'!K15,2) -> 27055.71 | L11: =ROUND('[7]2027'!L15,2) -> 24975.51 | ... AB11: =ROUND('[7]2027'!AB15,2) -> 66742.82 | AC11: =SUM(E11:AB11)*D11+SUM(E12:AB12)*D12+SUM(E13:AB13)*D13+SUM(E14:AB14)*D14 -> 30208541 | AE11: =+AC11 -> 30208541
C12: Sábado | D12: =+'[7]2027'!D16 -> 5 | E12: =ROUND('[7]2027'!E16,2) -> 43330.5 | F12: =ROUND('[7]2027'!F16,2) -> 39748.79 | G12: =ROUND('[7]2027'!G16,2) -> 36510.03 | H12: =ROUND('[7]2027'!H16,2) -> 33885.66 | I12: =ROUND('[7]2027'!I16,2) -> 32602.29 | J12: =ROUND('[7]2027'!J16,2) -> 29315.97 | K12: =ROUND('[7]2027'!K16,2) -> 26165.34 | L12: =ROUND('[7]2027'!L16,2) -> 22196.35 | ... AB12: =ROUND('[7]2027'!AB16,2) -> 65924.48 | AE12: =+AC15 -> 24071174
C13: Domingo | D13: =+'[7]2027'!D17 -> 5 | E13: =ROUND('[7]2027'!E17,2) -> 45437.1 | F13: =ROUND('[7]2027'!F17,2) -> 42313.62 | G13: =ROUND('[7]2027'!G17,2) -> 38963.35 | H13: =ROUND('[7]2027'!H17,2) -> 35859.14 | I13: =ROUND('[7]2027'!I17,2) -> 34342.83 | J13: =ROUND('[7]2027'!J17,2) -> 30819.21 | K13: =ROUND('[7]2027'!K17,2) -> 27378.92 | L13: =ROUND('[7]2027'!L17,2) -> 21925.47 | ... AB13: =ROUND('[7]2027'!AB17,2) -> 66655.38 | AE13: =+AC19 -> 32942148
C14: Festivo | D14: =+'[7]2027'!D18 -> 2 | E14: =ROUND('[7]2027'!E18,2) -> 45437.1 | F14: =ROUND('[7]2027'!F18,2) -> 42313.62 | G14: =ROUND('[7]2027'!G18,2) -> 38963.35 | H14: =ROUND('[7]2027'!H18,2) -> 35859.14 | I14: =ROUND('[7]2027'!I18,2) -> 34342.83 | J14: =ROUND('[7]2027'!J18,2) -> 30819.21 | K14: =ROUND('[7]2027'!K18,2) -> 27378.92 | L14: =ROUND('[7]2027'!L18,2) -> 21925.47 | ... AB14: =ROUND('[7]2027'!AB18,2) -> 66655.38 | AE14: =+AC23 -> 27847437
B15: 46419 | C15: Ordinario | D15: =+'[7]2027'!D19 -> 20 | E15: =ROUND('[7]2027'!E19,2) -> 38856.48 | F15: =ROUND('[7]2027'!F19,2) -> 35875.05 | G15: =ROUND('[7]2027'!G19,2) -> 33188.93 | H15: =ROUND('[7]2027'!H19,2) -> 31604.99 | I15: =ROUND('[7]2027'!I19,2) -> 30612.15 | J15: =ROUND('[7]2027'!J19,2) -> 27980.2 | K15: =ROUND('[7]2027'!K19,2) -> 26991.91 | L15: =ROUND('[7]2027'!L19,2) -> 26297.5 | ... AB15: =ROUND('[7]2027'!AB19,2) -> 63082.26 | AC15: =SUM(E15:AB15)*D15+SUM(E16:AB16)*D16+SUM(E17:AB17)*D17+SUM(E18:AB18)*D18 -> 24071174 | AE15: =+AC27 -> 25146241
B16: Feb | C16: Sábado | D16: =+'[7]2027'!D20 -> 4 | E16: =ROUND('[7]2027'!E20,2) -> 34735.89 | F16: =ROUND('[7]2027'!F20,2) -> 32632.89 | G16: =ROUND('[7]2027'!G20,2) -> 29722.48 | H16: =ROUND('[7]2027'!H20,2) -> 27737.12 | I16: =ROUND('[7]2027'!I20,2) -> 26252.73 | J16: =ROUND('[7]2027'!J20,2) -> 23237.75 | K16: =ROUND('[7]2027'!K20,2) -> 22613.5 | L16: =ROUND('[7]2027'!L20,2) -> 19631.8 | ... AB16: =ROUND('[7]2027'!AB20,2) -> 62078.81 | AE16: =+AC31 -> 6652499.5
B17: Feb | C17: Domingo | D17: =+'[7]2027'!D21 -> 4 | E17: =ROUND('[7]2027'!E21,2) -> 39324.77 | F17: =ROUND('[7]2027'!F21,2) -> 36814.26 | G17: =ROUND('[7]2027'!G21,2) -> 34223.08 | H17: =ROUND('[7]2027'!H21,2) -> 32635.02 | I17: =ROUND('[7]2027'!I21,2) -> 30645.15 | J17: =ROUND('[7]2027'!J21,2) -> 27396.37 | K17: =ROUND('[7]2027'!K21,2) -> 25352.6 | L17: =ROUND('[7]2027'!L21,2) -> 19887.47 | ... AB17: =ROUND('[7]2027'!AB21,2) -> 68240.07 | AE17: =+AC35 -> 7378392.1
B18: Feb | C18: Festivo | D18: =+'[7]2027'!D22 -> 0 | E18: =ROUND('[7]2027'!E22,2) -> 0 | F18: =ROUND('[7]2027'!F22,2) -> 0 | G18: =ROUND('[7]2027'!G22,2) -> 0 | H18: =ROUND('[7]2027'!H22,2) -> 0 | I18: =ROUND('[7]2027'!I22,2) -> 0 | J18: =ROUND('[7]2027'!J22,2) -> 0 | K18: =ROUND('[7]2027'!K22,2) -> 0 | L18: =ROUND('[7]2027'!L22,2) -> 0 | ... AB18: =ROUND('[7]2027'!AB22,2) -> 0 | AE18: =+AC39 -> 9177870.5
B19: 46447 | C19: Ordinario | D19: =+'[7]2027'!D23 -> 20 | E19: =ROUND('[7]2027'!E23,2) -> 53035.07 | F19: =ROUND('[7]2027'!F23,2) -> 48680.64 | G19: =ROUND('[7]2027'!G23,2) -> 44575.34 | H19: =ROUND('[7]2027'!H23,2) -> 41289.81 | I19: =ROUND('[7]2027'!I23,2) -> 38303.2 | J19: =ROUND('[7]2027'!J23,2) -> 32939.66 | K19: =ROUND('[7]2027'!K23,2) -> 30432.9 | L19: =ROUND('[7]2027'!L23,2) -> 31308.45 | ... AB19: =ROUND('[7]2027'!AB23,2) -> 75628.63 | AC19: =SUM(E19:AB19)*D19+SUM(E20:AB20)*D20+SUM(E21:AB21)*D21+SUM(E22:AB22)*D22 -> 32942148 | AE19: =+AC43 -> 10029118
C20: Sábado | D20: =+'[7]2027'!D24 -> 4 | E20: =ROUND('[7]2027'!E24,2) -> 49965.74 | F20: =ROUND('[7]2027'!F24,2) -> 45851.26 | G20: =ROUND('[7]2027'!G24,2) -> 42607.65 | H20: =ROUND('[7]2027'!H24,2) -> 39990.66 | I20: =ROUND('[7]2027'!I24,2) -> 36384.14 | J20: =ROUND('[7]2027'!J24,2) -> 30672.32 | K20: =ROUND('[7]2027'!K24,2) -> 28004.63 | L20: =ROUND('[7]2027'!L24,2) -> 23199.67 | ... AB20: =ROUND('[7]2027'!AB24,2) -> 68219.8 | AE20: =+AC47 -> 11917265
C21: Domingo | D21: =+'[7]2027'!D25 -> 4 | E21: =ROUND('[7]2027'!E25,2) -> 46959.95 | F21: =ROUND('[7]2027'!F25,2) -> 44152.18 | G21: =ROUND('[7]2027'!G25,2) -> 39880.33 | H21: =ROUND('[7]2027'!H25,2) -> 36939.59 | I21: =ROUND('[7]2027'!I25,2) -> 35073.99 | J21: =ROUND('[7]2027'!J25,2) -> 31210.47 | K21: =ROUND('[7]2027'!K25,2) -> 26938.82 | L21: =ROUND('[7]2027'!L25,2) -> 22899.6 | ... AB21: =ROUND('[7]2027'!AB25,2) -> 73005.94 | AE21: =+AC51 -> 23033067
C22: Festivo | D22: =+'[7]2027'!D26 -> 3 | E22: =ROUND('[7]2027'!E26,2) -> 46959.95 | F22: =ROUND('[7]2027'!F26,2) -> 44152.18 | G22: =ROUND('[7]2027'!G26,2) -> 39880.33 | H22: =ROUND('[7]2027'!H26,2) -> 36939.59 | I22: =ROUND('[7]2027'!I26,2) -> 35073.99 | J22: =ROUND('[7]2027'!J26,2) -> 31210.47 | K22: =ROUND('[7]2027'!K26,2) -> 26938.82 | L22: =ROUND('[7]2027'!L26,2) -> 22899.6 | ... AB22: =ROUND('[7]2027'!AB26,2) -> 73005.94 | AE22: =+AC55 -> 18451290
B23: 46478 | C23: Ordinario | D23: =+'[7]2027'!D27 -> 22 | E23: =ROUND('[7]2027'!E27,2) -> 46244.17 | F23: =ROUND('[7]2027'!F27,2) -> 44513 | G23: =ROUND('[7]2027'!G27,2) -> 40360.02 | H23: =ROUND('[7]2027'!H27,2) -> 39185.15 | I23: =ROUND('[7]2027'!I27,2) -> 36564.13 | J23: =ROUND('[7]2027'!J27,2) -> 26081.98 | K23: =ROUND('[7]2027'!K27,2) -> 23639.25 | L23: =ROUND('[7]2027'!L27,2) -> 21796.15 | ... AB23: =ROUND('[7]2027'!AB27,2) -> 74620.42 | AC23: =SUM(E23:AB23)*D23+SUM(E24:AB24)*D24+SUM(E25:AB25)*D25+SUM(E26:AB26)*D26 -> 27847437 | AE23: =SUM(AE11:AE22) -> 2.2685504e+08
B24: Feb | C24: Sábado | D24: =+'[7]2027'!D28 -> 4 | E24: =ROUND('[7]2027'!E28,2) -> 38104.71 | F24: =ROUND('[7]2027'!F28,2) -> 35417.88 | G24: =ROUND('[7]2027'!G28,2) -> 32498.01 | H24: =ROUND('[7]2027'!H28,2) -> 30342.34 | I24: =ROUND('[7]2027'!I28,2) -> 30489.66 | J24: =ROUND('[7]2027'!J28,2) -> 30842.21 | K24: =ROUND('[7]2027'!K28,2) -> 32446.58 | L24: =ROUND('[7]2027'!L28,2) -> 29939.41 | ... AB24: =ROUND('[7]2027'!AB28,2) -> 55484.53
B25: Feb | C25: Domingo | D25: =+'[7]2027'!D29 -> 4 | E25: =ROUND('[7]2027'!E29,2) -> 48588.36 | F25: =ROUND('[7]2027'!F29,2) -> 45648.92 | G25: =ROUND('[7]2027'!G29,2) -> 43041.6 | H25: =ROUND('[7]2027'!H29,2) -> 40590.75 | I25: =ROUND('[7]2027'!I29,2) -> 38879.28 | J25: =ROUND('[7]2027'!J29,2) -> 33226.5 | K25: =ROUND('[7]2027'!K29,2) -> 30414.74 | L25: =ROUND('[7]2027'!L29,2) -> 26163.04 | ... AB25: =ROUND('[7]2027'!AB29,2) -> 66378.39
B26: Feb | C26: Festivo | D26: =+'[7]2027'!D30 -> 0 | E26: =ROUND('[7]2027'!E30,2) -> 0 | F26: =ROUND('[7]2027'!F30,2) -> 0 | G26: =ROUND('[7]2027'!G30,2) -> 0 | H26: =ROUND('[7]2027'!H30,2) -> 0 | I26: =ROUND('[7]2027'!I30,2) -> 0 | J26: =ROUND('[7]2027'!J30,2) -> 0 | K26: =ROUND('[7]2027'!K30,2) -> 0 | L26: =ROUND('[7]2027'!L30,2) -> 0 | ... AB26: =ROUND('[7]2027'!AB30,2) -> 0
B27: 46508 | C27: Ordinario | D27: =+'[7]2027'!D31 -> 19 | E27: =ROUND('[7]2027'!E31,2) -> 49321.07 | F27: =ROUND('[7]2027'!F31,2) -> 45542.5 | G27: =ROUND('[7]2027'!G31,2) -> 41380.14 | H27: =ROUND('[7]2027'!H31,2) -> 37063.84 | I27: =ROUND('[7]2027'!I31,2) -> 33708.36 | J27: =ROUND('[7]2027'!J31,2) -> 24313.94 | K27: =ROUND('[7]2027'!K31,2) -> 21097.03 | L27: =ROUND('[7]2027'!L31,2) -> 16980.12 | ... AB27: =ROUND('[7]2027'!AB31,2) -> 62274.57 | AC27: =SUM(E27:AB27)*D27+SUM(E28:AB28)*D28+SUM(E29:AB29)*D29+SUM(E30:AB30)*D30 -> 25146241
C28: Sábado | D28: =+'[7]2027'!D32 -> 4 | E28: =ROUND('[7]2027'!E32,2) -> 33504.35 | F28: =ROUND('[7]2027'!F32,2) -> 30664.88 | G28: =ROUND('[7]2027'!G32,2) -> 28799.51 | H28: =ROUND('[7]2027'!H32,2) -> 26875.59 | I28: =ROUND('[7]2027'!I32,2) -> 25789.81 | J28: =ROUND('[7]2027'!J32,2) -> 24464.8 | K28: =ROUND('[7]2027'!K32,2) -> 22474.44 | L28: =ROUND('[7]2027'!L32,2) -> 19994.49 | ... AB28: =ROUND('[7]2027'!AB32,2) -> 52860.97
C29: Domingo | D29: =+'[7]2027'!D33 -> 5 | E29: =ROUND('[7]2027'!E33,2) -> 31153.73 | F29: =ROUND('[7]2027'!F33,2) -> 30720.56 | G29: =ROUND('[7]2027'!G33,2) -> 28260.64 | H29: =ROUND('[7]2027'!H33,2) -> 27445.19 | I29: =ROUND('[7]2027'!I33,2) -> 27449.27 | J29: =ROUND('[7]2027'!J33,2) -> 24984.38 | K29: =ROUND('[7]2027'!K33,2) -> 23928.38 | L29: =ROUND('[7]2027'!L33,2) -> 22259.36 | ... AB29: =ROUND('[7]2027'!AB33,2) -> 69511.53
C30: Festivo | D30: =+'[7]2027'!D34 -> 3 | E30: =ROUND('[7]2027'!E34,2) -> 31153.73 | F30: =ROUND('[7]2027'!F34,2) -> 30720.56 | G30: =ROUND('[7]2027'!G34,2) -> 28260.64 | H30: =ROUND('[7]2027'!H34,2) -> 27445.19 | I30: =ROUND('[7]2027'!I34,2) -> 27449.27 | J30: =ROUND('[7]2027'!J34,2) -> 24984.38 | K30: =ROUND('[7]2027'!K34,2) -> 23928.38 | L30: =ROUND('[7]2027'!L34,2) -> 22259.36 | ... AB30: =ROUND('[7]2027'!AB34,2) -> 69511.53
B31: 46539 | C31: Ordinario | D31: =+'[7]2027'!D35 -> 21 | E31: =ROUND('[7]2027'!E35,2) -> 5000 | F31: =ROUND('[7]2027'!F35,2) -> 5000 | G31: =ROUND('[7]2027'!G35,2) -> 5000 | H31: =ROUND('[7]2027'!H35,2) -> 5000 | I31: =ROUND('[7]2027'!I35,2) -> 5000 | J31: =ROUND('[7]2027'!J35,2) -> 5000 | K31: =ROUND('[7]2027'!K35,2) -> 5000 | L31: =ROUND('[7]2027'!L35,2) -> 5000 | ... AB31: =ROUND('[7]2027'!AB35,2) -> 27993.86 | AC31: =SUM(E31:AB31)*D31+SUM(E32:AB32)*D32+SUM(E33:AB33)*D33+SUM(E34:AB34)*D34 -> 6652499.5
B32: Feb | C32: Sábado | D32: =+'[7]2027'!D36 -> 4 | E32: =ROUND('[7]2027'!E36,2) -> 5000 | F32: =ROUND('[7]2027'!F36,2) -> 5000 | G32: =ROUND('[7]2027'!G36,2) -> 5000 | H32: =ROUND('[7]2027'!H36,2) -> 5000 | I32: =ROUND('[7]2027'!I36,2) -> 5000 | J32: =ROUND('[7]2027'!J36,2) -> 5000 | K32: =ROUND('[7]2027'!K36,2) -> 5000 | L32: =ROUND('[7]2027'!L36,2) -> 5000 | ... AB32: =ROUND('[7]2027'!AB36,2) -> 31643.58
B33: Feb | C33: Domingo | D33: =+'[7]2027'!D37 -> 4 | E33: =ROUND('[7]2027'!E37,2) -> 5000 | F33: =ROUND('[7]2027'!F37,2) -> 5000 | G33: =ROUND('[7]2027'!G37,2) -> 5000 | H33: =ROUND('[7]2027'!H37,2) -> 5000 | I33: =ROUND('[7]2027'!I37,2) -> 5000 | J33: =ROUND('[7]2027'!J37,2) -> 5000 | K33: =ROUND('[7]2027'!K37,2) -> 5000 | L33: =ROUND('[7]2027'!L37,2) -> 5000 | ... AB33: =ROUND('[7]2027'!AB37,2) -> 33862.82
B34: Feb | C34: Festivo | D34: =+'[7]2027'!D38 -> 1 | E34: =ROUND('[7]2027'!E38,2) -> 5000 | F34: =ROUND('[7]2027'!F38,2) -> 5000 | G34: =ROUND('[7]2027'!G38,2) -> 5000 | H34: =ROUND('[7]2027'!H38,2) -> 5000 | I34: =ROUND('[7]2027'!I38,2) -> 5000 | J34: =ROUND('[7]2027'!J38,2) -> 5000 | K34: =ROUND('[7]2027'!K38,2) -> 5000 | L34: =ROUND('[7]2027'!L38,2) -> 5000 | ... AB34: =ROUND('[7]2027'!AB38,2) -> 33862.82
B35: 46569 | C35: Ordinario | D35: =+'[7]2027'!D39 -> 20 | E35: =ROUND('[7]2027'!E39,2) -> 5000 | F35: =ROUND('[7]2027'!F39,2) -> 5000 | G35: =ROUND('[7]2027'!G39,2) -> 5000 | H35: =ROUND('[7]2027'!H39,2) -> 5000 | I35: =ROUND('[7]2027'!I39,2) -> 5000 | J35: =ROUND('[7]2027'!J39,2) -> 5000 | K35: =ROUND('[7]2027'!K39,2) -> 5000 | L35: =ROUND('[7]2027'!L39,2) -> 5000 | ... AB35: =ROUND('[7]2027'!AB39,2) -> 29212.65 | AC35: =SUM(E35:AB35)*D35+SUM(E36:AB36)*D36+SUM(E37:AB37)*D37+SUM(E38:AB38)*D38 -> 7378392.1
C36: Sábado | D36: =+'[7]2027'!D40 -> 5 | E36: =ROUND('[7]2027'!E40,2) -> 5000 | F36: =ROUND('[7]2027'!F40,2) -> 5000 | G36: =ROUND('[7]2027'!G40,2) -> 5000 | H36: =ROUND('[7]2027'!H40,2) -> 5000 | I36: =ROUND('[7]2027'!I40,2) -> 5000 | J36: =ROUND('[7]2027'!J40,2) -> 5000 | K36: =ROUND('[7]2027'!K40,2) -> 5000 | L36: =ROUND('[7]2027'!L40,2) -> 5000 | ... AB36: =ROUND('[7]2027'!AB40,2) -> 27935.75
C37: Domingo | D37: =+'[7]2027'!D41 -> 4 | E37: =ROUND('[7]2027'!E41,2) -> 5000 | F37: =ROUND('[7]2027'!F41,2) -> 5000 | G37: =ROUND('[7]2027'!G41,2) -> 5000 | H37: =ROUND('[7]2027'!H41,2) -> 5000 | I37: =ROUND('[7]2027'!I41,2) -> 5000 | J37: =ROUND('[7]2027'!J41,2) -> 5000 | K37: =ROUND('[7]2027'!K41,2) -> 5000 | L37: =ROUND('[7]2027'!L41,2) -> 5000 | ... AB37: =ROUND('[7]2027'!AB41,2) -> 32781.62
C38: Festivo | D38: =+'[7]2027'!D42 -> 2 | E38: =ROUND('[7]2027'!E42,2) -> 5000 | F38: =ROUND('[7]2027'!F42,2) -> 5000 | G38: =ROUND('[7]2027'!G42,2) -> 5000 | H38: =ROUND('[7]2027'!H42,2) -> 5000 | I38: =ROUND('[7]2027'!I42,2) -> 5000 | J38: =ROUND('[7]2027'!J42,2) -> 5000 | K38: =ROUND('[7]2027'!K42,2) -> 5000 | L38: =ROUND('[7]2027'!L42,2) -> 5000 | ... AB38: =ROUND('[7]2027'!AB42,2) -> 32781.62
