Workbook

Sheet Curv hora 2029 - 2033 (100%)
A1: EMPRESA DE ENERGIA DEL BAJO PUTUMAYO S.A. E.S.P.
A2: CANTIDAD DE ENERGIA REQUERIDA Y CURVA DE CARGA HORARIA
A3: CONVOCATORIA PÚBLICA CP-EBPCXXXXXXX
A4: TIPO DE OFERTA: CURVA
A5: PRODUCTO XXX
A6: CURVA TOTAL PROYECTADA
A7: MES/AÑO | B7: # DIAS | C7: TIPO DIA | D7: HORA | E7: H1 | F7: H2 | G7: H3 | H7: H4 | I7: H5 | J7: H6 | K7: H7 | L7: H8 | M7: H9 | N7: H10 | O7: H11 | P7: H12 | Q7: H13 | R7: H14 | S7: H15 | T7: H16 | U7: H17 | V7: H18 | W7: H19 | X7: H20 | Y7: H21 | Z7: H22 | AA7: H23 | AB7: H24 | AC7: TOTAL MES
D8: # DIAS | E8: kWh | F8: kWh | G8: kWh | H8: kWh | I8: kWh | J8: kWh | K8: kWh | L8: kWh | M8: kWh | N8: kWh | O8: kWh | P8: kWh | Q8: kWh | R8: kWh | S8: kWh | T8: kWh | U8: kWh | V8: kWh | W8: kWh | X8: kWh | Y8: kWh | Z8: kWh | AA8: kWh | AB8: kWh
A9: 47119 | B9: =DAY(EOMONTH(A9,0)) -> 31 | C9: D. habiles | D9: 21 | E9: 9352.53 | F9: 8760.62 | G9: 8373.71 | H9: 8115.02 | I9: 8039.79 | J9: 8197.09 | K9: 8244.38 | L9: 7594.04 | M9: 9083.98 | N9: 10355.06 | O9: 11529.11 | P9: 12381.98 | Q9: 12066.43 | R9: 12065.67 | S9: 12839.81 | T9: 12963.47 | U9: 12748.06 | V9: 14522.08 | W9: 15308.64 | X9: 16046.72 | Y9: 15310.08 | Z9: 14132.56 | AA9: 12470.98 | AB9: 10872.77 | AC9: =SUMPRODUCT((E9:AB11)*D9:D11) -> 8197571.2
C10: D. Sabados | D10: 4 | E10: 9240.11 | F10: 8669.79 | G10: 8274.66 | H10: 8032.67 | I10: 7941.15 | J10: 8068.15 | K10: 8187.95 | L10: 7370.42 | M10: 8669.87 | N10: 9633.99 | O10: 10494.43 | P10: 11160.3 | Q10: 11147.62 | R10: 11125.66 | S10: 11276.4 | T10: 11419.7 | U10: 11409.24 | V10: 13318.82 | W10: 14245.54 | X10: 15147.15 | Y10: 14464.91 | Z10: 13419.86 | AA10: 12101.98 | AB10: 10817.36
C11: D. dom y fest | D11: 6 | E11: 9635.86 | F11: 9063.68 | G11: 8473.37 | H11: 8285.67 | I11: 8064.2 | J11: 7940.69 | K11: 7786.3 | L11: 6774.89 | M11: 7956.32 | N11: 8860.49 | O11: 9729.11 | P11: 10468.96 | Q11: 10801.75 | R11: 10683.43 | S11: 10426.49 | T11: 10379.18 | U11: 10321.76 | V11: 12457.9 | W11: 13612.64 | X11: 14667.19 | Y11: 14101.08 | Z11: 13120.92 | AA11: 11812.34 | AB11: 10601.46
A12: 47150 | B12: =DAY(EOMONTH(A12,0)) -> 28 | C12: D. habiles | D12: 20 | E12: 9185.42 | F12: 8642.46 | G12: 8197.08 | H12: 8076.4 | I12: 8033.04 | J12: 8544.58 | K12: 9264.31 | L12: 8206.85 | M12: 9531.48 | N12: 10260.66 | O12: 11074.37 | P12: 11760.43 | Q12: 11276.84 | R12: 11663.75 | S12: 12561.6 | T12: 12775.16 | U12: 12743.52 | V12: 14674.06 | W12: 15328.59 | X12: 16220.86 | Y12: 15359.12 | Z12: 14029.09 | AA12: 11719.99 | AB12: 10521.57 | AC12: =SUMPRODUCT((E12:AB14)*D12:D14) -> 7424917.5
C13: D. Sabados | D13: 4 | E13: 8902.74 | F13: 8307.91 | G13: 7818.63 | H13: 7624.6 | I13: 7613.81 | J13: 7797.03 | K13: 8100.34 | L13: 7245.92 | M13: 8801 | N13: 9944.45 | O13: 10815.24 | P13: 11533.19 | Q13: 11449.22 | R13: 11225.06 | S13: 11175.03 | T13: 11504.49 | U13: 11617.81 | V13: 13624.67 | W13: 14697.59 | X13: 15624.81 | Y13: 14860.84 | Z13: 13682.25 | AA13: 12240.63 | AB13: 10792.09
C14: D. dom y fest | D14: 4 | E14: 9396.69 | F14: 8737.01 | G14: 8266.52 | H14: 7995.66 | I14: 7807.8 | J14: 7823.72 | K14: 7911.52 | L14: 7020.74 | M14: 8283.89 | N14: 9211.06 | O14: 10037.5 | P14: 10773.47 | Q14: 11142.74 | R14: 11136.04 | S14: 11053.72 | T14: 10937.22 | U14: 10958.59 | V14: 13011.77 | W14: 14045.43 | X14: 15178.82 | Y14: 14773.51 | Z14: 13863.35 | AA14: 12085.07 | AB14: 9522.04
A15: 47178 | B15: =DAY(EOMONTH(A15,0)) -> 31 | C15: D. habiles | D15: 19 | E15: 8825.54 | F15: 8257.38 | G15: 7932.7 | H15: 7769.41 | I15: 7796 | J15: 8346 | K15: 9068.02 | L15: 8056.82 | M15: 9301.37 | N15: 10178.65 | O15: 10898.11 | P15: 11515.06 | Q15: 10812.56 | R15: 11393.9 | S15: 12083.34 | T15: 12318.44 | U15: 12265.65 | V15: 14122.08 | W15: 14904.51 | X15: 15831.55 | Y15: 14929.56 | Z15: 13563.41 | AA15: 11651.8 | AB15: 10139.02 | AC15: =SUMPRODUCT((E15:AB17)*D15:D17) -> 7921661
C16: D. Sabados | D16: 5 | E16: 8178.81 | F16: 8000.96 | G16: 7654.9 | H16: 7434.25 | I16: 7436.32 | J16: 7677.44 | K16: 8101.07 | L16: 7278.42 | M16: 8822.34 | N16: 9751.43 | O16: 10415.98 | P16: 10939.24 | Q16: 10795.19 | R16: 10607.02 | S16: 10782.57 | T16: 10874.83 | U16: 11035.74 | V16: 13145.79 | W16: 14338.49 | X16: 15038.02 | Y16: 14203.16 | Z16: 13166.83 | AA16: 11769.13 | AB16: 10389.5
C17: D. dom y fest | D17: 7 | E17: 9151.28 | F17: 8546.45 | G17: 8120.57 | H17: 7877.19 | I17: 7783.37 | J17: 7811.86 | K17: 7934.96 | L17: 7039.54 | M17: 8220.98 | N17: 9043.71 | O17: 9613.93 | P17: 10056.15 | Q17: 10373.27 | R17: 10335.9 | S17: 10441.56 | T17: 10502.86 | U17: 10506.13 | V17: 12699.67 | W17: 13946.6 | X17: 14609.87 | Y17: 14075.16 | Z17: 13068.83 | AA17: 11593.56 | AB17: 10249.05
A18: 47209 | B18: =DAY(EOMONTH(A18,0)) -> 30 | C18: D. habiles | D18: 21 | E18: 8878.83 | F18: 8398.5 | G18: 8077.44 | H18: 7852.01 | I18: 7857.6 | J18: 8473.68 | K18: 9090.32 | L18: 8093.66 | M18: 9420.49 | N18: 10273.64 | O18: 10960.02 | P18: 11486.35 | Q18: 11196.91 | R18: 11421.5 | S18: 12364.27 | T18: 12674.41 | U18: 12704.03 | V18: 14658.74 | W18: 16040.24 | X18: 16307.14 | Y18: 15373.6 | Z18: 13977.08 | AA18: 12022.35 | AB18: 10384.65 | AC18: =SUMPRODUCT((E18:AB20)*D18:D20) -> 8010782.8
C19: D. Sabados | D19: 4 | E19: 9081.03 | F19: 8504.34 | G19: 8088.18 | H19: 7850.09 | I19: 7820.77 | J19: 8047.41 | K19: 8403.19 | L19: 7727.94 | M19: 9323.09 | N19: 10463.46 | O19: 11468.73 | P19: 12231.78 | Q19: 12260.95 | R19: 12246.41 | S19: 12136 | T19: 11895.67 | U19: 11789.02 | V19: 13754.67 | W19: 15085.73 | X19: 15632.7 | Y19: 15152.36 | Z19: 14092.71 | AA19: 12714.61 | AB19: 11469.46
C20: D. dom y fest | D20: 5 | E20: 9982.36 | F20: 9254.66 | G20: 8710.01 | H20: 8356.37 | I20: 8178.66 | J20: 8197.41 | K20: 8466.09 | L20: 7332.66 | M20: 8546.98 | N20: 9473.49 | O20: 10280.8 | P20: 11091.68 | Q20: 11577.56 | R20: 11603.52 | S20: 11650.9 | T20: 11689.8 | U20: 11581.91 | V20: 13565.62 | W20: 15333.85 | X20: 16101.03 | Y20: 15763.83 | Z20: 14431.3 | AA20: 12092.05 | AB20: 9554.44
A21: 47239 | B21: =DAY(EOMONTH(A21,0)) -> 31 | C21: D. habiles | D21: 21 | E21: 8374.9 | F21: 7841.24 | G21: 7534.72 | H21: 7309.91 | I21: 7244.49 | J21: 7868.41 | K21: 8719.25 | L21: 7826.07 | M21: 9091.55 | N21: 9859.47 | O21: 10691.21 | P21: 11275 | Q21: 10852.57 | R21: 10819.44 | S21: 11503.69 | T21: 11807.28 | U21: 11843.86 | V21: 14008.83 | W21: 15406.15 | X21: 15734.93 | Y21: 14789.08 | Z21: 13385.33 | AA21: 11360.78 | AB21: 9782.5 | AC21: =SUMPRODUCT((E21:AB23)*D21:D23) -> 7805466.7
C22: D. Sabados | D22: 4 | E22: 8584.28 | F22: 8042.96 | G22: 7615.64 | H22: 7405.23 | I22: 7338.26 | J22: 7602.14 | K22: 8042.18 | L22: 7415.92 | M22: 8741.39 | N22: 9743.57 | O22: 10398.14 | P22: 10953.44 | Q22: 10831.82 | R22: 10553.3 | S22: 10547.07 | T22: 10639.81 | U22: 10706.16 | V22: 13068.77 | W22: 14640.37 | X22: 14906.83 | Y22: 14051.07 | Z22: 12986.91 | AA22: 11482.77 | AB22: 10147.5
C23: D. dom y fest | D23: 6 | E23: 8941.97 | F23: 8197.45 | G23: 7785.75 | H23: 7526.43 | I23: 7378.69 | J23: 7461.93 | K23: 7734.01 | L23: 6833.57 | M23: 8113.41 | N23: 9125.7 | O23: 9931.73 | P23: 10515.65 | Q23: 10658.15 | R23: 10575.96 | S23: 10424.88 | T23: 11115.94 | U23: 10873.09 | V23: 12985.12 | W23: 13775.56 | X23: 14526.8 | Y23: 14623.65 | Z23: 13414.7 | AA23: 11681.59 | AB23: 10155.06
A24: 47270 | B24: =DAY(EOMONTH(A24,0)) -> 30 | C24: D. habiles | D24: 19 | E24: 7748.15 | F24: 7241.93 | G24: 7011.54 | H24: 6881.51 | I24: 6914.73 | J24: 7524.55 | K24: 8262.72 | L24: 7304.69 | M24: 8520.78 | N24: 9363.03 | O24: 9950.11 | P24: 10414.55 | Q24: 9925.97 | R24: 9988.58 | S24: 10644.51 | T24: 10849.36 | U24: 10977.06 | V24: 13158.87 | W24: 14386.88 | X24: 14741.91 | Y24: 13747.62 | Z24: 12277.45 | AA24: 10416.43 | AB24: 8899.7 | AC24: =SUMPRODUCT((E24:AB26)*D24:D26) -> 7057111.2
C25: D. Sabados | D25: 5 | E25: 7976.15 | F25: 7367.64 | G25: 6972.42 | H25: 6778.38 | I25: 6790.95 | J25: 7004.02 | K25: 7465.64 | L25: 6839.33 | M25: 8492.01 | N25: 9699.18 | O25: 10413.63 | P25: 10876.91 | Q25: 10659.42 | R25: 10569.5 | S25: 10604.74 | T25: 10457.99 | U25: 10441.76 | V25: 12678.76 | W25: 14178.95 | X25: 14529.53 | Y25: 13575.82 | Z25: 12389.28 | AA25: 10911.36 | AB25: 9532.81
C26: D. dom y fest | D26: 6 | E26: 8065.32 | F26: 7539.05 | G26: 7165.34 | H26: 6964.4 | I26: 6846.21 | J26: 6908.08 | K26: 7157.4 | L26: 6339.92 | M26: 7828.23 | N26: 8744.63 | O26: 9544.5 | P26: 10102.27 | Q26: 10447.23 | R26: 10376.34 | S26: 10179.41 | T26: 9853.12 | U26: 9662.76 | V26: 12146.44 | W26: 13453.72 | X26: 13733.04 | Y26: 13169.79 | Z26: 12013.5 | AA26: 10355.06 | AB26: 8934.29
A27: 47300 | B27: =DAY(EOMONTH(A27,0)) -> 31 | C27: D. habiles | D27: 20 | E27: 8057.5 | F27: 7527.44 | G27: 7248.25 | H27: 7083.7 | I27: 7108.55 | J27: 7718.06 | K27: 8418.36 | L27: 7558.56 | M27: 8959.55 | N27: 9839.25 | O27: 10565.51 | P27: 11271.82 | Q27: 10979.64 | R27: 10967.89 | S27: 11647.61 | T27: 12005.64 | U27: 12016.98 | V27: 14160.59 | W27: 15174.74 | X27: 15678.1 | Y27: 14690 | Z27: 13226.72 | AA27: 11233.26 | AB27: 9573.94 | AC27: =SUMPRODUCT((E27:AB29)*D27:D29) -> 7607010.6
C28: D. Sabados | D28: 4 | E28: 8237.52 | F28: 7650.15 | G28: 7291.27 | H28: 7129.78 | I28: 7064.79 | J28: 7298.92 | K28: 7672.91 | L28: 7139.92 | M28: 8634.83 | N28: 9636.83 | O28: 10292.24 | P28: 10837.69 | Q28: 10607.06 | R28: 10492.88 | S28: 10626.81 | T28: 10859.47 | U28: 10769.62 | V28: 12885.87 | W28: 14303.46 | X28: 14954.53 | Y28: 13959.49 | Z28: 12627.5 | AA28: 11044.35 | AB28: 9519.73
C29: D. dom y fest | D29: 7 | E29: 8233.91 | F29: 7651.46 | G29: 7264.21 | H29: 7036.78 | I29: 6928.96 | J29: 7049.1 | K29: 7264.49 | L29: 6476.14 | M29: 7759.78 | N29: 8724.65 | O29: 9317.09 | P29: 9826.52 | Q29: 10032.21 | R29: 10010.92 | S29: 10004.99 | T29: 9765.42 | U29: 9640.77 | V29: 11647.94 | W29: 13040.49 | X29: 13868.73 | Y29: 13232.36 | Z29: 12131.95 | AA29: 10556.14 | AB29: 9195.98
A30: 47331 | B30: =DAY(EOMONTH(A30,0)) -> 31 | C30: D. habiles | D30: 21 | E30: 8454.53 | F30: 7967.28 | G30: 7666.07 | H30: 7475.15 | I30: 7500.35 | J30: 7828.88 | K30: 8737.28 | L30: 7896.36 | M30: 9153.15 | N30: 10075.79 | O30: 10966.81 | P30: 11625.1 | Q30: 11474.75 | R30: 11765 | S30: 12670.83 | T30: 13217.27 | U30: 13209.54 | V30: 14823.46 | W30: 15877.15 | X30: 16671.31 | Y30: 15703.87 | Z30: 14185.37 | AA30: 12093.85 | AB30: 10317.87 | AC30: =SUMPRODUCT((E30:AB32)*D30:D32) -> 8180374.5
C31: D. Sabados | D31: 4 | E31: 9373.68 | F31: 8731.19 | G31: 7885.62 | H31: 8211.2 | I31: 7932.79 | J31: 8072.15 | K31: 8399.88 | L31: 8249.76 | M31: 9704.81 | N31: 10948.35 | O31: 11842.89 | P31: 12562.42 | Q31: 12439.56 | R31: 12401.41 | S31: 12571.7 | T31: 12331.83 | U31: 12352.67 | V31: 14266.09 | W31: 15741.47 | X31: 16334.43 | Y31: 15350.83 | Z31: 14132.79 | AA31: 12492.17 | AB31: 11112.29
C32: D. dom y fest | D32: 6 | E32: 9173.84 | F32: 8517.31 | G32: 8096.92 | H32: 7839.45 | I32: 7554.06 | J32: 7703.72 | K32: 8058.52 | L32: 7169.39 | M32: 8454.07 | N32: 9227.34 | O32: 9938.79 | P32: 10927.88 | Q32: 10821.02 | R32: 10559.08 | S32: 10589.27 | T32: 10309.22 | U32: 10396.54 | V32: 12711.91 | W32: 14344.32 | X32: 14741.09 | Y32: 14005.52 | Z32: 13029.55 | AA32: 11310.55 | AB32: 9872.17
A33: 47362 | B33: =DAY(EOMONTH(A33,0)) -> 30 | C33: D. habiles | D33: 20 | E33: 9058.46 | F33: 8449.98 | G33: 8192.14 | H33: 7959.4 | I33: 7836.68 | J33: 8236.17 | K33: 9226.37 | L33: 8302.29 | M33: 9743.35 | N33: 10700.77 | O33: 11582.93 | P33: 12192.46 | Q33: 11666.52 | R33: 11835.6 | S33: 12615.86 | T33: 12918.79 | U33: 13021.38 | V33: 15083.35 | W33: 16445.42 | X33: 16845.99 | Y33: 15644.52 | Z33: 14267.01 | AA33: 12317.8 | AB33: 10594.04 | AC33: =SUMPRODUCT((E33:AB35)*D33:D35) -> 8099220.8
C34: D. Sabados | D34: 5 | E34: 9336.72 | F34: 8704.47 | G34: 8251.85 | H34: 8004.82 | I34: 7908.96 | J34: 8072.31 | K34: 8581.43 | L34: 8191.48 | M34: 9798.94 | N34: 11121.74 | O34: 12251.96 | P34: 13108.44 | Q34: 12391.38 | R34: 13113.81 | S34: 13440.55 | T34: 13476.29 | U34: 12846.87 | V34: 15026.08 | W34: 16632.4 | X34: 16782.6 | Y34: 15801.89 | Z34: 14687.05 | AA34: 13076.05 | AB34: 11603.47
C35: D. dom y fest | D35: 5 | E35: 10249.1 | F35: 9543.95 | G35: 9016.31 | H35: 8689.14 | I35: 8409.19 | J35: 8326 | K35: 7949.24 | L35: 6746.02 | M35: 8001.57 | N35: 9061.06 | O35: 9636.37 | P35: 10132.36 | Q35: 10372.17 | R35: 9853.55 | S35: 8766.91 | T35: 8025.26 | U35: 8070.25 | V35: 11231.29 | W35: 12768.29 | X35: 14501.2 | Y35: 14081.72 | Z35: 13260.71 | AA35: 11697.96 | AB35: 10293.86
A36: 47392 | B36: =DAY(EOMONTH(A36,0)) -> 31 | C36: D. habiles | D36: 22 | E36: 9299.58 | F36: 8765.68 | G36: 8421.73 | H36: 8167.55 | I36: 8062.48 | J36: 8421.49 | K36: 9156.36 | L36: 8472.14 | M36: 10000.2 | N36: 11121.35 | O36: 12159.47 | P36: 13058.56 | Q36: 12839.19 | R36: 13065.43 | S36: 13570.92 | T36: 13912.8 | U36: 13827.03 | V36: 15753.65 | W36: 17108.14 | X36: 17087.2 | Y36: 15866.6 | Z36: 14376.37 | AA36: 12480.79 | AB36: 10972.23 | AC36: =SUMPRODUCT((E36:AB38)*D36:D38) -> 8618355.4
C37: D. Sabados | D37: 4 | E37: 9939.12 | F37: 9295.72 | G37: 8855.47 | H37: 8555.73 | I37: 8487.77 | J37: 8549.18 | K37: 9049.07 | L37: 8591.73 | M37: 10409.66 | N37: 11742.71 | O37: 12830.9 | P37: 13024.66 | Q37: 12368.27 | R37: 11550.37 | S37: 11693.13 | T37: 11598.2 | U37: 11131.92 | V37: 13387.07 | W37: 15118.22 | X37: 15240.25 | Y37: 14290.62 | Z37: 13159.46 | AA37: 11737.57 | AB37: 10428.57
C38: D. dom y fest | D38: 5 | E38: 9187.36 | F38: 8601.84 | G38: 8190.83 | H38: 7889.98 | I38: 7715.96 | J38: 7364.24 | K38: 7948.03 | L38: 7183.4 | M38: 8346.75 | N38: 9273.51 | O38: 10157.08 | P38: 10857.42 | Q38: 11124.24 | R38: 11174.18 | S38: 11069.52 | T38: 11023.8 | U38: 11006.78 | V38: 13158.44 | W38: 14981.99 | X38: 14426.73 | Y38: 13950.27 | Z38: 12411.36 | AA38: 11493.32 | AB38: 10051.21
A39: 47423 | B39: =DAY(EOMONTH(A39,0)) -> 30 | C39: D. habiles | D39: 20 | E39: 8781.6 | F39: 8213.04 | G39: 8008.78 | H39: 7765.47 | I39: 7829.83 | J39: 8168.78 | K39: 9077.21 | L39: 8328.23 | M39: 9797.91 | N39: 10742.95 | O39: 11646.75 | P39: 12463.99 | Q39: 11967.47 | R39: 12338.35 | S39: 13238.15 | T39: 13220.43 | U39: 13214.36 | V39: 15198.04 | W39: 16588.96 | X39: 16437.75 | Y39: 15335.45 | Z39: 13878.92 | AA39: 11928.27 | AB39: 10366.84 | AC39: =SUMPRODUCT((E39:AB41)*D39:D41) -> 8046799.7
C40: D. Sabados | D40: 4 | E40: 9178.67 | F40: 8627.53 | G40: 8212.42 | H40: 7854.69 | I40: 7665.35 | J40: 7995 | K40: 8356.65 | L40: 7737.56 | M40: 9313.47 | N40: 10140.51 | O40: 10847.52 | P40: 11301.83 | Q40: 11535.69 | R40: 11612.56 | S40: 11912.15 | T40: 12064.4 | U40: 12062.93 | V40: 14322.36 | W40: 16046.26 | X40: 16001.16 | Y40: 14889.52 | Z40: 13671.2 | AA40: 12231.98 | AB40: 10483.84
...

Sheet Curv hora 2029 - 2033
A1: EMPRESA DE ENERGIA DEL BAJO PUTUMAYO S.A. E.S.P.
A2: CANTIDAD DE ENERGIA REQUERIDA Y CURVA DE CARGA HORARIA
A3: CONVOCATORIA PÚBLICA CP-EBPC2025-003
A4: TIPO DE OFERTA: CURVA
A5: PRODUCTO 01
A6: CURVA TOTAL PROYECTADA
A7: MES/AÑO | B7: # DIAS | C7: TIPO DIA | D7: HORA | E7: H1 | F7: H2 | G7: H3 | H7: H4 | I7: H5 | J7: H6 | K7: H7 | L7: H8 | M7: H9 | N7: H10 | O7: H11 | P7: H12 | Q7: H13 | R7: H14 | S7: H15 | T7: H16 | U7: H17 | V7: H18 | W7: H19 | X7: H20 | Y7: H21 | Z7: H22 | AA7: H23 | AB7: H24 | AC7: TOTAL MES
D8: # DIAS | E8: kWh | F8: kWh | G8: kWh | H8: kWh | I8: kWh | J8: kWh | K8: kWh | L8: kWh | M8: kWh | N8: kWh | O8: kWh | P8: kWh | Q8: kWh | R8: kWh | S8: kWh | T8: kWh | U8: kWh | V8: kWh | W8: kWh | X8: kWh | Y8: kWh | Z8: kWh | AA8: kWh | AB8: kWh
A9: 47119 | B9: =DAY(EOMONTH(A9,0)) -> 31 | C9: D. habiles | D9: 21 | E9: =+'Curv hora 2029 - 2033 (100%)'!E9*0.5 -> 4676.265 | F9: =+'Curv hora 2029 - 2033 (100%)'!F9*0.5 -> 4380.31 | G9: =+'Curv hora 2029 - 2033 (100%)'!G9*0.5 -> 4186.855 | H9: =+'Curv hora 2029 - 2033 (100%)'!H9*0.5 -> 4057.51 | I9: =+'Curv hora 2029 - 2033 (100%)'!I9*0.5 -> 4019.895 | J9: =+'Curv hora 2029 - 2033 (100%)'!J9*0.5 -> 4098.545 | K9: =+'Curv hora 2029 - 2033 (100%)'!K9*0.5 -> 4122.19 | L9: =+'Curv hora 2029 - 2033 (100%)'!L9*0.5 -> 3797.02 | ... AB9: =+'Curv hora 2029 - 2033 (100%)'!AB9*0.5 -> 5436.385 | AC9: =SUMPRODUCT((E9:AB11)*D9:D11) -> 4098785.6
C10: D. Sabados | D10: 4 | E10: =+'Curv hora 2029 - 2033 (100%)'!E10*0.5 -> 4620.055 | F10: =+'Curv hora 2029 - 2033 (100%)'!F10*0.5 -> 4334.895 | G10: =+'Curv hora 2029 - 2033 (100%)'!G10*0.5 -> 4137.33 | H10: =+'Curv hora 2029 - 2033 (100%)'!H10*0.5 -> 4016.335 | I10: =+'Curv hora 2029 - 2033 (100%)'!I10*0.5 -> 3970.575 | J10: =+'Curv hora 2029 - 2033 (100%)'!J10*0.5 -> 4034.075 | K10: =+'Curv hora 2029 - 2033 (100%)'!K10*0.5 -> 4093.975 | L10: =+'Curv hora 2029 - 2033 (100%)'!L10*0.5 -> 3685.21 | ... AB10: =+'Curv hora 2029 - 2033 (100%)'!AB10*0.5 -> 5408.68
C11: D. dom y fest | D11: 6 | E11: =+'Curv hora 2029 - 2033 (100%)'!E11*0.5 -> 4817.93 | F11: =+'Curv hora 2029 - 2033 (100%)'!F11*0.5 -> 4531.84 | G11: =+'Curv hora 2029 - 2033 (100%)'!G11*0.5 -> 4236.685 | H11: =+'Curv hora 2029 - 2033 (100%)'!H11*0.5 -> 4142.835 | I11: =+'Curv hora 2029 - 2033 (100%)'!I11*0.5 -> 4032.1 | J11: =+'Curv hora 2029 - 2033 (100%)'!J11*0.5 -> 3970.345 | K11: =+'Curv hora 2029 - 2033 (100%)'!K11*0.5 -> 3893.15 | L11: =+'Curv hora 2029 - 2033 (100%)'!L11*0.5 -> 3387.445 | ... AB11: =+'Curv hora 2029 - 2033 (100%)'!AB11*0.5 -> 5300.73
A12: 47150 | B12: =DAY(EOMONTH(A12,0)) -> 28 | C12: D. habiles | D12: 20 | E12: =+'Curv hora 2029 - 2033 (100%)'!E12*0.5 -> 4592.71 | F12: =+'Curv hora 2029 - 2033 (100%)'!F12*0.5 -> 4321.23 | G12: =+'Curv hora 2029 - 2033 (100%)'!G12*0.5 -> 4098.54 | H12: =+'Curv hora 2029 - 2033 (100%)'!H12*0.5 -> 4038.2 | I12: =+'Curv hora 2029 - 2033 (100%)'!I12*0.5 -> 4016.52 | J12: =+'Curv hora 2029 - 2033 (100%)'!J12*0.5 -> 4272.29 | K12: =+'Curv hora 2029 - 2033 (100%)'!K12*0.5 -> 4632.155 | L12: =+'Curv hora 2029 - 2033 (100%)'!L12*0.5 -> 4103.425 | ... AB12: =+'Curv hora 2029 - 2033 (100%)'!AB12*0.5 -> 5260.785 | AC12: =SUMPRODUCT((E12:AB14)*D12:D14) -> 3712458.8
C13: D. Sabados | D13: 4 | E13: =+'Curv hora 2029 - 2033 (100%)'!E13*0.5 -> 4451.37 | F13: =+'Curv hora 2029 - 2033 (100%)'!F13*0.5 -> 4153.955 | G13: =+'Curv hora 2029 - 2033 (100%)'!G13*0.5 -> 3909.315 | H13: =+'Curv hora 2029 - 2033 (100%)'!H13*0.5 -> 3812.3 | I13: =+'Curv hora 2029 - 2033 (100%)'!I13*0.5 -> 3806.905 | J13: =+'Curv hora 2029 - 2033 (100%)'!J13*0.5 -> 3898.515 | K13: =+'Curv hora 2029 - 2033 (100%)'!K13*0.5 -> 4050.17 | L13: =+'Curv hora 2029 - 2033 (100%)'!L13*0.5 -> 3622.96 | ... AB13: =+'Curv hora 2029 - 2033 (100%)'!AB13*0.5 -> 5396.045
C14: D. dom y fest | D14: 4 | E14: =+'Curv hora 2029 - 2033 (100%)'!E14*0.5 -> 4698.345 | F14: =+'Curv hora 2029 - 2033 (100%)'!F14*0.5 -> 4368.505 | G14: =+'Curv hora 2029 - 2033 (100%)'!G14*0.5 -> 4133.26 | H14: =+'Curv hora 2029 - 2033 (100%)'!H14*0.5 -> 3997.83 | I14: =+'Curv hora 2029 - 2033 (100%)'!I14*0.5 -> 3903.9 | J14: =+'Curv hora 2029 - 2033 (100%)'!J14*0.5 -> 3911.86 | K14: =+'Curv hora 2029 - 2033 (100%)'!K14*0.5 -> 3955.76 | L14: =+'Curv hora 2029 - 2033 (100%)'!L14*0.5 -> 3510.37 | ... AB14: =+'Curv hora 2029 - 2033 (100%)'!AB14*0.5 -> 4761.02
A15: 47178 | B15: =DAY(EOMONTH(A15,0)) -> 31 | C15: D. habiles | D15: 19 | E15: =+'Curv hora 2029 - 2033 (100%)'!E15*0.5 -> 4412.77 | F15: =+'Curv hora 2029 - 2033 (100%)'!F15*0.5 -> 4128.69 | G15: =+'Curv hora 2029 - 2033 (100%)'!G15*0.5 -> 3966.35 | H15: =+'Curv hora 2029 - 2033 (100%)'!H15*0.5 -> 3884.705 | I15: =+'Curv hora 2029 - 2033 (100%)'!I15*0.5 -> 3898 | J15: =+'Curv hora 2029 - 2033 (100%)'!J15*0.5 -> 4173 | K15: =+'Curv hora 2029 - 2033 (100%)'!K15*0.5 -> 4534.01 | L15: =+'Curv hora 2029 - 2033 (100%)'!L15*0.5 -> 4028.41 | ... AB15: =+'Curv hora 2029 - 2033 (100%)'!AB15*0.5 -> 5069.51 | AC15: =SUMPRODUCT((E15:AB17)*D15:D17) -> 3960830.5
C16: D. Sabados | D16: 5 | E16: =+'Curv hora 2029 - 2033 (100%)'!E16*0.5 -> 4089.405 | F16: =+'Curv hora 2029 - 2033 (100%)'!F16*0.5 -> 4000.48 | G16: =+'Curv hora 2029 - 2033 (100%)'!G16*0.5 -> 3827.45 | H16: =+'Curv hora 2029 - 2033 (100%)'!H16*0.5 -> 3717.125 | I16: =+'Curv hora 2029 - 2033 (100%)'!I16*0.5 -> 3718.16 | J16: =+'Curv hora 2029 - 2033 (100%)'!J16*0.5 -> 3838.72 | K16: =+'Curv hora 2029 - 2033 (100%)'!K16*0.5 -> 4050.535 | L16: =+'Curv hora 2029 - 2033 (100%)'!L16*0.5 -> 3639.21 | ... AB16: =+'Curv hora 2029 - 2033 (100%)'!AB16*0.5 -> 5194.75
C17: D. dom y fest | D17: 7 | E17: =+'Curv hora 2029 - 2033 (100%)'!E17*0.5 -> 4575.64 | F17: =+'Curv hora 2029 - 2033 (100%)'!F17*0.5 -> 4273.225 | G17: =+'Curv hora 2029 - 2033 (100%)'!G17*0.5 -> 4060.285 | H17: =+'Curv hora 2029 - 2033 (100%)'!H17*0.5 -> 3938.595 | I17: =+'Curv hora 2029 - 2033 (100%)'!I17*0.5 -> 3891.685 | J17: =+'Curv hora 2029 - 2033 (100%)'!J17*0.5 -> 3905.93 | K17: =+'Curv hora 2029 - 2033 (100%)'!K17*0.5 -> 3967.48 | L17: =+'Curv hora 2029 - 2033 (100%)'!L17*0.5 -> 3519.77 | ... AB17: =+'Curv hora 2029 - 2033 (100%)'!AB17*0.5 -> 5124.525
A18: 47209 | B18: =DAY(EOMONTH(A18,0)) -> 30 | C18: D. habiles | D18: 21 | E18: =+'Curv hora 2029 - 2033 (100%)'!E18*0.5 -> 4439.415 | F18: =+'Curv hora 2029 - 2033 (100%)'!F18*0.5 -> 4199.25 | G18: =+'Curv hora 2029 - 2033 (100%)'!G18*0.5 -> 4038.72 | H18: =+'Curv hora 2029 - 2033 (100%)'!H18*0.5 -> 3926.005 | I18: =+'Curv hora 2029 - 2033 (100%)'!I18*0.5 -> 3928.8 | J18: =+'Curv hora 2029 - 2033 (100%)'!J18*0.5 -> 4236.84 | K18: =+'Curv hora 2029 - 2033 (100%)'!K18*0.5 -> 4545.16 | L18: =+'Curv hora 2029 - 2033 (100%)'!L18*0.5 -> 4046.83 | ... AB18: =+'Curv hora 2029 - 2033 (100%)'!AB18*0.5 -> 5192.325 | AC18: =SUMPRODUCT((E18:AB20)*D18:D20) -> 4005391.4
C19: D. Sabados | D19: 4 | E19: =+'Curv hora 2029 - 2033 (100%)'!E19*0.5 -> 4540.515 | F19: =+'Curv hora 2029 - 2033 (100%)'!F19*0.5 -> 4252.17 | G19: =+'Curv hora 2029 - 2033 (100%)'!G19*0.5 -> 4044.09 | H19: =+'Curv hora 2029 - 2033 (100%)'!H19*0.5 -> 3925.045 | I19: =+'Curv hora 2029 - 2033 (100%)'!I19*0.5 -> 3910.385 | J19: =+'Curv hora 2029 - 2033 (100%)'!J19*0.5 -> 4023.705 | K19: =+'Curv hora 2029 - 2033 (100%)'!K19*0.5 -> 4201.595 | L19: =+'Curv hora 2029 - 2033 (100%)'!L19*0.5 -> 3863.97 | ... AB19: =+'Curv hora 2029 - 2033 (100%)'!AB19*0.5 -> 5734.73
C20: D. dom y fest | D20: 5 | E20: =+'Curv hora 2029 - 2033 (100%)'!E20*0.5 -> 4991.18 | F20: =+'Curv hora 2029 - 2033 (100%)'!F20*0.5 -> 4627.33 | G20: =+'Curv hora 2029 - 2033 (100%)'!G20*0.5 -> 4355.005 | H20: =+'Curv hora 2029 - 2033 (100%)'!H20*0.5 -> 4178.185 | I20: =+'Curv hora 2029 - 2033 (100%)'!I20*0.5 -> 4089.33 | J20: =+'Curv hora 2029 - 2033 (100%)'!J20*0.5 -> 4098.705 | K20: =+'Curv hora 2029 - 2033 (100%)'!K20*0.5 -> 4233.045 | L20: =+'Curv hora 2029 - 2033 (100%)'!L20*0.5 -> 3666.33 | ... AB20: =+'Curv hora 2029 - 2033 (100%)'!AB20*0.5 -> 4777.22
A21: 47239 | B21: =DAY(EOMONTH(A21,0)) -> 31 | C21: D. habiles | D21: 21 | E21: =+'Curv hora 2029 - 2033 (100%)'!E21*0.5 -> 4187.45 | F21: =+'Curv hora 2029 - 2033 (100%)'!F21*0.5 -> 3920.62 | G21: =+'Curv hora 2029 - 2033 (100%)'!G21*0.5 -> 3767.36 | H21: =+'Curv hora 2029 - 2033 (100%)'!H21*0.5 -> 3654.955 | I21: =+'Curv hora 2029 - 2033 (100%)'!I21*0.5 -> 3622.245 | J21: =+'Curv hora 2029 - 2033 (100%)'!J21*0.5 -> 3934.205 | K21: =+'Curv hora 2029 - 2033 (100%)'!K21*0.5 -> 4359.625 | L21: =+'Curv hora 2029 - 2033 (100%)'!L21*0.5 -> 3913.035 | ... AB21: =+'Curv hora 2029 - 2033 (100%)'!AB21*0.5 -> 4891.25 | AC21: =SUMPRODUCT((E21:AB23)*D21:D23) -> 3902733.4
C22: D. Sabados | D22: 4 | E22: =+'Curv hora 2029 - 2033 (100%)'!E22*0.5 -> 4292.14 | F22: =+'Curv hora 2029 - 2033 (100%)'!F22*0.5 -> 4021.48 | G22: =+'Curv hora 2029 - 2033 (100%)'!G22*0.5 -> 3807.82 | H22: =+'Curv hora 2029 - 2033 (100%)'!H22*0.5 -> 3702.615 | I22: =+'Curv hora 2029 - 2033 (100%)'!I22*0.5 -> 3669.13 | J22: =+'Curv hora 2029 - 2033 (100%)'!J22*0.5 -> 3801.07 | K22: =+'Curv hora 2029 - 2033 (100%)'!K22*0.5 -> 4021.09 | L22: =+'Curv hora 2029 - 2033 (100%)'!L22*0.5 -> 3707.96 | ... AB22: =+'Curv hora 2029 - 2033 (100%)'!AB22*0.5 -> 5073.75
C23: D. dom y fest | D23: 6 | E23: =+'Curv hora 2029 - 2033 (100%)'!E23*0.5 -> 4470.985 | F23: =+'Curv hora 2029 - 2033 (100%)'!F23*0.5 -> 4098.725 | G23: =+'Curv hora 2029 - 2033 (100%)'!G23*0.5 -> 3892.875 | H23: =+'Curv hora 2029 - 2033 (100%)'!H23*0.5 -> 3763.215 | I23: =+'Curv hora 2029 - 2033 (100%)'!I23*0.5 -> 3689.345 | J23: =+'Curv hora 2029 - 2033 (100%)'!J23*0.5 -> 3730.965 | K23: =+'Curv hora 2029 - 2033 (100%)'!K23*0.5 -> 3867.005 | L23: =+'Curv hora 2029 - 2033 (100%)'!L23*0.5 -> 3416.785 | ... AB23: =+'Curv hora 2029 - 2033 (100%)'!AB23*0.5 -> 5077.53
A24: 47270 | B24: =DAY(EOMONTH(A24,0)) -> 30 | C24: D. habiles | D24: 19 | E24: =+'Curv hora 2029 - 2033 (100%)'!E24*0.5 -> 3874.075 | F24: =+'Curv hora 2029 - 2033 (100%)'!F24*0.5 -> 3620.965 | G24: =+'Curv hora 2029 - 2033 (100%)'!G24*0.5 -> 3505.77 | H24: =+'Curv hora 2029 - 2033 (100%)'!H24*0.5 -> 3440.755 | I24: =+'Curv hora 2029 - 2033 (100%)'!I24*0.5 -> 3457.365 | J24: =+'Curv hora 2029 - 2033 (100%)'!J24*0.5 -> 3762.275 | K24: =+'Curv hora 2029 - 2033 (100%)'!K24*0.5 -> 4131.36 | L24: =+'Curv hora 2029 - 2033 (100%)'!L24*0.5 -> 3652.345 | ... AB24: =+'Curv hora 2029 - 2033 (100%)'!AB24*0.5 -> 4449.85 | AC24: =SUMPRODUCT((E24:AB26)*D24:D26) -> 3528555.6
C25: D. Sabados | D25: 5 | E25: =+'Curv hora 2029 - 2033 (100%)'!E25*0.5 -> 3988.075 | F25: =+'Curv hora 2029 - 2033 (100%)'!F25*0.5 -> 3683.82 | G25: =+'Curv hora 2029 - 2033 (100%)'!G25*0.5 -> 3486.21 | H25: =+'Curv hora 2029 - 2033 (100%)'!H25*0.5 -> 3389.19 | I25: =+'Curv hora 2029 - 2033 (100%)'!I25*0.5 -> 3395.475 | J25: =+'Curv hora 2029 - 2033 (100%)'!J25*0.5 -> 3502.01 | K25: =+'Curv hora 2029 - 2033 (100%)'!K25*0.5 -> 3732.82 | L25: =+'Curv hora 2029 - 2033 (100%)'!L25*0.5 -> 3419.665 | ... AB25: =+'Curv hora 2029 - 2033 (100%)'!AB25*0.5 -> 4766.405
C26: D. dom y fest | D26: 6 | E26: =+'Curv hora 2029 - 2033 (100%)'!E26*0.5 -> 4032.66 | F26: =+'Curv hora 2029 - 2033 (100%)'!F26*0.5 -> 3769.525 | G26: =+'Curv hora 2029 - 2033 (100%)'!G26*0.5 -> 3582.67 | H26: =+'Curv hora 2029 - 2033 (100%)'!H26*0.5 -> 3482.2 | I26: =+'Curv hora 2029 - 2033 (100%)'!I26*0.5 -> 3423.105 | J26: =+'Curv hora 2029 - 2033 (100%)'!J26*0.5 -> 3454.04 | K26: =+'Curv hora 2029 - 2033 (100%)'!K26*0.5 -> 3578.7 | L26: =+'Curv hora 2029 - 2033 (100%)'!L26*0.5 -> 3169.96 | ... AB26: =+'Curv hora 2029 - 2033 (100%)'!AB26*0.5 -> 4467.145
A27: 47300 | B27: =DAY(EOMONTH(A27,0)) -> 31 | C27: D. habiles | D27: 20 | E27: =+'Curv hora 2029 - 2033 (100%)'!E27*0.5 -> 4028.75 | F27: =+'Curv hora 2029 - 2033 (100%)'!F27*0.5 -> 3763.72 | G27: =+'Curv hora 2029 - 2033 (100%)'!G27*0.5 -> 3624.125 | H27: =+'Curv hora 2029 - 2033 (100%)'!H27*0.5 -> 3541.85 | I27: =+'Curv hora 2029 - 2033 (100%)'!I27*0.5 -> 3554.275 | J27: =+'Curv hora 2029 - 2033 (100%)'!J27*0.5 -> 3859.03 | K27: =+'Curv hora 2029 - 2033 (100%)'!K27*0.5 -> 4209.18 | L27: =+'Curv hora 2029 - 2033 (100%)'!L27*0.5 -> 3779.28 | ... AB27: =+'Curv hora 2029 - 2033 (100%)'!AB27*0.5 -> 4786.97 | AC27: =SUMPRODUCT((E27:AB29)*D27:D29) -> 3803505.3
C28: D. Sabados | D28: 4 | E28: =+'Curv hora 2029 - 2033 (100%)'!E28*0.5 -> 4118.76 | F28: =+'Curv hora 2029 - 2033 (100%)'!F28*0.5 -> 3825.075 | G28: =+'Curv hora 2029 - 2033 (100%)'!G28*0.5 -> 3645.635 | H28: =+'Curv hora 2029 - 2033 (100%)'!H28*0.5 -> 3564.89 | I28: =+'Curv hora 2029 - 2033 (100%)'!I28*0.5 -> 3532.395 | J28: =+'Curv hora 2029 - 2033 (100%)'!J28*0.5 -> 3649.46 | K28: =+'Curv hora 2029 - 2033 (100%)'!K28*0.5 -> 3836.455 | L28: =+'Curv hora 2029 - 2033 (100%)'!L28*0.5 -> 3569.96 | ... AB28: =+'Curv hora 2029 - 2033 (100%)'!AB28*0.5 -> 4759.865
C29: D. dom y fest | D29: 7 | E29: =+'Curv hora 2029 - 2033 (100%)'!E29*0.5 -> 4116.955 | F29: =+'Curv hora 2029 - 2033 (100%)'!F29*0.5 -> 3825.73 | G29: =+'Curv hora 2029 - 2033 (100%)'!G29*0.5 -> 3632.105 | H29: =+'Curv hora 2029 - 2033 (100%)'!H29*0.5 -> 3518.39 | I29: =+'Curv hora 2029 - 2033 (100%)'!I29*0.5 -> 3464.48 | J29: =+'Curv hora 2029 - 2033 (100%)'!J29*0.5 -> 3524.55 | K29: =+'Curv hora 2029 - 2033 (100%)'!K29*0.5 -> 3632.245 | L29: =+'Curv hora 2029 - 2033 (100%)'!L29*0.5 -> 3238.07 | ... AB29: =+'Curv hora 2029 - 2033 (100%)'!AB29*0.5 -> 4597.99
A30: 47331 | B30: =DAY(EOMONTH(A30,0)) -> 31 | C30: D. habiles | D30: 21 | E30: =+'Curv hora 2029 - 2033 (100%)'!E30*0.5 -> 4227.265 | F30: =+'Curv hora 2029 - 2033 (100%)'!F30*0.5 -> 3983.64 | G30: =+'Curv hora 2029 - 2033 (100%)'!G30*0.5 -> 3833.035 | H30: =+'Curv hora 2029 - 2033 (100%)'!H30*0.5 -> 3737.575 | I30: =+'Curv hora 2029 - 2033 (100%)'!I30*0.5 -> 3750.175 | J30: =+'Curv hora 2029 - 2033 (100%)'!J30*0.5 -> 3914.44 | K30: =+'Curv hora 2029 - 2033 (100%)'!K30*0.5 -> 4368.64 | L30: =+'Curv hora 2029 - 2033 (100%)'!L30*0.5 -> 3948.18 | ... AB30: =+'Curv hora 2029 - 2033 (100%)'!AB30*0.5 -> 5158.935 | AC30: =SUMPRODUCT((E30:AB32)*D30:D32) -> 4090187.3
C31: D. Sabados | D31: 4 | E31: =+'Curv hora 2029 - 2033 (100%)'!E31*0.5 -> 4686.84 | F31: =+'Curv hora 2029 - 2033 (100%)'!F31*0.5 -> 4365.595 | G31: =+'Curv hora 2029 - 2033 (100%)'!G31*0.5 -> 3942.81 | H31: =+'Curv hora 2029 - 2033 (100%)'!H31*0.5 -> 4105.6 | I31: =+'Curv hora 2029 - 2033 (100%)'!I31*0.5 -> 3966.395 | J31: =+'Curv hora 2029 - 2033 (100%)'!J31*0.5 -> 4036.075 | K31: =+'Curv hora 2029 - 2033 (100%)'!K31*0.5 -> 4199.94 | L31: =+'Curv hora 2029 - 2033 (100%)'!L31*0.5 -> 4124.88 | ... AB31: =+'Curv hora 2029 - 2033 (100%)'!AB31*0.5 -> 5556.145
C32: D. dom y fest | D32: 6 | E32: =+'Curv hora 2029 - 2033 (100%)'!E32*0.5 -> 4586.92 | F32: =+'Curv hora 2029 - 2033 (100%)'!F32*0.5 -> 4258.655 | G32: =+'Curv hora 2029 - 2033 (100%)'!G32*0.5 -> 4048.46 | H32: =+'Curv hora 2029 - 2033 (100%)'!H32*0.5 -> 3919.725 | I32: =+'Curv hora 2029 - 2033 (100%)'!I32*0.5 -> 3777.03 | J32: =+'Curv hora 2029 - 2033 (100%)'!J32*0.5 -> 3851.86 | K32: =+'Curv hora 2029 - 2033 (100%)'!K32*0.5 -> 4029.26 | L32: =+'Curv hora 2029 - 2033 (100%)'!L32*0.5 -> 3584.695 | ... AB32: =+'Curv hora 2029 - 2033 (100%)'!AB32*0.5 -> 4936.085
A33: 47362 | B33: =DAY(EOMONTH(A33,0)) -> 30 | C33: D. habiles | D33: 20 | E33: =+'Curv hora 2029 - 2033 (100%)'!E33*0.5 -> 4529.23 | F33: =+'Curv hora 2029 - 2033 (100%)'!F33*0.5 -> 4224.99 | G33: =+'Curv hora 2029 - 2033 (100%)'!G33*0.5 -> 4096.07 | H33: =+'Curv hora 2029 - 2033 (100%)'!H33*0.5 -> 3979.7 | I33: =+'Curv hora 2029 - 2033 (100%)'!I33*0.5 -> 3918.34 | J33: =+'Curv hora 2029 - 2033 (100%)'!J33*0.5 -> 4118.085 | K33: =+'Curv hora 2029 - 2033 (100%)'!K33*0.5 -> 4613.185 | L33: =+'Curv hora 2029 - 2033 (100%)'!L33*0.5 -> 4151.145 | ... AB33: =+'Curv hora 2029 - 2033 (100%)'!AB33*0.5 -> 5297.02 | AC33: =SUMPRODUCT((E33:AB35)*D33:D35) -> 4049610.4
C34: D. Sabados | D34: 5 | E34: =+'Curv hora 2029 - 2033 (100%)'!E34*0.5 -> 4668.36 | F34: =+'Curv hora 2029 - 2033 (100%)'!F34*0.5 -> 4352.235 | G34: =+'Curv hora 2029 - 2033 (100%)'!G34*0.5 -> 4125.925 | H34: =+'Curv hora 2029 - 2033 (100%)'!H34*0.5 -> 4002.41 | I34: =+'Curv hora 2029 - 2033 (100%)'!I34*0.5 -> 3954.48 | J34: =+'Curv hora 2029 - 2033 (100%)'!J34*0.5 -> 4036.155 | K34: =+'Curv hora 2029 - 2033 (100%)'!K34*0.5 -> 4290.715 | L34: =+'Curv hora 2029 - 2033 (100%)'!L34*0.5 -> 4095.74 | ... AB34: =+'Curv hora 2029 - 2033 (100%)'!AB34*0.5 -> 5801.735
C35: D. dom y fest | D35: 5 | E35: =+'Curv hora 2029 - 2033 (100%)'!E35*0.5 -> 5124.55 | F35: =+'Curv hora 2029 - 2033 (100%)'!F35*0.5 -> 4771.975 | G35: =+'Curv hora 2029 - 2033 (100%)'!G35*0.5 -> 4508.155 | H35: =+'Curv hora 2029 - 2033 (100%)'!H35*0.5 -> 4344.57 | I35: =+'Curv hora 2029 - 2033 (100%)'!I35*0.5 -> 4204.595 | J35: =+'Curv hora 2029 - 2033 (100%)'!J35*0.5 -> 4163 | K35: =+'Curv hora 2029 - 2033 (100%)'!K35*0.5 -> 3974.62 | L35: =+'Curv hora 2029 - 2033 (100%)'!L35*0.5 -> 3373.01 | ... AB35: =+'Curv hora 2029 - 2033 (100%)'!AB35*0.5 -> 5146.93
A36: 47392 | B36: =DAY(EOMONTH(A36,0)) -> 31 | C36: D. habiles | D36: 22 | E36: =+'Curv hora 2029 - 2033 (100%)'!E36*0.5 -> 4649.79 | F36: =+'Curv hora 2029 - 2033 (100%)'!F36*0.5 -> 4382.84 | G36: =+'Curv hora 2029 - 2033 (100%)'!G36*0.5 -> 4210.865 | H36: =+'Curv hora 2029 - 2033 (100%)'!H36*0.5 -> 4083.775 | I36: =+'Curv hora 2029 - 2033 (100%)'!I36*0.5 -> 4031.24 | J36: =+'Curv hora 2029 - 2033 (100%)'!J36*0.5 -> 4210.745 | K36: =+'Curv hora 2029 - 2033 (100%)'!K36*0.5 -> 4578.18 | L36: =+'Curv hora 2029 - 2033 (100%)'!L36*0.5 -> 4236.07 | ... AB36: =+'Curv hora 2029 - 2033 (100%)'!AB36*0.5 -> 5486.115 | AC36: =SUMPRODUCT((E36:AB38)*D36:D38) -> 4309177.7
C37: D. Sabados | D37: 4 | E37: =+'Curv hora 2029 - 2033 (100%)'!E37*0.5 -> 4969.56 | F37: =+'Curv hora 2029 - 2033 (100%)'!F37*0.5 -> 4647.86 | G37: =+'Curv hora 2029 - 2033 (100%)'!G37*0.5 -> 4427.735 | H37: =+'Curv hora 2029 - 2033 (100%)'!H37*0.5 -> 4277.865 | I37: =+'Curv hora 2029 - 2033 (100%)'!I37*0.5 -> 4243.885 | J37: =+'Curv hora 2029 - 2033 (100%)'!J37*0.5 -> 4274.59 | K37: =+'Curv hora 2029 - 2033 (100%)'!K37*0.5 -> 4524.535 | L37: =+'Curv hora 2029 - 2033 (100%)'!L37*0.5 -> 4295.865 | ... AB37: =+'Curv hora 2029 - 2033 (100%)'!AB37*0.5 -> 5214.285
C38: D. dom y fest | D38: 5 | E38: =+'Curv hora 2029 - 2033 (100%)'!E38*0.5 -> 4593.68 | F38: =+'Curv hora 2029 - 2033 (100%)'!F38*0.5 -> 4300.92 | G38: =+'Curv hora 2029 - 2033 (100%)'!G38*0.5 -> 4095.415 | H38: =+'Curv hora 2029 - 2033 (100%)'!H38*0.5 -> 3944.99 | I38: =+'Curv hora 2029 - 2033 (100%)'!I38*0.5 -> 3857.98 | J38: =+'Curv hora 2029 - 2033 (100%)'!J38*0.5 -> 3682.12 | K38: =+'Curv hora 2029 - 2033 (100%)'!K38*0.5 -> 3974.015 | L38: =+'Curv hora 2029 - 2033 (100%)'!L38*0.5 -> 3591.7 | ... AB38: =+'Curv hora 2029 - 2033 (100%)'!AB38*0.5 -> 5025.605
A39: 47423 | B39: =DAY(EOMONTH(A39,0)) -> 30 | C39: D. habiles | D39: 20 | E39: =+'Curv hora 2029 - 2033 (100%)'!E39*0.5 -> 4390.8 | F39: =+'Curv hora 2029 - 2033 (100%)'!F39*0.5 -> 4106.52 | G39: =+'Curv hora 2029 - 2033 (100%)'!G39*0.5 -> 4004.39 | H39: =+'Curv hora 2029 - 2033 (100%)'!H39*0.5 -> 3882.735 | I39: =+'Curv hora 2029 - 2033 (100%)'!I39*0.5 -> 3914.915 | J39: =+'Curv hora 2029 - 2033 (100%)'!J39*0.5 -> 4084.39 | K39: =+'Curv hora 2029 - 2033 (100%)'!K39*0.5 -> 4538.605 | L39: =+'Curv hora 2029 - 2033 (100%)'!L39*0.5 -> 4164.115 | ... AB39: =+'Curv hora 2029 - 2033 (100%)'!AB39*0.5 -> 5183.42 | AC39: =SUMPRODUCT((E39:AB41)*D39:D41) -> 4023399.8
C40: D. Sabados | D40: 4 | E40: =+'Curv hora 2029 - 2033 (100%)'!E40*0.5 -> 4589.335 | F40: =+'Curv hora 2029 - 2033 (100%)'!F40*0.5 -> 4313.765 | G40: =+'Curv hora 2029 - 2033 (100%)'!G40*0.5 -> 4106.21 | H40: =+'Curv hora 2029 - 2033 (100%)'!H40*0.5 -> 3927.345 | I40: =+'Curv hora 2029 - 2033 (100%)'!I40*0.5 -> 3832.675 | J40: =+'Curv hora 2029 - 2033 (100%)'!J40*0.5 -> 3997.5 | K40: =+'Curv hora 2029 - 2033 (100%)'!K40*0.5 -> 4178.325 | L40: =+'Curv hora 2029 - 2033 (100%)'!L40*0.5 -> 3868.78 | ... AB40: =+'Curv hora 2029 - 2033 (100%)'!AB40*0.5 -> 5241.92
...

Sheet Cantidad maxima 
A2: FORMATO DE OFERTAS
A3: CONVOCATORIA PÚBLICA CP-EBPC2025-003
A4: OFERTA DE SUMINISTRO DE ENERGÍA ELECTRICA AÑOS 2029-2033
A5: TIPO DE OFERTA: CURVA
A6: PRODUCTO 01
A7: MES/AÑO | B7: ENERGIA SOLICITADA | C7: PAGUE LO CONTRATADO
C8: Oferta (%) De la Curva Demanda
B9: Necesidad TOTAL MES kWh | C9: Nivel de cobertura esperado % | D9: Energia Ofrecida kwh | E9: Precio de Oferta COP/kWh con dos cifras decimales, precio monomio fijo en pesos constantes de abril de 2025.
A11: 47119 | B11: 4098785.6 | C11: 1
A12: 47150 | B12: 3712458.8 | C12: 1
A13: 47178 | B13: 3960830.5 | C13: 1
A14: 47209 | B14: 4005391.4 | C14: 1
A15: 47239 | B15: 3902733.4 | C15: 1
A16: 47270 | B16: 3528555.6 | C16: 1
A17: 47300 | B17: 3803505.3 | C17: 1
A18: 47331 | B18: 4090187.3 | C18: 1
A19: 47362 | B19: 4049610.4 | C19: 1
A20: 47392 | B20: 4309177.7 | C20: 1
A21: 47423 | B21: 4023399.8 | C21: 1
A22: 47453 | B22: 4057095.6 | C22: 1
... A70: 48914 | B70: 4581822.9 | C70: 1
A71: TOTAL | B71: =SUM(B11:B70) -> 2.526039e+08
A73: NOMBRE Y FIRMA DEL REPRESENTANTE LEGAL
A74: AGENTE PROPONENTE
