Workbook
Name _Toc148954622: 'Banco de Preguntas'!#REF!
Name _Toc148954623: 'Banco de Preguntas'!#REF!
Name _Toc148954624: 'Banco de Preguntas'!#REF!
Name _Toc148954625: 'Banco de Preguntas'!#REF!
Name aaa: [1]Hoja9!$A$1,[1]Hoja9!$A$3,[1]Hoja9!$A$5,[1]Hoja9!$B$6,[1]Hoja9!$C$7
Name aaa: [1]Hoja9!$A$1,[1]Hoja9!$A$3,[1]Hoja9!$A$5,[1]Hoja9!$B$6,[1]Hoja9!$C$7
Name aaa: [1]Hoja9!$A$1,[1]Hoja9!$A$3,[1]Hoja9!$A$5,[1]Hoja9!$B$6,[1]Hoja9!$C$7
Name aaa: [1]Hoja9!$A$1,[1]Hoja9!$A$3,[1]Hoja9!$A$5,[1]Hoja9!$B$6,[1]Hoja9!$C$7
Name aaa: [1]Hoja9!$A$1,[1]Hoja9!$A$3,[1]Hoja9!$A$5,[1]Hoja9!$B$6,[1]Hoja9!$C$7
Name aaa: [1]Hoja9!$A$1,[1]Hoja9!$A$3,[1]Hoja9!$A$5,[1]Hoja9!$B$6,[1]Hoja9!$C$7
Name aaa: [1]Hoja9!$A$1,[1]Hoja9!$A$3,[1]Hoja9!$A$5,[1]Hoja9!$B$6,[1]Hoja9!$C$7
Name aaa: [1]Hoja9!$A$1,[1]Hoja9!$A$3,[1]Hoja9!$A$5,[1]Hoja9!$B$6,[1]Hoja9!$C$7
Name aaa: [1]Hoja9!$A$1,[1]Hoja9!$A$3,[1]Hoja9!$A$5,[1]Hoja9!$B$6,[1]Hoja9!$C$7
Name aaa: [1]Hoja9!$A$1,[1]Hoja9!$A$3,[1]Hoja9!$A$5,[1]Hoja9!$B$6,[1]Hoja9!$C$7
Name aaa: [1]Hoja9!$A$1,[1]Hoja9!$A$3,[1]Hoja9!$A$5,[1]Hoja9!$B$6,[1]Hoja9!$C$7
Name aaa: #REF!,#REF!,#REF!,#REF!,#REF!
Name AAAA: #REF!
Name Criterio_Extraer_Dem_Reg: #REF!
Name Criterio_Extraer_Dem_Reg: #REF!
Name Criterio_Extraer_Dem_Reg: #REF!
Name Criterio_Extraer_Dem_Reg: #REF!
Name Criterio_Extraer_Dem_Reg: #REF!
Name Criterio_Extraer_Dem_Reg: #REF!
Name Criterio_Extraer_Dem_Reg: #REF!
Name Criterio_Extraer_Dem_Reg: #REF!
Name Criterio_Extraer_Dem_Reg: #REF!
Name Criterio_Extraer_Dem_Reg: #REF!
Name Criterio_Extraer_Dem_Reg: #REF!
Name Criterio_Extraer_Dem_Reg: #REF!
Name Criterio_Extraer_Dem_Reg: #REF!
Name Cuadro: #REF!
Name Cuadro: #REF!
Name Cuadro: #REF!
Name Cuadro: #REF!
Name Cuadro: #REF!
Name Cuadro: #REF!
Name Cuadro: #REF!
Name Cuadro: #REF!
Name Cuadro: #REF!
Name Cuadro: #REF!
Name Cuadro: #REF!
Name Cuadro: #REF!
Name Cuadro: #REF!
Name eeee: [2]Comparación!#REF!
Name eeee: [2]Comparación!#REF!
Name eeee: [2]Comparación!#REF!
Name eeee: [2]Comparación!#REF!
Name eeee: [2]Comparación!#REF!
Name eeee: #REF!
Name eeee: [2]Comparación!#REF!
Name eeee: [2]Comparación!#REF!
Name eeee: [2]Comparación!#REF!
Name eeee: [2]Comparación!#REF!
Name eeee: [2]Comparación!#REF!
Name eeee: [2]Comparación!#REF!
Name eeee: #REF!
Name Meses: [3]Evaluación_Mensual!$S$2:$S$25
Name Meses: [3]Evaluación_Mensual!$S$2:$S$25
Name Meses: [3]Evaluación_Mensual!$S$2:$S$25
Name Meses: [3]Evaluación_Mensual!$S$2:$S$25

Sheet Listas desplegables
A2: Tipo de agente: | B2: Tipo de oferta:
A3: Comercializador | B3: CURVA
A4: Generador | B4: CURVA SOLAR
B5: CURVA FNCER
B6: PLANA SOLAR
B7: MIXTA
B8: PLANA

Sheet Banco de Preguntas
A2: Consolidado banco de preguntas y respuestas agentes convocatorias ESSA
A3: N° Convocatoria
A4: Nombre remitente correo:
A5: Correo electrónico
A6: Teléfono de contacto:
A9: AGENTE | B9: N° pregunta | C9: PREGUNTA | D9: RESPUESTA

Sheet Factor garantia
A2: 12. TABLA Factores de Indexación IPP serie oferta interna
A4: Mes | B4: Factor
A5: 46023 | B5: 1.01
A6: 46054 | B6: 1.01
A7: 46082 | B7: 1.01
A8: 46113 | B8: 1.01
A9: 46143 | B9: 1.01
A10: 46174 | B10: 1.01
A11: 46204 | B11: 1.02
A12: 46235 | B12: 1.02
A13: 46266 | B13: 1.02
A14: 46296 | B14: 1.02
A15: 46327 | B15: 1.03
A16: 46357 | B16: 1.03
... A64: 47818 | B64: 1.15

Sheet Cantidades suministrar P1_26-28
B2: ANEXO 10.1 CANTIDADES DE ENERGÍA REQUERIDA PRODUCTO 1
B3: AÑOS 2026 -2028
B6: Oferta Básica, para la Solicitud Pública de Ofertas No. CP-ESSC2025-003, del 1 de febrero de 2026 a 31 de diciembre de 2028.
B8: OFERENTE: | E8: Diligenciar
B9: Tipo de agente: | E9: Elegir de la lista desplegable
B10: Oferta No.: | E10: Diligenciar
B11: Tipo de oferta: | C11: PLANA | E11: Fijo
A12: 24 | B12: Franja Horaria | C12: H1-H24
B13: % de su oferta con FNCER: | E13: Diligenciar
B15: Mes-año | C15: Energia Solicitada (kWh) | D15: Energía Horaria solicitada kWh (h1-h24) | E15: % a ofertar | F15: Energia Oferta kWh | G15: Energia Horaria Ofertada kWh | H15: Precio $ / kWh
A17: 31 | B17: 46023 | E17: 0 | H17: 0
A18: 28 | B18: 46054 | C18: =+'Cantidades 1_(26-28)'!AD15 -> 3360000 | D18: =+C18/A18/$A$12 -> 5000 | F18: =+C18*$E$17 -> 0 | G18: =+F18/A18/$A$12 -> 0
A19: 31 | B19: 46082 | C19: =+'Cantidades 1_(26-28)'!AD16 -> 3720000 | D19: =+C19/A19/$A$12 -> 5000 | F19: =+C19*$E$17 -> 0 | G19: =+F19/A19/$A$12 -> 0
A20: 30 | B20: 46113 | C20: =+'Cantidades 1_(26-28)'!AD17 -> 3600000 | D20: =+C20/A20/$A$12 -> 5000 | F20: =+C20*$E$17 -> 0 | G20: =+F20/A20/$A$12 -> 0
A21: 31 | B21: 46143 | C21: =+'Cantidades 1_(26-28)'!AD18 -> 3720000 | D21: =+C21/A21/$A$12 -> 5000 | F21: =+C21*$E$17 -> 0 | G21: =+F21/A21/$A$12 -> 0
A22: 30 | B22: 46174 | C22: =+'Cantidades 1_(26-28)'!AD19 -> 3600000 | D22: =+C22/A22/$A$12 -> 5000 | F22: =+C22*$E$17 -> 0 | G22: =+F22/A22/$A$12 -> 0
A23: 31 | B23: 46204 | C23: =+'Cantidades 1_(26-28)'!AD20 -> 3720000 | D23: =+C23/A23/$A$12 -> 5000 | F23: =+C23*$E$17 -> 0 | G23: =+F23/A23/$A$12 -> 0
A24: 31 | B24: 46235 | C24: =+'Cantidades 1_(26-28)'!AD21 -> 3720000 | D24: =+C24/A24/$A$12 -> 5000 | F24: =+C24*$E$17 -> 0 | G24: =+F24/A24/$A$12 -> 0
A25: 30 | B25: 46266 | C25: =+'Cantidades 1_(26-28)'!AD22 -> 3600000 | D25: =+C25/A25/$A$12 -> 5000 | F25: =+C25*$E$17 -> 0 | G25: =+F25/A25/$A$12 -> 0
A26: 31 | B26: 46296 | C26: =+'Cantidades 1_(26-28)'!AD23 -> 3720000 | D26: =+C26/A26/$A$12 -> 5000 | F26: =+C26*$E$17 -> 0 | G26: =+F26/A26/$A$12 -> 0
A27: 30 | B27: 46327 | C27: =+'Cantidades 1_(26-28)'!AD24 -> 3600000 | D27: =+C27/A27/$A$12 -> 5000 | F27: =+C27*$E$17 -> 0 | G27: =+F27/A27/$A$12 -> 0
A28: 31 | B28: 46357 | C28: =+'Cantidades 1_(26-28)'!AD25 -> 3720000 | D28: =+C28/A28/$A$12 -> 5000 | F28: =+C28*$E$17 -> 0 | G28: =+F28/A28/$A$12 -> 0
A29: 31 | B29: 46388 | C29: =+'Cantidades 1_(26-28)'!AD64 -> 3720000 | D29: =+C29/A29/$A$12 -> 5000 | F29: =+C29*$E$17 -> 0 | G29: =+F29/A29/$A$12 -> 0 | H29: 0
A30: 28 | B30: 46419 | C30: =+'Cantidades 1_(26-28)'!AD65 -> 3360000 | D30: =+C30/A30/$A$12 -> 5000 | F30: =+C30*$E$17 -> 0 | G30: =+F30/A30/$A$12 -> 0
A31: 31 | B31: 46447 | C31: =+'Cantidades 1_(26-28)'!AD66 -> 3720000 | D31: =+C31/A31/$A$12 -> 5000 | F31: =+C31*$E$17 -> 0 | G31: =+F31/A31/$A$12 -> 0
A32: 30 | B32: 46478 | C32: =+'Cantidades 1_(26-28)'!AD67 -> 3600000 | D32: =+C32/A32/$A$12 -> 5000 | F32: =+C32*$E$17 -> 0 | G32: =+F32/A32/$A$12 -> 0
A33: 31 | B33: 46508 | C33: =+'Cantidades 1_(26-28)'!AD68 -> 3720000 | D33: =+C33/A33/$A$12 -> 5000 | F33: =+C33*$E$17 -> 0 | G33: =+F33/A33/$A$12 -> 0
A34: 30 | B34: 46539 | C34: =+'Cantidades 1_(26-28)'!AD69 -> 3600000 | D34: =+C34/A34/$A$12 -> 5000 | F34: =+C34*$E$17 -> 0 | G34: =+F34/A34/$A$12 -> 0
A35: 31 | B35: 46569 | C35: =+'Cantidades 1_(26-28)'!AD70 -> 3720000 | D35: =+C35/A35/$A$12 -> 5000 | F35: =+C35*$E$17 -> 0 | G35: =+F35/A35/$A$12 -> 0
A36: 31 | B36: 46600 | C36: =+'Cantidades 1_(26-28)'!AD71 -> 3720000 | D36: =+C36/A36/$A$12 -> 5000 | F36: =+C36*$E$17 -> 0 | G36: =+F36/A36/$A$12 -> 0
A37: 30 | B37: 46631 | C37: =+'Cantidades 1_(26-28)'!AD72 -> 3600000 | D37: =+C37/A37/$A$12 -> 5000 | F37: =+C37*$E$17 -> 0 | G37: =+F37/A37/$A$12 -> 0
A38: 31 | B38: 46661 | C38: =+'Cantidades 1_(26-28)'!AD73 -> 3720000 | D38: =+C38/A38/$A$12 -> 5000 | F38: =+C38*$E$17 -> 0 | G38: =+F38/A38/$A$12 -> 0
A39: 30 | B39: 46692 | C39: =+'Cantidades 1_(26-28)'!AD74 -> 3600000 | D39: =+C39/A39/$A$12 -> 5000 | F39: =+C39*$E$17 -> 0 | G39: =+F39/A39/$A$12 -> 0
A40: 31 | B40: 46722 | C40: =+'Cantidades 1_(26-28)'!AD75 -> 3720000 | D40: =+C40/A40/$A$12 -> 5000 | F40: =+C40*$E$17 -> 0 | G40: =+F40/A40/$A$12 -> 0
A41: 31 | B41: 46753 | C41: =+'Cantidades 1_(26-28)'!AD114 -> 3720000 | D41: =+C41/A41/$A$12 -> 5000 | F41: =+C41*$E$17 -> 0 | G41: =+F41/A41/$A$12 -> 0 | H41: 0
A42: 29 | B42: 46784 | C42: =+'Cantidades 1_(26-28)'!AD115 -> 3480000 | D42: =+C42/A42/$A$12 -> 5000 | F42: =+C42*$E$17 -> 0 | G42: =+F42/A42/$A$12 -> 0
A43: 31 | B43: 46813 | C43: =+'Cantidades 1_(26-28)'!AD116 -> 3720000 | D43: =+C43/A43/$A$12 -> 5000 | F43: =+C43*$E$17 -> 0 | G43: =+F43/A43/$A$12 -> 0
A44: 30 | B44: 46844 | C44: =+'Cantidades 1_(26-28)'!AD117 -> 3600000 | D44: =+C44/A44/$A$12 -> 5000 | F44: =+C44*$E$17 -> 0 | G44: =+F44/A44/$A$12 -> 0
A45: 31 | B45: 46874 | C45: =+'Cantidades 1_(26-28)'!AD118 -> 3720000 | D45: =+C45/A45/$A$12 -> 5000 | F45: =+C45*$E$17 -> 0 | G45: =+F45/A45/$A$12 -> 0
A46: 30 | B46: 46905 | C46: =+'Cantidades 1_(26-28)'!AD119 -> 3600000 | D46: =+C46/A46/$A$12 -> 5000 | F46: =+C46*$E$17 -> 0 | G46: =+F46/A46/$A$12 -> 0
...

Sheet Cantidades suministrar P2_2026
B2: ANEXO 10.2 CANTIDADES DE ENERGÍA REQUERIDA PRODUCTO 2
B3: AÑO 2026
B6: Oferta Básica, para la Solicitud Pública de Ofertas No. CP-ESSC2025-003, del 1 de febrero 2026 a 31 de diciembre de 2026.
B8: OFERENTE: | E8: Diligenciar
B9: Tipo de agente: | E9: Elegir de la lista desplegable
B10: Oferta No.: | E10: Diligenciar
B11: Tipo de oferta: | C11: CURVA | E11: Fijo
B12: % de su oferta con FNCER: | E12: Diligenciar
B14: Mes-año | C14: Energia Solicitada (kWh) | D14: % a ofertar | E14: Energia Oferta kWh | F14: Precio $ / kWh
A16: 31 | B16: 46023 | F16: 0
A17: 28 | B17: 46054 | C17: =+'Cantidades 2_(2026)'!AD15 -> 8204162 | D17: 0 | E17: =+C17*D17 -> 0
A18: 31 | B18: 46082 | C18: =+'Cantidades 2_(2026)'!AD16 -> 9865393.2 | D18: 0 | E18: =+C18*D18 -> 0
A19: 30 | B19: 46113 | C19: =+'Cantidades 2_(2026)'!AD17 -> 5842730.4 | D19: 0 | E19: =+C19*D19 -> 0
A20: 31 | B20: 46143 | C20: =+'Cantidades 2_(2026)'!AD18 -> 2193087.3 | D20: 0 | E20: =+C20*D20 -> 0
A21: 30 | B21: 46174 | C21: =+'Cantidades 2_(2026)'!AD19 -> 2044913.6 | D21: 0 | E21: =+C21*D21 -> 0
A22: 31 | B22: 46204 | C22: =+'Cantidades 2_(2026)'!AD20 -> 2074770.6 | D22: 0 | E22: =+C22*D22 -> 0
A23: 31 | B23: 46235 | C23: =+'Cantidades 2_(2026)'!AD21 -> 2068744 | D23: 0 | E23: =+C23*D23 -> 0
A24: 30 | B24: 46266 | C24: =+'Cantidades 2_(2026)'!AD22 -> 2666666.2 | D24: 0 | E24: =+C24*D24 -> 0
A25: 31 | B25: 46296 | C25: =+'Cantidades 2_(2026)'!AD23 -> 1969082 | D25: 0 | E25: =+C25*D25 -> 0
A26: 30 | B26: 46327 | C26: =+'Cantidades 2_(2026)'!AD24 -> 1831628.2 | D26: 0 | E26: =+C26*D26 -> 0
A27: 31 | B27: 46357 | C27: =+'Cantidades 2_(2026)'!AD25 -> 5062929.3 | D27: 0 | E27: =+C27*D27 -> 0
A28: =SUM(A16:A27) -> 365 | B28: TOTAL | C28: =SUM(C16:C27) -> 43824107 | D28: =+E28/C28 -> 0 | E28: =SUM(E16:E27) -> 0
B31: Notas:
B32: (1) La Energía Ofertada se distribuye en forma horaria de acuerdo con la curva de carga presentada en la tabla 9.2. TABLAS CANTIDADES DE ENERGÍA REQUERIDA PRODUCTO 2 AÑO 2026 del pliego de condiciones.
B34: (2) Tipo de Contrato: pague lo contratado.
B35: (3) Precio ofertado en $kWh, en pesos de Octubre 2025 (IPP Provisional)
B36: (4) El precio debe ser el mismo para todos los meses del año, con dos cifras decimales
B37: (5) El % igual o diferente para cada uno de los meses del año, con dos cifras decimales.
B38: (6) El precio incluye todos los cargos, impuestos y contribuciones que según la reglamentación vigente en la fecha de apertura de propuestas son responsabilidad de EL OFERENTE.
B39: (7) No serán tenidas en cuenta ofertas con condiciones y/o modificaciones adicionales a los Pliegos definitivos.
B40: (8) La oferta se acoge a todas las condiciones del pliego CP-ESSC2025-003.
B41: (9) Tipo de oferta curva
B42: EL OFERENTE deberá tener en cuenta lo siguiente al completar cada una de las Tablas de las cantidades a ofertar: Debe definir el porcentaje ofertado, hasta máximo el 100% de lo solicitado; EL CONTRATANTE aceptará la oferta de acuerdo a la metodología de evaluación hasta el máximo ofertado.
B48: FIRMA OFERENTE E.S.P.

Sheet Cantidades suministrar P3_2027
B2: ANEXO 10.3 CANTIDADES DE ENERGÍA REQUERIDA PRODUCTO 3
B3: AÑO 2027
B6: Oferta Básica, para la Solicitud Pública de Ofertas No. CP-ESSC2025-003, del 1 de enero 2027 a 31 de diciembre de 2027.
B8: OFERENTE: | E8: Diligenciar
B9: Tipo de agente: | E9: Elegir de la lista desplegable
B10: Oferta No.: | E10: Diligenciar
B11: Tipo de oferta: | C11: CURVA | E11: Fijo
B12: % de su oferta con FNCER: | E12: Diligenciar
B14: Mes-año | C14: Energia Solicitada (kWh) | D14: % a ofertar | E14: Energia Oferta kWh | F14: Precio $ / kWh
A16: 31 | B16: 46388 | C16: =+'Cantidades 3_(2027)'!AD14 -> 28661912 | D16: 0 | E16: =+C16*D16 -> 0 | F16: 0
A17: 28 | B17: 46419 | C17: =+'Cantidades 3_(2027)'!AD15 -> 25956636 | D17: 0 | E17: =+C17*D17 -> 0
A18: 31 | B18: 46447 | C18: =+'Cantidades 3_(2027)'!AD16 -> 28377636 | D18: 0 | E18: =+C18*D18 -> 0
A19: 30 | B19: 46478 | C19: =+'Cantidades 3_(2027)'!AD17 -> 21852568 | D19: 0 | E19: =+C19*D19 -> 0
A20: 31 | B20: 46508 | C20: =+'Cantidades 3_(2027)'!AD18 -> 23042026 | D20: 0 | E20: =+C20*D20 -> 0
A21: 30 | B21: 46539 | C21: =+'Cantidades 3_(2027)'!AD19 -> 6843780.2 | D21: 0 | E21: =+C21*D21 -> 0
A22: 31 | B22: 46569 | C22: =+'Cantidades 3_(2027)'!AD20 -> 3320362.4 | D22: 0 | E22: =+C22*D22 -> 0
A23: 31 | B23: 46600 | C23: =+'Cantidades 3_(2027)'!AD21 -> 7378162.4 | D23: 0 | E23: =+C23*D23 -> 0
A24: 30 | B24: 46631 | C24: =+'Cantidades 3_(2027)'!AD22 -> 7560028.8 | D24: 0 | E24: =+C24*D24 -> 0
A25: 31 | B25: 46661 | C25: =+'Cantidades 3_(2027)'!AD23 -> 9628746.9 | D25: 0 | E25: =+C25*D25 -> 0
A26: 30 | B26: 46692 | C26: =+'Cantidades 3_(2027)'!AD24 -> 13088728 | D26: 0 | E26: =+C26*D26 -> 0
A27: 31 | B27: 46722 | C27: =+'Cantidades 3_(2027)'!AD25 -> 18444368 | D27: 0 | E27: =+C27*D27 -> 0
A28: =SUM(A16:A27) -> 365 | B28: TOTAL | C28: =SUM(C16:C27) -> 1.9415495e+08 | D28: =+E28/C28 -> 0 | E28: =SUM(E16:E27) -> 0
B31: Notas:
B32: (1) La Energía Ofertada se distribuye en forma horaria de acuerdo con la curva de carga presentada en la tabla 9.3. TABLAS CANTIDADES DE ENERGÍA REQUERIDA PRODUCTO 3 AÑO 2027 del pliego de condiciones.
B34: (2) Tipo de Contrato: pague lo contratado.
B35: (3) Precio ofertado en $kWh, en pesos de Octubre 2025 (IPP Provisional)
B36: (4) El precio debe ser el mismo para todos los meses del año, con dos cifras decimales
B37: (5) El % igual o diferente para cada uno de los meses del año, con dos cifras decimales.
B38: (6) El precio incluye todos los cargos, impuestos y contribuciones que según la reglamentación vigente en la fecha de apertura de propuestas son responsabilidad de EL OFERENTE.
B39: (7) No serán tenidas en cuenta ofertas con condiciones y/o modificaciones adicionales a los Pliegos definitivos.
B40: (8) La oferta se acoge a todas las condiciones del pliego CP-ESSC2025-003.
B41: (9) Tipo de oferta curva
B42: EL OFERENTE deberá tener en cuenta lo siguiente al completar cada una de las Tablas de las cantidades a ofertar: Debe definir el porcentaje ofertado, hasta máximo el 100% de lo solicitado; EL CONTRATANTE aceptará la oferta de acuerdo a la metodología de evaluación hasta el máximo ofertado.
B48: FIRMA OFERENTE E.S.P.

Sheet Cantidades suministrar P4_2028
B2: ANEXO 10.4 CANTIDADES DE ENERGÍA REQUERIDA PRODUCTO 4
B3: AÑO 2028
B6: Oferta Básica, para la Solicitud Pública de Ofertas No. CP-ESSC2025-003, del 1 de enero de 2028 a 31 de diciembre de 2028.
B8: OFERENTE: | E8: Diligenciar
B9: Tipo de agente: | E9: Elegir de la lista desplegable
B10: Oferta No.: | E10: Diligenciar
B11: Tipo de oferta: | C11: CURVA | E11: Fijo
B12: % de su oferta con FNCER: | E12: Diligenciar
B14: Mes-año | C14: Energia Solicitada (kWh) | D14: % a ofertar | E14: Energia Oferta kWh | F14: Precio $ / kWh
A16: 31 | B16: 46753 | C16: =+'Cantidades P4_(2028)'!AD14 -> 14704773 | D16: 0 | E16: =+C16*D16 -> 0 | F16: 0
A17: 28 | B17: 46784 | C17: =+'Cantidades P4_(2028)'!AD15 -> 10265950 | D17: 0 | E17: =+C17*D17 -> 0
A18: 31 | B18: 46813 | C18: =+'Cantidades P4_(2028)'!AD16 -> 13243873 | D18: 0 | E18: =+C18*D18 -> 0
A19: 30 | B19: 46844 | C19: =+'Cantidades P4_(2028)'!AD17 -> 7655859.6 | D19: 0 | E19: =+C19*D19 -> 0
A20: 31 | B20: 46874 | C20: =+'Cantidades P4_(2028)'!AD18 -> 8689418.5 | D20: 0 | E20: =+C20*D20 -> 0
A21: 30 | B21: 46905 | C21: =+'Cantidades P4_(2028)'!AD19 -> 12471108 | D21: 0 | E21: =+C21*D21 -> 0
A22: 31 | B22: 46935 | C22: =+'Cantidades P4_(2028)'!AD20 -> 2132513 | D22: 0 | E22: =+C22*D22 -> 0
A23: 31 | B23: 46966 | C23: =+'Cantidades P4_(2028)'!AD21 -> 3655478.8 | D23: 0 | E23: =+C23*D23 -> 0
A24: 30 | B24: 46997 | C24: =+'Cantidades P4_(2028)'!AD22 -> 4619057.7 | D24: 0 | E24: =+C24*D24 -> 0
A25: 31 | B25: 47027 | C25: =+'Cantidades P4_(2028)'!AD23 -> 3459170.5 | D25: 0 | E25: =+C25*D25 -> 0
A26: 30 | B26: 47058 | C26: =+'Cantidades P4_(2028)'!AD24 -> 1619459.3 | D26: 0 | E26: =+C26*D26 -> 0
A27: 31 | B27: 47088 | C27: =+'Cantidades P4_(2028)'!AD25 -> 9419639.1 | D27: 0 | E27: =+C27*D27 -> 0
A28: =SUM(A16:A27) -> 365 | B28: TOTAL | C28: =SUM(C16:C27) -> 91936300 | D28: =+E28/C28 -> 0 | E28: =SUM(E16:E27) -> 0
B31: Notas:
B32: (1) La Energía Ofertada se distribuye en forma horaria de acuerdo con la curva de carga presentada en la tabla 9.4. TABLAS CANTIDADES DE ENERGÍA REQUERIDA PRODUCTO 4 AÑO 2028 del pliego de condiciones.
B34: (2) Tipo de Contrato: pague lo contratado.
B35: (3) Precio ofertado en $kWh, en pesos de Octubre 2025 (IPP Provisional)
B36: (4) El precio debe ser el mismo para todos los meses del año, con dos cifras decimales
B37: (5) El % igual o diferente para cada uno de los meses del año, con dos cifras decimales.
B38: (6) El precio incluye todos los cargos, impuestos y contribuciones que según la reglamentación vigente en la fecha de apertura de propuestas son responsabilidad de EL OFERENTE.
B39: (7) No serán tenidas en cuenta ofertas con condiciones y/o modificaciones adicionales a los Pliegos definitivos.
B40: (8) La oferta se acoge a todas las condiciones del pliego CP-ESSC2025-003.
B41: (9) Tipo de oferta curva
B42: EL OFERENTE deberá tener en cuenta lo siguiente al completar cada una de las Tablas de las cantidades a ofertar: Debe definir el porcentaje ofertado, hasta máximo el 100% de lo solicitado; EL CONTRATANTE aceptará la oferta de acuerdo a la metodología de evaluación hasta el máximo ofertado.
B48: FIRMA OFERENTE E.S.P.

Sheet Cantidades suministrar P5_26-28
B2: ANEXO 10.5 CANTIDADES DE ENERGÍA REQUERIDA PRODUCTO 5
B3: AÑOS 2026 -2028
B6: Oferta Básica, para la Solicitud Pública de Ofertas No. CP-ESSC2025-003, del 1 de febrero de 2026 a 31 de diciembre de 2028.
B8: OFERENTE: | D8: Diligenciar
B9: Tipo de agente: | D9: Elegir de la lista desplegable
B10: Oferta No.: | D10: Diligenciar
B11: Tipo de oferta: | C11: CURVA | D11: Fijo
B12: Franja Horaria | C12: H18-H24
B13: % de su oferta con FNCER: | D13: Diligenciar
B15: Mes-año | C15: Energia Solicitada (kWh) | D15: % a ofertar | E15: Energia Oferta kWh | F15: Precio $ / kWh
A17: 31 | B17: 46023 | D17: 0 | F17: 0
A18: 28 | B18: 46054 | C18: =+'Cantidades 5_(26-28)'!AD15 -> 12471487 | E18: =+C18*$D$17 -> 0
A19: 31 | B19: 46082 | C19: =+'Cantidades 5_(26-28)'!AD16 -> 13432833 | E19: =+C19*$D$17 -> 0
A20: 30 | B20: 46113 | C20: =+'Cantidades 5_(26-28)'!AD17 -> 11611265 | E20: =+C20*$D$17 -> 0
A21: 31 | B21: 46143 | C21: =+'Cantidades 5_(26-28)'!AD18 -> 6257333 | E21: =+C21*$D$17 -> 0
A22: 30 | B22: 46174 | C22: =+'Cantidades 5_(26-28)'!AD19 -> 7351802.1 | E22: =+C22*$D$17 -> 0
A23: 31 | B23: 46204 | C23: =+'Cantidades 5_(26-28)'!AD20 -> 8667289.6 | E23: =+C23*$D$17 -> 0
A24: 31 | B24: 46235 | C24: =+'Cantidades 5_(26-28)'!AD21 -> 8541286.1 | E24: =+C24*$D$17 -> 0
A25: 30 | B25: 46266 | C25: =+'Cantidades 5_(26-28)'!AD22 -> 10140571 | E25: =+C25*$D$17 -> 0
A26: 31 | B26: 46296 | C26: =+'Cantidades 5_(26-28)'!AD23 -> 10912077 | E26: =+C26*$D$17 -> 0
A27: 30 | B27: 46327 | C27: =+'Cantidades 5_(26-28)'!AD24 -> 9086699.7 | E27: =+C27*$D$17 -> 0
A28: 31 | B28: 46357 | C28: =+'Cantidades 5_(26-28)'!AD25 -> 12035402 | E28: =+C28*$D$17 -> 0
A29: 31 | B29: 46388 | C29: =+'Cantidades 5_(26-28)'!AD64 -> 13512052 | D29: 0 | E29: =+C29*$D$29 -> 0 | F29: 0
A30: 28 | B30: 46419 | C30: =+'Cantidades 5_(26-28)'!AD65 -> 12535983 | E30: =+C30*$D$29 -> 0
A31: 31 | B31: 46447 | C31: =+'Cantidades 5_(26-28)'!AD66 -> 13410647 | E31: =+C31*$D$29 -> 0
A32: 30 | B32: 46478 | C32: =+'Cantidades 5_(26-28)'!AD67 -> 11845997 | E32: =+C32*$D$29 -> 0
A33: 31 | B33: 46508 | C33: =+'Cantidades 5_(26-28)'!AD68 -> 12308880 | E33: =+C33*$D$29 -> 0
A34: 30 | B34: 46539 | C34: =+'Cantidades 5_(26-28)'!AD69 -> 7811321.4 | E34: =+C34*$D$29 -> 0
A35: 31 | B35: 46569 | C35: =+'Cantidades 5_(26-28)'!AD70 -> 7123196.9 | E35: =+C35*$D$29 -> 0
A36: 31 | B36: 46600 | C36: =+'Cantidades 5_(26-28)'!AD71 -> 8553825 | E36: =+C36*$D$29 -> 0
A37: 30 | B37: 46631 | C37: =+'Cantidades 5_(26-28)'!AD72 -> 7942306.5 | E37: =+C37*$D$29 -> 0
A38: 31 | B38: 46661 | C38: =+'Cantidades 5_(26-28)'!AD73 -> 9779601.8 | E38: =+C38*$D$29 -> 0
A39: 30 | B39: 46692 | C39: =+'Cantidades 5_(26-28)'!AD74 -> 10330944 | E39: =+C39*$D$29 -> 0
A40: 31 | B40: 46722 | C40: =+'Cantidades 5_(26-28)'!AD75 -> 11901394 | E40: =+C40*$D$29 -> 0
A41: 31 | B41: 46753 | C41: =+'Cantidades 5_(26-28)'!AD114 -> 13474937 | D41: 0 | E41: =+C41*$D$41 -> 0 | F41: 0
A42: 29 | B42: 46784 | C42: =+'Cantidades 5_(26-28)'!AD115 -> 11854314 | E42: =+C42*$D$41 -> 0
A43: 31 | B43: 46813 | C43: =+'Cantidades 5_(26-28)'!AD116 -> 13059269 | E43: =+C43*$D$41 -> 0
A44: 30 | B44: 46844 | C44: =+'Cantidades 5_(26-28)'!AD117 -> 10991944 | E44: =+C44*$D$41 -> 0
A45: 31 | B45: 46874 | C45: =+'Cantidades 5_(26-28)'!AD118 -> 11286422 | E45: =+C45*$D$41 -> 0
A46: 30 | B46: 46905 | C46: =+'Cantidades 5_(26-28)'!AD119 -> 12715256 | E46: =+C46*$D$41 -> 0
...

Sheet Cantidades suministrar P6_29-30
B2: ANEXO 10.6 CANTIDADES DE ENERGÍA REQUERIDA PRODUCTO 6
B3: AÑOS 2029 -2030
B6: Oferta Básica, para la Solicitud Pública de Ofertas No. CP-ESSC2025-003, del 1 de enero de 2029 a 31 de diciembre de 2030.
B8: OFERENTE: | E8: Diligenciar
B9: Tipo de agente: | E9: Elegir de la lista desplegable
B10: Oferta No.: | E10: Diligenciar
B11: Tipo de oferta: | C11: PLANA | E11: Fijo
A12: 24 | B12: Franja Horaria | C12: H1-H24
B13: % de su oferta con FNCER: | E13: Diligenciar
B15: Mes-año | C15: Energia Solicitada (kWh) | D15: Energía Horaria solicitada kWh (h1-h24) | E15: % a ofertar | F15: Energia Oferta kWh | G15: Energia Horaria Ofertada kWh | H15: Precio $ / kWh
A17: 31 | B17: 47119 | C17: =+'Cantidades P6_(2029-2040)'!AD14 -> 9820800 | D17: =+C17/A17/$A$12 -> 13200 | E17: 0 | F17: =+C17*$E$17 -> 0 | G17: =+F17/A17/$A$12 -> 0 | H17: 0
A18: 28 | B18: 47150 | C18: =+'Cantidades P6_(2029-2040)'!AD15 -> 8870400 | D18: =+C18/A18/$A$12 -> 13200 | F18: =+C18*$E$17 -> 0 | G18: =+F18/A18/$A$12 -> 0
A19: 31 | B19: 47178 | C19: =+'Cantidades P6_(2029-2040)'!AD16 -> 9820800 | D19: =+C19/A19/$A$12 -> 13200 | F19: =+C19*$E$17 -> 0 | G19: =+F19/A19/$A$12 -> 0
A20: 30 | B20: 47209 | C20: =+'Cantidades P6_(2029-2040)'!AD17 -> 9504000 | D20: =+C20/A20/$A$12 -> 13200 | F20: =+C20*$E$17 -> 0 | G20: =+F20/A20/$A$12 -> 0
A21: 31 | B21: 47239 | C21: =+'Cantidades P6_(2029-2040)'!AD18 -> 9820800 | D21: =+C21/A21/$A$12 -> 13200 | F21: =+C21*$E$17 -> 0 | G21: =+F21/A21/$A$12 -> 0
A22: 30 | B22: 47270 | C22: =+'Cantidades P6_(2029-2040)'!AD19 -> 9504000 | D22: =+C22/A22/$A$12 -> 13200 | F22: =+C22*$E$17 -> 0 | G22: =+F22/A22/$A$12 -> 0
A23: 31 | B23: 47300 | C23: =+'Cantidades P6_(2029-2040)'!AD20 -> 9820800 | D23: =+C23/A23/$A$12 -> 13200 | F23: =+C23*$E$17 -> 0 | G23: =+F23/A23/$A$12 -> 0
A24: 31 | B24: 47331 | C24: =+'Cantidades P6_(2029-2040)'!AD21 -> 9820800 | D24: =+C24/A24/$A$12 -> 13200 | F24: =+C24*$E$17 -> 0 | G24: =+F24/A24/$A$12 -> 0
A25: 30 | B25: 47362 | C25: =+'Cantidades P6_(2029-2040)'!AD22 -> 9504000 | D25: =+C25/A25/$A$12 -> 13200 | F25: =+C25*$E$17 -> 0 | G25: =+F25/A25/$A$12 -> 0
A26: 31 | B26: 47392 | C26: =+'Cantidades P6_(2029-2040)'!AD23 -> 9820800 | D26: =+C26/A26/$A$12 -> 13200 | F26: =+C26*$E$17 -> 0 | G26: =+F26/A26/$A$12 -> 0
A27: 30 | B27: 47423 | C27: =+'Cantidades P6_(2029-2040)'!AD24 -> 9504000 | D27: =+C27/A27/$A$12 -> 13200 | F27: =+C27*$E$17 -> 0 | G27: =+F27/A27/$A$12 -> 0
A28: 31 | B28: 47453 | C28: =+'Cantidades P6_(2029-2040)'!AD25 -> 9820800 | D28: =+C28/A28/$A$12 -> 13200 | F28: =+C28*$E$17 -> 0 | G28: =+F28/A28/$A$12 -> 0
A29: 31 | B29: 47484 | C29: =+'Cantidades P6_(2029-2040)'!AD64 -> 9820800 | D29: =+C29/A29/$A$12 -> 13200 | F29: =+C29*$E$17 -> 0 | G29: =+F29/A29/$A$12 -> 0 | H29: 0
A30: 28 | B30: 47515 | C30: =+'Cantidades P6_(2029-2040)'!AD65 -> 8870400 | D30: =+C30/A30/$A$12 -> 13200 | F30: =+C30*$E$17 -> 0 | G30: =+F30/A30/$A$12 -> 0
A31: 31 | B31: 47543 | C31: =+'Cantidades P6_(2029-2040)'!AD66 -> 9820800 | D31: =+C31/A31/$A$12 -> 13200 | F31: =+C31*$E$17 -> 0 | G31: =+F31/A31/$A$12 -> 0
A32: 30 | B32: 47574 | C32: =+'Cantidades P6_(2029-2040)'!AD67 -> 9504000 | D32: =+C32/A32/$A$12 -> 13200 | F32: =+C32*$E$17 -> 0 | G32: =+F32/A32/$A$12 -> 0
A33: 31 | B33: 47604 | C33: =+'Cantidades P6_(2029-2040)'!AD68 -> 9820800 | D33: =+C33/A33/$A$12 -> 13200 | F33: =+C33*$E$17 -> 0 | G33: =+F33/A33/$A$12 -> 0
A34: 30 | B34: 47635 | C34: =+'Cantidades P6_(2029-2040)'!AD69 -> 9504000 | D34: =+C34/A34/$A$12 -> 13200 | F34: =+C34*$E$17 -> 0 | G34: =+F34/A34/$A$12 -> 0
A35: 31 | B35: 47665 | C35: =+'Cantidades P6_(2029-2040)'!AD70 -> 9820800 | D35: =+C35/A35/$A$12 -> 13200 | F35: =+C35*$E$17 -> 0 | G35: =+F35/A35/$A$12 -> 0
A36: 31 | B36: 47696 | C36: =+'Cantidades P6_(2029-2040)'!AD71 -> 9820800 | D36: =+C36/A36/$A$12 -> 13200 | F36: =+C36*$E$17 -> 0 | G36: =+F36/A36/$A$12 -> 0
A37: 30 | B37: 47727 | C37: =+'Cantidades P6_(2029-2040)'!AD72 -> 9504000 | D37: =+C37/A37/$A$12 -> 13200 | F37: =+C37*$E$17 -> 0 | G37: =+F37/A37/$A$12 -> 0
A38: 31 | B38: 47757 | C38: =+'Cantidades P6_(2029-2040)'!AD73 -> 9820800 | D38: =+C38/A38/$A$12 -> 13200 | F38: =+C38*$E$17 -> 0 | G38: =+F38/A38/$A$12 -> 0
A39: 30 | B39: 47788 | C39: =+'Cantidades P6_(2029-2040)'!AD74 -> 9504000 | D39: =+C39/A39/$A$12 -> 13200 | F39: =+C39*$E$17 -> 0 | G39: =+F39/A39/$A$12 -> 0
A40: 31 | B40: 47818 | C40: =+'Cantidades P6_(2029-2040)'!AD75 -> 9820800 | D40: =+C40/A40/$A$12 -> 13200 | F40: =+C40*$E$17 -> 0 | G40: =+F40/A40/$A$12 -> 0
A41: =SUM(A17:A28) -> 365 | B41: TOTAL | C41: =SUM(C17:C40) -> 231264000 | E41: =+E17 -> 0 | F41: =SUM(F17:F40) -> 0
B44: Notas:
B45: (1) La Energía Ofertada se distribuye en forma horaria de acuerdo con la curva de carga presentada en la tabla 9.6. TABLAS CANTIDADES DE ENERGÍA REQUERIDA PRODUCTO 6 AÑOS 2029 A 2030 del pliego de condiciones.
B47: (2) Tipo de Contrato: pague lo contratado.
B48: (3) Precio ofertado en $kWh, en pesos de Octubre 2025 (IPP Provisional)
B49: (4) El precio igual para todos los meses por año e Independiente por año del producto, con dos cifras decimales
...

Sheet Hoja9
B2: Mes | C2: AÑO 2026 Energia Solicitada (kWh) | D2: AÑO 2027 Energia Solicitada (kWh) | E2: AÑO 2028 Energia Solicitada (kWh) | F2: AÑO 2029 Energia Solicitada (kWh) | G2: AÑO 2030 Energia Solicitada (kWh) | H2: AÑO 2031 Energia Solicitada (kWh) | I2: AÑO 2032 Energia Solicitada (kWh) | J2: AÑO 2033 Energia Solicitada (kWh) | K2: AÑO 2034 Energia Solicitada (kWh) | L2: AÑO 2035 Energia Solicitada (kWh) | M2: TOTAL PRODUCTO 2 Energia Solicitada (kWh)
B3: CURVA | C3: La misma curva de la tabla 9.1.2 del producto 1 | D3: La misma curva de la tabla 9.1.3 del producto 1 | E3: La misma curva de la tabla 9.1.4 del producto 1 | F3: La misma curva de la tabla 9.1.5 del producto 1 | G3: La misma curva de la tabla 9.1.6 del producto 1 | H3: La misma curva de la tabla 9.1.7 del producto 1 | I3: La misma curva de la tabla 9.1.8 del producto 1 | J3: La misma curva de la tabla 9.1.9 del producto 1 | K3: La misma curva de la tabla 9.1.10 del producto 1 | L3: La misma curva de la tabla 9.1.11 del producto 1
B4: ene | C4: =+#REF! -> #REF! | D4: =+#REF! -> #REF! | E4: =+#REF! -> #REF! | F4: =+#REF! -> #REF! | G4: =+#REF! -> #REF! | H4: =+#REF! -> #REF! | I4: =+#REF! -> #REF! | J4: =+#REF! -> #REF! | ... L4: =+#REF! -> #REF! | M4: =SUM(C4:L4) -> #REF!
B5: feb | C5: =+#REF! -> #REF! | D5: =+#REF! -> #REF! | E5: =+#REF! -> #REF! | F5: =+#REF! -> #REF! | G5: =+#REF! -> #REF! | H5: =+#REF! -> #REF! | I5: =+#REF! -> #REF! | J5: =+#REF! -> #REF! | ... L5: =+#REF! -> #REF! | M5: =SUM(C5:L5) -> #REF!
B6: mar | C6: =+#REF! -> #REF! | D6: =+#REF! -> #REF! | E6: =+#REF! -> #REF! | F6: =+#REF! -> #REF! | G6: =+#REF! -> #REF! | H6: =+#REF! -> #REF! | I6: =+#REF! -> #REF! | J6: =+#REF! -> #REF! | ... L6: =+#REF! -> #REF! | M6: =SUM(C6:L6) -> #REF!
B7: abr | C7: =+#REF! -> #REF! | D7: =+#REF! -> #REF! | E7: =+#REF! -> #REF! | F7: =+#REF! -> #REF! | G7: =+#REF! -> #REF! | H7: =+#REF! -> #REF! | I7: =+#REF! -> #REF! | J7: =+#REF! -> #REF! | ... L7: =+#REF! -> #REF! | M7: =SUM(C7:L7) -> #REF!
B8: may | C8: =+#REF! -> #REF! | D8: =+#REF! -> #REF! | E8: =+#REF! -> #REF! | F8: =+#REF! -> #REF! | G8: =+#REF! -> #REF! | H8: =+#REF! -> #REF! | I8: =+#REF! -> #REF! | J8: =+#REF! -> #REF! | ... L8: =+#REF! -> #REF! | M8: =SUM(C8:L8) -> #REF!
B9: jun | C9: =+#REF! -> #REF! | D9: =+#REF! -> #REF! | E9: =+#REF! -> #REF! | F9: =+#REF! -> #REF! | G9: =+#REF! -> #REF! | H9: =+#REF! -> #REF! | I9: =+#REF! -> #REF! | J9: =+#REF! -> #REF! | ... L9: =+#REF! -> #REF! | M9: =SUM(C9:L9) -> #REF!
B10: jul | C10: =+#REF! -> #REF! | D10: =+#REF! -> #REF! | E10: =+#REF! -> #REF! | F10: =+#REF! -> #REF! | G10: =+#REF! -> #REF! | H10: =+#REF! -> #REF! | I10: =+#REF! -> #REF! | J10: =+#REF! -> #REF! | ... L10: =+#REF! -> #REF! | M10: =SUM(C10:L10) -> #REF!
B11: ago | C11: =+#REF! -> #REF! | D11: =+#REF! -> #REF! | E11: =+#REF! -> #REF! | F11: =+#REF! -> #REF! | G11: =+#REF! -> #REF! | H11: =+#REF! -> #REF! | I11: =+#REF! -> #REF! | J11: =+#REF! -> #REF! | ... L11: =+#REF! -> #REF! | M11: =SUM(C11:L11) -> #REF!
B12: sep | C12: =+#REF! -> #REF! | D12: =+#REF! -> #REF! | E12: =+#REF! -> #REF! | F12: =+#REF! -> #REF! | G12: =+#REF! -> #REF! | H12: =+#REF! -> #REF! | I12: =+#REF! -> #REF! | J12: =+#REF! -> #REF! | ... L12: =+#REF! -> #REF! | M12: =SUM(C12:L12) -> #REF!
B13: oct | C13: =+#REF! -> #REF! | D13: =+#REF! -> #REF! | E13: =+#REF! -> #REF! | F13: =+#REF! -> #REF! | G13: =+#REF! -> #REF! | H13: =+#REF! -> #REF! | I13: =+#REF! -> #REF! | J13: =+#REF! -> #REF! | ... L13: =+#REF! -> #REF! | M13: =SUM(C13:L13) -> #REF!
B14: nov | C14: =+#REF! -> #REF! | D14: =+#REF! -> #REF! | E14: =+#REF! -> #REF! | F14: =+#REF! -> #REF! | G14: =+#REF! -> #REF! | H14: =+#REF! -> #REF! | I14: =+#REF! -> #REF! | J14: =+#REF! -> #REF! | ... L14: =+#REF! -> #REF! | M14: =SUM(C14:L14) -> #REF!
B15: dic | C15: =+#REF! -> #REF! | D15: =+#REF! -> #REF! | E15: =+#REF! -> #REF! | F15: =+#REF! -> #REF! | G15: =+#REF! -> #REF! | H15: =+#REF! -> #REF! | I15: =+#REF! -> #REF! | J15: =+#REF! -> #REF! | ... L15: =+#REF! -> #REF! | M15: =SUM(C15:L15) -> #REF!
B16: TOTAL | C16: =SUM(C4:C15) -> #REF! | D16: =SUM(D4:D15) -> #REF! | E16: =SUM(E4:E15) -> #REF! | F16: =SUM(F4:F15) -> #REF! | G16: =SUM(G4:G15) -> #REF! | H16: =SUM(H4:H15) -> #REF! | I16: =SUM(I4:I15) -> #REF! | J16: =SUM(J4:J15) -> #REF! | ... M16: =SUM(M4:M15) -> #REF!
M17: =+M16-#REF! -> #REF!

Sheet Hoja9 (2)
B2: Mes | C2: AÑO 2027 Energia Solicitada (kWh) | D2: AÑO 2028 Energia Solicitada (kWh) | E2: AÑO 2029 Energia Solicitada (kWh) | F2: AÑO 2030 Energia Solicitada (kWh) | G2: AÑO 2031 Energia Solicitada (kWh) | H2: AÑO 2032 Energia Solicitada (kWh) | I2: AÑO 2033 Energia Solicitada (kWh) | J2: AÑO 2034 Energia Solicitada (kWh) | K2: AÑO 2035 Energia Solicitada (kWh) | L2: AÑO 2036 Energia Solicitada (kWh) | M2: TOTAL PRODUCTO 3 Energia Solicitada (kWh)
B3: CURVA | C3: La misma curva de la tabla 9.1.3 del producto 1 | D3: La misma curva de la tabla 9.1.4 del producto 1 | E3: La misma curva de la tabla 9.1.5 del producto 1 | F3: La misma curva de la tabla 9.1.6 del producto 1 | G3: La misma curva de la tabla 9.1.7 del producto 1 | H3: La misma curva de la tabla 9.1.8 del producto 1 | I3: La misma curva de la tabla 9.1.9 del producto 1 | J3: La misma curva de la tabla 9.1.10 del producto 1 | K3: La misma curva de la tabla 9.1.11 del producto 1 | L3: La misma curva de la tabla 9.1.12 del producto 1
B4: ene | C4: =+#REF! -> #REF! | D4: =+#REF! -> #REF! | E4: =+#REF! -> #REF! | F4: =+#REF! -> #REF! | G4: =+#REF! -> #REF! | H4: =+#REF! -> #REF! | I4: =+#REF! -> #REF! | J4: =+#REF! -> #REF! | ... L4: =+#REF! -> #REF! | M4: =SUM(C4:L4) -> #REF!
B5: feb | C5: =+#REF! -> #REF! | D5: =+#REF! -> #REF! | E5: =+#REF! -> #REF! | F5: =+#REF! -> #REF! | G5: =+#REF! -> #REF! | H5: =+#REF! -> #REF! | I5: =+#REF! -> #REF! | J5: =+#REF! -> #REF! | ... L5: =+#REF! -> #REF! | M5: =SUM(C5:L5) -> #REF!
B6: mar | C6: =+#REF! -> #REF! | D6: =+#REF! -> #REF! | E6: =+#REF! -> #REF! | F6: =+#REF! -> #REF! | G6: =+#REF! -> #REF! | H6: =+#REF! -> #REF! | I6: =+#REF! -> #REF! | J6: =+#REF! -> #REF! | ... L6: =+#REF! -> #REF! | M6: =SUM(C6:L6) -> #REF!
B7: abr | C7: =+#REF! -> #REF! | D7: =+#REF! -> #REF! | E7: =+#REF! -> #REF! | F7: =+#REF! -> #REF! | G7: =+#REF! -> #REF! | H7: =+#REF! -> #REF! | I7: =+#REF! -> #REF! | J7: =+#REF! -> #REF! | ... L7: =+#REF! -> #REF! | M7: =SUM(C7:L7) -> #REF!
B8: may | C8: =+#REF! -> #REF! | D8: =+#REF! -> #REF! | E8: =+#REF! -> #REF! | F8: =+#REF! -> #REF! | G8: =+#REF! -> #REF! | H8: =+#REF! -> #REF! | I8: =+#REF! -> #REF! | J8: =+#REF! -> #REF! | ... L8: =+#REF! -> #REF! | M8: =SUM(C8:L8) -> #REF!
B9: jun | C9: =+#REF! -> #REF! | D9: =+#REF! -> #REF! | E9: =+#REF! -> #REF! | F9: =+#REF! -> #REF! | G9: =+#REF! -> #REF! | H9: =+#REF! -> #REF! | I9: =+#REF! -> #REF! | J9: =+#REF! -> #REF! | ... L9: =+#REF! -> #REF! | M9: =SUM(C9:L9) -> #REF!
B10: jul | C10: =+#REF! -> #REF! | D10: =+#REF! -> #REF! | E10: =+#REF! -> #REF! | F10: =+#REF! -> #REF! | G10: =+#REF! -> #REF! | H10: =+#REF! -> #REF! | I10: =+#REF! -> #REF! | J10: =+#REF! -> #REF! | ... L10: =+#REF! -> #REF! | M10: =SUM(C10:L10) -> #REF!
B11: ago | C11: =+#REF! -> #REF! | D11: =+#REF! -> #REF! | E11: =+#REF! -> #REF! | F11: =+#REF! -> #REF! | G11: =+#REF! -> #REF! | H11: =+#REF! -> #REF! | I11: =+#REF! -> #REF! | J11: =+#REF! -> #REF! | ... L11: =+#REF! -> #REF! | M11: =SUM(C11:L11) -> #REF!
B12: sep | C12: =+#REF! -> #REF! | D12: =+#REF! -> #REF! | E12: =+#REF! -> #REF! | F12: =+#REF! -> #REF! | G12: =+#REF! -> #REF! | H12: =+#REF! -> #REF! | I12: =+#REF! -> #REF! | J12: =+#REF! -> #REF! | ... L12: =+#REF! -> #REF! | M12: =SUM(C12:L12) -> #REF!
B13: oct | C13: =+#REF! -> #REF! | D13: =+#REF! -> #REF! | E13: =+#REF! -> #REF! | F13: =+#REF! -> #REF! | G13: =+#REF! -> #REF! | H13: =+#REF! -> #REF! | I13: =+#REF! -> #REF! | J13: =+#REF! -> #REF! | ... L13: =+#REF! -> #REF! | M13: =SUM(C13:L13) -> #REF!
B14: nov | C14: =+#REF! -> #REF! | D14: =+#REF! -> #REF! | E14: =+#REF! -> #REF! | F14: =+#REF! -> #REF! | G14: =+#REF! -> #REF! | H14: =+#REF! -> #REF! | I14: =+#REF! -> #REF! | J14: =+#REF! -> #REF! | ... L14: =+#REF! -> #REF! | M14: =SUM(C14:L14) -> #REF!
B15: dic | C15: =+#REF! -> #REF! | D15: =+#REF! -> #REF! | E15: =+#REF! -> #REF! | F15: =+#REF! -> #REF! | G15: =+#REF! -> #REF! | H15: =+#REF! -> #REF! | I15: =+#REF! -> #REF! | J15: =+#REF! -> #REF! | ... L15: =+#REF! -> #REF! | M15: =SUM(C15:L15) -> #REF!
B16: TOTAL | C16: =SUM(C4:C15) -> #REF! | D16: =SUM(D4:D15) -> #REF! | E16: =SUM(E4:E15) -> #REF! | F16: =SUM(F4:F15) -> #REF! | G16: =SUM(G4:G15) -> #REF! | H16: =SUM(H4:H15) -> #REF! | I16: =SUM(I4:I15) -> #REF! | J16: =SUM(J4:J15) -> #REF! | ... M16: =SUM(M4:M15) -> #REF!
M17: =+M16-#REF! -> #REF!

Sheet Cantidades 1_(26-28)
B4: 9.1 TABLAS CANTIDADES DE ENERGÍA REQUERIDA PRODUCTO 1 AÑO 2026 -2028 (kWh)
B5: ELETRIFICADORA DE SANTANDER S.A E.S.P.
B6: SOLICITUD PÚBLICA DE OFERTAS CP-ESSC2025-003
B7: PAGUELO CONTRATADO
B10: Mes | C10: Tipo Día | D10: Días | E10: H1 | F10: H2 | G10: H3 | H10: H4 | I10: H5 | J10: H6 | K10: H7 | L10: H8 | M10: H9 | N10: H10 | O10: H11 | P10: H12 | Q10: H13 | R10: H14 | S10: H15 | T10: H16 | U10: H17 | V10: H18 | W10: H19 | X10: H20 | Y10: H21 | Z10: H22 | AA10: H23 | AB10: H24 | AC10: TOTAL MES kWh | AE10: =+AC10 -> TOTAL MES kWh
B11: 46023 | C11: Ordinario | D11: 20 | AC11: =SUM(E11:AB11)*D11+SUM(E12:AB12)*D12+SUM(E13:AB13)*D13+SUM(E14:AB14)*D14 -> 0 | AE11: =+AC11 -> 0
C12: Sábado | D12: 5 | AE12: =+AC15 -> 3360000
C13: Domingo | D13: 4 | AE13: =+AC19 -> 3720000
C14: Festivo | D14: 2 | AE14: =+AC23 -> 3600000
B15: 46054 | C15: Ordinario | D15: 20 | E15: 5000 | F15: 5000 | G15: 5000 | H15: 5000 | I15: 5000 | J15: 5000 | K15: 5000 | L15: 5000 | M15: 5000 | N15: 5000 | O15: 5000 | P15: 5000 | Q15: 5000 | R15: 5000 | S15: 5000 | T15: 5000 | U15: 5000 | V15: 5000 | W15: 5000 | X15: 5000 | Y15: 5000 | Z15: 5000 | AA15: 5000 | AB15: 5000 | AC15: =SUM(E15:AB15)*D15+SUM(E16:AB16)*D16+SUM(E17:AB17)*D17+SUM(E18:AB18)*D18 -> 3360000 | AD15: =+AC15 -> 3360000 | AE15: =+AC27 -> 3720000
B16: Feb | C16: Sábado | D16: 4 | E16: 5000 | F16: 5000 | G16: 5000 | H16: 5000 | I16: 5000 | J16: 5000 | K16: 5000 | L16: 5000 | M16: 5000 | N16: 5000 | O16: 5000 | P16: 5000 | Q16: 5000 | R16: 5000 | S16: 5000 | T16: 5000 | U16: 5000 | V16: 5000 | W16: 5000 | X16: 5000 | Y16: 5000 | Z16: 5000 | AA16: 5000 | AB16: 5000 | AD16: =+AC19 -> 3720000 | AE16: =+AC31 -> 3600000
B17: Feb | C17: Domingo | D17: 4 | E17: 5000 | F17: 5000 | G17: 5000 | H17: 5000 | I17: 5000 | J17: 5000 | K17: 5000 | L17: 5000 | M17: 5000 | N17: 5000 | O17: 5000 | P17: 5000 | Q17: 5000 | R17: 5000 | S17: 5000 | T17: 5000 | U17: 5000 | V17: 5000 | W17: 5000 | X17: 5000 | Y17: 5000 | Z17: 5000 | AA17: 5000 | AB17: 5000 | AD17: =+AC23 -> 3600000 | AE17: =+AC35 -> 3720000
B18: Feb | C18: Festivo | D18: 0 | AD18: =+AC27 -> 3720000 | AE18: =+AC39 -> 3720000
B19: 46082 | C19: Ordinario | D19: 21 | E19: 5000 | F19: 5000 | G19: 5000 | H19: 5000 | I19: 5000 | J19: 5000 | K19: 5000 | L19: 5000 | M19: 5000 | N19: 5000 | O19: 5000 | P19: 5000 | Q19: 5000 | R19: 5000 | S19: 5000 | T19: 5000 | U19: 5000 | V19: 5000 | W19: 5000 | X19: 5000 | Y19: 5000 | Z19: 5000 | AA19: 5000 | AB19: 5000 | AC19: =SUM(E19:AB19)*D19+SUM(E20:AB20)*D20+SUM(E21:AB21)*D21+SUM(E22:AB22)*D22 -> 3720000 | AD19: =+AC31 -> 3600000 | AE19: =+AC43 -> 3600000
C20: Sábado | D20: 4 | E20: 5000 | F20: 5000 | G20: 5000 | H20: 5000 | I20: 5000 | J20: 5000 | K20: 5000 | L20: 5000 | M20: 5000 | N20: 5000 | O20: 5000 | P20: 5000 | Q20: 5000 | R20: 5000 | S20: 5000 | T20: 5000 | U20: 5000 | V20: 5000 | W20: 5000 | X20: 5000 | Y20: 5000 | Z20: 5000 | AA20: 5000 | AB20: 5000 | AD20: =+AC35 -> 3720000 | AE20: =+AC47 -> 3720000
C21: Domingo | D21: 5 | E21: 5000 | F21: 5000 | G21: 5000 | H21: 5000 | I21: 5000 | J21: 5000 | K21: 5000 | L21: 5000 | M21: 5000 | N21: 5000 | O21: 5000 | P21: 5000 | Q21: 5000 | R21: 5000 | S21: 5000 | T21: 5000 | U21: 5000 | V21: 5000 | W21: 5000 | X21: 5000 | Y21: 5000 | Z21: 5000 | AA21: 5000 | AB21: 5000 | AD21: =+AC39 -> 3720000 | AE21: =+AC51 -> 3600000
C22: Festivo | D22: 1 | E22: 5000 | F22: 5000 | G22: 5000 | H22: 5000 | I22: 5000 | J22: 5000 | K22: 5000 | L22: 5000 | M22: 5000 | N22: 5000 | O22: 5000 | P22: 5000 | Q22: 5000 | R22: 5000 | S22: 5000 | T22: 5000 | U22: 5000 | V22: 5000 | W22: 5000 | X22: 5000 | Y22: 5000 | Z22: 5000 | AA22: 5000 | AB22: 5000 | AD22: =+AC43 -> 3600000 | AE22: =+AC55 -> 3720000
B23: 46113 | C23: Ordinario | D23: 20 | E23: 5000 | F23: 5000 | G23: 5000 | H23: 5000 | I23: 5000 | J23: 5000 | K23: 5000 | L23: 5000 | M23: 5000 | N23: 5000 | O23: 5000 | P23: 5000 | Q23: 5000 | R23: 5000 | S23: 5000 | T23: 5000 | U23: 5000 | V23: 5000 | W23: 5000 | X23: 5000 | Y23: 5000 | Z23: 5000 | AA23: 5000 | AB23: 5000 | AC23: =SUM(E23:AB23)*D23+SUM(E24:AB24)*D24+SUM(E25:AB25)*D25+SUM(E26:AB26)*D26 -> 3600000 | AD23: =+AC47 -> 3720000 | AE23: =SUM(AE11:AE22) -> 40080000
B24: Feb | C24: Sábado | D24: 4 | E24: 5000 | F24: 5000 | G24: 5000 | H24: 5000 | I24: 5000 | J24: 5000 | K24: 5000 | L24: 5000 | M24: 5000 | N24: 5000 | O24: 5000 | P24: 5000 | Q24: 5000 | R24: 5000 | S24: 5000 | T24: 5000 | U24: 5000 | V24: 5000 | W24: 5000 | X24: 5000 | Y24: 5000 | Z24: 5000 | AA24: 5000 | AB24: 5000 | AD24: =+AC51 -> 3600000
B25: Feb | C25: Domingo | D25: 4 | E25: 5000 | F25: 5000 | G25: 5000 | H25: 5000 | I25: 5000 | J25: 5000 | K25: 5000 | L25: 5000 | M25: 5000 | N25: 5000 | O25: 5000 | P25: 5000 | Q25: 5000 | R25: 5000 | S25: 5000 | T25: 5000 | U25: 5000 | V25: 5000 | W25: 5000 | X25: 5000 | Y25: 5000 | Z25: 5000 | AA25: 5000 | AB25: 5000 | AD25: =+AC55 -> 3720000
B26: Feb | C26: Festivo | D26: 2 | E26: 5000 | F26: 5000 | G26: 5000 | H26: 5000 | I26: 5000 | J26: 5000 | K26: 5000 | L26: 5000 | M26: 5000 | N26: 5000 | O26: 5000 | P26: 5000 | Q26: 5000 | R26: 5000 | S26: 5000 | T26: 5000 | U26: 5000 | V26: 5000 | W26: 5000 | X26: 5000 | Y26: 5000 | Z26: 5000 | AA26: 5000 | AB26: 5000
B27: 46143 | C27: Ordinario | D27: 19 | E27: 5000 | F27: 5000 | G27: 5000 | H27: 5000 | I27: 5000 | J27: 5000 | K27: 5000 | L27: 5000 | M27: 5000 | N27: 5000 | O27: 5000 | P27: 5000 | Q27: 5000 | R27: 5000 | S27: 5000 | T27: 5000 | U27: 5000 | V27: 5000 | W27: 5000 | X27: 5000 | Y27: 5000 | Z27: 5000 | AA27: 5000 | AB27: 5000 | AC27: =SUM(E27:AB27)*D27+SUM(E28:AB28)*D28+SUM(E29:AB29)*D29+SUM(E30:AB30)*D30 -> 3720000
C28: Sábado | D28: 5 | E28: 5000 | F28: 5000 | G28: 5000 | H28: 5000 | I28: 5000 | J28: 5000 | K28: 5000 | L28: 5000 | M28: 5000 | N28: 5000 | O28: 5000 | P28: 5000 | Q28: 5000 | R28: 5000 | S28: 5000 | T28: 5000 | U28: 5000 | V28: 5000 | W28: 5000 | X28: 5000 | Y28: 5000 | Z28: 5000 | AA28: 5000 | AB28: 5000
C29: Domingo | D29: 5 | E29: 5000 | F29: 5000 | G29: 5000 | H29: 5000 | I29: 5000 | J29: 5000 | K29: 5000 | L29: 5000 | M29: 5000 | N29: 5000 | O29: 5000 | P29: 5000 | Q29: 5000 | R29: 5000 | S29: 5000 | T29: 5000 | U29: 5000 | V29: 5000 | W29: 5000 | X29: 5000 | Y29: 5000 | Z29: 5000 | AA29: 5000 | AB29: 5000
C30: Festivo | D30: 2 | E30: 5000 | F30: 5000 | G30: 5000 | H30: 5000 | I30: 5000 | J30: 5000 | K30: 5000 | L30: 5000 | M30: 5000 | N30: 5000 | O30: 5000 | P30: 5000 | Q30: 5000 | R30: 5000 | S30: 5000 | T30: 5000 | U30: 5000 | V30: 5000 | W30: 5000 | X30: 5000 | Y30: 5000 | Z30: 5000 | AA30: 5000 | AB30: 5000
B31: 46174 | C31: Ordinario | D31: 19 | E31: 5000 | F31: 5000 | G31: 5000 | H31: 5000 | I31: 5000 | J31: 5000 | K31: 5000 | L31: 5000 | M31: 5000 | N31: 5000 | O31: 5000 | P31: 5000 | Q31: 5000 | R31: 5000 | S31: 5000 | T31: 5000 | U31: 5000 | V31: 5000 | W31: 5000 | X31: 5000 | Y31: 5000 | Z31: 5000 | AA31: 5000 | AB31: 5000 | AC31: =SUM(E31:AB31)*D31+SUM(E32:AB32)*D32+SUM(E33:AB33)*D33+SUM(E34:AB34)*D34 -> 3600000
B32: Feb | C32: Sábado | D32: 4 | E32: 5000 | F32: 5000 | G32: 5000 | H32: 5000 | I32: 5000 | J32: 5000 | K32: 5000 | L32: 5000 | M32: 5000 | N32: 5000 | O32: 5000 | P32: 5000 | Q32: 5000 | R32: 5000 | S32: 5000 | T32: 5000 | U32: 5000 | V32: 5000 | W32: 5000 | X32: 5000 | Y32: 5000 | Z32: 5000 | AA32: 5000 | AB32: 5000
B33: Feb | C33: Domingo | D33: 4 | E33: 5000 | F33: 5000 | G33: 5000 | H33: 5000 | I33: 5000 | J33: 5000 | K33: 5000 | L33: 5000 | M33: 5000 | N33: 5000 | O33: 5000 | P33: 5000 | Q33: 5000 | R33: 5000 | S33: 5000 | T33: 5000 | U33: 5000 | V33: 5000 | W33: 5000 | X33: 5000 | Y33: 5000 | Z33: 5000 | AA33: 5000 | AB33: 5000
B34: Feb | C34: Festivo | D34: 3 | E34: 5000 | F34: 5000 | G34: 5000 | H34: 5000 | I34: 5000 | J34: 5000 | K34: 5000 | L34: 5000 | M34: 5000 | N34: 5000 | O34: 5000 | P34: 5000 | Q34: 5000 | R34: 5000 | S34: 5000 | T34: 5000 | U34: 5000 | V34: 5000 | W34: 5000 | X34: 5000 | Y34: 5000 | Z34: 5000 | AA34: 5000 | AB34: 5000
B35: 46204 | C35: Ordinario | D35: 22 | E35: 5000 | F35: 5000 | G35: 5000 | H35: 5000 | I35: 5000 | J35: 5000 | K35: 5000 | L35: 5000 | M35: 5000 | N35: 5000 | O35: 5000 | P35: 5000 | Q35: 5000 | R35: 5000 | S35: 5000 | T35: 5000 | U35: 5000 | V35: 5000 | W35: 5000 | X35: 5000 | Y35: 5000 | Z35: 5000 | AA35: 5000 | AB35: 5000 | AC35: =SUM(E35:AB35)*D35+SUM(E36:AB36)*D36+SUM(E37:AB37)*D37+SUM(E38:AB38)*D38 -> 3720000
C36: Sábado | D36: 4 | E36: 5000 | F36: 5000 | G36: 5000 | H36: 5000 | I36: 5000 | J36: 5000 | K36: 5000 | L36: 5000 | M36: 5000 | N36: 5000 | O36: 5000 | P36: 5000 | Q36: 5000 | R36: 5000 | S36: 5000 | T36: 5000 | U36: 5000 | V36: 5000 | W36: 5000 | X36: 5000 | Y36: 5000 | Z36: 5000 | AA36: 5000 | AB36: 5000
C37: Domingo | D37: 4 | E37: 5000 | F37: 5000 | G37: 5000 | H37: 5000 | I37: 5000 | J37: 5000 | K37: 5000 | L37: 5000 | M37: 5000 | N37: 5000 | O37: 5000 | P37: 5000 | Q37: 5000 | R37: 5000 | S37: 5000 | T37: 5000 | U37: 5000 | V37: 5000 | W37: 5000 | X37: 5000 | Y37: 5000 | Z37: 5000 | AA37: 5000 | AB37: 5000
C38: Festivo | D38: 1 | E38: 5000 | F38: 5000 | G38: 5000 | H38: 5000 | I38: 5000 | J38: 5000 | K38: 5000 | L38: 5000 | M38: 5000 | N38: 5000 | O38: 5000 | P38: 5000 | Q38: 5000 | R38: 5000 | S38: 5000 | T38: 5000 | U38: 5000 | V38: 5000 | W38: 5000 | X38: 5000 | Y38: 5000 | Z38: 5000 | AA38: 5000 | AB38: 5000
B39: 46235 | C39: Ordinario | D39: 19 | E39: 5000 | F39: 5000 | G39: 5000 | H39: 5000 | I39: 5000 | J39: 5000 | K39: 5000 | L39: 5000 | M39: 5000 | N39: 5000 | O39: 5000 | P39: 5000 | Q39: 5000 | R39: 5000 | S39: 5000 | T39: 5000 | U39: 5000 | V39: 5000 | W39: 5000 | X39: 5000 | Y39: 5000 | Z39: 5000 | AA39: 5000 | AB39: 5000 | AC39: =SUM(E39:AB39)*D39+SUM(E40:AB40)*D40+SUM(E41:AB41)*D41+SUM(E42:AB42)*D42 -> 3720000
B40: Feb | C40: Sábado | D40: 5 | E40: 5000 | F40: 5000 | G40: 5000 | H40: 5000 | I40: 5000 | J40: 5000 | K40: 5000 | L40: 5000 | M40: 5000 | N40: 5000 | O40: 5000 | P40: 5000 | Q40: 5000 | R40: 5000 | S40: 5000 | T40: 5000 | U40: 5000 | V40: 5000 | W40: 5000 | X40: 5000 | Y40: 5000 | Z40: 5000 | AA40: 5000 | AB40: 5000
B41: Feb | C41: Domingo | D41: 5 | E41: 5000 | F41: 5000 | G41: 5000 | H41: 5000 | I41: 5000 | J41: 5000 | K41: 5000 | L41: 5000 | M41: 5000 | N41: 5000 | O41: 5000 | P41: 5000 | Q41: 5000 | R41: 5000 | S41: 5000 | T41: 5000 | U41: 5000 | V41: 5000 | W41: 5000 | X41: 5000 | Y41: 5000 | Z41: 5000 | AA41: 5000 | AB41: 5000
B42: Feb | C42: Festivo | D42: 2 | E42: 5000 | F42: 5000 | G42: 5000 | H42: 5000 | I42: 5000 | J42: 5000 | K42: 5000 | L42: 5000 | M42: 5000 | N42: 5000 | O42: 5000 | P42: 5000 | Q42: 5000 | R42: 5000 | S42: 5000 | T42: 5000 | U42: 5000 | V42: 5000 | W42: 5000 | X42: 5000 | Y42: 5000 | Z42: 5000 | AA42: 5000 | AB42: 5000
B43: 46266 | C43: Ordinario | D43: 22 | E43: 5000 | F43: 5000 | G43: 5000 | H43: 5000 | I43: 5000 | J43: 5000 | K43: 5000 | L43: 5000 | M43: 5000 | N43: 5000 | O43: 5000 | P43: 5000 | Q43: 5000 | R43: 5000 | S43: 5000 | T43: 5000 | U43: 5000 | V43: 5000 | W43: 5000 | X43: 5000 | Y43: 5000 | Z43: 5000 | AA43: 5000 | AB43: 5000 | AC43: =SUM(E43:AB43)*D43+SUM(E44:AB44)*D44+SUM(E45:AB45)*D45+SUM(E46:AB46)*D46 -> 3600000
C44: Sábado | D44: 4 | E44: 5000 | F44: 5000 | G44: 5000 | H44: 5000 | I44: 5000 | J44: 5000 | K44: 5000 | L44: 5000 | M44: 5000 | N44: 5000 | O44: 5000 | P44: 5000 | Q44: 5000 | R44: 5000 | S44: 5000 | T44: 5000 | U44: 5000 | V44: 5000 | W44: 5000 | X44: 5000 | Y44: 5000 | Z44: 5000 | AA44: 5000 | AB44: 5000
C45: Domingo | D45: 4 | E45: 5000 | F45: 5000 | G45: 5000 | H45: 5000 | I45: 5000 | J45: 5000 | K45: 5000 | L45: 5000 | M45: 5000 | N45: 5000 | O45: 5000 | P45: 5000 | Q45: 5000 | R45: 5000 | S45: 5000 | T45: 5000 | U45: 5000 | V45: 5000 | W45: 5000 | X45: 5000 | Y45: 5000 | Z45: 5000 | AA45: 5000 | AB45: 5000
...

Sheet Cantidades 2_(2026)
B4: 9.2 TABLAS CANTIDADES DE ENERGÍA REQUERIDA PRODUCTO 2 AÑO 2026 (kWh)
B5: ELETRIFICADORA DE SANTANDER S.A E.S.P.
B6: SOLICITUD PÚBLICA DE OFERTAS CP-ESSC2025-003
B7: PAGUELO CONTRATADO
B10: Mes | C10: Tipo Día | D10: Días | E10: H1 | F10: H2 | G10: H3 | H10: H4 | I10: H5 | J10: H6 | K10: H7 | L10: H8 | M10: H9 | N10: H10 | O10: H11 | P10: H12 | Q10: H13 | R10: H14 | S10: H15 | T10: H16 | U10: H17 | V10: H18 | W10: H19 | X10: H20 | Y10: H21 | Z10: H22 | AA10: H23 | AB10: H24 | AC10: TOTAL MES kWh | AE10: =+AC10 -> TOTAL MES kWh
B11: 46023 | C11: Ordinario | D11: 20 | AC11: =SUM(E11:AB11)*D11+SUM(E12:AB12)*D12+SUM(E13:AB13)*D13+SUM(E14:AB14)*D14 -> 0 | AE11: =+AC11 -> 0
C12: Sábado | D12: 5 | AE12: =+AC15 -> 8204162
C13: Domingo | D13: 4 | AE13: =+AC19 -> 9865393.2
C14: Festivo | D14: 2 | AE14: =+AC23 -> 5842730.4
B15: 46054 | C15: Ordinario | D15: 20 | E15: 10269.7 | F15: 9463.9 | G15: 8888.4 | H15: 8511.6 | I15: 8539.3 | J15: 9291.3 | K15: 9253.1 | L15: 10724.5 | M15: 12208.3 | N15: 12936.9 | O15: 13807.3 | P15: 14391.3 | Q15: 13661.5 | R15: 14327 | S15: 15305.2 | T15: 15430.9 | U15: 15073.1 | V15: 14218.3 | W15: 15239.8 | X15: 15567.3 | Y15: 15160.1 | Z15: 14282.2 | AA15: 12851.3 | AB15: 11412.3 | AC15: =SUM(E15:AB15)*D15+SUM(E16:AB16)*D16+SUM(E17:AB17)*D17+SUM(E18:AB18)*D18 -> 8204162 | AD15: =+AC15 -> 8204162 | AE15: =+AC27 -> 2193087.3
B16: Feb | C16: Sábado | D16: 4 | E16: 10318.4 | F16: 9572.5 | G16: 8924.2 | H16: 8484.5 | I16: 8316.6 | J16: 8449.9 | K16: 8314.3 | L16: 9637.4 | M16: 11228.3 | N16: 12227.5 | O16: 13044.5 | P16: 13585.6 | Q16: 13261.5 | R16: 13048.4 | S16: 13143.2 | T16: 13140.9 | U16: 12865.5 | V16: 12741 | W16: 14432.7 | X16: 14827.6 | Y16: 14312.4 | Z16: 13616.6 | AA16: 12670.8 | AB16: 11558.5 | AD16: =+AC19 -> 9865393.2 | AE16: =+AC31 -> 2044913.6
B17: Feb | C17: Domingo | D17: 4 | E17: 10556.5 | F17: 9760 | G17: 9143.8 | H17: 8691.8 | I17: 8405.6 | J17: 8345.4 | K17: 7757.3 | L17: 8327.3 | M17: 9260.7 | N17: 10108.2 | O17: 10726.3 | P17: 11355 | Q17: 11715.5 | R17: 11826 | S17: 11926 | T17: 12003.3 | U17: 11891.8 | V17: 11852.2 | W17: 13737.6 | X17: 14581.6 | Y17: 14596.1 | Z17: 14110 | AA17: 12966.6 | AB17: 11600.1 | AD17: =+AC23 -> 5842730.4 | AE17: =+AC35 -> 2074770.6
B18: Feb | C18: Festivo | D18: 0 | E18: 0 | F18: 0 | G18: 0 | H18: 0 | I18: 0 | J18: 0 | K18: 0 | L18: 0 | M18: 0 | N18: 0 | O18: 0 | P18: 0 | Q18: 0 | R18: 0 | S18: 0 | T18: 0 | U18: 0 | V18: 0 | W18: 0 | X18: 0 | Y18: 0 | Z18: 0 | AA18: 0 | AB18: 0 | AD18: =+AC27 -> 2193087.3 | AE18: =+AC39 -> 2068744
B19: 46082 | C19: Ordinario | D19: 21 | E19: 11576.7 | F19: 10700.6 | G19: 10040.4 | H19: 9553.2 | I19: 9480 | J19: 10010.2 | K19: 9907.1 | L19: 11615.9 | M19: 13339.3 | N19: 14241.2 | O19: 15264.3 | P19: 15930.4 | Q19: 15177.1 | R19: 15981.2 | S19: 16955.8 | T19: 17060.5 | U19: 16677.1 | V19: 15751.2 | W19: 16682 | X19: 16953 | Y19: 16558.4 | Z19: 15721.8 | AA19: 14413.1 | AB19: 12940.9 | AC19: =SUM(E19:AB19)*D19+SUM(E20:AB20)*D20+SUM(E21:AB21)*D21+SUM(E22:AB22)*D22 -> 9865393.2 | AD19: =+AC31 -> 2044913.6 | AE19: =+AC43 -> 2666666.2
C20: Sábado | D20: 4 | E20: 11624.8 | F20: 10721 | G20: 10084.3 | H20: 9580.4 | I20: 9279.7 | J20: 9233.7 | K20: 9025.2 | L20: 10366.9 | M20: 11984.3 | N20: 12997.1 | O20: 13803.9 | P20: 14319.7 | Q20: 14045.7 | R20: 13847.3 | S20: 13734 | T20: 14196.7 | U20: 13545.9 | V20: 13395.4 | W20: 15321.3 | X20: 15624.4 | Y20: 15123.6 | Z20: 14479.1 | AA20: 13624.2 | AB20: 12537.7 | AD20: =+AC35 -> 2074770.6 | AE20: =+AC47 -> 1969082
C21: Domingo | D21: 5 | E21: 11491.6 | F21: 10647.4 | G21: 9893.8 | H21: 9365.1 | I21: 9119.9 | J21: 8960.2 | K21: 8278.2 | L21: 8916.8 | M21: 9841.9 | N21: 10687.9 | O21: 11329.2 | P21: 11935.5 | Q21: 12240.1 | R21: 12317.9 | S21: 12407 | T21: 12531.1 | U21: 12314.4 | V21: 12356.1 | W21: 14224.9 | X21: 14916 | Y21: 14880.2 | Z21: 14495 | AA21: 13458.8 | AB21: 12099.1 | AD21: =+AC39 -> 2068744 | AE21: =+AC51 -> 1831628.2
C22: Festivo | D22: 1 | E22: 11491.6 | F22: 10647.4 | G22: 9893.8 | H22: 9365.1 | I22: 9119.9 | J22: 8960.2 | K22: 8278.2 | L22: 8916.8 | M22: 9841.9 | N22: 10687.9 | O22: 11329.2 | P22: 11935.5 | Q22: 12240.1 | R22: 12317.9 | S22: 12407 | T22: 12531.1 | U22: 12314.4 | V22: 12356.1 | W22: 14224.9 | X22: 14916 | Y22: 14880.2 | Z22: 14495 | AA22: 13458.8 | AB22: 12099.1 | AD22: =+AC43 -> 2666666.2 | AE22: =+AC55 -> 5062929.3
B23: 46113 | C23: Ordinario | D23: 20 | E23: 6899.4 | F23: 6386.4 | G23: 5883.5 | H23: 5602.4 | I23: 5535.3 | J23: 5425.9 | K23: 5462.1 | L23: 6638.1 | M23: 7972.9 | N23: 8761.7 | O23: 9417.4 | P23: 9830.5 | Q23: 9554.9 | R23: 9380.3 | S23: 9480.1 | T23: 9477.9 | U23: 9250.2 | V23: 9167.9 | W23: 10605.2 | X23: 10729.4 | Y23: 10344.2 | Z23: 9811.1 | AA23: 9082.6 | AB23: 8200.2 | AC23: =SUM(E23:AB23)*D23+SUM(E24:AB24)*D24+SUM(E25:AB25)*D25+SUM(E26:AB26)*D26 -> 5842730.4 | AD23: =+AC47 -> 1969082 | AE23: =SUM(AE11:AE22) -> 43824107
B24: Feb | C24: Sábado | D24: 4 | E24: 6488.7 | F24: 5922.5 | G24: 5492.4 | H24: 5175.2 | I24: 5184.7 | J24: 5310.3 | K24: 5542 | L24: 6689.1 | M24: 7867.8 | N24: 8554.5 | O24: 9170.3 | P24: 9595.4 | Q24: 9196.1 | R24: 9476.2 | S24: 9958.6 | T24: 9990.8 | U24: 9754.7 | V24: 9432.4 | W24: 10427 | X24: 10560.4 | Y24: 10155.1 | Z24: 9490.5 | AA24: 8446.9 | AB24: 7294.4 | AD24: =+AC51 -> 1831628.2
B25: Feb | C25: Domingo | D25: 4 | E25: 7381.4 | F25: 6754.4 | G25: 6235.1 | H25: 5880.8 | I25: 5673.2 | J25: 5356.7 | K25: 5039.5 | L25: 5601.9 | M25: 6345.2 | N25: 7015.4 | O25: 7545.3 | P25: 7977.7 | Q25: 8176.7 | R25: 8213.5 | S25: 8141 | T25: 8082.6 | U25: 7949.1 | V25: 8072.8 | W25: 9606.3 | X25: 10045.5 | Y25: 9943.8 | Z25: 9485.2 | AA25: 8601.8 | AB25: 7547.5 | AD25: =+AC55 -> 5062929.3
B26: Feb | C26: Festivo | D26: 2 | E26: 7381.4 | F26: 6754.4 | G26: 6235.1 | H26: 5880.8 | I26: 5673.2 | J26: 5356.7 | K26: 5039.5 | L26: 5601.9 | M26: 6345.2 | N26: 7015.4 | O26: 7545.3 | P26: 7977.7 | Q26: 8176.7 | R26: 8213.5 | S26: 8141 | T26: 8082.6 | U26: 7949.1 | V26: 8072.8 | W26: 9606.3 | X26: 10045.5 | Y26: 9943.8 | Z26: 9485.2 | AA26: 8601.8 | AB26: 7547.5
B27: 46143 | C27: Ordinario | D27: 19 | E27: 2523.9 | F27: 2132.4 | G27: 1816.5 | H27: 1546.3 | I27: 1473.5 | J27: 1370.9 | K27: 1465.1 | L27: 2160.5 | M27: 2970.9 | N27: 3418.1 | O27: 3701.9 | P27: 3910.4 | Q27: 3757.3 | R27: 3599.8 | S27: 3594 | T27: 3545.6 | U27: 3429.5 | V27: 3481.2 | W27: 4401.7 | X27: 4489.2 | Y27: 4183.6 | Z27: 3804.6 | AA27: 3306.2 | AB27: 2747.9 | AC27: =SUM(E27:AB27)*D27+SUM(E28:AB28)*D28+SUM(E29:AB29)*D29+SUM(E30:AB30)*D30 -> 2193087.3
C28: Sábado | D28: 5 | E28: 1936.2 | F28: 1593.1 | G28: 1342 | H28: 1169 | I28: 1146.8 | J28: 1139.1 | K28: 1232.6 | L28: 1963 | M28: 2677.2 | N28: 3089.6 | O28: 3492.5 | P28: 3782.7 | Q28: 3591.1 | R28: 3682.6 | S28: 3911.2 | T28: 3900 | U28: 3771.8 | V28: 3601.4 | W28: 4228 | X28: 4401.8 | Y28: 4145.8 | Z28: 3725.3 | AA28: 3093.3 | AB28: 2434.2
C29: Domingo | D29: 5 | E29: 1931.1 | F29: 1659.7 | G29: 1381.3 | H29: 1233.3 | I29: 1185.9 | J29: 1032.3 | K29: 1007.2 | L29: 1472.7 | M29: 2012.5 | N29: 2432.1 | O29: 2751.2 | P29: 3147.6 | Q29: 3369.7 | R29: 3411.7 | S29: 3421.4 | T29: 3437.9 | U29: 3351.9 | V29: 3354 | W29: 4337.1 | X29: 4691.5 | Y29: 4632.5 | Z29: 4308 | AA29: 3712.7 | AB29: 3017.1
C30: Festivo | D30: 2 | E30: 1931.1 | F30: 1659.7 | G30: 1381.3 | H30: 1233.3 | I30: 1185.9 | J30: 1032.3 | K30: 1007.2 | L30: 1472.7 | M30: 2012.5 | N30: 2432.1 | O30: 2751.2 | P30: 3147.6 | Q30: 3369.7 | R30: 3411.7 | S30: 3421.4 | T30: 3437.9 | U30: 3351.9 | V30: 3354 | W30: 4337.1 | X30: 4691.5 | Y30: 4632.5 | Z30: 4308 | AA30: 3712.7 | AB30: 3017.1
B31: 46174 | C31: Ordinario | D31: 19 | E31: 1963.3 | F31: 1617.6 | G31: 1362.2 | H31: 1191.7 | I31: 1146.2 | J31: 1080.9 | K31: 1182.4 | L31: 1927.1 | M31: 2745.9 | N31: 3249.4 | O31: 3686.9 | P31: 3927.7 | Q31: 3795.9 | R31: 3644.9 | S31: 3652.2 | T31: 3627.3 | U31: 3539.9 | V31: 3549 | W31: 4285.5 | X31: 4418 | Y31: 4089.9 | Z31: 3715.4 | AA31: 3253.1 | AB31: 2730.9 | AC31: =SUM(E31:AB31)*D31+SUM(E32:AB32)*D32+SUM(E33:AB33)*D33+SUM(E34:AB34)*D34 -> 2044913.6
B32: Feb | C32: Sábado | D32: 4 | E32: 2170.9 | F32: 1818 | G32: 1549.8 | H32: 1363.8 | I32: 1341.9 | J32: 1413 | K32: 1456.6 | L32: 2182.9 | M32: 2950.3 | N32: 3394.3 | O32: 3813.3 | P32: 4086.7 | Q32: 3855.3 | R32: 4068.3 | S32: 4376.2 | T32: 4388.6 | U32: 4213.8 | V32: 3911 | W32: 4434.8 | X32: 4710.9 | Y32: 4489.4 | Z32: 4087.2 | AA32: 3431.6 | AB32: 2745.4
B33: Feb | C33: Domingo | D33: 4 | E33: 1825.6 | F33: 1549.8 | G33: 1324.3 | H33: 1178.3 | I33: 1120 | J33: 948.7 | K33: 870.4 | L33: 1348.6 | M33: 1901.6 | N33: 2246.2 | O33: 2654.8 | P33: 2957.3 | Q33: 3111.5 | R33: 3079.3 | S33: 3012.1 | T33: 2950.4 | U33: 2889.6 | V33: 3008.6 | W33: 3975.4 | X33: 4332 | Y33: 4213.6 | Z33: 3873.2 | AA33: 3273.5 | AB33: 2585.9
B34: Feb | C34: Festivo | D34: 3 | E34: 1825.6 | F34: 1549.8 | G34: 1324.3 | H34: 1178.3 | I34: 1120 | J34: 948.7 | K34: 870.4 | L34: 1348.6 | M34: 1901.6 | N34: 2246.2 | O34: 2654.8 | P34: 2957.3 | Q34: 3111.5 | R34: 3079.3 | S34: 3012.1 | T34: 2950.4 | U34: 2889.6 | V34: 3008.6 | W34: 3975.4 | X34: 4332 | Y34: 4213.6 | Z34: 3873.2 | AA34: 3273.5 | AB34: 2585.9
B35: 46204 | C35: Ordinario | D35: 22 | E35: 1881.7 | F35: 1550.5 | G35: 1332.2 | H35: 1170.6 | I35: 1145.5 | J35: 1116.9 | K35: 1173.2 | L35: 1893.3 | M35: 2731.1 | N35: 3205.7 | O35: 3632.7 | P35: 3826.9 | Q35: 3711.8 | R35: 3591 | S35: 605 | T35: 3628.6 | U35: 3508 | V35: 3488.8 | W35: 4207.8 | X35: 4452.5 | Y35: 4151.5 | Z35: 3745.8 | AA35: 3229.5 | AB35: 2679.5 | AC35: =SUM(E35:AB35)*D35+SUM(E36:AB36)*D36+SUM(E37:AB37)*D37+SUM(E38:AB38)*D38 -> 2074770.6
C36: Sábado | D36: 4 | E36: 2319.7 | F36: 1936.3 | G36: 1655.3 | H36: 1457.1 | I36: 1443.4 | J36: 1561.5 | K36: 1599.9 | L36: 2319.6 | M36: 3094.2 | N36: 3534.4 | O36: 3979.3 | P36: 4300.4 | Q36: 4057.4 | R36: 4239 | S36: 4544.1 | T36: 4544.2 | U36: 4362.1 | V36: 4093.4 | W36: 4718.4 | X36: 4918.6 | Y36: 4709 | Z36: 4296.1 | AA36: 3617.4 | AB36: 2886.8
C37: Domingo | D37: 4 | E37: 1904 | F37: 1626.7 | G37: 1392 | H37: 1177.1 | I37: 1104.9 | J37: 1009.8 | K37: 895.2 | L37: 1334.8 | M37: 1909.3 | N37: 2372.8 | O37: 2705.3 | P37: 2873.8 | Q37: 3162.9 | R37: 3181.9 | S37: 3167.4 | T37: 3190.8 | U37: 3126.8 | V37: 3053.2 | W37: 3899.9 | X37: 4388.2 | Y37: 4261.2 | Z37: 3944 | AA37: 3407.5 | AB37: 2810.1
C38: Festivo | D38: 1 | E38: 1904 | F38: 1626.7 | G38: 1392 | H38: 1177.1 | I38: 1104.9 | J38: 1009.8 | K38: 895.2 | L38: 1334.8 | M38: 1909.3 | N38: 2372.8 | O38: 2705.3 | P38: 2873.8 | Q38: 3162.9 | R38: 3181.9 | S38: 3167.4 | T38: 3190.8 | U38: 3126.8 | V38: 3053.2 | W38: 3899.9 | X38: 4388.2 | Y38: 4261.2 | Z38: 3944 | AA38: 3407.5 | AB38: 2810.1
B39: 46235 | C39: Ordinario | D39: 19 | E39: 2251 | F39: 1860.2 | G39: 1568.7 | H39: 1373.5 | I39: 1301.8 | J39: 1283.7 | K39: 1304.3 | L39: 2031.8 | M39: 2850.9 | N39: 3354.2 | O39: 3772.3 | P39: 4039 | Q39: 3889 | R39: 3762.3 | S39: 749.1 | T39: 677.8 | U39: 3503.8 | V39: 3492.5 | W39: 4262.5 | X39: 4381.4 | Y39: 4106.4 | Z39: 3727.4 | AA39: 3192.7 | AB39: 2623.2 | AC39: =SUM(E39:AB39)*D39+SUM(E40:AB40)*D40+SUM(E41:AB41)*D41+SUM(E42:AB42)*D42 -> 2068744
B40: Feb | C40: Sábado | D40: 5 | E40: 2155.2 | F40: 1800 | G40: 1528.4 | H40: 1336.8 | I40: 1318.5 | J40: 1421.9 | K40: 1490.4 | L40: 2230.9 | M40: 2989.6 | N40: 3419.5 | O40: 3865.6 | P40: 4167.5 | Q40: 3932.3 | R40: 4143.5 | S40: 4461.1 | T40: 4467.8 | U40: 4293.3 | V40: 4137.1 | W40: 4808.2 | X40: 4768.4 | Y40: 4516.3 | Z40: 4080.1 | AA40: 3385 | AB40: 2671.8
B41: Feb | C41: Domingo | D41: 5 | E41: 2151.6 | F41: 1778.9 | G41: 1489.4 | H41: 1280.1 | I41: 1192.2 | J41: 1073.8 | K41: 944.3 | L41: 1376.7 | M41: 1852.8 | N41: 2281.9 | O41: 2688.7 | P41: 3036.8 | Q41: 3164.9 | R41: 3125.7 | S41: 3089.2 | T41: 3115 | U41: 3040.9 | V41: 3031.8 | W41: 3963.3 | X41: 4468.3 | Y41: 4417.8 | Z41: 4063.5 | AA41: 3449 | AB41: 2775.9
B42: Feb | C42: Festivo | D42: 2 | E42: 2151.6 | F42: 1778.9 | G42: 1489.4 | H42: 1280.1 | I42: 1192.2 | J42: 1073.8 | K42: 944.3 | L42: 1376.7 | M42: 1852.8 | N42: 2281.9 | O42: 2688.7 | P42: 3036.8 | Q42: 3164.9 | R42: 3125.7 | S42: 3089.2 | T42: 3115 | U42: 3040.9 | V42: 3031.8 | W42: 3963.3 | X42: 4468.3 | Y42: 4417.8 | Z42: 4063.5 | AA42: 3449 | AB42: 2775.9
B43: 46266 | C43: Ordinario | D43: 22 | E43: 2912.5 | F43: 2508.6 | G43: 2196.2 | H43: 1974.8 | I43: 1909.9 | J43: 1820.6 | K43: 1864.8 | L43: 2681.2 | M43: 3553.1 | N43: 4055.9 | O43: 4484.3 | P43: 4697 | Q43: 4513.1 | R43: 4375.8 | S43: 4364.6 | T43: 4348.5 | U43: 4208.7 | V43: 4316.6 | W43: 5284.8 | X43: 5186.7 | Y43: 4833.2 | Z43: 4393.8 | AA43: 3865.2 | AB43: 3282.4 | AC43: =SUM(E43:AB43)*D43+SUM(E44:AB44)*D44+SUM(E45:AB45)*D45+SUM(E46:AB46)*D46 -> 2666666.2
C44: Sábado | D44: 4 | E44: 2396.9 | F44: 2024.7 | G44: 1764.9 | H44: 1573.4 | I44: 1576.5 | J44: 1685.5 | K44: 1821.6 | L44: 2653.9 | M44: 3464.5 | N44: 3906.8 | O44: 4374.9 | P44: 4697.5 | Q44: 4419.8 | R44: 4631.6 | S44: 4989 | T44: 5007 | U44: 4799.9 | V44: 4827 | W44: 5419.6 | X44: 5242.6 | Y44: 4915.1 | Z44: 4432.7 | AA44: 3737.8 | AB44: 3015.7
