Workbook

Sheet Cantidades 2026
C2: CANTIDADES DE ENERGÍA SOLICITADAS (kWh)
C3: EMPRESAS PÚBLICAS DE MEDELLÍN E.S.P.
C4: 2026
C6: Mes | D6: Tipo Día | E6: Días | F6: H1 | G6: H2 | H6: H3 | I6: H4 | J6: H5 | K6: H6 | L6: H7 | M6: H8 | N6: H9 | O6: H10 | P6: H11 | Q6: H12 | R6: H13 | S6: H14 | T6: H15 | U6: H16 | V6: H17 | W6: H18 | X6: H19 | Y6: H20 | Z6: H21 | AA6: H22 | AB6: H23 | AC6: H24 | AD6: TOTAL MES
C7: Ene | D7: Ordinario | E7: 20 | F7: =+[1]Resumen!F7*1000 -> 124578.86 | G7: =+[1]Resumen!G7*1000 -> 109402.7 | H7: =+[1]Resumen!H7*1000 -> 100411.45 | I7: =+[1]Resumen!I7*1000 -> 98605.226 | J7: =+[1]Resumen!J7*1000 -> 105052.62 | K7: =+[1]Resumen!K7*1000 -> 134050.26 | L7: =+[1]Resumen!L7*1000 -> 164230 | M7: =+[1]Resumen!M7*1000 -> 141470.41 | ... AC7: =+[1]Resumen!AC7*1000 -> 112919.12 | AD7: =SUM(F7:AC7)*E7+SUM(F8:AC8)*E8+SUM(F9:AC9)*E9+SUM(F10:AC10)*E10 -> 1.128558e+08
D8: Sábado | E8: 5 | F8: =+[1]Resumen!F8*1000 -> 118969.08 | G8: =+[1]Resumen!G8*1000 -> 103503.49 | H8: =+[1]Resumen!H8*1000 -> 93866.356 | I8: =+[1]Resumen!I8*1000 -> 89493.934 | J8: =+[1]Resumen!J8*1000 -> 96596.15 | K8: =+[1]Resumen!K8*1000 -> 111260.79 | L8: =+[1]Resumen!L8*1000 -> 132737.08 | M8: =+[1]Resumen!M8*1000 -> 110594.78 | ... AC8: =+[1]Resumen!AC8*1000 -> 96953
D9: Domingo | E9: 4 | F9: =+[1]Resumen!F9*1000 -> 118965 | G9: =+[1]Resumen!G9*1000 -> 101991.39 | H9: =+[1]Resumen!H9*1000 -> 90357.16 | I9: =+[1]Resumen!I9*1000 -> 83682.428 | J9: =+[1]Resumen!J9*1000 -> 85342.866 | K9: =+[1]Resumen!K9*1000 -> 91906.505 | L9: =+[1]Resumen!L9*1000 -> 101720.42 | M9: =+[1]Resumen!M9*1000 -> 72813.263 | ... AC9: =+[1]Resumen!AC9*1000 -> 80423.048
D10: Festivo | E10: 2 | F10: =+[1]Resumen!F10*1000 -> 101283.11 | G10: =+[1]Resumen!G10*1000 -> 90727.54 | H10: =+[1]Resumen!H10*1000 -> 79383.519 | I10: =+[1]Resumen!I10*1000 -> 73338.042 | J10: =+[1]Resumen!J10*1000 -> 73549.544 | K10: =+[1]Resumen!K10*1000 -> 79333.656 | L10: =+[1]Resumen!L10*1000 -> 80331.822 | M10: =+[1]Resumen!M10*1000 -> 43394.803 | ... AC10: =+[1]Resumen!AC10*1000 -> 65781.993
C11: Feb | D11: Ordinario | E11: 20 | F11: =+[1]Resumen!F11*1000 -> 134635.56 | G11: =+[1]Resumen!G11*1000 -> 119857.73 | H11: =+[1]Resumen!H11*1000 -> 112695.26 | I11: =+[1]Resumen!I11*1000 -> 112562.45 | J11: =+[1]Resumen!J11*1000 -> 128433.67 | K11: =+[1]Resumen!K11*1000 -> 182282.38 | L11: =+[1]Resumen!L11*1000 -> 213689.94 | M11: =+[1]Resumen!M11*1000 -> 174884.44 | ... AC11: =+[1]Resumen!AC11*1000 -> 119393.43 | AD11: =SUM(F11:AC11)*E11+SUM(F12:AC12)*E12+SUM(F13:AC13)*E13+SUM(F14:AC14)*E14 -> 1.1979185e+08
D12: Sábado | E12: 4 | F12: =+[1]Resumen!F12*1000 -> 146641.36 | G12: =+[1]Resumen!G12*1000 -> 130146.11 | H12: =+[1]Resumen!H12*1000 -> 119033.18 | I12: =+[1]Resumen!I12*1000 -> 116599.56 | J12: =+[1]Resumen!J12*1000 -> 125452.6 | K12: =+[1]Resumen!K12*1000 -> 141985.36 | L12: =+[1]Resumen!L12*1000 -> 171578.55 | M12: =+[1]Resumen!M12*1000 -> 151685.25 | ... AC12: =+[1]Resumen!AC12*1000 -> 117539.17
D13: Domingo | E13: 4 | F13: =+[1]Resumen!F13*1000 -> 137422.17 | G13: =+[1]Resumen!G13*1000 -> 119656.51 | H13: =+[1]Resumen!H13*1000 -> 108603.64 | I13: =+[1]Resumen!I13*1000 -> 103407.19 | J13: =+[1]Resumen!J13*1000 -> 105484.44 | K13: =+[1]Resumen!K13*1000 -> 111788.31 | L13: =+[1]Resumen!L13*1000 -> 125267.68 | M13: =+[1]Resumen!M13*1000 -> 97334.108 | ... AC13: =+[1]Resumen!AC13*1000 -> 96928.343
D14: Festivo | E14: 0 | F14: =+[1]Resumen!F14*1000 -> 0 | G14: =+[1]Resumen!G14*1000 -> 0 | H14: =+[1]Resumen!H14*1000 -> 0 | I14: =+[1]Resumen!I14*1000 -> 0 | J14: =+[1]Resumen!J14*1000 -> 0 | K14: =+[1]Resumen!K14*1000 -> 0 | L14: =+[1]Resumen!L14*1000 -> 0 | M14: =+[1]Resumen!M14*1000 -> 0 | ... AC14: =+[1]Resumen!AC14*1000 -> 0
C15: Mar | D15: Ordinario | E15: 21 | F15: =+[1]Resumen!F15*1000 -> 129822.01 | G15: =+[1]Resumen!G15*1000 -> 116525.85 | H15: =+[1]Resumen!H15*1000 -> 109482.61 | I15: =+[1]Resumen!I15*1000 -> 109419.41 | J15: =+[1]Resumen!J15*1000 -> 124085.57 | K15: =+[1]Resumen!K15*1000 -> 173701.67 | L15: =+[1]Resumen!L15*1000 -> 202642.59 | M15: =+[1]Resumen!M15*1000 -> 166205.96 | ... AC15: =+[1]Resumen!AC15*1000 -> 114342.74 | AD15: =SUM(F15:AC15)*E15+SUM(F16:AC16)*E16+SUM(F17:AC17)*E17+SUM(F18:AC18)*E18 -> 1.259155e+08
D16: Sábado | E16: 4 | F16: =+[1]Resumen!F16*1000 -> 130520.17 | G16: =+[1]Resumen!G16*1000 -> 115832.72 | H16: =+[1]Resumen!H16*1000 -> 106139.3 | I16: =+[1]Resumen!I16*1000 -> 103687.85 | J16: =+[1]Resumen!J16*1000 -> 113347.86 | K16: =+[1]Resumen!K16*1000 -> 132696.38 | L16: =+[1]Resumen!L16*1000 -> 158591.5 | M16: =+[1]Resumen!M16*1000 -> 144599.56 | ... AC16: =+[1]Resumen!AC16*1000 -> 115154.61
D17: Domingo | E17: 5 | F17: =+[1]Resumen!F17*1000 -> 130655.27 | G17: =+[1]Resumen!G17*1000 -> 113902.66 | H17: =+[1]Resumen!H17*1000 -> 102300.95 | I17: =+[1]Resumen!I17*1000 -> 96535.679 | J17: =+[1]Resumen!J17*1000 -> 97343.365 | K17: =+[1]Resumen!K17*1000 -> 103221.51 | L17: =+[1]Resumen!L17*1000 -> 112581.15 | M17: =+[1]Resumen!M17*1000 -> 88386.59 | ... AC17: =+[1]Resumen!AC17*1000 -> 93374.045
D18: Festivo | E18: 1 | F18: =+[1]Resumen!F18*1000 -> 153414.63 | G18: =+[1]Resumen!G18*1000 -> 137763.58 | H18: =+[1]Resumen!H18*1000 -> 126600.62 | I18: =+[1]Resumen!I18*1000 -> 120389.28 | J18: =+[1]Resumen!J18*1000 -> 123541.3 | K18: =+[1]Resumen!K18*1000 -> 129442.46 | L18: =+[1]Resumen!L18*1000 -> 136709.42 | M18: =+[1]Resumen!M18*1000 -> 113398.02 | ... AC18: =+[1]Resumen!AC18*1000 -> 125787.67
C19: Abr | D19: Ordinario | E19: 20 | F19: =+[1]Resumen!F19*1000 -> 130136.36 | G19: =+[1]Resumen!G19*1000 -> 115615.23 | H19: =+[1]Resumen!H19*1000 -> 108242.05 | I19: =+[1]Resumen!I19*1000 -> 108138.33 | J19: =+[1]Resumen!J19*1000 -> 122106.07 | K19: =+[1]Resumen!K19*1000 -> 167286.91 | L19: =+[1]Resumen!L19*1000 -> 197366.31 | M19: =+[1]Resumen!M19*1000 -> 163856.1 | ... AC19: =+[1]Resumen!AC19*1000 -> 119444.52 | AD19: =SUM(F19:AC19)*E19+SUM(F20:AC20)*E20+SUM(F21:AC21)*E21+SUM(F22:AC22)*E22 -> 1.2310701e+08
D20: Sábado | E20: 4 | F20: =+[1]Resumen!F20*1000 -> 132507.75 | G20: =+[1]Resumen!G20*1000 -> 114779.88 | H20: =+[1]Resumen!H20*1000 -> 104428.08 | I20: =+[1]Resumen!I20*1000 -> 102451.77 | J20: =+[1]Resumen!J20*1000 -> 110290.99 | K20: =+[1]Resumen!K20*1000 -> 127364.78 | L20: =+[1]Resumen!L20*1000 -> 154209.69 | M20: =+[1]Resumen!M20*1000 -> 137143.14 | ... AC20: =+[1]Resumen!AC20*1000 -> 118874.98
D21: Domingo | E21: 4 | F21: =+[1]Resumen!F21*1000 -> 138598.7 | G21: =+[1]Resumen!G21*1000 -> 120696.88 | H21: =+[1]Resumen!H21*1000 -> 108698.24 | I21: =+[1]Resumen!I21*1000 -> 103357.23 | J21: =+[1]Resumen!J21*1000 -> 104658.11 | K21: =+[1]Resumen!K21*1000 -> 108446.56 | L21: =+[1]Resumen!L21*1000 -> 122069.59 | M21: =+[1]Resumen!M21*1000 -> 99192.094 | ... AC21: =+[1]Resumen!AC21*1000 -> 94096.855
D22: Festivo | E22: 2 | F22: =+[1]Resumen!F22*1000 -> 154532.94 | G22: =+[1]Resumen!G22*1000 -> 135859.73 | H22: =+[1]Resumen!H22*1000 -> 123083.57 | I22: =+[1]Resumen!I22*1000 -> 116602.42 | J22: =+[1]Resumen!J22*1000 -> 118450.93 | K22: =+[1]Resumen!K22*1000 -> 122451.37 | L22: =+[1]Resumen!L22*1000 -> 128671.71 | M22: =+[1]Resumen!M22*1000 -> 100501.35 | ... AC22: =+[1]Resumen!AC22*1000 -> 127451.02
C23: May | D23: Ordinario | E23: 19 | F23: =+[1]Resumen!F23*1000 -> 60229.398 | G23: =+[1]Resumen!G23*1000 -> 51930.199 | H23: =+[1]Resumen!H23*1000 -> 47945.509 | I23: =+[1]Resumen!I23*1000 -> 48923.683 | J23: =+[1]Resumen!J23*1000 -> 66917.281 | K23: =+[1]Resumen!K23*1000 -> 114411.01 | L23: =+[1]Resumen!L23*1000 -> 137483.77 | M23: =+[1]Resumen!M23*1000 -> 106691.77 | ... AC23: =+[1]Resumen!AC23*1000 -> 49397.73 | AD23: =SUM(F23:AC23)*E23+SUM(F24:AC24)*E24+SUM(F25:AC25)*E25+SUM(F26:AC26)*E26 -> 61191885
D24: Sábado | E24: 5 | F24: =+[1]Resumen!F24*1000 -> 78490.882 | G24: =+[1]Resumen!G24*1000 -> 65557.25 | H24: =+[1]Resumen!H24*1000 -> 57947.932 | I24: =+[1]Resumen!I24*1000 -> 52760.584 | J24: =+[1]Resumen!J24*1000 -> 50038.675 | K24: =+[1]Resumen!K24*1000 -> 51023.126 | L24: =+[1]Resumen!L24*1000 -> 58861.4 | M24: =+[1]Resumen!M24*1000 -> 44578.352 | ... AC24: =+[1]Resumen!AC24*1000 -> 54782.368
D25: Domingo | E25: 5 | F25: =+[1]Resumen!F25*1000 -> 72646.544 | G25: =+[1]Resumen!G25*1000 -> 61216.407 | H25: =+[1]Resumen!H25*1000 -> 48644.039 | I25: =+[1]Resumen!I25*1000 -> 37756.871 | J25: =+[1]Resumen!J25*1000 -> 23886.116 | K25: =+[1]Resumen!K25*1000 -> 7589.4374 | L25: =+[1]Resumen!L25*1000 -> 0 | M25: =+[1]Resumen!M25*1000 -> 0 | ... AC25: =+[1]Resumen!AC25*1000 -> 19292.608
D26: Festivo | E26: 2 | F26: =+[1]Resumen!F26*1000 -> 58943.613 | G26: =+[1]Resumen!G26*1000 -> 48811.219 | H26: =+[1]Resumen!H26*1000 -> 42705.166 | I26: =+[1]Resumen!I26*1000 -> 38858.577 | J26: =+[1]Resumen!J26*1000 -> 42982.34 | K26: =+[1]Resumen!K26*1000 -> 53595.28 | L26: =+[1]Resumen!L26*1000 -> 49777.666 | M26: =+[1]Resumen!M26*1000 -> 23587.942 | ... AC26: =+[1]Resumen!AC26*1000 -> 18841.349
C27: Jun | D27: Ordinario | E27: 19 | F27: =+[1]Resumen!F27*1000 -> 39386.405 | G27: =+[1]Resumen!G27*1000 -> 30273.889 | H27: =+[1]Resumen!H27*1000 -> 25911.86 | I27: =+[1]Resumen!I27*1000 -> 25695.218 | J27: =+[1]Resumen!J27*1000 -> 31706.431 | K27: =+[1]Resumen!K27*1000 -> 53408.962 | L27: =+[1]Resumen!L27*1000 -> 72605.989 | M27: =+[1]Resumen!M27*1000 -> 51789.776 | ... AC27: =+[1]Resumen!AC27*1000 -> 17948.571 | AD27: =SUM(F27:AC27)*E27+SUM(F28:AC28)*E28+SUM(F29:AC29)*E29+SUM(F30:AC30)*E30 -> 37597003
D28: Sábado | E28: 4 | F28: =+[1]Resumen!F28*1000 -> 37782.544 | G28: =+[1]Resumen!G28*1000 -> 28167.325 | H28: =+[1]Resumen!H28*1000 -> 20450.165 | I28: =+[1]Resumen!I28*1000 -> 18600.791 | J28: =+[1]Resumen!J28*1000 -> 22108.763 | K28: =+[1]Resumen!K28*1000 -> 30085.309 | L28: =+[1]Resumen!L28*1000 -> 44703.746 | M28: =+[1]Resumen!M28*1000 -> 32879.981 | ... AC28: =+[1]Resumen!AC28*1000 -> 18982.358
D29: Domingo | E29: 4 | F29: =+[1]Resumen!F29*1000 -> 41827.298 | G29: =+[1]Resumen!G29*1000 -> 32904.957 | H29: =+[1]Resumen!H29*1000 -> 25798.217 | I29: =+[1]Resumen!I29*1000 -> 23510.58 | J29: =+[1]Resumen!J29*1000 -> 23861.644 | K29: =+[1]Resumen!K29*1000 -> 25628.055 | L29: =+[1]Resumen!L29*1000 -> 28225.579 | M29: =+[1]Resumen!M29*1000 -> 6899.6969 | ... AC29: =+[1]Resumen!AC29*1000 -> 15098.976
D30: Festivo | E30: 3 | F30: =+[1]Resumen!F30*1000 -> 37777.478 | G30: =+[1]Resumen!G30*1000 -> 27487.941 | H30: =+[1]Resumen!H30*1000 -> 21372.304 | I30: =+[1]Resumen!I30*1000 -> 18796.426 | J30: =+[1]Resumen!J30*1000 -> 18760.73 | K30: =+[1]Resumen!K30*1000 -> 22110.706 | L30: =+[1]Resumen!L30*1000 -> 24896.114 | M30: =+[1]Resumen!M30*1000 -> 706.28262 | ... AC30: =+[1]Resumen!AC30*1000 -> 15334.742
C31: Jul | D31: Ordinario | E31: 22 | F31: =+[1]Resumen!F31*1000 -> 58407.641 | G31: =+[1]Resumen!G31*1000 -> 48195.54 | H31: =+[1]Resumen!H31*1000 -> 42332.835 | I31: =+[1]Resumen!I31*1000 -> 42152.666 | J31: =+[1]Resumen!J31*1000 -> 48114.676 | K31: =+[1]Resumen!K31*1000 -> 71303.04 | L31: =+[1]Resumen!L31*1000 -> 91915.14 | M31: =+[1]Resumen!M31*1000 -> 72941.728 | ... AC31: =+[1]Resumen!AC31*1000 -> 41746.316 | AD31: =SUM(F31:AC31)*E31+SUM(F32:AC32)*E32+SUM(F33:AC33)*E33+SUM(F34:AC34)*E34 -> 56655222
D32: Sábado | E32: 4 | F32: =+[1]Resumen!F32*1000 -> 61301.796 | G32: =+[1]Resumen!G32*1000 -> 51153.081 | H32: =+[1]Resumen!H32*1000 -> 44152.255 | I32: =+[1]Resumen!I32*1000 -> 40733.277 | J32: =+[1]Resumen!J32*1000 -> 44885.598 | K32: =+[1]Resumen!K32*1000 -> 54246.751 | L32: =+[1]Resumen!L32*1000 -> 69153.415 | M32: =+[1]Resumen!M32*1000 -> 55086.098 | ... AC32: =+[1]Resumen!AC32*1000 -> 29790.176
D33: Domingo | E33: 4 | F33: =+[1]Resumen!F33*1000 -> 42878.829 | G33: =+[1]Resumen!G33*1000 -> 32946.172 | H33: =+[1]Resumen!H33*1000 -> 25215.815 | I33: =+[1]Resumen!I33*1000 -> 21224.337 | J33: =+[1]Resumen!J33*1000 -> 23234.593 | K33: =+[1]Resumen!K33*1000 -> 24701.799 | L33: =+[1]Resumen!L33*1000 -> 32866.918 | M33: =+[1]Resumen!M33*1000 -> 13085.5 | ... AC33: =+[1]Resumen!AC33*1000 -> 8303.5238
D34: Festivo | E34: 1 | F34: =+[1]Resumen!F34*1000 -> 79081.006 | G34: =+[1]Resumen!G34*1000 -> 65745.237 | H34: =+[1]Resumen!H34*1000 -> 57263.533 | I34: =+[1]Resumen!I34*1000 -> 50841.266 | J34: =+[1]Resumen!J34*1000 -> 46538.588 | K34: =+[1]Resumen!K34*1000 -> 40350.129 | L34: =+[1]Resumen!L34*1000 -> 43700.595 | M34: =+[1]Resumen!M34*1000 -> 23346.345 | ... AC34: =+[1]Resumen!AC34*1000 -> 38445.261
C35: Ago | D35: Ordinario | E35: 19 | F35: =+[1]Resumen!F35*1000 -> 63754.357 | G35: =+[1]Resumen!G35*1000 -> 52639.122 | H35: =+[1]Resumen!H35*1000 -> 46391.527 | I35: =+[1]Resumen!I35*1000 -> 45857.156 | J35: =+[1]Resumen!J35*1000 -> 53424.11 | K35: =+[1]Resumen!K35*1000 -> 80004.131 | L35: =+[1]Resumen!L35*1000 -> 102781.4 | M35: =+[1]Resumen!M35*1000 -> 81787.137 | ... AC35: =+[1]Resumen!AC35*1000 -> 46793.493 | AD35: =SUM(F35:AC35)*E35+SUM(F36:AC36)*E36+SUM(F37:AC37)*E37+SUM(F38:AC38)*E38 -> 59386897
D36: Sábado | E36: 5 | F36: =+[1]Resumen!F36*1000 -> 60429.298 | G36: =+[1]Resumen!G36*1000 -> 50327.28 | H36: =+[1]Resumen!H36*1000 -> 44257.331 | I36: =+[1]Resumen!I36*1000 -> 40973.694 | J36: =+[1]Resumen!J36*1000 -> 46411.355 | K36: =+[1]Resumen!K36*1000 -> 53529.46 | L36: =+[1]Resumen!L36*1000 -> 70152.916 | M36: =+[1]Resumen!M36*1000 -> 58733.691 | ... AC36: =+[1]Resumen!AC36*1000 -> 33664.434
D37: Domingo | E37: 5 | F37: =+[1]Resumen!F37*1000 -> 55867.636 | G37: =+[1]Resumen!G37*1000 -> 45992.728 | H37: =+[1]Resumen!H37*1000 -> 37449.231 | I37: =+[1]Resumen!I37*1000 -> 34625.451 | J37: =+[1]Resumen!J37*1000 -> 35656.939 | K37: =+[1]Resumen!K37*1000 -> 40123.866 | L37: =+[1]Resumen!L37*1000 -> 43796.347 | M37: =+[1]Resumen!M37*1000 -> 24642.255 | ... AC37: =+[1]Resumen!AC37*1000 -> 23599.544
D38: Festivo | E38: 2 | F38: =+[1]Resumen!F38*1000 -> 45392.196 | G38: =+[1]Resumen!G38*1000 -> 34005.225 | H38: =+[1]Resumen!H38*1000 -> 24791.861 | I38: =+[1]Resumen!I38*1000 -> 24637.648 | J38: =+[1]Resumen!J38*1000 -> 23954.317 | K38: =+[1]Resumen!K38*1000 -> 32559.939 | L38: =+[1]Resumen!L38*1000 -> 40796.107 | M38: =+[1]Resumen!M38*1000 -> 17984.652 | ... AC38: =+[1]Resumen!AC38*1000 -> 24199.281
C39: Sep | D39: Ordinario | E39: 22 | F39: =+[1]Resumen!F39*1000 -> 124017.53 | G39: =+[1]Resumen!G39*1000 -> 110124.47 | H39: =+[1]Resumen!H39*1000 -> 102336.65 | I39: =+[1]Resumen!I39*1000 -> 101378.52 | J39: =+[1]Resumen!J39*1000 -> 112060.74 | K39: =+[1]Resumen!K39*1000 -> 151748.19 | L39: =+[1]Resumen!L39*1000 -> 182087.54 | M39: =+[1]Resumen!M39*1000 -> 150547.84 | ... AC39: =+[1]Resumen!AC39*1000 -> 106579.81 | AD39: =SUM(F39:AC39)*E39+SUM(F40:AC40)*E40+SUM(F41:AC41)*E41+SUM(F42:AC42)*E42 -> 1.1331602e+08
D40: Sábado | E40: 4 | F40: =+[1]Resumen!F40*1000 -> 115303.52 | G40: =+[1]Resumen!G40*1000 -> 101590.24 | H40: =+[1]Resumen!H40*1000 -> 92247.34 | I40: =+[1]Resumen!I40*1000 -> 89244.319 | J40: =+[1]Resumen!J40*1000 -> 96797.527 | K40: =+[1]Resumen!K40*1000 -> 114489.91 | L40: =+[1]Resumen!L40*1000 -> 136197.8 | M40: =+[1]Resumen!M40*1000 -> 118730.97 | ... AC40: =+[1]Resumen!AC40*1000 -> 99820.421
D41: Domingo | E41: 4 | F41: =+[1]Resumen!F41*1000 -> 121038.04 | G41: =+[1]Resumen!G41*1000 -> 102716.82 | H41: =+[1]Resumen!H41*1000 -> 91746.403 | I41: =+[1]Resumen!I41*1000 -> 85331.235 | J41: =+[1]Resumen!J41*1000 -> 85731.54 | K41: =+[1]Resumen!K41*1000 -> 89576.467 | L41: =+[1]Resumen!L41*1000 -> 97437.618 | M41: =+[1]Resumen!M41*1000 -> 69570.729 | ... AC41: =+[1]Resumen!AC41*1000 -> 77901.477
D42: Festivo | E42: 0 | F42: =+[1]Resumen!F42*1000 -> 0 | G42: =+[1]Resumen!G42*1000 -> 0 | H42: =+[1]Resumen!H42*1000 -> 0 | I42: =+[1]Resumen!I42*1000 -> 0 | J42: =+[1]Resumen!J42*1000 -> 0 | K42: =+[1]Resumen!K42*1000 -> 0 | L42: =+[1]Resumen!L42*1000 -> 0 | M42: =+[1]Resumen!M42*1000 -> 0 | ... AC42: =+[1]Resumen!AC42*1000 -> 0
...

Sheet Cantidades 2027
C2: CANTIDADES DE ENERGÍA SOLICITADAS (kWh)
C3: EMPRESAS PÚBLICAS DE MEDELLÍN E.S.P.
C4: 2027
C6: Mes | D6: Tipo Día | E6: Días | F6: H1 | G6: H2 | H6: H3 | I6: H4 | J6: H5 | K6: H6 | L6: H7 | M6: H8 | N6: H9 | O6: H10 | P6: H11 | Q6: H12 | R6: H13 | S6: H14 | T6: H15 | U6: H16 | V6: H17 | W6: H18 | X6: H19 | Y6: H20 | Z6: H21 | AA6: H22 | AB6: H23 | AC6: H24 | AD6: TOTAL MES
C7: Ene | D7: Ordinario | E7: 19 | F7: =+[2]Resumen!F7*1000 -> 109780.65 | G7: =+[2]Resumen!G7*1000 -> 98065.2 | H7: =+[2]Resumen!H7*1000 -> 90827.454 | I7: =+[2]Resumen!I7*1000 -> 89166.565 | J7: =+[2]Resumen!J7*1000 -> 93626.47 | K7: =+[2]Resumen!K7*1000 -> 116292.35 | L7: =+[2]Resumen!L7*1000 -> 138799.03 | M7: =+[2]Resumen!M7*1000 -> 133384.72 | ... AC7: =+[2]Resumen!AC7*1000 -> 91044.077 | AD7: =SUM(F7:AC7)*E7+SUM(F8:AC8)*E8+SUM(F9:AC9)*E9+SUM(F10:AC10)*E10 -> 97669210
D8: Sábado | E8: 5 | F8: =+[2]Resumen!F8*1000 -> 104414.73 | G8: =+[2]Resumen!G8*1000 -> 92681.833 | H8: =+[2]Resumen!H8*1000 -> 85004.564 | I8: =+[2]Resumen!I8*1000 -> 81145.159 | J8: =+[2]Resumen!J8*1000 -> 86323.126 | K8: =+[2]Resumen!K8*1000 -> 97474.795 | L8: =+[2]Resumen!L8*1000 -> 112946.21 | M8: =+[2]Resumen!M8*1000 -> 107980.7 | ... AC8: =+[2]Resumen!AC8*1000 -> 77045.607
D9: Domingo | E9: 5 | F9: =+[2]Resumen!F9*1000 -> 105214.47 | G9: =+[2]Resumen!G9*1000 -> 92083.71 | H9: =+[2]Resumen!H9*1000 -> 82764.932 | I9: =+[2]Resumen!I9*1000 -> 77107.183 | J9: =+[2]Resumen!J9*1000 -> 78465.251 | K9: =+[2]Resumen!K9*1000 -> 83588.375 | L9: =+[2]Resumen!L9*1000 -> 90850.51 | M9: =+[2]Resumen!M9*1000 -> 81310.889 | ... AC9: =+[2]Resumen!AC9*1000 -> 63043.69
D10: Festivo | E10: 2 | F10: =+[2]Resumen!F10*1000 -> 86136.746 | G10: =+[2]Resumen!G10*1000 -> 78814.524 | H10: =+[2]Resumen!H10*1000 -> 70384.022 | I10: =+[2]Resumen!I10*1000 -> 65890.016 | J10: =+[2]Resumen!J10*1000 -> 66142.931 | K10: =+[2]Resumen!K10*1000 -> 71189.971 | L10: =+[2]Resumen!L10*1000 -> 71112.434 | M10: =+[2]Resumen!M10*1000 -> 55303.249 | ... AC10: =+[2]Resumen!AC10*1000 -> 50325.886
C11: Feb | D11: Ordinario | E11: 20 | F11: =+[2]Resumen!F11*1000 -> 114748.22 | G11: =+[2]Resumen!G11*1000 -> 103276.08 | H11: =+[2]Resumen!H11*1000 -> 97817.79 | I11: =+[2]Resumen!I11*1000 -> 97470.574 | J11: =+[2]Resumen!J11*1000 -> 109780.26 | K11: =+[2]Resumen!K11*1000 -> 152778.82 | L11: =+[2]Resumen!L11*1000 -> 175798.33 | M11: =+[2]Resumen!M11*1000 -> 156806.54 | ... AC11: =+[2]Resumen!AC11*1000 -> 92154.394 | AD11: =SUM(F11:AC11)*E11+SUM(F12:AC12)*E12+SUM(F13:AC13)*E13+SUM(F14:AC14)*E14 -> 1.0185448e+08
D12: Sábado | E12: 4 | F12: =+[2]Resumen!F12*1000 -> 125593.94 | G12: =+[2]Resumen!G12*1000 -> 112829.89 | H12: =+[2]Resumen!H12*1000 -> 103892.81 | I12: =+[2]Resumen!I12*1000 -> 101782.81 | J12: =+[2]Resumen!J12*1000 -> 108049.42 | K12: =+[2]Resumen!K12*1000 -> 120356.33 | L12: =+[2]Resumen!L12*1000 -> 143020.99 | M12: =+[2]Resumen!M12*1000 -> 139052.37 | ... AC12: =+[2]Resumen!AC12*1000 -> 91536.024
D13: Domingo | E13: 4 | F13: =+[2]Resumen!F13*1000 -> 117179.15 | G13: =+[2]Resumen!G13*1000 -> 103311.31 | H13: =+[2]Resumen!H13*1000 -> 94718.407 | I13: =+[2]Resumen!I13*1000 -> 90576.483 | J13: =+[2]Resumen!J13*1000 -> 92015.763 | K13: =+[2]Resumen!K13*1000 -> 96755.371 | L13: =+[2]Resumen!L13*1000 -> 106977.86 | M13: =+[2]Resumen!M13*1000 -> 98074.252 | ... AC13: =+[2]Resumen!AC13*1000 -> 74926.431
D14: Festivo | E14: 0 | F14: =+[2]Resumen!F14*1000 -> 0 | G14: =+[2]Resumen!G14*1000 -> 0 | H14: =+[2]Resumen!H14*1000 -> 0 | I14: =+[2]Resumen!I14*1000 -> 0 | J14: =+[2]Resumen!J14*1000 -> 0 | K14: =+[2]Resumen!K14*1000 -> 0 | L14: =+[2]Resumen!L14*1000 -> 0 | M14: =+[2]Resumen!M14*1000 -> 0 | ... AC14: =+[2]Resumen!AC14*1000 -> 0
C15: Mar | D15: Ordinario | E15: 20 | F15: =+[2]Resumen!F15*1000 -> 111268.61 | G15: =+[2]Resumen!G15*1000 -> 101290.61 | H15: =+[2]Resumen!H15*1000 -> 95893.017 | I15: =+[2]Resumen!I15*1000 -> 95722.407 | J15: =+[2]Resumen!J15*1000 -> 106552.55 | K15: =+[2]Resumen!K15*1000 -> 145276.88 | L15: =+[2]Resumen!L15*1000 -> 165930.23 | M15: =+[2]Resumen!M15*1000 -> 148688.06 | ... AC15: =+[2]Resumen!AC15*1000 -> 88056.354 | AD15: =SUM(F15:AC15)*E15+SUM(F16:AC16)*E16+SUM(F17:AC17)*E17+SUM(F18:AC18)*E18 -> 1.0675288e+08
D16: Sábado | E16: 4 | F16: =+[2]Resumen!F16*1000 -> 110545.91 | G16: =+[2]Resumen!G16*1000 -> 99712.157 | H16: =+[2]Resumen!H16*1000 -> 92156.083 | I16: =+[2]Resumen!I16*1000 -> 90175.119 | J16: =+[2]Resumen!J16*1000 -> 97170.703 | K16: =+[2]Resumen!K16*1000 -> 112104.52 | L16: =+[2]Resumen!L16*1000 -> 130543.26 | M16: =+[2]Resumen!M16*1000 -> 132524.87 | ... AC16: =+[2]Resumen!AC16*1000 -> 90303.335
D17: Domingo | E17: 4 | F17: =+[2]Resumen!F17*1000 -> 111665.31 | G17: =+[2]Resumen!G17*1000 -> 99119.361 | H17: =+[2]Resumen!H17*1000 -> 89773.924 | I17: =+[2]Resumen!I17*1000 -> 85362.208 | J17: =+[2]Resumen!J17*1000 -> 85521.029 | K17: =+[2]Resumen!K17*1000 -> 89510.049 | L17: =+[2]Resumen!L17*1000 -> 95780.592 | M17: =+[2]Resumen!M17*1000 -> 89656.568 | ... AC17: =+[2]Resumen!AC17*1000 -> 72796.138
D18: Festivo | E18: 3 | F18: =+[2]Resumen!F18*1000 -> 134111.39 | G18: =+[2]Resumen!G18*1000 -> 122548.82 | H18: =+[2]Resumen!H18*1000 -> 113625.63 | I18: =+[2]Resumen!I18*1000 -> 108307.07 | J18: =+[2]Resumen!J18*1000 -> 110678.78 | K18: =+[2]Resumen!K18*1000 -> 114155.29 | L18: =+[2]Resumen!L18*1000 -> 118594.06 | M18: =+[2]Resumen!M18*1000 -> 114432.16 | ... AC18: =+[2]Resumen!AC18*1000 -> 102504.26
C19: Abr | D19: Ordinario | E19: 22 | F19: =+[2]Resumen!F19*1000 -> 104942.86 | G19: =+[2]Resumen!G19*1000 -> 93877.009 | H19: =+[2]Resumen!H19*1000 -> 88252.311 | I19: =+[2]Resumen!I19*1000 -> 88102.997 | J19: =+[2]Resumen!J19*1000 -> 98456.69 | K19: =+[2]Resumen!K19*1000 -> 133469.06 | L19: =+[2]Resumen!L19*1000 -> 155136.44 | M19: =+[2]Resumen!M19*1000 -> 139801.55 | ... AC19: =+[2]Resumen!AC19*1000 -> 86174.358 | AD19: =SUM(F19:AC19)*E19+SUM(F20:AC20)*E20+SUM(F21:AC21)*E21+SUM(F22:AC22)*E22 -> 1.0053857e+08
D20: Sábado | E20: 4 | F20: =+[2]Resumen!F20*1000 -> 106380.64 | G20: =+[2]Resumen!G20*1000 -> 92758.115 | H20: =+[2]Resumen!H20*1000 -> 84783.593 | I20: =+[2]Resumen!I20*1000 -> 83217.827 | J20: =+[2]Resumen!J20*1000 -> 88367.66 | K20: =+[2]Resumen!K20*1000 -> 101439.28 | L20: =+[2]Resumen!L20*1000 -> 120759.88 | M20: =+[2]Resumen!M20*1000 -> 118913.96 | ... AC20: =+[2]Resumen!AC20*1000 -> 86339.769
D21: Domingo | E21: 4 | F21: =+[2]Resumen!F21*1000 -> 111872.97 | G21: =+[2]Resumen!G21*1000 -> 98240.55 | H21: =+[2]Resumen!H21*1000 -> 88853.826 | I21: =+[2]Resumen!I21*1000 -> 84811.026 | J21: =+[2]Resumen!J21*1000 -> 85459.339 | K21: =+[2]Resumen!K21*1000 -> 87805.857 | L21: =+[2]Resumen!L21*1000 -> 98011.626 | M21: =+[2]Resumen!M21*1000 -> 92466.956 | ... AC21: =+[2]Resumen!AC21*1000 -> 65812.897
D22: Festivo | E22: 0 | F22: =+[2]Resumen!F22*1000 -> 262635.61 | G22: =+[2]Resumen!G22*1000 -> 243730.93 | H22: =+[2]Resumen!H22*1000 -> 230655.93 | I22: =+[2]Resumen!I22*1000 -> 224578.99 | J22: =+[2]Resumen!J22*1000 -> 226776.5 | K22: =+[2]Resumen!K22*1000 -> 231055.07 | L22: =+[2]Resumen!L22*1000 -> 239176.48 | M22: =+[2]Resumen!M22*1000 -> 231916.24 | ... AC22: =+[2]Resumen!AC22*1000 -> 233959.74
C23: May | D23: Ordinario | E23: 19 | F23: =+[2]Resumen!F23*1000 -> 88161.224 | G23: =+[2]Resumen!G23*1000 -> 76240.999 | H23: =+[2]Resumen!H23*1000 -> 70408.525 | I23: =+[2]Resumen!I23*1000 -> 70296.113 | J23: =+[2]Resumen!J23*1000 -> 80657.17 | K23: =+[2]Resumen!K23*1000 -> 120026.88 | L23: =+[2]Resumen!L23*1000 -> 142942.43 | M23: =+[2]Resumen!M23*1000 -> 129425.16 | ... AC23: =+[2]Resumen!AC23*1000 -> 68439.784 | AD23: =SUM(F23:AC23)*E23+SUM(F24:AC24)*E24+SUM(F25:AC25)*E25+SUM(F26:AC26)*E26 -> 87017546
D24: Sábado | E24: 4 | F24: =+[2]Resumen!F24*1000 -> 90064.076 | G24: =+[2]Resumen!G24*1000 -> 77303.495 | H24: =+[2]Resumen!H24*1000 -> 69659.469 | I24: =+[2]Resumen!I24*1000 -> 65835.924 | J24: =+[2]Resumen!J24*1000 -> 67244.508 | K24: =+[2]Resumen!K24*1000 -> 75333.236 | L24: =+[2]Resumen!L24*1000 -> 94029.856 | M24: =+[2]Resumen!M24*1000 -> 95413.328 | ... AC24: =+[2]Resumen!AC24*1000 -> 69271.732
D25: Domingo | E25: 5 | F25: =+[2]Resumen!F25*1000 -> 90793.084 | G25: =+[2]Resumen!G25*1000 -> 79502.394 | H25: =+[2]Resumen!H25*1000 -> 67166.29 | I25: =+[2]Resumen!I25*1000 -> 58523.563 | J25: =+[2]Resumen!J25*1000 -> 53355.698 | K25: =+[2]Resumen!K25*1000 -> 50214.886 | L25: =+[2]Resumen!L25*1000 -> 53456.511 | M25: =+[2]Resumen!M25*1000 -> 48177.702 | ... AC25: =+[2]Resumen!AC25*1000 -> 44174.778
D26: Festivo | E26: 3 | F26: =+[2]Resumen!F26*1000 -> 82062.846 | G26: =+[2]Resumen!G26*1000 -> 69898.445 | H26: =+[2]Resumen!H26*1000 -> 62843.029 | I26: =+[2]Resumen!I26*1000 -> 59889.329 | J26: =+[2]Resumen!J26*1000 -> 68499.253 | K26: =+[2]Resumen!K26*1000 -> 85200.522 | L26: =+[2]Resumen!L26*1000 -> 93330.679 | M26: =+[2]Resumen!M26*1000 -> 86294.296 | ... AC26: =+[2]Resumen!AC26*1000 -> 40670.214
C27: Jun | D27: Ordinario | E27: 21 | F27: =+[2]Resumen!F27*1000 -> 70806.739 | G27: =+[2]Resumen!G27*1000 -> 59819.822 | H27: =+[2]Resumen!H27*1000 -> 54144.338 | I27: =+[2]Resumen!I27*1000 -> 53982.871 | J27: =+[2]Resumen!J27*1000 -> 60257.536 | K27: =+[2]Resumen!K27*1000 -> 84575.115 | L27: =+[2]Resumen!L27*1000 -> 106851.83 | M27: =+[2]Resumen!M27*1000 -> 98487.818 | ... AC27: =+[2]Resumen!AC27*1000 -> 45182.055 | AD27: =SUM(F27:AC27)*E27+SUM(F28:AC28)*E28+SUM(F29:AC29)*E29+SUM(F30:AC30)*E30 -> 68081871
D28: Sábado | E28: 4 | F28: =+[2]Resumen!F28*1000 -> 69751.684 | G28: =+[2]Resumen!G28*1000 -> 57684.52 | H28: =+[2]Resumen!H28*1000 -> 49256.444 | I28: =+[2]Resumen!I28*1000 -> 46490.855 | J28: =+[2]Resumen!J28*1000 -> 49928.884 | K28: =+[2]Resumen!K28*1000 -> 59048.072 | L28: =+[2]Resumen!L28*1000 -> 77107.538 | M28: =+[2]Resumen!M28*1000 -> 76658.069 | ... AC28: =+[2]Resumen!AC28*1000 -> 45793.912
D29: Domingo | E29: 4 | F29: =+[2]Resumen!F29*1000 -> 75497.221 | G29: =+[2]Resumen!G29*1000 -> 64794.801 | H29: =+[2]Resumen!H29*1000 -> 55751.484 | I29: =+[2]Resumen!I29*1000 -> 52312.561 | J29: =+[2]Resumen!J29*1000 -> 52175.81 | K29: =+[2]Resumen!K29*1000 -> 54034.693 | L29: =+[2]Resumen!L29*1000 -> 56699.178 | M29: =+[2]Resumen!M29*1000 -> 46115.391 | ... AC29: =+[2]Resumen!AC29*1000 -> 39288.175
D30: Festivo | E30: 1 | F30: =+[2]Resumen!F30*1000 -> 69350.348 | G30: =+[2]Resumen!G30*1000 -> 57829.976 | H30: =+[2]Resumen!H30*1000 -> 50403.494 | I30: =+[2]Resumen!I30*1000 -> 47158.422 | J30: =+[2]Resumen!J30*1000 -> 47280.325 | K30: =+[2]Resumen!K30*1000 -> 51173.044 | L30: =+[2]Resumen!L30*1000 -> 55632.652 | M30: =+[2]Resumen!M30*1000 -> 43947.656 | ... AC30: =+[2]Resumen!AC30*1000 -> 40244.645
C31: Jul | D31: Ordinario | E31: 20 | F31: =+[2]Resumen!F31*1000 -> 62872.519 | G31: =+[2]Resumen!G31*1000 -> 50703.038 | H31: =+[2]Resumen!H31*1000 -> 43586.664 | I31: =+[2]Resumen!I31*1000 -> 42857.337 | J31: =+[2]Resumen!J31*1000 -> 49033.26 | K31: =+[2]Resumen!K31*1000 -> 76288.344 | L31: =+[2]Resumen!L31*1000 -> 99248.955 | M31: =+[2]Resumen!M31*1000 -> 84857.052 | ... AC31: =+[2]Resumen!AC31*1000 -> 59239.596 | AD31: =SUM(F31:AC31)*E31+SUM(F32:AC32)*E32+SUM(F33:AC33)*E33+SUM(F34:AC34)*E34 -> 66098678
D32: Sábado | E32: 5 | F32: =+[2]Resumen!F32*1000 -> 58624.986 | G32: =+[2]Resumen!G32*1000 -> 46572.741 | H32: =+[2]Resumen!H32*1000 -> 39146.011 | I32: =+[2]Resumen!I32*1000 -> 35332.561 | J32: =+[2]Resumen!J32*1000 -> 39552.086 | K32: =+[2]Resumen!K32*1000 -> 49785.55 | L32: =+[2]Resumen!L32*1000 -> 67696.687 | M32: =+[2]Resumen!M32*1000 -> 60868.904 | ... AC32: =+[2]Resumen!AC32*1000 -> 45033.095
D33: Domingo | E33: 4 | F33: =+[2]Resumen!F33*1000 -> 44159.334 | G33: =+[2]Resumen!G33*1000 -> 32559.892 | H33: =+[2]Resumen!H33*1000 -> 23590.068 | I33: =+[2]Resumen!I33*1000 -> 18792.715 | J33: =+[2]Resumen!J33*1000 -> 20849.649 | K33: =+[2]Resumen!K33*1000 -> 22976.246 | L33: =+[2]Resumen!L33*1000 -> 31828.167 | M33: =+[2]Resumen!M33*1000 -> 17857.669 | ... AC33: =+[2]Resumen!AC33*1000 -> 26096.776
D34: Festivo | E34: 2 | F34: =+[2]Resumen!F34*1000 -> 75890.328 | G34: =+[2]Resumen!G34*1000 -> 60500.406 | H34: =+[2]Resumen!H34*1000 -> 49594.643 | I34: =+[2]Resumen!I34*1000 -> 42951.488 | J34: =+[2]Resumen!J34*1000 -> 38297.697 | K34: =+[2]Resumen!K34*1000 -> 33331.038 | L34: =+[2]Resumen!L34*1000 -> 39689.568 | M34: =+[2]Resumen!M34*1000 -> 25489.402 | ... AC34: =+[2]Resumen!AC34*1000 -> 54397.445
C35: Ago | D35: Ordinario | E35: 21 | F35: =+[2]Resumen!F35*1000 -> 56218.134 | G35: =+[2]Resumen!G35*1000 -> 43783.615 | H35: =+[2]Resumen!H35*1000 -> 36646.852 | I35: =+[2]Resumen!I35*1000 -> 35788.741 | J35: =+[2]Resumen!J35*1000 -> 44589.223 | K35: =+[2]Resumen!K35*1000 -> 77636.133 | L35: =+[2]Resumen!L35*1000 -> 102941.87 | M35: =+[2]Resumen!M35*1000 -> 85285.827 | ... AC35: =+[2]Resumen!AC35*1000 -> 55859.561 | AD35: =SUM(F35:AC35)*E35+SUM(F36:AC36)*E36+SUM(F37:AC37)*E37+SUM(F38:AC38)*E38 -> 63760823
D36: Sábado | E36: 3 | F36: =+[2]Resumen!F36*1000 -> 56589.682 | G36: =+[2]Resumen!G36*1000 -> 44060.962 | H36: =+[2]Resumen!H36*1000 -> 36186.189 | I36: =+[2]Resumen!I36*1000 -> 31529.091 | J36: =+[2]Resumen!J36*1000 -> 36507.526 | K36: =+[2]Resumen!K36*1000 -> 44843.841 | L36: =+[2]Resumen!L36*1000 -> 63850.143 | M36: =+[2]Resumen!M36*1000 -> 58569.901 | ... AC36: =+[2]Resumen!AC36*1000 -> 39706.849
D37: Domingo | E37: 5 | F37: =+[2]Resumen!F37*1000 -> 44572.099 | G37: =+[2]Resumen!G37*1000 -> 33868.409 | H37: =+[2]Resumen!H37*1000 -> 24926.159 | I37: =+[2]Resumen!I37*1000 -> 21514.591 | J37: =+[2]Resumen!J37*1000 -> 22474.672 | K37: =+[2]Resumen!K37*1000 -> 28237.475 | L37: =+[2]Resumen!L37*1000 -> 32506.333 | M37: =+[2]Resumen!M37*1000 -> 19308.279 | ... AC37: =+[2]Resumen!AC37*1000 -> 27021.628
D38: Festivo | E38: 2 | F38: =+[2]Resumen!F38*1000 -> 36855.174 | G38: =+[2]Resumen!G38*1000 -> 24834.186 | H38: =+[2]Resumen!H38*1000 -> 14690.262 | I38: =+[2]Resumen!I38*1000 -> 13723.421 | J38: =+[2]Resumen!J38*1000 -> 13213.398 | K38: =+[2]Resumen!K38*1000 -> 21758.603 | L38: =+[2]Resumen!L38*1000 -> 30681.004 | M38: =+[2]Resumen!M38*1000 -> 13630.986 | ... AC38: =+[2]Resumen!AC38*1000 -> 26887.402
C39: Sep | D39: Ordinario | E39: 22 | F39: =+[2]Resumen!F39*1000 -> 78888.976 | G39: =+[2]Resumen!G39*1000 -> 68171.219 | H39: =+[2]Resumen!H39*1000 -> 61961.905 | I39: =+[2]Resumen!I39*1000 -> 60964.843 | J39: =+[2]Resumen!J39*1000 -> 69244.669 | K39: =+[2]Resumen!K39*1000 -> 102414.11 | L39: =+[2]Resumen!L39*1000 -> 124226.71 | M39: =+[2]Resumen!M39*1000 -> 103001.25 | ... AC39: =+[2]Resumen!AC39*1000 -> 74480.637 | AD39: =SUM(F39:AC39)*E39+SUM(F40:AC40)*E40+SUM(F41:AC41)*E41+SUM(F42:AC42)*E42 -> 78875477
D40: Sábado | E40: 4 | F40: =+[2]Resumen!F40*1000 -> 68795.399 | G40: =+[2]Resumen!G40*1000 -> 58584.267 | H40: =+[2]Resumen!H40*1000 -> 51629.657 | I40: =+[2]Resumen!I40*1000 -> 48773.811 | J40: =+[2]Resumen!J40*1000 -> 54309.238 | K40: =+[2]Resumen!K40*1000 -> 68558.53 | L40: =+[2]Resumen!L40*1000 -> 83873.568 | M40: =+[2]Resumen!M40*1000 -> 75723.335 | ... AC40: =+[2]Resumen!AC40*1000 -> 69406.029
D41: Domingo | E41: 4 | F41: =+[2]Resumen!F41*1000 -> 76375.522 | G41: =+[2]Resumen!G41*1000 -> 61890.645 | H41: =+[2]Resumen!H41*1000 -> 53090.205 | I41: =+[2]Resumen!I41*1000 -> 47324.067 | J41: =+[2]Resumen!J41*1000 -> 47402.612 | K41: =+[2]Resumen!K41*1000 -> 49608.874 | L41: =+[2]Resumen!L41*1000 -> 55052.412 | M41: =+[2]Resumen!M41*1000 -> 39682.446 | ... AC41: =+[2]Resumen!AC41*1000 -> 50679.344
D42: Festivo | E42: 0 | F42: =+[2]Resumen!F42*1000 -> 0 | G42: =+[2]Resumen!G42*1000 -> 0 | H42: =+[2]Resumen!H42*1000 -> 0 | I42: =+[2]Resumen!I42*1000 -> 0 | J42: =+[2]Resumen!J42*1000 -> 0 | K42: =+[2]Resumen!K42*1000 -> 0 | L42: =+[2]Resumen!L42*1000 -> 0 | M42: =+[2]Resumen!M42*1000 -> 0 | ... AC42: =+[2]Resumen!AC42*1000 -> 0
...

Sheet Cantidades 2028
C2: CANTIDADES DE ENERGÍA SOLICITADAS (kWh)
C3: EMPRESAS PÚBLICAS DE MEDELLÍN E.S.P.
C4: 2028
C6: Mes | D6: Tipo Día | E6: Días | F6: H1 | G6: H2 | H6: H3 | I6: H4 | J6: H5 | K6: H6 | L6: H7 | M6: H8 | N6: H9 | O6: H10 | P6: H11 | Q6: H12 | R6: H13 | S6: H14 | T6: H15 | U6: H16 | V6: H17 | W6: H18 | X6: H19 | Y6: H20 | Z6: H21 | AA6: H22 | AB6: H23 | AC6: H24 | AD6: TOTAL MES
C7: Ene | D7: Ordinario | E7: 20 | F7: =+[3]Resumen!F7*1000 -> 71983.519 | G7: =+[3]Resumen!G7*1000 -> 57047.978 | H7: =+[3]Resumen!H7*1000 -> 48630.536 | I7: =+[3]Resumen!I7*1000 -> 47405 | J7: =+[3]Resumen!J7*1000 -> 61734.581 | K7: =+[3]Resumen!K7*1000 -> 93354.328 | L7: =+[3]Resumen!L7*1000 -> 126372.48 | M7: =+[3]Resumen!M7*1000 -> 130849.44 | ... AC7: =+[3]Resumen!AC7*1000 -> 88013.843 | AD7: =SUM(F7:AC7)*E7+SUM(F8:AC8)*E8+SUM(F9:AC9)*E9+SUM(F10:AC10)*E10 -> 1.0101246e+08
D8: Sábado | E8: 4 | F8: =+[3]Resumen!F8*1000 -> 74609.769 | G8: =+[3]Resumen!G8*1000 -> 58413.518 | H8: =+[3]Resumen!H8*1000 -> 48999.974 | I8: =+[3]Resumen!I8*1000 -> 45505.766 | J8: =+[3]Resumen!J8*1000 -> 53674.469 | K8: =+[3]Resumen!K8*1000 -> 69448.284 | L8: =+[3]Resumen!L8*1000 -> 94171.21 | M8: =+[3]Resumen!M8*1000 -> 101452.93 | ... AC8: =+[3]Resumen!AC8*1000 -> 84076.351
D9: Domingo | E9: 5 | F9: =+[3]Resumen!F9*1000 -> 75118.132 | G9: =+[3]Resumen!G9*1000 -> 57521.848 | H9: =+[3]Resumen!H9*1000 -> 46252.503 | I9: =+[3]Resumen!I9*1000 -> 40206.675 | J9: =+[3]Resumen!J9*1000 -> 41866.383 | K9: =+[3]Resumen!K9*1000 -> 48652.042 | L9: =+[3]Resumen!L9*1000 -> 60039.172 | M9: =+[3]Resumen!M9*1000 -> 58070.811 | ... AC9: =+[3]Resumen!AC9*1000 -> 67916.836
D10: Festivo | E10: 2 | F10: =+[3]Resumen!F10*1000 -> 67456.057 | G10: =+[3]Resumen!G10*1000 -> 54917.595 | H10: =+[3]Resumen!H10*1000 -> 42770.503 | I10: =+[3]Resumen!I10*1000 -> 35779.772 | J10: =+[3]Resumen!J10*1000 -> 35581.453 | K10: =+[3]Resumen!K10*1000 -> 40291.654 | L10: =+[3]Resumen!L10*1000 -> 42831.593 | M10: =+[3]Resumen!M10*1000 -> 33636.962 | ... AC10: =+[3]Resumen!AC10*1000 -> 56120.455
C11: Feb | D11: Ordinario | E11: 21 | F11: =+[3]Resumen!F11*1000 -> 67597.321 | G11: =+[3]Resumen!G11*1000 -> 53332.551 | H11: =+[3]Resumen!H11*1000 -> 46480.171 | I11: =+[3]Resumen!I11*1000 -> 46424.812 | J11: =+[3]Resumen!J11*1000 -> 66673.461 | K11: =+[3]Resumen!K11*1000 -> 112726.08 | L11: =+[3]Resumen!L11*1000 -> 148334.96 | M11: =+[3]Resumen!M11*1000 -> 144230.59 | ... AC11: =+[3]Resumen!AC11*1000 -> 81289.321 | AD11: =SUM(F11:AC11)*E11+SUM(F12:AC12)*E12+SUM(F13:AC13)*E13+SUM(F14:AC14)*E14 -> 99445567
D12: Sábado | E12: 4 | F12: =+[3]Resumen!F12*1000 -> 83401.23 | G12: =+[3]Resumen!G12*1000 -> 66755.57 | H12: =+[3]Resumen!H12*1000 -> 56323.301 | I12: =+[3]Resumen!I12*1000 -> 53841.276 | J12: =+[3]Resumen!J12*1000 -> 61790.699 | K12: =+[3]Resumen!K12*1000 -> 76108.664 | L12: =+[3]Resumen!L12*1000 -> 105043.07 | M12: =+[3]Resumen!M12*1000 -> 114117.38 | ... AC12: =+[3]Resumen!AC12*1000 -> 85078.074
D13: Domingo | E13: 4 | F13: =+[3]Resumen!F13*1000 -> 77524.194 | G13: =+[3]Resumen!G13*1000 -> 59928.235 | H13: =+[3]Resumen!H13*1000 -> 48621.266 | I13: =+[3]Resumen!I13*1000 -> 42502.035 | J13: =+[3]Resumen!J13*1000 -> 43620.574 | K13: =+[3]Resumen!K13*1000 -> 49129.953 | L13: =+[3]Resumen!L13*1000 -> 60728.435 | M13: =+[3]Resumen!M13*1000 -> 58260.729 | ... AC13: =+[3]Resumen!AC13*1000 -> 63905.287
D14: Festivo | E14: 0 | F14: =+[3]Resumen!F14*1000 -> 0 | G14: =+[3]Resumen!G14*1000 -> 0 | H14: =+[3]Resumen!H14*1000 -> 0 | I14: =+[3]Resumen!I14*1000 -> 0 | J14: =+[3]Resumen!J14*1000 -> 0 | K14: =+[3]Resumen!K14*1000 -> 0 | L14: =+[3]Resumen!L14*1000 -> 0 | M14: =+[3]Resumen!M14*1000 -> 0 | ... AC14: =+[3]Resumen!AC14*1000 -> 0
C15: Mar | D15: Ordinario | E15: 22 | F15: =+[3]Resumen!F15*1000 -> 72463.674 | G15: =+[3]Resumen!G15*1000 -> 58680.974 | H15: =+[3]Resumen!H15*1000 -> 51545.52 | I15: =+[3]Resumen!I15*1000 -> 51731.874 | J15: =+[3]Resumen!J15*1000 -> 71709.09 | K15: =+[3]Resumen!K15*1000 -> 116334.83 | L15: =+[3]Resumen!L15*1000 -> 150560.66 | M15: =+[3]Resumen!M15*1000 -> 149598.55 | ... AC15: =+[3]Resumen!AC15*1000 -> 85795.854 | AD15: =SUM(F15:AC15)*E15+SUM(F16:AC16)*E16+SUM(F17:AC17)*E17+SUM(F18:AC18)*E18 -> 1.1089801e+08
D16: Sábado | E16: 4 | F16: =+[3]Resumen!F16*1000 -> 79586.414 | G16: =+[3]Resumen!G16*1000 -> 63985.619 | H16: =+[3]Resumen!H16*1000 -> 54466.765 | I16: =+[3]Resumen!I16*1000 -> 52521.438 | J16: =+[3]Resumen!J16*1000 -> 62805.494 | K16: =+[3]Resumen!K16*1000 -> 82843.999 | L16: =+[3]Resumen!L16*1000 -> 111823.79 | M16: =+[3]Resumen!M16*1000 -> 125134.89 | ... AC16: =+[3]Resumen!AC16*1000 -> 94066.295
D17: Domingo | E17: 4 | F17: =+[3]Resumen!F17*1000 -> 80825.571 | G17: =+[3]Resumen!G17*1000 -> 63466.416 | H17: =+[3]Resumen!H17*1000 -> 51864.174 | I17: =+[3]Resumen!I17*1000 -> 46325.089 | J17: =+[3]Resumen!J17*1000 -> 47664.59 | K17: =+[3]Resumen!K17*1000 -> 54590.205 | L17: =+[3]Resumen!L17*1000 -> 65741.941 | M17: =+[3]Resumen!M17*1000 -> 69208.682 | ... AC17: =+[3]Resumen!AC17*1000 -> 74792.246
D18: Festivo | E18: 1 | F18: =+[3]Resumen!F18*1000 -> 91913.599 | G18: =+[3]Resumen!G18*1000 -> 74713.251 | H18: =+[3]Resumen!H18*1000 -> 63831.703 | I18: =+[3]Resumen!I18*1000 -> 59043.821 | J18: =+[3]Resumen!J18*1000 -> 62571.408 | K18: =+[3]Resumen!K18*1000 -> 69483.001 | L18: =+[3]Resumen!L18*1000 -> 79558.092 | M18: =+[3]Resumen!M18*1000 -> 83306.015 | ... AC18: =+[3]Resumen!AC18*1000 -> 88496.902
C19: Abr | D19: Ordinario | E19: 18 | F19: =+[3]Resumen!F19*1000 -> 73328.526 | G19: =+[3]Resumen!G19*1000 -> 58919.396 | H19: =+[3]Resumen!H19*1000 -> 51751.337 | I19: =+[3]Resumen!I19*1000 -> 52001.766 | J19: =+[3]Resumen!J19*1000 -> 70811.541 | K19: =+[3]Resumen!K19*1000 -> 110331.15 | L19: =+[3]Resumen!L19*1000 -> 144745.36 | M19: =+[3]Resumen!M19*1000 -> 147104.27 | ... AC19: =+[3]Resumen!AC19*1000 -> 88936.781 | AD19: =SUM(F19:AC19)*E19+SUM(F20:AC20)*E20+SUM(F21:AC21)*E21+SUM(F22:AC22)*E22 -> 1.0385629e+08
D20: Sábado | E20: 5 | F20: =+[3]Resumen!F20*1000 -> 78175.622 | G20: =+[3]Resumen!G20*1000 -> 61183.75 | H20: =+[3]Resumen!H20*1000 -> 51595.013 | I20: =+[3]Resumen!I20*1000 -> 49444.987 | J20: =+[3]Resumen!J20*1000 -> 57778.458 | K20: =+[3]Resumen!K20*1000 -> 73476.477 | L20: =+[3]Resumen!L20*1000 -> 98864.222 | M20: =+[3]Resumen!M20*1000 -> 109847.57 | ... AC20: =+[3]Resumen!AC20*1000 -> 93172.739
D21: Domingo | E21: 5 | F21: =+[3]Resumen!F21*1000 -> 83523.591 | G21: =+[3]Resumen!G21*1000 -> 65616.662 | H21: =+[3]Resumen!H21*1000 -> 54091.156 | I21: =+[3]Resumen!I21*1000 -> 48965.821 | J21: =+[3]Resumen!J21*1000 -> 50514.205 | K21: =+[3]Resumen!K21*1000 -> 54632.105 | L21: =+[3]Resumen!L21*1000 -> 67748.286 | M21: =+[3]Resumen!M21*1000 -> 71625.07 | ... AC21: =+[3]Resumen!AC21*1000 -> 72733.938
D22: Festivo | E22: 2 | F22: =+[3]Resumen!F22*1000 -> 93621.898 | G22: =+[3]Resumen!G22*1000 -> 74842.943 | H22: =+[3]Resumen!H22*1000 -> 62929.178 | I22: =+[3]Resumen!I22*1000 -> 57451.674 | J22: =+[3]Resumen!J22*1000 -> 59736.899 | K22: =+[3]Resumen!K22*1000 -> 64398.304 | L22: =+[3]Resumen!L22*1000 -> 74546.387 | M22: =+[3]Resumen!M22*1000 -> 74600.537 | ... AC22: =+[3]Resumen!AC22*1000 -> 91303.585
C23: May | D23: Ordinario | E23: 21 | F23: =+[3]Resumen!F23*1000 -> 72817.757 | G23: =+[3]Resumen!G23*1000 -> 58218.795 | H23: =+[3]Resumen!H23*1000 -> 50937.258 | I23: =+[3]Resumen!I23*1000 -> 51514.929 | J23: =+[3]Resumen!J23*1000 -> 71397.909 | K23: =+[3]Resumen!K23*1000 -> 113330.91 | L23: =+[3]Resumen!L23*1000 -> 149851.6 | M23: =+[3]Resumen!M23*1000 -> 151854.85 | ... AC23: =+[3]Resumen!AC23*1000 -> 88537.837 | AD23: =SUM(F23:AC23)*E23+SUM(F24:AC24)*E24+SUM(F25:AC25)*E25+SUM(F26:AC26)*E26 -> 1.0941004e+08
D24: Sábado | E24: 4 | F24: =+[3]Resumen!F24*1000 -> 82404.225 | G24: =+[3]Resumen!G24*1000 -> 65358.729 | H24: =+[3]Resumen!H24*1000 -> 56298.423 | I24: =+[3]Resumen!I24*1000 -> 53411.985 | J24: =+[3]Resumen!J24*1000 -> 61591.903 | K24: =+[3]Resumen!K24*1000 -> 75650.813 | L24: =+[3]Resumen!L24*1000 -> 103315.83 | M24: =+[3]Resumen!M24*1000 -> 116419.8 | ... AC24: =+[3]Resumen!AC24*1000 -> 91884.122
D25: Domingo | E25: 4 | F25: =+[3]Resumen!F25*1000 -> 78863.858 | G25: =+[3]Resumen!G25*1000 -> 61972.02 | H25: =+[3]Resumen!H25*1000 -> 50063.341 | I25: =+[3]Resumen!I25*1000 -> 44160.257 | J25: =+[3]Resumen!J25*1000 -> 43293.934 | K25: =+[3]Resumen!K25*1000 -> 45526.666 | L25: =+[3]Resumen!L25*1000 -> 56791.139 | M25: =+[3]Resumen!M25*1000 -> 60018.373 | ... AC25: =+[3]Resumen!AC25*1000 -> 68411.711
D26: Festivo | E26: 2 | F26: =+[3]Resumen!F26*1000 -> 71244.289 | G26: =+[3]Resumen!G26*1000 -> 54856.988 | H26: =+[3]Resumen!H26*1000 -> 45471.221 | I26: =+[3]Resumen!I26*1000 -> 42462.098 | J26: =+[3]Resumen!J26*1000 -> 50958.525 | K26: =+[3]Resumen!K26*1000 -> 64365.097 | L26: =+[3]Resumen!L26*1000 -> 79066.967 | M26: =+[3]Resumen!M26*1000 -> 83873.867 | ... AC26: =+[3]Resumen!AC26*1000 -> 69763.409
C27: Jun | D27: Ordinario | E27: 20 | F27: =+[3]Resumen!F27*1000 -> 63287.564 | G27: =+[3]Resumen!G27*1000 -> 48730.541 | H27: =+[3]Resumen!H27*1000 -> 41274.679 | I27: =+[3]Resumen!I27*1000 -> 41197.757 | J27: =+[3]Resumen!J27*1000 -> 56879.137 | K27: =+[3]Resumen!K27*1000 -> 87705.27 | L27: =+[3]Resumen!L27*1000 -> 122825.5 | M27: =+[3]Resumen!M27*1000 -> 130860.93 | ... AC27: =+[3]Resumen!AC27*1000 -> 76052.312 | AD27: =SUM(F27:AC27)*E27+SUM(F28:AC28)*E28+SUM(F29:AC29)*E29+SUM(F30:AC30)*E30 -> 94806405
D28: Sábado | E28: 4 | F28: =+[3]Resumen!F28*1000 -> 70659.377 | G28: =+[3]Resumen!G28*1000 -> 54102.198 | H28: =+[3]Resumen!H28*1000 -> 43819.356 | I28: =+[3]Resumen!I28*1000 -> 41131.38 | J28: =+[3]Resumen!J28*1000 -> 48980.015 | K28: =+[3]Resumen!K28*1000 -> 63175.18 | L28: =+[3]Resumen!L28*1000 -> 91028.984 | M28: =+[3]Resumen!M28*1000 -> 104057.43 | ... AC28: =+[3]Resumen!AC28*1000 -> 82083.612
D29: Domingo | E29: 4 | F29: =+[3]Resumen!F29*1000 -> 74802.548 | G29: =+[3]Resumen!G29*1000 -> 58332.731 | H29: =+[3]Resumen!H29*1000 -> 46856.247 | I29: =+[3]Resumen!I29*1000 -> 42043.582 | J29: =+[3]Resumen!J29*1000 -> 43134.974 | K29: =+[3]Resumen!K29*1000 -> 46371.493 | L29: =+[3]Resumen!L29*1000 -> 56599.851 | M29: =+[3]Resumen!M29*1000 -> 57854.63 | ... AC29: =+[3]Resumen!AC29*1000 -> 69083.55
D30: Festivo | E30: 2 | F30: =+[3]Resumen!F30*1000 -> 64826.482 | G30: =+[3]Resumen!G30*1000 -> 48989.166 | H30: =+[3]Resumen!H30*1000 -> 39090.056 | I30: =+[3]Resumen!I30*1000 -> 35151.245 | J30: =+[3]Resumen!J30*1000 -> 37855.784 | K30: =+[3]Resumen!K30*1000 -> 43833.297 | L30: =+[3]Resumen!L30*1000 -> 54110.556 | M30: =+[3]Resumen!M30*1000 -> 54690.969 | ... AC30: =+[3]Resumen!AC30*1000 -> 65847.314
C31: Jul | D31: Ordinario | E31: 19 | F31: =+[3]Resumen!F31*1000 -> 61200.743 | G31: =+[3]Resumen!G31*1000 -> 45708.192 | H31: =+[3]Resumen!H31*1000 -> 37173.743 | I31: =+[3]Resumen!I31*1000 -> 36571.575 | J31: =+[3]Resumen!J31*1000 -> 53106.474 | K31: =+[3]Resumen!K31*1000 -> 88813.837 | L31: =+[3]Resumen!L31*1000 -> 124191.95 | M31: =+[3]Resumen!M31*1000 -> 129668.02 | ... AC31: =+[3]Resumen!AC31*1000 -> 75651.114 | AD31: =SUM(F31:AC31)*E31+SUM(F32:AC32)*E32+SUM(F33:AC33)*E33+SUM(F34:AC34)*E34 -> 94967898
D32: Sábado | E32: 5 | F32: =+[3]Resumen!F32*1000 -> 66559.678 | G32: =+[3]Resumen!G32*1000 -> 49698.225 | H32: =+[3]Resumen!H32*1000 -> 39629.476 | I32: =+[3]Resumen!I32*1000 -> 35890.298 | J32: =+[3]Resumen!J32*1000 -> 43930.441 | K32: =+[3]Resumen!K32*1000 -> 59325.261 | L32: =+[3]Resumen!L32*1000 -> 86945.017 | M32: =+[3]Resumen!M32*1000 -> 100381.93 | ... AC32: =+[3]Resumen!AC32*1000 -> 70483.998
D33: Domingo | E33: 5 | F33: =+[3]Resumen!F33*1000 -> 55838.117 | G33: =+[3]Resumen!G33*1000 -> 38260.307 | H33: =+[3]Resumen!H33*1000 -> 26866.844 | I33: =+[3]Resumen!I33*1000 -> 21137.167 | J33: =+[3]Resumen!J33*1000 -> 23282.58 | K33: =+[3]Resumen!K33*1000 -> 27844.882 | L33: =+[3]Resumen!L33*1000 -> 41140.894 | M33: =+[3]Resumen!M33*1000 -> 43473.769 | ... AC33: =+[3]Resumen!AC33*1000 -> 49037.523
D34: Festivo | E34: 2 | F34: =+[3]Resumen!F34*1000 -> 76850.019 | G34: =+[3]Resumen!G34*1000 -> 57309.908 | H34: =+[3]Resumen!H34*1000 -> 45039.414 | I34: =+[3]Resumen!I34*1000 -> 38672.447 | J34: =+[3]Resumen!J34*1000 -> 37778.919 | K34: =+[3]Resumen!K34*1000 -> 37908.979 | L34: =+[3]Resumen!L34*1000 -> 50107.777 | M34: =+[3]Resumen!M34*1000 -> 52412.755 | ... AC34: =+[3]Resumen!AC34*1000 -> 71830.381
C35: Ago | D35: Ordinario | E35: 21 | F35: =+[3]Resumen!F35*1000 -> 57981.509 | G35: =+[3]Resumen!G35*1000 -> 42419.658 | H35: =+[3]Resumen!H35*1000 -> 34146.322 | I35: =+[3]Resumen!I35*1000 -> 33523.527 | J35: =+[3]Resumen!J35*1000 -> 51914.867 | K35: =+[3]Resumen!K35*1000 -> 91534.027 | L35: =+[3]Resumen!L35*1000 -> 128355.15 | M35: =+[3]Resumen!M35*1000 -> 130672.03 | ... AC35: =+[3]Resumen!AC35*1000 -> 73434.166 | AD35: =SUM(F35:AC35)*E35+SUM(F36:AC36)*E36+SUM(F37:AC37)*E37+SUM(F38:AC38)*E38 -> 95790142
D36: Sábado | E36: 4 | F36: =+[3]Resumen!F36*1000 -> 64152.23 | G36: =+[3]Resumen!G36*1000 -> 47928.86 | H36: =+[3]Resumen!H36*1000 -> 37860.341 | I36: =+[3]Resumen!I36*1000 -> 34394.073 | J36: =+[3]Resumen!J36*1000 -> 43093.07 | K36: =+[3]Resumen!K36*1000 -> 57735.889 | L36: =+[3]Resumen!L36*1000 -> 85946.284 | M36: =+[3]Resumen!M36*1000 -> 99730.937 | ... AC36: =+[3]Resumen!AC36*1000 -> 67395.965
D37: Domingo | E37: 4 | F37: =+[3]Resumen!F37*1000 -> 58564.138 | G37: =+[3]Resumen!G37*1000 -> 41796.787 | H37: =+[3]Resumen!H37*1000 -> 30058.563 | I37: =+[3]Resumen!I37*1000 -> 24929.196 | J37: =+[3]Resumen!J37*1000 -> 27199.592 | K37: =+[3]Resumen!K37*1000 -> 33846.972 | L37: =+[3]Resumen!L37*1000 -> 43462.035 | M37: =+[3]Resumen!M37*1000 -> 46094.341 | ... AC37: =+[3]Resumen!AC37*1000 -> 54060.877
D38: Festivo | E38: 2 | F38: =+[3]Resumen!F38*1000 -> 52154.235 | G38: =+[3]Resumen!G38*1000 -> 35142.157 | H38: =+[3]Resumen!H38*1000 -> 23644.123 | I38: =+[3]Resumen!I38*1000 -> 21282.152 | J38: =+[3]Resumen!J38*1000 -> 24258.092 | K38: =+[3]Resumen!K38*1000 -> 34328.536 | L38: =+[3]Resumen!L38*1000 -> 49186.496 | M38: =+[3]Resumen!M38*1000 -> 50443.458 | ... AC38: =+[3]Resumen!AC38*1000 -> 53509.683
C39: Sep | D39: Ordinario | E39: 21 | F39: =+[3]Resumen!F39*1000 -> 53815.17 | G39: =+[3]Resumen!G39*1000 -> 39293.432 | H39: =+[3]Resumen!H39*1000 -> 31743.14 | I39: =+[3]Resumen!I39*1000 -> 31281.802 | J39: =+[3]Resumen!J39*1000 -> 49651.353 | K39: =+[3]Resumen!K39*1000 -> 90205.453 | L39: =+[3]Resumen!L39*1000 -> 125473.53 | M39: =+[3]Resumen!M39*1000 -> 125482.41 | ... AC39: =+[3]Resumen!AC39*1000 -> 67134.857 | AD39: =SUM(F39:AC39)*E39+SUM(F40:AC40)*E40+SUM(F41:AC41)*E41+SUM(F42:AC42)*E42 -> 91500866
D40: Sábado | E40: 5 | F40: =+[3]Resumen!F40*1000 -> 58263.317 | G40: =+[3]Resumen!G40*1000 -> 42470.456 | H40: =+[3]Resumen!H40*1000 -> 32372.965 | I40: =+[3]Resumen!I40*1000 -> 29740.123 | J40: =+[3]Resumen!J40*1000 -> 39134.845 | K40: =+[3]Resumen!K40*1000 -> 57034.123 | L40: =+[3]Resumen!L40*1000 -> 83097.352 | M40: =+[3]Resumen!M40*1000 -> 95721.872 | ... AC40: =+[3]Resumen!AC40*1000 -> 68774.581
D41: Domingo | E41: 4 | F41: =+[3]Resumen!F41*1000 -> 59633.805 | G41: =+[3]Resumen!G41*1000 -> 40622.287 | H41: =+[3]Resumen!H41*1000 -> 29345.573 | I41: =+[3]Resumen!I41*1000 -> 23358.833 | J41: =+[3]Resumen!J41*1000 -> 24170.796 | K41: =+[3]Resumen!K41*1000 -> 28550.192 | L41: =+[3]Resumen!L41*1000 -> 38924.08 | M41: =+[3]Resumen!M41*1000 -> 40122.421 | ... AC41: =+[3]Resumen!AC41*1000 -> 47544.173
D42: Festivo | E42: 0 | F42: =+[3]Resumen!F42*1000 -> 0 | G42: =+[3]Resumen!G42*1000 -> 0 | H42: =+[3]Resumen!H42*1000 -> 0 | I42: =+[3]Resumen!I42*1000 -> 0 | J42: =+[3]Resumen!J42*1000 -> 0 | K42: =+[3]Resumen!K42*1000 -> 0 | L42: =+[3]Resumen!L42*1000 -> 0 | M42: =+[3]Resumen!M42*1000 -> 0 | ... AC42: =+[3]Resumen!AC42*1000 -> 0
...

Sheet Cantidades 2029
C2: CANTIDADES DE ENERGÍA SOLICITADAS (kWh)
C3: EMPRESAS PÚBLICAS DE MEDELLÍN E.S.P.
C4: 2029
C6: Mes | D6: Tipo Día | E6: Días | F6: H1 | G6: H2 | H6: H3 | I6: H4 | J6: H5 | K6: H6 | L6: H7 | M6: H8 | N6: H9 | O6: H10 | P6: H11 | Q6: H12 | R6: H13 | S6: H14 | T6: H15 | U6: H16 | V6: H17 | W6: H18 | X6: H19 | Y6: H20 | Z6: H21 | AA6: H22 | AB6: H23 | AC6: H24 | AD6: TOTAL MES
C7: Ene | D7: Ordinario | E7: 21 | F7: =+[4]Resumen!F7*1000 -> 78165.752 | G7: =+[4]Resumen!G7*1000 -> 67145.303 | H7: =+[4]Resumen!H7*1000 -> 61035.521 | I7: =+[4]Resumen!I7*1000 -> 60238.895 | J7: =+[4]Resumen!J7*1000 -> 73574.412 | K7: =+[4]Resumen!K7*1000 -> 98036.657 | L7: =+[4]Resumen!L7*1000 -> 123689.06 | M7: =+[4]Resumen!M7*1000 -> 126250.12 | ... AC7: =+[4]Resumen!AC7*1000 -> 100906.71 | AD7: =SUM(F7:AC7)*E7+SUM(F8:AC8)*E8+SUM(F9:AC9)*E9+SUM(F10:AC10)*E10 -> 1.0048524e+08
D8: Sábado | E8: 4 | F8: =+[4]Resumen!F8*1000 -> 83570.22 | G8: =+[4]Resumen!G8*1000 -> 71056.193 | H8: =+[4]Resumen!H8*1000 -> 63851.978 | I8: =+[4]Resumen!I8*1000 -> 61241.707 | J8: =+[4]Resumen!J8*1000 -> 67736.697 | K8: =+[4]Resumen!K8*1000 -> 79932.929 | L8: =+[4]Resumen!L8*1000 -> 99301.552 | M8: =+[4]Resumen!M8*1000 -> 104243.39 | ... AC8: =+[4]Resumen!AC8*1000 -> 102148.78
D9: Domingo | E9: 4 | F9: =+[4]Resumen!F9*1000 -> 83727.066 | G9: =+[4]Resumen!G9*1000 -> 70132.872 | H9: =+[4]Resumen!H9*1000 -> 61463.847 | I9: =+[4]Resumen!I9*1000 -> 56879.397 | J9: =+[4]Resumen!J9*1000 -> 58192.443 | K9: =+[4]Resumen!K9*1000 -> 63389.328 | L9: =+[4]Resumen!L9*1000 -> 72347.961 | M9: =+[4]Resumen!M9*1000 -> 69934.085 | ... AC9: =+[4]Resumen!AC9*1000 -> 89834.524
D10: Festivo | E10: 2 | F10: =+[4]Resumen!F10*1000 -> 78901.004 | G10: =+[4]Resumen!G10*1000 -> 69201.983 | H10: =+[4]Resumen!H10*1000 -> 59889.588 | I10: =+[4]Resumen!I10*1000 -> 54439.201 | J10: =+[4]Resumen!J10*1000 -> 54319.856 | K10: =+[4]Resumen!K10*1000 -> 57766.942 | L10: =+[4]Resumen!L10*1000 -> 59999.358 | M10: =+[4]Resumen!M10*1000 -> 51904.806 | ... AC10: =+[4]Resumen!AC10*1000 -> 81170.446
C11: Feb | D11: Ordinario | E11: 20 | F11: =+[4]Resumen!F11*1000 -> 83547.084 | G11: =+[4]Resumen!G11*1000 -> 72641.063 | H11: =+[4]Resumen!H11*1000 -> 67346.703 | I11: =+[4]Resumen!I11*1000 -> 67333.018 | J11: =+[4]Resumen!J11*1000 -> 85701.428 | K11: =+[4]Resumen!K11*1000 -> 122066.08 | L11: =+[4]Resumen!L11*1000 -> 150327.92 | M11: =+[4]Resumen!M11*1000 -> 146843.02 | ... AC11: =+[4]Resumen!AC11*1000 -> 105338.53 | AD11: =SUM(F11:AC11)*E11+SUM(F12:AC12)*E12+SUM(F13:AC13)*E13+SUM(F14:AC14)*E14 -> 1.0130964e+08
D12: Sábado | E12: 4 | F12: =+[4]Resumen!F12*1000 -> 98553.024 | G12: =+[4]Resumen!G12*1000 -> 85516.221 | H12: =+[4]Resumen!H12*1000 -> 77422.944 | I12: =+[4]Resumen!I12*1000 -> 75796.476 | J12: =+[4]Resumen!J12*1000 -> 83298.281 | K12: =+[4]Resumen!K12*1000 -> 97264.819 | L12: =+[4]Resumen!L12*1000 -> 121139.49 | M12: =+[4]Resumen!M12*1000 -> 127270.18 | ... AC12: =+[4]Resumen!AC12*1000 -> 112959.13
D13: Domingo | E13: 4 | F13: =+[4]Resumen!F13*1000 -> 94588.837 | G13: =+[4]Resumen!G13*1000 -> 80674.504 | H13: =+[4]Resumen!H13*1000 -> 71832.525 | I13: =+[4]Resumen!I13*1000 -> 67370.394 | J13: =+[4]Resumen!J13*1000 -> 69182.993 | K13: =+[4]Resumen!K13*1000 -> 74714.975 | L13: =+[4]Resumen!L13*1000 -> 85629.385 | M13: =+[4]Resumen!M13*1000 -> 84347.172 | ... AC13: =+[4]Resumen!AC13*1000 -> 97162.342
D14: Festivo | E14: 0 | F14: =+[4]Resumen!F14*1000 -> 0 | G14: =+[4]Resumen!G14*1000 -> 0 | H14: =+[4]Resumen!H14*1000 -> 0 | I14: =+[4]Resumen!I14*1000 -> 0 | J14: =+[4]Resumen!J14*1000 -> 0 | K14: =+[4]Resumen!K14*1000 -> 0 | L14: =+[4]Resumen!L14*1000 -> 0 | M14: =+[4]Resumen!M14*1000 -> 0 | ... AC14: =+[4]Resumen!AC14*1000 -> 0
C15: Mar | D15: Ordinario | E15: 19 | F15: =+[4]Resumen!F15*1000 -> 81265.295 | G15: =+[4]Resumen!G15*1000 -> 71065.634 | H15: =+[4]Resumen!H15*1000 -> 65812.331 | I15: =+[4]Resumen!I15*1000 -> 66013.682 | J15: =+[4]Resumen!J15*1000 -> 84199.691 | K15: =+[4]Resumen!K15*1000 -> 119386.99 | L15: =+[4]Resumen!L15*1000 -> 146271.35 | M15: =+[4]Resumen!M15*1000 -> 144862.14 | ... AC15: =+[4]Resumen!AC15*1000 -> 102639.22 | AD15: =SUM(F15:AC15)*E15+SUM(F16:AC16)*E16+SUM(F17:AC17)*E17+SUM(F18:AC18)*E18 -> 1.088526e+08
D16: Sábado | E16: 5 | F16: =+[4]Resumen!F16*1000 -> 90415.091 | G16: =+[4]Resumen!G16*1000 -> 78264.187 | H16: =+[4]Resumen!H16*1000 -> 70928.948 | I16: =+[4]Resumen!I16*1000 -> 69515.641 | J16: =+[4]Resumen!J16*1000 -> 77799.878 | K16: =+[4]Resumen!K16*1000 -> 93478.542 | L16: =+[4]Resumen!L16*1000 -> 116461.82 | M16: =+[4]Resumen!M16*1000 -> 126180.73 | ... AC16: =+[4]Resumen!AC16*1000 -> 112719.59
D17: Domingo | E17: 4 | F17: =+[4]Resumen!F17*1000 -> 91050.888 | G17: =+[4]Resumen!G17*1000 -> 77505.576 | H17: =+[4]Resumen!H17*1000 -> 68626.943 | I17: =+[4]Resumen!I17*1000 -> 64311.338 | J17: =+[4]Resumen!J17*1000 -> 65520.48 | K17: =+[4]Resumen!K17*1000 -> 71104.957 | L17: =+[4]Resumen!L17*1000 -> 80001.701 | M17: =+[4]Resumen!M17*1000 -> 81987.497 | ... AC17: =+[4]Resumen!AC17*1000 -> 97687.265
D18: Festivo | E18: 3 | F18: =+[4]Resumen!F18*1000 -> 98933.82 | G18: =+[4]Resumen!G18*1000 -> 85511.662 | H18: =+[4]Resumen!H18*1000 -> 77147.137 | I18: =+[4]Resumen!I18*1000 -> 73599.351 | J18: =+[4]Resumen!J18*1000 -> 76330.531 | K18: =+[4]Resumen!K18*1000 -> 82114.552 | L18: =+[4]Resumen!L18*1000 -> 90122.687 | M18: =+[4]Resumen!M18*1000 -> 91728.559 | ... AC18: =+[4]Resumen!AC18*1000 -> 108020.89
C19: Abr | D19: Ordinario | E19: 21 | F19: =+[4]Resumen!F19*1000 -> 79254.966 | G19: =+[4]Resumen!G19*1000 -> 68709.561 | H19: =+[4]Resumen!H19*1000 -> 63454.783 | I19: =+[4]Resumen!I19*1000 -> 63646.445 | J19: =+[4]Resumen!J19*1000 -> 80419.941 | K19: =+[4]Resumen!K19*1000 -> 110735.15 | L19: =+[4]Resumen!L19*1000 -> 137222.13 | M19: =+[4]Resumen!M19*1000 -> 138584.68 | ... AC19: =+[4]Resumen!AC19*1000 -> 101819.11 | AD19: =SUM(F19:AC19)*E19+SUM(F20:AC20)*E20+SUM(F21:AC21)*E21+SUM(F22:AC22)*E22 -> 1.032915e+08
D20: Sábado | E20: 4 | F20: =+[4]Resumen!F20*1000 -> 86186.586 | G20: =+[4]Resumen!G20*1000 -> 73201.47 | H20: =+[4]Resumen!H20*1000 -> 65873.947 | I20: =+[4]Resumen!I20*1000 -> 64338.001 | J20: =+[4]Resumen!J20*1000 -> 71170.546 | K20: =+[4]Resumen!K20*1000 -> 83460.971 | L20: =+[4]Resumen!L20*1000 -> 103332.99 | M20: =+[4]Resumen!M20*1000 -> 111043.77 | ... AC20: =+[4]Resumen!AC20*1000 -> 108955.2
D21: Domingo | E21: 5 | F21: =+[4]Resumen!F21*1000 -> 90198.871 | G21: =+[4]Resumen!G21*1000 -> 76466.876 | H21: =+[4]Resumen!H21*1000 -> 67783.959 | I21: =+[4]Resumen!I21*1000 -> 63945.549 | J21: =+[4]Resumen!J21*1000 -> 65473.317 | K21: =+[4]Resumen!K21*1000 -> 69095.929 | L21: =+[4]Resumen!L21*1000 -> 79513.384 | M21: =+[4]Resumen!M21*1000 -> 81837.633 | ... AC21: =+[4]Resumen!AC21*1000 -> 93948.608
D22: Festivo | E22: 0 | F22: =+[4]Resumen!F22*1000 -> 170172.67 | G22: =+[4]Resumen!G22*1000 -> 154176.98 | H22: =+[4]Resumen!H22*1000 -> 144281.16 | I22: =+[4]Resumen!I22*1000 -> 139792.8 | J22: =+[4]Resumen!J22*1000 -> 142034.09 | K22: =+[4]Resumen!K22*1000 -> 146620.2 | L22: =+[4]Resumen!L22*1000 -> 155896.63 | M22: =+[4]Resumen!M22*1000 -> 154348.67 | ... AC22: =+[4]Resumen!AC22*1000 -> 183150.19
C23: May | D23: Ordinario | E23: 21 | F23: =+[4]Resumen!F23*1000 -> 80497.6 | G23: =+[4]Resumen!G23*1000 -> 69671.468 | H23: =+[4]Resumen!H23*1000 -> 64215.378 | I23: =+[4]Resumen!I23*1000 -> 64571.575 | J23: =+[4]Resumen!J23*1000 -> 81763.583 | K23: =+[4]Resumen!K23*1000 -> 112603.15 | L23: =+[4]Resumen!L23*1000 -> 140988.26 | M23: =+[4]Resumen!M23*1000 -> 143088.68 | ... AC23: =+[4]Resumen!AC23*1000 -> 103061.01 | AD23: =SUM(F23:AC23)*E23+SUM(F24:AC24)*E24+SUM(F25:AC25)*E25+SUM(F26:AC26)*E26 -> 1.0766989e+08
D24: Sábado | E24: 4 | F24: =+[4]Resumen!F24*1000 -> 90723.698 | G24: =+[4]Resumen!G24*1000 -> 77618.723 | H24: =+[4]Resumen!H24*1000 -> 70721.912 | I24: =+[4]Resumen!I24*1000 -> 68639.314 | J24: =+[4]Resumen!J24*1000 -> 75482.949 | K24: =+[4]Resumen!K24*1000 -> 86640.356 | L24: =+[4]Resumen!L24*1000 -> 109188.43 | M24: =+[4]Resumen!M24*1000 -> 119638.46 | ... AC24: =+[4]Resumen!AC24*1000 -> 110266.02
D25: Domingo | E25: 4 | F25: =+[4]Resumen!F25*1000 -> 88596.047 | G25: =+[4]Resumen!G25*1000 -> 75435.129 | H25: =+[4]Resumen!H25*1000 -> 66478.968 | I25: =+[4]Resumen!I25*1000 -> 62217.459 | J25: =+[4]Resumen!J25*1000 -> 62319.166 | K25: =+[4]Resumen!K25*1000 -> 64725.618 | L25: =+[4]Resumen!L25*1000 -> 74701.477 | M25: =+[4]Resumen!M25*1000 -> 77059.145 | ... AC25: =+[4]Resumen!AC25*1000 -> 93251.593
D26: Festivo | E26: 2 | F26: =+[4]Resumen!F26*1000 -> 82115.926 | G26: =+[4]Resumen!G26*1000 -> 69599.129 | H26: =+[4]Resumen!H26*1000 -> 62227.346 | I26: =+[4]Resumen!I26*1000 -> 59908.079 | J26: =+[4]Resumen!J26*1000 -> 66233.17 | K26: =+[4]Resumen!K26*1000 -> 76068.58 | L26: =+[4]Resumen!L26*1000 -> 87649.154 | M26: =+[4]Resumen!M26*1000 -> 90724.606 | ... AC26: =+[4]Resumen!AC26*1000 -> 92836.848
C27: Jun | D27: Ordinario | E27: 19 | F27: =+[4]Resumen!F27*1000 -> 76119.421 | G27: =+[4]Resumen!G27*1000 -> 65287.264 | H27: =+[4]Resumen!H27*1000 -> 59797.512 | I27: =+[4]Resumen!I27*1000 -> 59790.576 | J27: =+[4]Resumen!J27*1000 -> 74428.308 | K27: =+[4]Resumen!K27*1000 -> 98775.141 | L27: =+[4]Resumen!L27*1000 -> 126429.25 | M27: =+[4]Resumen!M27*1000 -> 132309.05 | ... AC27: =+[4]Resumen!AC27*1000 -> 97023.155 | AD27: =SUM(F27:AC27)*E27+SUM(F28:AC28)*E28+SUM(F29:AC29)*E29+SUM(F30:AC30)*E30 -> 97804193
D28: Sábado | E28: 5 | F28: =+[4]Resumen!F28*1000 -> 84776.557 | G28: =+[4]Resumen!G28*1000 -> 71984.995 | H28: =+[4]Resumen!H28*1000 -> 64050.179 | I28: =+[4]Resumen!I28*1000 -> 61978.182 | J28: =+[4]Resumen!J28*1000 -> 68518.038 | K28: =+[4]Resumen!K28*1000 -> 79821.414 | L28: =+[4]Resumen!L28*1000 -> 101736.37 | M28: =+[4]Resumen!M28*1000 -> 111345.6 | ... AC28: =+[4]Resumen!AC28*1000 -> 104471.94
D29: Domingo | E29: 4 | F29: =+[4]Resumen!F29*1000 -> 86948.396 | G29: =+[4]Resumen!G29*1000 -> 74106.152 | H29: =+[4]Resumen!H29*1000 -> 65311.534 | I29: =+[4]Resumen!I29*1000 -> 61573.568 | J29: =+[4]Resumen!J29*1000 -> 62567.645 | K29: =+[4]Resumen!K29*1000 -> 65391.534 | L29: =+[4]Resumen!L29*1000 -> 73929.406 | M29: =+[4]Resumen!M29*1000 -> 74337.789 | ... AC29: =+[4]Resumen!AC29*1000 -> 94472.678
D30: Festivo | E30: 2 | F30: =+[4]Resumen!F30*1000 -> 79527.227 | G30: =+[4]Resumen!G30*1000 -> 67176.244 | H30: =+[4]Resumen!H30*1000 -> 59546.686 | I30: =+[4]Resumen!I30*1000 -> 56522.262 | J30: =+[4]Resumen!J30*1000 -> 58775.107 | K30: =+[4]Resumen!K30*1000 -> 63390.987 | L30: =+[4]Resumen!L30*1000 -> 71700.432 | M30: =+[4]Resumen!M30*1000 -> 71568.803 | ... AC30: =+[4]Resumen!AC30*1000 -> 92119.877
C31: Jul | D31: Ordinario | E31: 20 | F31: =+[4]Resumen!F31*1000 -> 86465.301 | G31: =+[4]Resumen!G31*1000 -> 74986.954 | H31: =+[4]Resumen!H31*1000 -> 68707.267 | I31: =+[4]Resumen!I31*1000 -> 68309.826 | J31: =+[4]Resumen!J31*1000 -> 83567.073 | K31: =+[4]Resumen!K31*1000 -> 111604.35 | L31: =+[4]Resumen!L31*1000 -> 139222.85 | M31: =+[4]Resumen!M31*1000 -> 142680.92 | ... AC31: =+[4]Resumen!AC31*1000 -> 108704.94 | AD31: =SUM(F31:AC31)*E31+SUM(F32:AC32)*E32+SUM(F33:AC33)*E33+SUM(F34:AC34)*E34 -> 1.0828386e+08
D32: Sábado | E32: 4 | F32: =+[4]Resumen!F32*1000 -> 94051.17 | G32: =+[4]Resumen!G32*1000 -> 80994.299 | H32: =+[4]Resumen!H32*1000 -> 73231.431 | I32: =+[4]Resumen!I32*1000 -> 70417.698 | J32: =+[4]Resumen!J32*1000 -> 76826.617 | K32: =+[4]Resumen!K32*1000 -> 88992.691 | L32: =+[4]Resumen!L32*1000 -> 110669.57 | M32: =+[4]Resumen!M32*1000 -> 120510.59 | ... AC32: =+[4]Resumen!AC32*1000 -> 109217.22
D33: Domingo | E33: 5 | F33: =+[4]Resumen!F33*1000 -> 86712.718 | G33: =+[4]Resumen!G33*1000 -> 73144.817 | H33: =+[4]Resumen!H33*1000 -> 64287.287 | I33: =+[4]Resumen!I33*1000 -> 59783.902 | J33: =+[4]Resumen!J33*1000 -> 61431.277 | K33: =+[4]Resumen!K33*1000 -> 64944.457 | L33: =+[4]Resumen!L33*1000 -> 75215.66 | M33: =+[4]Resumen!M33*1000 -> 76101.891 | ... AC33: =+[4]Resumen!AC33*1000 -> 93123.053
D34: Festivo | E34: 2 | F34: =+[4]Resumen!F34*1000 -> 101477.55 | G34: =+[4]Resumen!G34*1000 -> 86679.026 | H34: =+[4]Resumen!H34*1000 -> 77181.438 | I34: =+[4]Resumen!I34*1000 -> 72401.134 | J34: =+[4]Resumen!J34*1000 -> 72178.99 | K34: =+[4]Resumen!K34*1000 -> 72928.498 | L34: =+[4]Resumen!L34*1000 -> 82453.337 | M34: =+[4]Resumen!M34*1000 -> 83596.608 | ... AC34: =+[4]Resumen!AC34*1000 -> 108636.31
