Workbook

Sheet Anexo1
B3: ANEXO No 1 - PRODUCTO No. 1 - CURVA
B4: PAGUE LO CONTRATADO AÑO 2027
B5: PRECIO OFERTADO EN $ / kWh DE FEBRERO DE 2026
B8: MES | C8: ENERGIA SOLICITADA kWh/MES | D8: % OFERTADO ANUAL | E8: ENERGIA OFERTADA kWh/MES | F8: PRECIO OFERTADO ANUAL $/kWh
B10: 46388 | C10: =+'Anexo 5'!AC6 -> 24221131 | E10: =+'Cantidades Ofertadas Prod1'!AC6 -> 0
B11: 46419 | C11: =+'Anexo 5'!AC9 -> 22377856 | E11: =+'Cantidades Ofertadas Prod1'!AC9 -> 0
B12: 46447 | C12: =+'Anexo 5'!AC12 -> 24046148 | E12: =+'Cantidades Ofertadas Prod1'!AC12 -> 0
B13: 46478 | C13: =+'Anexo 5'!AC15 -> 22900488 | E13: =+'Cantidades Ofertadas Prod1'!AC15 -> 0
B14: 46508 | C14: =+'Anexo 5'!AC18 -> 23626140 | E14: =+'Cantidades Ofertadas Prod1'!AC18 -> 0
B15: 46539 | C15: =+'Anexo 5'!AC21 -> 22961808 | E15: =+'Cantidades Ofertadas Prod1'!AC21 -> 0
B16: 46569 | C16: =+'Anexo 5'!AC24 -> 24259657 | E16: =+'Cantidades Ofertadas Prod1'!AC24 -> 0
B17: 46600 | C17: =+'Anexo 5'!AC27 -> 24688809 | E17: =+'Cantidades Ofertadas Prod1'!AC27 -> 0
B18: 46631 | C18: =+'Anexo 5'!AC30 -> 24321860 | E18: =+'Cantidades Ofertadas Prod1'!AC30 -> 0
B19: 46661 | C19: =+'Anexo 5'!AC33 -> 24018034 | E19: =+'Cantidades Ofertadas Prod1'!AC33 -> 0
B20: 46692 | C20: =+'Anexo 5'!AC36 -> 22864092 | E20: =+'Cantidades Ofertadas Prod1'!AC36 -> 0
B21: 46722 | C21: =+'Anexo 5'!AC39 -> 24561468 | E21: =+'Cantidades Ofertadas Prod1'!AC39 -> 0
B22: TOTAL | C22: =+SUM(C10:C21) -> 284847491 | E22: =SUM(E10:E21) -> 0 | F22: =+F10 -> 0
B23: *Solo se debe ingresar valores en las celdas en color Naranja
B24: * Se debe ofertar un unico % para todos los meses del año.
B25: * Los % ofertados se aplicaran a las curvas de carga de la hoja "Anexo 5".
B26: * La energia ofertada se calcula de manera automatica en la hoja "Cantidades Ofertadas Prod1"
B27: * Se debe ofertar un unico precio por producto.
B28: * Para ofertas planas se debe diligenciar el anexo 1A, con un tope horario de 15.000 kWh
B32: ____________________________________________
B33: Firma del Representante Legal
B34: o Apoderado General (Responsable del negocio)

Sheet Anexo 1A
B3: ANEXO No 2A - PRODUCTO No. 1 - OFERTA PLANA BLOQUE 2
B4: PAGUE LO CONTRATADO AÑO 2027
B5: PRECIO OFERTADO EN $ / kWh DE FEBRERO DE 2026
B8: MES | C8: ENERGIA MAXIMA A OFERTAR kWh/MES | D8: kWh OFERTADO | E8: ENERGIA OFERTADA kWh/MES | F8: PRECIO OFERTADO ANUAL $/kWh
A9: 15000
A10: 31 | B10: 46388 | C10: =+$A$9*A10*24 -> 11160000 | D10: 0 | E10: =+$D$10*A10*24 -> 0
A11: 28 | B11: 46419 | C11: =+$A$9*A11*24 -> 10080000 | E11: =+$D$10*A11*24 -> 0
A12: 31 | B12: 46447 | C12: =+$A$9*A12*24 -> 11160000 | E12: =+$D$10*A12*24 -> 0
A13: 30 | B13: 46478 | C13: =+$A$9*A13*24 -> 10800000 | E13: =+$D$10*A13*24 -> 0
A14: 31 | B14: 46508 | C14: =+$A$9*A14*24 -> 11160000 | E14: =+$D$10*A14*24 -> 0
A15: 30 | B15: 46539 | C15: =+$A$9*A15*24 -> 10800000 | E15: =+$D$10*A15*24 -> 0
A16: 31 | B16: 46569 | C16: =+$A$9*A16*24 -> 11160000 | E16: =+$D$10*A16*24 -> 0
A17: 31 | B17: 46600 | C17: =+$A$9*A17*24 -> 11160000 | E17: =+$D$10*A17*24 -> 0
A18: 30 | B18: 46631 | C18: =+$A$9*A18*24 -> 10800000 | E18: =+$D$10*A18*24 -> 0
A19: 31 | B19: 46661 | C19: =+$A$9*A19*24 -> 11160000 | E19: =+$D$10*A19*24 -> 0
A20: 30 | B20: 46692 | C20: =+$A$9*A20*24 -> 10800000 | E20: =+$D$10*A20*24 -> 0
A21: 31 | B21: 46722 | C21: =+$A$9*A21*24 -> 11160000 | E21: =+$D$10*A21*24 -> 0
B22: TOTAL | C22: =+SUM(C10:C21) -> 131400000 | E22: =SUM(E10:E21) -> 0 | F22: =+F10 -> 0
B23: *Solo se debe ingresar valores en las celdas en color Naranja
B24: * Se debe oferta un valor de kWh el cual se aplica para todas las horas del año, con un tope horario de 15.000 kWh
B25: * Se debe ofertar un unico precio por producto.
B26: * A las ofertas planas al momento de la evaluación se le adicionarán 5 $/kWh al precio ofertado; con el fin de hacerlas comparables con las Ofertas que siguen la curva
B29: ____________________________________________
B30: Firma del Representante Legal
B31: o Apoderado General (Responsable del negocio)

Sheet Anexo 5
A1: CURVAS REQUERIDAS PRODUCTO 1 AÑO 2027 MODALIDAD PAGUE LO CONTRATADO - kWh
A4: Periodo | B4: Tipo de día | C4: H01 | D4: H02 | E4: H03 | F4: H04 | G4: H05 | H4: H06 | I4: H07 | J4: H08 | K4: H09 | L4: H10 | M4: H11 | N4: H12 | O4: H13 | P4: H14 | Q4: H15 | R4: H16 | S4: H17 | T4: H18 | U4: H19 | V4: H20 | W4: H21 | X4: H22 | Y4: H23 | Z4: H24 | AA4: TOTAL DÍA | AB4: Días/ | AC4: TOTAL MES
AB5: mes
A6: 46388 | B6: O | C6: 26386 | D6: 24861 | E6: 23943 | F6: 23469 | G6: 23797 | H6: 25214 | I6: 26562 | J6: 29085 | K6: 31923 | L6: 34072 | M6: 36262 | N6: 38327 | O6: 37976 | P6: 38021 | Q6: 38655 | R6: 38776 | S6: 38332 | T6: 37502 | U6: 40258 | V6: 42554 | W6: 41010 | X6: 38304 | Y6: 33954 | Z6: 29561 | AA6: =SUM(C6:Z6) -> 798804 | AB6: 19 | AC6: =+AA6*AB6+AA7*AB7+AA8*AB8 -> 24221131
B7: S | C7: 27023 | D7: 25300 | E7: 24249 | F7: 23587 | G7: 23608 | H7: 24401 | I7: 25325 | J7: 27890 | K7: 31062 | L7: 33456 | M7: 35250 | N7: 37024 | O7: 37216 | P7: 36851 | Q7: 36450 | R7: 36255 | S7: 35982 | T7: 35947 | U7: 39402 | V7: 41863 | W7: 40180 | X7: 37671 | Y7: 34111 | Z7: 30543 | AA7: =SUM(C7:Z7) -> 780646 | AB7: 5
B8: F | C8: 28328 | D8: 26467 | E8: 25233 | F8: 24362 | G8: 23937 | H8: 24104 | I8: 23868 | J8: 25277 | K8: 27691 | L8: 29817 | M8: 31387 | N8: 33021 | O8: 33989 | P8: 33874 | Q8: 33259 | R8: 32904 | S8: 32726 | T8: 32903 | U8: 36672 | V8: 39364 | W8: 38266 | X8: 35920 | Y8: 32302 | Z8: 28704 | AA8: =SUM(C8:Z8) -> 734375 | AB8: 7
A9: 46419 | B9: O | C9: 26540 | D9: 25073 | E9: 24229 | F9: 23814 | G9: 24294 | H9: 26494 | I9: 28247 | J9: 30150 | K9: 32675 | L9: 34567 | M9: 36634 | N9: 38549 | O9: 37780 | P9: 38072 | Q9: 38962 | R9: 39122 | S9: 38686 | T9: 37676 | U9: 39779 | V9: 42791 | W9: 41307 | X9: 38474 | Y9: 34003 | Z9: 29555 | AA9: =SUM(C9:Z9) -> 807473 | AB9: 20 | AC9: =+AA9*AB9+AA10*AB10+AA11*AB11 -> 22377856
B10: S | C10: 27523 | D10: 25895 | E10: 24849 | F10: 24248 | G10: 24319 | H10: 25172 | I10: 26537 | J10: 29101 | K10: 32395 | L10: 34690 | M10: 36514 | N10: 38285 | O10: 38334 | P10: 37843 | Q10: 37422 | R10: 37192 | S10: 36875 | T10: 36760 | U10: 39555 | V10: 42584 | W10: 40916 | X10: 38547 | Y10: 35159 | Z10: 31395 | AA10: =SUM(C10:Z10) -> 802110 | AB10: 4
B11: F | C11: 28586 | D11: 26739 | E11: 25613 | F11: 24768 | G11: 24498 | H11: 24752 | I11: 24954 | J11: 26607 | K11: 29254 | L11: 31421 | M11: 32857 | N11: 34409 | O11: 35279 | P11: 34995 | Q11: 34302 | R11: 33882 | S11: 33670 | T11: 33848 | U11: 36854 | V11: 40200 | W11: 39179 | X11: 36748 | Y11: 32755 | Z11: 28819 | AA11: =SUM(C11:Z11) -> 754989 | AB11: 4
A12: 46447 | B12: O | C12: 25976 | D12: 24571 | E12: 23793 | F12: 23404 | G12: 23920 | H12: 26078 | I12: 27589 | J12: 29695 | K12: 32120 | L12: 33936 | M12: 35872 | N12: 37617 | O12: 36922 | P12: 37075 | Q12: 37840 | R12: 37965 | S12: 37633 | T12: 36922 | U12: 39547 | V12: 42116 | W12: 40586 | X12: 37705 | Y12: 33324 | Z12: 28998 | AA12: =SUM(C12:Z12) -> 791204 | AB12: 20 | AC12: =+AA12*AB12+AA13*AB13+AA14*AB14 -> 24046148
B13: S | C13: 26795 | D13: 25172 | E13: 24309 | F13: 23816 | G13: 23846 | H13: 24751 | I13: 25541 | J13: 28353 | K13: 31410 | L13: 33626 | M13: 35385 | N13: 36852 | O13: 36823 | P13: 36300 | Q13: 35909 | R13: 35614 | S13: 35232 | T13: 35258 | U13: 38448 | V13: 40871 | W13: 39287 | X13: 37022 | Y13: 33651 | Z13: 30246 | AA13: =SUM(C13:Z13) -> 774517 | AB13: 4
B14: F | C14: 27614 | D14: 25828 | E14: 24778 | F14: 24065 | G14: 23770 | H14: 24120 | I14: 24033 | J14: 25819 | K14: 28251 | L14: 30212 | M14: 31580 | N14: 33134 | O14: 34059 | P14: 33801 | Q14: 33091 | R14: 32773 | S14: 32568 | T14: 32822 | U14: 36266 | V14: 39121 | W14: 38020 | X14: 35741 | Y14: 32034 | Z14: 28500 | AA14: =SUM(C14:Z14) -> 732000 | AB14: 7
A15: 46478 | B15: O | C15: 25378 | D15: 24032 | E15: 23223 | F15: 22847 | G15: 23323 | H15: 25062 | I15: 26343 | J15: 28664 | K15: 31088 | L15: 32987 | M15: 34991 | N15: 36807 | O15: 36159 | P15: 36325 | Q15: 37043 | R15: 37117 | S15: 36744 | T15: 36200 | U15: 39361 | V15: 41240 | W15: 39789 | X15: 36880 | Y15: 32477 | Z15: 28266 | AA15: =SUM(C15:Z15) -> 772346 | AB15: 22 | AC15: =+AA15*AB15+AA16*AB16+AA17*AB17 -> 22900488
B16: S | C16: 25918 | D16: 24383 | E16: 23396 | F16: 22813 | G16: 22920 | H16: 23578 | I16: 24407 | J16: 27342 | K16: 30352 | L16: 32636 | M16: 34287 | N16: 36160 | O16: 36275 | P16: 35838 | Q16: 35441 | R16: 35168 | S16: 35068 | T16: 35237 | U16: 38831 | V16: 40819 | W16: 39148 | X16: 36723 | Y16: 33309 | Z16: 29825 | AA16: =SUM(C16:Z16) -> 759874 | AB16: 4
B17: F | C17: 27010 | D17: 25287 | E17: 24172 | F17: 23415 | G17: 23121 | H17: 23082 | I17: 23261 | J17: 25277 | K17: 27635 | L17: 29704 | M17: 31177 | N17: 32678 | O17: 33551 | P17: 33310 | Q17: 32556 | R17: 32201 | S17: 31997 | T17: 32286 | U17: 36124 | V17: 38422 | W17: 37219 | X17: 34874 | Y17: 31283 | Z17: 27703 | AA17: =SUM(C17:Z17) -> 717345 | AB17: 4
A18: 46508 | B18: O | C18: 25415 | D18: 24024 | E18: 23249 | F18: 22862 | G18: 23320 | H18: 24812 | I18: 26371 | J18: 28808 | K18: 31298 | L18: 33254 | M18: 35221 | N18: 37088 | O18: 36524 | P18: 36517 | Q18: 37080 | R18: 37146 | S18: 36767 | T18: 36323 | U18: 39622 | V18: 41492 | W18: 39870 | X18: 36952 | Y18: 32480 | Z18: 28337 | AA18: =SUM(C18:Z18) -> 774832 | AB18: 19 | AC18: =+AA18*AB18+AA19*AB19+AA20*AB20 -> 23626140
B19: S | C19: 26356 | D19: 24832 | E19: 23911 | F19: 23369 | G19: 23463 | H19: 23847 | I19: 25097 | J19: 28047 | K19: 31126 | L19: 33505 | M19: 35136 | N19: 36624 | O19: 36628 | P19: 36045 | Q19: 35452 | R19: 35094 | S19: 34834 | T19: 35155 | U19: 39062 | V19: 40646 | W19: 39034 | X19: 36565 | Y19: 33130 | Z19: 29705 | AA19: =SUM(C19:Z19) -> 766663 | AB19: 4
B20: F | C20: 26817 | D20: 25150 | E20: 24116 | F20: 23427 | G20: 23216 | H20: 22954 | I20: 23425 | J20: 25670 | K20: 28167 | L20: 30384 | M20: 31899 | N20: 33483 | O20: 34177 | P20: 34038 | Q20: 33213 | R20: 34140 | S20: 32632 | T20: 32992 | U20: 36959 | V20: 39264 | W20: 38025 | X20: 35533 | Y20: 31840 | Z20: 28189 | AA20: =SUM(C20:Z20) -> 729710 | AB20: 8
A21: 46539 | B21: O | C21: 25115 | D21: 23695 | E21: 22985 | F21: 22604 | G21: 23025 | H21: 24305 | I21: 25994 | J21: 28566 | K21: 31164 | L21: 33101 | M21: 35125 | N21: 37015 | O21: 36406 | P21: 36365 | Q21: 37060 | R21: 37098 | S21: 36720 | T21: 36152 | U21: 38782 | V21: 41238 | W21: 39700 | X21: 36808 | Y21: 32270 | Z21: 28064 | AA21: =SUM(C21:Z21) -> 769357 | AB21: 21 | AC21: =+AA21*AB21+AA22*AB22+AA23*AB23 -> 22961808
B22: S | C22: 26329 | D22: 24690 | E22: 23751 | F22: 23220 | G22: 23267 | H22: 23644 | I22: 24879 | J22: 27797 | K22: 31090 | L22: 33351 | M22: 35116 | N22: 36646 | O22: 36746 | P22: 36370 | Q22: 35982 | R22: 35915 | S22: 35647 | T22: 35914 | U22: 39266 | V22: 41418 | W22: 39720 | X22: 37294 | Y22: 33703 | Z22: 30049 | AA22: =SUM(C22:Z22) -> 771804 | AB22: 4
B23: F | C23: 27401 | D23: 25655 | E23: 24641 | F23: 23949 | G23: 23786 | H23: 23758 | I23: 24075 | J23: 26414 | K23: 29014 | L23: 31022 | M23: 32673 | N23: 34270 | O23: 34840 | P23: 34598 | Q23: 33929 | R23: 33614 | S23: 33442 | T23: 33716 | U23: 37116 | V23: 39846 | W23: 38671 | X23: 36147 | Y23: 32356 | Z23: 28686 | AA23: =SUM(C23:Z23) -> 743619 | AB23: 5
A24: 46569 | B24: O | C24: 26296 | D24: 24800 | E24: 23937 | F24: 23467 | G24: 23867 | H24: 25142 | I24: 26514 | J24: 29384 | K24: 32174 | L24: 34361 | M24: 36478 | N24: 38355 | O24: 37691 | P24: 37772 | Q24: 38464 | R24: 38542 | S24: 37996 | T24: 37046 | U24: 39221 | V24: 42139 | W24: 40775 | X24: 38027 | Y24: 33493 | Z24: 29321 | AA24: =SUM(C24:Z24) -> 795262 | AB24: 20 | AC24: =+AA24*AB24+AA25*AB25+AA26*AB26 -> 24259657
B25: S | C25: 26355 | D25: 24637 | E25: 23762 | F25: 23177 | G25: 23233 | H25: 23722 | I25: 24901 | J25: 28377 | K25: 31685 | L25: 33950 | M25: 35731 | N25: 37236 | O25: 37167 | P25: 36585 | Q25: 36055 | R25: 35780 | S25: 35463 | T25: 35569 | U25: 38226 | V25: 41035 | W25: 39468 | X25: 37225 | Y25: 33714 | Z25: 30240 | AA25: =SUM(C25:Z25) -> 773293 | AB25: 5
B26: F | C26: 27968 | D26: 26250 | E26: 25117 | F26: 24376 | G26: 24145 | H26: 24153 | I26: 24311 | J26: 26521 | K26: 29172 | L26: 31372 | M26: 32972 | N26: 34456 | O26: 35192 | P26: 34805 | Q26: 34036 | R26: 33628 | S26: 33312 | T26: 33457 | U26: 36274 | V26: 39737 | W26: 38725 | X26: 36394 | Y26: 32606 | Z26: 29013 | AA26: =SUM(C26:Z26) -> 747992 | AB26: 6
A27: 46600 | B27: O | C27: 26605 | D27: 25187 | E27: 24405 | F27: 23941 | G27: 24361 | H27: 26050 | I27: 27554 | J27: 30110 | K27: 32784 | L27: 34831 | M27: 37001 | N27: 38901 | O27: 38232 | P27: 38535 | Q27: 39317 | R27: 39379 | S27: 38813 | T27: 37831 | U27: 40479 | V27: 42931 | W27: 41432 | X27: 38536 | Y27: 33945 | Z27: 29801 | AA27: =SUM(C27:Z27) -> 810961 | AB27: 21 | AC27: =+AA27*AB27+AA28*AB28+AA29*AB29 -> 24688809
B28: S | C28: 27693 | D28: 26155 | E28: 25193 | F28: 24473 | G28: 24419 | H28: 25097 | I28: 25901 | J28: 29180 | K28: 32495 | L28: 34767 | M28: 36758 | N28: 38265 | O28: 38276 | P28: 37865 | Q28: 37469 | R28: 37241 | S28: 36741 | T28: 36673 | U28: 39951 | V28: 42116 | W28: 40522 | X28: 38207 | Y28: 34837 | Z28: 31210 | AA28: =SUM(C28:Z28) -> 801504 | AB28: 3
B29: F | C29: 28210 | D29: 26460 | E29: 25307 | F29: 24573 | G29: 24334 | H29: 24415 | I29: 24411 | J29: 26711 | K29: 29308 | L29: 31449 | M29: 32965 | N29: 34536 | O29: 35347 | P29: 35030 | Q29: 34171 | R29: 33595 | S29: 33377 | T29: 33470 | U29: 36871 | V29: 39824 | W29: 38643 | X29: 36217 | Y29: 32521 | Z29: 28843 | AA29: =SUM(C29:Z29) -> 750588 | AB29: 7
A30: 46631 | B30: O | C30: 27081 | D30: 25589 | E30: 24657 | F30: 24250 | G30: 24644 | H30: 26258 | I30: 27814 | J30: 30452 | K30: 33102 | L30: 35305 | M30: 37492 | N30: 39497 | O30: 38808 | P30: 39090 | Q30: 40004 | R30: 40232 | S30: 39654 | T30: 38840 | U30: 42475 | V30: 43457 | W30: 41824 | X30: 38876 | Y30: 34190 | Z30: 30057 | AA30: =SUM(C30:Z30) -> 823648 | AB30: 22 | AC30: =+AA30*AB30+AA31*AB31+AA32*AB32 -> 24321860
B31: S | C31: 27804 | D31: 26029 | E31: 25068 | F31: 24542 | G31: 24564 | H31: 24791 | I31: 26033 | J31: 29566 | K31: 32934 | L31: 35338 | M31: 37240 | N31: 38763 | O31: 38668 | P31: 38174 | Q31: 37715 | R31: 37384 | S31: 37062 | T31: 37338 | U31: 41325 | V31: 42216 | W31: 40364 | X31: 37996 | Y31: 34537 | Z31: 31004 | AA31: =SUM(C31:Z31) -> 806455 | AB31: 4
B32: F | C32: 28309 | D32: 26610 | E32: 25494 | F32: 24630 | G32: 24239 | H32: 23943 | I32: 24125 | J32: 26383 | K32: 28929 | L32: 31017 | M32: 32472 | N32: 33862 | O32: 34666 | P32: 34420 | Q32: 33694 | R32: 33341 | S32: 33112 | T32: 33377 | U32: 37727 | V32: 39209 | W32: 38124 | X32: 35748 | Y32: 32037 | Z32: 28478 | AA32: =SUM(C32:Z32) -> 743946 | AB32: 4
A33: 46661 | B33: O | C33: 25662 | D33: 24287 | E33: 23523 | F33: 23113 | G33: 23566 | H33: 24867 | I33: 26524 | J33: 29008 | K33: 31502 | L33: 33469 | M33: 35507 | N33: 37396 | O33: 36740 | P33: 36942 | Q33: 37789 | R33: 37970 | S33: 37550 | T33: 37660 | U33: 41824 | V33: 41611 | W33: 39783 | X33: 36802 | Y33: 32423 | Z33: 28529 | AA33: =SUM(C33:Z33) -> 784047 | AB33: 20 | AC33: =+AA33*AB33+AA34*AB34+AA35*AB35 -> 24018034
B34: S | C34: 27016 | D34: 25476 | E34: 24541 | F34: 23920 | G34: 24045 | H34: 24418 | I34: 25798 | J34: 28975 | K34: 32140 | L34: 34339 | M34: 36210 | N34: 37779 | O34: 37841 | P34: 37413 | Q34: 36958 | R34: 36676 | S34: 36346 | T34: 37491 | U34: 42250 | V34: 42175 | W34: 40389 | X34: 37684 | Y34: 34350 | Z34: 30724 | AA34: =SUM(C34:Z34) -> 794954 | AB34: 5
B35: F | C35: 27107 | D35: 25466 | E35: 24334 | F35: 23543 | G35: 23291 | H35: 22963 | I35: 23402 | J35: 25551 | K35: 27988 | L35: 30128 | M35: 31646 | N35: 33139 | O35: 33976 | P35: 33697 | Q35: 33057 | R35: 32732 | S35: 32545 | T35: 33549 | U35: 38343 | V35: 38736 | W35: 37493 | X35: 35045 | Y35: 31410 | Z35: 27913 | AA35: =SUM(C35:Z35) -> 727054 | AB35: 6
A36: 46692 | B36: O | C36: 25189 | D36: 23816 | E36: 23055 | F36: 22698 | G36: 23226 | H36: 24710 | I36: 26473 | J36: 28996 | K36: 31444 | L36: 33338 | M36: 35366 | N36: 37309 | O36: 36547 | P36: 36568 | Q36: 37395 | R36: 37359 | S36: 37052 | T36: 37557 | U36: 41906 | V36: 41674 | W36: 39821 | X36: 36681 | Y36: 32172 | Z36: 28138 | AA36: =SUM(C36:Z36) -> 778490 | AB36: 20 | AC36: =+AA36*AB36+AA37*AB37+AA38*AB38 -> 22864092
B37: S | C37: 25865 | D37: 24406 | E37: 23515 | F37: 22946 | G37: 23046 | H37: 23334 | I37: 24605 | J37: 27531 | K37: 30626 | L37: 32783 | M37: 34508 | N37: 36094 | O37: 35947 | P37: 35277 | Q37: 35081 | R37: 34969 | S37: 34764 | T37: 36009 | U37: 40851 | V37: 40729 | W37: 38863 | X37: 36477 | Y37: 32947 | Z37: 29398 | AA37: =SUM(C37:Z37) -> 760571 | AB37: 4
B38: F | C38: 25970 | D38: 24407 | E38: 23348 | F38: 22572 | G38: 22468 | H38: 22191 | I38: 22719 | J38: 24957 | K38: 27399 | L38: 29496 | M38: 31022 | N38: 32572 | O38: 33339 | P38: 33035 | Q38: 32302 | R38: 31783 | S38: 31634 | T38: 32763 | U38: 37643 | V38: 38097 | W38: 36842 | X38: 34356 | Y38: 30637 | Z38: 27116 | AA38: =SUM(C38:Z38) -> 708668 | AB38: 6
A39: 46722 | B39: O | C39: 26986 | D39: 25353 | E39: 24410 | F39: 23925 | G39: 24259 | H39: 25322 | I39: 26507 | J39: 29626 | K39: 32539 | L39: 34692 | M39: 36656 | N39: 38648 | O39: 38268 | P39: 38237 | Q39: 38802 | R39: 38753 | S39: 38195 | T39: 37940 | U39: 42172 | V39: 42825 | W39: 41164 | X39: 38508 | Y39: 34433 | Z39: 30532 | AA39: =SUM(C39:Z39) -> 808752 | AB39: 22 | AC39: =+AA39*AB39+AA40*AB40+AA41*AB41 -> 24561468
B40: S | C40: 27244 | D40: 25598 | E40: 24658 | F40: 24036 | G40: 24069 | H40: 24669 | I40: 25394 | J40: 28311 | K40: 31285 | L40: 33359 | M40: 35025 | N40: 36415 | O40: 36413 | P40: 35893 | Q40: 35558 | R40: 35187 | S40: 34924 | T40: 35549 | U40: 40275 | V40: 40829 | W40: 39195 | X40: 36860 | Y40: 33526 | Z40: 30306 | AA40: =SUM(C40:Z40) -> 774578 | AB40: 3
B41: F | C41: 28146 | D41: 26431 | E41: 25233 | F41: 24383 | G41: 24050 | H41: 23929 | I41: 23890 | J41: 25824 | K41: 28228 | L41: 30340 | M41: 31922 | N41: 33407 | O41: 34207 | P41: 34165 | Q41: 33624 | R41: 33282 | S41: 33085 | T41: 33712 | U41: 38433 | V41: 39392 | W41: 38045 | X41: 35745 | Y41: 32381 | Z41: 29011 | AA41: =SUM(C41:Z41) -> 740865 | AB41: 6
A42: TOTAL AÑO | C42: =+SUM(C6:C41) -> 966016 | D42: =+SUM(D6:D41) -> 908611 | E42: =+SUM(E6:E41) -> 873997 | F42: =+SUM(F6:F41) -> 852604 | G42: =+SUM(G6:G41) -> 855256 | H42: =+SUM(H6:H41) -> 880102 | I42: =+SUM(I6:I41) -> 913384 | J42: =+SUM(J6:J41) -> 1004025 | ... AC42: =+SUM(AC6:AC41) -> 284847491

Sheet Cantidades Ofertadas Prod1
A1: CANTIDADES OFERTADAS PRODUCTO 1 AÑO 2027 MODALIDAD PAGUE LO CONTRATADO - kWh
A4: Periodo | B4: Tipo de día | C4: H01 | D4: H02 | E4: H03 | F4: H04 | G4: H05 | H4: H06 | I4: H07 | J4: H08 | K4: H09 | L4: H10 | M4: H11 | N4: H12 | O4: H13 | P4: H14 | Q4: H15 | R4: H16 | S4: H17 | T4: H18 | U4: H19 | V4: H20 | W4: H21 | X4: H22 | Y4: H23 | Z4: H24 | AA4: TOTAL DÍA | AB4: Días/ | AC4: TOTAL MES
AB5: mes
A6: 46388 | B6: O | C6: =ROUND('Anexo 5'!C6*Anexo1!$D$10,0) -> 0 | D6: =ROUND('Anexo 5'!D6*Anexo1!$D$10,0) -> 0 | E6: =ROUND('Anexo 5'!E6*Anexo1!$D$10,0) -> 0 | F6: =ROUND('Anexo 5'!F6*Anexo1!$D$10,0) -> 0 | G6: =ROUND('Anexo 5'!G6*Anexo1!$D$10,0) -> 0 | H6: =ROUND('Anexo 5'!H6*Anexo1!$D$10,0) -> 0 | I6: =ROUND('Anexo 5'!I6*Anexo1!$D$10,0) -> 0 | J6: =ROUND('Anexo 5'!J6*Anexo1!$D$10,0) -> 0 | ... Z6: =ROUND('Anexo 5'!Z6*Anexo1!$D$10,0) -> 0 | AA6: =SUM(C6:Z6) -> 0 | AB6: 19 | AC6: =+AA6*AB6+AA7*AB7+AA8*AB8 -> 0
B7: S | C7: =ROUND('Anexo 5'!C7*Anexo1!$D$10,0) -> 0 | D7: =ROUND('Anexo 5'!D7*Anexo1!$D$10,0) -> 0 | E7: =ROUND('Anexo 5'!E7*Anexo1!$D$10,0) -> 0 | F7: =ROUND('Anexo 5'!F7*Anexo1!$D$10,0) -> 0 | G7: =ROUND('Anexo 5'!G7*Anexo1!$D$10,0) -> 0 | H7: =ROUND('Anexo 5'!H7*Anexo1!$D$10,0) -> 0 | I7: =ROUND('Anexo 5'!I7*Anexo1!$D$10,0) -> 0 | J7: =ROUND('Anexo 5'!J7*Anexo1!$D$10,0) -> 0 | ... Z7: =ROUND('Anexo 5'!Z7*Anexo1!$D$10,0) -> 0 | AA7: =SUM(C7:Z7) -> 0 | AB7: 5
B8: F | C8: =ROUND('Anexo 5'!C8*Anexo1!$D$10,0) -> 0 | D8: =ROUND('Anexo 5'!D8*Anexo1!$D$10,0) -> 0 | E8: =ROUND('Anexo 5'!E8*Anexo1!$D$10,0) -> 0 | F8: =ROUND('Anexo 5'!F8*Anexo1!$D$10,0) -> 0 | G8: =ROUND('Anexo 5'!G8*Anexo1!$D$10,0) -> 0 | H8: =ROUND('Anexo 5'!H8*Anexo1!$D$10,0) -> 0 | I8: =ROUND('Anexo 5'!I8*Anexo1!$D$10,0) -> 0 | J8: =ROUND('Anexo 5'!J8*Anexo1!$D$10,0) -> 0 | ... Z8: =ROUND('Anexo 5'!Z8*Anexo1!$D$10,0) -> 0 | AA8: =SUM(C8:Z8) -> 0 | AB8: 7
A9: 46419 | B9: O | C9: =ROUND('Anexo 5'!C9*Anexo1!$D$10,0) -> 0 | D9: =ROUND('Anexo 5'!D9*Anexo1!$D$10,0) -> 0 | E9: =ROUND('Anexo 5'!E9*Anexo1!$D$10,0) -> 0 | F9: =ROUND('Anexo 5'!F9*Anexo1!$D$10,0) -> 0 | G9: =ROUND('Anexo 5'!G9*Anexo1!$D$10,0) -> 0 | H9: =ROUND('Anexo 5'!H9*Anexo1!$D$10,0) -> 0 | I9: =ROUND('Anexo 5'!I9*Anexo1!$D$10,0) -> 0 | J9: =ROUND('Anexo 5'!J9*Anexo1!$D$10,0) -> 0 | ... Z9: =ROUND('Anexo 5'!Z9*Anexo1!$D$10,0) -> 0 | AA9: =SUM(C9:Z9) -> 0 | AB9: 20 | AC9: =+AA9*AB9+AA10*AB10+AA11*AB11 -> 0
B10: S | C10: =ROUND('Anexo 5'!C10*Anexo1!$D$10,0) -> 0 | D10: =ROUND('Anexo 5'!D10*Anexo1!$D$10,0) -> 0 | E10: =ROUND('Anexo 5'!E10*Anexo1!$D$10,0) -> 0 | F10: =ROUND('Anexo 5'!F10*Anexo1!$D$10,0) -> 0 | G10: =ROUND('Anexo 5'!G10*Anexo1!$D$10,0) -> 0 | H10: =ROUND('Anexo 5'!H10*Anexo1!$D$10,0) -> 0 | I10: =ROUND('Anexo 5'!I10*Anexo1!$D$10,0) -> 0 | J10: =ROUND('Anexo 5'!J10*Anexo1!$D$10,0) -> 0 | ... Z10: =ROUND('Anexo 5'!Z10*Anexo1!$D$10,0) -> 0 | AA10: =SUM(C10:Z10) -> 0 | AB10: 4
B11: F | C11: =ROUND('Anexo 5'!C11*Anexo1!$D$10,0) -> 0 | D11: =ROUND('Anexo 5'!D11*Anexo1!$D$10,0) -> 0 | E11: =ROUND('Anexo 5'!E11*Anexo1!$D$10,0) -> 0 | F11: =ROUND('Anexo 5'!F11*Anexo1!$D$10,0) -> 0 | G11: =ROUND('Anexo 5'!G11*Anexo1!$D$10,0) -> 0 | H11: =ROUND('Anexo 5'!H11*Anexo1!$D$10,0) -> 0 | I11: =ROUND('Anexo 5'!I11*Anexo1!$D$10,0) -> 0 | J11: =ROUND('Anexo 5'!J11*Anexo1!$D$10,0) -> 0 | ... Z11: =ROUND('Anexo 5'!Z11*Anexo1!$D$10,0) -> 0 | AA11: =SUM(C11:Z11) -> 0 | AB11: 4
A12: 46447 | B12: O | C12: =ROUND('Anexo 5'!C12*Anexo1!$D$10,0) -> 0 | D12: =ROUND('Anexo 5'!D12*Anexo1!$D$10,0) -> 0 | E12: =ROUND('Anexo 5'!E12*Anexo1!$D$10,0) -> 0 | F12: =ROUND('Anexo 5'!F12*Anexo1!$D$10,0) -> 0 | G12: =ROUND('Anexo 5'!G12*Anexo1!$D$10,0) -> 0 | H12: =ROUND('Anexo 5'!H12*Anexo1!$D$10,0) -> 0 | I12: =ROUND('Anexo 5'!I12*Anexo1!$D$10,0) -> 0 | J12: =ROUND('Anexo 5'!J12*Anexo1!$D$10,0) -> 0 | ... Z12: =ROUND('Anexo 5'!Z12*Anexo1!$D$10,0) -> 0 | AA12: =SUM(C12:Z12) -> 0 | AB12: 20 | AC12: =+AA12*AB12+AA13*AB13+AA14*AB14 -> 0
B13: S | C13: =ROUND('Anexo 5'!C13*Anexo1!$D$10,0) -> 0 | D13: =ROUND('Anexo 5'!D13*Anexo1!$D$10,0) -> 0 | E13: =ROUND('Anexo 5'!E13*Anexo1!$D$10,0) -> 0 | F13: =ROUND('Anexo 5'!F13*Anexo1!$D$10,0) -> 0 | G13: =ROUND('Anexo 5'!G13*Anexo1!$D$10,0) -> 0 | H13: =ROUND('Anexo 5'!H13*Anexo1!$D$10,0) -> 0 | I13: =ROUND('Anexo 5'!I13*Anexo1!$D$10,0) -> 0 | J13: =ROUND('Anexo 5'!J13*Anexo1!$D$10,0) -> 0 | ... Z13: =ROUND('Anexo 5'!Z13*Anexo1!$D$10,0) -> 0 | AA13: =SUM(C13:Z13) -> 0 | AB13: 4
B14: F | C14: =ROUND('Anexo 5'!C14*Anexo1!$D$10,0) -> 0 | D14: =ROUND('Anexo 5'!D14*Anexo1!$D$10,0) -> 0 | E14: =ROUND('Anexo 5'!E14*Anexo1!$D$10,0) -> 0 | F14: =ROUND('Anexo 5'!F14*Anexo1!$D$10,0) -> 0 | G14: =ROUND('Anexo 5'!G14*Anexo1!$D$10,0) -> 0 | H14: =ROUND('Anexo 5'!H14*Anexo1!$D$10,0) -> 0 | I14: =ROUND('Anexo 5'!I14*Anexo1!$D$10,0) -> 0 | J14: =ROUND('Anexo 5'!J14*Anexo1!$D$10,0) -> 0 | ... Z14: =ROUND('Anexo 5'!Z14*Anexo1!$D$10,0) -> 0 | AA14: =SUM(C14:Z14) -> 0 | AB14: 7
A15: 46478 | B15: O | C15: =ROUND('Anexo 5'!C15*Anexo1!$D$10,0) -> 0 | D15: =ROUND('Anexo 5'!D15*Anexo1!$D$10,0) -> 0 | E15: =ROUND('Anexo 5'!E15*Anexo1!$D$10,0) -> 0 | F15: =ROUND('Anexo 5'!F15*Anexo1!$D$10,0) -> 0 | G15: =ROUND('Anexo 5'!G15*Anexo1!$D$10,0) -> 0 | H15: =ROUND('Anexo 5'!H15*Anexo1!$D$10,0) -> 0 | I15: =ROUND('Anexo 5'!I15*Anexo1!$D$10,0) -> 0 | J15: =ROUND('Anexo 5'!J15*Anexo1!$D$10,0) -> 0 | ... Z15: =ROUND('Anexo 5'!Z15*Anexo1!$D$10,0) -> 0 | AA15: =SUM(C15:Z15) -> 0 | AB15: 22 | AC15: =+AA15*AB15+AA16*AB16+AA17*AB17 -> 0
B16: S | C16: =ROUND('Anexo 5'!C16*Anexo1!$D$10,0) -> 0 | D16: =ROUND('Anexo 5'!D16*Anexo1!$D$10,0) -> 0 | E16: =ROUND('Anexo 5'!E16*Anexo1!$D$10,0) -> 0 | F16: =ROUND('Anexo 5'!F16*Anexo1!$D$10,0) -> 0 | G16: =ROUND('Anexo 5'!G16*Anexo1!$D$10,0) -> 0 | H16: =ROUND('Anexo 5'!H16*Anexo1!$D$10,0) -> 0 | I16: =ROUND('Anexo 5'!I16*Anexo1!$D$10,0) -> 0 | J16: =ROUND('Anexo 5'!J16*Anexo1!$D$10,0) -> 0 | ... Z16: =ROUND('Anexo 5'!Z16*Anexo1!$D$10,0) -> 0 | AA16: =SUM(C16:Z16) -> 0 | AB16: 4
B17: F | C17: =ROUND('Anexo 5'!C17*Anexo1!$D$10,0) -> 0 | D17: =ROUND('Anexo 5'!D17*Anexo1!$D$10,0) -> 0 | E17: =ROUND('Anexo 5'!E17*Anexo1!$D$10,0) -> 0 | F17: =ROUND('Anexo 5'!F17*Anexo1!$D$10,0) -> 0 | G17: =ROUND('Anexo 5'!G17*Anexo1!$D$10,0) -> 0 | H17: =ROUND('Anexo 5'!H17*Anexo1!$D$10,0) -> 0 | I17: =ROUND('Anexo 5'!I17*Anexo1!$D$10,0) -> 0 | J17: =ROUND('Anexo 5'!J17*Anexo1!$D$10,0) -> 0 | ... Z17: =ROUND('Anexo 5'!Z17*Anexo1!$D$10,0) -> 0 | AA17: =SUM(C17:Z17) -> 0 | AB17: 4
A18: 46508 | B18: O | C18: =ROUND('Anexo 5'!C18*Anexo1!$D$10,0) -> 0 | D18: =ROUND('Anexo 5'!D18*Anexo1!$D$10,0) -> 0 | E18: =ROUND('Anexo 5'!E18*Anexo1!$D$10,0) -> 0 | F18: =ROUND('Anexo 5'!F18*Anexo1!$D$10,0) -> 0 | G18: =ROUND('Anexo 5'!G18*Anexo1!$D$10,0) -> 0 | H18: =ROUND('Anexo 5'!H18*Anexo1!$D$10,0) -> 0 | I18: =ROUND('Anexo 5'!I18*Anexo1!$D$10,0) -> 0 | J18: =ROUND('Anexo 5'!J18*Anexo1!$D$10,0) -> 0 | ... Z18: =ROUND('Anexo 5'!Z18*Anexo1!$D$10,0) -> 0 | AA18: =SUM(C18:Z18) -> 0 | AB18: 19 | AC18: =+AA18*AB18+AA19*AB19+AA20*AB20 -> 0
B19: S | C19: =ROUND('Anexo 5'!C19*Anexo1!$D$10,0) -> 0 | D19: =ROUND('Anexo 5'!D19*Anexo1!$D$10,0) -> 0 | E19: =ROUND('Anexo 5'!E19*Anexo1!$D$10,0) -> 0 | F19: =ROUND('Anexo 5'!F19*Anexo1!$D$10,0) -> 0 | G19: =ROUND('Anexo 5'!G19*Anexo1!$D$10,0) -> 0 | H19: =ROUND('Anexo 5'!H19*Anexo1!$D$10,0) -> 0 | I19: =ROUND('Anexo 5'!I19*Anexo1!$D$10,0) -> 0 | J19: =ROUND('Anexo 5'!J19*Anexo1!$D$10,0) -> 0 | ... Z19: =ROUND('Anexo 5'!Z19*Anexo1!$D$10,0) -> 0 | AA19: =SUM(C19:Z19) -> 0 | AB19: 4
B20: F | C20: =ROUND('Anexo 5'!C20*Anexo1!$D$10,0) -> 0 | D20: =ROUND('Anexo 5'!D20*Anexo1!$D$10,0) -> 0 | E20: =ROUND('Anexo 5'!E20*Anexo1!$D$10,0) -> 0 | F20: =ROUND('Anexo 5'!F20*Anexo1!$D$10,0) -> 0 | G20: =ROUND('Anexo 5'!G20*Anexo1!$D$10,0) -> 0 | H20: =ROUND('Anexo 5'!H20*Anexo1!$D$10,0) -> 0 | I20: =ROUND('Anexo 5'!I20*Anexo1!$D$10,0) -> 0 | J20: =ROUND('Anexo 5'!J20*Anexo1!$D$10,0) -> 0 | ... Z20: =ROUND('Anexo 5'!Z20*Anexo1!$D$10,0) -> 0 | AA20: =SUM(C20:Z20) -> 0 | AB20: 8
A21: 46539 | B21: O | C21: =ROUND('Anexo 5'!C21*Anexo1!$D$10,0) -> 0 | D21: =ROUND('Anexo 5'!D21*Anexo1!$D$10,0) -> 0 | E21: =ROUND('Anexo 5'!E21*Anexo1!$D$10,0) -> 0 | F21: =ROUND('Anexo 5'!F21*Anexo1!$D$10,0) -> 0 | G21: =ROUND('Anexo 5'!G21*Anexo1!$D$10,0) -> 0 | H21: =ROUND('Anexo 5'!H21*Anexo1!$D$10,0) -> 0 | I21: =ROUND('Anexo 5'!I21*Anexo1!$D$10,0) -> 0 | J21: =ROUND('Anexo 5'!J21*Anexo1!$D$10,0) -> 0 | ... Z21: =ROUND('Anexo 5'!Z21*Anexo1!$D$10,0) -> 0 | AA21: =SUM(C21:Z21) -> 0 | AB21: 21 | AC21: =+AA21*AB21+AA22*AB22+AA23*AB23 -> 0
B22: S | C22: =ROUND('Anexo 5'!C22*Anexo1!$D$10,0) -> 0 | D22: =ROUND('Anexo 5'!D22*Anexo1!$D$10,0) -> 0 | E22: =ROUND('Anexo 5'!E22*Anexo1!$D$10,0) -> 0 | F22: =ROUND('Anexo 5'!F22*Anexo1!$D$10,0) -> 0 | G22: =ROUND('Anexo 5'!G22*Anexo1!$D$10,0) -> 0 | H22: =ROUND('Anexo 5'!H22*Anexo1!$D$10,0) -> 0 | I22: =ROUND('Anexo 5'!I22*Anexo1!$D$10,0) -> 0 | J22: =ROUND('Anexo 5'!J22*Anexo1!$D$10,0) -> 0 | ... Z22: =ROUND('Anexo 5'!Z22*Anexo1!$D$10,0) -> 0 | AA22: =SUM(C22:Z22) -> 0 | AB22: 4
B23: F | C23: =ROUND('Anexo 5'!C23*Anexo1!$D$10,0) -> 0 | D23: =ROUND('Anexo 5'!D23*Anexo1!$D$10,0) -> 0 | E23: =ROUND('Anexo 5'!E23*Anexo1!$D$10,0) -> 0 | F23: =ROUND('Anexo 5'!F23*Anexo1!$D$10,0) -> 0 | G23: =ROUND('Anexo 5'!G23*Anexo1!$D$10,0) -> 0 | H23: =ROUND('Anexo 5'!H23*Anexo1!$D$10,0) -> 0 | I23: =ROUND('Anexo 5'!I23*Anexo1!$D$10,0) -> 0 | J23: =ROUND('Anexo 5'!J23*Anexo1!$D$10,0) -> 0 | ... Z23: =ROUND('Anexo 5'!Z23*Anexo1!$D$10,0) -> 0 | AA23: =SUM(C23:Z23) -> 0 | AB23: 5
A24: 46569 | B24: O | C24: =ROUND('Anexo 5'!C24*Anexo1!$D$10,0) -> 0 | D24: =ROUND('Anexo 5'!D24*Anexo1!$D$10,0) -> 0 | E24: =ROUND('Anexo 5'!E24*Anexo1!$D$10,0) -> 0 | F24: =ROUND('Anexo 5'!F24*Anexo1!$D$10,0) -> 0 | G24: =ROUND('Anexo 5'!G24*Anexo1!$D$10,0) -> 0 | H24: =ROUND('Anexo 5'!H24*Anexo1!$D$10,0) -> 0 | I24: =ROUND('Anexo 5'!I24*Anexo1!$D$10,0) -> 0 | J24: =ROUND('Anexo 5'!J24*Anexo1!$D$10,0) -> 0 | ... Z24: =ROUND('Anexo 5'!Z24*Anexo1!$D$10,0) -> 0 | AA24: =SUM(C24:Z24) -> 0 | AB24: 20 | AC24: =+AA24*AB24+AA25*AB25+AA26*AB26 -> 0
B25: S | C25: =ROUND('Anexo 5'!C25*Anexo1!$D$10,0) -> 0 | D25: =ROUND('Anexo 5'!D25*Anexo1!$D$10,0) -> 0 | E25: =ROUND('Anexo 5'!E25*Anexo1!$D$10,0) -> 0 | F25: =ROUND('Anexo 5'!F25*Anexo1!$D$10,0) -> 0 | G25: =ROUND('Anexo 5'!G25*Anexo1!$D$10,0) -> 0 | H25: =ROUND('Anexo 5'!H25*Anexo1!$D$10,0) -> 0 | I25: =ROUND('Anexo 5'!I25*Anexo1!$D$10,0) -> 0 | J25: =ROUND('Anexo 5'!J25*Anexo1!$D$10,0) -> 0 | ... Z25: =ROUND('Anexo 5'!Z25*Anexo1!$D$10,0) -> 0 | AA25: =SUM(C25:Z25) -> 0 | AB25: 5
B26: F | C26: =ROUND('Anexo 5'!C26*Anexo1!$D$10,0) -> 0 | D26: =ROUND('Anexo 5'!D26*Anexo1!$D$10,0) -> 0 | E26: =ROUND('Anexo 5'!E26*Anexo1!$D$10,0) -> 0 | F26: =ROUND('Anexo 5'!F26*Anexo1!$D$10,0) -> 0 | G26: =ROUND('Anexo 5'!G26*Anexo1!$D$10,0) -> 0 | H26: =ROUND('Anexo 5'!H26*Anexo1!$D$10,0) -> 0 | I26: =ROUND('Anexo 5'!I26*Anexo1!$D$10,0) -> 0 | J26: =ROUND('Anexo 5'!J26*Anexo1!$D$10,0) -> 0 | ... Z26: =ROUND('Anexo 5'!Z26*Anexo1!$D$10,0) -> 0 | AA26: =SUM(C26:Z26) -> 0 | AB26: 6
A27: 46600 | B27: O | C27: =ROUND('Anexo 5'!C27*Anexo1!$D$10,0) -> 0 | D27: =ROUND('Anexo 5'!D27*Anexo1!$D$10,0) -> 0 | E27: =ROUND('Anexo 5'!E27*Anexo1!$D$10,0) -> 0 | F27: =ROUND('Anexo 5'!F27*Anexo1!$D$10,0) -> 0 | G27: =ROUND('Anexo 5'!G27*Anexo1!$D$10,0) -> 0 | H27: =ROUND('Anexo 5'!H27*Anexo1!$D$10,0) -> 0 | I27: =ROUND('Anexo 5'!I27*Anexo1!$D$10,0) -> 0 | J27: =ROUND('Anexo 5'!J27*Anexo1!$D$10,0) -> 0 | ... Z27: =ROUND('Anexo 5'!Z27*Anexo1!$D$10,0) -> 0 | AA27: =SUM(C27:Z27) -> 0 | AB27: 21 | AC27: =+AA27*AB27+AA28*AB28+AA29*AB29 -> 0
B28: S | C28: =ROUND('Anexo 5'!C28*Anexo1!$D$10,0) -> 0 | D28: =ROUND('Anexo 5'!D28*Anexo1!$D$10,0) -> 0 | E28: =ROUND('Anexo 5'!E28*Anexo1!$D$10,0) -> 0 | F28: =ROUND('Anexo 5'!F28*Anexo1!$D$10,0) -> 0 | G28: =ROUND('Anexo 5'!G28*Anexo1!$D$10,0) -> 0 | H28: =ROUND('Anexo 5'!H28*Anexo1!$D$10,0) -> 0 | I28: =ROUND('Anexo 5'!I28*Anexo1!$D$10,0) -> 0 | J28: =ROUND('Anexo 5'!J28*Anexo1!$D$10,0) -> 0 | ... Z28: =ROUND('Anexo 5'!Z28*Anexo1!$D$10,0) -> 0 | AA28: =SUM(C28:Z28) -> 0 | AB28: 3
B29: F | C29: =ROUND('Anexo 5'!C29*Anexo1!$D$10,0) -> 0 | D29: =ROUND('Anexo 5'!D29*Anexo1!$D$10,0) -> 0 | E29: =ROUND('Anexo 5'!E29*Anexo1!$D$10,0) -> 0 | F29: =ROUND('Anexo 5'!F29*Anexo1!$D$10,0) -> 0 | G29: =ROUND('Anexo 5'!G29*Anexo1!$D$10,0) -> 0 | H29: =ROUND('Anexo 5'!H29*Anexo1!$D$10,0) -> 0 | I29: =ROUND('Anexo 5'!I29*Anexo1!$D$10,0) -> 0 | J29: =ROUND('Anexo 5'!J29*Anexo1!$D$10,0) -> 0 | ... Z29: =ROUND('Anexo 5'!Z29*Anexo1!$D$10,0) -> 0 | AA29: =SUM(C29:Z29) -> 0 | AB29: 7
A30: 46631 | B30: O | C30: =ROUND('Anexo 5'!C30*Anexo1!$D$10,0) -> 0 | D30: =ROUND('Anexo 5'!D30*Anexo1!$D$10,0) -> 0 | E30: =ROUND('Anexo 5'!E30*Anexo1!$D$10,0) -> 0 | F30: =ROUND('Anexo 5'!F30*Anexo1!$D$10,0) -> 0 | G30: =ROUND('Anexo 5'!G30*Anexo1!$D$10,0) -> 0 | H30: =ROUND('Anexo 5'!H30*Anexo1!$D$10,0) -> 0 | I30: =ROUND('Anexo 5'!I30*Anexo1!$D$10,0) -> 0 | J30: =ROUND('Anexo 5'!J30*Anexo1!$D$10,0) -> 0 | ... Z30: =ROUND('Anexo 5'!Z30*Anexo1!$D$10,0) -> 0 | AA30: =SUM(C30:Z30) -> 0 | AB30: 22 | AC30: =+AA30*AB30+AA31*AB31+AA32*AB32 -> 0
B31: S | C31: =ROUND('Anexo 5'!C31*Anexo1!$D$10,0) -> 0 | D31: =ROUND('Anexo 5'!D31*Anexo1!$D$10,0) -> 0 | E31: =ROUND('Anexo 5'!E31*Anexo1!$D$10,0) -> 0 | F31: =ROUND('Anexo 5'!F31*Anexo1!$D$10,0) -> 0 | G31: =ROUND('Anexo 5'!G31*Anexo1!$D$10,0) -> 0 | H31: =ROUND('Anexo 5'!H31*Anexo1!$D$10,0) -> 0 | I31: =ROUND('Anexo 5'!I31*Anexo1!$D$10,0) -> 0 | J31: =ROUND('Anexo 5'!J31*Anexo1!$D$10,0) -> 0 | ... Z31: =ROUND('Anexo 5'!Z31*Anexo1!$D$10,0) -> 0 | AA31: =SUM(C31:Z31) -> 0 | AB31: 4
B32: F | C32: =ROUND('Anexo 5'!C32*Anexo1!$D$10,0) -> 0 | D32: =ROUND('Anexo 5'!D32*Anexo1!$D$10,0) -> 0 | E32: =ROUND('Anexo 5'!E32*Anexo1!$D$10,0) -> 0 | F32: =ROUND('Anexo 5'!F32*Anexo1!$D$10,0) -> 0 | G32: =ROUND('Anexo 5'!G32*Anexo1!$D$10,0) -> 0 | H32: =ROUND('Anexo 5'!H32*Anexo1!$D$10,0) -> 0 | I32: =ROUND('Anexo 5'!I32*Anexo1!$D$10,0) -> 0 | J32: =ROUND('Anexo 5'!J32*Anexo1!$D$10,0) -> 0 | ... Z32: =ROUND('Anexo 5'!Z32*Anexo1!$D$10,0) -> 0 | AA32: =SUM(C32:Z32) -> 0 | AB32: 4
A33: 46661 | B33: O | C33: =ROUND('Anexo 5'!C33*Anexo1!$D$10,0) -> 0 | D33: =ROUND('Anexo 5'!D33*Anexo1!$D$10,0) -> 0 | E33: =ROUND('Anexo 5'!E33*Anexo1!$D$10,0) -> 0 | F33: =ROUND('Anexo 5'!F33*Anexo1!$D$10,0) -> 0 | G33: =ROUND('Anexo 5'!G33*Anexo1!$D$10,0) -> 0 | H33: =ROUND('Anexo 5'!H33*Anexo1!$D$10,0) -> 0 | I33: =ROUND('Anexo 5'!I33*Anexo1!$D$10,0) -> 0 | J33: =ROUND('Anexo 5'!J33*Anexo1!$D$10,0) -> 0 | ... Z33: =ROUND('Anexo 5'!Z33*Anexo1!$D$10,0) -> 0 | AA33: =SUM(C33:Z33) -> 0 | AB33: 20 | AC33: =+AA33*AB33+AA34*AB34+AA35*AB35 -> 0
B34: S | C34: =ROUND('Anexo 5'!C34*Anexo1!$D$10,0) -> 0 | D34: =ROUND('Anexo 5'!D34*Anexo1!$D$10,0) -> 0 | E34: =ROUND('Anexo 5'!E34*Anexo1!$D$10,0) -> 0 | F34: =ROUND('Anexo 5'!F34*Anexo1!$D$10,0) -> 0 | G34: =ROUND('Anexo 5'!G34*Anexo1!$D$10,0) -> 0 | H34: =ROUND('Anexo 5'!H34*Anexo1!$D$10,0) -> 0 | I34: =ROUND('Anexo 5'!I34*Anexo1!$D$10,0) -> 0 | J34: =ROUND('Anexo 5'!J34*Anexo1!$D$10,0) -> 0 | ... Z34: =ROUND('Anexo 5'!Z34*Anexo1!$D$10,0) -> 0 | AA34: =SUM(C34:Z34) -> 0 | AB34: 5
B35: F | C35: =ROUND('Anexo 5'!C35*Anexo1!$D$10,0) -> 0 | D35: =ROUND('Anexo 5'!D35*Anexo1!$D$10,0) -> 0 | E35: =ROUND('Anexo 5'!E35*Anexo1!$D$10,0) -> 0 | F35: =ROUND('Anexo 5'!F35*Anexo1!$D$10,0) -> 0 | G35: =ROUND('Anexo 5'!G35*Anexo1!$D$10,0) -> 0 | H35: =ROUND('Anexo 5'!H35*Anexo1!$D$10,0) -> 0 | I35: =ROUND('Anexo 5'!I35*Anexo1!$D$10,0) -> 0 | J35: =ROUND('Anexo 5'!J35*Anexo1!$D$10,0) -> 0 | ... Z35: =ROUND('Anexo 5'!Z35*Anexo1!$D$10,0) -> 0 | AA35: =SUM(C35:Z35) -> 0 | AB35: 6
A36: 46692 | B36: O | C36: =ROUND('Anexo 5'!C36*Anexo1!$D$10,0) -> 0 | D36: =ROUND('Anexo 5'!D36*Anexo1!$D$10,0) -> 0 | E36: =ROUND('Anexo 5'!E36*Anexo1!$D$10,0) -> 0 | F36: =ROUND('Anexo 5'!F36*Anexo1!$D$10,0) -> 0 | G36: =ROUND('Anexo 5'!G36*Anexo1!$D$10,0) -> 0 | H36: =ROUND('Anexo 5'!H36*Anexo1!$D$10,0) -> 0 | I36: =ROUND('Anexo 5'!I36*Anexo1!$D$10,0) -> 0 | J36: =ROUND('Anexo 5'!J36*Anexo1!$D$10,0) -> 0 | ... Z36: =ROUND('Anexo 5'!Z36*Anexo1!$D$10,0) -> 0 | AA36: =SUM(C36:Z36) -> 0 | AB36: 20 | AC36: =+AA36*AB36+AA37*AB37+AA38*AB38 -> 0
B37: S | C37: =ROUND('Anexo 5'!C37*Anexo1!$D$10,0) -> 0 | D37: =ROUND('Anexo 5'!D37*Anexo1!$D$10,0) -> 0 | E37: =ROUND('Anexo 5'!E37*Anexo1!$D$10,0) -> 0 | F37: =ROUND('Anexo 5'!F37*Anexo1!$D$10,0) -> 0 | G37: =ROUND('Anexo 5'!G37*Anexo1!$D$10,0) -> 0 | H37: =ROUND('Anexo 5'!H37*Anexo1!$D$10,0) -> 0 | I37: =ROUND('Anexo 5'!I37*Anexo1!$D$10,0) -> 0 | J37: =ROUND('Anexo 5'!J37*Anexo1!$D$10,0) -> 0 | ... Z37: =ROUND('Anexo 5'!Z37*Anexo1!$D$10,0) -> 0 | AA37: =SUM(C37:Z37) -> 0 | AB37: 4
B38: F | C38: =ROUND('Anexo 5'!C38*Anexo1!$D$10,0) -> 0 | D38: =ROUND('Anexo 5'!D38*Anexo1!$D$10,0) -> 0 | E38: =ROUND('Anexo 5'!E38*Anexo1!$D$10,0) -> 0 | F38: =ROUND('Anexo 5'!F38*Anexo1!$D$10,0) -> 0 | G38: =ROUND('Anexo 5'!G38*Anexo1!$D$10,0) -> 0 | H38: =ROUND('Anexo 5'!H38*Anexo1!$D$10,0) -> 0 | I38: =ROUND('Anexo 5'!I38*Anexo1!$D$10,0) -> 0 | J38: =ROUND('Anexo 5'!J38*Anexo1!$D$10,0) -> 0 | ... Z38: =ROUND('Anexo 5'!Z38*Anexo1!$D$10,0) -> 0 | AA38: =SUM(C38:Z38) -> 0 | AB38: 6
A39: 46722 | B39: O | C39: =ROUND('Anexo 5'!C39*Anexo1!$D$10,0) -> 0 | D39: =ROUND('Anexo 5'!D39*Anexo1!$D$10,0) -> 0 | E39: =ROUND('Anexo 5'!E39*Anexo1!$D$10,0) -> 0 | F39: =ROUND('Anexo 5'!F39*Anexo1!$D$10,0) -> 0 | G39: =ROUND('Anexo 5'!G39*Anexo1!$D$10,0) -> 0 | H39: =ROUND('Anexo 5'!H39*Anexo1!$D$10,0) -> 0 | I39: =ROUND('Anexo 5'!I39*Anexo1!$D$10,0) -> 0 | J39: =ROUND('Anexo 5'!J39*Anexo1!$D$10,0) -> 0 | ... Z39: =ROUND('Anexo 5'!Z39*Anexo1!$D$10,0) -> 0 | AA39: =SUM(C39:Z39) -> 0 | AB39: 22 | AC39: =+AA39*AB39+AA40*AB40+AA41*AB41 -> 0
B40: S | C40: =ROUND('Anexo 5'!C40*Anexo1!$D$10,0) -> 0 | D40: =ROUND('Anexo 5'!D40*Anexo1!$D$10,0) -> 0 | E40: =ROUND('Anexo 5'!E40*Anexo1!$D$10,0) -> 0 | F40: =ROUND('Anexo 5'!F40*Anexo1!$D$10,0) -> 0 | G40: =ROUND('Anexo 5'!G40*Anexo1!$D$10,0) -> 0 | H40: =ROUND('Anexo 5'!H40*Anexo1!$D$10,0) -> 0 | I40: =ROUND('Anexo 5'!I40*Anexo1!$D$10,0) -> 0 | J40: =ROUND('Anexo 5'!J40*Anexo1!$D$10,0) -> 0 | ... Z40: =ROUND('Anexo 5'!Z40*Anexo1!$D$10,0) -> 0 | AA40: =SUM(C40:Z40) -> 0 | AB40: 3
B41: F | C41: =ROUND('Anexo 5'!C41*Anexo1!$D$10,0) -> 0 | D41: =ROUND('Anexo 5'!D41*Anexo1!$D$10,0) -> 0 | E41: =ROUND('Anexo 5'!E41*Anexo1!$D$10,0) -> 0 | F41: =ROUND('Anexo 5'!F41*Anexo1!$D$10,0) -> 0 | G41: =ROUND('Anexo 5'!G41*Anexo1!$D$10,0) -> 0 | H41: =ROUND('Anexo 5'!H41*Anexo1!$D$10,0) -> 0 | I41: =ROUND('Anexo 5'!I41*Anexo1!$D$10,0) -> 0 | J41: =ROUND('Anexo 5'!J41*Anexo1!$D$10,0) -> 0 | ... Z41: =ROUND('Anexo 5'!Z41*Anexo1!$D$10,0) -> 0 | AA41: =SUM(C41:Z41) -> 0 | AB41: 6
A42: TOTAL AÑO | C42: =+SUM(C6:C41) -> 0 | D42: =+SUM(D6:D41) -> 0 | E42: =+SUM(E6:E41) -> 0 | F42: =+SUM(F6:F41) -> 0 | G42: =+SUM(G6:G41) -> 0 | H42: =+SUM(H6:H41) -> 0 | I42: =+SUM(I6:I41) -> 0 | J42: =+SUM(J6:J41) -> 0 | ... AC42: =+SUM(AC6:AC41) -> 0

Sheet Anexo 2
B3: ANEXO No 2 - PRODUCTO No. 2 - CURVA
B4: PAGUE LO CONTRATADO AÑO 2028
B5: PRECIO OFERTADO EN $ / kWh DE FEBRERO DE 2026
B8: MES | C8: ENERGIA SOLICITADA kWh/MES | D8: % OFERTADO ANUAL | E8: ENERGIA OFERTADA kWh/MES | F8: PRECIO OFERTADO ANUAL $/kWh
B10: 46753 | C10: =+'Anexo 6'!AC6 -> 13414677 | E10: =+'Cantidades Ofertadas Prod 2'!AC6 -> 0
B11: 46784 | C11: =+'Anexo 6'!AC9 -> 12831352 | E11: =+'Cantidades Ofertadas Prod 2'!AC9 -> 0
B12: 46813 | C12: =+'Anexo 6'!AC12 -> 13373254 | E12: =+'Cantidades Ofertadas Prod 2'!AC12 -> 0
B13: 46844 | C13: =+'Anexo 6'!AC15 -> 12575484 | E13: =+'Cantidades Ofertadas Prod 2'!AC15 -> 0
B14: 46874 | C14: =+'Anexo 6'!AC18 -> 13125208 | E14: =+'Cantidades Ofertadas Prod 2'!AC18 -> 0
B15: 46905 | C15: =+'Anexo 6'!AC21 -> 12693374 | E15: =+'Cantidades Ofertadas Prod 2'!AC21 -> 0
B16: 46935 | C16: =+'Anexo 6'!AC24 -> 13399715 | E16: =+'Cantidades Ofertadas Prod 2'!AC24 -> 0
B17: 46966 | C17: =+'Anexo 6'!AC27 -> 13691680 | E17: =+'Cantidades Ofertadas Prod 2'!AC27 -> 0
B18: 46997 | C18: =+'Anexo 6'!AC30 -> 13450812 | E18: =+'Cantidades Ofertadas Prod 2'!AC30 -> 0
B19: 47027 | C19: =+'Anexo 6'!AC33 -> 13286149 | E19: =+'Cantidades Ofertadas Prod 2'!AC33 -> 0
B20: 47058 | C20: =+'Anexo 6'!AC36 -> 12653604 | E20: =+'Cantidades Ofertadas Prod 2'!AC36 -> 0
B21: 47088 | C21: =+'Anexo 6'!AC39 -> 13517547 | E21: =+'Cantidades Ofertadas Prod 2'!AC39 -> 0
B22: TOTAL | C22: =+SUM(C10:C21) -> 158012856 | E22: =SUM(E10:E21) -> 0 | F22: =+F10 -> 0
B23: *Solo se debe ingresar valores en las celdas en color Naranja
B24: * Se debe ofertar un unico % para todos los meses del año.
B25: * Los % ofertados se aplicaran a las curvas de carga de la hoja "Anexo 6".
B26: * La energia ofertada se calcula de manera automatica en la hoja "Cantidades Ofertadas Prod2"
B27: * Se debe ofertar un unico precio por producto.
B28: * Para ofertas planas se debe diligenciar el anexo 2A, con un tope horario de 10.000 kWh
B32: ____________________________________________
B33: Firma del Representante Legal
B34: o Apoderado General (Responsable del negocio)

Sheet Anexo 2A
B3: ANEXO No 2A - PRODUCTO No. 2 - OFERTA PLANA
B4: PAGUE LO CONTRATADO AÑO 2028
B5: PRECIO OFERTADO EN $ / kWh DE FEBRERO DE 2026
B8: MES | C8: ENERGIA MAXIMA A OFERTAR kWh/MES | D8: kWh OFERTADO | E8: ENERGIA OFERTADA kWh/MES | F8: PRECIO OFERTADO ANUAL $/kWh
A9: 10000
A10: 31 | B10: 46753 | C10: =+$A$9*A10*24 -> 7440000 | E10: =+$D$10*A10*24 -> 0
A11: 29 | B11: 46784 | C11: =+$A$9*A11*24 -> 6960000 | E11: =+$D$10*A11*24 -> 0
A12: 31 | B12: 46813 | C12: =+$A$9*A12*24 -> 7440000 | E12: =+$D$10*A12*24 -> 0
A13: 30 | B13: 46844 | C13: =+$A$9*A13*24 -> 7200000 | E13: =+$D$10*A13*24 -> 0
A14: 31 | B14: 46874 | C14: =+$A$9*A14*24 -> 7440000 | E14: =+$D$10*A14*24 -> 0
A15: 30 | B15: 46905 | C15: =+$A$9*A15*24 -> 7200000 | E15: =+$D$10*A15*24 -> 0
A16: 31 | B16: 46935 | C16: =+$A$9*A16*24 -> 7440000 | E16: =+$D$10*A16*24 -> 0
A17: 31 | B17: 46966 | C17: =+$A$9*A17*24 -> 7440000 | E17: =+$D$10*A17*24 -> 0
A18: 30 | B18: 46997 | C18: =+$A$9*A18*24 -> 7200000 | E18: =+$D$10*A18*24 -> 0
A19: 31 | B19: 47027 | C19: =+$A$9*A19*24 -> 7440000 | E19: =+$D$10*A19*24 -> 0
A20: 30 | B20: 47058 | C20: =+$A$9*A20*24 -> 7200000 | E20: =+$D$10*A20*24 -> 0
A21: 31 | B21: 47088 | C21: =+$A$9*A21*24 -> 7440000 | E21: =+$D$10*A21*24 -> 0
B22: TOTAL | C22: =+SUM(C10:C21) -> 87840000 | E22: =SUM(E10:E21) -> 0 | F22: =+F10 -> 0
B23: *Solo se debe ingresar valores en las celdas en color Naranja
B24: * Se debe oferta un valor de kWh el cual se aplica para todas las horas del año, con un tope horario de 10.000 kWh
B25: * Se debe ofertar un unico precio por producto.
B26: * A las ofertas planas al momento de la evaluación se le adicionarán 5 $/kWh al precio ofertado; con el fin de hacerlas comparables con las Ofertas que siguen la curva
B29: ____________________________________________
B30: Firma del Representante Legal
B31: o Apoderado General (Responsable del negocio)

Sheet Anexo 6
A1: CURVAS REQUERIDAS PRODUCTO 2 AÑO 2028 MODALIDAD PAGUE LO CONTRATADO - kWh
A4: Periodo | B4: Tipo de día | C4: H01 | D4: H02 | E4: H03 | F4: H04 | G4: H05 | H4: H06 | I4: H07 | J4: H08 | K4: H09 | L4: H10 | M4: H11 | N4: H12 | O4: H13 | P4: H14 | Q4: H15 | R4: H16 | S4: H17 | T4: H18 | U4: H19 | V4: H20 | W4: H21 | X4: H22 | Y4: H23 | Z4: H24 | AA4: TOTAL DÍA | AB4: Días/ | AC4: TOTAL MES
AB5: mes
A6: 46753 | B6: O | C6: 14603 | D6: 13759 | E6: 13251 | F6: 12988 | G6: 13170 | H6: 13954 | I6: 14700 | J6: 16096 | K6: 17667 | L6: 18857 | M6: 20068 | N6: 21211 | O6: 21017 | P6: 21042 | Q6: 21393 | R6: 21460 | S6: 21214 | T6: 20755 | U6: 22280 | V6: 23550 | W6: 22696 | X6: 21198 | Y6: 18791 | Z6: 16360 | AA6: =SUM(C6:Z6) -> 442080 | AB6: 20 | AC6: =+AA6*AB6+AA7*AB7+AA8*AB8 -> 13414677
B7: S | C7: 14955 | D7: 14002 | E7: 13420 | F7: 13053 | G7: 13065 | H7: 13504 | I7: 14016 | J7: 15435 | K7: 17191 | L7: 18516 | M7: 19508 | N7: 20490 | O7: 20596 | P7: 20394 | Q7: 20172 | R7: 20064 | S7: 19913 | T7: 19894 | U7: 21806 | V7: 23168 | W7: 22237 | X7: 20848 | Y7: 18878 | Z7: 16904 | AA7: =SUM(C7:Z7) -> 432029 | AB7: 4
B8: F | C8: 15677 | D8: 14648 | E8: 13965 | F8: 13483 | G8: 13247 | H8: 13340 | I8: 13209 | J8: 13989 | K8: 15325 | L8: 16502 | M8: 17370 | N8: 18275 | O8: 18810 | P8: 18747 | Q8: 18406 | R8: 18210 | S8: 18111 | T8: 18210 | U8: 20295 | V8: 21785 | W8: 21177 | X8: 19879 | Y8: 17877 | Z8: 15886 | AA8: =SUM(C8:Z8) -> 406423 | AB8: 7
A9: 46784 | B9: O | C9: 14688 | D9: 13876 | E9: 13409 | F9: 13179 | G9: 13445 | H9: 14663 | I9: 15632 | J9: 16686 | K9: 18083 | L9: 19130 | M9: 20274 | N9: 21334 | O9: 20908 | P9: 21070 | Q9: 21563 | R9: 21651 | S9: 21410 | T9: 20851 | U9: 22015 | V9: 23682 | W9: 22861 | X9: 21292 | Y9: 18818 | Z9: 16356 | AA9: =SUM(C9:Z9) -> 446876 | AB9: 21 | AC9: =+AA9*AB9+AA10*AB10+AA11*AB11 -> 12831352
B10: S | C10: 15232 | D10: 14331 | E10: 13752 | F10: 13420 | G10: 13459 | H10: 13931 | I10: 14686 | J10: 16105 | K10: 17928 | L10: 19198 | M10: 20208 | N10: 21188 | O10: 21215 | P10: 20943 | Q10: 20710 | R10: 20583 | S10: 20408 | T10: 20344 | U10: 21891 | V10: 23567 | W10: 22644 | X10: 21333 | Y10: 19458 | Z10: 17375 | AA10: =SUM(C10:Z10) -> 443909 | AB10: 4
B11: F | C11: 15820 | D11: 14798 | E11: 14175 | F11: 13707 | G11: 13558 | H11: 13698 | I11: 13810 | J11: 14725 | K11: 16190 | L11: 17389 | M11: 18184 | N11: 19043 | O11: 19524 | P11: 19367 | Q11: 18984 | R11: 18751 | S11: 18634 | T11: 18733 | U11: 20396 | V11: 22248 | W11: 21682 | X11: 20337 | Y11: 18128 | Z11: 15949 | AA11: =SUM(C11:Z11) -> 417830 | AB11: 4
A12: 46813 | B12: O | C12: 14376 | D12: 13598 | E12: 13168 | F12: 12952 | G12: 13238 | H12: 14432 | I12: 15269 | J12: 16434 | K12: 17776 | L12: 18781 | M12: 19852 | N12: 20818 | O12: 20433 | P12: 20519 | Q12: 20942 | R12: 21011 | S12: 20827 | T12: 20433 | U12: 21886 | V12: 23308 | W12: 22461 | X12: 20867 | Y12: 18442 | Z12: 16048 | AA12: =SUM(C12:Z12) -> 437871 | AB12: 22 | AC12: =+AA12*AB12+AA13*AB13+AA14*AB14 -> 13373254
B13: S | C13: 14829 | D13: 13931 | E13: 13453 | F13: 13181 | G13: 13197 | H13: 13698 | I13: 14135 | J13: 15691 | K13: 17383 | L13: 18609 | M13: 19583 | N13: 20395 | O13: 20379 | P13: 20089 | Q13: 19873 | R13: 19710 | S13: 19498 | T13: 19513 | U13: 21278 | V13: 22619 | W13: 21743 | X13: 20489 | Y13: 18623 | Z13: 16739 | AA13: =SUM(C13:Z13) -> 428638 | AB13: 4
B14: F | C14: 15282 | D14: 14294 | E14: 13713 | F14: 13318 | G14: 13155 | H14: 13349 | I14: 13300 | J14: 14289 | K14: 15635 | L14: 16720 | M14: 17477 | N14: 18337 | O14: 18849 | P14: 18706 | Q14: 18313 | R14: 18138 | S14: 18024 | T14: 18165 | U14: 20071 | V14: 21651 | W14: 21041 | X14: 19780 | Y14: 17728 | Z14: 15773 | AA14: =SUM(C14:Z14) -> 405108 | AB14: 5
A15: 46844 | B15: O | C15: 14045 | D15: 13300 | E15: 12852 | F15: 12644 | G15: 12907 | H15: 13870 | I15: 14579 | J15: 15863 | K15: 17205 | L15: 18256 | M15: 19365 | N15: 20370 | O15: 20011 | P15: 20103 | Q15: 20501 | R15: 20542 | S15: 20335 | T15: 20034 | U15: 21783 | V15: 22823 | W15: 22020 | X15: 20410 | Y15: 17974 | Z15: 15643 | AA15: =SUM(C15:Z15) -> 427435 | AB15: 18 | AC15: =+AA15*AB15+AA16*AB16+AA17*AB17 -> 12575484
B16: S | C16: 14344 | D16: 13494 | E16: 12948 | F16: 12625 | G16: 12685 | H16: 13049 | I16: 13507 | J16: 15132 | K16: 16798 | L16: 18062 | M16: 18975 | N16: 20012 | O16: 20075 | P16: 19834 | Q16: 19614 | R16: 19463 | S16: 19408 | T16: 19501 | U16: 21490 | V16: 22590 | W16: 21665 | X16: 20324 | Y16: 18434 | Z16: 16506 | AA16: =SUM(C16:Z16) -> 420535 | AB16: 5
B17: F | C17: 14948 | D17: 13994 | E17: 13378 | F17: 12958 | G17: 12796 | H17: 12774 | I17: 12873 | J17: 13989 | K17: 15294 | L17: 16439 | M17: 17254 | N17: 18085 | O17: 18568 | P17: 18434 | Q17: 18017 | R17: 17821 | S17: 17708 | T17: 17868 | U17: 19992 | V17: 21264 | W17: 20598 | X17: 19300 | Y17: 17313 | Z17: 15332 | AA17: =SUM(C17:Z17) -> 396997 | AB17: 7
A18: 46874 | B18: O | C18: 14065 | D18: 13295 | E18: 12867 | F18: 12652 | G18: 12906 | H18: 13731 | I18: 14594 | J18: 15943 | K18: 17321 | L18: 18404 | M18: 19492 | N18: 20526 | O18: 20213 | P18: 20209 | Q18: 20521 | R18: 20558 | S18: 20348 | T18: 20102 | U18: 21928 | V18: 22963 | W18: 22065 | X18: 20450 | Y18: 17975 | Z18: 15682 | AA18: =SUM(C18:Z18) -> 428810 | AB18: 21 | AC18: =+AA18*AB18+AA19*AB19+AA20*AB20 -> 13125208
B19: S | C19: 14586 | D19: 13743 | E19: 13233 | F19: 12933 | G19: 12985 | H19: 13197 | I19: 13889 | J19: 15522 | K19: 17226 | L19: 18543 | M19: 19445 | N19: 20268 | O19: 20271 | P19: 19948 | Q19: 19620 | R19: 19422 | S19: 19278 | T19: 19456 | U19: 21618 | V19: 22494 | W19: 21603 | X19: 20236 | Y19: 18335 | Z19: 16440 | AA19: =SUM(C19:Z19) -> 424291 | AB19: 4
B20: F | C20: 14841 | D20: 13919 | E20: 13346 | F20: 12965 | G20: 12848 | H20: 12703 | I20: 12964 | J20: 14206 | K20: 15588 | L20: 16815 | M20: 17654 | N20: 18530 | O20: 18915 | P20: 18838 | Q20: 18381 | R20: 18894 | S20: 18059 | T20: 18258 | U20: 20454 | V20: 21730 | W20: 21044 | X20: 19665 | Y20: 17621 | Z20: 15601 | AA20: =SUM(C20:Z20) -> 403839 | AB20: 6
A21: 46905 | B21: O | C21: 13900 | D21: 13113 | E21: 12720 | F21: 12509 | G21: 12742 | H21: 13451 | I21: 14386 | J21: 15809 | K21: 17247 | L21: 18319 | M21: 19439 | N21: 20485 | O21: 20148 | P21: 20125 | Q21: 20510 | R21: 20531 | S21: 20322 | T21: 20007 | U21: 21463 | V21: 22822 | W21: 21971 | X21: 20371 | Y21: 17859 | Z21: 15531 | AA21: =SUM(C21:Z21) -> 425780 | AB21: 20 | AC21: =+AA21*AB21+AA22*AB22+AA23*AB23 -> 12693374
B22: S | C22: 14571 | D22: 13664 | E22: 13144 | F22: 12850 | G22: 12876 | H22: 13085 | I22: 13769 | J22: 15384 | K22: 17206 | L22: 18457 | M22: 19434 | N22: 20281 | O22: 20336 | P22: 20128 | Q22: 19913 | R22: 19876 | S22: 19728 | T22: 19876 | U22: 21731 | V22: 22922 | W22: 21982 | X22: 20640 | Y22: 18652 | Z22: 16630 | AA22: =SUM(C22:Z22) -> 427135 | AB22: 4
B23: F | C23: 15165 | D23: 14198 | E23: 13637 | F23: 13254 | G23: 13164 | H23: 13149 | I23: 13324 | J23: 14618 | K23: 16057 | L23: 17168 | M23: 18082 | N23: 18966 | O23: 19281 | P23: 19148 | Q23: 18777 | R23: 18603 | S23: 18508 | T23: 18659 | U23: 20541 | V23: 22052 | W23: 21402 | X23: 20005 | Y23: 17906 | Z23: 15875 | AA23: =SUM(C23:Z23) -> 411539 | AB23: 6
A24: 46935 | B24: O | C24: 14553 | D24: 13725 | E24: 13247 | F24: 12987 | G24: 13209 | H24: 13914 | I24: 14673 | J24: 16262 | K24: 17806 | L24: 19016 | M24: 20188 | N24: 21227 | O24: 20859 | P24: 20904 | Q24: 21287 | R24: 21330 | S24: 21028 | T24: 20502 | U24: 21706 | V24: 23321 | W24: 22566 | X24: 21045 | Y24: 18536 | Z24: 16227 | AA24: =SUM(C24:Z24) -> 440118 | AB24: 19 | AC24: =+AA24*AB24+AA25*AB25+AA26*AB26 -> 13399715
B25: S | C25: 14585 | D25: 13635 | E25: 13151 | F25: 12827 | G25: 12858 | H25: 13128 | I25: 13781 | J25: 15704 | K25: 17535 | L25: 18789 | M25: 19774 | N25: 20607 | O25: 20569 | P25: 20247 | Q25: 19954 | R25: 19802 | S25: 19626 | T25: 19685 | U25: 21155 | V25: 22710 | W25: 21842 | X25: 20602 | Y25: 18658 | Z25: 16735 | AA25: =SUM(C25:Z25) -> 427959 | AB25: 5
B26: F | C26: 15478 | D26: 14528 | E26: 13900 | F26: 13490 | G26: 13362 | H26: 13367 | I26: 13454 | J26: 14677 | K26: 16145 | L26: 17362 | M26: 18247 | N26: 19069 | O26: 19476 | P26: 19262 | Q26: 18836 | R26: 18610 | S26: 18435 | T26: 18516 | U26: 20075 | V26: 21992 | W26: 21431 | X26: 20141 | Y26: 18045 | Z26: 16056 | AA26: =SUM(C26:Z26) -> 413954 | AB26: 7
A27: 46966 | B27: O | C27: 14724 | D27: 13939 | E27: 13506 | F27: 13250 | G27: 13482 | H27: 14417 | I27: 15249 | J27: 16664 | K27: 18144 | L27: 19277 | M27: 20477 | N27: 21529 | O27: 21159 | P27: 21326 | Q27: 21759 | R27: 21794 | S27: 21480 | T27: 20937 | U27: 22402 | V27: 23759 | W27: 22930 | X27: 21327 | Y27: 18786 | Z27: 16493 | AA27: =SUM(C27:Z27) -> 448810 | AB27: 21 | AC27: =+AA27*AB27+AA28*AB28+AA29*AB29 -> 13691680
B28: S | C28: 15326 | D28: 14475 | E28: 13943 | F28: 13544 | G28: 13514 | H28: 13889 | I28: 14334 | J28: 16149 | K28: 17983 | L28: 19241 | M28: 20343 | N28: 21177 | O28: 21183 | P28: 20955 | Q28: 20736 | R28: 20610 | S28: 20334 | T28: 20296 | U28: 22110 | V28: 23308 | W28: 22426 | X28: 21145 | Y28: 19279 | Z28: 17272 | AA28: =SUM(C28:Z28) -> 443572 | AB28: 4
B29: F | C29: 15612 | D29: 14644 | E29: 14006 | F29: 13599 | G29: 13467 | H29: 13512 | I29: 13510 | J29: 14783 | K29: 16220 | L29: 17405 | M29: 18244 | N29: 19113 | O29: 19562 | P29: 19387 | Q29: 18911 | R29: 18592 | S29: 18472 | T29: 18523 | U29: 20405 | V29: 22040 | W29: 21386 | X29: 20044 | Y29: 17998 | Z29: 15962 | AA29: =SUM(C29:Z29) -> 415397 | AB29: 6
A30: 46997 | B30: O | C30: 14987 | D30: 14162 | E30: 13646 | F30: 13420 | G30: 13638 | H30: 14532 | I30: 15393 | J30: 16853 | K30: 18320 | L30: 19539 | M30: 20749 | N30: 21859 | O30: 21478 | P30: 21633 | Q30: 22139 | R30: 22265 | S30: 21945 | T30: 21495 | U30: 23507 | V30: 24050 | W30: 23146 | X30: 21515 | Y30: 18922 | Z30: 16634 | AA30: =SUM(C30:Z30) -> 455827 | AB30: 21 | AC30: =+AA30*AB30+AA31*AB31+AA32*AB32 -> 13450812
B31: S | C31: 15387 | D31: 14405 | E31: 13874 | F31: 13582 | G31: 13594 | H31: 13720 | I31: 14407 | J31: 16363 | K31: 18227 | L31: 19557 | M31: 20609 | N31: 21452 | O31: 21400 | P31: 21126 | Q31: 20873 | R31: 20689 | S31: 20511 | T31: 20664 | U31: 22870 | V31: 23364 | W31: 22338 | X31: 21028 | Y31: 19114 | Z31: 17159 | AA31: =SUM(C31:Z31) -> 446313 | AB31: 5
B32: F | C32: 15667 | D32: 14727 | E32: 14109 | F32: 13631 | G32: 13415 | H32: 13251 | I32: 13352 | J32: 14601 | K32: 16010 | L32: 17165 | M32: 17971 | N32: 18740 | O32: 19185 | P32: 19049 | Q32: 18647 | R32: 18452 | S32: 18325 | T32: 18472 | U32: 20879 | V32: 21699 | W32: 21099 | X32: 19784 | Y32: 17730 | Z32: 15760 | AA32: =SUM(C32:Z32) -> 411720 | AB32: 4
A33: 47027 | B33: O | C33: 14202 | D33: 13441 | E33: 13018 | F33: 12791 | G33: 13042 | H33: 13762 | I33: 14679 | J33: 16054 | K33: 17434 | L33: 18523 | M33: 19651 | N33: 20696 | O33: 20333 | P33: 20445 | Q33: 20913 | R33: 21013 | S33: 20781 | T33: 20842 | U33: 23147 | V33: 23028 | W33: 22017 | X33: 20367 | Y33: 17944 | Z33: 15788 | AA33: =SUM(C33:Z33) -> 433911 | AB33: 21 | AC33: =+AA33*AB33+AA34*AB34+AA35*AB35 -> 13286149
B34: S | C34: 14951 | D34: 14099 | E34: 13581 | F34: 13238 | G34: 13307 | H34: 13514 | I34: 14277 | J34: 16035 | K34: 17787 | L34: 19004 | M34: 20040 | N34: 20908 | O34: 20942 | P34: 20705 | Q34: 20454 | R34: 20297 | S34: 20115 | T34: 20748 | U34: 23382 | V34: 23341 | W34: 22352 | X34: 20855 | Y34: 19010 | Z34: 17003 | AA34: =SUM(C34:Z34) -> 439945 | AB34: 4
B35: F | C35: 15002 | D35: 14094 | E35: 13467 | F35: 13029 | G35: 12890 | H35: 12709 | I35: 12952 | J35: 14141 | K35: 15489 | L35: 16674 | M35: 17513 | N35: 18340 | O35: 18803 | P35: 18649 | Q35: 18295 | R35: 18115 | S35: 18011 | T35: 18567 | U35: 21220 | V35: 21437 | W35: 20750 | X35: 19395 | Y35: 17383 | Z35: 15448 | AA35: =SUM(C35:Z35) -> 402373 | AB35: 6
A36: 47058 | B36: O | C36: 13940 | D36: 13180 | E36: 12759 | F36: 12562 | G36: 12854 | H36: 13675 | I36: 14651 | J36: 16047 | K36: 17402 | L36: 18450 | M36: 19572 | N36: 20648 | O36: 20226 | P36: 20238 | Q36: 20696 | R36: 20675 | S36: 20505 | T36: 20785 | U36: 23192 | V36: 23064 | W36: 22038 | X36: 20300 | Y36: 17805 | Z36: 15573 | AA36: =SUM(C36:Z36) -> 430837 | AB36: 20 | AC36: =+AA36*AB36+AA37*AB37+AA38*AB38 -> 12653604
B37: S | C37: 14315 | D37: 13507 | E37: 13014 | F37: 12699 | G37: 12754 | H37: 12914 | I37: 13617 | J37: 15237 | K37: 16949 | L37: 18143 | M37: 19098 | N37: 19976 | O37: 19894 | P37: 19523 | Q37: 19415 | R37: 19353 | S37: 19239 | T37: 19928 | U37: 22608 | V37: 22540 | W37: 21508 | X37: 20187 | Y37: 18234 | Z37: 16270 | AA37: =SUM(C37:Z37) -> 420922 | AB37: 4
B38: F | C38: 14373 | D38: 13507 | E38: 12921 | F38: 12492 | G38: 12435 | H38: 12281 | I38: 12573 | J38: 13812 | K38: 15163 | L38: 16324 | M38: 17168 | N38: 18026 | O38: 18451 | P38: 18283 | Q38: 17877 | R38: 17589 | S38: 17507 | T38: 18132 | U38: 20833 | V38: 21084 | W38: 20389 | X38: 19014 | Y38: 16955 | Z38: 15007 | AA38: =SUM(C38:Z38) -> 392196 | AB38: 6
A39: 47088 | B39: O | C39: 14935 | D39: 14031 | E39: 13509 | F39: 13241 | G39: 13426 | H39: 14014 | I39: 14670 | J39: 16396 | K39: 18008 | L39: 19199 | M39: 20286 | N39: 21389 | O39: 21178 | P39: 21161 | Q39: 21474 | R39: 21447 | S39: 21138 | T39: 20997 | U39: 23339 | V39: 23701 | W39: 22781 | X39: 21311 | Y39: 19056 | Z39: 16897 | AA39: =SUM(C39:Z39) -> 447584 | AB39: 19 | AC39: =+AA39*AB39+AA40*AB40+AA41*AB41 -> 13517547
B40: S | C40: 15078 | D40: 14167 | E40: 13646 | F40: 13302 | G40: 13321 | H40: 13652 | I40: 14054 | J40: 15668 | K40: 17314 | L40: 18461 | M40: 19384 | N40: 20153 | O40: 20152 | P40: 19864 | Q40: 19679 | R40: 19474 | S40: 19328 | T40: 19674 | U40: 22289 | V40: 22596 | W40: 21691 | X40: 20399 | Y40: 18554 | Z40: 16772 | AA40: =SUM(C40:Z40) -> 428672 | AB40: 5
B41: F | C41: 15577 | D41: 14627 | E41: 13965 | F41: 13494 | G41: 13310 | H41: 13243 | I41: 13221 | J41: 14292 | K41: 15622 | L41: 16791 | M41: 17666 | N41: 18488 | O41: 18931 | P41: 18908 | Q41: 18608 | R41: 18419 | S41: 18310 | T41: 18657 | U41: 21270 | V41: 21800 | W41: 21055 | X41: 19782 | Y41: 17921 | Z41: 16056 | AA41: =SUM(C41:Z41) -> 410013 | AB41: 7
A42: TOTAL AÑO | C42: =+SUM(C6:C41) -> 534619 | D42: =+SUM(D6:D41) -> 502850 | E42: =+SUM(E6:E41) -> 483693 | F42: =+SUM(F6:F41) -> 471849 | G42: =+SUM(G6:G41) -> 473321 | H42: =+SUM(H6:H41) -> 487072 | I42: =+SUM(I6:I41) -> 505489 | J42: =+SUM(J6:J41) -> 555654 | ... AC42: =+SUM(AC6:AC41) -> 158012856

Sheet Cantidades Ofertadas Prod 2
A1: CANTIDADES OFERTADAS PRODUCTO 2 AÑO 2028 MODALIDAD PAGUE LO CONTRATADO - kWh
A4: Periodo | B4: Tipo de día | C4: H01 | D4: H02 | E4: H03 | F4: H04 | G4: H05 | H4: H06 | I4: H07 | J4: H08 | K4: H09 | L4: H10 | M4: H11 | N4: H12 | O4: H13 | P4: H14 | Q4: H15 | R4: H16 | S4: H17 | T4: H18 | U4: H19 | V4: H20 | W4: H21 | X4: H22 | Y4: H23 | Z4: H24 | AA4: TOTAL DÍA | AB4: Días/ | AC4: TOTAL MES
AB5: mes
A6: 46753 | B6: O | C6: =ROUND('Anexo 6'!C6*'Anexo 2'!$D$10,0) -> 0 | D6: =ROUND('Anexo 6'!D6*'Anexo 2'!$D$10,0) -> 0 | E6: =ROUND('Anexo 6'!E6*'Anexo 2'!$D$10,0) -> 0 | F6: =ROUND('Anexo 6'!F6*'Anexo 2'!$D$10,0) -> 0 | G6: =ROUND('Anexo 6'!G6*'Anexo 2'!$D$10,0) -> 0 | H6: =ROUND('Anexo 6'!H6*'Anexo 2'!$D$10,0) -> 0 | I6: =ROUND('Anexo 6'!I6*'Anexo 2'!$D$10,0) -> 0 | J6: =ROUND('Anexo 6'!J6*'Anexo 2'!$D$10,0) -> 0 | ... Z6: =ROUND('Anexo 6'!Z6*'Anexo 2'!$D$10,0) -> 0 | AA6: =SUM(C6:Z6) -> 0 | AB6: 20 | AC6: =+AA6*AB6+AA7*AB7+AA8*AB8 -> 0
B7: S | C7: =ROUND('Anexo 6'!C7*'Anexo 2'!$D$10,0) -> 0 | D7: =ROUND('Anexo 6'!D7*'Anexo 2'!$D$10,0) -> 0 | E7: =ROUND('Anexo 6'!E7*'Anexo 2'!$D$10,0) -> 0 | F7: =ROUND('Anexo 6'!F7*'Anexo 2'!$D$10,0) -> 0 | G7: =ROUND('Anexo 6'!G7*'Anexo 2'!$D$10,0) -> 0 | H7: =ROUND('Anexo 6'!H7*'Anexo 2'!$D$10,0) -> 0 | I7: =ROUND('Anexo 6'!I7*'Anexo 2'!$D$10,0) -> 0 | J7: =ROUND('Anexo 6'!J7*'Anexo 2'!$D$10,0) -> 0 | ... Z7: =ROUND('Anexo 6'!Z7*'Anexo 2'!$D$10,0) -> 0 | AA7: =SUM(C7:Z7) -> 0 | AB7: 4
B8: F | C8: =ROUND('Anexo 6'!C8*'Anexo 2'!$D$10,0) -> 0 | D8: =ROUND('Anexo 6'!D8*'Anexo 2'!$D$10,0) -> 0 | E8: =ROUND('Anexo 6'!E8*'Anexo 2'!$D$10,0) -> 0 | F8: =ROUND('Anexo 6'!F8*'Anexo 2'!$D$10,0) -> 0 | G8: =ROUND('Anexo 6'!G8*'Anexo 2'!$D$10,0) -> 0 | H8: =ROUND('Anexo 6'!H8*'Anexo 2'!$D$10,0) -> 0 | I8: =ROUND('Anexo 6'!I8*'Anexo 2'!$D$10,0) -> 0 | J8: =ROUND('Anexo 6'!J8*'Anexo 2'!$D$10,0) -> 0 | ... Z8: =ROUND('Anexo 6'!Z8*'Anexo 2'!$D$10,0) -> 0 | AA8: =SUM(C8:Z8) -> 0 | AB8: 7
A9: 46784 | B9: O | C9: =ROUND('Anexo 6'!C9*'Anexo 2'!$D$10,0) -> 0 | D9: =ROUND('Anexo 6'!D9*'Anexo 2'!$D$10,0) -> 0 | E9: =ROUND('Anexo 6'!E9*'Anexo 2'!$D$10,0) -> 0 | F9: =ROUND('Anexo 6'!F9*'Anexo 2'!$D$10,0) -> 0 | G9: =ROUND('Anexo 6'!G9*'Anexo 2'!$D$10,0) -> 0 | H9: =ROUND('Anexo 6'!H9*'Anexo 2'!$D$10,0) -> 0 | I9: =ROUND('Anexo 6'!I9*'Anexo 2'!$D$10,0) -> 0 | J9: =ROUND('Anexo 6'!J9*'Anexo 2'!$D$10,0) -> 0 | ... Z9: =ROUND('Anexo 6'!Z9*'Anexo 2'!$D$10,0) -> 0 | AA9: =SUM(C9:Z9) -> 0 | AB9: 21 | AC9: =+AA9*AB9+AA10*AB10+AA11*AB11 -> 0
B10: S | C10: =ROUND('Anexo 6'!C10*'Anexo 2'!$D$10,0) -> 0 | D10: =ROUND('Anexo 6'!D10*'Anexo 2'!$D$10,0) -> 0 | E10: =ROUND('Anexo 6'!E10*'Anexo 2'!$D$10,0) -> 0 | F10: =ROUND('Anexo 6'!F10*'Anexo 2'!$D$10,0) -> 0 | G10: =ROUND('Anexo 6'!G10*'Anexo 2'!$D$10,0) -> 0 | H10: =ROUND('Anexo 6'!H10*'Anexo 2'!$D$10,0) -> 0 | I10: =ROUND('Anexo 6'!I10*'Anexo 2'!$D$10,0) -> 0 | J10: =ROUND('Anexo 6'!J10*'Anexo 2'!$D$10,0) -> 0 | ... Z10: =ROUND('Anexo 6'!Z10*'Anexo 2'!$D$10,0) -> 0 | AA10: =SUM(C10:Z10) -> 0 | AB10: 4
B11: F | C11: =ROUND('Anexo 6'!C11*'Anexo 2'!$D$10,0) -> 0 | D11: =ROUND('Anexo 6'!D11*'Anexo 2'!$D$10,0) -> 0 | E11: =ROUND('Anexo 6'!E11*'Anexo 2'!$D$10,0) -> 0 | F11: =ROUND('Anexo 6'!F11*'Anexo 2'!$D$10,0) -> 0 | G11: =ROUND('Anexo 6'!G11*'Anexo 2'!$D$10,0) -> 0 | H11: =ROUND('Anexo 6'!H11*'Anexo 2'!$D$10,0) -> 0 | I11: =ROUND('Anexo 6'!I11*'Anexo 2'!$D$10,0) -> 0 | J11: =ROUND('Anexo 6'!J11*'Anexo 2'!$D$10,0) -> 0 | ... Z11: =ROUND('Anexo 6'!Z11*'Anexo 2'!$D$10,0) -> 0 | AA11: =SUM(C11:Z11) -> 0 | AB11: 4
A12: 46813 | B12: O | C12: =ROUND('Anexo 6'!C12*'Anexo 2'!$D$10,0) -> 0 | D12: =ROUND('Anexo 6'!D12*'Anexo 2'!$D$10,0) -> 0 | E12: =ROUND('Anexo 6'!E12*'Anexo 2'!$D$10,0) -> 0 | F12: =ROUND('Anexo 6'!F12*'Anexo 2'!$D$10,0) -> 0 | G12: =ROUND('Anexo 6'!G12*'Anexo 2'!$D$10,0) -> 0 | H12: =ROUND('Anexo 6'!H12*'Anexo 2'!$D$10,0) -> 0 | I12: =ROUND('Anexo 6'!I12*'Anexo 2'!$D$10,0) -> 0 | J12: =ROUND('Anexo 6'!J12*'Anexo 2'!$D$10,0) -> 0 | ... Z12: =ROUND('Anexo 6'!Z12*'Anexo 2'!$D$10,0) -> 0 | AA12: =SUM(C12:Z12) -> 0 | AB12: 22 | AC12: =+AA12*AB12+AA13*AB13+AA14*AB14 -> 0
