Workbook

Sheet Cantidades 2026
C2: CANTIDADES DE ENERGÍA SOLICITADAS (kWh)
C3: EMPRESAS PÚBLICAS DE MEDELLÍN E.S.P.
C4: 2026
C6: Mes | D6: Tipo Día | E6: Días | F6: H1 | G6: H2 | H6: H3 | I6: H4 | J6: H5 | K6: H6 | L6: H7 | M6: H8 | N6: H9 | O6: H10 | P6: H11 | Q6: H12 | R6: H13 | S6: H14 | T6: H15 | U6: H16 | V6: H17 | W6: H18 | X6: H19 | Y6: H20 | Z6: H21 | AA6: H22 | AB6: H23 | AC6: H24 | AD6: TOTAL MES
C7: Ene | D7: Ordinario | E7: 20 | F7: =+[1]Resumen!F7*1000 -> 0 | G7: =+[1]Resumen!G7*1000 -> 0 | H7: =+[1]Resumen!H7*1000 -> 0 | I7: =+[1]Resumen!I7*1000 -> 0 | J7: =+[1]Resumen!J7*1000 -> 0 | K7: =+[1]Resumen!K7*1000 -> 0 | L7: =+[1]Resumen!L7*1000 -> 0 | M7: =+[1]Resumen!M7*1000 -> 0 | ... AC7: =+[1]Resumen!AC7*1000 -> 0 | AD7: =SUM(F7:AC7)*E7+SUM(F8:AC8)*E8+SUM(F9:AC9)*E9+SUM(F10:AC10)*E10 -> 69124564
D8: Sábado | E8: 5 | F8: =+[1]Resumen!F8*1000 -> 0 | G8: =+[1]Resumen!G8*1000 -> 0 | H8: =+[1]Resumen!H8*1000 -> 0 | I8: =+[1]Resumen!I8*1000 -> 0 | J8: =+[1]Resumen!J8*1000 -> 0 | K8: =+[1]Resumen!K8*1000 -> 0 | L8: =+[1]Resumen!L8*1000 -> 0 | M8: =+[1]Resumen!M8*1000 -> 0 | ... AC8: =+[1]Resumen!AC8*1000 -> 0
D9: Domingo | E9: 4 | F9: =+[1]Resumen!F9*1000 -> 0 | G9: =+[1]Resumen!G9*1000 -> 0 | H9: =+[1]Resumen!H9*1000 -> 0 | I9: =+[1]Resumen!I9*1000 -> 0 | J9: =+[1]Resumen!J9*1000 -> 0 | K9: =+[1]Resumen!K9*1000 -> 0 | L9: =+[1]Resumen!L9*1000 -> 0 | M9: =+[1]Resumen!M9*1000 -> 0 | ... AC9: =+[1]Resumen!AC9*1000 -> 0
D10: Festivo | E10: 2 | F10: =+[1]Resumen!F10*1000 -> 0 | G10: =+[1]Resumen!G10*1000 -> 0 | H10: =+[1]Resumen!H10*1000 -> 0 | I10: =+[1]Resumen!I10*1000 -> 0 | J10: =+[1]Resumen!J10*1000 -> 0 | K10: =+[1]Resumen!K10*1000 -> 0 | L10: =+[1]Resumen!L10*1000 -> 0 | M10: =+[1]Resumen!M10*1000 -> 0 | ... AC10: =+[1]Resumen!AC10*1000 -> 0
C11: Feb | D11: Ordinario | E11: 20 | F11: =+[1]Resumen!F11*1000 -> 0 | G11: =+[1]Resumen!G11*1000 -> 0 | H11: =+[1]Resumen!H11*1000 -> 0 | I11: =+[1]Resumen!I11*1000 -> 0 | J11: =+[1]Resumen!J11*1000 -> 0 | K11: =+[1]Resumen!K11*1000 -> 0 | L11: =+[1]Resumen!L11*1000 -> 0 | M11: =+[1]Resumen!M11*1000 -> 0 | ... AC11: =+[1]Resumen!AC11*1000 -> 0 | AD11: =SUM(F11:AC11)*E11+SUM(F12:AC12)*E12+SUM(F13:AC13)*E13+SUM(F14:AC14)*E14 -> 82906137
D12: Sábado | E12: 4 | F12: =+[1]Resumen!F12*1000 -> 0 | G12: =+[1]Resumen!G12*1000 -> 0 | H12: =+[1]Resumen!H12*1000 -> 0 | I12: =+[1]Resumen!I12*1000 -> 0 | J12: =+[1]Resumen!J12*1000 -> 0 | K12: =+[1]Resumen!K12*1000 -> 0 | L12: =+[1]Resumen!L12*1000 -> 0 | M12: =+[1]Resumen!M12*1000 -> 0 | ... AC12: =+[1]Resumen!AC12*1000 -> 0
D13: Domingo | E13: 4 | F13: =+[1]Resumen!F13*1000 -> 0 | G13: =+[1]Resumen!G13*1000 -> 0 | H13: =+[1]Resumen!H13*1000 -> 0 | I13: =+[1]Resumen!I13*1000 -> 0 | J13: =+[1]Resumen!J13*1000 -> 0 | K13: =+[1]Resumen!K13*1000 -> 0 | L13: =+[1]Resumen!L13*1000 -> 0 | M13: =+[1]Resumen!M13*1000 -> 0 | ... AC13: =+[1]Resumen!AC13*1000 -> 0
D14: Festivo | E14: 0 | F14: =+[1]Resumen!F14*1000 -> 0 | G14: =+[1]Resumen!G14*1000 -> 0 | H14: =+[1]Resumen!H14*1000 -> 0 | I14: =+[1]Resumen!I14*1000 -> 0 | J14: =+[1]Resumen!J14*1000 -> 0 | K14: =+[1]Resumen!K14*1000 -> 0 | L14: =+[1]Resumen!L14*1000 -> 0 | M14: =+[1]Resumen!M14*1000 -> 0 | ... AC14: =+[1]Resumen!AC14*1000 -> 0
C15: Mar | D15: Ordinario | E15: 21 | F15: =+[1]Resumen!F15*1000 -> 0 | G15: =+[1]Resumen!G15*1000 -> 0 | H15: =+[1]Resumen!H15*1000 -> 0 | I15: =+[1]Resumen!I15*1000 -> 0 | J15: =+[1]Resumen!J15*1000 -> 0 | K15: =+[1]Resumen!K15*1000 -> 0 | L15: =+[1]Resumen!L15*1000 -> 0 | M15: =+[1]Resumen!M15*1000 -> 0 | ... AC15: =+[1]Resumen!AC15*1000 -> 0 | AD15: =SUM(F15:AC15)*E15+SUM(F16:AC16)*E16+SUM(F17:AC17)*E17+SUM(F18:AC18)*E18 -> 65827997
D16: Sábado | E16: 4 | F16: =+[1]Resumen!F16*1000 -> 0 | G16: =+[1]Resumen!G16*1000 -> 0 | H16: =+[1]Resumen!H16*1000 -> 0 | I16: =+[1]Resumen!I16*1000 -> 0 | J16: =+[1]Resumen!J16*1000 -> 0 | K16: =+[1]Resumen!K16*1000 -> 0 | L16: =+[1]Resumen!L16*1000 -> 0 | M16: =+[1]Resumen!M16*1000 -> 0 | ... AC16: =+[1]Resumen!AC16*1000 -> 0
D17: Domingo | E17: 5 | F17: =+[1]Resumen!F17*1000 -> 0 | G17: =+[1]Resumen!G17*1000 -> 0 | H17: =+[1]Resumen!H17*1000 -> 0 | I17: =+[1]Resumen!I17*1000 -> 0 | J17: =+[1]Resumen!J17*1000 -> 0 | K17: =+[1]Resumen!K17*1000 -> 0 | L17: =+[1]Resumen!L17*1000 -> 0 | M17: =+[1]Resumen!M17*1000 -> 0 | ... AC17: =+[1]Resumen!AC17*1000 -> 0
D18: Festivo | E18: 1 | F18: =+[1]Resumen!F18*1000 -> 0 | G18: =+[1]Resumen!G18*1000 -> 0 | H18: =+[1]Resumen!H18*1000 -> 0 | I18: =+[1]Resumen!I18*1000 -> 0 | J18: =+[1]Resumen!J18*1000 -> 0 | K18: =+[1]Resumen!K18*1000 -> 0 | L18: =+[1]Resumen!L18*1000 -> 0 | M18: =+[1]Resumen!M18*1000 -> 0 | ... AC18: =+[1]Resumen!AC18*1000 -> 0
C19: Abr | D19: Ordinario | E19: 20 | F19: =+[1]Resumen!F19*1000 -> 0 | G19: =+[1]Resumen!G19*1000 -> 0 | H19: =+[1]Resumen!H19*1000 -> 0 | I19: =+[1]Resumen!I19*1000 -> 0 | J19: =+[1]Resumen!J19*1000 -> 0 | K19: =+[1]Resumen!K19*1000 -> 0 | L19: =+[1]Resumen!L19*1000 -> 0 | M19: =+[1]Resumen!M19*1000 -> 0 | ... AC19: =+[1]Resumen!AC19*1000 -> 0 | AD19: =SUM(F19:AC19)*E19+SUM(F20:AC20)*E20+SUM(F21:AC21)*E21+SUM(F22:AC22)*E22 -> 73334508
D20: Sábado | E20: 4 | F20: =+[1]Resumen!F20*1000 -> 0 | G20: =+[1]Resumen!G20*1000 -> 0 | H20: =+[1]Resumen!H20*1000 -> 0 | I20: =+[1]Resumen!I20*1000 -> 0 | J20: =+[1]Resumen!J20*1000 -> 0 | K20: =+[1]Resumen!K20*1000 -> 0 | L20: =+[1]Resumen!L20*1000 -> 0 | M20: =+[1]Resumen!M20*1000 -> 0 | ... AC20: =+[1]Resumen!AC20*1000 -> 0
D21: Domingo | E21: 4 | F21: =+[1]Resumen!F21*1000 -> 0 | G21: =+[1]Resumen!G21*1000 -> 0 | H21: =+[1]Resumen!H21*1000 -> 0 | I21: =+[1]Resumen!I21*1000 -> 0 | J21: =+[1]Resumen!J21*1000 -> 0 | K21: =+[1]Resumen!K21*1000 -> 0 | L21: =+[1]Resumen!L21*1000 -> 0 | M21: =+[1]Resumen!M21*1000 -> 0 | ... AC21: =+[1]Resumen!AC21*1000 -> 0
D22: Festivo | E22: 2 | F22: =+[1]Resumen!F22*1000 -> 0 | G22: =+[1]Resumen!G22*1000 -> 0 | H22: =+[1]Resumen!H22*1000 -> 0 | I22: =+[1]Resumen!I22*1000 -> 0 | J22: =+[1]Resumen!J22*1000 -> 0 | K22: =+[1]Resumen!K22*1000 -> 0 | L22: =+[1]Resumen!L22*1000 -> 0 | M22: =+[1]Resumen!M22*1000 -> 0 | ... AC22: =+[1]Resumen!AC22*1000 -> 0
C23: May | D23: Ordinario | E23: 19 | F23: =+[1]Resumen!F23*1000 -> 0 | G23: =+[1]Resumen!G23*1000 -> 0 | H23: =+[1]Resumen!H23*1000 -> 0 | I23: =+[1]Resumen!I23*1000 -> 0 | J23: =+[1]Resumen!J23*1000 -> 0 | K23: =+[1]Resumen!K23*1000 -> 0 | L23: =+[1]Resumen!L23*1000 -> 0 | M23: =+[1]Resumen!M23*1000 -> 0 | ... AC23: =+[1]Resumen!AC23*1000 -> 0 | AD23: =SUM(F23:AC23)*E23+SUM(F24:AC24)*E24+SUM(F25:AC25)*E25+SUM(F26:AC26)*E26 -> 29618522
D24: Sábado | E24: 5 | F24: =+[1]Resumen!F24*1000 -> 0 | G24: =+[1]Resumen!G24*1000 -> 0 | H24: =+[1]Resumen!H24*1000 -> 0 | I24: =+[1]Resumen!I24*1000 -> 0 | J24: =+[1]Resumen!J24*1000 -> 0 | K24: =+[1]Resumen!K24*1000 -> 0 | L24: =+[1]Resumen!L24*1000 -> 0 | M24: =+[1]Resumen!M24*1000 -> 0 | ... AC24: =+[1]Resumen!AC24*1000 -> 0
D25: Domingo | E25: 5 | F25: =+[1]Resumen!F25*1000 -> 0 | G25: =+[1]Resumen!G25*1000 -> 0 | H25: =+[1]Resumen!H25*1000 -> 0 | I25: =+[1]Resumen!I25*1000 -> 0 | J25: =+[1]Resumen!J25*1000 -> 0 | K25: =+[1]Resumen!K25*1000 -> 0 | L25: =+[1]Resumen!L25*1000 -> 0 | M25: =+[1]Resumen!M25*1000 -> 0 | ... AC25: =+[1]Resumen!AC25*1000 -> 0
D26: Festivo | E26: 2 | F26: =+[1]Resumen!F26*1000 -> 0 | G26: =+[1]Resumen!G26*1000 -> 0 | H26: =+[1]Resumen!H26*1000 -> 0 | I26: =+[1]Resumen!I26*1000 -> 0 | J26: =+[1]Resumen!J26*1000 -> 0 | K26: =+[1]Resumen!K26*1000 -> 0 | L26: =+[1]Resumen!L26*1000 -> 0 | M26: =+[1]Resumen!M26*1000 -> 0 | ... AC26: =+[1]Resumen!AC26*1000 -> 0
C27: Jun | D27: Ordinario | E27: 19 | F27: =+[1]Resumen!F27*1000 -> 0 | G27: =+[1]Resumen!G27*1000 -> 0 | H27: =+[1]Resumen!H27*1000 -> 0 | I27: =+[1]Resumen!I27*1000 -> 0 | J27: =+[1]Resumen!J27*1000 -> 0 | K27: =+[1]Resumen!K27*1000 -> 0 | L27: =+[1]Resumen!L27*1000 -> 0 | M27: =+[1]Resumen!M27*1000 -> 0 | ... AC27: =+[1]Resumen!AC27*1000 -> 0 | AD27: =SUM(F27:AC27)*E27+SUM(F28:AC28)*E28+SUM(F29:AC29)*E29+SUM(F30:AC30)*E30 -> 35450077
D28: Sábado | E28: 4 | F28: =+[1]Resumen!F28*1000 -> 0 | G28: =+[1]Resumen!G28*1000 -> 0 | H28: =+[1]Resumen!H28*1000 -> 0 | I28: =+[1]Resumen!I28*1000 -> 0 | J28: =+[1]Resumen!J28*1000 -> 0 | K28: =+[1]Resumen!K28*1000 -> 0 | L28: =+[1]Resumen!L28*1000 -> 0 | M28: =+[1]Resumen!M28*1000 -> 0 | ... AC28: =+[1]Resumen!AC28*1000 -> 0
D29: Domingo | E29: 4 | F29: =+[1]Resumen!F29*1000 -> 0 | G29: =+[1]Resumen!G29*1000 -> 0 | H29: =+[1]Resumen!H29*1000 -> 0 | I29: =+[1]Resumen!I29*1000 -> 0 | J29: =+[1]Resumen!J29*1000 -> 0 | K29: =+[1]Resumen!K29*1000 -> 0 | L29: =+[1]Resumen!L29*1000 -> 0 | M29: =+[1]Resumen!M29*1000 -> 0 | ... AC29: =+[1]Resumen!AC29*1000 -> 0
D30: Festivo | E30: 3 | F30: =+[1]Resumen!F30*1000 -> 0 | G30: =+[1]Resumen!G30*1000 -> 0 | H30: =+[1]Resumen!H30*1000 -> 0 | I30: =+[1]Resumen!I30*1000 -> 0 | J30: =+[1]Resumen!J30*1000 -> 0 | K30: =+[1]Resumen!K30*1000 -> 0 | L30: =+[1]Resumen!L30*1000 -> 0 | M30: =+[1]Resumen!M30*1000 -> 0 | ... AC30: =+[1]Resumen!AC30*1000 -> 0
C31: Jul | D31: Ordinario | E31: 22 | F31: =+[1]Resumen!F31*1000 -> 0 | G31: =+[1]Resumen!G31*1000 -> 0 | H31: =+[1]Resumen!H31*1000 -> 0 | I31: =+[1]Resumen!I31*1000 -> 0 | J31: =+[1]Resumen!J31*1000 -> 0 | K31: =+[1]Resumen!K31*1000 -> 0 | L31: =+[1]Resumen!L31*1000 -> 0 | M31: =+[1]Resumen!M31*1000 -> 0 | ... AC31: =+[1]Resumen!AC31*1000 -> 0 | AD31: =SUM(F31:AC31)*E31+SUM(F32:AC32)*E32+SUM(F33:AC33)*E33+SUM(F34:AC34)*E34 -> 31680984
D32: Sábado | E32: 4 | F32: =+[1]Resumen!F32*1000 -> 0 | G32: =+[1]Resumen!G32*1000 -> 0 | H32: =+[1]Resumen!H32*1000 -> 0 | I32: =+[1]Resumen!I32*1000 -> 0 | J32: =+[1]Resumen!J32*1000 -> 0 | K32: =+[1]Resumen!K32*1000 -> 0 | L32: =+[1]Resumen!L32*1000 -> 0 | M32: =+[1]Resumen!M32*1000 -> 0 | ... AC32: =+[1]Resumen!AC32*1000 -> 0
D33: Domingo | E33: 4 | F33: =+[1]Resumen!F33*1000 -> 0 | G33: =+[1]Resumen!G33*1000 -> 0 | H33: =+[1]Resumen!H33*1000 -> 0 | I33: =+[1]Resumen!I33*1000 -> 0 | J33: =+[1]Resumen!J33*1000 -> 0 | K33: =+[1]Resumen!K33*1000 -> 0 | L33: =+[1]Resumen!L33*1000 -> 0 | M33: =+[1]Resumen!M33*1000 -> 0 | ... AC33: =+[1]Resumen!AC33*1000 -> 0
D34: Festivo | E34: 1 | F34: =+[1]Resumen!F34*1000 -> 0 | G34: =+[1]Resumen!G34*1000 -> 0 | H34: =+[1]Resumen!H34*1000 -> 0 | I34: =+[1]Resumen!I34*1000 -> 0 | J34: =+[1]Resumen!J34*1000 -> 0 | K34: =+[1]Resumen!K34*1000 -> 0 | L34: =+[1]Resumen!L34*1000 -> 0 | M34: =+[1]Resumen!M34*1000 -> 0 | ... AC34: =+[1]Resumen!AC34*1000 -> 0
C35: Ago | D35: Ordinario | E35: 19 | F35: =+[1]Resumen!F35*1000 -> 0 | G35: =+[1]Resumen!G35*1000 -> 0 | H35: =+[1]Resumen!H35*1000 -> 0 | I35: =+[1]Resumen!I35*1000 -> 0 | J35: =+[1]Resumen!J35*1000 -> 0 | K35: =+[1]Resumen!K35*1000 -> 0 | L35: =+[1]Resumen!L35*1000 -> 0 | M35: =+[1]Resumen!M35*1000 -> 0 | ... AC35: =+[1]Resumen!AC35*1000 -> 0 | AD35: =SUM(F35:AC35)*E35+SUM(F36:AC36)*E36+SUM(F37:AC37)*E37+SUM(F38:AC38)*E38 -> 34639194
D36: Sábado | E36: 5 | F36: =+[1]Resumen!F36*1000 -> 0 | G36: =+[1]Resumen!G36*1000 -> 0 | H36: =+[1]Resumen!H36*1000 -> 0 | I36: =+[1]Resumen!I36*1000 -> 0 | J36: =+[1]Resumen!J36*1000 -> 0 | K36: =+[1]Resumen!K36*1000 -> 0 | L36: =+[1]Resumen!L36*1000 -> 0 | M36: =+[1]Resumen!M36*1000 -> 0 | ... AC36: =+[1]Resumen!AC36*1000 -> 0
D37: Domingo | E37: 5 | F37: =+[1]Resumen!F37*1000 -> 0 | G37: =+[1]Resumen!G37*1000 -> 0 | H37: =+[1]Resumen!H37*1000 -> 0 | I37: =+[1]Resumen!I37*1000 -> 0 | J37: =+[1]Resumen!J37*1000 -> 0 | K37: =+[1]Resumen!K37*1000 -> 0 | L37: =+[1]Resumen!L37*1000 -> 0 | M37: =+[1]Resumen!M37*1000 -> 0 | ... AC37: =+[1]Resumen!AC37*1000 -> 0
D38: Festivo | E38: 2 | F38: =+[1]Resumen!F38*1000 -> 0 | G38: =+[1]Resumen!G38*1000 -> 0 | H38: =+[1]Resumen!H38*1000 -> 0 | I38: =+[1]Resumen!I38*1000 -> 0 | J38: =+[1]Resumen!J38*1000 -> 0 | K38: =+[1]Resumen!K38*1000 -> 0 | L38: =+[1]Resumen!L38*1000 -> 0 | M38: =+[1]Resumen!M38*1000 -> 0 | ... AC38: =+[1]Resumen!AC38*1000 -> 0
C39: Sep | D39: Ordinario | E39: 22 | F39: =+[1]Resumen!F39*1000 -> 0 | G39: =+[1]Resumen!G39*1000 -> 0 | H39: =+[1]Resumen!H39*1000 -> 0 | I39: =+[1]Resumen!I39*1000 -> 0 | J39: =+[1]Resumen!J39*1000 -> 0 | K39: =+[1]Resumen!K39*1000 -> 0 | L39: =+[1]Resumen!L39*1000 -> 0 | M39: =+[1]Resumen!M39*1000 -> 0 | ... AC39: =+[1]Resumen!AC39*1000 -> 0 | AD39: =SUM(F39:AC39)*E39+SUM(F40:AC40)*E40+SUM(F41:AC41)*E41+SUM(F42:AC42)*E42 -> 73258851
D40: Sábado | E40: 4 | F40: =+[1]Resumen!F40*1000 -> 0 | G40: =+[1]Resumen!G40*1000 -> 0 | H40: =+[1]Resumen!H40*1000 -> 0 | I40: =+[1]Resumen!I40*1000 -> 0 | J40: =+[1]Resumen!J40*1000 -> 0 | K40: =+[1]Resumen!K40*1000 -> 0 | L40: =+[1]Resumen!L40*1000 -> 0 | M40: =+[1]Resumen!M40*1000 -> 0 | ... AC40: =+[1]Resumen!AC40*1000 -> 0
D41: Domingo | E41: 4 | F41: =+[1]Resumen!F41*1000 -> 0 | G41: =+[1]Resumen!G41*1000 -> 0 | H41: =+[1]Resumen!H41*1000 -> 0 | I41: =+[1]Resumen!I41*1000 -> 0 | J41: =+[1]Resumen!J41*1000 -> 0 | K41: =+[1]Resumen!K41*1000 -> 0 | L41: =+[1]Resumen!L41*1000 -> 0 | M41: =+[1]Resumen!M41*1000 -> 0 | ... AC41: =+[1]Resumen!AC41*1000 -> 0
D42: Festivo | E42: 0 | F42: =+[1]Resumen!F42*1000 -> 0 | G42: =+[1]Resumen!G42*1000 -> 0 | H42: =+[1]Resumen!H42*1000 -> 0 | I42: =+[1]Resumen!I42*1000 -> 0 | J42: =+[1]Resumen!J42*1000 -> 0 | K42: =+[1]Resumen!K42*1000 -> 0 | L42: =+[1]Resumen!L42*1000 -> 0 | M42: =+[1]Resumen!M42*1000 -> 0 | ... AC42: =+[1]Resumen!AC42*1000 -> 0
...

Sheet Cantidades 2027
C2: CANTIDADES DE ENERGÍA SOLICITADAS (kWh)
C3: EMPRESAS PÚBLICAS DE MEDELLÍN E.S.P.
C4: 2027
C6: Mes | D6: Tipo Día | E6: Días | F6: H1 | G6: H2 | H6: H3 | I6: H4 | J6: H5 | K6: H6 | L6: H7 | M6: H8 | N6: H9 | O6: H10 | P6: H11 | Q6: H12 | R6: H13 | S6: H14 | T6: H15 | U6: H16 | V6: H17 | W6: H18 | X6: H19 | Y6: H20 | Z6: H21 | AA6: H22 | AB6: H23 | AC6: H24 | AD6: TOTAL MES
C7: Ene | D7: Ordinario | E7: 19 | F7: =+[2]Resumen!F7*1000 -> 0 | G7: =+[2]Resumen!G7*1000 -> 0 | H7: =+[2]Resumen!H7*1000 -> 0 | I7: =+[2]Resumen!I7*1000 -> 0 | J7: =+[2]Resumen!J7*1000 -> 0 | K7: =+[2]Resumen!K7*1000 -> 0 | L7: =+[2]Resumen!L7*1000 -> 0 | M7: =+[2]Resumen!M7*1000 -> 171481.35 | ... AC7: =+[2]Resumen!AC7*1000 -> 0 | AD7: =SUM(F7:AC7)*E7+SUM(F8:AC8)*E8+SUM(F9:AC9)*E9+SUM(F10:AC10)*E10 -> 63756663
D8: Sábado | E8: 5 | F8: =+[2]Resumen!F8*1000 -> 0 | G8: =+[2]Resumen!G8*1000 -> 0 | H8: =+[2]Resumen!H8*1000 -> 0 | I8: =+[2]Resumen!I8*1000 -> 0 | J8: =+[2]Resumen!J8*1000 -> 0 | K8: =+[2]Resumen!K8*1000 -> 0 | L8: =+[2]Resumen!L8*1000 -> 0 | M8: =+[2]Resumen!M8*1000 -> 137706.05 | ... AC8: =+[2]Resumen!AC8*1000 -> 0
D9: Domingo | E9: 5 | F9: =+[2]Resumen!F9*1000 -> 0 | G9: =+[2]Resumen!G9*1000 -> 0 | H9: =+[2]Resumen!H9*1000 -> 0 | I9: =+[2]Resumen!I9*1000 -> 0 | J9: =+[2]Resumen!J9*1000 -> 0 | K9: =+[2]Resumen!K9*1000 -> 0 | L9: =+[2]Resumen!L9*1000 -> 0 | M9: =+[2]Resumen!M9*1000 -> 100756.86 | ... AC9: =+[2]Resumen!AC9*1000 -> 0
D10: Festivo | E10: 2 | F10: =+[2]Resumen!F10*1000 -> 0 | G10: =+[2]Resumen!G10*1000 -> 0 | H10: =+[2]Resumen!H10*1000 -> 0 | I10: =+[2]Resumen!I10*1000 -> 0 | J10: =+[2]Resumen!J10*1000 -> 0 | K10: =+[2]Resumen!K10*1000 -> 0 | L10: =+[2]Resumen!L10*1000 -> 0 | M10: =+[2]Resumen!M10*1000 -> 66624.523 | ... AC10: =+[2]Resumen!AC10*1000 -> 0
C11: Feb | D11: Ordinario | E11: 20 | F11: =+[2]Resumen!F11*1000 -> 0 | G11: =+[2]Resumen!G11*1000 -> 0 | H11: =+[2]Resumen!H11*1000 -> 0 | I11: =+[2]Resumen!I11*1000 -> 0 | J11: =+[2]Resumen!J11*1000 -> 0 | K11: =+[2]Resumen!K11*1000 -> 0 | L11: =+[2]Resumen!L11*1000 -> 0 | M11: =+[2]Resumen!M11*1000 -> 236163.39 | ... AC11: =+[2]Resumen!AC11*1000 -> 0 | AD11: =SUM(F11:AC11)*E11+SUM(F12:AC12)*E12+SUM(F13:AC13)*E13+SUM(F14:AC14)*E14 -> 76709571
D12: Sábado | E12: 4 | F12: =+[2]Resumen!F12*1000 -> 0 | G12: =+[2]Resumen!G12*1000 -> 0 | H12: =+[2]Resumen!H12*1000 -> 0 | I12: =+[2]Resumen!I12*1000 -> 0 | J12: =+[2]Resumen!J12*1000 -> 0 | K12: =+[2]Resumen!K12*1000 -> 0 | L12: =+[2]Resumen!L12*1000 -> 0 | M12: =+[2]Resumen!M12*1000 -> 209586.61 | ... AC12: =+[2]Resumen!AC12*1000 -> 0
D13: Domingo | E13: 4 | F13: =+[2]Resumen!F13*1000 -> 0 | G13: =+[2]Resumen!G13*1000 -> 0 | H13: =+[2]Resumen!H13*1000 -> 0 | I13: =+[2]Resumen!I13*1000 -> 0 | J13: =+[2]Resumen!J13*1000 -> 0 | K13: =+[2]Resumen!K13*1000 -> 0 | L13: =+[2]Resumen!L13*1000 -> 0 | M13: =+[2]Resumen!M13*1000 -> 148915.34 | ... AC13: =+[2]Resumen!AC13*1000 -> 0
D14: Festivo | E14: 0 | F14: =+[2]Resumen!F14*1000 -> 0 | G14: =+[2]Resumen!G14*1000 -> 0 | H14: =+[2]Resumen!H14*1000 -> 0 | I14: =+[2]Resumen!I14*1000 -> 0 | J14: =+[2]Resumen!J14*1000 -> 0 | K14: =+[2]Resumen!K14*1000 -> 0 | L14: =+[2]Resumen!L14*1000 -> 0 | M14: =+[2]Resumen!M14*1000 -> 0 | ... AC14: =+[2]Resumen!AC14*1000 -> 0
C15: Mar | D15: Ordinario | E15: 20 | F15: =+[2]Resumen!F15*1000 -> 0 | G15: =+[2]Resumen!G15*1000 -> 0 | H15: =+[2]Resumen!H15*1000 -> 0 | I15: =+[2]Resumen!I15*1000 -> 0 | J15: =+[2]Resumen!J15*1000 -> 0 | K15: =+[2]Resumen!K15*1000 -> 0 | L15: =+[2]Resumen!L15*1000 -> 0 | M15: =+[2]Resumen!M15*1000 -> 162009.57 | ... AC15: =+[2]Resumen!AC15*1000 -> 0 | AD15: =SUM(F15:AC15)*E15+SUM(F16:AC16)*E16+SUM(F17:AC17)*E17+SUM(F18:AC18)*E18 -> 58588907
D16: Sábado | E16: 4 | F16: =+[2]Resumen!F16*1000 -> 0 | G16: =+[2]Resumen!G16*1000 -> 0 | H16: =+[2]Resumen!H16*1000 -> 0 | I16: =+[2]Resumen!I16*1000 -> 0 | J16: =+[2]Resumen!J16*1000 -> 0 | K16: =+[2]Resumen!K16*1000 -> 0 | L16: =+[2]Resumen!L16*1000 -> 0 | M16: =+[2]Resumen!M16*1000 -> 141974.77 | ... AC16: =+[2]Resumen!AC16*1000 -> 0
D17: Domingo | E17: 4 | F17: =+[2]Resumen!F17*1000 -> 0 | G17: =+[2]Resumen!G17*1000 -> 0 | H17: =+[2]Resumen!H17*1000 -> 0 | I17: =+[2]Resumen!I17*1000 -> 0 | J17: =+[2]Resumen!J17*1000 -> 0 | K17: =+[2]Resumen!K17*1000 -> 0 | L17: =+[2]Resumen!L17*1000 -> 0 | M17: =+[2]Resumen!M17*1000 -> 88891.966 | ... AC17: =+[2]Resumen!AC17*1000 -> 0
D18: Festivo | E18: 3 | F18: =+[2]Resumen!F18*1000 -> 0 | G18: =+[2]Resumen!G18*1000 -> 0 | H18: =+[2]Resumen!H18*1000 -> 0 | I18: =+[2]Resumen!I18*1000 -> 0 | J18: =+[2]Resumen!J18*1000 -> 0 | K18: =+[2]Resumen!K18*1000 -> 0 | L18: =+[2]Resumen!L18*1000 -> 0 | M18: =+[2]Resumen!M18*1000 -> 119455.41 | ... AC18: =+[2]Resumen!AC18*1000 -> 0
C19: Abr | D19: Ordinario | E19: 22 | F19: =+[2]Resumen!F19*1000 -> 0 | G19: =+[2]Resumen!G19*1000 -> 0 | H19: =+[2]Resumen!H19*1000 -> 0 | I19: =+[2]Resumen!I19*1000 -> 0 | J19: =+[2]Resumen!J19*1000 -> 0 | K19: =+[2]Resumen!K19*1000 -> 0 | L19: =+[2]Resumen!L19*1000 -> 0 | M19: =+[2]Resumen!M19*1000 -> 179338.57 | ... AC19: =+[2]Resumen!AC19*1000 -> 0 | AD19: =SUM(F19:AC19)*E19+SUM(F20:AC20)*E20+SUM(F21:AC21)*E21+SUM(F22:AC22)*E22 -> 64978468
D20: Sábado | E20: 4 | F20: =+[2]Resumen!F20*1000 -> 0 | G20: =+[2]Resumen!G20*1000 -> 0 | H20: =+[2]Resumen!H20*1000 -> 0 | I20: =+[2]Resumen!I20*1000 -> 0 | J20: =+[2]Resumen!J20*1000 -> 0 | K20: =+[2]Resumen!K20*1000 -> 0 | L20: =+[2]Resumen!L20*1000 -> 0 | M20: =+[2]Resumen!M20*1000 -> 150642.28 | ... AC20: =+[2]Resumen!AC20*1000 -> 0
D21: Domingo | E21: 4 | F21: =+[2]Resumen!F21*1000 -> 0 | G21: =+[2]Resumen!G21*1000 -> 0 | H21: =+[2]Resumen!H21*1000 -> 0 | I21: =+[2]Resumen!I21*1000 -> 0 | J21: =+[2]Resumen!J21*1000 -> 0 | K21: =+[2]Resumen!K21*1000 -> 0 | L21: =+[2]Resumen!L21*1000 -> 0 | M21: =+[2]Resumen!M21*1000 -> 114600.98 | ... AC21: =+[2]Resumen!AC21*1000 -> 0
D22: Festivo | E22: 0 | F22: =+[2]Resumen!F22*1000 -> 0 | G22: =+[2]Resumen!G22*1000 -> 0 | H22: =+[2]Resumen!H22*1000 -> 0 | I22: =+[2]Resumen!I22*1000 -> 0 | J22: =+[2]Resumen!J22*1000 -> 0 | K22: =+[2]Resumen!K22*1000 -> 0 | L22: =+[2]Resumen!L22*1000 -> 0 | M22: =+[2]Resumen!M22*1000 -> 285690.17 | ... AC22: =+[2]Resumen!AC22*1000 -> 0
C23: May | D23: Ordinario | E23: 19 | F23: =+[2]Resumen!F23*1000 -> 0 | G23: =+[2]Resumen!G23*1000 -> 0 | H23: =+[2]Resumen!H23*1000 -> 0 | I23: =+[2]Resumen!I23*1000 -> 0 | J23: =+[2]Resumen!J23*1000 -> 0 | K23: =+[2]Resumen!K23*1000 -> 0 | L23: =+[2]Resumen!L23*1000 -> 0 | M23: =+[2]Resumen!M23*1000 -> 139071.53 | ... AC23: =+[2]Resumen!AC23*1000 -> 0 | AD23: =SUM(F23:AC23)*E23+SUM(F24:AC24)*E24+SUM(F25:AC25)*E25+SUM(F26:AC26)*E26 -> 48647934
D24: Sábado | E24: 4 | F24: =+[2]Resumen!F24*1000 -> 0 | G24: =+[2]Resumen!G24*1000 -> 0 | H24: =+[2]Resumen!H24*1000 -> 0 | I24: =+[2]Resumen!I24*1000 -> 0 | J24: =+[2]Resumen!J24*1000 -> 0 | K24: =+[2]Resumen!K24*1000 -> 0 | L24: =+[2]Resumen!L24*1000 -> 0 | M24: =+[2]Resumen!M24*1000 -> 96984.428 | ... AC24: =+[2]Resumen!AC24*1000 -> 0
D25: Domingo | E25: 5 | F25: =+[2]Resumen!F25*1000 -> 0 | G25: =+[2]Resumen!G25*1000 -> 0 | H25: =+[2]Resumen!H25*1000 -> 0 | I25: =+[2]Resumen!I25*1000 -> 0 | J25: =+[2]Resumen!J25*1000 -> 0 | K25: =+[2]Resumen!K25*1000 -> 0 | L25: =+[2]Resumen!L25*1000 -> 0 | M25: =+[2]Resumen!M25*1000 -> 38418.645 | ... AC25: =+[2]Resumen!AC25*1000 -> 0
D26: Festivo | E26: 3 | F26: =+[2]Resumen!F26*1000 -> 0 | G26: =+[2]Resumen!G26*1000 -> 0 | H26: =+[2]Resumen!H26*1000 -> 0 | I26: =+[2]Resumen!I26*1000 -> 0 | J26: =+[2]Resumen!J26*1000 -> 0 | K26: =+[2]Resumen!K26*1000 -> 0 | L26: =+[2]Resumen!L26*1000 -> 0 | M26: =+[2]Resumen!M26*1000 -> 85442.243 | ... AC26: =+[2]Resumen!AC26*1000 -> 0
C27: Jun | D27: Ordinario | E27: 21 | F27: =+[2]Resumen!F27*1000 -> 0 | G27: =+[2]Resumen!G27*1000 -> 0 | H27: =+[2]Resumen!H27*1000 -> 0 | I27: =+[2]Resumen!I27*1000 -> 0 | J27: =+[2]Resumen!J27*1000 -> 0 | K27: =+[2]Resumen!K27*1000 -> 0 | L27: =+[2]Resumen!L27*1000 -> 0 | M27: =+[2]Resumen!M27*1000 -> 153303.45 | ... AC27: =+[2]Resumen!AC27*1000 -> 0 | AD27: =SUM(F27:AC27)*E27+SUM(F28:AC28)*E28+SUM(F29:AC29)*E29+SUM(F30:AC30)*E30 -> 55973891
D28: Sábado | E28: 4 | F28: =+[2]Resumen!F28*1000 -> 0 | G28: =+[2]Resumen!G28*1000 -> 0 | H28: =+[2]Resumen!H28*1000 -> 0 | I28: =+[2]Resumen!I28*1000 -> 0 | J28: =+[2]Resumen!J28*1000 -> 0 | K28: =+[2]Resumen!K28*1000 -> 0 | L28: =+[2]Resumen!L28*1000 -> 0 | M28: =+[2]Resumen!M28*1000 -> 122318.43 | ... AC28: =+[2]Resumen!AC28*1000 -> 0
D29: Domingo | E29: 4 | F29: =+[2]Resumen!F29*1000 -> 0 | G29: =+[2]Resumen!G29*1000 -> 0 | H29: =+[2]Resumen!H29*1000 -> 0 | I29: =+[2]Resumen!I29*1000 -> 0 | J29: =+[2]Resumen!J29*1000 -> 0 | K29: =+[2]Resumen!K29*1000 -> 0 | L29: =+[2]Resumen!L29*1000 -> 0 | M29: =+[2]Resumen!M29*1000 -> 76696.802 | ... AC29: =+[2]Resumen!AC29*1000 -> 0
D30: Festivo | E30: 1 | F30: =+[2]Resumen!F30*1000 -> 0 | G30: =+[2]Resumen!G30*1000 -> 0 | H30: =+[2]Resumen!H30*1000 -> 0 | I30: =+[2]Resumen!I30*1000 -> 0 | J30: =+[2]Resumen!J30*1000 -> 0 | K30: =+[2]Resumen!K30*1000 -> 0 | L30: =+[2]Resumen!L30*1000 -> 0 | M30: =+[2]Resumen!M30*1000 -> 73582.441 | ... AC30: =+[2]Resumen!AC30*1000 -> 0
C31: Jul | D31: Ordinario | E31: 20 | F31: =+[2]Resumen!F31*1000 -> 0 | G31: =+[2]Resumen!G31*1000 -> 0 | H31: =+[2]Resumen!H31*1000 -> 0 | I31: =+[2]Resumen!I31*1000 -> 0 | J31: =+[2]Resumen!J31*1000 -> 0 | K31: =+[2]Resumen!K31*1000 -> 0 | L31: =+[2]Resumen!L31*1000 -> 0 | M31: =+[2]Resumen!M31*1000 -> 85651.629 | ... AC31: =+[2]Resumen!AC31*1000 -> 0 | AD31: =SUM(F31:AC31)*E31+SUM(F32:AC32)*E32+SUM(F33:AC33)*E33+SUM(F34:AC34)*E34 -> 37267230
D32: Sábado | E32: 5 | F32: =+[2]Resumen!F32*1000 -> 0 | G32: =+[2]Resumen!G32*1000 -> 0 | H32: =+[2]Resumen!H32*1000 -> 0 | I32: =+[2]Resumen!I32*1000 -> 0 | J32: =+[2]Resumen!J32*1000 -> 0 | K32: =+[2]Resumen!K32*1000 -> 0 | L32: =+[2]Resumen!L32*1000 -> 0 | M32: =+[2]Resumen!M32*1000 -> 50089.541 | ... AC32: =+[2]Resumen!AC32*1000 -> 0
D33: Domingo | E33: 4 | F33: =+[2]Resumen!F33*1000 -> 0 | G33: =+[2]Resumen!G33*1000 -> 0 | H33: =+[2]Resumen!H33*1000 -> 0 | I33: =+[2]Resumen!I33*1000 -> 0 | J33: =+[2]Resumen!J33*1000 -> 0 | K33: =+[2]Resumen!K33*1000 -> 0 | L33: =+[2]Resumen!L33*1000 -> 0 | M33: =+[2]Resumen!M33*1000 -> 14959.72 | ... AC33: =+[2]Resumen!AC33*1000 -> 0
D34: Festivo | E34: 2 | F34: =+[2]Resumen!F34*1000 -> 0 | G34: =+[2]Resumen!G34*1000 -> 0 | H34: =+[2]Resumen!H34*1000 -> 0 | I34: =+[2]Resumen!I34*1000 -> 0 | J34: =+[2]Resumen!J34*1000 -> 0 | K34: =+[2]Resumen!K34*1000 -> 0 | L34: =+[2]Resumen!L34*1000 -> 0 | M34: =+[2]Resumen!M34*1000 -> 13631 | ... AC34: =+[2]Resumen!AC34*1000 -> 0
C35: Ago | D35: Ordinario | E35: 21 | F35: =+[2]Resumen!F35*1000 -> 0 | G35: =+[2]Resumen!G35*1000 -> 0 | H35: =+[2]Resumen!H35*1000 -> 0 | I35: =+[2]Resumen!I35*1000 -> 0 | J35: =+[2]Resumen!J35*1000 -> 0 | K35: =+[2]Resumen!K35*1000 -> 0 | L35: =+[2]Resumen!L35*1000 -> 0 | M35: =+[2]Resumen!M35*1000 -> 91789.702 | ... AC35: =+[2]Resumen!AC35*1000 -> 0 | AD35: =SUM(F35:AC35)*E35+SUM(F36:AC36)*E36+SUM(F37:AC37)*E37+SUM(F38:AC38)*E38 -> 37886274
D36: Sábado | E36: 3 | F36: =+[2]Resumen!F36*1000 -> 0 | G36: =+[2]Resumen!G36*1000 -> 0 | H36: =+[2]Resumen!H36*1000 -> 0 | I36: =+[2]Resumen!I36*1000 -> 0 | J36: =+[2]Resumen!J36*1000 -> 0 | K36: =+[2]Resumen!K36*1000 -> 0 | L36: =+[2]Resumen!L36*1000 -> 0 | M36: =+[2]Resumen!M36*1000 -> 62455.727 | ... AC36: =+[2]Resumen!AC36*1000 -> 0
D37: Domingo | E37: 5 | F37: =+[2]Resumen!F37*1000 -> 0 | G37: =+[2]Resumen!G37*1000 -> 0 | H37: =+[2]Resumen!H37*1000 -> 0 | I37: =+[2]Resumen!I37*1000 -> 0 | J37: =+[2]Resumen!J37*1000 -> 0 | K37: =+[2]Resumen!K37*1000 -> 0 | L37: =+[2]Resumen!L37*1000 -> 0 | M37: =+[2]Resumen!M37*1000 -> 10859.535 | ... AC37: =+[2]Resumen!AC37*1000 -> 0
D38: Festivo | E38: 2 | F38: =+[2]Resumen!F38*1000 -> 0 | G38: =+[2]Resumen!G38*1000 -> 0 | H38: =+[2]Resumen!H38*1000 -> 0 | I38: =+[2]Resumen!I38*1000 -> 0 | J38: =+[2]Resumen!J38*1000 -> 0 | K38: =+[2]Resumen!K38*1000 -> 0 | L38: =+[2]Resumen!L38*1000 -> 0 | M38: =+[2]Resumen!M38*1000 -> 21023.851 | ... AC38: =+[2]Resumen!AC38*1000 -> 0
C39: Sep | D39: Ordinario | E39: 22 | F39: =+[2]Resumen!F39*1000 -> 0 | G39: =+[2]Resumen!G39*1000 -> 0 | H39: =+[2]Resumen!H39*1000 -> 0 | I39: =+[2]Resumen!I39*1000 -> 0 | J39: =+[2]Resumen!J39*1000 -> 0 | K39: =+[2]Resumen!K39*1000 -> 0 | L39: =+[2]Resumen!L39*1000 -> 0 | M39: =+[2]Resumen!M39*1000 -> 141665.41 | ... AC39: =+[2]Resumen!AC39*1000 -> 0 | AD39: =SUM(F39:AC39)*E39+SUM(F40:AC40)*E40+SUM(F41:AC41)*E41+SUM(F42:AC42)*E42 -> 54535558
D40: Sábado | E40: 4 | F40: =+[2]Resumen!F40*1000 -> 0 | G40: =+[2]Resumen!G40*1000 -> 0 | H40: =+[2]Resumen!H40*1000 -> 0 | I40: =+[2]Resumen!I40*1000 -> 0 | J40: =+[2]Resumen!J40*1000 -> 0 | K40: =+[2]Resumen!K40*1000 -> 0 | L40: =+[2]Resumen!L40*1000 -> 0 | M40: =+[2]Resumen!M40*1000 -> 109321.82 | ... AC40: =+[2]Resumen!AC40*1000 -> 0
D41: Domingo | E41: 4 | F41: =+[2]Resumen!F41*1000 -> 0 | G41: =+[2]Resumen!G41*1000 -> 0 | H41: =+[2]Resumen!H41*1000 -> 0 | I41: =+[2]Resumen!I41*1000 -> 0 | J41: =+[2]Resumen!J41*1000 -> 0 | K41: =+[2]Resumen!K41*1000 -> 0 | L41: =+[2]Resumen!L41*1000 -> 0 | M41: =+[2]Resumen!M41*1000 -> 57747.497 | ... AC41: =+[2]Resumen!AC41*1000 -> 0
D42: Festivo | E42: 0 | F42: =+[2]Resumen!F42*1000 -> 0 | G42: =+[2]Resumen!G42*1000 -> 0 | H42: =+[2]Resumen!H42*1000 -> 0 | I42: =+[2]Resumen!I42*1000 -> 0 | J42: =+[2]Resumen!J42*1000 -> 0 | K42: =+[2]Resumen!K42*1000 -> 0 | L42: =+[2]Resumen!L42*1000 -> 0 | M42: =+[2]Resumen!M42*1000 -> 0 | ... AC42: =+[2]Resumen!AC42*1000 -> 0
...

Sheet Cantidades 2028
C2: CANTIDADES DE ENERGÍA SOLICITADAS (kWh)
C3: EMPRESAS PÚBLICAS DE MEDELLÍN E.S.P.
C4: 2028
C6: Mes | D6: Tipo Día | E6: Días | F6: H1 | G6: H2 | H6: H3 | I6: H4 | J6: H5 | K6: H6 | L6: H7 | M6: H8 | N6: H9 | O6: H10 | P6: H11 | Q6: H12 | R6: H13 | S6: H14 | T6: H15 | U6: H16 | V6: H17 | W6: H18 | X6: H19 | Y6: H20 | Z6: H21 | AA6: H22 | AB6: H23 | AC6: H24 | AD6: TOTAL MES
C7: Ene | D7: Ordinario | E7: 20 | F7: =+[3]Resumen!F7*1000 -> 0 | G7: =+[3]Resumen!G7*1000 -> 0 | H7: =+[3]Resumen!H7*1000 -> 0 | I7: =+[3]Resumen!I7*1000 -> 0 | J7: =+[3]Resumen!J7*1000 -> 0 | K7: =+[3]Resumen!K7*1000 -> 0 | L7: =+[3]Resumen!L7*1000 -> 0 | M7: =+[3]Resumen!M7*1000 -> 168425.18 | ... AC7: =+[3]Resumen!AC7*1000 -> 0 | AD7: =SUM(F7:AC7)*E7+SUM(F8:AC8)*E8+SUM(F9:AC9)*E9+SUM(F10:AC10)*E10 -> 68247889
D8: Sábado | E8: 4 | F8: =+[3]Resumen!F8*1000 -> 0 | G8: =+[3]Resumen!G8*1000 -> 0 | H8: =+[3]Resumen!H8*1000 -> 0 | I8: =+[3]Resumen!I8*1000 -> 0 | J8: =+[3]Resumen!J8*1000 -> 0 | K8: =+[3]Resumen!K8*1000 -> 0 | L8: =+[3]Resumen!L8*1000 -> 0 | M8: =+[3]Resumen!M8*1000 -> 129905.08 | ... AC8: =+[3]Resumen!AC8*1000 -> 0
D9: Domingo | E9: 5 | F9: =+[3]Resumen!F9*1000 -> 0 | G9: =+[3]Resumen!G9*1000 -> 0 | H9: =+[3]Resumen!H9*1000 -> 0 | I9: =+[3]Resumen!I9*1000 -> 0 | J9: =+[3]Resumen!J9*1000 -> 0 | K9: =+[3]Resumen!K9*1000 -> 0 | L9: =+[3]Resumen!L9*1000 -> 0 | M9: =+[3]Resumen!M9*1000 -> 72772.191 | ... AC9: =+[3]Resumen!AC9*1000 -> 0
D10: Festivo | E10: 2 | F10: =+[3]Resumen!F10*1000 -> 0 | G10: =+[3]Resumen!G10*1000 -> 0 | H10: =+[3]Resumen!H10*1000 -> 0 | I10: =+[3]Resumen!I10*1000 -> 0 | J10: =+[3]Resumen!J10*1000 -> 0 | K10: =+[3]Resumen!K10*1000 -> 0 | L10: =+[3]Resumen!L10*1000 -> 0 | M10: =+[3]Resumen!M10*1000 -> 40732.415 | ... AC10: =+[3]Resumen!AC10*1000 -> 0
C11: Feb | D11: Ordinario | E11: 21 | F11: =+[3]Resumen!F11*1000 -> 0 | G11: =+[3]Resumen!G11*1000 -> 0 | H11: =+[3]Resumen!H11*1000 -> 0 | I11: =+[3]Resumen!I11*1000 -> 0 | J11: =+[3]Resumen!J11*1000 -> 0 | K11: =+[3]Resumen!K11*1000 -> 0 | L11: =+[3]Resumen!L11*1000 -> 0 | M11: =+[3]Resumen!M11*1000 -> 208505.31 | ... AC11: =+[3]Resumen!AC11*1000 -> 0 | AD11: =SUM(F11:AC11)*E11+SUM(F12:AC12)*E12+SUM(F13:AC13)*E13+SUM(F14:AC14)*E14 -> 75030960
D12: Sábado | E12: 4 | F12: =+[3]Resumen!F12*1000 -> 0 | G12: =+[3]Resumen!G12*1000 -> 0 | H12: =+[3]Resumen!H12*1000 -> 0 | I12: =+[3]Resumen!I12*1000 -> 0 | J12: =+[3]Resumen!J12*1000 -> 0 | K12: =+[3]Resumen!K12*1000 -> 0 | L12: =+[3]Resumen!L12*1000 -> 0 | M12: =+[3]Resumen!M12*1000 -> 167646.59 | ... AC12: =+[3]Resumen!AC12*1000 -> 0
D13: Domingo | E13: 4 | F13: =+[3]Resumen!F13*1000 -> 0 | G13: =+[3]Resumen!G13*1000 -> 0 | H13: =+[3]Resumen!H13*1000 -> 0 | I13: =+[3]Resumen!I13*1000 -> 0 | J13: =+[3]Resumen!J13*1000 -> 0 | K13: =+[3]Resumen!K13*1000 -> 0 | L13: =+[3]Resumen!L13*1000 -> 0 | M13: =+[3]Resumen!M13*1000 -> 90895.384 | ... AC13: =+[3]Resumen!AC13*1000 -> 0
D14: Festivo | E14: 0 | F14: =+[3]Resumen!F14*1000 -> 0 | G14: =+[3]Resumen!G14*1000 -> 0 | H14: =+[3]Resumen!H14*1000 -> 0 | I14: =+[3]Resumen!I14*1000 -> 0 | J14: =+[3]Resumen!J14*1000 -> 0 | K14: =+[3]Resumen!K14*1000 -> 0 | L14: =+[3]Resumen!L14*1000 -> 0 | M14: =+[3]Resumen!M14*1000 -> 0 | ... AC14: =+[3]Resumen!AC14*1000 -> 0
C15: Mar | D15: Ordinario | E15: 22 | F15: =+[3]Resumen!F15*1000 -> 0 | G15: =+[3]Resumen!G15*1000 -> 0 | H15: =+[3]Resumen!H15*1000 -> 0 | I15: =+[3]Resumen!I15*1000 -> 0 | J15: =+[3]Resumen!J15*1000 -> 0 | K15: =+[3]Resumen!K15*1000 -> 0 | L15: =+[3]Resumen!L15*1000 -> 0 | M15: =+[3]Resumen!M15*1000 -> 172036.49 | ... AC15: =+[3]Resumen!AC15*1000 -> 0 | AD15: =SUM(F15:AC15)*E15+SUM(F16:AC16)*E16+SUM(F17:AC17)*E17+SUM(F18:AC18)*E18 -> 68053303
D16: Sábado | E16: 4 | F16: =+[3]Resumen!F16*1000 -> 0 | G16: =+[3]Resumen!G16*1000 -> 0 | H16: =+[3]Resumen!H16*1000 -> 0 | I16: =+[3]Resumen!I16*1000 -> 0 | J16: =+[3]Resumen!J16*1000 -> 0 | K16: =+[3]Resumen!K16*1000 -> 0 | L16: =+[3]Resumen!L16*1000 -> 0 | M16: =+[3]Resumen!M16*1000 -> 141347.71 | ... AC16: =+[3]Resumen!AC16*1000 -> 0
D17: Domingo | E17: 4 | F17: =+[3]Resumen!F17*1000 -> 0 | G17: =+[3]Resumen!G17*1000 -> 0 | H17: =+[3]Resumen!H17*1000 -> 0 | I17: =+[3]Resumen!I17*1000 -> 0 | J17: =+[3]Resumen!J17*1000 -> 0 | K17: =+[3]Resumen!K17*1000 -> 0 | L17: =+[3]Resumen!L17*1000 -> 0 | M17: =+[3]Resumen!M17*1000 -> 71190.86 | ... AC17: =+[3]Resumen!AC17*1000 -> 0
D18: Festivo | E18: 1 | F18: =+[3]Resumen!F18*1000 -> 0 | G18: =+[3]Resumen!G18*1000 -> 0 | H18: =+[3]Resumen!H18*1000 -> 0 | I18: =+[3]Resumen!I18*1000 -> 0 | J18: =+[3]Resumen!J18*1000 -> 0 | K18: =+[3]Resumen!K18*1000 -> 0 | L18: =+[3]Resumen!L18*1000 -> 0 | M18: =+[3]Resumen!M18*1000 -> 88873.492 | ... AC18: =+[3]Resumen!AC18*1000 -> 0
C19: Abr | D19: Ordinario | E19: 18 | F19: =+[3]Resumen!F19*1000 -> 0 | G19: =+[3]Resumen!G19*1000 -> 0 | H19: =+[3]Resumen!H19*1000 -> 0 | I19: =+[3]Resumen!I19*1000 -> 0 | J19: =+[3]Resumen!J19*1000 -> 0 | K19: =+[3]Resumen!K19*1000 -> 0 | L19: =+[3]Resumen!L19*1000 -> 0 | M19: =+[3]Resumen!M19*1000 -> 188810.25 | ... AC19: =+[3]Resumen!AC19*1000 -> 0 | AD19: =SUM(F19:AC19)*E19+SUM(F20:AC20)*E20+SUM(F21:AC21)*E21+SUM(F22:AC22)*E22 -> 69237487
D20: Sábado | E20: 5 | F20: =+[3]Resumen!F20*1000 -> 0 | G20: =+[3]Resumen!G20*1000 -> 0 | H20: =+[3]Resumen!H20*1000 -> 0 | I20: =+[3]Resumen!I20*1000 -> 0 | J20: =+[3]Resumen!J20*1000 -> 0 | K20: =+[3]Resumen!K20*1000 -> 0 | L20: =+[3]Resumen!L20*1000 -> 0 | M20: =+[3]Resumen!M20*1000 -> 140108.81 | ... AC20: =+[3]Resumen!AC20*1000 -> 0
D21: Domingo | E21: 5 | F21: =+[3]Resumen!F21*1000 -> 0 | G21: =+[3]Resumen!G21*1000 -> 0 | H21: =+[3]Resumen!H21*1000 -> 0 | I21: =+[3]Resumen!I21*1000 -> 0 | J21: =+[3]Resumen!J21*1000 -> 0 | K21: =+[3]Resumen!K21*1000 -> 0 | L21: =+[3]Resumen!L21*1000 -> 0 | M21: =+[3]Resumen!M21*1000 -> 89864.051 | ... AC21: =+[3]Resumen!AC21*1000 -> 0
D22: Festivo | E22: 2 | F22: =+[3]Resumen!F22*1000 -> 0 | G22: =+[3]Resumen!G22*1000 -> 0 | H22: =+[3]Resumen!H22*1000 -> 0 | I22: =+[3]Resumen!I22*1000 -> 0 | J22: =+[3]Resumen!J22*1000 -> 0 | K22: =+[3]Resumen!K22*1000 -> 0 | L22: =+[3]Resumen!L22*1000 -> 0 | M22: =+[3]Resumen!M22*1000 -> 93712.848 | ... AC22: =+[3]Resumen!AC22*1000 -> 0
C23: May | D23: Ordinario | E23: 21 | F23: =+[3]Resumen!F23*1000 -> 0 | G23: =+[3]Resumen!G23*1000 -> 0 | H23: =+[3]Resumen!H23*1000 -> 0 | I23: =+[3]Resumen!I23*1000 -> 0 | J23: =+[3]Resumen!J23*1000 -> 0 | K23: =+[3]Resumen!K23*1000 -> 0 | L23: =+[3]Resumen!L23*1000 -> 0 | M23: =+[3]Resumen!M23*1000 -> 175266.64 | ... AC23: =+[3]Resumen!AC23*1000 -> 0 | AD23: =SUM(F23:AC23)*E23+SUM(F24:AC24)*E24+SUM(F25:AC25)*E25+SUM(F26:AC26)*E26 -> 67097745
D24: Sábado | E24: 4 | F24: =+[3]Resumen!F24*1000 -> 0 | G24: =+[3]Resumen!G24*1000 -> 0 | H24: =+[3]Resumen!H24*1000 -> 0 | I24: =+[3]Resumen!I24*1000 -> 0 | J24: =+[3]Resumen!J24*1000 -> 0 | K24: =+[3]Resumen!K24*1000 -> 0 | L24: =+[3]Resumen!L24*1000 -> 0 | M24: =+[3]Resumen!M24*1000 -> 130787.86 | ... AC24: =+[3]Resumen!AC24*1000 -> 0
D25: Domingo | E25: 4 | F25: =+[3]Resumen!F25*1000 -> 0 | G25: =+[3]Resumen!G25*1000 -> 0 | H25: =+[3]Resumen!H25*1000 -> 0 | I25: =+[3]Resumen!I25*1000 -> 0 | J25: =+[3]Resumen!J25*1000 -> 0 | K25: =+[3]Resumen!K25*1000 -> 0 | L25: =+[3]Resumen!L25*1000 -> 0 | M25: =+[3]Resumen!M25*1000 -> 59975.758 | ... AC25: =+[3]Resumen!AC25*1000 -> 0
D26: Festivo | E26: 2 | F26: =+[3]Resumen!F26*1000 -> 0 | G26: =+[3]Resumen!G26*1000 -> 0 | H26: =+[3]Resumen!H26*1000 -> 0 | I26: =+[3]Resumen!I26*1000 -> 0 | J26: =+[3]Resumen!J26*1000 -> 0 | K26: =+[3]Resumen!K26*1000 -> 0 | L26: =+[3]Resumen!L26*1000 -> 0 | M26: =+[3]Resumen!M26*1000 -> 89908.326 | ... AC26: =+[3]Resumen!AC26*1000 -> 0
C27: Jun | D27: Ordinario | E27: 20 | F27: =+[3]Resumen!F27*1000 -> 0 | G27: =+[3]Resumen!G27*1000 -> 0 | H27: =+[3]Resumen!H27*1000 -> 0 | I27: =+[3]Resumen!I27*1000 -> 0 | J27: =+[3]Resumen!J27*1000 -> 0 | K27: =+[3]Resumen!K27*1000 -> 0 | L27: =+[3]Resumen!L27*1000 -> 0 | M27: =+[3]Resumen!M27*1000 -> 185749 | ... AC27: =+[3]Resumen!AC27*1000 -> 0 | AD27: =SUM(F27:AC27)*E27+SUM(F28:AC28)*E28+SUM(F29:AC29)*E29+SUM(F30:AC30)*E30 -> 71045390
D28: Sábado | E28: 4 | F28: =+[3]Resumen!F28*1000 -> 0 | G28: =+[3]Resumen!G28*1000 -> 0 | H28: =+[3]Resumen!H28*1000 -> 0 | I28: =+[3]Resumen!I28*1000 -> 0 | J28: =+[3]Resumen!J28*1000 -> 0 | K28: =+[3]Resumen!K28*1000 -> 0 | L28: =+[3]Resumen!L28*1000 -> 0 | M28: =+[3]Resumen!M28*1000 -> 149350.79 | ... AC28: =+[3]Resumen!AC28*1000 -> 0
D29: Domingo | E29: 4 | F29: =+[3]Resumen!F29*1000 -> 0 | G29: =+[3]Resumen!G29*1000 -> 0 | H29: =+[3]Resumen!H29*1000 -> 0 | I29: =+[3]Resumen!I29*1000 -> 0 | J29: =+[3]Resumen!J29*1000 -> 0 | K29: =+[3]Resumen!K29*1000 -> 0 | L29: =+[3]Resumen!L29*1000 -> 0 | M29: =+[3]Resumen!M29*1000 -> 85964.165 | ... AC29: =+[3]Resumen!AC29*1000 -> 0
D30: Festivo | E30: 2 | F30: =+[3]Resumen!F30*1000 -> 0 | G30: =+[3]Resumen!G30*1000 -> 0 | H30: =+[3]Resumen!H30*1000 -> 0 | I30: =+[3]Resumen!I30*1000 -> 0 | J30: =+[3]Resumen!J30*1000 -> 0 | K30: =+[3]Resumen!K30*1000 -> 0 | L30: =+[3]Resumen!L30*1000 -> 0 | M30: =+[3]Resumen!M30*1000 -> 81695.414 | ... AC30: =+[3]Resumen!AC30*1000 -> 0
C31: Jul | D31: Ordinario | E31: 19 | F31: =+[3]Resumen!F31*1000 -> 0 | G31: =+[3]Resumen!G31*1000 -> 0 | H31: =+[3]Resumen!H31*1000 -> 0 | I31: =+[3]Resumen!I31*1000 -> 0 | J31: =+[3]Resumen!J31*1000 -> 0 | K31: =+[3]Resumen!K31*1000 -> 0 | L31: =+[3]Resumen!L31*1000 -> 0 | M31: =+[3]Resumen!M31*1000 -> 148065.8 | ... AC31: =+[3]Resumen!AC31*1000 -> 0 | AD31: =SUM(F31:AC31)*E31+SUM(F32:AC32)*E32+SUM(F33:AC33)*E33+SUM(F34:AC34)*E34 -> 61137014
D32: Sábado | E32: 5 | F32: =+[3]Resumen!F32*1000 -> 0 | G32: =+[3]Resumen!G32*1000 -> 0 | H32: =+[3]Resumen!H32*1000 -> 0 | I32: =+[3]Resumen!I32*1000 -> 0 | J32: =+[3]Resumen!J32*1000 -> 0 | K32: =+[3]Resumen!K32*1000 -> 0 | L32: =+[3]Resumen!L32*1000 -> 0 | M32: =+[3]Resumen!M32*1000 -> 107241.56 | ... AC32: =+[3]Resumen!AC32*1000 -> 0
D33: Domingo | E33: 5 | F33: =+[3]Resumen!F33*1000 -> 0 | G33: =+[3]Resumen!G33*1000 -> 0 | H33: =+[3]Resumen!H33*1000 -> 0 | I33: =+[3]Resumen!I33*1000 -> 0 | J33: =+[3]Resumen!J33*1000 -> 0 | K33: =+[3]Resumen!K33*1000 -> 0 | L33: =+[3]Resumen!L33*1000 -> 0 | M33: =+[3]Resumen!M33*1000 -> 48696.966 | ... AC33: =+[3]Resumen!AC33*1000 -> 0
D34: Festivo | E34: 2 | F34: =+[3]Resumen!F34*1000 -> 0 | G34: =+[3]Resumen!G34*1000 -> 0 | H34: =+[3]Resumen!H34*1000 -> 0 | I34: =+[3]Resumen!I34*1000 -> 0 | J34: =+[3]Resumen!J34*1000 -> 0 | K34: =+[3]Resumen!K34*1000 -> 0 | L34: =+[3]Resumen!L34*1000 -> 0 | M34: =+[3]Resumen!M34*1000 -> 52316.209 | ... AC34: =+[3]Resumen!AC34*1000 -> 0
C35: Ago | D35: Ordinario | E35: 21 | F35: =+[3]Resumen!F35*1000 -> 0 | G35: =+[3]Resumen!G35*1000 -> 0 | H35: =+[3]Resumen!H35*1000 -> 0 | I35: =+[3]Resumen!I35*1000 -> 0 | J35: =+[3]Resumen!J35*1000 -> 0 | K35: =+[3]Resumen!K35*1000 -> 0 | L35: =+[3]Resumen!L35*1000 -> 0 | M35: =+[3]Resumen!M35*1000 -> 153479.62 | ... AC35: =+[3]Resumen!AC35*1000 -> 0 | AD35: =SUM(F35:AC35)*E35+SUM(F36:AC36)*E36+SUM(F37:AC37)*E37+SUM(F38:AC38)*E38 -> 63065210
D36: Sábado | E36: 4 | F36: =+[3]Resumen!F36*1000 -> 0 | G36: =+[3]Resumen!G36*1000 -> 0 | H36: =+[3]Resumen!H36*1000 -> 0 | I36: =+[3]Resumen!I36*1000 -> 0 | J36: =+[3]Resumen!J36*1000 -> 0 | K36: =+[3]Resumen!K36*1000 -> 0 | L36: =+[3]Resumen!L36*1000 -> 0 | M36: =+[3]Resumen!M36*1000 -> 117287.74 | ... AC36: =+[3]Resumen!AC36*1000 -> 0
D37: Domingo | E37: 4 | F37: =+[3]Resumen!F37*1000 -> 0 | G37: =+[3]Resumen!G37*1000 -> 0 | H37: =+[3]Resumen!H37*1000 -> 0 | I37: =+[3]Resumen!I37*1000 -> 0 | J37: =+[3]Resumen!J37*1000 -> 0 | K37: =+[3]Resumen!K37*1000 -> 0 | L37: =+[3]Resumen!L37*1000 -> 0 | M37: =+[3]Resumen!M37*1000 -> 47984.154 | ... AC37: =+[3]Resumen!AC37*1000 -> 0
D38: Festivo | E38: 2 | F38: =+[3]Resumen!F38*1000 -> 0 | G38: =+[3]Resumen!G38*1000 -> 0 | H38: =+[3]Resumen!H38*1000 -> 0 | I38: =+[3]Resumen!I38*1000 -> 0 | J38: =+[3]Resumen!J38*1000 -> 0 | K38: =+[3]Resumen!K38*1000 -> 0 | L38: =+[3]Resumen!L38*1000 -> 0 | M38: =+[3]Resumen!M38*1000 -> 65397.829 | ... AC38: =+[3]Resumen!AC38*1000 -> 0
C39: Sep | D39: Ordinario | E39: 21 | F39: =+[3]Resumen!F39*1000 -> 0 | G39: =+[3]Resumen!G39*1000 -> 0 | H39: =+[3]Resumen!H39*1000 -> 0 | I39: =+[3]Resumen!I39*1000 -> 0 | J39: =+[3]Resumen!J39*1000 -> 0 | K39: =+[3]Resumen!K39*1000 -> 0 | L39: =+[3]Resumen!L39*1000 -> 0 | M39: =+[3]Resumen!M39*1000 -> 166896.95 | ... AC39: =+[3]Resumen!AC39*1000 -> 0 | AD39: =SUM(F39:AC39)*E39+SUM(F40:AC40)*E40+SUM(F41:AC41)*E41+SUM(F42:AC42)*E42 -> 66915979
D40: Sábado | E40: 5 | F40: =+[3]Resumen!F40*1000 -> 0 | G40: =+[3]Resumen!G40*1000 -> 0 | H40: =+[3]Resumen!H40*1000 -> 0 | I40: =+[3]Resumen!I40*1000 -> 0 | J40: =+[3]Resumen!J40*1000 -> 0 | K40: =+[3]Resumen!K40*1000 -> 0 | L40: =+[3]Resumen!L40*1000 -> 0 | M40: =+[3]Resumen!M40*1000 -> 130550.66 | ... AC40: =+[3]Resumen!AC40*1000 -> 0
D41: Domingo | E41: 4 | F41: =+[3]Resumen!F41*1000 -> 0 | G41: =+[3]Resumen!G41*1000 -> 0 | H41: =+[3]Resumen!H41*1000 -> 0 | I41: =+[3]Resumen!I41*1000 -> 0 | J41: =+[3]Resumen!J41*1000 -> 0 | K41: =+[3]Resumen!K41*1000 -> 0 | L41: =+[3]Resumen!L41*1000 -> 0 | M41: =+[3]Resumen!M41*1000 -> 55984.636 | ... AC41: =+[3]Resumen!AC41*1000 -> 0
D42: Festivo | E42: 0 | F42: =+[3]Resumen!F42*1000 -> 0 | G42: =+[3]Resumen!G42*1000 -> 0 | H42: =+[3]Resumen!H42*1000 -> 0 | I42: =+[3]Resumen!I42*1000 -> 0 | J42: =+[3]Resumen!J42*1000 -> 0 | K42: =+[3]Resumen!K42*1000 -> 0 | L42: =+[3]Resumen!L42*1000 -> 0 | M42: =+[3]Resumen!M42*1000 -> 0 | ... AC42: =+[3]Resumen!AC42*1000 -> 0
...

Sheet Cantidades 2029
C2: CANTIDADES DE ENERGÍA SOLICITADAS (kWh)
C3: EMPRESAS PÚBLICAS DE MEDELLÍN E.S.P.
C4: 2029
C6: Mes | D6: Tipo Día | E6: Días | F6: H1 | G6: H2 | H6: H3 | I6: H4 | J6: H5 | K6: H6 | L6: H7 | M6: H8 | N6: H9 | O6: H10 | P6: H11 | Q6: H12 | R6: H13 | S6: H14 | T6: H15 | U6: H16 | V6: H17 | W6: H18 | X6: H19 | Y6: H20 | Z6: H21 | AA6: H22 | AB6: H23 | AC6: H24 | AD6: TOTAL MES
C7: Ene | D7: Ordinario | E7: 21 | F7: =+[4]Resumen!F7*1000 -> 0 | G7: =+[4]Resumen!G7*1000 -> 0 | H7: =+[4]Resumen!H7*1000 -> 0 | I7: =+[4]Resumen!I7*1000 -> 0 | J7: =+[4]Resumen!J7*1000 -> 0 | K7: =+[4]Resumen!K7*1000 -> 0 | L7: =+[4]Resumen!L7*1000 -> 0 | M7: =+[4]Resumen!M7*1000 -> 114553.13 | ... AC7: =+[4]Resumen!AC7*1000 -> 0 | AD7: =SUM(F7:AC7)*E7+SUM(F8:AC8)*E8+SUM(F9:AC9)*E9+SUM(F10:AC10)*E10 -> 44246123
D8: Sábado | E8: 4 | F8: =+[4]Resumen!F8*1000 -> 0 | G8: =+[4]Resumen!G8*1000 -> 0 | H8: =+[4]Resumen!H8*1000 -> 0 | I8: =+[4]Resumen!I8*1000 -> 0 | J8: =+[4]Resumen!J8*1000 -> 0 | K8: =+[4]Resumen!K8*1000 -> 0 | L8: =+[4]Resumen!L8*1000 -> 0 | M8: =+[4]Resumen!M8*1000 -> 95389.725 | ... AC8: =+[4]Resumen!AC8*1000 -> 0
D9: Domingo | E9: 4 | F9: =+[4]Resumen!F9*1000 -> 0 | G9: =+[4]Resumen!G9*1000 -> 0 | H9: =+[4]Resumen!H9*1000 -> 0 | I9: =+[4]Resumen!I9*1000 -> 0 | J9: =+[4]Resumen!J9*1000 -> 0 | K9: =+[4]Resumen!K9*1000 -> 0 | L9: =+[4]Resumen!L9*1000 -> 0 | M9: =+[4]Resumen!M9*1000 -> 65448.185 | ... AC9: =+[4]Resumen!AC9*1000 -> 0
D10: Festivo | E10: 2 | F10: =+[4]Resumen!F10*1000 -> 0 | G10: =+[4]Resumen!G10*1000 -> 0 | H10: =+[4]Resumen!H10*1000 -> 0 | I10: =+[4]Resumen!I10*1000 -> 0 | J10: =+[4]Resumen!J10*1000 -> 0 | K10: =+[4]Resumen!K10*1000 -> 0 | L10: =+[4]Resumen!L10*1000 -> 0 | M10: =+[4]Resumen!M10*1000 -> 49729.782 | ... AC10: =+[4]Resumen!AC10*1000 -> 0
C11: Feb | D11: Ordinario | E11: 20 | F11: =+[4]Resumen!F11*1000 -> 0 | G11: =+[4]Resumen!G11*1000 -> 0 | H11: =+[4]Resumen!H11*1000 -> 0 | I11: =+[4]Resumen!I11*1000 -> 0 | J11: =+[4]Resumen!J11*1000 -> 0 | K11: =+[4]Resumen!K11*1000 -> 0 | L11: =+[4]Resumen!L11*1000 -> 0 | M11: =+[4]Resumen!M11*1000 -> 143361.84 | ... AC11: =+[4]Resumen!AC11*1000 -> 0 | AD11: =SUM(F11:AC11)*E11+SUM(F12:AC12)*E12+SUM(F13:AC13)*E13+SUM(F14:AC14)*E14 -> 47892330
D12: Sábado | E12: 4 | F12: =+[4]Resumen!F12*1000 -> 0 | G12: =+[4]Resumen!G12*1000 -> 0 | H12: =+[4]Resumen!H12*1000 -> 0 | I12: =+[4]Resumen!I12*1000 -> 0 | J12: =+[4]Resumen!J12*1000 -> 0 | K12: =+[4]Resumen!K12*1000 -> 0 | L12: =+[4]Resumen!L12*1000 -> 0 | M12: =+[4]Resumen!M12*1000 -> 125510.53 | ... AC12: =+[4]Resumen!AC12*1000 -> 0
D13: Domingo | E13: 4 | F13: =+[4]Resumen!F13*1000 -> 0 | G13: =+[4]Resumen!G13*1000 -> 0 | H13: =+[4]Resumen!H13*1000 -> 0 | I13: =+[4]Resumen!I13*1000 -> 0 | J13: =+[4]Resumen!J13*1000 -> 0 | K13: =+[4]Resumen!K13*1000 -> 0 | L13: =+[4]Resumen!L13*1000 -> 0 | M13: =+[4]Resumen!M13*1000 -> 86402.28 | ... AC13: =+[4]Resumen!AC13*1000 -> 0
D14: Festivo | E14: 0 | F14: =+[4]Resumen!F14*1000 -> 0 | G14: =+[4]Resumen!G14*1000 -> 0 | H14: =+[4]Resumen!H14*1000 -> 0 | I14: =+[4]Resumen!I14*1000 -> 0 | J14: =+[4]Resumen!J14*1000 -> 0 | K14: =+[4]Resumen!K14*1000 -> 0 | L14: =+[4]Resumen!L14*1000 -> 0 | M14: =+[4]Resumen!M14*1000 -> 0 | ... AC14: =+[4]Resumen!AC14*1000 -> 0
C15: Mar | D15: Ordinario | E15: 19 | F15: =+[4]Resumen!F15*1000 -> 0 | G15: =+[4]Resumen!G15*1000 -> 0 | H15: =+[4]Resumen!H15*1000 -> 0 | I15: =+[4]Resumen!I15*1000 -> 0 | J15: =+[4]Resumen!J15*1000 -> 0 | K15: =+[4]Resumen!K15*1000 -> 0 | L15: =+[4]Resumen!L15*1000 -> 0 | M15: =+[4]Resumen!M15*1000 -> 120819.26 | ... AC15: =+[4]Resumen!AC15*1000 -> 0 | AD15: =SUM(F15:AC15)*E15+SUM(F16:AC16)*E16+SUM(F17:AC17)*E17+SUM(F18:AC18)*E18 -> 44335232
D16: Sábado | E16: 5 | F16: =+[4]Resumen!F16*1000 -> 0 | G16: =+[4]Resumen!G16*1000 -> 0 | H16: =+[4]Resumen!H16*1000 -> 0 | I16: =+[4]Resumen!I16*1000 -> 0 | J16: =+[4]Resumen!J16*1000 -> 0 | K16: =+[4]Resumen!K16*1000 -> 0 | L16: =+[4]Resumen!L16*1000 -> 0 | M16: =+[4]Resumen!M16*1000 -> 105205.96 | ... AC16: =+[4]Resumen!AC16*1000 -> 0
D17: Domingo | E17: 4 | F17: =+[4]Resumen!F17*1000 -> 0 | G17: =+[4]Resumen!G17*1000 -> 0 | H17: =+[4]Resumen!H17*1000 -> 0 | I17: =+[4]Resumen!I17*1000 -> 0 | J17: =+[4]Resumen!J17*1000 -> 0 | K17: =+[4]Resumen!K17*1000 -> 0 | L17: =+[4]Resumen!L17*1000 -> 0 | M17: =+[4]Resumen!M17*1000 -> 68265.81 | ... AC17: =+[4]Resumen!AC17*1000 -> 0
D18: Festivo | E18: 3 | F18: =+[4]Resumen!F18*1000 -> 0 | G18: =+[4]Resumen!G18*1000 -> 0 | H18: =+[4]Resumen!H18*1000 -> 0 | I18: =+[4]Resumen!I18*1000 -> 0 | J18: =+[4]Resumen!J18*1000 -> 0 | K18: =+[4]Resumen!K18*1000 -> 0 | L18: =+[4]Resumen!L18*1000 -> 0 | M18: =+[4]Resumen!M18*1000 -> 76411.756 | ... AC18: =+[4]Resumen!AC18*1000 -> 0
C19: Abr | D19: Ordinario | E19: 21 | F19: =+[4]Resumen!F19*1000 -> 0 | G19: =+[4]Resumen!G19*1000 -> 0 | H19: =+[4]Resumen!H19*1000 -> 0 | I19: =+[4]Resumen!I19*1000 -> 0 | J19: =+[4]Resumen!J19*1000 -> 0 | K19: =+[4]Resumen!K19*1000 -> 0 | L19: =+[4]Resumen!L19*1000 -> 0 | M19: =+[4]Resumen!M19*1000 -> 124689.97 | ... AC19: =+[4]Resumen!AC19*1000 -> 0 | AD19: =SUM(F19:AC19)*E19+SUM(F20:AC20)*E20+SUM(F21:AC21)*E21+SUM(F22:AC22)*E22 -> 45269631
D20: Sábado | E20: 4 | F20: =+[4]Resumen!F20*1000 -> 0 | G20: =+[4]Resumen!G20*1000 -> 0 | H20: =+[4]Resumen!H20*1000 -> 0 | I20: =+[4]Resumen!I20*1000 -> 0 | J20: =+[4]Resumen!J20*1000 -> 0 | K20: =+[4]Resumen!K20*1000 -> 0 | L20: =+[4]Resumen!L20*1000 -> 0 | M20: =+[4]Resumen!M20*1000 -> 100767.28 | ... AC20: =+[4]Resumen!AC20*1000 -> 0
D21: Domingo | E21: 5 | F21: =+[4]Resumen!F21*1000 -> 0 | G21: =+[4]Resumen!G21*1000 -> 0 | H21: =+[4]Resumen!H21*1000 -> 0 | I21: =+[4]Resumen!I21*1000 -> 0 | J21: =+[4]Resumen!J21*1000 -> 0 | K21: =+[4]Resumen!K21*1000 -> 0 | L21: =+[4]Resumen!L21*1000 -> 0 | M21: =+[4]Resumen!M21*1000 -> 75307.149 | ... AC21: =+[4]Resumen!AC21*1000 -> 0
D22: Festivo | E22: 0 | F22: =+[4]Resumen!F22*1000 -> 0 | G22: =+[4]Resumen!G22*1000 -> 0 | H22: =+[4]Resumen!H22*1000 -> 0 | I22: =+[4]Resumen!I22*1000 -> 0 | J22: =+[4]Resumen!J22*1000 -> 0 | K22: =+[4]Resumen!K22*1000 -> 0 | L22: =+[4]Resumen!L22*1000 -> 0 | M22: =+[4]Resumen!M22*1000 -> 136024.58 | ... AC22: =+[4]Resumen!AC22*1000 -> 0
C23: May | D23: Ordinario | E23: 21 | F23: =+[4]Resumen!F23*1000 -> 0 | G23: =+[4]Resumen!G23*1000 -> 0 | H23: =+[4]Resumen!H23*1000 -> 0 | I23: =+[4]Resumen!I23*1000 -> 0 | J23: =+[4]Resumen!J23*1000 -> 0 | K23: =+[4]Resumen!K23*1000 -> 0 | L23: =+[4]Resumen!L23*1000 -> 0 | M23: =+[4]Resumen!M23*1000 -> 119458.12 | ... AC23: =+[4]Resumen!AC23*1000 -> 0 | AD23: =SUM(F23:AC23)*E23+SUM(F24:AC24)*E24+SUM(F25:AC25)*E25+SUM(F26:AC26)*E26 -> 44159243
D24: Sábado | E24: 4 | F24: =+[4]Resumen!F24*1000 -> 0 | G24: =+[4]Resumen!G24*1000 -> 0 | H24: =+[4]Resumen!H24*1000 -> 0 | I24: =+[4]Resumen!I24*1000 -> 0 | J24: =+[4]Resumen!J24*1000 -> 0 | K24: =+[4]Resumen!K24*1000 -> 0 | L24: =+[4]Resumen!L24*1000 -> 0 | M24: =+[4]Resumen!M24*1000 -> 99842.73 | ... AC24: =+[4]Resumen!AC24*1000 -> 0
D25: Domingo | E25: 4 | F25: =+[4]Resumen!F25*1000 -> 0 | G25: =+[4]Resumen!G25*1000 -> 0 | H25: =+[4]Resumen!H25*1000 -> 0 | I25: =+[4]Resumen!I25*1000 -> 0 | J25: =+[4]Resumen!J25*1000 -> 0 | K25: =+[4]Resumen!K25*1000 -> 0 | L25: =+[4]Resumen!L25*1000 -> 0 | M25: =+[4]Resumen!M25*1000 -> 64231.268 | ... AC25: =+[4]Resumen!AC25*1000 -> 0
D26: Festivo | E26: 2 | F26: =+[4]Resumen!F26*1000 -> 0 | G26: =+[4]Resumen!G26*1000 -> 0 | H26: =+[4]Resumen!H26*1000 -> 0 | I26: =+[4]Resumen!I26*1000 -> 0 | J26: =+[4]Resumen!J26*1000 -> 0 | K26: =+[4]Resumen!K26*1000 -> 0 | L26: =+[4]Resumen!L26*1000 -> 0 | M26: =+[4]Resumen!M26*1000 -> 75667.576 | ... AC26: =+[4]Resumen!AC26*1000 -> 0
C27: Jun | D27: Ordinario | E27: 19 | F27: =+[4]Resumen!F27*1000 -> 0 | G27: =+[4]Resumen!G27*1000 -> 0 | H27: =+[4]Resumen!H27*1000 -> 0 | I27: =+[4]Resumen!I27*1000 -> 0 | J27: =+[4]Resumen!J27*1000 -> 0 | K27: =+[4]Resumen!K27*1000 -> 0 | L27: =+[4]Resumen!L27*1000 -> 0 | M27: =+[4]Resumen!M27*1000 -> 127693.04 | ... AC27: =+[4]Resumen!AC27*1000 -> 0 | AD27: =SUM(F27:AC27)*E27+SUM(F28:AC28)*E28+SUM(F29:AC29)*E29+SUM(F30:AC30)*E30 -> 46032413
D28: Sábado | E28: 5 | F28: =+[4]Resumen!F28*1000 -> 0 | G28: =+[4]Resumen!G28*1000 -> 0 | H28: =+[4]Resumen!H28*1000 -> 0 | I28: =+[4]Resumen!I28*1000 -> 0 | J28: =+[4]Resumen!J28*1000 -> 0 | K28: =+[4]Resumen!K28*1000 -> 0 | L28: =+[4]Resumen!L28*1000 -> 0 | M28: =+[4]Resumen!M28*1000 -> 108874.38 | ... AC28: =+[4]Resumen!AC28*1000 -> 0
D29: Domingo | E29: 4 | F29: =+[4]Resumen!F29*1000 -> 0 | G29: =+[4]Resumen!G29*1000 -> 0 | H29: =+[4]Resumen!H29*1000 -> 0 | I29: =+[4]Resumen!I29*1000 -> 0 | J29: =+[4]Resumen!J29*1000 -> 0 | K29: =+[4]Resumen!K29*1000 -> 0 | L29: =+[4]Resumen!L29*1000 -> 0 | M29: =+[4]Resumen!M29*1000 -> 75410.409 | ... AC29: =+[4]Resumen!AC29*1000 -> 0
D30: Festivo | E30: 2 | F30: =+[4]Resumen!F30*1000 -> 0 | G30: =+[4]Resumen!G30*1000 -> 0 | H30: =+[4]Resumen!H30*1000 -> 0 | I30: =+[4]Resumen!I30*1000 -> 0 | J30: =+[4]Resumen!J30*1000 -> 0 | K30: =+[4]Resumen!K30*1000 -> 0 | L30: =+[4]Resumen!L30*1000 -> 0 | M30: =+[4]Resumen!M30*1000 -> 72955.062 | ... AC30: =+[4]Resumen!AC30*1000 -> 0
C31: Jul | D31: Ordinario | E31: 20 | F31: =+[4]Resumen!F31*1000 -> 0 | G31: =+[4]Resumen!G31*1000 -> 0 | H31: =+[4]Resumen!H31*1000 -> 0 | I31: =+[4]Resumen!I31*1000 -> 0 | J31: =+[4]Resumen!J31*1000 -> 0 | K31: =+[4]Resumen!K31*1000 -> 0 | L31: =+[4]Resumen!L31*1000 -> 0 | M31: =+[4]Resumen!M31*1000 -> 119358.97 | ... AC31: =+[4]Resumen!AC31*1000 -> 0 | AD31: =SUM(F31:AC31)*E31+SUM(F32:AC32)*E32+SUM(F33:AC33)*E33+SUM(F34:AC34)*E34 -> 45057085
D32: Sábado | E32: 4 | F32: =+[4]Resumen!F32*1000 -> 0 | G32: =+[4]Resumen!G32*1000 -> 0 | H32: =+[4]Resumen!H32*1000 -> 0 | I32: =+[4]Resumen!I32*1000 -> 0 | J32: =+[4]Resumen!J32*1000 -> 0 | K32: =+[4]Resumen!K32*1000 -> 0 | L32: =+[4]Resumen!L32*1000 -> 0 | M32: =+[4]Resumen!M32*1000 -> 98926.716 | ... AC32: =+[4]Resumen!AC32*1000 -> 0
D33: Domingo | E33: 5 | F33: =+[4]Resumen!F33*1000 -> 0 | G33: =+[4]Resumen!G33*1000 -> 0 | H33: =+[4]Resumen!H33*1000 -> 0 | I33: =+[4]Resumen!I33*1000 -> 0 | J33: =+[4]Resumen!J33*1000 -> 0 | K33: =+[4]Resumen!K33*1000 -> 0 | L33: =+[4]Resumen!L33*1000 -> 0 | M33: =+[4]Resumen!M33*1000 -> 67826.131 | ... AC33: =+[4]Resumen!AC33*1000 -> 0
D34: Festivo | E34: 2 | F34: =+[4]Resumen!F34*1000 -> 0 | G34: =+[4]Resumen!G34*1000 -> 0 | H34: =+[4]Resumen!H34*1000 -> 0 | I34: =+[4]Resumen!I34*1000 -> 0 | J34: =+[4]Resumen!J34*1000 -> 0 | K34: =+[4]Resumen!K34*1000 -> 0 | L34: =+[4]Resumen!L34*1000 -> 0 | M34: =+[4]Resumen!M34*1000 -> 70539.331 | ... AC34: =+[4]Resumen!AC34*1000 -> 0
C35: Ago | D35: Ordinario | E35: 21 | F35: =+[4]Resumen!F35*1000 -> 0 | G35: =+[4]Resumen!G35*1000 -> 0 | H35: =+[4]Resumen!H35*1000 -> 0 | I35: =+[4]Resumen!I35*1000 -> 0 | J35: =+[4]Resumen!J35*1000 -> 0 | K35: =+[4]Resumen!K35*1000 -> 0 | L35: =+[4]Resumen!L35*1000 -> 0 | M35: =+[4]Resumen!M35*1000 -> 121701.11 | ... AC35: =+[4]Resumen!AC35*1000 -> 0 | AD35: =SUM(F35:AC35)*E35+SUM(F36:AC36)*E36+SUM(F37:AC37)*E37+SUM(F38:AC38)*E38 -> 45711297
D36: Sábado | E36: 4 | F36: =+[4]Resumen!F36*1000 -> 0 | G36: =+[4]Resumen!G36*1000 -> 0 | H36: =+[4]Resumen!H36*1000 -> 0 | I36: =+[4]Resumen!I36*1000 -> 0 | J36: =+[4]Resumen!J36*1000 -> 0 | K36: =+[4]Resumen!K36*1000 -> 0 | L36: =+[4]Resumen!L36*1000 -> 0 | M36: =+[4]Resumen!M36*1000 -> 103093.56 | ... AC36: =+[4]Resumen!AC36*1000 -> 0
D37: Domingo | E37: 4 | F37: =+[4]Resumen!F37*1000 -> 0 | G37: =+[4]Resumen!G37*1000 -> 0 | H37: =+[4]Resumen!H37*1000 -> 0 | I37: =+[4]Resumen!I37*1000 -> 0 | J37: =+[4]Resumen!J37*1000 -> 0 | K37: =+[4]Resumen!K37*1000 -> 0 | L37: =+[4]Resumen!L37*1000 -> 0 | M37: =+[4]Resumen!M37*1000 -> 67117.288 | ... AC37: =+[4]Resumen!AC37*1000 -> 0
D38: Festivo | E38: 2 | F38: =+[4]Resumen!F38*1000 -> 0 | G38: =+[4]Resumen!G38*1000 -> 0 | H38: =+[4]Resumen!H38*1000 -> 0 | I38: =+[4]Resumen!I38*1000 -> 0 | J38: =+[4]Resumen!J38*1000 -> 0 | K38: =+[4]Resumen!K38*1000 -> 0 | L38: =+[4]Resumen!L38*1000 -> 0 | M38: =+[4]Resumen!M38*1000 -> 75698.385 | ... AC38: =+[4]Resumen!AC38*1000 -> 0
C39: Sep | D39: Ordinario | E39: 20 | F39: =+[4]Resumen!F39*1000 -> 0 | G39: =+[4]Resumen!G39*1000 -> 0 | H39: =+[4]Resumen!H39*1000 -> 0 | I39: =+[4]Resumen!I39*1000 -> 0 | J39: =+[4]Resumen!J39*1000 -> 0 | K39: =+[4]Resumen!K39*1000 -> 0 | L39: =+[4]Resumen!L39*1000 -> 0 | M39: =+[4]Resumen!M39*1000 -> 130323.06 | ... AC39: =+[4]Resumen!AC39*1000 -> 0 | AD39: =SUM(F39:AC39)*E39+SUM(F40:AC40)*E40+SUM(F41:AC41)*E41+SUM(F42:AC42)*E42 -> 47254069
D40: Sábado | E40: 5 | F40: =+[4]Resumen!F40*1000 -> 0 | G40: =+[4]Resumen!G40*1000 -> 0 | H40: =+[4]Resumen!H40*1000 -> 0 | I40: =+[4]Resumen!I40*1000 -> 0 | J40: =+[4]Resumen!J40*1000 -> 0 | K40: =+[4]Resumen!K40*1000 -> 0 | L40: =+[4]Resumen!L40*1000 -> 0 | M40: =+[4]Resumen!M40*1000 -> 111890 | ... AC40: =+[4]Resumen!AC40*1000 -> 0
D41: Domingo | E41: 5 | F41: =+[4]Resumen!F41*1000 -> 0 | G41: =+[4]Resumen!G41*1000 -> 0 | H41: =+[4]Resumen!H41*1000 -> 0 | I41: =+[4]Resumen!I41*1000 -> 0 | J41: =+[4]Resumen!J41*1000 -> 0 | K41: =+[4]Resumen!K41*1000 -> 0 | L41: =+[4]Resumen!L41*1000 -> 0 | M41: =+[4]Resumen!M41*1000 -> 72899.226 | ... AC41: =+[4]Resumen!AC41*1000 -> 0
D42: Festivo | E42: 0 | F42: =+[4]Resumen!F42*1000 -> 0 | G42: =+[4]Resumen!G42*1000 -> 0 | H42: =+[4]Resumen!H42*1000 -> 0 | I42: =+[4]Resumen!I42*1000 -> 0 | J42: =+[4]Resumen!J42*1000 -> 0 | K42: =+[4]Resumen!K42*1000 -> 0 | L42: =+[4]Resumen!L42*1000 -> 0 | M42: =+[4]Resumen!M42*1000 -> 0 | ... AC42: =+[4]Resumen!AC42*1000 -> 0
...

Sheet Cantidades 2030
C2: CANTIDADES DE ENERGÍA SOLICITADAS (kWh)
C3: EMPRESAS PÚBLICAS DE MEDELLÍN E.S.P.
C4: 2030
C6: Mes | D6: Tipo Día | E6: Días | F6: H1 | G6: H2 | H6: H3 | I6: H4 | J6: H5 | K6: H6 | L6: H7 | M6: H8 | N6: H9 | O6: H10 | P6: H11 | Q6: H12 | R6: H13 | S6: H14 | T6: H15 | U6: H16 | V6: H17 | W6: H18 | X6: H19 | Y6: H20 | Z6: H21 | AA6: H22 | AB6: H23 | AC6: H24 | AD6: TOTAL MES
C7: Ene | D7: Ordinario | E7: 21 | F7: =+[5]Resumen!F7*1000 -> 0 | G7: =+[5]Resumen!G7*1000 -> 0 | H7: =+[5]Resumen!H7*1000 -> 0 | I7: =+[5]Resumen!I7*1000 -> 0 | J7: =+[5]Resumen!J7*1000 -> 0 | K7: =+[5]Resumen!K7*1000 -> 0 | L7: =+[5]Resumen!L7*1000 -> 0 | M7: =+[5]Resumen!M7*1000 -> 126588.7 | ... AC7: =+[5]Resumen!AC7*1000 -> 0 | AD7: =SUM(F7:AC7)*E7+SUM(F8:AC8)*E8+SUM(F9:AC9)*E9+SUM(F10:AC10)*E10 -> 46682113
D8: Sábado | E8: 4 | F8: =+[5]Resumen!F8*1000 -> 0 | G8: =+[5]Resumen!G8*1000 -> 0 | H8: =+[5]Resumen!H8*1000 -> 0 | I8: =+[5]Resumen!I8*1000 -> 0 | J8: =+[5]Resumen!J8*1000 -> 0 | K8: =+[5]Resumen!K8*1000 -> 0 | L8: =+[5]Resumen!L8*1000 -> 0 | M8: =+[5]Resumen!M8*1000 -> 110762.83 | ... AC8: =+[5]Resumen!AC8*1000 -> 0
D9: Domingo | E9: 4 | F9: =+[5]Resumen!F9*1000 -> 0 | G9: =+[5]Resumen!G9*1000 -> 0 | H9: =+[5]Resumen!H9*1000 -> 0 | I9: =+[5]Resumen!I9*1000 -> 0 | J9: =+[5]Resumen!J9*1000 -> 0 | K9: =+[5]Resumen!K9*1000 -> 0 | L9: =+[5]Resumen!L9*1000 -> 0 | M9: =+[5]Resumen!M9*1000 -> 85315.622 | ... AC9: =+[5]Resumen!AC9*1000 -> 0
D10: Festivo | E10: 2 | F10: =+[5]Resumen!F10*1000 -> 0 | G10: =+[5]Resumen!G10*1000 -> 0 | H10: =+[5]Resumen!H10*1000 -> 0 | I10: =+[5]Resumen!I10*1000 -> 0 | J10: =+[5]Resumen!J10*1000 -> 0 | K10: =+[5]Resumen!K10*1000 -> 0 | L10: =+[5]Resumen!L10*1000 -> 0 | M10: =+[5]Resumen!M10*1000 -> 72073.408 | ... AC10: =+[5]Resumen!AC10*1000 -> 0
C11: Feb | D11: Ordinario | E11: 20 | F11: =+[5]Resumen!F11*1000 -> 0 | G11: =+[5]Resumen!G11*1000 -> 0 | H11: =+[5]Resumen!H11*1000 -> 0 | I11: =+[5]Resumen!I11*1000 -> 0 | J11: =+[5]Resumen!J11*1000 -> 0 | K11: =+[5]Resumen!K11*1000 -> 0 | L11: =+[5]Resumen!L11*1000 -> 0 | M11: =+[5]Resumen!M11*1000 -> 150231.11 | ... AC11: =+[5]Resumen!AC11*1000 -> 0 | AD11: =SUM(F11:AC11)*E11+SUM(F12:AC12)*E12+SUM(F13:AC13)*E13+SUM(F14:AC14)*E14 -> 48679337
D12: Sábado | E12: 4 | F12: =+[5]Resumen!F12*1000 -> 0 | G12: =+[5]Resumen!G12*1000 -> 0 | H12: =+[5]Resumen!H12*1000 -> 0 | I12: =+[5]Resumen!I12*1000 -> 0 | J12: =+[5]Resumen!J12*1000 -> 0 | K12: =+[5]Resumen!K12*1000 -> 0 | L12: =+[5]Resumen!L12*1000 -> 0 | M12: =+[5]Resumen!M12*1000 -> 135125.26 | ... AC12: =+[5]Resumen!AC12*1000 -> 0
D13: Domingo | E13: 4 | F13: =+[5]Resumen!F13*1000 -> 0 | G13: =+[5]Resumen!G13*1000 -> 0 | H13: =+[5]Resumen!H13*1000 -> 0 | I13: =+[5]Resumen!I13*1000 -> 0 | J13: =+[5]Resumen!J13*1000 -> 0 | K13: =+[5]Resumen!K13*1000 -> 0 | L13: =+[5]Resumen!L13*1000 -> 0 | M13: =+[5]Resumen!M13*1000 -> 102322.51 | ... AC13: =+[5]Resumen!AC13*1000 -> 0
D14: Festivo | E14: 0 | F14: =+[5]Resumen!F14*1000 -> 0 | G14: =+[5]Resumen!G14*1000 -> 0 | H14: =+[5]Resumen!H14*1000 -> 0 | I14: =+[5]Resumen!I14*1000 -> 0 | J14: =+[5]Resumen!J14*1000 -> 0 | K14: =+[5]Resumen!K14*1000 -> 0 | L14: =+[5]Resumen!L14*1000 -> 0 | M14: =+[5]Resumen!M14*1000 -> 0 | ... AC14: =+[5]Resumen!AC14*1000 -> 0
C15: Mar | D15: Ordinario | E15: 20 | F15: =+[5]Resumen!F15*1000 -> 0 | G15: =+[5]Resumen!G15*1000 -> 0 | H15: =+[5]Resumen!H15*1000 -> 0 | I15: =+[5]Resumen!I15*1000 -> 0 | J15: =+[5]Resumen!J15*1000 -> 0 | K15: =+[5]Resumen!K15*1000 -> 0 | L15: =+[5]Resumen!L15*1000 -> 0 | M15: =+[5]Resumen!M15*1000 -> 132614.74 | ... AC15: =+[5]Resumen!AC15*1000 -> 0 | AD15: =SUM(F15:AC15)*E15+SUM(F16:AC16)*E16+SUM(F17:AC17)*E17+SUM(F18:AC18)*E18 -> 47143261
D16: Sábado | E16: 5 | F16: =+[5]Resumen!F16*1000 -> 0 | G16: =+[5]Resumen!G16*1000 -> 0 | H16: =+[5]Resumen!H16*1000 -> 0 | I16: =+[5]Resumen!I16*1000 -> 0 | J16: =+[5]Resumen!J16*1000 -> 0 | K16: =+[5]Resumen!K16*1000 -> 0 | L16: =+[5]Resumen!L16*1000 -> 0 | M16: =+[5]Resumen!M16*1000 -> 119051.13 | ... AC16: =+[5]Resumen!AC16*1000 -> 0
D17: Domingo | E17: 5 | F17: =+[5]Resumen!F17*1000 -> 0 | G17: =+[5]Resumen!G17*1000 -> 0 | H17: =+[5]Resumen!H17*1000 -> 0 | I17: =+[5]Resumen!I17*1000 -> 0 | J17: =+[5]Resumen!J17*1000 -> 0 | K17: =+[5]Resumen!K17*1000 -> 0 | L17: =+[5]Resumen!L17*1000 -> 0 | M17: =+[5]Resumen!M17*1000 -> 88012.063 | ... AC17: =+[5]Resumen!AC17*1000 -> 0
D18: Festivo | E18: 1 | F18: =+[5]Resumen!F18*1000 -> 0 | G18: =+[5]Resumen!G18*1000 -> 0 | H18: =+[5]Resumen!H18*1000 -> 0 | I18: =+[5]Resumen!I18*1000 -> 0 | J18: =+[5]Resumen!J18*1000 -> 0 | K18: =+[5]Resumen!K18*1000 -> 0 | L18: =+[5]Resumen!L18*1000 -> 0 | M18: =+[5]Resumen!M18*1000 -> 94081.024 | ... AC18: =+[5]Resumen!AC18*1000 -> 0
C19: Abr | D19: Ordinario | E19: 20 | F19: =+[5]Resumen!F19*1000 -> 0 | G19: =+[5]Resumen!G19*1000 -> 0 | H19: =+[5]Resumen!H19*1000 -> 0 | I19: =+[5]Resumen!I19*1000 -> 0 | J19: =+[5]Resumen!J19*1000 -> 0 | K19: =+[5]Resumen!K19*1000 -> 0 | L19: =+[5]Resumen!L19*1000 -> 0 | M19: =+[5]Resumen!M19*1000 -> 136901.36 | ... AC19: =+[5]Resumen!AC19*1000 -> 0 | AD19: =SUM(F19:AC19)*E19+SUM(F20:AC20)*E20+SUM(F21:AC21)*E21+SUM(F22:AC22)*E22 -> 47295252
D20: Sábado | E20: 4 | F20: =+[5]Resumen!F20*1000 -> 0 | G20: =+[5]Resumen!G20*1000 -> 0 | H20: =+[5]Resumen!H20*1000 -> 0 | I20: =+[5]Resumen!I20*1000 -> 0 | J20: =+[5]Resumen!J20*1000 -> 0 | K20: =+[5]Resumen!K20*1000 -> 0 | L20: =+[5]Resumen!L20*1000 -> 0 | M20: =+[5]Resumen!M20*1000 -> 116960.82 | ... AC20: =+[5]Resumen!AC20*1000 -> 0
D21: Domingo | E21: 4 | F21: =+[5]Resumen!F21*1000 -> 0 | G21: =+[5]Resumen!G21*1000 -> 0 | H21: =+[5]Resumen!H21*1000 -> 0 | I21: =+[5]Resumen!I21*1000 -> 0 | J21: =+[5]Resumen!J21*1000 -> 0 | K21: =+[5]Resumen!K21*1000 -> 0 | L21: =+[5]Resumen!L21*1000 -> 0 | M21: =+[5]Resumen!M21*1000 -> 94564.791 | ... AC21: =+[5]Resumen!AC21*1000 -> 0
