Workbook

Sheet OF P1
C1: * La energia a ofertar debe ser expresada únicamente en kilovatio (kWh) redondeado a cero decimales
C4: OFERTA PRODUCTO 1
C5: MES | D5: ENERGIA SOLICITADA (KWh) | E5: % | F5: ENERGIA OFERTADA (KWh) | G5: PRECIO $/kWh
C6: 46388 | D6: =+VLOOKUP(C6,'CURVA P1'!$A$4:$AD$55,30,FALSE) -> 28682505 | E6: % | G6: $/kWh
C7: 46419 | D7: =+VLOOKUP(C7,'CURVA P1'!$A$4:$AD$55,30,FALSE) -> 31315340 | E7: % | G7: $/kWh
C8: 46447 | D8: =+VLOOKUP(C8,'CURVA P1'!$A$4:$AD$55,30,FALSE) -> 28669562 | E8: % | G8: $/kWh
C9: 46478 | D9: =+VLOOKUP(C9,'CURVA P1'!$A$4:$AD$55,30,FALSE) -> 30932254 | E9: % | G9: $/kWh
C10: 46508 | D10: =+VLOOKUP(C10,'CURVA P1'!$A$4:$AD$55,30,FALSE) -> 15982260 | E10: % | G10: $/kWh
C11: 46539 | D11: =+VLOOKUP(C11,'CURVA P1'!$A$4:$AD$55,30,FALSE) -> 20007543 | E11: % | G11: $/kWh
C12: 46569 | D12: =+VLOOKUP(C12,'CURVA P1'!$A$4:$AD$55,30,FALSE) -> 20327705 | E12: % | G12: $/kWh
C13: 46600 | D13: =+VLOOKUP(C13,'CURVA P1'!$A$4:$AD$55,30,FALSE) -> 17995137 | E13: % | G13: $/kWh
C14: 46631 | D14: =+VLOOKUP(C14,'CURVA P1'!$A$4:$AD$55,30,FALSE) -> 21229482 | E14: % | G14: $/kWh
C15: 46661 | D15: =+VLOOKUP(C15,'CURVA P1'!$A$4:$AD$55,30,FALSE) -> 18186273 | E15: % | G15: $/kWh
C16: 46692 | D16: =+VLOOKUP(C16,'CURVA P1'!$A$4:$AD$55,30,FALSE) -> 18888936 | E16: % | G16: $/kWh
C17: 46722 | D17: =+VLOOKUP(C17,'CURVA P1'!$A$4:$AD$55,30,FALSE) -> 31197528 | E17: % | G17: $/kWh
D18: =SUM(D6:D17) -> 283414525
D20: =D18/1000000 -> 283.41453
D21: =D20*1000 -> 283414.53

Sheet CURVA P1
A1: Curva de distribucion en kwh
A2: * La energia a ofertar debe ser expresada únicamente en kilovatio (kWh) redondeado a cero decimales
A4: TOTAL | C4: =+AD55 -> 283414525
A5: MES | B5: DÍA | C5: HORA 01 | D5: HORA 02 | E5: HORA 03 | F5: HORA 04 | G5: HORA 05 | H5: HORA 06 | I5: HORA 07 | J5: HORA 08 | K5: HORA 09 | L5: HORA 10 | M5: HORA 11 | N5: HORA 12 | O5: HORA 13 | P5: HORA 14 | Q5: HORA 15 | R5: HORA 16 | S5: HORA 17 | T5: HORA 18 | U5: HORA 19 | V5: HORA 20 | W5: HORA 21 | X5: HORA 22 | Y5: HORA 23 | Z5: HORA 24 | AA5: TOTAL DÍA | AB5: NUMERO DÍAS | AC5: TOTAL DÍA MES | AD5: TOTAL MES
A7: 46388 | B7: Hábil | C7: 41936 | D7: 39709 | E7: 37387 | F7: 35678 | G7: 35143 | H7: 36159 | I7: 36880 | J7: 32562 | K7: 34826 | L7: 35655 | M7: 36743 | N7: 37217 | O7: 33710 | P7: 41495 | Q7: 51600 | R7: 56039 | S7: 56737 | T7: 46518 | U7: 48361 | V7: 46986 | W7: 45539 | X7: 43881 | Y7: 40724 | Z7: 36486 | AA7: =SUM(C7:Z7) -> 987971 | AB7: 19 | AC7: =+AA7*AB7 -> 18771449 | AD7: =+SUM(AC7:AC10) -> 28682505
B8: Sábado | C8: 43464 | D8: 40822 | E8: 38181 | F8: 36263 | G8: 35447 | H8: 35769 | I8: 35906 | J8: 31277 | K8: 33935 | L8: 34888 | M8: 35572 | N8: 35463 | O8: 33276 | P8: 37440 | Q8: 43939 | R8: 47605 | S8: 48210 | T8: 41729 | U8: 45805 | V8: 44927 | W8: 43040 | X8: 41231 | Y8: 38949 | Z8: 35783 | AA8: =SUM(C8:Z8) -> 938921 | AB8: 5 | AC8: =+AA8*AB8 -> 4694605
B9: Domingo | C9: 42586 | D9: 40188 | E9: 37685 | F9: 35722 | G9: 34590 | H9: 34021 | I9: 33065 | J9: 24629 | K9: 23407 | L9: 22680 | M9: 21805 | N9: 21626 | O9: 22492 | P9: 26200 | Q9: 31396 | R9: 35520 | S9: 37435 | T9: 33579 | U9: 38546 | V9: 39771 | W9: 39581 | X9: 38873 | Y9: 36478 | Z9: 32732 | AA9: =SUM(C9:Z9) -> 784607 | AB9: 5 | AC9: =+AA9*AB9 -> 3923035
B10: Festivo | C10: 33803 | D10: 32240 | E10: 31165 | F10: 29911 | G10: 29304 | H10: 28755 | I10: 27179 | J10: 18387 | K10: 16889 | L10: 16116 | M10: 15943 | N10: 15741 | O10: 16454 | P10: 20501 | Q10: 25597 | R10: 29504 | S10: 30983 | T10: 29209 | U10: 34540 | V10: 35346 | W10: 34876 | X10: 33838 | Y10: 31665 | Z10: 28762 | AA10: =SUM(C10:Z10) -> 646708 | AB10: 2 | AC10: =+AA10*AB10 -> 1293416
A11: 46419 | B11: Hábil | C11: 48255 | D11: 44838 | E11: 42404 | F11: 40824 | G11: 40863 | H11: 44118 | I11: 46046 | J11: 42556 | K11: 44946 | L11: 45762 | M11: 47099 | N11: 46028 | O11: 39968 | P11: 50231 | Q11: 61617 | R11: 66255 | S11: 66560 | T11: 53158 | U11: 54013 | V11: 53529 | W11: 52433 | X11: 50020 | Y11: 45098 | Z11: 39727 | AA11: =SUM(C11:Z11) -> 1166348 | AB11: 20 | AC11: =+AA11*AB11 -> 23326960 | AD11: =+SUM(AC11:AC14) -> 31315340
B12: Sábado | C12: 46223 | D12: 42954 | E12: 40586 | F12: 39047 | G12: 38427 | H12: 39436 | I12: 41077 | J12: 38269 | K12: 41537 | L12: 42738 | M12: 43409 | N12: 42979 | O12: 39827 | P12: 43471 | Q12: 49790 | R12: 53509 | S12: 53835 | T12: 45073 | U12: 49065 | V12: 49376 | W12: 47435 | X12: 45339 | Y12: 42604 | Z12: 39047 | AA12: =SUM(C12:Z12) -> 1055053 | AB12: 4 | AC12: =+AA12*AB12 -> 4220212
B13: Domingo | C13: 47823 | D13: 44366 | E13: 41904 | F13: 39881 | G13: 38843 | H13: 38561 | I13: 38213 | J13: 30722 | K13: 29838 | L13: 29671 | M13: 29123 | N13: 29303 | O13: 30010 | P13: 33492 | Q13: 39113 | R13: 43767 | S13: 45877 | T13: 40099 | U13: 45131 | V13: 47617 | W13: 47892 | X13: 47351 | Y13: 44093 | Z13: 39352 | AA13: =SUM(C13:Z13) -> 942042 | AB13: 4 | AC13: =+AA13*AB13 -> 3768168
B14: Festivo | C14: 0 | D14: 0 | E14: 0 | F14: 0 | G14: 0 | H14: 0 | I14: 0 | J14: 0 | K14: 0 | L14: 0 | M14: 0 | N14: 0 | O14: 0 | P14: 0 | Q14: 0 | R14: 0 | S14: 0 | T14: 0 | U14: 0 | V14: 0 | W14: 0 | X14: 0 | Y14: 0 | Z14: 0 | AA14: =SUM(C14:Z14) -> 0 | AB14: 0 | AC14: =+AA14*AB14 -> 0
A15: 46447 | B15: Hábil | C15: 42438 | D15: 39189 | E15: 36930 | F15: 35294 | G15: 35134 | H15: 37302 | I15: 37693 | J15: 33501 | K15: 35187 | L15: 35414 | M15: 36192 | N15: 35473 | O15: 30763 | P15: 40390 | Q15: 51147 | R15: 55530 | S15: 56258 | T15: 44997 | U15: 46090 | V15: 45967 | W15: 45546 | X15: 44111 | Y15: 40230 | Z15: 35586 | AA15: =SUM(C15:Z15) -> 976362 | AB15: 20 | AC15: =+AA15*AB15 -> 19527240 | AD15: =+SUM(AC15:AC18) -> 28669562
B16: Sábado | C16: 44097 | D16: 40752 | E16: 38290 | F16: 36289 | G16: 35336 | H16: 35457 | I16: 35950 | J16: 32380 | K16: 34689 | L16: 35289 | M16: 35851 | N16: 35065 | O16: 32033 | P16: 36088 | Q16: 42715 | R16: 46532 | S16: 47331 | T16: 40490 | U16: 44005 | V16: 44119 | W16: 42963 | X16: 41861 | Y16: 40174 | Z16: 37247 | AA16: =SUM(C16:Z16) -> 935003 | AB16: 4 | AC16: =+AA16*AB16 -> 3740012
B17: Domingo | C17: 44800 | D17: 41474 | E17: 39117 | F17: 37202 | G17: 35997 | H17: 35170 | I17: 33915 | J17: 25618 | K17: 23974 | L17: 22599 | M17: 21167 | N17: 21019 | O17: 22106 | P17: 26056 | Q17: 31765 | R17: 36226 | S17: 38358 | T17: 33968 | U17: 38475 | V17: 41095 | W17: 41842 | X17: 41777 | Y17: 38623 | Z17: 34537 | AA17: =SUM(C17:Z17) -> 806880 | AB17: 4 | AC17: =+AA17*AB17 -> 3227520
B18: Festivo | C18: 35684 | D18: 32343 | E18: 30239 | F18: 28800 | G18: 28211 | H18: 27928 | I18: 27957 | J18: 21950 | K18: 21908 | L18: 22088 | M18: 22724 | N18: 23182 | O18: 22505 | P18: 27122 | Q18: 32133 | R18: 35252 | S18: 36386 | T18: 31475 | U18: 36690 | V18: 39243 | W18: 39433 | X18: 38220 | Y18: 33982 | Z18: 29475 | AA18: =SUM(C18:Z18) -> 724930 | AB18: 3 | AC18: =+AA18*AB18 -> 2174790
A19: 46478 | B19: Hábil | C19: 44738 | D19: 41342 | E19: 39022 | F19: 37383 | G19: 37293 | H19: 38546 | I19: 39663 | J19: 36746 | K19: 39674 | L19: 40487 | M19: 42012 | N19: 41757 | O19: 36265 | P19: 46015 | Q19: 57550 | R19: 61684 | S19: 61752 | T19: 49573 | U19: 50644 | V19: 50052 | W19: 49368 | X19: 47638 | Y19: 43601 | Z19: 38526 | AA19: =SUM(C19:Z19) -> 1071331 | AB19: 22 | AC19: =+AA19*AB19 -> 23569282 | AD19: =+SUM(AC19:AC22) -> 30932254
B20: Sábado | C20: 45959 | D20: 42639 | E20: 40181 | F20: 38169 | G20: 37405 | H20: 36598 | I20: 37816 | J20: 34278 | K20: 37566 | L20: 38497 | M20: 39438 | N20: 39246 | O20: 36403 | P20: 40429 | Q20: 46890 | R20: 50418 | S20: 50548 | T20: 43432 | U20: 46765 | V20: 45844 | W20: 44202 | X20: 42405 | Y20: 40123 | Z20: 37150 | AA20: =SUM(C20:Z20) -> 992401 | AB20: 4 | AC20: =+AA20*AB20 -> 3969604
B21: Domingo | C21: 46024 | D21: 42408 | E21: 39771 | F21: 37703 | G21: 36461 | H21: 34886 | I21: 34358 | J21: 26915 | K21: 25852 | L21: 24927 | M21: 24264 | N21: 24910 | O21: 25708 | P21: 29593 | Q21: 35350 | R21: 39547 | S21: 41275 | T21: 36260 | U21: 40882 | V21: 42756 | W21: 42279 | X21: 42018 | Y21: 39251 | Z21: 34944 | AA21: =SUM(C21:Z21) -> 848342 | AB21: 4 | AC21: =+AA21*AB21 -> 3393368
B22: Festivo | C22: 0 | D22: 0 | E22: 0 | F22: 0 | G22: 0 | H22: 0 | I22: 0 | J22: 0 | K22: 0 | L22: 0 | M22: 0 | N22: 0 | O22: 0 | P22: 0 | Q22: 0 | R22: 0 | S22: 0 | T22: 0 | U22: 0 | V22: 0 | W22: 0 | X22: 0 | Y22: 0 | Z22: 0 | AA22: =SUM(C22:Z22) -> 0 | AB22: 0 | AC22: =+AA22*AB22 -> 0
A23: 46508 | B23: Hábil | C23: 25971 | D23: 22672 | E23: 20181 | F23: 18421 | G23: 17938 | H23: 17756 | I23: 18985 | J23: 16415 | K23: 19746 | L23: 20852 | M23: 22195 | N23: 21678 | O23: 16294 | P23: 26297 | Q23: 37701 | R23: 41357 | S23: 41175 | T23: 29125 | U23: 29090 | V23: 28903 | W23: 28985 | X23: 27787 | Y23: 24090 | Z23: 19275 | AA23: =SUM(C23:Z23) -> 592889 | AB23: 19 | AC23: =+AA23*AB23 -> 11264891 | AD23: =+SUM(AC23:AC26) -> 15982260
B24: Sábado | C24: 27812 | D24: 24040 | E24: 21193 | F24: 19104 | G24: 18162 | H24: 16430 | I24: 17997 | J24: 14675 | K24: 18311 | L24: 19825 | M24: 20842 | N24: 20128 | O24: 17050 | P24: 21162 | Q24: 27367 | R24: 30343 | S24: 30298 | T24: 21870 | U24: 24743 | V24: 25107 | W24: 23712 | X24: 22510 | Y24: 20651 | Z24: 17500 | AA24: =SUM(C24:Z24) -> 520832 | AB24: 4 | AC24: =+AA24*AB24 -> 2083328
B25: Domingo | C25: 25777 | D25: 22636 | E25: 20157 | F25: 18123 | G25: 16791 | H25: 14156 | I25: 14387 | J25: 6928 | K25: 5685 | L25: 4768 | M25: 4360 | N25: 4113 | O25: 3857 | P25: 7226 | Q25: 13267 | R25: 17221 | S25: 19062 | T25: 14579 | U25: 18829 | V25: 20846 | W25: 21457 | X25: 21937 | Y25: 19902 | Z25: 16149 | AA25: =SUM(C25:Z25) -> 352213 | AB25: 5 | AC25: =+AA25*AB25 -> 1761065
B26: Festivo | C26: 18781 | D26: 15673 | E26: 13425 | F26: 11737 | G26: 10936 | H26: 9048 | I26: 9808 | J26: 3323 | K26: 3087 | L26: 3121 | M26: 3473 | N26: 3758 | O26: 3448 | P26: 7787 | Q26: 13492 | R26: 17285 | S26: 18291 | T26: 12722 | U26: 17497 | V26: 20726 | W26: 21452 | X26: 21095 | Y26: 17773 | Z26: 13254 | AA26: =SUM(C26:Z26) -> 290992 | AB26: 3 | AC26: =+AA26*AB26 -> 872976
A27: 46539 | B27: Hábil | C27: 31286 | D27: 27821 | E27: 25181 | F27: 23405 | G27: 22903 | H27: 22459 | I27: 24576 | J27: 22636 | K27: 26134 | L27: 27023 | M27: 28296 | N27: 28170 | O27: 22193 | P27: 31721 | Q27: 42634 | R27: 46573 | S27: 46747 | T27: 33484 | U27: 33371 | V27: 33627 | W27: 33190 | X27: 31780 | Y27: 28272 | Z27: 23528 | AA27: =SUM(C27:Z27) -> 717010 | AB27: 21 | AC27: =+AA27*AB27 -> 15057210 | AD27: =+SUM(AC27:AC30) -> 20007543
B28: Sábado | C28: 31749 | D28: 28374 | E28: 25788 | F28: 23828 | G28: 23155 | H28: 21544 | I28: 23565 | J28: 20851 | K28: 24143 | L28: 25131 | M28: 25833 | N28: 25103 | O28: 21516 | P28: 24946 | Q28: 32165 | R28: 36125 | S28: 36315 | T28: 27788 | U28: 30292 | V28: 30405 | W28: 28938 | X28: 27381 | Y28: 25328 | Z28: 22376 | AA28: =SUM(C28:Z28) -> 642639 | AB28: 4 | AC28: =+AA28*AB28 -> 2570556
B29: Domingo | C29: 31429 | D29: 28313 | E29: 25870 | F29: 23820 | G29: 22641 | H29: 20061 | I29: 20166 | J29: 12905 | K29: 11055 | L29: 10698 | M29: 9166 | N29: 8853 | O29: 9384 | P29: 12943 | Q29: 18574 | R29: 22719 | S29: 24962 | T29: 18999 | U29: 23179 | V29: 26378 | W29: 26897 | X29: 27392 | Y29: 25690 | Z29: 22448 | AA29: =SUM(C29:Z29) -> 484542 | AB29: 4 | AC29: =+AA29*AB29 -> 1938168
B30: Festivo | C30: 25130 | D30: 22080 | E30: 19906 | F30: 18130 | G30: 17410 | H30: 15526 | I30: 16281 | J30: 10823 | K30: 11499 | L30: 12159 | M30: 12545 | N30: 12399 | O30: 11426 | P30: 15190 | Q30: 20513 | R30: 23654 | S30: 24319 | T30: 17435 | U30: 21304 | V30: 25311 | W30: 25188 | X30: 24496 | Y30: 21546 | Z30: 17339 | AA30: =SUM(C30:Z30) -> 441609 | AB30: 1 | AC30: =+AA30*AB30 -> 441609
A31: 46569 | B31: Hábil | C31: 31940 | D31: 28554 | E31: 26115 | F31: 24191 | G31: 23596 | H31: 23743 | I31: 25212 | J31: 22579 | K31: 25865 | L31: 26753 | M31: 27994 | N31: 27034 | O31: 20994 | P31: 30308 | Q31: 41068 | R31: 44982 | S31: 44835 | T31: 32230 | U31: 31786 | V31: 32925 | W31: 32992 | X31: 31898 | Y31: 28537 | Z31: 23975 | AA31: =SUM(C31:Z31) -> 710106 | AB31: 20 | AC31: =+AA31*AB31 -> 14202120 | AD31: =+SUM(AC31:AC34) -> 20327705
B32: Sábado | C32: 30776 | D32: 27636 | E32: 25352 | F32: 23521 | G32: 22892 | H32: 21642 | I32: 22932 | J32: 19702 | K32: 22538 | L32: 23512 | M32: 23815 | N32: 23665 | O32: 20531 | P32: 24608 | Q32: 31470 | R32: 34652 | S32: 34563 | T32: 25327 | U32: 28322 | V32: 30234 | W32: 28735 | X32: 27751 | Y32: 26424 | Z32: 24011 | AA32: =SUM(C32:Z32) -> 624611 | AB32: 5 | AC32: =+AA32*AB32 -> 3123055
B33: Domingo | C33: 33347 | D33: 30079 | E33: 27445 | F33: 25491 | G33: 24167 | H33: 21969 | I33: 21810 | J33: 13358 | K33: 11925 | L33: 11177 | M33: 10016 | N33: 9341 | O33: 10086 | P33: 13882 | Q33: 19057 | R33: 23524 | S33: 25390 | T33: 21061 | U33: 24631 | V33: 27953 | W33: 28539 | X33: 28807 | Y33: 26818 | Z33: 23492 | AA33: =SUM(C33:Z33) -> 513365 | AB33: 4 | AC33: =+AA33*AB33 -> 2053460
B34: Festivo | C34: 28766 | D34: 25544 | E34: 23053 | F34: 21466 | G34: 20619 | H34: 19096 | I34: 19271 | J34: 12918 | K34: 12677 | L34: 12445 | M34: 12103 | N34: 11481 | O34: 10291 | P34: 14753 | Q34: 20254 | R34: 24137 | S34: 25197 | T34: 18250 | U34: 22370 | V34: 26396 | W34: 26454 | X34: 25621 | Y34: 22696 | Z34: 18677 | AA34: =SUM(C34:Z34) -> 474535 | AB34: 2 | AC34: =+AA34*AB34 -> 949070
A35: 46600 | B35: Hábil | C35: 28700 | D35: 25178 | E35: 22551 | F35: 20531 | G35: 19833 | H35: 19853 | I35: 20862 | J35: 18380 | K35: 21318 | L35: 22747 | M35: 24050 | N35: 23596 | O35: 17620 | P35: 27917 | Q35: 39568 | R35: 43495 | S35: 43489 | T35: 30002 | U35: 29905 | V35: 30646 | W35: 30937 | X35: 30313 | Y35: 26731 | Z35: 22238 | AA35: =SUM(C35:Z35) -> 640460 | AB35: 21 | AC35: =+AA35*AB35 -> 13449660 | AD35: =+SUM(AC35:AC38) -> 17995137
B36: Sábado | C36: 32979 | D36: 29177 | E36: 26225 | F36: 23905 | G36: 22711 | H36: 21101 | I36: 21941 | J36: 19092 | K36: 21819 | L36: 23332 | M36: 23461 | N36: 23838 | O36: 19875 | P36: 24245 | Q36: 30887 | R36: 34132 | S36: 34523 | T36: 25197 | U36: 28514 | V36: 28892 | W36: 27380 | X36: 27217 | Y36: 25949 | Z36: 23323 | AA36: =SUM(C36:Z36) -> 619715 | AB36: 3 | AC36: =+AA36*AB36 -> 1859145
B37: Domingo | C37: 30687 | D37: 27187 | E37: 24379 | F37: 22167 | G37: 20482 | H37: 17566 | I37: 16726 | J37: 9219 | K37: 7384 | L37: 5653 | M37: 5021 | N37: 3729 | O37: 4684 | P37: 9866 | Q37: 15044 | R37: 19391 | S37: 19954 | T37: 14386 | U37: 19060 | V37: 21344 | W37: 22051 | X37: 22773 | Y37: 20870 | Z37: 17455 | AA37: =SUM(C37:Z37) -> 397078 | AB37: 5 | AC37: =+AA37*AB37 -> 1985390
B38: Festivo | C38: 20835 | D38: 18133 | E38: 15882 | F38: 14412 | G38: 13667 | H38: 12325 | I38: 12059 | J38: 5552 | K38: 5450 | L38: 6232 | M38: 6525 | N38: 6941 | O38: 6560 | P38: 10815 | Q38: 16480 | R38: 20676 | S38: 21517 | T38: 13713 | U38: 18716 | V38: 21970 | W38: 22265 | X38: 23214 | Y38: 20686 | Z38: 15846 | AA38: =SUM(C38:Z38) -> 350471 | AB38: 2 | AC38: =+AA38*AB38 -> 700942
A39: 46631 | B39: Hábil | C39: 33068 | D39: 29195 | E39: 26318 | F39: 24086 | G39: 23261 | H39: 23190 | I39: 24533 | J39: 22457 | K39: 25696 | L39: 27313 | M39: 28920 | N39: 28526 | O39: 22826 | P39: 33661 | Q39: 44816 | R39: 48512 | S39: 47791 | T39: 34928 | U39: 35688 | V39: 34632 | W39: 34718 | X39: 34058 | Y39: 30569 | Z39: 25367 | AA39: =SUM(C39:Z39) -> 744129 | AB39: 22 | AC39: =+AA39*AB39 -> 16370838 | AD39: =+SUM(AC39:AC42) -> 21229482
B40: Sábado | C40: 34099 | D40: 30556 | E40: 27760 | F40: 25488 | G40: 24364 | H40: 22633 | I40: 24067 | J40: 21825 | K40: 25507 | L40: 26645 | M40: 27848 | N40: 27766 | O40: 24098 | P40: 28784 | Q40: 35777 | R40: 39005 | S40: 38711 | T40: 30611 | U40: 34288 | V40: 32884 | W40: 30932 | X40: 29783 | Y40: 28049 | Z40: 25383 | AA40: =SUM(C40:Z40) -> 696863 | AB40: 4 | AC40: =+AA40*AB40 -> 2787452
B41: Domingo | C41: 33360 | D41: 30008 | E41: 27450 | F41: 25378 | G41: 23862 | H41: 21748 | I41: 21517 | J41: 13764 | K41: 11897 | L41: 10216 | M41: 9945 | N41: 10182 | O41: 9970 | P41: 14624 | Q41: 21184 | R41: 25054 | S41: 26439 | T41: 20987 | U41: 25950 | V41: 27619 | W41: 28494 | X41: 28995 | Y41: 26602 | Z41: 22553 | AA41: =SUM(C41:Z41) -> 517798 | AB41: 4 | AC41: =+AA41*AB41 -> 2071192
B42: Festivo | C42: 0 | D42: 0 | E42: 0 | F42: 0 | G42: 0 | H42: 0 | I42: 0 | J42: 0 | K42: 0 | L42: 0 | M42: 0 | N42: 0 | O42: 0 | P42: 0 | Q42: 0 | R42: 0 | S42: 0 | T42: 0 | U42: 0 | V42: 0 | W42: 0 | X42: 0 | Y42: 0 | Z42: 0 | AA42: =SUM(C42:Z42) -> 0 | AB42: 0 | AC42: =+AA42*AB42 -> 0
...

Sheet OF P2 
C1: * La energia a ofertar debe ser expresada únicamente en kilovatio (kWh) redondeado a cero decimales - PLANA
C4: OFERTA PRODUCTO 2
C5: MES | D5: ENERGIA SOLICITADA (KWh) | E5: % | F5: ENERGIA OFERTADA (KWh) | G5: PRECIO $/kWh
C6: 46388 | D6: =+VLOOKUP(C6,'PLANA P2 '!$A$4:$AD$55,30,FALSE) -> 20832000 | E6: % | G6: $/kWh
C7: 46419 | D7: =+VLOOKUP(C7,'PLANA P2 '!$A$4:$AD$55,30,FALSE) -> 18816000
C8: 46447 | D8: =+VLOOKUP(C8,'PLANA P2 '!$A$4:$AD$55,30,FALSE) -> 20832000
C9: 46478 | D9: =+VLOOKUP(C9,'PLANA P2 '!$A$4:$AD$55,30,FALSE) -> 20160000
C10: 46508 | D10: =+VLOOKUP(C10,'PLANA P2 '!$A$4:$AD$55,30,FALSE) -> 20832000
C11: 46539 | D11: =+VLOOKUP(C11,'PLANA P2 '!$A$4:$AD$55,30,FALSE) -> 20160000
C12: 46569 | D12: =+VLOOKUP(C12,'PLANA P2 '!$A$4:$AD$55,30,FALSE) -> 20832000
C13: 46600 | D13: =+VLOOKUP(C13,'PLANA P2 '!$A$4:$AD$55,30,FALSE) -> 20832000
C14: 46631 | D14: =+VLOOKUP(C14,'PLANA P2 '!$A$4:$AD$55,30,FALSE) -> 20160000
C15: 46661 | D15: =+VLOOKUP(C15,'PLANA P2 '!$A$4:$AD$55,30,FALSE) -> 20832000
C16: 46692 | D16: =+VLOOKUP(C16,'PLANA P2 '!$A$4:$AD$55,30,FALSE) -> 20160000
C17: 46722 | D17: =+VLOOKUP(C17,'PLANA P2 '!$A$4:$AD$55,30,FALSE) -> 20832000
D18: =SUM(D6:D17) -> 245280000
D20: =D18/1000000 -> 245.28
D21: =D20*1000 -> 245280

Sheet PLANA P2 
A1: Curva de distribucion en kwh
A2: * La energia a ofertar debe ser expresada únicamente en kilovatio (kWh) redondeado a cero decimales
A4: TOTAL | C4: =+AD55 -> 245280000
A5: MES | B5: DÍA | C5: HORA 01 | D5: HORA 02 | E5: HORA 03 | F5: HORA 04 | G5: HORA 05 | H5: HORA 06 | I5: HORA 07 | J5: HORA 08 | K5: HORA 09 | L5: HORA 10 | M5: HORA 11 | N5: HORA 12 | O5: HORA 13 | P5: HORA 14 | Q5: HORA 15 | R5: HORA 16 | S5: HORA 17 | T5: HORA 18 | U5: HORA 19 | V5: HORA 20 | W5: HORA 21 | X5: HORA 22 | Y5: HORA 23 | Z5: HORA 24 | AA5: TOTAL DÍA | AB5: NUMERO DÍAS | AC5: TOTAL DÍA MES | AD5: TOTAL MES
A7: 46388 | B7: Hábil | C7: 28000 | D7: 28000 | E7: 28000 | F7: 28000 | G7: 28000 | H7: 28000 | I7: 28000 | J7: 28000 | K7: 28000 | L7: 28000 | M7: 28000 | N7: 28000 | O7: 28000 | P7: 28000 | Q7: 28000 | R7: 28000 | S7: 28000 | T7: 28000 | U7: 28000 | V7: 28000 | W7: 28000 | X7: 28000 | Y7: 28000 | Z7: 28000 | AA7: =SUM(C7:Z7) -> 672000 | AB7: 19 | AC7: =+AA7*AB7 -> 12768000 | AD7: =+SUM(AC7:AC10) -> 20832000
B8: Sábado | C8: 28000 | D8: 28000 | E8: 28000 | F8: 28000 | G8: 28000 | H8: 28000 | I8: 28000 | J8: 28000 | K8: 28000 | L8: 28000 | M8: 28000 | N8: 28000 | O8: 28000 | P8: 28000 | Q8: 28000 | R8: 28000 | S8: 28000 | T8: 28000 | U8: 28000 | V8: 28000 | W8: 28000 | X8: 28000 | Y8: 28000 | Z8: 28000 | AA8: =SUM(C8:Z8) -> 672000 | AB8: 5 | AC8: =+AA8*AB8 -> 3360000
B9: Domingo | C9: 28000 | D9: 28000 | E9: 28000 | F9: 28000 | G9: 28000 | H9: 28000 | I9: 28000 | J9: 28000 | K9: 28000 | L9: 28000 | M9: 28000 | N9: 28000 | O9: 28000 | P9: 28000 | Q9: 28000 | R9: 28000 | S9: 28000 | T9: 28000 | U9: 28000 | V9: 28000 | W9: 28000 | X9: 28000 | Y9: 28000 | Z9: 28000 | AA9: =SUM(C9:Z9) -> 672000 | AB9: 5 | AC9: =+AA9*AB9 -> 3360000
B10: Festivo | C10: 28000 | D10: 28000 | E10: 28000 | F10: 28000 | G10: 28000 | H10: 28000 | I10: 28000 | J10: 28000 | K10: 28000 | L10: 28000 | M10: 28000 | N10: 28000 | O10: 28000 | P10: 28000 | Q10: 28000 | R10: 28000 | S10: 28000 | T10: 28000 | U10: 28000 | V10: 28000 | W10: 28000 | X10: 28000 | Y10: 28000 | Z10: 28000 | AA10: =SUM(C10:Z10) -> 672000 | AB10: 2 | AC10: =+AA10*AB10 -> 1344000
A11: 46419 | B11: Hábil | C11: 28000 | D11: 28000 | E11: 28000 | F11: 28000 | G11: 28000 | H11: 28000 | I11: 28000 | J11: 28000 | K11: 28000 | L11: 28000 | M11: 28000 | N11: 28000 | O11: 28000 | P11: 28000 | Q11: 28000 | R11: 28000 | S11: 28000 | T11: 28000 | U11: 28000 | V11: 28000 | W11: 28000 | X11: 28000 | Y11: 28000 | Z11: 28000 | AA11: =SUM(C11:Z11) -> 672000 | AB11: 20 | AC11: =+AA11*AB11 -> 13440000 | AD11: =+SUM(AC11:AC14) -> 18816000
B12: Sábado | C12: 28000 | D12: 28000 | E12: 28000 | F12: 28000 | G12: 28000 | H12: 28000 | I12: 28000 | J12: 28000 | K12: 28000 | L12: 28000 | M12: 28000 | N12: 28000 | O12: 28000 | P12: 28000 | Q12: 28000 | R12: 28000 | S12: 28000 | T12: 28000 | U12: 28000 | V12: 28000 | W12: 28000 | X12: 28000 | Y12: 28000 | Z12: 28000 | AA12: =SUM(C12:Z12) -> 672000 | AB12: 4 | AC12: =+AA12*AB12 -> 2688000
B13: Domingo | C13: 28000 | D13: 28000 | E13: 28000 | F13: 28000 | G13: 28000 | H13: 28000 | I13: 28000 | J13: 28000 | K13: 28000 | L13: 28000 | M13: 28000 | N13: 28000 | O13: 28000 | P13: 28000 | Q13: 28000 | R13: 28000 | S13: 28000 | T13: 28000 | U13: 28000 | V13: 28000 | W13: 28000 | X13: 28000 | Y13: 28000 | Z13: 28000 | AA13: =SUM(C13:Z13) -> 672000 | AB13: 4 | AC13: =+AA13*AB13 -> 2688000
B14: Festivo | AA14: =SUM(C14:Z14) -> 0 | AB14: 0 | AC14: =+AA14*AB14 -> 0
A15: 46447 | B15: Hábil | C15: 28000 | D15: 28000 | E15: 28000 | F15: 28000 | G15: 28000 | H15: 28000 | I15: 28000 | J15: 28000 | K15: 28000 | L15: 28000 | M15: 28000 | N15: 28000 | O15: 28000 | P15: 28000 | Q15: 28000 | R15: 28000 | S15: 28000 | T15: 28000 | U15: 28000 | V15: 28000 | W15: 28000 | X15: 28000 | Y15: 28000 | Z15: 28000 | AA15: =SUM(C15:Z15) -> 672000 | AB15: 20 | AC15: =+AA15*AB15 -> 13440000 | AD15: =+SUM(AC15:AC18) -> 20832000
B16: Sábado | C16: 28000 | D16: 28000 | E16: 28000 | F16: 28000 | G16: 28000 | H16: 28000 | I16: 28000 | J16: 28000 | K16: 28000 | L16: 28000 | M16: 28000 | N16: 28000 | O16: 28000 | P16: 28000 | Q16: 28000 | R16: 28000 | S16: 28000 | T16: 28000 | U16: 28000 | V16: 28000 | W16: 28000 | X16: 28000 | Y16: 28000 | Z16: 28000 | AA16: =SUM(C16:Z16) -> 672000 | AB16: 4 | AC16: =+AA16*AB16 -> 2688000
B17: Domingo | C17: 28000 | D17: 28000 | E17: 28000 | F17: 28000 | G17: 28000 | H17: 28000 | I17: 28000 | J17: 28000 | K17: 28000 | L17: 28000 | M17: 28000 | N17: 28000 | O17: 28000 | P17: 28000 | Q17: 28000 | R17: 28000 | S17: 28000 | T17: 28000 | U17: 28000 | V17: 28000 | W17: 28000 | X17: 28000 | Y17: 28000 | Z17: 28000 | AA17: =SUM(C17:Z17) -> 672000 | AB17: 4 | AC17: =+AA17*AB17 -> 2688000
B18: Festivo | C18: 28000 | D18: 28000 | E18: 28000 | F18: 28000 | G18: 28000 | H18: 28000 | I18: 28000 | J18: 28000 | K18: 28000 | L18: 28000 | M18: 28000 | N18: 28000 | O18: 28000 | P18: 28000 | Q18: 28000 | R18: 28000 | S18: 28000 | T18: 28000 | U18: 28000 | V18: 28000 | W18: 28000 | X18: 28000 | Y18: 28000 | Z18: 28000 | AA18: =SUM(C18:Z18) -> 672000 | AB18: 3 | AC18: =+AA18*AB18 -> 2016000
A19: 46478 | B19: Hábil | C19: 28000 | D19: 28000 | E19: 28000 | F19: 28000 | G19: 28000 | H19: 28000 | I19: 28000 | J19: 28000 | K19: 28000 | L19: 28000 | M19: 28000 | N19: 28000 | O19: 28000 | P19: 28000 | Q19: 28000 | R19: 28000 | S19: 28000 | T19: 28000 | U19: 28000 | V19: 28000 | W19: 28000 | X19: 28000 | Y19: 28000 | Z19: 28000 | AA19: =SUM(C19:Z19) -> 672000 | AB19: 22 | AC19: =+AA19*AB19 -> 14784000 | AD19: =+SUM(AC19:AC22) -> 20160000
B20: Sábado | C20: 28000 | D20: 28000 | E20: 28000 | F20: 28000 | G20: 28000 | H20: 28000 | I20: 28000 | J20: 28000 | K20: 28000 | L20: 28000 | M20: 28000 | N20: 28000 | O20: 28000 | P20: 28000 | Q20: 28000 | R20: 28000 | S20: 28000 | T20: 28000 | U20: 28000 | V20: 28000 | W20: 28000 | X20: 28000 | Y20: 28000 | Z20: 28000 | AA20: =SUM(C20:Z20) -> 672000 | AB20: 4 | AC20: =+AA20*AB20 -> 2688000
B21: Domingo | C21: 28000 | D21: 28000 | E21: 28000 | F21: 28000 | G21: 28000 | H21: 28000 | I21: 28000 | J21: 28000 | K21: 28000 | L21: 28000 | M21: 28000 | N21: 28000 | O21: 28000 | P21: 28000 | Q21: 28000 | R21: 28000 | S21: 28000 | T21: 28000 | U21: 28000 | V21: 28000 | W21: 28000 | X21: 28000 | Y21: 28000 | Z21: 28000 | AA21: =SUM(C21:Z21) -> 672000 | AB21: 4 | AC21: =+AA21*AB21 -> 2688000
B22: Festivo | AA22: =SUM(C22:Z22) -> 0 | AB22: 0 | AC22: =+AA22*AB22 -> 0
A23: 46508 | B23: Hábil | C23: 28000 | D23: 28000 | E23: 28000 | F23: 28000 | G23: 28000 | H23: 28000 | I23: 28000 | J23: 28000 | K23: 28000 | L23: 28000 | M23: 28000 | N23: 28000 | O23: 28000 | P23: 28000 | Q23: 28000 | R23: 28000 | S23: 28000 | T23: 28000 | U23: 28000 | V23: 28000 | W23: 28000 | X23: 28000 | Y23: 28000 | Z23: 28000 | AA23: =SUM(C23:Z23) -> 672000 | AB23: 19 | AC23: =+AA23*AB23 -> 12768000 | AD23: =+SUM(AC23:AC26) -> 20832000
B24: Sábado | C24: 28000 | D24: 28000 | E24: 28000 | F24: 28000 | G24: 28000 | H24: 28000 | I24: 28000 | J24: 28000 | K24: 28000 | L24: 28000 | M24: 28000 | N24: 28000 | O24: 28000 | P24: 28000 | Q24: 28000 | R24: 28000 | S24: 28000 | T24: 28000 | U24: 28000 | V24: 28000 | W24: 28000 | X24: 28000 | Y24: 28000 | Z24: 28000 | AA24: =SUM(C24:Z24) -> 672000 | AB24: 4 | AC24: =+AA24*AB24 -> 2688000
B25: Domingo | C25: 28000 | D25: 28000 | E25: 28000 | F25: 28000 | G25: 28000 | H25: 28000 | I25: 28000 | J25: 28000 | K25: 28000 | L25: 28000 | M25: 28000 | N25: 28000 | O25: 28000 | P25: 28000 | Q25: 28000 | R25: 28000 | S25: 28000 | T25: 28000 | U25: 28000 | V25: 28000 | W25: 28000 | X25: 28000 | Y25: 28000 | Z25: 28000 | AA25: =SUM(C25:Z25) -> 672000 | AB25: 5 | AC25: =+AA25*AB25 -> 3360000
B26: Festivo | C26: 28000 | D26: 28000 | E26: 28000 | F26: 28000 | G26: 28000 | H26: 28000 | I26: 28000 | J26: 28000 | K26: 28000 | L26: 28000 | M26: 28000 | N26: 28000 | O26: 28000 | P26: 28000 | Q26: 28000 | R26: 28000 | S26: 28000 | T26: 28000 | U26: 28000 | V26: 28000 | W26: 28000 | X26: 28000 | Y26: 28000 | Z26: 28000 | AA26: =SUM(C26:Z26) -> 672000 | AB26: 3 | AC26: =+AA26*AB26 -> 2016000
A27: 46539 | B27: Hábil | C27: 28000 | D27: 28000 | E27: 28000 | F27: 28000 | G27: 28000 | H27: 28000 | I27: 28000 | J27: 28000 | K27: 28000 | L27: 28000 | M27: 28000 | N27: 28000 | O27: 28000 | P27: 28000 | Q27: 28000 | R27: 28000 | S27: 28000 | T27: 28000 | U27: 28000 | V27: 28000 | W27: 28000 | X27: 28000 | Y27: 28000 | Z27: 28000 | AA27: =SUM(C27:Z27) -> 672000 | AB27: 21 | AC27: =+AA27*AB27 -> 14112000 | AD27: =+SUM(AC27:AC30) -> 20160000
B28: Sábado | C28: 28000 | D28: 28000 | E28: 28000 | F28: 28000 | G28: 28000 | H28: 28000 | I28: 28000 | J28: 28000 | K28: 28000 | L28: 28000 | M28: 28000 | N28: 28000 | O28: 28000 | P28: 28000 | Q28: 28000 | R28: 28000 | S28: 28000 | T28: 28000 | U28: 28000 | V28: 28000 | W28: 28000 | X28: 28000 | Y28: 28000 | Z28: 28000 | AA28: =SUM(C28:Z28) -> 672000 | AB28: 4 | AC28: =+AA28*AB28 -> 2688000
B29: Domingo | C29: 28000 | D29: 28000 | E29: 28000 | F29: 28000 | G29: 28000 | H29: 28000 | I29: 28000 | J29: 28000 | K29: 28000 | L29: 28000 | M29: 28000 | N29: 28000 | O29: 28000 | P29: 28000 | Q29: 28000 | R29: 28000 | S29: 28000 | T29: 28000 | U29: 28000 | V29: 28000 | W29: 28000 | X29: 28000 | Y29: 28000 | Z29: 28000 | AA29: =SUM(C29:Z29) -> 672000 | AB29: 4 | AC29: =+AA29*AB29 -> 2688000
B30: Festivo | C30: 28000 | D30: 28000 | E30: 28000 | F30: 28000 | G30: 28000 | H30: 28000 | I30: 28000 | J30: 28000 | K30: 28000 | L30: 28000 | M30: 28000 | N30: 28000 | O30: 28000 | P30: 28000 | Q30: 28000 | R30: 28000 | S30: 28000 | T30: 28000 | U30: 28000 | V30: 28000 | W30: 28000 | X30: 28000 | Y30: 28000 | Z30: 28000 | AA30: =SUM(C30:Z30) -> 672000 | AB30: 1 | AC30: =+AA30*AB30 -> 672000
A31: 46569 | B31: Hábil | C31: 28000 | D31: 28000 | E31: 28000 | F31: 28000 | G31: 28000 | H31: 28000 | I31: 28000 | J31: 28000 | K31: 28000 | L31: 28000 | M31: 28000 | N31: 28000 | O31: 28000 | P31: 28000 | Q31: 28000 | R31: 28000 | S31: 28000 | T31: 28000 | U31: 28000 | V31: 28000 | W31: 28000 | X31: 28000 | Y31: 28000 | Z31: 28000 | AA31: =SUM(C31:Z31) -> 672000 | AB31: 20 | AC31: =+AA31*AB31 -> 13440000 | AD31: =+SUM(AC31:AC34) -> 20832000
B32: Sábado | C32: 28000 | D32: 28000 | E32: 28000 | F32: 28000 | G32: 28000 | H32: 28000 | I32: 28000 | J32: 28000 | K32: 28000 | L32: 28000 | M32: 28000 | N32: 28000 | O32: 28000 | P32: 28000 | Q32: 28000 | R32: 28000 | S32: 28000 | T32: 28000 | U32: 28000 | V32: 28000 | W32: 28000 | X32: 28000 | Y32: 28000 | Z32: 28000 | AA32: =SUM(C32:Z32) -> 672000 | AB32: 5 | AC32: =+AA32*AB32 -> 3360000
B33: Domingo | C33: 28000 | D33: 28000 | E33: 28000 | F33: 28000 | G33: 28000 | H33: 28000 | I33: 28000 | J33: 28000 | K33: 28000 | L33: 28000 | M33: 28000 | N33: 28000 | O33: 28000 | P33: 28000 | Q33: 28000 | R33: 28000 | S33: 28000 | T33: 28000 | U33: 28000 | V33: 28000 | W33: 28000 | X33: 28000 | Y33: 28000 | Z33: 28000 | AA33: =SUM(C33:Z33) -> 672000 | AB33: 4 | AC33: =+AA33*AB33 -> 2688000
B34: Festivo | C34: 28000 | D34: 28000 | E34: 28000 | F34: 28000 | G34: 28000 | H34: 28000 | I34: 28000 | J34: 28000 | K34: 28000 | L34: 28000 | M34: 28000 | N34: 28000 | O34: 28000 | P34: 28000 | Q34: 28000 | R34: 28000 | S34: 28000 | T34: 28000 | U34: 28000 | V34: 28000 | W34: 28000 | X34: 28000 | Y34: 28000 | Z34: 28000 | AA34: =SUM(C34:Z34) -> 672000 | AB34: 2 | AC34: =+AA34*AB34 -> 1344000
A35: 46600 | B35: Hábil | C35: 28000 | D35: 28000 | E35: 28000 | F35: 28000 | G35: 28000 | H35: 28000 | I35: 28000 | J35: 28000 | K35: 28000 | L35: 28000 | M35: 28000 | N35: 28000 | O35: 28000 | P35: 28000 | Q35: 28000 | R35: 28000 | S35: 28000 | T35: 28000 | U35: 28000 | V35: 28000 | W35: 28000 | X35: 28000 | Y35: 28000 | Z35: 28000 | AA35: =SUM(C35:Z35) -> 672000 | AB35: 21 | AC35: =+AA35*AB35 -> 14112000 | AD35: =+SUM(AC35:AC38) -> 20832000
B36: Sábado | C36: 28000 | D36: 28000 | E36: 28000 | F36: 28000 | G36: 28000 | H36: 28000 | I36: 28000 | J36: 28000 | K36: 28000 | L36: 28000 | M36: 28000 | N36: 28000 | O36: 28000 | P36: 28000 | Q36: 28000 | R36: 28000 | S36: 28000 | T36: 28000 | U36: 28000 | V36: 28000 | W36: 28000 | X36: 28000 | Y36: 28000 | Z36: 28000 | AA36: =SUM(C36:Z36) -> 672000 | AB36: 3 | AC36: =+AA36*AB36 -> 2016000
B37: Domingo | C37: 28000 | D37: 28000 | E37: 28000 | F37: 28000 | G37: 28000 | H37: 28000 | I37: 28000 | J37: 28000 | K37: 28000 | L37: 28000 | M37: 28000 | N37: 28000 | O37: 28000 | P37: 28000 | Q37: 28000 | R37: 28000 | S37: 28000 | T37: 28000 | U37: 28000 | V37: 28000 | W37: 28000 | X37: 28000 | Y37: 28000 | Z37: 28000 | AA37: =SUM(C37:Z37) -> 672000 | AB37: 5 | AC37: =+AA37*AB37 -> 3360000
B38: Festivo | C38: 28000 | D38: 28000 | E38: 28000 | F38: 28000 | G38: 28000 | H38: 28000 | I38: 28000 | J38: 28000 | K38: 28000 | L38: 28000 | M38: 28000 | N38: 28000 | O38: 28000 | P38: 28000 | Q38: 28000 | R38: 28000 | S38: 28000 | T38: 28000 | U38: 28000 | V38: 28000 | W38: 28000 | X38: 28000 | Y38: 28000 | Z38: 28000 | AA38: =SUM(C38:Z38) -> 672000 | AB38: 2 | AC38: =+AA38*AB38 -> 1344000
A39: 46631 | B39: Hábil | C39: 28000 | D39: 28000 | E39: 28000 | F39: 28000 | G39: 28000 | H39: 28000 | I39: 28000 | J39: 28000 | K39: 28000 | L39: 28000 | M39: 28000 | N39: 28000 | O39: 28000 | P39: 28000 | Q39: 28000 | R39: 28000 | S39: 28000 | T39: 28000 | U39: 28000 | V39: 28000 | W39: 28000 | X39: 28000 | Y39: 28000 | Z39: 28000 | AA39: =SUM(C39:Z39) -> 672000 | AB39: 22 | AC39: =+AA39*AB39 -> 14784000 | AD39: =+SUM(AC39:AC42) -> 20160000
B40: Sábado | C40: 28000 | D40: 28000 | E40: 28000 | F40: 28000 | G40: 28000 | H40: 28000 | I40: 28000 | J40: 28000 | K40: 28000 | L40: 28000 | M40: 28000 | N40: 28000 | O40: 28000 | P40: 28000 | Q40: 28000 | R40: 28000 | S40: 28000 | T40: 28000 | U40: 28000 | V40: 28000 | W40: 28000 | X40: 28000 | Y40: 28000 | Z40: 28000 | AA40: =SUM(C40:Z40) -> 672000 | AB40: 4 | AC40: =+AA40*AB40 -> 2688000
B41: Domingo | C41: 28000 | D41: 28000 | E41: 28000 | F41: 28000 | G41: 28000 | H41: 28000 | I41: 28000 | J41: 28000 | K41: 28000 | L41: 28000 | M41: 28000 | N41: 28000 | O41: 28000 | P41: 28000 | Q41: 28000 | R41: 28000 | S41: 28000 | T41: 28000 | U41: 28000 | V41: 28000 | W41: 28000 | X41: 28000 | Y41: 28000 | Z41: 28000 | AA41: =SUM(C41:Z41) -> 672000 | AB41: 4 | AC41: =+AA41*AB41 -> 2688000
B42: Festivo | AA42: =SUM(C42:Z42) -> 0 | AB42: 0 | AC42: =+AA42*AB42 -> 0
...

Sheet OF P3
C1: * La energia a ofertar debe ser expresada únicamente en kilovatio (kWh) redondeado a cero decimales
C4: OFERTA PRODUCTO 3
C5: MES | D5: ENERGIA SOLICITADA (KWh) | E5: % | F5: ENERGIA OFERTADA (KWh) | G5: PRECIO $/kWh
C6: 46753 | D6: =+VLOOKUP(C6,'CURVA P3'!$A$4:$AD$55,30,FALSE) -> 27293590 | E6: % | G6: $/kWh
C7: 46784 | D7: =+VLOOKUP(C7,'CURVA P3'!$A$4:$AD$55,30,FALSE) -> 28327143 | E7: % | G7: $/kWh
C8: 46813 | D8: =+VLOOKUP(C8,'CURVA P3'!$A$4:$AD$55,30,FALSE) -> 27529348 | E8: % | G8: $/kWh
C9: 46844 | D9: =+VLOOKUP(C9,'CURVA P3'!$A$4:$AD$55,30,FALSE) -> 28305101 | E9: % | G9: $/kWh
C10: 46874 | D10: =+VLOOKUP(C10,'CURVA P3'!$A$4:$AD$55,30,FALSE) -> 17994946 | E10: % | G10: $/kWh
C11: 46905 | D11: =+VLOOKUP(C11,'CURVA P3'!$A$4:$AD$55,30,FALSE) -> 24728392 | E11: % | G11: $/kWh
C12: 46935 | D12: =+VLOOKUP(C12,'CURVA P3'!$A$4:$AD$55,30,FALSE) -> 19351405 | E12: % | G12: $/kWh
C13: 46966 | D13: =+VLOOKUP(C13,'CURVA P3'!$A$4:$AD$55,30,FALSE) -> 19300018 | E13: % | G13: $/kWh
C14: 46997 | D14: =+VLOOKUP(C14,'CURVA P3'!$A$4:$AD$55,30,FALSE) -> 26083915 | E14: % | G14: $/kWh
C15: 47027 | D15: =+VLOOKUP(C15,'CURVA P3'!$A$4:$AD$55,30,FALSE) -> 23052095 | E15: % | G15: $/kWh
C16: 47058 | D16: =+VLOOKUP(C16,'CURVA P3'!$A$4:$AD$55,30,FALSE) -> 16958156 | E16: % | G16: $/kWh
C17: 47088 | D17: =+VLOOKUP(C17,'CURVA P3'!$A$4:$AD$55,30,FALSE) -> 26365460 | E17: % | G17: $/kWh
D18: =SUM(D6:D17) -> 285289569
D20: =D18/1000000 -> 285.28957
D21: =D20*1000 -> 285289.57

Sheet CURVA P3
A1: Curva de distribucion en kwh
A2: * La energia a ofertar debe ser expresada únicamente en kilovatio (kWh) redondeado a cero decimales
A4: TOTAL | C4: =+AD55 -> 285289569
A5: MES | B5: DÍA | C5: HORA 01 | D5: HORA 02 | E5: HORA 03 | F5: HORA 04 | G5: HORA 05 | H5: HORA 06 | I5: HORA 07 | J5: HORA 08 | K5: HORA 09 | L5: HORA 10 | M5: HORA 11 | N5: HORA 12 | O5: HORA 13 | P5: HORA 14 | Q5: HORA 15 | R5: HORA 16 | S5: HORA 17 | T5: HORA 18 | U5: HORA 19 | V5: HORA 20 | W5: HORA 21 | X5: HORA 22 | Y5: HORA 23 | Z5: HORA 24 | AA5: TOTAL DÍA | AB5: NUMERO DÍAS | AC5: TOTAL DÍA MES | AD5: TOTAL MES
A7: 46753 | B7: Hábil | C7: 40381 | D7: 38830 | E7: 37350 | F7: 36190 | G7: 35741 | H7: 36093 | I7: 35927 | J7: 37524 | K7: 29199 | L7: 25414 | M7: 23774 | N7: 21492 | O7: 20489 | P7: 30983 | Q7: 46682 | R7: 58735 | S7: 63747 | T7: 45876 | U7: 47143 | V7: 46528 | W7: 46070 | X7: 45334 | Y7: 43279 | Z7: 40410 | AA7: =SUM(C7:Z7) -> 933191 | AB7: 20 | AC7: =+AA7*AB7 -> 18663820 | AD7: =+SUM(AC7:AC10) -> 27293590
B8: Sábado | C8: 40691 | D8: 38882 | E8: 37222 | F8: 36044 | G8: 35406 | H8: 35405 | I8: 34974 | J8: 36233 | K8: 28288 | L8: 24478 | M8: 22484 | N8: 19677 | O8: 19642 | P8: 27140 | Q8: 40046 | R8: 51567 | S8: 56624 | T8: 42516 | U8: 45310 | V8: 44826 | W8: 43713 | X8: 42747 | Y8: 41469 | Z8: 39382 | AA8: =SUM(C8:Z8) -> 884766 | AB8: 4 | AC8: =+AA8*AB8 -> 3539064
B9: Domingo | C9: 40069 | D9: 38431 | E9: 36854 | F9: 35626 | G9: 34901 | H9: 34414 | I9: 33411 | J9: 31183 | K9: 19904 | L9: 14703 | M9: 11470 | N9: 8601 | O9: 11053 | P9: 18213 | Q9: 30161 | R9: 42172 | S9: 48249 | T9: 37477 | U9: 40860 | V9: 41934 | W9: 42086 | X9: 41887 | Y9: 40352 | Z9: 37755 | AA9: =SUM(C9:Z9) -> 771766 | AB9: 5 | AC9: =+AA9*AB9 -> 3858830
B10: Festivo | C10: 31909 | D10: 31092 | E10: 30434 | F10: 29732 | G10: 29378 | H10: 29070 | I10: 28018 | J10: 24854 | K10: 12919 | L10: 7565 | M10: 4702 | N10: 1811 | O10: 4232 | P10: 11533 | Q10: 23225 | R10: 34920 | S10: 40783 | T10: 31718 | U10: 35624 | V10: 36315 | W10: 35920 | X10: 35090 | Y10: 33543 | Z10: 31551 | AA10: =SUM(C10:Z10) -> 615938 | AB10: 2 | AC10: =+AA10*AB10 -> 1231876
A11: 46784 | B11: Hábil | C11: 42870 | D11: 40825 | E11: 39322 | F11: 38318 | G11: 38230 | H11: 39776 | I11: 40370 | J11: 43509 | K11: 34672 | L11: 30462 | M11: 28777 | N11: 24927 | O11: 22238 | P11: 34555 | Q11: 51559 | R11: 64140 | S11: 69227 | T11: 48664 | U11: 49068 | V11: 48865 | W11: 48683 | X11: 47472 | Y11: 44563 | Z11: 41191 | AA11: =SUM(C11:Z11) -> 1012283 | AB11: 21 | AC11: =+AA11*AB11 -> 21257943 | AD11: =+SUM(AC11:AC14) -> 28327143
B12: Sábado | C12: 40517 | D12: 38768 | E12: 37390 | F12: 36560 | G12: 36256 | H12: 36769 | I12: 37072 | J12: 39866 | K12: 31709 | L12: 27668 | M12: 25476 | N12: 22301 | O12: 21444 | P12: 28565 | Q12: 41721 | R12: 53693 | S12: 58931 | T12: 43263 | U12: 45854 | V12: 46030 | W12: 45085 | X12: 44083 | Y12: 42642 | Z12: 40409 | AA12: =SUM(C12:Z12) -> 922072 | AB12: 4 | AC12: =+AA12*AB12 -> 3688288
B13: Domingo | C13: 41898 | D13: 39899 | E13: 38430 | F13: 37195 | G13: 36570 | H13: 36227 | I13: 35433 | J13: 34179 | K13: 22490 | L13: 17610 | M13: 14653 | N13: 12150 | O13: 14619 | P13: 21578 | Q13: 34044 | R13: 46765 | S13: 53319 | T13: 40587 | U13: 43883 | V13: 45660 | W13: 46278 | X13: 46292 | Y13: 44305 | Z13: 41164 | AA13: =SUM(C13:Z13) -> 845228 | AB13: 4 | AC13: =+AA13*AB13 -> 3380912
B14: Festivo | C14: 0 | D14: 0 | E14: 0 | F14: 0 | G14: 0 | H14: 0 | I14: 0 | J14: 0 | K14: 0 | L14: 0 | M14: 0 | N14: 0 | O14: 0 | P14: 0 | Q14: 0 | R14: 0 | S14: 0 | T14: 0 | U14: 0 | V14: 0 | W14: 0 | X14: 0 | Y14: 0 | Z14: 0 | AB14: 0 | AC14: =+AA14*AB14 -> 0
A15: 46813 | B15: Hábil | C15: 40616 | D15: 38559 | E15: 37070 | F15: 35924 | G15: 35595 | H15: 36269 | I15: 36247 | J15: 38148 | K15: 29340 | L15: 24885 | M15: 22915 | N15: 19597 | O15: 17897 | P15: 29600 | Q15: 45570 | R15: 57472 | S15: 62574 | T15: 44023 | U15: 44718 | V15: 44772 | W15: 45018 | X15: 44631 | Y15: 42584 | Z15: 39711 | AA15: =SUM(C15:Z15) -> 913735 | AB15: 22 | AC15: =+AA15*AB15 -> 20102170 | AD15: =+SUM(AC15:AC18) -> 27529348
B16: Sábado | C16: 42048 | D16: 39913 | E16: 38269 | F16: 36940 | G16: 36198 | H16: 35983 | I16: 35842 | J16: 37438 | K16: 29120 | L16: 24851 | M16: 22742 | N16: 19251 | O16: 18623 | P16: 26212 | Q16: 39317 | R16: 50859 | S16: 55982 | T16: 41959 | U16: 44166 | V16: 44253 | W16: 43718 | X16: 43472 | Y16: 42708 | Z16: 40857 | AA16: =SUM(C16:Z16) -> 890721 | AB16: 4 | AC16: =+AA16*AB16 -> 3562884
B17: Domingo | C17: 42322 | D17: 40378 | E17: 38862 | F17: 37665 | G17: 36863 | H17: 36061 | I17: 34892 | J17: 32257 | K17: 20607 | L17: 14908 | M17: 11326 | N17: 8600 | O17: 11174 | P17: 18525 | Q17: 31028 | R17: 43118 | S17: 49228 | T17: 38252 | U17: 40969 | V17: 42936 | W17: 44121 | X17: 44765 | Y17: 43004 | Z17: 40209 | AA17: =SUM(C17:Z17) -> 802070 | AB17: 4 | AC17: =+AA17*AB17 -> 3208280
B18: Festivo | C18: 32207 | D18: 30431 | E18: 29297 | F18: 28526 | G18: 28168 | H18: 28056 | I18: 27862 | J18: 27344 | K18: 16796 | L18: 12123 | M18: 9854 | N18: 7223 | O18: 8201 | P18: 15832 | Q18: 27564 | R18: 38783 | S18: 44351 | T18: 32205 | U18: 35664 | V18: 37218 | W18: 37222 | X18: 36351 | Y18: 33756 | Z18: 30980 | AA18: =SUM(C18:Z18) -> 656014 | AB18: 1 | AC18: =+AA18*AB18 -> 656014
A19: 46844 | B19: Hábil | C19: 42251 | D19: 40116 | E19: 38632 | F19: 37531 | G19: 37382 | H19: 37986 | I19: 38280 | J19: 41997 | K19: 34259 | L19: 30217 | M19: 28909 | N19: 25860 | O19: 23031 | P19: 35142 | Q19: 52281 | R19: 64352 | S19: 69036 | T19: 48576 | U19: 49237 | V19: 49001 | W19: 49091 | X19: 48272 | Y19: 45680 | Z19: 42294 | AA19: =SUM(C19:Z19) -> 1009413 | AB19: 18 | AC19: =+AA19*AB19 -> 18169434 | AD19: =+SUM(AC19:AC22) -> 28305101
B20: Sábado | C20: 42575 | D20: 40498 | E20: 39036 | F20: 37755 | G20: 37139 | H20: 36514 | I20: 36830 | J20: 39519 | K20: 31984 | L20: 28047 | M20: 26093 | N20: 23435 | O20: 22751 | P20: 30343 | Q20: 43469 | R20: 55054 | S20: 59745 | T20: 44135 | U20: 46268 | V20: 45813 | W20: 45034 | X20: 44138 | Y20: 42759 | Z20: 40691 | AA20: =SUM(C20:Z20) -> 939625 | AB20: 5 | AC20: =+AA20*AB20 -> 4698125
B21: Domingo | C21: 42311 | D21: 40160 | E21: 38594 | F21: 37293 | G21: 36472 | H21: 35353 | I21: 34661 | J21: 33565 | K21: 22264 | L21: 17004 | M21: 13943 | N21: 11610 | O21: 14094 | P21: 21495 | Q21: 34013 | R21: 46062 | S21: 52016 | T21: 39573 | U21: 42808 | V21: 44279 | W21: 44357 | X21: 44521 | Y21: 42740 | Z21: 39646 | AA21: =SUM(C21:Z21) -> 828834 | AB21: 5 | AC21: =+AA21*AB21 -> 4144170
B22: Festivo | C22: 36283 | D22: 34415 | E22: 33077 | F22: 32111 | G22: 31464 | H22: 30545 | I22: 30181 | J22: 27585 | K22: 14675 | L22: 7911 | M22: 4149 | N22: 1400 | O22: 4143 | P22: 11448 | Q22: 23933 | R22: 35584 | S22: 41974 | T22: 32135 | U22: 35697 | V22: 36808 | W22: 36569 | X22: 36216 | Y22: 35126 | Z22: 33257 | AA22: =SUM(C22:Z22) -> 646686 | AB22: 2 | AC22: =+AA22*AB22 -> 1293372
A23: 46874 | B23: Hábil | C23: 23668 | D23: 22666 | E23: 21876 | F23: 21331 | G23: 21145 | H23: 21016 | I23: 32249 | J23: 33232 | K23: 26541 | L23: 22326 | M23: 19929 | N23: 17106 | O23: 15898 | P23: 24428 | Q23: 36457 | R23: 45227 | S23: 37849 | T23: 23920 | U23: 24129 | V23: 24166 | W23: 24306 | X23: 24052 | Y23: 22946 | Z23: 21337 | AA23: =SUM(C23:Z23) -> 607800 | AB23: 21 | AC23: =+AA23*AB23 -> 12763800 | AD23: =+SUM(AC23:AC26) -> 17994946
B24: Sábado | C24: 24347 | D24: 23101 | E24: 22119 | F24: 21454 | G24: 21115 | H24: 20607 | I24: 31874 | J24: 32317 | K24: 25756 | L24: 21749 | M24: 19130 | N24: 16112 | O24: 15692 | P24: 21749 | Q24: 31443 | R24: 40024 | S24: 32823 | T24: 21242 | U24: 22523 | V24: 22688 | W24: 22294 | X24: 21987 | Y24: 21451 | Z24: 20433 | AA24: =SUM(C24:Z24) -> 574030 | AB24: 4 | AC24: =+AA24*AB24 -> 2296120
B25: Domingo | C25: 23338 | D25: 22412 | E25: 21688 | F25: 21043 | G25: 20594 | H25: 19836 | I25: 30701 | J25: 29034 | K25: 20218 | L25: 15003 | M25: 11930 | N25: 9204 | O25: 10217 | P25: 15851 | Q25: 25483 | R25: 34316 | S25: 27786 | T25: 18523 | U25: 20201 | V25: 20988 | W25: 21294 | X25: 21566 | Y25: 20940 | Z25: 19655 | AA25: =SUM(C25:Z25) -> 501821 | AB25: 4 | AC25: =+AA25*AB25 -> 2007284
B26: Festivo | C26: 19984 | D26: 19097 | E26: 18458 | F26: 17986 | G26: 17764 | H26: 17244 | I26: 28424 | J26: 26963 | K26: 18568 | L26: 13898 | M26: 11145 | N26: 8645 | O26: 9504 | P26: 15668 | Q26: 25211 | R26: 34017 | S26: 27201 | T26: 17552 | U26: 19188 | V26: 20169 | W26: 20325 | X26: 20127 | Y26: 19072 | Z26: 17661 | AA26: =SUM(C26:Z26) -> 463871 | AB26: 2 | AC26: =+AA26*AB26 -> 927742
A27: 46905 | B27: Hábil | C27: 35666 | D27: 34035 | E27: 32777 | F27: 31938 | G27: 31637 | H27: 31298 | I27: 36971 | J27: 40195 | K27: 33174 | L27: 28949 | M27: 26877 | N27: 24042 | O27: 21629 | P27: 31728 | Q27: 46098 | R27: 56639 | S27: 56157 | T27: 37569 | U27: 37881 | V27: 38112 | W27: 38060 | X27: 37525 | Y27: 35812 | Z27: 33359 | AA27: =SUM(C27:Z27) -> 858128 | AB27: 20 | AC27: =+AA27*AB27 -> 17162560 | AD27: =+SUM(AC27:AC30) -> 24728392
B28: Sábado | C28: 36234 | D28: 34697 | E28: 33412 | F28: 32485 | G28: 32121 | H28: 31333 | I28: 37064 | J28: 39522 | K28: 32237 | L28: 27927 | M28: 25668 | N28: 22508 | O28: 21561 | P28: 27718 | Q28: 39915 | R28: 50619 | S28: 50028 | T28: 35400 | U28: 36780 | V28: 36916 | W28: 36192 | X28: 35612 | Y28: 34694 | Z28: 33224 | AA28: =SUM(C28:Z28) -> 823867 | AB28: 4 | AC28: =+AA28*AB28 -> 3295468
B29: Domingo | C29: 35802 | D29: 34358 | E29: 33215 | F29: 32237 | G29: 31683 | H29: 30442 | I29: 35157 | J29: 34338 | K29: 23443 | L29: 18725 | M29: 14734 | N29: 12005 | O29: 13897 | P29: 20505 | Q29: 31753 | R29: 42500 | S29: 43330 | T29: 31388 | U29: 33906 | V29: 35515 | W29: 35843 | X29: 36278 | Y29: 35604 | Z29: 33952 | AA29: =SUM(C29:Z29) -> 730610 | AB29: 4 | AC29: =+AA29*AB29 -> 2922440
B30: Festivo | C30: 31035 | D30: 29658 | E30: 28694 | F30: 27917 | G30: 27616 | H30: 26788 | I30: 31974 | J30: 31907 | K30: 22709 | L30: 18342 | M30: 15949 | N30: 13235 | O30: 14063 | P30: 20751 | Q30: 31652 | R30: 41757 | S30: 41578 | T30: 28935 | U30: 31137 | V30: 33130 | W30: 33024 | X30: 32505 | Y30: 30902 | Z30: 28704 | AA30: =SUM(C30:Z30) -> 673962 | AB30: 2 | AC30: =+AA30*AB30 -> 1347924
A31: 46935 | B31: Hábil | C31: 26556 | D31: 25438 | E31: 24606 | F31: 23953 | G31: 23688 | H31: 23652 | I31: 34225 | J31: 35496 | K31: 28717 | L31: 24349 | M31: 22027 | N31: 18932 | O31: 17206 | P31: 25877 | Q31: 38145 | R31: 47230 | S31: 40613 | T31: 25416 | U31: 25426 | V31: 25981 | W31: 26120 | X31: 25883 | Y31: 24741 | Z31: 23032 | AA31: =SUM(C31:Z31) -> 657309 | AB31: 19 | AC31: =+AA31*AB31 -> 12488871 | AD31: =+SUM(AC31:AC34) -> 19351405
B32: Sábado | C32: 25255 | D32: 24303 | E32: 23575 | F32: 22994 | G32: 22780 | H32: 22423 | I32: 32876 | J32: 33704 | K32: 26624 | L32: 22305 | M32: 19446 | N32: 16879 | O32: 16492 | P32: 22647 | Q32: 33058 | R32: 41630 | S32: 35152 | T32: 22375 | U32: 23638 | V32: 24323 | W32: 23861 | X32: 23535 | Y32: 23047 | Z32: 22092 | AA32: =SUM(C32:Z32) -> 605014 | AB32: 5 | AC32: =+AA32*AB32 -> 3025070
B33: Domingo | C33: 26056 | D33: 25074 | E33: 24273 | F33: 23642 | G33: 23207 | H33: 22569 | I33: 32660 | J33: 30907 | K33: 21861 | L33: 16811 | M33: 13371 | N33: 10371 | O33: 11939 | P33: 17924 | Q33: 27301 | R33: 36709 | S33: 30917 | T33: 20758 | U33: 22216 | V33: 23434 | W33: 23604 | X33: 23722 | Y33: 23051 | Z33: 21949 | AA33: =SUM(C33:Z33) -> 554326 | AB33: 5 | AC33: =+AA33*AB33 -> 2771630
B34: Festivo | C34: 23851 | D34: 22832 | E34: 22060 | F34: 21569 | G34: 21311 | H34: 20856 | I34: 31078 | J34: 30245 | K34: 21859 | L34: 17085 | M34: 14070 | N34: 11213 | O34: 11636 | P34: 18055 | Q34: 27825 | R34: 36942 | S34: 31095 | T34: 19854 | U34: 21199 | V34: 22603 | W34: 22583 | X34: 22242 | Y34: 21173 | Z34: 19681 | AA34: =SUM(C34:Z34) -> 532917 | AB34: 2 | AC34: =+AA34*AB34 -> 1065834
A35: 46966 | B35: Hábil | C35: 25704 | D35: 24518 | E35: 23613 | F35: 22893 | G35: 22608 | H35: 22513 | I35: 32856 | J35: 34251 | K35: 27139 | L35: 23128 | M35: 20795 | N35: 18022 | O35: 16249 | P35: 25342 | Q35: 37922 | R35: 46999 | S35: 40875 | T35: 25987 | U35: 26161 | V35: 26494 | W35: 26741 | X35: 26596 | Y35: 25412 | Z35: 23730 | AA35: =SUM(C35:Z35) -> 646548 | AB35: 21 | AC35: =+AA35*AB35 -> 13577508 | AD35: =+SUM(AC35:AC38) -> 19300018
B36: Sábado | C36: 27112 | D36: 25917 | E36: 24884 | F36: 24099 | G36: 23658 | H36: 23057 | I36: 33237 | J36: 34526 | K36: 27335 | L36: 23383 | M36: 20288 | N36: 18197 | O36: 17093 | P36: 23526 | Q36: 33790 | R36: 42706 | S36: 37043 | T36: 24478 | U36: 25843 | V36: 26034 | W36: 25647 | X36: 25562 | Y36: 25124 | Z36: 24180 | AA36: =SUM(C36:Z36) -> 636719 | AB36: 4 | AC36: =+AA36*AB36 -> 2546876
B37: Domingo | C37: 26440 | D37: 25320 | E37: 24422 | F37: 23666 | G37: 22971 | H37: 21983 | I37: 31666 | J37: 30132 | K37: 20688 | L37: 14966 | M37: 11935 | N37: 8579 | O37: 10093 | P37: 16824 | Q37: 26199 | R37: 35763 | S37: 29865 | T37: 20353 | U37: 22286 | V37: 23359 | W37: 23615 | X37: 24064 | Y37: 23413 | Z37: 22092 | AA37: =SUM(C37:Z37) -> 540694 | AB37: 4 | AC37: =+AA37*AB37 -> 2162776
B38: Festivo | C38: 21856 | D38: 20981 | E38: 20268 | F38: 19794 | G38: 19560 | H38: 19124 | I38: 28907 | J38: 27748 | K38: 19315 | L38: 14978 | M38: 12266 | N38: 9871 | O38: 10729 | P38: 16986 | Q38: 26782 | R38: 36111 | S38: 30436 | T38: 19718 | U38: 21507 | V38: 22528 | W38: 22531 | X38: 22650 | Y38: 21686 | Z38: 20097 | AA38: =SUM(C38:Z38) -> 506429 | AB38: 2 | AC38: =+AA38*AB38 -> 1012858
A39: 46997 | B39: Hábil | C39: 37241 | D39: 35326 | E39: 33846 | F39: 32694 | G39: 32254 | H39: 32234 | I39: 36634 | J39: 40084 | K39: 32539 | L39: 28863 | M39: 27141 | N39: 24070 | O39: 21642 | P39: 33109 | Q39: 48259 | R39: 59163 | S39: 58998 | T39: 41028 | U39: 41845 | V39: 41305 | W39: 41541 | X39: 41275 | Y39: 39352 | Z39: 36540 | AA39: =SUM(C39:Z39) -> 896983 | AB39: 21 | AC39: =+AA39*AB39 -> 18836643 | AD39: =+SUM(AC39:AC42) -> 26083915
B40: Sábado | C40: 36800 | D40: 35138 | E40: 33778 | F40: 32670 | G40: 32159 | H40: 31405 | I40: 35889 | J40: 39293 | K40: 31895 | L40: 27617 | M40: 25761 | N40: 23106 | O40: 22050 | P40: 29514 | Q40: 41834 | R40: 52154 | S40: 52501 | T40: 38307 | U40: 40661 | V40: 39894 | W40: 39016 | X40: 38372 | Y40: 37479 | Z40: 35915 | AA40: =SUM(C40:Z40) -> 853208 | AB40: 5 | AC40: =+AA40*AB40 -> 4266040
B41: Domingo | C41: 37163 | D41: 35530 | E41: 34244 | F41: 33183 | G41: 32490 | H41: 31414 | I41: 35049 | J41: 34088 | K41: 22879 | L41: 16670 | M41: 13909 | N41: 11287 | O41: 12430 | P41: 19969 | Q41: 32063 | R41: 42902 | S41: 44477 | T41: 33488 | U41: 36518 | V41: 37433 | W41: 38061 | X41: 38342 | Y41: 37020 | Z41: 34699 | AA41: =SUM(C41:Z41) -> 745308 | AB41: 4 | AC41: =+AA41*AB41 -> 2981232
B42: Festivo | C42: 0 | D42: 0 | E42: 0 | F42: 0 | G42: 0 | H42: 0 | I42: 0 | J42: 0 | K42: 0 | L42: 0 | M42: 0 | N42: 0 | O42: 0 | P42: 0 | Q42: 0 | R42: 0 | S42: 0 | T42: 0 | U42: 0 | V42: 0 | W42: 0 | X42: 0 | Y42: 0 | Z42: 0 | AB42: 0 | AC42: =+AA42*AB42 -> 0
...

Sheet OF P4
C1: * La energia a ofertar debe ser expresada únicamente en kilovatio (kWh) redondeado a cero decimales
C4: OFERTA PRODUCTO 4
C5: MES | D5: ENERGIA SOLICITADA (KWh) | E5: % | F5: ENERGIA OFERTADA (KWh) | G5: PRECIO $/kWh
C6: 47119 | D6: =+VLOOKUP(C6,'CURVA P4'!$A$4:$AD$55,30,FALSE) -> 34074890 | E6: % | G6: $/kWh
C7: 47150 | D7: =+VLOOKUP(C7,'CURVA P4'!$A$4:$AD$55,30,FALSE) -> 37016204
C8: 47178 | D8: =+VLOOKUP(C8,'CURVA P4'!$A$4:$AD$55,30,FALSE) -> 33999707
C9: 47209 | D9: =+VLOOKUP(C9,'CURVA P4'!$A$4:$AD$55,30,FALSE) -> 36272875
C10: 47239 | D10: =+VLOOKUP(C10,'CURVA P4'!$A$4:$AD$55,30,FALSE) -> 36538851
C11: 47270 | D11: =+VLOOKUP(C11,'CURVA P4'!$A$4:$AD$55,30,FALSE) -> 37976865
C12: 47300 | D12: =+VLOOKUP(C12,'CURVA P4'!$A$4:$AD$55,30,FALSE) -> 36037226
C13: 47331 | D13: =+VLOOKUP(C13,'CURVA P4'!$A$4:$AD$55,30,FALSE) -> 37660774
C14: 47362 | D14: =+VLOOKUP(C14,'CURVA P4'!$A$4:$AD$55,30,FALSE) -> 39521710
C15: 47392 | D15: =+VLOOKUP(C15,'CURVA P4'!$A$4:$AD$55,30,FALSE) -> 38647476
C16: 47423 | D16: =+VLOOKUP(C16,'CURVA P4'!$A$4:$AD$55,30,FALSE) -> 38283096
C17: 47453 | D17: =+VLOOKUP(C17,'CURVA P4'!$A$4:$AD$55,30,FALSE) -> 36672929
D18: =SUM(D6:D17) -> 442702603
D20: =D18/1000000 -> 442.7026
D21: =D20*1000 -> 442702.6

Sheet CURVA P4
A1: Curva de distribucion en kwh
A2: * La energia a ofertar debe ser expresada únicamente en kilovatio (kWh) redondeado a cero decimales
A4: TOTAL | C4: =+AD55 -> 442702603
A5: MES | B5: DÍA | C5: HORA 01 | D5: HORA 02 | E5: HORA 03 | F5: HORA 04 | G5: HORA 05 | H5: HORA 06 | I5: HORA 07 | J5: HORA 08 | K5: HORA 09 | L5: HORA 10 | M5: HORA 11 | N5: HORA 12 | O5: HORA 13 | P5: HORA 14 | Q5: HORA 15 | R5: HORA 16 | S5: HORA 17 | T5: HORA 18 | U5: HORA 19 | V5: HORA 20 | W5: HORA 21 | X5: HORA 22 | Y5: HORA 23 | Z5: HORA 24 | AA5: TOTAL DÍA | AB5: NUMERO DÍAS | AC5: TOTAL DÍA MES | AD5: TOTAL MES
A7: 47119 | B7: Hábil | C7: 49918 | D7: 46686 | E7: 44077 | F7: 42157 | G7: 41553 | H7: 42709 | I7: 43061 | J7: 33987 | K7: 29672 | L7: 27993 | M7: 28340 | N7: 27115 | O7: 24534 | P7: 35699 | Q7: 52657 | R7: 64537 | S7: 69227 | T7: 68034 | U7: 71131 | V7: 70030 | W7: 68602 | X7: 66311 | Y7: 61642 | Z7: 55444 | AA7: =SUM(C7:Z7) -> 1165116 | AB7: 21 | AC7: =+AA7*AB7 -> 24467436 | AD7: =+SUM(AC7:AC10) -> 34074890
B8: Sábado | C8: 51593 | D8: 48016 | E8: 45110 | F8: 42968 | G8: 42095 | H8: 42474 | I8: 42090 | J8: 32171 | K8: 27848 | L8: 26057 | M8: 25752 | N8: 23961 | O8: 23184 | P8: 30139 | Q8: 42769 | R8: 53652 | S8: 58381 | T8: 61019 | U8: 67469 | V8: 67052 | W8: 64728 | X8: 62392 | Y8: 59167 | Z8: 54743 | AA8: =SUM(C8:Z8) -> 1094830 | AB8: 4 | AC8: =+AA8*AB8 -> 4379320
B9: Domingo | C9: 50749 | D9: 47406 | E9: 44582 | F9: 42356 | G9: 41087 | H9: 40461 | I9: 38828 | J9: 24831 | K9: 15890 | L9: 12329 | M9: 10180 | N9: 8249 | O9: 10901 | P9: 17282 | Q9: 28602 | R9: 40222 | S9: 46524 | T9: 51816 | U9: 59550 | V9: 61722 | W9: 61452 | X9: 60334 | Y9: 56721 | Z9: 51592 | AA9: =SUM(C9:Z9) -> 923666 | AB9: 4 | AC9: =+AA9*AB9 -> 3694664
B10: Festivo | C10: 40903 | D10: 39282 | E10: 37855 | F10: 36401 | G10: 35652 | H10: 35013 | I10: 32767 | J10: 18152 | K10: 8549 | L10: 4952 | M10: 3412 | N10: 1477 | O10: 4234 | P10: 10969 | Q10: 22023 | R10: 33296 | S10: 39090 | T10: 46364 | U10: 54732 | V10: 56264 | W10: 55391 | X10: 53574 | Y10: 50286 | Z10: 46097 | AA10: =SUM(C10:Z10) -> 766735 | AB10: 2 | AC10: =+AA10*AB10 -> 1533470
A11: 47150 | B11: Hábil | C11: 57510 | D11: 53555 | E11: 50768 | F11: 48895 | G11: 48824 | H11: 52068 | I11: 53585 | J11: 45167 | K11: 40283 | L11: 38232 | M11: 38638 | N11: 35729 | O11: 30553 | P11: 44682 | Q11: 63870 | R11: 76779 | S11: 81554 | T11: 77533 | U11: 79128 | V11: 78979 | W11: 77734 | X11: 74968 | Y11: 68978 | Z11: 61635 | AA11: =SUM(C11:Z11) -> 1379647 | AB11: 20 | AC11: =+AA11*AB11 -> 27592940 | AD11: =+SUM(AC11:AC14) -> 37016204
B12: Sábado | C12: 55611 | D12: 51818 | E12: 49121 | F12: 47265 | G12: 46644 | H12: 47693 | I12: 48798 | J12: 40554 | K12: 36695 | L12: 34857 | M12: 34492 | N12: 32067 | O12: 29751 | P12: 36485 | Q12: 50118 | R12: 61802 | S12: 66688 | T12: 67397 | U12: 73171 | V12: 73799 | W12: 71392 | X12: 68800 | Y12: 65422 | Z12: 60595 | AA12: =SUM(C12:Z12) -> 1251035 | AB12: 4 | AC12: =+AA12*AB12 -> 5004140
B13: Domingo | C13: 57136 | D13: 53101 | E13: 50292 | F13: 48040 | G13: 46785 | H13: 46403 | I13: 45340 | J13: 32011 | K13: 22506 | L13: 19098 | M13: 17209 | N13: 15429 | O13: 18213 | P13: 24642 | Q13: 36975 | R13: 49702 | S13: 56629 | T13: 59886 | U13: 67039 | V13: 70769 | W13: 71280 | X13: 70604 | Y13: 66034 | Z13: 59658 | AA13: =SUM(C13:Z13) -> 1104781 | AB13: 4 | AC13: =+AA13*AB13 -> 4419124
B14: Festivo | C14: 0 | D14: 0 | E14: 0 | F14: 0 | G14: 0 | H14: 0 | I14: 0 | J14: 0 | K14: 0 | L14: 0 | M14: 0 | N14: 0 | O14: 0 | P14: 0 | Q14: 0 | R14: 0 | S14: 0 | T14: 0 | U14: 0 | V14: 0 | W14: 0 | X14: 0 | Y14: 0 | Z14: 0 | AA14: =SUM(C14:Z14) -> 0 | AB14: 0 | AC14: =+AA14*AB14 -> 0
A15: 47178 | B15: Hábil | C15: 50285 | D15: 46572 | E15: 44001 | F15: 42144 | G15: 41938 | H15: 44077 | I15: 44383 | J15: 35683 | K15: 30815 | L15: 28372 | M15: 28289 | N15: 25866 | O15: 21932 | P15: 34849 | Q15: 52475 | R15: 64314 | S15: 69235 | T15: 67167 | U15: 69270 | V15: 69157 | W15: 68202 | X15: 66046 | Y15: 61161 | Z15: 54766 | AA15: =SUM(C15:Z15) -> 1160999 | AB15: 19 | AC15: =+AA15*AB15 -> 22058981 | AD15: =+SUM(AC15:AC18) -> 33999707
B16: Sábado | C16: 52111 | D16: 48219 | E16: 45460 | F16: 43251 | G16: 42275 | H16: 42467 | I16: 42705 | J16: 34299 | K16: 29862 | L16: 27558 | M16: 27125 | N16: 24392 | O16: 22399 | P16: 29115 | Q16: 41864 | R16: 52928 | S16: 57932 | T16: 60164 | U16: 65702 | V16: 66119 | W16: 64220 | X16: 62313 | Y16: 59671 | Z16: 55645 | AA16: =SUM(C16:Z16) -> 1097796 | AB16: 5 | AC16: =+AA16*AB16 -> 5488980
B17: Domingo | C17: 52400 | D17: 48659 | E17: 45993 | F17: 43831 | G17: 42538 | H17: 41704 | I17: 39906 | J17: 26245 | K17: 17047 | L17: 12923 | M17: 10268 | N17: 8629 | O17: 11387 | P17: 17874 | Q17: 29759 | R17: 41479 | S17: 47957 | T17: 52653 | U17: 59355 | V17: 62786 | W17: 63560 | X17: 63208 | Y17: 59233 | Z17: 53703 | AA17: =SUM(C17:Z17) -> 953097 | AB17: 4 | AC17: =+AA17*AB17 -> 3812388
B18: Festivo | C18: 44009 | D18: 40247 | E18: 37826 | F18: 36180 | G18: 35359 | H18: 35175 | I18: 34705 | J18: 23489 | K18: 16043 | L18: 13504 | M18: 12884 | N18: 11265 | O18: 11782 | P18: 19090 | Q18: 30379 | R18: 40976 | S18: 46259 | T18: 50271 | U18: 57827 | V18: 61125 | W18: 61047 | X18: 59098 | Y18: 53580 | Z18: 47666 | AA18: =SUM(C18:Z18) -> 879786 | AB18: 3 | AC18: =+AA18*AB18 -> 2639358
A19: 47209 | B19: Hábil | C19: 53103 | D19: 49194 | E19: 46518 | F19: 44638 | G19: 44433 | H19: 45409 | I19: 46301 | J19: 38840 | K19: 35194 | L19: 33473 | M19: 34147 | N19: 32193 | O19: 27485 | P19: 40836 | Q19: 59479 | R19: 71273 | S19: 75552 | T19: 72562 | U19: 74198 | V19: 73735 | W19: 72997 | X19: 70649 | Y19: 65421 | Z19: 58531 | AA19: =SUM(C19:Z19) -> 1266161 | AB19: 21 | AC19: =+AA19*AB19 -> 26589381 | AD19: =+SUM(AC19:AC22) -> 36272875
B20: Sábado | C20: 54112 | D20: 50194 | E20: 47334 | F20: 45164 | G20: 44269 | H20: 43195 | I20: 44057 | J20: 35667 | K20: 32227 | L20: 30664 | M20: 30393 | N20: 28396 | O20: 26800 | P20: 33875 | Q20: 46979 | R20: 57903 | S20: 62246 | T20: 63900 | U20: 68982 | V20: 68366 | W20: 66352 | X20: 64153 | Y20: 61177 | Z20: 57081 | AA20: =SUM(C20:Z20) -> 1163486 | AB20: 4 | AC20: =+AA20*AB20 -> 4653944
B21: Domingo | C21: 54317 | D21: 50239 | E21: 47269 | F21: 44900 | G21: 43538 | H21: 41662 | I21: 40731 | J21: 27798 | K21: 18780 | L21: 15135 | M21: 13364 | N21: 12210 | O21: 14895 | P21: 21596 | Q21: 33740 | R21: 45494 | S21: 51561 | T21: 55572 | U21: 62211 | V21: 64936 | W21: 64925 | X21: 64632 | Y21: 61037 | Z21: 55368 | AA21: =SUM(C21:Z21) -> 1005910 | AB21: 5 | AC21: =+AA21*AB21 -> 5029550
B22: Festivo | C22: 0 | D22: 0 | E22: 0 | F22: 0 | G22: 0 | H22: 0 | I22: 0 | J22: 0 | K22: 0 | L22: 0 | M22: 0 | N22: 0 | O22: 0 | P22: 0 | Q22: 0 | R22: 0 | S22: 0 | T22: 0 | U22: 0 | V22: 0 | W22: 0 | X22: 0 | Y22: 0 | Z22: 0 | AA22: =SUM(C22:Z22) -> 0 | AB22: 0 | AC22: =+AA22*AB22 -> 0
A23: 47239 | B23: Hábil | C23: 53115 | D23: 49407 | E23: 46674 | F23: 44761 | G23: 44264 | H23: 43835 | I23: 45095 | J23: 37911 | K23: 34975 | L23: 33560 | M23: 34004 | N23: 31800 | O23: 27278 | P23: 40298 | Q23: 58461 | R23: 69507 | S23: 73441 | T23: 70437 | U23: 71688 | V23: 71784 | W23: 71492 | X23: 69592 | Y23: 64687 | Z23: 58201 | AA23: =SUM(C23:Z23) -> 1246267 | AB23: 21 | AC23: =+AA23*AB23 -> 26171607 | AD23: =+SUM(AC23:AC26) -> 36538851
B24: Sábado | C24: 55831 | D24: 51629 | E24: 48544 | F24: 46155 | G24: 45178 | H24: 43229 | I24: 44256 | J24: 35949 | K24: 33169 | L24: 32040 | M24: 31799 | N24: 29157 | O24: 27051 | P24: 33792 | Q24: 46165 | R24: 56923 | S24: 61023 | T24: 61844 | U24: 66643 | V24: 67335 | W24: 65689 | X24: 64002 | Y24: 61312 | Z24: 57293 | AA24: =SUM(C24:Z24) -> 1166008 | AB24: 4 | AC24: =+AA24*AB24 -> 4664032
B25: Domingo | C25: 53587 | D25: 49979 | E25: 47235 | F25: 44960 | G25: 43505 | H25: 40547 | I25: 40417 | J25: 27150 | K25: 18294 | L25: 14634 | M25: 13054 | N25: 11052 | O25: 12590 | P25: 18659 | Q25: 30847 | R25: 42064 | S25: 48129 | T25: 52505 | U25: 58956 | V25: 62033 | W25: 62663 | X25: 62798 | Y25: 59877 | Z25: 54817 | AA25: =SUM(C25:Z25) -> 970352 | AB25: 4 | AC25: =+AA25*AB25 -> 3881408
B26: Festivo | C26: 45929 | D26: 42379 | E26: 39855 | F26: 38019 | G26: 37176 | H26: 35207 | I26: 35627 | J26: 23805 | K26: 16135 | L26: 13596 | M26: 13050 | N26: 11533 | O26: 12601 | P26: 19708 | Q26: 31782 | R26: 42830 | S26: 48005 | T26: 51359 | U26: 58092 | V26: 61847 | W26: 62278 | X26: 61304 | Y26: 57145 | Z26: 51640 | AA26: =SUM(C26:Z26) -> 910902 | AB26: 2 | AC26: =+AA26*AB26 -> 1821804
A27: 47270 | B27: Hábil | C27: 56811 | D27: 52841 | E27: 49917 | F27: 47911 | G27: 47394 | H27: 46711 | I27: 48813 | J27: 42544 | K27: 39763 | L27: 38131 | M27: 38504 | N27: 36597 | O27: 31352 | P27: 44248 | Q27: 62432 | R27: 73975 | S27: 78370 | T27: 74344 | U27: 74806 | V27: 75563 | W27: 74705 | X27: 72421 | Y27: 67590 | Z27: 61098 | AA27: =SUM(C27:Z27) -> 1336841 | AB27: 19 | AC27: =+AA27*AB27 -> 25399979 | AD27: =+SUM(AC27:AC30) -> 37976865
B28: Sábado | C28: 58050 | D28: 54191 | E28: 51265 | F28: 49097 | G28: 48347 | H28: 46465 | I28: 48304 | J28: 40589 | K28: 37449 | L28: 35900 | M28: 35715 | N28: 33214 | O28: 30727 | P28: 36696 | Q28: 50065 | R28: 61433 | S28: 65883 | T28: 66495 | U28: 70393 | V28: 71516 | W28: 69510 | X28: 67431 | Y28: 64595 | Z28: 60582 | AA28: =SUM(C28:Z28) -> 1253912 | AB28: 5 | AC28: =+AA28*AB28 -> 6269560
B29: Domingo | C29: 57536 | D29: 53832 | E29: 51077 | F29: 48850 | G29: 47525 | H29: 44643 | I29: 44417 | J29: 31692 | K29: 21977 | L29: 18880 | M29: 16051 | N29: 13883 | O29: 16122 | P29: 22302 | Q29: 34170 | R29: 45748 | S29: 52547 | T29: 55754 | U29: 61908 | V29: 66496 | W29: 66871 | X29: 66672 | Y29: 64042 | Z29: 59427 | AA29: =SUM(C29:Z29) -> 1062422 | AB29: 4 | AC29: =+AA29*AB29 -> 4249688
B30: Festivo | C30: 50637 | D30: 47053 | E30: 44579 | F30: 42599 | G30: 41862 | H30: 39750 | I30: 40202 | J30: 29443 | K30: 22537 | L30: 20511 | M30: 20184 | N30: 18437 | O30: 19058 | P30: 25825 | Q30: 37491 | R30: 48029 | S30: 52959 | T30: 55262 | U30: 61138 | V30: 66228 | W30: 65910 | X30: 64425 | Y30: 60204 | Z30: 54496 | AA30: =SUM(C30:Z30) -> 1028819 | AB30: 2 | AC30: =+AA30*AB30 -> 2057638
