Workbook

Sheet Cantidades Producto 1
C2: CANTIDADES DE ENERGÍA SOLICITADAS (kWh)
C3: EMPRESAS PÚBLICAS DE MEDELLÍN E.S.P.
C4: 2026
C6: Mes | D6: Tipo Día | E6: Días | F6: H1 | G6: H2 | H6: H3 | I6: H4 | J6: H5 | K6: H6 | L6: H7 | M6: H8 | N6: H9 | O6: H10 | P6: H11 | Q6: H12 | R6: H13 | S6: H14 | T6: H15 | U6: H16 | V6: H17 | W6: H18 | X6: H19 | Y6: H20 | Z6: H21 | AA6: H22 | AB6: H23 | AC6: H24 | AD6: TOTAL MES
C7: Ene | D7: Ordinario | E7: 20 | F7: =+[1]Resumen!F7*1000 -> 118803.05 | G7: =+[1]Resumen!G7*1000 -> 102965.44 | H7: =+[1]Resumen!H7*1000 -> 93626.992 | I7: =+[1]Resumen!I7*1000 -> 91797.815 | J7: =+[1]Resumen!J7*1000 -> 99208.357 | K7: =+[1]Resumen!K7*1000 -> 129732.22 | L7: =+[1]Resumen!L7*1000 -> 161520.27 | M7: =+[1]Resumen!M7*1000 -> 143195.33 | ... AC7: =+[1]Resumen!AC7*1000 -> 131050.18 | AD7: =SUM(F7:AC7)*E7+SUM(F8:AC8)*E8+SUM(F9:AC9)*E9+SUM(F10:AC10)*E10 -> 1.196225e+08
D8: Sábado | E8: 5 | F8: =+[1]Resumen!F8*1000 -> 113731.69 | G8: =+[1]Resumen!G8*1000 -> 97498.696 | H8: =+[1]Resumen!H8*1000 -> 87446.258 | I8: =+[1]Resumen!I8*1000 -> 82954.404 | J8: =+[1]Resumen!J8*1000 -> 90481.271 | K8: =+[1]Resumen!K8*1000 -> 105903.93 | L8: =+[1]Resumen!L8*1000 -> 128647.02 | M8: =+[1]Resumen!M8*1000 -> 111176.43 | ... AC8: =+[1]Resumen!AC8*1000 -> 115425.43
D9: Domingo | E9: 4 | F9: =+[1]Resumen!F9*1000 -> 113723.43 | G9: =+[1]Resumen!G9*1000 -> 95929.086 | H9: =+[1]Resumen!H9*1000 -> 83793.976 | I9: =+[1]Resumen!I9*1000 -> 76877.948 | J9: =+[1]Resumen!J9*1000 -> 78613.166 | K9: =+[1]Resumen!K9*1000 -> 85486.196 | L9: =+[1]Resumen!L9*1000 -> 95888.127 | M9: =+[1]Resumen!M9*1000 -> 71128.072 | ... AC9: =+[1]Resumen!AC9*1000 -> 98213.121
D10: Festivo | E10: 2 | F10: =+[1]Resumen!F10*1000 -> 96105.208 | G10: =+[1]Resumen!G10*1000 -> 84910.786 | H10: =+[1]Resumen!H10*1000 -> 73004.789 | I10: =+[1]Resumen!I10*1000 -> 66612.361 | J10: =+[1]Resumen!J10*1000 -> 66799.961 | K10: =+[1]Resumen!K10*1000 -> 72733.852 | L10: =+[1]Resumen!L10*1000 -> 73943.476 | M10: =+[1]Resumen!M10*1000 -> 40842.905 | ... AC10: =+[1]Resumen!AC10*1000 -> 83130.958
C11: Feb | D11: Ordinario | E11: 20 | F11: =+[1]Resumen!F11*1000 -> 148904.24 | G11: =+[1]Resumen!G11*1000 -> 131850.26 | H11: =+[1]Resumen!H11*1000 -> 122882.96 | I11: =+[1]Resumen!I11*1000 -> 122286.62 | J11: =+[1]Resumen!J11*1000 -> 138689.16 | K11: =+[1]Resumen!K11*1000 -> 193109.74 | L11: =+[1]Resumen!L11*1000 -> 229558.65 | M11: =+[1]Resumen!M11*1000 -> 202595.71 | ... AC11: =+[1]Resumen!AC11*1000 -> 156975.3 | AD11: =SUM(F11:AC11)*E11+SUM(F12:AC12)*E12+SUM(F13:AC13)*E13+SUM(F14:AC14)*E14 -> 1.4518956e+08
D12: Sábado | E12: 4 | F12: =+[1]Resumen!F12*1000 -> 152302.6 | G12: =+[1]Resumen!G12*1000 -> 133240.41 | H12: =+[1]Resumen!H12*1000 -> 120948.52 | I12: =+[1]Resumen!I12*1000 -> 117010.39 | J12: =+[1]Resumen!J12*1000 -> 125498.7 | K12: =+[1]Resumen!K12*1000 -> 145616.52 | L12: =+[1]Resumen!L12*1000 -> 178665.18 | M12: =+[1]Resumen!M12*1000 -> 172555.14 | ... AC12: =+[1]Resumen!AC12*1000 -> 155587.97
D13: Domingo | E13: 4 | F13: =+[1]Resumen!F13*1000 -> 149955.14 | G13: =+[1]Resumen!G13*1000 -> 129668.37 | H13: =+[1]Resumen!H13*1000 -> 117160.52 | I13: =+[1]Resumen!I13*1000 -> 111192.77 | J13: =+[1]Resumen!J13*1000 -> 112630.14 | K13: =+[1]Resumen!K13*1000 -> 120389.52 | L13: =+[1]Resumen!L13*1000 -> 135993.78 | M13: =+[1]Resumen!M13*1000 -> 115804.01 | ... AC13: =+[1]Resumen!AC13*1000 -> 142494.35
D14: Festivo | E14: 0 | F14: =+[1]Resumen!F14*1000 -> 0 | G14: =+[1]Resumen!G14*1000 -> 0 | H14: =+[1]Resumen!H14*1000 -> 0 | I14: =+[1]Resumen!I14*1000 -> 0 | J14: =+[1]Resumen!J14*1000 -> 0 | K14: =+[1]Resumen!K14*1000 -> 0 | L14: =+[1]Resumen!L14*1000 -> 0 | M14: =+[1]Resumen!M14*1000 -> 0 | ... AC14: =+[1]Resumen!AC14*1000 -> 0
C15: Mar | D15: Ordinario | E15: 21 | F15: =+[1]Resumen!F15*1000 -> 118356.05 | G15: =+[1]Resumen!G15*1000 -> 102474.47 | H15: =+[1]Resumen!H15*1000 -> 93761.434 | I15: =+[1]Resumen!I15*1000 -> 92183.292 | J15: =+[1]Resumen!J15*1000 -> 100412.54 | K15: =+[1]Resumen!K15*1000 -> 139642.45 | L15: =+[1]Resumen!L15*1000 -> 167406.53 | M15: =+[1]Resumen!M15*1000 -> 143399.94 | ... AC15: =+[1]Resumen!AC15*1000 -> 126933.39 | AD15: =SUM(F15:AC15)*E15+SUM(F16:AC16)*E16+SUM(F17:AC17)*E17+SUM(F18:AC18)*E18 -> 1.1532532e+08
D16: Sábado | E16: 4 | F16: =+[1]Resumen!F16*1000 -> 114752.12 | G16: =+[1]Resumen!G16*1000 -> 97488.312 | H16: =+[1]Resumen!H16*1000 -> 87294.346 | I16: =+[1]Resumen!I16*1000 -> 82473.197 | J16: =+[1]Resumen!J16*1000 -> 86708.962 | K16: =+[1]Resumen!K16*1000 -> 97832.973 | L16: =+[1]Resumen!L16*1000 -> 118040.47 | M16: =+[1]Resumen!M16*1000 -> 105770.64 | ... AC16: =+[1]Resumen!AC16*1000 -> 110331.14
D17: Domingo | E17: 5 | F17: =+[1]Resumen!F17*1000 -> 111504.65 | G17: =+[1]Resumen!G17*1000 -> 95488.392 | H17: =+[1]Resumen!H17*1000 -> 84393.473 | I17: =+[1]Resumen!I17*1000 -> 78590.612 | J17: =+[1]Resumen!J17*1000 -> 79875.861 | K17: =+[1]Resumen!K17*1000 -> 84514.227 | L17: =+[1]Resumen!L17*1000 -> 93409.075 | M17: =+[1]Resumen!M17*1000 -> 70847.622 | ... AC17: =+[1]Resumen!AC17*1000 -> 92566.644
D18: Festivo | E18: 1 | F18: =+[1]Resumen!F18*1000 -> 103538.62 | G18: =+[1]Resumen!G18*1000 -> 88606.361 | H18: =+[1]Resumen!H18*1000 -> 79634.296 | I18: =+[1]Resumen!I18*1000 -> 72706.092 | J18: =+[1]Resumen!J18*1000 -> 75605.301 | K18: =+[1]Resumen!K18*1000 -> 82418.923 | L18: =+[1]Resumen!L18*1000 -> 92792.093 | M18: =+[1]Resumen!M18*1000 -> 74431.941 | ... AC18: =+[1]Resumen!AC18*1000 -> 105295.33
C19: Abr | D19: Ordinario | E19: 20 | F19: =+[1]Resumen!F19*1000 -> 122497.38 | G19: =+[1]Resumen!G19*1000 -> 107408.99 | H19: =+[1]Resumen!H19*1000 -> 99334.439 | I19: =+[1]Resumen!I19*1000 -> 99022.773 | J19: =+[1]Resumen!J19*1000 -> 113843.63 | K19: =+[1]Resumen!K19*1000 -> 163879.29 | L19: =+[1]Resumen!L19*1000 -> 196446.01 | M19: =+[1]Resumen!M19*1000 -> 169681.81 | ... AC19: =+[1]Resumen!AC19*1000 -> 132475.54 | AD19: =SUM(F19:AC19)*E19+SUM(F20:AC20)*E20+SUM(F21:AC21)*E21+SUM(F22:AC22)*E22 -> 1.2961433e+08
D20: Sábado | E20: 4 | F20: =+[1]Resumen!F20*1000 -> 131023.2 | G20: =+[1]Resumen!G20*1000 -> 115785.66 | H20: =+[1]Resumen!H20*1000 -> 102139.22 | I20: =+[1]Resumen!I20*1000 -> 98574.777 | J20: =+[1]Resumen!J20*1000 -> 107765.64 | K20: =+[1]Resumen!K20*1000 -> 127025.16 | L20: =+[1]Resumen!L20*1000 -> 163300.05 | M20: =+[1]Resumen!M20*1000 -> 161073.08 | ... AC20: =+[1]Resumen!AC20*1000 -> 127882.11
D21: Domingo | E21: 4 | F21: =+[1]Resumen!F21*1000 -> 127153.85 | G21: =+[1]Resumen!G21*1000 -> 108881.56 | H21: =+[1]Resumen!H21*1000 -> 96649.856 | I21: =+[1]Resumen!I21*1000 -> 90087.21 | J21: =+[1]Resumen!J21*1000 -> 90932.233 | K21: =+[1]Resumen!K21*1000 -> 96818.331 | L21: =+[1]Resumen!L21*1000 -> 110910.75 | M21: =+[1]Resumen!M21*1000 -> 91092.448 | ... AC21: =+[1]Resumen!AC21*1000 -> 106139.72
D22: Festivo | E22: 2 | F22: =+[1]Resumen!F22*1000 -> 128881.36 | G22: =+[1]Resumen!G22*1000 -> 111265.41 | H22: =+[1]Resumen!H22*1000 -> 98371.298 | I22: =+[1]Resumen!I22*1000 -> 90771.637 | J22: =+[1]Resumen!J22*1000 -> 90692.426 | K22: =+[1]Resumen!K22*1000 -> 95777.052 | L22: =+[1]Resumen!L22*1000 -> 108192.12 | M22: =+[1]Resumen!M22*1000 -> 88450.358 | ... AC22: =+[1]Resumen!AC22*1000 -> 108896.75
C23: May | D23: Ordinario | E23: 19 | F23: =+[1]Resumen!F23*1000 -> 99546.372 | G23: =+[1]Resumen!G23*1000 -> 81129.397 | H23: =+[1]Resumen!H23*1000 -> 71396.972 | I23: =+[1]Resumen!I23*1000 -> 67725.535 | J23: =+[1]Resumen!J23*1000 -> 66158.122 | K23: =+[1]Resumen!K23*1000 -> 74017.588 | L23: =+[1]Resumen!L23*1000 -> 98901.45 | M23: =+[1]Resumen!M23*1000 -> 96021.54 | ... AC23: =+[1]Resumen!AC23*1000 -> 97627.197 | AD23: =SUM(F23:AC23)*E23+SUM(F24:AC24)*E24+SUM(F25:AC25)*E25+SUM(F26:AC26)*E26 -> 1.1674581e+08
D24: Sábado | E24: 5 | F24: =+[1]Resumen!F24*1000 -> 65508.152 | G24: =+[1]Resumen!G24*1000 -> 55577.851 | H24: =+[1]Resumen!H24*1000 -> 48308.672 | I24: =+[1]Resumen!I24*1000 -> 49455.265 | J24: =+[1]Resumen!J24*1000 -> 66429.311 | K24: =+[1]Resumen!K24*1000 -> 96187.898 | L24: =+[1]Resumen!L24*1000 -> 149388.56 | M24: =+[1]Resumen!M24*1000 -> 152116.73 | ... AC24: =+[1]Resumen!AC24*1000 -> 88592.434
D25: Domingo | E25: 5 | F25: =+[1]Resumen!F25*1000 -> 82610.959 | G25: =+[1]Resumen!G25*1000 -> 70678.132 | H25: =+[1]Resumen!H25*1000 -> 62419.694 | I25: =+[1]Resumen!I25*1000 -> 62896.364 | J25: =+[1]Resumen!J25*1000 -> 87749.838 | K25: =+[1]Resumen!K25*1000 -> 124024.95 | L25: =+[1]Resumen!L25*1000 -> 187843.37 | M25: =+[1]Resumen!M25*1000 -> 199628.29 | ... AC25: =+[1]Resumen!AC25*1000 -> 107944.64
D26: Festivo | E26: 2 | F26: =+[1]Resumen!F26*1000 -> 93558.971 | G26: =+[1]Resumen!G26*1000 -> 75511.724 | H26: =+[1]Resumen!H26*1000 -> 66698.888 | I26: =+[1]Resumen!I26*1000 -> 66132.393 | J26: =+[1]Resumen!J26*1000 -> 82520.594 | K26: =+[1]Resumen!K26*1000 -> 105726.36 | L26: =+[1]Resumen!L26*1000 -> 151488.62 | M26: =+[1]Resumen!M26*1000 -> 155277.68 | ... AC26: =+[1]Resumen!AC26*1000 -> 98781.078
C27: Jun | D27: Ordinario | E27: 19 | F27: =+[1]Resumen!F27*1000 -> 126298.32 | G27: =+[1]Resumen!G27*1000 -> 109995.82 | H27: =+[1]Resumen!H27*1000 -> 100746.67 | I27: =+[1]Resumen!I27*1000 -> 100971.9 | J27: =+[1]Resumen!J27*1000 -> 111518.58 | K27: =+[1]Resumen!K27*1000 -> 142956.56 | L27: =+[1]Resumen!L27*1000 -> 178640.11 | M27: =+[1]Resumen!M27*1000 -> 166696.27 | ... AC27: =+[1]Resumen!AC27*1000 -> 136726.93 | AD27: =SUM(F27:AC27)*E27+SUM(F28:AC28)*E28+SUM(F29:AC29)*E29+SUM(F30:AC30)*E30 -> 1.2827847e+08
D28: Sábado | E28: 4 | F28: =+[1]Resumen!F28*1000 -> 130896.96 | G28: =+[1]Resumen!G28*1000 -> 112114.8 | H28: =+[1]Resumen!H28*1000 -> 103306.64 | I28: =+[1]Resumen!I28*1000 -> 98278.053 | J28: =+[1]Resumen!J28*1000 -> 106551.69 | K28: =+[1]Resumen!K28*1000 -> 121763.39 | L28: =+[1]Resumen!L28*1000 -> 154030.87 | M28: =+[1]Resumen!M28*1000 -> 141554.41 | ... AC28: =+[1]Resumen!AC28*1000 -> 128319.54
D29: Domingo | E29: 4 | F29: =+[1]Resumen!F29*1000 -> 130270.27 | G29: =+[1]Resumen!G29*1000 -> 113023.56 | H29: =+[1]Resumen!H29*1000 -> 99950.708 | I29: =+[1]Resumen!I29*1000 -> 92738.23 | J29: =+[1]Resumen!J29*1000 -> 92948.665 | K29: =+[1]Resumen!K29*1000 -> 98233.392 | L29: =+[1]Resumen!L29*1000 -> 109063.64 | M29: =+[1]Resumen!M29*1000 -> 87684.647 | ... AC29: =+[1]Resumen!AC29*1000 -> 111664.03
D30: Festivo | E30: 3 | F30: =+[1]Resumen!F30*1000 -> 119360.9 | G30: =+[1]Resumen!G30*1000 -> 104300.16 | H30: =+[1]Resumen!H30*1000 -> 93714.152 | I30: =+[1]Resumen!I30*1000 -> 89127.259 | J30: =+[1]Resumen!J30*1000 -> 92447.021 | K30: =+[1]Resumen!K30*1000 -> 98042.983 | L30: =+[1]Resumen!L30*1000 -> 113008.46 | M30: =+[1]Resumen!M30*1000 -> 96638.507 | ... AC30: =+[1]Resumen!AC30*1000 -> 115066.38
C31: Jul | D31: Ordinario | E31: 22 | F31: =+[1]Resumen!F31*1000 -> 111395.06 | G31: =+[1]Resumen!G31*1000 -> 95549.342 | H31: =+[1]Resumen!H31*1000 -> 86511.813 | I31: =+[1]Resumen!I31*1000 -> 84800.992 | J31: =+[1]Resumen!J31*1000 -> 93713.584 | K31: =+[1]Resumen!K31*1000 -> 130766.24 | L31: =+[1]Resumen!L31*1000 -> 161606.47 | M31: =+[1]Resumen!M31*1000 -> 138969.21 | ... AC31: =+[1]Resumen!AC31*1000 -> 113949.5 | AD31: =SUM(F31:AC31)*E31+SUM(F32:AC32)*E32+SUM(F33:AC33)*E33+SUM(F34:AC34)*E34 -> 1.146364e+08
D32: Sábado | E32: 4 | F32: =+[1]Resumen!F32*1000 -> 94480.721 | G32: =+[1]Resumen!G32*1000 -> 78200.282 | H32: =+[1]Resumen!H32*1000 -> 70254.735 | I32: =+[1]Resumen!I32*1000 -> 66910.173 | J32: =+[1]Resumen!J32*1000 -> 73361.995 | K32: =+[1]Resumen!K32*1000 -> 87097.96 | L32: =+[1]Resumen!L32*1000 -> 114925.82 | M32: =+[1]Resumen!M32*1000 -> 105411.87 | ... AC32: =+[1]Resumen!AC32*1000 -> 104711.86
D33: Domingo | E33: 4 | F33: =+[1]Resumen!F33*1000 -> 104995.13 | G33: =+[1]Resumen!G33*1000 -> 89480.85 | H33: =+[1]Resumen!H33*1000 -> 77508.266 | I33: =+[1]Resumen!I33*1000 -> 70866.596 | J33: =+[1]Resumen!J33*1000 -> 72472.088 | K33: =+[1]Resumen!K33*1000 -> 76677.508 | L33: =+[1]Resumen!L33*1000 -> 86786.574 | M33: =+[1]Resumen!M33*1000 -> 65230.885 | ... AC33: =+[1]Resumen!AC33*1000 -> 103027.65
D34: Festivo | E34: 1 | F34: =+[1]Resumen!F34*1000 -> 93016.275 | G34: =+[1]Resumen!G34*1000 -> 77028.305 | H34: =+[1]Resumen!H34*1000 -> 62098.385 | I34: =+[1]Resumen!I34*1000 -> 57687.715 | J34: =+[1]Resumen!J34*1000 -> 60148.628 | K34: =+[1]Resumen!K34*1000 -> 68814.671 | L34: =+[1]Resumen!L34*1000 -> 85410.852 | M34: =+[1]Resumen!M34*1000 -> 67324.317 | ... AC34: =+[1]Resumen!AC34*1000 -> 94870.993
C35: Ago | D35: Ordinario | E35: 19 | F35: =+[1]Resumen!F35*1000 -> 116018.31 | G35: =+[1]Resumen!G35*1000 -> 101434.98 | H35: =+[1]Resumen!H35*1000 -> 93375.266 | I35: =+[1]Resumen!I35*1000 -> 92247.186 | J35: =+[1]Resumen!J35*1000 -> 103398.42 | K35: =+[1]Resumen!K35*1000 -> 145002.07 | L35: =+[1]Resumen!L35*1000 -> 179527.26 | M35: =+[1]Resumen!M35*1000 -> 156646.53 | ... AC35: =+[1]Resumen!AC35*1000 -> 127383.1 | AD35: =SUM(F35:AC35)*E35+SUM(F36:AC36)*E36+SUM(F37:AC37)*E37+SUM(F38:AC38)*E38 -> 1.2230665e+08
D36: Sábado | E36: 5 | F36: =+[1]Resumen!F36*1000 -> 127554.56 | G36: =+[1]Resumen!G36*1000 -> 108898.14 | H36: =+[1]Resumen!H36*1000 -> 97110.007 | I36: =+[1]Resumen!I36*1000 -> 91193.694 | J36: =+[1]Resumen!J36*1000 -> 96745.608 | K36: =+[1]Resumen!K36*1000 -> 111546.48 | L36: =+[1]Resumen!L36*1000 -> 138647.11 | M36: =+[1]Resumen!M36*1000 -> 127470.83 | ... AC36: =+[1]Resumen!AC36*1000 -> 113318.02
D37: Domingo | E37: 5 | F37: =+[1]Resumen!F37*1000 -> 105974.65 | G37: =+[1]Resumen!G37*1000 -> 90750.372 | H37: =+[1]Resumen!H37*1000 -> 81208.745 | I37: =+[1]Resumen!I37*1000 -> 76092.945 | J37: =+[1]Resumen!J37*1000 -> 76903.778 | K37: =+[1]Resumen!K37*1000 -> 84595.339 | L37: =+[1]Resumen!L37*1000 -> 94833.483 | M37: =+[1]Resumen!M37*1000 -> 73997.663 | ... AC37: =+[1]Resumen!AC37*1000 -> 96357.006
D38: Festivo | E38: 2 | F38: =+[1]Resumen!F38*1000 -> 111048.4 | G38: =+[1]Resumen!G38*1000 -> 96990.19 | H38: =+[1]Resumen!H38*1000 -> 87054.61 | I38: =+[1]Resumen!I38*1000 -> 82412.212 | J38: =+[1]Resumen!J38*1000 -> 86221.735 | K38: =+[1]Resumen!K38*1000 -> 92719.579 | L38: =+[1]Resumen!L38*1000 -> 104768.7 | M38: =+[1]Resumen!M38*1000 -> 85093.807 | ... AC38: =+[1]Resumen!AC38*1000 -> 96732.797
C39: Sep | D39: Ordinario | E39: 22 | F39: =+[1]Resumen!F39*1000 -> 122809.59 | G39: =+[1]Resumen!G39*1000 -> 107837.44 | H39: =+[1]Resumen!H39*1000 -> 99418.993 | I39: =+[1]Resumen!I39*1000 -> 98469.153 | J39: =+[1]Resumen!J39*1000 -> 108821.95 | K39: =+[1]Resumen!K39*1000 -> 148947.87 | L39: =+[1]Resumen!L39*1000 -> 182723.34 | M39: =+[1]Resumen!M39*1000 -> 162830.14 | ... AC39: =+[1]Resumen!AC39*1000 -> 133752.25 | AD39: =SUM(F39:AC39)*E39+SUM(F40:AC40)*E40+SUM(F41:AC41)*E41+SUM(F42:AC42)*E42 -> 1.2785128e+08
D40: Sábado | E40: 4 | F40: =+[1]Resumen!F40*1000 -> 122014.01 | G40: =+[1]Resumen!G40*1000 -> 105531.49 | H40: =+[1]Resumen!H40*1000 -> 95634.803 | I40: =+[1]Resumen!I40*1000 -> 91279.905 | J40: =+[1]Resumen!J40*1000 -> 98019.587 | K40: =+[1]Resumen!K40*1000 -> 115169.69 | L40: =+[1]Resumen!L40*1000 -> 141733.45 | M40: =+[1]Resumen!M40*1000 -> 132093.29 | ... AC40: =+[1]Resumen!AC40*1000 -> 116274.35
D41: Domingo | E41: 4 | F41: =+[1]Resumen!F41*1000 -> 116121.45 | G41: =+[1]Resumen!G41*1000 -> 99250.793 | H41: =+[1]Resumen!H41*1000 -> 87315.79 | I41: =+[1]Resumen!I41*1000 -> 80667.157 | J41: =+[1]Resumen!J41*1000 -> 82086.114 | K41: =+[1]Resumen!K41*1000 -> 85145.791 | L41: =+[1]Resumen!L41*1000 -> 97500.078 | M41: =+[1]Resumen!M41*1000 -> 77010.166 | ... AC41: =+[1]Resumen!AC41*1000 -> 95820.481
D42: Festivo | E42: 0 | F42: =+[1]Resumen!F42*1000 -> 0 | G42: =+[1]Resumen!G42*1000 -> 0 | H42: =+[1]Resumen!H42*1000 -> 0 | I42: =+[1]Resumen!I42*1000 -> 0 | J42: =+[1]Resumen!J42*1000 -> 0 | K42: =+[1]Resumen!K42*1000 -> 0 | L42: =+[1]Resumen!L42*1000 -> 0 | M42: =+[1]Resumen!M42*1000 -> 0 | ... AC42: =+[1]Resumen!AC42*1000 -> 0
...

Sheet Cantidades Producto 2
C2: CANTIDADES DE ENERGÍA SOLICITADAS (kWh)
C3: EMPRESAS PÚBLICAS DE MEDELLÍN E.S.P.
C4: 2027
C6: Mes | D6: Tipo Día | E6: Días | F6: H1 | G6: H2 | H6: H3 | I6: H4 | J6: H5 | K6: H6 | L6: H7 | M6: H8 | N6: H9 | O6: H10 | P6: H11 | Q6: H12 | R6: H13 | S6: H14 | T6: H15 | U6: H16 | V6: H17 | W6: H18 | X6: H19 | Y6: H20 | Z6: H21 | AA6: H22 | AB6: H23 | AC6: H24 | AD6: TOTAL MES
C7: Ene | D7: Ordinario | E7: 19 | F7: =+[2]Resumen!F7*1000 -> 115710.32 | G7: =+[2]Resumen!G7*1000 -> 101957.94 | H7: =+[2]Resumen!H7*1000 -> 93538.938 | I7: =+[2]Resumen!I7*1000 -> 91675.173 | J7: =+[2]Resumen!J7*1000 -> 97686.288 | K7: =+[2]Resumen!K7*1000 -> 124543.34 | L7: =+[2]Resumen!L7*1000 -> 151353.3 | M7: =+[2]Resumen!M7*1000 -> 149962.64 | ... AC7: =+[2]Resumen!AC7*1000 -> 120528.2 | AD7: =SUM(F7:AC7)*E7+SUM(F8:AC8)*E8+SUM(F9:AC9)*E9+SUM(F10:AC10)*E10 -> 1.1354692e+08
D8: Sábado | E8: 5 | F8: =+[2]Resumen!F8*1000 -> 110346.05 | G8: =+[2]Resumen!G8*1000 -> 96453.5 | H8: =+[2]Resumen!H8*1000 -> 87470.246 | I8: =+[2]Resumen!I8*1000 -> 83063.781 | J8: =+[2]Resumen!J8*1000 -> 89294.708 | K8: =+[2]Resumen!K8*1000 -> 102528.35 | L8: =+[2]Resumen!L8*1000 -> 121151.68 | M8: =+[2]Resumen!M8*1000 -> 120428.82 | ... AC8: =+[2]Resumen!AC8*1000 -> 105364.25
D9: Domingo | E9: 5 | F9: =+[2]Resumen!F9*1000 -> 111200.19 | G9: =+[2]Resumen!G9*1000 -> 95703.301 | H9: =+[2]Resumen!H9*1000 -> 84804.677 | I9: =+[2]Resumen!I9*1000 -> 78266.48 | J9: =+[2]Resumen!J9*1000 -> 79855.6 | K9: =+[2]Resumen!K9*1000 -> 85888.576 | L9: =+[2]Resumen!L9*1000 -> 94614.885 | M9: =+[2]Resumen!M9*1000 -> 88121.043 | ... AC9: =+[2]Resumen!AC9*1000 -> 89092.621
D10: Festivo | E10: 2 | F10: =+[2]Resumen!F10*1000 -> 90234.562 | G10: =+[2]Resumen!G10*1000 -> 81366.752 | H10: =+[2]Resumen!H10*1000 -> 71366.057 | I10: =+[2]Resumen!I10*1000 -> 65984.807 | J10: =+[2]Resumen!J10*1000 -> 66237.569 | K10: =+[2]Resumen!K10*1000 -> 71995.244 | L10: =+[2]Resumen!L10*1000 -> 72167.404 | M10: =+[2]Resumen!M10*1000 -> 58277.004 | ... AC10: =+[2]Resumen!AC10*1000 -> 74514.476
C11: Feb | D11: Ordinario | E11: 20 | F11: =+[2]Resumen!F11*1000 -> 142727.67 | G11: =+[2]Resumen!G11*1000 -> 127519.34 | H11: =+[2]Resumen!H11*1000 -> 119498.97 | I11: =+[2]Resumen!I11*1000 -> 118620.55 | J11: =+[2]Resumen!J11*1000 -> 132857.02 | K11: =+[2]Resumen!K11*1000 -> 181222.63 | L11: =+[2]Resumen!L11*1000 -> 212287.64 | M11: =+[2]Resumen!M11*1000 -> 203982.92 | ... AC11: =+[2]Resumen!AC11*1000 -> 142613.71 | AD11: =SUM(F11:AC11)*E11+SUM(F12:AC12)*E12+SUM(F13:AC13)*E13+SUM(F14:AC14)*E14 -> 1.3781334e+08
D12: Sábado | E12: 4 | F12: =+[2]Resumen!F12*1000 -> 145400.79 | G12: =+[2]Resumen!G12*1000 -> 128442.64 | H12: =+[2]Resumen!H12*1000 -> 117247.55 | I12: =+[2]Resumen!I12*1000 -> 113283.47 | J12: =+[2]Resumen!J12*1000 -> 119871.57 | K12: =+[2]Resumen!K12*1000 -> 137437.93 | L12: =+[2]Resumen!L12*1000 -> 166364.21 | M12: =+[2]Resumen!M12*1000 -> 176787.25 | ... AC12: =+[2]Resumen!AC12*1000 -> 142380.91
D13: Domingo | E13: 4 | F13: =+[2]Resumen!F13*1000 -> 143518.8 | G13: =+[2]Resumen!G13*1000 -> 125387.63 | H13: =+[2]Resumen!H13*1000 -> 114268.27 | I13: =+[2]Resumen!I13*1000 -> 108837.66 | J13: =+[2]Resumen!J13*1000 -> 109750.36 | K13: =+[2]Resumen!K13*1000 -> 116593.88 | L13: =+[2]Resumen!L13*1000 -> 130257.06 | M13: =+[2]Resumen!M13*1000 -> 128468.55 | ... AC13: =+[2]Resumen!AC13*1000 -> 132078.38
D14: Festivo | E14: 0 | F14: =+[2]Resumen!F14*1000 -> 0 | G14: =+[2]Resumen!G14*1000 -> 0 | H14: =+[2]Resumen!H14*1000 -> 0 | I14: =+[2]Resumen!I14*1000 -> 0 | J14: =+[2]Resumen!J14*1000 -> 0 | K14: =+[2]Resumen!K14*1000 -> 0 | L14: =+[2]Resumen!L14*1000 -> 0 | M14: =+[2]Resumen!M14*1000 -> 0 | ... AC14: =+[2]Resumen!AC14*1000 -> 0
C15: Mar | D15: Ordinario | E15: 20 | F15: =+[2]Resumen!F15*1000 -> 113341.39 | G15: =+[2]Resumen!G15*1000 -> 99310.301 | H15: =+[2]Resumen!H15*1000 -> 91432.503 | I15: =+[2]Resumen!I15*1000 -> 89602.138 | J15: =+[2]Resumen!J15*1000 -> 94827.59 | K15: =+[2]Resumen!K15*1000 -> 126965.08 | L15: =+[2]Resumen!L15*1000 -> 148993.76 | M15: =+[2]Resumen!M15*1000 -> 143269.29 | ... AC15: =+[2]Resumen!AC15*1000 -> 113642.51 | AD15: =SUM(F15:AC15)*E15+SUM(F16:AC16)*E16+SUM(F17:AC17)*E17+SUM(F18:AC18)*E18 -> 1.04893e+08
D16: Sábado | E16: 4 | F16: =+[2]Resumen!F16*1000 -> 107964.46 | G16: =+[2]Resumen!G16*1000 -> 92967.496 | H16: =+[2]Resumen!H16*1000 -> 83944.946 | I16: =+[2]Resumen!I16*1000 -> 79151.774 | J16: =+[2]Resumen!J16*1000 -> 81136.254 | K16: =+[2]Resumen!K16*1000 -> 88965.318 | L16: =+[2]Resumen!L16*1000 -> 103584.76 | M16: =+[2]Resumen!M16*1000 -> 107605.08 | ... AC16: =+[2]Resumen!AC16*1000 -> 97195.144
D17: Domingo | E17: 4 | F17: =+[2]Resumen!F17*1000 -> 105494.67 | G17: =+[2]Resumen!G17*1000 -> 92184.735 | H17: =+[2]Resumen!H17*1000 -> 82264.727 | I17: =+[2]Resumen!I17*1000 -> 77269.529 | J17: =+[2]Resumen!J17*1000 -> 77995.087 | K17: =+[2]Resumen!K17*1000 -> 81161.016 | L17: =+[2]Resumen!L17*1000 -> 87758.313 | M17: =+[2]Resumen!M17*1000 -> 82461.49 | ... AC17: =+[2]Resumen!AC17*1000 -> 81956.079
D18: Festivo | E18: 3 | F18: =+[2]Resumen!F18*1000 -> 96957.166 | G18: =+[2]Resumen!G18*1000 -> 84721.667 | H18: =+[2]Resumen!H18*1000 -> 77103.479 | I18: =+[2]Resumen!I18*1000 -> 70388.225 | J18: =+[2]Resumen!J18*1000 -> 72782.217 | K18: =+[2]Resumen!K18*1000 -> 77741.25 | L18: =+[2]Resumen!L18*1000 -> 86180.909 | M18: =+[2]Resumen!M18*1000 -> 86701.173 | ... AC18: =+[2]Resumen!AC18*1000 -> 93552.032
C19: Abr | D19: Ordinario | E19: 22 | F19: =+[2]Resumen!F19*1000 -> 111767.55 | G19: =+[2]Resumen!G19*1000 -> 98873.672 | H19: =+[2]Resumen!H19*1000 -> 91876.993 | I19: =+[2]Resumen!I19*1000 -> 91489.554 | J19: =+[2]Resumen!J19*1000 -> 103887.38 | K19: =+[2]Resumen!K19*1000 -> 147957.92 | L19: =+[2]Resumen!L19*1000 -> 174706.73 | M19: =+[2]Resumen!M19*1000 -> 164771.58 | ... AC19: =+[2]Resumen!AC19*1000 -> 113022.66 | AD19: =SUM(F19:AC19)*E19+SUM(F20:AC20)*E20+SUM(F21:AC21)*E21+SUM(F22:AC22)*E22 -> 1.1894706e+08
D20: Sábado | E20: 4 | F20: =+[2]Resumen!F20*1000 -> 119958.46 | G20: =+[2]Resumen!G20*1000 -> 107505.13 | H20: =+[2]Resumen!H20*1000 -> 95121.248 | I20: =+[2]Resumen!I20*1000 -> 91683.567 | J20: =+[2]Resumen!J20*1000 -> 98874.67 | K20: =+[2]Resumen!K20*1000 -> 115729.76 | L20: =+[2]Resumen!L20*1000 -> 147326.36 | M20: =+[2]Resumen!M20*1000 -> 160960.53 | ... AC20: =+[2]Resumen!AC20*1000 -> 108852.3
D21: Domingo | E21: 4 | F21: =+[2]Resumen!F21*1000 -> 115356.24 | G21: =+[2]Resumen!G21*1000 -> 99824.129 | H21: =+[2]Resumen!H21*1000 -> 89159.986 | I21: =+[2]Resumen!I21*1000 -> 83360.821 | J21: =+[2]Resumen!J21*1000 -> 83602.105 | K21: =+[2]Resumen!K21*1000 -> 88470.274 | L21: =+[2]Resumen!L21*1000 -> 100309.76 | M21: =+[2]Resumen!M21*1000 -> 97102.27 | ... AC21: =+[2]Resumen!AC21*1000 -> 89357.838
D22: Festivo | E22: 0 | F22: =+[2]Resumen!F22*1000 -> 0 | G22: =+[2]Resumen!G22*1000 -> 0 | H22: =+[2]Resumen!H22*1000 -> 0 | I22: =+[2]Resumen!I22*1000 -> 0 | J22: =+[2]Resumen!J22*1000 -> 0 | K22: =+[2]Resumen!K22*1000 -> 0 | L22: =+[2]Resumen!L22*1000 -> 0 | M22: =+[2]Resumen!M22*1000 -> 0 | ... AC22: =+[2]Resumen!AC22*1000 -> 0
C23: May | D23: Ordinario | E23: 19 | F23: =+[2]Resumen!F23*1000 -> 90690.455 | G23: =+[2]Resumen!G23*1000 -> 73819.683 | H23: =+[2]Resumen!H23*1000 -> 64953.015 | I23: =+[2]Resumen!I23*1000 -> 61046.134 | J23: =+[2]Resumen!J23*1000 -> 55625.489 | K23: =+[2]Resumen!K23*1000 -> 53551.448 | L23: =+[2]Resumen!L23*1000 -> 71946.579 | M23: =+[2]Resumen!M23*1000 -> 87920.807 | ... AC23: =+[2]Resumen!AC23*1000 -> 79637.974 | AD23: =SUM(F23:AC23)*E23+SUM(F24:AC24)*E24+SUM(F25:AC25)*E25+SUM(F26:AC26)*E26 -> 1.068194e+08
D24: Sábado | E24: 4 | F24: =+[2]Resumen!F24*1000 -> 53036.379 | G24: =+[2]Resumen!G24*1000 -> 45739.064 | H24: =+[2]Resumen!H24*1000 -> 40252.752 | I24: =+[2]Resumen!I24*1000 -> 42449.716 | J24: =+[2]Resumen!J24*1000 -> 59196.452 | K24: =+[2]Resumen!K24*1000 -> 88540.046 | L24: =+[2]Resumen!L24*1000 -> 139151.93 | M24: =+[2]Resumen!M24*1000 -> 157722.78 | ... AC24: =+[2]Resumen!AC24*1000 -> 71876.396
D25: Domingo | E25: 5 | F25: =+[2]Resumen!F25*1000 -> 72477.72 | G25: =+[2]Resumen!G25*1000 -> 63715.108 | H25: =+[2]Resumen!H25*1000 -> 57695.682 | I25: =+[2]Resumen!I25*1000 -> 60232.601 | J25: =+[2]Resumen!J25*1000 -> 87434.857 | K25: =+[2]Resumen!K25*1000 -> 127702.94 | L25: =+[2]Resumen!L25*1000 -> 193545.52 | M25: =+[2]Resumen!M25*1000 -> 224754.1 | ... AC25: =+[2]Resumen!AC25*1000 -> 96473.784
D26: Festivo | E26: 3 | F26: =+[2]Resumen!F26*1000 -> 85548.637 | G26: =+[2]Resumen!G26*1000 -> 70010.46 | H26: =+[2]Resumen!H26*1000 -> 62449.132 | I26: =+[2]Resumen!I26*1000 -> 62920.358 | J26: =+[2]Resumen!J26*1000 -> 79781.41 | K26: =+[2]Resumen!K26*1000 -> 103475.87 | L26: =+[2]Resumen!L26*1000 -> 149617.28 | M26: =+[2]Resumen!M26*1000 -> 172447.2 | ... AC26: =+[2]Resumen!AC26*1000 -> 86488.08
C27: Jun | D27: Ordinario | E27: 21 | F27: =+[2]Resumen!F27*1000 -> 117079.46 | G27: =+[2]Resumen!G27*1000 -> 103122.58 | H27: =+[2]Resumen!H27*1000 -> 94960.37 | I27: =+[2]Resumen!I27*1000 -> 95173.935 | J27: =+[2]Resumen!J27*1000 -> 103169.13 | K27: =+[2]Resumen!K27*1000 -> 129138.26 | L27: =+[2]Resumen!L27*1000 -> 158554.73 | M27: =+[2]Resumen!M27*1000 -> 162976.93 | ... AC27: =+[2]Resumen!AC27*1000 -> 118972.62 | AD27: =SUM(F27:AC27)*E27+SUM(F28:AC28)*E28+SUM(F29:AC29)*E29+SUM(F30:AC30)*E30 -> 1.1872409e+08
D28: Sábado | E28: 4 | F28: =+[2]Resumen!F28*1000 -> 120889.58 | G28: =+[2]Resumen!G28*1000 -> 104524.33 | H28: =+[2]Resumen!H28*1000 -> 97221.202 | I28: =+[2]Resumen!I28*1000 -> 92580.423 | J28: =+[2]Resumen!J28*1000 -> 98526.946 | K28: =+[2]Resumen!K28*1000 -> 110878.55 | L28: =+[2]Resumen!L28*1000 -> 138102.24 | M28: =+[2]Resumen!M28*1000 -> 141192.71 | ... AC28: =+[2]Resumen!AC28*1000 -> 112517.42
D29: Domingo | E29: 4 | F29: =+[2]Resumen!F29*1000 -> 122395.62 | G29: =+[2]Resumen!G29*1000 -> 107874.87 | H29: =+[2]Resumen!H29*1000 -> 96223.139 | I29: =+[2]Resumen!I29*1000 -> 89756.313 | J29: =+[2]Resumen!J29*1000 -> 89391.497 | K29: =+[2]Resumen!K29*1000 -> 93325.533 | L29: =+[2]Resumen!L29*1000 -> 101214.29 | M29: =+[2]Resumen!M29*1000 -> 96848.494 | ... AC29: =+[2]Resumen!AC29*1000 -> 97673.172
D30: Festivo | E30: 1 | F30: =+[2]Resumen!F30*1000 -> 112217.32 | G30: =+[2]Resumen!G30*1000 -> 99805.719 | H30: =+[2]Resumen!H30*1000 -> 90636.709 | I30: =+[2]Resumen!I30*1000 -> 86556.709 | J30: =+[2]Resumen!J30*1000 -> 89095.645 | K30: =+[2]Resumen!K30*1000 -> 93783.551 | L30: =+[2]Resumen!L30*1000 -> 106367.36 | M30: =+[2]Resumen!M30*1000 -> 107382.31 | ... AC30: =+[2]Resumen!AC30*1000 -> 100898.28
C31: Jul | D31: Ordinario | E31: 20 | F31: =+[2]Resumen!F31*1000 -> 77323.214 | G31: =+[2]Resumen!G31*1000 -> 63664.227 | H31: =+[2]Resumen!H31*1000 -> 55724.723 | I31: =+[2]Resumen!I31*1000 -> 53900.482 | J31: =+[2]Resumen!J31*1000 -> 60609.276 | K31: =+[2]Resumen!K31*1000 -> 91984.926 | L31: =+[2]Resumen!L31*1000 -> 116996.61 | M31: =+[2]Resumen!M31*1000 -> 105359.53 | ... AC31: =+[2]Resumen!AC31*1000 -> 92136.527 | AD31: =SUM(F31:AC31)*E31+SUM(F32:AC32)*E32+SUM(F33:AC33)*E33+SUM(F34:AC34)*E34 -> 85800296
D32: Sábado | E32: 5 | F32: =+[2]Resumen!F32*1000 -> 57499.24 | G32: =+[2]Resumen!G32*1000 -> 43590.05 | H32: =+[2]Resumen!H32*1000 -> 37310.564 | I32: =+[2]Resumen!I32*1000 -> 34425.915 | J32: =+[2]Resumen!J32*1000 -> 39197.379 | K32: =+[2]Resumen!K32*1000 -> 50154.418 | L32: =+[2]Resumen!L32*1000 -> 73618.526 | M32: =+[2]Resumen!M32*1000 -> 74265.628 | ... AC32: =+[2]Resumen!AC32*1000 -> 82856.53
D33: Domingo | E33: 4 | F33: =+[2]Resumen!F33*1000 -> 69017.386 | G33: =+[2]Resumen!G33*1000 -> 55920.404 | H33: =+[2]Resumen!H33*1000 -> 45856.953 | I33: =+[2]Resumen!I33*1000 -> 40151.05 | J33: =+[2]Resumen!J33*1000 -> 41388.112 | K33: =+[2]Resumen!K33*1000 -> 45139.804 | L33: =+[2]Resumen!L33*1000 -> 53270.023 | M33: =+[2]Resumen!M33*1000 -> 43548.484 | ... AC33: =+[2]Resumen!AC33*1000 -> 84052.879
D34: Festivo | E34: 2 | F34: =+[2]Resumen!F34*1000 -> 56189.916 | G34: =+[2]Resumen!G34*1000 -> 42277.938 | H34: =+[2]Resumen!H34*1000 -> 28799.572 | I34: =+[2]Resumen!I34*1000 -> 25286.307 | J34: =+[2]Resumen!J34*1000 -> 26603.972 | K34: =+[2]Resumen!K34*1000 -> 34043.74 | L34: =+[2]Resumen!L34*1000 -> 49255.963 | M34: =+[2]Resumen!M34*1000 -> 42386.937 | ... AC34: =+[2]Resumen!AC34*1000 -> 76689.99
C35: Ago | D35: Ordinario | E35: 21 | F35: =+[2]Resumen!F35*1000 -> 69034.996 | G35: =+[2]Resumen!G35*1000 -> 56813.223 | H35: =+[2]Resumen!H35*1000 -> 49883.032 | I35: =+[2]Resumen!I35*1000 -> 48707.417 | J35: =+[2]Resumen!J35*1000 -> 58254.9 | K35: =+[2]Resumen!K35*1000 -> 95885.492 | L35: =+[2]Resumen!L35*1000 -> 124080.15 | M35: =+[2]Resumen!M35*1000 -> 110726.5 | ... AC35: =+[2]Resumen!AC35*1000 -> 94118.249 | AD35: =SUM(F35:AC35)*E35+SUM(F36:AC36)*E36+SUM(F37:AC37)*E37+SUM(F38:AC38)*E38 -> 86838019
D36: Sábado | E36: 3 | F36: =+[2]Resumen!F36*1000 -> 81217.314 | G36: =+[2]Resumen!G36*1000 -> 64899.308 | H36: =+[2]Resumen!H36*1000 -> 54304.899 | I36: =+[2]Resumen!I36*1000 -> 48476.462 | J36: =+[2]Resumen!J36*1000 -> 52125.142 | K36: =+[2]Resumen!K36*1000 -> 64282.498 | L36: =+[2]Resumen!L36*1000 -> 86806.341 | M36: =+[2]Resumen!M36*1000 -> 85078.295 | ... AC36: =+[2]Resumen!AC36*1000 -> 80363.006
D37: Domingo | E37: 5 | F37: =+[2]Resumen!F37*1000 -> 57526.943 | G37: =+[2]Resumen!G37*1000 -> 45407.382 | H37: =+[2]Resumen!H37*1000 -> 37876.66 | I37: =+[2]Resumen!I37*1000 -> 33485.01 | J37: =+[2]Resumen!J37*1000 -> 34018.68 | K37: =+[2]Resumen!K37*1000 -> 41072.083 | L37: =+[2]Resumen!L37*1000 -> 49182.504 | M37: =+[2]Resumen!M37*1000 -> 39963.39 | ... AC37: =+[2]Resumen!AC37*1000 -> 65056.98
D38: Festivo | E38: 2 | F38: =+[2]Resumen!F38*1000 -> 63864.165 | G38: =+[2]Resumen!G38*1000 -> 52752.501 | H38: =+[2]Resumen!H38*1000 -> 44346.989 | I38: =+[2]Resumen!I38*1000 -> 40126.28 | J38: =+[2]Resumen!J38*1000 -> 43035.304 | K38: =+[2]Resumen!K38*1000 -> 47883.227 | L38: =+[2]Resumen!L38*1000 -> 57518.145 | M38: =+[2]Resumen!M38*1000 -> 48851.051 | ... AC38: =+[2]Resumen!AC38*1000 -> 64557.8
C39: Sep | D39: Ordinario | E39: 22 | F39: =+[2]Resumen!F39*1000 -> 87460.245 | G39: =+[2]Resumen!G39*1000 -> 74801.766 | H39: =+[2]Resumen!H39*1000 -> 67460.57 | I39: =+[2]Resumen!I39*1000 -> 66395.31 | J39: =+[2]Resumen!J39*1000 -> 74922.952 | K39: =+[2]Resumen!K39*1000 -> 111042 | L39: =+[2]Resumen!L39*1000 -> 138098.13 | M39: =+[2]Resumen!M39*1000 -> 127692.23 | ... AC39: =+[2]Resumen!AC39*1000 -> 111967.9 | AD39: =SUM(F39:AC39)*E39+SUM(F40:AC40)*E40+SUM(F41:AC41)*E41+SUM(F42:AC42)*E42 -> 1.0052052e+08
D40: Sábado | E40: 4 | F40: =+[2]Resumen!F40*1000 -> 84904.406 | G40: =+[2]Resumen!G40*1000 -> 71015.089 | H40: =+[2]Resumen!H40*1000 -> 62955.686 | I40: =+[2]Resumen!I40*1000 -> 58460.704 | J40: =+[2]Resumen!J40*1000 -> 63548.715 | K40: =+[2]Resumen!K40*1000 -> 78297.36 | L40: =+[2]Resumen!L40*1000 -> 99861.955 | M40: =+[2]Resumen!M40*1000 -> 99412.506 | ... AC40: =+[2]Resumen!AC40*1000 -> 95193.61
D41: Domingo | E41: 4 | F41: =+[2]Resumen!F41*1000 -> 80821.481 | G41: =+[2]Resumen!G41*1000 -> 66776.083 | H41: =+[2]Resumen!H41*1000 -> 56299.829 | I41: =+[2]Resumen!I41*1000 -> 49853.852 | J41: =+[2]Resumen!J41*1000 -> 51009.533 | K41: =+[2]Resumen!K41*1000 -> 52552.318 | L41: =+[2]Resumen!L41*1000 -> 63128.736 | M41: =+[2]Resumen!M41*1000 -> 54316.72 | ... AC41: =+[2]Resumen!AC41*1000 -> 76599.561
D42: Festivo | E42: 0 | F42: =+[2]Resumen!F42*1000 -> 0 | G42: =+[2]Resumen!G42*1000 -> 0 | H42: =+[2]Resumen!H42*1000 -> 0 | I42: =+[2]Resumen!I42*1000 -> 0 | J42: =+[2]Resumen!J42*1000 -> 0 | K42: =+[2]Resumen!K42*1000 -> 0 | L42: =+[2]Resumen!L42*1000 -> 0 | M42: =+[2]Resumen!M42*1000 -> 0 | ... AC42: =+[2]Resumen!AC42*1000 -> 0
...

Sheet Cantidades Producto 3
C2: CANTIDADES DE ENERGÍA SOLICITADAS (kWh)
C3: EMPRESAS PÚBLICAS DE MEDELLÍN E.S.P.
C4: 2028
C6: Mes | D6: Tipo Día | E6: Días | F6: H1 | G6: H2 | H6: H3 | I6: H4 | J6: H5 | K6: H6 | L6: H7 | M6: H8 | N6: H9 | O6: H10 | P6: H11 | Q6: H12 | R6: H13 | S6: H14 | T6: H15 | U6: H16 | V6: H17 | W6: H18 | X6: H19 | Y6: H20 | Z6: H21 | AA6: H22 | AB6: H23 | AC6: H24 | AD6: TOTAL MES
C7: Ene | D7: Ordinario | E7: 20 | F7: =+[3]Resumen!F7*1000 -> 89371.422 | G7: =+[3]Resumen!G7*1000 -> 69462.157 | H7: =+[3]Resumen!H7*1000 -> 58252.107 | I7: =+[3]Resumen!I7*1000 -> 56630.726 | J7: =+[3]Resumen!J7*1000 -> 75807.178 | K7: =+[3]Resumen!K7*1000 -> 117984.84 | L7: =+[3]Resumen!L7*1000 -> 162037.44 | M7: =+[3]Resumen!M7*1000 -> 171837.88 | ... AC7: =+[3]Resumen!AC7*1000 -> 129596.21 | AD7: =SUM(F7:AC7)*E7+SUM(F8:AC8)*E8+SUM(F9:AC9)*E9+SUM(F10:AC10)*E10 -> 1.3525605e+08
D8: Sábado | E8: 4 | F8: =+[3]Resumen!F8*1000 -> 93020.066 | G8: =+[3]Resumen!G8*1000 -> 71412.905 | H8: =+[3]Resumen!H8*1000 -> 58864.112 | I8: =+[3]Resumen!I8*1000 -> 54215.553 | J8: =+[3]Resumen!J8*1000 -> 65127.411 | K8: =+[3]Resumen!K8*1000 -> 86170.172 | L8: =+[3]Resumen!L8*1000 -> 119179.75 | M8: =+[3]Resumen!M8*1000 -> 132538.39 | ... AC8: =+[3]Resumen!AC8*1000 -> 124483.56
D9: Domingo | E9: 5 | F9: =+[3]Resumen!F9*1000 -> 93663.26 | G9: =+[3]Resumen!G9*1000 -> 70194.928 | H9: =+[3]Resumen!H9*1000 -> 55166.86 | I9: =+[3]Resumen!I9*1000 -> 47116.67 | J9: =+[3]Resumen!J9*1000 -> 49329.513 | K9: =+[3]Resumen!K9*1000 -> 58374.198 | L9: =+[3]Resumen!L9*1000 -> 73579.929 | M9: =+[3]Resumen!M9*1000 -> 74252.402 | ... AC9: =+[3]Resumen!AC9*1000 -> 102967.44
D10: Festivo | E10: 2 | F10: =+[3]Resumen!F10*1000 -> 83542.886 | G10: =+[3]Resumen!G10*1000 -> 66812.82 | H10: =+[3]Resumen!H10*1000 -> 50624.867 | I10: =+[3]Resumen!I10*1000 -> 41300.881 | J10: =+[3]Resumen!J10*1000 -> 41034.029 | K10: =+[3]Resumen!K10*1000 -> 47288.433 | L10: =+[3]Resumen!L10*1000 -> 50717.478 | M10: =+[3]Resumen!M10*1000 -> 41565.989 | ... AC10: =+[3]Resumen!AC10*1000 -> 87245.752
C11: Feb | D11: Ordinario | E11: 21 | F11: =+[3]Resumen!F11*1000 -> 100135.97 | G11: =+[3]Resumen!G11*1000 -> 79768.687 | H11: =+[3]Resumen!H11*1000 -> 69378.976 | I11: =+[3]Resumen!I11*1000 -> 68911.009 | J11: =+[3]Resumen!J11*1000 -> 95395.138 | K11: =+[3]Resumen!K11*1000 -> 155541.71 | L11: =+[3]Resumen!L11*1000 -> 205701.97 | M11: =+[3]Resumen!M11*1000 -> 210684.77 | ... AC11: =+[3]Resumen!AC11*1000 -> 136682.83 | AD11: =SUM(F11:AC11)*E11+SUM(F12:AC12)*E12+SUM(F13:AC13)*E13+SUM(F14:AC14)*E14 -> 1.4899673e+08
D12: Sábado | E12: 4 | F12: =+[3]Resumen!F12*1000 -> 113131.67 | G12: =+[3]Resumen!G12*1000 -> 89458.619 | H12: =+[3]Resumen!H12*1000 -> 74966.806 | I12: =+[3]Resumen!I12*1000 -> 70481.667 | J12: =+[3]Resumen!J12*1000 -> 80449.296 | K12: =+[3]Resumen!K12*1000 -> 102020.57 | L12: =+[3]Resumen!L12*1000 -> 142327.92 | M12: =+[3]Resumen!M12*1000 -> 165892.49 | ... AC12: =+[3]Resumen!AC12*1000 -> 141821.42
D13: Domingo | E13: 4 | F13: =+[3]Resumen!F13*1000 -> 111294.88 | G13: =+[3]Resumen!G13*1000 -> 86426.124 | H13: =+[3]Resumen!H13*1000 -> 70594.352 | I13: =+[3]Resumen!I13*1000 -> 62057.08 | J13: =+[3]Resumen!J13*1000 -> 62974.228 | K13: =+[3]Resumen!K13*1000 -> 71336.59 | L13: =+[3]Resumen!L13*1000 -> 88153.731 | M13: =+[3]Resumen!M13*1000 -> 91319.479 | ... AC13: =+[3]Resumen!AC13*1000 -> 120877.63
D14: Festivo | E14: 0 | F14: =+[3]Resumen!F14*1000 -> 0 | G14: =+[3]Resumen!G14*1000 -> 0 | H14: =+[3]Resumen!H14*1000 -> 0 | I14: =+[3]Resumen!I14*1000 -> 0 | J14: =+[3]Resumen!J14*1000 -> 0 | K14: =+[3]Resumen!K14*1000 -> 0 | L14: =+[3]Resumen!L14*1000 -> 0 | M14: =+[3]Resumen!M14*1000 -> 0 | ... AC14: =+[3]Resumen!AC14*1000 -> 0
C15: Mar | D15: Ordinario | E15: 22 | F15: =+[3]Resumen!F15*1000 -> 84714.946 | G15: =+[3]Resumen!G15*1000 -> 64651.556 | H15: =+[3]Resumen!H15*1000 -> 53969.572 | I15: =+[3]Resumen!I15*1000 -> 52875.296 | J15: =+[3]Resumen!J15*1000 -> 72903.724 | K15: =+[3]Resumen!K15*1000 -> 121590.2 | L15: =+[3]Resumen!L15*1000 -> 164644.99 | M15: =+[3]Resumen!M15*1000 -> 174200.09 | ... AC15: =+[3]Resumen!AC15*1000 -> 121499.59 | AD15: =SUM(F15:AC15)*E15+SUM(F16:AC16)*E16+SUM(F17:AC17)*E17+SUM(F18:AC18)*E18 -> 1.3277833e+08
D16: Sábado | E16: 4 | F16: =+[3]Resumen!F16*1000 -> 89972.734 | G16: =+[3]Resumen!G16*1000 -> 67580.444 | H16: =+[3]Resumen!H16*1000 -> 54836.404 | I16: =+[3]Resumen!I16*1000 -> 50232.546 | J16: =+[3]Resumen!J16*1000 -> 58749.84 | K16: =+[3]Resumen!K16*1000 -> 77416.783 | L16: =+[3]Resumen!L16*1000 -> 109793.78 | M16: =+[3]Resumen!M16*1000 -> 128444.73 | ... AC16: =+[3]Resumen!AC16*1000 -> 116733.39
D17: Domingo | E17: 4 | F17: =+[3]Resumen!F17*1000 -> 88586.142 | G17: =+[3]Resumen!G17*1000 -> 66817.511 | H17: =+[3]Resumen!H17*1000 -> 52267.058 | I17: =+[3]Resumen!I17*1000 -> 45071.245 | J17: =+[3]Resumen!J17*1000 -> 47205.216 | K17: =+[3]Resumen!K17*1000 -> 55039.015 | L17: =+[3]Resumen!L17*1000 -> 68991.479 | M17: =+[3]Resumen!M17*1000 -> 74435.587 | ... AC17: =+[3]Resumen!AC17*1000 -> 95282.082
D18: Festivo | E18: 1 | F18: =+[3]Resumen!F18*1000 -> 76302.949 | G18: =+[3]Resumen!G18*1000 -> 54746.771 | H18: =+[3]Resumen!H18*1000 -> 42597.36 | I18: =+[3]Resumen!I18*1000 -> 35744.409 | J18: =+[3]Resumen!J18*1000 -> 40070.831 | K18: =+[3]Resumen!K18*1000 -> 49771.469 | L18: =+[3]Resumen!L18*1000 -> 65437.037 | M18: =+[3]Resumen!M18*1000 -> 74272.471 | ... AC18: =+[3]Resumen!AC18*1000 -> 96229.081
C19: Abr | D19: Ordinario | E19: 18 | F19: =+[3]Resumen!F19*1000 -> 89066.541 | G19: =+[3]Resumen!G19*1000 -> 69951.937 | H19: =+[3]Resumen!H19*1000 -> 60067.719 | I19: =+[3]Resumen!I19*1000 -> 60197.296 | J19: =+[3]Resumen!J19*1000 -> 85111.034 | K19: =+[3]Resumen!K19*1000 -> 140595.82 | L19: =+[3]Resumen!L19*1000 -> 187127.91 | M19: =+[3]Resumen!M19*1000 -> 196090.3 | ... AC19: =+[3]Resumen!AC19*1000 -> 125848.71 | AD19: =SUM(F19:AC19)*E19+SUM(F20:AC20)*E20+SUM(F21:AC21)*E21+SUM(F22:AC22)*E22 -> 1.3833478e+08
D20: Sábado | E20: 5 | F20: =+[3]Resumen!F20*1000 -> 100709.07 | G20: =+[3]Resumen!G20*1000 -> 80954.832 | H20: =+[3]Resumen!H20*1000 -> 65629.999 | I20: =+[3]Resumen!I20*1000 -> 61449.231 | J20: =+[3]Resumen!J20*1000 -> 73391.232 | K20: =+[3]Resumen!K20*1000 -> 95633.87 | L20: =+[3]Resumen!L20*1000 -> 136809.47 | M20: =+[3]Resumen!M20*1000 -> 164011.02 | ... AC20: =+[3]Resumen!AC20*1000 -> 127620.97
D21: Domingo | E21: 5 | F21: =+[3]Resumen!F21*1000 -> 98807.602 | G21: =+[3]Resumen!G21*1000 -> 75353.78 | H21: =+[3]Resumen!H21*1000 -> 60249.798 | I21: =+[3]Resumen!I21*1000 -> 52542.137 | J21: =+[3]Resumen!J21*1000 -> 54128.131 | K21: =+[3]Resumen!K21*1000 -> 61291.073 | L21: =+[3]Resumen!L21*1000 -> 78654.786 | M21: =+[3]Resumen!M21*1000 -> 85984.338 | ... AC21: =+[3]Resumen!AC21*1000 -> 103798.88
D22: Festivo | E22: 2 | F22: =+[3]Resumen!F22*1000 -> 99420.664 | G22: =+[3]Resumen!G22*1000 -> 76108.553 | H22: =+[3]Resumen!H22*1000 -> 60592.874 | I22: =+[3]Resumen!I22*1000 -> 52499.289 | J22: =+[3]Resumen!J22*1000 -> 53726.489 | K22: =+[3]Resumen!K22*1000 -> 60684.056 | L22: =+[3]Resumen!L22*1000 -> 79176.52 | M22: =+[3]Resumen!M22*1000 -> 86307.417 | ... AC22: =+[3]Resumen!AC22*1000 -> 101049.66
C23: May | D23: Ordinario | E23: 21 | F23: =+[3]Resumen!F23*1000 -> 68093.623 | G23: =+[3]Resumen!G23*1000 -> 46022.188 | H23: =+[3]Resumen!H23*1000 -> 34544.946 | I23: =+[3]Resumen!I23*1000 -> 32195.406 | J23: =+[3]Resumen!J23*1000 -> 44232.764 | K23: =+[3]Resumen!K23*1000 -> 61877.504 | L23: =+[3]Resumen!L23*1000 -> 103717.78 | M23: =+[3]Resumen!M23*1000 -> 132051.24 | ... AC23: =+[3]Resumen!AC23*1000 -> 96329.585 | AD23: =SUM(F23:AC23)*E23+SUM(F24:AC24)*E24+SUM(F25:AC25)*E25+SUM(F26:AC26)*E26 -> 1.3117665e+08
D24: Sábado | E24: 4 | F24: =+[3]Resumen!F24*1000 -> 48022.146 | G24: =+[3]Resumen!G24*1000 -> 31359.403 | H24: =+[3]Resumen!H24*1000 -> 21944.458 | I24: =+[3]Resumen!I24*1000 -> 23384.324 | J24: =+[3]Resumen!J24*1000 -> 46338.827 | K24: =+[3]Resumen!K24*1000 -> 81277.965 | L24: =+[3]Resumen!L24*1000 -> 141754.72 | M24: =+[3]Resumen!M24*1000 -> 173226.6 | ... AC24: =+[3]Resumen!AC24*1000 -> 93587.99
D25: Domingo | E25: 4 | F25: =+[3]Resumen!F25*1000 -> 58712.236 | G25: =+[3]Resumen!G25*1000 -> 39757.194 | H25: =+[3]Resumen!H25*1000 -> 30364.348 | I25: =+[3]Resumen!I25*1000 -> 32431.628 | J25: =+[3]Resumen!J25*1000 -> 58065.33 | K25: =+[3]Resumen!K25*1000 -> 96563.972 | L25: =+[3]Resumen!L25*1000 -> 161953.96 | M25: =+[3]Resumen!M25*1000 -> 196620.76 | ... AC25: =+[3]Resumen!AC25*1000 -> 105534.68
D26: Festivo | E26: 2 | F26: =+[3]Resumen!F26*1000 -> 67230.752 | G26: =+[3]Resumen!G26*1000 -> 44163.017 | H26: =+[3]Resumen!H26*1000 -> 32118.192 | I26: =+[3]Resumen!I26*1000 -> 31223.871 | J26: =+[3]Resumen!J26*1000 -> 48338.268 | K26: =+[3]Resumen!K26*1000 -> 70234.677 | L26: =+[3]Resumen!L26*1000 -> 119649.49 | M26: =+[3]Resumen!M26*1000 -> 151104.26 | ... AC26: =+[3]Resumen!AC26*1000 -> 102170.16
C27: Jun | D27: Ordinario | E27: 20 | F27: =+[3]Resumen!F27*1000 -> 88614.517 | G27: =+[3]Resumen!G27*1000 -> 68387.44 | H27: =+[3]Resumen!H27*1000 -> 57240.453 | I27: =+[3]Resumen!I27*1000 -> 57459.28 | J27: =+[3]Resumen!J27*1000 -> 78368.054 | K27: =+[3]Resumen!K27*1000 -> 117341.7 | L27: =+[3]Resumen!L27*1000 -> 166372.41 | M27: =+[3]Resumen!M27*1000 -> 188151.12 | ... AC27: =+[3]Resumen!AC27*1000 -> 128331.65 | AD27: =SUM(F27:AC27)*E27+SUM(F28:AC28)*E28+SUM(F29:AC29)*E29+SUM(F30:AC30)*E30 -> 1.3947566e+08
D28: Sábado | E28: 4 | F28: =+[3]Resumen!F28*1000 -> 102000.61 | G28: =+[3]Resumen!G28*1000 -> 78215.771 | H28: =+[3]Resumen!H28*1000 -> 66603.715 | I28: =+[3]Resumen!I28*1000 -> 61827.851 | J28: =+[3]Resumen!J28*1000 -> 73621.543 | K28: =+[3]Resumen!K28*1000 -> 93714.34 | L28: =+[3]Resumen!L28*1000 -> 135440.14 | M28: =+[3]Resumen!M28*1000 -> 155368.34 | ... AC28: =+[3]Resumen!AC28*1000 -> 130165.03
D29: Domingo | E29: 4 | F29: =+[3]Resumen!F29*1000 -> 103450.06 | G29: =+[3]Resumen!G29*1000 -> 80086.997 | H29: =+[3]Resumen!H29*1000 -> 63944.176 | I29: =+[3]Resumen!I29*1000 -> 55572.062 | J29: =+[3]Resumen!J29*1000 -> 56776.526 | K29: =+[3]Resumen!K29*1000 -> 62463.352 | L29: =+[3]Resumen!L29*1000 -> 79541.785 | M29: =+[3]Resumen!M29*1000 -> 87073.825 | ... AC29: =+[3]Resumen!AC29*1000 -> 107251.39
D30: Festivo | E30: 2 | F30: =+[3]Resumen!F30*1000 -> 87869.35 | G30: =+[3]Resumen!G30*1000 -> 67751.702 | H30: =+[3]Resumen!H30*1000 -> 54220.705 | I30: =+[3]Resumen!I30*1000 -> 48738.385 | J30: =+[3]Resumen!J30*1000 -> 54136.236 | K30: =+[3]Resumen!K30*1000 -> 62132.581 | L30: =+[3]Resumen!L30*1000 -> 81538.061 | M30: =+[3]Resumen!M30*1000 -> 93565.229 | ... AC30: =+[3]Resumen!AC30*1000 -> 104942.46
C31: Jul | D31: Ordinario | E31: 19 | F31: =+[3]Resumen!F31*1000 -> 78365.593 | G31: =+[3]Resumen!G31*1000 -> 58245.569 | H31: =+[3]Resumen!H31*1000 -> 47184.168 | I31: =+[3]Resumen!I31*1000 -> 45568.396 | J31: =+[3]Resumen!J31*1000 -> 66579.647 | K31: =+[3]Resumen!K31*1000 -> 113554.07 | L31: =+[3]Resumen!L31*1000 -> 158680.11 | M31: =+[3]Resumen!M31*1000 -> 169282.59 | ... AC31: =+[3]Resumen!AC31*1000 -> 111446.74 | AD31: =SUM(F31:AC31)*E31+SUM(F32:AC32)*E32+SUM(F33:AC33)*E33+SUM(F34:AC34)*E34 -> 1.2747981e+08
D32: Sábado | E32: 5 | F32: =+[3]Resumen!F32*1000 -> 72655.726 | G32: =+[3]Resumen!G32*1000 -> 50493.845 | H32: =+[3]Resumen!H32*1000 -> 39120.144 | I32: =+[3]Resumen!I32*1000 -> 35370.286 | J32: =+[3]Resumen!J32*1000 -> 45754.285 | K32: =+[3]Resumen!K32*1000 -> 65236.9 | L32: =+[3]Resumen!L32*1000 -> 103699.13 | M32: =+[3]Resumen!M32*1000 -> 127634.28 | ... AC32: =+[3]Resumen!AC32*1000 -> 109769.28
D33: Domingo | E33: 5 | F33: =+[3]Resumen!F33*1000 -> 81188.928 | G33: =+[3]Resumen!G33*1000 -> 58386.386 | H33: =+[3]Resumen!H33*1000 -> 43593.994 | I33: =+[3]Resumen!I33*1000 -> 35878.962 | J33: =+[3]Resumen!J33*1000 -> 37803.365 | K33: =+[3]Resumen!K33*1000 -> 44786.536 | L33: =+[3]Resumen!L33*1000 -> 60512.051 | M33: =+[3]Resumen!M33*1000 -> 67907.94 | ... AC33: =+[3]Resumen!AC33*1000 -> 100198.81
D34: Festivo | E34: 2 | F34: =+[3]Resumen!F34*1000 -> 69472.577 | G34: =+[3]Resumen!G34*1000 -> 46842.023 | H34: =+[3]Resumen!H34*1000 -> 29842.42 | I34: =+[3]Resumen!I34*1000 -> 24733.13 | J34: =+[3]Resumen!J34*1000 -> 28760.017 | K34: =+[3]Resumen!K34*1000 -> 39366.361 | L34: =+[3]Resumen!L34*1000 -> 61684.239 | M34: =+[3]Resumen!M34*1000 -> 71600.24 | ... AC34: =+[3]Resumen!AC34*1000 -> 98223.601
C35: Ago | D35: Ordinario | E35: 21 | F35: =+[3]Resumen!F35*1000 -> 73541.152 | G35: =+[3]Resumen!G35*1000 -> 54723.269 | H35: =+[3]Resumen!H35*1000 -> 44825.55 | I35: =+[3]Resumen!I35*1000 -> 43828.339 | J35: =+[3]Resumen!J35*1000 -> 67225.927 | K35: =+[3]Resumen!K35*1000 -> 119209.36 | L35: =+[3]Resumen!L35*1000 -> 166732.66 | M35: =+[3]Resumen!M35*1000 -> 174805.69 | ... AC35: =+[3]Resumen!AC35*1000 -> 113429.64 | AD35: =SUM(F35:AC35)*E35+SUM(F36:AC36)*E36+SUM(F37:AC37)*E37+SUM(F38:AC38)*E38 -> 1.3147171e+08
D36: Sábado | E36: 4 | F36: =+[3]Resumen!F36*1000 -> 90928.288 | G36: =+[3]Resumen!G36*1000 -> 68029.023 | H36: =+[3]Resumen!H36*1000 -> 53522.469 | I36: =+[3]Resumen!I36*1000 -> 48454.302 | J36: =+[3]Resumen!J36*1000 -> 58105.219 | K36: =+[3]Resumen!K36*1000 -> 79274.708 | L36: =+[3]Resumen!L36*1000 -> 116764.34 | M36: =+[3]Resumen!M36*1000 -> 137883.25 | ... AC36: =+[3]Resumen!AC36*1000 -> 108674.64
D37: Domingo | E37: 4 | F37: =+[3]Resumen!F37*1000 -> 75077.845 | G37: =+[3]Resumen!G37*1000 -> 53307.033 | H37: =+[3]Resumen!H37*1000 -> 40103.459 | I37: =+[3]Resumen!I37*1000 -> 33007.238 | J37: =+[3]Resumen!J37*1000 -> 35483.342 | K37: =+[3]Resumen!K37*1000 -> 44616.013 | L37: =+[3]Resumen!L37*1000 -> 59670.136 | M37: =+[3]Resumen!M37*1000 -> 67180.74 | ... AC37: =+[3]Resumen!AC37*1000 -> 90398.497
D38: Festivo | E38: 2 | F38: =+[3]Resumen!F38*1000 -> 78825.564 | G38: =+[3]Resumen!G38*1000 -> 58711.471 | H38: =+[3]Resumen!H38*1000 -> 46148.933 | I38: =+[3]Resumen!I38*1000 -> 40570.139 | J38: =+[3]Resumen!J38*1000 -> 47150.289 | K38: =+[3]Resumen!K38*1000 -> 56408.758 | L38: =+[3]Resumen!L38*1000 -> 75296.945 | M38: =+[3]Resumen!M38*1000 -> 84945.919 | ... AC38: =+[3]Resumen!AC38*1000 -> 89411.311
C39: Sep | D39: Ordinario | E39: 21 | F39: =+[3]Resumen!F39*1000 -> 85320.675 | G39: =+[3]Resumen!G39*1000 -> 65957.811 | H39: =+[3]Resumen!H39*1000 -> 55828.269 | I39: =+[3]Resumen!I39*1000 -> 55246.401 | J39: =+[3]Resumen!J39*1000 -> 78251.498 | K39: =+[3]Resumen!K39*1000 -> 130114.17 | L39: =+[3]Resumen!L39*1000 -> 177822.17 | M39: =+[3]Resumen!M39*1000 -> 188493.86 | ... AC39: =+[3]Resumen!AC39*1000 -> 125611.44 | AD39: =SUM(F39:AC39)*E39+SUM(F40:AC40)*E40+SUM(F41:AC41)*E41+SUM(F42:AC42)*E42 -> 1.3973544e+08
D40: Sábado | E40: 5 | F40: =+[3]Resumen!F40*1000 -> 97713.345 | G40: =+[3]Resumen!G40*1000 -> 75290.28 | H40: =+[3]Resumen!H40*1000 -> 61995.804 | I40: =+[3]Resumen!I40*1000 -> 57489.611 | J40: =+[3]Resumen!J40*1000 -> 68708.903 | K40: =+[3]Resumen!K40*1000 -> 90968.669 | L40: =+[3]Resumen!L40*1000 -> 128207.65 | M40: =+[3]Resumen!M40*1000 -> 151413.9 | ... AC40: =+[3]Resumen!AC40*1000 -> 118447.11
D41: Domingo | E41: 4 | F41: =+[3]Resumen!F41*1000 -> 89484.011 | G41: =+[3]Resumen!G41*1000 -> 66591.982 | H41: =+[3]Resumen!H41*1000 -> 51447.594 | I41: =+[3]Resumen!I41*1000 -> 43644.072 | J41: =+[3]Resumen!J41*1000 -> 45547.598 | K41: =+[3]Resumen!K41*1000 -> 50427.64 | L41: =+[3]Resumen!L41*1000 -> 67447.713 | M41: =+[3]Resumen!M41*1000 -> 75342.716 | ... AC41: =+[3]Resumen!AC41*1000 -> 92743.548
D42: Festivo | E42: 0 | F42: =+[3]Resumen!F42*1000 -> 0 | G42: =+[3]Resumen!G42*1000 -> 0 | H42: =+[3]Resumen!H42*1000 -> 0 | I42: =+[3]Resumen!I42*1000 -> 0 | J42: =+[3]Resumen!J42*1000 -> 0 | K42: =+[3]Resumen!K42*1000 -> 0 | L42: =+[3]Resumen!L42*1000 -> 0 | M42: =+[3]Resumen!M42*1000 -> 0 | ... AC42: =+[3]Resumen!AC42*1000 -> 0
...

Sheet Cantidades Producto 4
C2: CANTIDADES DE ENERGÍA SOLICITADAS (kWh)
C3: EMPRESAS PÚBLICAS DE MEDELLÍN E.S.P.
C4: 2029
C6: Mes | D6: Tipo Día | E6: Días | F6: H1 | G6: H2 | H6: H3 | I6: H4 | J6: H5 | K6: H6 | L6: H7 | M6: H8 | N6: H9 | O6: H10 | P6: H11 | Q6: H12 | R6: H13 | S6: H14 | T6: H15 | U6: H16 | V6: H17 | W6: H18 | X6: H19 | Y6: H20 | Z6: H21 | AA6: H22 | AB6: H23 | AC6: H24 | AD6: TOTAL MES
C7: Ene | D7: Ordinario | E7: 21 | F7: =+[4]Resumen!F7*1000 -> 118757.34 | G7: =+[4]Resumen!G7*1000 -> 102891.79 | H7: =+[4]Resumen!H7*1000 -> 94097.321 | I7: =+[4]Resumen!I7*1000 -> 92952.769 | J7: =+[4]Resumen!J7*1000 -> 107398.68 | K7: =+[4]Resumen!K7*1000 -> 141025.88 | L7: =+[4]Resumen!L7*1000 -> 176289.8 | M7: =+[4]Resumen!M7*1000 -> 180693.88 | ... AC7: =+[4]Resumen!AC7*1000 -> 151567.68 | AD7: =SUM(F7:AC7)*E7+SUM(F8:AC8)*E8+SUM(F9:AC9)*E9+SUM(F10:AC10)*E10 -> 1.4309377e+08
D8: Sábado | E8: 4 | F8: =+[4]Resumen!F8*1000 -> 121163.73 | G8: =+[4]Resumen!G8*1000 -> 103958.37 | H8: =+[4]Resumen!H8*1000 -> 94056.2 | I8: =+[4]Resumen!I8*1000 -> 90471.329 | J8: =+[4]Resumen!J8*1000 -> 99400.801 | K8: =+[4]Resumen!K8*1000 -> 116168.19 | L8: =+[4]Resumen!L8*1000 -> 142801.72 | M8: =+[4]Resumen!M8*1000 -> 150464.67 | ... AC8: =+[4]Resumen!AC8*1000 -> 146761.71
D9: Domingo | E9: 4 | F9: =+[4]Resumen!F9*1000 -> 121368.45 | G9: =+[4]Resumen!G9*1000 -> 102682.39 | H9: =+[4]Resumen!H9*1000 -> 90765.589 | I9: =+[4]Resumen!I9*1000 -> 84468.253 | J9: =+[4]Resumen!J9*1000 -> 86270.961 | K9: =+[4]Resumen!K9*1000 -> 93413.192 | L9: =+[4]Resumen!L9*1000 -> 105731.29 | M9: =+[4]Resumen!M9*1000 -> 103235.72 | ... AC9: =+[4]Resumen!AC9*1000 -> 129850.2
D10: Festivo | E10: 2 | F10: =+[4]Resumen!F10*1000 -> 114742.55 | G10: =+[4]Resumen!G10*1000 -> 101406.29 | H10: =+[4]Resumen!H10*1000 -> 88610.569 | I10: =+[4]Resumen!I10*1000 -> 81121.088 | J10: =+[4]Resumen!J10*1000 -> 80953.62 | K10: =+[4]Resumen!K10*1000 -> 85683.481 | L10: =+[4]Resumen!L10*1000 -> 88765.617 | M10: =+[4]Resumen!M10*1000 -> 78441.969 | ... AC10: =+[4]Resumen!AC10*1000 -> 117924.27
C11: Feb | D11: Ordinario | E11: 20 | F11: =+[4]Resumen!F11*1000 -> 138817.22 | G11: =+[4]Resumen!G11*1000 -> 122107.87 | H11: =+[4]Resumen!H11*1000 -> 113548.01 | I11: =+[4]Resumen!I11*1000 -> 113229.26 | J11: =+[4]Resumen!J11*1000 -> 133769.65 | K11: =+[4]Resumen!K11*1000 -> 182819.56 | L11: =+[4]Resumen!L11*1000 -> 223689.69 | M11: =+[4]Resumen!M11*1000 -> 224632.25 | ... AC11: =+[4]Resumen!AC11*1000 -> 169816.07 | AD11: =SUM(F11:AC11)*E11+SUM(F12:AC12)*E12+SUM(F13:AC13)*E13+SUM(F14:AC14)*E14 -> 1.551214e+08
D12: Sábado | E12: 4 | F12: =+[4]Resumen!F12*1000 -> 148018.19 | G12: =+[4]Resumen!G12*1000 -> 128972.9 | H12: =+[4]Resumen!H12*1000 -> 117397.8 | I12: =+[4]Resumen!I12*1000 -> 114255.69 | J12: =+[4]Resumen!J12*1000 -> 124021.82 | K12: =+[4]Resumen!K12*1000 -> 144939.06 | L12: =+[4]Resumen!L12*1000 -> 179006.45 | M12: =+[4]Resumen!M12*1000 -> 194126.73 | ... AC12: =+[4]Resumen!AC12*1000 -> 173539.89
D13: Domingo | E13: 4 | F13: =+[4]Resumen!F13*1000 -> 147050.55 | G13: =+[4]Resumen!G13*1000 -> 126859.68 | H13: =+[4]Resumen!H13*1000 -> 114127.9 | I13: =+[4]Resumen!I13*1000 -> 107686.03 | J13: =+[4]Resumen!J13*1000 -> 109690.83 | K13: =+[4]Resumen!K13*1000 -> 117994.03 | L13: =+[4]Resumen!L13*1000 -> 133917.41 | M13: =+[4]Resumen!M13*1000 -> 135243.96 | ... AC13: =+[4]Resumen!AC13*1000 -> 157259.92
D14: Festivo | E14: 0 | F14: =+[4]Resumen!F14*1000 -> 0 | G14: =+[4]Resumen!G14*1000 -> 0 | H14: =+[4]Resumen!H14*1000 -> 0 | I14: =+[4]Resumen!I14*1000 -> 0 | J14: =+[4]Resumen!J14*1000 -> 0 | K14: =+[4]Resumen!K14*1000 -> 0 | L14: =+[4]Resumen!L14*1000 -> 0 | M14: =+[4]Resumen!M14*1000 -> 0 | ... AC14: =+[4]Resumen!AC14*1000 -> 0
C15: Mar | D15: Ordinario | E15: 19 | F15: =+[4]Resumen!F15*1000 -> 120918.43 | G15: =+[4]Resumen!G15*1000 -> 104899.21 | H15: =+[4]Resumen!H15*1000 -> 96426.536 | I15: =+[4]Resumen!I15*1000 -> 95725.735 | J15: =+[4]Resumen!J15*1000 -> 111698.73 | K15: =+[4]Resumen!K15*1000 -> 152362.81 | L15: =+[4]Resumen!L15*1000 -> 187624.5 | M15: =+[4]Resumen!M15*1000 -> 191818.75 | ... AC15: =+[4]Resumen!AC15*1000 -> 152042.41 | AD15: =SUM(F15:AC15)*E15+SUM(F16:AC16)*E16+SUM(F17:AC17)*E17+SUM(F18:AC18)*E18 -> 1.4315175e+08
D16: Sábado | E16: 5 | F16: =+[4]Resumen!F16*1000 -> 125124.25 | G16: =+[4]Resumen!G16*1000 -> 107150.39 | H16: =+[4]Resumen!H16*1000 -> 96965.007 | I16: =+[4]Resumen!I16*1000 -> 93524.248 | J16: =+[4]Resumen!J16*1000 -> 101136.89 | K16: =+[4]Resumen!K16*1000 -> 116882.18 | L16: =+[4]Resumen!L16*1000 -> 144026.94 | M16: =+[4]Resumen!M16*1000 -> 156394.94 | ... AC16: =+[4]Resumen!AC16*1000 -> 147673.33
D17: Domingo | E17: 4 | F17: =+[4]Resumen!F17*1000 -> 123782.76 | G17: =+[4]Resumen!G17*1000 -> 106068.24 | H17: =+[4]Resumen!H17*1000 -> 94460.312 | I17: =+[4]Resumen!I17*1000 -> 88632.6 | J17: =+[4]Resumen!J17*1000 -> 90551.537 | K17: =+[4]Resumen!K17*1000 -> 97231.18 | L17: =+[4]Resumen!L17*1000 -> 108847.19 | M17: =+[4]Resumen!M17*1000 -> 110708.86 | ... AC17: =+[4]Resumen!AC17*1000 -> 130018.28
D18: Festivo | E18: 3 | F18: =+[4]Resumen!F18*1000 -> 114783.49 | G18: =+[4]Resumen!G18*1000 -> 97240.717 | H18: =+[4]Resumen!H18*1000 -> 87406.618 | I18: =+[4]Resumen!I18*1000 -> 82145.13 | J18: =+[4]Resumen!J18*1000 -> 85645.269 | K18: =+[4]Resumen!K18*1000 -> 93977.798 | L18: =+[4]Resumen!L18*1000 -> 106686.79 | M18: =+[4]Resumen!M18*1000 -> 110216.46 | ... AC18: =+[4]Resumen!AC18*1000 -> 131560.92
C19: Abr | D19: Ordinario | E19: 21 | F19: =+[4]Resumen!F19*1000 -> 118751.11 | G19: =+[4]Resumen!G19*1000 -> 103631.35 | H19: =+[4]Resumen!H19*1000 -> 95827.588 | I19: =+[4]Resumen!I19*1000 -> 95956.043 | J19: =+[4]Resumen!J19*1000 -> 114703.78 | K19: =+[4]Resumen!K19*1000 -> 158369.39 | L19: =+[4]Resumen!L19*1000 -> 195225.38 | M19: =+[4]Resumen!M19*1000 -> 199311.11 | ... AC19: =+[4]Resumen!AC19*1000 -> 149225.62 | AD19: =SUM(F19:AC19)*E19+SUM(F20:AC20)*E20+SUM(F21:AC21)*E21+SUM(F22:AC22)*E22 -> 1.4607574e+08
D20: Sábado | E20: 4 | F20: =+[4]Resumen!F20*1000 -> 126780.28 | G20: =+[4]Resumen!G20*1000 -> 111022.22 | H20: =+[4]Resumen!H20*1000 -> 99123.572 | I20: =+[4]Resumen!I20*1000 -> 96061.042 | J20: =+[4]Resumen!J20*1000 -> 106021.77 | K20: =+[4]Resumen!K20*1000 -> 123839.85 | L20: =+[4]Resumen!L20*1000 -> 156392.92 | M20: =+[4]Resumen!M20*1000 -> 174232.08 | ... AC20: =+[4]Resumen!AC20*1000 -> 149548.32
D21: Domingo | E21: 5 | F21: =+[4]Resumen!F21*1000 -> 125800.93 | G21: =+[4]Resumen!G21*1000 -> 107234.48 | H21: =+[4]Resumen!H21*1000 -> 95483.489 | I21: =+[4]Resumen!I21*1000 -> 89575.114 | J21: =+[4]Resumen!J21*1000 -> 91310.645 | K21: =+[4]Resumen!K21*1000 -> 97464.535 | L21: =+[4]Resumen!L21*1000 -> 111669.28 | M21: =+[4]Resumen!M21*1000 -> 114791.8 | ... AC21: =+[4]Resumen!AC21*1000 -> 131356.25
D22: Festivo | E22: 0 | F22: =+[4]Resumen!F22*1000 -> 0 | G22: =+[4]Resumen!G22*1000 -> 0 | H22: =+[4]Resumen!H22*1000 -> 0 | I22: =+[4]Resumen!I22*1000 -> 0 | J22: =+[4]Resumen!J22*1000 -> 0 | K22: =+[4]Resumen!K22*1000 -> 0 | L22: =+[4]Resumen!L22*1000 -> 0 | M22: =+[4]Resumen!M22*1000 -> 0 | ... AC22: =+[4]Resumen!AC22*1000 -> 0
C23: May | D23: Ordinario | E23: 21 | F23: =+[4]Resumen!F23*1000 -> 105718.31 | G23: =+[4]Resumen!G23*1000 -> 88234.695 | H23: =+[4]Resumen!H23*1000 -> 79095.73 | I23: =+[4]Resumen!I23*1000 -> 77343.888 | J23: =+[4]Resumen!J23*1000 -> 86237.148 | K23: =+[4]Resumen!K23*1000 -> 100868.12 | L23: =+[4]Resumen!L23*1000 -> 134875.2 | M23: =+[4]Resumen!M23*1000 -> 154413.73 | ... AC23: =+[4]Resumen!AC23*1000 -> 129854.76 | AD23: =SUM(F23:AC23)*E23+SUM(F24:AC24)*E24+SUM(F25:AC25)*E25+SUM(F26:AC26)*E26 -> 1.4173246e+08
D24: Sábado | E24: 4 | F24: =+[4]Resumen!F24*1000 -> 90604.178 | G24: =+[4]Resumen!G24*1000 -> 77004.23 | H24: =+[4]Resumen!H24*1000 -> 69460.766 | I24: =+[4]Resumen!I24*1000 -> 70436.847 | J24: =+[4]Resumen!J24*1000 -> 88570.981 | K24: =+[4]Resumen!K24*1000 -> 115658.18 | L24: =+[4]Resumen!L24*1000 -> 163728.83 | M24: =+[4]Resumen!M24*1000 -> 186429.79 | ... AC24: =+[4]Resumen!AC24*1000 -> 127713.02
D25: Domingo | E25: 4 | F25: =+[4]Resumen!F25*1000 -> 98854.36 | G25: =+[4]Resumen!G25*1000 -> 83372.12 | H25: =+[4]Resumen!H25*1000 -> 75768.825 | I25: =+[4]Resumen!I25*1000 -> 77124.351 | J25: =+[4]Resumen!J25*1000 -> 96702.652 | K25: =+[4]Resumen!K25*1000 -> 125804.83 | L25: =+[4]Resumen!L25*1000 -> 176072.89 | M25: =+[4]Resumen!M25*1000 -> 199821.4 | ... AC25: =+[4]Resumen!AC25*1000 -> 135719.93
D26: Festivo | E26: 2 | F26: =+[4]Resumen!F26*1000 -> 103570.62 | G26: =+[4]Resumen!G26*1000 -> 85478.378 | H26: =+[4]Resumen!H26*1000 -> 75697.742 | I26: =+[4]Resumen!I26*1000 -> 74779.042 | J26: =+[4]Resumen!J26*1000 -> 87694.557 | K26: =+[4]Resumen!K26*1000 -> 104167.73 | L26: =+[4]Resumen!L26*1000 -> 141751.41 | M26: =+[4]Resumen!M26*1000 -> 162540.47 | ... AC26: =+[4]Resumen!AC26*1000 -> 131475.83
C27: Jun | D27: Ordinario | E27: 19 | F27: =+[4]Resumen!F27*1000 -> 123470.61 | G27: =+[4]Resumen!G27*1000 -> 107275.92 | H27: =+[4]Resumen!H27*1000 -> 98488.59 | I27: =+[4]Resumen!I27*1000 -> 98709.823 | J27: =+[4]Resumen!J27*1000 -> 114859.75 | K27: =+[4]Resumen!K27*1000 -> 146733.54 | L27: =+[4]Resumen!L27*1000 -> 186307.09 | M27: =+[4]Resumen!M27*1000 -> 200448.17 | ... AC27: =+[4]Resumen!AC27*1000 -> 156414.25 | AD27: =SUM(F27:AC27)*E27+SUM(F28:AC28)*E28+SUM(F29:AC29)*E29+SUM(F30:AC30)*E30 -> 1.4805922e+08
D28: Sábado | E28: 5 | F28: =+[4]Resumen!F28*1000 -> 132926.56 | G28: =+[4]Resumen!G28*1000 -> 114105.34 | H28: =+[4]Resumen!H28*1000 -> 104730.07 | I28: =+[4]Resumen!I28*1000 -> 101014.45 | J28: =+[4]Resumen!J28*1000 -> 110940.04 | K28: =+[4]Resumen!K28*1000 -> 127300.84 | L28: =+[4]Resumen!L28*1000 -> 160731.16 | M28: =+[4]Resumen!M28*1000 -> 173932.08 | ... AC28: =+[4]Resumen!AC28*1000 -> 155775.02
D29: Domingo | E29: 4 | F29: =+[4]Resumen!F29*1000 -> 133005.23 | G29: =+[4]Resumen!G29*1000 -> 114343.77 | H29: =+[4]Resumen!H29*1000 -> 101642.33 | I29: =+[4]Resumen!I29*1000 -> 95083.169 | J29: =+[4]Resumen!J29*1000 -> 96257.38 | K29: =+[4]Resumen!K29*1000 -> 101117.1 | L29: =+[4]Resumen!L29*1000 -> 115316.97 | M29: =+[4]Resumen!M29*1000 -> 118500.53 | ... AC29: =+[4]Resumen!AC29*1000 -> 137968.48
D30: Festivo | E30: 2 | F30: =+[4]Resumen!F30*1000 -> 121130.13 | G30: =+[4]Resumen!G30*1000 -> 104893.14 | H30: =+[4]Resumen!H30*1000 -> 94166.555 | I30: =+[4]Resumen!I30*1000 -> 89841.746 | J30: =+[4]Resumen!J30*1000 -> 94232.546 | K30: =+[4]Resumen!K30*1000 -> 100594.68 | L30: =+[4]Resumen!L30*1000 -> 116143.52 | M30: =+[4]Resumen!M30*1000 -> 122529.83 | ... AC30: =+[4]Resumen!AC30*1000 -> 136186.64
C31: Jul | D31: Ordinario | E31: 20 | F31: =+[4]Resumen!F31*1000 -> 118597.44 | G31: =+[4]Resumen!G31*1000 -> 102500.37 | H31: =+[4]Resumen!H31*1000 -> 93708.647 | I31: =+[4]Resumen!I31*1000 -> 92544.682 | J31: =+[4]Resumen!J31*1000 -> 108490.85 | K31: =+[4]Resumen!K31*1000 -> 146514.07 | L31: =+[4]Resumen!L31*1000 -> 182950.17 | M31: =+[4]Resumen!M31*1000 -> 188273.95 | ... AC31: =+[4]Resumen!AC31*1000 -> 146911.76 | AD31: =SUM(F31:AC31)*E31+SUM(F32:AC32)*E32+SUM(F33:AC33)*E33+SUM(F34:AC34)*E34 -> 1.4337456e+08
D32: Sábado | E32: 4 | F32: =+[4]Resumen!F32*1000 -> 114277.61 | G32: =+[4]Resumen!G32*1000 -> 96575.999 | H32: =+[4]Resumen!H32*1000 -> 87400.623 | I32: =+[4]Resumen!I32*1000 -> 84427.673 | J32: =+[4]Resumen!J32*1000 -> 92974.807 | K32: =+[4]Resumen!K32*1000 -> 108912.65 | L32: =+[4]Resumen!L32*1000 -> 139854.65 | M32: =+[4]Resumen!M32*1000 -> 156044.61 | ... AC32: =+[4]Resumen!AC32*1000 -> 144585.54
D33: Domingo | E33: 5 | F33: =+[4]Resumen!F33*1000 -> 120705.83 | G33: =+[4]Resumen!G33*1000 -> 102528.54 | H33: =+[4]Resumen!H33*1000 -> 90654.554 | I33: =+[4]Resumen!I33*1000 -> 84418.201 | J33: =+[4]Resumen!J33*1000 -> 86002.477 | K33: =+[4]Resumen!K33*1000 -> 91481.947 | L33: =+[4]Resumen!L33*1000 -> 104137.13 | M33: =+[4]Resumen!M33*1000 -> 106987.3 | ... AC33: =+[4]Resumen!AC33*1000 -> 136255.55
D34: Festivo | E34: 2 | F34: =+[4]Resumen!F34*1000 -> 112249.92 | G34: =+[4]Resumen!G34*1000 -> 94387.594 | H34: =+[4]Resumen!H34*1000 -> 80877.573 | I34: =+[4]Resumen!I34*1000 -> 76755.499 | J34: =+[4]Resumen!J34*1000 -> 80207.275 | K34: =+[4]Resumen!K34*1000 -> 88767.214 | L34: =+[4]Resumen!L34*1000 -> 106236.04 | M34: =+[4]Resumen!M34*1000 -> 111267.03 | ... AC34: =+[4]Resumen!AC34*1000 -> 134206.36
